Workbook

Sheet Summary
B1: PUC DOCKET NO.
B2: ONCOR ELECTRIC DELIVERY COMPANY LLC
B3: CLASS ALLOCATION FACTORS
B4: FOR THE TEST YEAR ENDING 12/31/2024
B5: SPONSOR: MATTHEW A. TROXLE
B8: WORKPAPER - PRIMARY / SECONDARY SPLIT
A11: line | B11: Account 364 | C11: Total | D11: Primary | E11: Secondary | H11: Comment
B12: (a) | C12: (b) | D12: (c) | E12: (d)
A13: 1 | B13: Primary Only | C13: =Poles!C13 -> 1.7044701e+09 | D13: =C13 -> 1.7044701e+09
A14: =A13+1 -> 2 | B14: Secondary Only | C14: =D14+E14 -> 3.1565078e+08 | E14: =Poles!$C$14 -> 3.1565078e+08
A15: =A14+1 -> 3 | B15: Primary and Secondary | C15: =Poles!$C$15 -> 6.3607694e+08 | D15: =C15*C13/(C13+C14) -> 5.3668774e+08 | E15: =C15-D15 -> 99389191 | F15: <<< <<< <<< | H15: Split proportionately between primary and secondary
A16: =A15+1 -> 4 | B16: Total | C16: =SUM(C13:C15) -> 2.6561978e+09 | D16: =SUM(D13:D15) -> 2.2411579e+09 | E16: =SUM(E13:E15) -> 4.1503997e+08
A17: =A16+1 -> 5 | B17: Total Percentage | C17: =SUM(D17:F17) -> 1 | D17: =D16/$C$16 -> 0.84374659 | E17: =E16/$C$16 -> 0.15625341
A18: =A17+1 -> 6
A19: =A18+1 -> 7 | B19: Account 365 | C19: Total | D19: Primary | E19: Secondary | H19: Comment
A20: =A19+1 -> 8 | B20: (a) | C20: (b) | D20: (c) | E20: (d)
A21: =A20+1 -> 9 | B21: Primary Only | C21: =Conductors!C13 -> 1.1799976e+09 | D21: =C21 -> 1.1799976e+09
A22: =A21+1 -> 10 | B22: Secondary Only | C22: =Conductors!C16 -> 94309248 | E22: =C22 -> 94309248
A23: =A22+1 -> 11 | B23: Neutral | C23: =Conductors!C15 -> 4.0074778e+08 | D23: =$C$23/2 -> 2.0037389e+08 | E23: =$C$23/2 -> 2.0037389e+08 | F23: <<< <<< <<< | H23: Neutral is split equally between primary and secondary
A24: =A23+1 -> 12 | B24: Devices | C24: ='Other 365-368'!$D$13 -> 6.4948839e+08 | D24: =C24 -> 6.4948839e+08 | F24: <<< <<< <<< | H24: Devices such as switches are generally primary
A25: =A24+1 -> 13 | B25: Total Account | C25: =SUM(C21:C24) -> 2.324543e+09 | D25: =SUM(D21:D24) -> 2.0298599e+09 | E25: =SUM(E21:E24) -> 2.9468314e+08
A26: =A25+1 -> 14 | B26: Total Percentage | C26: =SUM(D26:E26) -> 1 | D26: =D25/$C$25 -> 0.87322965 | E26: =E25/$C$25 -> 0.12677035
A27: =A26+1 -> 15
A28: =A27+1 -> 16 | B28: Account 367 | C28: Total | D28: Primary | E28: Secondary | H28: Comment
A29: =A28+1 -> 17 | B29: (a) | C29: (b) | D29: (c) | E29: (d)
A30: =A29+1 -> 18 | B30: Primary Conductor Only | C30: =Conductors!$D$14 -> 1.6421272e+09 | D30: =C30 -> 1.6421272e+09
A31: =A30+1 -> 19 | B31: Secondary Conductor Only | C31: =Conductors!$D$17 -> 4.0941927e+08 | E31: =C31 -> 4.0941927e+08
B32: Neutral Conductor | C32: =Conductors!$D$15 -> 15527417 | D32: =C32/2 -> 7763708.5 | E32: =D32 -> 7763708.5 | F32: <<< <<< <<< | H32: Neutral is split equally between primary and secondary
A33: =A31+1 -> 20 | B33: Conductor subtotal | C33: =SUM(C30:C32) -> 2.0670739e+09 | D33: =SUM(D30:D32) -> 1.6498909e+09 | E33: =SUM(E30:E32) -> 4.1718298e+08
A34: =A33+1 -> 21 | B34: Devices | C34: ='Other 365-368'!$D$28 -> 5.3603824e+08 | D34: =C34 -> 5.3603824e+08 | F34: <<< <<< <<< | H34: Devices such as switchgear are generally primary
A35: =A34+1 -> 22 | B35: Network | C35: ='Other 365-368'!$D$29 -> 1492.68 | E35: =C35 -> 1492.68 | F35: <<< <<< <<< | H35: Network customers are secondary
A36: =A35+1 -> 23 | B36: Total Account | C36: =SUM(C33:C35) -> 2.6031136e+09 | D36: =SUM(D33:D35) -> 2.1859291e+09 | E36: =SUM(E33:E35) -> 4.1718447e+08
A37: =A36+1 -> 24 | B37: Conductor Percentage | C37: =SUM(D37:E37) -> 1 | D37: =D33/$C$33 -> 0.79817703 | E37: =E33/$C$33 -> 0.20182297
A38: =A37+1 -> 25 | B38: Total Percentage | C38: =SUM(D38:E38) -> 1 | D38: =D36/$C$36 -> 0.83973636 | E38: =E36/$C$36 -> 0.16026364
A39: =A38+1 -> 26
A40: =A39+1 -> 27 | B40: Account 366 | C40: Total | D40: Primary | E40: Secondary | H40: Comment
A41: =A40+1 -> 28 | B41: (a) | C41: (b) | D41: (c) | E41: (d)
A42: =A41+1 -> 29 | B42: Conduit | C42: ='Other 365-368'!$D$18 -> 9.6533652e+08 | D42: =$C42*D$37 -> 7.7050944e+08 | E42: =$C42*E$37 -> 1.9482708e+08 | F42: <<< <<< <<< | H42: Conduit is split on the basis of account 367 Conductor
A43: =A42+1 -> 30 | B43: Network Manholes | C43: ='Other 365-368'!$G$19 -> 0 | D43: 0 | E43: =$C43 -> 0 | F43: <<< <<< <<< | H43: Network customers are secondary
A44: =A43+1 -> 31 | B44: Other Manholes | C44: ='Other 365-368'!$I$19 -> 211086139 | D44: =$C$44 -> 211086139 | F44: <<< <<< <<< | H44: Non-Network manholes are usually primary
...

Sheet Poles
B1: =Summary!$B$1 -> PUC DOCKET NO.
B2: =Summary!$B$2 -> ONCOR ELECTRIC DELIVERY COMPANY LLC
B3: =Summary!$B$3 -> CLASS ALLOCATION FACTORS
B4: =Summary!$B$4 -> FOR THE TEST YEAR ENDING 12/31/2024
B5: =Summary!$B$5 -> SPONSOR: MATTHEW A. TROXLE
C8: WORKPAPER - Summary of Poles
C11: Plant Acct | D11: Plant Acct
B12: Description | C12: 364 | D12: 371 | E12: Total
B13: Primary Poles | C13: 1.7044701e+09 | E13: =SUM(C13:D13) -> 1.7044701e+09
B14: Secondary Poles | C14: 3.1565078e+08 | D14: 1392348.9 | E14: =SUM(C14:D14) -> 3.1704313e+08
B15: Primary & Secondary Poles | C15: 6.3607694e+08 | D15: 11099.17 | E15: =SUM(C15:D15) -> 6.3608803e+08
B16: Guardlights | C16: 1.1314872e+08 | D16: 1308590.6 | E16: =SUM(C16:D16) -> 1.1445731e+08
B18: Total | C18: =SUM(C13:C17) -> 2.7693465e+09 | D18: =SUM(D13:D17) -> 2712038.7 | E18: =SUM(E13:E17) -> 2.7720586e+09
B20: check: | C20: =(SUM(C13:C16)-C18)=0 -> TRUE | D20: =(SUM(D13:D16)-D18)=0 -> TRUE | E20: =(SUM(E13:E16)-E18)=0 -> TRUE

Sheet Conductors
B1: =Summary!$B$1 -> PUC DOCKET NO. | L1: check:
B2: =Summary!$B$2 -> ONCOR ELECTRIC DELIVERY COMPANY LLC
B3: =Summary!$B$3 -> CLASS ALLOCATION FACTORS
B4: =Summary!$B$4 -> FOR THE TEST YEAR ENDING 12/31/2024
B5: =Summary!$B$5 -> SPONSOR: MATTHEW A. TROXLE
D8: WORKPAPER - Summary of Conductors
C11: Account | D11: Account | E11: Account
B12: Description | C12: 365 | D12: 367 | E12: 373 | F12: Grand Total
B13: Primary OH Conductor | C13: 1.1799976e+09 | E13: 236.16 | F13: =SUM(C13:E13) -> 1.1799978e+09
B14: Primary UG Conductor | D14: 1.6421272e+09 | E14: 622.27262 | F14: =SUM(C14:E14) -> 1.6421278e+09
B15: Neutral Conductor | C15: 4.0074778e+08 | D15: 15527417 | E15: 235.96246 | F15: =SUM(C15:E15) -> 4.1627543e+08
B16: Secondary OH Conductor | C16: 94309248 | E16: 6153431 | F16: =SUM(C16:E16) -> 1.0046268e+08
B17: Secondary UG Conductor | D17: 4.0941927e+08 | E17: 4762494 | F17: =SUM(C17:E17) -> 4.1418177e+08
B18: Street Light OH Conductor | C18: 1631.2 | E18: 18774956 | F18: =SUM(C18:E18) -> 18776588
B19: Street Light UG Conductor | C19: 629.85 | D19: 39122.29 | E19: 43899748 | F19: =SUM(C19:E19) -> 43939501
F20: =SUM(C20:E20) -> 0 | H20: check:
B21: Total | C21: =SUM(C13:C20) -> 1.6750569e+09 | D21: =SUM(D13:D20) -> 2.067113e+09 | E21: =SUM(E14:E20) -> 73591488 | F21: =SUM(C21:E21) -> 3.8157614e+09 | H21: =IF((C21+D21+E21)-SUM(F13:F19)=0,TRUE,"check math") -> check math
C27: 365 | D27: 367 | E27: 373

Sheet Other 365-368
B1: =Summary!$B$1 -> PUC DOCKET NO. | F1: =Summary!$B$1 -> PUC DOCKET NO.
B2: =Summary!$B$2 -> ONCOR ELECTRIC DELIVERY COMPANY LLC | F2: =Summary!$B$2 -> ONCOR ELECTRIC DELIVERY COMPANY LLC
B3: =Summary!$B$3 -> CLASS ALLOCATION FACTORS | F3: =Summary!$B$3 -> CLASS ALLOCATION FACTORS
B4: =Summary!$B$4 -> FOR THE TEST YEAR ENDING 12/31/2024 | F4: =Summary!$B$4 -> FOR THE TEST YEAR ENDING 12/31/2024
B5: =Summary!$B$5 -> SPONSOR: MATTHEW A. TROXLE | F5: =Summary!$B$5 -> SPONSOR: MATTHEW A. TROXLE
B8: WORKPAPER - SUMMARY OF KEY ACCOUNTS
C12: Account | D12: Investment | E12: Key
C13: 365 | D13: 6.4948839e+08 | E13: Device
C14: 365 | D14: 1.5342344e+09 | E14: Wire
C15: 365 | D15: =SUM(D13:D14) -> 2.1837228e+09 | E15: Grand Total
C17: Account | D17: Investment | E17: Key
C18: 366 | D18: 9.6533652e+08 | E18: Conduit | G18: Network Manholes: | I18: Non-Network Manholes:
C19: 366 | D19: =G19+I19 -> 211086139 | E19: Manhole | G19: 0 | I19: 211086139
C20: 366 | D20: 1.5561036e+08 | E20: Pad
C21: 366 | D21: 80346608 | E21: Primary
C22: 366 | D22: 2.0351531e+08 | E22: Secondary
C23: 366 | D23: 21427897 | E23: Vault
C24: 366 | D24: =SUM(D18:D23) -> 1.6373228e+09 | E24: Grand Total
C26: Account | D26: Investment | E26: Key
C27: 367 | D27: 2.6408836e+09 | E27: Cable
C28: 367 | D28: 5.3603824e+08 | E28: Device
C29: 367 | D29: 1492.68 | E29: Network
C30: 367 | D30: =SUM(D27:D29) -> 3.1769233e+09 | E30: Grand Total | F30: note: do not include ntu
C32: Account | D32: Investment | E32: Key
C33: 368 | D33: 97829881 | E33: Auto Transformer
C34: 368 | D34: 1.6794885e+08 | E34: Capacitor Total
C35: 368 | D35: 2.7811394e+09 | E35: Other Total
C36: 368 | D36: 1.2074776e+08 | E36: Regulator Total
C37: 368 | D37: =SUM(D33:D36) -> 3.1676659e+09 | E37: Grand Total
