Workbook

Sheet 2018 Customer Count
A2: PUBLIC UTILITY COMMISSION OF TEXAS
A3: CENTERPOINT ENERGY HOUSTON ELECTRIC, LLC
A4: V-K-9.2 CERC SKF's
A5: TEST YEAR ENDED 12/31/2018
A6: DOCKET NUMBER PENDING ASSIGNMENT
A7: SPONSOR: M. TOWNSEND
A10: 2018 ALLOCATION FACTORS
A11: SOUTHERN GAS ONLY | G11: ENTEX CLASSIC
A12: (Based on Avg Customer Count for 12 mos end June 2017) | G12: (Based on Avg Customer Count for 12 mos end June 2017)
A13: Beaumont | B13: ='[1]BMT-ETX 2016-2017'!O15 -> 85120 | D13: =ROUNDDOWN(B13/$B$24,4) -> 0.033 | E13: =ABS(D13) -> 0.033 | G13: =A13 -> Beaumont | H13: =B13 -> 85120 | I13: =ROUND(H13/$H$20,4) -> 0.0442
A14: East Texas | B14: ='[1]BMT-ETX 2016-2017'!O28 -> 105295 | D14: =ROUND(B14/$B$24,4) -> 0.0408 | E14: =ABS(D14) -> 0.0408 | G14: =A14 -> East Texas | H14: =B14 -> 105295 | I14: =ROUND(H14/$H$20,4) -> 0.0546
A15: South Texas | B15: ='[1]Kera''s Counts'!O133 -> 142392.92 | D15: =ROUND(B15/$B$24,4) -> 0.0552 | E15: =ABS(D15) -> 0.0552 | G15: =A15 -> South Texas | H15: =B15 -> 142392.92 | I15: =ROUND(H15/$H$20,4) -> 0.0739
A16: Houston | B16: ='[1]Kera''s Counts'!O94 -> 1047951.5 | D16: =ROUND(B16/$B$24,4) -> 0.4065 | E16: =ABS(D16) -> 0.4065 | G16: =A16 -> Houston | H16: =B16 -> 1047951.5 | I16: =ROUNDUP(H16/$H$20,4) -> 0.5438
A17: Texas Coast | B17: ='[1]Kera''s Counts'!O107 -> 306576.92 | D17: =ROUND(B17/$B$24,4) -> 0.1189 | E17: =ABS(D17) -> 0.1189 | G17: =A17 -> Texas Coast | H17: =B17 -> 306576.92 | I17: =ROUND(H17/$H$20,4) -> 0.1591
A18: Louisiana Entex | B18: ='[1]Kera''s Counts'!O52 -> 115524.67 | D18: =ROUND(B18/$B$24,4) -> 0.0448 | E18: =ABS(D18) -> 0.0448 | G18: =A18 -> Louisiana Entex | H18: =B18 -> 115524.67 | I18: =ROUND(H18/$H$20,4) -> 0.0599
A19: Mississippi | B19: ='[1]Kera''s Counts'!O81 -> 124403.58 | D19: =ROUND(B19/$B$24,4) -> 0.0483 | E19: =ABS(D19) -> 0.0483 | G19: =A19 -> Mississippi | H19: =B19 -> 124403.58 | I19: =ROUND(H19/$H$20,4) -> 0.0645
A20: Arkansas | B20: ='[1]Kera''s Counts'!O13 -> 407685.08 | D20: =ROUND(B20/$B$24,4) -> 0.1581 | E20: =ABS(D20) -> 0.1581 | H20: =SUM(H13:H19) -> 1927264.6 | I20: =SUM(I13:I19) -> 1
A21: Texarkana | B21: ='[1]Kera''s Counts'!O23 -> 14503.167 | D21: =ROUND(B21/$B$24,4) -> 0.0056 | E21: =ABS(D21) -> 0.0056
A22: Louisiana Arkla | B22: ='[1]Kera''s Counts'!O39 -> 130179.42 | D22: =ROUNDUP(B22/$B$24,4) -> 0.0505 | E22: =ABS(D22) -> 0.0505 | H22: CLASSIC
A23: Oklahoma | B23: ='[1]Kera''s Counts'!O68 -> 98509.5 | D23: =ROUNDUP(B23/$B$24,4) -> 0.0383 | E23: =ABS(D23) -> 0.0383 | H23: ENTEX RURAL | I23: =SUM(I13:I15,I18:I19) -> 0.2971
B24: =SUM(B13:B23) -> 2578141.8 | D24: =SUM(D13:D23) -> 1 | E24: =SUM(E13:E23) -> 1 | H24: HOU GAS | I24: =SUM(I16:I17) -> 0.7029
I25: =SUM(I23:I24) -> 1
A29: TX METERS & REGULATORS | G29: HOUGAS ALLOC
A30: (Based on Avg Customer Count for 12 mos end June 2017) | G30: (Based on Avg Customer Count for 12 mos end June 2017)
A31: =A13 -> Beaumont | B31: =B13 -> 85120 | D31: =ROUNDDOWN(B31/$B$36,4) -> 0.0504 | E31: =ABS(D31) -> 0.0504 | G31: =A16 -> Houston | H31: =B16 -> 1047951.5 | I31: =ROUND(H31/$H$33,6) -> 0.773665
A32: =A14 -> East Texas | B32: =B14 -> 105295 | D32: =ROUND(B32/$B$36,4) -> 0.0624 | E32: =ABS(D32) -> 0.0624 | G32: =A17 -> Texas Coast | H32: =B17 -> 306576.92 | I32: =ROUND(H32/$H$33,6) -> 0.226335
A33: =A15 -> South Texas | B33: =B15 -> 142392.92 | D33: =ROUND(B33/$B$36,4) -> 0.0844 | E33: =ABS(D33) -> 0.0844 | H33: =SUM(H31:H32) -> 1354528.4 | I33: =SUM(I31:I32) -> 1
A34: =A16 -> Houston | B34: =B16 -> 1047951.5 | D34: =ROUNDUP(B34/$B$36,4) -> 0.6211 | E34: =ABS(D34) -> 0.6211
A35: =A17 -> Texas Coast | B35: =B17 -> 306576.92 | D35: =ROUND(B35/$B$36,4) -> 0.1817 | E35: =ABS(D35) -> 0.1817 | G35: ENTEX ALLOC
B36: =SUM(B31:B35) -> 1687336.3 | D36: =SUM(D31:D35) -> 1 | E36: =SUM(E31:E35) -> 1 | G36: Beaumont | H36: =B13 -> 85120 | I36: =ABS(ROUNDDOWN(H36/$H$41,4)) -> 0.1486
G37: East Texas | H37: =B14 -> 105295 | I37: =ABS(ROUND(H37/$H$41,4)) -> 0.1838
G38: South Texas | H38: =B15 -> 142392.92 | I38: =ABS(ROUNDUP(H38/$H$41,4)) -> 0.2487
G39: =+A18 -> Louisiana Entex | H39: =B18 -> 115524.67 | I39: =ABS(ROUND(H39/$H$41,4)) -> 0.2017
G40: Mississippi | H40: =B19 -> 124403.58 | I40: =ABS(ROUND(H40/$H$41,4)) -> 0.2172
H41: =SUM(H36:H40) -> 572736.17 | I41: =SUM(I36:I40) -> 1
A42: 2018 ALLOCATION FACTORS-GASOPS
A43: (Based on Avg Customer Count for 12 mos end June 2017)
A45: Beaumont | B45: =+B13 -> 85120 | D45: =ROUND(B45/$B$57,4) -> 0.0249 | E45: =ABS(D45) -> 0.0249 | G45: ARKLA ALLOC
A46: East Texas | B46: =+B14 -> 105295 | D46: =ROUNDUP(B46/$B$57,4) -> 0.0308 | E46: =ABS(D46) -> 0.0308 | G46: Arkansas | H46: =B20 -> 407685.08 | I46: =ABS(ROUND(H46/$H$50,4)) -> 0.6264 | L46: Arkansas | M46: =H46 -> 407685.08 | N46: =M46/$M$49 -> 0.78295918
A47: South Texas | B47: =+B15 -> 142392.92 | D47: =ROUND(B47/$B$57,4) -> 0.0416 | E47: =ABS(D47) -> 0.0416 | G47: Texarkana | H47: =B21 -> 14503.167 | I47: =ABS(ROUND(H47/$H$50,4)) -> 0.0223 | L47: Texarkana | M47: =H47 -> 14503.167 | N47: =M47/$M$49 -> 0.027853331
...

Sheet 2018 Broadband Units
A2: PUBLIC UTILITY COMMISSION OF TEXAS
A3: CENTERPOINT ENERGY HOUSTON ELECTRIC, LLC
A4: V-K-9.2 CERC SKF's
A5: TEST YEAR ENDED 12/31/2018
A6: DOCKET NUMBER PENDING ASSIGNMENT
A7: SPONSOR: M. TOWNSEND
A10: Broadband Project - Verizion Data Cost Distribution Allocation
A11: Cost Center: | B11: 130194
A15: Area | B15: Broadband Units | C15: Distribution %
A18: North
A19: South
A20: East | B20: =305+22 -> 327 | C20: =+B20/B$42 -> 0.41340076 | D20: =+C20/C24 -> 0.77122642
A21: West
A22: Tx Coast | B22: 97 | C22: =+B22/B$42 -> 0.12262958 | D22: =+C22/C24 -> 0.22877358
A24: Houston Area Total | B24: =SUM(B16:B23) -> 424 | C24: =SUM(C16:C23) -> 0.53603034
D29: MN Breakout | I29: 11034180 | J29: Houston/Texas Coast Verizon 3G Service | K29: =C24 -> 0.53603034
D30: 0.592 | E30: =+D30*C31 -> 0.26718584 | I30: 11034183 | J30: Broadband Charges for Mobile Data Usage | K30: =C34 -> 0.012642225
A31: HSP | B31: =355+2 -> 357 | C31: =+B31/B$42 -> 0.45132743 | D31: 0.408 | E31: =+D31*C31 -> 0.18414159 | I31: RA31241741 | J31: Gas Op Tech Serv | K31: =E30 -> 0.26718584
A32: Minnesota Total | B32: =SUM(B26:B31) -> 357 | C32: =SUM(C26:C31) -> 0.45132743 | I32: RA31241748 | J32: Gas Op Tech Serv | K32: =+E31 -> 0.18414159
J33: Total | K33: =SUM(K29:K32) -> 1
A34: Electric (Sugarland SC) | B34: 10 | C34: =+B34/B$42 -> 0.012642225
A35: Houston Leak Survey | C35: =+B35/B$42 -> 0
A36: Minnesota Fleet | C36: =+B36/B$42 -> 0
A38: Other Users Total | B38: =SUM(B34:B37) -> 10 | C38: =SUM(C34:C37) -> 0.012642225
A42: Grand Total Distribution | B42: =+B24+B31+B38 -> 791 | C42: =SUM(C38,C32,C24) -> 1

Sheet 1.18 Ticket Counts
A2: PUBLIC UTILITY COMMISSION OF TEXAS
A3: CENTERPOINT ENERGY HOUSTON ELECTRIC, LLC
A4: V-K-9.2 CERC SKF's
A5: TEST YEAR ENDED 12/31/2018
A6: DOCKET NUMBER PENDING ASSIGNMENT
A7: SPONSOR: M. TOWNSEND
A11: Underground Locating Research Dept.
A12: Tickets Researched Report
A13: from 1/01/2018 thru 1/31/2018
A17: Gas Tickets
D19: No. Dist. | E19: East Dist. | F19: So. Dist | G19: West Dist. | H19: Baytown | I19: Richmond
A20: 133406 TSUGL3 - Research | D20: 11029391 | E20: 11029394 | F20: 11029392 | G20: 11029393 | H20: 11029389 | I20: 11029390 | J20: Total
A21: Gas Tickets received | D21: =14407+67 -> 14474 | E21: =8431+86 -> 8517 | F21: =5793+62 -> 5855 | G21: =15728+97 -> 15825 | H21: =10976+48 -> 11024 | I21: =5422+21 -> 5443 | J21: =(D21+E21+F21+G21+H21+I21) -> 61138 | L21: =J23/J21 -> 0.73644869 | M21: Gas To Field
A22: 133403 TSUGL2 - Locates | D22: 11029382 | E22: 11029385 | F22: 11029383 | G22: 11029384 | H22: 11029380 | I22: 11029381
A23: Tickets sent for staking | D23: =10469+67 -> 10536 | E23: =7371+86 -> 7457 | F23: =4730+62 -> 4792 | G23: =12274+97 -> 12371 | H23: =6848+48 -> 6896 | I23: =2952+21 -> 2973 | J23: =(D23+E23+F23+G23+H23+I23) -> 45025
A26: Electric Tickets
D27: Baytown | F27: Galveston | H27: Greenspoint | J27: Humble | L27: South Houston | N27: Bellaire/Mag. Park
D28: 0.22 | E28: 0.78 | F28: 0.22 | G28: 0.78 | H28: 0.22 | I28: 0.78 | J28: 0.22 | K28: 0.78 | L28: 0.22 | M28: 0.78 | N28: 0.22 | O28: 0.78
D29: 11002001 | E29: 11029483 | F29: 11002003 | G29: 11029487 | H29: 11001995 | I29: 11029493 | J29: 11001997 | K29: 11029481 | L29: 11002000 | M29: 11029486 | N29: 11002142 | O29: 11029491
A30: 133406 TSUGL3 - Research | D30: =D31*D28 -> 1282.6 | E30: =D31*E28 -> 4547.4 | F30: =F31*F28 -> 694.98 | G30: =F31*G28 -> 2464.02 | H30: =H31*H28 -> 1368.84 | I30: =H31*I28 -> 4853.16 | J30: =J31*J28 -> 946.44 | K30: =J31*K28 -> 3355.56 | L30: =L31*L28 -> 1140.92 | M30: =L31*M28 -> 4045.08 | N30: =N31*N28 -> 1735.58 | O30: =N31*O28 -> 6153.42 | P30: SAP Upload
A31: Electric tickets received | D31: 5830 | F31: 3159 | H31: =6006+216 -> 6222 | J31: 4302 | L31: 5186 | N31: 7889
A32: 133403 TSUGL1 - Locates | D32: =D33*D28 -> 449.9 | E32: =D33*E28 -> 1595.1 | F32: =F33*F28 -> 92.62 | G32: =F33*G28 -> 328.38 | H32: =H33*H28 -> 929.5 | I32: =H33*I28 -> 3295.5 | J32: =J33*J28 -> 615.12 | K32: =J33*K28 -> 2180.88 | L32: =L33*L28 -> 579.26 | M32: =L33*M28 -> 2053.74 | N32: =N33*N28 -> 805.64 | O32: =N33*O28 -> 2856.36 | P32: SAP Upload
A33: Tickets sent for staking | D33: 2045 | F33: 421 | H33: =4009+216 -> 4225 | J33: 2796 | L33: 2633 | N33: 3662
D35: Cypress | F35: Fort Bend/Wharton | H35: HOC/Brazosport | J35: Katy | L35: Spring Branch | N35: Sugar Land
D36: 0.22 | E36: 0.78 | F36: 0.22 | G36: 0.78 | H36: 0.22 | I36: 0.78 | J36: 0.22 | K36: 0.78 | L36: 0.22 | M36: 0.78 | N36: 0.22 | O36: 0.78
D37: 11001996 | E37: 11029494 | F37: 11002006 | G37: 11029482 | H37: 11002143 | I37: 11029490 | J37: 11002007 | K37: 11029485 | L37: 11002008 | M37: 11029489 | N37: 11002009 | O37: 11029484
A38: 133406 TSUGL3 - Research | D38: =D39*D36 -> 1341.56 | E38: =D39*E36 -> 4756.44 | F38: =F39*F36 -> 743.38 | G38: =F39*G36 -> 2635.62 | H38: =H39*H36 -> 1236.84 | I38: =H39*I36 -> 4385.16 | J38: =J39*J36 -> 846.34 | K38: =J39*K36 -> 3000.66 | L38: =L39*L36 -> 779.68 | M38: =L39*M36 -> 2764.32 | N38: =N39*N36 -> 760.54 | O38: =N39*O36 -> 2696.46 | P38: SAP Upload
A39: Electric tickets received | D39: =5923+175 -> 6098 | F39: 3379 | H39: 5622 | J39: 3847 | L39: 3544 | N39: 3457
A40: 133403 TSUGL1 - Locates | D40: =D41*D36 -> 941.38 | E40: =D41*E36 -> 3337.62 | F40: =F41*F36 -> 433.18 | G40: =F41*G36 -> 1535.82 | H40: =H41*H36 -> 602.14 | I40: =H41*I36 -> 2134.86 | J40: =J41*J36 -> 605.22 | K40: =J41*K36 -> 2145.78 | L40: =L41*L36 -> 383.9 | M40: =L41*M36 -> 1361.1 | N40: =N41*N36 -> 582.56 | O40: =N41*O36 -> 2065.44 | P40: SAP Upload
A41: Tickets sent for staking | D41: =4104+175 -> 4279 | F41: 1969 | H41: 2737 | J41: 2751 | L41: 1745 | N41: 2648
D42: =$C$42*D41 -> 0 | H42: =$C$42*H41 -> 0 | J42: =$C$42*J41 -> 0 | L42: =$C$42*L41 -> 0 | N42: =$C$42*N41 -> 0
N43: Total Electric Tickets
N44: 0.22 | O44: 0.78 | P44: Total
K45: =P46/P45 -> 0.54516101 | L45: Elec to Field | M45: Research | N45: =N38+L38+J38+H38+F38+D38+D30+F30+H30+J30+L30+N30 -> 12877.7 | O45: =O38+M38+K38+I38+G38+E38+E30+G30+I30+K30+M30+O30 -> 45657.3 | P45: =N45+O45 -> 58535
A46: FOC | M46: Locate | N46: =N40+L40+J40+H40+F40+D40+D32+F32+H32+J32+L32+N32 -> 7020.42 | O46: =O40+M40+K40+I40+G40+E40+E32+G32+I32+K32+M32+O32 -> 24890.58 | P46: =N46+O46 -> 31911
A47: Ticket sent for staking | D47: 684
N48: Total Tickets
M49: Research | N49: =P45+J21 -> 119673
M50: Locate | N50: =J23+P46+D47 -> 77620

Sheet 2.18 Ticket Counts
A2: PUBLIC UTILITY COMMISSION OF TEXAS
A3: CENTERPOINT ENERGY HOUSTON ELECTRIC, LLC
A4: V-K-9.2 CERC SKF's
A5: TEST YEAR ENDED 12/31/2018
A6: DOCKET NUMBER PENDING ASSIGNMENT
A7: SPONSOR: M. TOWNSEND
A11: Underground Locating Research Dept.
A12: Tickets Researched Report
A13: from 2/01/2018 thru 2/28/2018
A17: Gas Tickets
D19: No. Dist. | E19: East Dist. | F19: So. Dist | G19: West Dist. | H19: Baytown | I19: Richmond
A20: 133406 TSUGL3 - Research | D20: 11029391 | E20: 11029394 | F20: 11029392 | G20: 11029393 | H20: 11029389 | I20: 11029390 | J20: Total
A21: Gas Tickets received | D21: =14971+68 -> 15039 | E21: =8838+44 -> 8882 | F21: =4806+34 -> 4840 | G21: =14545+76 -> 14621 | H21: =9353+32 -> 9385 | I21: =5158+18 -> 5176 | J21: =(D21+E21+F21+G21+H21+I21) -> 57943 | L21: =J23/J21 -> 0.73596465 | M21: Gas To Field
A22: 133403 TSUGL2 - Locates | D22: 11029382 | E22: 11029385 | F22: 11029383 | G22: 11029384 | H22: 11029380 | I22: 11029381
A23: Tickets sent for staking | D23: =10614+68 -> 10682 | E23: =7681+44 -> 7725 | F23: =3835+34 -> 3869 | G23: =11352+76 -> 11428 | H23: =6022+32 -> 6054 | I23: =2868+18 -> 2886 | J23: =(D23+E23+F23+G23+H23+I23) -> 42644
A26: Electric Tickets
D27: Baytown | F27: Galveston | H27: Greenspoint | J27: Humble | L27: South Houston | N27: Bellaire/Mag. Park
D28: 0.22 | E28: 0.78 | F28: 0.22 | G28: 0.78 | H28: 0.22 | I28: 0.78 | J28: 0.22 | K28: 0.78 | L28: 0.22 | M28: 0.78 | N28: 0.22 | O28: 0.78
D29: 11002001 | E29: 11029483 | F29: 11002003 | G29: 11029487 | H29: 11001995 | I29: 11029493 | J29: 11001997 | K29: 11029481 | L29: 11002000 | M29: 11029486 | N29: 11002142 | O29: 11029491
A30: 133406 TSUGL3 - Research | D30: =D31*D28 -> 1139.38 | E30: =D31*E28 -> 4039.62 | F30: =F31*F28 -> 637.56 | G30: =F31*G28 -> 2260.44 | H30: =H31*H28 -> 1343.98 | I30: =H31*I28 -> 4765.02 | J30: =J31*J28 -> 1010.46 | K30: =J31*K28 -> 3582.54 | L30: =L31*L28 -> 968.22 | M30: =L31*M28 -> 3432.78 | N30: =N31*N28 -> 1796.74 | O30: =N31*O28 -> 6370.26 | P30: SAP Upload
A31: Electric tickets received | D31: 5179 | F31: 2898 | H31: =5953+156 -> 6109 | J31: 4593 | L31: 4401 | N31: 8167
A32: 133403 TSUGL1 - Locates | D32: =D33*D28 -> 462.44 | E32: =D33*E28 -> 1639.56 | F32: =F33*F28 -> 86.24 | G32: =F33*G28 -> 305.76 | H32: =H33*H28 -> 865.48 | I32: =H33*I28 -> 3068.52 | J32: =J33*J28 -> 668.58 | K32: =J33*K28 -> 2370.42 | L32: =L33*L28 -> 476.3 | M32: =L33*M28 -> 1688.7 | N32: =N33*N28 -> 821.7 | O32: =N33*O28 -> 2913.3 | P32: SAP Upload
A33: Tickets sent for staking | D33: 2102 | F33: 392 | H33: =3778+156 -> 3934 | J33: 3039 | L33: 2165 | N33: 3735
D35: Cypress | F35: Fort Bend/Wharton | H35: HOC/Brazosport | J35: Katy | L35: Spring Branch | N35: Sugar Land
D36: 0.22 | E36: 0.78 | F36: 0.22 | G36: 0.78 | H36: 0.22 | I36: 0.78 | J36: 0.22 | K36: 0.78 | L36: 0.22 | M36: 0.78 | N36: 0.22 | O36: 0.78
D37: 11001996 | E37: 11029494 | F37: 11002006 | G37: 11029482 | H37: 11002143 | I37: 11029490 | J37: 11002007 | K37: 11029485 | L37: 11002008 | M37: 11029489 | N37: 11002009 | O37: 11029484
A38: 133406 TSUGL3 - Research | D38: =D39*D36 -> 1253.56 | E38: =D39*E36 -> 4444.44 | F38: =F39*F36 -> 738.1 | G38: =F39*G36 -> 2616.9 | H38: =H39*H36 -> 1045.22 | I38: =H39*I36 -> 3705.78 | J38: =J39*J36 -> 770 | K38: =J39*K36 -> 2730 | L38: =L39*L36 -> 698.28 | M38: =L39*M36 -> 2475.72 | N38: =N39*N36 -> 698.72 | O38: =N39*O36 -> 2477.28 | P38: SAP Upload
A39: Electric tickets received | D39: =5585+113 -> 5698 | F39: 3355 | H39: 4751 | J39: 3500 | L39: 3174 | N39: 3176
A40: 133403 TSUGL1 - Locates | D40: =D41*D36 -> 888.58 | E40: =D41*E36 -> 3150.42 | F40: =F41*F36 -> 417.56 | G40: =F41*G36 -> 1480.44 | H40: =H41*H36 -> 501.82 | I40: =H41*I36 -> 1779.18 | J40: =J41*J36 -> 559.02 | K40: =J41*K36 -> 1981.98 | L40: =L41*L36 -> 344.52 | M40: =L41*M36 -> 1221.48 | N40: =N41*N36 -> 538.34 | O40: =N41*O36 -> 1908.66 | P40: SAP Upload
A41: Tickets sent for staking | D41: =3926+113 -> 4039 | F41: 1898 | H41: 2281 | J41: 2541 | L41: 1566 | N41: 2447
D42: =$C$42*D41 -> 0 | H42: =$C$42*H41 -> 0 | J42: =$C$42*J41 -> 0 | L42: =$C$42*L41 -> 0 | N42: =$C$42*N41 -> 0
N43: Total Electric Tickets
N44: 0.22 | O44: 0.78 | P44: Total
K45: =P46/P45 -> 0.54797186 | L45: Elec to Field | M45: Research | N45: =N38+L38+J38+H38+F38+D38+D30+F30+H30+J30+L30+N30 -> 12100.22 | O45: =O38+M38+K38+I38+G38+E38+E30+G30+I30+K30+M30+O30 -> 42900.78 | P45: =N45+O45 -> 55001
A46: FOC | M46: Locate | N46: =N40+L40+J40+H40+F40+D40+D32+F32+H32+J32+L32+N32 -> 6630.58 | O46: =O40+M40+K40+I40+G40+E40+E32+G32+I32+K32+M32+O32 -> 23508.42 | P46: =N46+O46 -> 30139
A47: Ticket sent for staking | D47: 664
N48: Total Tickets
M49: Research | N49: =P45+J21 -> 112944
M50: Locate | N50: =J23+P46+D47 -> 73447

Sheet 3.18 Ticket Counts
A2: PUBLIC UTILITY COMMISSION OF TEXAS
A3: CENTERPOINT ENERGY HOUSTON ELECTRIC, LLC
A4: V-K-9.2 CERC SKF's
A5: TEST YEAR ENDED 12/31/2018
A6: DOCKET NUMBER PENDING ASSIGNMENT
A7: SPONSOR: M. TOWNSEND
A11: Underground Locating Research Dept.
A12: Tickets Researched Report
A13: from 3/01/2018 thru 3/31/2018
A17: Gas Tickets
D19: No. Dist. | E19: East Dist. | F19: So. Dist | G19: West Dist. | H19: Baytown | I19: Richmond
A20: 133406 TSUGL3 - Research | D20: 11029391 | E20: 11029394 | F20: 11029392 | G20: 11029393 | H20: 11029389 | I20: 11029390 | J20: Total
A21: Gas Tickets received | D21: 18835 | E21: 9439 | F21: 5593 | G21: 16993 | H21: 11853 | I21: 6182 | J21: =(D21+E21+F21+G21+H21+I21) -> 68895 | L21: =J23/J21 -> 0.73883446 | M21: Gas To Field
A22: 133403 TSUGL2 - Locates | D22: 11029382 | E22: 11029385 | F22: 11029383 | G22: 11029384 | H22: 11029380 | I22: 11029381
A23: Tickets sent for staking | D23: 13866 | E23: 8229 | F23: 4452 | G23: 13165 | H23: 7604 | I23: 3586 | J23: =(D23+E23+F23+G23+H23+I23) -> 50902
A26: Electric Tickets
D27: Baytown | F27: Galveston | H27: Greenspoint | J27: Humble | L27: South Houston | N27: Bellaire/Mag. Park
D28: 0.22 | E28: 0.78 | F28: 0.22 | G28: 0.78 | H28: 0.22 | I28: 0.78 | J28: 0.22 | K28: 0.78 | L28: 0.22 | M28: 0.78 | N28: 0.22 | O28: 0.78
D29: 11002001 | E29: 11029483 | F29: 11002003 | G29: 11029487 | H29: 11001995 | I29: 11029493 | J29: 11001997 | K29: 11029481 | L29: 11002000 | M29: 11029486 | N29: 11002142 | O29: 11029491
A30: 133406 TSUGL3 - Research | D30: =D31*D28 -> 1378.08 | E30: =D31*E28 -> 4885.92 | F30: =F31*F28 -> 778.36 | G30: =F31*G28 -> 2759.64 | H30: =H31*H28 -> 1713.58 | I30: =H31*I28 -> 6075.42 | J30: =J31*J28 -> 1246.08 | K30: =J31*K28 -> 4417.92 | L30: =L31*L28 -> 1166.66 | M30: =L31*M28 -> 4136.34 | N30: =N31*N28 -> 1863.62 | O30: =N31*O28 -> 6607.38 | P30: SAP Upload
A31: Electric tickets received | D31: 6264 | F31: 3538 | H31: 7789 | J31: 5664 | L31: 5303 | N31: 8471
A32: 133403 TSUGL1 - Locates | D32: =D33*D28 -> 573.98 | E32: =D33*E28 -> 2035.02 | F32: =F33*F28 -> 91.08 | G32: =F33*G28 -> 322.92 | H32: =H33*H28 -> 1127.72 | I32: =H33*I28 -> 3998.28 | J32: =J33*J28 -> 810.7 | K32: =J33*K28 -> 2874.3 | L32: =L33*L28 -> 614.68 | M32: =L33*M28 -> 2179.32 | N32: =N33*N28 -> 859.76 | O32: =N33*O28 -> 3048.24 | P32: SAP Upload
A33: Tickets sent for staking | D33: 2609 | F33: 414 | H33: 5126 | J33: 3685 | L33: 2794 | N33: 3908
D35: Cypress | F35: Fort Bend/Wharton | H35: HOC/Brazosport | J35: Katy | L35: Spring Branch | N35: Sugar Land
D36: 0.22 | E36: 0.78 | F36: 0.22 | G36: 0.78 | H36: 0.22 | I36: 0.78 | J36: 0.22 | K36: 0.78 | L36: 0.22 | M36: 0.78 | N36: 0.22 | O36: 0.78
D37: 11001996 | E37: 11029494 | F37: 11002006 | G37: 11029482 | H37: 11002143 | I37: 11029490 | J37: 11002007 | K37: 11029485 | L37: 11002008 | M37: 11029489 | N37: 11002009 | O37: 11029484
A38: 133406 TSUGL3 - Research | D38: =D39*D36 -> 1412.18 | E38: =D39*E36 -> 5006.82 | F38: =F39*F36 -> 843.04 | G38: =F39*G36 -> 2988.96 | H38: =H39*H36 -> 1268.08 | I38: =H39*I36 -> 4495.92 | J38: =J39*J36 -> 943.14 | K38: =J39*K36 -> 3343.86 | L38: =L39*L36 -> 793.98 | M38: =L39*M36 -> 2815.02 | N38: =N39*N36 -> 894.74 | O38: =N39*O36 -> 3172.26 | P38: SAP Upload
A39: Electric tickets received | D39: 6419 | F39: 3832 | H39: 5764 | J39: 4287 | L39: 3609 | N39: 4067
A40: 133403 TSUGL1 - Locates | D40: =D41*D36 -> 931.7 | E40: =D41*E36 -> 3303.3 | F40: =F41*F36 -> 497.86 | G40: =F41*G36 -> 1765.14 | H40: =H41*H36 -> 645.7 | I40: =H41*I36 -> 2289.3 | J40: =J41*J36 -> 666.38 | K40: =J41*K36 -> 2362.62 | L40: =L41*L36 -> 403.04 | M40: =L41*M36 -> 1428.96 | N40: =N41*N36 -> 667.48 | O40: =N41*O36 -> 2366.52 | P40: SAP Upload
A41: Tickets sent for staking | D41: 4235 | F41: 2263 | H41: 2935 | J41: 3029 | L41: 1832 | N41: 3034
D42: =$C$42*D41 -> 0 | H42: =$C$42*H41 -> 0 | J42: =$C$42*J41 -> 0 | L42: =$C$42*L41 -> 0 | N42: =$C$42*N41 -> 0
N43: Total Electric Tickets
N44: 0.22 | O44: 0.78 | P44: Total
K45: =P46/P45 -> 0.55169443 | L45: Elec to Field | M45: Research | N45: =N38+L38+J38+H38+F38+D38+D30+F30+H30+J30+L30+N30 -> 14301.54 | O45: =O38+M38+K38+I38+G38+E38+E30+G30+I30+K30+M30+O30 -> 50705.46 | P45: =N45+O45 -> 65007
A46: FOC | M46: Locate | N46: =N40+L40+J40+H40+F40+D40+D32+F32+H32+J32+L32+N32 -> 7890.08 | O46: =O40+M40+K40+I40+G40+E40+E32+G32+I32+K32+M32+O32 -> 27973.92 | P46: =N46+O46 -> 35864
A47: Ticket sent for staking | D47: 634
N48: Total Tickets
M49: Research | N49: =P45+J21 -> 133902
M50: Locate | N50: =J23+P46+D47 -> 87400

Sheet 4.18 Ticket Counts
A2: PUBLIC UTILITY COMMISSION OF TEXAS
A3: CENTERPOINT ENERGY HOUSTON ELECTRIC, LLC
A4: V-K-9.2 CERC SKF's
A5: TEST YEAR ENDED 12/31/2018
A6: DOCKET NUMBER PENDING ASSIGNMENT
A7: SPONSOR: M. TOWNSEND
A11: Underground Locating Research Dept.
A12: Tickets Researched Report
A13: from 4/01/2018 thru 4/30/2018
A17: Gas Tickets
D19: No. Dist. | E19: East Dist. | F19: So. Dist | G19: West Dist. | H19: Baytown | I19: Richmond
A20: 133406 TSUGL3 - Research | D20: 11029391 | E20: 11029394 | F20: 11029392 | G20: 11029393 | H20: 11029389 | I20: 11029390 | J20: Total
A21: Gas Tickets received | D21: =17443+56 -> 17499 | E21: =9579+30 -> 9609 | F21: =5359+21 -> 5380 | G21: =17105+63 -> 17168 | H21: =12172+40 -> 12212 | I21: =6653+22 -> 6675 | J21: =(D21+E21+F21+G21+H21+I21) -> 68543 | L21: =J23/J21 -> 0.72032155 | M21: Gas To Field
A22: 133403 TSUGL2 - Locates | D22: 11029382 | E22: 11029385 | F22: 11029383 | G22: 11029384 | H22: 11029380 | I22: 11029381
A23: Tickets sent for staking | D23: =12308+56 -> 12364 | E23: =8247+30 -> 8277 | F23: =4071+21 -> 4092 | G23: =13258+63 -> 13321 | H23: =7698+40 -> 7738 | I23: =3559+22 -> 3581 | J23: =(D23+E23+F23+G23+H23+I23) -> 49373
A26: Electric Tickets
D27: Baytown | F27: Galveston | H27: Greenspoint | J27: Humble | L27: South Houston | N27: Bellaire/Mag. Park
D28: 0.22 | E28: 0.78 | F28: 0.22 | G28: 0.78 | H28: 0.22 | I28: 0.78 | J28: 0.22 | K28: 0.78 | L28: 0.22 | M28: 0.78 | N28: 0.22 | O28: 0.78
D29: 11002001 | E29: 11029483 | F29: 11002003 | G29: 11029487 | H29: 11001995 | I29: 11029493 | J29: 11001997 | K29: 11029481 | L29: 11002000 | M29: 11029486 | N29: 11002142 | O29: 11029491
A30: 133406 TSUGL3 - Research | D30: =D31*D28 -> 1382.04 | E30: =D31*E28 -> 4899.96 | F30: =F31*F28 -> 757.68 | G30: =F31*G28 -> 2686.32 | H30: =H31*H28 -> 1514.48 | I30: =H31*I28 -> 5369.52 | J30: =J31*J28 -> 1156.54 | K30: =J31*K28 -> 4100.46 | L30: =L31*L28 -> 1226.94 | M30: =L31*M28 -> 4350.06 | N30: =N31*N28 -> 1840.08 | O30: =N31*O28 -> 6523.92 | P30: SAP Upload
A31: Electric tickets received | D31: 6282 | F31: 3444 | H31: =6763+121 -> 6884 | J31: 5257 | L31: 5577 | N31: 8364
A32: 133403 TSUGL1 - Locates | D32: =D33*D28 -> 560.78 | E32: =D33*E28 -> 1988.22 | F32: =F33*F28 -> 80.96 | G32: =F33*G28 -> 287.04 | H32: =H33*H28 -> 946 | I32: =H33*I28 -> 3354 | J32: =J33*J28 -> 749.98 | K32: =J33*K28 -> 2659.02 | L32: =L33*L28 -> 617.1 | M32: =L33*M28 -> 2187.9 | N32: =N33*N28 -> 847.88 | O32: =N33*O28 -> 3006.12 | P32: SAP Upload
A33: Tickets sent for staking | D33: 2549 | F33: 368 | H33: =4179+121 -> 4300 | J33: 3409 | L33: 2805 | N33: 3854
D35: Cypress | F35: Fort Bend/Wharton | H35: HOC/Brazosport | J35: Katy | L35: Spring Branch | N35: Sugar Land
D36: 0.22 | E36: 0.78 | F36: 0.22 | G36: 0.78 | H36: 0.22 | I36: 0.78 | J36: 0.22 | K36: 0.78 | L36: 0.22 | M36: 0.78 | N36: 0.22 | O36: 0.78
D37: 11001996 | E37: 11029494 | F37: 11002006 | G37: 11029482 | H37: 11002143 | I37: 11029490 | J37: 11002007 | K37: 11029485 | L37: 11002008 | M37: 11029489 | N37: 11002009 | O37: 11029484
A38: 133406 TSUGL3 - Research | D38: =D39*D36 -> 1531.86 | E38: =D39*E36 -> 5431.14 | F38: =F39*F36 -> 930.6 | G38: =F39*G36 -> 3299.4 | H38: =H39*H36 -> 1232.88 | I38: =H39*I36 -> 4371.12 | J38: =J39*J36 -> 998.14 | K38: =J39*K36 -> 3538.86 | L38: =L39*L36 -> 833.8 | M38: =L39*M36 -> 2956.2 | N38: =N39*N36 -> 786.94 | O38: =N39*O36 -> 2790.06 | P38: SAP Upload
A39: Electric tickets received | D39: =6860+103 -> 6963 | F39: 4230 | H39: 5604 | J39: 4537 | L39: 3790 | N39: 3577
A40: 133403 TSUGL1 - Locates | D40: =D41*D36 -> 980.1 | E40: =D41*E36 -> 3474.9 | F40: =F41*F36 -> 554.84 | G40: =F41*G36 -> 1967.16 | H40: =H41*H36 -> 625.02 | I40: =H41*I36 -> 2215.98 | J40: =J41*J36 -> 720.5 | K40: =J41*K36 -> 2554.5 | L40: =L41*L36 -> 412.06 | M40: =L41*M36 -> 1460.94 | N40: =N41*N36 -> 574.86 | O40: =N41*O36 -> 2038.14 | P40: SAP Upload
A41: Tickets sent for staking | D41: =4352+103 -> 4455 | F41: 2522 | H41: 2841 | J41: 3275 | L41: 1873 | N41: 2613
D42: =$C$42*D41 -> 0 | H42: =$C$42*H41 -> 0 | J42: =$C$42*J41 -> 0 | L42: =$C$42*L41 -> 0 | N42: =$C$42*N41 -> 0
N43: Total Electric Tickets
N44: 0.22 | O44: 0.78 | P44: Total
K45: =P46/P45 -> 0.54045172 | L45: Elec to Field | M45: Research | N45: =N38+L38+J38+H38+F38+D38+D30+F30+H30+J30+L30+N30 -> 14191.98 | O45: =O38+M38+K38+I38+G38+E38+E30+G30+I30+K30+M30+O30 -> 50317.02 | P45: =N45+O45 -> 64509
A46: FOC | M46: Locate | N46: =N40+L40+J40+H40+F40+D40+D32+F32+H32+J32+L32+N32 -> 7670.08 | O46: =O40+M40+K40+I40+G40+E40+E32+G32+I32+K32+M32+O32 -> 27193.92 | P46: =N46+O46 -> 34864
A47: Ticket sent for staking | D47: 668
N48: Total Tickets
M49: Research | N49: =P45+J21 -> 133052
M50: Locate | N50: =J23+P46+D47 -> 84905

Sheet 5.18 Ticket Counts
A2: PUBLIC UTILITY COMMISSION OF TEXAS
A3: CENTERPOINT ENERGY HOUSTON ELECTRIC, LLC
A4: V-K-9.2 CERC SKF's
A5: TEST YEAR ENDED 12/31/2018
A6: DOCKET NUMBER PENDING ASSIGNMENT
A7: SPONSOR: M. TOWNSEND
A11: Underground Locating Research Dept.
A12: Tickets Researched Report
A13: from 5/01/2018 thru 5/31/2018
A17: Gas Tickets
D19: No. Dist. | E19: East Dist. | F19: So. Dist | G19: West Dist. | H19: Baytown | I19: Richmond
A20: 133406 TSUGL3 - Research | D20: 11029391 | E20: 11029394 | F20: 11029392 | G20: 11029393 | H20: 11029389 | I20: 11029390 | J20: Total
A21: Gas Tickets received | D21: 17958 | E21: 10158 | F21: 5748 | G21: 17942 | H21: 12799 | I21: 6776 | J21: =(D21+E21+F21+G21+H21+I21) -> 71381 | L21: =J23/J21 -> 0.71645116 | M21: Gas To Field
A22: 133403 TSUGL2 - Locates | D22: 11029382 | E22: 11029385 | F22: 11029383 | G22: 11029384 | H22: 11029380 | I22: 11029381
A23: Tickets sent for staking | D23: 12335 | E23: 8834 | F23: 4402 | G23: 13984 | H23: 7922 | I23: 3664 | J23: =(D23+E23+F23+G23+H23+I23) -> 51141
A26: Electric Tickets
D27: Baytown | F27: Galveston | H27: Greenspoint | J27: Humble | L27: South Houston | N27: Bellaire/Mag. Park
D28: 0.22 | E28: 0.78 | F28: 0.22 | G28: 0.78 | H28: 0.22 | I28: 0.78 | J28: 0.22 | K28: 0.78 | L28: 0.22 | M28: 0.78 | N28: 0.22 | O28: 0.78
D29: 11002001 | E29: 11029483 | F29: 11002003 | G29: 11029487 | H29: 11001995 | I29: 11029493 | J29: 11001997 | K29: 11029481 | L29: 11002000 | M29: 11029486 | N29: 11002142 | O29: 11029491
A30: 133406 TSUGL3 - Research | D30: =D31*D28 -> 1492.04 | E30: =D31*E28 -> 5289.96 | F30: =F31*F28 -> 812.24 | G30: =F31*G28 -> 2879.76 | H30: =H31*H28 -> 1556.06 | I30: =H31*I28 -> 5516.94 | J30: =J31*J28 -> 1111.88 | K30: =J31*K28 -> 3942.12 | L30: =L31*L28 -> 1302.84 | M30: =L31*M28 -> 4619.16 | N30: =N31*N28 -> 2002.22 | O30: =N31*O28 -> 7098.78 | P30: SAP Upload
A31: Electric tickets received | D31: 6782 | F31: 3692 | H31: 7073 | J31: 5054 | L31: 5922 | N31: 9101
A32: 133403 TSUGL1 - Locates | D32: =D33*D28 -> 600.38 | E32: =D33*E28 -> 2128.62 | F32: =F33*F28 -> 96.36 | G32: =F33*G28 -> 341.64 | H32: =H33*H28 -> 1000.56 | I32: =H33*I28 -> 3547.44 | J32: =J33*J28 -> 753.72 | K32: =J33*K28 -> 2672.28 | L32: =L33*L28 -> 703.34 | M32: =L33*M28 -> 2493.66 | N32: =N33*N28 -> 968 | O32: =N33*O28 -> 3432 | P32: SAP Upload
A33: Tickets sent for staking | D33: 2729 | F33: 438 | H33: 4548 | J33: 3426 | L33: 3197 | N33: 4400
D35: Cypress | F35: Fort Bend/Wharton | H35: HOC/Brazosport | J35: Katy | L35: Spring Branch | N35: Sugar Land
D36: 0.22 | E36: 0.78 | F36: 0.22 | G36: 0.78 | H36: 0.22 | I36: 0.78 | J36: 0.22 | K36: 0.78 | L36: 0.22 | M36: 0.78 | N36: 0.22 | O36: 0.78
D37: 11001996 | E37: 11029494 | F37: 11002006 | G37: 11029482 | H37: 11002143 | I37: 11029490 | J37: 11002007 | K37: 11029485 | L37: 11002008 | M37: 11029489 | N37: 11002009 | O37: 11029484
A38: 133406 TSUGL3 - Research | D38: =D39*D36 -> 1536.26 | E38: =D39*E36 -> 5446.74 | F38: =F39*F36 -> 933.9 | G38: =F39*G36 -> 3311.1 | H38: =H39*H36 -> 1214.4 | I38: =H39*I36 -> 4305.6 | J38: =J39*J36 -> 997.7 | K38: =J39*K36 -> 3537.3 | L38: =L39*L36 -> 905.08 | M38: =L39*M36 -> 3208.92 | N38: =N39*N36 -> 867.46 | O38: =N39*O36 -> 3075.54 | P38: SAP Upload
A39: Electric tickets received | D39: 6983 | F39: 4245 | H39: 5520 | J39: 4535 | L39: 4114 | N39: 3943
A40: 133403 TSUGL1 - Locates | D40: =D41*D36 -> 1001.44 | E40: =D41*E36 -> 3550.56 | F40: =F41*F36 -> 558.14 | G40: =F41*G36 -> 1978.86 | H40: =H41*H36 -> 597.08 | I40: =H41*I36 -> 2116.92 | J40: =J41*J36 -> 718.3 | K40: =J41*K36 -> 2546.7 | L40: =L41*L36 -> 467.72 | M40: =L41*M36 -> 1658.28 | N40: =N41*N36 -> 661.76 | O40: =N41*O36 -> 2346.24 | P40: SAP Upload
A41: Tickets sent for staking | D41: 4552 | F41: 2537 | H41: 2714 | J41: 3265 | L41: 2126 | N41: 3008
D42: =$C$42*D41 -> 0 | H42: =$C$42*H41 -> 0 | J42: =$C$42*J41 -> 0 | L42: =$C$42*L41 -> 0 | N42: =$C$42*N41 -> 0
N43: Total Electric Tickets
N44: 0.22 | O44: 0.78 | P44: Total
K45: =P46/P45 -> 0.55163969 | L45: Elec to Field | M45: Research | N45: =N38+L38+J38+H38+F38+D38+D30+F30+H30+J30+L30+N30 -> 14732.08 | O45: =O38+M38+K38+I38+G38+E38+E30+G30+I30+K30+M30+O30 -> 52231.92 | P45: =N45+O45 -> 66964
A46: FOC | M46: Locate | N46: =N40+L40+J40+H40+F40+D40+D32+F32+H32+J32+L32+N32 -> 8126.8 | O46: =O40+M40+K40+I40+G40+E40+E32+G32+I32+K32+M32+O32 -> 28813.2 | P46: =N46+O46 -> 36940
A47: Ticket sent for staking | D47: 752
N48: Total Tickets
M49: Research | N49: =P45+J21 -> 138345
M50: Locate | N50: =J23+P46+D47 -> 88833

Sheet 6.18 Ticket Counts
A2: PUBLIC UTILITY COMMISSION OF TEXAS
A3: CENTERPOINT ENERGY HOUSTON ELECTRIC, LLC
A4: V-K-9.2 CERC SKF's
A5: TEST YEAR ENDED 12/31/2018
A6: DOCKET NUMBER PENDING ASSIGNMENT
A7: SPONSOR: M. TOWNSEND
A11: Underground Locating Research Dept.
A12: Tickets Researched Report
A13: from 6/01/2018 thru 6/30/2018
A17: Gas Tickets
D19: No. Dist. | E19: East Dist. | F19: So. Dist | G19: West Dist. | H19: Baytown | I19: Richmond
A20: 133406 TSUGL3 - Research | D20: 11029391 | E20: 11029394 | F20: 11029392 | G20: 11029393 | H20: 11029389 | I20: 11029390 | J20: Total
A21: Gas Tickets received | D21: 15930 | E21: 9722 | F21: 5910 | G21: 17020 | H21: 11951 | I21: 6141 | J21: =(D21+E21+F21+G21+H21+I21) -> 66674 | L21: =J23/J21 -> 0.72710502 | M21: Gas To Field
A22: 133403 TSUGL2 - Locates | D22: 11029382 | E22: 11029385 | F22: 11029383 | G22: 11029384 | H22: 11029380 | I22: 11029381
A23: Tickets sent for staking | D23: 11031 | E23: 8557 | F23: 4654 | G23: 13555 | H23: 7312 | I23: 3370 | J23: =(D23+E23+F23+G23+H23+I23) -> 48479
A26: Electric Tickets
D27: Baytown | F27: Galveston | H27: Greenspoint | J27: Humble | L27: South Houston | N27: Bellaire/Mag. Park
D28: 0.22 | E28: 0.78 | F28: 0.22 | G28: 0.78 | H28: 0.22 | I28: 0.78 | J28: 0.22 | K28: 0.78 | L28: 0.22 | M28: 0.78 | N28: 0.22 | O28: 0.78
D29: 11002001 | E29: 11029483 | F29: 11002003 | G29: 11029487 | H29: 11001995 | I29: 11029493 | J29: 11001997 | K29: 11029481 | L29: 11002000 | M29: 11029486 | N29: 11002142 | O29: 11029491
A30: 133406 TSUGL3 - Research | D30: =D31*D28 -> 1360.48 | E30: =D31*E28 -> 4823.52 | F30: =F31*F28 -> 770.44 | G30: =F31*G28 -> 2731.56 | H30: =H31*H28 -> 1400.08 | I30: =H31*I28 -> 4963.92 | J30: =J31*J28 -> 1006.06 | K30: =J31*K28 -> 3566.94 | L30: =L31*L28 -> 1323.3 | M30: =L31*M28 -> 4691.7 | N30: =N31*N28 -> 1917.3 | O30: =N31*O28 -> 6797.7 | P30: SAP Upload
A31: Electric tickets received | D31: 6184 | F31: 3502 | H31: 6364 | J31: 4573 | L31: 6015 | N31: 8715
A32: 133403 TSUGL1 - Locates | D32: =D33*D28 -> 528 | E32: =D33*E28 -> 1872 | F32: =F33*F28 -> 114.62 | G32: =F33*G28 -> 406.38 | H32: =H33*H28 -> 940.28 | I32: =H33*I28 -> 3333.72 | J32: =J33*J28 -> 663.3 | K32: =J33*K28 -> 2351.7 | L32: =L33*L28 -> 761.64 | M32: =L33*M28 -> 2700.36 | N32: =N33*N28 -> 962.94 | O32: =N33*O28 -> 3414.06 | P32: SAP Upload
A33: Tickets sent for staking | D33: 2400 | F33: 521 | H33: 4274 | J33: 3015 | L33: 3462 | N33: 4377
D35: Cypress | F35: Fort Bend/Wharton | H35: HOC/Brazosport | J35: Katy | L35: Spring Branch | N35: Sugar Land
D36: 0.22 | E36: 0.78 | F36: 0.22 | G36: 0.78 | H36: 0.22 | I36: 0.78 | J36: 0.22 | K36: 0.78 | L36: 0.22 | M36: 0.78 | N36: 0.22 | O36: 0.78
D37: 11001996 | E37: 11029494 | F37: 11002006 | G37: 11029482 | H37: 11002143 | I37: 11029490 | J37: 11002007 | K37: 11029485 | L37: 11002008 | M37: 11029489 | N37: 11002009 | O37: 11029484
A38: 133406 TSUGL3 - Research | D38: =D39*D36 -> 1346.4 | E38: =D39*E36 -> 4773.6 | F38: =F39*F36 -> 805.64 | G38: =F39*G36 -> 2856.36 | H38: =H39*H36 -> 1181.62 | I38: =H39*I36 -> 4189.38 | J38: =J39*J36 -> 967.56 | K38: =J39*K36 -> 3430.44 | L38: =L39*L36 -> 932.58 | M38: =L39*M36 -> 3306.42 | N38: =N39*N36 -> 818.4 | O38: =N39*O36 -> 2901.6 | P38: SAP Upload
A39: Electric tickets received | D39: 6120 | F39: 3662 | H39: 5371 | J39: 4398 | L39: 4239 | N39: 3720
A40: 133403 TSUGL1 - Locates | D40: =D41*D36 -> 920.48 | E40: =D41*E36 -> 3263.52 | F40: =F41*F36 -> 478.06 | G40: =F41*G36 -> 1694.94 | H40: =H41*H36 -> 597.52 | I40: =H41*I36 -> 2118.48 | J40: =J41*J36 -> 698.72 | K40: =J41*K36 -> 2477.28 | L40: =L41*L36 -> 483.56 | M40: =L41*M36 -> 1714.44 | N40: =N41*N36 -> 628.76 | O40: =N41*O36 -> 2229.24 | P40: SAP Upload
A41: Tickets sent for staking | D41: 4184 | F41: 2173 | H41: 2716 | J41: 3176 | L41: 2198 | N41: 2858
D42: =$C$42*D41 -> 0 | H42: =$C$42*H41 -> 0 | J42: =$C$42*J41 -> 0 | L42: =$C$42*L41 -> 0 | N42: =$C$42*N41 -> 0
N43: Total Electric Tickets
N44: 0.22 | O44: 0.78 | P44: Total
K45: =P46/P45 -> 0.56239759 | L45: Elec to Field | M45: Research | N45: =N38+L38+J38+H38+F38+D38+D30+F30+H30+J30+L30+N30 -> 13829.86 | O45: =O38+M38+K38+I38+G38+E38+E30+G30+I30+K30+M30+O30 -> 49033.14 | P45: =N45+O45 -> 62863
A46: FOC | M46: Locate | N46: =N40+L40+J40+H40+F40+D40+D32+F32+H32+J32+L32+N32 -> 7777.88 | O46: =O40+M40+K40+I40+G40+E40+E32+G32+I32+K32+M32+O32 -> 27576.12 | P46: =N46+O46 -> 35354
A47: Ticket sent for staking | D47: 721
N48: Total Tickets
M49: Research | N49: =P45+J21 -> 129537
M50: Locate | N50: =J23+P46+D47 -> 84554

Sheet 7.18Ticket Counts
A2: PUBLIC UTILITY COMMISSION OF TEXAS
A3: CENTERPOINT ENERGY HOUSTON ELECTRIC, LLC
A4: V-K-9.2 CERC SKF's
A5: TEST YEAR ENDED 12/31/2018
A6: DOCKET NUMBER PENDING ASSIGNMENT
A7: SPONSOR: M. TOWNSEND
A11: Underground Locating Research Dept.
A12: Tickets Researched Report
A13: from 7/01/2018 thru 7/31/2018
A17: Gas Tickets
D19: No. Dist. | E19: East Dist. | F19: So. Dist | G19: West Dist. | H19: Baytown | I19: Richmond
A20: 133406 TSUGL3 - Research | D20: 11029391 | E20: 11029394 | F20: 11029392 | G20: 11029393 | H20: 11029389 | I20: 11029390 | J20: Total
A21: Gas Tickets received | D21: 17231 | E21: 10379 | F21: 6347 | G21: 17339 | H21: 13394 | I21: 6948 | J21: =(D21+E21+F21+G21+H21+I21) -> 71638 | L21: =J23/J21 -> 0.73350736 | M21: Gas To Field
A22: 133403 TSUGL2 - Locates | D22: 11029382 | E22: 11029385 | F22: 11029383 | G22: 11029384 | H22: 11029380 | I22: 11029381
A23: Tickets sent for staking | D23: 12202 | E23: 9272 | F23: 5187 | G23: 13562 | H23: 8440 | I23: 3884 | J23: =(D23+E23+F23+G23+H23+I23) -> 52547
A26: Electric Tickets
D27: Baytown | F27: Galveston | H27: Greenspoint | J27: Humble | L27: South Houston | N27: Bellaire/Mag. Park
D28: 0.22 | E28: 0.78 | F28: 0.22 | G28: 0.78 | H28: 0.22 | I28: 0.78 | J28: 0.22 | K28: 0.78 | L28: 0.22 | M28: 0.78 | N28: 0.22 | O28: 0.78
D29: 11002001 | E29: 11029483 | F29: 11002003 | G29: 11029487 | H29: 11001995 | I29: 11029493 | J29: 11001997 | K29: 11029481 | L29: 11002000 | M29: 11029486 | N29: 11002142 | O29: 11029491
A30: 133406 TSUGL3 - Research | D30: =D31*D28 -> 1615.24 | E30: =D31*E28 -> 5726.76 | F30: =F31*F28 -> 837.54 | G30: =F31*G28 -> 2969.46 | H30: =H31*H28 -> 1467.18 | I30: =H31*I28 -> 5201.82 | J30: =J31*J28 -> 1174.8 | K30: =J31*K28 -> 4165.2 | L30: =L31*L28 -> 1442.1 | M30: =L31*M28 -> 5112.9 | N30: =N31*N28 -> 2019.38 | O30: =N31*O28 -> 7159.62 | P30: SAP Upload
A31: Electric tickets received | D31: 7342 | F31: 3807 | H31: 6669 | J31: 5340 | L31: 6555 | N31: 9179
A32: 133403 TSUGL1 - Locates | D32: =D33*D28 -> 670.12 | E32: =D33*E28 -> 2375.88 | F32: =F33*F28 -> 147.4 | G32: =F33*G28 -> 522.6 | H32: =H33*H28 -> 1018.82 | I32: =H33*I28 -> 3612.18 | J32: =J33*J28 -> 776.82 | K32: =J33*K28 -> 2754.18 | L32: =L33*L28 -> 788.7 | M32: =L33*M28 -> 2796.3 | N32: =N33*N28 -> 1032.9 | O32: =N33*O28 -> 3662.1 | P32: SAP Upload
A33: Tickets sent for staking | D33: 3046 | F33: 670 | H33: 4631 | J33: 3531 | L33: 3585 | N33: 4695
D35: Cypress | F35: Fort Bend/Wharton | H35: HOC/Brazosport | J35: Katy | L35: Spring Branch | N35: Sugar Land
D36: 0.22 | E36: 0.78 | F36: 0.22 | G36: 0.78 | H36: 0.22 | I36: 0.78 | J36: 0.22 | K36: 0.78 | L36: 0.22 | M36: 0.78 | N36: 0.22 | O36: 0.78
D37: 11001996 | E37: 11029494 | F37: 11002006 | G37: 11029482 | H37: 11002143 | I37: 11029490 | J37: 11002007 | K37: 11029485 | L37: 11002008 | M37: 11029489 | N37: 11002009 | O37: 11029484
A38: 133406 TSUGL3 - Research | D38: =D39*D36 -> 1283.04 | E38: =D39*E36 -> 4548.96 | F38: =F39*F36 -> 948.2 | G38: =F39*G36 -> 3361.8 | H38: =H39*H36 -> 1245.2 | I38: =H39*I36 -> 4414.8 | J38: =J39*J36 -> 1049.62 | K38: =J39*K36 -> 3721.38 | L38: =L39*L36 -> 993.3 | M38: =L39*M36 -> 3521.7 | N38: =N39*N36 -> 850.3 | O38: =N39*O36 -> 3014.7 | P38: SAP Upload
A39: Electric tickets received | D39: 5832 | F39: 4310 | H39: 5660 | J39: 4771 | L39: 4515 | N39: 3865
A40: 133403 TSUGL1 - Locates | D40: =D41*D36 -> 889.02 | E40: =D41*E36 -> 3151.98 | F40: =F41*F36 -> 600.38 | G40: =F41*G36 -> 2128.62 | H40: =H41*H36 -> 616.66 | I40: =H41*I36 -> 2186.34 | J40: =J41*J36 -> 766.48 | K40: =J41*K36 -> 2717.52 | L40: =L41*L36 -> 561.22 | M40: =L41*M36 -> 1989.78 | N40: =N41*N36 -> 666.38 | O40: =N41*O36 -> 2362.62 | P40: SAP Upload
A41: Tickets sent for staking | D41: 4041 | F41: 2729 | H41: 2803 | J41: 3484 | L41: 2551 | N41: 3029
D42: =$C$42*D41 -> 0 | H42: =$C$42*H41 -> 0 | J42: =$C$42*J41 -> 0 | L42: =$C$42*L41 -> 0 | N42: =$C$42*N41 -> 0
N43: Total Electric Tickets
N44: 0.22 | O44: 0.78 | P44: Total
K45: =P46/P45 -> 0.57181811 | L45: Elec to Field | M45: Research | N45: =N38+L38+J38+H38+F38+D38+D30+F30+H30+J30+L30+N30 -> 14925.9 | O45: =O38+M38+K38+I38+G38+E38+E30+G30+I30+K30+M30+O30 -> 52919.1 | P45: =N45+O45 -> 67845
A46: FOC | M46: Locate | N46: =N40+L40+J40+H40+F40+D40+D32+F32+H32+J32+L32+N32 -> 8534.9 | O46: =O40+M40+K40+I40+G40+E40+E32+G32+I32+K32+M32+O32 -> 30260.1 | P46: =N46+O46 -> 38795
A47: Ticket sent for staking | D47: 860
N48: Total Tickets
M49: Research | N49: =P45+J21 -> 139483
M50: Locate | N50: =J23+P46+D47 -> 92202

Sheet 8.18 Ticket Counts
A2: PUBLIC UTILITY COMMISSION OF TEXAS
A3: CENTERPOINT ENERGY HOUSTON ELECTRIC, LLC
A4: V-K-9.2 CERC SKF's
A5: TEST YEAR ENDED 12/31/2018
A6: DOCKET NUMBER PENDING ASSIGNMENT
A7: SPONSOR: M. TOWNSEND
A11: Underground Locating Research Dept.
A12: Tickets Researched Report
A13: from 8/01/2018 thru 8/31/2018
A17: Gas Tickets
D19: No. Dist. | E19: East Dist. | F19: So. Dist | G19: West Dist. | H19: Baytown | I19: Richmond
A20: 133406 TSUGL3 - Research | D20: 11029391 | E20: 11029394 | F20: 11029392 | G20: 11029393 | H20: 11029389 | I20: 11029390 | J20: Total
A21: Gas Tickets received | D21: =18252+74 -> 18326 | E21: =9800+33 -> 9833 | F21: =6886+49 -> 6935 | G21: =16643+116 -> 16759 | H21: =13689+82 -> 13771 | I21: =7224+38 -> 7262 | J21: =(D21+E21+F21+G21+H21+I21) -> 72886 | L21: =J23/J21 -> 0.72638092 | M21: Gas To Field
A22: 133403 TSUGL2 - Locates | D22: 11029382 | E22: 11029385 | F22: 11029383 | G22: 11029384 | H22: 11029380 | I22: 11029381
A23: Tickets sent for staking | D23: =12607+74 -> 12681 | E23: =8658+33 -> 8691 | F23: =5684+49 -> 5733 | G23: =12965+116 -> 13081 | H23: =8706+82 -> 8788 | I23: =3931+38 -> 3969 | J23: =(D23+E23+F23+G23+H23+I23) -> 52943
A26: Electric Tickets
D27: Baytown | F27: Galveston | H27: Greenspoint | J27: Humble | L27: South Houston | N27: Bellaire/Mag. Park
D28: 0.22 | E28: 0.78 | F28: 0.22 | G28: 0.78 | H28: 0.22 | I28: 0.78 | J28: 0.22 | K28: 0.78 | L28: 0.22 | M28: 0.78 | N28: 0.22 | O28: 0.78
D29: 11002001 | E29: 11029483 | F29: 11002003 | G29: 11029487 | H29: 11001995 | I29: 11029493 | J29: 11001997 | K29: 11029481 | L29: 11002000 | M29: 11029486 | N29: 11002142 | O29: 11029491
A30: 133406 TSUGL3 - Research | D30: =D31*D28 -> 1589.94 | E30: =D31*E28 -> 5637.06 | F30: =F31*F28 -> 858 | G30: =F31*G28 -> 3042 | H30: =H31*H28 -> 1487.86 | I30: =H31*I28 -> 5275.14 | J30: =J31*J28 -> 1225.62 | K30: =J31*K28 -> 4345.38 | L30: =L31*L28 -> 1584.44 | M30: =L31*M28 -> 5617.56 | N30: =N31*N28 -> 1917.96 | O30: =N31*O28 -> 6800.04 | P30: SAP Upload
A31: Electric tickets received | D31: 7227 | F31: 3900 | H31: =6578+185 -> 6763 | J31: 5571 | L31: 7202 | N31: 8718
A32: 133403 TSUGL1 - Locates | D32: =D33*D28 -> 645.92 | E32: =D33*E28 -> 2290.08 | F32: =F33*F28 -> 141.9 | G32: =F33*G28 -> 503.1 | H32: =H33*H28 -> 1051.38 | I32: =H33*I28 -> 3727.62 | J32: =J33*J28 -> 830.5 | K32: =J33*K28 -> 2944.5 | L32: =L33*L28 -> 844.8 | M32: =L33*M28 -> 2995.2 | N32: =N33*N28 -> 987.36 | O32: =N33*O28 -> 3500.64 | P32: SAP Upload
A33: Tickets sent for staking | D33: 2936 | F33: 645 | H33: =4594+185 -> 4779 | J33: 3775 | L33: 3840 | N33: 4488
D35: Cypress | F35: Fort Bend/Wharton | H35: HOC/Brazosport | J35: Katy | L35: Spring Branch | N35: Sugar Land
D36: 0.22 | E36: 0.78 | F36: 0.22 | G36: 0.78 | H36: 0.22 | I36: 0.78 | J36: 0.22 | K36: 0.78 | L36: 0.22 | M36: 0.78 | N36: 0.22 | O36: 0.78
D37: 11001996 | E37: 11029494 | F37: 11002006 | G37: 11029482 | H37: 11002143 | I37: 11029490 | J37: 11002007 | K37: 11029485 | L37: 11002008 | M37: 11029489 | N37: 11002009 | O37: 11029484
A38: 133406 TSUGL3 - Research | D38: =D39*D36 -> 1306.36 | E38: =D39*E36 -> 4631.64 | F38: =F39*F36 -> 935.44 | G38: =F39*G36 -> 3316.56 | H38: =H39*H36 -> 1318.9 | I38: =H39*I36 -> 4676.1 | J38: =J39*J36 -> 1107.7 | K38: =J39*K36 -> 3927.3 | L38: =L39*L36 -> 809.82 | M38: =L39*M36 -> 2871.18 | N38: =N39*N36 -> 973.72 | O38: =N39*O36 -> 3452.28 | P38: SAP Upload
A39: Electric tickets received | D39: =5749+189 -> 5938 | F39: 4252 | H39: 5995 | J39: 5035 | L39: 3681 | N39: 4426
A40: 133403 TSUGL1 - Locates | D40: =D41*D36 -> 899.8 | E40: =D41*E36 -> 3190.2 | F40: =F41*F36 -> 583.22 | G40: =F41*G36 -> 2067.78 | H40: =H41*H36 -> 669.9 | I40: =H41*I36 -> 2375.1 | J40: =J41*J36 -> 847.66 | K40: =J41*K36 -> 3005.34 | L40: =L41*L36 -> 481.36 | M40: =L41*M36 -> 1706.64 | N40: =N41*N36 -> 806.3 | O40: =N41*O36 -> 2858.7 | P40: SAP Upload
A41: Tickets sent for staking | D41: =3901+189 -> 4090 | F41: 2651 | H41: 3045 | J41: 3853 | L41: 2188 | N41: 3665
D42: =$C$42*D41 -> 0 | H42: =$C$42*H41 -> 0 | J42: =$C$42*J41 -> 0 | L42: =$C$42*L41 -> 0 | N42: =$C$42*N41 -> 0
N43: Total Electric Tickets
N44: 0.22 | O44: 0.78 | P44: Total
K45: =P46/P45 -> 0.58151889 | L45: Elec to Field | M45: Research | N45: =N38+L38+J38+H38+F38+D38+D30+F30+H30+J30+L30+N30 -> 15115.76 | O45: =O38+M38+K38+I38+G38+E38+E30+G30+I30+K30+M30+O30 -> 53592.24 | P45: =N45+O45 -> 68708
A46: FOC | M46: Locate | N46: =N40+L40+J40+H40+F40+D40+D32+F32+H32+J32+L32+N32 -> 8790.1 | O46: =O40+M40+K40+I40+G40+E40+E32+G32+I32+K32+M32+O32 -> 31164.9 | P46: =N46+O46 -> 39955
A47: Ticket sent for staking | D47: 998
N48: Total Tickets
M49: Research | N49: =P45+J21 -> 141594
M50: Locate | N50: =J23+P46+D47 -> 93896

Sheet 9.18 Ticket Counts
A2: PUBLIC UTILITY COMMISSION OF TEXAS
A3: CENTERPOINT ENERGY HOUSTON ELECTRIC, LLC
A4: V-K-9.2 CERC SKF's
A5: TEST YEAR ENDED 12/31/2018
A6: DOCKET NUMBER PENDING ASSIGNMENT
A7: SPONSOR: M. TOWNSEND
A11: Underground Locating Research Dept.
A12: Tickets Researched Report
A13: from 9/01/2018 thru 9/30/2018
A17: Gas Tickets
D19: No. Dist. | E19: East Dist. | F19: So. Dist | G19: West Dist. | H19: Baytown | I19: Richmond
A20: 133406 TSUGL3 - Research | D20: 11029391 | E20: 11029394 | F20: 11029392 | G20: 11029393 | H20: 11029389 | I20: 11029390 | J20: Total
A21: Gas Tickets received | D21: =14883+58 -> 14941 | E21: =8320+36 -> 8356 | F21: =5488+28 -> 5516 | G21: =13691+96 -> 13787 | H21: =10911+55 -> 10966 | I21: =5556+23 -> 5579 | J21: =(D21+E21+F21+G21+H21+I21) -> 59145 | L21: =J23/J21 -> 0.7248119 | M21: Gas To Field
A22: 133403 TSUGL2 - Locates | D22: 11029382 | E22: 11029385 | F22: 11029383 | G22: 11029384 | H22: 11029380 | I22: 11029381
A23: Tickets sent for staking | D23: =10239+58 -> 10297 | E23: =7172+36 -> 7208 | F23: =4552+28 -> 4580 | G23: =10596+96 -> 10692 | H23: =7053+55 -> 7108 | I23: =2961+23 -> 2984 | J23: =(D23+E23+F23+G23+H23+I23) -> 42869
A26: Electric Tickets
D27: Baytown | F27: Galveston | H27: Greenspoint | J27: Humble | L27: South Houston | N27: Bellaire/Mag. Park
D28: 0.22 | E28: 0.78 | F28: 0.22 | G28: 0.78 | H28: 0.22 | I28: 0.78 | J28: 0.22 | K28: 0.78 | L28: 0.22 | M28: 0.78 | N28: 0.22 | O28: 0.78
D29: 11002001 | E29: 11029483 | F29: 11002003 | G29: 11029487 | H29: 11001995 | I29: 11029493 | J29: 11001997 | K29: 11029481 | L29: 11002000 | M29: 11029486 | N29: 11002142 | O29: 11029491
A30: 133406 TSUGL3 - Research | D30: =D31*D28 -> 1373.24 | E30: =D31*E28 -> 4868.76 | F30: =F31*F28 -> 712.8 | G30: =F31*G28 -> 2527.2 | H30: =H31*H28 -> 1191.08 | I30: =H31*I28 -> 4222.92 | J30: =J31*J28 -> 944.02 | K30: =J31*K28 -> 3346.98 | L30: =L31*L28 -> 1168.86 | M30: =L31*M28 -> 4144.14 | N30: =N31*N28 -> 1583.12 | O30: =N31*O28 -> 5612.88 | P30: SAP Upload
A31: Electric tickets received | D31: 6242 | F31: 3240 | H31: =5257+157 -> 5414 | J31: 4291 | L31: 5313 | N31: 7196
A32: 133403 TSUGL1 - Locates | D32: =D33*D28 -> 628.1 | E32: =D33*E28 -> 2226.9 | F32: =F33*F28 -> 97.9 | G32: =F33*G28 -> 347.1 | H32: =H33*H28 -> 844.8 | I32: =H33*I28 -> 2995.2 | J32: =J33*J28 -> 673.42 | K32: =J33*K28 -> 2387.58 | L32: =L33*L28 -> 664.84 | M32: =L33*M28 -> 2357.16 | N32: =N33*N28 -> 815.98 | O32: =N33*O28 -> 2893.02 | P32: SAP Upload
A33: Tickets sent for staking | D33: 2855 | F33: 445 | H33: =3683+157 -> 3840 | J33: 3061 | L33: 3022 | N33: 3709
D35: Cypress | F35: Fort Bend/Wharton | H35: HOC/Brazosport | J35: Katy | L35: Spring Branch | N35: Sugar Land
D36: 0.22 | E36: 0.78 | F36: 0.22 | G36: 0.78 | H36: 0.22 | I36: 0.78 | J36: 0.22 | K36: 0.78 | L36: 0.22 | M36: 0.78 | N36: 0.22 | O36: 0.78
D37: 11001996 | E37: 11029494 | F37: 11002006 | G37: 11029482 | H37: 11002143 | I37: 11029490 | J37: 11002007 | K37: 11029485 | L37: 11002008 | M37: 11029489 | N37: 11002009 | O37: 11029484
A38: 133406 TSUGL3 - Research | D38: =D39*D36 -> 1050.94 | E38: =D39*E36 -> 3726.06 | F38: =F39*F36 -> 677.38 | G38: =F39*G36 -> 2401.62 | H38: =H39*H36 -> 1063.92 | I38: =H39*I36 -> 3772.08 | J38: =J39*J36 -> 917.62 | K38: =J39*K36 -> 3253.38 | L38: =L39*L36 -> 769.12 | M38: =L39*M36 -> 2726.88 | N38: =N39*N36 -> 755.04 | O38: =N39*O36 -> 2676.96 | P38: SAP Upload
A39: Electric tickets received | D39: =4640+137 -> 4777 | F39: 3079 | H39: 4836 | J39: 4171 | L39: 3496 | N39: 3432
A40: 133403 TSUGL1 - Locates | D40: =D41*D36 -> 725.56 | E40: =D41*E36 -> 2572.44 | F40: =F41*F36 -> 426.58 | G40: =F41*G36 -> 1512.42 | H40: =H41*H36 -> 543.18 | I40: =H41*I36 -> 1925.82 | J40: =J41*J36 -> 717.86 | K40: =J41*K36 -> 2545.14 | L40: =L41*L36 -> 533.72 | M40: =L41*M36 -> 1892.28 | N40: =N41*N36 -> 639.32 | O40: =N41*O36 -> 2266.68 | P40: SAP Upload
A41: Tickets sent for staking | D41: =3161+137 -> 3298 | F41: 1939 | H41: 2469 | J41: 3263 | L41: 2426 | N41: 2906
D42: =$C$42*D41 -> 0 | H42: =$C$42*H41 -> 0 | J42: =$C$42*J41 -> 0 | L42: =$C$42*L41 -> 0 | N42: =$C$42*N41 -> 0
N43: Total Electric Tickets
N44: 0.22 | O44: 0.78 | P44: Total
K45: =P46/P45 -> 0.59893308 | L45: Elec to Field | M45: Research | N45: =N38+L38+J38+H38+F38+D38+D30+F30+H30+J30+L30+N30 -> 12207.14 | O45: =O38+M38+K38+I38+G38+E38+E30+G30+I30+K30+M30+O30 -> 43279.86 | P45: =N45+O45 -> 55487
A46: FOC | M46: Locate | N46: =N40+L40+J40+H40+F40+D40+D32+F32+H32+J32+L32+N32 -> 7311.26 | O46: =O40+M40+K40+I40+G40+E40+E32+G32+I32+K32+M32+O32 -> 25921.74 | P46: =N46+O46 -> 33233
A47: Ticket sent for staking | D47: 940
N48: Total Tickets
M49: Research | N49: =P45+J21 -> 114632
M50: Locate | N50: =J23+P46+D47 -> 77042

Sheet 10.18 Ticket Counts
A2: PUBLIC UTILITY COMMISSION OF TEXAS
A3: CENTERPOINT ENERGY HOUSTON ELECTRIC, LLC
A4: V-K-9.2 CERC SKF's
A5: TEST YEAR ENDED 12/31/2018
A6: DOCKET NUMBER PENDING ASSIGNMENT
A7: SPONSOR: M. TOWNSEND
A11: Underground Locating Research Dept.
A12: Tickets Researched Report
A13: from 10/01/2018 thru 10/31/2018
A17: Gas Tickets
D19: No. Dist. | E19: East Dist. | F19: So. Dist | G19: West Dist. | H19: Baytown | I19: Richmond
A20: 133406 TSUGL3 - Research | D20: 11029391 | E20: 11029394 | F20: 11029392 | G20: 11029393 | H20: 11029389 | I20: 11029390 | J20: Total
A21: Gas Tickets received | D21: 17426 | E21: 9753 | F21: 6418 | G21: 17184 | H21: 12684 | I21: 7305 | J21: =(D21+E21+F21+G21+H21+I21) -> 70770 | L21: =J23/J21 -> 0.72144977 | M21: Gas To Field
A22: 133403 TSUGL2 - Locates | D22: 11029382 | E22: 11029385 | F22: 11029383 | G22: 11029384 | H22: 11029380 | I22: 11029381
A23: Tickets sent for staking | D23: 11981 | E23: 8440 | F23: 5163 | G23: 13594 | H23: 8153 | I23: 3726 | J23: =(D23+E23+F23+G23+H23+I23) -> 51057
A26: Electric Tickets
D27: Baytown | F27: Galveston | H27: Greenspoint | J27: Humble | L27: South Houston | N27: Bellaire/Mag. Park
D28: 0.22 | E28: 0.78 | F28: 0.22 | G28: 0.78 | H28: 0.22 | I28: 0.78 | J28: 0.22 | K28: 0.78 | L28: 0.22 | M28: 0.78 | N28: 0.22 | O28: 0.78
D29: 11002001 | E29: 11029483 | F29: 11002003 | G29: 11029487 | H29: 11001995 | I29: 11029493 | J29: 11001997 | K29: 11029481 | L29: 11002000 | M29: 11029486 | N29: 11002142 | O29: 11029491
A30: 133406 TSUGL3 - Research | D30: =D31*D28 -> 1470.26 | E30: =D31*E28 -> 5212.74 | F30: =F31*F28 -> 802.12 | G30: =F31*G28 -> 2843.88 | H30: =H31*H28 -> 1463.22 | I30: =H31*I28 -> 5187.78 | J30: =J31*J28 -> 1154.12 | K30: =J31*K28 -> 4091.88 | L30: =L31*L28 -> 1399.42 | M30: =L31*M28 -> 4961.58 | N30: =N31*N28 -> 1871.1 | O30: =N31*O28 -> 6633.9 | P30: SAP Upload
A31: Electric tickets received | D31: 6683 | F31: 3646 | H31: 6651 | J31: 5246 | L31: 6361 | N31: 8505
A32: 133403 TSUGL1 - Locates | D32: =D33*D28 -> 621.28 | E32: =D33*E28 -> 2202.72 | F32: =F33*F28 -> 118.14 | G32: =F33*G28 -> 418.86 | H32: =H33*H28 -> 1020.8 | I32: =H33*I28 -> 3619.2 | J32: =J33*J28 -> 804.1 | K32: =J33*K28 -> 2850.9 | L32: =L33*L28 -> 789.36 | M32: =L33*M28 -> 2798.64 | N32: =N33*N28 -> 929.72 | O32: =N33*O28 -> 3296.28 | P32: SAP Upload
A33: Tickets sent for staking | D33: 2824 | F33: 537 | H33: 4640 | J33: 3655 | L33: 3588 | N33: 4226
D35: Cypress | F35: Fort Bend/Wharton | H35: HOC/Brazosport | J35: Katy | L35: Spring Branch | N35: Sugar Land
D36: 0.22 | E36: 0.78 | F36: 0.22 | G36: 0.78 | H36: 0.22 | I36: 0.78 | J36: 0.22 | K36: 0.78 | L36: 0.22 | M36: 0.78 | N36: 0.22 | O36: 0.78
D37: 11001996 | E37: 11029494 | F37: 11002006 | G37: 11029482 | H37: 11002143 | I37: 11029490 | J37: 11002007 | K37: 11029485 | L37: 11002008 | M37: 11029489 | N37: 11002009 | O37: 11029484
A38: 133406 TSUGL3 - Research | D38: =D39*D36 -> 1313.62 | E38: =D39*E36 -> 4657.38 | F38: =F39*F36 -> 927.74 | G38: =F39*G36 -> 3289.26 | H38: =H39*H36 -> 1333.42 | I38: =H39*I36 -> 4727.58 | J38: =J39*J36 -> 1103.08 | K38: =J39*K36 -> 3910.92 | L38: =L39*L36 -> 1073.82 | M38: =L39*M36 -> 3807.18 | N38: =N39*N36 -> 834.68 | O38: =N39*O36 -> 2959.32 | P38: SAP Upload
A39: Electric tickets received | D39: 5971 | F39: 4217 | H39: 6061 | J39: 5014 | L39: 4881 | N39: 3794
A40: 133403 TSUGL1 - Locates | D40: =D41*D36 -> 936.32 | E40: =D41*E36 -> 3319.68 | F40: =F41*F36 -> 554.62 | G40: =F41*G36 -> 1966.38 | H40: =H41*H36 -> 737.44 | I40: =H41*I36 -> 2614.56 | J40: =J41*J36 -> 878.02 | K40: =J41*K36 -> 3112.98 | L40: =L41*L36 -> 768.46 | M40: =L41*M36 -> 2724.54 | N40: =N41*N36 -> 669.9 | O40: =N41*O36 -> 2375.1 | P40: SAP Upload
A41: Tickets sent for staking | D41: 4256 | F41: 2521 | H41: 3352 | J41: 3991 | L41: 3493 | N41: 3045
D42: =$C$42*D41 -> 0 | H42: =$C$42*H41 -> 0 | J42: =$C$42*J41 -> 0 | L42: =$C$42*L41 -> 0 | N42: =$C$42*N41 -> 0
N43: Total Electric Tickets
N44: 0.22 | O44: 0.78 | P44: Total
K45: =P46/P45 -> 0.59865732 | L45: Elec to Field | M45: Research | N45: =N38+L38+J38+H38+F38+D38+D30+F30+H30+J30+L30+N30 -> 14746.6 | O45: =O38+M38+K38+I38+G38+E38+E30+G30+I30+K30+M30+O30 -> 52283.4 | P45: =N45+O45 -> 67030
A46: FOC | M46: Locate | N46: =N40+L40+J40+H40+F40+D40+D32+F32+H32+J32+L32+N32 -> 8828.16 | O46: =O40+M40+K40+I40+G40+E40+E32+G32+I32+K32+M32+O32 -> 31299.84 | P46: =N46+O46 -> 40128
A47: Ticket sent for staking | D47: 1254
N48: Total Tickets
M49: Research | N49: =P45+J21 -> 137800
M50: Locate | N50: =J23+P46+D47 -> 92439

Sheet 11.18 Ticket Counts
A2: PUBLIC UTILITY COMMISSION OF TEXAS
A3: CENTERPOINT ENERGY HOUSTON ELECTRIC, LLC
A4: V-K-9.2 CERC SKF's
A5: TEST YEAR ENDED 12/31/2018
A6: DOCKET NUMBER PENDING ASSIGNMENT
A7: SPONSOR: M. TOWNSEND
A11: Underground Locating Research Dept.
A12: Tickets Researched Report
A13: from 11/01/2018 thru 11/30/2018
A17: Gas Tickets
D19: No. Dist. | E19: East Dist. | F19: So. Dist | G19: West Dist. | H19: Baytown | I19: Richmond
A20: 133406 TSUGL3 - Research | D20: 11029391 | E20: 11029394 | F20: 11029392 | G20: 11029393 | H20: 11029389 | I20: 11029390 | J20: Total
A21: Gas Tickets received | D21: 13950 | E21: 9161 | F21: 5667 | G21: 16008 | H21: 11980 | I21: 6343 | J21: =(D21+E21+F21+G21+H21+I21) -> 63109 | L21: =J23/J21 -> 0.73667781 | M21: Gas To Field
A22: 133403 TSUGL2 - Locates | D22: 11029382 | E22: 11029385 | F22: 11029383 | G22: 11029384 | H22: 11029380 | I22: 11029381
A23: Tickets sent for staking | D23: 9910 | E23: 8007 | F23: 4609 | G23: 12815 | H23: 7897 | I23: 3253 | J23: =(D23+E23+F23+G23+H23+I23) -> 46491
A26: Electric Tickets
D27: Baytown | F27: Galveston | H27: Greenspoint | J27: Humble | L27: South Houston | N27: Bellaire/Mag. Park
D28: 0.22 | E28: 0.78 | F28: 0.22 | G28: 0.78 | H28: 0.22 | I28: 0.78 | J28: 0.22 | K28: 0.78 | L28: 0.22 | M28: 0.78 | N28: 0.22 | O28: 0.78
D29: 11002001 | E29: 11029483 | F29: 11002003 | G29: 11029487 | H29: 11001995 | I29: 11029493 | J29: 11001997 | K29: 11029481 | L29: 11002000 | M29: 11029486 | N29: 11002142 | O29: 11029491
A30: 133406 TSUGL3 - Research | D30: =D31*D28 -> 1315.6 | E30: =D31*E28 -> 4664.4 | F30: =F31*F28 -> 685.08 | G30: =F31*G28 -> 2428.92 | H30: =H31*H28 -> 1159.84 | I30: =H31*I28 -> 4112.16 | J30: =J31*J28 -> 932.14 | K30: =J31*K28 -> 3304.86 | L30: =L31*L28 -> 1202.52 | M30: =L31*M28 -> 4263.48 | N30: =N31*N28 -> 1778.7 | O30: =N31*O28 -> 6306.3 | P30: SAP Upload
A31: Electric tickets received | D31: 5980 | F31: 3114 | H31: 5272 | J31: 4237 | L31: 5466 | N31: 8085
A32: 133403 TSUGL1 - Locates | D32: =D33*D28 -> 582.78 | E32: =D33*E28 -> 2066.22 | F32: =F33*F28 -> 97.24 | G32: =F33*G28 -> 344.76 | H32: =H33*H28 -> 818.62 | I32: =H33*I28 -> 2902.38 | J32: =J33*J28 -> 652.52 | K32: =J33*K28 -> 2313.48 | L32: =L33*L28 -> 677.16 | M32: =L33*M28 -> 2400.84 | N32: =N33*N28 -> 892.76 | O32: =N33*O28 -> 3165.24 | P32: SAP Upload
A33: Tickets sent for staking | D33: 2649 | F33: 442 | H33: 3721 | J33: 2966 | L33: 3078 | N33: 4058
D35: Cypress | F35: Fort Bend/Wharton | H35: HOC/Brazosport | J35: Katy | L35: Spring Branch | N35: Sugar Land
D36: 0.22 | E36: 0.78 | F36: 0.22 | G36: 0.78 | H36: 0.22 | I36: 0.78 | J36: 0.22 | K36: 0.78 | L36: 0.22 | M36: 0.78 | N36: 0.22 | O36: 0.78
D37: 11001996 | E37: 11029494 | F37: 11002006 | G37: 11029482 | H37: 11002143 | I37: 11029490 | J37: 11002007 | K37: 11029485 | L37: 11002008 | M37: 11029489 | N37: 11002009 | O37: 11029484
A38: 133406 TSUGL3 - Research | D38: =D39*D36 -> 1130.8 | E38: =D39*E36 -> 4009.2 | F38: =F39*F36 -> 822.58 | G38: =F39*G36 -> 2916.42 | H38: =H39*H36 -> 1346.62 | I38: =H39*I36 -> 4774.38 | J38: =J39*J36 -> 953.92 | K38: =J39*K36 -> 3382.08 | L38: =L39*L36 -> 1052.7 | M38: =L39*M36 -> 3732.3 | N38: =N39*N36 -> 800.8 | O38: =N39*O36 -> 2839.2 | P38: SAP Upload
A39: Electric tickets received | D39: 5140 | F39: 3739 | H39: 6121 | J39: 4336 | L39: 4785 | N39: 3640
A40: 133403 TSUGL1 - Locates | D40: =D41*D36 -> 792.22 | E40: =D41*E36 -> 2808.78 | F40: =F41*F36 -> 518.32 | G40: =F41*G36 -> 1837.68 | H40: =H41*H36 -> 727.76 | I40: =H41*I36 -> 2580.24 | J40: =J41*J36 -> 738.76 | K40: =J41*K36 -> 2619.24 | L40: =L41*L36 -> 766.92 | M40: =L41*M36 -> 2719.08 | N40: =N41*N36 -> 642.62 | O40: =N41*O36 -> 2278.38 | P40: SAP Upload
A41: Tickets sent for staking | D41: 3601 | F41: 2356 | H41: 3308 | J41: 3358 | L41: 3486 | N41: 2921
D42: =$C$42*D41 -> 0 | H42: =$C$42*H41 -> 0 | J42: =$C$42*J41 -> 0 | L42: =$C$42*L41 -> 0 | N42: =$C$42*N41 -> 0
N43: Total Electric Tickets
N44: 0.22 | O44: 0.78 | P44: Total
K45: =P46/P45 -> 0.59991655 | L45: Elec to Field | M45: Research | N45: =N38+L38+J38+H38+F38+D38+D30+F30+H30+J30+L30+N30 -> 13181.3 | O45: =O38+M38+K38+I38+G38+E38+E30+G30+I30+K30+M30+O30 -> 46733.7 | P45: =N45+O45 -> 59915
A46: FOC | M46: Locate | N46: =N40+L40+J40+H40+F40+D40+D32+F32+H32+J32+L32+N32 -> 7907.68 | O46: =O40+M40+K40+I40+G40+E40+E32+G32+I32+K32+M32+O32 -> 28036.32 | P46: =N46+O46 -> 35944
A47: Ticket sent for staking | D47: 1205
N48: Total Tickets
M49: Research | N49: =P45+J21 -> 123024
M50: Locate | N50: =J23+P46+D47 -> 83640

Sheet 12.18 Ticket Counts
A2: PUBLIC UTILITY COMMISSION OF TEXAS
A3: CENTERPOINT ENERGY HOUSTON ELECTRIC, LLC
A4: V-K-9.2 CERC SKF's
A5: TEST YEAR ENDED 12/31/2018
A6: DOCKET NUMBER PENDING ASSIGNMENT
A7: SPONSOR: M. TOWNSEND
A11: Underground Locating Research Dept.
A12: Tickets Researched Report
A13: from 12/01/2018 thru 12/31/2018
A17: Gas Tickets
D19: No. Dist. | E19: East Dist. | F19: So. Dist | G19: West Dist. | H19: Baytown | I19: Richmond
A20: 133406 TSUGL3 - Research | D20: 11029391 | E20: 11029394 | F20: 11029392 | G20: 11029393 | H20: 11029389 | I20: 11029390 | J20: Total
A21: Gas Tickets received | D21: 12174 | E21: 7362 | F21: 4940 | G21: 12687 | H21: 10056 | I21: 5231 | J21: =(D21+E21+F21+G21+H21+I21) -> 52450 | L21: =J23/J21 -> 0.7415062 | M21: Gas To Field
A22: 133403 TSUGL2 - Locates | D22: 11029382 | E22: 11029385 | F22: 11029383 | G22: 11029384 | H22: 11029380 | I22: 11029381
A23: Tickets sent for staking | D23: 8820 | E23: 6503 | F23: 3977 | G23: 10104 | H23: 6578 | I23: 2910 | J23: =(D23+E23+F23+G23+H23+I23) -> 38892
A26: Electric Tickets
D27: Baytown | F27: Galveston | H27: Greenspoint | J27: Humble | L27: South Houston | N27: Bellaire/Mag. Park
D28: 0.22 | E28: 0.78 | F28: 0.22 | G28: 0.78 | H28: 0.22 | I28: 0.78 | J28: 0.22 | K28: 0.78 | L28: 0.22 | M28: 0.78 | N28: 0.22 | O28: 0.78
D29: 11002001 | E29: 11029483 | F29: 11002003 | G29: 11029487 | H29: 11001995 | I29: 11029493 | J29: 11001997 | K29: 11029481 | L29: 11002000 | M29: 11029486 | N29: 11002142 | O29: 11029491
A30: 133406 TSUGL3 - Research | D30: =D31*D28 -> 1120.24 | E30: =D31*E28 -> 3971.76 | F30: =F31*F28 -> 544.28 | G30: =F31*G28 -> 1929.72 | H30: =H31*H28 -> 1084.82 | I30: =H31*I28 -> 3846.18 | J30: =J31*J28 -> 790.46 | K30: =J31*K28 -> 2802.54 | L30: =L31*L28 -> 1032.9 | M30: =L31*M28 -> 3662.1 | N30: =N31*N28 -> 1456.4 | O30: =N31*O28 -> 5163.6 | P30: SAP Upload
A31: Electric tickets received | D31: 5092 | F31: 2474 | H31: 4931 | J31: 3593 | L31: 4695 | N31: 6620
