Workbook
Name \M: #REF!
Name _asd2: '[1]O & M'!$T$5
Name _M: #REF!
Name Account: [2]Source!#REF!
Name Account2: [2]Source!#REF!
Name AccountDescr: [2]Source!#REF!
Name AccountDescr2: [2]Source!#REF!
Name Activity: [2]Source!#REF!
Name Activity2: [2]Source!#REF!
Name ActivityDescr: [2]Source!#REF!
Name ActivityDescr2: [2]Source!#REF!
Name Affiliate: [2]Source!#REF!
Name Affiliate2: [2]Source!#REF!
Name AffiliateDescr: [2]Source!#REF!
Name ASD: '[3]O & M'!$T$5
Name Completed: '[4]FIT Paid - Combined'!$AO$5
Name completed2: '[5]FIT Paid - Combined'!$AO$5
Name Credit: [6]JOURNAL!#REF!
Name Debit: [6]JOURNAL!#REF!
Name DeptDescr: [2]Source!#REF!
Name DeptDescr2: [2]Source!#REF!
Name DeptID: [2]Source!#REF!
Name DeptID2: [2]Source!#REF!
Name EC: [2]Source!#REF!
Name ECDescr: [2]Source!#REF!
Name ECDescr2: [2]Source!#REF!
Name ECID: [2]Source!#REF!
Name Elapsed: '[4]FIT Paid - Combined'!$AO$4
Name entry: [6]JOURNAL!$B$9:$R$353,[6]JOURNAL!$I$3,[6]JOURNAL!$G$3,[6]JOURNAL!$E$3,[6]JOURNAL!$B$7,[6]JOURNAL!$B$3
Name EntryFields: [6]JOURNAL!$B$9:$R$353,[6]JOURNAL!$I$3,[6]JOURNAL!$G$3,[6]JOURNAL!$E$3,[6]JOURNAL!$B$7,[6]JOURNAL!$B$3
Name FFT: #REF!
Name KeyControlFigure: '[4]FIT Paid - Combined'!$T$399
Name Lines: [6]JOURNAL!#REF!
Name Location: [2]Source!#REF!
Name Location2: [2]Source!#REF!
Name LocationDescr: [2]Source!#REF!
Name LocationDescr2: [2]Source!#REF!
Name MENU: #REF!
Name NvsASD: "V2000-12-31"
Name NvsAutoDrillOk: "VN"
Name NvsElapsedTime: 0.000582986111112405
Name NvsElapsedTime: 0.000689467597112525
Name NvsEndTime: 36257.3051395833
Name NvsEndTime: 36923.3059673611
Name NvsInstSpec: "%"
Name NvsLayoutType: "M3"
Name NvsNplSpec: "%,X,RZF..nPlosion,CZF.."
Name NvsPanelEffdt: "V1998-01-01"
Name NvsPanelSetid: "VSHARE"
Name NvsParentRef: [7]Sheet1!$T$303
Name NvsReqBU: "VGEN"
Name NvsReqBU: "VLSGD"
Name NvsReqBUOnly: "VY"
Name NvsTransLed: "VN"
Name NvsTreeASD: "V2000-12-31"
Name NvsValTbl.ACCOUNT: "GL_ACCOUNT_TBL"
Name NvsValTbl.AFFILIATE: "BUS_UNIT_TBL_FS"
Name NvsValTbl.CURRENCY_CD: "CURRENCY_CD_TBL"
Name NvsValTbl.DEPTID: "DEPARTMENT_TBL"
Name NvsValTbl.TU_LOCATION: "TU_LOC_TBL"

Sheet  
A1: 2022 RATE CASE
A2: ONCOR ELECTRIC DELIVERY COMPANY LLC
A3: LEAD-LAG STUDY RESULTS
A4: FOR THE TEST-YEAR ENDING DECEMBER 31, 2021
A5: SPONSOR: A. THENMADATHIL
A7: Line | C7: Revenue | D7: Expense
A8: No. | B8: Description | C8: Lag Days* | D8: Lead Days | E8: Reference
B9: (a) | C9: (b) | D9: (c) | E9: (d)
A11: 1 | B11: Operation & Maintenance Expenses
A12: =A11+1 -> 2 | B12: Labor
A13: =A12+1 -> 3 | B13: Payroll | C13: =+'1'!H14 -> 52.9 | D13: =+'2'!J35 -> -12.11 | E13: WP/II-B-9/2
A14: =A13+1 -> 4 | B14: Incentive Pay | C14: =+$C$13 -> 52.9 | D14: ='3'!J17 -> -249.34672 | E14: WP/II-B-9/3
A15: =A14+1 -> 5
A16: =A15+1 -> 6 | B16: Non-Labor
A17: =A16+1 -> 7 | B17: Affiliate Charges - Sempra | C17: =+$C$13 -> 52.9 | D17: =+'4'!K24 -> -44.96 | E17: WP/II-B-9/4
A18: =A17+1 -> 8 | B18: Affiliate Charges - Other | C18: =+$C$13 -> 52.9 | D18: =+'6'!D17 -> -46.93 | E18: WP/II-B-9/6
A19: =A18+1 -> 9 | B19: TCOS
A20: =A19+1 -> 10 | B20: Oncor | C20: 0 | D20: 0 | E20: N/A
A21: =A20+1 -> 11 | B21: Non-Oncor | C21: =+$C$13 -> 52.9 | D21: ='5'!E16 -> -50.22 | E21: WP/II-B-9/5
A22: =A21+1 -> 12 | B22: Amortized O&M Expenses | C22: 0 | D22: 0 | E22: N/A
A23: =A22+1 -> 13 | B23: Other O&M | C23: =+$C$13 -> 52.9 | D23: ='6'!D17 -> -46.93 | E23: WP/II-B-9/6
A24: =A23+1 -> 14 | B24: Pension & Supplemental Retirement Benefits | C24: =+$C$13 -> 52.9 | D24: =+'6-4'!I36 -> -53.506661 | E24: WP/II-B-9/6-4
A25: =A24+1 -> 15 | B25: Other Post-Employment Benefits | C25: =+$C$13 -> 52.9 | D25: ='6-5'!I23 -> 10.708699 | E25: WP/II-B-9/6-5
A26: =A25+1 -> 16
A27: =A26+1 -> 17 | B27: Federal Income Taxes
A28: =A27+1 -> 18 | B28: Current | C28: =+$C$13 -> 52.9 | D28: =+'7'!F20 -> -36.25 | E28: WP/II-B-9/7
A29: =A28+1 -> 19 | B29: Deferred | C29: 0 | D29: 0 | E29: N/A
A30: =A29+1 -> 20
A31: =A30+1 -> 21 | B31: Taxes Other Than Income Taxes
A32: =A31+1 -> 22 | B32: Payroll Taxes | C32: =+$C$13 -> 52.9 | D32: =+'8'!D16 -> -11.66 | E32: WP/II-B-9/8
A33: =A32+1 -> 23 | B33: State Gross Margin Taxes | C33: =+$C$13 -> 52.9 | D33: =+'9'!F23 -> 47.17 | E33: WP/II-B-9/9
A34: =A33+1 -> 24 | B34: Local Franchise Taxes | C34: =+$C$13 -> 52.9 | D34: ='10'!F37 -> -54.99 | E34: WP/II-B-9/10
A35: =A34+1 -> 25 | B35: Ad Valorem Taxes | C35: =+$C$13 -> 52.9 | D35: =+'11'!G37 -> -209.9 | E35: WP/II-B-9/11
A36: =A35+1 -> 26
A37: =A36+1 -> 27 | B37: Depreciation Expense | C37: 0 | D37: 0 | E37: N/A
A38: =A37+1 -> 28
A39: =A38+1 -> 29 | B39: Return | C39: 0 | D39: 0 | E39: N/A
A40: =A39+1 -> 30
A41: =A40+1 -> 31 | B41: Average Daily Bank Balances | D41: =+'12'!H26 -> 8420858 | E41: WP/II-B-9/12
A42: =A41+1 -> 32 | B42: Working Funds and Other | D42: ='13'!C16 -> -8308312 | E42: WP/II-B-9/13
...

Sheet 1
A1: 2022 RATE CASE
A2: =' '!A2 -> ONCOR ELECTRIC DELIVERY COMPANY LLC
A3: OVERALL REVENUE LAG
A4: FOR THE LEAD-LAG STUDY-PERIOD ENDING SEPTEMBER 30, 2021
A5: SPONSOR: A. THENMADATHIL
A7: Line No. | C7: Revenue Type | E7: Revenues | F7: Ref | H7: Revenue Lag Days | I7: Ref | J7: Wtd Dollar Days
C8: (a) | E8: (b) | F8: (c) | H8: (d) | I8: (e) | J8: (f)
A10: 1 | C10: CC&B | E10: 3.7554495e+09 | F10: (1) | H10: =+'1-1'!E20 -> 52.738161 | I10: WP/II-B-9/1-1 | J10: =H10*E10 -> 1.980555e+11
A11: 2
A12: 3 | C12: FIM | E12: 5.5022935e+08 | F12: (2) | H12: =+'1-1'!H20 -> 54.040667 | I12: WP/II-B-9/1-1 | J12: =+H12*E12 -> 2.9734761e+10
A13: 4
A14: 5 | C14: Total | E14: =SUM(E10:E12) -> 4.3056788e+09 | H14: =ROUND(J14/E14,2) -> 52.9 | J14: =SUM(J10:J12) -> 2.2779026e+11
A15: 6
A16: 7 | C16: Sources: | D16: (1) | E16: CC&B Revenue.xlsx
A17: 8 | D17: (2) | E17: FIM Revenue.xlsx

Sheet 1-1
A1: 2022 RATE CASE
A2: =' '!A2 -> ONCOR ELECTRIC DELIVERY COMPANY LLC
A3: REVENUE LAG BY REVENUE TYPE
A4: FOR THE LEAD-LAG STUDY-PERIOD ENDING SEPTEMBER 30, 2021
A5: SPONSOR: A. THENMADATHIL
A7: Line No. | C7: Description | E7: CC&B | F7: Reference | H7: FIM | I7: Reference
C8: (a) | E8: (b) | F8: (c) | H8: (d) | I8: (e)
A10: 1 | C10: Average service period
A11: =A10+1 -> 2 | C11: (365.25 days/12 months)/2 | E11: =ROUND(365.25/12/2,3) -> 15.219 | H11: =ROUND(365.25/12/2,3) -> 15.219
A12: =A11+1 -> 3
A13: =A12+1 -> 4 | C13: Billing Process Lag | E13: =+'1-1-2'!D20 -> 2.8031609 | F13: WP/II-B-9/1-1-2 | H13: =+'1-1-2'!D20 -> 2.8031609 | I13: WP/II-B-9/1-1-2
A14: =A13+1 -> 5
A15: =A14+1 -> 6 | C15: Collection Lag | E15: =+'1-1-3'!E14 -> 34.716 | F15: WP/II-B-9/1-1-3 | H15: 36.018506 | I15: (1)
A16: =A15+1 -> 7
A17: =A16+1 -> 8 | C17: Receipt of funds lag | E17: 0 | H17: 0
A18: =A17+1 -> 9
A19: =A18+1 -> 10
A20: =A19+1 -> 11 | C20: Operating Revenues Lag Days | E20: =SUM(E11:E18) -> 52.738161 | H20: =SUM(H11:H18) -> 54.040667
A21: =A20+1 -> 12
A22: =A21+1 -> 13 | C22: Source: | D22: (1) | E22: FIM Revenue.xlsx

Sheet 1-1-2
A1: 2022 RATE CASE
A2: =' '!A2 -> ONCOR ELECTRIC DELIVERY COMPANY LLC
A3: BILLING LAG
A4: FOR THE LEAD-LAG STUDY-PERIOD ENDING SEPTEMBER 30, 2021
A5: SPONSOR: A. THENMADATHIL
A7: Line No. | B7: Description | C7: Hours | D7: Days | E7: Reference
B8: (a) | C8: (b) | D8: (c) | E8: (d)
A10: 1 | B10: Period from Meter Reading Date to Invoice Date:
A11: =+A10+1 -> 2
A12: =+A11+1 -> 3 | B12: Calculated from invoice sample | D12: =+'1-1-2-1'!I128 -> 2.0948276 | E12: WP/II-B-9/1-1-2-1
A13: =+A12+1 -> 4
A14: =+A13+1 -> 5
A15: =+A14+1 -> 6 | B15: Invoicing Period
A16: =+A15+1 -> 7
A17: =+A16+1 -> 8 | B17: Start at midnight and end at 5 p.m. | C17: 17 | D17: =+C17/24 -> 0.70833333
A18: =+A17+1 -> 9
A19: =+A18+1 -> 10
A20: =+A19+1 -> 11 | B20: Total Billing Lag Days | D20: =SUM(D10:D17) -> 2.8031609

Sheet 1-1-2-1
A1: 2022 RATE CASE
A2: =' '!A2 -> ONCOR ELECTRIC DELIVERY COMPANY LLC
A3: REVENUE LAG - CALCULATION OF LAG DAYS FROM METER READ TO INVOICE (INVOICE SAMPLE RESULTS)
A4: FOR THE LEAD-LAG STUDY-PERIOD ENDING SEPTEMBER 30, 2021
A5: SPONSOR: A. THENMADATHIL
A7: Line No. | C7: Invoice Number | E7: Meter Read Date | F7: Meter Read Day of Week | G7: Invoice Date | I7: Lag Days from Meter Read to Invoice
C8: (a) | E8: (b) | F8: (c) | G8: (d) | I8: (e)
A10: 1 | C10: 8100077074126595973Z11 | E10: 44107 | F10: SATURDAY | G10: 44109 | I10: =+G10-E10 -> 2
A11: =A10+1 -> 2 | C11: 8100049185045251330Z10 | E11: 44243 | F11: TUESDAY | G11: 44244 | I11: =+G11-E11 -> 1
A12: =A11+1 -> 3 | C12: 8100024388456009046Z12 | E12: 44185 | F12: SUNDAY | G12: 44186 | I12: =+G12-E12 -> 1
A13: =A12+1 -> 4 | C13: 8100085552562066843Z11 | E13: 44422 | F13: SATURDAY | G13: 44424 | I13: =+G13-E13 -> 2
A14: =A13+1 -> 5 | C14: 8100067654692395487Z05 | E14: 44244 | F14: WEDNESDAY | G14: 44245 | I14: =+G14-E14 -> 1
A15: =A14+1 -> 6 | C15: 8100071883947499761Z10 | E15: 44431 | F15: MONDAY | G15: 44432 | I15: =+G15-E15 -> 1
A16: =A15+1 -> 7 | C16: 8100011182484050189Z11 | E16: 44195 | F16: WEDNESDAY | G16: 44196 | I16: =+G16-E16 -> 1
A17: =A16+1 -> 8 | C17: 8100071193269760821Z10 | E17: 44396 | F17: MONDAY | G17: 44411 | I17: =+G17-E17 -> 15
A18: =A17+1 -> 9 | C18: 8100099838838429441Z05 | E18: 44421 | F18: FRIDAY | G18: 44424 | I18: =+G18-E18 -> 3
A19: =A18+1 -> 10 | C19: 8100042975703997060Z11 | E19: 44362 | F19: TUESDAY | G19: 44363 | I19: =+G19-E19 -> 1
A20: =A19+1 -> 11 | C20: 8100521646481945548Z11 | E20: 44243 | F20: TUESDAY | G20: 44252 | I20: =+G20-E20 -> 9
A21: =A20+1 -> 12 | C21: 8100078797199145876Z11 | E21: 44216 | F21: WEDNESDAY | G21: 44217 | I21: =+G21-E21 -> 1
A22: =A21+1 -> 13 | C22: 8100094467212000969Z11 | E22: 44443 | F22: SATURDAY | G22: 44446 | I22: =+G22-E22 -> 3
... A62: =A61+1 -> 53 | C62: 8100071719156021454Z10 | E62: 44426 | F62: WEDNESDAY | G62: 44427 | I62: =+G62-E62 -> 1
A63: 54 | C63: 8100010879393209558Z07 | E63: 44134 | F63: FRIDAY | G63: 44137 | I63: =+G63-E63 -> 3
A64: =A63+1 -> 55 | C64: 8100079087361026687Z11 | E64: 44405 | F64: WEDNESDAY | G64: 44407 | I64: =+G64-E64 -> 2
A65: =A64+1 -> 56 | C65: 8100077663497250430Z10 | E65: 44285 | F65: TUESDAY | G65: 44286 | I65: =+G65-E65 -> 1
A66: =A65+1 -> 57 | C66: 8100080521212495869Z05 | E66: 44250 | F66: TUESDAY | G66: 44251 | I66: =+G66-E66 -> 1
A67: =A66+1 -> 58 | C67: 8100039073011168055Z11 | E67: 44191 | F67: SATURDAY | G67: 44193 | I67: =+G67-E67 -> 2
A68: =A67+1 -> 59 | C68: 8100069329120748832Z10 | E68: 44420 | F68: THURSDAY | G68: 44421 | I68: =+G68-E68 -> 1
A69: =A68+1 -> 60 | C69: 8100048926514972078Z10 | E69: 44242 | F69: MONDAY | G69: 44243 | I69: =+G69-E69 -> 1
A70: =A69+1 -> 61 | C70: 8100037853653739443Z10 | E70: 44293 | F70: WEDNESDAY | G70: 44294 | I70: =+G70-E70 -> 1
A71: =A70+1 -> 62 | C71: 8100080456219611987Z10 | E71: 44242 | F71: MONDAY | G71: 44243 | I71: =+G71-E71 -> 1
A72: =A71+1 -> 63 | C72: 8100022594781329054Z10 | E72: 44317 | F72: SATURDAY | G72: 44319 | I72: =+G72-E72 -> 2
A73: =A72+1 -> 64 | C73: 8100049508108927390Z11 | E73: 44124 | F73: TUESDAY | G73: 44125 | I73: =+G73-E73 -> 1
A74: =A73+1 -> 65 | C74: 8100088592851062141Z11 | E74: 44226 | F74: SATURDAY | G74: 44228 | I74: =+G74-E74 -> 2
A75: =A74+1 -> 66 | C75: 8100055474539217486Z12 | E75: 44185 | F75: SUNDAY | G75: 44186 | I75: =+G75-E75 -> 1
... A90: =A89+1 -> 81 | C90: 8100081338536924045Z10 | E90: 44242 | F90: MONDAY | G90: 44243 | I90: =+G90-E90 -> 1
A91: 82 | C91: 8100079304813040531Z12 | E91: 44172 | F91: MONDAY | G91: 44173 | I91: =+G91-E91 -> 1
A92: =A91+1 -> 83 | C92: 8100011314505525524Z13 | E92: 44214 | F92: MONDAY | G92: 44215 | I92: =+G92-E92 -> 1
A93: =A92+1 -> 84 | C93: 8100085602856111852Z13 | E93: 44163 | F93: SATURDAY | G93: 44165 | I93: =+G93-E93 -> 2
A94: =A93+1 -> 85 | C94: 8100059242118099064Z12 | E94: 44355 | F94: TUESDAY | G94: 44356 | I94: =+G94-E94 -> 1
A95: =A94+1 -> 86 | C95: 8100083710538997582Z11 | E95: 44114 | F95: SATURDAY | G95: 44116 | I95: =+G95-E95 -> 2
...

Sheet 1-1-3
A1: 2022 RATE CASE
A2: =' '!A2 -> ONCOR ELECTRIC DELIVERY COMPANY LLC
A3: CALCULATION OF COLLECTION LAG
A4: FOR THE LEAD-LAG STUDY-PERIOD ENDING SEPTEMBER 30, 2021
A5: SPONSOR: A. THENMADATHIL
A7: Line
A8: No. | B8: Description | C8: Reference | D8: Amount | E8: Collection Lag Days
B9: (a) | C9: (b) | D9: (c) | E9: (d)
A11: 1 | B11: Total Accounts Receivable | C11: WP/II-B-9/1-1-3-1 | D11: =+'1-1-3-1'!D25 -> 1.3037315e+11
A12: 2 | B12: Revenues | C12: CC&B Revenue.xlsx | D12: 3.7554495e+09
A13: 3
A14: 4 | B14: Collection Lag (Line 1/Line 2) | E14: =ROUND(D11/D12,3) -> 34.716

Sheet 1-1-3-1
A1: 2022 RATE CASE
A2: =' '!A2 -> ONCOR ELECTRIC DELIVERY COMPANY LLC
A3: COLLECTION LAG
A4: FOR THE LEAD-LAG STUDY-PERIOD ENDING SEPTEMBER 30, 2021
A5: SPONSOR: A. THENMADATHIL
A7: Line
A8: No. | B8: Description | D8: Monthly Total
B9: (a) | D9: (b)
A11: 1 | B11: Sum of CC&B Daily A/R Balances
A12: 2 | B12: 44105 | D12: =+'1-1-3-1-1'!C41 -> 1.1762378e+10
A13: 3 | B13: 44136 | D13: =+'1-1-3-1-1'!E41 -> 9.8038933e+09
A14: 4 | B14: 44166 | D14: =+'1-1-3-1-1'!G41 -> 1.010434e+10
A15: 5 | B15: 44197 | D15: =+'1-1-3-1-1'!C76 -> 1.0516028e+10
A16: 6 | B16: 44228 | D16: =+'1-1-3-1-1'!E76 -> 1.0707084e+10
A17: 7 | B17: 44256 | D17: =+'1-1-3-1-1'!G76 -> 1.1923043e+10
A18: 8 | B18: 44287 | D18: =+'1-1-3-1-1'!C111 -> 9.9091148e+09
A19: 9 | B19: 44317 | D19: =+'1-1-3-1-1'!E111 -> 9.1357107e+09
A20: 10 | B20: 44348 | D20: =+'1-1-3-1-1'!G111 -> 9.5189259e+09
A21: 11 | B21: 44378 | D21: =+'1-1-3-1-1'!C146 -> 1.1350904e+10
A22: 12 | B22: 44409 | D22: =+'1-1-3-1-1'!E146 -> 1.3010918e+10
A23: 13 | B23: 44440 | D23: =+'1-1-3-1-1'!G146 -> 1.2630809e+10
A24: 14
A25: 15 | B25: Total Accounts Receivable | D25: =SUM(D12:D24) -> 1.3037315e+11
A26: 16
A27: 17 | B27: Source: WP/II-B-9/1-1-3-1-1

Sheet 1-1-3-1-1
A1: 2022 RATE CASE
A2: ='1'!A2 -> ONCOR ELECTRIC DELIVERY COMPANY LLC
A3: CUSTOMER INFORMATION SYSTEM DAILY ACCOUNTS RECEIVABLE
A4: FOR THE LEAD-LAG STUDY-PERIOD ENDING SEPTEMBER 30, 2021
A5: SPONSOR: A. THENMADATHIL
A7: Line No. | B7: Date | C7: A/R Balance | D7: Date | E7: A/R Balance | F7: Date | G7: A/R Balance
B8: (a) | C8: (b) | D8: (c) | E8: (d) | F8: (e) | G8: (f)
A10: 1 | B10: 44105 | C10: 4.1649087e+08 | D10: =+B40+1 -> 44136 | E10: 3.4840699e+08 | F10: =+D39+1 -> 44166 | G10: 3.1293526e+08
A11: =A10+1 -> 2 | B11: =+B10+1 -> 44106 | C11: 4.1246377e+08 | D11: =+D10+1 -> 44137 | E11: 3.2906713e+08 | F11: =+F10+1 -> 44167 | G11: 3.1699304e+08
A12: =A11+1 -> 3 | B12: =+B11+1 -> 44107 | C12: 4.1246377e+08 | D12: =+D11+1 -> 44138 | E12: 3.3200559e+08 | F12: =+F11+1 -> 44168 | G12: 3.2113828e+08
A13: =A12+1 -> 4 | B13: =+B12+1 -> 44108 | C13: 4.1246377e+08 | D13: =+D12+1 -> 44139 | E13: 3.3284994e+08 | F13: =+F12+1 -> 44169 | G13: 3.1177795e+08
A14: =A13+1 -> 5 | B14: =+B13+1 -> 44109 | C14: 4.0147216e+08 | D14: =+D13+1 -> 44140 | E14: 3.3480366e+08 | F14: =+F13+1 -> 44170 | G14: 3.2506549e+08
A15: =A14+1 -> 6 | B15: =+B14+1 -> 44110 | C15: 4.0108729e+08 | D15: =+D14+1 -> 44141 | E15: 3.2862643e+08 | F15: =+F14+1 -> 44171 | G15: 3.2506549e+08
A16: =A15+1 -> 7 | B16: =+B15+1 -> 44111 | C16: 3.9959011e+08 | D16: =+D15+1 -> 44142 | E16: 3.2862643e+08 | F16: =+F15+1 -> 44172 | G16: 3.2865297e+08
A17: =A16+1 -> 8 | B17: =+B16+1 -> 44112 | C17: 3.9862667e+08 | D17: =+D16+1 -> 44143 | E17: 3.2862643e+08 | F17: =+F16+1 -> 44173 | G17: 3.2771174e+08
A18: =A17+1 -> 9 | B18: =+B17+1 -> 44113 | C18: 3.9106316e+08 | D18: =+D17+1 -> 44144 | E18: 3.2385078e+08 | F18: =+F17+1 -> 44174 | G18: 3.2842422e+08
A19: =A18+1 -> 10 | B19: =+B18+1 -> 44114 | C19: 3.9106316e+08 | D19: =+D18+1 -> 44145 | E19: 3.2380616e+08 | F19: =+F18+1 -> 44175 | G19: 3.2896895e+08
A20: =A19+1 -> 11 | B20: =+B19+1 -> 44115 | C20: 3.9106316e+08 | D20: =+D19+1 -> 44146 | E20: 3.3498921e+08 | F20: =+F19+1 -> 44176 | G20: 3.2503676e+08
A21: =A20+1 -> 12 | B21: =+B20+1 -> 44116 | C21: 4.0165998e+08 | D21: =+D20+1 -> 44147 | E21: 3.2235445e+08 | F21: =+F20+1 -> 44177 | G21: 3.2503676e+08
A22: =A21+1 -> 13 | B22: =+B21+1 -> 44117 | C22: 3.9088685e+08 | D22: =+D21+1 -> 44148 | E22: 3.209638e+08 | F22: =+F21+1 -> 44178 | G22: 3.2503676e+08
... A39: =A38+1 -> 30 | B39: =+B38+1 -> 44134 | C39: 3.4840699e+08 | D39: =+D38+1 -> 44165 | E39: 3.0534855e+08 | F39: =+F38+1 -> 44195 | G39: 3.1617165e+08
A40: =A39+1 -> 31 | B40: =+B39+1 -> 44135 | C40: 3.4840699e+08 | F40: =+F39+1 -> 44196 | G40: 3.2004974e+08
A41: =A40+1 -> 32 | C41: =SUM(C10:C40) -> 1.1762378e+10 | E41: =SUM(E10:E40) -> 9.8038933e+09 | G41: =SUM(G10:G40) -> 1.010434e+10
A42: Line No. | B42: Date | C42: A/R Balance | D42: Date | E42: A/R Balance | F42: Date | G42: A/R Balance
B43: (a) | C43: (b) | D43: (c) | E43: (d) | F43: (e) | G43: (f)
A45: =A41+1 -> 33 | B45: =+F40+1 -> 44197 | C45: 320049742 | D45: =+B75+1 -> 44228 | E45: 3.7003812e+08 | F45: =+D73+1 -> 44257 | G45: 3.731075e+08
A46: =A45+1 -> 34 | B46: =+B45+1 -> 44198 | C46: 320049742 | D46: =+D45+1 -> 44229 | E46: 3.7396466e+08 | F46: =+F45+1 -> 44258 | G46: 3.7696053e+08
A47: =A46+1 -> 35 | B47: =+B46+1 -> 44199 | C47: 320049742 | D47: =+D46+1 -> 44230 | E47: 3.7595983e+08 | F47: =+F46+1 -> 44259 | G47: 3.799082e+08
A48: =A47+1 -> 36 | B48: =+B47+1 -> 44200 | C48: 3.2569394e+08 | D48: =+D47+1 -> 44231 | E48: 3.8082559e+08 | F48: =+F47+1 -> 44260 | G48: 3.8075685e+08
A49: =A48+1 -> 37 | B49: =+B48+1 -> 44201 | C49: 3.2660685e+08 | D49: =+D48+1 -> 44232 | E49: 3.7990342e+08 | F49: =+F48+1 -> 44261 | G49: 3.8075685e+08
A50: =A49+1 -> 38 | B50: =+B49+1 -> 44202 | C50: 3.2700189e+08 | D50: =+D49+1 -> 44233 | E50: 3.7990342e+08 | F50: =+F49+1 -> 44262 | G50: 3.8075685e+08
A51: =A50+1 -> 39 | B51: =+B50+1 -> 44203 | C51: 3.3193079e+08 | D51: =+D50+1 -> 44234 | E51: 3.7990342e+08 | F51: =+F50+1 -> 44263 | G51: 3.7944955e+08
A52: =A51+1 -> 40 | B52: =+B51+1 -> 44204 | C52: 3.3111653e+08 | D52: =+D51+1 -> 44235 | E52: 3.818177e+08 | F52: =+F51+1 -> 44264 | G52: 3.8132351e+08
A53: =A52+1 -> 41 | B53: =+B52+1 -> 44205 | C53: 3.4582489e+08 | D53: =+D52+1 -> 44236 | E53: 3.7755817e+08 | F53: =+F52+1 -> 44265 | G53: 3.8269876e+08
A54: =A53+1 -> 42 | B54: =+B53+1 -> 44206 | C54: 3.4582489e+08 | D54: =+D53+1 -> 44237 | E54: 3.7212725e+08 | F54: =+F53+1 -> 44266 | G54: 3.8527124e+08
A55: =A54+1 -> 43 | B55: =+B54+1 -> 44207 | C55: 3.3279804e+08 | D55: =+D54+1 -> 44238 | E55: 3.7272351e+08 | F55: =+F54+1 -> 44267 | G55: 3.8340464e+08
A56: =A55+1 -> 44 | B56: =+B55+1 -> 44208 | C56: 3.3530803e+08 | D56: =+D55+1 -> 44239 | E56: 3.6696474e+08 | F56: =+F55+1 -> 44268 | G56: 3.8340464e+08
A57: =A56+1 -> 45 | B57: =+B56+1 -> 44209 | C57: 3.3976575e+08 | D57: =+D56+1 -> 44240 | E57: 3.6696474e+08 | F57: =+F56+1 -> 44269 | G57: 3.8340464e+08
... A73: =A72+1 -> 61 | B73: =+B72+1 -> 44225 | C73: 3.6272682e+08 | D73: =+D72+1 -> 44256 | E73: 3.7163397e+08 | F73: =+F72+1 -> 44285 | G73: 3.8563942e+08
A74: =A73+1 -> 62 | B74: =+B73+1 -> 44226 | C74: 3.6272682e+08 | E74: 0 | F74: =+F73+1 -> 44286 | G74: 3.8193918e+08
...

Sheet 2
A1: 2022 RATE CASE
A2: =' '!A2 -> ONCOR ELECTRIC DELIVERY COMPANY LLC
A3: LABOR - PAYROLL LEAD DAYS
A4: FOR THE LEAD-LAG STUDY-PERIOD ENDING SEPTEMBER 30, 2021
A5: SPONSOR: A. THENMADATHIL
A7: Line No. | B7: Payroll Type | C7: Payroll Expense | D7: Percent | E7: Reference | F7: (Lead)/Lag | G7: Reference | H7: Check Float | I7: Reference | J7: Total (Lead)/Lag | K7: Weighted Dollar Days
B8: (a) | C8: (b) | D8: (c) | E8: (d) | F8: (e) | G8: (f) | H8: (g) | I8: (h) | J8: (i) | K8: (j)
A10: 1 | B10: Bi-Weekly
A11: 2
A12: 3 | B12: Direct Deposit | C12: =+C15*D12 -> 46520803 | D12: =D21 -> 0.9977 | E12: WP/II-B-9/2-1 | F12: =-'2-2'!C25 -> -11.96 | G12: WP/II-B-9/2-2 | H12: =H21 -> 0 | J12: =F12+H12 -> -11.96 | K12: =C12*J12 -> -5.563888e+08
A13: 4 | B13: Manual | C13: =C15-C12 -> 107244.51 | D13: =D22 -> 0.0023 | E13: WP/II-B-9/2-1 | F13: =F12 -> -11.96 | G13: WP/II-B-9/2-2 | H13: =H22 -> -7.27 | I13: WP/II-B-9/2-4 | J13: =F13+H13 -> -19.23 | K13: =C13*J13 -> -2062311.9
A14: 5
A15: 6 | B15: Total Bi-Weekly Pay | C15: =+D15*C35 -> 46628048 | D15: =+'2-6'!E11 -> 0.1713 | E15: WP/II-B-9/2-6 | J15: =K15/C15 -> -11.976721 | K15: =SUM(K12:K13) -> -5.5845112e+08
A16: 7
A17: 8 | B17: Semi-Monthly
A18: 9
A19: 10 | B19: 1st Pay Period:
A20: 11
A21: 12 | B21: Direct Deposit | C21: =+C24*D21 -> 1.1176193e+08 | D21: =+'2-1'!F18 -> 0.9977 | E21: WP/II-B-9/2-1 | F21: =+'2-3'!C57 -> -12.08 | G21: WP/II-B-9/2-3 | H21: 0 | J21: =F21+H21 -> -12.08 | K21: =C21*J21 -> -1.3500841e+09
A22: 13 | B22: Manual | C22: =C24-C21 -> 257645.02 | D22: =+'2-1'!G18 -> 0.0023 | E22: WP/II-B-9/2-1 | F22: =+'2-3'!C57 -> -12.08 | G22: WP/II-B-9/2-3 | H22: ='2-4'!D14 -> -7.27 | I22: WP/II-B-9/2-4 | J22: =F22+H22 -> -19.35 | K22: =C22*J22 -> -4985431.2
A23: 14
A24: 15 | B24: Total 1st Pay Period | C24: =+C33*D24 -> 1.1201958e+08 | D24: ='2-5'!C31 -> 0.4966 | E24: WP/II-B-9/2-5 | J24: =K24/C24 -> -12.096721 | K24: =SUM(K21:K22) -> -1.3550695e+09
A25: 16
A26: 17 | B26: 2nd Pay Period:
A27: 18
A28: 19 | B28: Direct Deposit | C28: =+C31*D28 -> 1.132923e+08 | D28: =+'2-1'!F18 -> 0.9977 | E28: WP/II-B-9/2-1 | F28: =+'2-3'!C58 -> -12.17 | G28: WP/II-B-9/2-3 | H28: 0 | J28: =F28+H28 -> -12.17 | K28: =C28*J28 -> -1.3787673e+09
A29: 20 | B29: Manual | C29: =C31-C28 -> 261172.99 | D29: =+'2-1'!G18 -> 0.0023 | E29: WP/II-B-9/2-1 | F29: =+'2-3'!C58 -> -12.17 | G29: WP/II-B-9/2-3 | H29: =+H22 -> -7.27 | I29: WP/II-B-9/2-4 | J29: =F29+H29 -> -19.44 | K29: =C29*J29 -> -5077202.8
A30: 21
A31: 22 | B31: Total 2nd Pay Period | C31: =+D31*C33 -> 1.1355347e+08 | D31: ='2-5'!D31 -> 0.5034 | E31: WP/II-B-9/2-5 | J31: =K31/C31 -> -12.186721 | K31: =SUM(K28:K29)-1 -> -1.3838445e+09
A32: 23
A33: 24 | B33: Total Semi-Monthly | C33: =+C35*D33 -> 2.2557305e+08 | D33: =+'2-6'!F11 -> 0.8287 | E33: WP/II-B-9/2-6 | J33: =K33/C33 -> -12.142027 | K33: =K31+K24+1 -> -2.738914e+09
A34: 25
A35: 26 | B35: Total | C35: 2.7220109e+08 | D35: =+D33+D15 -> 1 | E35: Schedule II-D-3 * | F35: =ROUND(((C15*F12)+(C24*F21)+(C31*F28))/C35,2) -> -12.1 | J35: =ROUND(K35/C35,2) -> -12.11 | K35: =K33+K15 -> -3.2973651e+09
A36: 27 | E36: *Net of Incentive Pay

Sheet 2-1
A1: 2022 RATE CASE
A2: =' '!A2 -> ONCOR ELECTRIC DELIVERY COMPANY LLC
A3: PAYROLL LEAD - DIRECT DEPOSIT CALCULATION
A4: FOR THE LEAD-LAG STUDY-PERIOD ENDING SEPTEMBER 30, 2021
A5: SPONSOR: A. THENMADATHIL
A7: Line No. | B7: Period/Business Unit | C7: Direct Deposit | D7: Manual Checks | E7: Total - Direct Deposit and Manual Checks | F7: Percent Paid via Direct Deposit | G7: Percent Paid via Manual Check
B8: (a) | C8: (b) | D8: (c) | E8: (d) | F8: (e) | G8: (f)
A10: 1 | B10: 44105
A11: =A10+1 -> 2 | B11: Transmission | C11: 7333759.5 | D11: 13002.55 | E11: =+C11+D11 -> 7346762.1
A12: =A11+1 -> 3 | B12: Distribution | C12: 19176623 | D12: 58444.75 | E12: =+C12+D12 -> 19235068
A13: =A12+1 -> 4
A14: =A13+1 -> 5 | B14: 44440
A15: =A14+1 -> 6 | B15: Transmission | C15: 6931833 | D15: 0 | E15: =+C15+D15 -> 6931833
A16: =A15+1 -> 7 | B16: Distribution | C16: 20093523 | D16: 52184.22 | E16: =+C16+D16 -> 20145707
A17: =A16+1 -> 8
A18: =A17+1 -> 9 | B18: Total Payments | C18: =SUM(C10:C16) -> 53535739 | D18: =SUM(D10:D16) -> 123631.52 | E18: =SUM(E10:E16) -> 53659370 | F18: =+ROUND(C18/$E$18,4) -> 0.9977 | G18: =+ROUND(D18/$E$18,4) -> 0.0023
A19: =A18+1 -> 10
A20: =A19+1 -> 11 | F20: (1) | G20: (2)
A21: =A20+1 -> 12 | B21: Note:
A22: =A21+1 -> 13 | B22: (1) The calculation is Col (b) Ln 9 divided by Col (d) Ln 9.
A23: =A22+1 -> 14 | B23: (2) The calculation is Col (c) Ln 9 divided by Col (d) Ln 9.
A24: =A23+1 -> 15
A25: =A24+1 -> 16 | B25: Source: | C25: Payroll direct deposit.xlsx

Sheet 2-2
A1: 2022 RATE CASE
A2: =' '!A2 -> ONCOR ELECTRIC DELIVERY COMPANY LLC
A3: PAYROLL LEAD - BI-WEEKLY PAYROLL CALCULATION
A4: FOR THE LEAD-LAG STUDY-PERIOD ENDING SEPTEMBER 30, 2021
A5: SPONSOR: A. THENMADATHIL
A7: Line No. | B7: Bi-Weekly | C7: Days
B8: (a) | C8: (b)
A10: 1 | B10: Conditions:
A11: 2
A12: 3 | B12: Pay Periods cover 14 days.
A13: 4 | B13: Start on Monday and end on the second following Sunday.
A14: 5 | B14: Payment Checks or Direct Deposits typically are made on Friday, five days after end of pay period.
A15: 6 | B15: (If the scheduled pay date is a holiday, payment is made on the preceding work day. During
A16: 7 | B16: the test period, with the exception of one instance, all paydays fell on the regularly scheduled Friday.)
A17: 8
A18: 9
A19: 10 | B19: Days in Period:
A20: 11
A21: 12 | B21: 14 days. Midpoint = 7
A22: 13
A23: 14 | B23: Payroll Lead Formula:
A24: 15
A25: 16 | B25: (7 days) + (4.96 days) = | C25: =7+4.96 -> 11.96
A27: Sources: | B27: Holidays.xlsx
B28: Bi-Weekly Payroll Calendar 2021.xlsx
B29: Bi-Weekly Payroll Calendar 2020.xlsx

Sheet 2-2-1
A1: 2022 RATE CASE
A2: =' '!A2 -> ONCOR ELECTRIC DELIVERY COMPANY LLC
A3: PAYROLL LEAD - HOLIDAY/WEEKEND FACTOR CALCULATION - BI-WEEKLY
A4: FOR THE LEAD-LAG STUDY-PERIOD ENDING SEPTEMBER 30, 2021
A5: SPONSOR: A. THENMADATHIL
A8: Line No. | B8: Scheduled Payday | C8: Normal Payment Lead Days | E8: Lead Days Reflecting Holiday Adjustments | G8: Total
B9: (a) | C9: (b) | E9: (c) | G9: (d)
A11: 1 | B11: 44113 | C11: 5 | G11: =C11+E11 -> 5
A12: 2 | B12: 44127 | C12: 5 | G12: =C12+E12 -> 5
A13: 3 | B13: 44141 | C13: 5 | G13: =C13+E13 -> 5
A14: 4 | B14: 44155 | C14: 5 | G14: =C14+E14 -> 5
A15: 5 | B15: 44169 | C15: 5 | G15: =C15+E15 -> 5
A16: 6 | B16: 44183 | C16: 5 | E16: 0 | G16: =C16+E16 -> 5
A17: 7 | B17: 44196 | C17: 0 | E17: 4 | G17: =C17+E17 -> 4
A18: 8 | B18: 44211 | C18: 5 | G18: =C18+E18 -> 5
A19: 9 | B19: 44225 | C19: 5 | G19: =C19+E19 -> 5
A20: 10 | B20: 44239 | C20: 5 | G20: =C20+E20 -> 5
A21: 11 | B21: 44253 | C21: 5 | G21: =C21+E21 -> 5
A22: 12 | B22: 44267 | C22: 5 | G22: =C22+E22 -> 5
A23: 13 | B23: 44281 | C23: 5 | G23: =C23+E23 -> 5
A24: 14 | B24: 44295 | C24: 5 | G24: =C24+E24 -> 5
A25: 15 | B25: 44309 | C25: 5 | G25: =C25+E25 -> 5
A26: =+A25+1 -> 16 | B26: 44323 | C26: 5 | G26: =C26+E26 -> 5
A27: =+A26+1 -> 17 | B27: 44337 | C27: 5 | G27: =C27+E27 -> 5
A28: =+A27+1 -> 18 | B28: 44351 | C28: 5 | G28: =C28+E28 -> 5
A29: =+A28+1 -> 19 | B29: 44365 | C29: 5 | G29: =C29+E29 -> 5
A30: =+A29+1 -> 20 | B30: 44379 | C30: 5 | E30: 0 | G30: =C30+E30 -> 5
A31: =+A30+1 -> 21 | B31: 44393 | C31: 5 | G31: =C31+E31 -> 5
A32: =+A31+1 -> 22 | B32: 44407 | C32: 5 | G32: =C32+E32 -> 5
A33: =+A32+1 -> 23 | B33: 44421 | C33: 5 | G33: =C33+E33 -> 5
A34: =+A33+1 -> 24 | B34: 44435 | C34: 5 | G34: =C34+E34 -> 5
A35: =+A34+1 -> 25 | B35: 44449 | C35: 5 | E35: 0 | G35: =C35+E35 -> 5
A36: =+A35+1 -> 26 | B36: 44463 | C36: 5 | G36: =C36+E36 -> 5
A37: =+A36+1 -> 27 | B37: Total Days | C37: =SUM(C11:C36) -> 125 | E37: =SUM(E11:E36) -> 4 | G37: =SUM(G11:G36) -> 129
A38: =+A37+1 -> 28
A39: =+A38+1 -> 29
A40: =+A39+1 -> 30 | B40: Number of Annual Payroll Cycles | G40: =SUM(A36) -> 26
A41: =+A40+1 -> 31 | B41: Average of Lead Days Before Payment | G41: =ROUND(G37/G40,2) -> 4.96
A42: =+A41+1 -> 32
A43: =+A42+1 -> 33
...

Sheet 2-3
A1: 2022 RATE CASE
A2: =' '!A2 -> ONCOR ELECTRIC DELIVERY COMPANY LLC
A3: PAYROLL LEAD - SEMI-MONTHLY PAYROLL CALCULATION
A4: FOR THE LEAD-LAG STUDY-PERIOD ENDING SEPTEMBER 30, 2021
A5: SPONSOR: A. THENMADATHIL
A7: Line No. | B7: Semi-Monthly
B8: (a) | C8: (b) | D8: (c) | E8: (d)
A10: 1 | B10: Assumptions:
A11: 2
A12: 3 | B12: First Pay Period | C12: 26th - 10th
A13: 4 | B13: Second Pay Period | C13: 11th - 25th
A14: 5
A15: 6
A16: 7 | B16: Days in Period:
A17: 8
A18: 9 | B18: Average Days in Month | C18: =ROUND(366/12,3) -> 30.5 | D18: Days of Year divided by 12 months
A19: 10
A20: 11 | B20: First Pay Period | C20: =C18-C21 -> 15.5 | D20: Col (b) Ln 9 minus Col (b) Ln 12
A21: 12 | B21: Second Pay Period | C21: 15
A22: 13 | B22: Average First Pay Period | C22: =ROUND(+C20/2,3) -> 7.75 | D22: Col (b) Ln 11 divided by 2
A23: 14 | B23: Average Second Pay Period | C23: =ROUND(+C21/2,3) -> 7.5 | D23: Col (b) Ln 12 divided by 2
A24: 15
A25: 16
A26: 17 | B26: Days Until Payment:
A27: 18
A28: 19 | B28: First Pay Period | C28: 5 | D28: End on 10th, Paid on 15th
A29: 20 | B29: Second Pay Period | C29: =E47 -> 5.42 | D29: Col (d) Ln 38
A30: 21 | C30: Days of Month | E30: Difference
A31: 22 | B31: 44105 | C31: 31 | D31: 25 | E31: =C31-D31 -> 6
A32: 23 | B32: 44136 | C32: 30 | D32: 25 | E32: =C32-D32 -> 5
A33: 24 | B33: 44166 | C33: 31 | D33: 25 | E33: =C33-D33 -> 6
A34: =A33+1 -> 25 | B34: 44197 | C34: 31 | D34: 25 | E34: =C34-D34 -> 6
A35: =A34+1 -> 26 | B35: 44228 | C35: 28 | D35: 25 | E35: =C35-D35 -> 3
A36: =A35+1 -> 27 | B36: 44256 | C36: 31 | D36: 25 | E36: =C36-D36 -> 6
A37: =A36+1 -> 28 | B37: 44287 | C37: 30 | D37: 25 | E37: =C37-D37 -> 5
A38: =A37+1 -> 29 | B38: 44317 | C38: 31 | D38: 25 | E38: =C38-D38 -> 6
A39: =A38+1 -> 30 | B39: 44348 | C39: 30 | D39: 25 | E39: =C39-D39 -> 5
A40: =A39+1 -> 31 | B40: 44378 | C40: 31 | D40: 25 | E40: =C40-D40 -> 6
A41: =A40+1 -> 32 | B41: 44409 | C41: 31 | D41: 25 | E41: =C41-D41 -> 6
A42: =A41+1 -> 33 | B42: 44440 | C42: 30 | D42: 25 | E42: =C42-D42 -> 5
...

Sheet 2-3-1
A1: 2022 RATE CASE
A2: =' '!A2 -> ONCOR ELECTRIC DELIVERY COMPANY LLC
A3: PAYROLL LEAD - HOLIDAY/WEEKEND FACTOR CALCULATION - SEMI MONTHLY
A4: FOR THE LEAD-LAG STUDY-PERIOD ENDING SEPTEMBER 30, 2021
A5: SPONSOR: A. THENMADATHIL
C7: Days Payday Moved Up
A8: Line No. | B8: Scheduled Payday | C8: 1st Pay Period | D8: 2nd Pay Period | F8: Actual Payday | H8: Difference
B9: (a) | C9: (b) | D9: (c) | F9: (d) | H9: (e)
A11: 1 | B11: 44119 | C11: 0 | D11: 0 | F11: =+B11-C11-D11 -> 44119 | H11: =+B11-F11 -> 0
A12: 2 | B12: =+B11+16 -> 44135 | C12: 0 | D12: 1 | F12: =+B12-C12-D12 -> 44134 | H12: =+B12-F12 -> 1
A13: 3 | B13: =+B12+15 -> 44150 | C13: 2 | D13: 0 | F13: =+B13-C13-D13 -> 44148 | H13: =+B13-F13 -> 2
A14: 4 | B14: =+B13+15 -> 44165 | C14: 0 | D14: 0 | F14: =+B14-C14-D14 -> 44165 | H14: =+B14-F14 -> 0
A15: 5 | B15: =+B14+15 -> 44180 | C15: 0 | D15: 0 | F15: =+B15-C15-D15 -> 44180 | H15: =+B15-F15 -> 0
A16: 6 | B16: =+B15+16 -> 44196 | C16: 0 | D16: 0 | F16: =+B16-C16-D16 -> 44196 | H16: =+B16-F16 -> 0
A17: 7 | B17: =+B16+15 -> 44211 | C17: 0 | D17: 0 | F17: =+B17-C17-D17 -> 44211 | H17: =+B17-F17 -> 0
A18: 8 | B18: =+B17+16 -> 44227 | C18: 0 | D18: 2 | F18: =+B18-C18-D18 -> 44225 | H18: =+B18-F18 -> 2
A19: 9 | B19: =+B18+15 -> 44242 | C19: 3 | D19: 0 | F19: =+B19-C19-D19 -> 44239 | H19: =+B19-F19 -> 3
A20: 10 | B20: =+B19+13 -> 44255 | C20: 0 | D20: 2 | F20: =+B20-C20-D20 -> 44253 | H20: =+B20-F20 -> 2
A21: 11 | B21: =+B20+15 -> 44270 | C21: 0 | D21: 0 | F21: =+B21-C21-D21 -> 44270 | H21: =+B21-F21 -> 0
A22: 12 | B22: =+B21+16 -> 44286 | C22: 0 | D22: 0 | F22: =+B22-C22-D22 -> 44286 | H22: =+B22-F22 -> 0
A23: 13 | B23: =+B22+15 -> 44301 | C23: 0 | D23: 0 | F23: =+B23-C23-D23 -> 44301 | H23: =+B23-F23 -> 0
A24: 14 | B24: =+B23+15 -> 44316 | C24: 0 | D24: 0 | F24: =+B24-C24-D24 -> 44316 | H24: =+B24-F24 -> 0
A25: 15 | B25: =+B24+15 -> 44331 | C25: 1 | D25: 0 | F25: =+B25-C25-D25 -> 44330 | H25: =+B25-F25 -> 1
A26: =+A25+1 -> 16 | B26: =+B25+16 -> 44347 | C26: 0 | D26: 3 | F26: =+B26-C26-D26 -> 44344 | H26: =+B26-F26 -> 3
A27: =+A26+1 -> 17 | B27: =+B26+15 -> 44362 | C27: 0 | D27: 0 | F27: =+B27-C27-D27 -> 44362 | H27: =+B27-F27 -> 0
A28: =+A27+1 -> 18 | B28: =+B27+15 -> 44377 | C28: 0 | D28: 0 | F28: =+B28-C28-D28 -> 44377 | H28: =+B28-F28 -> 0
A29: =+A28+1 -> 19 | B29: =+B28+15 -> 44392 | C29: 0 | D29: 0 | F29: =+B29-C29-D29 -> 44392 | H29: =+B29-F29 -> 0
A30: =+A29+1 -> 20 | B30: =+B29+16 -> 44408 | C30: 0 | D30: 1 | F30: =+B30-C30-D30 -> 44407 | H30: =+B30-F30 -> 1
A31: =+A30+1 -> 21 | B31: =+B30+15 -> 44423 | C31: 2 | D31: 0 | F31: =+B31-C31-D31 -> 44421 | H31: =+B31-F31 -> 2
A32: =+A31+1 -> 22 | B32: =+B31+16 -> 44439 | C32: 0 | D32: 0 | F32: =+B32-C32-D32 -> 44439 | H32: =+B32-F32 -> 0
A33: =+A32+1 -> 23 | B33: =+B32+15 -> 44454 | C33: 0 | D33: 0 | F33: =+B33-C33-D33 -> 44454 | H33: =+B33-F33 -> 0
A34: =+A33+1 -> 24 | B34: =+B33+15 -> 44469 | C34: 0 | D34: 0 | F34: =+B34-C34-D34 -> 44469 | H34: =+B34-F34 -> 0
A35: =+A34+1 -> 25
A36: =+A35+1 -> 26 | B36: Total | C36: =SUM(C11:C35) -> 8 | D36: =SUM(D11:D35) -> 9 | H36: =SUM(H11:H35) -> 17
A37: =+A36+1 -> 27
A38: =+A37+1 -> 28 | B38: Average | C38: =ROUND(C36/12,2) -> 0.67 | D38: =ROUND(D36/12,2) -> 0.75
A39: =+A38+1 -> 29
A40: =+A39+1 -> 30 | B40: Sources: | C40: Holidays.xlsx
A41: =+A40+1 -> 31 | C41: Payroll Calendar Semi-Monthly

Sheet 2-4
A1: 2022 RATE CASE
A2: =' '!A2 -> ONCOR ELECTRIC DELIVERY COMPANY LLC
A3: PAYROLL LEAD - CHECK FLOAT CALCULATION
A4: FOR THE LEAD-LAG STUDY-PERIOD ENDING SEPTEMBER 30, 2021
A5: SPONSOR: A. THENMADATHIL
E7: Weighted
A8: Line No. | B8: Business Unit | C8: Net Amount | D8: (Lead)/Lag Days | E8: Dollar Days | F8: Total
B9: (a) | C9: (b) | D9: (c) | E9: (d)
A11: 1 | B11: Transmission | C11: 50746.94 | D11: -8.4547616 | E11: =+D11*C11 -> -429053.28
A12: 2 | B12: Distribution | C12: 196900.21 | D12: -6.9640342 | E12: =+D12*C12 -> -1371219.8
A13: 3
A14: 4 | B14: Total | C14: =SUM(C11:C12) -> 247647.15 | D14: =ROUND(E14/C14,2) -> -7.27 | E14: =SUM(E11:E12) -> -1800273.1
A15: 5
A16: 6 | B16: Source: | C16: Payroll manual check sample.xlsx

Sheet 2-5
A1: 2022 RATE CASE
A2: =' '!A2 -> ONCOR ELECTRIC DELIVERY COMPANY LLC
A3: PAYROLL LEAD - PAY CYCLE CALCULATION
A4: FOR THE LEAD-LAG STUDY-PERIOD ENDING SEPTEMBER 30, 2021
A5: SPONSOR: A. THENMADATHIL
A7: Line No. | B7: Description | C7: First Cycle | D7: Second Cycle | E7: Third Cycle | F7: Total
B8: (a) | C8: (b) | D8: (c) | E8: (c) | F8: (d)
B9: Biweekly
A10: 1 | B10: Distribution
A11: 2 | B11: October 2020 | C11: 3227958.8 | D11: 3209451.1 | E11: 0 | F11: =SUM(C11:E11) -> 6437409.9
A12: 3 | B12: September 2021 | C12: 3577242.9 | D12: 3603265.5 | E12: 0 | F12: =SUM(C12:E12) -> 7180508.4
A13: 4 | B13: Total | C13: =SUM(C11+C12) -> 6805201.7 | D13: =SUM(D11+D12) -> 6812716.6 | E13: =SUM(E11+E12) -> 0 | F13: =SUM(F11+F12) -> 13617918
A14: 5 | B14: Percent | C14: =ROUND(SUM(C13/$F$13),4) -> 0.4997 | D14: =ROUND(SUM(D13/$F$13),4) -> 0.5003 | E14: =ROUND(SUM(E13/$F$13),4) -> 0 | F14: =SUM(C13+D13+E13)/F13 -> 1
A15: 6
B16: Semimonthly
A17: 1 | B17: Distribution
A18: 2 | B18: October 2020 | C18: 11931676 | D18: 11638891 | F18: =SUM(C18:E18) -> 23570566
A19: 3 | B19: September 2021 | C19: 12194054 | D19: 12233896 | F19: =SUM(C19:E19) -> 24427950
A20: 4 | B20: Total | C20: =SUM(C18+C19) -> 24125730 | D20: =SUM(D18+D19) -> 23872786 | F20: =SUM(F18+F19) -> 47998516
A21: 5 | B21: Percent | C21: =ROUND(SUM(C20/$F$20),4) -> 0.5026 | D21: =ROUND(SUM(D20/$F$20),4) -> 0.4974 | F21: =SUM(C20+D20+E20)/F20 -> 1
A24: 7 | B24: Transmission
A25: 8 | B25: October 2020 | C25: 5401716.1 | D25: 5859475 | F25: =SUM(C25:E25) -> 11261191
A26: 9 | B26: September 2021 | C26: 5220787.5 | D26: 5497216.9 | F26: =SUM(C26:E26) -> 10718004
A27: 10 | B27: Total | C27: =SUM(C25+C26) -> 10622504 | D27: =SUM(D25+D26) -> 11356692 | F27: =SUM(F25+F26) -> 21979196
A28: 11 | B28: Percent | C28: =ROUND(SUM(C27/$F$27),4) -> 0.4833 | D28: =ROUND(SUM(D27/$F$27),4) -> 0.5167 | F28: =SUM(C27+D27+E27)/F27 -> 1
A29: 12
A30: 13 | B30: Total T&D | C30: =C27+C20 -> 34748233 | D30: =D27+D20 -> 35229478 | F30: =SUM(C30:E30) -> 69977712
A31: 14 | B31: Percent | C31: =ROUND(C30/F30,4) -> 0.4966 | D31: =ROUND(D30/F30,4) -> 0.5034 | F31: =SUM(C30+D30+E30)/F30 -> 1
A32: 15
A33: 16 | B33: Source: | C33: Payroll pay cycles.xlsx

Sheet 2-6
A1: 2022 RATE CASE
A2: =' '!A2 -> ONCOR ELECTRIC DELIVERY COMPANY LLC
A3: PAYROLL LEAD - BI-WEEKLY/SEMI-MONTHLY PAY CALCULATION
A4: FOR THE LEAD-LAG STUDY-PERIOD ENDING SEPTEMBER 30, 2021
A5: SPONSOR: A. THENMADATHIL
A7: Line | E7: Bi-Weekly | F7: Semi-Monthly
A8: No. | B8: Description | C8: Total Payroll | D8: Bi-Weekly | E8: Percent | F8: Percent
B9: (a) | C9: (b) | D9: (c) | E9: (d) | F9: (e)
A11: 1 | B11: Payroll | C11: 6.017112e+08 | D11: 1.0308301e+08 | E11: =ROUND(D11/C11,4) -> 0.1713 | F11: =1-E11 -> 0.8287
A12: 2
A13: 3 | B13: Source: | C13: Payroll semi-monthly & bi-weekly.xlsx

Sheet 3
A1: 2022 RATE CASE
A2: =' '!A2 -> ONCOR ELECTRIC DELIVERY COMPANY LLC
A3: LABOR - INCENTIVE PAY LEAD DAYS
A4: FOR THE LEAD-LAG STUDY-PERIOD ENDING SEPTEMBER 30, 2021
A5: SPONSOR: A. THENMADATHIL
A7: Line No. | B7: Description | C7: Payroll Expense | D7: Percent | E7: Reference | F7: (Lead)/Lag | G7: Reference | H7: Check Float | I7: Reference | J7: Total (Lead)/Lag | K7: Weighted Dollar Days
B8: (a) | C8: (b) | D8: (c) | E8: (d) | F8: (e) | G8: (f) | H8: (g) | I8: (h) | J8: (i) | K8: (j)
A10: 1 | B10: Test Year Incentive | C10: =+C12-C11 -> 24995198
A11: =A10+1 -> 2 | B11: Adjustment Needed | C11: 2583392.3
A12: =A11+1 -> 3 | B12: Adjusted Incentive | C12: 27578590 | E12: Source 1
A14: =A12+1 -> 4
A15: =A14+1 -> 5 | B15: Direct Deposit | C15: =+C17*D15 -> 27515160 | D15: =+'2-1'!F18 -> 0.9977 | E15: WP/II-B-9/2-1 | F15: ='3-1'!F34 -> -249.33 | G15: WP/II-B-9/3-1 | H15: 0 | J15: =+H15+F15 -> -249.33 | K15: =+J15*C15 -> -6.8603547e+09
A16: =A15+1 -> 6 | B16: Manual | C16: =+C17*D16 -> 63430.758 | D16: =+'2-1'!G18 -> 0.0023 | E16: WP/II-B-9/2-1 | F16: =F15 -> -249.33 | G16: WP/II-B-9/3-1 | H16: ='2-4'!D14 -> -7.27 | I16: WP/II-B-9/2-4 | J16: =+H16+F16 -> -256.6 | K16: =+J16*C16 -> -16276332
A17: =A16+1 -> 7 | B17: Total Adjusted Incentive | C17: =+C12 -> 27578590 | J17: =K17/C17 -> -249.34672 | K17: =+K16+K15 -> -6.8766311e+09
A18: =A17+1 -> 8
A19: =A18+1 -> 9
A20: =A19+1 -> 10 | B20: Source 1: | C20: Iteration "Adjusted Test Year Amount"

Sheet 3-1
A1: 2022 RATE CASE
A2: =' '!A2 -> ONCOR ELECTRIC DELIVERY COMPANY LLC
A3: PEP AWARD LEAD PAYMENT CALCULATION
A4: FOR THE LEAD-LAG STUDY-PERIOD ENDING SEPTEMBER 30, 2021
A5: SPONSOR: A. THENMADATHIL
A7: Line No. | B7: Month | C7: Accrual Date | D7: Mid Month | E7: Payout Date | F7: (Lead)/Lag Days
B8: (a) | C8: (b) | D8: (c) | E8: (d) | F8: (e)
A10: 1 | B10: 44105 | C10: 44135 | D10: =IF(C10=0,"",DATE(YEAR(C10),MONTH(C10),1)+INT(DAY(DATE(YEAR(C10),MONTH(C10)+1,1)-1)/2)-0.5) -> 44119.5 | E10: 44263 | F10: =D10-E10 -> -143.5
A11: 2
A12: 3 | B12: =B10+31 -> 44136 | C12: =C10+30 -> 44165 | D12: =IF(C12=0,"",DATE(YEAR(C12),MONTH(C12),1)+INT(DAY(DATE(YEAR(C12),MONTH(C12)+1,1)-1)/2)-0.5) -> 44150.5 | E12: =$E$10 -> 44263 | F12: =D12-E12 -> -112.5
A13: 4
A14: 5 | B14: =B12+30 -> 44166 | C14: =C12+31 -> 44196 | D14: =IF(C14=0,"",DATE(YEAR(C14),MONTH(C14),1)+INT(DAY(DATE(YEAR(C14),MONTH(C14)+1,1)-1)/2)-0.5) -> 44180.5 | E14: =$E$10 -> 44263 | F14: =D14-E14 -> -82.5
A15: 6
A16: 7 | B16: =B14+31 -> 44197 | C16: =C14+31 -> 44227 | D16: =IF(C16=0,"",DATE(YEAR(C16),MONTH(C16),1)+INT(DAY(DATE(YEAR(C16),MONTH(C16)+1,1)-1)/2)-0.5) -> 44211.5 | E16: 44627 | F16: =D16-E16 -> -415.5
A17: 8
A18: 9 | B18: =B16+31 -> 44228 | C18: 44255 | D18: =IF(C18=0,"",DATE(YEAR(C18),MONTH(C18),1)+INT(DAY(DATE(YEAR(C18),MONTH(C18)+1,1)-1)/2)-0.5) -> 44241.5 | E18: =+E16 -> 44627 | F18: =D18-E18 -> -385.5
A19: 10
A20: 11 | B20: =B18+29 -> 44257 | C20: 44286 | D20: =IF(C20=0,"",DATE(YEAR(C20),MONTH(C20),1)+INT(DAY(DATE(YEAR(C20),MONTH(C20)+1,1)-1)/2)-0.5) -> 44270.5 | E20: =+E18 -> 44627 | F20: =D20-E20 -> -356.5
A21: 12
A22: 13 | B22: =B20+31 -> 44288 | C22: =C20+30 -> 44316 | D22: =IF(C22=0,"",DATE(YEAR(C22),MONTH(C22),1)+INT(DAY(DATE(YEAR(C22),MONTH(C22)+1,1)-1)/2)-0.5) -> 44301.5 | E22: =+E20 -> 44627 | F22: =D22-E22 -> -325.5
A23: 14
A24: 15 | B24: =B22+30 -> 44318 | C24: =C22+31 -> 44347 | D24: =IF(C24=0,"",DATE(YEAR(C24),MONTH(C24),1)+INT(DAY(DATE(YEAR(C24),MONTH(C24)+1,1)-1)/2)-0.5) -> 44331.5 | E24: =E22 -> 44627 | F24: =D24-E24 -> -295.5
A25: 16
A26: 17 | B26: =B24+31 -> 44349 | C26: =C24+30 -> 44377 | D26: =IF(C26=0,"",DATE(YEAR(C26),MONTH(C26),1)+INT(DAY(DATE(YEAR(C26),MONTH(C26)+1,1)-1)/2)-0.5) -> 44362.5 | E26: =E24 -> 44627 | F26: =D26-E26 -> -264.5
A27: 18
A28: 19 | B28: =B26+30 -> 44379 | C28: =C26+31 -> 44408 | D28: =IF(C28=0,"",DATE(YEAR(C28),MONTH(C28),1)+INT(DAY(DATE(YEAR(C28),MONTH(C28)+1,1)-1)/2)-0.5) -> 44392.5 | E28: =E26 -> 44627 | F28: =D28-E28 -> -234.5
A29: 20
A30: 21 | B30: =B28+31 -> 44410 | C30: =C28+31 -> 44439 | D30: =IF(C30=0,"",DATE(YEAR(C30),MONTH(C30),1)+INT(DAY(DATE(YEAR(C30),MONTH(C30)+1,1)-1)/2)-0.5) -> 44423.5 | E30: =E28 -> 44627 | F30: =D30-E30 -> -203.5
A31: 22
A32: 23 | B32: =B30+31 -> 44441 | C32: =C30+30 -> 44469 | D32: =IF(C32=0,"",DATE(YEAR(C32),MONTH(C32),1)+INT(DAY(DATE(YEAR(C32),MONTH(C32)+1,1)-1)/2)-0.5) -> 44454.5 | E32: =E30 -> 44627 | F32: =D32-E32 -> -172.5
A33: 24
A34: 25 | B34: Average | F34: =ROUND(AVERAGE(F10:F32),2) -> -249.33

Sheet 3-2
A1: 2022 RATE CASE
A2: =' '!A2 -> ONCOR ELECTRIC DELIVERY COMPANY LLC
A3: METER READER INCENTIVE LEAD DAYS - PAYMENT CALCULATION
A4: FOR THE LEAD-LAG STUDY-PERIOD ENDING SEPTEMBER 30, 2021
A5: SPONSOR: A. THENMADATHIL
A7: Line No. | B7: Month | C7: Accrual Date | D7: Mid Month | E7: Payout Date | F7: (Lead)/Lag Days
B8: (a) | C8: (b) | D8: (c) | E8: (d) | F8: (e)
A10: 1 | B10: No Longer have Meter Readers thus no incentive effective 1/13.
A11: 2
A12: 3
A13: 4
A14: 5
A15: 6
A16: 7
A17: 8
A18: 9
A19: 10
A20: 11
A21: 12
A22: 13
... A34: 25

Sheet 4
A1: 2022 RATE CASE
A2: =' '!A2 -> ONCOR ELECTRIC DELIVERY COMPANY LLC
A3: NON-LABOR O&M - ONCOR ELECTRIC DELIVERY COMPANY LLC AND OTHER AFFILIATES
A4: FOR THE LEAD-LAG STUDY-PERIOD ENDING SEPTEMBER 30, 2021
A5: SPONSOR: A. THENMADATHIL
A7: Line | G7: Date | H7: Date | I7: Later of Paid | J7: Days Paid | K7: (Lead)/Lag
A8: No. | B8: Month | C8: From | D8: To | E8: Total Days | F8: Mid-Point | G8: Paid | H8: Due | I8: or Due Date | J8: After EOM | K8: Days
B9: (a) | C9: (b) | D9: (c) | E9: (d) | F9: (e) | G9: (f) | H9: (g) | I9: (h) | J9: (i) | K9: (j)
A11: 1 | B11: 44105 | C11: 44105 | D11: 44135 | E11: =D11-C11+1 -> 31 | F11: =E11/2 -> 15.5 | G11: 44165 | H11: 44165 | I11: =MAX(G11:H11) -> 44165 | J11: =+I11-D11 -> 30 | K11: =-J11-F11 -> -45.5 | N11: =H11 -> 44165
A12: =A11+1 -> 2 | B12: 44136 | C12: 44136 | D12: 44165 | E12: =D12-C12+1 -> 30 | F12: =E12/2 -> 15 | G12: 44196 | H12: 44196 | I12: =MAX(G12:H12) -> 44196 | J12: =+I12-D12 -> 31 | K12: =-J12-F12 -> -46 | N12: =H12 -> 44196
A13: =A12+1 -> 3 | B13: 44166 | C13: 44166 | D13: 44196 | E13: =D13-C13+1 -> 31 | F13: =E13/2 -> 15.5 | G13: 44227 | H13: 44227 | I13: =MAX(G13:H13) -> 44227 | J13: =+I13-D13 -> 31 | K13: =-J13-F13 -> -46.5 | N13: =H13 -> 44227
A14: =A13+1 -> 4 | B14: 44197 | C14: 44197 | D14: 44227 | E14: =D14-C14+1 -> 31 | F14: =E14/2 -> 15.5 | G14: 44253 | H14: 44253 | I14: =MAX(G14:H14) -> 44253 | J14: =+I14-D14 -> 26 | K14: =-J14-F14 -> -41.5 | N14: =H14 -> 44253
A15: =A14+1 -> 5 | B15: 44228 | C15: 44228 | D15: 44255 | E15: =D15-C15+1 -> 28 | F15: =E15/2 -> 14 | G15: 44286 | H15: 44286 | I15: =MAX(G15:H15) -> 44286 | J15: =+I15-D15 -> 31 | K15: =-J15-F15 -> -45 | N15: =H15 -> 44286
A16: =A15+1 -> 6 | B16: 44256 | C16: 44256 | D16: 44286 | E16: =D16-C16+1 -> 31 | F16: =E16/2 -> 15.5 | G16: 44316 | H16: 44316 | I16: =MAX(G16:H16) -> 44316 | J16: =+I16-D16 -> 30 | K16: =-J16-F16 -> -45.5 | N16: =H16 -> 44316
A17: =A16+1 -> 7 | B17: 44287 | C17: 44287 | D17: 44316 | E17: =D17-C17+1 -> 30 | F17: =E17/2 -> 15 | G17: 44344 | H17: 44344 | I17: =MAX(G17:H17) -> 44344 | J17: =+I17-D17 -> 28 | K17: =-J17-F17 -> -43 | N17: =H17 -> 44344
A18: =A17+1 -> 8 | B18: 44317 | C18: 44317 | D18: 44347 | E18: =D18-C18+1 -> 31 | F18: =E18/2 -> 15.5 | G18: 44377 | H18: 44377 | I18: =MAX(G18:H18) -> 44377 | J18: =+I18-D18 -> 30 | K18: =-J18-F18 -> -45.5 | N18: =H18 -> 44377
A19: =A18+1 -> 9 | B19: 44348 | C19: 44348 | D19: 44377 | E19: =D19-C19+1 -> 30 | F19: =E19/2 -> 15 | G19: 44407 | H19: 44407 | I19: =MAX(G19:H19) -> 44407 | J19: =+I19-D19 -> 30 | K19: =-J19-F19 -> -45 | N19: =H19 -> 44407
A20: =A19+1 -> 10 | B20: 44378 | C20: 44378 | D20: 44408 | E20: =D20-C20+1 -> 31 | F20: =E20/2 -> 15.5 | G20: 44439 | H20: 44439 | I20: =MAX(G20:H20) -> 44439 | J20: =+I20-D20 -> 31 | K20: =-J20-F20 -> -46.5 | N20: =H20 -> 44439
A21: =A20+1 -> 11 | B21: 44409 | C21: 44409 | D21: 44439 | E21: =D21-C21+1 -> 31 | F21: =E21/2 -> 15.5 | G21: 44469 | H21: 44469 | I21: =MAX(G21:H21) -> 44469 | J21: =+I21-D21 -> 30 | K21: =-J21-F21 -> -45.5 | N21: =H21 -> 44469
A22: =A21+1 -> 12 | B22: 44440 | C22: 44440 | D22: 44469 | E22: =D22-C22+1 -> 30 | F22: =E22/2 -> 15 | G22: 44498 | H22: 44498 | I22: =MAX(G22:H22) -> 44498 | J22: =+I22-D22 -> 29 | K22: =-J22-F22 -> -44 | N22: =H22 -> 44498
A23: =A22+1 -> 13
A24: =A23+1 -> 14 | G24: Average | K24: =ROUND(AVERAGE(K11:K22),2) -> -44.96
A25: =A24+1 -> 15
A26: =A25+1 -> 16
A27: =A26+1 -> 17 | B27: Source: | C27: Affiliate Payment Dates 12ME 9.30.21.pdf

Sheet 5
A1: 2022 RATE CASE
A2: =' '!A2 -> ONCOR ELECTRIC DELIVERY COMPANY LLC
A3: TCOS - NON-ONCOR
A4: FOR THE LEAD-LAG STUDY-PERIOD ENDING SEPTEMBER 30, 2021
A5: SPONSOR: A. THENMADATHIL
A7: Line No. | C7: Description | E7: (Lead)/Lag Days
C8: (a) | E8: (b)
A10: 1 | C10: Average service period
A11: =A10+1 -> 2 | C11: (365.25 days/12 months)/2 | E11: =ROUND(365.25/12/2,3)*-1 -> -15.219
A12: =A11+1 -> 3
A13: =A12+1 -> 4 | C13: Days from end of Service Period to Payment | E13: -35
A14: =A13+1 -> 5
A15: =A14+1 -> 6
A16: =A15+1 -> 7 | C16: Total Lead Days | E16: =ROUND(SUM(E11:E14),2) -> -50.22

Sheet 6
A1: 2022 RATE CASE
A2: =' '!A2 -> ONCOR ELECTRIC DELIVERY COMPANY LLC
A3: NON-LABOR O&M - OTHER THIRD PARTY O&M
A4: FOR THE LEAD-LAG STUDY-PERIOD ENDING SEPTEMBER 30, 2021
A5: SPONSOR: A. THENMADATHIL
A9: Line | D9: Total (Lead)/Lag | F9: Weighted
A10: No. | B10: Business Unit | C10: Amount | D10: Days | E10: Reference | F10: Dollar Days
B11: (a) | C11: (b) | D11: (c) | E11: (d) | F11: (e)
A13: 1 | B13: Transmission | C13: =+'6-1'!C17 -> 86691097 | D13: =+'6-1'!D17 -> -29.73029 | E13: WP/II-B-9/6-1 | F13: =+D13*C13 -> -2.5773515e+09
A14: =A13+1 -> 2 | B14: Distribution | C14: ='6-2'!C17 -> 4.7040816e+08 | D14: =+'6-2'!D17 -> -50.540894 | E14: WP/II-B-9/6-2 | F14: =C14*D14 -> -2.3774849e+10
A15: =A14+1 -> 3 | B15: Corporate * | C15: 1423446.1 | D15: ='6-3'!G23 -> 97.77 | E15: WP/II-B-9/6-3 | F15: =C15*D15 -> 1.3917032e+08
A16: =A15+1 -> 4
A17: =A16+1 -> 5 | B17: Total | C17: =SUM(C13:C15) -> 5.585227e+08 | D17: =ROUND(F17/C17,2) -> -46.93 | F17: =SUM(F13:F15) -> -2.621303e+10
A18: =A17+1 -> 6
A19: =A18+1 -> 7
A20: =A19+1 -> 8 | B20: * Source: | C20: Lead Lag Samples

Sheet 6-1
A1: 2022 RATE CASE
A2: =' '!A2 -> ONCOR ELECTRIC DELIVERY COMPANY LLC
A3: NON-LABOR O&M - THIRD PARTY O&M - TRANSMISSION
A4: FOR THE LEAD-LAG STUDY-PERIOD ENDING SEPTEMBER 30, 2021
A5: SPONSOR: A. THENMADATHIL
A9: Line | C9: Population | D9: (Lead)/Lag | F9: Weighted
A10: No. | B10: Strata | C10: Dollars | D10: Days | E10: Reference | F10: Dollar Days
B11: (a) | C11: (b) | D11: (c) | E11: (d) | F11: (e)
A13: 1 | B13: Item Amount < $10,000 | C13: 22309902 | D13: ='6-1-1'!G43 -> -29.36 | E13: WP/II-B-9/6-1-1 | F13: =C13*D13 -> -6.5501874e+08
A14: =A13+1 -> 2 | B14: Item Amount_>= $10,000 and <= $25,000 | C14: 14751915 | D14: ='6-1-2'!G33 -> -28.34 | E14: WP/II-B-9/6-1-2 | F14: =C14*D14 -> -4.1806928e+08
A15: =A14+1 -> 3 | B15: Item Amount > $25,000 | C15: 49629279 | D15: ='6-1-3'!G79 -> -30.31 | E15: WP/II-B-9/6-1-3 | F15: =C15*D15 -> -1.5042634e+09
A16: =A15+1 -> 4
A17: =A16+1 -> 5 | B17: Total | C17: =SUM(C13:C15) -> 86691097 | D17: =+F17/C17 -> -29.73029 | F17: =SUM(F13:F15) -> -2.5773515e+09
A18: =A17+1 -> 6
A19: =A18+1 -> 7
A20: =A19+1 -> 8
A21: =A20+1 -> 9 | B21: Source: | C21: Lead Lag Samples.xlsx

Sheet 6-1-1
A1: 2022 RATE CASE
A2: ='1-1-3-1-1'!A2 -> ONCOR ELECTRIC DELIVERY COMPANY LLC
A3: NON-LABOR O&M - THIRD PARTY O&M SAMPLE - TRANSMISSION (STRATA 1: <$10,000)
A4: FOR THE LEAD-LAG STUDY-PERIOD ENDING SEPTEMBER 30, 2021
A5: SPONSOR: A. THENMADATHIL
F7: Later of Due Date
A8: Line | D8: Begin | E8: Type of | F8: or Check Clear | G8: (Lead)/Lag | H8: Weighted Dollar
A9: No. | B9: Voucher | C9: Amount | D9: Date | E9: Begin Date | F9: Date | G9: Days | H9: Days
B10: (a) | C10: (b) | D10: (c) | E10: (d) | F10: (e) | G10: (f) | H10: (g)
A12: 1 | B12: 00457936 | C12: 96.77 | D12: 44113.5 | E12: Midpoint of Benefit Period | F12: 44121 | G12: =D12-F12 -> -7.5 | H12: =IF(ISERR(G12*C12),"",G12*C12) -> -725.775
A13: =A12+1 -> 2 | B13: 00501568 | C13: 818.05 | D13: 44264 | E13: Invoice Date | F13: 44345 | G13: =D13-F13 -> -81 | H13: =IF(ISERR(G13*C13),"",G13*C13) -> -66262.05
A14: =A13+1 -> 3 | B14: M925724 | C14: 3181 | D14: 44308.5 | E14: Midpoint of Benefit Period | F14: 44355 | G14: =D14-F14 -> -46.5 | H14: =IF(ISERR(G14*C14),"",G14*C14) -> -147916.5
A15: =A14+1 -> 4 | B15: 00483673 | C15: 637.77 | D15: 44246 | E15: Invoice Date | F15: 44279 | G15: =D15-F15 -> -33 | H15: =IF(ISERR(G15*C15),"",G15*C15) -> -21046.41
A16: =A15+1 -> 5 | B16: M913793 | C16: 594.5 | D16: 44278 | E16: Midpoint of Benefit Period | F16: 44312 | G16: =D16-F16 -> -34 | H16: =IF(ISERR(G16*C16),"",G16*C16) -> -20213
A17: =A16+1 -> 6 | B17: 00508717 | C17: 295.41 | D17: 44346.5 | E17: Midpoint of Benefit Period | F17: 44384 | G17: =D17-F17 -> -37.5 | H17: =IF(ISERR(G17*C17),"",G17*C17) -> -11077.875
A18: =A17+1 -> 7 | B18: M929919 | C18: 37.45 | D18: 44317 | E18: Midpoint of Benefit Period | F18: 44357 | G18: =D18-F18 -> -40 | H18: =IF(ISERR(G18*C18),"",G18*C18) -> -1498
A19: =A18+1 -> 8 | B19: 00498823 | C19: 220.47 | D19: 44332 | E19: Midpoint of Benefit Period | F19: 44337 | G19: =D19-F19 -> -5 | H19: =IF(ISERR(G19*C19),"",G19*C19) -> -1102.35
A20: =A19+1 -> 9 | B20: M889957 | C20: 10.28 | D20: 44262 | E20: Invoice Date | F20: 44291 | G20: =D20-F20 -> -29 | H20: =IF(ISERR(G20*C20),"",G20*C20) -> -298.12
A21: =A20+1 -> 10 | B21: 00470283 | C21: 3950 | D21: 44120 | E21: Midpoint of Benefit Period | F21: 44186 | G21: =D21-F21 -> -66 | H21: =IF(ISERR(G21*C21),"",G21*C21) -> -260700
A22: =A21+1 -> 11 | B22: 00518590 | C22: 1170.18 | D22: 44433 | E22: Invoice Date | F22: 44468 | G22: =D22-F22 -> -35 | H22: =IF(ISERR(G22*C22),"",G22*C22) -> -40956.3
A23: =A22+1 -> 12 | B23: 00465104 | C23: 65.18 | D23: 44114.5 | E23: Midpoint of Benefit Period | F23: 44153 | G23: =D23-F23 -> -38.5 | H23: =IF(ISERR(G23*C23),"",G23*C23) -> -2509.43
A24: =A23+1 -> 13 | B24: 00518893 | C24: 5458.29 | D24: 44448 | E24: Midpoint of Benefit Period | F24: 44463 | G24: =D24-F24 -> -15 | H24: =IF(ISERR(G24*C24),"",G24*C24) -> -81874.35
... A41: =A40+1 -> 30 | B41: M981952 | C41: 9.75 | D41: 44417 | E41: Midpoint of Benefit Period | F41: 44454 | G41: =D41-F41 -> -37 | H41: =IF(ISERR(G41*C41),"",G41*C41) -> -360.75
A42: =A41+1 -> 31
A43: =A42+1 -> 32 | B43: Subtotal | C43: =SUM(C12:C42) -> 35433.64 | G43: =+ROUND(H43/C43,2) -> -29.36 | H43: =SUM(H12:H42) -> -1040329.8
A44: =A43+1 -> 33
A45: =A44+1 -> 34 | B45: Source: | C45: 3rd party O&M - TRN sample 2021.xlsx

Sheet 6-1-2
A1: 2022 RATE CASE
A2: ='1-1-3-1-1'!A2 -> ONCOR ELECTRIC DELIVERY COMPANY LLC
A3: NON-LABOR O&M - THIRD PARTY O&M SAMPLE - TRANSMISSION (STRATA 2: >=$10,000 AND <=$25,000)
A4: FOR THE LEAD-LAG STUDY-PERIOD ENDING SEPTEMBER 30, 2021
A5: SPONSOR: A. THENMADATHIL
F7: Later of Due Date
A8: Line | D8: Begin | E8: Type of | F8: or Check Clear | G8: (Lead)/Lag | H8: Weighted Dollar
A9: No. | B9: Voucher | C9: Amount | D9: Date | E9: Begin Date | F9: Date | G9: Days | H9: Days
B10: (a) | C10: (b) | D10: (c) | E10: (d) | F10: (e) | G10: (f) | H10: (g)
A12: 1 | B12: 00463570 | C12: 19797.09 | D12: 44120 | E12: Midpoint of Benefit Period | F12: 44149 | G12: =D12-F12 -> -29 | H12: =IF(ISERR(G12*C12),"",G12*C12) -> -574115.61
A13: =A12+1 -> 2 | B13: M972114 | C13: 24566.04 | D13: 44362.5 | E13: Midpoint of Benefit Period | F13: 44422 | G13: =D13-F13 -> -59.5 | H13: =IF(ISERR(G13*C13),"",G13*C13) -> -1461679.4
A14: =A13+1 -> 3 | B14: 00498936 | C14: 17310.08 | D14: 44332 | E14: Midpoint of Benefit Period | F14: 44347 | G14: =D14-F14 -> -15 | H14: =IF(ISERR(G14*C14),"",G14*C14) -> -259651.2
A15: =A14+1 -> 4 | B15: M981252 | C15: 20209.4 | D15: 44379 | E15: Midpoint of Benefit Period | F15: 44440 | G15: =D15-F15 -> -61 | H15: =IF(ISERR(G15*C15),"",G15*C15) -> -1232773.4
A16: =A15+1 -> 5 | B16: 00510690 | C16: 19006.84 | D16: 44386.5 | E16: Midpoint of Benefit Period | F16: 44419 | G16: =D16-F16 -> -32.5 | H16: =IF(ISERR(G16*C16),"",G16*C16) -> -617722.3
A17: =A16+1 -> 6 | B17: M996349 | C17: 10326.55 | D17: 44425.5 | E17: Midpoint of Benefit Period | F17: 44466 | G17: =D17-F17 -> -40.5 | H17: =IF(ISERR(G17*C17),"",G17*C17) -> -418225.27
A18: =A17+1 -> 7 | B18: M827175 | C18: 23479.42 | D18: 44110.5 | E18: Midpoint of Benefit Period | F18: 44150 | G18: =D18-F18 -> -39.5 | H18: =IF(ISERR(G18*C18),"",G18*C18) -> -927437.09
A19: =A18+1 -> 8 | B19: 00517268 | C19: 23610.8 | D19: 44420.5 | E19: Midpoint of Benefit Period | F19: 44463 | G19: =D19-F19 -> -42.5 | H19: =IF(ISERR(G19*C19),"",G19*C19) -> -1003459
A20: =A19+1 -> 9 | B20: M914531 | C20: 16691.2 | D20: 44273 | E20: Midpoint of Benefit Period | F20: 44309 | G20: =D20-F20 -> -36 | H20: =IF(ISERR(G20*C20),"",G20*C20) -> -600883.2
A21: =A20+1 -> 10 | B21: M930386 | C21: 18524.15 | D21: 44306.5 | E21: Midpoint of Benefit Period | F21: 44346 | G21: =D21-F21 -> -39.5 | H21: =IF(ISERR(G21*C21),"",G21*C21) -> -731703.93
A22: =A21+1 -> 11 | B22: M917146 | C22: 23127.61 | D22: 44300.5 | E22: Midpoint of Benefit Period | F22: 44337 | G22: =D22-F22 -> -36.5 | H22: =IF(ISERR(G22*C22),"",G22*C22) -> -844157.77
A23: =A22+1 -> 12 | B23: M827174 | C23: 23050.1 | D23: 44103.5 | E23: Midpoint of Benefit Period | F23: 44143 | G23: =D23-F23 -> -39.5 | H23: =IF(ISERR(G23*C23),"",G23*C23) -> -910478.95
A24: =A23+1 -> 13 | B24: M957862 | C24: 10800 | D24: 44362.5 | E24: Midpoint of Benefit Period | F24: 44407 | G24: =D24-F24 -> -44.5 | H24: =IF(ISERR(G24*C24),"",G24*C24) -> -480600
... A31: =A30+1 -> 20 | B31: M857640 | C31: 14563.41 | D31: 44182 | E31: Midpoint of Benefit Period | F31: 44216 | G31: =D31-F31 -> -34 | H31: =IF(ISERR(G31*C31),"",G31*C31) -> -495155.94
A32: =A31+1 -> 21
A33: =A32+1 -> 22 | B33: Total | C33: =SUM(C12:C32) -> 359661.5 | G33: =+ROUND(H33/C33,2) -> -28.34 | H33: =SUM(H12:H32) -> -10193949
A34: =A33+1 -> 23
A35: =A34+1 -> 24 | B35: Source: | C35: 3rd party O&M - TRN sample 2021.xlsx

Sheet 6-1-3
A1: 2022 RATE CASE
A2: ='1-1-3-1-1'!A2 -> ONCOR ELECTRIC DELIVERY COMPANY LLC
A3: NON-LABOR O&M - THIRD PARTY O&M SAMPLE - TRANSMISSION (STRATA 3: >$25,000)
A4: FOR THE LEAD-LAG STUDY-PERIOD ENDING SEPTEMBER 30, 2021
A5: SPONSOR: A. THENMADATHIL
F7: Later of Due Date
A8: Line | D8: Begin | E8: Type of | F8: or Check Clear | G8: (Lead)/Lag | H8: Weighted Dollar
A9: No. | B9: Voucher | C9: Amount | D9: Date | E9: Begin Date | F9: Date | G9: Days | H9: Days
B10: (a) | C10: (b) | D10: (c) | E10: (d) | F10: (e) | G10: (f) | H10: (g)
A12: 1 | B12: M834028 | C12: 32538.22 | D12: 44089.5 | E12: Midpoint of Benefit Period | F12: 44155 | G12: =D12-F12 -> -65.5 | H12: =IF(ISERR(G12*C12),"",G12*C12) -> -2131253.4
A13: =+A12+1 -> 2 | B13: M809469 | C13: 77700 | D13: 44096 | E13: Invoice Date | F13: 44126 | G13: =D13-F13 -> -30 | H13: =IF(ISERR(G13*C13),"",G13*C13) -> -2331000
A14: =+A13+1 -> 3 | B14: M823693 | C14: 270108 | D14: 44103.5 | E14: Midpoint of Benefit Period | F14: 44142 | G14: =D14-F14 -> -38.5 | H14: =IF(ISERR(G14*C14),"",G14*C14) -> -10399158
A15: =+A14+1 -> 4 | B15: M838482 | C15: 70000 | D15: 44143.5 | E15: Midpoint of Benefit Period | F15: 44177 | G15: =D15-F15 -> -33.5 | H15: =IF(ISERR(G15*C15),"",G15*C15) -> -2345000
A16: =+A15+1 -> 5 | B16: 00466883 | C16: 80504.06 | D16: 44089.5 | E16: Midpoint of Benefit Period | F16: 44157 | G16: =D16-F16 -> -67.5 | H16: =IF(ISERR(G16*C16),"",G16*C16) -> -5434024
A17: =+A16+1 -> 6 | B17: M932779 | C17: 29600 | D17: 44334 | E17: Invoice Date | F17: 44364 | G17: =D17-F17 -> -30 | H17: =IF(ISERR(G17*C17),"",G17*C17) -> -888000
A18: =+A17+1 -> 7 | B18: 00508071 | C18: 95242.6 | D18: 44362.5 | E18: removed from sample | F18: 44392 | G18: =D18-F18 -> -29.5 | H18: =IF(ISERR(G18*C18),"",G18*C18) -> -2809656.7
A19: =+A18+1 -> 8 | B19: 00487902 | C19: 276269.12 | D19: 44258 | E19: Midpoint of Benefit Period | F19: 44264 | G19: =D19-F19 -> -6 | H19: =IF(ISERR(G19*C19),"",G19*C19) -> -1657614.7
A20: =+A19+1 -> 9 | B20: 00521915 | C20: 27318.45 | D20: 44485 | E20: Midpoint of Benefit Period | F20: 44484 | G20: =D20-F20 -> 1 | H20: =IF(ISERR(G20*C20),"",G20*C20) -> 27318.45
A21: =+A20+1 -> 10 | B21: 00512835 | C21: 31638.97 | D21: 44393 | E21: Midpoint of Benefit Period | F21: 44422 | G21: =D21-F21 -> -29 | H21: =IF(ISERR(G21*C21),"",G21*C21) -> -917530.13
A22: =+A21+1 -> 11 | B22: 00523186 | C22: 246280.95 | D22: 44416 | E22: Midpoint of Benefit Period | F22: 44473 | G22: =D22-F22 -> -57 | H22: =IF(ISERR(G22*C22),"",G22*C22) -> -14038014
A23: =+A22+1 -> 12 | B23: 00472865 | C23: 33871.43 | D23: 44176 | E23: Invoice Date | F23: 44206 | G23: =D23-F23 -> -30 | H23: =IF(ISERR(G23*C23),"",G23*C23) -> -1016142.9
A24: =+A23+1 -> 13 | B24: M884832 | C24: 28807.9 | D24: 44229 | E24: Midpoint of Benefit Period | F24: 44279 | G24: =D24-F24 -> -50 | H24: =IF(ISERR(G24*C24),"",G24*C24) -> -1440395
... A77: =+A76+1 -> 66 | B77: 00462030 | C77: 213494.06 | D77: 44117 | E77: Midpoint of Benefit Period | F77: 44124 | G77: =D77-F77 -> -7 | H77: =IF(ISERR(G77*C77),"",G77*C77) -> -1494458.4
A78: =+A77+1 -> 67
A79: =+A78+1 -> 68 | B79: Subtotal | C79: =SUM(C12:C78) -> 4232643 | G79: =+ROUND(H79/C79,2) -> -30.31 | H79: =SUM(H12:H78) -> -1.2828116e+08
A80: =+A79+1 -> 69
A81: =+A80+1 -> 70 | B81: Source: | C81: 3rd party O&M - TRN sample 2021.xlsx

Sheet 6-2
A1: 2022 RATE CASE
A2: =' '!A2 -> ONCOR ELECTRIC DELIVERY COMPANY LLC
A3: NON-LABOR O&M - THIRD PARTY O&M - DISTRIBUTION
A4: FOR THE LEAD-LAG STUDY-PERIOD ENDING SEPTEMBER 30, 2021
A5: SPONSOR: A. THENMADATHIL
A9: Line | C9: Population | D9: (Lead)/Lag | F9: Weighted
A10: No. | B10: Strata | C10: Dollars | D10: Days | E10: Reference | F10: Dollar Days
B11: (a) | C11: (b) | D11: (c) | E11: (d) | F11: (e)
A13: 1 | B13: Item Amount < $10,000 | C13: 1.0091309e+08 | D13: =+'6-2-1'!G38 -> -92.57 | E13: WP/II-B-9/6-2-1 | F13: =C13*D13 -> -9.3415243e+09
A14: =A13+1 -> 2 | B14: Item Amount_>= $10,000 and <= $25,000 | C14: 56499540 | D14: ='6-2-2'!G27 -> -59.96 | E14: WP/II-B-9/6-2-2 | F14: =C14*D14 -> -3.3877124e+09
A15: =A14+1 -> 3 | B15: Item Amount > $25,000 | C15: 3.1299553e+08 | D15: ='6-2-3'!G90 -> -35.29 | E15: WP/II-B-9/6-2-3 | F15: =C15*D15 -> -1.1045612e+10
A16: =A15+1 -> 4
A17: =A16+1 -> 5 | B17: Total | C17: =SUM(C13:C15) -> 4.7040816e+08 | D17: =+F17/C17 -> -50.540894 | F17: =SUM(F13:F15) -> -2.3774849e+10
A18: =A17+1 -> 6
A19: =A18+1 -> 7
A20: =A19+1 -> 8
A21: =A20+1 -> 9 | B21: Source: | C21: Lead Lag Sample.xlsx

Sheet 6-2-1
A1: 2022 RATE CASE
A2: ='1-1-3-1-1'!A2 -> ONCOR ELECTRIC DELIVERY COMPANY LLC
A3: NON-LABOR O&M - THIRD PARTY O&M SAMPLE - DISTRIBUTION (STRATA 1: <$10,000)
A4: FOR THE LEAD-LAG STUDY-PERIOD ENDING SEPTEMBER 30, 2021
A5: SPONSOR: A. THENMADATHIL
F7: Later of Due Date
A8: Line | D8: Begin | E8: Type of | F8: or Check Clear | G8: (Lead)/Lag | H8: Weighted Dollar
A9: No. | B9: Voucher | C9: Amount | D9: Date | E9: Begin Date | F9: Date | G9: Days | H9: Days
B10: (a) | C10: (b) | D10: (c) | E10: (d) | F10: (e) | G10: (f) | H10: (g)
A12: 1 | B12: 00458139 | C12: 352.32 | D12: 44061 | E12: Midpoint of Benefit Period | F12: 44114 | G12: =D12-F12 -> -53 | H12: =IF(ISERR(G12*C12),"",G12*C12) -> -18672.96
A13: 2 | B13: M906156 | C13: 1522.85 | D13: 44270 | E13: Midpoint of Benefit Period | F13: 44300 | G13: =D13-F13 -> -30 | H13: =IF(ISERR(G13*C13),"",G13*C13) -> -45685.5
A14: 3 | B14: M817440 | C14: 1062.5 | D14: 44060 | E14: Midpoint of Benefit Period | F14: 44118 | G14: =D14-F14 -> -58 | H14: =IF(ISERR(G14*C14),"",G14*C14) -> -61625
A15: 4 | B15: M996548 | C15: 256.35 | D15: 44462 | E15: Midpoint of Benefit Period | F15: 44492 | G15: =D15-F15 -> -30 | H15: =IF(ISERR(G15*C15),"",G15*C15) -> -7690.5
A16: 5 | B16: M912978 | C16: 43.4 | D16: 44305 | E16: Midpoint of Benefit Period | F16: 44333 | G16: =D16-F16 -> -28 | H16: =IF(ISERR(G16*C16),"",G16*C16) -> -1215.2
A17: 6 | B17: M814000 | C17: 114.8 | D17: 44049 | E17: Midpoint of Benefit Period | F17: 44122 | G17: =D17-F17 -> -73 | H17: =IF(ISERR(G17*C17),"",G17*C17) -> -8380.4
A18: 7 | B18: M984492 | C18: 14.32 | D18: 44439 | E18: Midpoint of Benefit Period | F18: 44466 | G18: =D18-F18 -> -27 | H18: =IF(ISERR(G18*C18),"",G18*C18) -> -386.64
