Workbook
Name \p: #REF!
Name \p: #REF!
Name \p: #REF!
Name \p: #REF!
Name _1961COPY: #REF!
Name _1961COPY: #REF!
Name _1961COPY: #REF!
Name _1961COPY: #REF!
Name _1961COPY: #REF!
Name _1961COPY: #REF!
Name _1961COPY: #REF!
Name _1961COPY: 'II-E-3.12 ITC Utilized'!$A$1185:$B$1186
Name _1962: #REF!
Name _1962: #REF!
Name _1962: #REF!
Name _1962: #REF!
Name _1962: #REF!
Name _1962: #REF!
Name _1962: #REF!
Name _1962: 'II-E-3.10'!$B$61:$G$111
Name _1962: 'II-E-3.12 ITC Utilized'!$A$1:$E$37
Name _1963: #REF!
Name _1963: #REF!
Name _1963: #REF!
Name _1963: #REF!
Name _1963: #REF!
Name _1963: #REF!
Name _1963: #REF!
Name _1963: 'II-E-3.10'!$B$115:$G$163
Name _1963: 'II-E-3.12 ITC Utilized'!#REF!
Name _1964: #REF!
Name _1964: #REF!
Name _1964: #REF!
Name _1964: #REF!
Name _1964: #REF!
Name _1964: #REF!
Name _1964: #REF!
Name _1964: 'II-E-3.10'!$B$167:$G$215
Name _1964: 'II-E-3.12 ITC Utilized'!#REF!
Name _1965: #REF!
Name _1965: #REF!
Name _1965: #REF!
Name _1965: #REF!
Name _1965: #REF!
Name _1965: #REF!
Name _1965: #REF!
Name _1965: 'II-E-3.10'!$B$219:$G$267
Name _1965: 'II-E-3.12 ITC Utilized'!#REF!
Name _1966: #REF!
Name _1966: #REF!
Name _1966: #REF!
Name _1966: #REF!
Name _1966: #REF!
Name _1966: #REF!
Name _1966: #REF!
Name _1966: 'II-E-3.10'!$B$271:$G$319
Name _1966: 'II-E-3.12 ITC Utilized'!#REF!
Name _1967: #REF!
Name _1967: #REF!
Name _1967: #REF!

Sheet Macros

Sheet I-A
F1: Schedule I-A
B2: PUBLIC UTILITY COMMISSION OF TEXAS
B3: AEP TEXAS INC
B4: I-A COST OF SERVICE SUMMARY
B5: TEST YEAR ENDING 12/31/2018
C8: 1 | D8: 2 | E8: 3 | F8: 4
C10: Reference | D10: Amount at | E10: Adjustment | F10: Amount
A11: Line | B11: Description | C11: Schedule | D11: at | E11: to | F11: at
A12: No. | D12: Existing Rates | E12: Existing Rates | F12: Proposed Rates
A14: 1 | B14: Transmission and Distribution Cost of Service | C14: 1-A-1 | D14: =D16+D17+D18 -> 5.9140261e+08 | E14: =E16+E17+E18 -> 27752838 | F14: =F16+F17+F18 -> 6.1915544e+08
A15: =A14+1 -> 2
A16: =A15+1 -> 3 | B16: Distribution Customer Meter | D16: ='[9]I-A'!$D$16+'[10]I-A'!$D$16 -> 4.5079701e+08 | E16: =F16-D16 -> 1.6835844e+08 | F16: ='I-A-1'!K36 -> 6.1915544e+08
A17: =A16+1 -> 4 | B17: Transition System Base Rate Charge Adjustment | D17: ='[10]I-A'!$D$17+'[9]I-A'!$D$17 -> 1.317052e+08 | E17: =-D17 -> -1.317052e+08 | F17: =SUM(D17:E17) -> 0
A18: =A17+1 -> 5 | B18: Energy Efficiency Base Rate | D18: ='[10]I-A'!$D$18+'[9]I-A'!$D$18 -> 8900402 | E18: =-D18 -> -8900402 | F18: =SUM(D18:E18) -> 0
A19: =A18+1 -> 6 | B19: Transmission and Distribution Cost of Service | D19: =SUM(D16:D18) -> 5.9140261e+08 | E19: =SUM(E16:E18) -> 27752838 | F19: =SUM(F16:F18) -> 6.1915544e+08
A20: =A19+1 -> 7
A21: =A20+1 -> 8 | B21: DCRF | D21: ='[10]I-A'!$D$21+'[9]I-A'!$D$21 -> 73810076 | E21: =-D21 -> -73810076 | F21: =SUM(D21:E21) -> 0
A22: =A21+1 -> 9 | B22: TCRF | D22: ='[10]I-A'!$D$22+'[9]I-A'!$D$22 -> 2.0226217e+08 | E22: =F22-D22 -> 1.2512656e+08 | F22: ='[10]I-A'!$F$22+'[9]I-A'!$F$22 -> 3.2738873e+08
A23: =A22+1 -> 10 | B23: Rider - Advanced Metering Recovery | D23: ='[10]I-A'!$D$23+'[9]I-A'!$D$23 -> 29883535 | E23: =-D23 -> -29883535 | F23: =SUM(D23:E23) -> 0
A24: =A23+1 -> 11 | B24: Rider - Energy Efficiency | D24: ='[10]I-A'!$D$24+'[9]I-A'!$D$24 -> 11349957 | E24: ='[10]I-A'!$E$24+'[9]I-A'!$E$24 -> 8900401.8 | F24: =SUM(D24:E24) -> 20250359
A25: =A24+1 -> 12 | B25: Rider - Merger Savings | D25: ='[10]I-A'!$D$25+'[9]I-A'!$D$25 -> -989896.26 | E25: =-D25 -> 989896.26 | F25: =SUM(D25:E25) -> 0
A26: =A25+1 -> 13 | B26: Rider - Tax Refund | E26: ='[10]I-A'!$E$26+'[9]I-A'!$E$26 -> -20741598 | F26: =SUM(D26:E26) -> -20741598
A27: =A26+1 -> 14 | F27: =SUM(D27:E27) -> 0
A28: =A27+1 -> 15 | F28: =SUM(D28:E28) -> 0
A29: =A28+1 -> 16
A30: =A29+1 -> 17 | B30: TOTAL NON-BYPASSABLE DELIVERY CHARGE | D30: =SUM(D19:D29) -> 9.0771845e+08 | E30: =SUM(E19:E29) -> 38334482 | F30: =SUM(F19:F29) -> 9.4605293e+08
A31: =A30+1 -> 18
A32: =A31+1 -> 19 | B32: Transition Charge Allowance | D32: -3169202.7 | F32: =D32 -> -3169202.7
A33: =A32+1 -> 20 | B33: Transition Charge 2 | D33: 2.0167863e+08 | F33: =D33 -> 2.0167863e+08
A34: =A33+1 -> 21 | B34: Transition Charge 3 | D34: 75526075 | F34: =D34 -> 75526075
A35: =A34+1 -> 22
A36: =A35+1 -> 23 | B36: Nuclear Decommissioning | D36: -387868.4 | F36: =D36 -> -387868.4
A37: =A36+1 -> 24 | B37: Rider - Competitive Metering | D37: ='[9]I-A'!$D$37+'[10]I-A'!$D$33 -> 2774.48 | F37: =D37 -> 2774.48
A38: =A37+1 -> 25 | B38: Rider - State Colleges and Universities Discount Rider | D38: ='[9]I-A'!$D$38+'[10]I-A'!$D$34 -> -564139.09 | E38: =-D38 -> 564139.09 | F38: =SUM(D38:E38) -> 0
A39: =A38+1 -> 26
A40: =A39+1 -> 27 | B40: TOTAL | D40: =SUM(D30:D38) -> 1.1808047e+09 | E40: =SUM(E30:E38) -> 38898621 | F40: =SUM(F30:F38) -> 1.2197033e+09
B43: TRANSMISSION
B44: TCOS revenues per Docket 49192 | D44: =280015560.83116+143357310 -> 4.2337287e+08
B45: Transmission revenue requirement | D45: ='I-A-1'!G36 -> 4.2021337e+08
B47: Net change | D47: =D45-D44+D46 -> -3159501.9

Sheet I-A-1
K1: Schedule I-A-1
B2: PUBLIC UTILITY COMMISSION OF TEXAS
B3: AEP TEXAS INC
B4: I-A-1 TOTAL COST OF SERVICE BY FUNCTION
B5: TEST YEAR ENDING 12/31/2018
B6: ='I-A'!B6
D8: 1 | E8: 2 | F8: 3 | G8: 4 | H8: 5 | I8: 6 | J8: 7 | K8: 8
D9: Test Year | F9: Company | G9: Transmission | H9: Distribution | I9: Metering | J9: T&D Customer | L9: Check
C10: Reference | D10: Total | E10: Company | F10: Total | G10: Function | H10: Function | I10: Function | J10: Service | K10: Total
A11: Line | B11: Description | C11: Schedule | D11: Electric | E11: Adjustments | F11: Request | G11: (TRAN) | H11: (DIST) | I11: (MET) | J11: (TDCS) | K11: TX-Retail
A12: No.
A14: 1 | B14: Operating and Maintenance, and A&G Expenses | C14: II-D-2 | D14: ='II-D-2 A&G'!E29-'II-D-2 A&G'!F31 -> 5.7351097e+08 | E14: =+F14-D14 -> -3.3130573e+08 | F14: ='II-D-2 A&G'!J29 -> 2.4220524e+08 | G14: ='II-D-2 A&G'!M29 -> 67024337 | H14: ='II-D-2 A&G'!N29 -> 1.31959e+08 | I14: ='II-D-2 A&G'!O29 -> 25903002 | J14: ='II-D-2 A&G'!P29 -> 17318896 | K14: =+SUM(H14:J14) -> 1.751809e+08 | L14: =K14+G14-F14 -> -0.020000041
A15: =+A14+1 -> 2 | B15: Depreciation & Amortization Expenses | C15: II-E-1 | D15: ='II-E-1 Dep. Exp.'!E68-'II-E-1 Dep. Exp.'!F68 -> 2.4188912e+08 | E15: =+F15-D15 -> 23130483 | F15: ='II-E-1 Dep. Exp.'!J68 -> 2.650196e+08 | G15: ='II-E-1 Dep. Exp.'!M68 -> 93376396 | H15: ='II-E-1 Dep. Exp.'!N68 -> 1.4027223e+08 | I15: ='II-E-1 Dep. Exp.'!O68 -> 31187220 | J15: ='II-E-1 Dep. Exp.'!P68 -> 183756.44 | K15: =+SUM(H15:J15) -> 1.7164321e+08 | L15: =K15+G15-F15 -> 0
A16: =+A15+1 -> 3 | B16: Taxes Other Than Federal Income Tax | C16: II-E-2 | D16: ='II-E-2 Taxes Other'!E41+'II-E-2 Taxes Other'!F41 -> 1.3034397e+08 | E16: =+F16-D16 -> 22441203 | F16: ='II-E-2 Taxes Other'!K41 -> 1.5278517e+08 | G16: ='II-E-2 Taxes Other'!N41 -> 47195345 | H16: ='II-E-2 Taxes Other'!O41 -> 1.0184134e+08 | I16: ='II-E-2 Taxes Other'!P41 -> 2894842 | J16: ='II-E-2 Taxes Other'!Q41 -> 853638.85 | K16: =+SUM(H16:J16) -> 1.0558982e+08 | L16: =K16+G16-F16 -> 0
A17: =+A16+1 -> 4 | B17: Federal Income Tax | C17: II-E-3 | D17: ='II-E-3 FIT'!E51 -> 56176858 | E17: =+F17-D17 -> -4681468 | F17: ='II-E-3 FIT'!J51 -> 51495390 | G17: ='II-E-3 FIT'!M51 -> 31504840 | H17: ='II-E-3 FIT'!N51 -> 18624105 | I17: ='II-E-3 FIT'!O51 -> 1211467 | J17: ='II-E-3 FIT'!P51 -> 154978 | K17: =+SUM(H17:J17) -> 19990550 | L17: =K17+G17-F17 -> 0
A18: =+A17+1 -> 5 | L18: =K18+G18-F18 -> 0
A19: =+A18+1 -> 6 | B19: Return on Rate Base | C19: II-B | D19: ='II-B'!D39 -> 4.2011268e+08 | E19: =+F19-D19 -> -61389678 | F19: ='II-B'!F39 -> 3.58723e+08 | G19: ='II-B'!G39 -> 1.8647719e+08 | H19: ='II-B'!H39 -> 1.6264276e+08 | I19: ='II-B'!I39 -> 8832868 | J19: ='II-B'!J39 -> 770176.56 | K19: =+SUM(H19:J19) -> 1.722458e+08 | L19: =K19+G19-F19 -> 0
A20: =+A19+1 -> 7 | L20: =K20+G20-F20 -> 0
A21: =+A20+1 -> 8 | B21: TOTAL COST OF SERVICE | D21: =SUM(D14:D20) -> 1.4220336e+09 | E21: =SUM(E14:E20) -> -3.5180519e+08 | F21: =SUM(F14:F20) -> 1.0702284e+09 | G21: =SUM(G14:G20) -> 4.2557811e+08 | H21: =SUM(H14:H20) -> 5.5533944e+08 | I21: =SUM(I14:I20) -> 70029399 | J21: =SUM(J14:J20) -> 19281446 | K21: =+SUM(H21:J21) -> 6.4465029e+08 | L21: =K21+G21-F21 -> -0.0200001
A22: =+A21+1 -> 9
A23: =+A22+1 -> 10 | B23: Decommissioning Expense | C23: II-E-4 | D23: 0 | E23: 0 | F23: 0 | G23: 0 | H23: 0 | K23: =+SUM(H23:J23) -> 0
A24: =+A23+1 -> 11 | K24: =+SUM(H24:J24) -> 0
A25: =+A24+1 -> 12 | K25: =+SUM(H25:J25) -> 0
A26: =+A25+1 -> 13 | K26: =+SUM(H26:J26) -> 0
A27: =+A26+1 -> 14 | B27: Minus: Other Revenues | C27: II-E-5 | D27: ='[10]I-A-1'!D27+'[9]I-A-1'!D27 -> -1.2831254e+09 | E27: ='[10]I-A-1'!E27+'[9]I-A-1'!E27 -> 1.2522659e+09 | F27: ='[10]I-A-1'!F27+'[9]I-A-1'!F27 -> -30859584 | G27: ='[10]I-A-1'!G27+'[9]I-A-1'!G27 -> -5364743.9 | H27: ='[10]I-A-1'!H27+'[9]I-A-1'!H27 -> -25302644 | I27: ='[10]I-A-1'!I27+'[9]I-A-1'!I27 -> -192196.48 | J27: ='[10]I-A-1'!J27+'[9]I-A-1'!J27 -> 0 | K27: =+SUM(H27:J27) -> -25494840 | L27: =K27+G27-F27 -> 0
A28: =+A27+1 -> 15
A29: =+A28+1 -> 16 | B29: TOTAL ADJUSTED REVENUE REQUIREMENT | D29: =SUM(D21:D27) -> 1.3890815e+08 | E29: =SUM(E21:E27) -> 9.0046067e+08 | F29: =SUM(F21:F27) -> 1.0393688e+09 | G29: =SUM(G21:G27) -> 4.2021337e+08 | H29: =SUM(H21:H27) -> 5.300368e+08 | I29: =SUM(I21:I27) -> 69837202 | J29: =SUM(J21:J27) -> 19281446 | K29: =SUM(K21:K27) -> 6.1915544e+08
A30: =+A29+1 -> 17
A31: =+A30+1 -> 18
A32: =+A31+1 -> 19
A33: =+A32+1 -> 20 | B33: TOTAL REVENUE REQUIREMENT FOR DISTRIBUTION ASSETS ONLY | H33: =SUM(H29:H32) -> 5.300368e+08 | I33: =SUM(I29:I32) -> 69837202 | J33: =SUM(J29:J32) -> 19281446 | K33: =+SUM(H33:J33) -> 6.1915544e+08
A34: =+A33+1 -> 21
A35: =+A34+1 -> 22 | K35: =+H35 -> 0
A36: =+A35+1 -> 23 | B36: TOTAL ADJUSTED REVENUE REQUIREMENT | D36: =SUM(D29:D35) -> 1.3890815e+08 | E36: =SUM(E29:E35) -> 9.0046067e+08 | F36: =SUM(F29:F35) -> 1.0393688e+09 | G36: =SUM(G29:G35) -> 4.2021337e+08 | H36: =SUM(H33:H35) -> 5.300368e+08 | I36: =SUM(I33:I35) -> 69837202 | J36: =SUM(J33:J35) -> 19281446 | K36: =SUM(H36:J36) -> 6.1915544e+08
F37: ='[10]I-A-1'!F37+'[9]I-A-1'!F36 -> 1.0393688e+09 | G37: ='[10]I-A-1'!G37+'[9]I-A-1'!G36 -> 4.2021337e+08 | H37: ='[10]I-A-1'!H37+'[9]I-A-1'!H36 -> 5.300368e+08 | I37: ='[10]I-A-1'!I37+'[9]I-A-1'!I36 -> 69837203 | J37: ='[10]I-A-1'!J37+'[9]I-A-1'!J36 -> 19281446 | K37: ='[10]I-A-1'!K37+'[9]I-A-1'!K36 -> 6.1915545e+08

Sheet I-A-2
B2: PUBLIC UTILITY COMMISSION OF TEXAS
B3: AEP TEXAS INC
B4: I-A-2 ADJUSTMENTS TO TEST YEAR
B5: TEST YEAR ENDING 12/31/2018
B10: Description | C10: Sched | D10: Workpaper
A11: Line | C11: I-A-1 | D11: Schedule | E11: Amount | F11: Witness
A12: No. | C12: Ref
A14: 1 | B14: O&M Expense
A15: =A14+1 -> 2
A16: =A15+1 -> 3 | B16: Expense amount, as adjusted by FERC Account:
A17: =A16+1 -> 4 | B17: 556 | C17: Line 1 | D17: WP II-D-1 | E17: -1.47 | F17: Please See Exhibit RWH-2 for the list of sponsoring witnesses
A18: =A17+1 -> 5 | B18: 560 | C18: Line 1 | D18: WP II-D-1 | E18: 16405039 | F18: Please See Exhibit RWH-2 for the list of sponsoring witnesses
A19: =A18+1 -> 6 | B19: 561 | C19: Line 1 | D19: WP II-D-1 | E19: 2855275.5 | F19: Please See Exhibit RWH-2 for the list of sponsoring witnesses
A20: =A19+1 -> 7 | B20: 562 | C20: Line 1 | D20: WP II-D-1 | E20: 838863.31 | F20: Please See Exhibit RWH-2 for the list of sponsoring witnesses
A21: =A20+1 -> 8 | B21: 563 | C21: Line 1 | D21: WP II-D-1 | E21: 607135.54 | F21: Please See Exhibit RWH-2 for the list of sponsoring witnesses
A22: =A21+1 -> 9 | B22: 565 | C22: Line 1 | D22: WP II-D-1 | E22: 0 | F22: Please See Exhibit RWH-2 for the list of sponsoring witnesses
A23: =A22+1 -> 10 | B23: 565 | C23: Line 1 | D23: WP II-D-1 | E23: 560180.51 | F23: Please See Exhibit RWH-2 for the list of sponsoring witnesses
A24: =A23+1 -> 11 | B24: 566 | C24: Line 1 | D24: WP II-D-1 | E24: 6405455.1 | F24: Please See Exhibit RWH-2 for the list of sponsoring witnesses
A25: =A24+1 -> 12 | B25: 567 | C25: Line 1 | D25: WP II-D-1 | E25: 2260064.6 | F25: Please See Exhibit RWH-2 for the list of sponsoring witnesses
A26: =A25+1 -> 13 | B26: 557 | C26: Line 1 | D26: WP II-D-1 | E26: -7191.61 | F26: Please See Exhibit RWH-2 for the list of sponsoring witnesses
A27: =A26+1 -> 14 | B27: 568 | C27: Line 1 | D27: WP II-D-1 | E27: 85370.202 | F27: Please See Exhibit RWH-2 for the list of sponsoring witnesses
A28: =A27+1 -> 15 | B28: 569 | C28: Line 1 | D28: WP II-D-1 | E28: 1518853 | F28: Please See Exhibit RWH-2 for the list of sponsoring witnesses
A29: =A28+1 -> 16 | B29: 570 | C29: Line 1 | D29: WP II-D-1 | E29: 6632854.4 | F29: Please See Exhibit RWH-2 for the list of sponsoring witnesses
A30: =A29+1 -> 17 | B30: 571 | C30: Line 1 | D30: WP II-D-1 | E30: 11547130 | F30: Please See Exhibit RWH-2 for the list of sponsoring witnesses
A31: =A30+1 -> 18 | B31: 572 | C31: Line 1 | D31: WP II-D-1 | E31: 1584.63 | F31: Please See Exhibit RWH-2 for the list of sponsoring witnesses
A32: =A31+1 -> 19 | B32: 573 | C32: Line 1 | D32: WP II-D-1 | E32: -19558.549 | F32: Please See Exhibit RWH-2 for the list of sponsoring witnesses
A33: =A32+1 -> 20 | B33: 580 | C33: Line 1 | D33: WP II-D-1 | E33: 7795705.8 | F33: Please See Exhibit RWH-2 for the list of sponsoring witnesses
A34: =A33+1 -> 21 | B34: 581 | C34: Line 1 | D34: WP II-D-1 | E34: 3556648.7 | F34: Please See Exhibit RWH-2 for the list of sponsoring witnesses
A35: =A34+1 -> 22 | B35: 582 | C35: Line 1 | D35: WP II-D-1 | E35: 1548391.2 | F35: Please See Exhibit RWH-2 for the list of sponsoring witnesses
A36: =A35+1 -> 23 | B36: 583 | C36: Line 1 | D36: WP II-D-1 | E36: 5876627.4 | F36: Please See Exhibit RWH-2 for the list of sponsoring witnesses
A37: =A36+1 -> 24 | B37: 584 | C37: Line 1 | D37: WP II-D-1 | E37: 1268562.8 | F37: Please See Exhibit RWH-2 for the list of sponsoring witnesses
A38: =A37+1 -> 25 | B38: 585 | C38: Line 1 | D38: WP II-D-1 | E38: 103205.15 | F38: Please See Exhibit RWH-2 for the list of sponsoring witnesses
A39: =A38+1 -> 26 | B39: 586 | C39: Line 1 | D39: WP II-D-1 | E39: 7427114.4 | F39: Please See Exhibit RWH-2 for the list of sponsoring witnesses
A40: =A39+1 -> 27 | B40: 587 | C40: Line 1 | D40: WP II-D-1 | E40: 1240621.7 | F40: Please See Exhibit RWH-2 for the list of sponsoring witnesses
A41: =A40+1 -> 28 | B41: 588 | C41: Line 1 | D41: WP II-D-1 | E41: 27904703 | F41: Please See Exhibit RWH-2 for the list of sponsoring witnesses
A42: =A41+1 -> 29 | B42: 589 | C42: Line 1 | D42: WP II-D-1 | E42: 2009215.5 | F42: Please See Exhibit RWH-2 for the list of sponsoring witnesses
A43: =A42+1 -> 30 | B43: 590 | C43: Line 1 | D43: WP II-D-1 | E43: 153114.44 | F43: Please See Exhibit RWH-2 for the list of sponsoring witnesses
A44: =A43+1 -> 31 | B44: 591 | C44: Line 1 | D44: WP II-D-1 | E44: 18936.124 | F44: Please See Exhibit RWH-2 for the list of sponsoring witnesses
A45: =A44+1 -> 32 | B45: 592 | C45: Line 1 | D45: WP II-D-1 | E45: 2625066.2 | F45: Please See Exhibit RWH-2 for the list of sponsoring witnesses
A46: =A45+1 -> 33 | B46: 593 | C46: Line 1 | D46: WP II-D-1 | E46: 46799475 | F46: Please See Exhibit RWH-2 for the list of sponsoring witnesses
...

Sheet II-B
K1: Schedule II-B
B2: PUBLIC UTILITY COMMISSION OF TEXAS
B3: AEP TEXAS INC
B4: II-B RATE BASE BY FUNCTION
B5: TEST YEAR ENDING 12/31/2018
B6: ='I-A'!B6
D8: 1 | E8: 2 | F8: 3 | G8: 4 | H8: 5 | I8: 6 | J8: 7 | K8: 8
D9: Test Year | F9: Company
C10: Reference | D10: Total | E10: Company | F10: Total | G10: TRAN | H10: DIST | I10: MET | J10: TDCS | K10: Total | L10: Check
A11: Line | B11: Description | C11: Schedule | D11: Electric | E11: Adjustments | F11: Request | K11: TX-Retail
A12: No.
A14: 1 | B14: Original Cost of Plant | C14: II-B-1 | D14: ='II-B-1 Plant'!E51-'II-B-1 Plant'!F51 -> 7.8651045e+09 | E14: =+F14-D14 -> -91588360 | F14: ='II-B-1 Plant'!J51 -> 7.7735162e+09 | G14: ='II-B-1 Plant'!M51 -> 3.7156586e+09 | H14: =+F14-G14-I14-J14 -> 3.8243995e+09 | I14: ='II-B-1 Plant'!O51 -> 2.3345323e+08 | J14: ='II-B-1 Plant'!P51 -> 4800.4855 | K14: =+SUM(H14:J14) -> 4.0578575e+09
A15: =+A14+1 -> 2 | B15: General Plant | C15: II-B-2 | D15: ='II-B-2 General Plant'!E31-'II-B-2 General Plant'!F31 -> 4.1291424e+08 | E15: =+F15-D15 -> 1258230.7 | F15: ='II-B-2 General Plant'!J31 -> 4.1417247e+08 | G15: ='II-B-2 General Plant'!M31 -> 1.4358583e+08 | H15: =+F15-G15-I15-J15 -> 2.5813457e+08 | I15: ='II-B-2 General Plant'!O31 -> 9638071.8 | J15: ='II-B-2 General Plant'!P31 -> 2813996.7 | K15: =+SUM(H15:J15) -> 2.7058664e+08
A16: =+A15+1 -> 3 | B16: Comm. Equipment | C16: II-B-3 | D16: ='II-B-3 Comm. Equip.'!E17-'II-B-3 Comm. Equip.'!F17 -> 1.2471037e+08 | E16: =+F16-D16 -> -1925527.1 | F16: ='II-B-3 Comm. Equip.'!J17 -> 1.2278485e+08 | G16: ='II-B-3 Comm. Equip.'!M17 -> 11247748 | H16: =+F16-G16-I16-J16 -> 95208035 | I16: ='II-B-3 Comm. Equip.'!O17 -> 16328967 | J16: ='II-B-3 Comm. Equip.'!P17 -> 97.082531 | K16: =+SUM(H16:J16) -> 1.115371e+08
A17: =+A16+1 -> 4 | B17: Total Plant | D17: =SUM(D14:D16) -> 8.4027291e+09 | E17: =SUM(E14:E16) -> -92255657 | F17: =SUM(F14:F16) -> 8.3104735e+09 | G17: =SUM(G14:G16) -> 3.8704922e+09 | H17: =SUM(H14:H16) -> 4.1777421e+09 | I17: =SUM(I14:I16) -> 2.5942027e+08 | J17: =SUM(J14:J16) -> 2818894.3 | K17: =SUM(K14:K16) -> 4.4399813e+09
A18: =+A17+1 -> 5
A19: =+A18+1 -> 6 | B19: Minus: Accumulated Depreciation | C19: II-B-5 | D19: =-'II-B-5 Depreciation'!E53-'II-B-5 Depreciation'!E80+'II-B-5 Depreciation'!F53+'II-B-5 Depreciation'!F80 -> -2.0915659e+09 | E19: =+F19-D19 -> 21158740 | F19: =-'II-B-5 Depreciation'!J53-'II-B-5 Depreciation'!J80 -> -2.0704071e+09 | G19: =-'II-B-5 Depreciation'!M53-'II-B-5 Depreciation'!M80 -> -5.9276057e+08 | H19: =+F19-G19-I19-J19 -> -1.3212813e+09 | I19: =-'II-B-5 Depreciation'!O53-'II-B-5 Depreciation'!O80 -> -1.557741e+08 | J19: =-'II-B-5 Depreciation'!P53-'II-B-5 Depreciation'!P80 -> -591110.36 | K19: =+SUM(H19:J19) -> -1.4776466e+09
A20: =+A19+1 -> 7 | B20: Net Plant In Service | D20: =SUM(D17:D19) -> 6.3111633e+09 | E20: =SUM(E17:E19) -> -71096917 | F20: =SUM(F17:F19) -> 6.2400664e+09 | G20: =SUM(G17:G19) -> 3.2777317e+09 | H20: =SUM(H17:H19) -> 2.8564608e+09 | I20: =SUM(I17:I19) -> 1.0364617e+08 | J20: =SUM(J17:J19) -> 2227784 | K20: =SUM(K17:K19) -> 2.9623347e+09
A21: =+A20+1 -> 8
A22: =+A21+1 -> 9 | B22: Other Rate Base Items:
A23: =+A22+1 -> 10 | B23: CWIP | C23: II-B-4 | D23: =+'II-B-4 CWIP'!E15-'II-B-4 CWIP'!F18 -> 8.3600397e+08 | E23: =+F23-D23 -> -8.3600397e+08 | F23: =+'II-B-4 CWIP'!H15 -> 0 | K23: =+SUM(H23:J23) -> 0
A24: =+A23+1 -> 11 | B24: Cash Working Capital | C24: II-B-9 | D24: ='II-B-9 CWCapital'!E21 -> 0 | E24: =+F24-D24 -> -22940282 | F24: =+'II-B-9 CWCapital'!J27 -> -22940282 | G24: =+'II-B-9 CWCapital'!M27 -> -16030645 | H24: =+'II-B-9 CWCapital'!N27 -> -5222388.9 | I24: =+'II-B-9 CWCapital'!O27 -> -1687248.9 | J24: =+'II-B-9 CWCapital'!P27 -> 0 | K24: =+SUM(H24:J24) -> -6909637.8
A25: =+A24+1 -> 12 | B25: Prepayments | C25: II-B-10 | D25: ='II-B-10 Prepayments'!E32-'II-B-10 Prepayments'!F32 -> 3321592.2 | E25: =+F25-D25 -> 83596897 | F25: ='II-B-10 Prepayments'!J34 -> 86918490 | G25: ='II-B-10 Prepayments'!M34 -> 7413933.4 | H25: =+F25-G25-I25-J25 -> 51592864 | I25: ='II-B-10 Prepayments'!O34 -> 15909433 | J25: ='II-B-10 Prepayments'!P34 -> 12002259 | K25: =+SUM(H25:J25) -> 79504556
A26: =+A25+1 -> 13 | B26: Materials & Supplies | C26: II-B-8 | D26: ='II-B-8 M&S'!E19-'II-B-8 M&S'!F19 -> 48920552 | E26: =+F26-D26 -> -1642649.5 | F26: ='II-B-8 M&S'!J21 -> 47277903 | G26: ='II-B-8 M&S'!M21 -> 15176994 | H26: =+F26-G26-I26-J26 -> 31038229 | I26: ='II-B-8 M&S'!O21 -> 1061695 | J26: ='II-B-8 M&S'!P21 -> 984.63864 | K26: =+SUM(H26:J26) -> 32100909
A27: =+A26+1 -> 14 | B27: Plant Held for Future Use | C27: II-B-6 | D27: ='II-B-6 Plant Future'!E19 -> 4941591.7 | E27: =+F27-D27 -> -1809575.7 | F27: ='II-B-6 Plant Future'!K16 -> 3132016 | H27: ='II-B-6 Plant Future'!M19 -> 3132016 | J27: 0 | K27: =+SUM(H27:J27) -> 3132016
A28: =+A27+1 -> 15 | B28: Accumulated Provisions and ADIT | C28: II-B-7 | D28: ='II-B-7 Accum. Provisions'!E21-'II-B-7 Accum. Provisions'!F21 -> -7.8247377e+08 | E28: =+F28-D28 -> 2718715.6 | F28: ='II-B-7 Accum. Provisions'!J23 -> -7.7975505e+08 | G28: ='II-B-7 Accum. Provisions'!M23 -> -3.5551501e+08 | H28: =+'II-B-7 Accum. Provisions'!N23 -> -3.9372002e+08 | I28: =+'II-B-7 Accum. Provisions'!O23 -> -26771625 | J28: =+'II-B-7 Accum. Provisions'!P23 -> -3748404.2 | K28: =+SUM(H28:J28) -> -4.2424004e+08
A29: =+A28+1 -> 16 | B29: Rate Base - Other | C29: II-B-11 | D29: ='II-B-11 Rate Base Other'!E26-'II-B-11 Rate Base Other'!F26 -> -7.2787606e+08 | E29: =+F29-D29 -> 1.413207e+08 | F29: ='II-B-11 Rate Base Other'!J26 -> -5.8655535e+08 | G29: ='II-B-11 Rate Base Other'!M26 -> -3.21874e+08 | H29: ='II-B-11 Rate Base Other'!N26 -> -2.5542378e+08 | I29: ='II-B-11 Rate Base Other'!O26 -> -9062766.8 | J29: ='II-B-11 Rate Base Other'!P26 -> -194805.38 | K29: =+SUM(H29:J29) -> -2.6468135e+08
A30: =+A29+1 -> 17 | B30: Regulatory Assets | C30: II-B-12 | D30: ='II-B-12 Reg. Assets'!E27 -> 2.4256073e+08 | E30: =+F30-D30 -> -1.6163311e+08 | F30: ='II-B-12 Reg. Assets'!J27 -> 80927618 | G30: ='II-B-12 Reg. Assets'!M27 -> 28183978 | H30: =+F30-G30-I30-J30 -> 10427639 | I30: ='II-B-12 Reg. Assets'!O27 -> 41720546 | J30: ='II-B-12 Reg. Assets'!P27 -> 595454.45 | K30: =+SUM(H30:J30) -> 52743639
A31: =+A30+1 -> 18
A32: =+A31+1 -> 19
A33: =+A32+1 -> 20 | B33: Subtotal | D33: =SUM(D23:D32) -> -3.7460139e+08 | E33: =SUM(E23:E32) -> -7.9639327e+08 | F33: =SUM(F23:F32) -> -1.1709947e+09 | G33: =SUM(G23:G32) -> -6.4264475e+08 | H33: =SUM(H23:H32) -> -5.5817543e+08 | I33: =SUM(I23:I32) -> 21170033 | J33: =SUM(J23:J32) -> 8655488.8 | K33: =SUM(K23:K32) -> -5.2834991e+08
A34: =+A33+1 -> 21
A35: =+A34+1 -> 22 | B35: TOTAL RATE BASE | D35: =D33+D20 -> 5.9365619e+09 | E35: =E33+E20 -> -8.6749019e+08 | F35: =F33+F20 -> 5.0690717e+09 | G35: =G33+G20 -> 2.6350869e+09 | H35: =H33+H20 -> 2.2982853e+09 | I35: =I33+I20 -> 1.248162e+08 | J35: =J33+J20 -> 10883273 | K35: =K33+K20 -> 2.4339848e+09
A36: =+A35+1 -> 23
A37: =+A36+1 -> 24 | B37: Rate of Return | D37: ='II-C-2.1'!$G$25 -> 0.070767 | F37: ='II-C-2.1'!$G$25 -> 0.070767 | G37: ='II-C-2.1'!$G$25 -> 0.070767 | H37: ='II-C-2.1'!$G$25 -> 0.070767 | I37: ='II-C-2.1'!$G$25 -> 0.070767 | J37: ='II-C-2.1'!$G$25 -> 0.070767
A38: =+A37+1 -> 25
A39: =+A38+1 -> 26 | B39: RETURN ON RATE BASE | D39: =+D35*D37 -> 4.2011268e+08 | F39: =+F35*F37 -> 3.58723e+08 | G39: =+G35*G37 -> 1.8647719e+08 | H39: =+H35*H37 -> 1.6264276e+08 | I39: =+I35*I37 -> 8832868 | J39: =+J35*J37 -> 770176.56 | K39: =+SUM(H39:J39) -> 1.722458e+08

Sheet II-B-1 Plant
B2: PUBLIC UTILITY COMMISSION OF TEXAS
B3: AEP TEXAS INC
B4: II-B-1 ORIGINAL COST OF UTILITY PLANT
B5: TEST YEAR ENDING 12/31/2018
B6: ='I-A'!B6
E8: 1 | F8: 2 | G8: 3 | H8: 4 | I8: 5 | J8: 6 | K8: 7 | L8: 8 | M8: 9 | N8: 10 | O8: 11 | P8: 12 | Q8: 13
H9: Company | I9: Texas
B10: Account | C10: Description | D10: Reference | E10: Total | F10: Non-Regulated | G10: Known | H10: Total | I10: Retail | J10: Allocation to | K10: FF | L10: Functionalization | M10: TRAN | N10: DIST | O10: MET | P10: TDCS | Q10: Total
A11: Line | B11: Number | D11: Schedule | E11: Company | F11: or | G11: Change | H11: Electric | I11: Allocation | J11: Texas | K11: # | L11: Factor | R11: CHECK
A12: No. | F12: Non-Electric | I12: Factor | L12: Name
A14: 1 | B14: Intangible Plant-Gross | D14: II-B-1
A15: =+A14+1 -> 2 | B15: A301 | C15: Organization | E15: ='[10]II-B-1 Plant'!E15+'[9]II-B-1 Plant'!E15 -> 21967.68 | F15: ='[10]II-B-1 Plant'!F15+'[9]II-B-1 Plant'!F15 -> 1731.05 | G15: ='[10]II-B-1 Plant'!G15+'[9]II-B-1 Plant'!G15 -> 0 | H15: =+E15-F15+G15 -> 20236.63 | I15: 1 | J15: =+I15*H15 -> 20236.63 | K15: 25 | L15: TOTREV | M15: ='[10]II-B-1 Plant'!M15+'[9]II-B-1 Plant'!M15 -> 2113.29 | N15: ='[10]II-B-1 Plant'!N15+'[9]II-B-1 Plant'!N15 -> 15244.304 | O15: ='[10]II-B-1 Plant'!O15+'[9]II-B-1 Plant'!O15 -> 2457.0266 | P15: ='[10]II-B-1 Plant'!P15+'[9]II-B-1 Plant'!P15 -> 422.00911 | Q15: =+SUM(M15:P15) -> 20236.63
A16: =+A15+1 -> 3 | B16: A302 | C16: Franchise & Consents | E16: ='[10]II-B-1 Plant'!E16+'[9]II-B-1 Plant'!E16 -> 0 | F16: ='[10]II-B-1 Plant'!F16+'[9]II-B-1 Plant'!F16 -> 0 | G16: ='[10]II-B-1 Plant'!G16+'[9]II-B-1 Plant'!G16 -> 0 | H16: =+E16-F16+G16 -> 0 | I16: 1 | J16: =+I16*H16 -> 0 | K16: 25 | L16: TOTREV | M16: ='[10]II-B-1 Plant'!M16+'[9]II-B-1 Plant'!M16 -> 0 | N16: ='[10]II-B-1 Plant'!N16+'[9]II-B-1 Plant'!N16 -> 0 | O16: ='[10]II-B-1 Plant'!O16+'[9]II-B-1 Plant'!O16 -> 0 | P16: ='[10]II-B-1 Plant'!P16+'[9]II-B-1 Plant'!P16 -> 0 | Q16: =+SUM(M16:P16) -> 0
A17: =+A16+1 -> 4 | B17: A303 | C17: Miscellaneous Intangible Plant | E17: ='[10]II-B-1 Plant'!E17+'[9]II-B-1 Plant'!E17 -> 1.4393051e+08 | F17: ='[10]II-B-1 Plant'!F17+'[9]II-B-1 Plant'!F17 -> 545799.06 | G17: ='[10]II-B-1 Plant'!G17+'[9]II-B-1 Plant'!G17 -> 0 | H17: =+E17-F17+G17 -> 1.4338471e+08 | I17: 1 | J17: =SUM((H17-M17)*I17)+M17 -> 1.4338471e+08 | K17: 29/20 | L17: DIRECT/DPLTSVC-NX | M17: ='[10]II-B-1 Plant'!M17+'[9]II-B-1 Plant'!M17 -> 37599009 | N17: ='[10]II-B-1 Plant'!N17+'[9]II-B-1 Plant'!N17 -> 1.0213767e+08 | O17: ='[10]II-B-1 Plant'!O17+'[9]II-B-1 Plant'!O17 -> 3643656.7 | P17: ='[10]II-B-1 Plant'!P17+'[9]II-B-1 Plant'!P17 -> 4378.4764 | Q17: =+SUM(M17:P17) -> 1.4338471e+08
A18: =+A17+1 -> 5 | C18: Subtotal | E18: =+SUM(E15:E17) -> 1.4395248e+08 | F18: =+SUM(F15:F17) -> 547530.11 | G18: =+SUM(G15:G17) -> 0 | H18: =+SUM(H15:H17) -> 1.4340495e+08 | J18: =SUM(J15:J17) -> 1.4340495e+08 | M18: =+SUM(M15:M17) -> 37601122 | N18: =+SUM(N15:N17) -> 1.0215291e+08 | O18: =+SUM(O15:O17) -> 3646113.7 | P18: =+SUM(P15:P17) -> 4800.4855 | Q18: =+SUM(Q15:Q17) -> 1.4340495e+08
A19: =+A18+1 -> 6
A20: =+A19+1 -> 7 | B20: Transmission Plant-Gross | D20: II-B-1
A21: =+A20+1 -> 8 | B21: A349 | C21: Land Owned in Fee | E21: ='[9]II-B-1 Plant'!E21 -> 0 | F21: ='[9]II-B-1 Plant'!F21 -> 0 | G21: ='[9]II-B-1 Plant'!G21 -> 0 | H21: =+E21-F21+G21 -> 0 | J21: =+I21*H21 -> 0 | K21: 29 | L21: DIRECT | M21: ='[9]II-B-1 Plant'!M21 -> 0 | N21: ='[9]II-B-1 Plant'!N21 -> 0 | O21: ='[9]II-B-1 Plant'!O21 -> 0 | P21: ='[9]II-B-1 Plant'!P21 -> 0 | Q21: =+SUM(M21:P21) -> 0
A22: =+A21+1 -> 9 | B22: A350 | C22: Land and Land Rights | E22: ='[10]II-B-1 Plant'!E21+'[10]II-B-1 Plant'!E22+'[9]II-B-1 Plant'!E22 -> 1.0721588e+08 | F22: ='[10]II-B-1 Plant'!F21+'[10]II-B-1 Plant'!F22+'[9]II-B-1 Plant'!F22 -> 0 | G22: ='[10]II-B-1 Plant'!G21+'[10]II-B-1 Plant'!G22+'[9]II-B-1 Plant'!G22 -> -2865367.4 | H22: =+E22-F22+G22 -> 1.0435051e+08 | I22: 1 | J22: =SUM((H22-M22)*I22)+M22 -> 1.0435051e+08 | K22: 29 | L22: DIRECT | M22: ='[10]II-B-1 Plant'!M21+'[10]II-B-1 Plant'!M22+'[9]II-B-1 Plant'!M22 -> 1.0435051e+08 | N22: ='[10]II-B-1 Plant'!N21+'[10]II-B-1 Plant'!N22+'[9]II-B-1 Plant'!N22 -> -1.3969839e-09 | O22: ='[10]II-B-1 Plant'!O21+'[10]II-B-1 Plant'!O22+'[9]II-B-1 Plant'!O22 -> 0 | P22: ='[10]II-B-1 Plant'!P21+'[10]II-B-1 Plant'!P22+'[9]II-B-1 Plant'!P22 -> 0 | Q22: =+SUM(M22:P22) -> 1.0435051e+08
A23: =+A22+1 -> 10 | B23: A352 | C23: Structures and Improvements | E23: ='[10]II-B-1 Plant'!E23+'[9]II-B-1 Plant'!E23 -> 57812679 | F23: ='[10]II-B-1 Plant'!F23+'[9]II-B-1 Plant'!F23 -> 0 | G23: ='[10]II-B-1 Plant'!G23+'[9]II-B-1 Plant'!G23 -> -57283.7 | H23: =+E23-F23+G23 -> 57755396 | I23: 1 | J23: =SUM((H23-M23)*I23)+M23 -> 57755396 | K23: 29 | L23: DIRECT | M23: ='[10]II-B-1 Plant'!M23+'[9]II-B-1 Plant'!M23 -> 57755396 | N23: ='[10]II-B-1 Plant'!N23+'[9]II-B-1 Plant'!N23 -> 0 | O23: ='[10]II-B-1 Plant'!O23+'[9]II-B-1 Plant'!O23 -> 0 | P23: ='[10]II-B-1 Plant'!P23+'[9]II-B-1 Plant'!P23 -> 0 | Q23: =+SUM(M23:P23) -> 57755396
A24: =+A23+1 -> 11 | B24: A353 | C24: Station Equipment | E24: ='[10]II-B-1 Plant'!E24+'[9]II-B-1 Plant'!E24 -> 1.8046015e+09 | F24: ='[10]II-B-1 Plant'!F24+'[9]II-B-1 Plant'!F24 -> 238419.99 | G24: ='[10]II-B-1 Plant'!G24+'[9]II-B-1 Plant'!G24 -> -2088112.7 | H24: =+E24-F24+G24 -> 1.802275e+09 | I24: 1 | J24: =SUM((H24-M24)*I24)+M24 -> 1.802275e+09 | K24: 29 | L24: DIRECT | M24: ='[10]II-B-1 Plant'!M24+'[9]II-B-1 Plant'!M24 -> 1.802275e+09 | N24: ='[10]II-B-1 Plant'!N24+'[9]II-B-1 Plant'!N24 -> -2.3841858e-07 | O24: ='[10]II-B-1 Plant'!O24+'[9]II-B-1 Plant'!O24 -> 0 | P24: ='[10]II-B-1 Plant'!P24+'[9]II-B-1 Plant'!P24 -> 0 | Q24: =+SUM(M24:P24) -> 1.802275e+09
A25: =+A24+1 -> 12 | B25: A354 | C25: Towers and Fixtures | E25: ='[10]II-B-1 Plant'!E25+'[9]II-B-1 Plant'!E25 -> 49999122 | F25: ='[10]II-B-1 Plant'!F25+'[9]II-B-1 Plant'!F25 -> 0 | G25: ='[10]II-B-1 Plant'!G25+'[9]II-B-1 Plant'!G25 -> 5744.77 | H25: =+E25-F25+G25 -> 50004867 | I25: 1 | J25: =SUM((H25-M25)*I25)+M25 -> 50004867 | K25: 29 | L25: DIRECT | M25: ='[10]II-B-1 Plant'!M25+'[9]II-B-1 Plant'!M25 -> 50004867 | N25: ='[10]II-B-1 Plant'!N25+'[9]II-B-1 Plant'!N25 -> 0 | O25: ='[10]II-B-1 Plant'!O25+'[9]II-B-1 Plant'!O25 -> 0 | P25: ='[10]II-B-1 Plant'!P25+'[9]II-B-1 Plant'!P25 -> 0 | Q25: =+SUM(M25:P25) -> 50004867
A26: =+A25+1 -> 13 | B26: A355 | C26: Poles and Fixtures | E26: ='[10]II-B-1 Plant'!E26+'[9]II-B-1 Plant'!E26 -> 9.370228e+08 | F26: ='[10]II-B-1 Plant'!F26+'[9]II-B-1 Plant'!F26 -> 0 | G26: ='[10]II-B-1 Plant'!G26+'[9]II-B-1 Plant'!G26 -> -333289.99 | H26: =+E26-F26+G26 -> 9.3668951e+08 | I26: 1 | J26: =SUM((H26-M26)*I26)+M26 -> 9.3668951e+08 | K26: 29 | L26: DIRECT | M26: ='[10]II-B-1 Plant'!M26+'[9]II-B-1 Plant'!M26 -> 9.3668951e+08 | N26: ='[10]II-B-1 Plant'!N26+'[9]II-B-1 Plant'!N26 -> 0 | O26: ='[10]II-B-1 Plant'!O26+'[9]II-B-1 Plant'!O26 -> 0 | P26: ='[10]II-B-1 Plant'!P26+'[9]II-B-1 Plant'!P26 -> 0 | Q26: =+SUM(M26:P26) -> 9.3668951e+08
A27: =+A26+1 -> 14 | B27: A356 | C27: O.H. Conductors & Devices | E27: ='[10]II-B-1 Plant'!E27+'[9]II-B-1 Plant'!E27 -> 6.9705641e+08 | F27: ='[10]II-B-1 Plant'!F27+'[9]II-B-1 Plant'!F27 -> 0 | G27: ='[10]II-B-1 Plant'!G27+'[9]II-B-1 Plant'!G27 -> -54296.42 | H27: =+E27-F27+G27 -> 6.9700211e+08 | I27: 1 | J27: =SUM((H27-M27)*I27)+M27 -> 6.9700211e+08 | K27: 29 | L27: DIRECT | M27: ='[10]II-B-1 Plant'!M27+'[9]II-B-1 Plant'!M27 -> 6.9700211e+08 | N27: ='[10]II-B-1 Plant'!N27+'[9]II-B-1 Plant'!N27 -> 0 | O27: ='[10]II-B-1 Plant'!O27+'[9]II-B-1 Plant'!O27 -> 0 | P27: ='[10]II-B-1 Plant'!P27+'[9]II-B-1 Plant'!P27 -> 0 | Q27: =+SUM(M27:P27) -> 6.9700211e+08
A28: =+A27+1 -> 15 | B28: A357 | C28: Undergound Conduit | E28: ='[10]II-B-1 Plant'!E28+'[9]II-B-1 Plant'!E28 -> 4836777 | F28: ='[10]II-B-1 Plant'!F28+'[9]II-B-1 Plant'!F28 -> 0 | G28: ='[10]II-B-1 Plant'!G28+'[9]II-B-1 Plant'!G28 -> 0 | H28: =+E28-F28+G28 -> 4836777 | I28: 1 | J28: =SUM((H28-M28)*I28)+M28 -> 4836777 | K28: 29 | L28: DIRECT | M28: ='[10]II-B-1 Plant'!M28+'[9]II-B-1 Plant'!M28 -> 4836777 | N28: ='[10]II-B-1 Plant'!N28+'[9]II-B-1 Plant'!N28 -> 0 | O28: ='[10]II-B-1 Plant'!O28+'[9]II-B-1 Plant'!O28 -> 0 | P28: ='[10]II-B-1 Plant'!P28+'[9]II-B-1 Plant'!P28 -> 0 | Q28: =+SUM(M28:P28) -> 4836777
A29: =+A28+1 -> 16 | B29: A358 | C29: Underground Conductors | E29: ='[10]II-B-1 Plant'!E29+'[9]II-B-1 Plant'!E29 -> 25088976 | F29: ='[10]II-B-1 Plant'!F29+'[9]II-B-1 Plant'!F29 -> 0 | G29: ='[10]II-B-1 Plant'!G29+'[9]II-B-1 Plant'!G29 -> 0 | H29: =+E29-F29+G29 -> 25088976 | I29: 1 | J29: =SUM((H29-M29)*I29)+M29 -> 25088976 | K29: 29 | L29: DIRECT | M29: ='[10]II-B-1 Plant'!M29+'[9]II-B-1 Plant'!M29 -> 25088976 | N29: ='[10]II-B-1 Plant'!N29+'[9]II-B-1 Plant'!N29 -> 0 | O29: ='[10]II-B-1 Plant'!O29+'[9]II-B-1 Plant'!O29 -> 0 | P29: ='[10]II-B-1 Plant'!P29+'[9]II-B-1 Plant'!P29 -> 0 | Q29: =+SUM(M29:P29) -> 25088976
A30: =+A29+1 -> 17 | B30: A359 | C30: Roads and Trails | E30: ='[10]II-B-1 Plant'!E30+'[9]II-B-1 Plant'!E30 -> 54376.24 | F30: ='[10]II-B-1 Plant'!F30+'[9]II-B-1 Plant'!F30 -> 0 | G30: ='[10]II-B-1 Plant'!G30+'[9]II-B-1 Plant'!G30 -> 0 | H30: =+E30-F30+G30 -> 54376.24 | I30: 1 | J30: =SUM((H30-M30)*I30)+M30 -> 54376.24 | K30: 29 | L30: DIRECT | M30: ='[10]II-B-1 Plant'!M30+'[9]II-B-1 Plant'!M30 -> 54376.24 | N30: ='[10]II-B-1 Plant'!N30+'[9]II-B-1 Plant'!N30 -> 0 | O30: ='[10]II-B-1 Plant'!O30+'[9]II-B-1 Plant'!O30 -> 0 | P30: ='[10]II-B-1 Plant'!P30+'[9]II-B-1 Plant'!P30 -> 0 | Q30: =+SUM(M30:P30) -> 54376.24
A31: =+A30+1 -> 18 | C31: Subtotal | E31: =SUM(E21:E30) -> 3.6836885e+09 | F31: =SUM(F21:F30) -> 238419.99 | G31: =SUM(G21:G30) -> -5392605.5 | H31: =SUM(H21:H30) -> 3.6780575e+09 | J31: =SUM(J21:J30) -> 3.6780575e+09 | M31: =SUM(M21:M30) -> 3.6780575e+09 | N31: =SUM(N21:N30) -> -2.3981556e-07 | O31: =SUM(O21:O30) -> 0 | P31: =SUM(P21:P30) -> 0 | Q31: =SUM(Q21:Q30) -> 3.6780575e+09
A32: =+A31+1 -> 19
A33: =+A32+1 -> 20 | B33: Distribution Plant-Gross | D33: II-B-1
A34: =+A33+1 -> 21 | B34: A360 | C34: Land and Land Rights | E34: ='[10]II-B-1 Plant'!E34+'[9]II-B-1 Plant'!E34 -> 23099513 | F34: ='[10]II-B-1 Plant'!F34+'[9]II-B-1 Plant'!F34 -> 0 | G34: ='[10]II-B-1 Plant'!G34+'[9]II-B-1 Plant'!G34 -> 0 | H34: =+E34-F34+G34 -> 23099513 | I34: 1 | J34: =SUM((H34-M34)*I34)+M34 -> 23099513 | K34: 29 | L34: DIRECT | M34: ='[10]II-B-1 Plant'!M34+'[9]II-B-1 Plant'!M34 -> 0 | N34: ='[10]II-B-1 Plant'!N34+'[9]II-B-1 Plant'!N34 -> 23099513 | O34: ='[10]II-B-1 Plant'!O34+'[9]II-B-1 Plant'!O34 -> 0 | P34: ='[10]II-B-1 Plant'!P34+'[9]II-B-1 Plant'!P34 -> 0 | Q34: =+SUM(M34:P34) -> 23099513
A35: =+A34+1 -> 22 | B35: A361 | C35: Structures and Improvements | E35: ='[10]II-B-1 Plant'!E35+'[9]II-B-1 Plant'!E35 -> 19700103 | F35: ='[10]II-B-1 Plant'!F35+'[9]II-B-1 Plant'!F35 -> 0 | G35: ='[10]II-B-1 Plant'!G35+'[9]II-B-1 Plant'!G35 -> -2149571.1 | H35: =+E35-F35+G35 -> 17550532 | I35: 1 | J35: =SUM((H35-M35)*I35)+M35 -> 17550532 | K35: 29 | L35: DIRECT | M35: ='[10]II-B-1 Plant'!M35+'[9]II-B-1 Plant'!M35 -> 0 | N35: ='[10]II-B-1 Plant'!N35+'[9]II-B-1 Plant'!N35 -> 17550532 | O35: ='[10]II-B-1 Plant'!O35+'[9]II-B-1 Plant'!O35 -> 0 | P35: ='[10]II-B-1 Plant'!P35+'[9]II-B-1 Plant'!P35 -> 0 | Q35: =+SUM(M35:P35) -> 17550532
A36: =+A35+1 -> 23 | B36: A362 | C36: Station Equipment | E36: ='[10]II-B-1 Plant'!E36+'[9]II-B-1 Plant'!E36 -> 5.5331907e+08 | F36: ='[10]II-B-1 Plant'!F36+'[9]II-B-1 Plant'!F36 -> 0 | G36: ='[10]II-B-1 Plant'!G36+'[9]II-B-1 Plant'!G36 -> -5175555.2 | H36: =+E36-F36+G36 -> 5.4814351e+08 | I36: 1 | J36: =SUM((H36-M36)*I36)+M36 -> 5.4814351e+08 | K36: 29 | L36: DIRECT | M36: ='[10]II-B-1 Plant'!M36+'[9]II-B-1 Plant'!M36 -> 0 | N36: ='[10]II-B-1 Plant'!N36+'[9]II-B-1 Plant'!N36 -> 5.4814351e+08 | O36: ='[10]II-B-1 Plant'!O36+'[9]II-B-1 Plant'!O36 -> 0 | P36: ='[10]II-B-1 Plant'!P36+'[9]II-B-1 Plant'!P36 -> 0 | Q36: =+SUM(M36:P36) -> 5.4814351e+08
A37: =+A36+1 -> 24 | B37: A363 | C37: Storage Battery Equipment | E37: ='[10]II-B-1 Plant'!E37+'[9]II-B-1 Plant'!E37 -> 0 | F37: ='[10]II-B-1 Plant'!F37+'[9]II-B-1 Plant'!F37 -> 0 | G37: ='[10]II-B-1 Plant'!G37+'[9]II-B-1 Plant'!G37 -> 0 | H37: =+E37-F37+G37 -> 0 | J37: =SUM((H37-M37)*I37)+M37 -> 0 | K37: 29 | L37: DIRECT | M37: ='[10]II-B-1 Plant'!M37+'[9]II-B-1 Plant'!M37 -> 0 | N37: ='[10]II-B-1 Plant'!N37+'[9]II-B-1 Plant'!N37 -> 0 | O37: ='[10]II-B-1 Plant'!O37+'[9]II-B-1 Plant'!O37 -> 0 | P37: ='[10]II-B-1 Plant'!P37+'[9]II-B-1 Plant'!P37 -> 0 | Q37: =+SUM(M37:P37) -> 0
A38: =+A37+1 -> 25 | B38: A364 | C38: Poles,Towers & Fixtures-Primary | E38: ='[10]II-B-1 Plant'!E38+'[9]II-B-1 Plant'!E38 -> 8.5231111e+08 | F38: ='[10]II-B-1 Plant'!F38+'[9]II-B-1 Plant'!F38 -> 0 | G38: ='[10]II-B-1 Plant'!G38+'[9]II-B-1 Plant'!G38 -> -40944570 | H38: =+E38-F38+G38 -> 8.1136654e+08 | I38: 1 | J38: =SUM((H38-M38)*I38)+M38 -> 8.1136654e+08 | K38: 29 | L38: DIRECT | M38: ='[10]II-B-1 Plant'!M38+'[9]II-B-1 Plant'!M38 -> 0 | N38: ='[10]II-B-1 Plant'!N38+'[9]II-B-1 Plant'!N38 -> 8.1136654e+08 | O38: ='[10]II-B-1 Plant'!O38+'[9]II-B-1 Plant'!O38 -> 0 | P38: ='[10]II-B-1 Plant'!P38+'[9]II-B-1 Plant'!P38 -> 0 | Q38: =+SUM(M38:P38) -> 8.1136654e+08
A39: =+A38+1 -> 26 | B39: A365 | C39: O.H. Conductors & Devices-Primary | E39: ='[10]II-B-1 Plant'!E39+'[9]II-B-1 Plant'!E39 -> 7.4906994e+08 | F39: ='[10]II-B-1 Plant'!F39+'[9]II-B-1 Plant'!F39 -> 0 | G39: ='[10]II-B-1 Plant'!G39+'[9]II-B-1 Plant'!G39 -> -29081166 | H39: =+E39-F39+G39 -> 7.1998877e+08 | I39: 1 | J39: =SUM((H39-M39)*I39)+M39 -> 7.1998877e+08 | K39: 29 | L39: DIRECT | M39: ='[10]II-B-1 Plant'!M39+'[9]II-B-1 Plant'!M39 -> 0 | N39: ='[10]II-B-1 Plant'!N39+'[9]II-B-1 Plant'!N39 -> 7.1998877e+08 | O39: ='[10]II-B-1 Plant'!O39+'[9]II-B-1 Plant'!O39 -> 0 | P39: ='[10]II-B-1 Plant'!P39+'[9]II-B-1 Plant'!P39 -> 0 | Q39: =+SUM(M39:P39) -> 7.1998877e+08
A40: =+A39+1 -> 27 | B40: A366 | C40: Underground Conduits-Primary | E40: ='[10]II-B-1 Plant'!E40+'[9]II-B-1 Plant'!E40 -> 81076082 | F40: ='[10]II-B-1 Plant'!F40+'[9]II-B-1 Plant'!F40 -> 0 | G40: ='[10]II-B-1 Plant'!G40+'[9]II-B-1 Plant'!G40 -> -236447.67 | H40: =+E40-F40+G40 -> 80839635 | I40: 1 | J40: =SUM((H40-M40)*I40)+M40 -> 80839635 | K40: 29 | L40: DIRECT | M40: ='[10]II-B-1 Plant'!M40+'[9]II-B-1 Plant'!M40 -> 0 | N40: ='[10]II-B-1 Plant'!N40+'[9]II-B-1 Plant'!N40 -> 80839635 | O40: ='[10]II-B-1 Plant'!O40+'[9]II-B-1 Plant'!O40 -> 0 | P40: ='[10]II-B-1 Plant'!P40+'[9]II-B-1 Plant'!P40 -> 0 | Q40: =+SUM(M40:P40) -> 80839635
A41: =+A40+1 -> 28 | B41: A367 | C41: U.G. Conductors & Devices-Primary | E41: ='[10]II-B-1 Plant'!E41+'[9]II-B-1 Plant'!E41 -> 3.4829801e+08 | F41: ='[10]II-B-1 Plant'!F41+'[9]II-B-1 Plant'!F41 -> 0 | G41: ='[10]II-B-1 Plant'!G41+'[9]II-B-1 Plant'!G41 -> -2088447.6 | H41: =+E41-F41+G41 -> 3.4620957e+08 | I41: 1 | J41: =SUM((H41-M41)*I41)+M41 -> 3.4620957e+08 | K41: 29 | L41: DIRECT | M41: ='[10]II-B-1 Plant'!M41+'[9]II-B-1 Plant'!M41 -> 0 | N41: ='[10]II-B-1 Plant'!N41+'[9]II-B-1 Plant'!N41 -> 3.4620957e+08 | O41: ='[10]II-B-1 Plant'!O41+'[9]II-B-1 Plant'!O41 -> 0 | P41: ='[10]II-B-1 Plant'!P41+'[9]II-B-1 Plant'!P41 -> 0 | Q41: =+SUM(M41:P41) -> 3.4620957e+08
A42: =+A41+1 -> 29 | B42: A368 | C42: Line Transformers-Primary | E42: ='[10]II-B-1 Plant'!E42+'[9]II-B-1 Plant'!E42 -> 6.9968632e+08 | F42: ='[10]II-B-1 Plant'!F42+'[9]II-B-1 Plant'!F42 -> 0 | G42: ='[10]II-B-1 Plant'!G42+'[9]II-B-1 Plant'!G42 -> -1941889 | H42: =+E42-F42+G42 -> 6.9774443e+08 | I42: 1 | J42: =SUM((H42-M42)*I42)+M42 -> 6.9774443e+08 | K42: 29 | L42: DIRECT | M42: ='[10]II-B-1 Plant'!M42+'[9]II-B-1 Plant'!M42 -> 0 | N42: ='[10]II-B-1 Plant'!N42+'[9]II-B-1 Plant'!N42 -> 6.9774443e+08 | O42: ='[10]II-B-1 Plant'!O42+'[9]II-B-1 Plant'!O42 -> 0 | P42: ='[10]II-B-1 Plant'!P42+'[9]II-B-1 Plant'!P42 -> 0 | Q42: =+SUM(M42:P42) -> 6.9774443e+08
A43: =+A42+1 -> 30 | B43: A369 | C43: Services | E43: ='[10]II-B-1 Plant'!E43+'[9]II-B-1 Plant'!E43 -> 3.0381696e+08 | F43: ='[10]II-B-1 Plant'!F43+'[9]II-B-1 Plant'!F43 -> 0 | G43: ='[10]II-B-1 Plant'!G43+'[9]II-B-1 Plant'!G43 -> -42596.366 | H43: =+E43-F43+G43 -> 3.0377436e+08 | I43: 1 | J43: =SUM((H43-M43)*I43)+M43 -> 3.0377436e+08 | K43: 29 | L43: DIRECT | M43: ='[10]II-B-1 Plant'!M43+'[9]II-B-1 Plant'!M43 -> 0 | N43: ='[10]II-B-1 Plant'!N43+'[9]II-B-1 Plant'!N43 -> 3.0377436e+08 | O43: ='[10]II-B-1 Plant'!O43+'[9]II-B-1 Plant'!O43 -> 0 | P43: ='[10]II-B-1 Plant'!P43+'[9]II-B-1 Plant'!P43 -> 0 | Q43: =+SUM(M43:P43) -> 3.0377436e+08
...

Sheet II-B-2 General Plant
B2: PUBLIC UTILITY COMMISSION OF TEXAS
B3: AEP TEXAS INC
B4: II-B-2 GENERAL PLANT FUNCTIONALIZATION
B5: TEST YEAR ENDING 12/31/2018
B6: ='I-A'!B6
E8: 1 | F8: 2 | G8: 3 | H8: 4 | I8: 5 | J8: 6 | K8: 7 | L8: 8 | M8: 9 | N8: 10 | O8: 11 | P8: 12 | Q8: 13
H9: Company | I9: Texas
B10: Account | C10: Description | D10: Reference | E10: Total | F10: Non-Regulated | G10: Known | H10: Total | I10: Retail | J10: Allocation to | K10: FF | L10: Funct | M10: TRAN | N10: DIST | O10: MET | P10: TDCS | Q10: Total
A11: Line | B11: Number | D11: Schedule | E11: Company | F11: or | G11: Change | H11: Electric | I11: Allocation | J11: Texas | K11: # | L11: Factor | R11: CHECK
A12: No. | F12: Non-Electric | I12: Factor | L12: Name
A14: 1 | B14: General Plant-Gross | D14: II-B-2
A15: =+A14+1 -> 2 | B15: A388 | C15: Land Owned in Fee | E15: ='[10]II-B-2 General Plant'!E15+'[9]II-B-2 General Plant'!E15 -> 0 | F15: ='[10]II-B-2 General Plant'!F15+'[9]II-B-2 General Plant'!F15 -> 0 | G15: ='[10]II-B-2 General Plant'!G15+'[9]II-B-2 General Plant'!G15 -> 0 | H15: =+E15-F15+G15 -> 0 | I15: 0 | J15: =+I15*H15 -> 0 | M15: ='[10]II-B-2 General Plant'!M15+'[9]II-B-2 General Plant'!M15 -> 0 | N15: ='[10]II-B-2 General Plant'!N15+'[9]II-B-2 General Plant'!N15 -> 0 | O15: ='[10]II-B-2 General Plant'!O15+'[9]II-B-2 General Plant'!O15 -> 0 | P15: ='[10]II-B-2 General Plant'!P15+'[9]II-B-2 General Plant'!P15 -> 0 | Q15: =+SUM(M15:P15) -> 0
A16: =+A15+1 -> 3 | B16: A389 | C16: Land and Land Rights | E16: ='[10]II-B-2 General Plant'!E16+'[10]II-B-2 General Plant'!E17+'[9]II-B-2 General Plant'!E16 -> 14943659 | F16: ='[10]II-B-2 General Plant'!F16+'[10]II-B-2 General Plant'!F17+'[9]II-B-2 General Plant'!F16 -> 0 | G16: ='[10]II-B-2 General Plant'!G16+'[10]II-B-2 General Plant'!G17+'[9]II-B-2 General Plant'!G16 -> 1258230.7 | H16: =+E16-F16+G16 -> 16201890 | I16: 1 | J16: =SUM((H16-M16)*I16)+M16 -> 16201890 | K16: 29/22 | L16: DIRECT/DSQFT | M16: ='[10]II-B-2 General Plant'!M16+'[10]II-B-2 General Plant'!M17+'[9]II-B-2 General Plant'!M16 -> 1258230.7 | N16: ='[10]II-B-2 General Plant'!N16+'[10]II-B-2 General Plant'!N17+'[9]II-B-2 General Plant'!N16 -> 14205666 | O16: ='[10]II-B-2 General Plant'!O16+'[10]II-B-2 General Plant'!O17+'[9]II-B-2 General Plant'!O16 -> 558461.94 | P16: ='[10]II-B-2 General Plant'!P16+'[10]II-B-2 General Plant'!P17+'[9]II-B-2 General Plant'!P16 -> 179531.54 | Q16: =+SUM(M16:P16) -> 16201890
A17: =+A16+1 -> 4 | B17: A390 | C17: Structures and Improvements | E17: ='[10]II-B-2 General Plant'!E18+'[9]II-B-2 General Plant'!E17 -> 3.3352769e+08 | F17: ='[10]II-B-2 General Plant'!F18+'[9]II-B-2 General Plant'!F17 -> 2661.7 | G17: ='[10]II-B-2 General Plant'!G18+'[9]II-B-2 General Plant'!G17 -> 0 | H17: =+E17-F17+G17 -> 3.3352503e+08 | I17: 1 | J17: =SUM((H17-M17)*I17)+M17 -> 3.3352503e+08 | K17: 29/22 | L17: DIRECT/DSQFT | M17: ='[10]II-B-2 General Plant'!M18+'[9]II-B-2 General Plant'!M17 -> 1.1665066e+08 | N17: ='[10]II-B-2 General Plant'!N18+'[9]II-B-2 General Plant'!N17 -> 2.0638456e+08 | O17: ='[10]II-B-2 General Plant'!O18+'[9]II-B-2 General Plant'!O17 -> 7908998.8 | P17: ='[10]II-B-2 General Plant'!P18+'[9]II-B-2 General Plant'!P17 -> 2580810.9 | Q17: =+SUM(M17:P17) -> 3.3352503e+08
A18: =+A17+1 -> 5 | B18: A391 | C18: Office Furniture & Equip. | E18: ='[10]II-B-2 General Plant'!E19+'[9]II-B-2 General Plant'!E18+'[10]II-B-2 General Plant'!E20 -> 7161931 | F18: ='[10]II-B-2 General Plant'!F19+'[9]II-B-2 General Plant'!F18+'[10]II-B-2 General Plant'!F20 -> 184508.68 | G18: ='[10]II-B-2 General Plant'!G19+'[9]II-B-2 General Plant'!G18+'[10]II-B-2 General Plant'!G20 -> 0 | H18: =+E18-F18+G18 -> 6977422.3 | I18: 1 | J18: =SUM((H18-M18)*I18)+M18 -> 6977422.3 | K18: 29/22 | L18: DIRECT/DSQFT | M18: ='[10]II-B-2 General Plant'!M19+'[9]II-B-2 General Plant'!M18+'[10]II-B-2 General Plant'!M20 -> 2035756.6 | N18: ='[10]II-B-2 General Plant'!N19+'[9]II-B-2 General Plant'!N18+'[10]II-B-2 General Plant'!N20 -> 4749326.6 | O18: ='[10]II-B-2 General Plant'!O19+'[9]II-B-2 General Plant'!O18+'[10]II-B-2 General Plant'!O20 -> 138760.08 | P18: ='[10]II-B-2 General Plant'!P19+'[9]II-B-2 General Plant'!P18+'[10]II-B-2 General Plant'!P20 -> 53579.066 | Q18: =+SUM(M18:P18) -> 6977422.3
A19: =+A18+1 -> 6 | B19: A392 | C19: Transportation Equipment | E19: ='[10]II-B-2 General Plant'!E21+'[10]II-B-2 General Plant'!E22+'[9]II-B-2 General Plant'!E19 -> 283185.64 | F19: ='[10]II-B-2 General Plant'!F21+'[10]II-B-2 General Plant'!F22+'[9]II-B-2 General Plant'!F19 -> 19016.03 | G19: ='[10]II-B-2 General Plant'!G21+'[10]II-B-2 General Plant'!G22+'[9]II-B-2 General Plant'!G19 -> 0 | H19: =+E19-F19+G19 -> 264169.61 | I19: 1 | J19: =SUM((H19-M19)*I19)+M19 -> 264169.61 | K19: 29/16 | L19: DIRECT/DPLTXGNL-N | M19: ='[10]II-B-2 General Plant'!M21+'[10]II-B-2 General Plant'!M22+'[9]II-B-2 General Plant'!M19 -> 1993.09 | N19: ='[10]II-B-2 General Plant'!N21+'[10]II-B-2 General Plant'!N22+'[9]II-B-2 General Plant'!N19 -> 254202.08 | O19: ='[10]II-B-2 General Plant'!O21+'[10]II-B-2 General Plant'!O22+'[9]II-B-2 General Plant'!O19 -> 7974.0804 | P19: ='[10]II-B-2 General Plant'!P21+'[10]II-B-2 General Plant'!P22+'[9]II-B-2 General Plant'!P19 -> 0.36431269 | Q19: =+SUM(M19:P19) -> 264169.61
A20: =+A19+1 -> 7 | B20: A393 | C20: Store Equipment | E20: ='[10]II-B-2 General Plant'!E23+'[9]II-B-2 General Plant'!E20 -> 1316420.4 | F20: ='[10]II-B-2 General Plant'!F23+'[9]II-B-2 General Plant'!F20 -> 29447.92 | G20: ='[10]II-B-2 General Plant'!G23+'[9]II-B-2 General Plant'!G20 -> 0 | H20: =+E20-F20+G20 -> 1286972.5 | I20: 1 | J20: =SUM((H20-M20)*I20)+M20 -> 1286972.5 | K20: 29/28 | L20: DIRECT/DMANDS | M20: ='[10]II-B-2 General Plant'!M23+'[9]II-B-2 General Plant'!M20 -> 3676.24 | N20: ='[10]II-B-2 General Plant'!N23+'[9]II-B-2 General Plant'!N20 -> 1242141.7 | O20: ='[10]II-B-2 General Plant'!O23+'[9]II-B-2 General Plant'!O20 -> 41125.522 | P20: ='[10]II-B-2 General Plant'!P23+'[9]II-B-2 General Plant'!P20 -> 29.054975 | Q20: =+SUM(M20:P20) -> 1286972.5
A21: =+A20+1 -> 8 | B21: A394 | C21: Tools, Shop & Garage Equip. | E21: ='[10]II-B-2 General Plant'!E24+'[9]II-B-2 General Plant'!E21 -> 48850563 | F21: ='[10]II-B-2 General Plant'!F24+'[9]II-B-2 General Plant'!F21 -> 51269.93 | G21: ='[10]II-B-2 General Plant'!G24+'[9]II-B-2 General Plant'!G21 -> 0 | H21: =+E21-F21+G21 -> 48799293 | I21: 1 | J21: =SUM((H21-M21)*I21)+M21 -> 48799293 | K21: 29/16 | L21: DIRECT/DPLTXGNL-N | M21: ='[10]II-B-2 General Plant'!M24+'[9]II-B-2 General Plant'!M21 -> 23106515 | N21: ='[10]II-B-2 General Plant'!N24+'[9]II-B-2 General Plant'!N21 -> 24912214 | O21: ='[10]II-B-2 General Plant'!O24+'[9]II-B-2 General Plant'!O21 -> 780530.33 | P21: ='[10]II-B-2 General Plant'!P24+'[9]II-B-2 General Plant'!P21 -> 34.696336 | Q21: =+SUM(M21:P21) -> 48799293
A22: =+A21+1 -> 9 | B22: A395 | C22: Laboratory Equipment | E22: ='[10]II-B-2 General Plant'!E25+'[9]II-B-2 General Plant'!E22 -> 2366780.8 | F22: ='[10]II-B-2 General Plant'!F25+'[9]II-B-2 General Plant'!F22 -> 1925886.6 | G22: ='[10]II-B-2 General Plant'!G25+'[9]II-B-2 General Plant'!G22 -> 0 | H22: =+E22-F22+G22 -> 440894.21 | I22: 1 | J22: =SUM((H22-M22)*I22)+M22 -> 440894.21 | K22: 29/16 | L22: DIRECT/DPLTXGNL-N | M22: ='[10]II-B-2 General Plant'!M25+'[9]II-B-2 General Plant'!M22 -> 75794.62 | N22: ='[10]II-B-2 General Plant'!N25+'[9]II-B-2 General Plant'!N22 -> 354456.1 | O22: ='[10]II-B-2 General Plant'!O25+'[9]II-B-2 General Plant'!O22 -> 10643.488 | P22: ='[10]II-B-2 General Plant'!P25+'[9]II-B-2 General Plant'!P22 -> 0 | Q22: =+SUM(M22:P22) -> 440894.21
A23: =+A22+1 -> 10 | B23: A396 | C23: Power Operated Equipment | E23: ='[10]II-B-2 General Plant'!E26+'[9]II-B-2 General Plant'!E23 -> 225096.38 | F23: ='[10]II-B-2 General Plant'!F26+'[9]II-B-2 General Plant'!F23 -> 32898.03 | G23: ='[10]II-B-2 General Plant'!G26+'[9]II-B-2 General Plant'!G23 -> 0 | H23: =+E23-F23+G23 -> 192198.35 | I23: 1 | J23: =SUM((H23-M23)*I23)+M23 -> 192198.35 | K23: 29/16 | L23: DIRECT/DPLTXGNL-N | M23: ='[10]II-B-2 General Plant'!M26+'[9]II-B-2 General Plant'!M23 -> 0 | N23: ='[10]II-B-2 General Plant'!N26+'[9]II-B-2 General Plant'!N23 -> 186595.33 | O23: ='[10]II-B-2 General Plant'!O26+'[9]II-B-2 General Plant'!O23 -> 5603.0213 | P23: ='[10]II-B-2 General Plant'!P26+'[9]II-B-2 General Plant'!P23 -> 0 | Q23: =+SUM(M23:P23) -> 192198.35
A24: =+A23+1 -> 11 | C24: Subtotal | E24: =SUM(E15:E23) -> 4.0867533e+08 | F24: =SUM(F15:F23) -> 2245688.9 | G24: =SUM(G15:G23) -> 1258230.7 | H24: =SUM(H15:H23) -> 4.0768787e+08 | J24: =SUM(J15:J23) -> 4.0768787e+08 | M24: =SUM(M15:M23) -> 1.4313262e+08 | N24: =SUM(N15:N23) -> 2.5228917e+08 | O24: =SUM(O15:O23) -> 9452097.3 | P24: =SUM(P15:P23) -> 2813985.6 | Q24: =SUM(Q15:Q23) -> 4.0768787e+08
A25: =+A24+1 -> 12
A26: =+A25+1 -> 13 | B26: A398 | C26: Misc. Equipment | E26: ='[10]II-B-2 General Plant'!E29+'[9]II-B-2 General Plant'!E26 -> 5163815.6 | F26: ='[10]II-B-2 General Plant'!F29+'[9]II-B-2 General Plant'!F26 -> 51787.88 | G26: ='[10]II-B-2 General Plant'!G29+'[9]II-B-2 General Plant'!G26 -> 0 | H26: =+E26-F26+G26 -> 5112027.8 | I26: 1 | J26: =SUM((H26-M26)*I26)+M26 -> 5112027.8 | K26: 29/16 | L26: DIRECT/DPLTXGNL-N | M26: ='[10]II-B-2 General Plant'!M29+'[9]II-B-2 General Plant'!M26 -> 453209.64 | N26: ='[10]II-B-2 General Plant'!N29+'[9]II-B-2 General Plant'!N26 -> 4514924.7 | O26: ='[10]II-B-2 General Plant'!O29+'[9]II-B-2 General Plant'!O26 -> 143884.57 | P26: ='[10]II-B-2 General Plant'!P29+'[9]II-B-2 General Plant'!P26 -> 8.8805376 | Q26: =+SUM(M26:P26) -> 5112027.8
A27: =+A26+1 -> 14 | B27: A399 | C27: Other Tangible | E27: ='[10]II-B-2 General Plant'!E30+'[9]II-B-2 General Plant'!E27 -> 1372572.4 | F27: ='[10]II-B-2 General Plant'!F30+'[9]II-B-2 General Plant'!F27 -> 0 | G27: ='[10]II-B-2 General Plant'!G30+'[9]II-B-2 General Plant'!G27 -> 0 | H27: =+E27-F27+G27 -> 1372572.4 | I27: 1 | J27: =SUM((H27-M27)*I27)+M27 -> 1372572.4 | K27: 29/16 | L27: DIRECT/DPLTXGNL-N | M27: ='[10]II-B-2 General Plant'!M30+'[9]II-B-2 General Plant'!M27 -> 0 | N27: ='[10]II-B-2 General Plant'!N30+'[9]II-B-2 General Plant'!N27 -> 1330480.2 | O27: ='[10]II-B-2 General Plant'!O30+'[9]II-B-2 General Plant'!O27 -> 42089.951 | P27: ='[10]II-B-2 General Plant'!P30+'[9]II-B-2 General Plant'!P27 -> 2.2850494 | Q27: =+SUM(M27:P27) -> 1372572.4
A28: =+A27+1 -> 15
A29: =+A28+1 -> 16 | C29: Subtotal | E29: =SUM(E26:E28) -> 6536388 | F29: =SUM(F26:F28) -> 51787.88 | G29: =SUM(G26:G28) -> 0 | H29: =SUM(H26:H28) -> 6484600.2 | J29: =SUM(J26:J28) -> 6484600.2 | M29: =SUM(M26:M28) -> 453209.64 | N29: =SUM(N26:N28) -> 5845404.8 | O29: =SUM(O26:O28) -> 185974.52 | P29: =SUM(P26:P28) -> 11.165587 | Q29: =SUM(Q26:Q28) -> 6484600.2
A30: =+A29+1 -> 17
A31: =+A30+1 -> 18 | B31: TOTAL GENERAL PLANT GROSS | D31: II-B-2 | E31: =E24+E29 -> 4.1521172e+08 | F31: =F24+F29 -> 2297476.8 | G31: =G24+G29 -> 1258230.7 | H31: =H24+H29 -> 4.1417247e+08 | J31: =+J29+J24 -> 4.1417247e+08 | M31: =M24+M29 -> 1.4358583e+08 | N31: =N24+N29 -> 2.5813457e+08 | O31: =O24+O29 -> 9638071.8 | P31: =P24+P29 -> 2813996.7 | Q31: =Q24+Q29 -> 4.1417247e+08
E34: =E31-F31 -> 4.1291424e+08

Sheet II-B-3 Comm. Equip.
B2: PUBLIC UTILITY COMMISSION OF TEXAS
B3: AEP TEXAS INC
B4: II-B-3 COMMUNICATION EQUIPMENT
B5: TEST YEAR ENDING 12/31/2018
B6: ='I-A'!B6
E8: 1 | F8: 2 | G8: 3 | H8: 4 | I8: 5 | J8: 6 | K8: 7 | L8: 8 | M8: 9 | N8: 10 | O8: 11 | P8: 12 | Q8: 13
H9: Company | I9: Texas
B10: Account | C10: Description | D10: Reference | E10: Total | F10: Non-Regulated | G10: Known | H10: Total | I10: Retail | J10: Allocation to | K10: FF | L10: Funct | M10: TRAN | N10: DIST | O10: MET | P10: TDCS | Q10: Total
A11: Line | B11: Number | D11: Schedule | E11: Company | F11: or | G11: Change | H11: Electric | I11: Allocation | J11: Texas | K11: # | L11: Factor | R11: CHECK
A12: No. | F12: Non-Electric | I12: Factor | L12: Name
A14: 1 | B14: A397 | C14: Total Communication Equipment | E14: ='[10]II-B-3 Comm. Equip.'!E19+'[9]II-B-3 Comm. Equip.'!E14 -> 1.2494796e+08 | F14: ='[10]II-B-3 Comm. Equip.'!F19+'[9]II-B-3 Comm. Equip.'!F14 -> 237590.12 | G14: ='[10]II-B-3 Comm. Equip.'!G19+'[9]II-B-3 Comm. Equip.'!G14 -> -1925527.1 | H14: =+E14-F14+G14 -> 1.2278485e+08 | I14: 1 | J14: =SUM((H14-M14)*I14)+M14 -> 1.2278485e+08 | K14: 29/16 | L14: DIRECT/DPLTXGNL-N | M14: ='[10]II-B-3 Comm. Equip.'!M19+'[9]II-B-3 Comm. Equip.'!M14 -> 11247748 | N14: ='[10]II-B-3 Comm. Equip.'!N19+'[9]II-B-3 Comm. Equip.'!N14 -> 95208035 | O14: ='[10]II-B-3 Comm. Equip.'!O19+'[9]II-B-3 Comm. Equip.'!O14 -> 16328967 | P14: ='[10]II-B-3 Comm. Equip.'!P19+'[9]II-B-3 Comm. Equip.'!P14 -> 97.082531 | Q14: =+SUM(M14:P14) -> 1.2278485e+08
A15: =+A14+1 -> 2 | C15: Subtotal | E15: =SUM(E14) -> 1.2494796e+08 | F15: =SUM(F14) -> 237590.12 | G15: =SUM(G14) -> -1925527.1 | H15: =SUM(H14) -> 1.2278485e+08 | J15: =SUM(J14) -> 1.2278485e+08 | M15: =SUM(M14) -> 11247748 | N15: =SUM(N14) -> 95208035 | O15: =SUM(O14) -> 16328967 | P15: =SUM(P14) -> 97.082531 | Q15: =SUM(Q14) -> 1.2278485e+08
A16: =+A15+1 -> 3
A17: =+A16+1 -> 4 | B17: TOTAL COMMUNICATION EQUIPMENT | E17: =+E15 -> 1.2494796e+08 | F17: =+F15 -> 237590.12 | G17: =+G15 -> -1925527.1 | H17: =+H15 -> 1.2278485e+08 | J17: =+J15 -> 1.2278485e+08 | M17: =+M15 -> 11247748 | N17: =+N15 -> 95208035 | O17: =+O15 -> 16328967 | P17: =+P15 -> 97.082531 | Q17: =+Q15 -> 1.2278485e+08
A18: =+A17+1 -> 5
A19: =+A18+1 -> 6 | B19: TOTAL GENERAL PLANT GROSS INCLUDE. COMM. EQUIP. | D19: II-B-2-3 | E19: =+'II-B-2 General Plant'!E31+'II-B-3 Comm. Equip.'!E17 -> 5.4015968e+08 | F19: =+'II-B-2 General Plant'!F31+'II-B-3 Comm. Equip.'!F17 -> 2535066.9 | G19: =+'II-B-2 General Plant'!G31+'II-B-3 Comm. Equip.'!G17 -> -667296.38 | H19: =+'II-B-2 General Plant'!H31+'II-B-3 Comm. Equip.'!H17 -> 5.3695732e+08 | J19: =+'II-B-2 General Plant'!J31+'II-B-3 Comm. Equip.'!J17 -> 5.3695732e+08 | M19: =+'II-B-2 General Plant'!M31+'II-B-3 Comm. Equip.'!M17 -> 1.5483358e+08 | N19: =+'II-B-2 General Plant'!N31+'II-B-3 Comm. Equip.'!N17 -> 3.5334261e+08 | O19: =+'II-B-2 General Plant'!O31+'II-B-3 Comm. Equip.'!O17 -> 25967039 | P19: =+'II-B-2 General Plant'!P31+'II-B-3 Comm. Equip.'!P17 -> 2814093.8 | Q19: =+'II-B-2 General Plant'!Q31+'II-B-3 Comm. Equip.'!Q17 -> 5.3695732e+08
A20: =+A19+1 -> 7
A21: =+A20+1 -> 8 | B21: TOTAL PLANT IN SERVICE-GROSS (INCL. INTANGIBLES) | D21: II-B-1-3 | E21: =+'II-B-1 Plant'!E51+'II-B-2 General Plant'!E31+'II-B-3 Comm. Equip.'!E17 -> 8.4060502e+09 | F21: =+'II-B-1 Plant'!F51+'II-B-2 General Plant'!F31+'II-B-3 Comm. Equip.'!F17 -> 3321017 | G21: =+'II-B-1 Plant'!G51+'II-B-2 General Plant'!G31+'II-B-3 Comm. Equip.'!G17 -> -92255657 | H21: =+'II-B-1 Plant'!H51+'II-B-2 General Plant'!H31+'II-B-3 Comm. Equip.'!H17 -> 8.3104735e+09 | J21: =+'II-B-1 Plant'!J51+'II-B-2 General Plant'!J31+'II-B-3 Comm. Equip.'!J17 -> 8.3104735e+09 | M21: =+'II-B-1 Plant'!M51+'II-B-2 General Plant'!M31+'II-B-3 Comm. Equip.'!M17 -> 3.8704922e+09 | N21: =+'II-B-1 Plant'!N51+'II-B-2 General Plant'!N31+'II-B-3 Comm. Equip.'!N17 -> 4.1777421e+09 | O21: =+'II-B-1 Plant'!O51+'II-B-2 General Plant'!O31+'II-B-3 Comm. Equip.'!O17 -> 2.5942027e+08 | P21: =+'II-B-1 Plant'!P51+'II-B-2 General Plant'!P31+'II-B-3 Comm. Equip.'!P17 -> 2818894.3 | Q21: =+'II-B-1 Plant'!Q51+'II-B-2 General Plant'!Q31+'II-B-3 Comm. Equip.'!Q17 -> 8.3104735e+09
A22: =+A21+1 -> 9
A23: =+A22+1 -> 10 | B23: TOTAL PLANT IN SERVICE-GROSS (EXCL. INTANGIBLES) | D23: II-B-1-3 | E23: =+'II-B-1 Plant'!E52+'II-B-2 General Plant'!E31+'II-B-3 Comm. Equip.'!E17 -> 8.2620977e+09 | F23: =+'II-B-1 Plant'!F52+'II-B-2 General Plant'!F31+'II-B-3 Comm. Equip.'!F17 -> 2773486.9 | G23: =+'II-B-1 Plant'!G52+'II-B-2 General Plant'!G31+'II-B-3 Comm. Equip.'!G17 -> -92255657 | H23: =+'II-B-1 Plant'!H52+'II-B-2 General Plant'!H31+'II-B-3 Comm. Equip.'!H17 -> 8.1670685e+09 | J23: =+'II-B-1 Plant'!J52+'II-B-2 General Plant'!J31+'II-B-3 Comm. Equip.'!J17 -> 8.1670685e+09 | M23: =+'II-B-1 Plant'!M52+'II-B-2 General Plant'!M31+'II-B-3 Comm. Equip.'!M17 -> 3.8328911e+09 | N23: =+'II-B-1 Plant'!N52+'II-B-2 General Plant'!N31+'II-B-3 Comm. Equip.'!N17 -> 4.0755892e+09 | O23: =+'II-B-1 Plant'!O52+'II-B-2 General Plant'!O31+'II-B-3 Comm. Equip.'!O17 -> 2.5577415e+08 | P23: =+'II-B-1 Plant'!P52+'II-B-2 General Plant'!P31+'II-B-3 Comm. Equip.'!P17 -> 2814093.8 | Q23: =+'II-B-1 Plant'!Q52+'II-B-2 General Plant'!Q31+'II-B-3 Comm. Equip.'!Q17 -> 8.1670685e+09
E26: =E17-F17 -> 1.2471037e+08

Sheet II-B-4 CWIP
Q1: SCHEDULE II-B-4
B2: PUBLIC UTILITY COMMISSION OF TEXAS
B3: AEP TEXAS INC
B4: II-B-4 CONSTRUCTION WORK IN PROGRESS
B5: TEST YEAR ENDING 12/31/2018
B6: ='I-A'!B6
E8: 1 | F8: 2 | G8: 3 | H8: 4 | I8: 5 | J8: 6 | K8: 7 | L8: 8 | M8: 9 | N8: 10 | O8: 11 | P8: 12 | Q8: 13
H9: Company | I9: Texas
B10: Account | C10: Description | D10: Reference | E10: Total | F10: Non-Regulated or | G10: Known | H10: Total | I10: Retail | J10: Allocation to | K10: FF | L10: Funct | M10: TRAN | N10: DIST | O10: MET | P10: TDCS | Q10: Total
A11: Line | B11: Number | D11: Schedule | E11: Company | F11: Non-Electric | G11: Change | H11: Electric | I11: Allocation | J11: Texas | K11: # | L11: Factor | R11: CHECK
A12: No. | I12: Factor | L12: Name
A14: 1 | C14: Construction Work in Progress
A15: =+A14+1 -> 2 | B15: A107 | C15: CWIP | E15: ='[10]II-B-4 CWIP'!E15+'[9]II-B-4 CWIP'!E15 -> 8.3618645e+08 | F15: ='[10]II-B-4 CWIP'!F15+'[9]II-B-4 CWIP'!F15 -> 182478.16 | G15: ='[10]II-B-4 CWIP'!G15+'[9]II-B-4 CWIP'!G15 -> -8.3600397e+08 | H15: =+E15-F15+G15 -> 0 | J15: =+H15*I15 -> 0 | K15: * | L15: * | N15: =+J15-M15 -> 0 | Q15: =+SUM(M15:P15) -> 0
A16: =+A15+1 -> 3 | C16: Subtotal | E16: =SUM(E15) -> 8.3618645e+08 | F16: =SUM(F15) -> 182478.16 | G16: =SUM(G15) -> -8.3600397e+08 | H16: =SUM(H15) -> 0 | N16: =+N15 -> 0 | Q16: =+Q15 -> 0
A17: =+A16+1 -> 4
A18: =+A17+1 -> 5 | B18: TOTAL CWIP | D18: II-B-4 | E18: =E16 -> 8.3618645e+08 | F18: =F16 -> 182478.16 | G18: =G16 -> -8.3600397e+08 | H18: =H16 -> 0 | N18: =+N16 -> 0 | Q18: =+Q16 -> 0

Sheet II-B-5 Depreciation
B2: PUBLIC UTILITY COMMISSION OF TEXAS
B3: AEP TEXAS INC
B4: II-B-5 ACCUMULATED DEPRECIATION
B5: TEST YEAR ENDING 12/31/2018
B6: ='I-A'!B6
E8: 1 | F8: 2 | G8: 3 | H8: 4 | I8: 5 | J8: 6 | K8: 7 | L8: 8 | M8: 9 | N8: 10 | O8: 11 | P8: 12 | Q8: 13
H9: Company | I9: Texas
B10: Account | C10: Description | D10: Reference | E10: Total | F10: Non-Regulated or | G10: Known | H10: Total | I10: Retail | J10: Allocation to | K10: FF | L10: Funct | M10: TRAN | N10: DIST | O10: MET | P10: TDCS | Q10: Total
A11: Line | B11: Number | D11: Schedule | E11: Company | F11: Non-Electric | G11: Change | H11: Electric | I11: Allocation | J11: Texas | K11: # | L11: Factor | R11: CHECK
A12: No. | I12: Factor | L12: Name
A14: 1 | B14: Intangible Plant
A15: =+A14+1 -> 2 | B15: Accumulated Depreciation | D15: II-B-5
A16: =+A15+1 -> 3 | B16: A301 | C16: Organization | E16: ='[10]II-B-5 Depreciation'!E16+'[9]II-B-5 Depreciation'!E16 -> 1731.05 | F16: ='[10]II-B-5 Depreciation'!F16+'[9]II-B-5 Depreciation'!F16 -> 1731.05 | G16: ='[10]II-B-5 Depreciation'!G16+'[9]II-B-5 Depreciation'!G16 -> 0 | H16: ='[10]II-B-5 Depreciation'!H16+'[9]II-B-5 Depreciation'!H16 -> 0 | I16: 0 | J16: =+I16*H16 -> 0 | K16: 25 | L16: TOTREV | M16: ='[10]II-B-5 Depreciation'!M16+'[9]II-B-5 Depreciation'!M16 -> 0 | N16: ='[10]II-B-5 Depreciation'!N16+'[9]II-B-5 Depreciation'!N16 -> 0 | O16: ='[10]II-B-5 Depreciation'!O16+'[9]II-B-5 Depreciation'!O16 -> 0 | P16: ='[10]II-B-5 Depreciation'!P16+'[9]II-B-5 Depreciation'!P16 -> 0 | Q16: =+SUM(M16:P16) -> 0
A17: =+A16+1 -> 4 | B17: A302 | C17: Franchise & Consents-Merger assets-Other | E17: ='[10]II-B-5 Depreciation'!E17+'[9]II-B-5 Depreciation'!E17 -> 0 | F17: ='[10]II-B-5 Depreciation'!F17+'[9]II-B-5 Depreciation'!F17 -> 0 | G17: ='[10]II-B-5 Depreciation'!G17+'[9]II-B-5 Depreciation'!G17 -> 0 | H17: ='[10]II-B-5 Depreciation'!H17+'[9]II-B-5 Depreciation'!H17 -> 0 | I17: 0 | J17: =+I17*H17 -> 0 | K17: 25 | L17: TOTREV | M17: ='[10]II-B-5 Depreciation'!M17+'[9]II-B-5 Depreciation'!M17 -> 0 | N17: ='[10]II-B-5 Depreciation'!N17+'[9]II-B-5 Depreciation'!N17 -> 0 | O17: ='[10]II-B-5 Depreciation'!O17+'[9]II-B-5 Depreciation'!O17 -> 0 | P17: ='[10]II-B-5 Depreciation'!P17+'[9]II-B-5 Depreciation'!P17 -> 0 | Q17: =+SUM(M17:P17) -> 0
