Workbook
Name \p: #REF!
Name \p: #REF!
Name \p: #REF!
Name \p: #REF!
Name \p: #REF!
Name \p: #REF!
Name \p: #REF!
Name \p: #REF!
Name \p: #REF!
Name \p: #REF!
Name \p: #REF!
Name \p: #REF!
Name \p: #REF!
Name \p: #REF!
Name _2006_Summary_Combined: #REF!
Name _2006_Summary_Combined: #REF!
Name _2006_Summary_Combined: #REF!
Name _2006_Summary_Combined: #REF!
Name _2006_Summary_Combined: #REF!
Name _2006_Summary_Combined: #REF!
Name _2006_Summary_Combined: #REF!
Name _2006_Summary_Combined: #REF!
Name _2006_Summary_Combined: #REF!
Name _2006_Summary_Combined: #REF!
Name _2006_Summary_Combined: #REF!
Name _2006_Summary_Combined: #REF!
Name _2006_Summary_Combined: #REF!
Name _2006_Summary_Combined: #REF!
Name _2006_Summary_Combined: #REF!
Name _963: #REF!
Name _963: #REF!
Name _963: #REF!
Name _963: #REF!
Name _963: #REF!
Name _963: #REF!
Name _963: #REF!
Name _963: #REF!
Name _963: #REF!
Name _963: #REF!
Name _963: #REF!
Name _963: #REF!
Name _963: #REF!
Name _963: #REF!
Name _985: #REF!
Name _985: #REF!
Name _985: #REF!
Name _985: #REF!
Name _985: #REF!
Name _985: #REF!
Name _985: #REF!
Name _985: #REF!
Name _985: #REF!
Name _985: #REF!
Name _985: #REF!
Name _985: #REF!
Name _985: #REF!
Name _985: #REF!
Name _991: #REF!
Name _991: #REF!
Name _991: #REF!

Sheet WP II-B.1 Prepayments
A1: PUBLIC UTILITY COMMISSION OF TEXAS | F1: WP/ II-B.1
A2: AEP TEXAS INC - CENTRAL DIVISION
A3: PREPAYMENTS
A4: TEST YEAR ENDING 12/31/2018
A8: Line No. | B8: Account Number | C8: Description | D8: Transmission | E8: Distribution | F8: Total T&D
A9: 1 | B9: Per Book Balances at Test Year End
A10: =A9+1 -> 2 | B10: 1650001 | C10: Prepaid Insurance | D10: 227989 | E10: 658074 | F10: =SUM(D10:E10) -> 886063
A11: =A10+1 -> 3 | B11: 1650005 | C11: Prepaid Employee Benefits | D11: 0 | E11: 0 | F11: =SUM(D11:E11) -> 0
A12: =A11+1 -> 4 | B12: 1650006 | C12: Other Prepayments | D12: 405000 | E12: -175667 | F12: =SUM(D12:E12) -> 229333
A13: =A12+1 -> 5 | B13: 1650010 | C13: Prepaid Pension Benefits | D13: 14547992 | E13: 120007525 | F13: =SUM(D13:E13) -> 134555517
A14: =A13+1 -> 6 | B14: 1650014 | C14: FAS 158 Qual Contra Asset | D14: -14547992 | E14: -120007525 | F14: =SUM(D14:E14) -> -134555517
A15: =A14+1 -> 7 | B15: 1650021 | C15: Prepaid Insurance - EIS | D15: 145586 | E15: 1043255 | F15: =SUM(D15:E15) -> 1188841
A16: =A15+1 -> 8 | B16: 1650023 | C16: Prepaid Lease | D16: 148117 | E16: 87643 | F16: =SUM(D16:E16) -> 235760
A17: =A16+1 -> 9 | B17: 1650035 | C17: PRW Without MED-D Benefits | D17: 2683304 | E17: 28153030 | F17: =SUM(D17:E17) -> 30836334
A18: =A17+1 -> 10 | B18: 1650037 | C18: FAS158 Contra-PRW Exclud Med-D | D18: -2683304 | E18: -28153030 | F18: =SUM(D18:E18) -> -30836334
A19: =A18+1 -> 11 | D19: =SUM(D10:D18) -> 926692 | E19: =SUM(E10:E18) -> 1613305 | F19: =SUM(F10:F18) -> 2539997
A20: =A19+1 -> 12
A21: =A20+1 -> 13 | B21: 13-Month Average
A22: =A21+1 -> 14 | B22: 1650001 | C22: Prepaid Insurance | D22: 192093.46 | E22: 618851.77 | F22: =SUM(D22:E22) -> 810945.23
A23: =A22+1 -> 15 | B23: 1650005 | C23: Prepaid Employee Benefits | D23: 302.30769 | E23: 2839.2308 | F23: =SUM(D23:E23) -> 3141.5385
A24: =A23+1 -> 16 | B24: 1650006 | C24: Other Prepayments | D24: 342692.31 | E24: -204378.23 | F24: =SUM(D24:E24) -> 138314.08
A25: =A24+1 -> 17 | B25: 1650010 | C25: Prepaid Pension Benefits | D25: 14993341 | E25: 122032194 | F25: =SUM(D25:E25) -> 1.3702553e+08
A26: =A25+1 -> 18 | B26: 1650014 | C26: FAS 158 Qual Contra Asset | D26: -14993341 | E26: -122032194 | F26: =SUM(D26:E26) -> -1.3702553e+08
A27: =A26+1 -> 19 | B27: 1650021 | C27: Prepaid Insurance - EIS | D27: 146820.69 | E27: 1302565.8 | F27: =SUM(D27:E27) -> 1449386.5
A28: =A27+1 -> 20 | B28: 1650023 | C28: Prepaid Lease | D28: 90198.692 | E28: 76326.385 | F28: =SUM(D28:E28) -> 166525.08
A29: =A28+1 -> 21 | B29: 1650035 | C29: PRW Without MED-D Benefits | D29: 2171299.4 | E29: 22810126 | F29: =SUM(D29:E29) -> 24981426
A30: =A29+1 -> 22 | B30: 1650037 | C30: FAS158 Contra-PRW Exclud Med-D | D30: -2171299.4 | E30: -22810126 | F30: =SUM(D30:E30) -> -24981426
A31: =A30+1 -> 23 | D31: =SUM(D22:D30) -> 772107.46 | E31: =SUM(E22:E30) -> 1796204.9 | F31: =SUM(F22:F30) -> 2568312.4
A32: =A31+1 -> 24
A33: =A32+1 -> 25 | C33: Adjustment | D33: =D31-D19 -> -154584.54 | E33: =E31-E19 -> 182899.92 | F33: =F31-F19 -> 28315.385
B39: Purpose: To adjust prepayments to reflect 13 month average balance

Sheet WP II-B.2 Material and Supplies
A1: PUBLIC UTILITY COMMISSION OF TEXAS | F1: WP/ II-B.2
A2: AEP TEXAS INC - CENTRAL DIVISION
A3: MATERIALS AND SUPPLIES
A4: TEST YEAR ENDING 12/31/2018
A8: Line No. | B8: Account Number | C8: Description | D8: Transmission | E8: Distribution | F8: Total T&D
A9: 1 | B9: Per Book Balances at Test Year End
A10: 2 | B10: 154 | C10: Material and Supplies | D10: ='[10]II-B-8-1 M&S MONTHLY'!$P$13 -> 11764735 | E10: ='[10]II-B-8-1 M&S MONTHLY'!$P$17 -> 29731671 | F10: =SUM(D10:E10) -> 41496406
A11: =A10+1 -> 3 | B11: 163 | C11: Undistributed M&S Expenses | D11: 0 | E11: 0 | F11: =SUM(D11:E11) -> 0
A12: =A11+1 -> 4
A13: =A12+1 -> 5 | B13: 13 Month Average
A14: =A13+1 -> 6 | B14: 154 | C14: Material and Supplies | D14: ='[10]II-B-8-1 M&S MONTHLY'!$Q$13 -> 12187416 | E14: ='[10]II-B-8-1 M&S MONTHLY'!$Q$17 -> 27143745 | F14: =SUM(D14:E14) -> 39331160
A15: =A14+1 -> 7 | B15: 163 | C15: Undistributed M&S Expenses | D15: 0 | E15: 0 | F15: =SUM(D15:E15) -> 0
A16: =A15+1 -> 8
A17: =A16+1 -> 9 | C17: Adjustment | D17: =D14-D10 -> 422680.12 | E17: =E14-E10 -> -2587926.1 | F17: =F14-F10 -> -2165246
B23: Purpose: To adjust materials and supplies to reflect 13 month average balance

Sheet WP II-B.3 Catastrophe
A1: PUBLIC UTILITY COMMISSION OF TEXAS | F1: WP/ II-B.3
A2: AEP TEXAS INC - CENTRAL DIVISION
A3: CATASTROPHE RESERVE ADJUSTMENT
A4: TEST YEAR ENDING 12/31/2018
A8: Line No. | B8: Account Number | C8: Description | D8: Transmission | E8: Distribution | F8: Total T&D
A9: 1 | B9: 1823 | C9: Per Book Catastrophe Reserve | D9: 1540600.1 | E9: 1.5090899e+08 | F9: =SUM(D9:E9) -> 1.5244959e+08
A10: =A9+1 -> 2 | B10: =B9 -> 1823 | C10: Transmission Carrying Costs | D10: 2995779 | E10: 0 | F10: =SUM(D10:E10) -> 2995779
A11: =A10+1 -> 3 | B11: =B10 -> 1823 | C11: Distribution Principal Securitized | D11: 0 | E11: -1.6462889e+08 | F11: =SUM(D11:E11) -> -1.6462889e+08
A12: 4 | B12: =B11 -> 1823 | C12: Adjusted Amount | D12: =SUM(D9:D11) -> 4536379 | E12: =SUM(E9:E11) -> -13719898 | F12: =SUM(F9:F11) -> -9183518.5
A14: =A12+1 -> 5 | B14: =B12 -> 1823 | C14: Adjustment | D14: =SUM(D10:D11) -> 2995779 | E14: =SUM(E10:E11) -> -1.6462889e+08 | F14: =SUM(F10:F11) -> -1.6163311e+08
B17: Purpose: To Adjust Catastrophe Reserve to be in Synch with PUCT Docket Nos. 48577 & 49308

Sheet WP II-B.4 Prepaid Pension
B1: PUBLIC UTILITY COMMISSION OF TEXAS | G1: WP II-B.4
B2: AEP TEXAS INC - CENTRAL DIVISION
B3: WP/ II-B.4 PREPAID PENSION AND FAS 158
B4: TEST YEAR ENDING 12/31/2018
A8: Line No. | B8: Account Number | C8: Description | D8: Reference | E8: Adjusted '13 Month AVG | F8: Rate Base Adjustment | G8: Total Company Electric
A11: 1 | C11: Transmission
A12: 2 | B12: 1650010 | C12: Prepaid Pension Benefits | D12: II-B-10 | E12: ='[10]II-B-10-1 Prepayments (MONTHLY)'!$Q$16 -> 14993341 | F12: =-G26*E12 -> -10484707 | G12: =+E12+F12 -> 4508633.8
A13: 3 | B13: 1650014 | C13: FAS 158 Qual Contra Asset | D13: II-B-10 | E13: ='[10]II-B-10-1 Prepayments (MONTHLY)'!$Q$17 -> -14993341 | F13: =-E13 -> 14993341 | G13: =+E13+F13 -> 0
A14: 4 | B14: 1650037 | C14: FAS158 Contra-PRW Exclud Med-D | D14: II-B-10 | E14: ='[10]II-B-10-1 Prepayments (MONTHLY)'!$Q$21 -> -2171299.4 | F14: =-E14 -> 2171299.4 | G14: =+E14+F14 -> 0
A16: 5 | E16: =+SUM(E12:E15) -> -2171299.4 | F16: =+SUM(F12:F15) -> 6679933.2 | G16: =+SUM(G12:G15) -> 4508633.8
A18: 6 | C18: Distribution
A19: 7 | B19: 1650010 | C19: Prepaid Pension Benefits | D19: II-B-10 | E19: ='[10]II-B-10-1 Prepayments (MONTHLY)'!$Q$30 -> 122032194 | F19: =-G27*E19 -> -67512724 | G19: =+E19+F19 -> 54519470
A20: 8 | B20: 1650014 | C20: FAS 158 Qual Contra Asset | D20: II-B-10 | E20: ='[10]II-B-10-1 Prepayments (MONTHLY)'!$Q$31 -> -122032194 | F20: =-E20 -> 122032194 | G20: =+E20+F20 -> 0
A21: 9 | B21: 1650037 | C21: FAS158 Contra-PRW Exclud Med-D | D21: II-B-10 | E21: ='[10]II-B-10-1 Prepayments (MONTHLY)'!$Q$35 -> -22810126 | F21: =-E21 -> 22810126 | G21: =+E21+F21 -> 0
A23: 10 | E23: =+SUM(E19:E22) -> -22810126 | F23: =+SUM(F19:F22) -> 77329596 | G23: =+SUM(G19:G22) -> 54519470
A25: 11 | F25: O&M | G25: Capital
A26: 12 | C26: Payroll Expense Ratio | D26: WP/II-D-2-3 | E26: Transmission | F26: =+'WP II-D-2-4 ASC 715 OPEB'!$E$10 -> 0.30070909 | G26: =-F26+1 -> 0.69929091
A27: 13 | D27: WP/II-D-2-3 | E27: Distribution | F27: =+'WP II-D-2-5 SFAS 112'!$F$10 -> 0.446763 | G27: =-F27+1 -> 0.553237
A30: 14 | C30: Purpose:
A31: 15 | C31: To remove FAS 158 balances from rate base and adjust prepaid pension benefits in rate
A32: 16 | C32: base per PUCT ruling in Docket 33309

Sheet WP II-B.5 Plant held for Future
B1: PUBLIC UTILITY COMMISSION OF TEXAS
B2: AEP TEXAS INC - CENTRAL DIVISION
B3: ANALYSIS OF PLANT HELD FOR FUTURE USE
B4: TEST YEAR ENDED 12/31/18
A6: Line No. | B6: Business Unit | C6: Account | D6: Plant Account | E6: description | F6: long_description | G6: Estimated In Service Date | H6: Amount | I6: Adjustment | J6: Total
A7: 1 | B7: 211 | C7: 1050001 | D7: 36000 | E7: Land Parcel | F7: James Rowe Substation : AEPTC : 5132 | G7: 2021 | H7: 186208.56 | I7: =-H7 -> -186208.56 | J7: =SUM(H7:I7) -> 0
A8: 2 | B8: 211 | C8: 1050001 | D8: 36000 | E8: Land Parcel | F8: Pantera 138kV Station : AEPTC : 5213 | G8: 2021 | H8: 287810.24 | I8: =-H8 -> -287810.24 | J8: =SUM(H8:I8) -> 0
A9: 3 | B9: 211 | C9: 1050001 | D9: 36000 | E9: Land Parcel | F9: Valadez 138kV Substation : AEPTC : 5187 | G9: 2019 | H9: 3023997.3 | J9: =SUM(H9:I9) -> 3023997.3
A10: 4 | B10: 211 | C10: 1050001 | D10: 36000 | E10: Land Parcel | F10: James Rowe Substation : AEPTC : 5132 | G10: 2021 | H10: 8712.75 | I10: =-H10 -> -8712.75 | J10: =SUM(H10:I10) -> 0
A11: 5 | B11: 211 | C11: 1050001 | D11: 36000 | E11: Land Parcel | F11: Marina 138/12kV Substation : AEPTC : 5195 | G11: TBD | H11: 272882.64 | I11: =-H11 -> -272882.64 | J11: =SUM(H11:I11) -> 0
A12: 6 | B12: 211 | C12: 1050001 | D12: 36000 | E12: Land Parcel | F12: James Rowe Substation : AEPTC : 5132 | G12: 2021 | H12: 591060.99 | I12: =-H12 -> -591060.99 | J12: =SUM(H12:I12) -> 0
A13: 7 | B13: 211 | C13: 1050001 | D13: 36000 | E13: Land Parcel | F13: Resaca 69kV Substation : AEPTC : 1204 | G13: 2020 | H13: 87385.24 | J13: =SUM(H13:I13) -> 87385.24
A14: 8 | B14: 211 | C14: 1050001 | D14: 36000 | E14: Land Parcel | F14: Resaca 69kV Substation : AEPTC : 1204 | G14: 2020 | H14: 20633.42 | J14: =SUM(H14:I14) -> 20633.42
A15: 9 | B15: 211 | C15: 1050001 | D15: 36000 | E15: Land Parcel | F15: Iowa 138/12.47KV Substation : AEPTC : 5152 | G15: 2023 | H15: 244307.96 | I15: =-H15 -> -244307.96 | J15: =SUM(H15:I15) -> 0
A16: 10 | B16: 211 | C16: 1050001 | D16: 36000 | E16: Land Parcel | F16: James Rowe Substation : AEPTC : 5132 | G16: 2021 | H16: 218592.58 | I16: =-H16 -> -218592.58 | J16: =SUM(H16:I16) -> 0
A17: 11 | B17: Total Account 1050001 | H17: =SUM(H7:H16) -> 4941591.7 | I17: =SUM(I7:I16) -> -1809575.7 | J17: =SUM(J7:J16) -> 3132016
B20: Purpose: To adjust plant held for future use to remove assets not scheduled to be in service by 12/31/2020

Sheet WP II-B.6 PRW MED-D
B1: PUBLIC UTILITY COMMISSION OF TEXAS | H1: WP II-B.6
B2: AEP TEXAS INC - CENTRAL DIVISION
B3: WP/ II-B.5 PRW WITHOUT MED-D
B4: TEST YEAR ENDING 12/31/2018
A8: Line No. | B8: Account Number | C8: Description | D8: Reference | E8: Adjusted '13 Month AVG | F8: Adjustment for capitalization | G8: Rate Base Adjustment | H8: Total Company
A11: 1 | C11: Transmission
A12: 2 | B12: 1650035 | C12: PRW Without MED-D Benefits | D12: II-B-10 | E12: ='[10]II-B-10-1 Prepayments (MONTHLY)'!$Q$20 -> 2171299.4 | F12: =G20 -> 0.69929091 | G12: =-E12*F12 -> -1518369.9 | H12: =+E12+G12 -> 652929.46
A15: 3 | C15: Distribution
A16: 4 | B16: 1650035 | C16: PRW Without MED-D Benefits | D16: II-B-10 | E16: ='[10]II-B-10-1 Prepayments (MONTHLY)'!$Q$34 -> 22810126 | F16: =G21 -> 0.553237 | G16: =-E16*F16 -> -12619406 | H16: =+E16+G16 -> 10190721
A19: 5 | F19: O&M | G19: Capital
A20: 6 | C20: Payroll Expense Ratio | D20: WP/II-D-2-3 | E20: Transmission | F20: =+'WP II-D-2-4 ASC 715 OPEB'!$E$10 -> 0.30070909 | G20: =-F20+1 -> 0.69929091
A21: 7 | D21: WP/II-D-2-3 | E21: Distribution | F21: =+'WP II-D-2-5 SFAS 112'!$F$10 -> 0.446763 | G21: =-F21+1 -> 0.553237
B24: Purpose: To adjust PWR without Med D prepayment to reflect capitalization

Sheet WP II-B-1-1 TCOS 
A1: PUBLIC UTILITY COMMISSION OF TEXAS | F1: WP II-B-1-1
A2: AEP TEXAS INC - CENTRAL DIVISION
A3: WP/ II-B ADJUSTMENTS FROM TCOS FILINGS
A4: TEST YEAR ENDING 12/31/2018
A8: Line No. | B8: Account | C8: Description | D8: Plant | E8: Provision | F8: Net
A10: 2 | B10: 356 | C10: Sonora-Hamilton Line (TCC) - Raise structures | D10: 305362.57 | E10: 34811 | F10: =+SUM(D10:E10) -> 340173.57
A11: =+A10+1 -> 3 | B11: 353 | C11: Valero East: New Line Terminal | D11: -111356.82 | E11: -9200 | F11: =+SUM(D11:E11) -> -120556.82
A12: =+A11+1 -> 4 | B12: 353 | C12: STEC Rangerville Through Path Purchase | D12: -1399739.1 | E12: -33774 | F12: =+SUM(D12:E12) -> -1433513.1
A13: =+A12+1 -> 5 | B13: 353 | C13: Lorentz 138kV Substation | D13: -141047 | E13: -11881 | F13: =+SUM(D13:E13) -> -152928
A14: =+A13+1 -> 6 | B14: 353 | C14: LON HILL - AHC | D14: -705.74 | E14: -11 | F14: =+SUM(D14:E14) -> -716.74
A15: =+A14+1 -> 7 | B15: 353 | C15: LAPALMA: ADD 345/138 KV AUTO | D15: -165268.94 | E15: -1707 | F15: =+SUM(D15:E15) -> -166975.94
A16: =+A15+1 -> 8 | B16: 350.1 | C16: Victoria - Edna 138 kV, ROW | D16: -702.22 | E16: -6 | F16: =+SUM(D16:E16) -> -708.22
A17: =+A16+1 -> 9 | B17: 355 | C17: Victoria - Edna 138 kV, Relocate | D17: -22614.9 | E17: -10666 | F17: =+SUM(D17:E17) -> -33280.9
A18: =+A17+1 -> 10 | B18: 356 | C18: Victoria - Edna 138 kV, Relocate | D18: -11725.46 | E18: -3856 | F18: =+SUM(D18:E18) -> -15581.46
A19: =+A18+1 -> 11 | B19: 355 | C19: Victoria - Lolita 138 kV, Relocate | D19: -22753.94 | E19: -9581 | F19: =+SUM(D19:E19) -> -32334.94
A20: =+A19+1 -> 12 | B20: 356 | C20: Victoria - Lolita 138 kV, Relocate | D20: -13486.82 | E20: -3959 | F20: =+SUM(D20:E20) -> -17445.82
A21: =+A20+1 -> 13 | B21: 350.1 | C21: Victoria - Lolita 138 kV, ROW | D21: -2306.57 | E21: -22 | F21: =+SUM(D21:E21) -> -2328.57
A22: =+A21+1 -> 14 | B22: 355 | C22: Gregory - Rincon 69 kV, Relocate 3.3 mile section | D22: -273093.07 | E22: -5395 | F22: =+SUM(D22:E22) -> -278488.07
... A26: =+A25+1 -> 18 | B26: 355 | C26: Brook Hollow - Point Comfort | D26: -1331.54 | E26: -2 | F26: =+SUM(D26:E26) -> -1333.54
A27: =+A26+1 -> 19 | B27: 350 | C27: Land Purchase for Bonilla Substatio | D27: -792320.94 | F27: =+SUM(D27:E27) -> -792320.94
A28: =+A27+1 -> 20 | B28: 350 | C28: Property:New Borglum 138kV | D28: -464239.99 | F28: =+SUM(D28:E28) -> -464239.99
A29: =+A28+1 -> 21
A30: =+A29+1 -> 22 | B30: Total | D30: =SUM(D10:D29) -> -3164358.8 | E30: =SUM(E10:E29) -> -55702 | F30: =SUM(F10:F29) -> -3220060.8
B34: Purpose: adjust plant in service to reflect outstanding proforma adjustments from Interim TCOS filings

Sheet WP II-B-1-2
B1: PUBLIC UTILITY COMMISSION OF TEXAS | G1: WP II-B-1-2
B2: AEP TEXAS INC - CENTRAL DIVISION
B3: WP/ II-B-1-1 HURRICANE HARVEY PLANT ADJUSTMENT
B4: TEST YEAR ENDING 12/31/2018
A8: Line No. | B8: Account Number | C8: Description | D8: Reference | E8: PLANT 101 | F8: Removal Costs | G8: Accum Depr Removal Amount
A11: 1 | B11: 36100 - Structures and Improvements Total | D11: WP II-B-1-2.1 | E11: -2308533.6 | F11: -2149571.1 | G11: -214280.32
A12: 2 | B12: 36200 - Station Equipment | D12: WP II-B-1-2.1 | E12: -5436148.3 | F12: -5061822.7 | G12: -504588.54
A13: 3 | B13: 36216 - Station Equipment-SmartGrid | D13: WP II-B-1-2.1 | E13: -122143.1 | F13: -113732.5 | G13: -11337.441
A14: =A13+1 -> 4 | B14: 36400 - Poles, Towers and Fixtures | D14: WP II-B-1-2.1 | E14: -43972452 | F14: -40944570 | G14: -4081565.5
A15: =A14+1 -> 5 | B15: 36500 - Overhead Conductors, Device | D15: WP II-B-1-2.1 | E15: -31231740 | F15: -29081166 | G15: -2898960.3
A16: =A15+1 -> 6 | B16: 36600 - Underground Conduit | D16: WP II-B-1-2.1 | E16: -253933.16 | F16: -236447.67 | G16: -23570.321
A17: =A16+1 -> 7 | B17: 36700 - Undergrnd Conductors,Device | D17: WP II-B-1-2.1 | E17: -2242889.9 | F17: -2088447.6 | G17: -208187.2
A18: =A17+1 -> 8 | B18: 36800 - Line Transformers | D18: WP II-B-1-2.1 | E18: -2085493.2 | F18: -1941889 | G18: -193577.49
A19: =A18+1 -> 9 | B19: 36900 - Services | D19: WP II-B-1-2.1 | E19: -45746.4 | F19: -42596.366 | G19: -4246.2251
A20: =A19+1 -> 10 | B20: 37100 - Installs Customer Premises | D20: WP II-B-1-2.1 | E20: -26308.78 | F20: -24497.194 | G20: -2442.0064
A21: =A20+1 -> 11 | B21: 37300 - Street Lghtng & Signal Sys | D21: WP II-B-1-2.1 | E21: -4844607.8 | F21: -4511014.8 | G21: -449681.18
A22: =A21+1 -> 12 | B22: 39700 - Communication Equipment | D22: WP II-B-1-2.1 | E22: -701948.77 | F22: -653613.55 | G22: -65155.563
A23: =A22+1 -> 13 | B23: 39716 - GridSmart Communic Equip | D23: WP II-B-1-2.1 | E23: -1365972.5 | F23: -1271913.5 | G23: -126790.89
A24: =A23+1 -> 14
A25: =A24+1 -> 15 | E25: =SUM(E11:E24) -> -94637918 | F25: =SUM(F11:F24) -> -88121282 | G25: =SUM(G11:G24) -> -8784383
B28: Purpose: To adjust plant-in-service to be in synch with PUCT Docket No 49308

Sheet WP II-B-5-1
B1: PUBLIC UTILITY COMMISSION OF TEXAS | I1: WP II-B-1-3
B2: AEP TEXAS INC - CENTRAL DIVISION
B3: WP/ II-B-1-5 ALLOCATION OF RWIP
B4: TEST YEAR ENDING 12/31/2018
D9: Transmission | E9: Distribution | H9: Transmission | I9: Distribution
A10: Line | D10: Balance Provision | E10: Balance Provision | H10: Allocate RWIP | I10: Allocate RWIP
A11: No. | D11: for Depreciation | E11: for Depreciation | F11: Total | H11: Balance | I11: Balance
A12: 1 | B12: Transmission Plant
A13: =A12+1 -> 2 | B13: Accumulated Depreciation
A14: =A13+1 -> 3 | B14: A352 | C14: Structures and Improvements | D14: 4522075.2 | F14: =SUM(D14:E14) -> 4522075.2 | H14: =$D$57*(D14/$D$54) -> -77446.356 | I14: =$E$57*(E14/$E$54) -> 0
A15: =A14+1 -> 4 | B15: A353 | C15: Station Equipment | D15: 1.4871021e+08 | F15: =SUM(D15:E15) -> 1.4871021e+08 | H15: =$D$57*(D15/$D$54) -> -2546853.6 | I15: =$E$57*(E15/$E$54) -> 0
A16: =A15+1 -> 5 | B16: A354 | C16: Towers and Fixtures | D16: 15571694 | F16: =SUM(D16:E16) -> 15571694 | H16: =$D$57*(D16/$D$54) -> -266685.3 | I16: =$E$57*(E16/$E$54) -> 0
A17: =A16+1 -> 6 | B17: A355 | C17: Poles and Fixtures | D17: 94346974 | F17: =SUM(D17:E17) -> 94346974 | H17: =$D$57*(D17/$D$54) -> -1615813.3 | I17: =$E$57*(E17/$E$54) -> 0
A18: =A17+1 -> 7 | B18: A356 | C18: O.H. Conductors & Devices | D18: 44255148 | F18: =SUM(D18:E18) -> 44255148 | H18: =$D$57*(D18/$D$54) -> -757926.36 | I18: =$E$57*(E18/$E$54) -> 0
A19: =A18+1 -> 8 | B19: A357 | C19: Undergound Conduit | D19: 6150.54 | F19: =SUM(D19:E19) -> 6150.54 | H19: =$D$57*(D19/$D$54) -> -105.33591 | I19: =$E$57*(E19/$E$54) -> 0
A20: =A19+1 -> 9 | B20: A358 | C20: Underground Conductors | D20: 2964620.9 | F20: =SUM(D20:E20) -> 2964620.9 | H20: =$D$57*(D20/$D$54) -> -50772.947 | I20: =$E$57*(E20/$E$54) -> 0
A21: =A20+1 -> 10 | B21: A359 | C21: Roads and Trails | D21: 48847.58 | F21: =SUM(D21:E21) -> 48847.58 | H21: =$D$57*(D21/$D$54) -> -836.57766 | I21: =$E$57*(E21/$E$54) -> 0
A22: =A21+1 -> 11 | C22: Subtotal | D22: =SUM(D14:D21) -> 3.1042572e+08 | E22: =SUM(E14:E21) -> 0 | F22: =SUM(F14:F21) -> 3.1042572e+08 | H22: =SUM(H14:H21) -> -5316439.8 | I22: =SUM(I14:I21) -> 0
A23: =A22+1 -> 12
A24: =A23+1 -> 13 | B24: Distribution Plant
A25: =A24+1 -> 14 | B25: Accumulated Depreciation
A26: =A25+1 -> 15 | B26: A361 | C26: Structures and Improvements | E26: 2554890.7 | F26: =SUM(D26:E26) -> 2554890.7 | H26: =$D$57*(D26/$D$54) -> 0 | I26: =$E$57*(E26/$E$54) -> -19586.675
A27: =A26+1 -> 16 | B27: A362 | C27: Station Equipment | E27: 23754966 | F27: =SUM(D27:E27) -> 23754966 | H27: =$D$57*(D27/$D$54) -> 0 | I27: =$E$57*(E27/$E$54) -> -182113.78
A28: =A27+1 -> 17 | B28: A364P | C28: Poles,Towers & Fixtures-Primary | E28: 2.5423935e+08 | F28: =SUM(D28:E28) -> 2.5423935e+08 | H28: =$D$57*(D28/$D$54) -> 0 | I28: =$E$57*(E28/$E$54) -> -1949086.7
A29: =A28+1 -> 18 | B29: A365P | C29: O.H. Conductors & Devices-Primary | E29: 2.0828835e+08 | F29: =SUM(D29:E29) -> 2.0828835e+08 | H29: =$D$57*(D29/$D$54) -> 0 | I29: =$E$57*(E29/$E$54) -> -1596810.5
A30: =A29+1 -> 19 | B30: A366P | C30: Underground Conduits-Primary | E30: 19362583 | F30: =SUM(D30:E30) -> 19362583 | H30: =$D$57*(D30/$D$54) -> 0 | I30: =$E$57*(E30/$E$54) -> -148440.25
A31: =A30+1 -> 20 | B31: A367P | C31: U.G. Conductors & Devices-Primary | E31: 69074564 | F31: =SUM(D31:E31) -> 69074564 | H31: =$D$57*(D31/$D$54) -> 0 | I31: =$E$57*(E31/$E$54) -> -529549.48
A32: =A31+1 -> 21 | B32: A368P | C32: Line Transformers-Primary | E32: 84244879 | F32: =SUM(D32:E32) -> 84244879 | H32: =$D$57*(D32/$D$54) -> 0 | I32: =$E$57*(E32/$E$54) -> -645850.36
A33: =A32+1 -> 22 | B33: A369 | C33: Services | E33: 1.0815265e+08 | F33: =SUM(D33:E33) -> 1.0815265e+08 | H33: =$D$57*(D33/$D$54) -> 0 | I33: =$E$57*(E33/$E$54) -> -829135.61
A34: =A33+1 -> 23 | B34: A370 | C34: Meters | E34: 1.1953072e+08 | F34: =SUM(D34:E34) -> 1.1953072e+08 | H34: =$D$57*(D34/$D$54) -> 0 | I34: =$E$57*(E34/$E$54) -> -916363.78
A35: =A34+1 -> 24 | B35: A371 | C35: Install. on Customer Prem. | E35: 28587588 | F35: =SUM(D35:E35) -> 28587588 | H35: =$D$57*(D35/$D$54) -> 0 | I35: =$E$57*(E35/$E$54) -> -219162.33
A36: =A35+1 -> 25 | B36: A373 | C36: Street Lights | E36: 20468539 | F36: =SUM(D36:E36) -> 20468539 | H36: =$D$57*(D36/$D$54) -> 0 | I36: =$E$57*(E36/$E$54) -> -156918.9
A37: =A36+1 -> 26 | C37: Subtotal | D37: =SUM(D26:D36) -> 0 | E37: =SUM(E26:E36) -> 9.3825908e+08 | F37: =SUM(F26:F36) -> 9.3825908e+08 | H37: =SUM(H26:H36) -> 0 | I37: =SUM(I26:I36) -> -7193018.4
A38: =A37+1 -> 27
A39: =A38+1 -> 28 | B39: General Plant
A40: =A39+1 -> 29 | B40: Accumulated Depreciation
A41: =A40+1 -> 30 | B41: A390 | C41: Structures and Improvements | D41: 445787.05 | E41: =SUM('[10]II-B-5 Depreciation'!N65:P65) -> 30479347 | F41: =SUM(D41:E41) -> 30925134 | H41: =$D$57*(D41/$D$54) -> -7634.6769 | I41: =$E$57*(E41/$E$54) -> -233665.21
A42: =A41+1 -> 31 | B42: A391 | C42: Office Furniture & Equip. | D42: 2004.85 | E42: =SUM('[10]II-B-5 Depreciation'!N66:P66) -> 419953.3 | F42: =SUM(D42:E42) -> 421958.15 | H42: =$D$57*(D42/$D$54) -> -34.335636 | I42: =$E$57*(E42/$E$54) -> -3219.5072
A43: =A42+1 -> 32 | B43: A392 | C43: Transportation Equipment | D43: 0 | E43: =SUM('[10]II-B-5 Depreciation'!N67:P67) -> 105419.09 | F43: =SUM(D43:E43) -> 105419.09 | H43: =$D$57*(D43/$D$54) -> 0 | I43: =$E$57*(E43/$E$54) -> -808.17918
A44: =A43+1 -> 33 | B44: A393 | C44: Store Equipment | D44: 437.52 | E44: =SUM('[10]II-B-5 Depreciation'!N68:P68) -> 473216.24 | F44: =SUM(D44:E44) -> 473653.76 | H44: =$D$57*(D44/$D$54) -> -7.493093 | I44: =$E$57*(E44/$E$54) -> -3627.8392
...

Sheet WP II-B-9.1 D Lead Lag
I1: WP II-B-9.1
A2: PUBLIC UTILITY COMMISSION OF TEXAS
A3: AEP TEXAS INC - CENTRAL DIVISION
A4: LEAD/LAG STUDY RESULTS
A5: FOR THE TEST YEAR ENDED December 31, 2018
A8: Line | C8: Adjusted Test | E8: Avg. Daily | F8: Revenue | G8: Expense | H8: Net | I8: Working Capital
A9: No. | B9: Description | C9: Year Amount | D9: Prepayments | E9: Expense | F9: Lag Days | G9: Lead Days | H9: (Lead)/Lag | I9: Requirement
B10: (a) | C10: (b) | E10: (c) | F10: (d) | G10: (e) | H10: (f) | I10: (g)
A11: 1
A12: =+A11+1 -> 2 | B12: Operation & Maintenance Expense | C12: =+'[10]II-D-2 A&G'!N29+'[10]II-D-2 A&G'!O29+'[10]II-D-2 A&G'!P29-C14-C13 -> 1.3176422e+08 | D12: ='[11]TCC - DIST'!$D$29 -> 3454946.1 | E12: =(C12-D12)/365 -> 351532.25 | F12: ='[11]TCC - DIST'!$C$12 -> 59.16 | G12: ='[11]TCC - DIST'!$D$14 -> -30 | H12: =F12+G12 -> 29.16 | I12: =E12*H12 -> 10250681
A13: =+A12+1 -> 3 | B13: Transmission Expense | C13: ='[10]II-D-1 O&M'!N22 -> 202266.41 | E13: =(C13-D13)/365 -> 554.15455 | F13: =F12 -> 59.16 | G13: ='[11]TCC - DIST'!$D$12 -> -50.21 | H13: =F13+G13 -> 8.95 | I13: =E13*H13 -> 4959.6832
A14: =+A13+1 -> 4 | B14: Incentive Compensation | C14: 4990169.5 | E14: =(C14-D14)/365 -> 13671.697 | F14: =F12 -> 59.16 | G14: ='[11]TCC - DIST'!$D$13 -> -247.74 | H14: =F14+G14 -> -188.58 | I14: =E14*H14 -> -2578208.7
A15: =+A14+1 -> 5 | C15: =SUM(C12:C14) -> 1.3695665e+08 | I15: =SUM(I12:I14) -> 7677431.5
A16: =+A15+1 -> 6 | B16: Federal Income Taxes
A17: =+A16+1 -> 7 | B17: Current | C17: ='[10]II-E-3.15'!$J$127 -> 12572668 | E17: =C17/365 -> 34445.666 | F17: =F12 -> 59.16 | G17: ='[11]TCC - DIST'!$D$17 -> -37 | H17: =F17+G17 -> 22.16 | I17: =E17*H17 -> 763315.96
A18: =+A17+1 -> 8 | B18: Deferred | C18: =+'[10]II-E-3.15'!J129+'[10]II-E-3.15'!J136 -> 4023787.4 | E18: =C18/365 -> 11024.075 | F18: 0 | G18: ='[12]DIST - Results'!D15 -> 0 | H18: =F18+G18 -> 0 | I18: =E18*H18 -> 0
A19: =+A18+1 -> 9 | B19: Total FIT | C19: =SUM(C17:C18) -> 16596455 | D19: =SUM(D17:D18) -> 0 | I19: =SUM(I17:I18) -> 763315.96
A20: =+A19+1 -> 10
A21: =+A20+1 -> 11 | B21: Taxes Other Than Income Taxes | C21: =+'[10]II-E-2 Taxes Other'!O41+'[10]II-E-2 Taxes Other'!P41+'[10]II-E-2 Taxes Other'!Q41 -> 88812349 | D21: 0 | E21: =(C21-D21)/365 -> 243321.51 | F21: =F12 -> 59.16 | G21: ='[11]TCC - DIST'!$D$21 -> -106 | H21: =F21+G21 -> -46.84 | I21: =E21*H21 -> -11397179
A22: =+A21+1 -> 12
A23: =+A22+1 -> 13 | B23: Depreciation Expense | C23: =+'[10]II-E-1 Dep. Exp.'!N68+'[10]II-E-1 Dep. Exp.'!O68+'[10]II-E-1 Dep. Exp.'!P68 -> 1.3349303e+08 | E23: =C23/365 -> 365734.32 | F23: 0 | G23: ='[12]DIST - Results'!D20 -> 0 | H23: =F23+G23 -> 0 | I23: =E23*H23 -> 0
A24: =+A23+1 -> 14
A25: =+A24+1 -> 15 | B25: ERCOT Matrix Expense-Rider | C25: 0 | E25: =(C25-D25)/365 -> 0 | F25: 58.51 | G25: -53.92 | H25: =F25+G25 -> 4.59 | I25: =E25*H25 -> 0
A26: =+A25+1 -> 16 | B26: Current FIT - ERCOT Matrix Expense-Rider | C26: 0 | E26: =C26/365 -> 0 | F26: 58.51 | G26: =+G17 -> -37 | H26: =F26+G26 -> 21.51 | I26: =E26*H26 -> 0
A27: =+A26+1 -> 17
A28: =+A27+1 -> 18
A29: =+A28+1 -> 19 | B29: Return | C29: ='[10]I-A-1'!$K$36 -> 4.9378258e+08 | E29: =C29/365 -> 1352829 | F29: 0 | G29: ='[12]DIST - Results'!D22 -> 0 | H29: =F29+G29 -> 0 | I29: =E29*H29 -> 0
A30: =+A29+1 -> 20
A31: =+A30+1 -> 21 | C31: =SUM(C21:C29)+C15+C19 -> 8.6964107e+08 | D31: =SUM(D19:D29)+D12 -> 3454946.1 | I31: =SUM(I21:I29)+I15+I19 -> -2956431.8
A32: =+A31+1 -> 22
A33: =+A32+1 -> 23 | B33: Average Daily Bank Balances | I33: 0
A34: =+A33+1 -> 24 | B34: Working Funds and Other | I34: -176903
A35: =+A34+1 -> 25
A36: =+A35+1 -> 26 | I36: =SUM(I31:I34) -> -3133334.8
B39: Purpose: To calculate current cash working capital fot the Distribution function.

Sheet WP II-B-9.2 T Lead Lag
I1: WP II-B-9.2
A2: PUBLIC UTILITY COMMISSION OF TEXAS
A3: AEP TEXAS INC - CENTRAL DIVISION
A4: LEAD/LAG STUDY RESULTS
A5: FOR THE TEST YEAR ENDED December 31, 2018
A8: Line | C8: Adjusted Test | E8: Avg. Daily | F8: Revenue | G8: Expense | H8: Net | I8: Working Capital
A9: No. | B9: Description | C9: Year Amount | D9: Prepayments | E9: Expense | F9: Lag Days | G9: Lead Days | H9: (Lead)/Lag | I9: Requirement
B10: (a) | C10: (b) | E10: (c) | F10: (d) | G10: (e) | H10: (f) | I10: (g)
A11: 1
A12: 2 | B12: Operation & Maintenance Expense | C12: =+'[10]II-D-2 A&G'!M29-C14-C13 -> 42228509 | D12: ='[11]TCC - TRAN'!$D$28 -> 1112957.9 | E12: =(C12-D12)/365 -> 112645.35 | F12: ='[11]TCC - TRAN'!$C$13 -> 57.258333 | G12: ='[11]TCC - TRAN'!$D$14 -> -39.23 | H12: =F12+G12 -> 18.028333 | I12: =E12*H12 -> 2030807.9
A13: 2 | B13: Transmission Expense | C13: 0 | E13: =(C13-D13)/365 -> 0 | H13: =F13+G13 -> 0 | I13: =E13*H13 -> 0
A14: 2 | B14: Incentive Compensation | C14: 469830.95 | E14: =(C14-D14)/365 -> 1287.2081 | F14: =F12 -> 57.258333 | G14: ='[11]TCC - TRAN'!$D$13 -> -249.62 | H14: =F14+G14 -> -192.36167 | I14: =E14*H14 -> -247609.49
A15: 2 | C15: =SUM(C12:C14) -> 42698340 | I15: =SUM(I12:I14) -> 1783198.4
A16: 2
A17: 2 | B17: Federal Income Taxes
A18: 2 | B18: Current | C18: ='[10]II-E-3.15'!I127 -> -6149913.1 | E18: =C18/365 -> -16849.077 | F18: =F12 -> 57.258333 | G18: ='[11]TCC - TRAN'!$D$17 -> -37 | H18: =F18+G18 -> 20.258333 | I18: =E18*H18 -> -341334.22
A19: 2 | B19: Deferred | C19: ='[10]II-E-3.15'!$I$136+'[10]II-E-3.15'!I129 -> 27953770 | E19: =C19/365 -> 76585.671 | F19: 0 | G19: 0 | H19: =F19+G19 -> 0 | I19: =E19*H19 -> 0
A20: 2 | B20: Total FIT | C20: =SUM(C18:C19) -> 21803857 | D20: =SUM(D18:D19) -> 0 | I20: =I18+I19 -> -341334.22
A21: 2
A22: 2 | B22: Taxes Other Than Income Taxes | C22: =+'[10]II-E-2 Taxes Other'!N41 -> 27485447 | D22: 0 | E22: =(C22-D22)/365 -> 75302.596 | F22: =F12 -> 57.258333 | G22: ='[11]TCC - TRAN'!$D$21 -> -192.43 | H22: =F22+G22 -> -135.17167 | I22: =E22*H22 -> -10178777
A23: 2
A24: 2 | B24: Depreciation Expense | C24: =+'[10]II-E-1 Dep. Exp.'!M68 -> 58732005 | E24: =C24/365 -> 160909.6 | F24: 0 | G24: 0 | H24: =F24+G24 -> 0 | I24: =E24*H24 -> 0
A25: 2
A26: 2 | B26: Return | C26: ='[10]II-B'!G39 -> 1.2835301e+08 | E26: =C26/365 -> 351652.09 | F26: 0 | G26: 0 | H26: =F26+G26 -> 0 | I26: =E26*H26 -> 0
A27: 2
A28: 2 | C28: =SUM(C20:C26)+C15 -> 2.7907266e+08 | D28: =SUM(D20:D26)+D12 -> 1112957.9 | I28: =SUM(I20:I26)+I15 -> -8736913.2
A29: 2
A30: 2 | B30: Average Daily Bank Balances | I30: 0
A31: 2 | B31: Working Funds and Other | I31: -156593
A32: 2
A33: 2 | I33: =SUM(I28:I31) -> -8893506.2
B35: Purpose: To calculate current cash working capital fot the Distribution function.

Sheet WP II-D-1-1 Payroll
A1: PUBLIC UTILITY COMMISSION OF TEXAS | F1: WP II-D-1-1
A2: AEP TEXAS INC - CENTRAL DIVISION
A3: BASE PAYROLL EXPENSE ADJUSTMENT
A4: TEST YEAR ENDING 12/31/2018
A8: Line | B8: Description | C8: Account | D8: Test Year | E8: Projected | F8: Adjustment
A9: 1
A10: =A9+1 -> 2 | B10: Adjust Distibution Payroll Expense
A11: =A10+1 -> 3 | C11: 5800 | D11: 2338270.7 | E11: 2446265.9 | F11: =E11-D11 -> 107995.2
A12: =A11+1 -> 4 | C12: 5810 | D12: 2694435.5 | E12: 2818880.5 | F12: =E12-D12 -> 124445
A13: =A12+1 -> 5 | C13: 5820 | D13: 159806.21 | E13: 167187 | F13: =E13-D13 -> 7380.7976
A14: =A13+1 -> 6 | C14: 5830 | D14: -2555924.1 | E14: -2673971.8 | F14: =E14-D14 -> -118047.72
A15: =A14+1 -> 7 | C15: 5840 | D15: 110216.6 | E15: 115307.06 | F15: =E15-D15 -> 5090.4559
A16: =A15+1 -> 8 | C16: 5850 | D16: 24049.947 | E16: 25160.716 | F16: =E16-D16 -> 1110.7691
A17: =A16+1 -> 9 | C17: 5860 | D17: 3411971.9 | E17: 3569557 | F17: =E17-D17 -> 157585.08
A18: =A17+1 -> 10 | C18: 5870 | D18: 803431.1 | E18: 840538.3 | F18: =E18-D18 -> 37107.209
A19: =A18+1 -> 11 | C19: 5880 | D19: 7536290.6 | E19: 7884361.2 | F19: =E19-D19 -> 348070.56
A20: =A19+1 -> 12 | C20: 5900 | D20: 70346.487 | E20: 73595.505 | F20: =E20-D20 -> 3249.0177
A21: =A20+1 -> 13 | C21: 5910 | D21: 11.98458 | E21: 12.538099 | F21: =E21-D21 -> 0.55351894
A22: =A21+1 -> 14 | C22: 5920 | D22: -7268.6426 | E22: -7604.3516 | F22: =E22-D22 -> -335.70899
... A40: =A39+1 -> 32 | C40: 9350 | D40: 2292241.9 | E40: 2398111.2 | F40: =E40-D40 -> 105869.31
A41: =A40+1 -> 33 | C41: Total | D41: =SUM(D11:D40) -> 33046375 | E41: =SUM(E11:E40) -> 34572652 | F41: =SUM(F11:F40) -> 1526277.4
A42: =A41+1 -> 34
A43: =A42+1 -> 35 | B43: Adjust Transmission Payroll Expense
A44: =A43+1 -> 36 | C44: 5600 | D44: 1165459.9 | E44: 1197527.8 | F44: =E44-D44 -> 32067.93
A45: =A44+1 -> 37 | C45: 5612 | D45: 70126.638 | E45: 72056.191 | F45: =E45-D45 -> 1929.5526
A46: =A45+1 -> 38 | C46: 5620 | D46: 626029.43 | E46: 643254.79 | F46: =E46-D46 -> 17225.361
A47: =A46+1 -> 39 | C47: 5630 | D47: 23690.988 | E47: 24342.852 | F47: =E47-D47 -> 651.86366
A48: =A47+1 -> 40 | C48: 5660 | D48: 512752.5 | E48: 526861.01 | F48: =E48-D48 -> 14108.517
A49: =A48+1 -> 41 | C49: 5680 | D49: 2900.367 | E49: 2980.1713 | F49: =E49-D49 -> 79.804346
A50: =A49+1 -> 42 | C50: 5690 | D50: 785.03842 | E50: 806.63895 | F50: =E50-D50 -> 21.600535
A51: =A50+1 -> 43 | C51: 5700 | D51: 1758413.4 | E51: 1806796.6 | F51: =E51-D51 -> 48383.199
A52: =A51+1 -> 44 | C52: 5710 | D52: 447611.03 | E52: 459927.16 | F52: =E52-D52 -> 12316.133
A53: =A52+1 -> 45 | C53: 5730 | D53: 5520.8692 | E53: 5672.7774 | F53: =E53-D53 -> 151.90814
A54: =A53+1 -> 46 | C54: 9200 | D54: 1431.5424 | E54: 1470.9317 | F54: =E54-D54 -> 39.38926
A55: =A54+1 -> 47 | C55: 9302 | D55: 575.04077 | E55: 590.86316 | F55: =E55-D55 -> 15.822395
A56: =A55+1 -> 48 | C56: 9350 | D56: 33478.312 | E56: 34399.477 | F56: =E56-D56 -> 921.16441
A57: =A56+1 -> 49 | C57: Total | D57: =SUM(D44:D56) -> 4648775.1 | E57: =SUM(E44:E56) -> 4776687.3 | F57: =SUM(F44:F56) -> 127912.25
A58: =A57+1 -> 50
A59: =A58+1 -> 51 | B59: Combined Distribution and Transmission
A60: =A59+1 -> 52 | C60: 5600 | D60: 1165459.9 | E60: 1197527.8 | F60: =F44 -> 32067.93
...

Sheet WP II-D-1-2 TCOS
B1: PUBLIC UTILITY COMMISSION OF TEXAS | E1: WP II-D-1-2
B2: AEP TEXAS INC - NORTH DIVISION
B3: REMOVE TCOS EXPENSE
B4: TEST YEAR ENDING 12/31/2018
A9: Line No. | B9: DESCRIPTION | C9: Account | D9: Transmission | E9: Distribution
A11: 1 | B11: ERCOT Matrix Expense - Affil | C11: 5650044 | E11: -25078582
A12: 2 | B12: ERCOT Matrix Expense - Non Aff | C12: 5650045 | E12: -2.416774e+08
A14: 3 | D14: =SUM(D11:D13) -> 0 | E14: =SUM(E11:E13) -> -2.6675598e+08
B16: To remove Test Year TCOS Expense recovered through Rider

Sheet WP II-D-1-3 AEPSC
B1: PUBLIC UTILITY COMMISSION OF TEXAS | F1: WP II-D-1-3
B2: AEP TEXAS INC - CENTRAL DIVISION
B3: AEPSC AND AFFILIATE ADJUSTMENT
B4: TEST YEAR ENDING 12/31/2018
A8: Line No. | B8: Description | C8: Account | D8: Transmission | E8: Distribution | F8: Total
A9: 1 | D9: `
A10: =A9+1 -> 2 | B10: Adjust AEPSC billing | C10: 5600 | D10: -103150.97 | E10: -102.11 | F10: =SUM(D10:E10) -> -103253.08
A11: =A10+1 -> 3 | C11: 5612 | D11: 31923.26 | E11: 472.93 | F11: =SUM(D11:E11) -> 32396.19
A12: =A11+1 -> 4 | C12: 5615 | D12: 5658.62 | E12: 220.47 | F12: =SUM(D12:E12) -> 5879.09
A13: =A12+1 -> 5 | C13: 5616 | D13: -2.3 | E13: -2.61 | F13: =SUM(D13:E13) -> -4.91
A14: =A13+1 -> 6 | C14: 5620 | D14: 594.94 | F14: =SUM(D14:E14) -> 594.94
A15: =A14+1 -> 7 | C15: 5630 | D15: -439.64 | E15: -1.29 | F15: =SUM(D15:E15) -> -440.93
A16: =A15+1 -> 8 | C16: 5660 | D16: -66494.35 | E16: -1276.93 | F16: =SUM(D16:E16) -> -67771.28
A17: =A16+1 -> 9 | C17: 5680 | D17: 594.42 | E17: -0.31 | F17: =SUM(D17:E17) -> 594.11
A18: =A17+1 -> 10 | C18: 5690 | D18: 99.09 | F18: =SUM(D18:E18) -> 99.09
A19: =A18+1 -> 11 | C19: 5691 | D19: 210.11 | F19: =SUM(D19:E19) -> 210.11
A20: =A19+1 -> 12 | C20: 5692 | D20: 3281.71 | E20: 13.89 | F20: =SUM(D20:E20) -> 3295.6
A21: =A20+1 -> 13 | C21: 5700 | D21: 4787.86 | E21: -0.17 | F21: =SUM(D21:E21) -> 4787.69
A22: =A21+1 -> 14 | C22: 5710 | D22: -2190.82 | E22: 61.81 | F22: =SUM(D22:E22) -> -2129.01
A23: =A22+1 -> 15 | C23: 5720 | D23: -263.75 | F23: =SUM(D23:E23) -> -263.75
A24: =A23+1 -> 16 | C24: 5730 | D24: -862.69 | E24: -7.06 | F24: =SUM(D24:E24) -> -869.75
A25: =A24+1 -> 17 | C25: 5800 | D25: 730.44 | E25: 23976.4 | F25: =SUM(D25:E25) -> 24706.84
A26: =A25+1 -> 18 | C26: 5820 | D26: 7.07 | E26: -1864.2 | F26: =SUM(D26:E26) -> -1857.13
A27: =A26+1 -> 19 | C27: 5830 | D27: -3777.19 | E27: -1751.68 | F27: =SUM(D27:E27) -> -5528.87
A28: =A27+1 -> 20 | C28: 5840 | E28: 441.44 | F28: =SUM(D28:E28) -> 441.44
A29: =A28+1 -> 21 | C29: 5860 | D29: 39.25 | E29: 31717.47 | F29: =SUM(D29:E29) -> 31756.72
A30: =A29+1 -> 22 | C30: 5880 | D30: 3619.28 | E30: 9025.91 | F30: =SUM(D30:E30) -> 12645.19
A31: =A30+1 -> 23 | C31: 5900 | E31: 417.18 | F31: =SUM(D31:E31) -> 417.18
A32: =A31+1 -> 24 | C32: 5910 | D32: 14.55 | F32: =SUM(D32:E32) -> 14.55
A33: =A32+1 -> 25 | C33: 5920 | D33: -77.84 | E33: -1650.92 | F33: =SUM(D33:E33) -> -1728.76
A34: =A33+1 -> 26 | C34: 5930 | D34: -0.63 | E34: 2210.93 | F34: =SUM(D34:E34) -> 2210.3
A35: =A34+1 -> 27 | C35: 5940 | D35: 0.51 | F35: =SUM(D35:E35) -> 0.51
A36: =A35+1 -> 28 | C36: 5970 | E36: 22.01 | F36: =SUM(D36:E36) -> 22.01
A37: =A36+1 -> 29 | C37: 5980 | D37: -0.25 | E37: -4.45 | F37: =SUM(D37:E37) -> -4.7
A38: =A37+1 -> 30 | C38: 9010 | E38: 2111.82 | F38: =SUM(D38:E38) -> 2111.82
A39: =A38+1 -> 31 | C39: 9020 | D39: 253.39 | E39: 4422.38 | F39: =SUM(D39:E39) -> 4675.77
A40: =A39+1 -> 32 | C40: 9030 | D40: 3628.75 | E40: 115166.31 | F40: =SUM(D40:E40) -> 118795.06
A41: =A40+1 -> 33 | C41: 9050 | E41: 1488.21 | F41: =SUM(D41:E41) -> 1488.21
A42: =A41+1 -> 34 | C42: 9070 | D42: -1.81 | E42: -7526.59 | F42: =SUM(D42:E42) -> -7528.4
A43: =A42+1 -> 35 | C43: 9080 | D43: -0.17 | E43: 100.12 | F43: =SUM(D43:E43) -> 99.95
...

Sheet WP II-D-1-4 ICP
A1: PUBLIC UTILITY COMMISSION OF TEXAS | F1: WP II-D-1-4
A2: AEP TEXAS INC - CENTRAL DIVISION
A3: ANNUAL INCENTIVE PLAN EXPENSE ADJUSTMENT
A4: TEST YEAR ENDING 12/31/2018
A8: Line | B8: Description | C8: Account | D8: Test Year | E8: Projected | F8: Adjustment
A9: 1
A10: =A9+1 -> 2 | B10: Adjust Transmission Annual Incentive Plan | C10: 5600 | D10: 135599.2 | E10: 87416.033 | F10: =E10-D10 -> -48183.168
A11: =A10+1 -> 3 | C11: 5612 | D11: 7596.7859 | E11: 4897.3805 | F11: =E11-D11 -> -2699.4054
A12: =A11+1 -> 4 | C12: 5620 | D12: 67713.764 | E12: 43652.681 | F12: =E12-D12 -> -24061.083
A13: =A12+1 -> 5 | C13: 5630 | D13: 32.248956 | E13: 20.789767 | F13: =E13-D13 -> -11.459189
A14: =A13+1 -> 6 | C14: 5660 | D14: 211203.76 | E14: 136208.37 | F14: =E14-D14 -> -74995.399
A15: =A14+1 -> 7 | C15: 5680 | D15: 533.32856 | E15: 343.81815 | F15: =E15-D15 -> -189.5104
A16: =A15+1 -> 8 | C16: 5690 | D16: 505.1387 | E16: 325.64514 | F16: =E16-D16 -> -179.49355
A17: =A16+1 -> 9 | C17: 5700 | D17: 243798.05 | E17: 157168.02 | F17: =E17-D17 -> -86630.026
A18: =A17+1 -> 10 | C18: 5710 | D18: 44247.823 | E18: 28570.322 | F18: =E18-D18 -> -15677.501
A19: =A18+1 -> 11 | C19: 5730 | D19: 187.16602 | E19: 120.65935 | F19: =E19-D19 -> -66.506675
A20: =A19+1 -> 12 | C20: 9200 | D20: 324.35125 | E20: 209.09784 | F20: =E20-D20 -> -115.25341
A21: =A20+1 -> 13 | C21: 9302 | D21: 166.545 | E21: 107.3657 | F21: =E21-D21 -> -59.1793
A22: =A21+1 -> 14 | C22: 9350 | D22: 3829.2024 | E22: 2468.552 | F22: =E22-D22 -> -1360.6504
A23: =A22+1 -> 15 | C23: Total | D23: =SUM(D10:D22) -> 715737.37 | E23: =SUM(E10:E22) -> 461508.73 | F23: =SUM(F10:F22) -> -254228.64
A24: =A23+1 -> 16
A25: =A24+1 -> 17 | B25: Adjust Distribution Annual Incentive Plan | C25: 5800 | D25: 225499.75 | E25: 174534.56 | F25: =E25-D25 -> -50965.191
A26: =A25+1 -> 18 | C26: 5810 | D26: 267328.12 | E26: 211483.04 | F26: =E26-D26 -> -55845.074
A27: =A26+1 -> 19 | C27: 5820 | D27: 24853.986 | E27: 19661.967 | F27: =E27-D27 -> -5192.019
A28: =A27+1 -> 20 | C28: 5830 | D28: 242820.8 | E28: 192094.16 | F28: =E28-D28 -> -50726.639
A29: =A28+1 -> 21 | C29: 5840 | D29: 5440.214 | E29: 4303.7486 | F29: =E29-D29 -> -1136.4654
A30: =A29+1 -> 22 | C30: 5850 | D30: 3325.1971 | E30: 2630.5606 | F30: =E30-D30 -> -694.63655
A31: =A30+1 -> 23 | C31: 5860 | D31: 609934.91 | E31: 486922.96 | F31: =E31-D31 -> -123011.95
A32: =A31+1 -> 24 | C32: 5870 | D32: 67085.457 | E32: 53071.247 | F32: =E32-D32 -> -14014.21
A33: =A32+1 -> 25 | C33: 5880 | D33: 1373030.5 | E33: 1098482.7 | F33: =E33-D33 -> -274547.79
A34: =A33+1 -> 26 | C34: 5900 | D34: 6122.5968 | E34: 6092.7854 | F34: =E34-D34 -> -29.811454
A35: =A34+1 -> 27 | C35: 5920 | D35: -4630.6975 | E35: -2751.4564 | F35: =E35-D35 -> 1879.2411
A36: =A35+1 -> 28 | C36: 5930 | D36: 1360739.2 | E36: 1078872.3 | F36: =E36-D36 -> -281866.87
A37: =A36+1 -> 29 | C37: 5940 | D37: 16316.063 | E37: 12907.623 | F37: =E37-D37 -> -3408.4396
... A52: =A51+1 -> 44 | C52: 9350 | D52: 324729.57 | E52: 215643.73 | F52: =E52-D52 -> -109085.84
A53: =A52+1 -> 45 | C53: Total | D53: =SUM(D25:D52) -> 5699203 | E53: =SUM(E25:E52) -> 4469837.5 | F53: =SUM(F25:F52) -> -1229365.5
A54: =A53+1 -> 46
A55: =A54+1 -> 47 | B55: Total Company Annual Incentive Plan Adj | C55: 5600 | D55: =D10 -> 135599.2 | E55: =E10 -> 87416.033 | F55: =E55-D55 -> -48183.168
A56: =A55+1 -> 48 | C56: 5612 | D56: =D11 -> 7596.7859 | E56: =E11 -> 4897.3805 | F56: =E56-D56 -> -2699.4054
A57: =A56+1 -> 49 | C57: 5620 | D57: =D12 -> 67713.764 | E57: =E12 -> 43652.681 | F57: =E57-D57 -> -24061.083
...

Sheet WP II-D-1-5 LTIP
A1: PUBLIC UTILITY COMMISSION OF TEXAS | F1: WP II-D-1-5
A2: AEP TEXAS INC - CENTRAL DIVISION
A3: LONG TERM INCENTIVE PLAN EXPENSE ADJUSTMENT
A4: TEST YEAR ENDING 12/31/2018
A8: Line | B8: Description | C8: Account | D8: Test Year | E8: Projected | F8: Adjustment
A9: 1
A10: =A9+1 -> 2 | B10: Adjust Transmission Long Term Incentive Plan | C10: 5600 | D10: 1875.7172 | E10: 1540.1889 | F10: =E10-D10 -> -335.52835
A11: =A10+1 -> 3 | C11: 5612 | D11: 93.844799 | E11: 78.309652 | F11: =E11-D11 -> -15.535147
A12: =A11+1 -> 4 | C12: 5620 | D12: 980.48555 | E12: 803.12487 | F12: =E12-D12 -> -177.36068
A13: =A12+1 -> 5 | C13: 5630 | D13: 0.56880646 | E13: 0.44937147 | F13: =E13-D13 -> -0.11943499
A14: =A13+1 -> 6 | C14: 5660 | D14: 1541.8864 | E14: 1131.1264 | F14: =E14-D14 -> -410.76005
A15: =A14+1 -> 7 | C15: 5680 | D15: 8.4760924 | E15: 6.3318971 | F15: =E15-D15 -> -2.1441954
A16: =A15+1 -> 8 | C16: 5690 | D16: 2.3156087 | E16: 1.8538759 | F16: =E16-D16 -> -0.46173275
A17: =A16+1 -> 9 | C17: 5700 | D17: 2759.2045 | E17: 2331.6476 | F17: =E17-D17 -> -427.5569
A18: =A17+1 -> 10 | C18: 5710 | D18: 644.3043 | E18: 522.00107 | F18: =E18-D18 -> -122.30324
A19: =A18+1 -> 11 | C19: 5730 | D19: 5.12832 | E19: 3.7842503 | F19: =E19-D19 -> -1.3440698
A20: =A19+1 -> 12 | C20: 9200 | D20: 2.404584 | E20: 2.213346 | F20: =E20-D20 -> -0.19123799
A21: =A20+1 -> 13 | C21: 9302 | D21: 1.3143944 | E21: 1.0821015 | F21: =E21-D21 -> -0.23229285
A22: =A21+1 -> 14 | C22: 9350 | D22: 45.706615 | E22: 38.309997 | F22: =E22-D22 -> -7.3966184
A23: =A22+1 -> 15 | C23: Total | D23: =SUM(D10:D22) -> 7961.3573 | E23: =SUM(E10:E22) -> 6460.4233 | F23: =SUM(F10:F22) -> -1500.934
A24: =A23+1 -> 16
A25: =A24+1 -> 17 | B25: Adjust Distribution Long Term Incentive Plan | C25: 5800 | D25: 17216.89 | E25: 14311.182 | F25: =E25-D25 -> -2905.7077
A26: =A25+1 -> 18 | C26: 5810 | D26: 25824.593 | E26: 21497.51 | F26: =E26-D26 -> -4327.083
A27: =A26+1 -> 19 | C27: 5820 | D27: 2852.8441 | E27: 2315.15 | F27: =E27-D27 -> -537.69411
A28: =A27+1 -> 20 | C28: 5830 | D28: 27470.216 | E28: 22783.814 | F28: =E28-D28 -> -4686.4025
A29: =A28+1 -> 21 | C29: 5840 | D29: 1092.4206 | E29: 888.99513 | F29: =E29-D29 -> -203.42546
A30: =A29+1 -> 22 | C30: 5850 | D30: 279.4773 | E30: 244.83821 | F30: =E30-D30 -> -34.63909
A31: =A30+1 -> 23 | C31: 5860 | D31: 60523.924 | E31: 50241.095 | F31: =E31-D31 -> -10282.829
A32: =A31+1 -> 24 | C32: 5870 | D32: 7140.9756 | E32: 5926.8449 | F32: =E32-D32 -> -1214.1308
A33: =A32+1 -> 25 | C33: 5880 | D33: 83922.243 | E33: 63549.225 | F33: =E33-D33 -> -20373.018
A34: =A33+1 -> 26 | C34: 5900 | D34: 76.051596 | E34: 61.443911 | F34: =E34-D34 -> -14.607685
A35: =A34+1 -> 27 | C35: 5920 | D35: 98.332019 | E35: 76.228296 | F35: =E35-D35 -> -22.103723
A36: =A35+1 -> 28 | C36: 5930 | D36: 125398.69 | E36: 103099.3 | F36: =E36-D36 -> -22299.39
A37: =A36+1 -> 29 | C37: 5940 | D37: 1254.5125 | E37: 1041.0392 | F37: =E37-D37 -> -213.47327
... A52: =A51+1 -> 44 | C52: 9350 | D52: 19429.324 | E52: 16090.214 | F52: =E52-D52 -> -3339.1107
A53: =A52+1 -> 45 | C53: Total | D53: =SUM(D25:D52) -> 483824.19 | E53: =SUM(E25:E52) -> 393963.07 | F53: =SUM(F25:F52) -> -89861.117
A54: =A53+1 -> 46
A55: =A54+1 -> 47 | B55: Total Company Long Term Incentive Plan Adj | C55: 5600 | D55: =D10 -> 1875.7172 | E55: =E10 -> 1540.1889 | F55: =E55-D55 -> -335.52835
A56: =A55+1 -> 48 | C56: 5612 | D56: =D11 -> 93.844799 | E56: =E11 -> 78.309652 | F56: =E56-D56 -> -15.535147
A57: =A56+1 -> 49 | C57: 5620 | D57: =D12 -> 980.48555 | E57: =E12 -> 803.12487 | F57: =E57-D57 -> -177.36068
...

Sheet WP II-D-1-6 DSM
A1: PUBLIC UTILITY COMMISSION OF TEXAS | D1: WP II-D-1-6
A2: AEP TEXAS INC - CENTRAL DIVISION
A3: DSM EXPENSE ADJUSTMENT
A4: TEST YEAR ENDING 12/31/2018
A9: DESCRIPTION | B9: Account | C9: Transmission | D9: Distribution
A11: Test Year DSM Expense | B11: 9070001 | D11: =-SUM('[13]TCC 2018'!$E$25,'[13]TCC 2018'!$F$25) -> -13833608
B12: 9070014 | D12: 72975.18
C14: =SUM(C11:C13) -> 0 | D14: =SUM(D11:D13) -> -13760633
A16: To remove Test Year DSM costs recovered through Rider

Sheet WP II-D-1-7 NONRECURRING
A1: PUBLIC UTILITY COMMISSION OF TEXAS | G1: WP/ II-D-1-7
A2: AEP TEXAS INC - CENTRAL DIVISION
A3: WP/ II-D-1-7 RECLASS NONRECURRING ACTIVITY
A4: TEST YEAR ENDING 12/31/2018
A8: Line No. | B8: Account Number | C8: Description | E8: Transmission | F8: Distribution | G8: Total T&D
A10: 1 | B10: 5860 | C10: Meter Expenses | E10: 405000 | F10: -405000 | G10: =+SUM(E10:F10) -> 0
A11: 2 | C11: Correct 2/18 journal id RECLPREPAY, s/b Distribution
A13: 3 | C13: Total | E13: =+SUM(E10:E11) -> 405000 | F13: =+SUM(F10:F11) -> -405000 | G13: =+SUM(G10:G11) -> 0

Sheet WP II-D-1-8 Functionalization
A1: PUBLIC UTILITY COMMISSION OF TEXAS | G1: WP II-D-1-8
A2: AEP TEXAS INC - CENTRAL DIVISION
A3: FUNCTIONALIZE O&M ACTIVITY
A4: TEST YEAR ENDING 12/31/2018
A8: Line | B8: Description | D8: Account | E8: Transmission | F8: Distribution | G8: Total
A9: 1
A10: =A9+1 -> 2 | B10: Adjust Transmission activity recorded in distribution accounts
A11: =A10+1 -> 3 | C11: 580 | D11: Oper Supervision & Engineering | E11: -41186.71 | G11: =SUM(E11:F11) -> -41186.71
A12: =A11+1 -> 4 | C12: 582 | D12: Station Expenses | E12: -11400.12 | G12: =SUM(E12:F12) -> -11400.12
A13: =A12+1 -> 5 | C13: 583 | D13: Overhead Line Expenses | E13: -6830.28 | G13: =SUM(E13:F13) -> -6830.28
A14: =A13+1 -> 6 | C14: 586 | D14: Meter Expenses | E14: -4467.06 | G14: =SUM(E14:F14) -> -4467.06
A15: =A14+1 -> 7 | C15: 588 | D15: Miscellaneous Distribution Exp | E15: -84001.87 | G15: =SUM(E15:F15) -> -84001.87
A16: =A15+1 -> 8 | C16: 590 | D16: Maint Supv & Engineering | E16: 59.59 | G16: =SUM(E16:F16) -> 59.59
A17: =A16+1 -> 9 | C17: 591 | D17: Maintenance of Structures | E17: -10376.63 | G17: =SUM(E17:F17) -> -10376.63
A18: =A17+1 -> 10 | C18: 592 | D18: Maint of Station Equipment | E18: -46287.54 | G18: =SUM(E18:F18) -> -46287.54
A19: =A18+1 -> 11 | C19: 593 | D19: Maintenance of Overhead Lines | E19: -2050.56 | G19: =SUM(E19:F19) -> -2050.56
A20: =A19+1 -> 12 | C20: 598 | D20: Maint of Misc Distribution Plt | E20: -4527.28 | G20: =SUM(E20:F20) -> -4527.28
A21: =A20+1 -> 13 | C21: 560 | D21: Oper Supervision & Engineering | E21: 41186.71 | G21: =SUM(E21:F21) -> 41186.71
A22: =A21+1 -> 14 | C22: 562 | D22: Station Expenses | E22: 11400.12 | G22: =SUM(E22:F22) -> 11400.12
A23: =A22+1 -> 15 | C23: 563 | D23: Overhead Line Expenses | E23: 6830.28 | G23: =SUM(E23:F23) -> 6830.28
A24: =A23+1 -> 16 | C24: 566 | D24: Misc Transmission Expenses | E24: 4467.06 | G24: =SUM(E24:F24) -> 4467.06
A25: =A24+1 -> 17 | C25: 566 | D25: Misc Transmission Expenses | E25: 84001.87 | G25: =SUM(E25:F25) -> 84001.87
A26: =A25+1 -> 18 | C26: 568 | D26: Maint Supv & Engineering | E26: -59.59 | G26: =SUM(E26:F26) -> -59.59
A27: =A26+1 -> 19 | C27: 569 | D27: Maintenance of Structures | E27: 10376.63 | G27: =SUM(E27:F27) -> 10376.63
A28: =A27+1 -> 20 | C28: 570 | D28: Maint of Station Equipment | E28: 46287.54 | G28: =SUM(E28:F28) -> 46287.54
A29: =A28+1 -> 21 | C29: 571 | D29: Maintenance of Overhead Lines | E29: 2050.56 | G29: =SUM(E29:F29) -> 2050.56
A30: =A29+1 -> 22 | C30: 573 | D30: Maint of Misc Trnsmssion Plt | E30: 4527.28 | G30: =SUM(E30:F30) -> 4527.28
A31: =A30+1 -> 23 | C31: Total | E31: =SUM(E11:E30) -> 0 | F31: =SUM(F11:F30) -> 0 | G31: =SUM(G11:G30) -> 0
A32: =A31+1 -> 24
A33: =A32+1 -> 25 | B33: Adjust Distribution activity recorded in transmission accounts
A34: =A33+1 -> 26 | C34: 560 | D34: Oper Supervision & Engineering | F34: -24959.27 | G34: =SUM(E34:F34) -> -24959.27
A35: =A34+1 -> 27 | C35: 561 | D35: Load Dispatching | F35: -32711.23 | G35: =SUM(E35:F35) -> -32711.23
A36: =A35+1 -> 28 | C36: 562 | D36: Station Expenses - Nonassoc | F36: -7751.46 | G36: =SUM(E36:F36) -> -7751.46
A37: =A36+1 -> 29 | C37: 563 | D37: Overhead Line Expenses | F37: -17464.76 | G37: =SUM(E37:F37) -> -17464.76
A38: =A37+1 -> 30 | C38: 566 | D38: Misc Transmission Expenses | F38: -56404.89 | G38: =SUM(E38:F38) -> -56404.89
A39: =A38+1 -> 31 | C39: 568 | D39: Maint Supv & Engineering | F39: -26.67 | G39: =SUM(E39:F39) -> -26.67
A40: =A39+1 -> 32 | C40: 569 | D40: Maintenance of Structures | F40: -5137.54 | G40: =SUM(E40:F40) -> -5137.54
A41: =A40+1 -> 33 | C41: 570 | D41: Maint of Station Equipment | F41: -16019.71 | G41: =SUM(E41:F41) -> -16019.71
A42: =A41+1 -> 34 | C42: 571 | D42: Maintenance of Overhead Lines | F42: 521.55 | G42: =SUM(E42:F42) -> 521.55
A43: =A42+1 -> 35 | C43: 573 | D43: Maint of Misc Trnsmssion Plt | F43: -77.2 | G43: =SUM(E43:F43) -> -77.2
...

Sheet WP II-D-1-9 Bad Debt
A1: PUBLIC UTILITY COMMISSION OF TEXAS | D1: WP II-D-1-9
A2: AEP TEXAS INC - CENTRAL DIVISION
A3: BAD DEBT EXPENSE ADJUSTMENT
A4: TEST YEAR ENDING 12/31/2018
A7: DESCRIPTION | B7: FERC | C7: Transmission | D7: Distribution
A9: Bad Debt Expense For Test Year | B9: 904 | C9: 2509.02 | D9: 816088.35
A11: Adjustments:
A12: Pro forma Bad Debt Expense Adjustment | C12: ='[14]TCC Test Yr'!$E$17 -> -2500 | D12: ='[14]TCC Test Yr'!$E$99 -> -789340.03
A14: Total Adjustments | C14: =C12 -> -2500 | D14: =D12 -> -789340.03
A16: Pro forma Bad Debt Expense | C16: =SUM(C9:C12) -> 9.02 | D16: =SUM(D9:D12) -> 26748.32
A18: Total Proforma T & D | C18: =SUM(C16:D16) -> 26757.34
A21: Purpose: To adjust bad debt expense to represent actual test year bad debt cost

Sheet WP II-D-1-10 Sales Expenses
A1: PUBLIC UTILITY COMMISSION OF TEXAS | G1: WP/ II-D-1-10
A2: AEP TEXAS INC - CENTRAL DIVISION
A3: WP/ II-D-1-10 ELIMINATION OF SALES EXPENSES
A4: TEST YEAR ENDING 12/31/2018
A8: Line No. | B8: Account Number | C8: Description | E8: Transmission | F8: Distribution | G8: Total T&D
A9: 1 | B9: 9110 | C9: Supervision | E9: 0 | F9: =-13.02+2.26 -> -10.76 | G9: =+SUM(E9:F9) -> -10.76
A10: 2 | B10: 9120 | C10: Demonstrating & Selling Exp | E10: =-10191.47-'[10]Attachment II-D-1 O&M'!$I$146 -> -9585.23 | F10: =-246971.4-'[10]Attachment II-D-1 O&M'!$I$199 -> -232338.6 | G10: =+SUM(E10:F10) -> -241923.83
A12: 3 | C12: Total | E12: =+SUM(E9:E10) -> -9585.23 | F12: =+SUM(F9:F10) -> -232349.36 | G12: =+SUM(G9:G10) -> -241934.59
B22: Purpose: To eliminate Demonstrating & Selling Expenses from Operating Income in accordance with PUC SUBST. R. 25.231(b)(2)(F).

Sheet WP II-D-1-11 EMP EXP
A1: PUBLIC UTILITY COMMISSION OF TEXAS | E1: WP II-D-1-11
A2: AEP TEXAS INC - CENTRAL DIVISION
A3: WP/ II-D-1-11 EMPLOYEE EXPENSE ADJUSTMENT
A4: TEST YEAR ENDING 12/31/2018
A8: Line No. | B8: Account Number | C8: Transmission | D8: Distribution | E8: Total T&D
A9: 1 | B9: 5600 | C9: -647.64 | D9: 0 | E9: =+SUM(C9:D9) -> -647.64
A10: =+A9+1 -> 2 | B10: 5660 | C10: -41.13 | D10: 0 | E10: =+SUM(C10:D10) -> -41.13
A11: =+A10+1 -> 3 | B11: 5800 | C11: 0 | D11: -895.08 | E11: =+SUM(C11:D11) -> -895.08
A12: =+A11+1 -> 4 | B12: 5810 | C12: 0 | D12: -290.14 | E12: =+SUM(C12:D12) -> -290.14
A13: =+A12+1 -> 5 | B13: 5830 | C13: 0 | D13: -52.33 | E13: =+SUM(C13:D13) -> -52.33
A14: =+A13+1 -> 6 | B14: 5840 | C14: 0 | D14: -198.55 | E14: =+SUM(C14:D14) -> -198.55
A15: =+A14+1 -> 7 | B15: 5860 | C15: 0 | D15: -2605.82 | E15: =+SUM(C15:D15) -> -2605.82
A16: =+A15+1 -> 8 | B16: 5880 | C16: 0 | D16: -7906.67 | E16: =+SUM(C16:D16) -> -7906.67
A17: =+A16+1 -> 9 | B17: 5920 | C17: -127.56 | D17: 0 | E17: =+SUM(C17:D17) -> -127.56
A18: =+A17+1 -> 10 | B18: 5930 | C18: 0 | D18: -29.54 | E18: =+SUM(C18:D18) -> -29.54
A19: =+A18+1 -> 11 | B19: 5950 | C19: 0 | D19: -81.46 | E19: =+SUM(C19:D19) -> -81.46
A20: =+A19+1 -> 12 | B20: 9010 | C20: 0 | D20: -173.17 | E20: =+SUM(C20:D20) -> -173.17
A21: =+A20+1 -> 13 | B21: 9030 | C21: 0 | D21: -2142.69 | E21: =+SUM(C21:D21) -> -2142.69
... A26: =+A25+1 -> 18 | B26: 9350 | C26: 0 | D26: -1141.97 | E26: =+SUM(C26:D26) -> -1141.97
A27: Total | C27: =+SUM(C9:C26) -> -816.33 | D27: =+SUM(D9:D26) -> -53613.27 | E27: =+SUM(E9:E26) -> -54429.6
B31: Purpose: To remove employee expenses the Company is not seeking to recover.

Sheet WP II-D-1-12 Distibution OM
A1: PUBLIC UTILITY COMMISSION OF TEXAS | G1: WP/ II-D-1-12
A2: AEP TEXAS INC - CENTRAL DIVISION
A3: WP/ II-D-1-12 DISTRIBUTION O&M EXPENSE
A4: TEST YEAR ENDING 12/31/2018
A8: Line No. | B8: Account Number | C8: Description | E8: Transmission | F8: Distribution | G8: Total T&D
A10: 1 | B10: 5930 | C10: Vegetation Management | F10: 4000000 | G10: =+SUM(E10:F10) -> 4000000
A12: 3 | C12: Total | E12: =+SUM(E10:E10) -> 0 | F12: =+SUM(F10:F10) -> 4000000 | G12: =+SUM(G10:G10) -> 4000000
B22: Purpose: To increase Distribution O&M expense for Vegetation Management expenses as discussed in the Direct testimony of Thomas M. Coad.

Sheet WP II-D-1-13 Tree Trimming
A1: PUBLIC UTILITY COMMISSION OF TEXAS | G1: WP/ II-D-1-13
A2: AEP TEXAS INC - CENTRAL DIVISION
A3: WP/ II-D-1-13 TREE TRIMMING
A4: TEST YEAR ENDING 12/31/2018
A8: Line No. | B8: Account Number | C8: Description | E8: Transmission | F8: Distribution | G8: Total T&D
A10: 1 | B10: 5630 | C10: Tree trimming | E10: 255107 | G10: =+SUM(E10:F10) -> 255107
A11: 2 | B11: 5930 | C11: Tree trimming | F11: 2726923 | G11: =+SUM(E11:F11) -> 2726923
A13: 3 | C13: Total | E13: =+SUM(E10:E11) -> 255107 | F13: =+SUM(F10:F11) -> 2726923 | G13: =+SUM(G10:G11) -> 2982030
B23: Purpose: To increase O&M expense for non-capitalized tree trimming expense as discussed in the Direct testimony of Thomas M. Coad and Daniel R. Boezio.

Sheet WP II-D-2-1 Cr Line Fees
A1: PUBLIC UTILITY COMMISSION OF TEXAS | G1: WP/ II-D-2-1
A2: AEP TEXAS INC - CENTRAL DIVISION
A3: WP/ II-D-2-1 RECLASSIFICATION OF BANK CREDIT FEES
A4: TEST YEAR ENDING 12/31/2018
A8: Line No. | B8: Account Number | C8: Description | E8: Transmission | F8: Distribution | G8: Total T&D
A9: 1 | B9: 9302 | C9: Misc General Expenses | E9: 98080.62 | F9: 121265.57 | G9: =SUM(E9:F9) -> 219346.19
B21: Purpose: To reclassify bank lines of credit expense from interest expense (A/C 4310007) to A&G
B22: Expense (A/C 9302)

Sheet WP II-D-2-2 Catastrophe reserve
B1: PUBLIC UTILITY COMMISSION OF TEXAS | F1: WP/ II-D-2-x
B2: AEP TEXAS INC - CENTRAL DIVISION
B3: WP/ II-D-2-2 Catastrophe Rreserve Expense
B4: TEST YEAR ENDING 12/31/2018
A8: Line No. | B8: Account Number | C8: Description | D8: Transmission | E8: Distribution | F8: Total T&D
A9: 1 | B9: 1823 | C9: Filed Reserve Amount | D9: -4536379 | E9: 13719898 | F9: =SUM(D9:E9) -> 9183518.5
A10: 2 | B10: 1823 | C10: Target Reserve | D10: ='[15]Pro-Forma Adjustment'!$D$10 -> 160445.36 | E10: ='[15]Pro-Forma Adjustment'!$E$10 -> 10439555 | F10: =SUM(D10:E10) -> 10600000
A11: 3 | B11: 1823 | C11: Adjustment | D11: =D10-D9 -> 4696824.4 | E11: =E10-E9 -> -3280342.9 | F11: =SUM(D11:E11) -> 1416481.5
A12: 4 | B12: N/A | C12: Amortization Period | D12: 3 | E12: 3 | F12: 3
A13: 5 | B13: 924 | C13: Pro-Forma Adjustment To Build Storm Reserve | D13: =D11/D12 -> 1565608.1 | E13: =E11/E12 -> -1093447.6 | F13: =SUM(D13:E13) -> 472160.5
A15: 6 | B15: 924 | C15: Adjustment Annual Storm | D15: ='[15]Pro-Forma Adjustment'!$D$15 -> 35570.435 | E15: ='[15]Pro-Forma Adjustment'!$E$15 -> 2314429.6 | F15: =D15+E15 -> 2350000
A16: 7 | B16: 924 | C16: Total Reserve Amount | D16: =D13+D15 -> 1601178.6 | E16: =E13+E15 -> 1220981.9 | F16: =F13+F15 -> 2822160.5
A17: 8 | B17: 924 | C17: Amount in Test Year | D17: -126918 | E17: -1173082 | F17: =SUM(D17:E17) -> -1300000
A18: 9 | B18: 924 | C18: Pro-Forma Adjustment | D18: =D16+D17 -> 1474260.6 | E18: =E16+E17 -> 47899.972 | F18: =F16+F17 -> 1522160.5
B21: Purpose: To increase catastrophe reserve expense as discussed in the direct testimony of Randall W. Hamlett.

Sheet WP II-D-2-3 ASC 715-30 Pension
A1: PUBLIC UTILITY COMMISSION OF TEXAS | G1: WP/ II-D-2-3
A2: AEP TEXAS INC - CENTRAL DIVISION
A3: WP/ II-D-2-3 ASC 715-30 (SFAS 87) PENSION EXPENSE
A4: TEST YEAR ENDING 12/31/2018
A8: Line No. | B8: Account Number | C8: Description | D8: Reference | E8: Transmission | F8: Distribution | G8: Total T&D
A9: 1 | B9: Pension Expense Per Books For TY Ending 12/31/18
A10: =A9+1 -> 2 | B10: 9260003 | C10: Pension Plan | E10: 998625 | F10: 5942629 | G10: =+SUM(E10:F10) -> 6941254
A11: =A10+1 -> 3 | B11: 9260037 | C11: Supplemental Pension | F11: 21570 | G11: =+SUM(F11:F11) -> 21570
A12: =A11+1 -> 4 | B12: 9260042 | C12: SERP Pension - Non-Service | F12: 184591 | G12: =+SUM(F12:F12) -> 184591
A13: =A12+1 -> 5 | B13: 9260050 | C13: Frg Ben Loading - Pension | E13: -682770.93 | F13: -2546376.6 | G13: =+SUM(E13:F13) -> -3229147.5
A14: =A13+1 -> 6 | B14: 9260062 | C14: Pension Plan - Non-Service | E14: -110011.06 | F14: -1886067 | G14: =+SUM(E14:F14) -> -1996078.1
A15: =A14+1 -> 7 | C15: Test Year SFAS 87 Pension Expense | E15: =SUM(E10:E14) -> 205843.01 | F15: =SUM(F10:F14) -> 1716346.4 | G15: =SUM(G10:G14) -> 1922189.4
A16: =A15+1 -> 8
A17: =A16+1 -> 9 | B17: Gross Pension Expense | G17: =+SUM(G10:G12)+SUM(G14) -> 5151336.9
A18: =A17+1 -> 10
A19: =A18+1 -> 11 | B19: 2019 Actuarial Estimate
A20: =A19+1 -> 12 | C20: 2019 ASC 715-30 (SFAS 87) Pension Cost | D20: Qualfd Rpt | E20: 831000 | F20: 3354000 | G20: =+SUM(E20:F20) -> 4185000
A21: =A20+1 -> 13 | C21: 2019 ASC 715-30 (SFAS 87) SERP Cost | D21: SERP Rpt | E21: 0 | F21: 179000 | G21: =+SUM(E21:F21) -> 179000
A22: =A21+1 -> 14 | E22: =SUM(E20:E21) -> 831000 | F22: =SUM(F20:F21) -> 3533000 | G22: =SUM(G20:G21) -> 4364000
A23: =A22+1 -> 15
A24: =A23+1 -> 16 | B24: 2018 Payroll Expense Ratio | E24: ='[10]II-D-3.4 Exp vs Capital'!$C$24/'[10]II-D-3.4 Exp vs Capital'!$F$24 -> 0.30070909 | F24: ='[10]II-D-3.4 Exp vs Capital'!$AD$24/'[10]II-D-3.4 Exp vs Capital'!$AG$24 -> 0.446763
A25: =A24+1 -> 17 | B25: 2018 Pension Cost Expense | E25: =+E22*E24 -> 249889.25 | F25: =+F22*F24 -> 1578413.7 | G25: =SUM(E25:F25) -> 1828302.9
A26: =A25+1 -> 18
A27: =A26+1 -> 19
A28: =A27+1 -> 20 | B28: Increase (Decrease) to TY Expense | D28: 926 | E28: =+E25-E15 -> 44046.243 | F28: =+F25-F15 -> -137932.71 | G28: =+G25-G15 -> -93886.471
B31: Purpose: To adjust pension expense to reflect current actuarial reports

Sheet WP II-D-2-4 ASC 715 OPEB
A1: PUBLIC UTILITY COMMISSION OF TEXAS | G1: WP/ II-D-2-4
A2: AEP TEXAS INC - CENTRAL DIVISION
A3: WP/ II-D-2-4 ASC 715 (SFAS 106) ADUSTMENT
A4: TEST YEAR ENDING 12/31/2018
A8: Line No. | B8: Account Number | C8: Description | D8: Reference | E8: Transmission | F8: Distribution | G8: Total T&D
A9: 1 | C9: 2019 ASC 715 (SFAS 106) Net Periodic Cost-Net of Medicare Subsidy | D9: Non-UMWA | E9: -455000 | F9: -4733000 | G9: =SUM(E9:F9) -> -5188000
A10: =A9+1 -> 2 | C10: Payroll Expense Ratio | D10: II-D-3-4 | E10: ='[10]II-D-3.4 Exp vs Capital'!$C$24/'[10]II-D-3.4 Exp vs Capital'!$F$24 -> 0.30070909 | F10: ='[10]II-D-3.4 Exp vs Capital'!$AD$24/'[10]II-D-3.4 Exp vs Capital'!$AG$24 -> 0.446763
A11: =A10+1 -> 3 | C11: 2019 ASC 715 (SFAS 106) Expense | D11: (a) | E11: =+E9*E10 -> -136822.64 | F11: =+F9*F10 -> -2114529.3 | G11: =SUM(E11:F11) -> -2251351.9
A12: =A11+1 -> 4
A13: =A12+1 -> 5 | B13: 9260021 | C13: ASC 715 (SFAS 106) OPEB | E13: 86465.03 | F13: 588695.03 | G13: =SUM(E13:F13) -> 675160.06
A14: =A13+1 -> 6 | B14: 9260043 | C14: OPEB Non-Service | E14: -663769.07 | F14: -6548251 | G14: =SUM(E14:F14) -> -7212020
A15: =A14+1 -> 7 | B15: 9260053 | C15: Capitalized ASC 715 (SFAS 106) OPEB | D15: WP II-D-2-4-1 | E15: ='WP II-D-2-4-1 OPEB_FAS 112'!F20 -> -34771.539 | F15: ='WP II-D-2-4-1 OPEB_FAS 112'!F12 -> -12698.184 | G15: =SUM(E15:F15) -> -47469.722
A16: =A15+1 -> 8 | B16: 9260060 | C16: Amort-Post Retirement Benefit | E16: 52826.52 | F16: 478915.8 | G16: =SUM(E16:F16) -> 531742.32
A17: =A16+1 -> 9 | C17: Test Year OPEB expense | D17: (b) | E17: =SUM(E13:E16) -> -559249.06 | F17: =SUM(F13:F16) -> -5493338.3 | G17: =SUM(G13:G16) -> -6052587.4
A18: =A17+1 -> 10
