Workbook

Sheet RBH-1 Constant Growth DCF
B2: Constant Growth Discounted Cash Flow Model
B3: 30 Day Average Stock Price
E5: [1] | F5: [2] | G5: [3] | H5: [4] | I5: [5] | J5: [6] | K5: [7] | L5: [8] | N5: [9] | O5: [10] | P5: [11]
B6: Company | C6: Ticker | E6: Annualized Dividend | F6: Average Stock Price | G6: Dividend Yield | H6: Expected Dividend Yield | I6: Zacks Earnings Growth | J6: First Call Earnings Growth | K6: Value Line Earnings Growth | L6: Average Earnings Growth | N6: Low ROE | O6: Mean ROE | P6: High ROE
B8: ALLETE, Inc. | C8: ALE | E8: 2.35 | F8: 80.266667 | G8: =E8/F8 -> 0.029277409 | H8: =G8*(1+0.5*L8) -> 0.030082537 | I8: NA | J8: 0.06 | K8: 0.05 | L8: =AVERAGE(I8:K8) -> 0.055 | N8: =G8*(1+0.5*MIN(I8:K8))+MIN(I8:K8) -> 0.080009344 | O8: =H8+L8 -> 0.085082537 | P8: =G8*(1+0.5*MAX(I8:K8))+MAX(I8:K8) -> 0.090155731
B9: Alliant Energy Corporation | C9: LNT | E9: 1.42 | F9: 45.564667 | G9: =E9/F9 -> 0.031164499 | H9: =G9*(1+0.5*L9) -> 0.03219033 | I9: 0.06 | J9: 0.0725 | K9: 0.065 | L9: =AVERAGE(I9:K9) -> 0.065833333 | N9: =G9*(1+0.5*MIN(I9:K9))+MIN(I9:K9) -> 0.092099434 | O9: =H9+L9 -> 0.098023664 | P9: =G9*(1+0.5*MAX(I9:K9))+MAX(I9:K9) -> 0.10479421
B10: Ameren Corporation | C10: AEE | E10: 1.9 | F10: 70.764333 | G10: =E10/F10 -> 0.026849684 | H10: =G10*(1+0.5*L10) -> 0.027789423 | I10: 0.068 | J10: 0.077 | K10: 0.065 | L10: =AVERAGE(I10:K10) -> 0.07 | N10: =G10*(1+0.5*MIN(I10:K10))+MIN(I10:K10) -> 0.092722299 | O10: =H10+L10 -> 0.097789423 | P10: =G10*(1+0.5*MAX(I10:K10))+MAX(I10:K10) -> 0.1048834
B11: Avangrid, Inc. | C11: AGR | E11: 1.76 | F11: 49.391 | G11: =E11/F11 -> 0.035634022 | H11: =G11*(1+0.5*L11) -> 0.037350394 | I11: 0.077 | J11: 0.092 | K11: 0.12 | L11: =AVERAGE(I11:K11) -> 0.096333333 | N11: =G11*(1+0.5*MIN(I11:K11))+MIN(I11:K11) -> 0.11400593 | O11: =H11+L11 -> 0.13368373 | P11: =G11*(1+0.5*MAX(I11:K11))+MAX(I11:K11) -> 0.15777206
B12: Black Hills Corporation | C12: BKH | E12: 2.02 | F12: 70.591333 | G12: =E12/F12 -> 0.028615411 | H12: =G12*(1+0.5*L12) -> 0.029322688 | I12: 0.047 | J12: 0.0363 | K12: 0.065 | L12: =AVERAGE(I12:K12) -> 0.049433333 | N12: =G12*(1+0.5*MIN(I12:K12))+MIN(I12:K12) -> 0.06543478 | O12: =H12+L12 -> 0.078756022 | P12: =G12*(1+0.5*MAX(I12:K12))+MAX(I12:K12) -> 0.094545412
B13: CMS Energy Corporation | C13: CMS | E13: 1.53 | F13: 53.586333 | G13: =E13/F13 -> 0.028552056 | H13: =G13*(1+0.5*L13) -> 0.029498557 | I13: 0.06 | J13: 0.0689 | K13: 0.07 | L13: =AVERAGE(I13:K13) -> 0.0663 | N13: =G13*(1+0.5*MIN(I13:K13))+MIN(I13:K13) -> 0.089408618 | O13: =H13+L13 -> 0.095798557 | P13: =G13*(1+0.5*MAX(I13:K13))+MAX(I13:K13) -> 0.099551378
B14: Consolidated Edison, Inc. | C14: ED | E14: 2.96 | F14: 80.953667 | G14: =E14/F14 -> 0.036564125 | H14: =G14*(1+0.5*L14) -> 0.037051037 | I14: 0.02 | J14: 0.0299 | K14: 0.03 | L14: =AVERAGE(I14:K14) -> 0.026633333 | N14: =G14*(1+0.5*MIN(I14:K14))+MIN(I14:K14) -> 0.056929766 | O14: =H14+L14 -> 0.063684371 | P14: =G14*(1+0.5*MAX(I14:K14))+MAX(I14:K14) -> 0.067112587
B15: DTE Energy Company | C15: DTE | E15: 3.78 | F15: 121.32633 | G15: =E15/F15 -> 0.031155644 | H15: =G15*(1+0.5*L15) -> 0.031942843 | I15: 0.06 | J15: 0.0416 | K15: 0.05 | L15: =AVERAGE(I15:K15) -> 0.050533333 | N15: =G15*(1+0.5*MIN(I15:K15))+MIN(I15:K15) -> 0.073403681 | O15: =H15+L15 -> 0.082476176 | P15: =G15*(1+0.5*MAX(I15:K15))+MAX(I15:K15) -> 0.092090313
B16: Duke Energy Corporation | C16: DUK | E16: 3.71 | F16: 89.399333 | G16: =E16/F16 -> 0.041499191 | H16: =G16*(1+0.5*L16) -> 0.042536671 | I16: 0.05 | J16: 0.045 | K16: 0.055 | L16: =AVERAGE(I16:K16) -> 0.05 | N16: =G16*(1+0.5*MIN(I16:K16))+MIN(I16:K16) -> 0.087432923 | O16: =H16+L16 -> 0.092536671 | P16: =G16*(1+0.5*MAX(I16:K16))+MAX(I16:K16) -> 0.097640419
B17: El Paso Electric Company | C17: EE | E17: 1.44 | F17: 55.155333 | G17: =E17/F17 -> 0.026108083 | H17: =G17*(1+0.5*L17) -> 0.026578028 | I17: 0.027 | J17: 0.051 | K17: 0.03 | L17: =AVERAGE(I17:K17) -> 0.036 | N17: =G17*(1+0.5*MIN(I17:K17))+MIN(I17:K17) -> 0.053460542 | O17: =H17+L17 -> 0.062578028 | P17: =G17*(1+0.5*MAX(I17:K17))+MAX(I17:K17) -> 0.077773839
B18: Evergy, Inc | C18: EVRG | E18: 1.9 | F18: 57.002667 | G18: =E18/F18 -> 0.033331774 | H18: =G18*(1+0.5*L18) -> 0.03441089 | I18: 0.067 | J18: 0.0625 | K18: NMF | L18: =AVERAGE(I18:K18) -> 0.06475 | N18: =G18*(1+0.5*MIN(I18:K18))+MIN(I18:K18) -> 0.096873392 | O18: =H18+L18 -> 0.09916089 | P18: =G18*(1+0.5*MAX(I18:K18))+MAX(I18:K18) -> 0.10144839
B19: Eversource Energy | C19: ES | E19: 2.14 | F19: 69.894333 | G19: =E19/F19 -> 0.030617647 | H19: =G19*(1+0.5*L19) -> 0.031489229 | I19: 0.057 | J19: 0.0588 | K19: 0.055 | L19: =AVERAGE(I19:K19) -> 0.056933333 | N19: =G19*(1+0.5*MIN(I19:K19))+MIN(I19:K19) -> 0.086459632 | O19: =H19+L19 -> 0.088422562 | P19: =G19*(1+0.5*MAX(I19:K19))+MAX(I19:K19) -> 0.090317805
B20: Hawaiian Electric Industries, Inc. | C20: HE | E20: 1.28 | F20: 38.426667 | G20: =E20/F20 -> 0.033310201 | H20: =G20*(1+0.5*L20) -> 0.034281749 | I20: 0.062 | J20: 0.078 | K20: 0.035 | L20: =AVERAGE(I20:K20) -> 0.058333333 | N20: =G20*(1+0.5*MIN(I20:K20))+MIN(I20:K20) -> 0.06889313 | O20: =H20+L20 -> 0.092615082 | P20: =G20*(1+0.5*MAX(I20:K20))+MAX(I20:K20) -> 0.1126093
B21: NextEra Energy, Inc. | C21: NEE | E21: 5 | F21: 185.68567 | G21: =E21/F21 -> 0.026927226 | H21: =G21*(1+0.5*L21) -> 0.028011496 | I21: 0.077 | J21: 0.0746 | K21: 0.09 | L21: =AVERAGE(I21:K21) -> 0.080533333 | N21: =G21*(1+0.5*MIN(I21:K21))+MIN(I21:K21) -> 0.10253161 | O21: =H21+L21 -> 0.10854483 | P21: =G21*(1+0.5*MAX(I21:K21))+MAX(I21:K21) -> 0.11813895
B22: NorthWestern Corporation | C22: NWE | E22: 2.3 | F22: 67.207333 | G22: =E22/F22 -> 0.034222456 | H22: =G22*(1+0.5*L22) -> 0.034698148 | I22: 0.031 | J22: 0.0274 | K22: 0.025 | L22: =AVERAGE(I22:K22) -> 0.0278 | N22: =G22*(1+0.5*MIN(I22:K22))+MIN(I22:K22) -> 0.059650237 | O22: =H22+L22 -> 0.062498148 | P22: =G22*(1+0.5*MAX(I22:K22))+MAX(I22:K22) -> 0.065752904
B23: OGE Energy Corp. | C23: OGE | E23: 1.46 | F23: 41.971 | G23: =E23/F23 -> 0.034785924 | H23: =G23*(1+0.5*L23) -> 0.035768626 | I23: 0.048 | J23: NA | K23: 0.065 | L23: =AVERAGE(I23:K23) -> 0.0565 | N23: =G23*(1+0.5*MIN(I23:K23))+MIN(I23:K23) -> 0.083620786 | O23: =H23+L23 -> 0.092268626 | P23: =G23*(1+0.5*MAX(I23:K23))+MAX(I23:K23) -> 0.10091647
B24: Otter Tail Corporation | C24: OTTR | E24: 1.4 | F24: 49.899 | G24: =E24/F24 -> 0.028056674 | H24: =G24*(1+0.5*L24) -> 0.029038658 | I24: NA | J24: 0.09 | K24: 0.05 | L24: =AVERAGE(I24:K24) -> 0.07 | N24: =G24*(1+0.5*MIN(I24:K24))+MIN(I24:K24) -> 0.078758091 | O24: =H24+L24 -> 0.099038658 | P24: =G24*(1+0.5*MAX(I24:K24))+MAX(I24:K24) -> 0.11931922
B25: Pinnacle West Capital Corporation | C25: PNW | E25: 2.95 | F25: 91.666333 | G25: =E25/F25 -> 0.032181935 | H25: =G25*(1+0.5*L25) -> 0.033005793 | I25: 0.048 | J25: 0.0456 | K25: 0.06 | L25: =AVERAGE(I25:K25) -> 0.0512 | N25: =G25*(1+0.5*MIN(I25:K25))+MIN(I25:K25) -> 0.078515683 | O25: =H25+L25 -> 0.084205793 | P25: =G25*(1+0.5*MAX(I25:K25))+MAX(I25:K25) -> 0.093147393
B26: PNM Resources, Inc. | C26: PNM | E26: 1.16 | F26: 44.137 | G26: =E26/F26 -> 0.026281804 | H26: =G26*(1+0.5*L26) -> 0.026991413 | I26: 0.046 | J26: 0.041 | K26: 0.075 | L26: =AVERAGE(I26:K26) -> 0.054 | N26: =G26*(1+0.5*MIN(I26:K26))+MIN(I26:K26) -> 0.067820581 | O26: =H26+L26 -> 0.080991413 | P26: =G26*(1+0.5*MAX(I26:K26))+MAX(I26:K26) -> 0.10226737
B27: Portland General Electric Company | C27: POR | E27: 1.45 | F27: 49.886667 | G27: =E27/F27 -> 0.029065883 | H27: =G27*(1+0.5*L27) -> 0.029690799 | I27: 0.04 | J27: 0.049 | K27: 0.04 | L27: =AVERAGE(I27:K27) -> 0.043 | N27: =G27*(1+0.5*MIN(I27:K27))+MIN(I27:K27) -> 0.0696472 | O27: =H27+L27 -> 0.072690799 | P27: =G27*(1+0.5*MAX(I27:K27))+MAX(I27:K27) -> 0.078777997
B28: Southern Company | C28: SO | E28: 2.4 | F28: 49.840333 | G28: =E28/F28 -> 0.048153771 | H28: =G28*(1+0.5*L28) -> 0.048969175 | I28: 0.045 | J28: 0.0216 | K28: 0.035 | L28: =AVERAGE(I28:K28) -> 0.033866667 | N28: =G28*(1+0.5*MIN(I28:K28))+MIN(I28:K28) -> 0.070273832 | O28: =H28+L28 -> 0.082835842 | P28: =G28*(1+0.5*MAX(I28:K28))+MAX(I28:K28) -> 0.094237231
B29: WEC Energy Group, Inc. | C29: WEC | E29: 2.36 | F29: 75.560333 | G29: =E29/F29 -> 0.031233319 | H29: =G29*(1+0.5*L29) -> 0.032013631 | I29: 0.044 | J29: 0.0459 | K29: 0.06 | L29: =AVERAGE(I29:K29) -> 0.049966667 | N29: =G29*(1+0.5*MIN(I29:K29))+MIN(I29:K29) -> 0.075920452 | O29: =H29+L29 -> 0.081980298 | P29: =G29*(1+0.5*MAX(I29:K29))+MAX(I29:K29) -> 0.092170319
B30: Xcel Energy Inc. | C30: XEL | E30: 1.62 | F30: 54.412667 | G30: =E30/F30 -> 0.029772479 | H30: =G30*(1+0.5*L30) -> 0.030665654 | I30: 0.059 | J30: 0.066 | K30: 0.055 | L30: =AVERAGE(I30:K30) -> 0.06 | N30: =G30*(1+0.5*MIN(I30:K30))+MIN(I30:K30) -> 0.085591223 | O30: =H30+L30 -> 0.090665654 | P30: =G30*(1+0.5*MAX(I30:K30))+MAX(I30:K30) -> 0.096754971
B32: Proxy Group Mean | G32: =AVERAGE(G8:G30) -> 0.03188527 | H32: =AVERAGE(H8:H30) -> 0.032755555 | I32: =AVERAGE(I8:I30) -> 0.052047619 | J32: =AVERAGE(J8:J30) -> 0.056118182 | K32: =AVERAGE(K8:K30) -> 0.056590909 | L32: =AVERAGE(L8:L30) -> 0.055345652 | N32: =AVERAGE(N8:N30) -> 0.079541877 | O32: =AVERAGE(O8:O30) -> 0.088101207 | P32: =AVERAGE(P8:P30) -> 0.097920768
B33: Proxy Group Median | G33: =MEDIAN(G8:G30) -> 0.031155644 | H33: =MEDIAN(H8:H30) -> 0.031942843 | I33: =MEDIAN(I8:I30) -> 0.05 | J33: =MEDIAN(J8:J30) -> 0.0549 | K33: =MEDIAN(K8:K30) -> 0.055 | L33: =MEDIAN(L8:L30) -> 0.055 | N33: =MEDIAN(N8:N30) -> 0.078758091 | O33: =MEDIAN(O8:O30) -> 0.088422562 | P33: =MEDIAN(P8:P30) -> 0.096754971
B35: Notes:
B36: [1] Source: Bloomberg Professional
B37: [2] Source: Bloomberg Professional, equals indicated number of trading day average as of March 15, 2019
B38: [3] Equals [1] / [2]
B39: [4] Equals [3] x (1 + 0.5 x [8])
B40: [5] Source: Zacks
B41: [6] Source: Yahoo! Finance
B42: [7] Source: Value Line
B43: [8] Equals Average([5], [6], [7])
B44: [9] Equals [3] x (1 + 0.5 x Minimum([5], [6], [7])) + Minimum([5], [6], [7])
B45: [10] Equals [4] + [8]
...

Sheet RBH-2 MRP Bloomberg
B2: Ex-Ante Market Risk Premium
B3: Market DCF Method Based - Bloomberg
D5: [1] | E5: [2] | F5: [3]
D6: S&P 500 Est. Required Market Return | E6: Current 30-Year Treasury (30-day average) | F6: Implied Market Risk Premium
D7: =I512 -> 0.13639002 | E7: ='RBH-4 CAPM'!C10 -> 0.030316667 | F7: =D7-E7 -> 0.10607335
D10: [4] | E10: [5] | F10: [6] | G10: [7] | H10: [8] | I10: [9]
B11: Company | C11: Ticker | D11: Market Capitalization | E11: Weight in Index | F11: Estimated Dividend Yield | G11: Long-Term Growth Est. | H11: DCF Result | I11: Weighted DCF Result
B12: Agilent Technologies Inc | C12: A | D12: 25750.537 | E12: =IF(OR(H12="N/A",D12="N/A"),"N/A",D12/$D$512) -> N/A | F12: 0.0082737361 | G12: N/A | H12: =IFERROR(F12*(1+0.5*G12)+G12,"N/A") -> N/A | I12: =IF(AND(ISNUMBER(D12),ISNUMBER(H12)),E12*H12,"N/A") -> N/A
B13: American Airlines Group Inc | C13: AAL | D13: 14113.816 | E13: =IF(OR(H13="N/A",D13="N/A"),"N/A",D13/$D$512) -> 0.00056869667 | F13: 0.012917595 | G13: 0.09535 | H13: =IFERROR(F13*(1+0.5*G13)+G13,"N/A") -> 0.10888344 | I13: =IF(AND(ISNUMBER(D13),ISNUMBER(H13)),E13*H13,"N/A") -> 6.192165e-05
B14: Advance Auto Parts Inc | C14: AAP | D14: 11097.404 | E14: =IF(OR(H14="N/A",D14="N/A"),"N/A",D14/$D$512) -> 0.00044715451 | F14: 0.0015499871 | G14: 0.15473 | H14: =IFERROR(F14*(1+0.5*G14)+G14,"N/A") -> 0.1563999 | I14: =IF(AND(ISNUMBER(D14),ISNUMBER(H14)),E14*H14,"N/A") -> 6.9934921e-05
B15: Apple Inc | C15: AAPL | D15: 877607.91 | E15: =IF(OR(H15="N/A",D15="N/A"),"N/A",D15/$D$512) -> 0.035361996 | F15: 0.015780142 | G15: 0.094 | H15: =IFERROR(F15*(1+0.5*G15)+G15,"N/A") -> 0.11052181 | I15: =IF(AND(ISNUMBER(D15),ISNUMBER(H15)),E15*H15,"N/A") -> 0.0039082717
B16: AbbVie Inc | C16: ABBV | D16: 119983.29 | E16: =IF(OR(H16="N/A",D16="N/A"),"N/A",D16/$D$512) -> 0.0048345607 | F16: 0.053122695 | G16: 0.08813 | H16: =IFERROR(F16*(1+0.5*G16)+G16,"N/A") -> 0.14359355 | I16: =IF(AND(ISNUMBER(D16),ISNUMBER(H16)),E16*H16,"N/A") -> 0.00069421171
B17: AmerisourceBergen Corp | C17: ABC | D17: 16925.188 | E17: =IF(OR(H17="N/A",D17="N/A"),"N/A",D17/$D$512) -> 0.000681977 | F17: 0.020042405 | G17: 0.08697 | H17: =IFERROR(F17*(1+0.5*G17)+G17,"N/A") -> 0.10788395 | I17: =IF(AND(ISNUMBER(D17),ISNUMBER(H17)),E17*H17,"N/A") -> 7.3574372e-05
B18: ABIOMED Inc | C18: ABMD | D18: 15023.943 | E18: =IF(OR(H18="N/A",D18="N/A"),"N/A",D18/$D$512) -> 0.00060536899 | F18: 0.00% | G18: 0.29 | H18: =IFERROR(F18*(1+0.5*G18)+G18,"N/A") -> 0.29 | I18: =IF(AND(ISNUMBER(D18),ISNUMBER(H18)),E18*H18,"N/A") -> 0.00017555701
B19: Abbott Laboratories | C19: ABT | D19: 140271.72 | E19: =IF(OR(H19="N/A",D19="N/A"),"N/A",D19/$D$512) -> 0.0056520546 | F19: 0.01525169 | G19: 0.11688 | H19: =IFERROR(F19*(1+0.5*G19)+G19,"N/A") -> 0.133023 | I19: =IF(AND(ISNUMBER(D19),ISNUMBER(H19)),E19*H19,"N/A") -> 0.00075185325
B20: Accenture PLC | C20: ACN | D20: 106224.74 | E20: =IF(OR(H20="N/A",D20="N/A"),"N/A",D20/$D$512) -> 0.0042801789 | F20: 0.017615241 | G20: 0.10267 | H20: =IFERROR(F20*(1+0.5*G20)+G20,"N/A") -> 0.12118952 | I20: =IF(AND(ISNUMBER(D20),ISNUMBER(H20)),E20*H20,"N/A") -> 0.00051871283
B21: Adobe Inc | C21: ADBE | D21: 125746.54 | E21: =IF(OR(H21="N/A",D21="N/A"),"N/A",D21/$D$512) -> 0.0050667827 | F21: 0 | G21: 0.1716 | H21: =IFERROR(F21*(1+0.5*G21)+G21,"N/A") -> 0.1716 | I21: =IF(AND(ISNUMBER(D21),ISNUMBER(H21)),E21*H21,"N/A") -> 0.00086945991
B22: Analog Devices Inc | C22: ADI | D22: 40289.903 | E22: =IF(OR(H22="N/A",D22="N/A"),"N/A",D22/$D$512) -> 0.0016234258 | F22: 0.018959686 | G22: 0.11975 | H22: =IFERROR(F22*(1+0.5*G22)+G22,"N/A") -> 0.1398449 | I22: =IF(AND(ISNUMBER(D22),ISNUMBER(H22)),E22*H22,"N/A") -> 0.00022702782
B23: Archer-Daniels-Midland Co | C23: ADM | D23: 24184.634 | E23: =IF(OR(H23="N/A",D23="N/A"),"N/A",D23/$D$512) -> 0.00097448635 | F23: 0.032862436 | G23: 0.014 | H23: =IFERROR(F23*(1+0.5*G23)+G23,"N/A") -> 0.047092473 | I23: =IF(AND(ISNUMBER(D23),ISNUMBER(H23)),E23*H23,"N/A") -> 4.5890972e-05
B24: Automatic Data Processing Inc | C24: ADP | D24: 67657.642 | E24: =IF(OR(H24="N/A",D24="N/A"),"N/A",D24/$D$512) -> 0.002726171 | F24: 0.018710965 | G24: 0.14 | H24: =IFERROR(F24*(1+0.5*G24)+G24,"N/A") -> 0.16002073 | I24: =IF(AND(ISNUMBER(D24),ISNUMBER(H24)),E24*H24,"N/A") -> 0.00043624388
B25: Alliance Data Systems Corp | C25: ADS | D25: 9137.3309 | E25: =IF(OR(H25="N/A",D25="N/A"),"N/A",D25/$D$512) -> 0.0003681761 | F25: 0.014361116 | G25: -0.01325 | H25: =IFERROR(F25*(1+0.5*G25)+G25,"N/A") -> 0.0010159736 | I25: =IF(AND(ISNUMBER(D25),ISNUMBER(H25)),E25*H25,"N/A") -> 3.7405718e-07
B26: Autodesk Inc | C26: ADSK | D26: 33569.674 | E26: =IF(OR(H26="N/A",D26="N/A"),"N/A",D26/$D$512) -> 0.0013526435 | F26: 0 | G26: 0.51812 | H26: =IFERROR(F26*(1+0.5*G26)+G26,"N/A") -> 0.51812 | I26: =IF(AND(ISNUMBER(D26),ISNUMBER(H26)),E26*H26,"N/A") -> 0.00070083167
B27: Ameren Corp | C27: AEE | D27: 17868.424 | E27: =IF(OR(H27="N/A",D27="N/A"),"N/A",D27/$D$512) -> 0.00071998339 | F27: 0.026738773 | G27: 0.06353 | H27: =IFERROR(F27*(1+0.5*G27)+G27,"N/A") -> 0.09111813 | I27: =IF(AND(ISNUMBER(D27),ISNUMBER(H27)),E27*H27,"N/A") -> 6.5603541e-05
B28: American Electric Power Co Inc | C28: AEP | D28: 41342.43 | E28: =IF(OR(H28="N/A",D28="N/A"),"N/A",D28/$D$512) -> 0.001665836 | F28: 0.032096409 | G28: 0.0612 | H28: =IFERROR(F28*(1+0.5*G28)+G28,"N/A") -> 0.094278559 | I28: =IF(AND(ISNUMBER(D28),ISNUMBER(H28)),E28*H28,"N/A") -> 0.00015705262
B29: AES Corp/VA | C29: AES | D29: 12128.619 | E29: =IF(OR(H29="N/A",D29="N/A"),"N/A",D29/$D$512) -> 0.00048870591 | F29: 0.03036592 | G29: 0.07668 | H29: =IFERROR(F29*(1+0.5*G29)+G29,"N/A") -> 0.10821015 | I29: =IF(AND(ISNUMBER(D29),ISNUMBER(H29)),E29*H29,"N/A") -> 5.288294e-05
B30: Aflac Inc | C30: AFL | D30: 37479.102 | E30: =IF(OR(H30="N/A",D30="N/A"),"N/A",D30/$D$512) -> 0.0015101685 | F30: 0.021901902 | G30: 0.0343 | H30: =IFERROR(F30*(1+0.5*G30)+G30,"N/A") -> 0.05657752 | I30: =IF(AND(ISNUMBER(D30),ISNUMBER(H30)),E30*H30,"N/A") -> 8.5441589e-05
... B33: Apartment Investment & Management Co | C33: AIV | D33: 7325.8169 | E33: =IF(OR(H33="N/A",D33="N/A"),"N/A",D33/$D$512) -> 0.00029518365 | F33: 0.040882237 | G33: 0.08767 | H33: =IFERROR(F33*(1+0.5*G33)+G33,"N/A") -> 0.13034431 | I33: =IF(AND(ISNUMBER(D33),ISNUMBER(H33)),E33*H33,"N/A") -> 3.8475509e-05
B34: Assurant Inc | C34: AIZ | D34: 6091.2515 | E34: =IF(OR(H34="N/A",D34="N/A"),"N/A",D34/$D$512) -> N/A | F34: 0.025270941 | G34: N/A | H34: =IFERROR(F34*(1+0.5*G34)+G34,"N/A") -> N/A | I34: =IF(AND(ISNUMBER(D34),ISNUMBER(H34)),E34*H34,"N/A") -> N/A
B35: Arthur J Gallagher & Co | C35: AJG | D35: 14776.337 | E35: =IF(OR(H35="N/A",D35="N/A"),"N/A",D35/$D$512) -> 0.00059539203 | F35: 0.02136273 | G35: 0.1017 | H35: =IFERROR(F35*(1+0.5*G35)+G35,"N/A") -> 0.12414903 | I35: =IF(AND(ISNUMBER(D35),ISNUMBER(H35)),E35*H35,"N/A") -> 7.391734e-05
B36: Akamai Technologies Inc | C36: AKAM | D36: 11828.01 | E36: =IF(OR(H36="N/A",D36="N/A"),"N/A",D36/$D$512) -> 0.00047659327 | F36: 0.00% | G36: 0.154 | H36: =IFERROR(F36*(1+0.5*G36)+G36,"N/A") -> 0.154 | I36: =IF(AND(ISNUMBER(D36),ISNUMBER(H36)),E36*H36,"N/A") -> 7.3395364e-05
B37: Albemarle Corp | C37: ALB | D37: 9033.4951 | E37: =IF(OR(H37="N/A",D37="N/A"),"N/A",D37/$D$512) -> 0.00036399218 | F37: 0.016050105 | G37: 0.12188 | H37: =IFERROR(F37*(1+0.5*G37)+G37,"N/A") -> 0.1389082 | I37: =IF(AND(ISNUMBER(D37),ISNUMBER(H37)),E37*H37,"N/A") -> 5.0561497e-05
B38: Align Technology Inc | C38: ALGN | D38: 20183.712 | E38: =IF(OR(H38="N/A",D38="N/A"),"N/A",D38/$D$512) -> 0.00081327472 | F38: 0.00% | G38: 0.23193 | H38: =IFERROR(F38*(1+0.5*G38)+G38,"N/A") -> 0.23193 | I38: =IF(AND(ISNUMBER(D38),ISNUMBER(H38)),E38*H38,"N/A") -> 0.00018862281
B39: Alaska Air Group Inc | C39: ALK | D39: 6889.4826 | E39: =IF(OR(H39="N/A",D39="N/A"),"N/A",D39/$D$512) -> 0.00027760216 | F39: 0.024497848 | G39: 0.2537 | H39: =IFERROR(F39*(1+0.5*G39)+G39,"N/A") -> 0.2813054 | I39: =IF(AND(ISNUMBER(D39),ISNUMBER(H39)),E39*H39,"N/A") -> 7.8090987e-05
B40: Allstate Corp/The | C40: ALL | D40: 31483.381 | E40: =IF(OR(H40="N/A",D40="N/A"),"N/A",D40/$D$512) -> 0.0012685792 | F40: 0.02039224 | G40: 0.09 | H40: =IFERROR(F40*(1+0.5*G40)+G40,"N/A") -> 0.11130989 | I40: =IF(AND(ISNUMBER(D40),ISNUMBER(H40)),E40*H40,"N/A") -> 0.00014120542
B41: Allegion PLC | C41: ALLE | D41: 8351.0614 | E41: =IF(OR(H41="N/A",D41="N/A"),"N/A",D41/$D$512) -> 0.00033649446 | F41: 0.012012216 | G41: 0.10217 | H41: =IFERROR(F41*(1+0.5*G41)+G41,"N/A") -> 0.11479586 | I41: =IF(AND(ISNUMBER(D41),ISNUMBER(H41)),E41*H41,"N/A") -> 3.862817e-05
B42: Alexion Pharmaceuticals Inc | C42: ALXN | D42: 30411.948 | E42: =IF(OR(H42="N/A",D42="N/A"),"N/A",D42/$D$512) -> 0.0012254073 | F42: 0 | G42: 0.1578 | H42: =IFERROR(F42*(1+0.5*G42)+G42,"N/A") -> 0.1578 | I42: =IF(AND(ISNUMBER(D42),ISNUMBER(H42)),E42*H42,"N/A") -> 0.00019336928
B43: Applied Materials Inc | C43: AMAT | D43: 38345.967 | E43: =IF(OR(H43="N/A",D43="N/A"),"N/A",D43/$D$512) -> 0.0015450977 | F43: 0.020970537 | G43: 0.0923 | H43: =IFERROR(F43*(1+0.5*G43)+G43,"N/A") -> 0.11423833 | I43: =IF(AND(ISNUMBER(D43),ISNUMBER(H43)),E43*H43,"N/A") -> 0.00017650937
B44: Advanced Micro Devices Inc | C44: AMD | D44: 23413.411 | E44: =IF(OR(H44="N/A",D44="N/A"),"N/A",D44/$D$512) -> 0.00094341098 | F44: 0 | G44: 0.15667 | H44: =IFERROR(F44*(1+0.5*G44)+G44,"N/A") -> 0.15667 | I44: =IF(AND(ISNUMBER(D44),ISNUMBER(H44)),E44*H44,"N/A") -> 0.0001478042
B45: AMETEK Inc | C45: AME | D45: 18385.789 | E45: =IF(OR(H45="N/A",D45="N/A"),"N/A",D45/$D$512) -> 0.00074082991 | F45: 0.0070907066 | G45: 0.08978 | H45: =IFERROR(F45*(1+0.5*G45)+G45,"N/A") -> 0.097189008 | I45: =IF(AND(ISNUMBER(D45),ISNUMBER(H45)),E45*H45,"N/A") -> 7.2000525e-05
B46: Affiliated Managers Group Inc | C46: AMG | D46: 5691.5259 | E46: =IF(OR(H46="N/A",D46="N/A"),"N/A",D46/$D$512) -> 0.00022933215 | F46: 0.012684042 | G46: 0.0498 | H46: =IFERROR(F46*(1+0.5*G46)+G46,"N/A") -> 0.062799875 | I46: =IF(AND(ISNUMBER(D46),ISNUMBER(H46)),E46*H46,"N/A") -> 1.4402031e-05
...

Sheet RBH-2 MRP Value Line
B2: Ex-Ante Market Risk Premium
B3: Market DCF Method Based - Value Line
D5: [1] | E5: [2] | F5: [3]
D6: S&P 500 Est. Required Market Return | E6: Current 30-Year Treasury (30-day average) | F6: Implied Market Risk Premium
D7: =I512 -> 0.16747389 | E7: ='RBH-4 CAPM'!C10 -> 0.030316667 | F7: =D7-E7 -> 0.13715722
D10: [4] | E10: [5] | F10: [6] | G10: [7] | H10: [8] | I10: [9]
B11: Company | C11: Ticker | D11: Market Capitalization | E11: Weight in Index | F11: Estimated Dividend Yield | G11: Long-Term Growth Est. | H11: DCF Result | I11: Weighted DCF Result
B12: Agilent Technologies Inc | C12: A | D12: 25036.14 | E12: =IF(OR(H12="N/A",D12="N/A"),"N/A",D12/$D$512) -> 0.0011363597 | F12: 0.0084 | G12: 0.095 | H12: =IFERROR(F12*(1+0.5*G12)+G12,"N/A") -> 0.103799 | I12: =IF(AND(ISNUMBER(D12),ISNUMBER(H12)),E12*H12,"N/A") -> 0.000117953
B13: American Airlines Group Inc | C13: AAL | D13: 14839.21 | E13: =IF(OR(H13="N/A",D13="N/A"),"N/A",D13/$D$512) -> 0.00067353354 | F13: 0.0124 | G13: 0.01 | H13: =IFERROR(F13*(1+0.5*G13)+G13,"N/A") -> 0.022462 | I13: =IF(AND(ISNUMBER(D13),ISNUMBER(H13)),E13*H13,"N/A") -> 1.512891e-05
B14: Advance Auto Parts Inc | C14: AAP | D14: 11235.15 | E14: =IF(OR(H14="N/A",D14="N/A"),"N/A",D14/$D$512) -> 0.00050994968 | F14: 0.0016 | G14: 0.13 | H14: =IFERROR(F14*(1+0.5*G14)+G14,"N/A") -> 0.131704 | I14: =IF(AND(ISNUMBER(D14),ISNUMBER(H14)),E14*H14,"N/A") -> 6.7162412e-05
B15: Apple Inc | C15: AAPL | D15: 815891 | E15: =IF(OR(H15="N/A",D15="N/A"),"N/A",D15/$D$512) -> 0.037032292 | F15: 0.0187 | G15: 0.175 | H15: =IFERROR(F15*(1+0.5*G15)+G15,"N/A") -> 0.19533625 | I15: =IF(AND(ISNUMBER(D15),ISNUMBER(H15)),E15*H15,"N/A") -> 0.007233749
B16: AbbVie Inc | C16: ABBV | D16: 117685.5 | E16: =IF(OR(H16="N/A",D16="N/A"),"N/A",D16/$D$512) -> 0.0053416005 | F16: 0.0547 | G16: 0.145 | H16: =IFERROR(F16*(1+0.5*G16)+G16,"N/A") -> 0.20366575 | I16: =IF(AND(ISNUMBER(D16),ISNUMBER(H16)),E16*H16,"N/A") -> 0.0010879011
B17: AmerisourceBergen Corp | C17: ABC | D17: 16107.54 | E17: =IF(OR(H17="N/A",D17="N/A"),"N/A",D17/$D$512) -> 0.00073110148 | F17: 0.021 | G17: 0.08 | H17: =IFERROR(F17*(1+0.5*G17)+G17,"N/A") -> 0.10184 | I17: =IF(AND(ISNUMBER(D17),ISNUMBER(H17)),E17*H17,"N/A") -> 7.4455375e-05
B18: ABIOMED Inc | C18: ABMD | D18: 14302.31 | E18: =IF(OR(H18="N/A",D18="N/A"),"N/A",D18/$D$512) -> 0.00064916431 | F18: 0 | G18: 0.245 | H18: =IFERROR(F18*(1+0.5*G18)+G18,"N/A") -> 0.245 | I18: =IF(AND(ISNUMBER(D18),ISNUMBER(H18)),E18*H18,"N/A") -> 0.00015904526
B19: Abbott Laboratories | C19: ABT | D19: 134886.4 | E19: =IF(OR(H19="N/A",D19="N/A"),"N/A",D19/$D$512) -> 0.0061223282 | F19: 0.0167 | G19: 0.1 | H19: =IFERROR(F19*(1+0.5*G19)+G19,"N/A") -> 0.117535 | I19: =IF(AND(ISNUMBER(D19),ISNUMBER(H19)),E19*H19,"N/A") -> 0.00071958785
B20: Accenture PLC | C20: ACN | D20: 103264.5 | E20: =IF(OR(H20="N/A",D20="N/A"),"N/A",D20/$D$512) -> 0.004687049 | F20: 0.0189 | G20: 0.095 | H20: =IFERROR(F20*(1+0.5*G20)+G20,"N/A") -> 0.11479775 | I20: =IF(AND(ISNUMBER(D20),ISNUMBER(H20)),E20*H20,"N/A") -> 0.00053806268
B21: Adobe Inc | C21: ADBE | D21: 124578.4 | E21: =IF(OR(H21="N/A",D21="N/A"),"N/A",D21/$D$512) -> 0.0056544608 | F21: 0 | G21: 0.22 | H21: =IFERROR(F21*(1+0.5*G21)+G21,"N/A") -> 0.22 | I21: =IF(AND(ISNUMBER(D21),ISNUMBER(H21)),E21*H21,"N/A") -> 0.0012439814
B22: Analog Devices Inc | C22: ADI | D22: 38923.42 | E22: =IF(OR(H22="N/A",D22="N/A"),"N/A",D22/$D$512) -> 0.0017666863 | F22: 0.0204 | G22: 0.105 | H22: =IFERROR(F22*(1+0.5*G22)+G22,"N/A") -> 0.126471 | I22: =IF(AND(ISNUMBER(D22),ISNUMBER(H22)),E22*H22,"N/A") -> 0.00022343458
B23: Archer-Daniels-Midland Co | C23: ADM | D23: 23615.2 | E23: =IF(OR(H23="N/A",D23="N/A"),"N/A",D23/$D$512) -> 0.001071865 | F23: 0.0332 | G23: 0.095 | H23: =IFERROR(F23*(1+0.5*G23)+G23,"N/A") -> 0.129777 | I23: =IF(AND(ISNUMBER(D23),ISNUMBER(H23)),E23*H23,"N/A") -> 0.00013910342
... B25: Alliance Data Systems Corp | C25: ADS | D25: 9043.95 | E25: =IF(OR(H25="N/A",D25="N/A"),"N/A",D25/$D$512) -> 0.0004104938 | F25: 0.0152 | G25: 0.135 | H25: =IFERROR(F25*(1+0.5*G25)+G25,"N/A") -> 0.151226 | I25: =IF(AND(ISNUMBER(D25),ISNUMBER(H25)),E25*H25,"N/A") -> 6.2077335e-05
B26: Autodesk Inc | C26: ADSK | D26: 33458 | E26: =IF(OR(H26="N/A",D26="N/A"),"N/A",D26/$D$512) -> N/A | F26: 0 | G26: N/A | H26: =IFERROR(F26*(1+0.5*G26)+G26,"N/A") -> N/A | I26: =IF(AND(ISNUMBER(D26),ISNUMBER(H26)),E26*H26,"N/A") -> N/A
B27: Ameren Corp | C27: AEE | D27: 17413.29 | E27: =IF(OR(H27="N/A",D27="N/A"),"N/A",D27/$D$512) -> 0.00079036787 | F27: 0.0275 | G27: 0.065 | H27: =IFERROR(F27*(1+0.5*G27)+G27,"N/A") -> 0.09339375 | I27: =IF(AND(ISNUMBER(D27),ISNUMBER(H27)),E27*H27,"N/A") -> 7.3815419e-05
B28: American Electric Power Co Inc | C28: AEP | D28: 40174.8 | E28: =IF(OR(H28="N/A",D28="N/A"),"N/A",D28/$D$512) -> 0.0018234849 | F28: 0.0339 | G28: 0.04 | H28: =IFERROR(F28*(1+0.5*G28)+G28,"N/A") -> 0.074578 | I28: =IF(AND(ISNUMBER(D28),ISNUMBER(H28)),E28*H28,"N/A") -> 0.00013599186
B29: AES Corp/VA | C29: AES | D29: 11702.79 | E29: =IF(OR(H29="N/A",D29="N/A"),"N/A",D29/$D$512) -> N/A | F29: 0.0311 | G29: N/A | H29: =IFERROR(F29*(1+0.5*G29)+G29,"N/A") -> N/A | I29: =IF(AND(ISNUMBER(D29),ISNUMBER(H29)),E29*H29,"N/A") -> N/A
B30: Aflac Inc | C30: AFL | D30: 36729.55 | E30: =IF(OR(H30="N/A",D30="N/A"),"N/A",D30/$D$512) -> 0.0016671092 | F30: 0.023 | G30: 0.085 | H30: =IFERROR(F30*(1+0.5*G30)+G30,"N/A") -> 0.1089775 | I30: =IF(AND(ISNUMBER(D30),ISNUMBER(H30)),E30*H30,"N/A") -> 0.00018167739
B31: Allergan PLC | C31: AGN | D31: 48219.6 | E31: =IF(OR(H31="N/A",D31="N/A"),"N/A",D31/$D$512) -> 0.0021886285 | F31: 0.0207 | G31: 0.045 | H31: =IFERROR(F31*(1+0.5*G31)+G31,"N/A") -> 0.06616575 | I31: =IF(AND(ISNUMBER(D31),ISNUMBER(H31)),E31*H31,"N/A") -> 0.00014481225
B32: American International Group Inc | C32: AIG | D32: 36987.13 | E32: =IF(OR(H32="N/A",D32="N/A"),"N/A",D32/$D$512) -> 0.0016788005 | F32: 0.0306 | G32: 0.52 | H32: =IFERROR(F32*(1+0.5*G32)+G32,"N/A") -> 0.558556 | I32: =IF(AND(ISNUMBER(D32),ISNUMBER(H32)),E32*H32,"N/A") -> 0.00093770407
B33: Apartment Investment & Management Co | C33: AIV | D33: 7526.18 | E33: =IF(OR(H33="N/A",D33="N/A"),"N/A",D33/$D$512) -> 0.00034160408 | F33: 0.0326 | G33: 0.055 | H33: =IFERROR(F33*(1+0.5*G33)+G33,"N/A") -> 0.0884965 | I33: =IF(AND(ISNUMBER(D33),ISNUMBER(H33)),E33*H33,"N/A") -> 3.0230765e-05
B34: Assurant Inc | C34: AIZ | D34: 6259.43 | E34: =IF(OR(H34="N/A",D34="N/A"),"N/A",D34/$D$512) -> 0.00028410785 | F34: 0.0239 | G34: 0.075 | H34: =IFERROR(F34*(1+0.5*G34)+G34,"N/A") -> 0.09979625 | I34: =IF(AND(ISNUMBER(D34),ISNUMBER(H34)),E34*H34,"N/A") -> 2.8352898e-05
B35: Arthur J Gallagher & Co | C35: AJG | D35: 14372.69 | E35: =IF(OR(H35="N/A",D35="N/A"),"N/A",D35/$D$512) -> 0.00065235877 | F35: 0.022 | G35: 0.17 | H35: =IFERROR(F35*(1+0.5*G35)+G35,"N/A") -> 0.19387 | I35: =IF(AND(ISNUMBER(D35),ISNUMBER(H35)),E35*H35,"N/A") -> 0.00012647279
B36: Akamai Technologies Inc | C36: AKAM | D36: 11972.36 | E36: =IF(OR(H36="N/A",D36="N/A"),"N/A",D36/$D$512) -> 0.00054341073 | F36: 0 | G36: 0.175 | H36: =IFERROR(F36*(1+0.5*G36)+G36,"N/A") -> 0.175 | I36: =IF(AND(ISNUMBER(D36),ISNUMBER(H36)),E36*H36,"N/A") -> 9.5096878e-05
B37: Albemarle Corp | C37: ALB | D37: 8983.42 | E37: =IF(OR(H37="N/A",D37="N/A"),"N/A",D37/$D$512) -> 0.00040774641 | F37: 0.0174 | G37: 0.085 | H37: =IFERROR(F37*(1+0.5*G37)+G37,"N/A") -> 0.1031395 | I37: =IF(AND(ISNUMBER(D37),ISNUMBER(H37)),E37*H37,"N/A") -> 4.2054761e-05
B38: Align Technology Inc | C38: ALGN | D38: 18773.59 | E38: =IF(OR(H38="N/A",D38="N/A"),"N/A",D38/$D$512) -> 0.00085211022 | F38: 0 | G38: 0.285 | H38: =IFERROR(F38*(1+0.5*G38)+G38,"N/A") -> 0.285 | I38: =IF(AND(ISNUMBER(D38),ISNUMBER(H38)),E38*H38,"N/A") -> 0.00024285141
B39: Alaska Air Group Inc | C39: ALK | D39: 6902.05 | E39: =IF(OR(H39="N/A",D39="N/A"),"N/A",D39/$D$512) -> 0.00031327558 | F39: 0.025 | G39: 0.035 | H39: =IFERROR(F39*(1+0.5*G39)+G39,"N/A") -> 0.0604375 | I39: =IF(AND(ISNUMBER(D39),ISNUMBER(H39)),E39*H39,"N/A") -> 1.8933593e-05
B40: Allstate Corp/The | C40: ALL | D40: 32167.8 | E40: =IF(OR(H40="N/A",D40="N/A"),"N/A",D40/$D$512) -> 0.001460057 | F40: 0.0215 | G40: 0.115 | H40: =IFERROR(F40*(1+0.5*G40)+G40,"N/A") -> 0.13773625 | I40: =IF(AND(ISNUMBER(D40),ISNUMBER(H40)),E40*H40,"N/A") -> 0.00020110277
B41: Allegion PLC | C41: ALLE | D41: 8325.22 | E41: =IF(OR(H41="N/A",D41="N/A"),"N/A",D41/$D$512) -> 0.00037787152 | F41: 0.0123 | G41: 0.105 | H41: =IFERROR(F41*(1+0.5*G41)+G41,"N/A") -> 0.11794575 | I41: =IF(AND(ISNUMBER(D41),ISNUMBER(H41)),E41*H41,"N/A") -> 4.456834e-05
... B43: Applied Materials Inc | C43: AMAT | D43: 35668.7 | E43: =IF(OR(H43="N/A",D43="N/A"),"N/A",D43/$D$512) -> 0.0016189585 | F43: 0.0213 | G43: 0.19 | H43: =IFERROR(F43*(1+0.5*G43)+G43,"N/A") -> 0.2133235 | I43: =IF(AND(ISNUMBER(D43),ISNUMBER(H43)),E43*H43,"N/A") -> 0.0003453619
B44: Advanced Micro Devices Inc | C44: AMD | D44: 22190.4 | E44: =IF(OR(H44="N/A",D44="N/A"),"N/A",D44/$D$512) -> N/A | F44: 0 | G44: N/A | H44: =IFERROR(F44*(1+0.5*G44)+G44,"N/A") -> N/A | I44: =IF(AND(ISNUMBER(D44),ISNUMBER(H44)),E44*H44,"N/A") -> N/A
B45: AMETEK Inc | C45: AME | D45: 18320.91 | E45: =IF(OR(H45="N/A",D45="N/A"),"N/A",D45/$D$512) -> 0.00083156363 | F45: 0.0071 | G45: 0.105 | H45: =IFERROR(F45*(1+0.5*G45)+G45,"N/A") -> 0.11247275 | I45: =IF(AND(ISNUMBER(D45),ISNUMBER(H45)),E45*H45,"N/A") -> 9.3528248e-05
B46: Affiliated Managers Group Inc | C46: AMG | D46: 6061.77 | E46: =IF(OR(H46="N/A",D46="N/A"),"N/A",D46/$D$512) -> 0.0002751363 | F46: 0.0154 | G46: 0.065 | H46: =IFERROR(F46*(1+0.5*G46)+G46,"N/A") -> 0.0809005 | I46: =IF(AND(ISNUMBER(D46),ISNUMBER(H46)),E46*H46,"N/A") -> 2.2258665e-05
...

Sheet RBH-3 Beta
B2: Bloomberg and Value Line Beta Coefficients
E4: [1] | F4: [2]
B5: Company | C5: Ticker | E5: Bloomberg | F5: Value Line
B7: ='RBH-1 Constant Growth DCF'!B8 -> ALLETE, Inc. | C7: ='RBH-1 Constant Growth DCF'!C8 -> ALE | E7: 0.4482832 | F7: 0.65
B8: ='RBH-1 Constant Growth DCF'!B9 -> Alliant Energy Corporation | C8: ='RBH-1 Constant Growth DCF'!C9 -> LNT | E8: 0.52806807 | F8: 0.65
B9: ='RBH-1 Constant Growth DCF'!B10 -> Ameren Corporation | C9: ='RBH-1 Constant Growth DCF'!C10 -> AEE | E9: 0.43553996 | F9: 0.6
B10: ='RBH-1 Constant Growth DCF'!B11 -> Avangrid, Inc. | C10: ='RBH-1 Constant Growth DCF'!C11 -> AGR | E10: 0.46795049 | F10: 0.4
B11: ='RBH-1 Constant Growth DCF'!B12 -> Black Hills Corporation | C11: ='RBH-1 Constant Growth DCF'!C12 -> BKH | E11: 0.53396392 | F11: 0.75
B12: ='RBH-1 Constant Growth DCF'!B13 -> CMS Energy Corporation | C12: ='RBH-1 Constant Growth DCF'!C13 -> CMS | E12: 0.46631581 | F12: 0.55
B13: ='RBH-1 Constant Growth DCF'!B14 -> Consolidated Edison, Inc. | C13: ='RBH-1 Constant Growth DCF'!C14 -> ED | E13: 0.46974313 | F13: 0.45
B14: ='RBH-1 Constant Growth DCF'!B15 -> DTE Energy Company | C14: ='RBH-1 Constant Growth DCF'!C15 -> DTE | E14: 0.50299174 | F14: 0.55
B15: ='RBH-1 Constant Growth DCF'!B16 -> Duke Energy Corporation | C15: ='RBH-1 Constant Growth DCF'!C16 -> DUK | E15: 0.43103719 | F15: 0.5
B16: ='RBH-1 Constant Growth DCF'!B17 -> El Paso Electric Company | C16: ='RBH-1 Constant Growth DCF'!C17 -> EE | E16: 0.50251919 | F16: 0.65
B17: ='RBH-1 Constant Growth DCF'!B18 -> Evergy, Inc | C17: ='RBH-1 Constant Growth DCF'!C18 -> EVRG | E17: 0.41390449 | F17: 0.52285924
B18: ='RBH-1 Constant Growth DCF'!B19 -> Eversource Energy | C18: ='RBH-1 Constant Growth DCF'!C19 -> ES | E18: 0.56493223 | F18: 0.6
... B29: ='RBH-1 Constant Growth DCF'!B30 -> Xcel Energy Inc. | C29: ='RBH-1 Constant Growth DCF'!C30 -> XEL | E29: 0.47912061 | F29: 0.5
B31: Mean | E31: =AVERAGE(E7:E29) -> 0.48488443 | F31: =AVERAGE(F7:F29) -> 0.5879504
B33: Notes:
B34: [1] Source: Bloomberg Professional
B35: [2] Source: Value Line

Sheet RBH-4 CAPM
B2: Capital Asset Pricing Model and Empirical Capital Asset Pricing Model Results
B3: Bloomberg, and Value Line Derived Market Risk Premium
C5: 1 | D5: =C5+1 -> 2 | E5: =D5+1 -> 3 | F5: =E5+1 -> 4 | G5: =F5+1 -> 5 | H5: =G5+1 -> 6 | I5: [7] | J5: [8]
G6: CAPM | I6: ECAPM
C7: Risk-Free Rate | D7: Average Beta Coefficient | E7: Bloomberg Market DCF Derived | F7: Value Line Market DCF Derived | G7: Bloomberg MRP | H7: Value Line MRP | I7: Bloomberg MRP | J7: Value Line MRP
B9: PROXY GROUP AVERAGE BLOOMBERG BETA COEFFICIENT
B10: Current 30-Year Treasury (30-day average) [9] | C10: 0.030316667 | D10: ='RBH-3 Beta'!E31 -> 0.48488443 | E10: ='RBH-2 MRP Bloomberg'!F7 -> 0.10607335 | F10: ='RBH-2 MRP Value Line'!F7 -> 0.13715722 | G10: =$C10+$D10*E10 -> 0.081749983 | H10: =$C10+$D10*F10 -> 0.096822067 | I10: =$C10+($D10*E10*0.75)+(0.25*E10) -> 0.095409992 | J10: =$C10+($D10*F10*0.75)+(0.25*F10) -> 0.11448502
B11: Near-Term Projected 30-Year Treasury [10] | C11: =AVERAGE(3.1,3.1,3.2,3.3,3.4,3.4)/100 -> 0.0325 | D11: =D10 -> 0.48488443 | E11: =E10 -> 0.10607335 | F11: =F10 -> 0.13715722 | G11: =$C11+$D11*E11 -> 0.083933317 | H11: =$C11+$D11*F11 -> 0.0990054 | I11: =$C11+($D11*E11*0.75)+(0.25*E11) -> 0.097593325 | J11: =$C11+($D11*F11*0.75)+(0.25*F11) -> 0.11666836
B12: Mean | G12: =AVERAGE(G10:G11) -> 0.08284165 | H12: =AVERAGE(H10:H11) -> 0.097913733 | I12: =AVERAGE(I10:I11) -> 0.096501659 | J12: =AVERAGE(J10:J11) -> 0.11557669
G14: CAPM | I14: ECAPM
C15: Risk-Free Rate | D15: Average Beta Coefficient | E15: Bloomberg Market DCF Derived | F15: Value Line Market DCF Derived | G15: Bloomberg MRP | H15: Value Line MRP | I15: Bloomberg MRP | J15: Value Line MRP
B17: PROXY GROUP AVERAGE VALUE LINE AVERAGE BETA COEFFICIENT
B18: Current 30-Year Treasury (30-day average) [9] | C18: =C10 -> 0.030316667 | D18: ='RBH-3 Beta'!F31 -> 0.5879504 | E18: =E10 -> 0.10607335 | F18: =F10 -> 0.13715722 | G18: =$C18+$D18*E18 -> 0.092682537 | H18: =$C18+$D18*F18 -> 0.11095831 | I18: =$C18+($D18*E18*0.75)+(0.25*E18) -> 0.10360941 | J18: =$C18+($D18*F18*0.75)+(0.25*F18) -> 0.1250872
B19: Near-Term Projected 30-Year Treasury [10] | C19: =C11 -> 0.0325 | D19: =D18 -> 0.5879504 | E19: =E10 -> 0.10607335 | F19: =F10 -> 0.13715722 | G19: =$C19+$D19*E19 -> 0.09486587 | H19: =$C19+$D19*F19 -> 0.11314164 | I19: =$C19+($D19*E19*0.75)+(0.25*E19) -> 0.10579274 | J19: =$C19+($D19*F19*0.75)+(0.25*F19) -> 0.12727054
B20: Mean | G20: =AVERAGE(G18:G19) -> 0.093774203 | H20: =AVERAGE(H18:H19) -> 0.11204998 | I20: =AVERAGE(I18:I19) -> 0.10470107 | J20: =AVERAGE(J18:J19) -> 0.12617887
B22: Notes:
B23: [1] See Notes [9] and [10]
B24: [2] Source: Exhibit RBH-3
B25: [3] Source: Exhibit RBH-2
B26: [4] Source: Exhibit RBH-2
B27: [5] Equals Col. [1] + (Col. [2] x Col. [3])
B28: [6] Equals Col. [1] + (Col. [2] x Col. [4])
B29: [7] Equals Col. [1] + (Col. [2] x Col. [3] x 0.75) + (Col. [3] x 0.25)
B30: [8] Equals Col. [1] + (Col. [2] x Col. [4] x 0.75) + (Col. [4] x 0.25)
B31: [9] Source: Bloomberg Professional
B32: [10] Source: Blue Chip Financial Forecasts, Vol. 38, No. 3, March 1, 2019, at 2.

Sheet RBH-5 Risk Premium
C2: Bond Yield Plus Risk Premium
C4: [1] | D4: [2] | E4: [3] | F4: [4] | G4: [5]
C5: Constant | D5: Slope | E5: 30-Year Treasury Yield | F5: Risk Premium | G5: Return on Equity
C6: =INTERCEPT(G46:G1629,LN(F46:F1629)) -> -0.024847305 | D6: =SLOPE(G46:G1629,LN(F46:F1629)) -> -0.026837421
D7: Current 30-Year Treasury | E7: ='RBH-4 CAPM'!C10 -> 0.030316667 | F7: =($C$6+LN(E7)*$D$6) -> 0.068977867 | G7: =E7+F7 -> 0.099294534
D8: Near-Term Projected 30-Year Treasury | E8: ='RBH-4 CAPM'!C11 -> 0.0325 | F8: =($C$6+LN(E8)*$D$6) -> 0.067111527 | G8: =E8+F8 -> 0.099611527
D9: Long-Term Projected 30-Year Treasury | E9: =AVERAGE(3.9,4.2)/100 -> 0.0405 | F9: =($C$6+LN(E9)*$D$6) -> 0.061205633 | G9: =E9+F9 -> 0.10170563
B30: Notes:
B31: [1] Constant of regression equation
B32: [2] Slope of regression equation
B33: [3] Source: Current = Bloomberg Professional,
B34: [3] Near Term Projected = Blue Chip Financial Forecasts, Vol. 38, No. 3, March 1, 2019, at 2.
B35: [3] Long Term Projected = Blue Chip Financial Forecasts, Vol. 37, No. 12, December 1, 2018, at 14.
B36: [4] Equals [1] + ln([3]) x [2]
B37: [5] Equals [3] + [4]
B38: [6] Source: S&P Global Market Intelligence
B39: [7] Source: S&P Global Market Intelligence
B40: [8] Source: Bloomberg Professional, equals 200-trading day average (i.e. lag period)
B41: [9] Equals [7] - [8]
D43: =C2 -> Bond Yield Plus Risk Premium
D44: [6] | E44: [7] | F44: [8] | G44: [9]
D45: Date of Electric Rate Case | E45: Return on Equity | F45: 30-Year Treasury Yield | G45: Risk Premium | I45: < 9%?
D46: 29221 | E46: 0.145 | F46: 0.093579 | G46: =E46-F46 -> 0.051421 | I46: =--(Risk_Prem2[[#This Row],[Return on Equity]]<0.09) -> 0
D47: 29227 | E47: 0.1439 | F47: 0.0938335 | G47: =E47-F47 -> 0.0500665 | I47: =--(Risk_Prem2[[#This Row],[Return on Equity]]<0.09) -> 0
D48: 29229 | E48: 0.15 | F48: 0.0939585 | G48: =E48-F48 -> 0.0560415 | I48: =--(Risk_Prem2[[#This Row],[Return on Equity]]<0.09) -> 0
D49: 29234 | E49: 0.1517 | F49: 0.0941565 | G49: =E49-F49 -> 0.0575435 | I49: =--(Risk_Prem2[[#This Row],[Return on Equity]]<0.09) -> 0
D50: 29237 | E50: 0.1393 | F50: 0.094369 | G50: =E50-F50 -> 0.044931 | I50: =--(Risk_Prem2[[#This Row],[Return on Equity]]<0.09) -> 0
D51: 29243 | E51: 0.155 | F51: 0.0947045 | G51: =E51-F51 -> 0.0602955 | I51: =--(Risk_Prem2[[#This Row],[Return on Equity]]<0.09) -> 0
D52: 29250 | E52: 0.1386 | F52: 0.0952055 | G52: =E52-F52 -> 0.0433945 | I52: =--(Risk_Prem2[[#This Row],[Return on Equity]]<0.09) -> 0
D53: 29251 | E53: 0.1261 | F53: 0.095306 | G53: =E53-F53 -> 0.030794 | I53: =--(Risk_Prem2[[#This Row],[Return on Equity]]<0.09) -> 0
D54: 29257 | E54: 0.1371 | F54: 0.095789 | G54: =E54-F54 -> 0.041311 | I54: =--(Risk_Prem2[[#This Row],[Return on Equity]]<0.09) -> 0
D55: 29264 | E55: 0.128 | F55: 0.096326 | G55: =E55-F55 -> 0.031674 | I55: =--(Risk_Prem2[[#This Row],[Return on Equity]]<0.09) -> 0
D56: 29265 | E56: 0.13 | F56: 0.0964645 | G56: =E56-F56 -> 0.0335355 | I56: =--(Risk_Prem2[[#This Row],[Return on Equity]]<0.09) -> 0
D57: 29270 | E57: 0.135 | F57: 0.096782 | G57: =E57-F57 -> 0.038218 | I57: =--(Risk_Prem2[[#This Row],[Return on Equity]]<0.09) -> 0
... D1629: 43538 | E1629: 0.094 | F1629: 0.031196105 | G1629: =E1629-F1629 -> 0.062803895 | I1629: =--(Risk_Prem2[[#This Row],[Return on Equity]]<0.09) -> 0
F1632: # of Cases: | G1632: =COUNT(Risk_Prem2[Return on Equity]) -> 1584 | I1632: =SUM(I46:I1629) -> 10
F1633: Average: | G1633: =AVERAGE(Risk_Prem2[Risk Premium]) -> 0.046655706

Sheet RBH-6 Expected Earnings
A1: Expected Earnings Analysis
C3: [1] | D3: [2] | E3: [3] | F3: [4] | G3: [5] | H3: [6]
C4: Expected
C5: ROE | D5: Shares Outstanding | G5: Adjustment | H5: Adjusted
A6: Company | B6: Ticker | C6: 2021-23/ 2022-24 | D6: 2019 | E6: 2021-23/ 2022-24 | F6: % Increase | G6: Factor | H6: ROE
A8: ALLETE, Inc. | B8: ALE | C8: 0.09 | D8: 51.5 | E8: 51.5 | F8: =(E8/D8)^(1/5)-1 -> 0 | G8: =2*(1+F8)/(2+F8) -> 1 | H8: =C8*G8 -> 0.09
A9: Alliant Energy Corporation | B9: LNT | C9: 0.1 | D9: 240 | E9: 250 | F9: =(E9/D9)^(1/5)-1 -> 0.0081978185 | G9: =2*(1+F9)/(2+F9) -> 1.0040822 | H9: =C9*G9 -> 0.10040822
A10: Ameren Corporation | B10: AEE | C10: 0.105 | D10: 246.5 | E10: 253 | F10: =(E10/D10)^(1/5)-1 -> 0.0052190712 | G10: =2*(1+F10)/(2+F10) -> 1.0026027 | H10: =C10*G10 -> 0.10527329
A11: Avangrid, Inc. | B11: AGR | C11: 0.065 | D11: 309 | E11: 309 | F11: =(E11/D11)^(1/5)-1 -> 0 | G11: =2*(1+F11)/(2+F11) -> 1 | H11: =C11*G11 -> 0.065
A12: Black Hills Corporation | B12: BKH | C12: 0.1 | D12: 60.5 | E12: 61 | F12: =(E12/D12)^(1/4)-1 -> 0.0020597431 | G12: =2*(1+F12)/(2+F12) -> 1.0010288 | H12: =C12*G12 -> 0.10010288
A13: CMS Energy Corporation | B13: CMS | C13: 0.14 | D13: 285 | E13: 297 | F13: =(E13/D13)^(1/5)-1 -> 0.0082827051 | G13: =2*(1+F13)/(2+F13) -> 1.0041243 | H13: =C13*G13 -> 0.1405774
A14: Consolidated Edison, Inc. | B14: ED | C14: 0.085 | D14: 328 | E14: 332 | F14: =(E14/D14)^(1/5)-1 -> 0.002427213 | G14: =2*(1+F14)/(2+F14) -> 1.0012121 | H14: =C14*G14 -> 0.085103032
A15: DTE Energy Company | B15: DTE | C15: 0.105 | D15: 192 | E15: 200 | F15: =(E15/D15)^(1/5)-1 -> 0.0081978185 | G15: =2*(1+F15)/(2+F15) -> 1.0040822 | H15: =C15*G15 -> 0.10542863
A16: Duke Energy Corporation | B16: DUK | C16: 0.085 | D16: 731.5 | E16: 750 | F16: =(E16/D16)^(1/5)-1 -> 0.005007694 | G16: =2*(1+F16)/(2+F16) -> 1.0024976 | H16: =C16*G16 -> 0.085212295
A17: El Paso Electric Company | B17: EE | C17: 0.085 | D17: 40.7 | E17: 41 | F17: =(E17/D17)^(1/4)-1 -> 0.00183768 | G17: =2*(1+F17)/(2+F17) -> 1.000918 | H17: =C17*G17 -> 0.08507803
A18: Evergy, Inc. | B18: EVRG | C18: 0.085 | D18: 225 | E18: 212 | F18: =(E18/D18)^(1/5)-1 -> -0.011832267 | G18: =2*(1+F18)/(2+F18) -> 0.99404866 | H18: =C18*G18 -> 0.084494136
A19: Eversource Energy | B19: ES | C19: 0.095 | D19: 316.89 | E19: 316.89 | F19: =(E19/D19)^(1/5)-1 -> 0 | G19: =2*(1+F19)/(2+F19) -> 1 | H19: =C19*G19 -> 0.095
A20: Hawaiian Electric Industries, Inc. | B20: HE | C20: 0.095 | D20: 110 | E20: 113 | F20: =(E20/D20)^(1/4)-1 -> 0.0067495394 | G20: =2*(1+F20)/(2+F20) -> 1.0033634 | H20: =C20*G20 -> 0.095319525
A21: NextEra Energy, Inc. | B21: NEE | C21: 0.135 | D21: 535 | E21: 535 | F21: =(E21/D21)^(1/5)-1 -> 0 | G21: =2*(1+F21)/(2+F21) -> 1 | H21: =C21*G21 -> 0.135
A22: NorthWestern Corporation | B22: NWE | C22: 0.09 | D22: 50.5 | E22: 51 | F22: =(E22/D22)^(1/4)-1 -> 0.00246611 | G22: =2*(1+F22)/(2+F22) -> 1.0012315 | H22: =C22*G22 -> 0.090110838
A23: OGE Energy Corp. | B23: OGE | C23: 0.115 | D23: 199.7 | E23: 199.7 | F23: =(E23/D23)^(1/5)-1 -> 0 | G23: =2*(1+F23)/(2+F23) -> 1 | H23: =C23*G23 -> 0.115
A24: Otter Tail Corporation | B24: OTTR | C24: 0.105 | D24: 39.75 | E24: 41.75 | F24: =(E24/D24)^(1/5)-1 -> 0.009866276 | G24: =2*(1+F24)/(2+F24) -> 1.0049089 | H24: =C24*G24 -> 0.10551544
A25: Pinnacle West Capital Corporation | B25: PNW | C25: 0.105 | D25: 112.75 | E25: 114.25 | F25: =(E25/D25)^(1/4)-1 -> 0.0033094771 | G25: =2*(1+F25)/(2+F25) -> 1.001652 | H25: =C25*G25 -> 0.10517346
A26: PNM Resources, Inc. | B26: PNM | C26: 0.095 | D26: 79.65 | E26: 83 | F26: =(E26/D26)^(1/4)-1 -> 0.010352867 | G26: =2*(1+F26)/(2+F26) -> 1.0051498 | H26: =C26*G26 -> 0.095489229
A27: Portland General Electric Company | B27: POR | C27: 0.09 | D27: 89.4 | E27: 90 | F27: =(E27/D27)^(1/4)-1 -> 0.001673646 | G27: =2*(1+F27)/(2+F27) -> 1.0008361 | H27: =C27*G27 -> 0.090075251
A28: Southern Company | B28: SO | C28: 0.13 | D28: 1050 | E28: 1090 | F28: =(E28/D28)^(1/5)-1 -> 0.0075055328 | G28: =2*(1+F28)/(2+F28) -> 1.0037387 | H28: =C28*G28 -> 0.13048604
A29: Wisconsin Energy Corporation | B29: WEC | C29: 0.125 | D29: 315.5 | E29: 315.5 | F29: =(E29/D29)^(1/5)-1 -> 0 | G29: =2*(1+F29)/(2+F29) -> 1 | H29: =C29*G29 -> 0.125
A30: Xcel Energy Inc. | B30: XEL | C30: 0.105 | D30: 518 | E30: 533 | F30: =(E30/D30)^(1/4)-1 -> 0.0071620713 | G30: =2*(1+F30)/(2+F30) -> 1.0035683 | H30: =C30*G30 -> 0.10537467
G32: Median | H32: =MEDIAN(H8:H30) -> 0.10010288
G33: Average | H33: =AVERAGE(H8:H30) -> 0.10148793
A34: Notes:
A35: [1] Source: Value Line | B35: [3] Source: Value Line | F35: [5] Equals (2 x (1 + [4])) / (2 + [4])
A36: [2] Source: Value Line | B36: [4] Equals =([3] / [2])^(1/3)-1; ([3] / [2])^(1/4)-1 | F36: [6] Equals [1] x [5]

Sheet RBH-7 Flotation Costs
B2: Flotation Cost Adjustment
B4: Two most recent open market common stock issuances per company, if available | G4: Emera issuances are included for comparison, but are not in averages.
D5: [1] | E5: [2] | F5: [3] | G5: [4] | H5: [5] | I5: [6] | J5: [7] | K5: [8] | L5: [9]
B6: Company | C6: Date | D6: Shares Issued | E6: Offering Price | F6: Underwriting Discount | G6: Offering Expense | H6: Net Proceeds Per Share | I6: Total Flotation Costs | J6: Gross Equity Issue Before Costs | K6: Net Proceeds | L6: Flotation Cost Percentage
B8: American Electric Power Company, Inc. | C8: 39904 | D8: 69000000 | E8: 24.5 | F8: 0.735 | G8: 400000 | H8: =K8/D8 -> 23.759203 | I8: =G8+(F8*D8) -> 51115000 | J8: =D8*E8 -> 1690500000 | K8: =J8-I8 -> 1639385000 | L8: =I8/J8 -> 0.030236616
B9: American Electric Power Company, Inc. | C9: 37679 | D9: 57500000 | E9: 20.95 | F9: 0.6285 | G9: 550000 | H9: =K9/D9 -> 20.311935 | I9: =G9+(F9*D9) -> 36688750 | J9: =D9*E9 -> 1204625000 | K9: =J9-I9 -> 1167936250 | L9: =I9/J9 -> 0.030456574
K10: Average | L10: =AVERAGE(L9:L9) -> 0.030456574
B12: ALLETE, Inc. | C12: 41697 | D12: 3220000 | E12: 49.75 | F12: 1.74125 | G12: 450000 | H12: =K12/D12 -> 47.868998 | I12: =G12+(F12*D12) -> 6056825 | J12: =D12*E12 -> 160195000 | K12: =J12-I12 -> 154138175 | L12: =I12/J12 -> 0.037809076
B13: ALLETE, Inc. | C13: 37036 | D13: 7475000 | E13: 23.68 | F13: 0.9472 | G13: 350000 | H13: =K13/D13 -> 22.685977 | I13: =G13+(F13*D13) -> 7430320 | J13: =D13*E13 -> 177008000 | K13: =J13-I13 -> 169577680 | L13: =I13/J13 -> 0.041977312
B14: Alliant Energy Corporation | C14: 37803 | D14: 17250000 | E14: 19.25 | F14: 0.77 | G14: 370000 | H14: =K14/D14 -> 18.458551 | I14: =G14+(F14*D14) -> 13652500 | J14: =D14*E14 -> 332062500 | K14: =J14-I14 -> 318410000 | L14: =I14/J14 -> 0.041114248
B15: Alliant Energy Corporation | C15: 37203 | D15: 9775000 | E15: 28 | F15: 1.05 | G15: 425000 | H15: =K15/D15 -> 26.906522 | I15: =G15+(F15*D15) -> 10688750 | J15: =D15*E15 -> 273700000 | K15: =J15-I15 -> 263011250 | L15: =I15/J15 -> 0.039052795
B16: Ameren Corp. | C16: 40065 | D16: 21850000 | E16: 25.25 | F16: 0.7575 | G16: 450000 | H16: =K16/D16 -> 24.471905 | I16: =G16+(F16*D16) -> 17001375 | J16: =D16*E16 -> 551712500 | K16: =J16-I16 -> 534711125 | L16: =I16/J16 -> 0.030815642
B17: Ameren Corp. | C17: 38168 | D17: 10925000 | E17: 42 | F17: 1.26 | G17: 400000 | H17: =K17/D17 -> 40.703387 | I17: =G17+(F17*D17) -> 14165500 | J17: =D17*E17 -> 458850000 | K17: =J17-I17 -> 444684500 | L17: =I17/J17 -> 0.030871745
B18: Avangrid, Inc. | C18: 41543 | D18: 5750000 | E18: 37.25 | F18: 1.30375 | G18: 250000 | H18: =K18/D18 -> 35.902772 | I18: =G18+(F18*D18) -> 7746562.5 | J18: =D18*E18 -> 214187500 | K18: =J18-I18 -> 2.0644094e+08 | L18: =I18/J18 -> 0.036167202
B19: Avangrid, Inc. | C19: 40437 | D19: 20355000 | E19: 25.75 | F19: 1.094375 | G19: 325000 | H19: =K19/D19 -> 24.639658 | I19: =G19+(F19*D19) -> 22601003 | J19: =D19*E19 -> 524141250 | K19: =J19-I19 -> 5.0154025e+08 | L19: =I19/J19 -> 0.043120062
B20: Black Hills Corporation | C20: 42327 | D20: 5980000 | E20: 40.25 | F20: 1.40875 | G20: 1200000 | H20: =K20/D20 -> 38.640581 | I20: =G20+(F20*D20) -> 9624325 | J20: =D20*E20 -> 240695000 | K20: =J20-I20 -> 231070675 | L20: =I20/J20 -> 0.039985563
B21: Black Hills Corporation | C21: 40494 | D21: 4600000 | E21: 29.75 | F21: 1.04125 | G21: 276650 | H21: =K21/D21 -> 28.648609 | I21: =G21+(F21*D21) -> 5066400 | J21: =D21*E21 -> 136850000 | K21: =J21-I21 -> 131783600 | L21: =I21/J21 -> 0.037021556
B22: CMS Energy Corporation | C22: 38441 | D22: 23000000 | E22: 12.25 | F22: 0.4288 | G22: 325000 | H22: =K22/D22 -> 11.80707 | I22: =G22+(F22*D22) -> 10187400 | J22: =D22*E22 -> 281750000 | K22: =J22-I22 -> 271562600 | L22: =I22/J22 -> 0.036157587
B23: CMS Energy Corporation | C23: 38267 | D23: 32775000 | E23: 9.1 | F23: 0.3185 | G23: 325000 | H23: =K23/D23 -> 8.7715839 | I23: =G23+(F23*D23) -> 10763838 | J23: =D23*E23 -> 298252500 | K23: =J23-I23 -> 2.8748866e+08 | L23: =I23/J23 -> 0.036089681
B24: Consolidated Edison, Inc | C24: 42955 | D24: 4100000 | E24: 83.7701 | F24: =84.06-83.7701 -> 0.2899 | G24: 350000 | H24: =K24/D24 -> 83.394834 | I24: =G24+(F24*D24) -> 1538590 | J24: =D24*E24 -> 343457410 | K24: =J24-I24 -> 341918820 | L24: =I24/J24 -> 0.0044797112
B25: Consolidated Edison, Inc | C25: 42501 | D25: 10120000 | E25: 71.5 | F25: 2.145 | G25: 550000 | H25: =K25/D25 -> 69.300652 | I25: =G25+(F25*D25) -> 22257400 | J25: =D25*E25 -> 723580000 | K25: =J25-I25 -> 701322600 | L25: =I25/J25 -> 0.030760109
B26: DTE Energy Company | C26: 37426 | D26: 6325000 | E26: 43.25 | F26: 1.4056 | G26: 250000 | H26: =K26/D26 -> 41.804874 | I26: =G26+(F26*D26) -> 9140420 | J26: =D26*E26 -> 273556250 | K26: =J26-I26 -> 264415830 | L26: =I26/J26 -> 0.033413311
B27: Duke Energy Corporation | C27: 43165 | D27: 21275000 | E27: 74.072 | F27: 0 | G27: 450000 | H27: =K27/D27 -> 74.050848 | I27: =G27+(F27*D27) -> 450000 | J27: =D27*E27 -> 1575881800 | K27: =J27-I27 -> 1575431800 | L27: =I27/J27 -> 0.00028555441
B28: Duke Energy Corporation | C28: 42430 | D28: 10637500 | E28: 72 | F28: 2.16 | G28: 400000 | H28: =K28/D28 -> 69.802397 | I28: =G28+(F28*D28) -> 23377000 | J28: =D28*E28 -> 765900000 | K28: =J28-I28 -> 742523000 | L28: =I28/J28 -> 0.030522261
B29: Evergy, Inc. | C29: 42640 | D29: =52600000+7890000 -> 60490000 | E29: 26.45 | F29: 0.7935 | G29: 500000 | H29: =K29/D29 -> 25.648234 | I29: =G29+(F29*D29) -> 48498815 | J29: =D29*E29 -> 1599960500 | K29: =J29-I29 -> 1551461685 | L29: =I29/J29 -> 0.030312508
B30: Evergy, Inc. | C30: 41540 | D30: 8916000 | E30: 31.15 | F30: 1.09 | G30: 250000 | H30: =K30/D30 -> 30.031961 | I30: =G30+(F30*D30) -> 9968440 | J30: =D30*E30 -> 277733400 | K30: =J30-I30 -> 267764960 | L30: =I30/J30 -> 0.035892118
B31: Eversource Energy | C31: 39888 | D31: 18975000 | E31: 20.2 | F31: 0.6565 | G31: 335000 | H31: =K31/D31 -> 19.525845 | I31: =G31+(F31*D31) -> 12792088 | J31: =D31*E31 -> 383295000 | K31: =J31-I31 -> 3.7050291e+08 | L31: =I31/J31 -> 0.033374
B32: Eversource Energy | C32: 38692 | D32: 23000000 | E32: 19.09 | F32: 0.62 | G32: 340000 | H32: =K32/D32 -> 18.455217 | I32: =G32+(F32*D32) -> 14600000 | J32: =D32*E32 -> 439070000 | K32: =J32-I32 -> 424470000 | L32: =I32/J32 -> 0.033252101
B33: Hawaiian Electric Industries, Inc. | C33: 41351 | D33: 7000000 | E33: 26.75 | F33: 1.00312 | G33: 450000 | H33: =K33/D33 -> 25.682594 | I33: =G33+(F33*D33) -> 7471840 | J33: =D33*E33 -> 187250000 | K33: =J33-I33 -> 179778160 | L33: =I33/J33 -> 0.039903017
B34: Hawaiian Electric Industries, Inc. | C34: 39784 | D34: 5750000 | E34: 23 | F34: 0.8625 | G34: 300000 | H34: =K34/D34 -> 22.085326 | I34: =G34+(F34*D34) -> 5259375 | J34: =D34*E34 -> 132250000 | K34: =J34-I34 -> 126990625 | L34: =I34/J34 -> 0.039768431
B35: NextEra Energy, Inc. | C35: 42675 | D35: 13800000 | E35: 124 | F35: 0 | G35: 750000 | H35: =K35/D35 -> 123.94565 | I35: =G35+(F35*D35) -> 750000 | J35: =D35*E35 -> 1711200000 | K35: =J35-I35 -> 1710450000 | L35: =I35/J35 -> 0.00043828892
B36: NextEra Energy, Inc. | C36: 41596 | D36: 11100000 | E36: 88.03 | F36: 0 | G36: 750000 | H36: =K36/D36 -> 87.962432 | I36: =G36+(F36*D36) -> 750000 | J36: =D36*E36 -> 977133000 | K36: =J36-I36 -> 976383000 | L36: =I36/J36 -> 0.0007675516
B37: NorthWestern Corporation | C37: 42276 | D37: 1100000 | E37: 51.81 | F37: 1.33 | G37: 1000000 | H37: =K37/D37 -> 49.570909 | I37: =G37+(F37*D37) -> 2463000 | J37: =D37*E37 -> 56991000 | K37: =J37-I37 -> 54528000 | L37: =I37/J37 -> 0.04321735
B38: NorthWestern Corporation | C38: 41948 | D38: 7766990 | E38: 51.5 | F38: 1.8025 | G38: 1000000 | H38: =K38/D38 -> 49.56875 | I38: =G38+(F38*D38) -> 14999999 | J38: =D38*E38 -> 399999985 | K38: =J38-I38 -> 3.8499999e+08 | L38: =I38/J38 -> 0.0375
B39: OGE Energy Corp. | C39: 37854 | D39: 5324074 | E39: 21.6 | F39: 0.79 | G39: 325000 | H39: =K39/D39 -> 20.748957 | I39: =G39+(F39*D39) -> 4531018.5 | J39: =D39*E39 -> 1.15e+08 | K39: =J39-I39 -> 1.1046898e+08 | L39: =I39/J39 -> 0.039400161
B40: Otter Tail Corporation | C40: 39709 | D40: 5175000 | E40: 30 | F40: 1.0875 | G40: 400000 | H40: =K40/D40 -> 28.835205 | I40: =G40+(F40*D40) -> 6027812.5 | J40: =D40*E40 -> 155250000 | K40: =J40-I40 -> 1.4922219e+08 | L40: =I40/J40 -> 0.03882649
B41: Otter Tail Corporation | C41: 38328 | D41: 3335000 | E41: 25.45 | F41: 0.95 | G41: 300000 | H41: =K41/D41 -> 24.410045 | I41: =G41+(F41*D41) -> 3468250 | J41: =D41*E41 -> 84875750 | K41: =J41-I41 -> 81407500 | L41: =I41/J41 -> 0.040862673
... B53: Xcel Energy Inc. | C53: 39700 | D53: 17250000 | E53: 20.25 | F53: 0.15 | G53: 600000 | H53: =K53/D53 -> 20.065217 | I53: =G53+(F53*D53) -> 3187500 | J53: =D53*E53 -> 349312500 | K53: =J53-I53 -> 346125000 | L53: =I53/J53 -> 0.0091250671
B55: Mean | I55: =AVERAGE(I8:I53) -> 13261973 | J55: =AVERAGE(J8:J53) -> 4.9698053e+08
K56: WEIGHTED AVERAGE FLOTATION COSTS: | L56: =I55/J55 -> 0.026685096 | M56: [10]
...

Sheet RBH-8 Rate Mechanisms
A2: Summary of Adjustment Clauses & Alternative Regulation/Incentive Plans
D4: Adjustment Clauses | K4: Alternative Regulation / Incentive Plans
A5: Company | B5: Parent | C5: State | D5: Fuel/ Purchased Power | E5: Decoupling (F/P) [1] | F5: New Capital Investment [2] | G5: Energy Efficiency [3] | H5: Renewables & RPS [4] | I5: Environmental [5] | J5: Other [6] | K5: Formula-Based Rates | L5: Multiyear Rate Plans | M5: Performance Based Ratemaking | N5: CWIP Allowed in Rate Base (L/F) | O5: Forward Test Year | P5: Price Freeze/ Cap | Q5: Earnings Sharing | R5: Formula-Based ROE | S5: Service Quality/ Performance | T5: Merger Savings
A6: ALLETE (Minnesota Power) | B6: ALE | C6: Minnesota | D6: ü | G6: ü | H6: ü | I6: ü | J6: ü | N6: L | O6: ü
A7: Superior Water, Light and Power Company | B7: ALE | C7: Wisconsin | D7: ü | J7: ü | N7: L | O7: ü
A8: Interstate Power and Light Company | B8: LNT | C8: Iowa | D8: ü | G8: ü | H8: ü | I8: ü | J8: ü | L8: ü | P8: ü
A9: Wisconsin Power and Light Company | B9: LNT | C9: Wisconsin | D9: ü | J9: ü | L9: ü | N9: L | O9: ü | P9: ü | Q9: ü
A10: Ameren Illinois Company | B10: AEE | C10: Illinois | D10: ü | F10: ü | G10: ü | H10: ü | I10: ü | J10: ü | K10: ü | N10: L | Q10: ü | R10: ü | S10: ü
A11: Union Electric Company | B11: AEE | C11: Missouri | D11: ü | E11: P | G11: ü | I11: ü | J11: ü
A12: United Illuminating Company | B12: AGR | C12: Connecticut | D12: ü | E12: F | G12: ü | H12: ü | I12: ü | J12: ü | L12: ü | Q12: ü
A13: Central Maine Power Company | B13: AGR | C13: Maine | D13: ü | E13: F | J13: ü | Q13: ü
A14: New York State Electric & Gas Corporation | B14: AGR | C14: New York | D14: ü | E14: F | G14: ü | H14: ü | J14: ü | L14: ü | M14: ü | P14: ü | Q14: ü
A15: Rochester Gas and Electric Corporation | B15: AGR | C15: New York | D15: ü | E15: F | G15: ü | H15: ü | J15: ü | L15: ü | M15: ü | P15: ü | Q15: ü
A16: Black Hills Colorado Electric Utility Company, LP | B16: BKH | C16: Colorado | D16: ü | F16: ü | G16: ü | H16: ü | J16: ü | M16: ü | N16: F
A17: Black Hills Power, Inc. | B17: BKH | C17: South Dakota | D17: ü | E17: P | F17: ü | G17: ü | I17: ü | J17: ü | M17: ü
A18: Black Hills Power, Inc. | B18: BKH | C18: Wyoming | D18: ü | J18: ü | M18: ü
A19: Cheyenne Light, Fuel and Power Company | B19: BKH | C19: Wyoming | D19: ü | E19: P | G19: ü | J19: ü
A20: Consumers Energy Company | B20: CMS | C20: Michigan | D20: ü | G20: ü | H20: ü | J20: ü | N20: L | O20: ü
A21: Rockland Electric Company | B21: ED | C21: New Jersey | D21: ü | F21: ü | G21: ü | H21: ü | J21: ü
A22: Consolidated Edison Company of New York, Inc. | B22: ED | C22: New York | D22: ü | E22: F | F22: ü | G22: ü | H22: ü | I22: ü | J22: ü | L22: ü | O22: ü | P22: ü | Q22: ü
A23: Orange and Rockland Utilities, Inc. | B23: ED | C23: New York | D23: ü | E23: F | F23: ü | G23: ü | H23: ü | J23: ü | L23: ü | O23: ü | P23: ü | Q23: ü
A24: DTE Electric Company | B24: DTE | C24: Michigan | D24: ü | G24: ü | H24: ü | I24: ü | J24: ü | N24: L | O24: ü
A25: Duke Energy Florida, LLC | B25: DUK | C25: Florida | D25: ü | F25: ü | G25: ü | I25: ü | J25: ü | L25: ü | M25: ü | O25: ü | P25: ü
A26: Duke Energy Indiana, LLC | B26: DUK | C26: Indiana | D26: ü | E26: P | F26: ü | G26: ü | H26: ü | I26: ü | J26: ü | N26: F | P26: ü
A27: Duke Energy Kentucky, Inc. | B27: DUK | C27: Kentucky | D27: ü | E27: P | G27: ü | I27: ü | J27: ü | N27: F | O27: ü
A28: Duke Energy Carolinas, LLC | B28: DUK | C28: North Carolina | D28: ü | E28: P | G28: ü | H28: ü | I28: ü | J28: ü | P28: ü
A29: Duke Energy Progress, LLC | B29: DUK | C29: North Carolina | D29: ü | E29: P | F29: ü | G29: ü | H29: ü | I29: ü | J29: ü
A30: Duke Energy Ohio, Inc. | B30: DUK | C30: Ohio | D30: ü | E30: P | F30: ü | G30: ü | H30: ü | J30: ü | Q30: ü
A31: Duke Energy Carolinas, LLC | B31: DUK | C31: South Carolina | D31: ü | E31: P | G31: ü | H31: ü | I31: ü | J31: ü | L31: ü | P31: ü
A32: Duke Energy Progress, LLC | B32: DUK | C32: South Carolina | D32: ü | E32: P | G32: ü | H32: ü | I32: ü | J32: ü
A33: El Paso Electric Company | B33: EE | C33: New Mexico | D33: ü | G33: ü | J33: ü
A34: El Paso Electric Company | B34: EE | C34: Texas | D34: ü | G34: ü | J34: ü
A35: Kansas City Power & Light Company | B35: EVRG | C35: Kansas | D35: ü | G35: ü | I35: ü | J35: ü
A36: Kansas City Power & Light Company | B36: EVRG | C36: Missouri | D36: ü | E36: P | G36: ü | I36: ü | J36: ü
A37: KCP&L Greater Missouri Operations Company | B37: EVRG | C37: Missouri | D37: ü | G37: ü | H37: ü | I37: ü | J37: ü
A38: Westar Energy (KPL) | B38: EVRG | C38: Kansas | D38: ü | E38: P | G38: ü | I38: ü | J38: ü | T38: ü
A39: Connecticut Light and Power Company | B39: ES | C39: Connecticut | D39: ü | E39: F | F39: ü | G39: ü | I39: ü | J39: ü | L39: ü | O39: ü | P39: ü | Q39: ü
A40: NSTAR Electric Company | B40: ES | C40: Massachusetts | D40: ü | E40: F | F40: ü | G40: ü | H40: ü | J40: ü | L40: ü | M40: ü | Q40: ü | S40: ü
A41: Western Massachusetts Electric Company | B41: ES | C41: Massachusetts | D41: ü | E41: F | F41: ü | G41: ü | H41: ü | J41: ü | L41: ü | M41: ü | Q41: ü | S41: ü
A42: Public Service Company of New Hampshire | B42: ES | C42: New Hampshire | D42: ü | E42: P | F42: ü | G42: ü | J42: ü | L42: ü | P42: ü | Q42: ü
...

Sheet RBH-9 Capital Expenditures
A2: Planned Capital Expenditures / 2018 Net Plant
B28: Company | C28: Ticker | D28: 3-year CAPEX / Net Plant [1]
B30: ALLETE, Inc. | C30: ALE | D30: =VLOOKUP($C30,$H$30:$I$53,2,FALSE) -> 0.30403519 | H30: POR | I30: 0.19351494
B31: Alliant Energy Corporation | C31: LNT | D31: =VLOOKUP($C31,$H$30:$I$53,2,FALSE) -> 0.37959397 | H31: EVRG | I31: 0.20246412
B32: Ameren Corporation | C32: AEE | D32: =VLOOKUP($C32,$H$30:$I$53,2,FALSE) -> 0.35036716 | H32: OGE | I32: 0.20908455
B33: Avangrid, Inc. | C33: AGR | D33: =VLOOKUP($C33,$H$30:$I$53,2,FALSE) -> 0.29717684 | H33: NWE | I33: 0.21855543
B34: Black Hills Corporation | C34: BKH | D34: =VLOOKUP($C34,$H$30:$I$53,2,FALSE) -> 0.31903209 | H34: SO | I34: 0.24893035
B35: CMS Energy Corporation | C35: CMS | D35: =VLOOKUP($C35,$H$30:$I$53,2,FALSE) -> 0.37663025 | H35: ED | I35: 0.25622754
B36: Consolidated Edison, Inc. | C36: ED | D36: =VLOOKUP($C36,$H$30:$I$53,2,FALSE) -> 0.25622754 | H36: PNW | I36: 0.26509414
B37: DTE Energy Company | C37: DTE | D37: =VLOOKUP($C37,$H$30:$I$53,2,FALSE) -> 0.40180139 | H37: PNM | I37: 0.27496935
B38: Duke Energy Corporation | C38: DUK | D38: =VLOOKUP($C38,$H$30:$I$53,2,FALSE) -> 0.3111713 | H38: EE | I38: 0.28399837
B39: El Paso Electric Company | C39: EE | D39: =VLOOKUP($C39,$H$30:$I$53,2,FALSE) -> 0.28399837 | H39: HE | I39: 0.28477207
B40: Evergy, Inc | C40: EVRG | D40: =VLOOKUP($C40,$H$30:$I$53,2,FALSE) -> 0.20246412 | H40: AGR | I40: 0.29717684
B41: Eversource Energy | C41: ES | D41: =VLOOKUP($C41,$H$30:$I$53,2,FALSE) -> 0.33350365 | H41: ALE | I41: 0.30403519
... B52: Xcel Energy Inc. | C52: XEL | D52: =VLOOKUP($C52,$H$30:$I$53,2,FALSE) -> 0.31468661 | H52: NEE | I52: 0.42710851
H53: OTTR | I53: 0.46049428
B54: Median | D54: =MEDIAN(D30:D52) -> 0.30403519
B56: AEP Texas | D56: 0.42185702
B60: Notes:
B61: [1] Sources: Value Line; American Electric Power Company, Inc. SEC Form 10-K (Dec 31, 2018).

Sheet RBH-10 Capital Structure
B1: Proxy Group Capital Structure | N1: Proxy Group Capital Structure
D3: % Common Equity | P3: % Long-Term Debt
B4: Company | C4: Ticker | D4: 2018Q3 | E4: 2018Q2 | F4: 2018Q1 | G4: 2017Q4 | H4: 2017Q3 | I4: 2017Q2 | J4: 2017Q1 | K4: 2016Q4 | L4: Average | N4: Company | O4: Ticker | P4: 2018Q3 | Q4: 2018Q2 | R4: 2018Q1 | S4: 2017Q4 | T4: 2017Q3 | U4: 2017Q2 | V4: 2017Q1 | W4: 2016Q4 | X4: Average
