Workbook

Sheet  Exh Rate Case Exp
A1: AEP TEXAS INC
A2: SUMMARY OF RATE CASE EXPENSES
A3: PUC DOCKET NOS. 33309, 33310, 34301, 40261, 47015, 48222 and 48577
A5: AEP Texas | B5: Total Expenses
A7: PUC Docket No. 33309/33310/34301
A8: Legal Expenses - Central | B8: ='Trailing Charges Central'!I166 -> 211749.86
A9: Legal Expenses - North | B9: ='Trailing Charges North'!I30 -> 1827.2
A10: Total Requested Company Expenses Docket No. 33309/33310/34301 | B10: =B8+B9 -> 213577.06
A13: PUC Docket No. 40261
A14: Legal Expenses | B14: =+'Docket 40261'!H23 -> 82047.58
A15: Employee Expenses | B15: =+'Docket 40261'!H27 -> 55.48
A16: Total Company Expenses Docket No. 40261 | B16: =SUM(B14:B15) -> 82103.06
A19: PUC Docket No. 47015
A20: Other Expenses | B20: ='2017 DCRF 47015'!H21 -> 4314.05
A21: Employee Expenses | B21: =+'2017 DCRF 47015'!H74 -> 4005.91
A22: Total Company Expenses Docket No. 47015 | B22: =SUM(B20:B21) -> 8319.96
A25: PUC Docket No. 48222
A26: Other Expenses | B26: =+'2018 DCRF 48222 '!H30 -> 372.25
A27: Employee Expenses | B27: =+'2018 DCRF 48222 '!H66 -> 23414.13
A28: Total Company Expenses Docket No. 48222 | B28: =+SUM(B26:B27) -> 23786.38
A30: PUC Docket No. 48577
A31: Consultant Expenses | B31: =+'Docket 48577 '!H10 -> 2400
A32: Legal Expenses | B32: =+'Docket 48577 '!H47 -> 366397.52
A33: Other Expenses | B33: =+'Docket 48577 '!H71 -> 26383.77
A34: Employee Expenses | B34: =+'Docket 48577 '!H101 -> 3994.81
A35: Total Company Expenses Docket No. 48577 | B35: =SUM(B31:B34) -> 399176.1
A38: Total Company Expenses Docket Nos. 33309, 33310, 34301, 40261, 47015, 48222 and 48577 | B38: =B10+B16+B22+B28+B35 -> 726962.56
A39: Less: Over-Recovery on 34301 Rate Case Amortization- Allocable to Cities | B39: ='Trailing Charges Central'!I170 -> -143175.95
A41: Total Company Expenses to be collected for Docket Nos. 33309, 33310, 34301, 40261, 47015, 48222 and 48577 | B41: =B38+B39 -> 583786.61
A44: Municipal Expenses Reimbursed by AEP Texas | B44: Total Expenses
A46: PUC Docket No. 33309/33310/34301
A47: City of Abilene | B47: =+'Trailing Charges North'!I17 -> 1094.64
A48: City of McAllen | B48: =+'Trailing Charges Central'!I63 -> 234968.2
A50: Total Expenses Requested for Reimbursment Associated with Docket Nos. 33309/33310/34301 | B50: =SUM(B47:B49) -> 236062.84
A53: PUC Docket No. 47015
A54: City of McAllen | B54: =+'2017 DCRF 47015'!H15 -> 12680.27
A55: Total Expenses Reimbursed Docket No. 48222 | B55: =SUM(B54:B54) -> 12680.27
A58: Financo
A59: City of McAllen | B59: =+'2018 DCRF 48222 '!H17 -> 24321.45
A60: Total Expenses Reimbursed Docket No. 48222 | B60: =SUM(B59:B59) -> 24321.45
...

Sheet Exh Rate Case Exp 2
A1: AEP TEXAS INC
A2: SUMMARY OF RATE CASE EXPENSES
A3: PUC DOCKET NOS. 33309, 33310, 34301, 40261, 47015, 48222 and 48577
B5: Description of Service Provided | C5: Total Expenses
A6: =' Exh Rate Case Exp'!A7 -> PUC Docket No. 33309/33310/34301
A8: Legal Expenses
A9: Bracewell & Giuliani | B9: Bracewell & Giuliani attorneys provided counsel to AEP Texas in Docket Nos. 33309 and 33310. These costs were required to carry out the activities required to prosecute this case. These activities are described in detail in the voluminous invoices provided in the work papers to this Exhibit. As shown in the invoices, the activities were not duplicative or excessive and provided substantial value to the Company. The billing rates to AEP Texas for the attorneys at Bracewell & Giuliani ranged between $120/hour to $325/hour. Paralegal services were charged to AEP Texas at a rate of $80/hour to $90/hour. Bracewell & Giuliani was also reimbursed for expenses related to copying and courier charges. The billing rates charged by Bracewell & Giuliani to AEP Texas were the firm's normal hourly billing rates, were comparable to the rates charged by other attorneys for similar services to other Texas utilities, and were the normal hourly rates or were lower than the normal hourly billing rates charged by the firm for services to non-regulated entities. | C9: ='Trailing Charges Central'!I101 -> 147341.08
A10: Clark Thomas & Winters | B10: Clark Thomas & Winters attorneys provided counsel to AEP Texas in Docket Nos. 33309, 33310 and 34301. These costs were required to carry out the activities required to prosecute this case. These activities are described in detail in the voluminous invoices provided in the work papers to this Exhibit. As shown in the invoices, the activities were not duplicative or excessive and provided substantial value to the Company. The billing rates to AEP Texas for the attorneys at Clark Thomas & Winters ranged between $125/hour to $340/hour. Paralegal services were charged to AEP Texas at a rate of $90/hour. Clark Thomas & Winters was also reimbursed for expenses related to copying and courier charges. The billing rates charged by Clark Thomas & Winters to AEP Texas were the firm's normal hourly billing rates, were comparable to the rates charged by other attorneys for similar services to other Texas utilities, and were the normal hourly rates or were lower than the normal hourly billing rates charged by the firm for services to non-regulated entities. | C10: ='Trailing Charges Central'!I165+'Trailing Charges North'!I30 -> 66235.98
B11: Total Legal | C11: =C9+C10 -> 213577.06
B13: Over-Recovery on 34301 Rate Case Amortization | C13: ='Trailing Charges Central'!I170 -> -143175.95
A15: Total Expenses Associated with Dockets 33309, 33310 and 34301 | C15: =C11+C13 -> 70401.106
A17: =+' Exh Rate Case Exp'!A13 -> PUC Docket No. 40261
A19: Legal Expenses
A20: Bracewell & Giuliani | B20: Bracewell & Giuliani attorneys provided counsel to AEP Texas in Docket No 40261. These costs were required to carry out the activites required to prosecute this case. These activities are described in detail in the voluminous invoices provided in the work papers to this Exhibit. As shown in the invoices, the activities were not duplicative or excessive and provided substantial value to the Company. The billing rates to AEP Texas for the Attorney at Bracewell & Giuliani ranged between $150/hour to $320/hour. Bracewell & Giuliani was also reimbursed for expenses related to copying and courier charges. The billing rates charged by Bracewell & Giuliani to AEP Texas were the firm's normal hourly billing rates, were comparable to the rates charged by other attorneys for similar services to other Texas utilities, and were the normal hourly rates or were lower than the normal hourly rates charged by the firm for services to non-regulated utilities. | C20: ='Docket 40261'!H23 -> 82047.58
B21: Total Legal | C21: =SUM(C20) -> 82047.58
A23: Employee Expenses
B24: Non payroll employee expenses related to Docket No. 47015 including air fare, car rentals, taxi, hotels, meals, supplies and miscellaneous expenses. | C24: ='Docket 40261'!H27 -> 55.48
A26: Total Expenses Associated with Docket 40261 | C26: =C21+C24 -> 82103.06
A27: =+' Exh Rate Case Exp'!A19 -> PUC Docket No. 47015
A30: Other Expenses
A31: FedEx | B31: These expenses cover delivery services to provide time-sensitive documents to attorneys or representatives of other parties to Docket No. 47015 located outside of Austin or to members of the AEP Texas rate case team located outside of Austin where facsimile transmission was not feasible due to the bulk of the documents, such as multi-page responses to discovery and voluminous materials requested from AEP Texas' voluminous room. | C31: ='2017 DCRF 47015'!H20 -> 4314.05
B32: Total Other | C32: =C31 -> 4314.05
A34: Employee Expenses
B35: Non payroll employee expenses related to Docket No. 47015 including air fare, car rentals, taxi, hotels, meals, supplies and miscellaneous expenses. | C35: ='2017 DCRF 47015'!H74 -> 4005.91
A37: Total Expenses Associated with Docket 47015 | C37: =C32+C35 -> 8319.96
A39: =+' Exh Rate Case Exp'!A25 -> PUC Docket No. 48222
A41: Other Expenses
A42: Robert Half | B42: Robert Half furnished temporary clerical personnel to AEP's Austin regulatory services office to assist with the preparation of the rate filing package and responding to discovery. AEP's Austin regulatory services office does not have sufficient full time clerical personnel to handle the requirements associated with preparation of a major rate case filing and the extensive discovery generated by such a case. | C42: ='2018 DCRF 48222 '!H25 -> 322.09
A43: US Postal Service | B43: Cost of postage necessary to mail documents and other materials to parties in connection with the case. | C43: ='2018 DCRF 48222 '!H29 -> 50.16
B44: Total Other | C44: =SUM(C42:C43) -> 372.25
A46: Employee Expenses
B47: Non payroll employee expenses related to Docket No. 48222 including air fare, car rentals, taxi, hotels, meals, supplies and miscellaneous expenses. | C47: ='2018 DCRF 48222 '!H66 -> 23414.13
A49: Total Expenses Associated with Docket 44701 | C49: =C44+C47 -> 23786.38
A51: =+' Exh Rate Case Exp'!A30 -> PUC Docket No. 48577
A53: Legal Expenses
A54: Duggins, Wren, Mann & Romero, LLP | B54: DWMR attorneys provided counsel to AEP Texas in Docket No. 48577. These costs were required to carry out the activities required to prosecute this case. These activities are described in detail in the voluminous invoices provided in the work papers to this Exhibit. As shown in the invoices, the activities were not duplicative or excessive and provided substantial value to the Company. The billing rates to AEP Texas for the attorneys at DWMR ranged between $335/hour to $395/hour. Paralegal services were charged to AEP Texas at a rate of $135/hour. DWMR was also reimbursed for courier expenses. The billing rates charged by DWMR to AEP Texas were the firm's normal hourly billing rates, were comparable to the rates charged by other attorneys for similar services to other Texas utilities, and were the normal hourly rates or were lower than the normal hourly billing rates charged by the firm for services to non-regulated entities. | C54: ='Docket 48577 '!H46 -> 366397.52
B55: Total Legal | C55: =SUM(C54) -> 366397.52
A57: Consultant Expenses
A58: Financo | C58: ='Docket 48577 '!H9 -> 2400
B59: Total Consultant | C59: =C58 -> 2400
...

Sheet Docket 40261
A1: AMERICAN ELECTRIC POWER TEXAS INC
A2: SUMMARY OF RATE CASE EXPENSES
A3: PUC DOCKET NO. 40261
A6: Category | B6: Descr | C6: Voucher | D6: Vendor | E6: Name | F6: Amount | G6: Adjustment | H6: Requested | I6: Employee Name | J6: Year | K6: Period | L6: Invoice | M6: Invoice Date
A7: Legal | B7: Legal | C7: 01499816 | D7: 0000199577 | E7: BRACEWELL & GIULIANI LLP | F7: 5824.8 | G7: 0 | H7: =+F7+G7 -> 5824.8 | J7: 2012 | K7: 3 | L7: 21505447 | M7: 40966
A8: Legal | B8: Legal | C8: 01500576 | D8: 0000199577 | E8: BRACEWELL & GIULIANI LLP | F8: 16914.5 | G8: 0 | H8: =+F8+G8 -> 16914.5 | J8: 2012 | K8: 3 | L8: 21506988 | M8: 40966
E9: Subtotal | F9: =+F8+F7 -> 22739.3 | G9: =+G8+G7 -> 0 | H9: =+H8+H7 -> 22739.3
A10: Legal | B10: Legal | C10: 01507417 | D10: 0000199577 | E10: BRACEWELL & GIULIANI LLP | F10: 15392 | H10: =+F10+G10 -> 15392 | J10: 2012 | K10: 4 | L10: 21509869 | M10: 3/31/2012
E11: Subtotal | F11: =+F10 -> 15392 | G11: =+G10 -> 0 | H11: =+H10 -> 15392
A12: Legal | B12: Legal | C12: 01515976 | D12: 0000199577 | E12: BRACEWELL & GIULIANI LLP | F12: 32550.12 | H12: =+F12+G12 -> 32550.12 | J12: 2012 | K12: 5 | L12: 21512285 | M12: 4/30/2012
E13: Subtotal | F13: =+F12 -> 32550.12 | G13: =+G12 -> 0 | H13: =+H12 -> 32550.12
A14: Legal | B14: Legal | C14: 01525515 | D14: 0000199577 | E14: BRACEWELL & GIULIANI LLP | F14: 3243.04 | H14: =+F14+G14 -> 3243.04 | J14: 2012 | K14: 6 | L14: 21515035 | M14: 5/31/2012
E15: Subtotal | F15: =+F14 -> 3243.04 | G15: =+G14 -> 0 | H15: =+H14 -> 3243.04
A16: Legal | B16: Legal | C16: 01533428 | D16: 0000199577 | E16: BRACEWELL & GIULIANI LLP | F16: 6580.04 | H16: =+F16+G16 -> 6580.04 | J16: 2012 | K16: 8 | L16: 21517990 | M16: 7/31/2012
E17: Subtotal | F17: =+F16 -> 6580.04 | G17: =+G16 -> 0 | H17: =+H16 -> 6580.04
A18: Legal | B18: Legal | C18: 01543356 | D18: 0000199577 | E18: BRACEWELL & GIULIANI LLP | F18: 1415.08 | H18: =+F18+G18 -> 1415.08 | J18: 2012 | K18: 9 | L18: 21521308 | M18: 8/31/2012
E19: Subtotal | F19: =+F18 -> 1415.08 | G19: =+G18 -> 0 | H19: =+H18 -> 1415.08
A20: Legal | B20: Legal | C20: 01549738 | D20: 0000199577 | E20: BRACEWELL & GIULIANI LLP | F20: 128 | H20: =+F20+G20 -> 128 | J20: 2012 | K20: 10 | L20: 21523732 | M20: 9/30/2012
E21: Subtotal | F21: =+F20 -> 128 | G21: =+G20 -> 0 | H21: =+H20 -> 128
E22: Total BRACEWELL & GIULIANI LLP | F22: =+F21+F19+F17+F15+F13+F11+F9 -> 82047.58 | G22: =+G21+G19+G17+G15+G13+G11+G9 -> 0 | H22: =+H21+H19+H17+H15+H13+H11+H9 -> 82047.58
A23: Total Legal | F23: =+F22 -> 82047.58 | G23: =+G22 -> 0 | H23: =+H22 -> 82047.58
A25: Employee Expense | B25: Meal - Business | C25: 01508982 | D25: 0000146747 | E25: JP MORGAN CHASE CORPORATE CARD ACTIVITY | F25: 55.48 | G25: 0 | H25: =+F25+G25 -> 55.48 | I25: WALKER, TERI L | J25: 2012 | K25: 4 | L25: 0000091005ER79 | M25: 4/23/2012
E26: Subtotal | F26: =+F25 -> 55.48 | G26: =+G25 -> 0 | H26: =+H25 -> 55.48
A27: Total Employee Expense | F27: =+F26 -> 55.48 | G27: =+G26 -> 0 | H27: =+H26 -> 55.48
A29: Grand Total - Docket 40261 | F29: =+F27+F22 -> 82103.06 | G29: =+G27+G22 -> 0 | H29: =+H27+H22 -> 82103.06
A33: Divisional Allocation
A34: Sum of Sum Amount | B34: Unit
B35: 119 | C35: 211 | E35: Grand Total
A36: Total | B36: 41051.53 | C36: 41051.53 | E36: =+C36+B36 -> 82103.06
A37: Rate Case Expense Divisional Split | B37: 0.5 | C37: 0.5

Sheet 2017 DCRF 47015
A1: AMERICAN ELECTRIC POWER TEXAS INC
A2: SUMMARY OF RATE CASE EXPENSES
A3: PUC DOCKET NO. 47015
A6: Category | B6: Desc | C6: Voucher | D6: Vendor | E6: Name | F6: Amount | G6: Adjustment | H6: Requested | I6: Emp. Name | J6: Year | K6: Period | L6: Invoice | M6: Invoice date
A7: Cities | B7: Intervenor | C7: 804669 | D7: 97118 | E7: MCALLEN, CITY OF | F7: 4239.96 | G7: 0 | H7: =+F7+G7 -> 4239.96 | J7: 2017 | K7: (06) Jun | L7: 4701597482378 | M7: 42873
A8: Cities | B8: Intervenor | C8: 807297 | D8: 97118 | E8: MCALLEN, CITY OF | F8: 7329.81 | G8: 0 | H8: =+F8+G8 -> 7329.81 | J8: 2017 | K8: (06) Jun | L8: 4701597483244 | M8: 42895
E9: Subtotal | F9: =+SUM(F7:F8) -> 11569.77 | G9: =+SUM(G7:G8) -> 0 | H9: =+SUM(H7:H8) -> 11569.77
A10: Cities | B10: Intervenor | C10: 812336 | D10: 97118 | E10: MCALLEN, CITY OF | F10: 814.5 | G10: 0 | H10: =+F10+G10 -> 814.5 | J10: 2017 | K10: (08) Aug | L10: 4701597484267 | M10: 42926
E11: Subtotal | F11: =+F10 -> 814.5 | G11: =+G10 -> 0 | H11: =+H10 -> 814.5
A12: Cities | B12: Intervenor | C12: 828777 | D12: 97118 | E12: MCALLEN, CITY OF | F12: 296 | G12: 0 | H12: =+F12+G12 -> 296 | J12: 2017 | K12: (10) Oct | L12: 4701597485160 | M12: 42961
E13: Subtotal | F13: =+F12 -> 296 | G13: =+G12 -> 0 | H13: =+H12 -> 296
E14: Total MCALLEN, CITY OF | F14: =+F13+F11+F9 -> 12680.27 | G14: =+G13+G11+G9 -> 0 | H14: =+H13+H11+H9 -> 12680.27
A15: Total Cities | F15: =+F14 -> 12680.27 | G15: =+G14 -> 0 | H15: =+H14 -> 12680.27
A17: Other | B17: Postage | C17: 178556 | D17: 109159 | E17: FEDEX | F17: 19.09 | G17: 0 | H17: =+F17+G17 -> 19.09 | J17: 2017 | K17: (04) Apr | L17: 576921009 | M17: 42838
A18: Other | B18: Postage | C18: 794435 | D18: 109159 | E18: FEDEX | F18: 4294.96 | G18: 0 | H18: =+F18+G18 -> 4294.96 | J18: 2017 | K18: (04) Apr | L18: 576154348 | M18: 42831
E19: Subtotal | F19: =+SUM(F17:F18) -> 4314.05 | G19: =+SUM(G17:G18) -> 0 | H19: =+SUM(H17:H18) -> 4314.05
E20: Total FEDEX | F20: =+F19 -> 4314.05 | G20: =+G19 -> 0 | H20: =+H19 -> 4314.05
A21: Total Other | F21: =+F20 -> 4314.05 | G21: =+G20 -> 0 | H21: =+H20 -> 4314.05
A23: Employee Expense | B23: Parking | C23: 2054773 | D23: 161803 | E23: BANK OF AMERICA | F23: 5 | G23: 0 | H23: =+F23+G23 -> 5 | I23: STEWIEN, CAROL J | J23: 2017 | K23: (03) Mar | L23: EX0000432404 | M23: 42817
A24: Employee Expense | B24: Personal Mileage | C24: 2062408 | D24: 93058 | E24: TOUNGATE, JAY E | F24: 251.45 | G24: 0 | H24: =+F24+G24 -> 251.45 | I24: TOUNGATE, JAY E | J24: 2017 | K24: (04) Apr | L24: EX0000438248 | M24: 42830
A25: Employee Expense | B25: Meal-Self | C25: 2062408 | D25: 93058 | E25: TOUNGATE, JAY E | F25: 24.16 | G25: 0 | H25: =+F25+G25 -> 24.16 | I25: TOUNGATE, JAY E | J25: 2017 | K25: (04) Apr | L25: EX0000438248 | M25: 42830
A26: Employee Expense | B26: Meal-Self | C26: 2062408 | D26: 93058 | E26: TOUNGATE, JAY E | F26: 12.5 | G26: 0 | H26: =+F26+G26 -> 12.5 | I26: TOUNGATE, JAY E | J26: 2017 | K26: (04) Apr | L26: EX0000438248 | M26: 42830
A27: Employee Expense | B27: Meal-Self | C27: 2062408 | D27: 93058 | E27: TOUNGATE, JAY E | F27: 10.7 | G27: 0 | H27: =+F27+G27 -> 10.7 | I27: TOUNGATE, JAY E | J27: 2017 | K27: (04) Apr | L27: EX0000438248 | M27: 42830
A28: Employee Expense | B28: Parking | C28: 2062409 | D28: 161803 | E28: BANK OF AMERICA | F28: 15 | G28: 0 | H28: =+F28+G28 -> 15 | I28: TOUNGATE, JAY E | J28: 2017 | K28: (04) Apr | L28: EX0000438248 | M28: 42830
A29: Employee Expense | B29: Parking | C29: 2062409 | D29: 161803 | E29: BANK OF AMERICA | F29: 5 | G29: 0 | H29: =+F29+G29 -> 5 | I29: TOUNGATE, JAY E | J29: 2017 | K29: (04) Apr | L29: EX0000438248 | M29: 42830
A30: Employee Expense | B30: Parking | C30: 2062409 | D30: 161803 | E30: BANK OF AMERICA | F30: 15 | G30: 0 | H30: =+F30+G30 -> 15 | I30: TOUNGATE, JAY E | J30: 2017 | K30: (04) Apr | L30: EX0000438248 | M30: 42830
A31: Employee Expense | B31: Parking | C31: 2062409 | D31: 161803 | E31: BANK OF AMERICA | F31: 5 | G31: 0 | H31: =+F31+G31 -> 5 | I31: TOUNGATE, JAY E | J31: 2017 | K31: (04) Apr | L31: EX0000438248 | M31: 42830
A32: Employee Expense | B32: Meal-Self | C32: 2062409 | D32: 161803 | E32: BANK OF AMERICA | F32: 22.35 | G32: 0 | H32: =+F32+G32 -> 22.35 | I32: TOUNGATE, JAY E | J32: 2017 | K32: (04) Apr | L32: EX0000438248 | M32: 42830
A33: Employee Expense | B33: Meal-Self | C33: 2062409 | D33: 161803 | E33: BANK OF AMERICA | F33: 6.48 | G33: 0 | H33: =+F33+G33 -> 6.48 | I33: TOUNGATE, JAY E | J33: 2017 | K33: (04) Apr | L33: EX0000438248 | M33: 42830
A34: Employee Expense | B34: Meal-Self | C34: 2062409 | D34: 161803 | E34: BANK OF AMERICA | F34: 18.64 | G34: 0 | H34: =+F34+G34 -> 18.64 | I34: TOUNGATE, JAY E | J34: 2017 | K34: (04) Apr | L34: EX0000438248 | M34: 42830
... A38: Employee Expense | B38: Meal-Self | C38: 2062409 | D38: 161803 | E38: BANK OF AMERICA | F38: 14.17 | G38: 0 | H38: =+F38+G38 -> 14.17 | I38: TOUNGATE, JAY E | J38: 2017 | K38: (04) Apr | L38: EX0000438248 | M38: 42830
E39: Subtotal | F39: =+SUM(F23:F38) -> 498.4 | G39: =+SUM(G23:G38) -> 0 | H39: =+SUM(H23:H38) -> 498.4
A41: Employee Expense | B41: Personal Mileage | C41: 2079293 | D41: 93058 | E41: TOUNGATE, JAY E | F41: 13.91 | G41: 0 | H41: =+F41+G41 -> 13.91 | I41: TOUNGATE, JAY E | J41: 2017 | K41: (05) May | L41: EX0000456925 | M41: 42873
A42: Employee Expense | B42: Personal Mileage | C42: 2079293 | D42: 93058 | E42: TOUNGATE, JAY E | F42: 13.91 | G42: 0 | H42: =+F42+G42 -> 13.91 | I42: TOUNGATE, JAY E | J42: 2017 | K42: (05) May | L42: EX0000456925 | M42: 42873
A43: Employee Expense | B43: Meal-Self | C43: 2079294 | D43: 161803 | E43: BANK OF AMERICA | F43: 13 | G43: 0 | H43: =+F43+G43 -> 13 | I43: TOUNGATE, JAY E | J43: 2017 | K43: (05) May | L43: EX0000456925 | M43: 42873
A44: Employee Expense | B44: Meal-Self | C44: 2079294 | D44: 161803 | E44: BANK OF AMERICA | F44: 20.27 | G44: 0 | H44: =+F44+G44 -> 20.27 | I44: TOUNGATE, JAY E | J44: 2017 | K44: (05) May | L44: EX0000456925 | M44: 42873
A45: Employee Expense | B45: Meal-Business | C45: 2079294 | D45: 161803 | E45: BANK OF AMERICA | F45: 55.65 | G45: 0 | H45: =+F45+G45 -> 55.65 | I45: TOUNGATE, JAY E | J45: 2017 | K45: (05) May | L45: EX0000456925 | M45: 42873
A46: Employee Expense | B46: Meal-Self | C46: 2079294 | D46: 161803 | E46: BANK OF AMERICA | F46: 26 | G46: 0 | H46: =+F46+G46 -> 26 | I46: TOUNGATE, JAY E | J46: 2017 | K46: (05) May | L46: EX0000456925 | M46: 42873
A47: Employee Expense | B47: Meal-Self | C47: 2079294 | D47: 161803 | E47: BANK OF AMERICA | F47: 9.06 | G47: 0 | H47: =+F47+G47 -> 9.06 | I47: TOUNGATE, JAY E | J47: 2017 | K47: (05) May | L47: EX0000456925 | M47: 42873
A48: Employee Expense | B48: Meal-Self | C48: 2079294 | D48: 161803 | E48: BANK OF AMERICA | F48: 16.78 | G48: 0 | H48: =+F48+G48 -> 16.78 | I48: TOUNGATE, JAY E | J48: 2017 | K48: (05) May | L48: EX0000456925 | M48: 42873
...

Sheet 2018 DCRF 48222 
A1: AMERICAN ELECTRIC POWER TEXAS INC
A2: SUMMARY OF RATE CASE EXPENSES
A3: PUC DOCKET NO. 48222
A6: Category | B6: Desc | C6: Voucher | D6: Vendor | E6: Name | F6: Amount | G6: Adjustment | H6: Requested | I6: Emp. Name | J6: Year | K6: Period | L6: Invoice | M6: Invoice Date
A7: Cities | B7: Intervenor | C7: 00891815 | D7: 0000097118 | E7: MCALLEN, CITY OF | F7: 5660.6 | G7: 0 | H7: =+F7+G7 -> 5660.6 | J7: 2018 | K7: 9 | L7: 97491936DKT48222 | M7: 43230
A8: Cities | B8: Intervenor | C8: 00891816 | D8: 0000097118 | E8: MCALLEN, CITY OF | F8: 17041 | G8: 0 | H8: =+F8+G8 -> 17041 | J8: 2018 | K8: 9 | L8: 97492334DKT48222 | M8: 43263
A9: Cities | B9: Intervenor | C9: 00891817 | D9: 0000097118 | E9: MCALLEN, CITY OF | F9: 175 | G9: 0 | H9: =+F9+G9 -> 175 | J9: 2018 | K9: 9 | L9: 97494170DKT48222 | M9: 43320
A10: Cities | B10: Intervenor | C10: 00891818 | D10: 0000097118 | E10: MCALLEN, CITY OF | F10: 313.5 | G10: 0 | H10: =+F10+G10 -> 313.5 | J10: 2018 | K10: 9 | L10: 97494843DKT48222 | M10: 43354
A11: Cities | B11: Intervenor | C11: 00891819 | D11: 0000097118 | E11: MCALLEN, CITY OF | F11: 743 | G11: 0 | H11: =+F11+G11 -> 743 | J11: 2018 | K11: 9 | L11: 97494955DKT48222 | M11: 43344
E12: Subtotal | F12: =+SUM(F7:F11) -> 23933.1 | G12: =+SUM(G7:G11) -> 0 | H12: =+SUM(H7:H11) -> 23933.1
A13: Cities | B13: Intervenor | C13: 00895179 | D13: 0000097118 | E13: MCALLEN, CITY OF | F13: 358.75 | G13: 0 | H13: =+F13+G13 -> 358.75 | J13: 2018 | K13: 10 | L13: 0000106587EX0000683369 | M13: 43377
A14: Cities | B14: Intervenor | C14: 00895179 | D14: 0000097118 | E14: MCALLEN, CITY OF | F14: 29.6 | G14: 0 | H14: =+F14+G14 -> 29.6 | J14: 2018 | K14: 10 | L14: 0000106587EX0000683369 | M14: 43377
E15: Subtotal | F15: =+SUM(F13:F14) -> 388.35 | G15: =+SUM(G13:G14) -> 0 | H15: =+SUM(H13:H14) -> 388.35
E16: Total MCALLEN, CITY OF | F16: =+F15+F12 -> 24321.45 | G16: =+G15+G12 -> 0 | H16: =+H15+H12 -> 24321.45
A17: Total Cities | F17: =+F16 -> 24321.45 | G17: =+G16 -> 0 | H17: =+H16 -> 24321.45
A19: Other | B19: Temporary Employees | C19: 2215275 | D19: 164567 | E19: ROBERT HALF TECHNOLOGY | F19: 247.1 | G19: 0 | H19: =+F19+G19 -> 247.1 | J19: 2018 | K19: (04) Apr | L19: AEPIN00126670 | M19: 43199
E20: Subtotal | F20: =+F19 -> 247.1 | G20: =+G19 -> 0 | H20: =+H19 -> 247.1
A21: Other | B21: Temporary Employees | C21: 2230324 | D21: 164567 | E21: ROBERT HALF TECHNOLOGY | F21: 49.42 | G21: 0 | H21: =+F21+G21 -> 49.42 | J21: 2018 | K21: (05) May | L21: AEPIN00130429 | M21: 43220
E22: Subtotal | F22: =+F21 -> 49.42 | G22: =+G21 -> 0 | H22: =+H21 -> 49.42
A23: Other | B23: Temporary Employees | C23: 2278581 | D23: 164567 | E23: ROBERT HALF TECHNOLOGY | F23: 25.57 | G23: 0 | H23: =+F23+G23 -> 25.57 | J23: 2018 | K23: (08) Aug | L23: AEPIN00150177 | M23: 43336
E24: Subtotal | F24: =+F23 -> 25.57 | G24: =+G23 -> 0 | H24: =+H23 -> 25.57
E25: Total ROBERT HALF TECHNOLOGY | F25: =+F24+F22+F20 -> 322.09 | G25: =+G24+G22+G20 -> 0 | H25: =+H24+H22+H20 -> 322.09
A27: Other | B27: Postage | C27: 885914 | D27: 80046 | E27: US POSTAL SERVICE | F27: 50.16 | G27: 0 | H27: =+F27+G27 -> 50.16 | J27: 2018 | K27: (08) Aug | L27: 201802 | M27: 43329
E28: Subtotal | F28: =+F27 -> 50.16 | G28: =+G27 -> 0 | H28: =+H27 -> 50.16
E29: Total US POSTAL SERVICE | F29: =+F28 -> 50.16 | G29: =+G28 -> 0 | H29: =+H28 -> 50.16
A30: Total Other | F30: =+F29+F25 -> 372.25 | G30: =+G29+G25 -> 0 | H30: =+H29+H25 -> 372.25
A33: Employee Expense | B33: Office Supplies | C33: 854762 | D33: 161803 | E33: BANK OF AMERICA | F33: 180.79 | G33: 0 | H33: =+F33+G33 -> 180.79 | I33: GULLICKSON, GREGORY K | J33: 2018 | K33: (03) Mar | L33: EX0000590208 | M33: 43171
A34: Employee Expense | B34: Office Supplies | C34: 854857 | D34: 161803 | E34: BANK OF AMERICA | F34: 399.64 | G34: 0 | H34: =+F34+G34 -> 399.64 | I34: GULLICKSON, GREGORY K | J34: 2018 | K34: (03) Mar | L34: EX0000590211 | M34: 43171
A35: Employee Expense | B35: Office Supplies | C35: 856146 | D35: 161803 | E35: BANK OF AMERICA | F35: 342.55 | G35: 0 | H35: =+F35+G35 -> 342.55 | I35: GULLICKSON, GREGORY K | J35: 2018 | K35: (03) Mar | L35: EX0000591684 | M35: 43178
A36: Employee Expense | B36: Tax | C36: 858342 | D36: 161803 | E36: BANK OF AMERICA | F36: 204.52 | G36: 0 | H36: =+F36+G36 -> 204.52 | I36: GULLICKSON, GREGORY K | J36: 2018 | K36: (03) Mar | L36: EX0000598796 | M36: 43187
A37: Employee Expense | B37: Office Supplies | C37: 858342 | D37: 161803 | E37: BANK OF AMERICA | F37: 565 | G37: 0 | H37: =+F37+G37 -> 565 | I37: GULLICKSON, GREGORY K | J37: 2018 | K37: (03) Mar | L37: EX0000598796 | M37: 43187
A38: Employee Expense | B38: Office Supplies | C38: 858342 | D38: 161803 | E38: BANK OF AMERICA | F38: 1914 | G38: 0 | H38: =+F38+G38 -> 1914 | I38: GULLICKSON, GREGORY K | J38: 2018 | K38: (03) Mar | L38: EX0000598796 | M38: 43187
E39: Subtotal | F39: =+SUM(F33:F38) -> 3606.5 | G39: =+SUM(G33:G38) -> 0 | H39: =+SUM(H33:H38) -> 3606.5
A40: Employee Expense | B40: Meal-Business | C40: 862052 | D40: 161803 | E40: BANK OF AMERICA | F40: 57.23 | G40: 0 | H40: =+F40+G40 -> 57.23 | I40: BEATY, STEVEN J | J40: 2018 | K40: (04) Apr | L40: EX0000608540 | M40: 43209
A41: Employee Expense | B41: Postage | C41: 862960 | D41: 161803 | E41: BANK OF AMERICA | F41: 19 | G41: 0 | H41: =+F41+G41 -> 19 | I41: GULLICKSON, GREGORY K | J41: 2018 | K41: (04) Apr | L41: EX0000610656 | M41: 43215
A42: Employee Expense | B42: Postage | C42: 862960 | D42: 161803 | E42: BANK OF AMERICA | F42: 12.72 | G42: 0 | H42: =+F42+G42 -> 12.72 | I42: GULLICKSON, GREGORY K | J42: 2018 | K42: (04) Apr | L42: EX0000610656 | M42: 43215
E43: Subtotal | F43: =+SUM(F40:F42) -> 88.95 | G43: =+SUM(G40:G42) -> 0 | H43: =+SUM(H40:H42) -> 88.95
A44: Employee Expense | B44: Meal-Business | C44: 868015 | D44: 161803 | E44: BANK OF AMERICA | F44: 61.91 | G44: 0 | H44: =+F44+G44 -> 61.91 | I44: BEATY, STEVEN J | J44: 2018 | K44: (05) May | L44: EX0000623604 | M44: 43242
A45: Employee Expense | B45: Meal-Business | C45: 868015 | D45: 161803 | E45: BANK OF AMERICA | F45: 57.9 | G45: 0 | H45: =+F45+G45 -> 57.9 | I45: BEATY, STEVEN J | J45: 2018 | K45: (05) May | L45: EX0000623604 | M45: 43242
A46: Employee Expense | B46: Meal-Self | C46: 2227859 | D46: 161803 | E46: BANK OF AMERICA | F46: 19 | G46: 0 | H46: =+F46+G46 -> 19 | I46: KIMANI, PETER K | J46: 2018 | K46: (05) May | L46: EX0000620517 | M46: 43235
...

Sheet Docket 48577 
A1: AMERICAN ELECTRIC POWER TEXAS INC
A2: SUMMARY OF RATE CASE EXPENSES
A3: PUC DOCKET NO. 48577
A6: Category | B6: Desc | C6: Voucher | D6: Vendor | E6: Name | F6: Amount | G6: Adjustment | H6: Requested | I6: Employee | J6: Year | K6: Period | L6: Invoice | M6: Invoice Date
A7: Consultant | B7: Prof. Services | C7: 282134 | D7: 26132 | E7: FINANCO INC | F7: 2400 | G7: 0 | H7: 2400 | J7: 2017 | K7: (11) Nov | L7: 4013 | M7: 43008
E8: Subtotal | F8: =+F7 -> 2400 | G8: =+G7 -> 0 | H8: =+H7 -> 2400
E9: Total FINANCO INC | F9: =+F8 -> 2400 | G9: =+G8 -> 0 | H9: =+H8 -> 2400
A10: Total Consultant | F10: =+F9 -> 2400 | G10: =+G9 -> 0 | H10: =+H9 -> 2400
A13: Legal | B13: Legal | C13: 844337 | D13: 256019 | E13: DUGGINS WREN MANN & ROMERO LLP | F13: 26299.81 | G13: 0 | H13: =+F13+G13 -> 26299.81 | J13: 2018 | K13: (01) Jan | L13: 27422 | M13: 43111
E14: Subtotal | F14: =+F13 -> 26299.81 | G14: =+G13 -> 0 | H14: =+H13 -> 26299.81
A15: Legal | B15: Legal | C15: 850306 | D15: 256019 | E15: DUGGINS WREN MANN & ROMERO LLP | F15: 37698.17 | G15: 0 | H15: =+F15+G15 -> 37698.17 | J15: 2018 | K15: (02) Feb | L15: 27636 | M15: 43143
E16: Subtotal | F16: =+F15 -> 37698.17 | G16: =+G15 -> 0 | H16: =+H15 -> 37698.17
A17: Legal | B17: Legal | C17: 856698 | D17: 256019 | E17: DUGGINS WREN MANN & ROMERO LLP | F17: 25392.28 | G17: 0 | H17: =+F17+G17 -> 25392.28 | J17: 2018 | K17: (03) Mar | L17: 27881 | M17: 43173
E18: Subtotal | F18: =+F17 -> 25392.28 | G18: =+G17 -> 0 | H18: =+H17 -> 25392.28
A19: Legal | B19: Legal | C19: 860826 | D19: 256019 | E19: DUGGINS WREN MANN & ROMERO LLP | F19: 3039.73 | G19: 0 | H19: =+F19+G19 -> 3039.73 | J19: 2018 | K19: (04) Apr | L19: 28025 | M19: 43196
E20: Subtotal | F20: =+F19 -> 3039.73 | G20: =+G19 -> 0 | H20: =+H19 -> 3039.73
A21: Legal | B21: Legal | C21: 866372 | D21: 256019 | E21: DUGGINS WREN MANN & ROMERO LLP | F21: 9147.55 | G21: 0 | H21: =+F21+G21 -> 9147.55 | J21: 2018 | K21: (05) May | L21: 28280 | M21: 43230
E22: Subtotal | F22: =+F21 -> 9147.55 | G22: =+G21 -> 0 | H22: =+H21 -> 9147.55
A23: Legal | B23: Legal | C23: 872909 | D23: 256019 | E23: DUGGINS WREN MANN & ROMERO LLP | F23: 2592.55 | G23: 0 | H23: =+F23+G23 -> 2592.55 | J23: 2018 | K23: (06) Jun | L23: 28516 | M23: 43263
E24: Subtotal | F24: =+F23 -> 2592.55 | G24: =+G23 -> 0 | H24: =+H23 -> 2592.55
A25: Legal | B25: Legal | C25: 878991 | D25: 256019 | E25: DUGGINS WREN MANN & ROMERO LLP | F25: 30811.33 | G25: 0 | H25: =+F25+G25 -> 30811.33 | J25: 2018 | K25: (07) Jul | L25: 28752 | M25: 43291
A26: Legal | B26: Legal | C26: 878992 | D26: 256019 | E26: DUGGINS WREN MANN & ROMERO LLP | F26: 225.15 | G26: 0 | H26: =+F26+G26 -> 225.15 | J26: 2018 | K26: (07) Jul | L26: 28753 | M26: 43291
E27: Subtotal | F27: =+F26+F25 -> 31036.48 | G27: =+G26+G25 -> 0 | H27: =+H26+H25 -> 31036.48
A28: Legal | B28: Legal | C28: 884858 | D28: 256019 | E28: DUGGINS WREN MANN & ROMERO LLP | F28: 36165.13 | G28: 0 | H28: =+F28+G28 -> 36165.13 | J28: 2018 | K28: (08) Aug | L28: 29038 | M28: 43321
E29: Subtotal | F29: =+F28 -> 36165.13 | G29: =+G28 -> 0 | H29: =+H28 -> 36165.13
A30: Legal | B30: Legal | C30: 891475 | D30: 256019 | E30: DUGGINS WREN MANN & ROMERO LLP | F30: 38537.33 | G30: 0 | H30: =+F30+G30 -> 38537.33 | J30: 2018 | K30: (09) Sep | L30: 29329 | M30: 43356
E31: Subtotal | F31: =+F30 -> 38537.33 | G31: =+G30 -> 0 | H31: =+H30 -> 38537.33
A32: Legal | B32: Legal | C32: 896878 | D32: 256019 | E32: DUGGINS WREN MANN & ROMERO LLP | F32: 3511.21 | G32: 0 | H32: =+F32+G32 -> 3511.21 | J32: 2018 | K32: (10) Oct | L32: 29525 | M32: 43384
E33: Subtotal | F33: =+F32 -> 3511.21 | G33: =+G32 -> 0 | H33: =+H32 -> 3511.21
A34: Legal | B34: Legal | C34: 907606 | D34: 256019 | E34: DUGGINS WREN MANN & ROMERO LLP | F34: 31734.05 | G34: 0 | H34: =+F34+G34 -> 31734.05 | J34: 2018 | K34: (12) Dec | L34: 29524 | M34: 43384
A35: Legal | B35: Legal | C35: 908014 | D35: 256019 | E35: DUGGINS WREN MANN & ROMERO LLP | F35: 18588.84 | G35: 0 | H35: =+F35+G35 -> 18588.84 | J35: 2018 | K35: (12) Dec | L35: 29754 | M35: 43416
A36: Legal | B36: Legal | C36: 908364 | D36: 256019 | E36: DUGGINS WREN MANN & ROMERO LLP | F36: 17068.73 | G36: 0 | H36: =+F36+G36 -> 17068.73 | J36: 2018 | K36: (12) Dec | L36: 29753 | M36: 43416
A37: Legal | B37: Legal | C37: 910274 | D37: 256019 | E37: DUGGINS WREN MANN & ROMERO LLP | F37: 16101.54 | G37: 0 | H37: =+F37+G37 -> 16101.54 | J37: 2018 | K37: (12) Dec | L37: 29978 | M37: 43440
A38: Legal | B38: Legal | C38: 911224 | D38: 256019 | E38: DUGGINS WREN MANN & ROMERO LLP | F38: 10251.91 | G38: 0 | H38: =+F38+G38 -> 10251.91 | J38: 2018 | K38: (12) Dec | L38: 29977 | M38: 43440
E39: Subtotal | F39: =+SUM(F34:F38) -> 93745.07 | G39: =+SUM(G34:G38) -> 0 | H39: =+SUM(H34:H38) -> 93745.07
A40: Legal | B40: Legal | C40: 916059 | D40: 256019 | E40: DUGGINS WREN MANN & ROMERO LLP | F40: 726.79 | G40: 0 | H40: 726.79 | J40: 2019 | K40: (01) Jan | L40: 30257 | M40: 43476
A41: Legal | B41: Legal | C41: 916060 | D41: 256019 | E41: DUGGINS WREN MANN & ROMERO LLP | F41: 28173.42 | G41: 0 | H41: 28173.42 | J41: 2019 | K41: (01) Jan | L41: 30258 | M41: 43476
E42: Subtotal | F42: =+SUM(F40:F41) -> 28900.21 | G42: =+SUM(G40:G41) -> 0 | H42: =+SUM(H40:H41) -> 28900.21
A43: Legal | B43: Legal | C43: 921399 | D43: 256019 | E43: DUGGINS WREN MANN & ROMERO LLP | F43: 30168 | G43: 0 | H43: =+F43+G43 -> 30168 | J43: 2019 | K43: (02) Feb | L43: 30507 | M43: 43508
A44: Legal | B44: Legal | C44: 921995 | D44: 256019 | E44: DUGGINS WREN MANN & ROMERO LLP | F44: 164 | G44: 0 | H44: =+F44+G44 -> 164 | J44: 2019 | K44: (02) Feb | L44: 30506 | M44: 43508
...

Sheet Trailing Charges Central
A1: AMERICAN ELECTRIC POWER TEXAS INC
A2: SUMMARY OF RATE CASE EXPENSES
A3: PUC DOCKET NOS. 28840/33309 (CENTRAL)
A7: Category | B7: Descr | C7: Voucher | D7: Vendor | E7: Name | F7: Amount | G7: Adjustment | H7: Total | I7: Central Division Requested | J7: Central % | K7: Employee Name | L7: Year | M7: Period | N7: Invoice | O7: Invoice Date
A8: Cities | B8: Cities | C8: 01064000 | D8: 0000097118 | E8: MCALLEN, CITY OF | F8: 172 | G8: 0 | H8: =+F8+G8 -> 172 | I8: =+H8 -> 172 | J8: =+I8/H8 -> 1 | L8: 2008 | M8: 4 | N8: 33309FEB2008 | O8: 39545
A9: Cities | B9: Cities | C9: 01064008 | D9: 0000097118 | E9: MCALLEN, CITY OF | F9: 710.5 | G9: 0 | H9: =+F9+G9 -> 710.5 | I9: =+H9 -> 710.5 | J9: =+I9/H9 -> 1 | L9: 2008 | M9: 4 | N9: 33309 | O9: 39545
A10: Cities | B10: Cities | C10: 01066033 | D10: 0000097118 | E10: MCALLEN, CITY OF | F10: 4283.46 | G10: 0 | H10: =+F10+G10 -> 4283.46 | I10: =+H10 -> 4283.46 | J10: =+I10/H10 -> 1 | L10: 2008 | M10: 4 | N10: 33309 | O10: 39545
A11: Cities | B11: Cities | C11: 01066711 | D11: 0000097118 | E11: MCALLEN, CITY OF | F11: 203 | G11: 0 | H11: =+F11+G11 -> 203 | I11: =+H11 -> 203 | J11: =+I11/H11 -> 1 | L11: 2008 | M11: 4 | N11: 33309 | O11: 39504
A12: Cities | B12: Cities | C12: 01059153 | D12: 0000097118 | E12: MCALLEN, CITY OF | F12: 29331.96 | G12: 0 | H12: =+F12+G12 -> 29331.96 | I12: =+H12 -> 29331.96 | J12: =+I12/H12 -> 1 | L12: 2008 | M12: 4 | N12: 33309 | O12: 39521
A13: Cities | B13: Cities | C13: 01063999 | D13: 0000097118 | E13: MCALLEN, CITY OF | F13: 23391.38 | G13: 0 | H13: =+F13+G13 -> 23391.38 | I13: =+H13 -> 23391.38 | J13: =+I13/H13 -> 1 | L13: 2008 | M13: 4 | N13: 33309DEC2007 | O13: 39545
E14: Subtotal | F14: =+SUM(F8:F13) -> 58092.3 | G14: =+SUM(G8:G13) -> 0 | H14: =+SUM(H8:H13) -> 58092.3 | I14: =+SUM(I8:I13) -> 58092.3
A15: Cities | B15: Cities | C15: 01079391 | D15: 0000097118 | E15: MCALLEN, CITY OF | F15: 7111 | G15: 0 | H15: =+F15+G15 -> 7111 | I15: =+H15 -> 7111 | J15: =+I15/H15 -> 1 | L15: 2008 | M15: 5 | N15: 35915 | O15: 39580
E16: Subtotal | F16: =+F15 -> 7111 | G16: =+G15 -> 0 | H16: =+H15 -> 7111 | I16: =+I15 -> 7111
A17: Cities | B17: Cities | C17: 01091323 | D17: 0000097118 | E17: MCALLEN, CITY OF | F17: 7535.9 | G17: 0 | H17: =+F17+G17 -> 7535.9 | I17: =+H17 -> 7535.9 | J17: =+I17/H17 -> 1 | L17: 2008 | M17: 6 | N17: 36251 | O17: 39610
E18: Subtotal | F18: =+F17 -> 7535.9 | G18: =+G17 -> 0 | H18: =+H17 -> 7535.9 | I18: =+I17 -> 7535.9
A19: Cities | B19: Cities | C19: 01111817 | D19: 0000097118 | E19: MCALLEN, CITY OF | F19: 2266.6 | G19: 0 | H19: =+F19+G19 -> 2266.6 | I19: =+H19 -> 2266.6 | J19: =+I19/H19 -> 1 | L19: 2008 | M19: 8 | N19: 3330936553 | O19: 39626
A20: Cities | B20: Cities | C20: 01103762 | D20: 0000097118 | E20: MCALLEN, CITY OF | F20: 23391.38 | G20: 0 | H20: =+F20+G20 -> 23391.38 | I20: =+H20 -> 23391.38 | J20: =+I20/H20 -> 1 | L20: 2008 | M20: 8 | N20: 3330934911 | O20: 39545
E21: Subtotal | F21: =+F20+F19 -> 25657.98 | G21: =+G20+G19 -> 0 | H21: =+H20+H19 -> 25657.98 | I21: =+I20+I19 -> 25657.98
A22: Cities | B22: Cities | C22: 01119115 | D22: 0000097118 | E22: MCALLEN, CITY OF | F22: 1371.85 | G22: 0 | H22: =+F22+G22 -> 1371.85 | I22: =+H22 -> 1371.85 | J22: =+I22/H22 -> 1 | L22: 2008 | M22: 9 | N22: 3330936984 | O22: 39675
E23: Subtotal | F23: =+F22 -> 1371.85 | G23: =+G22 -> 0 | H23: =+H22 -> 1371.85 | I23: =+I22 -> 1371.85
A24: Cities | B24: Cities | C24: 01130842 | D24: 0000097118 | E24: MCALLEN, CITY OF | F24: 8434.58 | G24: 0 | H24: =+F24+G24 -> 8434.58 | I24: =+H24 -> 8434.58 | J24: =+I24/H24 -> 1 | L24: 2008 | M24: 10 | N24: 33309 | O24: 39713
E25: Subtotal | F25: =+F24 -> 8434.58 | G25: =+G24 -> 0 | H25: =+H24 -> 8434.58 | I25: =+I24 -> 8434.58
A26: Cities | B26: Cities | C26: 01151450 | D26: 0000097118 | E26: MCALLEN, CITY OF | F26: 789.79 | G26: 0 | H26: =+F26+G26 -> 789.79 | I26: =+H26 -> 789.79 | J26: =+I26/H26 -> 1 | L26: 2008 | M26: 12 | N26: 33309 | O26: 39773
E27: Subtotal | F27: =+F26 -> 789.79 | G27: =+G26 -> 0 | H27: =+H26 -> 789.79 | I27: =+I26 -> 789.79
A28: Cities | B28: Cities | C28: 01167304 | D28: 0000097118 | E28: MCALLEN, CITY OF | F28: 25394.37 | G28: 0 | H28: =+F28+G28 -> 25394.37 | I28: =+H28 -> 25394.37 | J28: =+I28/H28 -> 1 | L28: 2009 | M28: 1 | N28: 3330938672 | O28: 39822
A29: Cities | B29: Cities | C29: 01167301 | D29: 0000097118 | E29: MCALLEN, CITY OF | F29: 24209.3 | G29: 0 | H29: =+F29+G29 -> 24209.3 | I29: =+H29 -> 24209.3 | J29: =+I29/H29 -> 1 | L29: 2009 | M29: 1 | N29: 3330938484 | O29: 39794
E30: Subtotal | F30: =+F29+F28 -> 49603.67 | G30: =+G29+G28 -> 0 | H30: =+H29+H28 -> 49603.67 | I30: =+I29+I28 -> 49603.67
A31: Cities | B31: Cities | C31: 01177712 | D31: 0000097118 | E31: MCALLEN, CITY OF | F31: 16687.22 | G31: 0 | H31: =+F31+G31 -> 16687.22 | I31: =+H31 -> 16687.22 | J31: =+I31/H31 -> 1 | L31: 2009 | M31: 3 | N31: 33309 | O31: 39840
E32: Subtotal | F32: =+F31 -> 16687.22 | G32: =+G31 -> 0 | H32: =+H31 -> 16687.22 | I32: =+I31 -> 16687.22
A33: Cities | B33: Cities | C33: 01195228 | D33: 0000097118 | E33: MCALLEN, CITY OF | F33: 2127.9 | G33: 0 | H33: =+F33+G33 -> 2127.9 | I33: =+H33 -> 2127.9 | J33: =+I33/H33 -> 1 | L33: 2009 | M33: 4 | N33: 39893 | O33: 39884
A34: Cities | B34: Cities | C34: 01195227 | D34: 0000097118 | E34: MCALLEN, CITY OF | F34: 1067.25 | G34: 0 | H34: =+F34+G34 -> 1067.25 | I34: =+H34 -> 1067.25 | J34: =+I34/H34 -> 1 | L34: 2009 | M34: 4 | N34: 33309 | O34: 39869
E35: Subtotal | F35: =+F34+F33 -> 3195.15 | G35: =+G34+G33 -> 0 | H35: =+H34+H33 -> 3195.15 | I35: =+I34+I33 -> 3195.15
A36: Cities | B36: Cities | C36: 01200359 | D36: 0000097118 | E36: MCALLEN, CITY OF | F36: 703.5 | G36: 0 | H36: =+F36+G36 -> 703.5 | I36: =+H36 -> 703.5 | J36: =+I36/H36 -> 1 | L36: 2009 | M36: 5 | N36: 28840 | O36: 39798
A37: Cities | B37: Cities | C37: 01200360 | D37: 0000097118 | E37: MCALLEN, CITY OF | F37: 1962.96 | G37: 0 | H37: =+F37+G37 -> 1962.96 | I37: =+H37 -> 1962.96 | J37: =+I37/H37 -> 1 | L37: 2009 | M37: 5 | N37: 28840 | O37: 39610
A38: Cities | B38: Cities | C38: 01200361 | D38: 0000097118 | E38: MCALLEN, CITY OF | F38: 1526.81 | G38: 0 | H38: =+F38+G38 -> 1526.81 | I38: =+H38 -> 1526.81 | J38: =+I38/H38 -> 1 | L38: 2009 | M38: 5 | N38: 28840 | O38: 39580
A39: Cities | B39: Cities | C39: 01200358 | D39: 0000097118 | E39: MCALLEN, CITY OF | F39: 478.5 | G39: 0 | H39: =+F39+G39 -> 478.5 | I39: =+H39 -> 478.5 | J39: =+I39/H39 -> 1 | L39: 2009 | M39: 5 | N39: 28840 | O39: 39840
A40: Cities | B40: Cities | C40: 01200357 | D40: 0000097118 | E40: MCALLEN, CITY OF | F40: 4103.15 | G40: 0 | H40: =+F40+G40 -> 4103.15 | I40: =+H40 -> 4103.15 | J40: =+I40/H40 -> 1 | L40: 2009 | M40: 5 | N40: 33309 | O40: 39932
A41: Cities | B41: Cities | C41: 01197060 | D41: 0000097118 | E41: MCALLEN, CITY OF | F41: 9784.65 | G41: 0 | H41: =+F41+G41 -> 9784.65 | I41: =+H41 -> 9784.65 | J41: =+I41/H41 -> 1 | L41: 2009 | M41: 5 | N41: 3330937703 | O41: 39918
E42: Subtotal | F42: =+SUM(F36:F41) -> 18559.57 | G42: =+SUM(G36:G41) -> 0 | H42: =+SUM(H36:H41) -> 18559.57 | I42: =+SUM(I36:I41) -> 18559.57
A43: Cities | B43: Cities | C43: 01215483 | D43: 0000097118 | E43: MCALLEN, CITY OF | F43: 1067.97 | G43: 0 | H43: =+F43+G43 -> 1067.97 | I43: =+H43 -> 1067.97 | J43: =+I43/H43 -> 1 | L43: 2009 | M43: 7 | N43: 33309 | O43: 39988
...

Sheet Trailing Charges North
A1: AMERICAN ELECTRIC POWER TEXAS INC
A2: SUMMARY OF RATE CASE EXPENSES
A3: PUC DOCKET NO. 33310 (NORTH)
A8: Category | B8: Descr | C8: Voucher | D8: Vendor | E8: Name | F8: Amount | G8: Adjustment | H8: Total | I8: North Division Requested | J8: North % | K8: Employee Name | L8: Year | M8: Period | N8: Invoice | O8: Invoice Date
A9: Cities | B9: Cities | C9: 01087298 | D9: 0000097098 | E9: ABILENE, CITY OF | F9: 273.5 | G9: 0 | H9: =+F9+G9 -> 273.5 | I9: =+H9 -> 273.5 | J9: =+I9/H9 -> 1 | L9: 2008 | M9: 6 | N9: 3331035913 | O9: 39575
A10: Cities | B10: Cities | C10: 01091322 | D10: 0000097098 | E10: ABILENE, CITY OF | F10: 633.64 | G10: 0 | H10: =+F10+G10 -> 633.64 | I10: =+H10 -> 633.64 | J10: =+I10/H10 -> 1 | L10: 2008 | M10: 6 | N10: 33310 | O10: 39617
E11: Subtotal | F11: =+F10+F9 -> 907.14 | G11: =+G10+G9 -> 0 | H11: =+H10+H9 -> 907.14 | I11: =+I10+I9 -> 907.14
A12: Cities | B12: Cities | C12: 01104330 | D12: 0000097098 | E12: ABILENE, CITY OF | F12: 29 | G12: 0 | H12: =+F12+G12 -> 29 | I12: =+G12+H12 -> 29 | J12: =+I12/H12 -> 1 | L12: 2008 | M12: 8 | N12: 3331036540 | O12: 39626
E13: Subtotal | F13: =+F12 -> 29 | G13: =+G12 -> 0 | H13: =+H12 -> 29 | I13: =+H13 -> 29
A14: Cities | B14: Cities | C14: 01151452 | D14: 0000097098 | E14: ABILENE, CITY OF | F14: 158.5 | G14: 0 | H14: =+F14+G14 -> 158.5 | I14: =+G14+H14 -> 158.5 | J14: =+I14/H14 -> 1 | L14: 2008 | M14: 12 | N14: 35913 | O14: 39778
E15: Subtotal | F15: =+F14 -> 158.5 | G15: =+G14 -> 0 | H15: =+H14 -> 158.5 | I15: =+I14 -> 158.5
E16: Total ABILENE, CITY OF | F16: =+F15+F13+F11 -> 1094.64 | G16: =+G15+G13+G11 -> 0 | H16: =+H15+H13+H11 -> 1094.64 | I16: =+I15+I13+I11 -> 1094.64
A17: Total Cities | F17: =+F16 -> 1094.64 | G17: =+G16 -> 0 | H17: =+H16 -> 1094.64 | I17: =+I16 -> 1094.64
A19: Legal | B19: Legal | C19: 01045580 | D19: 0000001353 | E19: CLARK THOMAS & WINTERS | F19: 294.5 | G19: 0 | H19: =+F19+G19 -> 294.5 | I19: 66.05 | J19: =+I19/H19 -> 0.22427844 | L19: 2008 | M19: 2 | N19: 147354 | O19: 39500
E20: Subtotal | F20: =+F19 -> 294.5 | G20: =+G19 -> 0 | H20: =+H19 -> 294.5 | I20: =+I19 -> 66.05
A21: Legal | B21: Legal | C21: 01054347 | D21: 0000001353 | E21: CLARK THOMAS & WINTERS | F21: 18 | G21: 0 | H21: =+F21+G21 -> 18 | I21: 4.04 | J21: =+I21/H21 -> 0.22444444 | L21: 2008 | M21: 3 | N21: 147958 | O21: 39524
E22: Subtotal | F22: =+F21 -> 18 | G22: =+G21 -> 0 | H22: =+H21 -> 18 | I22: =+I21 -> 4.04
A23: Legal | B23: Legal | C23: 01064198 | D23: 0000001353 | E23: CLARK THOMAS & WINTERS | F23: 4943.29 | G23: 0 | H23: =+F23+G23 -> 4943.29 | I23: 1111.37 | J23: =+I23/H23 -> 0.22482395 | L23: 2008 | M23: 4 | N23: 149417 | O23: 39552
E24: Subtotal | F24: =+F23 -> 4943.29 | G24: =+G23 -> 0 | H24: =+H23 -> 4943.29 | I24: =+I23 -> 1111.37
A25: Legal | B25: Legal | C25: 01079983 | D25: 0000001353 | E25: CLARK THOMAS & WINTERS | F25: 1991.33 | G25: 0 | H25: =+F25+G25 -> 1991.33 | I25: 447.7 | J25: =+I25/H25 -> 0.22482461 | L25: 2008 | M25: 5 | N25: 151472 | O25: 39591
E26: Subtotal | F26: =+F25 -> 1991.33 | G26: =+G25 -> 0 | H26: =+H25 -> 1991.33 | I26: =+I25 -> 447.7
A27: Legal | B27: Legal | C27: 01089740 | D27: 0000001353 | E27: CLARK THOMAS & WINTERS | F27: 873 | G27: 0 | H27: =+F27+G27 -> 873 | I27: 198.04 | J27: =+I27/H27 -> 0.22684994 | L27: 2008 | M27: 6 | N27: 152844 | O27: 39622
E28: Subtotal | F28: =+F27 -> 873 | G28: =+G27 -> 0 | H28: =+H27 -> 873 | I28: =+I27 -> 198.04
E29: Total CLARK THOMAS & WINTERS | F29: =+F28+F26+F24+F22+F20 -> 8120.12 | G29: =+G28+G26+G24+G22+G20 -> 0 | H29: =+H28+H26+H24+H22+H20 -> 8120.12 | I29: =+I28+I26+I24+I22+I20 -> 1827.2
A30: Total Legal | F30: =+F29 -> 8120.12 | G30: =+G29 -> 0 | H30: =+H29 -> 8120.12 | I30: =+I29 -> 1827.2
A32: Grand Total- North Trailing Charges Docket Nos. 31433/33310/34310 | F32: =+F30+F17 -> 9214.76 | G32: =+G30+G17 -> 0 | H32: =+H30+H17 -> 9214.76 | I32: =+I30+I17 -> 2921.84
