Workbook
Name a: #REF!
Name a: #REF!
Name page1: #REF!
Name page10: #REF!
Name page2: #REF!
Name page3: #REF!
Name page4: #REF!
Name page5: #REF!
Name page6: #REF!
Name page7: #REF!
Name page8: #REF!
Name page9: #REF!
Name q: [2]Summary!#REF!
Name q: [2]Summary!#REF!
Name ResBasic: [3]Summary!#REF!
Name ResBasic: [3]Summary!#REF!
Name ResEconomy1: [3]Summary!#REF!
Name ResEconomy1: [3]Summary!#REF!
Name ResEconomy2: [3]Summary!#REF!
Name ResEconomy2: [3]Summary!#REF!
Name ResWaterHeating: [3]Summary!#REF!
Name ResWaterHeating: [3]Summary!#REF!
Name test: [2]Summary!#REF!
Name test: [2]Summary!#REF!
Name test1: [2]Summary!#REF!
Name test1: [2]Summary!#REF!
Name total: #REF!
Name w: [2]Summary!#REF!
Name w: [2]Summary!#REF!

Sheet II-H-1
B2: PUBLIC UTILITY COMMISSION OF TEXAS
B3: AEP TEXAS INC
B4: II-H-1 SUMMARY OF TEST YEAR ADJUSTMENTS
B5: TEST YEAR ENDING 12/31/2018
B6: DOCKET NUMBER (PENDING ASSIGNMENT)
B9: Refer to Schedule II-H-1.1 for the summary of test year adjustments

Sheet II-H-1.1
B2: PUBLIC UTILITY COMMISSION OF TEXAS
B3: AEP TEXAS INC
B4: II-H-1.1 TEST YEAR SALES DATA
B5: TEST YEAR ENDING 12/31/2018
B6: DOCKET NUMBER (PENDING ASSIGNMENT)
A8: AEP TEXAS
A9: TEST YEAR DATA BY RATE CLASS
A10: FOR TEST YEAR ENDED DECEMBER 31, 2018
D12: Average | E12: Year-end | F12: Unadjusted | G12: Weather kWh | H12: Customer kWh | I12: Other kWh | J12: Adjusted
A13: LINE | B13: DESCRIPTION | C13: VOLT | D13: Customers | E13: Customers | F13: kWh at Meter | G13: Adjustment | H13: Adjustment | I13: Adjustment | J13: kWh
A15: 1 | B15: RESIDENTIAL SERVICE | C15: SEC | D15: ='II-H-3.1-3'!Q14 -> 871709.17 | E15: ='II-H-3.1-3'!O14 -> 876553 | F15: ='II-H-1.2'!P14 -> 12103111472 | G15: ='II-H-1.2'!P44 -> -169072907 | H15: ='II-H-1.2'!P74 -> 63143017 | I15: ='II-H-1.2'!P106 -> 0 | J15: ='II-H-1.2'!P136 -> 1.1997182e+10
A17: 2 | B17: SECONDARY < 10 kW | C17: SEC | D17: ='II-H-3.1-3'!Q16 -> 89262.917 | E17: ='II-H-3.1-3'!O16 -> 89158 | F17: ='II-H-1.2'!P16 -> 580596232 | G17: ='II-H-1.2'!P46 -> -345003.32 | H17: ='II-H-1.2'!P76 -> -947844.49 | I17: ='II-H-1.2'!P108 -> 0 | J17: ='II-H-1.2'!P138 -> 5.7930338e+08
A19: 3 | B19: SECONDARY > 10 kW NCP | C19: SEC | D19: ='II-H-3.1-3'!Q18 -> 71945.25 | E19: ='II-H-3.1-3'!O18 -> 72592 | F19: ='II-H-1.2'!P18 -> 8003640659 | G19: ='II-H-1.2'!P48 -> -1982220.5 | H19: ='II-H-1.2'!P78 -> 68711313 | I19: ='II-H-1.2'!P110 -> 0 | J19: ='II-H-1.2'!P140 -> 8.0703698e+09
A20: 4 | B20: SECONDARY > 10 Kw 4CP | C20: SEC | D20: ='II-H-3.1-3'!Q19 -> 493 | E20: ='II-H-3.1-3'!O19 -> 478 | F20: ='II-H-1.2'!P19 -> 1211080649 | G20: ='II-H-1.2'!P49 -> -1430125.9 | H20: ='II-H-1.2'!P79 -> -33749815 | I20: ='II-H-1.2'!P111 -> 0 | J20: ='II-H-1.2'!P141 -> 1.1759007e+09
A21: 5 | B21: TOTAL SECONDARY > 10 kW | D21: =SUM(D19:D20) -> 72438.25 | E21: =SUM(E19:E20) -> 73070 | F21: =SUM(F19:F20) -> 9214721308 | G21: =SUM(G19:G20) -> -3412346.4 | H21: =SUM(H19:H20) -> 34961497 | I21: =SUM(I19:I20) -> 0 | J21: =SUM(J19:J20) -> 9.2462705e+09
A23: 6 | B23: PRIMARY NCP | C23: PRI | D23: ='II-H-3.1-3'!Q22 -> 570.5 | E23: ='II-H-3.1-3'!O22 -> 574 | F23: ='II-H-1.2'!P22 -> 303778954 | G23: ='II-H-1.2'!P52 -> 457811.69 | H23: ='II-H-1.2'!P82 -> 1814803.6 | I23: ='II-H-1.2'!P114 -> 0 | J23: ='II-H-1.2'!P144 -> 3.0605157e+08
A24: 7 | B24: PRIMARY 4CP | C24: PRI | D24: ='II-H-3.1-3'!Q23 -> 471.75 | E24: ='II-H-3.1-3'!O23 -> 471 | F24: ='II-H-1.2'!P23 -> 4089664935 | G24: ='II-H-1.2'!P53 -> 0 | H24: ='II-H-1.2'!P83 -> -5969816.8 | I24: ='II-H-1.2'!P115 -> 0 | J24: ='II-H-1.2'!P145 -> 4.0836951e+09
A25: 8 | B25: TOTAL PRIMARY | D25: =SUM(D23:D24) -> 1042.25 | E25: =SUM(E23:E24) -> 1045 | F25: =SUM(F23:F24) -> 4393443889 | G25: =SUM(G23:G24) -> 457811.69 | H25: =SUM(H23:H24) -> -4155013.1 | I25: =SUM(I23:I24) -> 0 | J25: =SUM(J23:J24) -> 4.3897467e+09
A27: 9 | B27: TRANSMISSION | C27: TRA | D27: ='II-H-3.1-3'!Q26 -> 85 | E27: ='II-H-3.1-3'!Q26 -> 85 | F27: ='II-H-1.2'!P26 -> 5453190408 | G27: ='II-H-1.2'!P56 -> 0 | H27: ='II-H-1.2'!P86 -> 2.918065e+08 | I27: ='II-H-1.2'!P118 -> 0 | J27: ='II-H-1.2'!P148 -> 5.7449969e+09
A29: 10 | B29: LIGHTING | C29: SEC | D29: ='II-H-3.1-3'!Q28 -> 220662.25 | E29: =1873+428 -> 2301 | F29: ='II-H-1.2'!P28 -> 262407146 | G29: ='II-H-1.2'!P58 -> 0 | H29: ='II-H-1.2'!P88 -> -181100.56 | I29: ='II-H-1.2'!P120 -> 0 | J29: ='II-H-1.2'!P150 -> 2.6222605e+08
A31: 11 | B31: TOTAL RETAIL | D31: =D29+D27+D25+D21+D17+D15 -> 1255199.8 | E31: =E29+E27+E25+E21+E17+E15 -> 1042212 | F31: =F29+F27+F25+F21+F17+F15 -> 32007470455 | G31: =G29+G27+G25+G21+G17+G15 -> -172372445 | H31: =H29+H27+H25+H21+H17+H15 -> 3.8462706e+08 | I31: =I29+I27+I25+I21+I17+I15 -> 0 | J31: =J29+J27+J25+J21+J17+J15 -> 3.2219725e+10
A33: 12 | B33: WHOLESALE PRI | C33: PRI | D33: ='II-H-3.1-3'!Q32 -> 0 | E33: ='II-H-3.1-3'!O32 -> 0 | F33: ='II-H-1.2'!P32 -> 0 | G33: ='II-H-1.2'!P62 -> 0 | H33: ='II-H-1.2'!P92 -> 0 | I33: ='II-H-1.2'!P124 -> 0 | J33: ='II-H-1.2'!P154 -> 0
A34: 13 | B34: WHOLESALE TRANS | C34: TRA | D34: ='II-H-3.1-3'!Q33 -> 0 | E34: ='II-H-3.1-3'!O33 -> 0 | F34: ='II-H-1.2'!P33 -> 0 | G34: ='II-H-1.2'!P63 -> 0 | H34: ='II-H-1.2'!P93 -> 0 | I34: ='II-H-1.2'!P125 -> 0
A35: 14 | B35: TOTAL WHOLESALE | D35: ='II-H-3.1-3'!Q131 -> 0 | E35: ='II-H-3.1-3'!O131 -> 0 | F35: =SUM(F33:F34) -> 0 | G35: =SUM(G33:G34) -> 0 | H35: =SUM(H33:H34) -> 0 | I35: =SUM(I33:I34) -> 0 | J35: =SUM(J33:J34) -> 0
A37: 15 | B37: TOTAL AEP TX | D37: =+D35+D31 -> 1255199.8 | E37: =+E35+E31 -> 1042212 | F37: =+F35+F31 -> 32007470455 | G37: =+G35+G31 -> -172372445 | H37: =+H35+H31 -> 3.8462706e+08 | I37: =+I35+I31 -> 0 | J37: =+J35+J31 -> 3.2219725e+10
B39: Note: Secondary < 10 kW includes Unmetered service; Lighting customers are fixture counts.

Sheet II-H-1.2
B2: PUBLIC UTILITY COMMISSION OF TEXAS
B3: AEP TEXAS INC
B4: II-H-1.2 MONTHLY SALES DATA
B5: TEST YEAR ENDING 12/31/2018
B6: DOCKET NUMBER (PENDING ASSIGNMENT)
B7: AEP TEXAS
B8: UNADJUSTED BILLING KWH AT METER
B9: FOR TEST YEAR ENDED DECEMBER 31, 2018
A12: LINE | B12: DESCRIPTION | C12: VOLT | D12: JANUARY | E12: FEBRUARY | F12: MARCH | G12: APRIL | H12: MAY | I12: JUNE | J12: JULY | K12: AUGUST | L12: SEPTEMBER | M12: OCTOBER | N12: NOVEMBER | O12: DECEMBER | P12: TOTAL
Q13: dist rate | R13: trans rate
A14: 1 | B14: RESIDENTIAL SERVICE | C14: SEC | D14: ='[4]II-H-1.2'!$D$8+'[5]II-H-1.2'!$D$8 -> 1187765247 | E14: ='[4]II-H-1.2'!$E$8+'[5]II-H-1.2'!$E$8 -> 880784604 | F14: ='[4]II-H-1.2'!$F$8+'[5]II-H-1.2'!$F$8 -> 702884785 | G14: ='[4]II-H-1.2'!$G$8+'[5]II-H-1.2'!$G$8 -> 737229219 | H14: ='[6]Billed kWh'!J85+'[5]II-H-1.2'!$H$8 -> 818132631 | I14: ='[6]Billed kWh'!K85+'[5]II-H-1.2'!$I$8 -> 1248494359 | J14: ='[6]Billed kWh'!L85+'[5]II-H-1.2'!$J$8 -> 1307274429 | K14: ='[6]Billed kWh'!M85+'[5]II-H-1.2'!$K$8 -> 1327155842 | L14: ='[6]Billed kWh'!N85+'[5]II-H-1.2'!$L$8 -> 1281003285 | M14: ='[6]Billed kWh'!O85+'[5]II-H-1.2'!$M$8 -> 999055732 | N14: ='[6]Billed kWh'!P85+'[5]II-H-1.2'!$N$8 -> 758197962 | O14: ='[6]Billed kWh'!Q85+'[5]II-H-1.2'!$O$8 -> 855133377 | P14: =SUM(D14:O14) -> 12103111472 | Q14: ='II-H-4.1 Functions'!F15/'II-H-1.2'!P14 -> 0.014721066 | R14: ='II-H-4.1 Functions'!H15/'II-H-1.2'!P14 -> 0.0052870156
A16: 2 | B16: SECONDARY < 10 kW | C16: SEC | D16: ='[6]Billed kWh'!F12+'[5]II-H-1.2'!$D$10 -> 52387683 | E16: ='[6]Billed kWh'!G12+'[5]II-H-1.2'!$E$10 -> 44007425 | F16: ='[6]Billed kWh'!H12+'[5]II-H-1.2'!$F$10 -> 41415235 | G16: ='[6]Billed kWh'!I12+'[5]II-H-1.2'!$G$10 -> 43220513 | H16: ='[6]Billed kWh'!J12+'[5]II-H-1.2'!$H$10 -> 43994819 | I16: ='[6]Billed kWh'!K12+'[5]II-H-1.2'!$I$10 -> 53800786 | J16: ='[6]Billed kWh'!L12+'[5]II-H-1.2'!$J$10 -> 55164376 | K16: ='[6]Billed kWh'!M12+'[5]II-H-1.2'!$K$10 -> 55433077 | L16: ='[6]Billed kWh'!N12+'[5]II-H-1.2'!$L$10 -> 55189705 | M16: ='[6]Billed kWh'!O12+'[5]II-H-1.2'!$M$10 -> 48472763 | N16: ='[6]Billed kWh'!P12+'[5]II-H-1.2'!$N$10 -> 42646592 | O16: ='[6]Billed kWh'!Q12+'[5]II-H-1.2'!$O$10 -> 44863258 | P16: =SUM(D16:O16) -> 580596232 | Q16: ='II-H-4.1 Functions'!F17/'II-H-1.2'!P16 -> 0.019511289 | R16: ='II-H-4.1 Functions'!H17/'II-H-1.2'!P16 -> 0.0026675947
A18: 3 | B18: SECONDARY > 10 kW NCP | C18: SEC | D18: ='[6]Billed kWh'!F30+'[5]II-H-1.2'!$D$12 -> 617758227 | E18: ='[6]Billed kWh'!G30+'[5]II-H-1.2'!$E$12 -> 556084841 | F18: ='[6]Billed kWh'!H30+'[5]II-H-1.2'!$F$12 -> 558942613 | G18: ='[6]Billed kWh'!I30+'[5]II-H-1.2'!$G$12 -> 605162513 | H18: ='[6]Billed kWh'!J30+'[5]II-H-1.2'!$H$12 -> 628387410 | I18: ='[6]Billed kWh'!K30+'[5]II-H-1.2'!$I$12 -> 779428797 | J18: ='[6]Billed kWh'!L30+'[5]II-H-1.2'!$J$12 -> 788525135 | K18: ='[6]Billed kWh'!M30+'[5]II-H-1.2'!$K$12 -> 797101000 | L18: ='[6]Billed kWh'!N30+'[5]II-H-1.2'!$L$12 -> 806339744 | M18: ='[6]Billed kWh'!O30+'[5]II-H-1.2'!$M$12 -> 699340712 | N18: ='[6]Billed kWh'!P30+'[5]II-H-1.2'!$N$12 -> 585836747 | O18: ='[6]Billed kWh'!Q30+'[5]II-H-1.2'!$O$12 -> 580732920 | P18: =SUM(D18:O18) -> 8003640659
A19: 4 | B19: SECONDARY > 10 kW 4CP | C19: SEC | D19: ='[6]Billed kWh'!F21+'[5]II-H-1.2'!D13 -> 103285168 | E19: ='[6]Billed kWh'!G21+'[5]II-H-1.2'!E13 -> 88205306 | F19: ='[6]Billed kWh'!H21+'[5]II-H-1.2'!F13 -> 88837676 | G19: ='[6]Billed kWh'!I21+'[5]II-H-1.2'!G13 -> 92617462 | H19: ='[6]Billed kWh'!J21+'[5]II-H-1.2'!H13 -> 96277050 | I19: ='[6]Billed kWh'!K21+'[5]II-H-1.2'!I13 -> 101782093 | J19: ='[6]Billed kWh'!L21+'[5]II-H-1.2'!J13 -> 112888067 | K19: ='[6]Billed kWh'!M21+'[5]II-H-1.2'!K13 -> 107756758 | ... O19: ='[6]Billed kWh'!Q21+'[5]II-H-1.2'!O13 -> 92547279 | P19: =SUM(D19:O19) -> 1211080649
A20: 5 | B20: TOTAL SECONDARY > 10 kW | D20: =SUM(D18:D19) -> 721043395 | E20: =SUM(E18:E19) -> 644290147 | F20: =SUM(F18:F19) -> 647780289 | G20: =SUM(G18:G19) -> 697779975 | H20: =SUM(H18:H19) -> 724664460 | I20: =SUM(I18:I19) -> 881210890 | J20: =SUM(J18:J19) -> 901413202 | K20: =SUM(K18:K19) -> 904857758 | ... P20: =SUM(P18:P19) -> 9214721308
A22: 6 | B22: PRIMARY NCP | C22: PRI | D22: ='[6]Billed kWh'!F82+'[5]II-H-1.2'!D16 -> 22763927 | E22: ='[6]Billed kWh'!G82+'[5]II-H-1.2'!E16 -> 22233694 | F22: ='[6]Billed kWh'!H82+'[5]II-H-1.2'!F16 -> 21505721 | G22: ='[6]Billed kWh'!I82+'[5]II-H-1.2'!G16 -> 23581205 | H22: ='[6]Billed kWh'!J82+'[5]II-H-1.2'!H16 -> 24029745 | I22: ='[6]Billed kWh'!K82+'[5]II-H-1.2'!I16 -> 27769076 | J22: ='[6]Billed kWh'!L82+'[5]II-H-1.2'!J16 -> 25217671 | K22: ='[6]Billed kWh'!M82+'[5]II-H-1.2'!K16 -> 29729548 | ... O22: ='[6]Billed kWh'!Q82+'[5]II-H-1.2'!O16 -> 25367936 | P22: =SUM(D22:O22) -> 303778954
A23: 7 | B23: PRIMARY 4CP | C23: PRI | D23: ='[6]Billed kWh'!F77+'[5]II-H-1.2'!D17 -> 328485905 | E23: ='[6]Billed kWh'!G77+'[5]II-H-1.2'!E17 -> 292364752 | F23: ='[6]Billed kWh'!H77+'[5]II-H-1.2'!F17 -> 312199493 | G23: ='[6]Billed kWh'!I77+'[5]II-H-1.2'!G17 -> 320624447 | H23: ='[6]Billed kWh'!J77+'[5]II-H-1.2'!H17 -> 338718878 | I23: ='[6]Billed kWh'!K77+'[5]II-H-1.2'!I17 -> 370216564 | J23: ='[6]Billed kWh'!L77+'[5]II-H-1.2'!J17 -> 364949086 | K23: ='[6]Billed kWh'!M77+'[5]II-H-1.2'!K17 -> 367964122 | ... O23: ='[6]Billed kWh'!Q77+'[5]II-H-1.2'!O17 -> 328944965 | P23: =SUM(D23:O23) -> 4089664935
A24: 8 | B24: TOTAL PRIMARY | D24: =SUM(D22:D23) -> 351249832 | E24: =SUM(E22:E23) -> 314598446 | F24: =SUM(F22:F23) -> 333705214 | G24: =SUM(G22:G23) -> 344205652 | H24: =SUM(H22:H23) -> 362748623 | I24: =SUM(I22:I23) -> 397985640 | J24: =SUM(J22:J23) -> 390166757 | K24: =SUM(K22:K23) -> 397693670 | ... P24: =SUM(P22:P23) -> 4393443889
A26: 9 | B26: TRANSMISSION | C26: TRA | D26: ='[6]Billed kWh'!F97+'[5]II-H-1.2'!D20 -> 530719273 | E26: ='[6]Billed kWh'!G97+'[5]II-H-1.2'!E20 -> 349122435 | F26: ='[6]Billed kWh'!H97+'[5]II-H-1.2'!F20 -> 568341249 | G26: ='[6]Billed kWh'!I97+'[5]II-H-1.2'!G20 -> 536467367 | H26: ='[6]Billed kWh'!J97+'[5]II-H-1.2'!H20 -> 501093104 | I26: ='[6]Billed kWh'!K97+'[5]II-H-1.2'!I20 -> 504926500 | J26: ='[6]Billed kWh'!L97+'[5]II-H-1.2'!J20 -> 368328476 | K26: ='[6]Billed kWh'!M97+'[5]II-H-1.2'!K20 -> 415971240 | ... O26: ='[6]Billed kWh'!Q97+'[5]II-H-1.2'!O20 -> 364087140 | P26: =SUM(D26:O26) -> 5453190408
A28: 10 | B28: LIGHTING | C28: SEC | D28: ='[6]Billed kWh'!F71+'[5]II-H-1.2'!D22 -> 21891804 | E28: ='[6]Billed kWh'!G71+'[5]II-H-1.2'!E22 -> 21808568 | F28: ='[6]Billed kWh'!H71+'[5]II-H-1.2'!F22 -> 21865686 | G28: ='[6]Billed kWh'!I71+'[5]II-H-1.2'!G22 -> 21884664 | H28: ='[6]Billed kWh'!J71+'[5]II-H-1.2'!H22 -> 21865890 | I28: ='[6]Billed kWh'!K71+'[5]II-H-1.2'!I22 -> 21865532 | J28: ='[6]Billed kWh'!L71+'[5]II-H-1.2'!J22 -> 21871358 | K28: ='[6]Billed kWh'!M71+'[5]II-H-1.2'!K22 -> 21863875 | ... O28: ='[6]Billed kWh'!Q71+'[5]II-H-1.2'!O22 -> 21864010 | P28: =SUM(D28:O28) -> 262407146 | Q28: ='II-H-4.1 Functions'!F29/'II-H-1.2'!P28 -> 0.067212039 | R28: ='II-H-4.1 Functions'!H29/'II-H-1.2'!P28 -> 0.002609387
A30: 11 | B30: TOTAL RETAIL | D30: =D28+D26+D24+D20+D16+D14 -> 2865057234 | E30: =E28+E26+E24+E20+E16+E14 -> 2254611625 | F30: =F28+F26+F24+F20+F16+F14 -> 2315992458 | G30: =G28+G26+G24+G20+G16+G14 -> 2380787390 | H30: =H28+H26+H24+H20+H16+H14 -> 2472499527 | I30: =I28+I26+I24+I20+I16+I14 -> 3108283707 | J30: =J28+J26+J24+J20+J16+J14 -> 3044218598 | K30: =K28+K26+K24+K20+K16+K14 -> 3122975462 | ... P30: =P28+P26+P24+P20+P16+P14 -> 32007470455
A32: 12 | B32: WHOLESALE PRI | C32: PRI | D32: 0 | E32: 0 | F32: 0 | G32: 0 | H32: 0 | I32: 0 | J32: 0 | K32: 0 | L32: 0 | M32: 0 | N32: 0 | O32: 0 | P32: =SUM(D32:O32) -> 0
A33: 13 | B33: WHOLESALE TRANS | C33: TRA | P33: =SUM(D33:O33) -> 0
A34: 14 | B34: TOTAL WHOLESALE | D34: =SUM(D32:D33) -> 0 | E34: =SUM(E32:E33) -> 0 | F34: =SUM(F32:F33) -> 0 | G34: =SUM(G32:G33) -> 0 | H34: =SUM(H32:H33) -> 0 | I34: =SUM(I32:I33) -> 0 | J34: =SUM(J32:J33) -> 0 | K34: =SUM(K32:K33) -> 0 | ... P34: =SUM(P32:P33) -> 0
A36: 15 | B36: TOTAL AEP TEXAS | D36: =+D34+D30 -> 2865057234 | E36: =+E34+E30 -> 2254611625 | F36: =+F34+F30 -> 2315992458 | G36: =+G34+G30 -> 2380787390 | H36: =+H34+H30 -> 2472499527 | I36: =+I34+I30 -> 3108283707 | J36: =+J34+J30 -> 3044218598 | K36: =+K34+K30 -> 3122975462 | ... P36: =+P34+P30 -> 32007470455
B37: =+B7 -> AEP TEXAS
B38: WEATHER ADJUSTMENTS TO KWH AT METER
B39: =+B9 -> FOR TEST YEAR ENDED DECEMBER 31, 2018
A42: LINE | B42: DESCRIPTION | C42: VOLT | D42: =D12 -> JANUARY | E42: =E12 -> FEBRUARY | F42: =F12 -> MARCH | G42: =G12 -> APRIL | H42: =H12 -> MAY | I42: =I12 -> JUNE | J42: =J12 -> JULY | K42: =K12 -> AUGUST | ... O42: =O12 -> DECEMBER | P42: =+P12 -> TOTAL
A44: 1 | B44: RESIDENTIAL SERVICE | C44: SEC | D44: =-'[7]TCC by class'!C22+'[5]II-H-1.2'!D39 -> -155127058 | E44: =-'[7]TCC by class'!D22+'[5]II-H-1.2'!E39 -> -62130204 | F44: =-'[7]TCC by class'!E22+'[5]II-H-1.2'!F39 -> 7333556 | G44: =-'[7]TCC by class'!F22+'[5]II-H-1.2'!G39 -> -3961366 | H44: =-'[7]TCC by class'!G22+'[5]II-H-1.2'!H39 -> 31982624 | I44: =-'[7]TCC by class'!H22+'[5]II-H-1.2'!I39 -> -59697400 | J44: =-'[7]TCC by class'!I22+'[5]II-H-1.2'!J39 -> 4322941 | K44: =-'[7]TCC by class'!J22+'[5]II-H-1.2'!K39 -> 16737076 | ... O44: =-'[7]TCC by class'!N22+'[5]II-H-1.2'!O39 -> 33942751 | P44: =SUM(D44:O44) -> -169072907
A46: 2 | B46: SECONDARY < 10 kW | C46: SEC | D46: =-'[7]TCC by class'!C17+'[5]II-H-1.2'!D41 -> -647314.76 | E46: =-'[7]TCC by class'!D17+'[5]II-H-1.2'!E41 -> -203654.11 | F46: =-'[7]TCC by class'!E17+'[5]II-H-1.2'!F41 -> -610097.86 | G46: =-'[7]TCC by class'!F17+'[5]II-H-1.2'!G41 -> -266425.84 | H46: =-'[7]TCC by class'!G17+'[5]II-H-1.2'!H41 -> 789362.19 | I46: =-'[7]TCC by class'!H17+'[5]II-H-1.2'!I41 -> -1548911.2 | J46: =-'[7]TCC by class'!I17+'[5]II-H-1.2'!J41 -> 46199.63 | K46: =-'[7]TCC by class'!J17+'[5]II-H-1.2'!K41 -> 424092.29 | ... O46: =-'[7]TCC by class'!N17+'[5]II-H-1.2'!O41 -> 510140.7 | P46: =SUM(D46:O46) -> -345003.32
A48: 3 | B48: SECONDARY > 10 kW NCP | C48: SEC | D48: =-'[7]TCC by class'!C19+'[5]II-H-1.2'!D43 -> -7705107 | E48: =-'[7]TCC by class'!D19+'[5]II-H-1.2'!E43 -> -2506173.9 | F48: =-'[7]TCC by class'!E19+'[5]II-H-1.2'!F43 -> -9276340.2 | G48: =-'[7]TCC by class'!F19+'[5]II-H-1.2'!G43 -> -4400742.5 | H48: =-'[7]TCC by class'!G19+'[5]II-H-1.2'!H43 -> 12271334 | I48: =-'[7]TCC by class'!H19+'[5]II-H-1.2'!I43 -> -22290013 | J48: =-'[7]TCC by class'!I19+'[5]II-H-1.2'!J43 -> 2126732 | K48: =-'[7]TCC by class'!J19+'[5]II-H-1.2'!K43 -> 6402328.7 | ... O48: =-'[7]TCC by class'!N19+'[5]II-H-1.2'!O43 -> 7565286.2 | P48: =SUM(D48:O48) -> -1982220.5
A49: 4 | B49: SECONDARY > 10 kW 4CP | C49: SEC | D49: =-'[7]TCC by class'!C18+'[5]II-H-1.2'!D44 -> -1245610.1 | E49: =-'[7]TCC by class'!D18+'[5]II-H-1.2'!E44 -> -462292.73 | F49: =-'[7]TCC by class'!E18+'[5]II-H-1.2'!F44 -> -1103737.7 | G49: =-'[7]TCC by class'!F18+'[5]II-H-1.2'!G44 -> -423723.27 | H49: =-'[7]TCC by class'!G18+'[5]II-H-1.2'!H44 -> 1531043.4 | I49: =-'[7]TCC by class'!H18+'[5]II-H-1.2'!I44 -> -3302692 | J49: =-'[7]TCC by class'!I18+'[5]II-H-1.2'!J44 -> -199243.4 | K49: =-'[7]TCC by class'!J18+'[5]II-H-1.2'!K44 -> 782122.87 | ... O49: =-'[7]TCC by class'!N18+'[5]II-H-1.2'!O44 -> 772567.19 | P49: =SUM(D49:O49) -> -1430125.9
A50: 5 | B50: TOTAL SECONDARY > 10 kW | D50: =SUM(D48:D49) -> -8950717.2 | E50: =SUM(E48:E49) -> -2968466.6 | F50: =SUM(F48:F49) -> -10380078 | G50: =SUM(G48:G49) -> -4824465.8 | H50: =SUM(H48:H49) -> 13802377 | I50: =SUM(I48:I49) -> -25592705 | J50: =SUM(J48:J49) -> 1927488.6 | K50: =SUM(K48:K49) -> 7184451.6 | ... P50: =SUM(P48:P49) -> -3412346.4
A52: 6 | B52: PRIMARY NCP | C52: PRI | D52: =+-'[7]TCC by class'!C21+'[5]II-H-1.2'!D47 -> -1514158.1 | E52: =+-'[7]TCC by class'!D21+'[5]II-H-1.2'!E47 -> -456066.29 | F52: =+-'[7]TCC by class'!E21+'[5]II-H-1.2'!F47 -> -2415686.2 | G52: =+-'[7]TCC by class'!F21+'[5]II-H-1.2'!G47 -> -1151685.4 | H52: =+-'[7]TCC by class'!G21+'[5]II-H-1.2'!H47 -> 3105541.9 | I52: =+-'[7]TCC by class'!H21+'[5]II-H-1.2'!I47 -> -5087814.5 | J52: =+-'[7]TCC by class'!I21+'[5]II-H-1.2'!J47 -> 574389.74 | K52: =+-'[7]TCC by class'!J21+'[5]II-H-1.2'!K47 -> 1470588.1 | ... O52: =+-'[7]TCC by class'!N21+'[5]II-H-1.2'!O47 -> 2082473.9 | P52: =SUM(D52:O52) -> 457811.69
A53: 7 | B53: PRIMARY 4CP | C53: PRI | P53: =SUM(D53:O53) -> 0
A54: 8 | B54: TOTAL PRIMARY | D54: =SUM(D52:D53) -> -1514158.1 | E54: =SUM(E52:E53) -> -456066.29 | F54: =SUM(F52:F53) -> -2415686.2 | G54: =SUM(G52:G53) -> -1151685.4 | H54: =SUM(H52:H53) -> 3105541.9 | I54: =SUM(I52:I53) -> -5087814.5 | J54: =SUM(J52:J53) -> 574389.74 | K54: =SUM(K52:K53) -> 1470588.1 | ... P54: =SUM(P52:P53) -> 457811.69
A56: 9 | B56: TRANSMISSION | C56: TRA | D56: =-'[7]TCC by class'!C23 -> 0 | E56: =-'[7]TCC by class'!D23 -> 0 | F56: =-'[7]TCC by class'!E23 -> 0 | G56: =-'[7]TCC by class'!F23 -> 0 | H56: =-'[7]TCC by class'!G23 -> 0 | I56: =-'[7]TCC by class'!H23 -> 0 | J56: =-'[7]TCC by class'!I23 -> 0 | K56: =-'[7]TCC by class'!J23 -> 0 | ... O56: =-'[7]TCC by class'!N23 -> 0 | P56: =SUM(D56:O56) -> 0
A58: 10 | B58: LIGHTING | C58: SEC | P58: =SUM(D58:O58) -> 0
G59: 0
...

Sheet II-H-1.3
B2: PUBLIC UTILITY COMMISSION OF TEXAS
B3: AEP TEXAS INC
B4: II-H-1.3 UNADJUSTED TEST YEAR KWH DATA
B5: TEST YEAR ENDING 12/31/2018
B6: DOCKET NUMBER (PENDING ASSIGNMENT)
A7: AEP TEXAS
A8: UNADJUSTED BILLING KWH
A9: FOR TEST YEAR ENDED DECEMBER 31, 2018
A12: LINE | B12: DESCRIPTION | C12: VOLT | D12: KWH @ Source | E12: Percentage | F12: KWH @ Meter | G12: Percentage
A14: 1 | B14: RESIDENTIAL SERVICE | C14: SEC | D14: =+'II-H-1.2'!P167 -> 1.3073055e+10 | E14: =+D14/$D$36 -> 0.38335397 | F14: ='II-H-1.2'!P14 -> 12103111472 | G14: =F14/$F$36 -> 0.37813396
A16: 2 | B16: SECONDARY < 10 kW | C16: SEC | D16: =+'II-H-1.2'!P169 -> 6.2712521e+08 | E16: =+D16/$D$36 -> 0.018389806 | F16: ='II-H-1.2'!P16 -> 580596232 | G16: =F16/$F$36 -> 0.018139398
A18: 3 | B18: SECONDARY > 10 kW NCP | C18: SEC | D18: =+'II-H-1.2'!P171 -> 8.6450524e+09 | E18: =+D18/$D$36 -> 0.25350733 | F18: ='II-H-1.2'!P18 -> 8003640659 | G18: =F18/$F$36 -> 0.25005539
A19: 4 | B19: SECONDARY > 10 kW 4CP | C19: SEC | D19: =+'II-H-1.2'!P172 -> 1.3081367e+09 | E19: =+D19/$D$36 -> 0.038359771 | F19: ='II-H-1.2'!P19 -> 1211080649 | G19: =F19/$F$36 -> 0.037837437
A20: 5 | B20: TOTAL SECONDARY > 10 kW | D20: =SUM(D18:D19) -> 9.9531891e+09 | E20: =SUM(E18:E19) -> 0.2918671 | F20: ='II-H-1.2'!P20 -> 9214721308 | G20: =F20/$F$36 -> 0.28789283
A22: 6 | B22: PRIMARY NCP | C22: PRI | D22: =+'II-H-1.2'!P175 -> 3.1921092e+08 | E22: =+D22/$D$36 -> 0.0093605342 | F22: ='II-H-1.2'!P22 -> 303778954 | G22: =F22/$F$36 -> 0.0094908767
A23: 7 | B23: PRIMARY 4CP | C23: PRI | D23: =+'II-H-1.2'!P176 -> 4.2974199e+09 | E23: =+D23/$D$36 -> 0.12601745 | F23: ='II-H-1.2'!P23 -> 4089664935 | G23: =F23/$F$36 -> 0.1277722
A24: 8 | B24: TOTAL PRIMARY | D24: =SUM(D22:D23) -> 4.6166308e+09 | E24: =SUM(E22:E23) -> 0.13537798 | F24: ='II-H-1.2'!P24 -> 4393443889 | G24: =F24/$F$36 -> 0.13726308
A26: 9 | B26: TRANSMISSION | C26: TRA | D26: =+'II-H-1.2'!P179 -> 5.5483486e+09 | E26: =+D26/$D$36 -> 0.16269965 | F26: ='II-H-1.2'!P26 -> 5453190408 | G26: =F26/$F$36 -> 0.17037243
A28: 10 | B28: LIGHTING | C28: SEC | D28: =+'II-H-1.2'!P181 -> 2.8343645e+08 | E28: =+D28/$D$36 -> 0.0083114844 | F28: ='II-H-1.2'!P28 -> 262407146 | G28: =F28/$F$36 -> 0.0081983094
A30: 11 | B30: TOTAL RETAIL | D30: =+D14+D16+D20+D24+D26+D28 -> 3.4101785e+10 | E30: =+E14+E16+E20+E24+E26+E28 -> 1 | F30: =+F14+F16+F20+F24+F26+F28 -> 32007470455 | G30: =F30/$F$36 -> 1
A32: 12 | B32: WHOLESALE PRI | C32: PRI | D32: 0 | F32: ='II-H-1.2'!P32 -> 0 | G32: =F32/$F$36 -> 0
A33: 13 | B33: WHOLESALE TRANS | C33: TRA | D33: 0 | F33: ='II-H-1.2'!P33 -> 0 | G33: =F33/$F$36 -> 0
A34: 14 | B34: TOTAL WHOLESALE | D34: =SUM(D32:D33) -> 0 | F34: ='II-H-1.2'!P34 -> 0 | G34: =F34/$F$36 -> 0
A36: 15 | B36: TOTAL AEP TEXAS | D36: =+D30+D34 -> 3.4101785e+10 | E36: =+E30+E34 -> 1 | F36: =+F30+F34 -> 32007470455 | G36: =+G30+G34 -> 1

Sheet Sch II-H-1.5
B2: PUBLIC UTILITY COMMISSION OF TEXAS
B3: AEP TEXAS INC
B4: II-H-1.5 ADJUSTMENTS TO OPERATING STATISTICS
B5: TEST YEAR ENDING 12/31/2018
B6: DOCKET NUMBER (PENDING ASSIGNMENT)
A9: Line | B9: Description
A10: 1 | B10: This schedule provides a narrative explanation of all adjustments made to Test Year operating
B11: statistics provided in RFP Schedule II-H-1.
A13: 2 | B13: Residential Service: adjustment made for weather normalized kWh sales; annualize to
B14: year-end customer count and associated kWh sales.
A16: 3 | B16: Secondary ≤ 10 kW Service: adjustment made for weather normalized kWh sales; annualize to
B17: year-end customer count and associated kWh sales.
A19: 4 | B19: Secondary ≥10 kW Service: adjustment made for weather normalized kWh sales; annualize to
B20: year-end customer count and associated kWh sales.
A22: 5 | B22: Primary Service: adjustment made for weather normalized kWh sales; annualize to year-end
B23: customer count and associated kWh sales.
A25: 6 | B25: Transmission Service: annualize to year-end customer count and associated kWh sales.
A27: 7 | B27: Lighting Service: annualize to year-end customer count and associated kWh sales.

Sheet II-H-3.1-3
B2: PUBLIC UTILITY COMMISSION OF TEXAS
B3: AEP TEXAS INC
B4: II-H-3.1-H-3.3 CUSTOMER ADJUSTMENTS
B5: TEST YEAR ENDING 12/31/2018
B6: DOCKET NUMBER (PENDING ASSIGNMENT)
B7: ='II-H-1.2'!B7:O7 -> AEP TEXAS
B8: BOOKED CUSTOMER COUNT
B9: ='II-H-1.2'!B9:O9 -> FOR TEST YEAR ENDED DECEMBER 31, 2018
B10: II-H-3.1
D11: ='II-H-1.2'!D11 -> 0 | G11: ='II-H-1.2'!G11 -> 0
A12: LINE | B12: DESCRIPTION | C12: VOLT | D12: ='II-H-1.2'!D12 -> JANUARY | E12: ='II-H-1.2'!E12 -> FEBRUARY | F12: ='II-H-1.2'!F12 -> MARCH | G12: ='II-H-1.2'!G12 -> APRIL | H12: ='II-H-1.2'!H12 -> MAY | I12: ='II-H-1.2'!I12 -> JUNE | J12: ='II-H-1.2'!J12 -> JULY | K12: ='II-H-1.2'!K12 -> AUGUST | ... O12: ='II-H-1.2'!O12 -> DECEMBER | P12: TOTAL | Q12: AVERAGE
R13: cust | S13: meter | U13: cust | V13: meter
A14: 1 | B14: RESIDENTIAL SERVICE | C14: SEC | D14: ='[6]Incl Customers'!G85+'[5]II-H-3.1'!D8 -> 866062 | E14: ='[6]Incl Customers'!H85+'[5]II-H-3.1'!E8 -> 866633 | F14: ='[6]Incl Customers'!I85+'[5]II-H-3.1'!F8 -> 867947 | G14: ='[6]Incl Customers'!J85+'[5]II-H-3.1'!G8 -> 869158 | H14: ='[6]Incl Customers'!K85+'[5]II-H-3.1'!H8 -> 870372 | I14: ='[6]Incl Customers'!L85+'[5]II-H-3.1'!I8 -> 870490 | J14: ='[6]Incl Customers'!M85+'[5]II-H-3.1'!J8 -> 870393 | K14: ='[6]Incl Customers'!N85+'[5]II-H-3.1'!K8 -> 875458 | L14: ='[4]II-H-3.1'!$L$8+'[5]II-H-3.1'!$L$8 -> 875459 | M14: ='[4]II-H-3.1'!M8+'[5]II-H-3.1'!M8 -> 875792 | N14: ='[4]II-H-3.1'!N8+'[5]II-H-3.1'!N8 -> 876193 | O14: ='[4]II-H-3.1'!O8+'[5]II-H-3.1'!O8 -> 876553 | P14: =SUM(D14:O14) -> 10460510 | Q14: =P14/12 -> 871709.17 | R14: =+'II-H-4.1 Functions'!D15/'II-H-3.1-3'!P14 -> 3.1463551 | S14: =+'II-H-4.1 Functions'!E15/'II-H-3.1-3'!P14 -> 3.8411203 | U14: 3.19 | V14: 3.55
A16: 2 | B16: SECONDARY < 10 kW | C16: SEC | D16: ='[6]Incl Customers'!G12+'[5]II-H-3.1'!D10 -> 90324 | E16: ='[6]Incl Customers'!H12+'[5]II-H-3.1'!E10 -> 88828 | F16: ='[6]Incl Customers'!I12+'[5]II-H-3.1'!F10 -> 88597 | G16: ='[6]Incl Customers'!J12+'[5]II-H-3.1'!G10 -> 88868 | H16: ='[6]Incl Customers'!K12+'[5]II-H-3.1'!H10 -> 89101 | I16: ='[6]Incl Customers'!L12+'[5]II-H-3.1'!I10 -> 89284 | J16: ='[6]Incl Customers'!M12+'[5]II-H-3.1'!J10 -> 89364 | K16: ='[6]Incl Customers'!N12+'[5]II-H-3.1'!K10 -> 89665 | L16: ='[4]II-H-3.1'!L10+'[5]II-H-3.1'!L10 -> 89328 | M16: ='[4]II-H-3.1'!M10+'[5]II-H-3.1'!M10 -> 89393 | N16: ='[4]II-H-3.1'!N10+'[5]II-H-3.1'!N10 -> 89245 | O16: ='[4]II-H-3.1'!O10+'[5]II-H-3.1'!O10 -> 89158 | P16: =SUM(D16:O16) -> 1071155 | Q16: =P16/12 -> 89262.917 | R16: =+'II-H-4.1 Functions'!D17/'II-H-3.1-3'!P16 -> 3.4902669 | S16: =+'II-H-4.1 Functions'!E17/'II-H-3.1-3'!P16 -> 4.7033876 | U16: 3.2 | V16: 3.68
A18: 3 | B18: SECONDARY > 10 kW NCP | C18: SEC | D18: ='[6]Incl Customers'!G30+'[5]II-H-3.1'!D12 -> 69969 | E18: ='[6]Incl Customers'!H30+'[5]II-H-3.1'!E12 -> 71234 | F18: ='[6]Incl Customers'!I30+'[5]II-H-3.1'!F12 -> 71975 | G18: ='[6]Incl Customers'!J30+'[5]II-H-3.1'!G12 -> 72047 | H18: ='[6]Incl Customers'!K30+'[5]II-H-3.1'!H12 -> 71959 | I18: ='[6]Incl Customers'!L30+'[5]II-H-3.1'!I12 -> 72027 | J18: ='[6]Incl Customers'!M30+'[5]II-H-3.1'!J12 -> 72168 | K18: ='[6]Incl Customers'!N30+'[5]II-H-3.1'!K12 -> 72470 | L18: ='[4]II-H-3.1'!L12+'[5]II-H-3.1'!L12 -> 72222 | M18: ='[4]II-H-3.1'!M12+'[5]II-H-3.1'!M12 -> 72235 | N18: ='[4]II-H-3.1'!N12+'[5]II-H-3.1'!N12 -> 72445 | O18: ='[4]II-H-3.1'!O12+'[5]II-H-3.1'!O12 -> 72592 | P18: =SUM(D18:O18) -> 863343 | Q18: =P18/12 -> 71945.25 | R18: =+'II-H-4.1 Functions'!D19/'II-H-3.1-3'!P18 -> 3.4452993 | S18: =+'II-H-4.1 Functions'!E19/'II-H-3.1-3'!P18 -> 16.341177 | U18: 3.26 | V18: 15.81
A19: 4 | B19: SECONDARY > 10 kW 4CP | C19: SEC | D19: ='[6]Incl Customers'!G21+'[5]II-H-3.1'!D13 -> 505 | E19: ='[6]Incl Customers'!H21+'[5]II-H-3.1'!E13 -> 506 | F19: ='[6]Incl Customers'!I21+'[5]II-H-3.1'!F13 -> 505 | G19: ='[6]Incl Customers'!J21+'[5]II-H-3.1'!G13 -> 502 | H19: ='[6]Incl Customers'!K21+'[5]II-H-3.1'!H13 -> 503 | I19: ='[6]Incl Customers'!L21+'[5]II-H-3.1'!I13 -> 494 | J19: ='[6]Incl Customers'!M21+'[5]II-H-3.1'!J13 -> 495 | K19: ='[6]Incl Customers'!N21+'[5]II-H-3.1'!K13 -> 497 | L19: ='[4]II-H-3.1'!L13+'[5]II-H-3.1'!L13 -> 477 | M19: ='[4]II-H-3.1'!M13+'[5]II-H-3.1'!M13 -> 476 | N19: ='[4]II-H-3.1'!N13+'[5]II-H-3.1'!N13 -> 478 | O19: ='[4]II-H-3.1'!O13+'[5]II-H-3.1'!O13 -> 478 | P19: =SUM(D19:O19) -> 5916 | Q19: =P19/12 -> 493 | R19: =+'II-H-4.1 Functions'!D20/'II-H-3.1-3'!P19 -> 26.667578 | S19: =+'II-H-4.1 Functions'!E20/'II-H-3.1-3'!P19 -> 22.198059 | U19: 26.52 | V19: 15.81
A20: 5 | B20: TOTAL SECONDARY > 10 kW | D20: =SUM(D18:D19) -> 70474 | E20: =SUM(E18:E19) -> 71740 | F20: =SUM(F18:F19) -> 72480 | G20: =SUM(G18:G19) -> 72549 | H20: =SUM(H18:H19) -> 72462 | I20: =SUM(I18:I19) -> 72521 | J20: =SUM(J18:J19) -> 72663 | K20: =SUM(K18:K19) -> 72967 | ... O20: =SUM(O18:O19) -> 73070 | P20: =SUM(D20:O20) -> 869259 | Q20: =P20/12 -> 72438.25
A22: 6 | B22: PRIMARY NCP | C22: PRI | D22: ='[6]Incl Customers'!G82+'[5]II-H-3.1'!D16 -> 566 | E22: ='[6]Incl Customers'!H82+'[5]II-H-3.1'!E16 -> 565 | F22: ='[6]Incl Customers'!I82+'[5]II-H-3.1'!F16 -> 565 | G22: ='[6]Incl Customers'!J82+'[5]II-H-3.1'!G16 -> 560 | H22: ='[6]Incl Customers'!K82+'[5]II-H-3.1'!H16 -> 564 | I22: ='[6]Incl Customers'!L82+'[5]II-H-3.1'!I16 -> 572 | J22: ='[6]Incl Customers'!M82+'[5]II-H-3.1'!J16 -> 567 | K22: ='[6]Incl Customers'!N82+'[5]II-H-3.1'!K16 -> 580 | ... O22: ='[6]Incl Customers'!R82+'[5]II-H-3.1'!O16 -> 574 | P22: =SUM(D22:O22) -> 6846 | Q22: =P22/12 -> 570.5 | R22: =+'II-H-4.1 Functions'!D23/'II-H-3.1-3'!P22 -> 4.0787219 | S22: =+'II-H-4.1 Functions'!E23/'II-H-3.1-3'!P22 -> 152.38637 | U22: 3.8 | V22: 154.62
A23: 7 | B23: PRIMARY 4CP | C23: PRI | D23: ='[6]Incl Customers'!G77+'[5]II-H-3.1'!D17 -> 470 | E23: ='[6]Incl Customers'!H77+'[5]II-H-3.1'!E17 -> 470 | F23: ='[6]Incl Customers'!I77+'[5]II-H-3.1'!F17 -> 475 | G23: ='[6]Incl Customers'!J77+'[5]II-H-3.1'!G17 -> 464 | H23: ='[6]Incl Customers'!K77+'[5]II-H-3.1'!H17 -> 476 | I23: ='[6]Incl Customers'!L77+'[5]II-H-3.1'!I17 -> 480 | J23: ='[6]Incl Customers'!M77+'[5]II-H-3.1'!J17 -> 472 | K23: ='[6]Incl Customers'!N77+'[5]II-H-3.1'!K17 -> 468 | ... O23: ='[6]Incl Customers'!R77+'[5]II-H-3.1'!O17 -> 471 | P23: =SUM(D23:O23) -> 5661 | Q23: =P23/12 -> 471.75 | R23: =+'II-H-4.1 Functions'!D24/'II-H-3.1-3'!P23 -> 27.738956 | S23: =+'II-H-4.1 Functions'!E24/'II-H-3.1-3'!P23 -> 158.16809 | U23: 28.41 | V23: 154.62
A24: 8 | B24: TOTAL PRIMARY | D24: =SUM(D22:D23) -> 1036 | E24: =SUM(E22:E23) -> 1035 | F24: =SUM(F22:F23) -> 1040 | G24: =SUM(G22:G23) -> 1024 | H24: =SUM(H22:H23) -> 1040 | I24: =SUM(I22:I23) -> 1052 | J24: =SUM(J22:J23) -> 1039 | K24: =SUM(K22:K23) -> 1048 | ... O24: =SUM(O22:O23) -> 1045 | P24: =SUM(D24:O24) -> 12507 | Q24: =P24/12 -> 1042.25
A26: 9 | B26: TRANSMISSION | C26: TRA | D26: ='[6]Incl Customers'!G97+'[5]II-H-3.1'!D20 -> 85 | E26: ='[6]Incl Customers'!H97+'[5]II-H-3.1'!E20 -> 79 | F26: ='[6]Incl Customers'!I97+'[5]II-H-3.1'!F20 -> 79 | G26: ='[6]Incl Customers'!J97+'[5]II-H-3.1'!G20 -> 81 | H26: ='[6]Incl Customers'!K97+'[5]II-H-3.1'!H20 -> 84 | I26: ='[6]Incl Customers'!L97+'[5]II-H-3.1'!I20 -> 84 | J26: ='[6]Incl Customers'!M97+'[5]II-H-3.1'!J20 -> 79 | K26: ='[6]Incl Customers'!N97+'[5]II-H-3.1'!K20 -> 81 | ... O26: ='[6]Incl Customers'!R97+'[5]II-H-3.1'!O20 -> 64 | P26: =SUM(D26:O26) -> 974 | Q26: 85 | R26: =+'II-H-4.1 Functions'!D27/'II-H-3.1-3'!P26 -> 34.491335 | S26: =+'II-H-4.1 Functions'!E27/'II-H-3.1-3'!P26 -> 1534.7576 | U26: 38.84 | V26: 1869.15
A28: 10 | B28: LIGHTING | C28: SEC | D28: =+'[8]Active Units Lights'!F71+'[5]II-H-3.1'!D22 -> 228698 | E28: =+'[8]Active Units Lights'!G71+'[5]II-H-3.1'!E22 -> 219174 | F28: =+'[8]Active Units Lights'!H71+'[5]II-H-3.1'!F22 -> 219915 | G28: =+'[8]Active Units Lights'!I71+'[5]II-H-3.1'!G22 -> 220030 | H28: =+'[8]Active Units Lights'!J71+'[5]II-H-3.1'!H22 -> 220408 | I28: =+'[8]Active Units Lights'!K71+'[5]II-H-3.1'!I22 -> 220169 | J28: =+'[8]Active Units Lights'!L71+'[5]II-H-3.1'!J22 -> 217297 | K28: =+'[8]Active Units Lights'!M71+'[5]II-H-3.1'!K22 -> 221274 | ... O28: =+'[8]Active Units Lights'!Q71+'[5]II-H-3.1'!O22 -> 220232 | P28: =SUM(D28:O28) -> 2647947 | Q28: =P28/12 -> 220662.25
A30: 11 | B30: TOTAL RETAIL | D30: =D28+D26+D24+D20+D16+D14 -> 1256679 | E30: =E28+E26+E24+E20+E16+E14 -> 1247489 | F30: =F28+F26+F24+F20+F16+F14 -> 1250058 | G30: =G28+G26+G24+G20+G16+G14 -> 1251710 | H30: =H28+H26+H24+H20+H16+H14 -> 1253467 | I30: =I28+I26+I24+I20+I16+I14 -> 1253600 | J30: =J28+J26+J24+J20+J16+J14 -> 1250835 | K30: =K28+K26+K24+K20+K16+K14 -> 1260493 | ... O30: =O28+O26+O24+O20+O16+O14 -> 1260122 | P30: =SUM(D30:O30) -> 15062352 | Q30: =P30/12 -> 1255196
A32: 12 | B32: WHOLESALE PRI | C32: PRI
A33: 13 | B33: WHOLESALE TRANS | C33: TRA
A34: 14 | B34: TOTAL WHOLESALE
A36: 15 | B36: TOTAL AEP TEXAS | D36: =D34+D30 -> 1256679 | E36: =+E34+E30 -> 1247489 | F36: =+F34+F30 -> 1250058 | G36: =+G34+G30 -> 1251710 | H36: =+H34+H30 -> 1253467 | I36: =+I34+I30 -> 1253600 | J36: =+J34+J30 -> 1250835 | K36: =+K34+K30 -> 1260493 | L36: =+L34+L30 -> 1258943 | ... O36: =+O34+O30 -> 1260122 | P36: =SUM(D36:O36) -> 15062352 | Q36: =+Q34+Q30 -> 1255196
B37: Note: Secondary < 10 kW includes Unmetered service; Lighting customers are fixture counts.
B39: =+B7 -> AEP TEXAS
B40: CUSTOMER COUNT ADJUSTMENT
B41: =+B9 -> FOR TEST YEAR ENDED DECEMBER 31, 2018
D43: =D11 -> 0 | G43: =G11 -> 0
A44: LINE | B44: DESCRIPTION | C44: VOLT | D44: =+D12 -> JANUARY | E44: =+E12 -> FEBRUARY | F44: =+F12 -> MARCH | G44: =+G12 -> APRIL | H44: =+H12 -> MAY | I44: =+I12 -> JUNE | J44: =+J12 -> JULY | K44: =+K12 -> AUGUST | ... O44: =+O12 -> DECEMBER | P44: TOTAL | Q44: AVERAGE
A46: 1 | B46: RESIDENTIAL SERVICE | C46: SEC | D46: =+'[4]II-H-3.1'!D40+'[5]II-H-3.1'!D41 -> 10491 | E46: =+'[4]II-H-3.1'!E40+'[5]II-H-3.1'!E41 -> 9920 | F46: =+'[4]II-H-3.1'!F40+'[5]II-H-3.1'!F41 -> 8606 | G46: =+'[4]II-H-3.1'!G40+'[5]II-H-3.1'!G41 -> 7395 | H46: =+'[4]II-H-3.1'!H40+'[5]II-H-3.1'!H41 -> 6181 | I46: =+'[4]II-H-3.1'!I40+'[5]II-H-3.1'!I41 -> 6063 | J46: =+'[4]II-H-3.1'!J40+'[5]II-H-3.1'!J41 -> 6160 | K46: =+'[4]II-H-3.1'!K40+'[5]II-H-3.1'!K41 -> 1095 | ... O46: =+'[4]II-H-3.1'!O40+'[5]II-H-3.1'!O41 -> 0 | P46: =SUM(D46:O46) -> 58126 | Q46: =P46/12 -> 4843.8333
A48: 2 | B48: SECONDARY < 10 kW | C48: SEC | D48: =+'[4]II-H-3.1'!D42+'[5]II-H-3.1'!D43 -> -1166 | E48: =+'[4]II-H-3.1'!E42+'[5]II-H-3.1'!E43 -> 330 | F48: =+'[4]II-H-3.1'!F42+'[5]II-H-3.1'!F43 -> 561 | G48: =+'[4]II-H-3.1'!G42+'[5]II-H-3.1'!G43 -> 290 | H48: =+'[4]II-H-3.1'!H42+'[5]II-H-3.1'!H43 -> 57 | I48: =+'[4]II-H-3.1'!I42+'[5]II-H-3.1'!I43 -> -126 | J48: =+'[4]II-H-3.1'!J42+'[5]II-H-3.1'!J43 -> -206 | K48: =+'[4]II-H-3.1'!K42+'[5]II-H-3.1'!K43 -> -507 | ... O48: =+'[4]II-H-3.1'!O42+'[5]II-H-3.1'!O43 -> 0 | P48: =SUM(D48:O48) -> -1259 | Q48: =P48/12 -> -104.91667
A50: 3 | B50: SECONDARY > 10 kW NCP | C50: SEC | D50: =+'[4]II-H-3.1'!D44+'[5]II-H-3.1'!D45 -> 2623 | E50: =+'[4]II-H-3.1'!E44+'[5]II-H-3.1'!E45 -> 1358 | F50: =+'[4]II-H-3.1'!F44+'[5]II-H-3.1'!F45 -> 617 | G50: =+'[4]II-H-3.1'!G44+'[5]II-H-3.1'!G45 -> 545 | H50: =+'[4]II-H-3.1'!H44+'[5]II-H-3.1'!H45 -> 633 | I50: =+'[4]II-H-3.1'!I44+'[5]II-H-3.1'!I45 -> 565 | J50: =+'[4]II-H-3.1'!J44+'[5]II-H-3.1'!J45 -> 424 | K50: =+'[4]II-H-3.1'!K44+'[5]II-H-3.1'!K45 -> 122 | ... O50: =+'[4]II-H-3.1'!O44+'[5]II-H-3.1'!O45 -> 0 | P50: =SUM(D50:O50) -> 7761 | Q50: =P50/12 -> 646.75
A51: 4 | B51: SECONDARY > 10 kW 4CP | C51: SEC | D51: =+'[4]II-H-3.1'!D45+'[5]II-H-3.1'!D46 -> -27 | E51: =+'[4]II-H-3.1'!E45+'[5]II-H-3.1'!E46 -> -28 | F51: =+'[4]II-H-3.1'!F45+'[5]II-H-3.1'!F46 -> -27 | G51: =+'[4]II-H-3.1'!G45+'[5]II-H-3.1'!G46 -> -24 | H51: =+'[4]II-H-3.1'!H45+'[5]II-H-3.1'!H46 -> -25 | I51: =+'[4]II-H-3.1'!I45+'[5]II-H-3.1'!I46 -> -16 | J51: =+'[4]II-H-3.1'!J45+'[5]II-H-3.1'!J46 -> -17 | K51: =+'[4]II-H-3.1'!K45+'[5]II-H-3.1'!K46 -> -19 | ... O51: =+'[4]II-H-3.1'!O45+'[5]II-H-3.1'!O46 -> 0 | P51: =SUM(D51:O51) -> -180 | Q51: =P51/12 -> -15
A52: 5 | B52: TOTAL SECONDARY > 10 kW | D52: =SUM(D50:D51) -> 2596 | E52: =SUM(E50:E51) -> 1330 | F52: =SUM(F50:F51) -> 590 | G52: =SUM(G50:G51) -> 521 | H52: =SUM(H50:H51) -> 608 | I52: =SUM(I50:I51) -> 549 | J52: =SUM(J50:J51) -> 407 | K52: =SUM(K50:K51) -> 103 | ... O52: =SUM(O50:O51) -> 0 | P52: =SUM(D52:O52) -> 7581 | Q52: =SUM(Q50:Q51) -> 631.75
A54: 6 | B54: PRIMARY NCP | C54: PRI | D54: =+'[4]II-H-3.1'!D48+'[5]II-H-3.1'!D49 -> 8 | E54: =+'[4]II-H-3.1'!E48+'[5]II-H-3.1'!E49 -> 9 | F54: =+'[4]II-H-3.1'!F48+'[5]II-H-3.1'!F49 -> 9 | G54: =+'[4]II-H-3.1'!G48+'[5]II-H-3.1'!G49 -> 14 | H54: =+'[4]II-H-3.1'!H48+'[5]II-H-3.1'!H49 -> 10 | I54: =+'[4]II-H-3.1'!I48+'[5]II-H-3.1'!I49 -> 2 | J54: =+'[4]II-H-3.1'!J48+'[5]II-H-3.1'!J49 -> 7 | K54: =+'[4]II-H-3.1'!K48+'[5]II-H-3.1'!K49 -> -6 | ... O54: =+'[4]II-H-3.1'!O48+'[5]II-H-3.1'!O49 -> 0 | P54: =SUM(D54:O54) -> 42 | Q54: =P54/12 -> 3.5
A55: 7 | B55: PRIMARY 4CP | C55: PRI | D55: =+'[4]II-H-3.1'!D49+'[5]II-H-3.1'!D50 -> 1 | E55: =+'[4]II-H-3.1'!E49+'[5]II-H-3.1'!E50 -> 1 | F55: =+'[4]II-H-3.1'!F49+'[5]II-H-3.1'!F50 -> -4 | G55: =+'[4]II-H-3.1'!G49+'[5]II-H-3.1'!G50 -> 7 | H55: =+'[4]II-H-3.1'!H49+'[5]II-H-3.1'!H50 -> -5 | I55: =+'[4]II-H-3.1'!I49+'[5]II-H-3.1'!I50 -> -9 | J55: =+'[4]II-H-3.1'!J49+'[5]II-H-3.1'!J50 -> -1 | K55: =+'[4]II-H-3.1'!K49+'[5]II-H-3.1'!K50 -> 3 | ... O55: =+'[4]II-H-3.1'!O49+'[5]II-H-3.1'!O50 -> 0 | P55: =SUM(D55:O55) -> -9 | Q55: =P55/12 -> -0.75
...

Sheet II-H-4.1 Monthly
B2: PUBLIC UTILITY COMMISSION OF TEXAS
B3: AEP TEXAS INC
B4: II-H-4.1 REVENUE IMPACTS MONTHLY
B5: TEST YEAR ENDING 12/31/2018
B6: DOCKET NUMBER (PENDING ASSIGNMENT)
B8: AEP TEXAS
B9: UNADJUSTED BILLED REVENUE
B10: FOR TEST YEAR ENDED DECEMBER 31, 2018
A13: LINE | B13: DESCRIPTION | C13: VOLT | D13: JANUARY | E13: FEBRUARY | F13: MARCH | G13: APRIL | H13: MAY | I13: JUNE | J13: JULY | K13: AUGUST | L13: SEPTEMBER | M13: OCTOBER | N13: NOVEMBER | O13: DECEMBER | P13: TOTAL
A15: 1 | B15: RESIDENTIAL SERVICE | C15: SEC | D15: ='[6]Sales of Elec'!F85+'[5]II-H-4.1 Monthly'!D8 -> 59562881 | E15: ='[6]Sales of Elec'!G85+'[5]II-H-4.1 Monthly'!E8 -> 46223915 | F15: ='[6]Sales of Elec'!H85+'[5]II-H-4.1 Monthly'!F8 -> 36481296 | G15: ='[6]Sales of Elec'!I85+'[5]II-H-4.1 Monthly'!G8 -> 37837457 | H15: ='[6]Sales of Elec'!J85+'[5]II-H-4.1 Monthly'!H8 -> 41112166 | I15: ='[6]Sales of Elec'!K85+'[5]II-H-4.1 Monthly'!I8 -> 58461559 | J15: ='[6]Sales of Elec'!L85+'[5]II-H-4.1 Monthly'!J8 -> 60803686 | K15: ='[6]Sales of Elec'!M85+'[5]II-H-4.1 Monthly'!K8 -> 61629222 | ... O15: ='[6]Sales of Elec'!Q85+'[5]II-H-4.1 Monthly'!O8 -> 43224125 | P15: =SUM(D15:O15) -> 5.940381e+08
A17: 2 | B17: SECONDARY < 10 kW | C17: SEC | D17: ='[6]Sales of Elec'!F12+'[5]II-H-4.1 Monthly'!D10 -> 4017775.7 | E17: ='[6]Sales of Elec'!G12+'[5]II-H-4.1 Monthly'!E10 -> 3527136.3 | F17: ='[6]Sales of Elec'!H12+'[5]II-H-4.1 Monthly'!F10 -> 3367785.1 | G17: ='[6]Sales of Elec'!I12+'[5]II-H-4.1 Monthly'!G10 -> 3473543.3 | H17: ='[6]Sales of Elec'!J12+'[5]II-H-4.1 Monthly'!H10 -> 3520682.9 | I17: ='[6]Sales of Elec'!K12+'[5]II-H-4.1 Monthly'!I10 -> 4069750.4 | J17: ='[6]Sales of Elec'!L12+'[5]II-H-4.1 Monthly'!J10 -> 4143613.9 | K17: ='[6]Sales of Elec'!M12+'[5]II-H-4.1 Monthly'!K10 -> 4161293.4 | ... O17: ='[6]Sales of Elec'!Q12+'[5]II-H-4.1 Monthly'!O10 -> 3476509.3 | P17: =SUM(D17:O17) -> 44821473
A19: 3 | B19: SECONDARY > 10 kW NCP | C19: SEC | D19: ='[6]Sales of Elec'!F30+'[5]II-H-4.1 Monthly'!D12 -> 29523362 | E19: ='[6]Sales of Elec'!G30+'[5]II-H-4.1 Monthly'!E12 -> 28956586 | F19: ='[6]Sales of Elec'!H30+'[5]II-H-4.1 Monthly'!F12 -> 27785575 | G19: ='[6]Sales of Elec'!I30+'[5]II-H-4.1 Monthly'!G12 -> 27734369 | H19: ='[6]Sales of Elec'!J30+'[5]II-H-4.1 Monthly'!H12 -> 28220722 | I19: ='[6]Sales of Elec'!K30+'[5]II-H-4.1 Monthly'!I12 -> 30198895 | J19: ='[6]Sales of Elec'!L30+'[5]II-H-4.1 Monthly'!J12 -> 30022349 | K19: ='[6]Sales of Elec'!M30+'[5]II-H-4.1 Monthly'!K12 -> 30408070 | ... O19: ='[6]Sales of Elec'!Q30+'[5]II-H-4.1 Monthly'!O12 -> 27601159 | P19: =SUM(D19:O19) -> 3.466567e+08
A20: 4 | B20: SECONDARY > 10 kW 4CP | C20: SEC | D20: ='[6]Sales of Elec'!F21+'[5]II-H-4.1 Monthly'!D13 -> 2751168.4 | E20: ='[6]Sales of Elec'!G21+'[5]II-H-4.1 Monthly'!E13 -> 2680446.6 | F20: ='[6]Sales of Elec'!H21+'[5]II-H-4.1 Monthly'!F13 -> 2602449.6 | G20: ='[6]Sales of Elec'!I21+'[5]II-H-4.1 Monthly'!G13 -> 2576572.6 | H20: ='[6]Sales of Elec'!J21+'[5]II-H-4.1 Monthly'!H13 -> 2595536.4 | I20: ='[6]Sales of Elec'!K21+'[5]II-H-4.1 Monthly'!I13 -> 2560709.3 | J20: ='[6]Sales of Elec'!L21+'[5]II-H-4.1 Monthly'!J13 -> 2650227 | K20: ='[6]Sales of Elec'!M21+'[5]II-H-4.1 Monthly'!K13 -> 2729544.8 | ... O20: ='[6]Sales of Elec'!Q21+'[5]II-H-4.1 Monthly'!O13 -> 2551472.5 | P20: =SUM(D20:O20) -> 31960019
A21: 5 | B21: TOTAL SECONDARY > 10 kW | D21: =SUM(D19:D20) -> 32274530 | E21: =SUM(E19:E20) -> 31637032 | F21: =SUM(F19:F20) -> 30388024 | G21: =SUM(G19:G20) -> 30310942 | H21: =SUM(H19:H20) -> 30816258 | I21: =SUM(I19:I20) -> 32759604 | J21: =SUM(J19:J20) -> 32672576 | K21: =SUM(K19:K20) -> 33137615 | ... P21: =SUM(P19:P20) -> 3.7861672e+08
A23: 6 | B23: PRIMARY NCP | C23: PRI | D23: ='[6]Sales of Elec'!F82+'[5]II-H-4.1 Monthly'!D16 -> 666902.32 | E23: ='[6]Sales of Elec'!G82+'[5]II-H-4.1 Monthly'!E16 -> 677520.78 | F23: ='[6]Sales of Elec'!H82+'[5]II-H-4.1 Monthly'!F16 -> 652064.27 | G23: ='[6]Sales of Elec'!I82+'[5]II-H-4.1 Monthly'!G16 -> 674447.48 | H23: ='[6]Sales of Elec'!J82+'[5]II-H-4.1 Monthly'!H16 -> 699770.27 | I23: ='[6]Sales of Elec'!K82+'[5]II-H-4.1 Monthly'!I16 -> 728477.63 | J23: ='[6]Sales of Elec'!L82+'[5]II-H-4.1 Monthly'!J16 -> 708664.35 | K23: ='[6]Sales of Elec'!M82+'[5]II-H-4.1 Monthly'!K16 -> 771698.32 | ... O23: ='[6]Sales of Elec'!Q82+'[5]II-H-4.1 Monthly'!O16 -> 732600.22 | P23: =SUM(D23:O23) -> 8725085
A24: 7 | B24: PRIMARY 4CP | C24: PRI | D24: ='[6]Sales of Elec'!F77+'[5]II-H-4.1 Monthly'!D17 -> 6997307.2 | E24: ='[6]Sales of Elec'!G77+'[5]II-H-4.1 Monthly'!E17 -> 6686883.6 | F24: ='[6]Sales of Elec'!H77+'[5]II-H-4.1 Monthly'!F17 -> 6771838.6 | G24: ='[6]Sales of Elec'!I77+'[5]II-H-4.1 Monthly'!G17 -> 6632990.7 | H24: ='[6]Sales of Elec'!J77+'[5]II-H-4.1 Monthly'!H17 -> 7112153.5 | I24: ='[6]Sales of Elec'!K77+'[5]II-H-4.1 Monthly'!I17 -> 7260254.1 | J24: ='[6]Sales of Elec'!L77+'[5]II-H-4.1 Monthly'!J17 -> 7111674.3 | K24: ='[6]Sales of Elec'!M77+'[5]II-H-4.1 Monthly'!K17 -> 7042631.6 | ... O24: ='[6]Sales of Elec'!Q77+'[5]II-H-4.1 Monthly'!O17 -> 6592901.7 | P24: =SUM(D24:O24) -> 83153991
A25: 8 | B25: TOTAL PRIMARY | D25: =SUM(D23:D24) -> 7664209.5 | E25: =SUM(E23:E24) -> 7364404.4 | F25: =SUM(F23:F24) -> 7423902.9 | G25: =SUM(G23:G24) -> 7307438.2 | H25: =SUM(H23:H24) -> 7811923.8 | I25: =SUM(I23:I24) -> 7988731.8 | J25: =SUM(J23:J24) -> 7820338.7 | K25: =SUM(K23:K24) -> 7814330 | ... P25: =SUM(P23:P24) -> 91879076
A27: 9 | B27: TRANSMISSION | C27: TRA | D27: ='[6]Sales of Elec'!F97+'[5]II-H-4.1 Monthly'!D20 -> 5167460.3 | E27: ='[6]Sales of Elec'!G97+'[5]II-H-4.1 Monthly'!E20 -> 3802453.8 | F27: ='[6]Sales of Elec'!H97+'[5]II-H-4.1 Monthly'!F20 -> 4561676.1 | G27: ='[6]Sales of Elec'!I97+'[5]II-H-4.1 Monthly'!G20 -> 4154398.8 | H27: ='[6]Sales of Elec'!J97+'[5]II-H-4.1 Monthly'!H20 -> 4347111.8 | I27: ='[6]Sales of Elec'!K97+'[5]II-H-4.1 Monthly'!I20 -> 4738061.7 | J27: ='[6]Sales of Elec'!L97+'[5]II-H-4.1 Monthly'!J20 -> 3729155.4 | K27: ='[6]Sales of Elec'!M97+'[5]II-H-4.1 Monthly'!K20 -> 3862540.2 | ... O27: ='[6]Sales of Elec'!Q97+'[5]II-H-4.1 Monthly'!O20 -> 2625361.6 | P27: =SUM(D27:O27) -> 49149052
A29: 10 | B29: LIGHTING | C29: SEC | D29: ='[6]Sales of Elec'!F71+'[5]II-H-4.1 Monthly'!D22 -> 2206674.3 | E29: ='[6]Sales of Elec'!G71+'[5]II-H-4.1 Monthly'!E22 -> 2199185 | F29: ='[6]Sales of Elec'!H71+'[5]II-H-4.1 Monthly'!F22 -> 2196843.5 | G29: ='[6]Sales of Elec'!I71+'[5]II-H-4.1 Monthly'!G22 -> 2198649.6 | H29: ='[6]Sales of Elec'!J71+'[5]II-H-4.1 Monthly'!H22 -> 2197657.9 | I29: ='[6]Sales of Elec'!K71+'[5]II-H-4.1 Monthly'!I22 -> 2198275 | J29: ='[6]Sales of Elec'!L71+'[5]II-H-4.1 Monthly'!J22 -> 2198643.7 | K29: ='[6]Sales of Elec'!M71+'[5]II-H-4.1 Monthly'!K22 -> 2197724.8 | ... O29: ='[6]Sales of Elec'!Q71+'[5]II-H-4.1 Monthly'!O22 -> 2149235.6 | P29: =SUM(D29:O29) -> 26176142
A31: 11 | B31: TOTAL RETAIL | D31: =D29+D27+D25+D21+D17+D15 -> 1.1089353e+08 | E31: =E29+E27+E25+E21+E17+E15 -> 94754126 | F31: =F29+F27+F25+F21+F17+F15 -> 84419528 | G31: =G29+G27+G25+G21+G17+G15 -> 85282429 | H31: =H29+H27+H25+H21+H17+H15 -> 89805801 | I31: =I29+I27+I25+I21+I17+I15 -> 1.1021598e+08 | J31: =J29+J27+J25+J21+J17+J15 -> 1.1136801e+08 | K31: =K29+K27+K25+K21+K17+K15 -> 1.1280272e+08 | ... P31: =P29+P27+P25+P21+P17+P15 -> 1.1846806e+09
A33: 12 | B33: WHOLESALE PRI | C33: PRI | P33: =SUM(D33:O33) -> 0
A34: 13 | B34: WHOLESALE TRANS | C34: TRA | P34: =SUM(D34:O34) -> 0
A35: 14 | B35: TOTAL WHOLESALE | D35: =SUM(D33:D34) -> 0 | E35: =SUM(E33:E34) -> 0 | F35: =SUM(F33:F34) -> 0 | G35: =SUM(G33:G34) -> 0 | H35: =SUM(H33:H34) -> 0 | I35: =SUM(I33:I34) -> 0 | J35: =SUM(J33:J34) -> 0 | K35: =SUM(K33:K34) -> 0 | ... P35: =SUM(P33:P34) -> 0
A37: 15 | B37: TOTAL AEP TEXAS | D37: =+D35+D31 -> 1.1089353e+08 | E37: =+E35+E31 -> 94754126 | F37: =+F35+F31 -> 84419528 | G37: =+G35+G31 -> 85282429 | H37: =+H35+H31 -> 89805801 | I37: =+I35+I31 -> 1.1021598e+08 | J37: =+J35+J31 -> 1.1136801e+08 | K37: =+K35+K31 -> 1.1280272e+08 | ... P37: =+P35+P31 -> 1.1846806e+09
B41: AEP TEXAS
B42: TRANSMISSION SYSTEM CHARGE ADJUSTMENT
B43: =B10 -> FOR TEST YEAR ENDED DECEMBER 31, 2018
A46: LINE | B46: DESCRIPTION | C46: VOLT | D46: =+D13 -> JANUARY | E46: =+E13 -> FEBRUARY | F46: =+F13 -> MARCH | G46: =+G13 -> APRIL | H46: =+H13 -> MAY | I46: =+I13 -> JUNE | J46: =+J13 -> JULY | K46: =+K13 -> AUGUST | ... O46: =+O13 -> DECEMBER | P46: TOTAL
A48: 1 | B48: RESIDENTIAL SERVICE | C48: SEC | D48: =-'[6]TCC Sales Elec Base Rate Dist T'!T166+'[5]II-H-4.1 Monthly'!D40 -> -6288378.5 | E48: =-'[6]TCC Sales Elec Base Rate Dist T'!U166+'[5]II-H-4.1 Monthly'!E40 -> -4665888.2 | F48: =-'[6]TCC Sales Elec Base Rate Dist T'!V166+'[5]II-H-4.1 Monthly'!F40 -> -3721823.7 | G48: =-'[6]TCC Sales Elec Base Rate Dist T'!W166+'[5]II-H-4.1 Monthly'!G40 -> -3889921.1 | H48: =-'[6]TCC Sales Elec Base Rate Dist T'!X166+'[5]II-H-4.1 Monthly'!H40 -> -4318220.9 | I48: =-'[6]TCC Sales Elec Base Rate Dist T'!Y166+'[5]II-H-4.1 Monthly'!I40 -> -6599540.8 | J48: =-'[6]TCC Sales Elec Base Rate Dist T'!Z166+'[5]II-H-4.1 Monthly'!J40 -> -6920597.2 | K48: =-'[6]TCC Sales Elec Base Rate Dist T'!AA166+'[5]II-H-4.1 Monthly'!K40 -> -7016731.2 | ... O48: =-'[6]TCC Sales Elec Base Rate Dist T'!AE166+'[5]II-H-4.1 Monthly'!O40 -> -4533211.2 | P48: =SUM(D48:O48) -> -63989339
A50: 2 | B50: SECONDARY < 10 kW | C50: SEC | D50: =-'[6]TCC Sales Elec Base Rate Dist T'!T19+'[5]II-H-4.1 Monthly'!D42 -> -140145.56 | E50: =-'[6]TCC Sales Elec Base Rate Dist T'!U19+'[5]II-H-4.1 Monthly'!E42 -> -117930.87 | F50: =-'[6]TCC Sales Elec Base Rate Dist T'!V19+'[5]II-H-4.1 Monthly'!F42 -> -110616.65 | G50: =-'[6]TCC Sales Elec Base Rate Dist T'!W19+'[5]II-H-4.1 Monthly'!G42 -> -115048.78 | H50: =-'[6]TCC Sales Elec Base Rate Dist T'!X19+'[5]II-H-4.1 Monthly'!H42 -> -117104.3 | I50: =-'[6]TCC Sales Elec Base Rate Dist T'!Y19+'[5]II-H-4.1 Monthly'!I42 -> -143402.29 | J50: =-'[6]TCC Sales Elec Base Rate Dist T'!Z19+'[5]II-H-4.1 Monthly'!J42 -> -147396.09 | K50: =-'[6]TCC Sales Elec Base Rate Dist T'!AA19+'[5]II-H-4.1 Monthly'!K42 -> -148004.46 | ... O50: =-'[6]TCC Sales Elec Base Rate Dist T'!AE19+'[5]II-H-4.1 Monthly'!O42 -> -120066.44 | P50: =SUM(D50:O50) -> -1548795.4
A52: 3 | B52: SECONDARY > 10 kW NCP | C52: SEC | D52: =-'[6]TCC Sales Elec Base Rate Dist T'!T55+'[5]II-H-4.1 Monthly'!D44 -> -3196595.3 | E52: =-'[6]TCC Sales Elec Base Rate Dist T'!U55+'[5]II-H-4.1 Monthly'!E44 -> -3141242.8 | F52: =-'[6]TCC Sales Elec Base Rate Dist T'!V55+'[5]II-H-4.1 Monthly'!F44 -> -2965288.4 | G52: =-'[6]TCC Sales Elec Base Rate Dist T'!W55+'[5]II-H-4.1 Monthly'!G44 -> -2860064.6 | H52: =-'[6]TCC Sales Elec Base Rate Dist T'!X55+'[5]II-H-4.1 Monthly'!H44 -> -2927905.4 | I52: =-'[6]TCC Sales Elec Base Rate Dist T'!Y55+'[5]II-H-4.1 Monthly'!I44 -> -3123318.5 | J52: =-'[6]TCC Sales Elec Base Rate Dist T'!Z55+'[5]II-H-4.1 Monthly'!J44 -> -3088594.9 | K52: =-'[6]TCC Sales Elec Base Rate Dist T'!AA55+'[5]II-H-4.1 Monthly'!K44 -> -3137089.5 | ... O52: =-'[6]TCC Sales Elec Base Rate Dist T'!AE55+'[5]II-H-4.1 Monthly'!O44 -> -3015447.4 | P52: =SUM(D52:O52) -> -36701168
A53: 4 | B53: SECONDARY > 10 kW 4CP | C53: SEC | D53: =-'[6]TCC Sales Elec Base Rate Dist T'!T37+'[5]II-H-4.1 Monthly'!D45 -> -351612.37 | E53: =-'[6]TCC Sales Elec Base Rate Dist T'!U37+'[5]II-H-4.1 Monthly'!E45 -> -347078.54 | F53: =-'[6]TCC Sales Elec Base Rate Dist T'!V37+'[5]II-H-4.1 Monthly'!F45 -> -349584.7 | G53: =-'[6]TCC Sales Elec Base Rate Dist T'!W37+'[5]II-H-4.1 Monthly'!G45 -> -345585.25 | H53: =-'[6]TCC Sales Elec Base Rate Dist T'!X37+'[5]II-H-4.1 Monthly'!H45 -> -349271.97 | I53: =-'[6]TCC Sales Elec Base Rate Dist T'!Y37+'[5]II-H-4.1 Monthly'!I45 -> -328297.44 | J53: =-'[6]TCC Sales Elec Base Rate Dist T'!Z37+'[5]II-H-4.1 Monthly'!J45 -> -350442.32 | K53: =-'[6]TCC Sales Elec Base Rate Dist T'!AA37+'[5]II-H-4.1 Monthly'!K45 -> -340313.07 | ... O53: =-'[6]TCC Sales Elec Base Rate Dist T'!AE37+'[5]II-H-4.1 Monthly'!O45 -> -343486.19 | P53: =SUM(D53:O53) -> -4133847.1
A54: 5 | B54: TOTAL SECONDARY > 10 kW | D54: =SUM(D52:D53) -> -3548207.7 | E54: =SUM(E52:E53) -> -3488321.4 | F54: =SUM(F52:F53) -> -3314873.1 | G54: =SUM(G52:G53) -> -3205649.8 | H54: =SUM(H52:H53) -> -3277177.3 | I54: =SUM(I52:I53) -> -3451615.9 | J54: =SUM(J52:J53) -> -3439037.2 | K54: =SUM(K52:K53) -> -3477402.6 | ... P54: =SUM(P52:P53) -> -40835015
A56: 6 | B56: PRIMARY NCP | C56: PRI | D56: =-'[6]TCC Sales Elec Base Rate Dist T'!T160+'[5]II-H-4.1 Monthly'!D48 -> -80996.35 | E56: =-'[6]TCC Sales Elec Base Rate Dist T'!U160+'[5]II-H-4.1 Monthly'!E48 -> -88502.84 | F56: =-'[6]TCC Sales Elec Base Rate Dist T'!V160+'[5]II-H-4.1 Monthly'!F48 -> -82625.69 | G56: =-'[6]TCC Sales Elec Base Rate Dist T'!W160+'[5]II-H-4.1 Monthly'!G48 -> -85888.65 | H56: =-'[6]TCC Sales Elec Base Rate Dist T'!X160+'[5]II-H-4.1 Monthly'!H48 -> -92163.95 | I56: =-'[6]TCC Sales Elec Base Rate Dist T'!Y160+'[5]II-H-4.1 Monthly'!I48 -> -97019.97 | J56: =-'[6]TCC Sales Elec Base Rate Dist T'!Z160+'[5]II-H-4.1 Monthly'!J48 -> -93002.55 | K56: =-'[6]TCC Sales Elec Base Rate Dist T'!AA160+'[5]II-H-4.1 Monthly'!K48 -> -106513.46 | ... O56: =-'[6]TCC Sales Elec Base Rate Dist T'!AE160+'[5]II-H-4.1 Monthly'!O48 -> -91481.58 | P56: =SUM(D56:O56) -> -1127710.6
A57: 7 | B57: PRIMARY 4CP | C57: PRI | D57: =-'[6]TCC Sales Elec Base Rate Dist T'!T150+'[5]II-H-4.1 Monthly'!D49 -> -1119691.8 | E57: =-'[6]TCC Sales Elec Base Rate Dist T'!U150+'[5]II-H-4.1 Monthly'!E49 -> -1085094.4 | F57: =-'[6]TCC Sales Elec Base Rate Dist T'!V150+'[5]II-H-4.1 Monthly'!F49 -> -1077634.8 | G57: =-'[6]TCC Sales Elec Base Rate Dist T'!W150+'[5]II-H-4.1 Monthly'!G49 -> -1039649.4 | H57: =-'[6]TCC Sales Elec Base Rate Dist T'!X150+'[5]II-H-4.1 Monthly'!H49 -> -1103622.5 | I57: =-'[6]TCC Sales Elec Base Rate Dist T'!Y150+'[5]II-H-4.1 Monthly'!I49 -> -1093973.3 | J57: =-'[6]TCC Sales Elec Base Rate Dist T'!Z150+'[5]II-H-4.1 Monthly'!J49 -> -1082501.7 | K57: =-'[6]TCC Sales Elec Base Rate Dist T'!AA150+'[5]II-H-4.1 Monthly'!K49 -> -1076152.8 | ... O57: =-'[6]TCC Sales Elec Base Rate Dist T'!AE150+'[5]II-H-4.1 Monthly'!O49 -> -1046925.7 | P57: =SUM(D57:O57) -> -12989907
A58: 8 | B58: TOTAL PRIMARY | D58: =SUM(D56:D57) -> -1200688.2 | E58: =SUM(E56:E57) -> -1173597.3 | F58: =SUM(F56:F57) -> -1160260.5 | G58: =SUM(G56:G57) -> -1125538 | H58: =SUM(H56:H57) -> -1195786.4 | I58: =SUM(I56:I57) -> -1190993.3 | J58: =SUM(J56:J57) -> -1175504.2 | K58: =SUM(K56:K57) -> -1182666.3 | ... P58: =SUM(P56:P57) -> -14117617
A60: 9 | B60: TRANSMISSION | C60: TRA | D60: =-'[6]TCC Sales Elec Base Rate Dist T'!T190+'[5]II-H-4.1 Monthly'!D52 -> -1139916.5 | E60: =-'[6]TCC Sales Elec Base Rate Dist T'!U190+'[5]II-H-4.1 Monthly'!E52 -> -799631.29 | F60: =-'[6]TCC Sales Elec Base Rate Dist T'!V190+'[5]II-H-4.1 Monthly'!F52 -> -960719.01 | G60: =-'[6]TCC Sales Elec Base Rate Dist T'!W190+'[5]II-H-4.1 Monthly'!G52 -> -837829.32 | H60: =-'[6]TCC Sales Elec Base Rate Dist T'!X190+'[5]II-H-4.1 Monthly'!H52 -> -893336.29 | I60: =-'[6]TCC Sales Elec Base Rate Dist T'!Y190+'[5]II-H-4.1 Monthly'!I52 -> -1008355.8 | J60: =-'[6]TCC Sales Elec Base Rate Dist T'!Z190+'[5]II-H-4.1 Monthly'!J52 -> -746546.03 | K60: =-'[6]TCC Sales Elec Base Rate Dist T'!AA190+'[5]II-H-4.1 Monthly'!K52 -> -767426.25 | ... O60: =-'[6]TCC Sales Elec Base Rate Dist T'!AE190+'[5]II-H-4.1 Monthly'!O52 -> -597428.16 | P60: =SUM(D60:O60) -> -10529707
A62: 10 | B62: LIGHTING | C62: SEC | D62: =-'[6]TCC Sales Elec Base Rate Dist T'!T138+'[5]II-H-4.1 Monthly'!D54 -> -57128.99 | E62: =-'[6]TCC Sales Elec Base Rate Dist T'!U138+'[5]II-H-4.1 Monthly'!E54 -> -56917.81 | F62: =-'[6]TCC Sales Elec Base Rate Dist T'!V138+'[5]II-H-4.1 Monthly'!F54 -> -57059.29 | G62: =-'[6]TCC Sales Elec Base Rate Dist T'!W138+'[5]II-H-4.1 Monthly'!G54 -> -57105.29 | H62: =-'[6]TCC Sales Elec Base Rate Dist T'!X138+'[5]II-H-4.1 Monthly'!H54 -> -57062.17 | I62: =-'[6]TCC Sales Elec Base Rate Dist T'!Y138+'[5]II-H-4.1 Monthly'!I54 -> -57057.64 | J62: =-'[6]TCC Sales Elec Base Rate Dist T'!Z138+'[5]II-H-4.1 Monthly'!J54 -> -57070.98 | K62: =-'[6]TCC Sales Elec Base Rate Dist T'!AA138+'[5]II-H-4.1 Monthly'!K54 -> -57050.55 | ... O62: =-'[6]TCC Sales Elec Base Rate Dist T'!AE138+'[5]II-H-4.1 Monthly'!O54 -> -57040.58 | P62: =SUM(D62:O62) -> -684721.79
A64: 11 | B64: TOTAL RETAIL | D64: =D62+D60+D58+D54+D50+D48 -> -12374465 | E64: =E62+E60+E58+E54+E50+E48 -> -10302287 | F64: =F62+F60+F58+F54+F50+F48 -> -9325352.3 | G64: =G62+G60+G58+G54+G50+G48 -> -9231092.4 | H64: =H62+H60+H58+H54+H50+H48 -> -9858687.5 | I64: =I62+I60+I58+I54+I50+I48 -> -12450966 | J64: =J62+J60+J58+J54+J50+J48 -> -12486152 | K64: =K62+K60+K58+K54+K50+K48 -> -12649281 | ... P64: =P62+P60+P58+P54+P50+P48 -> -1.317052e+08
A66: 12 | B66: WHOLESALE PRI | C66: PRI | P66: =SUM(D66:O66) -> 0
...

Sheet II-H-4.1 Functions
B2: PUBLIC UTILITY COMMISSION OF TEXAS
B3: AEP TEXAS INC
B4: II-H-4.1 REVENUE IMPACTS FUNCTIONS
B5: TEST YEAR ENDING 12/31/2018
B6: DOCKET NUMBER (PENDING ASSIGNMENT)
A8: AEP TEXAS
A9: UNADJUSTED BILLED REVENUE
A10: FOR TEST YEAR ENDED DECEMBER 31, 2018
A13: LINE | B13: DESCRIPTION | C13: VOLT | D13: Customer Revenue - Base Tariff | E13: Meter Revenue - Base Tariff | F13: Distribution Service Revenue - Base Tariff | G13: Facilities Charge | H13: Transmission Service Revenue - Base Tariff | I13: Total Base Tariff Revenue | K13: Energy Efficiency Rider | L13: Transition Charge Riders (TC) | M13: DCRF | N13: Competitive Metering Rider | O13: Transmission Cost Recovery Rider (TCRF) | P13: State Colleges and Universities Discount Rider | Q13: Advanced Metering Recovery Rider | R13: Misc Riders | S13: Total Riders | U13: Total Revenue
W14: EECRF in base rates
A15: 1 | B15: RESIDENTIAL SERVICE | C15: SEC | D15: ='[6]TCC Sales Elec Base Rate Custom'!$T$71+'[5]II-H-4.1 Functions'!$D$8 -> 32912479 | E15: ='[6]TCC Sales Elec Base Rate Meter '!$T$40+'[5]II-H-4.1 Functions'!$E$8 -> 40180077 | F15: =SUM('[6]TCC Sales Elec Base Rate Dist T'!$H$166:$S$166)+'[5]II-H-4.1 Functions'!$F$8 -> 1.781707e+08 | H15: =SUM('[6]TCC Sales Elec Base Rate Dist T'!$T$166:$AE$166)+'[5]II-H-4.1 Functions'!$H$8 -> 63989339 | I15: =H15+F15+E15+D15+G15 -> 3.152526e+08 | K15: =-'II-H-4.1 Monthly'!P113 -> 6852076.5 | L15: =-'II-H-4.1 Monthly'!P146 -> 1.1474721e+08 | M15: =-'II-H-4.1 Monthly'!P336 -> 38120918 | N15: =-'II-H-4.1 Monthly'!P179 -> 0 | O15: =-'II-H-4.1 Monthly'!P305 -> 95799428 | P15: =-'II-H-4.1 Monthly'!P212 -> -8840.33 | Q15: =-'II-H-4.1 Monthly'!P243 -> 23799602 | R15: =-'II-H-4.1 Monthly'!P274 -> -524890.6 | S15: =SUM(K15:R15) -> 2.787855e+08 | U15: =S15+I15 -> 5.940381e+08 | W15: =-F49/F15 -> 0.024483062
A17: 2 | B17: SECONDARY < 10 kW | C17: SEC | D17: ='[6]TCC Sales Elec Base Rate Custom'!$T$11+'[5]II-H-4.1 Functions'!$D$10 -> 3738616.9 | E17: ='[6]TCC Sales Elec Base Rate Meter '!$T$8+'[5]II-H-4.1 Functions'!$E$10 -> 5038057.2 | F17: =SUM('[6]TCC Sales Elec Base Rate Dist T'!$H$19:$S$19)+'[5]II-H-4.1 Functions'!$F$10 -> 11328181 | H17: =SUM('[6]TCC Sales Elec Base Rate Dist T'!$T$19:$AE$19)+'[5]II-H-4.1 Functions'!$H$10 -> 1548795.4 | I17: =H17+F17+E17+D17+G17 -> 21653651 | K17: =-'II-H-4.1 Monthly'!P115 -> 139559 | L17: =-'II-H-4.1 Monthly'!P148 -> 10869601 | M17: =-'II-H-4.1 Monthly'!P338 -> 5077510 | N17: =-'II-H-4.1 Monthly'!P181 -> 0 | O17: =-'II-H-4.1 Monthly'!P307 -> 2695807 | P17: =-'II-H-4.1 Monthly'!P214 -> -7355.89 | Q17: =-'II-H-4.1 Monthly'!P245 -> 4429023.3 | R17: =-'II-H-4.1 Monthly'!P276 -> -36322.54 | S17: =SUM(K17:R17) -> 23167822 | U17: =S17+I17 -> 44821473 | W17: =-F51/F17 -> 0.014187966
I18: =H18+F18+E18+D18+G18 -> 0
A19: 3 | B19: SECONDARY > 10 kW NCP | C19: SEC | D19: ='[6]TCC Sales Elec Base Rate Custom'!$T$29+'[5]II-H-4.1 Functions'!$D$12 -> 2974475.1 | E19: ='[6]TCC Sales Elec Base Rate Meter '!$T$26+'[5]II-H-4.1 Functions'!$E$12 -> 14108041 | F19: =SUM('[6]TCC Sales Elec Base Rate Dist T'!$H$55:$S$55)+'[5]II-H-4.1 Functions'!$F$12 -> 1.0895568e+08 | G19: 0 | H19: =SUM('[6]TCC Sales Elec Base Rate Dist T'!$T$55:$AE$55)+'[5]II-H-4.1 Functions'!$H$12 -> 36701168 | I19: =H19+F19+E19+D19+G19 -> 1.6273936e+08 | K19: =-'II-H-4.1 Monthly'!P117 -> 3502203.9 | L19: =-'II-H-4.1 Monthly'!P150 -> 97782094 | M19: =-'II-H-4.1 Monthly'!P340 -> 21514316 | N19: =-'II-H-4.1 Monthly'!P183 -> 0 | O19: =-'II-H-4.1 Monthly'!P309 -> 59877725 | P19: =-'II-H-4.1 Monthly'!P216 -> -162767.7 | Q19: =-'II-H-4.1 Monthly'!P247 -> 1671203.2 | R19: =-'II-H-4.1 Monthly'!P278 -> -272150.19 | S19: =SUM(K19:R19) -> 1.8391262e+08 | U19: =S19+I19 -> 3.4665199e+08 | W19: =-F53/F19 -> 0.023489827
A20: 4 | B20: SECONDARY > 10 kW 4CP | C20: SEC | D20: ='[6]TCC Sales Elec Base Rate Custom'!$T$20+'[5]II-H-4.1 Functions'!$D$13 -> 157765.39 | E20: ='[6]TCC Sales Elec Base Rate Meter '!$T$17+'[5]II-H-4.1 Functions'!$E$13 -> 131323.72 | F20: =SUM('[6]TCC Sales Elec Base Rate Dist T'!$H$37:$S$37)+'[5]II-H-4.1 Functions'!$F$13 -> 11243079 | H20: =SUM('[6]TCC Sales Elec Base Rate Dist T'!$T$37:$AE$37)+'[5]II-H-4.1 Functions'!$H$13 -> 4133847.1 | I20: =H20+F20+E20+D20+G20 -> 15666015 | K20: =-'II-H-4.1 Monthly'!P118 -> 556575.63 | L20: =-'II-H-4.1 Monthly'!P151 -> 8300549.9 | M20: =-'II-H-4.1 Monthly'!P341 -> 2276327.2 | N20: =-'II-H-4.1 Monthly'!P184 -> 0 | O20: =-'II-H-4.1 Monthly'!P310 -> 5232800 | P20: =-'II-H-4.1 Monthly'!P217 -> -46593.72 | Q20: ='II-H-4.1 Monthly'!P248 -> 0 | R20: =-'II-H-4.1 Monthly'!P279 -> -25654.91 | S20: =SUM(K20:R20) -> 16294004 | U20: =S20+I20 -> 31960019 | W20: =-F54/F20 -> 0.022712337
A21: 5 | B21: TOTAL SECONDARY > 10 kW | D21: =SUM(D19:D20) -> 3132240.5 | E21: =SUM(E19:E20) -> 14239365 | F21: =SUM(F19:F20) -> 1.2019876e+08 | H21: =SUM(H19:H20) -> 40835015 | I21: =SUM(I19:I20) -> 1.7840538e+08 | K21: =SUM(K19:K20) -> 4058779.6 | L21: =SUM(L19:L20) -> 1.0608264e+08 | M21: =SUM(M19:M20) -> 23790643 | N21: =SUM(N19:N20) -> 0 | O21: =SUM(O19:O20) -> 65110525 | P21: =SUM(P19:P20) -> -209361.42 | Q21: =SUM(Q19:Q20) -> 1671203.2 | R21: =SUM(R19:R20) -> -297805.1 | S21: =SUM(S19:S20) -> 2.0020663e+08 | U21: =S21+I21 -> 3.7861201e+08
A23: 6 | B23: PRIMARY NCP | C23: PRI | D23: ='[6]TCC Sales Elec Base Rate Custom'!$T$68+'[5]II-H-4.1 Functions'!$D$16 -> 27922.93 | E23: ='[6]TCC Sales Elec Base Rate Meter '!$T$37+'[5]II-H-4.1 Functions'!$E$16 -> 1043237.1 | F23: =SUM('[6]TCC Sales Elec Base Rate Dist T'!$H$160:$S$160)+'[5]II-H-4.1 Functions'!$F$16 -> 2316816.5 | H23: =SUM('[6]TCC Sales Elec Base Rate Dist T'!$T$160:$AE$160)+'[5]II-H-4.1 Functions'!$H$16 -> 1127710.6 | I23: =H23+F23+E23+D23+G23 -> 4515687.1 | K23: =-'II-H-4.1 Monthly'!P121 -> 66719.89 | L23: =-'II-H-4.1 Monthly'!P154 -> 1755313.7 | M23: =-'II-H-4.1 Monthly'!P344 -> 385027.52 | N23: =-'II-H-4.1 Monthly'!P187 -> 0 | O23: =-'II-H-4.1 Monthly'!P313 -> 2051920.4 | P23: =-'II-H-4.1 Monthly'!P220 -> -24669.7 | Q23: =-'II-H-4.1 Monthly'!P251 -> -16292.98 | R23: =-'II-H-4.1 Monthly'!P282 -> -8620.99 | S23: =SUM(K23:R23) -> 4209397.9 | U23: =S23+I23 -> 8725085 | W23: =-F57/F23 -> 0.036262894
