Workbook

Sheet (a-c) AEP TX Mtrd kW Adj
B2: PUBLIC UTILITY COMMISSION OF TEXAS
B3: AEP TEXAS INC
B4: IV-J-5 BILLING DETERMINANTS
B5: TEST YEAR ENDING 12/31/2018
B6: DOCKET NUMBER (PENDING ASSIGNMENT)
B9: NOTE: Please see Schedule II-H-4.1 Tab "Dist kW" and "Trans kW" for Billing Demands and Adjustments.
B11: METERED KW
B12: TARF_CD | C12: MKW_JAN18 | D12: MKW_FEB18 | E12: MKW_MAR18 | F12: MKW_APR18 | G12: MKW_MAY18 | H12: MKW_JUN18 | I12: MKW_JUL18 | J12: MKW_AUG18 | K12: MKW_SEP18 | L12: MKW_OCT18 | M12: MKW_NOV18 | N12: MKW_DEC18 | O12: MKW_TOTAL
B13: Total Sec > 10 kW NCP | C13: ='Central WP'!B35+'North WP'!B31 -> 2540442.3 | D13: ='Central WP'!C35+'North WP'!C31 -> 2473951.5 | E13: ='Central WP'!D35+'North WP'!D31 -> 2325708.7 | F13: ='Central WP'!E35+'North WP'!E31 -> 2252675.3 | G13: ='Central WP'!F35+'North WP'!F31 -> 2410126.7 | H13: ='Central WP'!G35+'North WP'!G31 -> 2476379.4 | I13: ='Central WP'!H35+'North WP'!H31 -> 2444023.6 | J13: ='Central WP'!I35+'North WP'!I31 -> 2476250.8 | ... N13: ='Central WP'!M35+'North WP'!M31 -> 2378682.3 | O13: =SUM(C13:N13) -> 29057896
B14: Total Sec > 10 kW | C14: ='Central WP'!B44+'North WP'!B36 -> 264471.42 | D14: ='Central WP'!C44+'North WP'!C36 -> 249595.48 | E14: ='Central WP'!D44+'North WP'!D36 -> 250134.86 | F14: ='Central WP'!E44+'North WP'!E36 -> 241819.86 | G14: ='Central WP'!F44+'North WP'!F36 -> 252812.57 | H14: ='Central WP'!G44+'North WP'!G36 -> 256034.55 | I14: ='Central WP'!H44+'North WP'!H36 -> 269223.52 | J14: ='Central WP'!I44+'North WP'!I36 -> 270983.38 | ... N14: ='Central WP'!M44+'North WP'!M36 -> 252292.11 | O14: =SUM(C14:N14) -> 3134342.3
B15: Total Sec > 10 kW | C15: =SUM(C13:C14) -> 2804913.8 | D15: =SUM(D13:D14) -> 2723547 | E15: =SUM(E13:E14) -> 2575843.6 | F15: =SUM(F13:F14) -> 2494495.2 | G15: =SUM(G13:G14) -> 2662939.3 | H15: =SUM(H13:H14) -> 2732413.9 | I15: =SUM(I13:I14) -> 2713247.1 | J15: =SUM(J13:J14) -> 2747234.2 | ... O15: =SUM(O13:O14) -> 32192238
B18: Weather Adjustment Metered kW
B19: Total Sec > 10 kW NCP | C19: ='Central WP'!B49+'North WP'!B41 -> -31560.06 | D19: ='Central WP'!C49+'North WP'!C41 -> -11004 | E19: ='Central WP'!D49+'North WP'!D41 -> -38059.53 | F19: ='Central WP'!E49+'North WP'!E41 -> -15564.69 | G19: ='Central WP'!F49+'North WP'!F41 -> 46537.89 | H19: ='Central WP'!G49+'North WP'!G41 -> -71823.99 | I19: ='Central WP'!H49+'North WP'!H41 -> 5846.2 | J19: ='Central WP'!I49+'North WP'!I41 -> 19852.24 | ... N19: ='Central WP'!M49+'North WP'!M41 -> 31402.58 | O19: =SUM(C19:N19) -> -1391.69
B20: Total Sec > 10 kW 4CP | C20: ='Central WP'!B50+'North WP'!B42 -> -3180.86 | D20: ='Central WP'!C50+'North WP'!C42 -> -1279.78 | E20: ='Central WP'!D50+'North WP'!D42 -> -3164.42 | F20: ='Central WP'!E50+'North WP'!E42 -> -1150.62 | G20: ='Central WP'!F50+'North WP'!F42 -> 4086.91 | H20: ='Central WP'!G50+'North WP'!G42 -> -8286.84 | I20: ='Central WP'!H50+'North WP'!H42 -> -153.52 | J20: ='Central WP'!I50+'North WP'!I42 -> 1985.06 | ... N20: ='Central WP'!M50+'North WP'!M42 -> 2223.06 | O20: =SUM(C20:N20) -> -2997.35
B21: Total Sec > 10 kW | C21: =SUM(C19:C20) -> -34740.92 | D21: =SUM(D19:D20) -> -12283.78 | E21: =SUM(E19:E20) -> -41223.95 | F21: =SUM(F19:F20) -> -16715.31 | G21: =SUM(G19:G20) -> 50624.8 | H21: =SUM(H19:H20) -> -80110.83 | I21: =SUM(I19:I20) -> 5692.68 | J21: =SUM(J19:J20) -> 21837.3 | ... O21: =SUM(O19:O20) -> -4389.04
B24: Customer Adjustment Metered kW
B25: Total Sec > 10 kW NCP | C25: ='Central WP'!B55+'North WP'!B47 -> 93461.52 | D25: ='Central WP'!C55+'North WP'!C47 -> 46674.007 | E25: ='Central WP'!D55+'North WP'!D47 -> 19458.432 | F25: ='Central WP'!E55+'North WP'!E47 -> 16960.661 | G25: ='Central WP'!F55+'North WP'!F47 -> 21896.557 | H25: ='Central WP'!G55+'North WP'!G47 -> 18218.588 | I25: ='Central WP'!H55+'North WP'!H47 -> 14389.456 | J25: ='Central WP'!I55+'North WP'!I47 -> 4254.0572 | ... N25: ='Central WP'!M55+'North WP'!M47 -> 0 | O25: =SUM(C25:N25) -> 265207.8
B26: Total Sec > 10 kW 4CP | C26: ='Central WP'!B56+'North WP'!B48 -> -13425.448 | D26: ='Central WP'!C56+'North WP'!C48 -> -13172.211 | E26: ='Central WP'!D56+'North WP'!D48 -> -12660.868 | F26: ='Central WP'!E56+'North WP'!E48 -> -11174.936 | G26: ='Central WP'!F56+'North WP'!F48 -> -12950.555 | H26: ='Central WP'!G56+'North WP'!G48 -> -8032.0218 | I26: ='Central WP'!H56+'North WP'!H48 -> -9211.4768 | J26: ='Central WP'!I56+'North WP'!I48 -> -10729.39 | ... N26: ='Central WP'!M56+'North WP'!M48 -> 0 | O26: =SUM(C26:N26) -> -89589.302
B27: Total Sec > 10 kW | C27: =SUM(C25:C26) -> 80036.073 | D27: =SUM(D25:D26) -> 33501.796 | E27: =SUM(E25:E26) -> 6797.5644 | F27: =SUM(F25:F26) -> 5785.7255 | G27: =SUM(G25:G26) -> 8946.0019 | H27: =SUM(H25:H26) -> 10186.566 | I27: =SUM(I25:I26) -> 5177.9795 | J27: =SUM(J25:J26) -> -6475.3328 | ... O27: =SUM(O25:O26) -> 175618.5
B30: Total Adjusted Metered kW
B31: Total Sec > 10 kW NCP | C31: ='Central WP'!B61+'North WP'!B53 -> 2602343.8 | D31: ='Central WP'!C61+'North WP'!C53 -> 2509621.5 | E31: ='Central WP'!D61+'North WP'!D53 -> 2307107.7 | F31: ='Central WP'!E61+'North WP'!E53 -> 2254071.3 | G31: ='Central WP'!F61+'North WP'!F53 -> 2478561.2 | H31: ='Central WP'!G61+'North WP'!G53 -> 2422774 | I31: ='Central WP'!H61+'North WP'!H53 -> 2464259.2 | J31: ='Central WP'!I61+'North WP'!I53 -> 2500357.1 | ... N31: ='Central WP'!M61+'North WP'!M53 -> 2410084.9 | O31: =SUM(C31:N31) -> 29321712
B32: Total Sec > 10 kW 4CP | C32: ='Central WP'!B62+'North WP'!B54 -> 247865.12 | D32: ='Central WP'!C62+'North WP'!C54 -> 235143.49 | E32: ='Central WP'!D62+'North WP'!D54 -> 234309.57 | F32: ='Central WP'!E62+'North WP'!E54 -> 229494.31 | G32: ='Central WP'!F62+'North WP'!F54 -> 243948.92 | H32: ='Central WP'!G62+'North WP'!G54 -> 239715.69 | I32: ='Central WP'!H62+'North WP'!H54 -> 259858.52 | J32: ='Central WP'!I62+'North WP'!I54 -> 262239.05 | ... N32: ='Central WP'!M62+'North WP'!M54 -> 254515.17 | O32: =SUM(C32:N32) -> 3041755.7
B33: Total Sec > 10 kW | C33: =SUM(C31:C32) -> 2850208.9 | D33: =SUM(D31:D32) -> 2744765 | E33: =SUM(E31:E32) -> 2541417.2 | F33: =SUM(F31:F32) -> 2483565.6 | G33: =SUM(G31:G32) -> 2722510.1 | H33: =SUM(H31:H32) -> 2662489.6 | I33: =SUM(I31:I32) -> 2724117.8 | J33: =SUM(J31:J32) -> 2762596.1 | ... O33: =SUM(O31:O32) -> 32363468

Sheet (d-f)
B2: PUBLIC UTILITY COMMISSION OF TEXAS
B3: AEP TEXAS INC
B4: IV-J-5 BILLING DETERMINANTS
B5: TEST YEAR ENDING 12/31/2018
B6: DOCKET NUMBER (PENDING ASSIGNMENT)
B9: NOTE: Please see Schedule II-H-1.2 for kWh Billing and Adjustments.

Sheet (g-i)
B2: PUBLIC UTILITY COMMISSION OF TEXAS
B3: AEP TEXAS INC
B4: IV-J-5 BILLING DETERMINANTS
B5: TEST YEAR ENDING 12/31/2018
B6: DOCKET NUMBER (PENDING ASSIGNMENT)
B9: NOTE: Please see Schedule II-H-3-1.3 for Customer Bills and Adjustments.

Sheet Central WP
A2: PUBLIC UTILITY COMMISSION OF TEXAS
A3: AEP TEXAS INC
A4: IV-J-5 BILLING DETERMINANTS
A5: TEST YEAR ENDING 12/31/2018
A6: DOCKET NUMBER (PENDING ASSIGNMENT)
A8: UADJUSTED BILLED KW
A9: TARF_CD | B9: BKW_JAN18 | C9: BKW_FEB18 | D9: BKW_MAR18 | E9: BKW_APR18 | F9: BKW_MAY18 | G9: BKW_JUN18 | H9: BKW_JUL18 | I9: BKW_AUG18 | J9: BKW_SEP18 | K9: BKW_OCT18 | L9: BKW_NOV18 | M9: BKW_DEC18 | N9: BKW_TOTAL
A10: 830/831/833 | B10: 52605.4 | C10: 52221.5 | D10: 52222.6 | E10: 52584.4 | F10: 52361 | G10: 53154.7 | H10: 53441.4 | I10: 53477.8 | J10: 53706.1 | K10: 53655.3 | L10: 55167.6 | M10: 52573 | N10: =SUM(B10:M10) -> 637170.8
A11: 836* | B11: 10448.4 | C11: 8412 | D11: 7966.8 | E11: 8005.6 | F11: 9652.7 | G11: 10938.4 | H11: 13932.3 | I11: 15286 | J11: 15159.9 | K11: 12978.4 | L11: 12876.3 | M11: 13505.7 | N11: =SUM(B11:M11) -> 139162.5
A12: 838* | B12: 14809.8 | C12: 16382.5 | D12: 18274.1 | E12: 23191.8 | F12: 24144.8 | G12: 27107.4 | H12: 23675 | I12: 22176.6 | J12: 19945.9 | K12: 12578 | L12: 11035.2 | M12: 13209.3 | N12: =SUM(B12:M12) -> 226530.4
A13: 855 | B13: 621939.2 | C13: 614168.6 | D13: 583789.9 | E13: 576672.6 | F13: 585427.3 | G13: 600536.2 | H13: 593953.7 | I13: 595977.8 | J13: 597697.7 | K13: 584580.1 | L13: 578575.6 | M13: 585025.2 | N13: =SUM(B13:M13) -> 7118343.9
A14: 857 | B14: 1589815.9 | C14: 1561093 | D14: 1508204.6 | E14: 1505382.9 | F14: 1532076.3 | G14: 1581869 | H14: 1577222.1 | I14: 1593547.7 | J14: 1592992.9 | K14: 1559437.3 | L14: 1539946.1 | M14: 1545466.8 | N14: =SUM(B14:M14) -> 18687055
A15: Total Sec > 10 kW NCP | B15: =SUM(B10:B14) -> 2289618.7 | C15: =SUM(C10:C14) -> 2252277.6 | D15: =SUM(D10:D14) -> 2170458 | E15: =SUM(E10:E14) -> 2165837.3 | F15: =SUM(F10:F14) -> 2203662.1 | G15: =SUM(G10:G14) -> 2273605.7 | H15: =SUM(H10:H14) -> 2262224.5 | I15: =SUM(I10:I14) -> 2280465.9 | ... N15: =SUM(N10:N14) -> 26808262
A18: 834/835 | B18: 6701.8 | C18: 4785.4 | D18: 5670.4 | E18: 3393.6 | F18: 4617.3 | G18: 4652.1 | H18: 7557.4 | I18: 20750.6 | J18: 28094.8 | K18: 28613.3 | L18: 21296.2 | M18: 10272.7 | N18: =SUM(B18:M18) -> 146405.6
A19: 837* | B19: 4559.6 | C19: 3626 | D19: 2278.4 | E19: 2534.2 | F19: 1877 | G19: 1823.3 | H19: 1896.4 | I19: 4889.5 | J19: 5606.9 | K19: 4844.7 | L19: 4501.9 | M19: 5198.7 | N19: =SUM(B19:M19) -> 43636.6
A20: 839* | B20: 3889.6 | C20: 3700.4 | D20: 3488.3 | E20: 5524.9 | F20: 6052 | G20: 7404.4 | H20: 5682.2 | I20: 6123.5 | J20: 4782.1 | K20: 2842.6 | L20: 2418 | M20: 2522.1 | N20: =SUM(B20:M20) -> 54430.1
A21: 853 | B21: 111.4 | C21: 111.4 | D21: 111.4 | E21: 111.4 | F21: 111.4 | G21: 124.9 | H21: 153.1 | I21: 137.2 | J21: 0 | K21: 245 | L21: 122.5 | M21: 122.5 | N21: =SUM(B21:M21) -> 1462.2
A22: 856 | B22: 9348.9 | C22: 9323.6 | D22: 9259.9 | E22: 9421.7 | F22: 9517.7 | G22: 10303.1 | H22: 9720 | I22: 9432.6 | J22: 10132.9 | K22: 10097 | L22: 9536.5 | M22: 9247 | N22: =SUM(B22:M22) -> 115340.9
A23: 858 | B23: 158167.9 | C23: 155657 | D23: 159127.2 | E23: 156938.3 | F23: 160561.4 | G23: 170980.4 | H23: 164484.4 | I23: 168292.7 | J23: 171746.8 | K23: 164384.3 | L23: 161973.6 | M23: 152908.6 | N23: =SUM(B23:M23) -> 1945222.6
A24: Total Sec > 10 kW 4CP | B24: =SUM(B18:B23) -> 182779.2 | C24: =SUM(C18:C23) -> 177203.8 | D24: =SUM(D18:D23) -> 179935.6 | E24: =SUM(E18:E23) -> 177924.1 | F24: =SUM(F18:F23) -> 182736.8 | G24: =SUM(G18:G23) -> 195288.2 | H24: =SUM(H18:H23) -> 189493.5 | I24: =SUM(I18:I23) -> 209626.1 | ... N24: =SUM(N18:N23) -> 2306498
A26: Total Sec > 10 kW | B26: =B15+B24 -> 2472397.9 | C26: =C15+C24 -> 2429481.4 | D26: =D15+D24 -> 2350393.6 | E26: =E15+E24 -> 2343761.4 | F26: =F15+F24 -> 2386398.9 | G26: =G15+G24 -> 2468893.9 | H26: =H15+H24 -> 2451718 | I26: =I15+I24 -> 2490092 | ... N26: =N15+N24 -> 29114760
A28: METERED KW
A29: TARF_CD | B29: MKW_JAN18 | C29: MKW_FEB18 | D29: MKW_MAR18 | E29: MKW_APR18 | F29: MKW_MAY18 | G29: MKW_JUN18 | H29: MKW_JUL18 | I29: MKW_AUG18 | J29: MKW_SEP18 | K29: MKW_OCT18 | L29: MKW_NOV18 | M29: MKW_DEC18 | N29: MKW_TOTAL
A30: 830/831/833 | B30: 42097.058 | C30: 44123.886 | D30: 44894.07 | E30: 45524.219 | F30: 43952.896 | G30: 45098.102 | H30: 45460.12 | I30: 42986.857 | J30: 45645.825 | K30: 45971.211 | L30: 46088.869 | M30: 43428.071 | N30: =SUM(B30:M30) -> 535271.18
A31: 836* | B31: 10451.052 | C31: 8414.285 | D31: 7967.622 | E31: 8006.37 | F31: 9653.684 | G31: 10938.867 | H31: 13933.595 | I31: 15286.252 | J31: 15161.21 | K31: 12979.746 | L31: 12880.641 | M31: 13510.94 | N31: =SUM(B31:M31) -> 139184.26
A32: 838* | B32: 14820.731 | C32: 16395.537 | D32: 18288.189 | E32: 23206.023 | F32: 24156.4 | G32: 27123.86 | H32: 23689.256 | I32: 22190.139 | J32: 19957.68 | K32: 12573.203 | L32: 10939.873 | M32: 13216.782 | N32: =SUM(B32:M32) -> 226557.67
A33: 855 | B33: 568133.03 | C33: 550525.65 | D33: 494965.55 | E33: 465056.5 | F33: 478152.07 | G33: 510201.19 | H33: 496693.18 | I33: 504589.86 | J33: 514747.93 | K33: 493848.23 | L33: 496463.57 | M33: 505320.04 | N33: =SUM(B33:M33) -> 6078696.8
A34: 857 | B34: 1462476.1 | C34: 1415248 | D34: 1320478.4 | E34: 1283085 | F34: 1404907.6 | G34: 1404907.6 | H34: 1387658.1 | I34: 1412917.9 | J34: 1427360.4 | K34: 1380183.5 | L34: 1370150.2 | M34: 1367811.4 | N34: =SUM(B34:M34) -> 16637184
A35: Total Sec > 10 kW NCP | B35: =SUM(B30:B34) -> 2097978 | C35: =SUM(C30:C34) -> 2034707.3 | D35: =SUM(D30:D34) -> 1886593.9 | E35: =SUM(E30:E34) -> 1824878.1 | F35: =SUM(F30:F34) -> 1960822.7 | G35: =SUM(G30:G34) -> 1998269.6 | H35: =SUM(H30:H34) -> 1967434.3 | I35: =SUM(I30:I34) -> 1997971 | ... N35: =SUM(N30:N34) -> 23616894
A38: 834/835 | B38: 5979.43 | C38: 4382.885 | D38: 5258.189 | E38: 3145.37 | F38: 4407.93 | G38: 4326.912 | H38: 6706.461 | I38: 16451.494 | J38: 22392.038 | K38: 22721.588 | L38: 17326.022 | M38: 8451.938 | N38: =SUM(B38:M38) -> 121550.26
A39: 837* | B39: 4099.536 | C39: 2899.008 | D39: 1683.024 | E39: 2046.767 | F39: 1464.984 | G39: 1361.184 | H39: 1462.848 | I39: 4665.792 | J39: 5310.144 | K39: 4477.728 | L39: 3940.128 | M39: 4640.256 | N39: =SUM(B39:M39) -> 38051.399
A40: 839* | B40: 3693.677 | C40: 3503.194 | D40: 3260.615 | E40: 5272.562 | F40: 5676.308 | G40: 7038.125 | H40: 5304.998 | I40: 5812.684 | J40: 4542.797 | K40: 2727.558 | L40: 2279.558 | M40: 2368.461 | N40: =SUM(B40:M40) -> 51480.537
A41: 853 | B41: 102.784 | C41: 98.304 | D41: 88.704 | E41: 106.88 | F41: 60.16 | G41: 124.928 | H41: 153.088 | I41: 137.216 | J41: 0 | K41: 205.952 | L41: 103.296 | M41: 81.664 | N41: =SUM(B41:M41) -> 1262.976
A42: 856 | B42: 8521.876 | C42: 8612.652 | D42: 8560.96 | E42: 9005.815 | F42: 9108.025 | G42: 9866.451 | H42: 9321.745 | I42: 8974.634 | J42: 9847.96 | K42: 10010.99 | L42: 9276.718 | M42: 8703.498 | N42: =SUM(B42:M42) -> 109811.32
A43: 858 | B43: 140950.73 | C43: 135749.78 | D43: 141998.1 | E43: 140405.75 | F43: 146671.5 | G43: 155734.12 | H43: 153271.74 | I43: 152945.23 | J43: 158626.19 | K43: 152882.6 | L43: 147557 | M43: 136254.94 | N43: =SUM(B43:M43) -> 1763047.7
A44: Total Sec > 10 kW 4CP | B44: =SUM(B38:B43) -> 163348.04 | C44: =SUM(C38:C43) -> 155245.82 | D44: =SUM(D38:D43) -> 160849.59 | E44: =SUM(E38:E43) -> 159983.15 | F44: =SUM(F38:F43) -> 167388.91 | G44: =SUM(G38:G43) -> 178451.72 | H44: =SUM(H38:H43) -> 176220.88 | I44: =SUM(I38:I43) -> 188987.05 | ... N44: =SUM(N38:N43) -> 2085204.2
A46: Total Sec > 10 kW | B46: =B35+B44 -> 2261326 | C46: =C35+C44 -> 2189953.2 | D46: =D35+D44 -> 2047443.5 | E46: =E35+E44 -> 1984861.3 | F46: =F35+F44 -> 2128211.6 | G46: =G35+G44 -> 2176721.4 | H46: =H35+H44 -> 2143655.2 | I46: =I35+I44 -> 2186958 | ... N46: =N35+N44 -> 25702098
A48: Weather Adjustment Metered kW
A49: Total Sec > 10 kW NCP | B49: =ROUND(B35*'Central Adj WP'!D20,2) -> -24897.42 | C49: =ROUND(C35*'Central Adj WP'!E20,2) -> -7516.26 | D49: =ROUND(D35*'Central Adj WP'!F20,2) -> -38917.28 | E49: =ROUND(E35*'Central Adj WP'!G20,2) -> -18745.47 | F49: =ROUND(F35*'Central Adj WP'!H20,2) -> 44827.95 | G49: =ROUND(G35*'Central Adj WP'!I20,2) -> -46734.41 | H49: =ROUND(H35*'Central Adj WP'!J20,2) -> 19413.49 | I49: =ROUND(I35*'Central Adj WP'!K20,2) -> 16477.42 | ... M49: =ROUND(M35*'Central Adj WP'!O20,2) -> 34158.35 | N49: =SUM(B49:M49) -> 21192.27
A50: Total Sec > 10 kW 4CP | B50: =ROUND(B44*'Central Adj WP'!D21,2) -> -1927.7 | C50: =ROUND(C44*'Central Adj WP'!E21,2) -> -568.58 | D50: =ROUND(D44*'Central Adj WP'!F21,2) -> -3317.7 | E50: =ROUND(E44*'Central Adj WP'!G21,2) -> -1652.74 | F50: =ROUND(F44*'Central Adj WP'!H21,2) -> 3833.6 | G50: =ROUND(G44*'Central Adj WP'!I21,2) -> -4261.75 | H50: =ROUND(H44*'Central Adj WP'!J21,2) -> 1705.65 | I50: =ROUND(I44*'Central Adj WP'!K21,2) -> 1500.37 | ... M50: =ROUND(M44*'Central Adj WP'!O21,2) -> 2660.47 | N50: =SUM(B50:M50) -> 1563.48
...

Sheet North WP
A2: PUBLIC UTILITY COMMISSION OF TEXAS
A3: AEP TEXAS INC
A4: IV-J-5 BILLING DETERMINANTS
A5: TEST YEAR ENDING 12/31/2018
A6: DOCKET NUMBER (PENDING ASSIGNMENT)
A8: UNADJUSTED BILLED KW
A9: TARF_CD | B9: BKW_JAN18 | C9: BKW_FEB18 | D9: BKW_MAR18 | E9: BKW_APR18 | F9: BKW_MAY18 | G9: BKW_JUN18 | H9: BKW_JUL18 | I9: BKW_AUG18 | J9: BKW_SEP18 | K9: BKW_OCT18 | L9: BKW_NOV18 | M9: BKW_DEC18 | N9: BKW_TOTAL
A10: 833 | B10: 144.9 | C10: 143.7 | D10: 142.2 | E10: 141.4 | F10: 166.5 | G10: 147.2 | H10: 139.5 | I10: 139.5 | J10: 154.9 | K10: 123.2 | L10: 123.2 | M10: 128.6 | N10: =SUM(B10:M10) -> 1694.8
A11: 835 | B11: 1357 | C11: 1394.7 | D11: 1467.8 | E11: 1471.3 | F11: 1448.9 | G11: 1434 | H11: 1408.4 | I11: 1424.7 | J11: 1406.8 | K11: 1411.5 | L11: 1417.1 | M11: 1392.8 | N11: =SUM(B11:M11) -> 17035
A12: 836 | B12: 521168.5 | C12: 514659.2 | D12: 508468.2 | E12: 504695.2 | F12: 515750.3 | G12: 535685.5 | H12: 545389.6 | I12: 540841.8 | J12: 537227.4 | K12: 520588.7 | L12: 515706.3 | M12: 520131.5 | N12: =SUM(B12:M12) -> 6280312.2
A13: 838* | B13: 2579.8 | C13: 3277.6 | D13: 3837.3 | E13: 4422 | F13: 5363.2 | G13: 6432.5 | H13: 6261.3 | I13: 6489.3 | J13: 6271.4 | K13: 3856.6 | L13: 2565.6 | M13: 2560.8 | N13: =SUM(B13:M13) -> 53917.4
A14: 857* | B14: 807.4 | C14: 839.2 | D14: 720.2 | E14: 798.5 | F14: 695.4 | G14: 881.9 | H14: 765.6 | I14: 828.5 | J14: 859.4 | K14: 789.7 | L14: 875.6 | M14: 915.4 | N14: =SUM(B14:M14) -> 9776.8
A15: Total Sec > 10 kW NCP | B15: =SUM(B10:B14) -> 526057.6 | C15: =SUM(C10:C14) -> 520314.4 | D15: =SUM(D10:D14) -> 514635.7 | E15: =SUM(E10:E14) -> 511528.4 | F15: =SUM(F10:F14) -> 523424.3 | G15: =SUM(G10:G14) -> 544581.1 | H15: =SUM(H10:H14) -> 553964.4 | I15: =SUM(I10:I14) -> 549723.8 | ... N15: =SUM(N10:N14) -> 6362736.2
A18: 837 | B18: 96808 | C18: 87094.5 | D18: 88045.8 | E18: 88410 | F18: 95431.6 | G18: 85068 | H18: 101386.9 | I18: 89587.6 | J18: 92230.1 | K18: 87860 | L18: 86361.8 | M18: 85116.2 | N18: =SUM(B18:M18) -> 1083400.5
A19: 839* | B19: 26260.5 | C19: 27058.7 | D19: 17402.1 | E19: 8499.6 | F19: 1245.4 | G19: 1346.8 | H19: 1082.1 | I19: 990.9 | J19: 1026.3 | K19: 4460.7 | L19: 11532.4 | M19: 24480.4 | N19: =SUM(B19:M19) -> 125385.9
A20: Total Sec > 10 kW 4CP | B20: =SUM(B18:B19) -> 123068.5 | C20: =SUM(C18:C19) -> 114153.2 | D20: =SUM(D18:D19) -> 105447.9 | E20: =SUM(E18:E19) -> 96909.6 | F20: =SUM(F18:F19) -> 96677 | G20: =SUM(G18:G19) -> 86414.8 | H20: =SUM(H18:H19) -> 102469 | I20: =SUM(I18:I19) -> 90578.5 | ... N20: =SUM(N18:N19) -> 1208786.4
A22: Total Sec > 10 kW | B22: =B15+B20 -> 649126.1 | C22: =C15+C20 -> 634467.6 | D22: =D15+D20 -> 620083.6 | E22: =E15+E20 -> 608438 | F22: =F15+F20 -> 620101.3 | G22: =G15+G20 -> 630995.9 | H22: =H15+H20 -> 656433.4 | I22: =I15+I20 -> 640302.3 | ... N22: =N15+N20 -> 7571522.6
A24: METERED KW
A25: TARF_CD | B25: MKW_JAN18 | C25: MKW_FEB18 | D25: MKW_MAR18 | E25: MKW_APR18 | F25: MKW_MAY18 | G25: MKW_JUN18 | H25: MKW_JUL18 | I25: MKW_AUG18 | J25: MKW_SEP18 | K25: MKW_OCT18 | L25: MKW_NOV18 | M25: MKW_DEC18 | N25: MKW_TOTAL
A26: 833 | B26: 93.5 | C26: 92.6 | D26: 84 | E26: 77.8 | F26: 147.1 | G26: 117.9 | H26: 69 | I26: 84.4 | J26: 80.7 | K26: 71.3 | L26: 59.4 | M26: 94.1 | N26: =SUM(B26:M26) -> 1071.8
A27: 835 | B27: 568.871 | C27: 762.841 | D27: 1061.72 | E27: 1128.505 | F27: 1117.224 | G27: 1157.143 | H27: 852.127 | I27: 1031.32 | J27: 917.828 | K27: 1002.053 | L27: 1083.086 | M27: 924.161 | N27: =SUM(B27:M27) -> 11606.879
A28: 836 | B28: 439090.93 | C28: 434493.65 | D28: 433723.37 | E28: 421521.43 | F28: 442023.98 | G28: 469524.5 | H28: 468669.47 | I28: 469894.47 | J28: 471161.76 | K28: 447111.94 | L28: 438644.44 | M28: 431323.07 | N28: =SUM(B28:M28) -> 5367183
A29: 838* | B29: 1934.374 | C29: 3088.755 | D29: 3562.94 | E29: 4301.422 | F29: 5338.251 | G29: 6427.475 | H29: 6237.637 | I29: 6458.701 | J29: 6220.894 | K29: 3669.803 | L29: 2246.624 | M29: 2138.289 | N29: =SUM(B29:M29) -> 51625.165
A30: 857* | B30: 776.646 | C30: 806.315 | D30: 682.859 | E30: 768.047 | F30: 677.497 | G30: 882.703 | H30: 761.077 | I30: 810.921 | J30: 820.726 | K30: 736.965 | L30: 875.742 | M30: 915.458 | N30: =SUM(B30:M30) -> 9514.956
A31: Total Sec > 10 kW NCP | B31: =SUM(B26:B30) -> 442464.32 | C31: =SUM(C26:C30) -> 439244.16 | D31: =SUM(D26:D30) -> 439114.88 | E31: =SUM(E26:E30) -> 427797.21 | F31: =SUM(F26:F30) -> 449304.05 | G31: =SUM(G26:G30) -> 478109.72 | H31: =SUM(H26:H30) -> 476589.31 | I31: =SUM(I26:I30) -> 478279.82 | ... N31: =SUM(N26:N30) -> 5441001.8
B32: =B31/B15 -> 0.84109482 | C32: =C31/C15 -> 0.8441899 | D32: =D31/D15 -> 0.85325383 | E32: =E31/E15 -> 0.83631174 | F32: =F31/F15 -> 0.85839356 | G32: =G31/G15 -> 0.87794035 | H32: =H31/H15 -> 0.86032479 | I32: =I31/I15 -> 0.87003658 | ... N32: =N31/N15 -> 0.85513553
A34: 837 | B34: 79546.211 | C34: 72303.499 | D34: 75624.411 | E34: 75223.674 | F34: 84345.646 | G34: 76495.628 | H34: 92005.751 | I34: 81077.463 | J34: 84320.243 | K34: 78318.365 | L34: 76738.629 | M34: 72068.525 | N34: =SUM(B34:M34) -> 948068.05
A35: 839* | B35: 21577.176 | C35: 22046.16 | D35: 13660.852 | E35: 6613.044 | F35: 1078.012 | G35: 1087.2 | H35: 996.888 | I35: 918.868 | J35: 892.64 | K35: 3397.188 | L35: 9079.246 | M35: 19722.832 | N35: =SUM(B35:M35) -> 101070.11
A36: Total Sec > 10 kW 4CP | B36: =SUM(B34:B35) -> 101123.39 | C36: =SUM(C34:C35) -> 94349.659 | D36: =SUM(D34:D35) -> 89285.263 | E36: =SUM(E34:E35) -> 81836.718 | F36: =SUM(F34:F35) -> 85423.658 | G36: =SUM(G34:G35) -> 77582.828 | H36: =SUM(H34:H35) -> 93002.639 | I36: =SUM(I34:I35) -> 81996.331 | ... N36: =SUM(N34:N35) -> 1049138.2
A38: Total Sec > 10 kW | B38: =B31+B36 -> 543587.71 | C38: =C31+C36 -> 533593.82 | D38: =D31+D36 -> 528400.15 | E38: =E31+E36 -> 509633.93 | F38: =F31+F36 -> 534727.71 | G38: =G31+G36 -> 555692.55 | H38: =H31+H36 -> 569591.95 | I38: =I31+I36 -> 560276.15 | ... N38: =N31+N36 -> 6490140
A40: Weather Adjustment Metered kW
A41: Total Sec > 10 kW NCP | B41: =ROUND(B31*'North Adj WP'!D20,2) -> -6662.64 | C41: =ROUND(C31*'North Adj WP'!E20,2) -> -3487.74 | D41: =ROUND(D31*'North Adj WP'!F20,2) -> 857.75 | E41: =ROUND(E31*'North Adj WP'!G20,2) -> 3180.78 | F41: =ROUND(F31*'North Adj WP'!H20,2) -> 1709.94 | G41: =ROUND(G31*'North Adj WP'!I20,2) -> -25089.58 | H41: =ROUND(H31*'North Adj WP'!J20,2) -> -13567.29 | I41: =ROUND(I31*'North Adj WP'!K20,2) -> 3374.82 | ... M41: =ROUND(M31*'North Adj WP'!O20,2) -> -2755.77 | N41: =SUM(B41:M41) -> -22583.96
A42: Total Sec > 10 kW 4CP | B42: =ROUND(B36*'North Adj WP'!D21,2) -> -1253.16 | C42: =ROUND(C36*'North Adj WP'!E21,2) -> -711.2 | D42: =ROUND(D36*'North Adj WP'!F21,2) -> 153.28 | E42: =ROUND(E36*'North Adj WP'!G21,2) -> 502.12 | F42: =ROUND(F36*'North Adj WP'!H21,2) -> 253.31 | G42: =ROUND(G36*'North Adj WP'!I21,2) -> -4025.09 | H42: =ROUND(H36*'North Adj WP'!J21,2) -> -1859.17 | I42: =ROUND(I36*'North Adj WP'!K21,2) -> 484.69 | ... M42: =ROUND(M36*'North Adj WP'!O21,2) -> -437.41 | N42: =SUM(B42:M42) -> -4560.83
A43: Total Sec > 10 kW
A46: Customer Adjustment Metered kW
A47: Total Sec > 10 kW NCP | B47: =(B31+B41)*'North Adj WP'!D29 -> 11964.86 | C47: =(C31+C41)*'North Adj WP'!E29 -> 8942.5267 | D47: =(D31+D41)*'North Adj WP'!F29 -> 7798.0421 | E47: =(E31+E41)*'North Adj WP'!G29 -> 7259.1913 | F47: =(F31+F41)*'North Adj WP'!H29 -> 6055.3771 | G47: =(G31+G41)*'North Adj WP'!I29 -> 5773.0781 | H47: =(H31+H41)*'North Adj WP'!J29 -> 3465.5964 | I47: =(I31+I41)*'North Adj WP'!K29 -> 2072.8772 | ... M47: =(M31+M41)*'North Adj WP'!O29 -> 0 | N47: =SUM(B47:M47) -> 60591.457
A48: Total Sec > 10 kW 4CP | B48: =(B36+B42)*'North Adj WP'!D30 -> -3630.6476 | C48: =(C36+C42)*'North Adj WP'!E30 -> -2868.2906 | D48: =(D36+D42)*'North Adj WP'!F30 -> -2765.1877 | E48: =(E36+E42)*'North Adj WP'!G30 -> -1553.3258 | F48: =(F36+F42)*'North Adj WP'!H30 -> -3163.1052 | G48: =(G36+G42)*'North Adj WP'!I30 -> -441.40176 | H48: =(H36+H42)*'North Adj WP'!J30 -> -2219.1668 | I48: =(I36+I42)*'North Adj WP'!K30 -> 0 | ... M48: =(M36+M42)*'North Adj WP'!O30 -> 0 | N48: =SUM(B48:M48) -> -16101.212
A49: Total Sec > 10 kW
A52: Total Adjusted Metered kW
A53: Total Sec > 10 kW NCP | B53: =B31+B41+B47 -> 447766.54 | C53: =C31+C41+C47 -> 444698.95 | D53: =D31+D41+D47 -> 447770.68 | E53: =E31+E41+E47 -> 438237.18 | F53: =F31+F41+F47 -> 457069.37 | G53: =G31+G41+G47 -> 458793.22 | H53: =H31+H41+H47 -> 466487.61 | I53: =I31+I41+I47 -> 483727.51 | ... M53: =M31+M41+M47 -> 432639.3 | N53: =SUM(B53:M53) -> 5479009.3
...

Sheet Central Adj WP
B2: PUBLIC UTILITY COMMISSION OF TEXAS
B3: AEP TEXAS INC
B4: IV-J-5 BILLING DETERMINANTS
B5: TEST YEAR ENDING 12/31/2018
B6: DOCKET NUMBER (PENDING ASSIGNMENT)
B8: CENTRAL
B9: DESCRIPTION | C9: VOLT | D9: JANUARY | E9: FEBRUARY | F9: MARCH | G9: JANUARY | H9: FEBRUARY | I9: MARCH | J9: APRIL | K9: MAY | L9: JUNE | M9: OCTOBER | N9: NOVEMBER | O9: DECEMBER | P9: TOTAL
B11: SECONDARY > 10 kW NCP | C11: SEC | D11: 2298784.7 | E11: 2279421.9 | F11: 2197974.2 | G11: 2194759.7 | H11: 2231410 | I11: 2300573.3 | J11: 2286677.4 | K11: 2304600.4 | L11: 2299886.8 | M11: 2242766.3 | N11: 2213180.4 | O11: 2223836.3 | P11: 27073871
B12: SECONDARY > 10 kW 4CP | C12: SEC | D12: 178437.9 | E12: 174247.7 | F12: 176919.7 | G12: 174738.7 | H12: 178950.8 | I12: 190986.8 | J12: 185520.7 | K12: 204333.2 | L12: 215936.6 | M12: 206667.8 | N12: 195775 | O12: 177883.8 | P12: 2260398.7
B14: WEATHER
B15: SECONDARY > 10 kW NCP | C15: SEC | D15: -27280.467 | E15: -8420.2426 | F15: -45340.535 | G15: -22544.953 | H15: 51014.069 | I15: -53804.519 | J15: 22563.595 | K15: 19006.217 | L15: -6601.0652 | M15: 683.82446 | N15: 55244.496 | O15: 39089.735 | P15: =SUM(D15:O15) -> 23610.155
B16: SECONDARY > 10 kW 4CP | C16: SEC | D16: -2105.7732 | E16: -638.17023 | F16: -3649.1626 | G16: -1805.1706 | H16: 4098.3963 | I16: -4561.1104 | J16: 1795.6623 | K16: 1622.198 | L16: -530.11432 | M16: 54.231834 | N16: 4375.7664 | O16: 2948.6163 | P16: =SUM(D16:O16) -> 1605.37
B17: TOTAL SECONDARY > 10 kW | D17: =SUM(D15:D16) -> -29386.24 | E17: =SUM(E15:E16) -> -9058.4128 | F17: =SUM(F15:F16) -> -48989.697 | G17: =SUM(G15:G16) -> -24350.124 | H17: =SUM(H15:H16) -> 55112.465 | I17: =SUM(I15:I16) -> -58365.629 | J17: =SUM(J15:J16) -> 24359.257 | K17: =SUM(K15:K16) -> 20628.415 | ... O17: =SUM(O15:O16) -> 42038.352 | P17: -31520.114
B19: WEATHER FACTOR
B20: SECONDARY > 10 kW NCP | D20: =D15/D11 -> -0.011867343 | E20: =E15/E11 -> -0.0036940255 | F20: =F15/F11 -> -0.020628329 | G20: =G15/G11 -> -0.010272174 | H20: =H15/H11 -> 0.022861809 | I20: =I15/I11 -> -0.023387439 | J20: =J15/J11 -> 0.0098674149 | K20: =K15/K11 -> 0.0082470771 | ... O20: =O15/O11 -> 0.017577614
B21: SECONDARY > 10 kW 4CP | D21: =D16/D12 -> -0.011801154 | E21: =E16/E12 -> -0.0036624313 | F21: =F16/F12 -> -0.020626095 | G21: =G16/G12 -> -0.010330686 | H21: =H16/H12 -> 0.022902364 | I21: =I16/I12 -> -0.02388181 | J21: =J16/J12 -> 0.0096790403 | K21: =K16/K12 -> 0.0079389841 | ... O21: =O16/O12 -> 0.016576081
B23: CUSTOMER
B24: SECONDARY > 10 kW NCP | C24: SEC | D24: 90369.512 | E24: 42426.171 | F24: 13871.061 | G24: 11788.942 | H24: 17624.291 | I24: 14671.424 | J24: 12572.354 | K24: 2495.3501 | L24: 10316.334 | M24: 11017.628 | N24: 4489.5547 | O24: 0 | P24: =SUM(D24:O24) -> 231642.62
B25: SECONDARY > 10 kW 4CP | C25: SEC | D25: -10827.411 | E25: -11607.614 | F25: -11113.562 | G25: -10618.725 | H25: -10229.22 | I25: -8322.5754 | J25: -7290.7566 | K25: -11509.272 | L25: 673.14527 | M25: 646.00635 | N25: 0 | O25: 0 | P25: =SUM(D25:O25) -> -80199.985
B28: CUSTOMER FACTOR
B29: SECONDARY > 10 kW NCP | C29: SEC | D29: =D24/D11 -> 0.039311864 | E29: =E24/E11 -> 0.018612689 | F29: =F24/F11 -> 0.0063108387 | G29: =G24/G11 -> 0.0053714042 | H29: =H24/H11 -> 0.0078982757 | I29: =I24/I11 -> 0.0063772904 | J29: =J24/J11 -> 0.0054980883 | K29: =K24/K11 -> 0.0010827691 | ... O29: =O24/O11 -> 0
B30: SECONDARY > 10 kW 4CP | C30: SEC | D30: =D25/D12 -> -0.060678877 | E30: =E25/E12 -> -0.066615593 | F30: =F25/F12 -> -0.062816985 | G30: =G25/G12 -> -0.060769168 | H30: =H25/H12 -> -0.057162191 | I30: =I25/I12 -> -0.043576705 | J30: =J25/J12 -> -0.039298885 | K30: =K25/K12 -> -0.056326002 | ... O30: =O25/O12 -> 0

Sheet North Adj WP
B2: PUBLIC UTILITY COMMISSION OF TEXAS
B3: AEP TEXAS INC
B4: IV-J-5 BILLING DETERMINANTS
B5: TEST YEAR ENDING 12/31/2018
B6: DOCKET NUMBER (PENDING ASSIGNMENT)
B8: NORTH
B9: DESCRIPTION | C9: VOLT | D9: JANUARY | E9: FEBRUARY | F9: MARCH | G9: JANUARY | H9: FEBRUARY | I9: MARCH | J9: APRIL | K9: MAY | L9: JUNE | M9: OCTOBER | N9: NOVEMBER | O9: DECEMBER | P9: TOTAL
B11: SECONDARY > 10 kW NCP | C11: SEC | D11: 530521.2 | E11: 523329.6 | F11: 518453.6 | G11: 515296.9 | H11: 527213.2 | I11: 547426.9 | J11: 556366.6 | K11: 554246.9 | L11: 551032.9 | M11: 529958 | N11: 521165.5 | O11: 525906.8 | P11: =SUM(D11:O11) -> 6400918.1
B12: SECONDARY > 10 kW 4CP | C12: SEC | D12: 121881.3 | E12: 114747.8 | F12: 106025.9 | G12: 96666.1 | H12: 96709.6 | I12: 86597.1 | J12: 102108.2 | K12: 88830 | L12: 90134.7 | M12: 89782.2 | N12: 97907.4 | O12: 109528.2 | P12: =SUM(D12:O12) -> 1200918.5
B14: WEATHER
B15: SECONDARY > 10 kW NCP | C15: SEC | D15: -7988.6065 | E15: -4155.4012 | F15: 1012.7224 | G15: 3831.3645 | H15: 2006.4424 | I15: -28727.108 | J15: -15838.352 | K15: 3910.8539 | L15: 9560.9613 | M15: 12495.336 | N15: 1023.6626 | O15: -3328.6534 | P15: =SUM(D15:O15) -> -26196.778
B16: SECONDARY > 10 kW 4CP | C16: SEC | D16: -1510.4033 | E16: -864.96433 | F16: 182.014 | G16: 593.1097 | H16: 286.77256 | I16: -4492.7576 | J16: -2041.1942 | K16: 525.08517 | L16: 1105.2151 | M16: 1368.9573 | N16: 46.757397 | O16: -521.9284 | P16: =SUM(D16:O16) -> -5323.3367
B17: TOTAL SECONDARY > 10 kW | D17: =SUM(D15:D16) -> -9499.0099 | E17: =SUM(E15:E16) -> -5020.3655 | F17: =SUM(F15:F16) -> 1194.7364 | G17: =SUM(G15:G16) -> 4424.4742 | H17: =SUM(H15:H16) -> 2293.215 | I17: =SUM(I15:I16) -> -33219.866 | J17: =SUM(J15:J16) -> -17879.546 | K17: =SUM(K15:K16) -> 4435.939 | ... O17: =SUM(O15:O16) -> -3850.5818 | P17: -31520.114
B19: WEATHER FACTOR
B20: SECONDARY > 10 kW NCP | D20: =D15/D11 -> -0.015058035 | E20: =E15/E11 -> -0.0079403137 | F20: =F15/F11 -> 0.001953352 | G20: =G15/G11 -> 0.0074352562 | H20: =H15/H11 -> 0.0038057515 | I20: =I15/I11 -> -0.05247661 | J20: =J15/J11 -> -0.028467474 | K20: =K15/K11 -> 0.0070561583 | ... O20: =O15/O11 -> -0.00632936
B21: SECONDARY > 10 kW 4CP | D21: =D16/D12 -> -0.012392412 | E21: =E16/E12 -> -0.00753796 | F21: =F16/F12 -> 0.0017166938 | G21: =G16/G12 -> 0.0061356535 | H21: =H16/H12 -> 0.0029652957 | I21: =I16/I12 -> -0.051881155 | J21: =J16/J12 -> -0.019990502 | K21: =K16/K12 -> 0.0059111243 | ... O21: =O16/O12 -> -0.0047652422
B23: CUSTOMER
B24: SECONDARY > 10 kW NCP | C24: SEC | D24: 14565.368 | E24: 10739.69 | F24: 9189.0329 | G24: 8679.4195 | H24: 7078.4384 | I24: 6976.1539 | J24: 4164.2557 | K24: 2385.2895 | L24: 4359.9028 | M24: 2752.5722 | N24: 1170.1506 | O24: 0 | P24: =SUM(D24:O24) -> 72060.274
B25: SECONDARY > 10 kW 4CP | C25: SEC | D25: -4430.8306 | E25: -3514.9023 | F25: -3278.022 | G25: -1823.6102 | H25: -3570.4186 | I25: -519.64774 | J25: -2486.1368 | K25: 0 | L25: 0 | M25: 584.30229 | N25: 0 | O25: 0 | P25: =SUM(D25:O25) -> -19039.266
B28: CUSTOMER FACTOR
B29: SECONDARY > 10 kW NCP | C29: SEC | D29: =D24/D11 -> 0.027454828 | E29: =E24/E11 -> 0.020521847 | F29: =F24/F11 -> 0.017723925 | G29: =G24/G11 -> 0.016843531 | H29: =H24/H11 -> 0.01342614 | I29: =I24/I11 -> 0.012743535 | J29: =J24/J11 -> 0.0074847335 | K29: =K24/K11 -> 0.0043036588 | ... O29: =O24/O11 -> 0
B30: SECONDARY > 10 kW 4CP | C30: SEC | D30: =D25/D12 -> -0.036353654 | E30: =E25/E12 -> -0.030631544 | F30: =F25/F12 -> -0.030917182 | G30: =G25/G12 -> -0.018865044 | H30: =H25/H12 -> -0.036918968 | I30: =I25/I12 -> -0.0060007522 | J30: =J25/J12 -> -0.024348062 | K30: =K25/K12 -> 0 | ... O30: =O25/O12 -> 0
