Workbook

Sheet MSL
C2: Central Divison | G2: North Divison | K2: Central Divison | P2: North Divison | U2: AEP TX
B3: Municipal Street Lighting | C3: Code | D3: AEPTX kWh | E3: Facilities Price | G3: Code | H3: AEPTX kWh | I3: Facilities Price | K3: Code | L3: TYE Monthly Fixture Count | M3: Annual kWh | N3: Current Annual Revenue | P3: Code | Q3: TYE Monthly Fixture Count | R3: Annual kWh | S3: Current Annual Revenue | U3: Code | V3: TYE Annual Fixture Count | W3: Annual kWh | X3: Proposed Rate | Y3: Proposed Revenue
B4: Mercury Vapor* | X4: =[1]AEPTX!$D$54+0.02 -> 0.33115133
B5: 100 Watt | C5: 931 | D5: 40 | E5: 4.1 | F5: =(X5-E5)/E5 -> 0.34146341 | G5: 931 | K5: 931 | L5: =2366+1 -> 2367 | M5: =L5*D5*12 -> 1136160 | N5: =ROUND(L5*E5,2)*12 -> 116456.4 | P5: 931 | Q5: 0 | R5: =Q5*H5*12 -> 0 | U5: 931 | V5: =(L5+Q5)*12 -> 28404 | W5: =M5+R5 -> 1136160 | X5: =ROUND(E5*(1+$X$4),2)+0.04 -> 5.5 | Y5: =ROUND(V5*X5,2) -> 156222
B6: 175 Watt | C6: 932 | D6: 70 | E6: 4.64 | F6: =(X6-E6)/E6 -> 0.3362069 | G6: 932 | H6: 70 | I6: 4.84 | J6: =($X$6-I6)/I6 -> 0.28099174 | K6: 932 | L6: =982+13+258+195 -> 1448 | M6: =L6*D6*12 -> 1216320 | N6: =ROUND(L6*E6,2)*12 -> 80624.64 | P6: 932 | Q6: =4643+2+3 -> 4648 | R6: =Q6*H6*12 -> 3904320 | S6: =ROUND(Q6*I6,2)*12 -> 269955.84 | U6: 932 | V6: =(L6+Q6)*12 -> 73152 | W6: =M6+R6 -> 5120640 | X6: =ROUND(E6*(1+$X$4),2)+0.02 -> 6.2 | Y6: =ROUND(V6*X6,2) -> 453542.4
B7: 250 Watt (remove) | C7: 933 | D7: 100 | E7: 6.35 | G7: 933 | K7: 933 | L7: 0 | M7: =L7*D7*12 -> 0 | N7: =ROUND(L7*E7,2)*12 -> 0 | P7: 933 | Q7: 0 | R7: =Q7*H7*12 -> 0 | U7: 933 | V7: =(L7+Q7)*12 -> 0 | W7: =M7+R7 -> 0 | X7: 0 | Y7: =ROUND(V7*X7,2) -> 0
B8: 400 Watt | C8: 935 | D8: 145 | E8: 7.61 | F8: =(X8-E8)/E8 -> 0.33377135 | G8: 935 | H8: 145 | I8: 8.87 | J8: =(X8-I8)/I8 -> 0.14430665 | K8: 935 | L8: =1644+3+522 -> 2169 | M8: =L8*D8*12 -> 3774060 | N8: =ROUND(L8*E8,2)*12 -> 198073.08 | P8: 935 | Q8: =885+66+10+18+24 -> 1003 | R8: =Q8*H8*12 -> 1745220 | S8: =ROUND(Q8*I8,2)*12 -> 106759.32 | U8: 935 | V8: =(L8+Q8+(L11*2)+(Q9*2))*12 -> 40752 | W8: =M8+R8 -> 5519280 | X8: =ROUND(E8*(1+$X$4),2)+0.02 -> 10.15 | Y8: =ROUND(V8*X8,2) -> 413632.8
B9: Twin 400 Watt (remove) | C9: 936 | G9: 936 | H9: 320 | I9: 12.5 | K9: 936 | L9: 0 | M9: =L9*D9*12 -> 0 | N9: =ROUND(L9*E9,2)*12 -> 0 | P9: 936 | Q9: 12 | R9: =Q9*H9*12 -> 46080 | S9: =ROUND(Q9*I9,2)*12 -> 1800 | U9: 936 | V9: 0 | W9: =M9+R9 -> 46080 | X9: 0 | Y9: =ROUND(V9*X9,2) -> 0
B10: 1,000 Watt (remove) | C10: 937 | D10: 365 | E10: 10.71 | G10: 937 | K10: 937 | L10: 0 | M10: =L10*D10*12 -> 0 | N10: =ROUND(L10*E10,2)*12 -> 0 | P10: 937 | Q10: 0 | R10: =Q10*H10*12 -> 0 | U10: 937 | V10: =(L10+Q10)*12 -> 0 | W10: =M10+R10 -> 0 | X10: 0 | Y10: =ROUND(V10*X10,2) -> 0
B11: Twin 400 Watt (remove) | C11: 938 | D11: 290 | E11: 11.78 | G11: 938 | K11: 938 | L11: 100 | M11: =L11*D11*12 -> 348000 | N11: =ROUND(L11*E11,2)*12 -> 14136 | P11: 938 | Q11: 0 | R11: =Q11*H11*12 -> 0 | U11: 938 | V11: 0 | W11: =M11+R11 -> 348000 | X11: 0 | Y11: =ROUND(V11*X11,2) -> 0
B13: Metal Halide
B14: 150 Watt | C14: 959 | D14: 65 | E14: 6.7 | F14: =(X14-E14)/E14 -> 0.3358209 | G14: 959 | K14: 959 | L14: 215 | M14: =L14*D14*12 -> 167700 | N14: =ROUND(L14*E14,2)*12 -> 17286 | P14: 959 | U14: 959 | V14: =(L14+Q14)*12 -> 2580 | W14: =M14+R14 -> 167700 | X14: =ROUND(E14*(1+$X$4),2)+0.03 -> 8.95 | Y14: =ROUND(V14*X14,2) -> 23091
B15: 175 Watt** | C15: 960 | D15: 75 | E15: 6.7 | F15: =(X15-E15)/E15 -> 0.3358209 | G15: 960 | K15: 960 | L15: =521+123 -> 644 | M15: =L15*D15*12 -> 579600 | N15: =ROUND(L15*E15,2)*12 -> 51777.6 | P15: 960 | U15: 960 | V15: =(L15+Q15)*12 -> 7728 | W15: =M15+R15 -> 579600 | X15: =ROUND(E15*(1+$X$4),2)+0.03 -> 8.95 | Y15: =ROUND(V15*X15,2) -> 69165.6
B16: 250 Watt | C16: 961 | D16: 105 | E16: 6.9 | F16: =(X16-E16)/E16 -> 0.33333333 | G16: 961 | K16: 961 | L16: 103 | M16: =L16*D16*12 -> 129780 | N16: =ROUND(L16*E16,2)*12 -> 8528.4 | P16: 961 | U16: 961 | V16: =(L16+Q16+(L18*2)+(Q18*2))*12 -> 1740 | W16: =M16+R16 -> 129780 | X16: =ROUND(E16*(1+$X$4),2)+0.02 -> 9.2 | Y16: =ROUND(V16*X16,2) -> 16008
B17: 400 Watt | C17: 962 | D17: 155 | E17: 7.27 | F17: =(X17-E17)/E17 -> 0.33425034 | G17: 962 | K17: 962 | L17: =1097+7+63 -> 1167 | M17: =L17*D17*12 -> 2170620 | N17: =ROUND(L17*E17,2)*12 -> 101809.08 | P17: 962 | U17: 962/965 | V17: =(L17+Q17+(L19*2)+(Q19))*12 -> 18156 | W17: =M17+R17 -> 2170620 | X17: =ROUND(E17*(1+$X$4),2)+0.02 -> 9.7 | Y17: =ROUND(V17*X17,2) -> 176113.2
B18: Twin 250 Watt (remove) | C18: 964 | D18: 210 | E18: 11.04 | G18: 964 | K18: 964 | L18: 21 | M18: =L18*D18*12 -> 52920 | N18: =ROUND(L18*E18,2)*12 -> 2782.08 | P18: 964 | U18: 964 | V18: 0 | W18: =M18+R18 -> 52920 | Y18: =ROUND(V18*X18,2) -> 0
B19: Twin 400 Watt Central (remove) | C19: 965 | D19: 310 | E19: 11.66 | G19: 965 | H19: =155*2 -> 310 | I19: 9.71 | K19: 965 | L19: 159 | M19: =L19*D19*12 -> 591480 | N19: =ROUND(L19*E19,2)*12 -> 22247.28 | P19: 965 | Q19: 28 | R19: =Q19*H19*12 -> 104160 | S19: =ROUND(Q19*I19,2)*12 -> 3262.56 | U19: 965 | V19: 0 | W19: =M19+R19 -> 695640 | Y19: =ROUND(V19*X19,2) -> 0
B20: 1,000 Watt (flood) | C20: 966 | D20: 367 | E20: 8.67 | F20: =(X20-E20)/E20 -> 0.1361015 | G20: 966 | H20: 367 | I20: 7.4 | J20: =(X20-I20)/I20 -> 0.33108108 | K20: 966 | L20: 737 | M20: =L20*D20*12 -> 3245748 | N20: =ROUND(L20*E20,2)*12 -> 76677.48 | P20: 966 | Q20: 53 | R20: =Q20*H20*12 -> 233412 | S20: =ROUND(Q20*I20,2)*12 -> 4706.4 | U20: 966 | V20: =(L20+Q20)*12 -> 9480 | W20: =M20+R20 -> 3479160 | X20: =ROUND(I20*(1+$X$4),2) -> 9.85 | Y20: =ROUND(V20*X20,2) -> 93378
B22: High Pressure Sodium
B23: 70 Watt | C23: 944 | D23: 28 | E23: 4.12 | F23: =(X23-E23)/E23 -> 0.33009709 | G23: 944 | H23: 28 | I23: 4.71 | J23: =(X23-I23)/I23 -> 0.16348195 | K23: 944 | L23: =81+126 -> 207 | M23: =L23*D23*12 -> 69552 | N23: =ROUND(L23*E23,2)*12 -> 10234.08 | P23: 944 | Q23: =15615+20+18+8+6 -> 15667 | R23: =Q23*H23*12 -> 5264112 | S23: =ROUND(Q23*I23,2)*12 -> 885498.84 | U23: 944 | V23: =(L23+Q23)*12 -> 190488 | W23: =M23+R23 -> 5333664 | X23: =ROUND(E23*(1+$X$4),2) -> 5.48 | Y23: =ROUND(V23*X23,2) -> 1043874.2
B24: 100 Watt | C24: 945 | D24: 39 | E24: 4.21 | F24: =(X24-E24)/E24 -> 0.33016627 | G24: 945 | H24: 39 | I24: 5.59 | J24: =(X24-I24)/I24 -> 0.0017889088 | K24: 945 | L24: =10505+1+65+113 -> 10684 | M24: =L24*D24*12 -> 5000112 | N24: =ROUND(L24*E24,2)*12 -> 539755.68 | P24: 945 | Q24: 0 | R24: =Q24*H24*12 -> 0 | U24: 945 | V24: =(L24+Q24)*12 -> 128208 | W24: =M24+R24 -> 5000112 | X24: =ROUND(E24*(1+$X$4),2) -> 5.6 | Y24: =ROUND(V24*X24,2) -> 717964.8
B25: 150 Watt | C25: 946 | D25: 57 | E25: 4.33 | F25: =(X25-E25)/E25 -> 0.33025404 | G25: 946 | H25: 57 | I25: 4.97 | J25: =(X25-I25)/I25 -> 0.15895372 | K25: 946 | L25: =37584+114+434+447 -> 38579 | M25: =L25*D25*12 -> 26388036 | N25: =ROUND(L25*E25,2)*12 -> 2004564.8 | P25: 946 | Q25: 3428 | R25: =Q25*H25*12 -> 2344752 | S25: =ROUND(Q25*I25,2)*12 -> 204445.92 | U25: 946 | V25: =(L25+Q25+(Q27*2)+(L30*2))*12 -> 509796 | W25: =M25+R25 -> 28732788 | X25: =ROUND(E25*(1+$X$4),2) -> 5.76 | Y25: =ROUND(V25*X25,2) -> 2936425
B26: 250 Watt | C26: 947 | D26: 104 | E26: 6.06 | F26: =(X26-E26)/E26 -> 0.33168317 | G26: 947 | H26: 104 | I26: 7.39 | J26: =(X26-I26)/I26 -> 0.092016238 | K26: 947 | L26: =41215+108+1042 -> 42365 | M26: =L26*D26*12 -> 52871520 | N26: =ROUND(L26*E26,2)*12 -> 3080782.8 | P26: 947 | Q26: 3912 | R26: =Q26*H26*12 -> 4882176 | S26: =ROUND(Q26*I26,2)*12 -> 346916.16 | U26: 947 | V26: =(L26+Q26+(Q29*2)+(L31*2))*12 -> 577476 | W26: =M26+R26 -> 57753696 | X26: =ROUND(E26*(1+$X$4),2) -> 8.07 | Y26: =ROUND(V26*X26,2) -> 4660231.3
B27: Twin 150 Watt (remove) | C27: 948 | G27: 948 | H27: 114 | I27: 12.38 | K27: 948 | L27: 0 | M27: =L27*D27*12 -> 0 | N27: =ROUND(L27*E27,2)*12 -> 0 | P27: 948 | Q27: 106 | R27: =Q27*H27*12 -> 145008 | S27: =ROUND(Q27*I27,2)*12 -> 15747.36 | U27: 948 | V27: 0 | W27: =M27+R27 -> 145008 | X27: 0 | Y27: =ROUND(V27*X27,2) -> 0
B28: 400 Watt | C28: 949 | D28: 165 | E28: 6.57 | F28: =(X28-E28)/E28 -> 0.33181126 | G28: 949 | H28: 155 | I28: 8.77 | J28: =(X28-I28)/I28 -> -0.0022805017 | K28: 949 | L28: =3587 -> 3587 | M28: =L28*D28*12 -> 7102260 | N28: =ROUND(L28*E28,2)*12 -> 282799.08 | P28: 949 | Q28: 61 | R28: =Q28*H28*12 -> 113460 | S28: =ROUND(Q28*I28,2)*12 -> 6419.64 | U28: 949 | V28: =((L28+Q28)+(+L32*2))*12 -> 45312 | W28: =M28+R28 -> 7215720 | X28: =ROUND(E28*(1+$X$4),2) -> 8.75 | Y28: =ROUND(V28*X28,2) -> 396480
B29: Twin 250 Watt (remove) | C29: 950 | G29: 950 | H29: 208 | I29: 13.76 | K29: 950 | L29: 0 | M29: =L29*D29*12 -> 0 | N29: =ROUND(L29*E29,2)*12 -> 0 | P29: 950 | Q29: 131 | R29: =Q29*H29*12 -> 326976 | S29: =ROUND(Q29*I29,2)*12 -> 21630.72 | U29: 950 | V29: 0 | W29: =M29+R29 -> 326976 | X29: 0 | Y29: =ROUND(V29*X29,2) -> 0
B30: Twin 150 Watt (remove) | C30: 952 | D30: 140 | E30: 6.4 | G30: 952 | K30: 952 | L30: 132 | M30: =L30*D30*12 -> 221760 | N30: =ROUND(L30*E30,2)*12 -> 10137.6 | P30: 952 | Q30: 0 | R30: =Q30*H30*12 -> 0 | U30: 952 | V30: 0 | W30: =M30+R30 -> 221760 | X30: 0 | Y30: =ROUND(V30*X30,2) -> 0
B31: Twin 250 Watt (remove) | C31: 953 | D31: 210 | E31: 9.86 | G31: 953 | K31: 953 | L31: 792 | M31: =L31*D31*12 -> 1995840 | N31: =ROUND(L31*E31,2)*12 -> 93709.44 | P31: 953 | Q31: 0 | R31: =Q31*H31*12 -> 0 | U31: 953 | V31: 0 | W31: =M31+R31 -> 1995840 | X31: 0 | Y31: =ROUND(V31*X31,2) -> 0
B32: Twin 400 Watt (remove) | C32: 954 | D32: 330 | E32: 10.86 | G32: 954 | K32: 954 | L32: 64 | M32: =L32*D32*12 -> 253440 | N32: =ROUND(L32*E32,2)*12 -> 8340.48 | P32: 954 | Q32: 0 | R32: =Q32*H32*12 -> 0 | U32: 954 | V32: 0 | W32: =M32+R32 -> 253440 | X32: 0 | Y32: =ROUND(V32*X32,2) -> 0
B33: 1,000 Watt | C33: 955 | D33: 367 | E33: 5.55 | F33: =(X33-E33)/E33 -> 0.33333333 | G33: 955 | H33: 367 | I33: 5.86 | J33: =(X33-I33)/I33 -> 0.26279863 | K33: 955 | L33: =536 -> 536 | M33: =L33*D33*12 -> 2360544 | N33: =ROUND(L33*E33,2)*12 -> 35697.6 | P33: 955 | Q33: 48 | R33: =Q33*H33*12 -> 211392 | S33: =ROUND(Q33*I33,2)*12 -> 3375.36 | U33: 955 | V33: =(L33+Q33)*12 -> 7008 | W33: =M33+R33 -> 2571936 | X33: =ROUND(E33*(1+$X$4),2)+0.01 -> 7.4 | Y33: =ROUND(V33*X33,2) -> 51859.2
M34: =L34*D34*12 -> 0
B35: Incandescent 500 Watt (remove) | C35: 971 | G35: 971 | H35: 227 | I35: 7.71 | K35: 971 | L35: 0 | M35: =L35*D35*12 -> 0 | N35: =ROUND(L35*E35,2)*12 -> 0 | P35: 971 | Q35: 0 | R35: =Q35*H35*12 -> 0 | S35: =ROUND(Q35*I35,2) -> 0 | U35: 971 | V35: =(L35+Q35)*12 -> 0 | W35: =M35+R35 -> 0 | X35: 0 | Y35: =ROUND(V35*X35,2) -> 0
B37: *MV no longer available
B38: ** 175 MH no longer available
B40: Ornamental Street Lighting - Cities of Mcallen, Odem, Uvalde
B41: Metal Halide
B42: 400 Watt Street Light | C42: 975 | D42: 155 | E42: 11.39 | F42: =(X42-E42)/E42 -> 0.3309921 | K42: 975 | L42: 0 | M42: =L42*D42*12 -> 0 | N42: =ROUND(L42*E42,2)*12 -> 0 | U42: 975 | V42: =(L42+Q42)*12 -> 0 | W42: =M42+R42 -> 0 | X42: =ROUND(E42*(1+$X$4),2) -> 15.16 | Y42: =ROUND(V42*X42,2) -> 0
B43: 175 Watt Post Top Light* | C43: 976 | D43: 75 | E43: 19.2 | F43: =(X43-E43)/E43 -> 0.33125 | K43: 976 | L43: 582 | M43: =L43*D43*12 -> 523800 | N43: =ROUND(L43*E43,2)*12 -> 134092.8 | U43: 976 | V43: =(L43+Q43)*12 -> 6984 | W43: =M43+R43 -> 523800 | X43: =ROUND(E43*(1+$X$4),2) -> 25.56 | Y43: =ROUND(V43*X43,2) -> 178511.04
B44: 150 Watt Post Top Light | C44: 978 | D44: 65 | E44: 19.2 | F44: =(X44-E44)/E44 -> 0.33125 | K44: 978 | L44: 147 | M44: =L44*D44*12 -> 114660 | N44: =ROUND(L44*E44,2)*12 -> 33868.8 | U44: 978 | V44: =(L44+Q44)*12 -> 1764 | W44: =M44+R44 -> 114660 | X44: =ROUND(E44*(1+$X$4),2) -> 25.56 | Y44: =ROUND(V44*X44,2) -> 45087.84
B46: High Pressure Sodium Lamp
...

Sheet Non-Roadway
C2: Central Divison | G2: North Divison | K2: Central Divison | P2: North Divison | U2: AEP TX
B3: Non-Roadway Lighting Service | C3: Code | D3: AEPTX kWh | E3: Facilities Price | G3: Code | H3: AEPTX kWh | I3: Facilities Price | K3: Code | L3: TYE Monthly Fixture Count | M3: Annual kWh | N3: Current Revenue | P3: Code | Q3: TYE Monthly Fixture Count | R3: Annual kWh | S3: Current Revenue | U3: Code | V3: TYE Annual Fixture Count | W3: Annual kWh | X3: Proposed Rate | Y3: Proposed Revenue
B4: Security Lighting | X4: =[1]AEPTX!$D$54 -> 0.31115133
B5: Mercury Vapor*
B6: 175 Watt | C6: 901 | D6: 70 | E6: 3.17 | F6: =(X6-E6)/E6 -> 0.52996845 | G6: 901 | H6: 70 | I6: 4.71 | J6: =(X6-I6)/I6 -> 0.029723992 | K6: 901 | L6: 1331 | M6: =L6*D6*12 -> 1118040 | N6: =ROUND(L6*E6,2)*12 -> 50631.24 | P6: 901 | Q6: 6204 | R6: =Q6*H6*12 -> 5211360 | S6: =ROUND(Q6*I6,2)*12 -> 350650.08 | U6: 901 | V6: =(L6+Q6)*12 -> 90420 | W6: =M6+R6 -> 6329400 | X6: =ROUND(E6*(1+$X$4),2)+0.69 -> 4.85 | Y6: =ROUND(V6*X6,2) -> 438537
B7: 400 Watt | C7: 902 | D7: 145 | E7: 3.91 | F7: =(X7-E7)/E7 -> 0.53452685 | G7: 902 | H7: 145 | I7: 6.66 | J7: =(X7-I7)/I7 -> -0.099099099 | K7: 902 | L7: 1478 | M7: =L7*D7*12 -> 2571720 | N7: =ROUND(L7*E7,2)*12 -> 69347.76 | P7: 902 | Q7: 1809 | R7: =Q7*H7*12 -> 3147660 | S7: =ROUND(Q7*I7,2)*12 -> 144575.28 | U7: 902 | V7: =(L7+Q7)*12 -> 39444 | W7: =M7+R7 -> 5719380 | X7: =ROUND(E7*(1+$X$4),2)+0.87 -> 6 | Y7: =ROUND(V7*X7,2) -> 236664
B9: High Pressure Sodium
B10: 70 Watt | C10: 903 | G10: 903 | H10: 28 | I10: 2.16 | J10: =(X10-I10)/I10 -> 0.31944444 | K10: 903 | P10: 903 | Q10: 2547 | R10: =Q10*H10*12 -> 855792 | S10: =ROUND(Q10*I10,2)*12 -> 66018.24 | U10: 903 | V10: =(L10+Q10)*12 -> 30564 | W10: =M10+R10 -> 855792 | X10: =ROUND(I10*(1+$X$4),2)+0.02 -> 2.85 | Y10: =ROUND(V10*X10,2) -> 87107.4
B11: 100 Watt | C11: 903 | D11: 39 | E11: 2.94 | F11: =(X11-E11)/E11 -> 0.61564626 | G11: 915 | H11: 39 | I11: 5.06 | J11: =(X11-I11)/I11 -> -0.061264822 | K11: 903 | L11: 7623 | M11: =L11*D11*12 -> 3567564 | N11: =ROUND(L11*E11,2)*12 -> 268939.44 | P11: 915 | Q11: 1 | R11: =Q11*H11*12 -> 468 | S11: =ROUND(Q11*I11,2)*12 -> 60.72 | U11: 903/915 | V11: =(L11+Q11)*12 -> 91488 | W11: =M11+R11 -> 3568032 | X11: =X23 -> 4.75 | Y11: =ROUND(V11*X11,2) -> 434568
B12: 150 Watt | C12: 904 | D12: 57 | E12: 3.11 | F12: =(X12-E12)/E12 -> 0.52733119 | G12: 904 | H12: 57 | I12: 2.3 | J12: =(X12-I12)/I12 -> 1.0652174 | K12: 904 | L12: 13234 | M12: =L12*D12*12 -> 9052056 | N12: =ROUND(L12*E12,2)*12 -> 493892.88 | P12: 904 | Q12: 698 | R12: =Q12*H12*12 -> 477432 | S12: =ROUND(Q12*I12,2)*12 -> 19264.8 | U12: 904 | V12: =(L12+Q12)*12 -> 167184 | W12: =M12+R12 -> 9529488 | X12: =X24 -> 4.75 | Y12: =ROUND(V12*X12,2) -> 794124
B13: 250 Watt | C13: 905 | D13: 104 | E13: 3.6 | F13: =(X13-E13)/E13 -> 0.45833333 | G13: 916 | H13: 104 | I13: 6.22 | J13: =(X13-I13)/I13 -> -0.15594855 | K13: 905 | L13: 10759 | M13: =L13*D13*12 -> 13427232 | N13: =ROUND(L13*E13,2)*12 -> 464788.8 | P13: 916 | Q13: 243 | R13: =Q13*H13*12 -> 303264 | S13: =ROUND(Q13*I13,2)*12 -> 18137.52 | U13: 905/916 | V13: =(L13+Q13)*12 -> 132024 | W13: =M13+R13 -> 13730496 | X13: =X25 -> 5.25 | Y13: =ROUND(V13*X13,2) -> 693126
B15: Low Pressure Sodium (Brewster, Jeff Davis, Presidio, Reeves Counties only)
B16: 35 Watt* | C16: 905 | G16: 905 | H16: 24 | I16: 4.09 | J16: =(X16-I16)/I16 -> 0.31051345 | K16: 905 | P16: 905 | Q16: 35 | R16: =Q16*H16*12 -> 10080 | S16: =ROUND(Q16*I16,2)*12 -> 1717.8 | U16: 905 | V16: =(L16+Q16)*12 -> 420 | W16: =M16+R16 -> 10080 | X16: =ROUND(I16*(1+$X$4),2) -> 5.36 | Y16: =ROUND(V16*X16,2) -> 2251.2
B17: 55 Watt | C17: 906 | G17: 906 | H17: 28 | I17: 4.48 | J17: =(X17-I17)/I17 -> 0.31026786 | K17: 906 | P17: 906 | Q17: 75 | R17: =Q17*H17*12 -> 25200 | S17: =ROUND(Q17*I17,2)*12 -> 4032 | U17: 906 | V17: =(L17+Q17)*12 -> 900 | W17: =M17+R17 -> 25200 | X17: =ROUND(I17*(1+$X$4),2) -> 5.87 | Y17: =ROUND(V17*X17,2) -> 5283
B18: 90 Watt | C18: 907 | G18: 907 | H18: 44 | I18: 4.74 | J18: =(X18-I18)/I18 -> 0.31012658 | K18: 907 | P18: 907 | Q18: 38 | R18: =Q18*H18*12 -> 20064 | S18: =ROUND(Q18*I18,2)*12 -> 2161.44 | U18: 907 | V18: =(L18+Q18)*12 -> 456 | W18: =M18+R18 -> 20064 | X18: =ROUND(I18*(1+$X$4),2) -> 6.21 | Y18: =ROUND(V18*X18,2) -> 2831.76
B19: *additional lights not available
B21: Flood Lighting
B22: High Pressure Sodium
B23: 100 Watt | C23: 906 | D23: 39 | E23: 3.6 | F23: =(X23-E23)/E23 -> 0.31944444 | G23: 917 | H23: 39 | I23: 6.23 | J23: =(X23-I23)/I23 -> -0.23756019 | K23: 906 | L23: 1635 | M23: =L23*D23*12 -> 765180 | N23: =ROUND(L23*E23,2)*12 -> 70632 | P23: 917 | Q23: 0 | R23: =Q23*H23*12 -> 0 | S23: =ROUND(Q23*I23,2)*12 -> 0 | U23: 906/917 | V23: =(L23+Q23)*12 -> 19620 | W23: =M23+R23 -> 765180 | X23: =ROUND(E23*(1+$X$4),2)+0.03 -> 4.75 | Y23: =ROUND(V23*X23,2) -> 93195
B24: 150 Watt | G24: 908 | H24: 63 | I24: 2.88 | J24: =(X24-I24)/I24 -> 0.64930556 | P24: 908 | Q24: 714 | R24: =Q24*H24*12 -> 539784 | S24: =ROUND(Q24*I24,2)*12 -> 24675.84 | U24: 908 | V24: =(L24+Q24)*12 -> 8568 | W24: =M24+R24 -> 539784 | X24: =X23 -> 4.75 | Y24: =ROUND(V24*X24,2) -> 40698
B25: 250 Watt | C25: 907 | D25: 104 | E25: 3.99 | F25: =(X25-E25)/E25 -> 0.31578947 | G25: 909 | H25: 104 | I25: 3.73 | J25: =(X25-I25)/I25 -> 0.4075067 | K25: 907 | L25: 5612 | M25: =L25*D25*12 -> 7003776 | N25: =ROUND(L25*E25,2)*12 -> 268702.56 | P25: 909 | Q25: 658 | R25: =Q25*H25*12 -> 821184 | S25: =ROUND(Q25*I25,2)*12 -> 29452.08 | U25: 907/909 | V25: =(L25+Q25)*12 -> 75240 | W25: =M25+R25 -> 7824960 | X25: =ROUND(E25*(1+$X$4),2)+0.02 -> 5.25 | Y25: =ROUND(V25*X25,2) -> 395010
B26: 400 Watt | C26: 908 | D26: 155 | E26: 5.07 | F26: =(X26-E26)/E26 -> 0.094674556 | G26: 910 | H26: 155 | I26: 4.23 | J26: =(X26-I26)/I26 -> 0.31205674 | K26: 908 | L26: 12608 | M26: =L26*D26*12 -> 23450880 | N26: =ROUND(L26*E26,2)*12 -> 767070.72 | P26: 910 | Q26: 1311 | R26: =Q26*H26*12 -> 2438460 | S26: =ROUND(Q26*I26,2)*12 -> 66546.36 | U26: 908/910 | V26: =(L26+Q26)*12 -> 167028 | W26: =M26+R26 -> 25889340 | X26: =ROUND(I26*(1+$X$4),2) -> 5.55 | Y26: =ROUND(V26*X26,2) -> 927005.4
B27: 1,000 Watt | C27: 909 | D27: 367 | E27: 5.55 | F27: =(X27-E27)/E27 -> 0.31531532 | G27: 911 | H27: 367 | I27: 5.86 | J27: =(X27-I27)/I27 -> 0.24573379 | K27: 909 | L27: 4559 | M27: =L27*D27*12 -> 20077836 | N27: =ROUND(L27*E27,2)*12 -> 303629.4 | P27: 911 | Q27: 373 | R27: =Q27*H27*12 -> 1642692 | S27: =ROUND(Q27*I27,2)*12 -> 26229.36 | U27: 909/911 | V27: =(L27+Q27)*12 -> 59184 | W27: =M27+R27 -> 21720528 | X27: =ROUND(E27*(1+$X$4),2)+0.02 -> 7.3 | Y27: =ROUND(V27*X27,2) -> 432043.2
B29: Metal Halide
B30: 250 Watt | C30: 910 | D30: 105 | E30: 5.21 | F30: =(X30-E30)/E30 -> 0.31477927 | G30: 912 | H30: 105 | I30: 5.68 | J30: =(X30-I30)/I30 -> 0.20598592 | K30: 910 | L30: 913 | M30: =L30*D30*12 -> 1150380 | N30: =ROUND(L30*E30,2)*12 -> 57080.76 | P30: 912 | Q30: 322 | R30: =Q30*H30*12 -> 405720 | S30: =ROUND(Q30*I30,2)*12 -> 21947.52 | U30: 910/912 | V30: =(L30+Q30)*12 -> 14820 | W30: =M30+R30 -> 1556100 | X30: =ROUND(E30*(1+$X$4),2)+0.02 -> 6.85 | Y30: =ROUND(V30*X30,2) -> 101517
B31: 400 Watt | C31: 911 | D31: 155 | E31: 5.59 | F31: =(X31-E31)/E31 -> 0.31484794 | G31: 913 | H31: 155 | I31: 6.16 | J31: =(X31-I31)/I31 -> 0.19318182 | K31: 911 | L31: 3530 | M31: =L31*D31*12 -> 6565800 | N31: =ROUND(L31*E31,2)*12 -> 236792.4 | P31: 913 | Q31: 1257 | R31: =Q31*H31*12 -> 2338020 | S31: =ROUND(Q31*I31,2)*12 -> 92917.44 | U31: 911/913 | V31: =(L31+Q31)*12 -> 57444 | W31: =M31+R31 -> 8903820 | X31: =ROUND(E31*(1+$X$4),2)+0.02 -> 7.35 | Y31: =ROUND(V31*X31,2) -> 422213.4
B32: 1,000 Watt | G32: 914 | H32: 367 | I32: 7.4 | J32: =(X32-I32)/I32 -> 0.31081081 | P32: 914 | Q32: 501 | R32: =Q32*H32*12 -> 2206404 | S32: =ROUND(Q32*I32,2)*12 -> 44488.8 | V32: =(L32+Q32)*12 -> 6012 | W32: =M32+R32 -> 2206404 | X32: =ROUND(I32*(1+$X$4),2) -> 9.7 | Y32: =ROUND(V32*X32,2) -> 58316.4
B33: 1,000 Watt 6x7 NBP | C33: 912 | D33: 367 | E33: 6.67 | F33: =(X33-E33)/E33 -> 0.31184408 | K33: 912 | L33: 3503 | M33: =L33*D33*12 -> 15427212 | N33: =ROUND(L33*E33,2)*12 -> 280380.12 | U33: 912 | V33: =(L33+Q33)*12 -> 42036 | W33: =M33+R33 -> 15427212 | X33: =ROUND(E33*(1+$X$4),2) -> 8.75 | Y33: =ROUND(V33*X33,2) -> 367815
B34: 1,000 Watt 3x3 NBP | C34: 913 | D34: 367 | E34: 6.67 | F34: =(X34-E34)/E34 -> 0.31184408 | K34: 913 | L34: 160 | M34: =L34*D34*12 -> 704640 | N34: =ROUND(L34*E34,2) -> 1067.2 | U34: 913 | V34: =(L34+Q34)*12 -> 1920 | W34: =M34+R34 -> 704640 | X34: =ROUND(E34*(1+$X$4),2) -> 8.75 | Y34: =ROUND(V34*X34,2) -> 16800
B36: 20-60 Watt LED | C36: 980 | D36: 14 | U36: 918 | V36: new offering | X36: =MSL!X55 -> 6.35
B37: 61-100 Watt LED | C37: 981 | D37: 29 | U37: 919 | V37: new offering | X37: =MSL!X56 -> 6.46
B38: 120-160 Watt LED | C38: 982 | D38: 46 | U38: 920 | V38: new offering | X38: =MSL!X57 -> 9.44
B39: 200-240 Watt LED | C39: 983 | D39: 73 | U39: 921 | V39: new offering | X39: =MSL!X58 -> 11.53
B40: 40-80 Watt LED Open Bottom | D40: 19 | U40: 922 | V40: new offering | X40: =MSL!X60 -> 5.7511081
B41: 130-170 Watt LED Floodlight | D41: 50 | U41: 923 | V41: new offering | X41: =MSL!X61 -> 16.001108
B44: *MV no longer available | L44: =SUM(L6:L34) -> 66945 | M44: =SUM(M6:M34) -> 104882316 | N44: =SUM(N6:N34) -> 3332955.3 | Q44: =SUM(Q6:Q34) -> 16786 | R44: =SUM(R6:R34) -> 20443584 | S44: =SUM(S6:S34) -> 912875.28 | U44: annual fixtures | V44: =SUM(V6:V34) -> 1004772 | X44: Billed Rev | Y44: =SUM(Y6:Y39) -> 5549105.8
B45: Non-Roadway Lighting rates for transmission and Distribution Service are the same as the Secondary <= 10 kW rates | U45: total fixtures | V45: =L44+Q44 -> 83731 | X45: Rev Req | Y45: =[1]AEPTX!$B$52+[1]AEPTX!$C$52 -> 5551190.6
B46: Non-Roadway Lighting rates are non-metered | V46: =V45*12 -> 1004772 | X46: Difference | Y46: =Y44-Y45 -> -2084.81
