Workbook

Sheet AEP TX 451 Pro forma
C2: AEP TEXAS | D2: DISCRETIONARY SERVICE FEES REVENUE | L2: AEP TEXAS COMBINED | O2: CENTRAL | R2: NORTH
B3: CODE | C3: DISCRETIONARY SERVICE | D3: CENTRAL | E3: NORTH | F3: TOTAL TEST YEAR | H3: AEP TEXAS PROPOSED | I3: ANNUAL OCCURRENCES | J3: TOTAL | L3: DISTRIBUTION FUNCTION | M3: METER FUNCTION | O3: DISTRIBUTION FUNCTION | P3: METER FUNCTION | R3: DISTRIBUTION FUNCTION | S3: METER FUNCTION
B4: AMEDF | C4: ADV MTR EQP INSTL/MTR DATA FEE | D4: ='Central Discretionary Fees'!Q5 -> 1272 | E4: 0 | F4: =D4+E4 -> 1272 | H4: as calculated | I4: varies | J4: =F4 -> 1272 | M4: =J4-F4 -> 0 | P4: ='Central Discretionary Fees'!V5 -> 0 | S4: 0
B5: BCNSV | C5: BUILDER CONSTRUCTION SRV FEE | D5: ='Central Discretionary Fees'!Q6 -> 104619 | E5: ='North Discretionary Fees'!Q5 -> 24859 | F5: =D5+E5 -> 129478 | H5: removed | I5: 0 | J5: 0 | L5: =J5-F5 -> -129478 | O5: ='Central Discretionary Fees'!V6 -> -104619 | R5: ='North Discretionary Fees'!V5 -> -24860
B6: BSFEE | C6: BROKEN METER SEAL | D6: ='Central Discretionary Fees'!Q7 -> 27776 | E6: ='North Discretionary Fees'!Q6 -> 11180 | F6: =D6+E6 -> 38956 | H6: 29 | I6: ='Central Discretionary Fees'!S7+'North Discretionary Fees'!S6 -> 620 | J6: =ROUND(I6*H6,2) -> 17980 | M6: =J6-F6 -> -20976 | P6: ='Central Discretionary Fees'!V7 -> -14784 | S6: ='North Discretionary Fees'!V6 -> -6192
B7: DAFEE | C7: METER ACCESS DENIAL | D7: ='Central Discretionary Fees'!Q8 -> 1462 | E7: ='North Discretionary Fees'!Q7 -> 236 | F7: =D7+E7 -> 1698 | H7: 100 | I7: ='Central Discretionary Fees'!S8+'North Discretionary Fees'!S7 -> 34 | J7: =F7 -> 1698 | M7: =J7-F7 -> 0 | P7: ='Central Discretionary Fees'!V8 -> 0 | S7: ='North Discretionary Fees'!V7 -> 0
B9: DOFEE | C9: DISPATCHED ORDER FEE | D9: ='Central Discretionary Fees'!Q9 -> 138110 | E9: ='North Discretionary Fees'!Q8 -> 19930 | F9: =D9+E9 -> 158040
C10: CANCEL ROUTINE | H10: removed | I10: ='Central Discretionary Fees'!S10+'North Discretionary Fees'!S9 -> 6860 | J10: 0
C11: CANCEL PRIORITY | H11: removed | I11: ='Central Discretionary Fees'!S11+'North Discretionary Fees'!S10 -> 8 | J11: 0
C12: UNEXECUTABLE ROUTINE | H12: 25 | I12: ='Central Discretionary Fees'!S12+'North Discretionary Fees'!S11 -> 3397 | J12: =ROUND(I12*H12,2) -> 84925
C13: UNEXECUTABLE PRIORITY | H13: 33 | I13: ='Central Discretionary Fees'!S13+'North Discretionary Fees'!S12 -> 24 | J13: =ROUND(I13*H13,2) -> 792 | L13: =(J12+J13)-F9 -> -72323 | O13: =SUM('Central Discretionary Fees'!V10:V13) -> -58368 | R13: =SUM('North Discretionary Fees'!V9:V12) -> -13955
B15: ENDIV | C15: ENERGY DIVERSION | D15: ='Central Discretionary Fees'!Q14 -> 78357.66 | E15: ='North Discretionary Fees'!Q14 -> 35036.06 | F15: =D15+E15 -> 113393.72 | H15: as calculated | I15: varies | J15: =F15 -> 113393.72 | L15: =J15-F15 -> 0 | O15: ='Central Discretionary Fees'!V14 -> 0
B16: LPCPR | C16: LATE PYMT CHRG TEXAS | D16: ='Central Discretionary Fees'!Q15 -> 0 | E16: ='North Discretionary Fees'!Q15 -> 0 | F16: =D16+E16 -> 0 | H16: as calculated | I16: varies | J16: =F16 -> 0 | L16: =J16-F16 -> 0 | O16: ='Central Discretionary Fees'!V15 -> 0
B17: OPOUT | C17: AMS OPTOUT CHARGE RECURRING | D17: ='Central Discretionary Fees'!Q16 -> 20064 | E17: ='North Discretionary Fees'!Q16 -> 11304 | F17: =D17+E17 -> 31368 | H17: 40 | I17: ='Central Discretionary Fees'!S16+'North Discretionary Fees'!S16 -> 1370 | J17: =ROUND(I17*H17,2) -> 54800 | M17: =J17-F17 -> 23432 | P17: ='Central Discretionary Fees'!V16 -> 22176 | S17: ='North Discretionary Fees'!V16 -> 1256
B19: PDFEE | C19: PRIORITY DISCONNECT | D19: ='Central Discretionary Fees'!Q17 -> 192720 | E19: ='North Discretionary Fees'!Q17 -> 38546 | F19: =D19+E19 -> 231266
C20: AT METER NON-STANDARD | H20: 32 | I20: ='Central Discretionary Fees'!S18+'North Discretionary Fees'!S18 -> 4507 | J20: =ROUND(I20*H20,2) -> 144224
C21: AT PREMIUM LOCATION NON-STANDARD | H21: 72 | I21: ='Central Discretionary Fees'!S19+'North Discretionary Fees'!S19 -> 270 | J21: =ROUND(I21*H21,2) -> 19440
C22: AT PREMIUM LOCATION STANDARD | H22: 72 | I22: ='Central Discretionary Fees'!S20+'North Discretionary Fees'!S20 -> 2224 | J22: =ROUND(I22*H22,2) -> 160128 | L22: =(J20+J21+J22)-F19 -> 92526 | O22: =SUM('Central Discretionary Fees'!V18:V20) -> 80276 | R22: =SUM('North Discretionary Fees'!V18:V20) -> 12246
B24: RECON | C24: RECONNECT CHARGE | D24: ='Central Discretionary Fees'!Q21 -> 111507 | E24: ='North Discretionary Fees'!Q21 -> 14678 | F24: =D24+E24 -> 126185
C25: AT METER NON STANDARD
C26: STANDARD RECONNECT | H26: 49 | I26: ='Central Discretionary Fees'!S23+'North Discretionary Fees'!S23 -> 2646 | J26: =ROUND(I26*H26,2) -> 129654
C27: SAME DAY RECONNECT | H27: 69 | I27: ='Central Discretionary Fees'!S24+'North Discretionary Fees'!S24 -> 369 | J27: =ROUND(I27*H27,2) -> 25461
C28: WEEKEND | H28: 86 | I28: ='Central Discretionary Fees'!S25+'North Discretionary Fees'!S25 -> 121 | J28: =ROUND(I28*H28,2) -> 10406
C29: HOLIDAY | H29: 125 | I29: ='Central Discretionary Fees'!S26+'North Discretionary Fees'!S26 -> 0 | J29: =ROUND(I29*H29,2) -> 0
C30: AT PREMIUM LOCATION STANDARD & NON STANDARD
C31: STANDARD RECONNECT | H31: 98 | I31: ='Central Discretionary Fees'!S28+'North Discretionary Fees'!S28 -> 909 | J31: =ROUND(I31*H31,2) -> 89082
C32: SAME DAY RECONNECT | H32: 134 | I32: ='Central Discretionary Fees'!S29+'North Discretionary Fees'!S29 -> 40 | J32: =ROUND(I32*H32,2) -> 5360
C33: WEEKEND | H33: 134 | I33: ='Central Discretionary Fees'!S30+'North Discretionary Fees'!S30 -> 0 | J33: =ROUND(I33*H33,2) -> 0
C34: HOLIDAY | H34: 170 | I34: ='Central Discretionary Fees'!S31+'North Discretionary Fees'!S31 -> 1 | J34: =ROUND(I34*H34,2) -> 170 | L34: =SUM(J26:J34)-F24 -> 133948 | O34: =SUM('Central Discretionary Fees'!V23:V31) -> 116561 | R34: =SUM('North Discretionary Fees'!V23:V31) -> 17403
B36: SCTRF | C36: SERV COND TEMP REMVL (CLEARANCE) | D36: ='Central Discretionary Fees'!Q33 -> 29840.34 | E36: ='North Discretionary Fees'!Q33 -> 5497 | F36: =D36+E36 -> 35337.34 | H36: as calculated | I36: varies | J36: =F36 -> 35337.34 | L36: =J36-F36 -> 0 | O36: ='Central Discretionary Fees'!V33 -> 0 | R36: ='North Discretionary Fees'!V33 -> 0
B37: SPSFE | C37: SPEC PROD/SERV FEE | D37: ='Central Discretionary Fees'!Q34 -> 2106.17 | E37: ='North Discretionary Fees'!Q34 -> 705 | F37: =D37+E37 -> 2811.17 | H37: as calculated | I37: varies | J37: =F37 -> 2811.17 | L37: =J37-F37 -> 0 | O37: ='Central Discretionary Fees'!V34 -> 0 | R37: ='North Discretionary Fees'!V34 -> 0
B38: SRFEE | C38: SPECIAL MTR READ FEE | D38: ='Central Discretionary Fees'!Q35 -> 48 | E38: ='North Discretionary Fees'!Q35 -> 16 | F38: =D38+E38 -> 64 | H38: 40 | I38: ='Central Discretionary Fees'!S35+'North Discretionary Fees'!S35 -> 4 | J38: =ROUND(I38*H38,2) -> 160 | M38: =J38-F38 -> 96 | P38: ='Central Discretionary Fees'!V35 -> 72 | S38: ='North Discretionary Fees'!V35 -> 24
B40: SVCHG | C40: SERVICE CHARGE | D40: ='Central Discretionary Fees'!Q36 -> 94752 | E40: ='North Discretionary Fees'!Q36 -> 11058 | F40: =D40+E40 -> 105810
C41: DURING BUSINESS DAYS 8:00 AM - 5:00 PM CPT | H41: 81 | I41: ='Central Discretionary Fees'!S37+'North Discretionary Fees'!S37 -> 598 | J41: =ROUND(I41*H41,2) -> 48438
C42: DURING BUSINESS DAYS NON-BUSINESS HOURS | H42: 110 | I42: ='Central Discretionary Fees'!S38+'North Discretionary Fees'!S38 -> 450 | J42: =ROUND(I42*H42,2) -> 49500
C43: WEEKEND | H43: 110 | I43: ='Central Discretionary Fees'!S39+'North Discretionary Fees'!S39 -> 0 | J43: =ROUND(I43*H43,2) -> 0
C44: HOLIDAY | H44: 140 | I44: ='Central Discretionary Fees'!S40+'North Discretionary Fees'!S40 -> 20 | J44: =ROUND(I44*H44,2) -> 2800 | L44: =SUM(J41:J44)-F40 -> -5072 | O44: =SUM('Central Discretionary Fees'!V37:V40) -> -4661 | R44: =SUM('North Discretionary Fees'!V37:V40) -> -411
B46: SVCON | C46: SERVICE CONN CHARGE | D46: ='Central Discretionary Fees'!Q41 -> 1094266 | E46: ='North Discretionary Fees'!Q41 -> 284805 | F46: =D46+E46 -> 1379071
C47: NON-STANDARD METER CT NEW | H47: 287 | I47: ='Central Discretionary Fees'!S42+'North Discretionary Fees'!S42 -> 477 | J47: =ROUND(I47*H47,2) -> 136899
C48: NON-STANDARD METER CT EXISTING | H48: 134 | I48: ='Central Discretionary Fees'!S43+'North Discretionary Fees'!S43 -> 779 | J48: =ROUND(I48*H48,2) -> 104386
...

Sheet Central Discretionary Fees
D2: Central Miscellaneouse Service Fees Account 451 Detail | E2: TCC Miscellaneouse Service Fees Account 451 Detail
B4: CO. | C4: CODE | D4: DISCRETIONARY SERVICE | E4: 201801 | F4: 201802 | G4: 201803 | H4: 201804 | I4: 201805 | J4: 201806 | K4: 201807 | L4: 201808 | M4: 201809 | N4: 201810 | O4: 201811 | P4: 201812 | Q4: Sum: | R4: FEE | S4: ANNUAL OCCURRENCES | T4: CURRENT REVENUE | U4: AEPTX | V4: CHANGE
B5: 94 | C5: AMEDF | D5: ADV MTR EQP INSTL/MTR DATA FEE | E5: 848 | F5: 424 | G5: 0.00 | H5: 570 | I5: -570 | J5: 0.00 | K5: 0.00 | L5: 0.00 | M5: 0.00 | N5: 0.00 | O5: 0.00 | P5: 0.00 | Q5: 1272 | S5: 2 | T5: =Q5 -> 1272 | U5: varies | V5: =T5-Q5 -> 0
B6: 94 | C6: BCNSV | D6: BUILDER CONSTRUCTION SRV FEE | E6: 7654 | F6: 10062 | G6: 8428 | H6: 10191 | I6: 10492 | J6: 9632 | K6: 8643 | L6: 10062 | M6: 6493 | N6: 7826 | O6: 7998 | P6: 7138 | Q6: 104619 | R6: 43 | S6: 2433 | T6: =R6*S6 -> 104619 | U6: ='AEP TX 451 Pro forma'!H5 -> removed | V6: =-T6 -> -104619
B7: 94 | C7: BSFEE | D7: BROKEN METER SEAL | E7: 2852 | F7: 2542 | G7: 2170 | H7: 1736 | I7: 2046 | J7: 2728 | K7: 2356 | L7: 2666 | M7: 2418 | N7: 2294 | O7: 1798 | P7: 2170 | Q7: 27776 | R7: 62 | S7: 448 | T7: =R7*S7 -> 27776 | U7: ='AEP TX 451 Pro forma'!H6 -> 29 | V7: =(U7*S7)-T7 -> -14784
B8: 94 | C8: DAFEE | D8: METER ACCESS DENIAL | E8: 0 | F8: 336 | G8: 0 | H8: 224 | I8: 168 | J8: 112 | K8: 0.00 | L8: 0 | M8: 224 | N8: 224 | O8: 62 | P8: 112 | Q8: 1462 | R8: 56 | S8: 30 | T8: =Q8 -> 1462 | U8: ='AEP TX 451 Pro forma'!H7 -> 100 | V8: 0
B9: 94 | C9: DOFEE | D9: DISPATCHED ORDER FEE | E9: 12380 | F9: 10648 | G9: 11461 | H9: 11958 | I9: 10155 | J9: 11593 | K9: 9728 | L9: 11585 | M9: 12016 | N9: 15396 | O9: 12025 | P9: 9165 | Q9: 138110
D10: CANCEL ROUTINE | R10: 13 | S10: =2833+526+526+85+181+181+181+19+19+86+86+86+86+14+36+36+36+36+36+4+34+34+34+34+34+16+2+126+3+6+7+64+19+63+18+8+60+1+11+13+3+13+2 -> 5698 | T10: =R10*S10 -> 74074 | U10: ='AEP TX 451 Pro forma'!H10 -> removed | V10: =-T10 -> -74074
D11: CANCEL PRIORITY | R11: 22 | S11: 6 | T11: =R11*S11 -> 132 | U11: ='AEP TX 451 Pro forma'!H11 -> removed | V11: =-T11 -> -132
D12: UNEXECUTABLE ROUTINE | R12: 20 | S12: =2584+85+76+76+19+14+14+11+11+11+4+4+3+36+11+1+20+6+11+6+8+6+18+20+6+7+6+24+9+46+5 -> 3158 | T12: =R12*S12 -> 63160 | U12: ='AEP TX 451 Pro forma'!H12 -> 25 | V12: =(U12*S12)-T12 -> 15790
D13: UNEXECUTABLE PRIORITY | R13: 31 | S13: =14+10 -> 24 | T13: =R13*S13 -> 744 | U13: ='AEP TX 451 Pro forma'!H13 -> 33 | V13: =(U13*S13)-T13 -> 48
B14: 94 | C14: ENDIV | D14: ENERGY DIVERSION | E14: 9323.57 | F14: 5851.06 | G14: 4310.55 | H14: 5066.72 | I14: 5798.17 | J14: 6641.52 | K14: 6169.77 | L14: 8998.01 | M14: 7343.29 | N14: 7551.59 | O14: 5752.85 | P14: 5550.56 | Q14: 78357.66 | S14: 235 | T14: =Q14 -> 78357.66 | U14: ='AEP TX 451 Pro forma'!H15 -> as calculated | V14: 0
B15: 94 | C15: LPCPR | D15: LATE PYMT CHRG TEXAS | E15: 0 | F15: 0 | G15: 0 | H15: 0 | I15: 0 | J15: 0 | K15: 0 | L15: 0 | M15: 0 | N15: 0 | O15: 0 | P15: 0 | Q15: 0 | S15: 0 | U15: ='AEP TX 451 Pro forma'!H16 -> as calculated | V15: 0
B16: 94 | C16: OPOUT | D16: AMS OPTOUT CHARGE RECURRING | E16: 1653 | F16: 1615 | G16: 1672 | H16: 1672 | I16: 1653 | J16: 1672 | K16: 1615 | L16: 1710 | M16: 1672 | N16: 1672 | O16: 1710 | P16: 1748 | Q16: 20064 | R16: 19 | S16: 1056 | T16: =R16*S16 -> 20064 | U16: ='AEP TX 451 Pro forma'!H17 -> 40 | V16: =(U16*S16)-T16 -> 22176
B17: 94 | C17: PDFEE | D17: PRIORITY DISCONNECT | E17: 19404 | F17: 15040 | G17: 17052 | H17: 15280 | I17: 15256 | J17: 13828 | K17: 14300 | L17: 16488 | M17: 16340 | N17: 19440 | O17: 16968 | P17: 13324 | Q17: 192720
D18: AT METER NON-STANDARD | R18: 20 | S18: =4038-27 -> 4011 | T18: =R18*S18 -> 80220 | U18: ='AEP TX 451 Pro forma'!H20 -> 32 | V18: =(U18*S18)-T18 -> 48132
D19: AT PREMIUM LOCATION NON-STANDARD | R19: 56 | S19: 209 | T19: =R19*S19 -> 11704 | U19: ='AEP TX 451 Pro forma'!H21 -> 72 | V19: =(U19*S19)-T19 -> 3344
D20: AT PREMIUM LOCATION STANDARD | R20: 56 | S20: 1800 | T20: =R20*S20 -> 100800 | U20: ='AEP TX 451 Pro forma'!H22 -> 72 | V20: =(U20*S20)-T20 -> 28800
B21: 94 | C21: RECON | D21: RECONNECT CHARGE | E21: 11955 | F21: 9405 | G21: 9862 | H21: 8939 | I21: 8480 | J21: 8070 | K21: 7085 | L21: 10046 | M21: 8998 | N21: 11822 | O21: 9322 | P21: 7523 | Q21: 111507
D22: At Meter Non-Standard
D23: Standard Reconnect | R23: 20 | S23: =1121+256+256+32+246+23+6+14+152+26+1+35+9+16+4+24+6+8+11+21+1+8+8+2+1+5+6+3+84 -> 2385 | T23: =R23*S23 -> 47700 | U23: ='AEP TX 451 Pro forma'!H26 -> 49 | V23: =(U23*S23)-T23 -> 69165
D24: Same Day Reconnect | R24: 38 | S24: =160+32+30+7+12+18+6+1+3+5+2+4+2+4+8+12+3+2+37+5 -> 353 | T24: =R24*S24 -> 13414 | U24: ='AEP TX 451 Pro forma'!H27 -> 69 | V24: =(U24*S24)-T24 -> 10943
D25: Weekend | R25: 48 | S25: =54+24+10+3+2+1+2+1+1+1+2+1 -> 102 | T25: =R25*S25 -> 4896 | U25: ='AEP TX 451 Pro forma'!H28 -> 86 | V25: =(U25*S25)-T25 -> 3876
D26: Holiday | R26: 60 | T26: =R26*S26 -> 0 | U26: ='AEP TX 451 Pro forma'!H29 -> 125 | V26: 0
D27: At Premium Location Standard & Non-Standard
D28: Standard Reconnect | R28: 56 | S28: =510+7+2+74+74+3+2+48+20+13+4 -> 757 | T28: =R28*S28 -> 42392 | U28: ='AEP TX 451 Pro forma'!H31 -> 98 | V28: =(U28*S28)-T28 -> 31794
D29: Same Day Reconnect | R29: 107 | S29: =19+2+5+1+2 -> 29 | T29: =R29*S29 -> 3103 | U29: ='AEP TX 451 Pro forma'!H32 -> 134 | V29: =(U29*S29)-T29 -> 783
D30: Weekend | R30: 107 | T30: =R30*S30 -> 0 | U30: ='AEP TX 451 Pro forma'!H33 -> 134 | V30: 0
D31: Holiday | R31: 133 | T31: =R31*S31 -> 0 | U31: ='AEP TX 451 Pro forma'!H34 -> 170 | V31: 0
B33: 94 | C33: SCTRF | D33: SERV COND TEMP REMVL | E33: -75 | F33: 2427.35 | G33: 6750 | H33: 3825 | I33: 150 | J33: 300 | K33: 4336.85 | L33: 3300 | M33: 2775 | N33: 2451.21 | O33: 2549.93 | P33: 1050 | Q33: 29840.34 | R33: as calc | T33: =Q33 -> 29840.34 | U33: ='AEP TX 451 Pro forma'!H36 -> as calculated | V33: 0
B34: 94 | C34: SPSFE | D34: SPEC PROD/SERV FEE | E34: 106 | F34: 76 | G34: 1075.17 | H34: 106 | I34: 61 | J34: 121 | K34: 46 | L34: 61 | M34: 136 | N34: 76 | O34: 107 | P34: 135 | Q34: 2106.17 | R34: as calc | T34: =Q34 -> 2106.17 | U34: ='AEP TX 451 Pro forma'!H37 -> as calculated | V34: 0
B35: 94 | C35: SRFEE | D35: SPECIAL MTR READ FEE | E35: 0.00 | F35: 0.00 | G35: 0.00 | H35: 16 | I35: 0.00 | J35: 0 | K35: 0 | L35: 0 | M35: 16 | N35: 0.00 | O35: 0.00 | P35: 16 | Q35: 48 | R35: 16 | S35: 3 | T35: =R35*S35 -> 48 | U35: ='AEP TX 451 Pro forma'!H38 -> 40 | V35: =(U35*S35)-T35 -> 72
B36: 94 | C36: SVCHG | D36: SERVICE CHARGE | E36: 13898 | F36: 6972 | G36: 8964 | H36: 6981 | I36: 7663 | J36: 8516 | K36: 10075 | L36: 5328 | M36: 7630 | N36: 7024 | O36: 8005 | P36: 3696 | Q36: 94752
D37: During Business Days 8:00am-5:00pm CPT | R37: 70 | S37: =514+12+5-12+2 -> 521 | T37: =R37*S37 -> 36470 | U37: ='AEP TX 451 Pro forma'!H41 -> 81 | V37: =(U37*S37)-T37 -> 5731
D38: During Business Days Non-Business Hours | R38: 134 | S38: =408+10-3 -> 415 | T38: =R38*S38 -> 55610 | U38: ='AEP TX 451 Pro forma'!H42 -> 110 | V38: =(U38*S38)-T38 -> -9960
D39: Weekend | R39: 134 | U39: ='AEP TX 451 Pro forma'!H43 -> 110 | V39: 0
D40: Holiday | R40: 167 | S40: =17-1 -> 16 | T40: =R40*S40 -> 2672 | U40: ='AEP TX 451 Pro forma'!H44 -> 140 | V40: =(U40*S40)-T40 -> -432
B41: 94 | C41: SVCON | D41: SERVICE CONN CHARGE | E41: 82496 | F41: 102782 | G41: 101821 | H41: 100738 | I41: 101798 | J41: 88064 | K41: 90396 | L41: 100787 | M41: 78192 | N41: 85937 | O41: 79810 | P41: 81445 | Q41: 1094266
D42: CT NEW NON-STANDARD METER | R42: 301 | S42: 354 | T42: =R42*S42 -> 106554 | U42: ='AEP TX 451 Pro forma'!H47 -> 287 | V42: =(U42*S42)-T42 -> -4956
D43: CT EXISTING NON-STANDARD METER | R43: 102 | S43: =24+633 -> 657 | T43: =R43*S43 -> 67014 | U43: ='AEP TX 451 Pro forma'!H48 -> 134 | V43: =(U43*S43)-T43 -> 21024
...

Sheet North Discretionary Fees
D2: North Miscellaneouse Service Fees Account 451 Detail | E2: TNC Miscellaneouse Service Fees Account 451 Detail
B4: CO. | C4: CODE | D4: DISCRETIONARY SERVICE | E4: 201801 | F4: 201802 | G4: 201803 | H4: 201804 | I4: 201805 | J4: 201806 | K4: 201807 | L4: 201808 | M4: 201809 | N4: 201810 | O4: 201811 | P4: 201812 | Q4: Sum: | R4: FEE | S4: ANNUAL OCCURRENCES | U4: AEPTX | V4: CHANGE
B5: 97 | C5: BCNSV | D5: BUILDER CONSTRUCTION SRV FEE | E5: 2068 | F5: 2244 | G5: 2376 | H5: 2244 | I5: 2156 | J5: 2112 | K5: 1848 | L5: 2816 | M5: 1188 | N5: 1892 | O5: 1979 | P5: 1936 | Q5: 24859 | R5: 44 | S5: 565 | T5: =R5*S5 -> 24860 | U5: ='AEP TX 451 Pro forma'!H5 -> removed | V5: =-T5 -> -24860
B6: 97 | C6: BSFEE | D6: BROKEN METER SEAL | E6: 585 | F6: 975 | G6: 1235 | H6: 650 | I6: 910 | J6: 1040 | K6: 910 | L6: 1235 | M6: 1235 | N6: 975 | O6: 585 | P6: 845 | Q6: 11180 | R6: 65 | S6: 172 | T6: =R6*S6 -> 11180 | U6: ='AEP TX 451 Pro forma'!H6 -> 29 | V6: =(U6*S6)-T6 -> -6192
B7: 97 | C7: DAFEE | D7: METER ACCESS DENIAL | E7: 0.00 | F7: 0 | G7: 0.00 | H7: 0.00 | I7: 62 | J7: 0.00 | K7: 0.00 | L7: 0.00 | M7: 0.00 | N7: 174 | O7: 0.00 | P7: 0.00 | Q7: 236 | R7: as calc | S7: 4 | T7: =Q7 -> 236 | U7: 0 | V7: 0
B8: 97 | C8: DOFEE | D8: DISPATCHED ORDER FEE | E8: 1672 | F8: 1658 | G8: 1648 | H8: 2024 | I8: 1258 | J8: 1229 | K8: 1659 | L8: 1816 | M8: 1616 | N8: 1932 | O8: 1865 | P8: 1553 | Q8: 19930
D9: CANCEL ROUTINE | R9: 13 | S9: =524+128+128+2+120+4+124+1+1+55+30+14+16+10+5 -> 1162 | T9: =R9*S9 -> 15106 | U9: ='AEP TX 451 Pro forma'!H10 -> removed | V9: =-T9 -> -15106
D10: CANCEL PRIORITY | R10: 22 | S10: 2 | T10: =R10*S10 -> 44 | U10: ='AEP TX 451 Pro forma'!H11 -> removed | V10: =-T10 -> -44
D11: UNEXECUTABLE ROUTINE | R11: 20 | S11: =221+2+6+2+1+3+4 -> 239 | T11: =R11*S11 -> 4780 | U11: ='AEP TX 451 Pro forma'!H12 -> 25 | V11: =(U11*S11)-T11 -> 1195
D12: UNEXECUTABLE PRIORITY | R12: 32 | T12: =R12*S12 -> 0 | U12: ='AEP TX 451 Pro forma'!H13 -> 33 | V12: =(U12*S12)-T12 -> 0
B14: 97 | C14: ENDIV | D14: ENERGY DIVERSION | E14: 2627.43 | F14: 3824.12 | G14: 2878.71 | H14: 2144.67 | I14: 2405.18 | J14: 3650.81 | K14: 3052.17 | L14: 5079.26 | M14: 2051.85 | N14: 3491.38 | O14: 1387.24 | P14: 2443.24 | Q14: 35036.06 | R14: varies | S14: 84 | T14: =Q14 -> 35036.06 | U14: ='AEP TX 451 Pro forma'!H15 -> as calculated | V14: 0
B15: 97 | C15: LPCPR | D15: LATE PYMT CHRG TEXAS | E15: 0 | F15: 0 | G15: 0 | H15: 0 | I15: 0 | J15: 0 | K15: 0 | L15: 0 | M15: 0 | N15: 0 | O15: 0 | P15: 0 | Q15: 0 | R15: varies | T15: =Q15 -> 0 | U15: ='AEP TX 451 Pro forma'!H16 -> as calculated | V15: 0
B16: 97 | C16: OPOUT | D16: AMS OPTOUT CHARGE RECURRING | E16: 972 | F16: 972 | G16: 936 | H16: 936 | I16: 936 | J16: 936 | K16: 936 | L16: 1008 | M16: 936 | N16: 900 | O16: 936 | P16: 900 | Q16: 11304 | R16: 36 | S16: 314 | T16: =R16*S16 -> 11304 | U16: ='AEP TX 451 Pro forma'!H17 -> 40 | V16: =(U16*S16)-T16 -> 1256
B17: 97 | C17: PDFEE | D17: PRIORITY DISCONNECT | E17: 3728 | F17: 3619 | G17: 3825 | H17: 2542 | I17: 2449 | J17: 2317 | K17: 3339 | L17: 3411 | M17: 3624 | N17: 4621 | O17: 2643 | P17: 2428 | Q17: 38546
D18: AT METER NON-STANDARD | R18: 21 | S18: 496 | T18: =R18*S18 -> 10416 | U18: ='AEP TX 451 Pro forma'!H20 -> 32 | V18: =(U18*S18)-T18 -> 5456
D19: AT PREMIUM LOCATION NON-STANDARD | R19: 58 | S19: 61 | T19: =R19*S19 -> 3538 | U19: ='AEP TX 451 Pro forma'!H21 -> 72 | V19: =(U19*S19)-T19 -> 854
D20: AT PREMIUM LOCATION STANDARD | R20: 58 | S20: 424 | T20: =R20*S20 -> 24592 | U20: ='AEP TX 451 Pro forma'!H22 -> 72 | V20: =(U20*S20)-T20 -> 5936
B21: 97 | C21: RECON | D21: RECONNECT CHARGE | E21: 1265 | F21: 1838 | G21: 1286 | H21: 793 | I21: 731 | J21: 878 | K21: 1439 | L21: 1210 | M21: 1081 | N21: 1358 | O21: 1306 | P21: 1493 | Q21: 14678
D22: At Meter Non-Standard
D23: Standard Reconnect | R23: 11 | S23: =127+28+28+18+12+2+5+4+3+11+1+1+21 -> 261 | T23: =R23*S23 -> 2871 | U23: ='Central Discretionary Fees'!U23 -> 49 | V23: =(U23*S23)-T23 -> 9918
D24: Same Day Reconnect | R24: 39 | S24: =11+2+3 -> 16 | T24: =R24*S24 -> 624 | U24: ='Central Discretionary Fees'!U24 -> 69 | V24: =(U24*S24)-T24 -> 480
D25: Weekend | R25: 53 | S25: =13+4+2 -> 19 | T25: =R25*S25 -> 1007 | U25: ='Central Discretionary Fees'!U25 -> 86 | V25: =(U25*S25)-T25 -> 627
D26: Holiday | R26: 66 | T26: =R26*S26 -> 0 | U26: ='Central Discretionary Fees'!U26 -> 125 | V26: =(U26*S26)-T26 -> 0
D27: At Premium Location Standard & Non-Standard
D28: Standard Reconnect | R28: 58 | S28: =114+3+2+22+9+2 -> 152 | T28: =R28*S28 -> 8816 | U28: ='Central Discretionary Fees'!U28 -> 98 | V28: =(U28*S28)-T28 -> 6080
D29: Same Day Reconnect | R29: 110 | S29: =8+3 -> 11 | T29: =R29*S29 -> 1210 | U29: ='Central Discretionary Fees'!U29 -> 134 | V29: =(U29*S29)-T29 -> 264
D30: Weekend | R30: 110 | T30: =R30*S30 -> 0 | U30: ='Central Discretionary Fees'!U30 -> 134 | V30: =(U30*S30)-T30 -> 0
D31: Holiday | R31: 136 | S31: 1 | T31: =R31*S31 -> 136 | U31: ='Central Discretionary Fees'!U31 -> 170 | V31: =(U31*S31)-T31 -> 34
B33: 97 | C33: SCTRF | D33: SERV COND TEMP REMVL | E33: 0.00 | F33: 150 | G33: 1050 | H33: 825 | I33: 0.00 | J33: 0.00 | K33: 750 | L33: 525 | M33: 525 | N33: 697 | O33: 825 | P33: 150 | Q33: 5497 | R33: as calc | S33: 72 | T33: =Q33 -> 5497 | U33: ='AEP TX 451 Pro forma'!H36 -> as calculated | V33: 0
B34: 97 | C34: SPSFE | D34: SPEC PROD/SERV FEE | E34: 15 | F34: 0.00 | G34: 30 | H34: 45 | I34: 120 | J34: 30 | K34: 45 | L34: 105 | M34: 105 | N34: 75 | O34: 75 | P34: 60 | Q34: 705 | R34: as calc | S34: 39 | T34: =Q34 -> 705 | U34: ='AEP TX 451 Pro forma'!H37 -> as calculated | V34: 0
B35: 97 | C35: SRFEE | D35: SPECIAL MTR READ FEE | E35: 0.00 | F35: 0.00 | G35: 0.00 | H35: 0.00 | I35: 0.00 | J35: 0.00 | K35: 0 | L35: 0.00 | M35: 0.00 | N35: 0.00 | O35: 16 | P35: 0 | Q35: 16 | R35: 16 | S35: 1 | T35: =Q35 -> 16 | U35: ='AEP TX 451 Pro forma'!H38 -> 40 | V35: =(U35*S35)-T35 -> 24
B36: 97 | C36: SVCHG | D36: SERVICE CHARGE | E36: 951 | F36: 1260 | G36: 360 | H36: 990 | I36: 1398 | J36: 1272 | K36: 1647 | L36: 642 | M36: 702 | N36: 498 | O36: 846 | P36: 492 | Q36: 11058
D37: During Business Days 8:00am-5:00pm CPT | R37: 72 | S37: =75+2 -> 77 | T37: =R37*S37 -> 5544 | U37: ='AEP TX 451 Pro forma'!H41 -> 81 | V37: =(U37*S37)-T37 -> 693
D38: During Business Days Non-Business Hours | R38: 138 | S38: 35 | T38: =R38*S38 -> 4830 | U38: ='AEP TX 451 Pro forma'!H42 -> 110 | V38: =(U38*S38)-T38 -> -980
D39: Weekend | R39: 138 | T39: =R39*S39 -> 0 | U39: ='AEP TX 451 Pro forma'!H43 -> 110 | V39: =(U39*S39)-T39 -> 0
D40: Holiday | R40: 171 | S40: 4 | T40: =R40*S40 -> 684 | U40: ='AEP TX 451 Pro forma'!H44 -> 140 | V40: =(U40*S40)-T40 -> -124
B41: 97 | C41: SVCON | D41: SERVICE CONN CHARGE | E41: 18283 | F41: 19637 | G41: 26856 | H41: 23211 | I41: 31049 | J41: 23430 | K41: 24696 | L41: 27977 | M41: 30265 | N41: 19803 | O41: 18128 | P41: 21470 | Q41: 284805
D42: CT NEW NON-STANDARD METER | R42: 305 | S42: 123 | T42: =R42*S42 -> 37515 | U42: ='AEP TX 451 Pro forma'!H47 -> 287 | V42: =(U42*S42)-T42 -> -2214
D43: CT EXISTING NON-STANDARD METER | R43: 110 | S43: 122 | T43: =R43*S43 -> 13420 | U43: ='AEP TX 451 Pro forma'!H48 -> 134 | V43: =(U43*S43)-T43 -> 2928
D44: CT EXISTING PRIORITY NON-STANDARD METER | R44: 163 | S44: 96 | T44: =R44*S44 -> 15648 | U44: ='AEP TX 451 Pro forma'!H49 -> 171 | V44: =(U44*S44)-T44 -> 768
...
