Workbook

Sheet Billing Units
A1: AEP TEXAS
A2: TEST YEAR DATA BY RATE CLASS
A3: FOR TEST YEAR ENDED DECEMBER 30, 2018
B5: AEP Texas | D5: Year-end | E5: Annual | F5: Annual | G5: Adjusted | H5: Distribution | I5: Distribution | J5: Transmission
A6: LINE | B6: DESCRIPTION | C6: VOLT | D6: Customer | E6: Applications | F6: Applications | G6: kWh | H6: Billing Determinant | I6: Billing Determinant | J6: Billing Determinant
D7: Applications | E7: Cust Charge | F7: Meter Charge | I7: No Ratchet
A9: 1 | B9: RESIDENTIAL SERVICE | C9: SEC | D9: ='[1]Billing Units'!$D$9+'[2]Billing Units'!$D$9 -> 876553 | E9: =ROUND(D9*12,0) -> 10518636 | F9: =E9 -> 10518636 | G9: ='[1]Billing Units'!$G$9+'[2]Billing Units'!$G$9 -> 1.1997182e+10 | H9: =G9 -> 1.1997182e+10 | J9: =G9 -> 1.1997182e+10
A11: 2 | B11: SECONDARY < 10 kW | C11: SEC | D11: ='[1]Billing Units'!$D$11+'[2]Billing Units'!$D$11 -> 89158 | E11: =ROUND(D11*12,0) -> 1069896 | F11: ='[1]Billing Units'!$F$11+'[2]Billing Units'!$F$11 -> 1037676 | G11: ='[1]Billing Units'!$G$11+'[2]Billing Units'!$G$11 -> 5.7930338e+08 | H11: =G11 -> 5.7930338e+08 | J11: =G11 -> 5.7930338e+08
A13: 3 | B13: SECONDARY > 10 kW NCP | C13: SEC | D13: ='[1]Billing Units'!$D$13+'[2]Billing Units'!$D$13 -> 72592 | E13: =ROUND(D13*12,0) -> 871104 | F13: =E13 -> 871104 | G13: ='[1]Billing Units'!$G$13+'[2]Billing Units'!$G$13 -> 8.0703698e+09 | H13: ='[1]Billing Units'!$H$13+'[2]Billing Units'!$H$13 -> 33775906 | I13: ='[1]Billing Units'!$I$13+'[2]Billing Units'!$I$13 -> 29321712 | J13: ='[1]Billing Units'!$J$13+'[2]Billing Units'!$J$13 -> 29307091
A14: 4 | B14: SECONDARY > 10 kW 4CP | C14: SEC | D14: ='[1]Billing Units'!$D$14+'[2]Billing Units'!$D$14 -> 478 | E14: =ROUND(D14*12,0) -> 5736 | F14: =E14 -> 5736 | G14: ='[1]Billing Units'!$G$14+'[2]Billing Units'!$G$14 -> 1.1759007e+09 | H14: ='[1]Billing Units'!$H$14+'[2]Billing Units'!$H$14 -> 3358360 | I14: ='[1]Billing Units'!$I$14+'[2]Billing Units'!$I$14 -> 3041755.7 | J14: ='[1]Billing Units'!$J$14+'[2]Billing Units'!$J$14 -> 2191434
A15: 5 | B15: TOTAL SECONDARY > 10 kW | D15: =SUM(D13:D14) -> 73070 | E15: =SUM(E13:E14) -> 876840 | F15: =SUM(F13:F14) -> 876840 | G15: =SUM(G13:G14) -> 9.2462705e+09 | H15: =SUM(H13:H14) -> 37134266 | I15: =I13+I14 -> 32363468 | J15: =SUM(J13:J14) -> 31498526
A17: 6 | B17: PRIMARY NCP | C17: PRI | D17: ='[1]Billing Units'!$D$17+'[2]Billing Units'!$D$17 -> 574 | E17: =ROUND(D17*12,0) -> 6888 | F17: =E17 -> 6888 | G17: ='[1]Billing Units'!$G$17+'[2]Billing Units'!$G$17 -> 3.0605157e+08 | H17: ='[1]Billing Units'!$H$17+'[2]Billing Units'!$H$17 -> 958871.29 | J17: ='[1]Billing Units'!$J$17+'[2]Billing Units'!$J$17 -> 806479.37
A18: 7 | B18: PRIMARY 4CP | C18: PRI | D18: ='[1]Billing Units'!$D$18+'[2]Billing Units'!$D$18 -> 471 | E18: =ROUND(D18*12,0) -> 5652 | F18: =E18 -> 5652 | G18: ='[1]Billing Units'!$G$18+'[2]Billing Units'!$G$18 -> 4.0836951e+09 | H18: ='[1]Billing Units'!$H$18+'[2]Billing Units'!$H$18 -> 9502752 | J18: ='[1]Billing Units'!$J$18+'[2]Billing Units'!$J$18 -> 6724400.4
A19: 8 | B19: TOTAL PRIMARY | D19: =SUM(D17:D18) -> 1045 | E19: =SUM(E17:E18) -> 12540 | F19: =SUM(F17:F18) -> 12540 | G19: =SUM(G17:G18) -> 4.3897467e+09 | H19: =SUM(H17:H18) -> 10461623 | J19: =SUM(J17:J18) -> 7530879.8
A21: 9 | B21: TRANSMISSION IDR | C21: TRA | D21: ='[1]Billing Units'!$D$21+'[2]Billing Units'!$D$21 -> 85 | E21: =ROUND(D21*12,0) -> 1020 | F21: =E21 -> 1020 | G21: ='[1]Billing Units'!$G$21+'[2]Billing Units'!$G$21 -> 5.7449969e+09 | H21: ='[1]Billing Units'!$H$21+'[2]Billing Units'!$H$21 -> 16829578 | J21: ='[1]Billing Units'!$J$21+'[2]Billing Units'!$J$21 -> 6571184.2
A23: 10 | B23: LIGHTING* | C23: SEC | D23: ='[1]Billing Units'!$D$23+'[2]Billing Units'!$D$23 -> 220232 | E23: =22476+5136 -> 27612 | F23: 0 | G23: =+'[2]Billing Units'!$G$23+'[1]Billing Units'!$G$23 -> 2.6222605e+08 | H23: =G23 -> 2.6222605e+08 | J23: =G23 -> 2.6222605e+08
A25: 11 | B25: TOTAL RETAIL | D25: =D9+D11+D15+D19+D21+D23 -> 1260143 | E25: =E9+E11+E15+E19+E21+E23 -> 12506544 | F25: =F9+F11+F15+F19+F21+F23 -> 12446712 | G25: =G23+G21+G19+G15+G11+G9 -> 3.2219725e+10
B27: *Year end fixture counts

Sheet Rate Summary
B1: Public Utility Commission of Texas
B3: Test Year Ended December 31, 2018
B4: Rate Design Workpaper - AEP TEXAS
B7: CLASS | C7: RATE CHARGES
C9: CHARGES | D9: RATES
B11: RESIDENTIAL | C11: CUSTOMER CHARGE | D11: ='AEPTX RS'!E27 -> 1.54 | E11: per customer
C12: METERING CHARGE | D12: ='AEPTX RS'!E22 -> 4.4 | E12: per customer
C13: DISTRIBUTION SERVICE CHARGE | D13: ='AEPTX RS'!H20 -> 0.02311 | E13: per kWh
B14: SECONDARY =<10 kW | C14: CUSTOMER CHARGE | D14: ='AEPTX Sec LT 10'!E28 -> 1.54 | E14: per customer
C15: METERING CHARGE | D15: ='AEPTX Sec LT 10'!E23 -> 5.88 | E15: per customer
C16: DISTRIBUTION SERVICE CHARGE | D16: ='AEPTX Sec LT 10'!H21 -> 0.02422 | E16: per kWh
B17: SECONDARY >10kW | C17: CUSTOMER CHARGE | D17: ='AEPTX Sec GT 10'!E32 -> 1.54 | E17: per customer
B18: 4CP | C18: METERING CHARGE | D18: ='AEPTX Sec GT 10'!E27 -> 16.38 | E18: per customer
C19: DISTRIBUTION SERVICE CHARGE | D19: ='AEPTX Sec GT 10'!K25 -> 5.33 | E19: per kW
B20: SECONDARY >10kW | C20: CUSTOMER CHARGE | D20: ='AEPTX Sec GT 10'!E32 -> 1.54 | E20: per customer
B21: NCP | C21: METERING CHARGE | D21: ='AEPTX Sec GT 10'!E27 -> 16.38 | E21: per customer
C22: DISTRIBUTION SERVICE CHARGE | D22: ='AEPTX Sec GT 10'!K25 -> 5.33 | E22: per kW
B23: PRIMARY | C23: CUSTOMER CHARGE | D23: ='AEPTX Primary '!E31 -> 1.61 | E23: per customer
B24: 4CP | C24: METERING CHARGE | D24: ='AEPTX Primary '!E26 -> 162.81 | E24: per customer
C25: DISTRIBUTION SERVICE CHARGE | D25: ='AEPTX Primary '!K24 -> 3.696 | E25: per kW
B26: PRIMARY | C26: CUSTOMER CHARGE | D26: ='AEPTX Primary '!E31 -> 1.61 | E26: per customer
B27: NCP | C27: METERING CHARGE | D27: ='AEPTX Primary '!E26 -> 162.81 | E27: per customer
C28: DISTRIBUTION SERVICE CHARGE | D28: ='AEPTX Primary '!K24 -> 3.696 | E28: per kW
B29: TRANSMISSION | C29: CUSTOMER CHARGE | D29: ='AEPTX Trans'!E28 -> 1.74 | E29: per customer
C30: METERING CHARGE | D30: ='AEPTX Trans'!E23 -> 999.51 | E30: per customer
C31: DISTRIBUTION SERVICE CHARGE | D31: ='AEPTX Trans'!K21 -> 0.2494 | E31: per kW
B32: LIGHTING | C32: CUSTOMER CHARGE | D32: ='AEPTX Lighting'!E27 -> 0 | E32: per customer
C33: FIXTURES REVENUES | D33: ='AEPTX Lighting'!J35 -> 17089102
C34: DISTRIBUTION SERVICE CHARGE | D34: ='AEPTX Lighting'!H20 -> 0 | E34: per kWh
B37: Other Non-ByPassable Charges:
B38: CLASS | C38: RATE CHARGES
C39: CHARGES | D39: RATES
B41: RESIDENTIAL | C41: Transmission Cost Recovery Factor | D41: ='[3]AEPTX ERCOT Matrix 2018'!$I$9 -> 0.01294 | E41: per kWh
C42: Nuclear Decommissioning Charge* | D42: ='[4]EXHIBIT JLJ-4'!$F$11 -> 2.8e-05 | E42: per kWh
C43: Income Tax Refund Rider | D43: ='[5]AEP TX'!$E$23 -> 0.0335 | E43: % Base Rev
B44: SECONDARY =<10 kW | C44: Transmission Cost Recovery Factor | D44: ='[3]AEPTX ERCOT Matrix 2018'!$I$10 -> 0.007601 | E44: per kWh
C45: Nuclear Decommissioning Charge* | D45: ='[4]EXHIBIT JLJ-4'!$F$15 -> 3.5e-05 | E45: per kWh
C46: Income Tax Refund Rider | D46: ='[5]AEP TX'!$F$23 -> 0.0335 | E46: % Base Rev
B47: SECONDARY >10kW | C47: Transmission Cost Recovery Factor | D47: ='[3]AEPTX ERCOT Matrix 2018'!$I$11 -> 4.568 | E47: per 4CP kW
B48: 4CP | C48: Nuclear Decommissioning Charge* | D48: ='[4]EXHIBIT JLJ-4'!$F$19 -> 0.007879 | E48: per kW
...

Sheet Revenue Summary
D4: PUBLIC UTILITY COMMISSION OF TEXAS
D5: AEP TEXAS INC
D6: IV-J-1 REVENUE SUMMARY
D7: TEST YEAR ENDING 12/31/2018
D8: Docket - TBD
E10: 1 | F10: 2 | G10: 3 | H10: 4 | I10: 5 | J10: 6 | K10: 7 | L10: 8
E11: Test Year
D12: Description | E12: Revenue | F12: Residential | G12: Secondary | H12: Secondary | I12: Primary | J12: Transmission | K12: Lighting | L12: Total
B13: Line | E13: Requirement | G13: =< 10 kW | H13: > 10 kW | L13: TX Retail
B14: No. | E14: Total
B16: 1 | D16: Transmission (TRAN) | E16: ='[6]AEPTX ERCOT Matrix 2018'!$C$24 -> 327388729 | F16: ='[6]AEPTX ERCOT Matrix 2018'!$E$9 -> 1.5523863e+08 | G16: ='[6]AEPTX ERCOT Matrix 2018'!$E$10 -> 6396087.9 | H16: ='[6]AEPTX ERCOT Matrix 2018'!$E$11+'[6]AEPTX ERCOT Matrix 2018'!$E$12 -> 1.009142e+08 | I16: ='[6]AEPTX ERCOT Matrix 2018'!$E$13+'[6]AEPTX ERCOT Matrix 2018'!$E$14 -> 34235755 | J16: ='[6]AEPTX ERCOT Matrix 2018'!$E$15 -> 30604049 | K16: ='[6]AEPTX ERCOT Matrix 2018'!$E$16 -> 0 | L16: =SUM(F16:K16) -> 3.2738873e+08
B17: 2 | D17: Distribution (DIST) | E17: ='[7]II-I-1'!$D$15 -> 5.300373e+08 | F17: ='[7]II-I-1'!$E$15 -> 2.7725047e+08 | G17: ='[7]II-I-1'!$F$15 -> 13165915 | H17: ='[7]II-I-1'!$G$15 -> 1.7244752e+08 | I17: ='[7]II-I-1'!$H$15 -> 38671232 | J17: ='[7]II-I-1'!$I$15 -> 4196817.8 | K17: ='[7]II-I-1'!$J$15 -> 24305349 | L17: =SUM(F17:K17) -> 5.300373e+08
B18: 3 | D18: Metering (MET) | E18: ='[7]II-I-1'!$D$16 -> 69836702 | F18: ='[7]II-I-1'!$E$16 -> 46309180 | G18: ='[7]II-I-1'!$F$16 -> 6100793.1 | H18: ='[7]II-I-1'!$G$16 -> 14365529 | I18: ='[7]II-I-1'!$H$16 -> 2041695.3 | J18: ='[7]II-I-1'!$I$16 -> 1019505.2 | K18: ='[7]II-I-1'!$J$16 -> 0 | L18: =SUM(F18:K18) -> 69836702
B19: 4 | D19: Customer - Billing (TBIL) - T&D Customer Service (TDCS) | E19: ='[7]II-I-1'!$D$17 -> 19281512 | F19: ='[7]II-I-1'!$E$17 -> 16211654 | G19: ='[7]II-I-1'!$F$17 -> 1651296.8 | H19: ='[7]II-I-1'!$G$17 -> 1353924.9 | I19: ='[7]II-I-1'!$H$17 -> 20249.74 | J19: ='[7]II-I-1'!$I$17 -> 1775.3968 | K19: ='[7]II-I-1'!$J$17 -> 42611.089 | L19: =SUM(F19:K19) -> 19281512
B20: 5
B21: 6 | D21: DIST + TRAN + MET + TBILL + TDCS | E21: =SUM(E16:E19) -> 9.4654425e+08 | F21: =SUM(F16:F19) -> 4.9500994e+08 | G21: =SUM(G16:G19) -> 27314092 | H21: =SUM(H16:H19) -> 2.8908118e+08 | I21: =SUM(I16:I19) -> 74968933 | J21: =SUM(J16:J19) -> 35822148 | K21: =SUM(K16:K19) -> 24347960 | L21: =SUM(L16:L19) -> 9.4654424e+08
B22: 7
B23: 8 | D23: PROOF OF REVENUE SCHEDULE IV-J-7 | E23: =L23 -> 9.4655582e+08 | F23: ='AEPTX RS'!J37 -> 494979094 | G23: ='AEPTX Sec LT 10'!J39 -> 26183188 | H23: ='AEPTX Sec GT 10'!J44 -> 289131326 | I23: ='AEPTX Primary '!J43 -> 74963742 | J23: ='AEPTX Trans'!J38 -> 35822548 | K23: ='AEPTX Lighting'!J38+'AEPTX Sec LT 10'!J44 -> 25475919 | L23: =SUM(F23:K23) -> 9.4655582e+08
B24: 9 | D24: RATE DESIGN DIFFERENCE | E24: =L24 -> 11572.935 | F24: =F23-F21 -> -30842.2 | G24: =G23-G21 -> -1130904.4 | H24: =H23-H21 -> 50150.135 | I24: =I23-I21 -> -5190.5645 | J24: =J23-J21 -> 400.40217 | K24: =K23-K21 -> 1127959.6 | L24: =L23-L21 -> 11572.935

Sheet AEPTX RS
B1: PROOF OF REVENUE STATEMENT
B2: FOR THE TEST YEAR ENDING DECEMBER 31, 2018
B4: RESIDENTIAL SERVICE - AEPTX
D8: ESTIMATED
D9: BILLING
B10: CLASS BILLING STATISTICS | D10: UNITS
B11: Number of Annual Bills | D11: ='Billing Units'!E9 -> 10518636
B12: Annual kWh | D12: ='Billing Units'!G9 -> 1.1997182e+10
B13: Annual Billing kW | D13: 0
D15: CALCULATION OF UNIT CHARGES USING FORECASTED BILLING UNITS
D16: POINT OF DELIVERY | G16: FACILITIES CHARGE | J16: FACILITIES CHARGE
D17: (POD) CHARGE | G17: (PER KWH) | J17: (PER KW)
B18: FUNCTION | D18: $ | E18: $/Bill/Month | G18: $ | H18: $/kWh | J18: $ | K18: $/kW
B19: 1. Transmission (TRAN) | D19: 0 | E19: 0 | G19: ='[3]AEPTX ERCOT Matrix 2018'!$E$9 -> 1.5523863e+08 | H19: =+ROUND(G19/D12,6) -> 0.01294 | J19: 0 | K19: =IF(J19=0,J19,ROUND(J19/G$13,4)) -> 0
B20: 2. Distribution (DIST) | G20: ='[7]Retail Summary Proposed'!$G$57+'[7]Retail Summary Proposed'!$G$72 -> 2.7725047e+08 | H20: =IF(G20=0,G20,ROUND(G20/D$12,6)) -> 0.02311 | J20: 0 | K20: 0
B21: 3. Transmission & Distribution Utility
B22: Metering System Services (MET) | D22: ='[7]Retail Summary Proposed'!$G$62 -> 46309180 | E22: =IF(D22=0,D22,ROUND(D22/D$11,2)) -> 4.4 | G22: 0 | H22: 0 | J22: 0 | K22: 0
B23: 4. Transmission & Distribution Utility
B24: Billing System Services (TD-BILL) | E24: =IF(D24=0,D24,ROUND(D24/D$11,2)) -> 0 | G24: 0 | H24: 0
B25: 5. Additional Billing Services (A-BILL) | D25: 0 | E25: 0 | G25: 0 | H25: 0 | J25: 0 | K25: 0
B26: 6. Transmission & Distribution Utility
B27: Customer Service (TDCS) | D27: ='[7]Retail Summary Proposed'!$G$67 -> 16211654 | E27: =IF(D27=0,D27,ROUND(D27/D$11,2)) -> 1.54 | G27: 0 | H27: 0
B28: TOTAL | D28: =IF(SUM(D19:D27)<1,D19,SUM(D19:D27)) -> 62520834 | E28: =SUM(E19:E27) -> 5.94 | G28: =IF(SUM(G19:G27)<1,G19,SUM(G19:G27)) -> 4.324891e+08 | H28: =SUM(H19:H27) -> 0.03605 | J28: =IF(SUM(J19:J27)<1,J19,SUM(J19:J27)) -> 0 | K28: =IF(SUM(K19:K27)<1,K19,SUM(K19:K27)) -> 0
D30: FUNCTION | G30: PROPOSED CHARGES
D31: SUMMARY | H31: UNIT | J31: TOTAL
B32: FUNCTION | D32: $ | G32: DESCRIPTION | H32: CHARGE | J32: REVENUE
B33: 1. Transmission (TRAN) | D33: =G19 -> 1.5523863e+08
B34: 2. Distribution (DIST) | D34: =D20+G20+J20 -> 2.7725047e+08 | G34: POD CHARGE | H34: =+E28 -> 5.94 | J34: =ROUND(+H34*D11,0) -> 62480698
B35: 3. Transmission & Distribution Utility | G35: FACILITIES CHARGE TRANS | H35: =H19 -> 0.01294 | J35: =ROUND(+H35*D12,0) -> 155243530
B36: Metering System Services (MET) | D36: =D22+G22+J22 -> 46309180 | G36: FACILITIES CHARGE DIST | H36: =H20 -> 0.02311 | I36: * | J36: =ROUND(+H36*D12,0) -> 277254866
B37: 4. Transmission & Distribution Utility | G37: TOTAL | J37: =SUM(J34:J36) -> 494979094
B38: Billing System Services (TD-BILL) | D38: =D24+G24+J24 -> 0
B39: 5. Additional Billing Services (A-BILL) | D39: 0 | G39: *Unit Charge is per kWh
B40: 6. Transmission & Distribution Utility
B41: Customer Service (TDCS) | D41: =D27+G27+J27 -> 16211654
B42: TOTAL | D42: =SUM(D33:D41) -> 4.9500994e+08

Sheet AEPTX Sec LT 10
B1: PROOF OF REVENUE STATEMENT
B2: FOR THE TEST YEAR ENDING DECEMBER 31, 2018
B4: SECONDARY <= 10 KW - AEPTX
D8: ESTIMATED | E8: ESTIMATED
D9: BILLING | E9: BILLING
B10: CLASS BILLING STATISTICS | D10: UNITS | E10: LIGHTING UNITS
B11: Number of Annual Bills | D11: ='Billing Units'!E11 -> 1069896 | E11: ='Billing Units'!E23 -> 27612
B12: Number of Annual Bills - Meters | D12: ='Billing Units'!F11 -> 1037676 | E12: ='Billing Units'!F23 -> 0
B13: Annual kWh | D13: ='Billing Units'!H11 -> 5.7930338e+08 | E13: ='Billing Units'!G23 -> 2.6222605e+08
B14: Annual Billing kW | D14: 0 | E14: 0
D16: CALCULATION OF UNIT CHARGES USING FORECASTED BILLING UNITS
D17: POINT OF DELIVERY | G17: FACILITIES CHARGE | J17: FACILITIES CHARGE
D18: (POD) CHARGE | G18: (PER KWH) | J18: (PER KW)
B19: FUNCTION | D19: $ | E19: $/Bill/Month | G19: $ | H19: $/kWh | J19: $ | K19: $/kW
B20: 1. Transmission (TRAN) | D20: 0 | E20: 0 | G20: ='[3]AEPTX ERCOT Matrix 2018'!$E$10 -> 6396087.9 | H20: =ROUND(G20/(D13+E13),6) -> 0.007601 | J20: 0 | K20: =IF(J20=0,J20,ROUND(J20/G$14,4)) -> 0
B21: 2. Distribution (DIST) | G21: ='[7]Retail Summary Proposed'!$H$57+'[7]Retail Summary Proposed'!$H$72+'[7]Retail Summary Proposed'!$P$57+'[7]Retail Summary Proposed'!$P$72-'AEPTX Lighting'!J35 -> 20382161 | H21: =IF(G21=0,G21,ROUND(G21/(D$13+E13),6)) -> 0.02422 | J21: 0 | K21: 0
B22: 3. Transmission & Distribution Utility
B23: Metering System Services (MET) | D23: ='[7]Retail Summary Proposed'!$H$62+'[7]Retail Summary Proposed'!$P$62 -> 6100793.1 | E23: =IF(D23=0,D23,ROUND(D23/(D$12+E12),2)) -> 5.88 | G23: 0 | H23: 0 | J23: 0 | K23: 0
B24: 4. Transmission & Distribution Utility
B25: Billing System Services (TD-BILL) | E25: =IF(D25=0,D25,ROUND(D25/D$11,2)) -> 0 | G25: 0 | H25: 0
B26: 5. Additional Billing Services (A-BILL) | D26: 0 | E26: 0 | G26: 0 | H26: 0 | J26: 0 | K26: 0
B27: 6. Transmission & Distribution Utility
B28: Customer Service (TDCS) | D28: ='[7]Retail Summary Proposed'!$H$67+'[7]Retail Summary Proposed'!$P$67 -> 1693907.9 | E28: =IF(D28=0,D28,ROUND(D28/(D$11+E11),2)) -> 1.54 | G28: 0 | H28: 0
B29: TOTAL | D29: =IF(SUM(D20:D28)<1,D20,SUM(D20:D28)) -> 7794701 | E29: =SUM(E20:E28) -> 7.42 | G29: =IF(SUM(G20:G28)<1,G20,SUM(G20:G28)) -> 26778249 | H29: =SUM(H20:H28) -> 0.031821 | J29: =IF(SUM(J20:J28)<1,J20,SUM(J20:J28)) -> 0 | K29: =IF(SUM(K20:K28)<1,K20,SUM(K20:K28)) -> 0
D31: FUNCTION | G31: PROPOSED CHARGES
D32: SUMMARY | H32: UNIT | J32: TOTAL
B33: FUNCTION | D33: $ | G33: DESCRIPTION | H33: CHARGE | J33: REVENUE
B34: 1. Transmission (TRAN) | D34: =G20 -> 6396087.9
B35: 2. Distribution (DIST) | D35: =D21+G21+J21 -> 20382161 | G35: POD CHARGE CUST | H35: =E28 -> 1.54 | J35: =ROUND(+H35*D11,0) -> 1647640
B36: 3. Transmission & Distribution Utility | G36: POD CHARGE METER | H36: =E23 -> 5.88 | J36: =ROUND(+H36*D12,0) -> 6101535
B37: Metering System Services (MET) | D37: =D23+G23+J23 -> 6100793.1 | G37: FACILITIES CHARGE TRAN | H37: =H20 -> 0.007601 | J37: =ROUND(+H37*D13,0) -> 4403285
B38: 4. Transmission & Distribution Utility | G38: FACILITIES CHARGE DIST | H38: =H21 -> 0.02422 | I38: * | J38: =ROUND(+H38*D13,0) -> 14030728
B39: Billing System Services (TD-BILL) | D39: =D25+G25+J25 -> 0 | G39: TOTAL SECONDARY <= 10 kW | J39: =SUM(J35:J38) -> 26183188
B40: 5. Additional Billing Services (A-BILL) | D40: 0
B41: 6. Transmission & Distribution Utility | G41: POD CHARGE CUST - LIGHT | H41: =H35 -> 1.54 | J41: =ROUND(H41*E11,0) -> 42522
B42: Customer Service (TDCS) | D42: =D28+G28+J28 -> 1693907.9 | G42: FACILITIES CHARGE TRAN - LIGHT | H42: =H37 -> 0.007601 | J42: =ROUND(H42*E13,0) -> 1993180
B43: TOTAL | D43: =SUM(D34:D42) -> 34572950 | G43: FACILITIES CHARGE DIST - LIGHT | H43: =H38 -> 0.02422 | J43: =ROUND(H43*E13,0) -> 6351115
G44: TOTAL LIGHTING DISTRIBUTION | J44: =SUM(J41:J43) -> 8386817
G46: TOTAL SECONDARY <= 10 kW & LIGHTING | J46: =J39+J44 -> 34570005
G47: *Unit Charge is per kWh

Sheet AEPTX Sec GT 10
B1: PROOF OF REVENUE STATEMENT
B2: FOR THE TEST YEAR ENDING DECEMBER 31, 2018
B4: SECONDARY > 10 KW - AEPTX
D8: ESTIMATED
D9: BILLING
B10: CLASS BILLING STATISTICS | D10: UNITS
B11: Number of Annual Bills | D11: ='Billing Units'!F15 -> 876840
B12: Annual kWh | D12: ='Billing Units'!G15 -> 9.2462705e+09
B13: Annual Billing kW 80% Ratchet | D13: ='Billing Units'!H15 -> 37134266
B14: Annual Billing kW No Ratchet | D14: ='Billing Units'!I15 -> 32363468
B15: 4CP Billing kW | D15: ='Billing Units'!J14 -> 2191434
B16: NCP Billing kW | D16: ='Billing Units'!J13 -> 29307091
D18: CALCULATION OF UNIT CHARGES USING FORECASTED BILLING UNITS
D19: POINT OF DELIVERY | G19: FACILITIES CHARGE | J19: FACILITIES CHARGE
D20: (POD) CHARGE | G20: (PER KWH) | J20: (PER KW)
B21: FUNCTION | D21: $ | E21: $/Bill/Month | G21: $ | H21: $/kWh | J21: $ | K21: $/kW
B22: 1. Transmission (TRAN) | D22: 0 | E22: 0 | G22: 0 | H22: 0 | J22: 0 | K22: =IF(J22=0,J22,ROUND(J22/G$14,4)) -> 0
B23: 4CP CUSTOMERS | J23: ='[3]AEPTX ERCOT Matrix 2018'!$E$11 -> 10009841 | K23: =ROUND(J23/D15,3) -> 4.568
B24: NCP CUSTOMERS | J24: ='[3]AEPTX ERCOT Matrix 2018'!$E$12 -> 90904363 | K24: =ROUND(J24/D16,3) -> 3.102
B25: 2. Distribution (DIST) | H25: =IF(G25=0,G25,ROUND(G25/D$13,6)) -> 0 | J25: ='[7]Retail Summary Proposed'!$I$57+'[7]Retail Summary Proposed'!$I$72 -> 1.7244752e+08 | K25: =IF(J25=0,J25,ROUND(J25/D$14,2)) -> 5.33
B26: 3. Transmission & Distribution Utility
B27: Metering System Services (MET) | D27: ='[7]Retail Summary Proposed'!$I$62 -> 14365529 | E27: =IF(D27=0,D27,ROUND(D27/D$11,2)) -> 16.38 | G27: 0 | H27: 0 | J27: 0 | K27: 0
B28: 4. Transmission & Distribution Utility
B29: Billing System Services (TD-BILL) | E29: =IF(D29=0,D29,ROUND(D29/D$11,2)) -> 0 | G29: 0 | H29: 0
B30: 5. Additional Billing Services (A-BILL) | D30: 0 | E30: 0 | G30: 0 | H30: 0 | J30: 0 | K30: 0
B31: 6. Transmission & Distribution Utility
B32: Customer Service (TDCS) | D32: ='[7]Retail Summary Proposed'!$I$67 -> 1353924.9 | E32: =IF(D32=0,D32,ROUND(D32/D$11,2)) -> 1.54 | G32: 0 | H32: 0
B33: TOTAL | D33: =IF(SUM(D22:D32)<1,D22,SUM(D22:D32)) -> 15719453 | E33: =SUM(E22:E32) -> 17.92 | G33: =IF(SUM(G22:G32)<1,G22,SUM(G22:G32)) -> 0 | H33: =SUM(H22:H32) -> 0 | J33: =IF(SUM(J22:J32)<1,J22,SUM(J22:J32)) -> 2.7336172e+08
D35: FUNCTION | G35: PROPOSED CHARGES
D36: SUMMARY | H36: UNIT | J36: TOTAL
B37: FUNCTION | D37: $ | G37: DESCRIPTION | H37: CHARGE | J37: REVENUE
B38: 1. Transmission (TRAN) | D38: =J23+J24 -> 1.009142e+08
B39: 2. Distribution (DIST) | D39: =D25+G25+J25 -> 1.7244752e+08 | G39: POD CHARGE | H39: =E33 -> 17.92 | J39: =ROUND(+H39*D11,0) -> 15712973
G41: FACILITIES CHARGE - TRANS 4CP | H41: =K23 -> 4.568 | I41: * | J41: =ROUND(+H41*D15,0) -> 10010471
B42: 3. Transmission & Distribution Utility | G42: FACILITIES CHARGE - TRANS NCP | H42: =K24 -> 3.102 | I42: * | J42: =ROUND(+H42*D16,0) -> 90910598
B43: Metering System Services (MET) | D43: =D27+G27+J27 -> 14365529 | G43: FACILITIES CHARGE - DIST | H43: =K25 -> 5.33 | I43: * | J43: =ROUND(+H43*D14,0) -> 172497284
B44: 4. Transmission & Distribution Utility | G44: TOTAL | J44: =SUM(J39:J43) -> 289131326
B45: Billing System Services (TD-BILL) | D45: =D29+G29+J29 -> 0
B46: 5. Additional Billing Services (A-BILL) | D46: 0 | G46: *Unit Charge is per kW
B47: 6. Transmission & Distribution Utility
...

Sheet AEPTX Primary 
B1: PROOF OF REVENUE STATEMENT
B2: FOR THE TEST YEAR ENDING DECEMBER 31, 2018
B4: PRIMARY - AEPTX
D8: ESTIMATED
D9: BILLING
B10: CLASS BILLING STATISTICS | D10: UNITS
B11: Number of Annual Bills | D11: ='Billing Units'!E19 -> 12540
B12: Annual kWh | D12: ='Billing Units'!G19 -> 4.3897467e+09
B13: Annual Billing kW | D13: ='Billing Units'!H19 -> 10461623
B14: 4CP Billing kW | D14: ='Billing Units'!J18 -> 6724400.4
B15: NCP Billing kW | D15: ='Billing Units'!J17 -> 806479.37
D17: CALCULATION OF UNIT CHARGES USING FORECASTED BILLING UNITS
D18: POINT OF DELIVERY | G18: FACILITIES CHARGE | J18: FACILITIES CHARGE
D19: (POD) CHARGE | G19: (PER KWH) | J19: (PER KW)
B20: FUNCTION | D20: $ | E20: $/Bill/Month | G20: $ | H20: $/kWh | J20: $ | K20: $/kW
B21: 1. Transmission (TRAN) | D21: 0 | E21: 0 | G21: 0 | H21: 0 | J21: 0 | K21: =IF(J21=0,J21,ROUND(J21/G$14,4)) -> 0
B22: 4CP CUSTOMERS | J22: ='[3]AEPTX ERCOT Matrix 2018'!$E$13 -> 31711960 | K22: =J22/D14 -> 4.7159536
B23: NCP CUSTOMERS | J23: ='[3]AEPTX ERCOT Matrix 2018'!$E$14 -> 2523794.9 | K23: =J23/D15 -> 3.129398
B24: 2. Distribution (DIST) | H24: =IF(G24=0,G24,ROUND(G24/D$13,6)) -> 0 | J24: ='[7]Retail Summary Proposed'!$L$57+'[7]Retail Summary Proposed'!$L$72 -> 38671232 | K24: =IF(J24=0,J24,ROUND(J24/D$13,3)) -> 3.696
B25: 3. Transmission & Distribution Utility
B26: Metering System Services (MET) | D26: ='[7]Retail Summary Proposed'!$L$62 -> 2041695.3 | E26: =IF(D26=0,D26,ROUND(D26/D$11,2)) -> 162.81 | G26: 0 | H26: 0 | J26: 0 | K26: 0
B27: 4. Transmission & Distribution Utility
B28: Billing System Services (TD-BILL) | E28: =IF(D28=0,D28,ROUND(D28/D$11,2)) -> 0 | G28: 0 | H28: 0
B29: 5. Additional Billing Services (A-BILL) | D29: 0 | E29: 0 | G29: 0 | H29: 0 | J29: 0 | K29: 0
B30: 6. Transmission & Distribution Utility
B31: Customer Service (TDCS) | D31: ='[7]Retail Summary Proposed'!$L$67 -> 20249.74 | E31: =IF(D31=0,D31,ROUND(D31/D$11,2)) -> 1.61 | G31: 0 | H31: 0
B32: TOTAL | D32: =IF(SUM(D21:D31)<1,D21,SUM(D21:D31)) -> 2061945 | E32: =SUM(E21:E31) -> 164.42 | G32: =IF(SUM(G21:G31)<1,G21,SUM(G21:G31)) -> 0 | H32: =SUM(H21:H31) -> 0 | J32: =IF(SUM(J21:J31)<1,J21,SUM(J21:J31)) -> 72906988 | K32: =IF(SUM(K21:K31)<1,K21,SUM(K21:K31)) -> 11.541352
D34: FUNCTION | G34: PROPOSED CHARGES
D35: SUMMARY | H35: UNIT | J35: TOTAL
B36: FUNCTION | D36: $ | G36: DESCRIPTION | H36: CHARGE | J36: REVENUE
B37: 1. Transmission (TRAN) | D37: =J22+J23 -> 34235755
B38: 2. Distribution (DIST) | D38: =D24+J24 -> 38671232 | G38: POD CHARGE | H38: =E32 -> 164.42 | J38: =ROUND(+H38*D11,0) -> 2061827
B39: 3. Transmission & Distribution Utility
B40: Metering System Services (MET) | D40: =D26+G26+J26 -> 2041695.3 | G40: FACILITIES CHARGE - TRANS 4CP | H40: =K22 -> 4.7159536 | I40: * | J40: =ROUND(H40*D14,0) -> 31711960
B41: 4. Transmission & Distribution Utility | G41: FACILITIES CHARGE - TRANS NCP | H41: =K23 -> 3.129398 | I41: * | J41: =ROUND(H41*D15,0) -> 2523795
B42: Billing System Services (TD-BILL) | D42: =D28+G28+J28 -> 0 | G42: FACILITIES CHARGE - DIST | H42: =K24 -> 3.696 | I42: * | J42: =ROUND(+H42*D13,0) -> 38666160
B43: 5. Additional Billing Services (A-BILL) | D43: 0 | G43: TOTAL | J43: =SUM(J38:J42) -> 74963742
B44: 6. Transmission & Distribution Utility
B45: Customer Service (TDCS) | D45: =D31+G31+J31 -> 20249.74 | G45: *Unit Charge is per kW
B46: TOTAL | D46: =SUM(D37:D45) -> 74968933

Sheet AEPTX Trans
B1: PROOF OF REVENUE STATEMENT
B2: FOR THE TEST YEAR ENDING DECEMBER 31, 2018
B4: TRANSMISSION NCP - AEPTX
D8: ESTIMATED
D9: BILLING
B10: CLASS BILLING STATISTICS | D10: UNITS
B11: Number of Annual Bills | D11: ='Billing Units'!E21 -> 1020
B12: Annual kWh | D12: ='Billing Units'!G21 -> 5.7449969e+09
B13: Annual Billing kW | D13: ='Billing Units'!H21 -> 16829578
B14: 4CP Billing kW | D14: ='Billing Units'!J21 -> 6571184.2
D16: CALCULATION OF UNIT CHARGES USING FORECASTED BILLING UNITS
D17: POINT OF DELIVERY | G17: FACILITIES CHARGE | J17: FACILITIES CHARGE
D18: (POD) CHARGE | G18: (PER KWH) | J18: (PER KW)
B19: FUNCTION | D19: $ | E19: $/Bill/Month | G19: $ | H19: $/kWh | J19: $ | K19: $/kW
B20: 1. Transmission (TRAN) | D20: 0 | E20: 0 | G20: 0 | H20: 0 | J20: ='[3]AEPTX ERCOT Matrix 2018'!$E$15 -> 30604049 | K20: =IF(J20=0,J20,ROUND(J20/D$14,4)) -> 4.6573
B21: 2. Distribution (DIST) | G21: 0 | H21: =IF(G21=0,G21,ROUND(G21/D$13,6)) -> 0 | J21: ='[7]Retail Summary Proposed'!$O$72+'[7]Retail Summary Proposed'!$O$57 -> 4196817.8 | K21: =IF(J21=0,J21,ROUND(J21/D$13,4)) -> 0.2494
B22: 3. Transmission & Distribution Utility
B23: Metering System Services (MET) | D23: ='[7]Retail Summary Proposed'!$O$62 -> 1019505.2 | E23: =IF(D23=0,D23,ROUND(D23/D$11,2)) -> 999.51 | G23: 0 | H23: 0 | J23: 0 | K23: 0
B24: 4. Transmission & Distribution Utility
B25: Billing System Services (TD-BILL) | E25: =IF(D25=0,D25,ROUND(D25/D$11,2)) -> 0 | G25: 0 | H25: 0
B26: 5. Additional Billing Services (A-BILL) | D26: 0 | E26: 0 | G26: 0 | H26: 0 | J26: 0 | K26: 0
B27: 6. Transmission & Distribution Utility
B28: Customer Service (TDCS) | D28: ='[7]Retail Summary Proposed'!$O$67 -> 1775.3968 | E28: =IF(D28=0,D28,ROUND(D28/D$11,2)) -> 1.74 | G28: 0 | H28: 0
B29: TOTAL | D29: =IF(SUM(D20:D28)<1,D20,SUM(D20:D28)) -> 1021280.6 | E29: =SUM(E20:E28) -> 1001.25 | G29: =IF(SUM(G20:G28)<1,G20,SUM(G20:G28)) -> 0 | H29: =SUM(H20:H28) -> 0 | J29: =IF(SUM(J20:J28)<1,J20,SUM(J20:J28)) -> 34800867 | K29: =IF(SUM(K20:K28)<1,K20,SUM(K20:K28)) -> 4.9067
D31: FUNCTION | G31: PROPOSED CHARGES
D32: SUMMARY | H32: UNIT | J32: TOTAL
B33: FUNCTION | D33: $ | G33: DESCRIPTION | H33: CHARGE | J33: REVENUE
B34: 1. Transmission (TRAN) | D34: =J20 -> 30604049
B35: 2. Distribution (DIST) | D35: =D21+G21+J21 -> 4196817.8 | G35: POD CHARGE | H35: =E29 -> 1001.25 | J35: =ROUND(+H35*D11,0) -> 1021275
B36: 3. Transmission & Distribution Utility | G36: FACILITIES CHARGE - TRANS | H36: =K20 -> 4.6573 | J36: =ROUND(+H36*D14,0) -> 30603976
B37: Metering System Services (MET) | D37: =D23+G23+J23 -> 1019505.2 | G37: FACILITIES CHARGE - DIST | H37: =K21 -> 0.2494 | I37: * | J37: =ROUND(+H37*D13,0) -> 4197297
B38: 4. Transmission & Distribution Utility | G38: TOTAL | J38: =SUM(J35:J37) -> 35822548
B39: Billing System Services (TD-BILL) | D39: =D25+G25+J25 -> 0
B40: 5. Additional Billing Services (A-BILL) | D40: 0 | G40: *Unit Charge is per kW
B41: 6. Transmission & Distribution Utility
B42: Customer Service (TDCS) | D42: =D28+G28+J28 -> 1775.3968
B43: TOTAL | D43: =SUM(D34:D42) -> 35822148

Sheet AEPTX Lighting
B1: PROOF OF REVENUE STATEMENT
B2: FOR THE TEST YEAR ENDING DECEMBER 31, 2018
B4: LIGHTING SERVICE - AEPTX
D8: ESTIMATED | E8: ESTIMATED
D9: BILLING | E9: BILLING
B10: CLASS BILLING STATISTICS | D10: UNITS | E10: SEC < 10 kW UNITS
B11: Number of Annual Bills | D11: ='Billing Units'!E23 -> 27612 | E11: ='Billing Units'!E11 -> 1069896
B12: Annual kWh | D12: ='Billing Units'!G23 -> 2.6222605e+08 | E12: ='Billing Units'!G11 -> 5.7930338e+08
B13: Annual Billing kW | D13: 0 | E13: 0
D15: CALCULATION OF UNIT CHARGES USING FORECASTED BILLING UNITS
D16: POINT OF DELIVERY | G16: FACILITIES CHARGE | J16: FACILITIES CHARGE
D17: (POD) CHARGE | G17: (PER KWH) | J17: (PER KW)
B18: FUNCTION | D18: $ | E18: $/Bill/Month | G18: $ | H18: $/kWh | J18: $ | K18: $/kW
B19: 1. Transmission (TRAN) | D19: 0 | E19: 0 | J19: 0 | K19: =IF(J19=0,J19,ROUND(J19/G$13,4)) -> 0
B20: 2. Distribution (DIST) | J20: 0 | K20: 0
B21: 3. Transmission & Distribution Utility
B22: Metering System Services (MET) | D22: 0 | E22: =IF(D22=0,D22,ROUND(D22/(D$11+E11),2)) -> 0 | G22: 0 | H22: 0 | J22: 0 | K22: 0
B23: 4. Transmission & Distribution Utility
B24: Billing System Services (TD-BILL) | E24: =IF(D24=0,D24,ROUND(D24/D$11,2)) -> 0 | G24: 0 | H24: 0
B25: 5. Additional Billing Services (A-BILL) | D25: 0 | E25: 0 | G25: 0 | H25: 0 | J25: 0 | K25: 0
B26: 6. Transmission & Distribution Utility
B27: Customer Service (TDCS) | E27: =IF(D27=0,D27,ROUND(D27/(D$11+E11),2)) -> 0 | G27: 0 | H27: 0
B28: TOTAL | D28: =IF(SUM(D19:D27)<1,D19,SUM(D19:D27)) -> 0 | E28: =SUM(E19:E27) -> 0 | G28: =IF(SUM(G19:G27)<1,G19,SUM(G19:G27)) -> 0 | H28: =SUM(H19:H27) -> 0 | J28: =IF(SUM(J19:J27)<1,J19,SUM(J19:J27)) -> 0 | K28: =IF(SUM(K19:K27)<1,K19,SUM(K19:K27)) -> 0
D30: FUNCTION | G30: PROPOSED CHARGES
D31: SUMMARY | H31: UNIT | J31: TOTAL
B32: FUNCTION | D32: $ | G32: DESCRIPTION | H32: CHARGE | J32: REVENUE
B33: 1. Transmission (TRAN) | D33: =G19 -> 0
B34: 2. Distribution (DIST) | D34: =D20+G20+J20 -> 0 | G34: POD CHARGE | H34: =+E28 -> 0 | J34: SEE SEC<=10 kW
B35: 3. Transmission & Distribution Utility | G35: LIGHTING FIXTURES | J35: =[8]AEPTX!$D$33+'[9]Non-Roadway'!$Y$46+[9]MSL!$Y$65 -> 17089102
B36: Metering System Services (MET) | D36: =D22+G22+J22 -> 0 | G36: FACILITIES CHARGE TRANS | J36: SEE SEC<=10 kW
B37: 4. Transmission & Distribution Utility | G37: FACILITIES CHARGE DIST | H37: =+H28 -> 0 | I37: * | J37: SEE SEC<=10 kW
B38: Billing System Services (TD-BILL) | D38: =D24+G24+J24 -> 0 | G38: TOTAL | J38: =SUM(J34:J37) -> 17089102
B39: 5. Additional Billing Services (A-BILL) | D39: 0
B40: 6. Transmission & Distribution Utility | G40: *Unit Charge is per kWh
B41: Customer Service (TDCS) | D41: =D27+G27+J27 -> 0
B42: TOTAL | D42: =SUM(D33:D41) -> 0
