Workbook
Name \M: #REF!
Name _asd2: '[1]O & M'!$T$5
Name _M: #REF!
Name Account: [2]Source!#REF!
Name Account2: [2]Source!#REF!
Name AccountDescr: [2]Source!#REF!
Name AccountDescr2: [2]Source!#REF!
Name Activity: [2]Source!#REF!
Name Activity2: [2]Source!#REF!
Name ActivityDescr: [2]Source!#REF!
Name ActivityDescr2: [2]Source!#REF!
Name Affiliate: [2]Source!#REF!
Name Affiliate2: [2]Source!#REF!
Name AffiliateDescr: [2]Source!#REF!
Name ASD: '[3]O & M'!$T$5
Name Completed: '[4]FIT Paid - Combined'!$AO$5
Name completed2: '[5]FIT Paid - Combined'!$AO$5
Name Credit: [6]JOURNAL!#REF!
Name Debit: [6]JOURNAL!#REF!
Name DeptDescr: [2]Source!#REF!
Name DeptDescr2: [2]Source!#REF!
Name DeptID: [2]Source!#REF!
Name DeptID2: [2]Source!#REF!
Name EC: [2]Source!#REF!
Name ECDescr: [2]Source!#REF!
Name ECDescr2: [2]Source!#REF!
Name ECID: [2]Source!#REF!
Name Elapsed: '[4]FIT Paid - Combined'!$AO$4
Name entry: [6]JOURNAL!$B$9:$R$353,[6]JOURNAL!$I$3,[6]JOURNAL!$G$3,[6]JOURNAL!$E$3,[6]JOURNAL!$B$7,[6]JOURNAL!$B$3
Name EntryFields: [6]JOURNAL!$B$9:$R$353,[6]JOURNAL!$I$3,[6]JOURNAL!$G$3,[6]JOURNAL!$E$3,[6]JOURNAL!$B$7,[6]JOURNAL!$B$3
Name FFT: #REF!
Name KeyControlFigure: '[4]FIT Paid - Combined'!$T$399
Name Lines: [6]JOURNAL!#REF!
Name Location: [2]Source!#REF!
Name Location2: [2]Source!#REF!
Name LocationDescr: [2]Source!#REF!
Name LocationDescr2: [2]Source!#REF!
Name MENU: #REF!
Name NvsASD: "V2000-12-31"
Name NvsAutoDrillOk: "VN"
Name NvsElapsedTime: 0.000582986111112405
Name NvsElapsedTime: 0.000689467597112525
Name NvsEndTime: 36257.3051395833
Name NvsEndTime: 36923.3059673611
Name NvsInstSpec: "%"
Name NvsLayoutType: "M3"
Name NvsNplSpec: "%,X,RZF..nPlosion,CZF.."
Name NvsPanelEffdt: "V1998-01-01"
Name NvsPanelSetid: "VSHARE"
Name NvsParentRef: [7]Sheet1!$T$303
Name NvsReqBU: "VGEN"
Name NvsReqBU: "VLSGD"
Name NvsReqBUOnly: "VY"
Name NvsTransLed: "VN"
Name NvsTreeASD: "V2000-12-31"
Name NvsValTbl.ACCOUNT: "GL_ACCOUNT_TBL"
Name NvsValTbl.AFFILIATE: "BUS_UNIT_TBL_FS"
Name NvsValTbl.CURRENCY_CD: "CURRENCY_CD_TBL"
Name NvsValTbl.DEPTID: "DEPARTMENT_TBL"
Name NvsValTbl.TU_LOCATION: "TU_LOC_TBL"

Sheet  
A1: 2025 RATE CASE
A2: ONCOR ELECTRIC DELIVERY COMPANY LLC
A3: LEAD-LAG STUDY RESULTS
A4: FOR THE TEST-YEAR ENDING DECEMBER 31, 2024
A5: SPONSOR: A. THENMADATHIL
A7: Line | C7: Revenue | D7: Expense
A8: No. | B8: Description | C8: Lag Days* | D8: Lead Days | E8: Reference
B9: (a) | C9: (b) | D9: (c) | E9: `
A11: 1 | B11: Operation & Maintenance Expenses
A12: =A11+1 -> 2 | B12: Labor
A13: =A12+1 -> 3 | B13: Payroll | C13: =+'1'!H14 -> 53.27 | D13: =+'2'!J18 -> -12 | E13: WP/II-B-9/2
A14: =A13+1 -> 4 | B14: Incentive Pay | C14: =+$C$13 -> 53.27 | D14: ='3'!J17 -> -255.74549 | E14: WP/II-B-9/3
A15: =A14+1 -> 5
A16: =A15+1 -> 6 | B16: Non-Labor
A17: =A16+1 -> 7 | B17: Affiliate Charges - Sempra | C17: =+$C$13 -> 53.27 | D17: =+'4'!K24 -> -45.17 | E17: WP/II-B-9/4
A18: =A17+1 -> 8 | B18: Affiliate Charges - Other | C18: =+$C$13 -> 53.27 | D18: =+'6'!D17 -> -48.81 | E18: WP/II-B-9/6
A19: =A18+1 -> 9 | B19: TCOS
A20: =A19+1 -> 10 | B20: Oncor | C20: 0 | D20: 0 | E20: N/A
A21: =A20+1 -> 11 | B21: Non-Oncor | C21: =+$C$13 -> 53.27 | D21: ='5'!E16 -> -50.22 | E21: WP/II-B-9/5
A22: =A21+1 -> 12 | B22: Amortized O&M Expenses | C22: 0 | D22: 0 | E22: N/A
A23: =A22+1 -> 13 | B23: Other O&M | C23: =+$C$13 -> 53.27 | D23: ='6'!D17 -> -48.81 | E23: WP/II-B-9/6
A24: =A23+1 -> 14 | B24: Pension & Supplemental Retirement Benefits | C24: =+$C$13 -> 53.27 | D24: =+'6-4'!I36 -> -57.434985 | E24: WP/II-B-9/6-4
A25: =A24+1 -> 15 | B25: Other Post-Employment Benefits | C25: =+$C$13 -> 53.27 | D25: ='6-5'!I23 -> 10.665188 | E25: WP/II-B-9/6-5
A26: =A25+1 -> 16
A27: =A26+1 -> 17 | B27: Federal Income Taxes
A28: =A27+1 -> 18 | B28: Current | C28: =+$C$13 -> 53.27 | D28: =+'7'!F20 -> -37.5 | E28: WP/II-B-9/7
A29: =A28+1 -> 19 | B29: Deferred | C29: 0 | D29: 0 | E29: N/A
A30: =A29+1 -> 20
A31: =A30+1 -> 21 | B31: Taxes Other Than Income Taxes
A32: =A31+1 -> 22 | B32: Payroll Taxes | C32: =+$C$13 -> 53.27 | D32: =+'8'!D16 -> -11.47 | E32: WP/II-B-9/8
A33: =A32+1 -> 23 | B33: State Gross Margin Taxes | C33: =+$C$13 -> 53.27 | D33: =+'9'!F23 -> 46.25 | E33: WP/II-B-9/9
A34: =A33+1 -> 24 | B34: Local Franchise Taxes | C34: =+$C$13 -> 53.27 | D34: ='10'!F37 -> -58.48 | E34: WP/II-B-9/10
A35: =A34+1 -> 25 | B35: Ad Valorem Taxes | C35: =+$C$13 -> 53.27 | D35: =+'11'!G37 -> -212.48 | E35: WP/II-B-9/11
A36: =A35+1 -> 26
A37: =A36+1 -> 27 | B37: Depreciation Expense | C37: 0 | D37: 0 | E37: N/A
A38: =A37+1 -> 28
A39: =A38+1 -> 29 | B39: Return | C39: 0 | D39: 0 | E39: N/A
A40: =A39+1 -> 30
A41: =A40+1 -> 31 | B41: Average Daily Bank Balances | D41: =+'12'!J26 -> 2149754 | E41: WP/II-B-9/12
A42: =A41+1 -> 32 | B42: Working Funds and Other | D42: ='13'!C16 -> -3435810 | E42: WP/II-B-9/13
...

Sheet 1
A1: 2025 RATE CASE
A2: =' '!A2 -> ONCOR ELECTRIC DELIVERY COMPANY LLC
A3: OVERALL REVENUE LAG
A4: FOR THE LEAD-LAG STUDY-PERIOD ENDING SEPTEMBER 30, 2024
A5: SPONSOR: A. THENMADATHIL
A7: Line No. | C7: Revenue Type | E7: Revenues | F7: Ref | H7: Revenue Lag Days | I7: Ref | J7: Wtd Dollar Days
C8: (a) | E8: (b) | F8: (c) | H8: (d) | I8: (e) | J8: (f)
A10: 1 | C10: CC&B | E10: 4.9545563e+09 | F10: (1) | H10: =+'1-1'!E20 -> 53.14 | I10: WP/II-B-9/1-1 | J10: =H10*E10 -> 2.6328512e+11
A11: 2
A12: 3 | C12: FIM | E12: 4.3858816e+08 | F12: (2) | H12: =+'1-1'!H20 -> 54.782667 | I12: WP/II-B-9/1-1 | J12: =+H12*E12 -> 2.4027029e+10
A13: 4
A14: 5 | C14: Total | E14: =SUM(E10:E12) -> 5.3931445e+09 | H14: =ROUND(J14/E14,2) -> 53.27 | J14: =SUM(J10:J12) -> 2.8731215e+11
A15: 6
A16: 7 | C16: Sources: | D16: (1) | E16: CC&B Revenue.xlsx
A17: 8 | D17: (2) | E17: FIM Revenue.xlsx

Sheet 1-1
A1: 2025 RATE CASE
A2: =' '!A2 -> ONCOR ELECTRIC DELIVERY COMPANY LLC
A3: REVENUE LAG BY REVENUE TYPE
A4: FOR THE LEAD-LAG STUDY-PERIOD ENDING SEPTEMBER 30, 2024
A5: SPONSOR: A. THENMADATHIL
A7: Line No. | C7: Description | E7: CC&B | F7: Reference | H7: FIM | I7: Reference
C8: (a) | E8: (b) | F8: (c) | H8: (d) | I8: (e)
A10: 1 | C10: Average service period
A11: =A10+1 -> 2 | C11: (365.25 days/12 months)/2 | E11: =ROUND(365.25/12/2,3) -> 15.219 | H11: =ROUND(365.25/12/2,3) -> 15.219
A12: =A11+1 -> 3
A13: =A12+1 -> 4 | C13: Billing Process Lag | E13: =+'1-1-2'!D20 -> 3 | F13: WP/II-B-9/1-1-2 | H13: =+'1-1-2'!D20 -> 3 | I13: WP/II-B-9/1-1-2
A14: =A13+1 -> 5
A15: =A14+1 -> 6 | C15: Collection Lag | E15: =+'1-1-3'!E14 -> 34.921 | F15: WP/II-B-9/1-1-3 | H15: 36.563667 | I15: (1)
A16: =A15+1 -> 7
A17: =A16+1 -> 8 | C17: Receipt of funds lag | E17: 0 | H17: 0
A18: =A17+1 -> 9
A19: =A18+1 -> 10
A20: =A19+1 -> 11 | C20: Operating Revenues Lag Days | E20: =SUM(E11:E18) -> 53.14 | H20: =SUM(H11:H18) -> 54.782667
A21: =A20+1 -> 12
A22: =A21+1 -> 13 | C22: Source: | D22: (1) | E22: FIM Revenue.xlsx

Sheet 1-1-2
A1: 2025 RATE CASE
A2: =' '!A2 -> ONCOR ELECTRIC DELIVERY COMPANY LLC
A3: BILLING LAG
A4: FOR THE LEAD-LAG STUDY-PERIOD ENDING SEPTEMBER 30, 2024
A5: SPONSOR: A. THENMADATHIL
A7: Line No. | B7: Description | C7: Hours | D7: Days | E7: Reference
B8: (a) | C8: (b) | D8: (c) | E8: (d)
A10: 1 | B10: Period from Meter Reading Date to Invoice Date:
A11: =+A10+1 -> 2
A12: =+A11+1 -> 3 | B12: Calculated from invoice sample | D12: =+'1-1-2-1'!I133 -> 2.25 | E12: WP/II-B-9/1-1-2-1
A13: =+A12+1 -> 4
A14: =+A13+1 -> 5
A15: =+A14+1 -> 6 | B15: Invoicing Period
A16: =+A15+1 -> 7
A17: =+A16+1 -> 8 | B17: Start at midnight and end at 6 p.m. | C17: 18 | D17: =+C17/24 -> 0.75
A18: =+A17+1 -> 9
A19: =+A18+1 -> 10
A20: =+A19+1 -> 11 | B20: Total Billing Lag Days | D20: =SUM(D10:D17) -> 3

Sheet 1-1-2-1
A1: 2025 RATE CASE
A2: =' '!A2 -> ONCOR ELECTRIC DELIVERY COMPANY LLC
A3: REVENUE LAG - CALCULATION OF LAG DAYS FROM METER READ TO INVOICE (INVOICE SAMPLE RESULTS)
A4: FOR THE LEAD-LAG STUDY-PERIOD ENDING SEPTEMBER 30, 2024
A5: SPONSOR: A. THENMADATHIL
A7: Line No. | C7: Invoice Number | E7: Meter Read Date | F7: Meter Read Day of Week | G7: Invoice Date | I7: Lag Days from Meter Read to Invoice
C8: (a) | E8: (b) | F8: (c) | G8: (d) | I8: (e)
A10: 1 | C10: 8100043205069255144Z12 | E10: 45549 | F10: SATURDAY | G10: 45551 | I10: =+G10-E10 -> 2
A11: 2 | C11: 8100062363011579138Z11 | E11: 45440 | F11: TUESDAY | G11: 45441 | I11: =+G11-E11 -> 1
A12: 3 | C12: 8100024471742069054Z10 | E12: 45199 | F12: SATURDAY | G12: 45201 | I12: =+G12-E12 -> 2
A13: 4 | C13: 8100032714029819322Z11 | E13: 45507 | F13: SATURDAY | G13: 45509 | I13: =+G13-E13 -> 2
A14: 5 | C14: 8100074884162602514Z12 | E14: 45278 | F14: MONDAY | G14: 45279 | I14: =+G14-E14 -> 1
A15: 6 | C15: 8100057637848476372Z11 | E15: 45396 | F15: SUNDAY | G15: 45397 | I15: =+G15-E15 -> 1
A16: 7 | C16: 8100058052947228795Z11 | E16: 45445 | F16: SUNDAY | G16: 45446 | I16: =+G16-E16 -> 1
A17: 8 | C17: 8100087036466151487Z10 | E17: 45248 | F17: SATURDAY | G17: 45250 | I17: =+G17-E17 -> 2
A18: 9 | C18: 8100018086801149832Z11 | E18: 45395 | F18: SATURDAY | G18: 45397 | I18: =+G18-E18 -> 2
A19: 10 | C19: 8100089945249242888Z12 | E19: 45481 | F19: MONDAY | G19: 45482 | I19: =+G19-E19 -> 1
A20: 11 | C20: 8100002485754879007Z11 | E20: 45213 | F20: SATURDAY | G20: 45215 | I20: =+G20-E20 -> 2
A21: 12 | C21: 8100090319583189668Z12 | E21: 45409 | F21: SATURDAY | G21: 45411 | I21: =+G21-E21 -> 2
... A129: 120 | C129: 8100035760543093937Z11 | E129: 45199 | F129: SATURDAY | G129: 45201 | I129: =+G129-E129 -> 2
A130: 121
A131: 122 | C131: Total | I131: =SUM(I10:I129) -> 270
A132: 123
A133: 124 | C133: Average | I133: =+I131/A129 -> 2.25
A134: 125
A135: 126
A136: 127 | C136: Source: | E136: Revenue billing sample.xlsx

Sheet 1-1-3
A1: 2025 RATE CASE
A2: =' '!A2 -> ONCOR ELECTRIC DELIVERY COMPANY LLC
A3: CALCULATION OF COLLECTION LAG
A4: FOR THE LEAD-LAG STUDY-PERIOD ENDING SEPTEMBER 30, 2024
A5: SPONSOR: A. THENMADATHIL
A7: Line
A8: No. | B8: Description | C8: Reference | D8: Amount | E8: Collection Lag Days
B9: (a) | C9: (b) | D9: (c) | E9: (d)
A11: 1 | B11: Total Accounts Receivable | C11: WP/II-B-9/1-1-3-1 | D11: =+'1-1-3-1'!D25 -> 1.730205e+11
A12: 2 | B12: Revenues | C12: CC&B Revenue.xlsx | D12: 4.9545563e+09
A13: 3
A14: 4 | B14: Collection Lag (Line 1/Line 2) | E14: =ROUND(D11/D12,3) -> 34.921

Sheet 1-1-3-1
A1: 2025 RATE CASE
A2: =' '!A2 -> ONCOR ELECTRIC DELIVERY COMPANY LLC
A3: COLLECTION LAG
A4: FOR THE LEAD-LAG STUDY-PERIOD ENDING SEPTEMBER 30, 2024
A5: SPONSOR: A. THENMADATHIL
A7: Line
A8: No. | B8: Description | D8: Monthly Total
B9: (a) | D9: (b)
A11: 1 | B11: Sum of CC&B Daily A/R Balances
A12: 2 | B12: 45200 | D12: =+'1-1-3-1-1'!C41 -> 1.6587049e+10
A13: 3 | B13: 45231 | D13: =+'1-1-3-1-1'!E41 -> 1.3500263e+10
A14: 4 | B14: 45261 | D14: =+'1-1-3-1-1'!G41 -> 1.2938964e+10
A15: 5 | B15: 45292 | D15: =+'1-1-3-1-1'!C76 -> 1.369932e+10
A16: 6 | B16: 45323 | D16: =+'1-1-3-1-1'!E76 -> 1.5108631e+10
A17: 7 | B17: 45352 | D17: =+'1-1-3-1-1'!G76 -> 1.3348486e+10
A18: 8 | B18: 45383 | D18: =+'1-1-3-1-1'!C111 -> 1.145409e+10
A19: 9 | B19: 45413 | D19: =+'1-1-3-1-1'!E111 -> 1.2366701e+10
A20: 10 | B20: 45444 | D20: =+'1-1-3-1-1'!G111 -> 1.313313e+10
A21: 11 | B21: 45474 | D21: =+'1-1-3-1-1'!C146 -> 1.6062645e+10
A22: 12 | B22: 45505 | D22: =+'1-1-3-1-1'!E146 -> 1.7522719e+10
A23: 13 | B23: 45536 | D23: =+'1-1-3-1-1'!G146 -> 1.7298505e+10
A24: 14
A25: 15 | B25: Total Accounts Receivable | D25: =SUM(D12:D24) -> 1.730205e+11
A26: 16
A27: 17 | B27: Source: WP/II-B-9/1-1-3-1-1

Sheet 1-1-3-1-1
A1: 2025 RATE CASE
A2: ='1'!A2 -> ONCOR ELECTRIC DELIVERY COMPANY LLC
A3: CUSTOMER INFORMATION SYSTEM DAILY ACCOUNTS RECEIVABLE
A4: FOR THE LEAD-LAG STUDY-PERIOD ENDING SEPTEMBER 30, 2024
A5: SPONSOR: A. THENMADATHIL
A7: Line No. | B7: Date | C7: A/R Balance | D7: Date | E7: A/R Balance | F7: Date | G7: A/R Balance
B8: (a) | C8: (b) | D8: (c) | E8: (d) | F8: (e) | G8: (f)
A10: 1 | B10: 45200 | C10: 5.8288559e+08 | D10: =+B40+1 -> 45231 | E10: 4.991696e+08 | F10: =+D39+1 -> 45261 | G10: 3.8997668e+08
A11: =A10+1 -> 2 | B11: =+B10+1 -> 45201 | C11: 5.8288559e+08 | D11: =+D10+1 -> 45232 | E11: 4.8524353e+08 | F11: =+F10+1 -> 45262 | G11: 4.099081e+08
A12: =A11+1 -> 3 | B12: =+B11+1 -> 45202 | C12: 5.8876055e+08 | D12: =+D11+1 -> 45233 | E12: 4.8431528e+08 | F12: =+F11+1 -> 45263 | G12: 4.099081e+08
A13: =A12+1 -> 4 | B13: =+B12+1 -> 45203 | C13: 5.8770522e+08 | D13: =+D12+1 -> 45234 | E13: 4.8431528e+08 | F13: =+F12+1 -> 45264 | G13: 4.1019937e+08
A14: =A13+1 -> 5 | B14: =+B13+1 -> 45204 | C14: 5.8770522e+08 | D14: =+D13+1 -> 45235 | E14: 4.8431528e+08 | F14: =+F13+1 -> 45265 | G14: 4.1444652e+08
A15: =A14+1 -> 6 | B15: =+B14+1 -> 45205 | C15: 5.5665051e+08 | D15: =+D14+1 -> 45236 | E15: 4.7455429e+08 | F15: =+F14+1 -> 45266 | G15: 4.1209659e+08
A16: =A15+1 -> 7 | B16: =+B15+1 -> 45206 | C16: 5.5665051e+08 | D16: =+D15+1 -> 45237 | E16: 4.7595258e+08 | F16: =+F15+1 -> 45267 | G16: 4.1080649e+08
A17: =A16+1 -> 8 | B17: =+B16+1 -> 45207 | C17: 5.5665051e+08 | D17: =+D16+1 -> 45238 | E17: 4.6962688e+08 | F17: =+F16+1 -> 45268 | G17: 4.1127055e+08
A18: =A17+1 -> 9 | B18: =+B17+1 -> 45208 | C18: 5.817128e+08 | D18: =+D17+1 -> 45239 | E18: 4.6408745e+08 | F18: =+F17+1 -> 45269 | G18: 4.1127055e+08
A19: =A18+1 -> 10 | B19: =+B18+1 -> 45209 | C19: 5.7397055e+08 | D19: =+D18+1 -> 45240 | E19: 4.6703473e+08 | F19: =+F18+1 -> 45270 | G19: 4.1127055e+08
A20: =A19+1 -> 11 | B20: =+B19+1 -> 45210 | C20: 5.7062726e+08 | D20: =+D19+1 -> 45241 | E20: 4.6703473e+08 | F20: =+F19+1 -> 45271 | G20: 4.1178704e+08
A21: =A20+1 -> 12 | B21: =+B20+1 -> 45211 | C21: 5.576829e+08 | D21: =+D20+1 -> 45242 | E21: 4.6703473e+08 | F21: =+F20+1 -> 45272 | G21: 4.1268056e+08
A22: =A21+1 -> 13 | B22: =+B21+1 -> 45212 | C22: 5.394778e+08 | D22: =+D21+1 -> 45243 | E22: 4.6032428e+08 | F22: =+F21+1 -> 45273 | G22: 4.1113205e+08
... A39: =A38+1 -> 30 | B39: =+B38+1 -> 45229 | C39: 4.8181089e+08 | D39: =+D38+1 -> 45260 | E39: 3.7863746e+08 | F39: =+F38+1 -> 45290 | G39: 4.2088558e+08
A40: =A39+1 -> 31 | B40: =+B39+1 -> 45230 | C40: 4.9620935e+08 | F40: =+F39+1 -> 45291 | G40: 4.2088558e+08
A41: =A40+1 -> 32 | C41: =SUM(C10:C40) -> 1.6587049e+10 | E41: =SUM(E10:E40) -> 1.3500263e+10 | G41: =SUM(G10:G40) -> 1.2938964e+10
A42: Line No. | B42: Date | C42: A/R Balance | D42: Date | E42: A/R Balance | F42: Date | G42: A/R Balance
B43: (a) | C43: (b) | D43: (c) | E43: (d) | F43: (e) | G43: (f)
A45: =A41+1 -> 33 | B45: =+F40+1 -> 45292 | C45: 4.2088558e+08 | D45: =+B75+1 -> 45323 | E45: 4.978564e+08 | F45: =+D73+1 -> 45352 | G45: 4.8043735e+08
A46: =A45+1 -> 34 | B46: =+B45+1 -> 45293 | C46: 4.3035146e+08 | D46: =+D45+1 -> 45324 | E46: 5.1189052e+08 | F46: =+F45+1 -> 45353 | G46: 4.8043735e+08
A47: =A46+1 -> 35 | B47: =+B46+1 -> 45294 | C47: 4.3434088e+08 | D47: =+D46+1 -> 45325 | E47: 5.1189052e+08 | F47: =+F46+1 -> 45354 | G47: 4.8043735e+08
A48: =A47+1 -> 36 | B48: =+B47+1 -> 45295 | C48: 4.2675766e+08 | D48: =+D47+1 -> 45326 | E48: 5.1189052e+08 | F48: =+F47+1 -> 45355 | G48: 4.758927e+08
A49: =A48+1 -> 37 | B49: =+B48+1 -> 45296 | C49: 4.2766324e+08 | D49: =+D48+1 -> 45327 | E49: 5.1689472e+08 | F49: =+F48+1 -> 45356 | G49: 4.7589426e+08
A50: =A49+1 -> 38 | B50: =+B49+1 -> 45297 | C50: 4.4607484e+08 | D50: =+D49+1 -> 45328 | E50: 5.3747791e+08 | F50: =+F49+1 -> 45357 | G50: 4.7140242e+08
A51: =A50+1 -> 39 | B51: =+B50+1 -> 45298 | C51: 4.4607484e+08 | D51: =+D50+1 -> 45329 | E51: 5.3757316e+08 | F51: =+F50+1 -> 45358 | G51: 4.6018172e+08
A52: =A51+1 -> 40 | B52: =+B51+1 -> 45299 | C52: 4.3429311e+08 | D52: =+D51+1 -> 45330 | E52: 5.3564156e+08 | F52: =+F51+1 -> 45359 | G52: 4.5799609e+08
A53: =A52+1 -> 41 | B53: =+B52+1 -> 45300 | C53: 4.3755411e+08 | D53: =+D52+1 -> 45331 | E53: 5.3459063e+08 | F53: =+F52+1 -> 45360 | G53: 4.5799609e+08
A54: =A53+1 -> 42 | B54: =+B53+1 -> 45301 | C54: 4.3703759e+08 | D54: =+D53+1 -> 45332 | E54: 5.3459063e+08 | F54: =+F53+1 -> 45361 | G54: 4.5799609e+08
A55: =A54+1 -> 43 | B55: =+B54+1 -> 45302 | C55: 4.3746895e+08 | D55: =+D54+1 -> 45333 | E55: 5.3459063e+08 | F55: =+F54+1 -> 45362 | G55: 4.4730593e+08
A56: =A55+1 -> 44 | B56: =+B55+1 -> 45303 | C56: 4.2630195e+08 | D56: =+D55+1 -> 45334 | E56: 5.2193809e+08 | F56: =+F55+1 -> 45363 | G56: 4.4137036e+08
A57: =A56+1 -> 45 | B57: =+B56+1 -> 45304 | C57: 4.2630195e+08 | D57: =+D56+1 -> 45335 | E57: 5.2435003e+08 | F57: =+F56+1 -> 45364 | G57: 4.3342042e+08
... A73: =A72+1 -> 61 | B73: =+B72+1 -> 45320 | C73: 4.7132156e+08 | D73: =+D72+1 -> 45351 | E73: 4.7941819e+08 | F73: =+F72+1 -> 45380 | G73: 3.9366007e+08
A74: =A73+1 -> 62 | B74: =+B73+1 -> 45321 | C74: 4.8725933e+08 | E74: 0 | F74: =+F73+1 -> 45381 | G74: 3.9366007e+08
...

Sheet 2
A1: 2025 RATE CASE
A2: =' '!A2 -> ONCOR ELECTRIC DELIVERY COMPANY LLC
A3: LABOR - PAYROLL LEAD DAYS
A4: FOR THE LEAD-LAG STUDY-PERIOD ENDING SEPTEMBER 30, 2024
A5: SPONSOR: A. THENMADATHIL
A7: Line No. | B7: Payroll Type | C7: Payroll Expense | D7: Percent | E7: Reference | F7: (Lead)/Lag | G7: Reference | H7: Check Float | I7: Reference | J7: Total (Lead)/Lag | K7: Weighted Dollar Days
B8: (a) | C8: (b) | D8: (c) | E8: (d) | F8: (e) | G8: (f) | H8: (g) | I8: (h) | J8: (i) | K8: (j)
A10: 1 | B10: Bi-Weekly
A11: 2
A12: 3 | B12: Direct Deposit | C12: =+C15*D12 -> 3.2710117e+08 | D12: ='2-1'!F18 -> 0.9995 | E12: WP/II-B-9/2-1 | F12: =-'2-2'!C25 -> -12 | G12: WP/II-B-9/2-2 | H12: 0 | J12: =F12+H12 -> -12 | K12: =C12*J12 -> -3.9252141e+09
A13: 4 | B13: Manual | C13: =C15-C12 -> 163632.4 | D13: ='2-1'!G18 -> 0.0005 | E13: WP/II-B-9/2-1 | F13: =F12 -> -12 | G13: WP/II-B-9/2-2 | H13: ='2-4'!D14 -> 9.02 | I13: WP/II-B-9/2-4 | J13: =F13+H13 -> -2.98 | K13: =C13*J13 -> -487624.56
A14: 5
A15: 6 | B15: Total Bi-Weekly Pay | C15: =+D15*C18 -> 3.272648e+08 | D15: =+'2-6'!E11 -> 1 | E15: WP/II-B-9/2-6 | J15: =K15/C15 -> -11.99549 | K15: =SUM(K12:K13) -> -3.9257017e+09
A16: 7
A17: 8
A18: 9 | B18: Total | C18: 3.272648e+08 | D18: =+D15 -> 1 | E18: Schedule II-D-3 * | F18: =ROUND((C15*F12)/C18,2) -> -12 | J18: =ROUND(K18/C18,2) -> -12 | K18: =+K15 -> -3.9257017e+09
A19: 10 | E19: *Net of Incentive Pay

Sheet 2-1
A1: 2025 RATE CASE
A2: =' '!A2 -> ONCOR ELECTRIC DELIVERY COMPANY LLC
A3: PAYROLL LEAD - DIRECT DEPOSIT CALCULATION
A4: FOR THE LEAD-LAG STUDY-PERIOD ENDING SEPTEMBER 30, 2024
A5: SPONSOR: A. THENMADATHIL
A7: Line No. | B7: Period/Business Unit | C7: Direct Deposit | D7: Manual Checks | E7: Total - Direct Deposit and Manual Checks | F7: Percent Paid via Direct Deposit | G7: Percent Paid via Manual Check
B8: (a) | C8: (b) | D8: (c) | E8: (d) | F8: (e) | G8: (f)
A10: 1 | B10: 45200
A11: =A10+1 -> 2 | B11: Transmission | C11: 9467594.4 | D11: 2176.29 | E11: =+C11+D11 -> 9469770.7
A12: =A11+1 -> 3 | B12: Distribution | C12: 25450128 | D12: 4841.49 | E12: =+C12+D12 -> 25454970
A13: =A12+1 -> 4
A14: =A13+1 -> 5 | B14: 45536
A15: =A14+1 -> 6 | B15: Transmission | C15: 9320372.1 | D15: 133.49 | E15: =+C15+D15 -> 9320505.6
A16: =A15+1 -> 7 | B16: Distribution | C16: 26167254 | D16: 26113.37 | E16: =+C16+D16 -> 26193367
A17: =A16+1 -> 8
A18: =A17+1 -> 9 | B18: Total Payments | C18: =SUM(C10:C16) -> 70405349 | D18: =SUM(D10:D16) -> 33264.64 | E18: =SUM(E10:E16) -> 70438613 | F18: =+ROUND(C18/$E$18,4) -> 0.9995 | G18: =+ROUND(D18/$E$18,4) -> 0.0005
A19: =A18+1 -> 10
A20: =A19+1 -> 11 | F20: (1) | G20: (2)
A21: =A20+1 -> 12 | B21: Note:
A22: =A21+1 -> 13 | B22: (1) The calculation is Col (b) Ln 9 divided by Col (d) Ln 9.
A23: =A22+1 -> 14 | B23: (2) The calculation is Col (c) Ln 9 divided by Col (d) Ln 9.
A24: =A23+1 -> 15
A25: =A24+1 -> 16 | B25: Source: | C25: Payroll direct deposit.xlsx

Sheet 2-2
A1: 2025 RATE CASE
A2: =' '!A2 -> ONCOR ELECTRIC DELIVERY COMPANY LLC
A3: PAYROLL LEAD - BI-WEEKLY PAYROLL CALCULATION
A4: FOR THE LEAD-LAG STUDY-PERIOD ENDING SEPTEMBER 30, 2024
A5: SPONSOR: A. THENMADATHIL
A7: Line No. | B7: Bi-Weekly | C7: Days
B8: (a) | C8: (b)
A10: 1 | B10: Conditions:
A11: 2
A12: 3 | B12: Pay Periods cover 14 days.
A13: 4 | B13: Start on Monday and end on the second following Sunday.
A14: 5 | B14: Payment Checks or Direct Deposits typically are made on Friday, five days after end of pay period.
A15: 6 | B15: (If the scheduled pay date is a holiday, payment is made on the preceding work day. During
A16: 7 | B16: the test period, with the exception of one instance, all paydays fell on the regularly scheduled Friday.)
A17: 8
A18: 9
A19: 10 | B19: Days in Period:
A20: 11
A21: 12 | B21: 14 days. Midpoint = 7
A22: 13
A23: 14 | B23: Payroll Lead Formula:
A24: 15
A25: 16 | B25: (7 days) + (5 days) = | C25: =7+'2-2-1'!G43 -> 12
A27: Sources: | B27: Holidays.xlsx
B28: Bi-Weekly Payroll Calendar 2024.xlsx
B29: Bi-Weekly Payroll Calendar 2023.xlsx

Sheet 2-2-1
A1: 2025 RATE CASE
A2: =' '!A2 -> ONCOR ELECTRIC DELIVERY COMPANY LLC
A3: PAYROLL LEAD - HOLIDAY/WEEKEND FACTOR CALCULATION - BI-WEEKLY
A4: FOR THE LEAD-LAG STUDY-PERIOD ENDING SEPTEMBER 30, 2024
A5: SPONSOR: A. THENMADATHIL
A8: Line No. | B8: Scheduled Payday | C8: Normal Payment Lead Days | E8: Lead Days Reflecting Holiday Adjustments | G8: Total
B9: (a) | C9: (b) | E9: (c) | G9: (d)
A11: 1 | B11: 45177 | C11: 5 | G11: =C11+E11 -> 5
A12: 2 | B12: 45191 | C12: 5 | G12: =C12+E12 -> 5
A13: 3 | B13: 45205 | C13: 5 | G13: =C13+E13 -> 5
A14: 4 | B14: 45219 | C14: 5 | G14: =C14+E14 -> 5
A15: 5 | B15: 45233 | C15: 5 | G15: =C15+E15 -> 5
A16: 6 | B16: 45247 | C16: 5 | G16: =C16+E16 -> 5
A17: 7 | B17: 45261 | C17: 5 | G17: =C17+E17 -> 5
A18: 8 | B18: 45275 | C18: 5 | G18: =C18+E18 -> 5
A19: 9 | B19: 45289 | C19: 5 | G19: =C19+E19 -> 5
A20: 10 | B20: 45303 | C20: 5 | G20: =C20+E20 -> 5
A21: 11 | B21: 45317 | C21: 5 | G21: =C21+E21 -> 5
A22: 12 | B22: 45331 | C22: 5 | G22: =C22+E22 -> 5
... A38: 28 | B38: 45555 | C38: 5 | G38: =C38+E38 -> 5
A39: 29 | B39: Total Days | C39: =SUM(C11:C38) -> 140 | E39: =SUM(E11:E38) -> 0 | G39: =SUM(G11:G38) -> 140
A40: 30
A41: 31
A42: 32 | B42: Number of Annual Payroll Cycles | G42: =A38 -> 28
A43: 33 | B43: Average of Lead Days Before Payment | G43: =ROUND(G39/G42,2) -> 5
A44: 34
A45: 35
A46: 36 | B46: Sources: | C46: Holidays.xlsx
A47: 37 | C47: Bi-Weekly Payroll Calendar 2023.xlsx
A48: 38 | C48: Bi-Weekly Payroll Calendar 2024.xlsx

Sheet 2-3
A1: 2025 RATE CASE
A2: =' '!A2 -> ONCOR ELECTRIC DELIVERY COMPANY LLC
A3: PAYROLL LEAD - SEMI-MONTHLY PAYROLL CALCULATION
A4: FOR THE LEAD-LAG STUDY-PERIOD ENDING SEPTEMBER 30, 2024
A5: SPONSOR: A. THENMADATHIL
A7: Line No. | B7: Semi-Monthly
B8: (a) | C8: (b) | D8: (c) | E8: (d)
A10: 1 | B10: As of the first pay date of January 2024 Oncor moved entire payroll to bi-weekly
A11: 2

Sheet 2-3-1
A1: 2025 RATE CASE
A2: =' '!A2 -> ONCOR ELECTRIC DELIVERY COMPANY LLC
A3: PAYROLL LEAD - HOLIDAY/WEEKEND FACTOR CALCULATION - SEMI MONTHLY
A4: FOR THE LEAD-LAG STUDY-PERIOD ENDING SEPTEMBER 30, 2024
A5: SPONSOR: A. THENMADATHIL
C7: Days Payday Moved Up
A8: Line No. | B8: Scheduled Payday | C8: 1st Pay Period | D8: 2nd Pay Period | F8: Actual Payday | H8: Difference
B9: (a) | C9: (b) | D9: (c) | F9: (d) | H9: (e)
A11: 1 | B11: As of the first pay date of January 2024 Oncor moved entire payroll to bi-weekly
A12: 2

Sheet 2-4
A1: 2025 RATE CASE
A2: =' '!A2 -> ONCOR ELECTRIC DELIVERY COMPANY LLC
A3: PAYROLL LEAD - CHECK FLOAT CALCULATION
A4: FOR THE LEAD-LAG STUDY-PERIOD ENDING SEPTEMBER 30, 2024
A5: SPONSOR: A. THENMADATHIL
E7: Weighted
A8: Line No. | B8: Business Unit | C8: Net Amount | D8: (Lead)/Lag Days | E8: Dollar Days | F8: Total
B9: (a) | C9: (b) | D9: (c) | E9: (d)
A11: 1 | B11: Transmission | C11: 44829.02 | D11: 23.999366 | E11: =+D11*C11 -> 1075868.1
A12: 2 | B12: Distribution | C12: 209872.09 | D12: 5.8149497 | E12: =+D12*C12 -> 1220395.7
A13: 3
A14: 4 | B14: Total | C14: =SUM(C11:C12) -> 254701.11 | D14: =ROUND(E14/C14,2) -> 9.02 | E14: =SUM(E11:E12) -> 2296263.7
A15: 5
A16: 6 | B16: Source: | C16: Payroll manual check sample.xlsx

Sheet 2-5
A1: 2025 RATE CASE
A2: =' '!A2 -> ONCOR ELECTRIC DELIVERY COMPANY LLC
A3: PAYROLL LEAD - PAY CYCLE CALCULATION
A4: FOR THE LEAD-LAG STUDY-PERIOD ENDING SEPTEMBER 30, 2024
A5: SPONSOR: A. THENMADATHIL
A7: Line No. | B7: Description | C7: First Cycle | D7: Second Cycle | E7: Third Cycle | F7: Total
B8: (a) | C8: (b) | D8: (c) | E8: (c) | F8: (d)
B9: Biweekly
A10: 1 | B10: Distribution
A11: 2 | B11: October 2023 | C11: 20148158 | D11: 19036521 | F11: =SUM(C11:E11) -> 39184679
A12: 3 | B12: September 2024 | C12: 20610519 | D12: 19795323 | F12: =SUM(C12:E12) -> 40405842
A13: 4 | B13: Total | C13: =SUM(C11 + C12) -> 40758678 | D13: =SUM(D11 + D12) -> 38831843 | E13: =SUM(E11 + E12) -> 0 | F13: =SUM(F11 + F12) -> 79590521
A14: 5 | B14: Percent | C14: =ROUND(SUM(C13/$F$13),4) -> 0.5121 | D14: =ROUND(SUM(D13/$F$13),4) -> 0.4879 | E14: =ROUND(SUM(E13/$F$13),4) -> 0 | F14: =SUM(C13+D13+E13) / F13 -> 1
A15: 6
A16: 7
A17: 8 | B17: Transmission
A18: 9 | B18: October 2023 | C18: 6980073.6 | D18: 7501641.8 | F18: =SUM(C18:E18) -> 14481715
A19: 10 | B19: September 2024 | C19: 7318260.7 | D19: 6915797 | F19: =SUM(C19:E19) -> 14234058
A20: 11 | B20: Total | C20: =SUM(C18 + C19) -> 14298334 | D20: =SUM(D18 + D19) -> 14417439 | F20: =SUM(F18 + F19) -> 28715773
A21: 12 | B21: Percent | C21: =ROUND(SUM(C20/$F$20),4) -> 0.4979 | D21: =ROUND(SUM(D20/$F$20),4) -> 0.5021 | F21: =SUM(C20+D20+E20) / F20 -> 1
A22: 13
A23: 14 | B23: Total T&D | C23: =C20 -> 14298334 | D23: =D20 -> 14417439 | F23: =SUM(C23:E23) -> 28715773
A24: 15 | B24: Percent | C24: =ROUND(C23/F23,4) -> 0.4979 | D24: =ROUND(D23/F23,4) -> 0.5021 | F24: =SUM(C23+D23+E23) / F23 -> 1
A25: 16
A26: 17 | B26: Source: | C26: Payroll pay cycles.xlsx

Sheet 2-6
A1: 2025 RATE CASE
A2: =' '!A2 -> ONCOR ELECTRIC DELIVERY COMPANY LLC
A3: PAYROLL LEAD - BI-WEEKLY/SEMI-MONTHLY PAY CALCULATION
A4: FOR THE LEAD-LAG STUDY-PERIOD ENDING SEPTEMBER 30, 2024
A5: SPONSOR: A. THENMADATHIL
A7: Line | E7: Bi-Weekly | F7: Semi-Monthly
A8: No. | B8: Description | C8: Total Payroll | D8: Bi-Weekly | E8: Percent | F8: Percent
B9: (a) | C9: (b) | D9: (c) | E9: (d) | F9: (e)
A11: 1 | B11: Payroll | C11: 7.8851023e+08 | D11: =C11 -> 7.8851023e+08 | E11: =ROUND(D11/C11,4) -> 1 | F11: =1-E11 -> 0
A12: 2
A13: 3 | B13: Source: | C13: Payroll semi-monthly & bi-weekly.xlsx

Sheet 3
A1: 2025 RATE CASE
A2: =' '!A2 -> ONCOR ELECTRIC DELIVERY COMPANY LLC
A3: LABOR - INCENTIVE PAY LEAD DAYS
A4: FOR THE LEAD-LAG STUDY-PERIOD ENDING SEPTEMBER 30, 2024
A5: SPONSOR: A. THENMADATHIL
A7: Line No. | B7: Description | C7: Payroll Expense | D7: Percent | E7: Reference | F7: (Lead)/Lag | G7: Reference | H7: Check Float | I7: Reference | J7: Total (Lead)/Lag | K7: Weighted Dollar Days
B8: (a) | C8: (b) | D8: (c) | E8: (d) | F8: (e) | G8: (f) | H8: (g) | I8: (h) | J8: (i) | K8: (j)
A10: 1 | B10: Test Year Incentive | C10: =+C12-C11 -> 68494556
A11: =A10+1 -> 2 | B11: Adjustment Needed | C11: -5816139.7
A12: =A11+1 -> 3 | B12: Adjusted Incentive | C12: 62678416 | E12: Source 1
A14: =A12+1 -> 4
A15: =A14+1 -> 5 | B15: Direct Deposit | C15: =+C17*D15 -> 62647077 | D15: =+'2-1'!F18 -> 0.9995 | E15: WP/II-B-9/2-1 | F15: ='3-1'!F34 -> -255.75 | G15: WP/II-B-9/3-1 | H15: 0 | J15: =+H15+F15 -> -255.75 | K15: =+J15*C15 -> -1.602199e+10
A16: =A15+1 -> 6 | B16: Manual | C16: =+C17*D16 -> 31339.208 | D16: =+'2-1'!G18 -> 0.0005 | E16: WP/II-B-9/2-1 | F16: =F15 -> -255.75 | G16: WP/II-B-9/3-1 | H16: ='2-4'!D14 -> 9.02 | I16: WP/II-B-9/2-4 | J16: =+H16+F16 -> -246.73 | K16: =+J16*C16 -> -7732322.8
A17: =A16+1 -> 7 | B17: Total Adjusted Incentive | C17: =+C12 -> 62678416 | J17: =K17/C17 -> -255.74549 | K17: =+K16+K15 -> -1.6029722e+10
A18: =A17+1 -> 8
A19: =A18+1 -> 9
A20: =A19+1 -> 10 | B20: Source 1: | C20: Iteration "Adjusted Test Year Amount"

Sheet 3-1
A1: 2025 RATE CASE
A2: =' '!A2 -> ONCOR ELECTRIC DELIVERY COMPANY LLC
A3: PEP AWARD LEAD PAYMENT CALCULATION
A4: FOR THE LEAD-LAG STUDY-PERIOD ENDING SEPTEMBER 30, 2024
A5: SPONSOR: A. THENMADATHIL
A7: Line No. | B7: Month | C7: Accrual Date | D7: Mid Month | E7: Payout Date | F7: (Lead)/Lag Days
B8: (a) | C8: (b) | D8: (c) | E8: (d) | F8: (e)
A10: 1 | B10: 45200 | C10: 45230 | D10: =IF(C10=0,"",DATE(YEAR(C10),MONTH(C10),1)+INT(DAY(DATE(YEAR(C10),MONTH(C10)+1,1)-1)/2)-0.5) -> 45214.5 | E10: 45362 | F10: =D10-E10 -> -147.5
A11: 2
A12: 3 | B12: =B10+31 -> 45231 | C12: =C10+30 -> 45260 | D12: =IF(C12=0,"",DATE(YEAR(C12),MONTH(C12),1)+INT(DAY(DATE(YEAR(C12),MONTH(C12)+1,1)-1)/2)-0.5) -> 45245.5 | E12: =$E$10 -> 45362 | F12: =D12-E12 -> -116.5
A13: 4
A14: 5 | B14: =B12+30 -> 45261 | C14: =C12+31 -> 45291 | D14: =IF(C14=0,"",DATE(YEAR(C14),MONTH(C14),1)+INT(DAY(DATE(YEAR(C14),MONTH(C14)+1,1)-1)/2)-0.5) -> 45275.5 | E14: =$E$10 -> 45362 | F14: =D14-E14 -> -86.5
A15: 6
A16: 7 | B16: =B14+31 -> 45292 | C16: =C14+31 -> 45322 | D16: =IF(C16=0,"",DATE(YEAR(C16),MONTH(C16),1)+INT(DAY(DATE(YEAR(C16),MONTH(C16)+1,1)-1)/2)-0.5) -> 45306.5 | E16: 45730 | F16: =D16-E16 -> -423.5
A17: 8
A18: 9 | B18: =B16+31 -> 45323 | C18: 45350 | D18: =IF(C18=0,"",DATE(YEAR(C18),MONTH(C18),1)+INT(DAY(DATE(YEAR(C18),MONTH(C18)+1,1)-1)/2)-0.5) -> 45336.5 | E18: =+E16 -> 45730 | F18: =D18-E18 -> -393.5
A19: 10
A20: 11 | B20: =B18+29 -> 45352 | C20: 45382 | D20: =IF(C20=0,"",DATE(YEAR(C20),MONTH(C20),1)+INT(DAY(DATE(YEAR(C20),MONTH(C20)+1,1)-1)/2)-0.5) -> 45366.5 | E20: =+E18 -> 45730 | F20: =D20-E20 -> -363.5
A21: 12
A22: 13 | B22: =B20+31 -> 45383 | C22: =C20+30 -> 45412 | D22: =IF(C22=0,"",DATE(YEAR(C22),MONTH(C22),1)+INT(DAY(DATE(YEAR(C22),MONTH(C22)+1,1)-1)/2)-0.5) -> 45397.5 | E22: =+E20 -> 45730 | F22: =D22-E22 -> -332.5
A23: 14
A24: 15 | B24: =B22+30 -> 45413 | C24: =C22+31 -> 45443 | D24: =IF(C24=0,"",DATE(YEAR(C24),MONTH(C24),1)+INT(DAY(DATE(YEAR(C24),MONTH(C24)+1,1)-1)/2)-0.5) -> 45427.5 | E24: =E22 -> 45730 | F24: =D24-E24 -> -302.5
A25: 16
A26: 17 | B26: =B24+31 -> 45444 | C26: =C24+30 -> 45473 | D26: =IF(C26=0,"",DATE(YEAR(C26),MONTH(C26),1)+INT(DAY(DATE(YEAR(C26),MONTH(C26)+1,1)-1)/2)-0.5) -> 45458.5 | E26: =E24 -> 45730 | F26: =D26-E26 -> -271.5
A27: 18
A28: 19 | B28: =B26+30 -> 45474 | C28: =C26+31 -> 45504 | D28: =IF(C28=0,"",DATE(YEAR(C28),MONTH(C28),1)+INT(DAY(DATE(YEAR(C28),MONTH(C28)+1,1)-1)/2)-0.5) -> 45488.5 | E28: =E26 -> 45730 | F28: =D28-E28 -> -241.5
A29: 20
A30: 21 | B30: =B28+31 -> 45505 | C30: =C28+31 -> 45535 | D30: =IF(C30=0,"",DATE(YEAR(C30),MONTH(C30),1)+INT(DAY(DATE(YEAR(C30),MONTH(C30)+1,1)-1)/2)-0.5) -> 45519.5 | E30: =E28 -> 45730 | F30: =D30-E30 -> -210.5
A31: 22
A32: 23 | B32: =B30+31 -> 45536 | C32: =C30+30 -> 45565 | D32: =IF(C32=0,"",DATE(YEAR(C32),MONTH(C32),1)+INT(DAY(DATE(YEAR(C32),MONTH(C32)+1,1)-1)/2)-0.5) -> 45550.5 | E32: =E30 -> 45730 | F32: =D32-E32 -> -179.5
A33: 24
A34: 25 | B34: Average | F34: =ROUND(AVERAGE(F10:F32),2) -> -255.75

Sheet 3-2
A1: 2025 RATE CASE
A2: =' '!A2 -> ONCOR ELECTRIC DELIVERY COMPANY LLC
A3: METER READER INCENTIVE LEAD DAYS - PAYMENT CALCULATION
A4: FOR THE LEAD-LAG STUDY-PERIOD ENDING SEPTEMBER 30, 2024
A5: SPONSOR: A. THENMADATHIL
A7: Line No. | B7: Month | C7: Accrual Date | D7: Mid Month | E7: Payout Date | F7: (Lead)/Lag Days
B8: (a) | C8: (b) | D8: (c) | E8: (d) | F8: (e)
A10: 1 | B10: No Longer have Meter Readers thus no incentive effective 1/13.
A11: 2
A12: 3
A13: 4
A14: 5
A15: 6
A16: 7
A17: 8
A18: 9
A19: 10
A20: 11
A21: 12
A22: 13
... A34: 25

Sheet 4
A1: 2025 RATE CASE
A2: =' '!A2 -> ONCOR ELECTRIC DELIVERY COMPANY LLC
A3: NON-LABOR O&M - ONCOR ELECTRIC DELIVERY COMPANY LLC AND OTHER AFFILIATES
A4: FOR THE LEAD-LAG STUDY-PERIOD ENDING SEPTEMBER 30, 2024
A5: SPONSOR: A. THENMADATHIL
A7: Line | G7: Date | H7: Date | I7: Later of Paid | J7: Days Paid | K7: (Lead)/Lag
A8: No. | B8: Month | C8: From | D8: To | E8: Total Days | F8: Mid-Point | G8: Paid | H8: Due | I8: or Due Date | J8: After EOM | K8: Days
B9: (a) | C9: (b) | D9: (c) | E9: (d) | F9: (e) | G9: (f) | H9: (g) | I9: (h) | J9: (i) | K9: (j)
A11: 1 | B11: 45200 | C11: 45200 | D11: 45230 | E11: =D11-C11+1 -> 31 | F11: =E11/2 -> 15.5 | G11: 45260 | H11: 45260 | I11: =MAX(G11:H11) -> 45260 | J11: =+I11-D11 -> 30 | K11: =-J11-F11 -> -45.5 | N11: =H11 -> 45260
A12: =A11+1 -> 2 | B12: 45231 | C12: 45231 | D12: 45260 | E12: =D12-C12+1 -> 30 | F12: =E12/2 -> 15 | G12: 45289 | H12: 45289 | I12: =MAX(G12:H12) -> 45289 | J12: =+I12-D12 -> 29 | K12: =-J12-F12 -> -44 | N12: =H12 -> 45289
A13: =A12+1 -> 3 | B13: 45261 | C13: 45261 | D13: 45291 | E13: =D13-C13+1 -> 31 | F13: =E13/2 -> 15.5 | G13: 45322 | H13: 45322 | I13: =MAX(G13:H13) -> 45322 | J13: =+I13-D13 -> 31 | K13: =-J13-F13 -> -46.5 | N13: =H13 -> 45322
A14: =A13+1 -> 4 | B14: 45292 | C14: 45292 | D14: 45322 | E14: =D14-C14+1 -> 31 | F14: =E14/2 -> 15.5 | G14: 45351 | H14: 45351 | I14: =MAX(G14:H14) -> 45351 | J14: =+I14-D14 -> 29 | K14: =-J14-F14 -> -44.5 | N14: =H14 -> 45351
A15: =A14+1 -> 5 | B15: 45323 | C15: 45323 | D15: 45351 | E15: =D15-C15+1 -> 29 | F15: =E15/2 -> 14.5 | G15: 45380 | H15: 45380 | I15: =MAX(G15:H15) -> 45380 | J15: =+I15-D15 -> 29 | K15: =-J15-F15 -> -43.5 | N15: =H15 -> 45380
A16: =A15+1 -> 6 | B16: 45352 | C16: 45352 | D16: 45382 | E16: =D16-C16+1 -> 31 | F16: =E16/2 -> 15.5 | G16: 45412 | H16: 45412 | I16: =MAX(G16:H16) -> 45412 | J16: =+I16-D16 -> 30 | K16: =-J16-F16 -> -45.5 | N16: =H16 -> 45412
A17: =A16+1 -> 7 | B17: 45383 | C17: 45383 | D17: 45412 | E17: =D17-C17+1 -> 30 | F17: =E17/2 -> 15 | G17: 45443 | H17: 45443 | I17: =MAX(G17:H17) -> 45443 | J17: =+I17-D17 -> 31 | K17: =-J17-F17 -> -46 | N17: =H17 -> 45443
A18: =A17+1 -> 8 | B18: 45413 | C18: 45413 | D18: 45443 | E18: =D18-C18+1 -> 31 | F18: =E18/2 -> 15.5 | G18: 45471 | H18: 45471 | I18: =MAX(G18:H18) -> 45471 | J18: =+I18-D18 -> 28 | K18: =-J18-F18 -> -43.5 | N18: =H18 -> 45471
A19: =A18+1 -> 9 | B19: 45444 | C19: 45444 | D19: 45473 | E19: =D19-C19+1 -> 30 | F19: =E19/2 -> 15 | G19: 45504 | H19: 45504 | I19: =MAX(G19:H19) -> 45504 | J19: =+I19-D19 -> 31 | K19: =-J19-F19 -> -46 | N19: =H19 -> 45504
A20: =A19+1 -> 10 | B20: 45474 | C20: 45474 | D20: 45504 | E20: =D20-C20+1 -> 31 | F20: =E20/2 -> 15.5 | G20: 45534 | H20: 45534 | I20: =MAX(G20:H20) -> 45534 | J20: =+I20-D20 -> 30 | K20: =-J20-F20 -> -45.5 | N20: =H20 -> 45534
A21: =A20+1 -> 11 | B21: 45505 | C21: 45505 | D21: 45535 | E21: =D21-C21+1 -> 31 | F21: =E21/2 -> 15.5 | G21: 45565 | H21: 45565 | I21: =MAX(G21:H21) -> 45565 | J21: =+I21-D21 -> 30 | K21: =-J21-F21 -> -45.5 | N21: =H21 -> 45565
A22: =A21+1 -> 12 | B22: 45536 | C22: 45536 | D22: 45565 | E22: =D22-C22+1 -> 30 | F22: =E22/2 -> 15 | G22: 45596 | H22: 45596 | I22: =MAX(G22:H22) -> 45596 | J22: =+I22-D22 -> 31 | K22: =-J22-F22 -> -46 | N22: =H22 -> 45596
A23: =A22+1 -> 13
A24: =A23+1 -> 14 | G24: Average | K24: =ROUND(AVERAGE(K11:K22),2) -> -45.17
A25: =A24+1 -> 15
A26: =A25+1 -> 16
A27: =A26+1 -> 17 | B27: Source: | C27: Affiliate Payment Dates 12ME 9.30.24

Sheet 5
A1: 2025 RATE CASE
A2: =' '!A2 -> ONCOR ELECTRIC DELIVERY COMPANY LLC
A3: TCOS - NON-ONCOR
A4: FOR THE LEAD-LAG STUDY-PERIOD ENDING SEPTEMBER 30, 2024
A5: SPONSOR: A. THENMADATHIL
A7: Line No. | C7: Description | E7: (Lead)/Lag Days
C8: (a) | E8: (b)
A10: 1 | C10: Average service period
A11: =A10+1 -> 2 | C11: (365.25 days/12 months)/2 | E11: =ROUND(365.25/12/2,3)*-1 -> -15.219
A12: =A11+1 -> 3
A13: =A12+1 -> 4 | C13: Days from end of Service Period to Payment | E13: -35
A14: =A13+1 -> 5
A15: =A14+1 -> 6
A16: =A15+1 -> 7 | C16: Total Lead Days | E16: =ROUND(SUM(E11:E14),2) -> -50.22

Sheet 6
A1: 2025 RATE CASE
A2: =' '!A2 -> ONCOR ELECTRIC DELIVERY COMPANY LLC
A3: NON-LABOR O&M - OTHER THIRD PARTY O&M
A4: FOR THE LEAD-LAG STUDY-PERIOD ENDING SEPTEMBER 30, 2024
A5: SPONSOR: A. THENMADATHIL
A9: Line | D9: Total (Lead)/Lag | F9: Weighted
A10: No. | B10: Business Unit | C10: Amount | D10: Days | E10: Reference | F10: Dollar Days
B11: (a) | C11: (b) | D11: (c) | E11: (d) | F11: (e)
A13: 1 | B13: Transmission | C13: =+'6-1'!C17 -> 90583679 | D13: =+'6-1'!D17 -> -47.609962 | E13: WP/II-B-9/6-1 | F13: =+D13*C13 -> -4.3126855e+09
A14: =A13+1 -> 2 | B14: Distribution | C14: ='6-2'!C17 -> 7.2644002e+08 | D14: =+'6-2'!D17 -> -48.936752 | E14: WP/II-B-9/6-2 | F14: =C14*D14 -> -3.5549615e+10
A15: =A14+1 -> 3 | B15: Corporate | C15: =+'6-3'!C37 -> 1724828.1 | D15: ='6-3'!G37 -> -58.47 | E15: WP/II-B-9/6-3 | F15: =C15*D15 -> -1.008507e+08
A16: =A15+1 -> 4
A17: =A16+1 -> 5 | B17: Total | C17: =SUM(C13:C15) -> 8.1874853e+08 | D17: =ROUND(F17/C17,2) -> -48.81 | F17: =SUM(F13:F15) -> -3.9963152e+10
A18: =A17+1 -> 6
A19: =A18+1 -> 7
A20: =A19+1 -> 8 | B20: Source: | C20: Lead Lag Samples

Sheet 6-1
A1: 2025 RATE CASE
A2: =' '!A2 -> ONCOR ELECTRIC DELIVERY COMPANY LLC
A3: NON-LABOR O&M - THIRD PARTY O&M - TRANSMISSION
A4: FOR THE LEAD-LAG STUDY-PERIOD ENDING SEPTEMBER 30, 2024
A5: SPONSOR: A. THENMADATHIL
A9: Line | C9: Population | D9: (Lead)/Lag | F9: Weighted
A10: No. | B10: Strata | C10: Dollars | D10: Days | E10: Reference | F10: Dollar Days
B11: (a) | C11: (b) | D11: (c) | E11: (d) | F11: (e)
A13: 1 | B13: Item Amount < $10,000 | C13: 21612711 | D13: ='6-1-1'!G43 -> -41.62 | E13: WP/II-B-9/6-1-1 | F13: =C13*D13 -> -8.9952104e+08
A14: =A13+1 -> 2 | B14: Item Amount_>= $10,000 and <= $25,000 | C14: 13680576 | D14: ='6-1-2'!G32 -> -42.2 | E14: WP/II-B-9/6-1-2 | F14: =C14*D14 -> -5.7732032e+08
A15: =A14+1 -> 3 | B15: Item Amount > $25,000 | C15: 55290392 | D15: ='6-1-3'!G89 -> -51.29 | E15: WP/II-B-9/6-1-3 | F15: =C15*D15 -> -2.8358442e+09
A16: =A15+1 -> 4
A17: =A16+1 -> 5 | B17: Total | C17: =SUM(C13:C15) -> 90583679 | D17: =+F17/C17 -> -47.609962 | F17: =SUM(F13:F15) -> -4.3126855e+09
A18: =A17+1 -> 6
A19: =A18+1 -> 7
A20: =A19+1 -> 8
A21: =A20+1 -> 9 | B21: Source: | C21: Lead Lag Samples.xlsx

Sheet 6-1-1
A1: 2025 RATE CASE
A2: ='1-1-3-1-1'!A2 -> ONCOR ELECTRIC DELIVERY COMPANY LLC
A3: NON-LABOR O&M - THIRD PARTY O&M SAMPLE - TRANSMISSION (STRATA 1: <$10,000)
A4: FOR THE LEAD-LAG STUDY-PERIOD ENDING SEPTEMBER 30, 2024
A5: SPONSOR: A. THENMADATHIL
F7: Later of Due Date
A8: Line | D8: Begin | E8: Type of | F8: or Check Clear | G8: (Lead)/Lag | H8: Weighted Dollar
A9: No. | B9: Voucher | C9: Amount | D9: Date | E9: Begin Date | F9: Date | G9: Days | H9: Days
B10: (a) | C10: (b) | D10: (c) | E10: (d) | F10: (e) | G10: (f) | H10: (g)
A12: 1 | B12: 00660495 | C12: 57.64 | D12: 45310.5 | E12: Midpoint of Benefit Period | F12: 45334 | G12: =D12-F12 -> -23.5 | H12: =IF(ISERR(G12*C12),"",G12*C12) -> -1354.54
A13: =A12+1 -> 2 | B13: M1615722 | C13: 37.11 | D13: 45464 | E13: Midpoint of Benefit Period | F13: 45514 | G13: =D13-F13 -> -50 | H13: =IF(ISERR(G13*C13),"",G13*C13) -> -1855.5
A14: =A13+1 -> 3 | B14: 00686901 | C14: 81.19 | D14: 45517 | E14: Invoice Date | F14: 45554 | G14: =D14-F14 -> -37 | H14: =IF(ISERR(G14*C14),"",G14*C14) -> -3004.03
A15: =A14+1 -> 4 | B15: M1634300 | C15: 7473.46 | D15: 45519 | E15: Invoice Date | F15: 45549 | G15: =D15-F15 -> -30 | H15: =IF(ISERR(G15*C15),"",G15*C15) -> -224203.8
A16: =A15+1 -> 5 | B16: M1593450 | C16: 1623.75 | D16: 45468 | E16: Invoice Date | F16: 45498 | G16: =D16-F16 -> -30 | H16: =IF(ISERR(G16*C16),"",G16*C16) -> -48712.5
A17: =A16+1 -> 6 | B17: M1536247 | C17: 1484.91 | D17: 45379 | E17: Invoice Date | F17: 45411 | G17: =D17-F17 -> -32 | H17: =IF(ISERR(G17*C17),"",G17*C17) -> -47517.12
A18: =A17+1 -> 7 | B18: M1524717 | C18: 2587.2 | D18: 45357 | E18: Invoice Date | F18: 45387 | G18: =D18-F18 -> -30 | H18: =IF(ISERR(G18*C18),"",G18*C18) -> -77616
A19: =A18+1 -> 8 | B19: 00684805 | C19: 219.61 | D19: 45489 | E19: Midpoint of Benefit Period | F19: 45527 | G19: =D19-F19 -> -38 | H19: =IF(ISERR(G19*C19),"",G19*C19) -> -8345.18
A20: =A19+1 -> 9 | B20: 00674222 | C20: 65.5 | D20: 45415.5 | E20: Midpoint of Benefit Period | F20: 45434 | G20: =D20-F20 -> -18.5 | H20: =IF(ISERR(G20*C20),"",G20*C20) -> -1211.75
A21: =A20+1 -> 10 | B21: 00677265 | C21: 173.63 | D21: 45428 | E21: Midpoint of Benefit Period | F21: 45467 | G21: =D21-F21 -> -39 | H21: =IF(ISERR(G21*C21),"",G21*C21) -> -6771.57
A22: =A21+1 -> 11 | B22: 00648261 | C22: 2073.92 | D22: 45232 | E22: Midpoint of Benefit Period | F22: 45267 | G22: =D22-F22 -> -35 | H22: =IF(ISERR(G22*C22),"",G22*C22) -> -72587.2
A23: =A22+1 -> 12 | B23: M1569770 | C23: 548 | D23: 45379 | E23: Midpoint of Benefit Period | F23: 45442 | G23: =D23-F23 -> -63 | H23: =IF(ISERR(G23*C23),"",G23*C23) -> -34524
A24: =A23+1 -> 13 | B24: 00641806 | C24: 153.57 | D24: 45550.5 | E24: Midpoint of Benefit Period | F24: 45222 | G24: =D24-F24 -> 328.5 | H24: =IF(ISERR(G24*C24),"",G24*C24) -> 50447.745
... A41: =A40+1 -> 30 | B41: 00687597 | C41: 540.17 | D41: 45489 | E41: Midpoint of Benefit Period | F41: 45554 | G41: =D41-F41 -> -65 | H41: =IF(ISERR(G41*C41),"",G41*C41) -> -35111.05
A42: =A41+1 -> 31
A43: =A42+1 -> 32 | B43: Subtotal | C43: =SUM(C12:C42) -> 43754.31 | G43: =+ROUND(H43/C43,2) -> -41.62 | H43: =SUM(H12:H42) -> -1820850.9
A44: =A43+1 -> 33
A45: =A44+1 -> 34 | B45: Source: | C45: 3rd party O&M - TRN sample.xlsx

Sheet 6-1-2
A1: 2025 RATE CASE
A2: ='1-1-3-1-1'!A2 -> ONCOR ELECTRIC DELIVERY COMPANY LLC
A3: NON-LABOR O&M - THIRD PARTY O&M SAMPLE - TRANSMISSION (STRATA 2: >=$10,000 AND <=$25,000)
A4: FOR THE LEAD-LAG STUDY-PERIOD ENDING SEPTEMBER 30, 2024
A5: SPONSOR: A. THENMADATHIL
F7: Later of Due Date
A8: Line | D8: Begin | E8: Type of | F8: or Check Clear | G8: (Lead)/Lag | H8: Weighted Dollar
A9: No. | B9: Voucher | C9: Amount | D9: Date | E9: Begin Date | F9: Date | G9: Days | H9: Days
B10: (a) | C10: (b) | D10: (c) | E10: (d) | F10: (e) | G10: (f) | H10: (g)
A12: 1 | B12: M1494216 | C12: 13379 | D12: 45313 | E12: Invoice Date | F12: 45353 | G12: =D12-F12 -> -40 | H12: =IF(ISERR(G12*C12),"",G12*C12) -> -535160
A13: =A12+1 -> 2 | B13: M1470433 | C13: 12750 | D13: 45257 | E13: Midpoint of Benefit Period | F13: 45295 | G13: =D13-F13 -> -38 | H13: =IF(ISERR(G13*C13),"",G13*C13) -> -484500
A14: =A13+1 -> 3 | B14: 00681620 | C14: 24998.65 | D14: 45484.5 | E14: Midpoint of Benefit Period | F14: 45518 | G14: =D14-F14 -> -33.5 | H14: =IF(ISERR(G14*C14),"",G14*C14) -> -837454.78
A15: =A14+1 -> 4 | B15: M1468738 | C15: 13800.64 | D15: 45245.5 | E15: Midpoint of Benefit Period | F15: 45291 | G15: =D15-F15 -> -45.5 | H15: =IF(ISERR(G15*C15),"",G15*C15) -> -627929.12
A16: =A15+1 -> 5 | B16: M1613724 | C16: 17768.92 | D16: 45437.5 | E16: Midpoint of Benefit Period | F16: 45519 | G16: =D16-F16 -> -81.5 | H16: =IF(ISERR(G16*C16),"",G16*C16) -> -1448167
A17: =A16+1 -> 6 | B17: 00653111 | C17: 20301.82 | D17: 45274.5 | E17: Midpoint of Benefit Period | F17: 45301 | G17: =D17-F17 -> -26.5 | H17: =IF(ISERR(G17*C17),"",G17*C17) -> -537998.23
A18: =A17+1 -> 7 | B18: M1442179 | C18: 11742.64 | D18: 45216 | E18: Invoice Date | F18: 45246 | G18: =D18-F18 -> -30 | H18: =IF(ISERR(G18*C18),"",G18*C18) -> -352279.2
A19: =A18+1 -> 8 | B19: M1634300 | C19: 10658.07 | D19: 45519 | E19: Invoice Date | F19: 45549 | G19: =D19-F19 -> -30 | H19: =IF(ISERR(G19*C19),"",G19*C19) -> -319742.1
A20: =A19+1 -> 9 | B20: 00651339 | C20: 14289 | D20: 45266 | E20: Invoice Date | F20: 45314 | G20: =D20-F20 -> -48 | H20: =IF(ISERR(G20*C20),"",G20*C20) -> -685872
A21: =A20+1 -> 10 | B21: M1515075 | C21: 24263.8 | D21: 45322 | E21: Midpoint of Benefit Period | F21: 45360 | G21: =D21-F21 -> -38 | H21: =IF(ISERR(G21*C21),"",G21*C21) -> -922024.4
A22: =A21+1 -> 11 | B22: M1436330 | C22: 10473.72 | D22: 45201 | E22: Invoice Date | F22: 45239 | G22: =D22-F22 -> -38 | H22: =IF(ISERR(G22*C22),"",G22*C22) -> -398001.36
A23: =A22+1 -> 12 | B23: M1529360 | C23: 11730 | D23: 45307 | E23: Midpoint of Benefit Period | F23: 45373 | G23: =D23-F23 -> -66 | H23: =IF(ISERR(G23*C23),"",G23*C23) -> -774180
A24: =A23+1 -> 13 | B24: M1446368 | C24: 22060.58 | D24: 45218 | E24: Midpoint of Benefit Period | F24: 45260 | G24: =D24-F24 -> -42 | H24: =IF(ISERR(G24*C24),"",G24*C24) -> -926544.36
... A30: =A29+1 -> 19 | B30: M1434388 | C30: 17604.58 | D30: 45189 | E30: Midpoint of Benefit Period | F30: 45227 | G30: =D30-F30 -> -38 | H30: =IF(ISERR(G30*C30),"",G30*C30) -> -668974.04
A31: =A30+1 -> 20
A32: =A31+1 -> 21 | B32: Total | C32: =SUM(C12:C31) -> 310959.06 | G32: =+ROUND(H32/C32,2) -> -42.2 | H32: =SUM(H12:H31) -> -13122143
A33: =A32+1 -> 22
A34: =A33+1 -> 23 | B34: Source: | C34: 3rd party O&M - TRN sample .xlsx

Sheet 6-1-3
A1: 2025 RATE CASE
A2: ='1-1-3-1-1'!A2 -> ONCOR ELECTRIC DELIVERY COMPANY LLC
A3: NON-LABOR O&M - THIRD PARTY O&M SAMPLE - TRANSMISSION (STRATA 3: >$25,000)
A4: FOR THE LEAD-LAG STUDY-PERIOD ENDING SEPTEMBER 30, 2024
A5: SPONSOR: A. THENMADATHIL
F7: Later of Due Date
A8: Line | D8: Begin | E8: Type of | F8: or Check Clear | G8: (Lead)/Lag | H8: Weighted Dollar
A9: No. | B9: Voucher | C9: Amount | D9: Date | E9: Begin Date | F9: Date | G9: Days | H9: Days
B10: (a) | C10: (b) | D10: (c) | E10: (d) | F10: (e) | G10: (f) | H10: (g)
A12: 1 | B12: M1490389 | C12: 25038.4 | D12: 45273 | E12: Midpoint of Benefit Period | F12: 45314 | G12: =D12-F12 -> -41 | H12: =IF(ISERR(G12*C12),"",G12*C12) -> -1026574.4
A13: =+A12+1 -> 2 | B13: M1531048 | C13: 28910 | D13: 45360 | E13: Midpoint of Benefit Period | F13: 45396 | G13: =D13-F13 -> -36 | H13: =IF(ISERR(G13*C13),"",G13*C13) -> -1040760
A14: =+A13+1 -> 3 | B14: M1475240 | C14: 144571.04 | D14: 45474.5 | E14: Midpoint of Benefit Period | F14: 45335 | G14: =D14-F14 -> 139.5 | H14: =IF(ISERR(G14*C14),"",G14*C14) -> 20167660
A15: =+A14+1 -> 4 | B15: M1632118 | C15: 88400 | D15: 45490 | E15: Midpoint of Benefit Period | F15: 45530 | G15: =D15-F15 -> -40 | H15: =IF(ISERR(G15*C15),"",G15*C15) -> -3536000
A16: =+A15+1 -> 5 | B16: M1654081 | C16: 88087.85 | D16: 45539 | E16: Midpoint of Benefit Period | F16: 45572 | G16: =D16-F16 -> -33 | H16: =IF(ISERR(G16*C16),"",G16*C16) -> -2906899.1
A17: =+A16+1 -> 6 | B17: M1472905 | C17: 85934.22 | D17: 45231 | E17: Invoice Date | F17: 45280 | G17: =D17-F17 -> -49 | H17: =IF(ISERR(G17*C17),"",G17*C17) -> -4210776.8
A18: =+A17+1 -> 7 | B18: M1644341 | C18: 73000 | D18: 45436.5 | E18: removed from sample | F18: 45556 | G18: =D18-F18 -> -119.5 | H18: =IF(ISERR(G18*C18),"",G18*C18) -> -8723500
A19: =+A18+1 -> 8 | B19: 00641525 | C19: 40869.79 | D19: 45221.5 | E19: Midpoint of Benefit Period | F19: 45242 | G19: =D19-F19 -> -20.5 | H19: =IF(ISERR(G19*C19),"",G19*C19) -> -837830.7
A20: =+A19+1 -> 9 | B20: 00649379 | C20: 75000 | D20: 45259 | E20: Invoice Date | F20: 45268 | G20: =D20-F20 -> -9 | H20: =IF(ISERR(G20*C20),"",G20*C20) -> -675000
A21: =+A20+1 -> 10 | B21: 00658838 | C21: 42896.78 | D21: 45307 | E21: Midpoint of Benefit Period | F21: 45341 | G21: =D21-F21 -> -34 | H21: =IF(ISERR(G21*C21),"",G21*C21) -> -1458490.5
A22: =+A21+1 -> 11 | B22: M1478464 | C22: 198926.93 | D22: 45281 | E22: Invoice Date | F22: 45311 | G22: =D22-F22 -> -30 | H22: =IF(ISERR(G22*C22),"",G22*C22) -> -5967807.9
A23: =+A22+1 -> 12 | B23: M1614739 | C23: 37754 | D23: 45416 | E23: Midpoint of Benefit Period | F23: 45528 | G23: =D23-F23 -> -112 | H23: =IF(ISERR(G23*C23),"",G23*C23) -> -4228448
A24: =+A23+1 -> 13 | B24: M1451715 | C24: 26901.34 | D24: 45224 | E24: Midpoint of Benefit Period | F24: 45263 | G24: =D24-F24 -> -39 | H24: =IF(ISERR(G24*C24),"",G24*C24) -> -1049152.3
... A87: =+A86+1 -> 76 | B87: 00684359 | C87: 70823.32 | D87: 45508 | E87: Midpoint of Benefit Period | F87: 45517 | G87: =D87-F87 -> -9 | H87: =IF(ISERR(G87*C87),"",G87*C87) -> -637409.88
A88: =+A87+1 -> 77
A89: =+A88+1 -> 78 | B89: Subtotal | C89: =SUM(C12:C88) -> 4460898.5 | G89: =+ROUND(H89/C89,2) -> -51.29 | H89: =SUM(H12:H88) -> -2.2879577e+08
A90: =+A89+1 -> 79
A91: =+A90+1 -> 80 | B91: Source: | C91: 3rd party O&M - TRN sample.xlsx

Sheet 6-2
A1: 2025 RATE CASE
A2: =' '!A2 -> ONCOR ELECTRIC DELIVERY COMPANY LLC
A3: NON-LABOR O&M - THIRD PARTY O&M - DISTRIBUTION
A4: FOR THE LEAD-LAG STUDY-PERIOD ENDING SEPTEMBER 30, 2024
A5: SPONSOR: A. THENMADATHIL
A9: Line | C9: Population | D9: (Lead)/Lag | F9: Weighted
A10: No. | B10: Strata | C10: Dollars | D10: Days | E10: Reference | F10: Dollar Days
B11: (a) | C11: (b) | D11: (c) | E11: (d) | F11: (e)
A13: 1 | B13: Item Amount < $10,000 | C13: 1.2442204e+08 | D13: =+'6-2-1'!G45 -> -45.44 | E13: WP/II-B-9/6-2-1 | F13: =C13*D13 -> -5.6537377e+09
A14: =A13+1 -> 2 | B14: Item Amount_>= $10,000 and <= $25,000 | C14: 92127281 | D14: ='6-2-2'!G36 -> -56.63 | E14: WP/II-B-9/6-2-2 | F14: =C14*D14 -> -5.2171679e+09
A15: =A14+1 -> 3 | B15: Item Amount > $25,000 | C15: 5.098907e+08 | D15: ='6-2-3'!G143 -> -48.4 | E15: WP/II-B-9/6-2-3 | F15: =C15*D15 -> -2.467871e+10
A16: =A15+1 -> 4
A17: =A16+1 -> 5 | B17: Total | C17: =SUM(C13:C15) -> 7.2644002e+08 | D17: =+F17/C17 -> -48.936752 | F17: =SUM(F13:F15) -> -3.5549615e+10
A18: =A17+1 -> 6
A19: =A18+1 -> 7
A20: =A19+1 -> 8
A21: =A20+1 -> 9 | B21: Source: | C21: Lead Lag Sample.xlsx

Sheet 6-2-1
A1: 2025 RATE CASE
A2: ='1-1-3-1-1'!A2 -> ONCOR ELECTRIC DELIVERY COMPANY LLC
A3: NON-LABOR O&M - THIRD PARTY O&M SAMPLE - DISTRIBUTION (STRATA 1: <$10,000)
A4: FOR THE LEAD-LAG STUDY-PERIOD ENDING SEPTEMBER 30, 2024
A5: SPONSOR: A. THENMADATHIL
F7: Later of Due Date
A8: Line | D8: Begin | E8: Type of | F8: or Check Clear | G8: (Lead)/Lag | H8: Weighted Dollar
A9: No. | B9: Voucher | C9: Amount | D9: Date | E9: Begin Date | F9: Date | G9: Days | H9: Days
B10: (a) | C10: (b) | D10: (c) | E10: (d) | F10: (e) | G10: (f) | H10: (g)
A12: 1 | B12: M1569542 | C12: 40.67 | D12: 45414 | E12: Midpoint of Benefit Period | F12: 45457 | G12: =D12-F12 -> -43 | H12: =IF(ISERR(G12*C12),"",G12*C12) -> -1748.81
A13: 2 | B13: 00640508 | C13: 1732 | D13: 45189 | E13: Midpoint of Benefit Period | F13: 45239 | G13: =D13-F13 -> -50 | H13: =IF(ISERR(G13*C13),"",G13*C13) -> -86600
A14: 3 | B14: M1574543 | C14: 9118.2 | D14: 45409 | E14: Midpoint of Benefit Period | F14: 45463 | G14: =D14-F14 -> -54 | H14: =IF(ISERR(G14*C14),"",G14*C14) -> -492382.8
A15: 4 | B15: M1490747 | C15: 32.55 | D15: 45310 | E15: Invoice Date | F15: 45325 | G15: =D15-F15 -> -15 | H15: =IF(ISERR(G15*C15),"",G15*C15) -> -488.25
A16: 5 | B16: M1447965 | C16: 2.01 | D16: 45234 | E16: Invoice Date | F16: 45264 | G16: =D16-F16 -> -30 | H16: =IF(ISERR(G16*C16),"",G16*C16) -> -60.3
A17: 6 | B17: M1649606 | C17: 84.63 | D17: 45504 | E17: Midpoint of Benefit Period | F17: 45574 | G17: =D17-F17 -> -70 | H17: =IF(ISERR(G17*C17),"",G17*C17) -> -5924.1
A18: 7 | B18: M1619079 | C18: 255.43 | D18: 45418 | E18: Invoice Date | F18: 45513 | G18: =D18-F18 -> -95 | H18: =IF(ISERR(G18*C18),"",G18*C18) -> -24265.85
A19: 8 | B19: M1621645 | C19: 9096.8 | D19: 45458.5 | E19: Midpoint of Benefit Period | F19: 45532 | G19: =D19-F19 -> -73.5 | H19: =IF(ISERR(G19*C19),"",G19*C19) -> -668614.8
A20: 9 | B20: M1459434 | C20: 930.28 | D20: 45157 | E20: Invoice Date | F20: 45282 | G20: =D20-F20 -> -125 | H20: =IF(ISERR(G20*C20),"",G20*C20) -> -116285
A21: 10 | B21: M1429477 | C21: 306.07 | D21: 45206 | E21: Invoice Date | F21: 45236 | G21: =D21-F21 -> -30 | H21: =IF(ISERR(G21*C21),"",G21*C21) -> -9182.1
A22: 11 | B22: M1603287 | C22: 848.68 | D22: 45489 | E22: Invoice Date | F22: 45491 | G22: =D22-F22 -> -2 | H22: =IF(ISERR(G22*C22),"",G22*C22) -> -1697.36
A23: 12 | B23: M1414566 | C23: 1179.64 | D23: 45174 | E23: Invoice Date | F23: 45213 | G23: =D23-F23 -> -39 | H23: =IF(ISERR(G23*C23),"",G23*C23) -> -46005.96
... A43: 32 | B43: M1432060 | C43: 2565 | D43: 45195 | E43: Invoice Date | F43: 45234 | G43: =D43-F43 -> -39 | H43: =IF(ISERR(G43*C43),"",G43*C43) -> -100035
A44: 33
A45: 34 | B45: Total | C45: =SUM(C12:C44) -> 57332.19 | G45: =+ROUND(H45/C45,2) -> -45.44 | H45: =SUM(H12:H44) -> -2605063.5
A46: 35
A47: 36
A48: 37
A49: 38
A50: 39 | B50: Source: | C50: 3rd party O&M - ESD sample.xlsx

Sheet 6-2-2
A1: 2025 RATE CASE
A2: ='1-1-3-1-1'!A2 -> ONCOR ELECTRIC DELIVERY COMPANY LLC
A3: NON-LABOR O&M - THIRD PARTY O&M SAMPLE - DISTRIBUTION (STRATA 2: >=$10,000 AND <=$25,000)
A4: FOR THE LEAD-LAG STUDY-PERIOD ENDING SEPTEMBER 30, 2024
A5: SPONSOR: A. THENMADATHIL
F7: Later of Due Date
A8: Line | D8: Begin | E8: Type of | F8: or Check Clear | G8: (Lead)/Lag | H8: Weighted Dollar
A9: No. | B9: Voucher | C9: Amount | D9: Date | E9: Begin Date | F9: Date | G9: Days | H9: Days
B10: (a) | C10: (b) | D10: (c) | E10: (d) | F10: (e) | G10: (f) | H10: (g)
A12: 1 | B12: M1629327 | C12: 14508 | D12: 45501.5 | E12: Midpoint of Benefit Period | F12: 45546 | G12: =D12-F12 -> -44.5 | H12: =IF(ISERR(G12*C12),"",G12*C12) -> -645606
A13: =+A12+1 -> 2 | B13: 00650921 | C13: 14059.32 | D13: 45245.5 | E13: Midpoint of Benefit Period | F13: 45282 | G13: =D13-F13 -> -36.5 | H13: =IF(ISERR(G13*C13),"",G13*C13) -> -513165.18
A14: 3 | B14: M1537037 | C14: 12078.29 | D14: 45305 | E14: Midpoint of Benefit Period | F14: 45385 | G14: =D14-F14 -> -80 | H14: =IF(ISERR(G14*C14),"",G14*C14) -> -966263.2
A15: 4 | B15: M1613573 | C15: 10631.94 | D15: 45447 | E15: Midpoint of Benefit Period | F15: 45518 | G15: =D15-F15 -> -71 | H15: =IF(ISERR(G15*C15),"",G15*C15) -> -754867.74
A16: 5 | B16: M1597087 | C16: 12157.6 | D16: 45458 | E16: Midpoint of Benefit Period | F16: 45501 | G16: =D16-F16 -> -43 | H16: =IF(ISERR(G16*C16),"",G16*C16) -> -522776.8
A17: 6 | B17: 00653476 | C17: 14669.51 | D17: 45275 | E17: Invoice Date | F17: 45305 | G17: =D17-F17 -> -30 | H17: =IF(ISERR(G17*C17),"",G17*C17) -> -440085.3
A18: 7 | B18: M1607797 | C18: 15402.5 | D18: 45458.5 | E18: Midpoint of Benefit Period | F18: 45526 | G18: =D18-F18 -> -67.5 | H18: =IF(ISERR(G18*C18),"",G18*C18) -> -1039668.8
A19: 8 | B19: M1597781 | C19: 10908.56 | D19: 45455.5 | E19: Midpoint of Benefit Period | F19: 45512 | G19: =D19-F19 -> -56.5 | H19: =IF(ISERR(G19*C19),"",G19*C19) -> -616333.64
A20: 9 | B20: M1550804 | C20: 11609.44 | D20: 45378 | E20: Midpoint of Benefit Period | F20: 45417 | G20: =D20-F20 -> -39 | H20: =IF(ISERR(G20*C20),"",G20*C20) -> -452768.16
A21: 10 | B21: M1507747 | C21: 15129.54 | D21: 45307 | E21: Midpoint of Benefit Period | F21: 45370 | G21: =D21-F21 -> -63 | H21: =IF(ISERR(G21*C21),"",G21*C21) -> -953161.02
A22: 11 | B22: 00665903 | C22: 10620 | D22: 45307 | E22: Midpoint of Benefit Period | F22: 45371 | G22: =D22-F22 -> -64 | H22: =IF(ISERR(G22*C22),"",G22*C22) -> -679680
A23: 12 | B23: 00683506 | C23: 12500 | D23: 45489 | E23: Midpoint of Benefit Period | F23: 45511 | G23: =D23-F23 -> -22 | H23: =IF(ISERR(G23*C23),"",G23*C23) -> -275000
A24: 13 | B24: M1491151 | C24: 16230.4 | D24: 45287 | E24: Midpoint of Benefit Period | F24: 45338 | G24: =D24-F24 -> -51 | H24: =IF(ISERR(G24*C24),"",G24*C24) -> -827750.4
A25: 14 | B25: M1590982 | C25: 12333.15 | D25: 45442 | E25: Midpoint of Benefit Period | F25: 45492 | G25: =D25-F25 -> -50 | H25: =IF(ISERR(G25*C25),"",G25*C25) -> -616657.5
... A34: 23 | B34: M1574169 | C34: 10175.67 | D34: 45436 | E34: Invoice Date | F34: 45469 | G34: =D34-F34 -> -33 | H34: =IF(ISERR(G34*C34),"",G34*C34) -> -335797.11
A35: 24
A36: 25 | B36: Total | C36: =SUM(C12:C35) -> 309849.34 | G36: =+ROUND(H36/C36,2) -> -56.63 | H36: =SUM(H12:H34) -> -17547175
A37: 26
A38: 27
A39: 28
A40: 29
A41: 30 | B41: Source: | C41: 3rd party O&M - ESD sample.XLSX

Sheet 6-2-3
A1: 2025 RATE CASE
A2: ='1-1-3-1-1'!A2 -> ONCOR ELECTRIC DELIVERY COMPANY LLC
A3: NON-LABOR O&M - THIRD PARTY O&M SAMPLE - DISTRIBUTION (STRATA 3: >$25,000)
A4: FOR THE LEAD-LAG STUDY-PERIOD ENDING SEPTEMBER 30, 2024
A5: SPONSOR: A. THENMADATHIL
F7: Later of Due Date
A8: Line | D8: Begin | E8: Type of | F8: or Check Clear | G8: (Lead)/Lag | H8: Weighted Dollar
A9: No. | B9: Voucher | C9: Amount | D9: Date | E9: Begin Date | F9: Date | G9: Days | H9: Days
B10: (a) | C10: (b) | D10: (c) | E10: (d) | F10: (e) | G10: (f) | H10: (g)
A12: 1 | B12: M1527463 | C12: 125225.25 | D12: 45282.5 | E12: =IF(D12=B12,"Invoice Date", "Midpoint of Benefit Period") -> Midpoint of Benefit Period | F12: 45371 | G12: =D12-F12 -> -88.5 | H12: =IF(ISERR(G12*C12),"",G12*C12) -> -11082435
A13: 2 | B13: 00671243 | C13: 44147.81 | D13: 45392 | E13: =IF(D13=B13,"Invoice Date", "Midpoint of Benefit Period") -> Midpoint of Benefit Period | F13: 45433 | G13: =D13-F13 -> -41 | H13: =IF(ISERR(G13*C13),"",G13*C13) -> -1810060.2
A14: 3 | B14: M1631302 | C14: 69397.32 | D14: 45443 | E14: =IF(D14=B14,"Invoice Date", "Midpoint of Benefit Period") -> Midpoint of Benefit Period | F14: 45547 | G14: -8 | H14: =IF(ISERR(G14*C14),"",G14*C14) -> -555178.56
A15: 4 | B15: M1577956 | C15: 97313.1 | D15: 45336 | E15: =IF(D15=B15,"Invoice Date", "Midpoint of Benefit Period") -> Midpoint of Benefit Period | F15: 45450 | G15: =D15-F15 -> -114 | H15: =IF(ISERR(G15*C15),"",G15*C15) -> -11093693
A16: 5 | B16: M1610171 | C16: 100199.63 | D16: 45480.5 | E16: =IF(D16=B16,"Invoice Date", "Midpoint of Benefit Period") -> Midpoint of Benefit Period | F16: 45503 | G16: =D16-F16 -> -22.5 | H16: =IF(ISERR(G16*C16),"",G16*C16) -> -2254491.7
A17: 6 | B17: M1588622 | C17: 36737.86 | D17: 45397.5 | E17: =IF(D17=B17,"Invoice Date", "Midpoint of Benefit Period") -> Midpoint of Benefit Period | F17: 45469 | G17: =D17-F17 -> -71.5 | H17: =IF(ISERR(G17*C17),"",G17*C17) -> -2626757
A18: 7 | B18: M1567767 | C18: 58003.29 | D18: 45415.5 | E18: =IF(D18=B18,"Invoice Date", "Midpoint of Benefit Period") -> Midpoint of Benefit Period | F18: 45453 | G18: =D18-F18 -> -37.5 | H18: =IF(ISERR(G18*C18),"",G18*C18) -> -2175123.4
A19: 8 | B19: M1428240 | C19: 32706.59 | D19: 45120 | E19: =IF(D19=B19,"Invoice Date", "Midpoint of Benefit Period") -> Midpoint of Benefit Period | F19: 45210 | G19: =D19-F19 -> -90 | H19: =IF(ISERR(G19*C19),"",G19*C19) -> -2943593.1
A20: 9 | B20: M1428557 | C20: 26378.23 | D20: 45140 | E20: =IF(D20=B20,"Invoice Date", "Midpoint of Benefit Period") -> Midpoint of Benefit Period | F20: 45209 | G20: =D20-F20 -> -69 | H20: =IF(ISERR(G20*C20),"",G20*C20) -> -1820097.9
A21: 10 | B21: M1608283 | C21: 27426.6 | D21: 45427 | E21: =IF(D21=B21,"Invoice Date", "Midpoint of Benefit Period") -> Midpoint of Benefit Period | F21: 45499 | G21: =D21-F21 -> -72 | H21: =IF(ISERR(G21*C21),"",G21*C21) -> -1974715.2
A22: 11 | B22: M1613231 | C22: 33498.28 | D22: 45436.5 | E22: =IF(D22=B22,"Invoice Date", "Midpoint of Benefit Period") -> Midpoint of Benefit Period | F22: 45511 | G22: =D22-F22 -> -74.5 | H22: =IF(ISERR(G22*C22),"",G22*C22) -> -2495621.9
A23: 12 | B23: M1562816 | C23: 31075.78 | D23: 45410 | E23: =IF(D23=B23,"Invoice Date", "Midpoint of Benefit Period") -> Midpoint of Benefit Period | F23: 45444 | G23: =D23-F23 -> -34 | H23: =IF(ISERR(G23*C23),"",G23*C23) -> -1056576.5
A24: 13 | B24: M1437562 | C24: 54849.62 | D24: 45184.5 | E24: =IF(D24=B24,"Invoice Date", "Midpoint of Benefit Period") -> Midpoint of Benefit Period | F24: 45224 | G24: =D24-F24 -> -39.5 | H24: =IF(ISERR(G24*C24),"",G24*C24) -> -2166560
A25: 14 | B25: M1617758 | C25: 59026.42 | D25: 45436 | E25: =IF(D25=B25,"Invoice Date", "Midpoint of Benefit Period") -> Midpoint of Benefit Period | F25: 45524 | G25: =D25-F25 -> -88 | H25: =IF(ISERR(G25*C25),"",G25*C25) -> -5194325
A26: 15 | B26: M1634739 | C26: 69403.52 | D26: 45435 | E26: =IF(D26=B26,"Invoice Date", "Midpoint of Benefit Period") -> Midpoint of Benefit Period | F26: 45540 | G26: =D26-F26 -> -105 | H26: =IF(ISERR(G26*C26),"",G26*C26) -> -7287369.6
... A41: 30 | B41: M1654067 | C41: 270012 | D41: 45490 | E41: =IF(D41=B41,"Invoice Date", "Midpoint of Benefit Period") -> Midpoint of Benefit Period | F41: 45574 | G41: =D41-F41 -> -84 | H41: =IF(ISERR(G41*C41),"",G41*C41) -> -22681008
A42: 31 | B42: M1506044 | C42: 0 | D42: 0 | E42: =IF(D42=B42,"Invoice Date", "Midpoint of Benefit Period") -> Midpoint of Benefit Period | G42: =D42-F42 -> 0 | H42: =IF(ISERR(G42*C42),"",G42*C42) -> 0
A43: 32 | B43: M1630821 | C43: 62350 | D43: 45448.5 | E43: =IF(D43=B43,"Invoice Date", "Midpoint of Benefit Period") -> Midpoint of Benefit Period | F43: 45548 | G43: =D43-F43 -> -99.5 | H43: =IF(ISERR(G43*C43),"",G43*C43) -> -6203825
A44: =A43+1 -> 33 | B44: 00660121 | C44: 148426.83 | D44: 45307 | E44: =IF(D44=B44,"Invoice Date", "Midpoint of Benefit Period") -> Midpoint of Benefit Period | F44: 45352 | G44: =D44-F44 -> -45 | H44: =IF(ISERR(G44*C44),"",G44*C44) -> -6679207.3
A45: =A44+1 -> 34 | B45: M1613473 | C45: 91835 | D45: 45481.5 | E45: =IF(D45=B45,"Invoice Date", "Midpoint of Benefit Period") -> Midpoint of Benefit Period | F45: 45518 | G45: =D45-F45 -> -36.5 | H45: =IF(ISERR(G45*C45),"",G45*C45) -> -3351977.5
