Workbook
Name Account: '[1]Drill Down YTD by Dept'!#REF!
Name Account: '[1]Drill Down YTD by Dept'!#REF!
Name Account: '[1]Drill Down YTD by Dept'!#REF!
Name Account2: '[1]Drill Down YTD by Dept'!#REF!
Name Account2: '[1]Drill Down YTD by Dept'!#REF!
Name Account2: '[1]Drill Down YTD by Dept'!#REF!
Name AccountDescr: '[1]Drill Down YTD by Dept'!#REF!
Name AccountDescr: '[1]Drill Down YTD by Dept'!#REF!
Name AccountDescr: '[1]Drill Down YTD by Dept'!#REF!
Name AccountDescr2: '[1]Drill Down YTD by Dept'!#REF!
Name AccountDescr2: '[1]Drill Down YTD by Dept'!#REF!
Name AccountDescr2: '[1]Drill Down YTD by Dept'!#REF!
Name Activity: '[1]Drill Down YTD by Dept'!#REF!
Name Activity: '[1]Drill Down YTD by Dept'!#REF!
Name Activity: '[1]Drill Down YTD by Dept'!#REF!
Name Activity2: '[1]Drill Down YTD by Dept'!#REF!
Name Activity2: '[1]Drill Down YTD by Dept'!#REF!
Name Activity2: '[1]Drill Down YTD by Dept'!#REF!
Name ActivityDescr: '[1]Drill Down YTD by Dept'!#REF!
Name ActivityDescr: '[1]Drill Down YTD by Dept'!#REF!
Name ActivityDescr: '[1]Drill Down YTD by Dept'!#REF!
Name ActivityDescr2: '[1]Drill Down YTD by Dept'!#REF!
Name ActivityDescr2: '[1]Drill Down YTD by Dept'!#REF!
Name ActivityDescr2: '[1]Drill Down YTD by Dept'!#REF!
Name Affiliate: '[1]Drill Down YTD by Dept'!#REF!
Name Affiliate: '[1]Drill Down YTD by Dept'!#REF!
Name Affiliate: '[1]Drill Down YTD by Dept'!#REF!
Name Affiliate2: '[1]Drill Down YTD by Dept'!#REF!
Name Affiliate2: '[1]Drill Down YTD by Dept'!#REF!
Name Affiliate2: '[1]Drill Down YTD by Dept'!#REF!
Name AffiliateDescr: '[1]Drill Down YTD by Dept'!#REF!
Name AffiliateDescr: '[1]Drill Down YTD by Dept'!#REF!
Name AffiliateDescr: '[1]Drill Down YTD by Dept'!#REF!
Name APN: #REF!
Name APN: #REF!
Name APN: #REF!
Name ASD: #REF!
Name ASD: #REF!
Name ASD: #REF!
Name BUnPlosion: #REF!
Name Completed: #REF!
Name Completed: #REF!
Name Completed: #REF!
Name DeptDescr: '[1]Drill Down YTD by Dept'!#REF!
Name DeptDescr: '[1]Drill Down YTD by Dept'!#REF!
Name DeptDescr: '[1]Drill Down YTD by Dept'!#REF!
Name DeptDescr2: '[1]Drill Down YTD by Dept'!#REF!
Name DeptDescr2: '[1]Drill Down YTD by Dept'!#REF!
Name DeptDescr2: '[1]Drill Down YTD by Dept'!#REF!
Name DeptID: '[1]Drill Down YTD by Dept'!#REF!
Name DeptID: '[1]Drill Down YTD by Dept'!#REF!
Name DeptID: '[1]Drill Down YTD by Dept'!#REF!
Name DeptID2: '[1]Drill Down YTD by Dept'!#REF!
Name DeptID2: '[1]Drill Down YTD by Dept'!#REF!
Name DeptID2: '[1]Drill Down YTD by Dept'!#REF!
Name EC: '[1]Drill Down YTD by Dept'!#REF!
Name EC: '[1]Drill Down YTD by Dept'!#REF!
Name EC: '[1]Drill Down YTD by Dept'!#REF!
Name ECDescr: '[1]Drill Down YTD by Dept'!#REF!
Name ECDescr: '[1]Drill Down YTD by Dept'!#REF!

Sheet WP COVID-19 Sum page1
A1: Oncor Electric Delivery Company LLC | C1: WP/II-B-12 COVID-19 Incremental Costs
A2: Account 1823575-Reg Asset - COVID19 Incrmtl Exp | C2: Page 1 of 3
A3: Test Year Ending December 31, 2024
A4: Sponsor: W. Alan Ledbetter, R. Prachyl, & Coler D. Snelleman
B7: Summary
A8: Deferred COVID19-Incremental Expense (approved) | B8: ='Dkt53601 Approved Unamo page2'!P16+'Dkt53601 Approved Unamo page2'!P25+'Dkt53601 Approved Unamo page2'!P29+'Dkt53601 Approved Unamo page2'!P32+'Dkt53601 Approved Unamo page2'!P38+'Dkt53601 Approved Unamo page2'!P42+'Dkt53601 Approved Unamo page2'!P45+'Dkt53601 Approved Unamo page2'!P46 -> 34618626 | C8: Balance approved in Docket No. 53601
A9: Amortization May 1, 2023 through 12-31-2024 | B9: ='Dkt53601 Approved Unamo page2'!P48 -> -11464418 | C9: Approved amortization began May 1, 2023 effective with Docket No. 53601 base rates
A10: Approved unamortized balance at 12-31-2024 | B10: =SUM(B8:B9) -> 23154208 | C10: Reference page 2 of this workpaper
A12: Deferred COVID19-Incremental Expense (to be reviewed)
A13: Year 2022 | B13: 2322099.6 | C13: (Amount excludes corrections recorded in 2022 related to 12-31-2021 balance approved in Docket No. 53601)
A14: YTD March 31, 2023 | B14: 80329.13
A15: Balance at 12-31-2024 to be reviewed in this rate case | B15: =SUM(B13:B14) -> 2402428.7 | C15: Reference page 3 of this workpaper
A17: Account 1823575-Reg Asset - COVID19 Incrmtl Exp | B17: =B10+B15 -> 25556637 | C17: Balance @ 12-31-2024

Sheet Dkt53601 Approved Unamo page2
A1: Regulatory Asset 1823575 - Covid19 Incremental Expenses Approved in Docket No. 53601 - Unamortized Balance at December 31, 2024 Including Approved Annual Amortization | P1: ='WP COVID-19 Sum page1'!C1 -> WP/II-B-12 COVID-19 Incremental Costs
P2: Page 2 of 3
P3: Approved
A4: Incremental COVID19 Expenses Summary | D4: Approved Unamortized Balance at December 31, 2024
D5: Jan. | E5: Feb. | F5: Mar. | G5: Apr. | H5: May. | I5: Jun. | J5: Jul. | K5: Aug. | L5: Sep. | M5: Oct. | N5: Nov. | O5: Dec. | P5: Grand Total
A6: Contractor Expenses
B7: Additional Cleaning | D7: 491664.15 | E7: 567686.89 | F7: 442700.02 | G7: 940560.44 | H7: 449682.66 | I7: 645362.89 | J7: 874941.7 | K7: 927491.27 | L7: 801688.39 | M7: 861764.19 | N7: 780378.5 | O7: 1569635.6 | P7: =SUM(D7:O7) -> 9353556.7
B8: Accruals Add'l Cleaning | D8: 0 | E8: 0 | F8: 0 | G8: 0 | H8: 0 | I8: 0 | J8: 0 | K8: 0 | L8: 0 | M8: 0 | N8: 0 | O8: 0 | P8: =SUM(D8:O8) -> 0
B9: Net Additional Cleaning impact | D9: =SUM(D7:D8) -> 491664.15 | E9: =SUM(E7:E8) -> 567686.89 | F9: =SUM(F7:F8) -> 442700.02 | G9: =SUM(G7:G8) -> 940560.44 | H9: =SUM(H7:H8) -> 449682.66 | I9: =SUM(I7:I8) -> 645362.89 | J9: =SUM(J7:J8) -> 874941.7 | K9: =SUM(K7:K8) -> 927491.27 | ... O9: =SUM(O7:O8) -> 1569635.6 | P9: =SUM(D9:O9) -> 9353556.7
B10: Information Technology System Support | D10: 0 | E10: 0 | F10: 0 | G10: 29840 | H10: 0 | I10: 26980 | J10: 46790 | K10: 33360 | L10: 57865 | M10: 13612.5 | N10: 13777.5 | O10: 161080.4 | P10: =SUM(D10:O10) -> 383305.4
B11: Medical | D11: 442111.14 | E11: 285976.27 | F11: 412821.74 | G11: 1169130.2 | H11: 193530.64 | I11: 366018.12 | J11: 395623.82 | K11: 312402.01 | L11: 366082.92 | M11: 474061.75 | N11: 384640.68 | O11: 747434.21 | P11: =SUM(D11:O11) -> 5549833.5
B12: Security | D12: 368798.52 | E12: 380172.16 | F12: 432880.55 | G12: 856845.62 | H12: 123784.56 | I12: 331301.08 | J12: 331751.03 | K12: 404128.58 | L12: 330941.9 | M12: 418512.93 | N12: 325220.89 | O12: 831981.42 | P12: =SUM(D12:O12) -> 5136319.2
B13: Security & Medical | D13: 1207.88 | E13: 279.85 | F13: 386.67 | G13: 6088.39 | H13: 1931.99 | I13: 4261.69 | J13: 4240.61 | K13: 2528.29 | L13: 1356.48 | M13: 812.04 | N13: 2647.91 | O13: 1843.35 | P13: =SUM(D13:O13) -> 27585.15
B14: Temporary Augmented Staff | D14: 0 | E14: 0 | F14: 0 | G14: 0 | H14: 0 | I14: 0 | J14: 0 | K14: 0 | L14: 0 | M14: 0 | N14: 0 | O14: 0 | P14: =SUM(D14:O14) -> 0
A16: Total Contractor Expenses | D16: =SUM(D10:D15)+D9 -> 1303781.7 | E16: =SUM(E10:E15)+E9 -> 1234115.2 | F16: =SUM(F10:F15)+F9 -> 1288789 | G16: =SUM(G10:G15)+G9 -> 3002464.6 | H16: =SUM(H10:H15)+H9 -> 768929.85 | I16: =SUM(I10:I15)+I9 -> 1373923.8 | J16: =SUM(J10:J15)+J9 -> 1653347.2 | K16: =SUM(K10:K15)+K9 -> 1679910.1 | ... P16: =SUM(P10:P15)+P9 -> 20450600
A18: Employee Expenses
B19: Employee Appreciation | D19: 1665.54 | E19: 984.46 | F19: -4366.25 | G19: 0 | H19: 0 | I19: 9138.04 | J19: 251.19 | K19: 27.87 | L19: 0 | M19: 700 | N19: 0 | O19: 2690.91 | P19: =SUM(D19:O19) -> 11091.76
B20: Hotel stay for social distancing | D20: 0 | E20: 0 | F20: 0 | G20: 288.76 | H20: 0 | I20: 637.32 | J20: 0 | K20: 1217.52 | L20: 1545.6 | M20: 0 | N20: 0 | O20: 0 | P20: =SUM(D20:O20) -> 3689.2
B21: Meals | D21: 99695.1 | E21: 109461.02 | F21: 54978.63 | G21: 265113.06 | H21: 116125.37 | I21: 158969.02 | J21: 161962.39 | K21: 123003.67 | L21: 133782.36 | M21: 132446.64 | N21: 109693.66 | O21: 282917.7 | P21: =SUM(D21:O21) -> 1748148.6
B22: Mileage | D22: 13338.16 | E22: 13017.06 | F22: 16777.29 | G22: 30583.01 | H22: 10345.16 | I22: 44916.79 | J22: 43351.15 | K22: 44290.01 | L22: 38433.93 | M22: 29585.68 | N22: 27659.33 | O22: 54111.13 | P22: =SUM(D22:O22) -> 366408.7
B23: Vacation Buyback | D23: 0 | E23: 0 | F23: 0 | G23: 0 | H23: 0 | I23: 0 | J23: 0 | K23: 0 | L23: 0 | M23: 0 | N23: 0 | O23: 868896.66 | P23: =SUM(D23:O23) -> 868896.66
B24: Internal Overtime & Benefits/Taxes | D24: 0 | E24: 0 | F24: 0 | G24: 136.3 | H24: 360.17 | I24: 734.37 | J24: 260.71 | K24: 279.14 | L24: 403.58 | M24: 223.29 | N24: -2643.48 | O24: 4678.36 | P24: =SUM(D24:O24) -> 4432.44
A25: Total Employee Expenses | D25: =SUM(D19:D24) -> 114698.8 | E25: =SUM(E19:E24) -> 123462.54 | F25: =SUM(F19:F24) -> 67389.67 | G25: =SUM(G19:G24) -> 296121.13 | H25: =SUM(H19:H24) -> 126830.7 | I25: =SUM(I19:I24) -> 214395.54 | J25: =SUM(J19:J24) -> 205825.44 | K25: =SUM(K19:K24) -> 168818.21 | ... P25: =SUM(P19:P24) -> 3002667.4
A27: Material/Supplies Purchases
B28: Safety/Cleaning Supplies | D28: 35340.22 | E28: 35509.98 | F28: 9406.49 | G28: 25563.81 | H28: 104396.83 | I28: 343352.08 | J28: 427989.83 | K28: 557801.18 | L28: 171645.93 | M28: 188369.72 | N28: 256493.91 | O28: 199857.36 | P28: =SUM(D28:O28) -> 2355727.3
A29: Total Material/Supplies Purchases | D29: =SUM(D28) -> 35340.22 | E29: =SUM(E28) -> 35509.98 | F29: =SUM(F28) -> 9406.49 | G29: =SUM(G28) -> 25563.81 | H29: =SUM(H28) -> 104396.83 | I29: =SUM(I28) -> 343352.08 | J29: =SUM(J28) -> 427989.83 | K29: =SUM(K28) -> 557801.18 | ... O29: =SUM(O28) -> 199857.36 | P29: =SUM(D29:O29) -> 2355727.3
A30: Professional/Consulting Services
B31: COVID19 consulting/ discussion | D31: 10057.5 | E31: 39217 | F31: 221808.81 | G31: 6030 | H31: 19423.51 | I31: 3993.7 | J31: 50595 | K31: 231864.5 | L31: 214000 | M31: 27205 | N31: 62549.14 | O31: 54401.87 | P31: =SUM(D31:O31) -> 941146.03
A32: Total Professional/Consulting Services | D32: =D31 -> 10057.5 | E32: =E31 -> 39217 | F32: =F31 -> 221808.81 | G32: =G31 -> 6030 | H32: =H31 -> 19423.51 | I32: =I31 -> 3993.7 | J32: =J31 -> 50595 | K32: =K31 -> 231864.5 | ... O32: =O31 -> 54401.87 | P32: =SUM(D32:O32) -> 941146.03
A33: Rental/Lease Expenses
B34: Generators Rental & Supplies | D34: 24367.95 | E34: 18359.96 | F34: 27138.86 | G34: 21614.31 | H34: 26532.83 | I34: 19330.31 | J34: 11051.06 | K34: 26999.48 | L34: 26120.5 | M34: 27438.61 | N34: 16896.1 | O34: 57596.07 | P34: =SUM(D34:O34) -> 303446.04
B35: Mobile office & hand wash stations | D35: 12343.44 | E35: 6659.84 | F35: 15582.72 | G35: 22375.79 | H35: 14846.94 | I35: 9740.23 | J35: 13897.22 | K35: 15998.08 | L35: 16338.8 | M35: 23107.74 | N35: 8303.07 | O35: 25018.43 | P35: =SUM(D35:O35) -> 184212.3
B36: Rental Vehicles | D36: 447870.35 | E36: 221591.19 | F36: 974807.18 | G36: 603386.69 | H36: 617380.54 | I36: 738561.86 | J36: 497525.72 | K36: 334212.13 | L36: 363926.59 | M36: 355061.77 | N36: 770569.53 | O36: 1008824.5 | P36: =SUM(D36:O36) -> 6933718.1
B37: Wifi/Zoom/Webex /Webex Desktop Cameras | D37: 8688.41 | E37: 486.08 | F37: 1674.85 | G37: 8901.7 | H37: 10894.41 | I37: 6444.76 | J37: 4082.95 | K37: 8077.2 | L37: 40814.27 | M37: 532.72 | N37: 6989.07 | O37: 91448.1 | P37: =SUM(D37:O37) -> 189034.52
A38: Total Rental/Lease Expenses | D38: =SUM(D34:D37) -> 493270.15 | E38: =SUM(E34:E37) -> 247097.07 | F38: =SUM(F34:F37) -> 1019203.6 | G38: =SUM(G34:G37) -> 656278.49 | H38: =SUM(H34:H37) -> 669654.72 | I38: =SUM(I34:I37) -> 774077.16 | J38: =SUM(J34:J37) -> 526556.95 | K38: =SUM(K34:K37) -> 385286.89 | ... O38: =SUM(O34:O37) -> 1182887.1 | P38: =SUM(D38:O38) -> 7610411
A39: Temporary Facilities
B40: Generators Rental & Supplies | D40: 0 | E40: 0 | F40: 2393.14 | G40: 0 | H40: 0 | I40: 0 | J40: 0 | K40: 0 | L40: 0 | M40: 0 | N40: 0 | O40: 0 | P40: =SUM(D40:O40) -> 2393.14
B41: Porta-Potties | D41: 24803.78 | E41: 23293.34 | F41: 12226.11 | G41: 9660.22 | H41: 5194.31 | I41: 20750.55 | J41: 15389.5 | K41: 8951.12 | L41: 17126.08 | M41: 8422.14 | N41: 14621.7 | O41: 30276.4 | P41: =SUM(D41:O41) -> 190715.25
A42: Total Temporary Facilities | D42: =SUM(D40:D41) -> 24803.78 | E42: =SUM(E40:E41) -> 23293.34 | F42: =SUM(F40:F41) -> 14619.25 | G42: =SUM(G40:G41) -> 9660.22 | H42: =SUM(H40:H41) -> 5194.31 | I42: =SUM(I40:I41) -> 20750.55 | J42: =SUM(J40:J41) -> 15389.5 | K42: =SUM(K40:K41) -> 8951.12 | ... O42: =SUM(O40:O41) -> 30276.4 | P42: =SUM(D42:O42) -> 193108.39
A43: Temporary office furnishings
...

Sheet To be reviewed page3
A1: Regulatory Asset 1823575- Covid19 Incremental Expenses 2022 through March 31, 2023 at 12-31-2024 - To Be Reviewed Balance | P1: ='WP COVID-19 Sum page1'!C1 -> WP/II-B-12 COVID-19 Incremental Costs
P2: Page 3 of 3
P3: To Be Reviewed
A4: Incremental COVID19 Expenses Summary | D4: Covid19 Incremental Expenses Incurred 2022 through Q1 2023 - To Be Reviewed
D5: Jan. | E5: Feb. | F5: Mar. | G5: Apr. | H5: May. | I5: Jun. | J5: Jul. | K5: Aug. | L5: Sep. | M5: Oct. | N5: Nov. | O5: Dec. | P5: Grand Total
A6: Contractor Expenses
B7: Additional Cleaning | D7: 0 | E7: 220985.44 | F7: 360094.72 | G7: 193238.17 | H7: 162500.72 | I7: -3408.71 | J7: 269372.71 | K7: 196283.49 | L7: 155636.77 | M7: 162918.02 | N7: 104001.86 | O7: 206637.08 | P7: =SUM(D7:O7) -> 2028260.3
B8: Accruals Add'l Cleaning | D8: 193414.89 | E8: 10062.69 | F8: 24013.66 | G8: -101588.03 | H8: -86302.67 | I8: 50117.82 | J8: 31578.53 | K8: -66988.57 | L8: 48467.16 | M8: -81796.37 | N8: 45370.6 | O8: -129924.32 | P8: =SUM(D8:O8) -> -63574.61
B9: Net Additional Cleaning impact | D9: =SUM(D7:D8) -> 193414.89 | E9: =SUM(E7:E8) -> 231048.13 | F9: =SUM(F7:F8) -> 384108.38 | G9: =SUM(G7:G8) -> 91650.14 | H9: =SUM(H7:H8) -> 76198.05 | I9: =SUM(I7:I8) -> 46709.11 | J9: =SUM(J7:J8) -> 300951.24 | K9: =SUM(K7:K8) -> 129294.92 | ... O9: =SUM(O7:O8) -> 76712.76 | P9: =SUM(D9:O9) -> 1964685.7
B10: Information Technology System Support | D10: 0 | E10: 0 | F10: 0 | G10: 0 | H10: 4500 | I10: -43421.25 | J10: 0 | K10: 0 | L10: 0 | M10: 0 | N10: 0 | O10: 0 | P10: =SUM(D10:O10) -> -38921.25
B11: Medical | D11: 0 | E11: 0 | F11: 41125 | G11: 70290 | H11: 35340 | I11: -15365 | J11: 73705 | K11: 26900 | L11: 0 | M11: 48500 | N11: 18750 | O11: 35425 | P11: =SUM(D11:O11) -> 334670
B12: Security | D12: 0 | E12: 0 | F12: 0 | G12: 0 | H12: 0 | I12: 0 | J12: 0 | K12: 0 | L12: 0 | M12: 0 | N12: 0 | O12: 0 | P12: =SUM(D12:O12) -> 0
B13: Security & Medical | D13: 0 | E13: 0 | F13: 0 | G13: 0 | H13: 0 | I13: 0 | J13: 0 | K13: 0 | L13: 0 | M13: 0 | N13: 0 | O13: 0 | P13: =SUM(D13:O13) -> 0
B14: Temporary Augmented Staff | D14: -75449.73 | E14: 0 | F14: 41274.02 | G14: 0 | H14: 0 | I14: 0 | J14: 0 | K14: 0 | L14: 0 | M14: 0 | N14: 0 | O14: 0 | P14: =SUM(D14:O14) -> -34175.71
A16: Total Contractor Expenses | D16: =SUM(D10:D15)+D9 -> 117965.16 | E16: =SUM(E10:E15)+E9 -> 231048.13 | F16: =SUM(F10:F15)+F9 -> 466507.4 | G16: =SUM(G10:G15)+G9 -> 161940.14 | H16: =SUM(H10:H15)+H9 -> 116038.05 | I16: =SUM(I10:I15)+I9 -> -12077.14 | J16: =SUM(J10:J15)+J9 -> 374656.24 | K16: =SUM(K10:K15)+K9 -> 156194.92 | ... P16: =SUM(P10:P15)+P9 -> 2226258.7
A18: Employee Expenses
B19: Employee Appreciation | D19: 0 | E19: 0 | F19: 0 | G19: 0 | H19: 0 | I19: 0 | J19: 0 | K19: 0 | L19: 0 | M19: 0 | N19: 0 | O19: 0 | P19: =SUM(D19:O19) -> 0
B20: Hotel stay for social distancing | D20: 0 | E20: 0 | F20: 0 | G20: 0 | H20: 0 | I20: 0 | J20: 0 | K20: 0 | L20: 0 | M20: 0 | N20: 0 | O20: 0 | P20: =SUM(D20:O20) -> 0
B21: Meals | D21: 0 | E21: 0 | F21: 0 | G21: 0 | H21: 0 | I21: 0 | J21: 0 | K21: 0 | L21: 0 | M21: 0 | N21: 0 | O21: 25.77 | P21: =SUM(D21:O21) -> 25.77
B22: Mileage | D22: 0 | E22: 0 | F22: 0 | G22: 0 | H22: 0 | I22: 0 | J22: 0 | K22: 0 | L22: 0 | M22: 0 | N22: 0 | O22: 679.86 | P22: =SUM(D22:O22) -> 679.86
B23: Vacation Buyback | D23: 0 | E23: 0 | F23: 0 | G23: 0 | H23: 0 | I23: 0 | J23: 0 | K23: 0 | L23: 0 | M23: 0 | N23: 0 | O23: 0 | P23: =SUM(D23:O23) -> 0
B24: Internal Overtime & Benefits/Taxes | D24: 0 | E24: 0 | F24: 0 | G24: 0 | H24: 0 | I24: 0 | J24: 0 | K24: 0 | L24: 0 | M24: 0 | N24: 0 | O24: 0 | P24: =SUM(D24:O24) -> 0
A25: Total Employee Expenses | D25: =SUM(D19:D24) -> 0 | E25: =SUM(E19:E24) -> 0 | F25: =SUM(F19:F24) -> 0 | G25: =SUM(G19:G24) -> 0 | H25: =SUM(H19:H24) -> 0 | I25: =SUM(I19:I24) -> 0 | J25: =SUM(J19:J24) -> 0 | K25: =SUM(K19:K24) -> 0 | ... P25: =SUM(P19:P24) -> 705.63
A27: Material/Supplies Purchases | D27: 0 | E27: 0 | F27: 0 | G27: 0 | H27: 0 | I27: 0 | J27: 0 | K27: 0 | L27: 0 | M27: 0 | N27: 0 | O27: 0 | P27: =SUM(D27:O27) -> 0
B28: Safety/Cleaning Supplies | D28: 0 | E28: 6162.69 | F28: 4740.68 | G28: 243.13 | H28: 1205.4 | I28: -6054.39 | J28: 14741.83 | K28: 0 | L28: 0 | M28: 0 | N28: 0 | O28: 0 | P28: =SUM(D28:O28) -> 21039.34
A29: Total Material/Supplies Purchases | D29: =SUM(D28) -> 0 | E29: =SUM(E28) -> 6162.69 | F29: =SUM(F28) -> 4740.68 | G29: =SUM(G28) -> 243.13 | H29: =SUM(H28) -> 1205.4 | I29: =SUM(I28) -> -6054.39 | J29: =SUM(J28) -> 14741.83 | K29: =SUM(K28) -> 0 | ... O29: =SUM(O28) -> 0 | P29: =SUM(D29:O29) -> 21039.34
A30: Professional/Consulting Services | D30: 0 | E30: 0 | F30: 0 | G30: 0 | H30: 0 | I30: 0 | J30: 0 | K30: 0 | L30: 0 | M30: 0 | N30: 0 | O30: 0 | P30: =SUM(D30:O30) -> 0
B31: COVID19 consulting/ discussion | D31: 0 | E31: 72255 | F31: 0 | G31: 60701.25 | H31: 21573.75 | I31: 0 | J31: 0 | K31: 0 | L31: 0 | M31: 0 | N31: 0 | O31: 0 | P31: =SUM(D31:O31) -> 154530
A32: Total Professional/Consulting Services | D32: =D31 -> 0 | E32: =E31 -> 72255 | F32: =F31 -> 0 | G32: =G31 -> 60701.25 | H32: =H31 -> 21573.75 | I32: =I31 -> 0 | J32: =J31 -> 0 | K32: =K31 -> 0 | ... O32: =O31 -> 0 | P32: =SUM(D32:O32) -> 154530
A33: Rental/Lease Expenses
B34: Generators Rental & Supplies | D34: 0 | E34: 0 | F34: 0 | G34: 0 | H34: 0 | I34: 0 | J34: 0 | K34: 0 | L34: 0 | M34: 0 | N34: 0 | O34: -1000 | P34: =SUM(D34:O34) -> -1000
B35: Mobile office & hand wash stations | D35: 0 | E35: 0 | F35: 0 | G35: 1460.08 | H35: 0 | I35: 0 | J35: 0 | K35: 0 | L35: 0 | M35: 0 | N35: 0 | O35: 0 | P35: =SUM(D35:O35) -> 1460.08
B36: Rental Vehicles | D36: 0 | E36: 0 | F36: 0 | G36: 0 | H36: 0 | I36: 0 | J36: 0 | K36: 0 | L36: 0 | M36: 0 | N36: 0 | O36: 0 | P36: =SUM(D36:O36) -> 0
B37: Wifi/Zoom/Webex /Webex Desktop Cameras | D37: 0 | E37: 0 | F37: 0 | G37: 0 | H37: 0 | I37: 0 | J37: 0 | K37: 0 | L37: 0 | M37: 0 | N37: 0 | O37: 0 | P37: =SUM(D37:O37) -> 0
A38: Total Rental/Lease Expenses | D38: =SUM(D34:D37) -> 0 | E38: =SUM(E34:E37) -> 0 | F38: =SUM(F34:F37) -> 0 | G38: =SUM(G34:G37) -> 1460.08 | H38: =SUM(H34:H37) -> 0 | I38: =SUM(I34:I37) -> 0 | J38: =SUM(J34:J37) -> 0 | K38: =SUM(K34:K37) -> 0 | ... O38: =SUM(O34:O37) -> -1000 | P38: =SUM(D38:O38) -> 460.08
A39: Temporary Facilities
B40: Generators Rental & Supplies | D40: 0 | E40: 0 | F40: 0 | G40: 0 | H40: 0 | I40: 0 | J40: 0 | K40: 0 | L40: 0 | M40: 0 | N40: 0 | O40: 0 | P40: =SUM(D40:O40) -> 0
B41: Porta-Potties | D41: 0 | E41: 0 | F41: 0 | G41: 0 | H41: 0 | I41: 0 | J41: 0 | K41: 0 | L41: 0 | M41: 0 | N41: 0 | O41: -565.03 | P41: =SUM(D41:O41) -> -565.03
A42: Total Temporary Facilities | D42: =SUM(D40:D41) -> 0 | E42: =SUM(E40:E41) -> 0 | F42: =SUM(F40:F41) -> 0 | G42: =SUM(G40:G41) -> 0 | H42: =SUM(H40:H41) -> 0 | I42: =SUM(I40:I41) -> 0 | J42: =SUM(J40:J41) -> 0 | K42: =SUM(K40:K41) -> 0 | ... O42: =SUM(O40:O41) -> -565.03 | P42: =SUM(D42:O42) -> -565.03
A43: Temporary office furnishings
...
