Workbook
Name Load_Forecast__Economic__Weather_Year_Assumption: Index!$B$16

Sheet Index
A1: RTP Scope Section Number | B1: Input Assumption | C1: Status | D1: Date
A2: Transmission Topology
A3: 4.3 | B3: Start Cases | C3: ='Start Cases'!B2 -> Final | D3: =IF('Start Cases'!B1= "","N/A",'Start Cases'!B1) -> 45345
A4: 4.3 | B4: Recently Approved RPG Projects | C4: ='Recently Approved RPG Projects'!C2 -> Final | D4: ='Recently Approved RPG Projects'!C1 -> 45511
A5: 4.3 | B5: Model Updates/Corrections | C5: ='Model Updates & Corrections'!B2 -> Final | D5: ='Model Updates & Corrections'!B1 -> 45515
A6: 3.1.3 | B6: Transmission & Generation Outages | C6: ='Transmission & Gen Outages'!B2 -> Final | D6: =IF('Transmission & Gen Outages'!B1= "","N/A",'Transmission & Gen Outages'!B1) -> 45345
A7: Generation
A8: 3.2.1 | B8: Generation Additions, Retirements and Mothballs | C8: ='Gen Add, Ret. and Mothball'!B2 -> Final | D8: ='Gen Add, Ret. and Mothball'!B1 -> 45345
A9: 3.2.2 | B9: Renewable Generation Dispatch | C9: ='Renewable Generation Dispatch'!B2 -> Final | D9: =IF('Renewable Generation Dispatch'!B1= "","N/A",'Renewable Generation Dispatch'!B1) -> 45345
A10: 3.2.3 | B10: Switchable Generation | C10: ='Switchable Generation'!B2 -> Final | D10: =IF('Switchable Generation'!B1= "","N/A",'Switchable Generation'!B1) -> 45345
A11: 3.2.4 | B11: DC Tie Modeling and Dispatch | C11: ='DC Tie Modeling & Dispatch'!B2 -> Final | D11: =IF('DC Tie Modeling & Dispatch'!B1= "","N/A",'DC Tie Modeling & Dispatch'!B1) -> 45345
A12: 3.2.5 | B12: Reserve Requirements | C12: ='Reserve Requirement'!B2 -> Final | D12: =IF('Reserve Requirement'!B1= "","N/A",'Reserve Requirement'!B1) -> 45345
A13: 3.2.6 | B13: Fuel Price Assumptions | C13: ='Fuel Price Assumptions'!B2 -> Final | D13: =IF('Fuel Price Assumptions'!B1= "","N/A",'Fuel Price Assumptions'!B1) -> 45321
A14: 3.2.6 | B14: Emission Cost Assumptions | C14: ='Emission Cost Assumptions'!B2 -> Final | D14: =IF('Emission Cost Assumptions'!B1= "","N/A",'Emission Cost Assumptions'!B1) -> 45352
A15: Demand
A16: 3.3 | B16: Load Forecast (Economic) Weather Year Assumption | C16: ='Economic Case-Load Forecast'!B2 -> Final | D16: =IF('Economic Case-Load Forecast'!B1= "","N/A",'Economic Case-Load Forecast'!B1) -> 45418

Sheet Start Cases
A1: Date Last Updated: | B1: 45345 | C1: Back
A2: Status | B2: Final
A5: Based on 2023 RTP final summer peak reliability cases for years 2026 and 2029

Sheet Recently Approved RPG Projects
B1: Date Last Updated: | C1: 45511 | D1: Back
B2: Status | C2: Final
A5: RPG Project ID | B5: Project Name | C5: TDSP | D5: Approve Date | E5: 2026 | F5: 2029
A6: 22RPG026 | B6: =VLOOKUP(A6,'[1]2023'!$A$2:$AF$60, 10,FALSE) -> Wimberley Loop project | C6: =VLOOKUP(A6,'[1]2023'!$A$2:$AF$60, 11,FALSE) -> PEC | D6: 2023 | F6: X
A7: 22RPG042 | B7: =VLOOKUP(A7,'[1]2023'!$A$2:$AF$60, 10,FALSE) -> Carver to Maxwell 138 kV Line Rebuild Project | C7: =VLOOKUP(A7,'[1]2023'!$A$2:$AF$60, 11,FALSE) -> AEPSC | D7: 2022 | E7: X | F7: X
A8: 22RPG047 | B8: =VLOOKUP(A8,'[1]2023'!$A$2:$AF$60, 10,FALSE) -> Peck to Driver 138 kV Line Project | C8: =VLOOKUP(A8,'[1]2023'!$A$2:$AF$60, 11,FALSE) -> Oncor | D8: 2023 | E8: X | F8: X
A9: 23RPG001 | B9: =VLOOKUP(A9,'[1]2023'!$A$2:$AF$60, 10,FALSE) -> Bessel to Falfurrias 138 kV Line Rebuild Project | C9: =VLOOKUP(A9,'[1]2023'!$A$2:$AF$60, 11,FALSE) -> AEPSC | D9: 2023 | E9: X | F9: X
A10: 23RPG004 | B10: =VLOOKUP(A10,'[1]2023'!$A$2:$AF$60, 10,FALSE) -> Lockhart to Luling 69-kV Transmission Line Overhaul Project | C10: =VLOOKUP(A10,'[1]2023'!$A$2:$AF$60, 11,FALSE) -> LCRA | D10: 2023 | E10: X | F10: X
A11: 23RPG006 | B11: =VLOOKUP(A11,'[1]2023'!$A$2:$AF$60, 10,FALSE) -> North Lake 138 kV Switch Rebuild | C11: =VLOOKUP(A11,'[1]2023'!$A$2:$AF$60, 11,FALSE) -> Oncor | D11: 2023 | E11: X | F11: X
A12: 23RPG012 | B12: =VLOOKUP(A12,'[1]2023'!$A$2:$AF$60, 10,FALSE) -> Stone Lake Area Upgrades Project | C12: =VLOOKUP(A12,'[1]2023'!$A$2:$AF$60, 11,FALSE) -> CNP | D12: 2023 | E12: X | F12: X
A13: 23RPG013 | B13: =VLOOKUP(A13,'[1]2023'!$A$2:$AF$60, 10,FALSE) -> Silverleaf and Cowpen 345/138-kV Stations Project | C13: =VLOOKUP(A13,'[1]2023'!$A$2:$AF$60, 11,FALSE) -> TNMP | D13: 2023 | F13: X
A14: 23RPG015 | B14: =VLOOKUP(A14,'[1]2023'!$A$2:$AF$60, 10,FALSE) -> Cuero Substation Upgrade Project | C14: =VLOOKUP(A14,'[1]2023'!$A$2:$AF$60, 11,FALSE) -> LCRA | D14: 2023 | E14: X | F14: X
A15: 23RPG016 | B15: =VLOOKUP(A15,'[1]2023'!$A$2:$AF$60, 10,FALSE) -> Tributary Switch – Vincent Rebuild Project | C15: =VLOOKUP(A15,'[1]2023'!$A$2:$AF$60, 11,FALSE) -> ONCOR | D15: 2023 | E15: X | F15: X
A16: 23RPG018 | B16: =VLOOKUP(A16,'[1]2023'!$A$2:$AF$60, 10,FALSE) -> Arlington Reliability Enhancement Project | C16: =VLOOKUP(A16,'[1]2023'!$A$2:$AF$60, 11,FALSE) -> ONCOR | D16: 2023 | E16: X | F16: X
A17: 23RPG019 | B17: =VLOOKUP(A17,'[1]2023'!$A$2:$AF$60, 10,FALSE) -> Stanton Loop South Dynamic Reactive Power Project | C17: =VLOOKUP(A17,'[1]2023'!$A$2:$AF$60, 11,FALSE) -> ONCOR | D17: 2023 | E17: X | F17: X
A18: 23RPG021 | B18: =VLOOKUP(A18,'[1]2023'!$A$2:$AF$60, 10,FALSE) -> West Columbia to Big Creek ckt 89 Reconductor Project | C18: =VLOOKUP(A18,'[1]2023'!$A$2:$AF$60, 11,FALSE) -> CNP | D18: 2023 | E18: X | F18: X
A19: 23RPG023 | B19: =VLOOKUP(A19,'[1]2023'!$A$2:$AF$60, 10,FALSE) -> Pecos County Transmission Improvement Projet | C19: =VLOOKUP(A19,'[1]2023'!$A$2:$AF$60, 11,FALSE) -> TNMP | D19: 2024 | F19: X
A20: 23RPG026 | B20: =VLOOKUP(A20,'[1]2023'!$A$2:$AF$60, 10,FALSE) -> Synchronous Condensers Project | C20: =VLOOKUP(A20,'[1]2023'!$A$2:$AF$60, 11,FALSE) -> WETT | D20: 2023 | F20: X
A21: 23RPG027 | B21: =VLOOKUP(A21,'[1]2023'!$A$2:$AF$60, 10,FALSE) -> Bakersfield Dynamic Reactive Substation Upgrade | C21: =VLOOKUP(A21,'[1]2023'!$A$2:$AF$60, 11,FALSE) -> LCRA | D21: 2023 | F21: X
A22: 23RPG028 | B22: =VLOOKUP(A22,'[1]2023'!$A$2:$AF$60, 10,FALSE) -> Rio Medina Project | C22: =VLOOKUP(A22,'[1]2023'!$A$2:$AF$60, 11,FALSE) -> STEC | D22: 2024 | F22: X
A23: 23RPG029 | B23: =VLOOKUP(A23,'[1]2023'!$A$2:$AF$60, 10,FALSE) -> West Texas Synchronous Condenser Project | C23: =VLOOKUP(A23,'[1]2023'!$A$2:$AF$60, 11,FALSE) -> ONCOR | D23: 2023 | F23: X
A24: 23RPG034 | B24: =VLOOKUP(A24,'[1]2023'!$A$2:$AF$60, 10,FALSE) -> West Texas 345-kV Infrastructure Rebuild Project | C24: =VLOOKUP(A24,'[1]2023'!$A$2:$AF$60, 11,FALSE) -> Oncor | D24: 2024 | F24: X
A25: 23RPG032 | B25: San Antonio South Reliability II Project | C25: BEC | D25: 2024 | F25: X
A26: 24RPG002 | B26: Rockhound 345/138-kV Switch and Grey Well Draw to Buffalo 2nd 138-kV Circuit Project | C26: Oncor | D26: 2024 | E26: X | F26: X
A27: 24RPG005 | B27: Montfort Switch to Shankle Switch 138-kV Line Project | C27: Oncor | D27: 2024 | E27: X | F27: X
A28: 24RPG006 | B28: Prairieland 345/138-kV Switch and Prairieland Switch to Quartz Sand Switch/Hog Mountain Pod 138-kV Line Project | C28: Oncor | D28: 2024 | E28: X | F28: X
A29: 24RPG009 | B29: Sonora to Uvalde to Campwood to Bandera Area Transmission Project | C29: AEPSC, LCRA, BEC | D29: 2024 | F29: X
A30: 24RPG003 | B30: Eastside 345/138-kV Switching Station Project | C30: CPS | D30: 2024 | F30: X
A31: 24RPG004 | B31: Omicron Reliability Project | C31: CPS | D31: 2024 | F31: X
A32: 23RPG032 | B32: San Antonio South Reliability II Project | C32: BEC | D32: 2024 | F32: X

Sheet Model Updates & Corrections
A1: Date Last Updated: | B1: 45515 | C1: Back
A2: Status | B2: Final
A5: Model Corrections/Updates Made to the 2022 RTP Cases
A6: Transmission Changes | B6: TO | C6: 2026 | D6: 2029 | E6: Comments
A8: Added the Tier 4 Project that adds bus Hog Mountain 138 kV POD | B8: Oncor | C8: X | D8: X | E8: TPIT Project 76686 (Tier 4)
A9: Backed out RTP placeholder project 2023-NC6 Telico Area Upgrades | B9: Oncor | C9: X | D9: X | E9: Replaced by RPG-approved Montfort Switch to Shankle Switch 138-kV Line Tier 3 Project (24RPG005)
A10: Added missing P7 contingencies associated with ERCOT RPG approved LRGV project Option 2 | B10: AEP/STEC | D10: X | E10: P7 contingencies missing in SSWG contingency database
A11: Updated Elmaton POI reconfiguration | B11: CNP | C11: X | D11: X | E11: Based on CNP's feedback
A12: Updated P7 contingency definitions for King - Rothwood 345-kV circuits 74 and 75 to include split bus configuration | B12: CNP | C12: X | D12: X | E12: Based on CNP's feedback
A13: Added missing Teal - Limmer second 345-kV circuit and associated contingencies of RPG-approved Tier 3 project 'East Hutto Area 345/138 kV Project (22RPG027) | B13: Oncor/LCRA | C13: X | D13: X | E13: The second circuit was not added during the 2023 RTP case conditioning process
A14: Updated DLRs for Pawnee (5725) - Spruce (5400) and Pawnee (5725) - Tango (8689) 345-kV lines based on TSP input | B14: CPS | C14: X | E14: Based on CPS's feedback to ERCOT Operations
A15: Updated line ratings for Big Hill (76003) - Bakersfield (76002) 345-kV double circuit | B15: STEC | C15: X | D15: X | E15: Based on comments from STEC
A16: Updated ratings on Howard (5231) - Miguel (5901) 345-kV line based on latest submission in MOD | B16: CPS/STEC | D16: X | E16: MOD Project 75255 (Tier 1)
A30: Generation Changes | B30: TO | C30: 2026 | D30: 2029 | E30: Comments
A32: Changed POI for Maleza Solar (21INR0220) to JULIA__POI_5 (44220) | B32: CNP | C32: X | D32: X | E32: Based on latest information in RIOO as of 2/1/2024
A33: Updated capacity of Roadrunner Crossing Wind I (19INR0117) TO 126.9 MW | B33: LST | C33: X | D33: X | E33: Based on latest information in RIOO as of 2/1/2024
A34: Updated unit size for Gulf Star Solar (23INR0111) to 451.63 MW | B34: CNP | C34: X | D34: X | E34: Based on latest information in RIOO as of 2/1/2024
A35: Updated unit size for Padua Grid BESS (22INR0368) to 51.1 MW | B35: CPS | C35: X | D35: X | E35: Based on latest information in RIOO as of 2/1/2024
A38: Phase Shifters | B38: TO | C38: 2026 | D38: 2029 | E38: Comments

Sheet Transmission & Gen Outages
A1: Date Last Updated: | B1: 45345 | C1: Back
A2: Status | B2: Final
A5: Outaged Element | B5: Associated TO/RE | C5: 2026 | D5: 2029 | E5: Notes
A6: Spencer Unit 4 | B6: City of Garland | C6: X | D6: X | E6: NSO posted
A7: Spencer Unit 5 | B7: City of Garland | C7: X | D7: X | E7: NSO posted
A8: Powerlane Plant STG 1 | B8: GEUS | C8: X | D8: X | E8: NSO posted
A9: CHISHOLM GRID BAT | B9: Chisholm Grid, LLC/Able Grid | C9: X | E9: NSO posted
A11: Automated maintenance schedules modeled by UPLAN

Sheet Gen Add, Ret. and Mothball
A1: Date Last Updated: | B1: 45345 | C1: Back
A2: Status | B2: Final
A3: 6.9(1) conditions met as of: | B3: 45511
A6: New generators that met PG 6.9(1) requirements
A7: GINR Reference Number | B7: Project Name | C7: County | D7: Projected Date | E7: Fuel | F7: MW For Grid | G7: Changes From Last Report | H7: Meets Section 6.9 Requirements (1)(b) through (1)(d) | I7: 2026 | J7: 2029 | K7: Comments
A8: 21INR0505 | B8: Ramsey Storage | C8: Wharton | D8: 46022 | E8: Other | F8: 510.4 | H8: 45156 | I8: X | J8: X
A9: 22INR0267 | B9: Shaula II Solar | C9: DeWitt | D9: 46172 | E9: Solar | F9: 205.2 | H9: 45012 | I9: X | J9: X
A10: 23INR0555 | B10: Farmersville West BESS 1 | C10: Collin | D10: 45391 | E10: Other | F10: 9.9 | H10: 45203 | I10: X | J10: X
A11: 22INR0251 | B11: Shaula I Solar | C11: DeWitt | D11: 45960 | E11: Solar | F11: 205.2 | H11: 45012 | I11: X | J11: X
A12: 23INR0507 | B12: Bay City BESS | C12: Matagorda | D12: 45233 | E12: Other | F12: 9.99 | H12: 45049 | I12: X | J12: X
A13: 23INR0483 | B13: Rio Nogales CT1 Rotor Replacement | C13: Guadalupe | D13: 45085 | E13: Gas | F13: 3.1 | H13: 45212 | I13: X | J13: X
A14: 20INR0208 | B14: Signal Solar | C14: Hunt | D14: 45731 | E14: Solar | F14: 51.79 | H14: 45089 | I14: X | J14: X
A15: 23INR0367 | B15: Fewell Solar | C15: Limestone | D15: 45909 | E15: Solar | F15: 203.5 | H15: 45166 | I15: X | J15: X
A16: 23INR0554 | B16: Hamilton BESS | C16: Val Verde | D16: 45404 | E16: Other | F16: 9.95 | H16: 45049 | I16: X | J16: X
A17: 21INR0012 | B17: Air Products GCA | C17: Galveston | D17: 45359 | E17: Gas | F17: 60 | H17: 44998 | I17: X | J17: X
A18: 22INR0260 | B18: Eliza Storage | C18: Kaufman | D18: 45597 | E18: Other | F18: 100.2 | H18: 44974 | I18: X | J18: X
A19: 24INR0070 | B19: Sypert Branch Solar Project | C19: Milam | D19: 45809 | E19: Solar | F19: 261.78 | H19: 45217 | I19: X | J19: X
... A25: 22INR0422 | B25: Ferdinand Grid BESS | C25: Bexar | D25: 46173 | E25: Other | F25: 202.65 | H25: 45156 | I25: X | J25: X
A26: 23INR0030 | B26: Langer Solar | C26: Bosque | D26: 46447 | E26: Solar | F26: 249.8 | H26: 45296 | J26: X
A27: 23INR0543 | B27: Continental BESS | C27: Starr | D27: 45380 | E27: Other | F27: 9.8 | H27: 45082 | I27: X | J27: X
A28: 23INR0514 | B28: North Mercedes BESS | C28: Hidalgo | D28: 45271 | E28: Other | F28: 9.99 | H28: 45078 | I28: X | J28: X
A29: 21INR0511 | B29: Wolf Ridge Repower | C29: Cooke | D29: 45384 | E29: Wind | F29: 121.5 | H29: 45016 | I29: X | J29: X
A30: 23INR0508 | B30: Los Fresnos BESS | C30: Cameron | D30: 45268 | E30: Other | F30: 9.99 | H30: 44981 | I30: X | J30: X
A31: 22INR0502 | B31: Shamrock | C31: Crockett | D31: 45401 | E31: Wind | F31: 223.92 | H31: 45044 | I31: X | J31: X
A32: 24INR0010 | B32: Pinnington Solar | C32: Jack | D32: 45945 | E32: Solar | F32: 666.1 | H32: 45245 | I32: X | J32: X
A33: 24INR0436 | B33: Carambola BESS | C33: Hidalgo | D33: 46173 | E33: Other | F33: 97.43 | H33: 45146 | I33: X | J33: X
A34: 23INR0219 | B34: Dogfish BESS | C34: Pecos | D34: 45657 | E34: Other | F34: 75 | H34: 45139 | I34: X | J34: X
A35: 21INR0515 | B35: Roadrunner Crossing Wind II SLF | C35: Eastland | D35: 45677 | E35: Wind | F35: 126.72 | H35: 45047 | I35: X | J35: X
A36: 25INR0223 | B36: Uhland Maxwell | C36: Caldwell | D36: 45762 | E36: Gas | F36: 188.4 | H36: 45174 | I36: X | J36: X
A37: 23INR0556 | B37: IEP Orchard BESS | C37: Fort Bend | D37: 45510 | E37: Other | F37: 9.99 | H37: 45295 | I37: X | J37: X
A38: 24INR0273 | B38: Al Pastor BESS | C38: Dawson | D38: 45520 | E38: Other | F38: 103.1 | H38: 45231 | I38: X | J38: X
... A117: 23INR0044 | B117: Parliament Solar | C117: Waller | D117: 45657 | E117: Solar | F117: 484.56 | H117: 45315 | I117: X | J117: X
A123: PG 6.9(1) Inactive Projects
A124: INR | B124: Project Name | C124: Fuel | D124: County | E124: Inactive Date | F124: MW
A125: 19INR0099a | B125: Kontiki 1 Wind (ERIK) | C125: WIND | D125: Glasscock | E125: 44630 | F125: 255.3
A126: 19INR0099b | B126: Kontiki 2 Wind (ERNEST) | C126: WIND | D126: Glasscock | E126: 44630 | F126: 255.3
A127: 17INR0022 | B127: MIRAGE | C127: GAS | D127: Harris | E127: 45077.478 | F127: 11
A130: PG 6.9(1) Cancelled Projects
A131: INR | B131: Project Name | C131: Fuel | D131: County | E131: Inactive Date | F131: MW
A132: 23INR0042 | B132: Delilah Solar 3 | C132: SOLAR | D132: Lamar | E132: 45077 | F132: 204.1
...

Sheet Renewable Generation Dispatch
A1: Date Last Updated: | B1: 45345 | C1: Back
A2: Status | B2: Final
A5: Solar
A6: http://www.ercot.com/gridinfo/resource
A7: Weather years used for analysis:
A8: Base | B8: 2013
A11: Wind
A12: http://www.ercot.com/gridinfo/resource
A13: Weather years used for analysis:
A14: Base | B14: 2013
A16: Hydro
A17: Unit specific monthly capacity factors modeled based on historical dispatch levels during the last three years.

Sheet Switchable Generation
A1: Date Last Updated: | B1: 45345 | C1: Back
A2: Status | B2: Final
A5: Operational Resources (Switchable)
A7: Unavailable to ERCOT during summer 6/1-9/30
A9: UNIT NAME | B9: UNIT CODE | C9: COUNTY | D9: FUEL | E9: ZONE | F9: IN SERVICE | G9: 2026 | H9: 2029
A10: ANTELOPE IC 1 | B10: ANTLP_G1 | C10: HALE | D10: GAS | E10: WEST | F10: 2016 | G10: 54 | H10: 54
A11: ANTELOPE IC 2 | B11: ANTLP_G2 | C11: HALE | D11: GAS | E11: WEST | F11: 2016 | G11: 54 | H11: 54
A12: ANTELOPE IC 3 | B12: ANTLP_G3 | C12: HALE | D12: GAS | E12: WEST | F12: 2016 | G12: 54 | H12: 54
A13: ELK STATION CTG 1 | B13: AEEC_ELK_1 | C13: HALE | D13: GAS | E13: WEST | F13: 2016 | G13: 190 | H13: 190
A14: ELK STATION CTG 2 | B14: AEEC_ELK_2 | C14: HALE | D14: GAS | E14: WEST | F14: 2016 | G14: 190 | H14: 190
A15: TENASKA KIAMICHI STATION 2CT101 | B15: KMCHI_2CT101 | C15: FANNIN | D15: GAS-CC | E15: NORTH | F15: 2003 | G15: 185 | H15: -
A16: TENASKA KIAMICHI STATION 2CT201 | B16: KMCHI_2CT201 | C16: FANNIN | D16: GAS-CC | E16: NORTH | F16: 2003 | G16: 185 | H16: -
A17: TENASKA KIAMICHI STATION 2ST | B17: KMCHI_2ST | C17: FANNIN | D17: GAS-CC | E17: NORTH | F17: 2003 | G17: 330 | H17: -
A19: Switchable Capacity Unavailable to ERCOT | B19: SWITCH_UNAVAIL | D19: GAS | G19: =SUM(G10:G17) -> 1242 | H19: =SUM(H10:H17) -> 542
A21: Unavailable to ERCOT during winter 12/1-2/28
A23: UNIT NAME | B23: UNIT CODE | C23: COUNTY | D23: FUEL | E23: ZONE | F23: IN SERVICE | G23: 2025/2026 | H23: 2027/2028
A24: TENASKA KIAMICHI STATION 2CT101 | B24: KMCHI_2CT101 | C24: FANNIN | D24: GAS-CC | E24: NORTH | F24: 2003 | G24: 185 | H24: -
A26: Switchable Capacity Unavailable to ERCOT | B26: SWITCH_UNAVAIL | D26: GAS | G26: =G24 -> 185 | H26: -

Sheet DC Tie Modeling & Dispatch
A1: Date Last Updated: | B1: 45345 | C1: Back
A2: Status | B2: Final
A5: Economic Analysis
A6: DC Tie Dispatch - 8760-hour Assumptions
A7: DC_E | B7: Import + Export | C7: Mapped to hourly generation and demand profiles based on historical operational data.
A8: DC_N | B8: Import + Export | C8: Mapped to hourly generation and demand profiles based on historical operational data.
A9: DC_L | B9: Import + Export | C9: Mapped to hourly generation and demand profiles based on historical operational data.
A10: DC_R | B10: Import + Export | C10: Mapped to hourly generation and demand profiles based on historical operational data.

Sheet Reserve Requirement
A1: Date Last Updated: | B1: 45345 | C1: Back
A2: Status | B2: Final
A5: Economic Analysis | B5: 1599
A6: The reserve requirement used in the economic models are based on a review of ERCOT’s 2024 Responsive Reserve and Regulation Up requirements. Note that the MW contribution of load resources is not an input into the economic model.

Sheet Fuel Price Assumptions
A1: Date Last Updated: | B1: 45321 | C1: Back
A2: Status | B2: Final
A3: Source | B3: EIA 2023 AEO Reference Case
A6: Year | B6: Jan | C6: Feb | D6: Mar | E6: Apr | F6: May | G6: Jun | H6: Jul | I6: Aug | J6: Sep | K6: Oct | L6: Nov | M6: Dec | N6: Average
A7: 2024 | B7: =HLOOKUP($A7,'[2]Source Data'!$C$11:$J$14,2)*'[2]Source Data'!B$6 -> 4.5573335 | C7: =HLOOKUP($A7,'[2]Source Data'!$C$11:$J$14,2)*'[2]Source Data'!C$6 -> 4.3328086 | D7: =HLOOKUP($A7,'[2]Source Data'!$C$11:$J$14,2)*'[2]Source Data'!D$6 -> 4.0585658 | E7: =HLOOKUP($A7,'[2]Source Data'!$C$11:$J$14,2)*'[2]Source Data'!E$6 -> 4.1635823 | F7: =HLOOKUP($A7,'[2]Source Data'!$C$11:$J$14,2)*'[2]Source Data'!F$6 -> 4.2715217 | G7: =HLOOKUP($A7,'[2]Source Data'!$C$11:$J$14,2)*'[2]Source Data'!G$6 -> 4.342856 | H7: =HLOOKUP($A7,'[2]Source Data'!$C$11:$J$14,2)*'[2]Source Data'!H$6 -> 4.2426219 | I7: =HLOOKUP($A7,'[2]Source Data'!$C$11:$J$14,2)*'[2]Source Data'!I$6 -> 4.3035181 | ... M7: =HLOOKUP($A7,'[2]Source Data'!$C$11:$J$14,2)*'[2]Source Data'!M$6 -> 4.6405693 | N7: =AVERAGE(B7:M7) -> 4.344237
A8: 2025 | B8: =HLOOKUP($A8,'[2]Source Data'!$C$11:$J$14,2)*'[2]Source Data'!B$6 -> 3.9899733 | C8: =HLOOKUP($A8,'[2]Source Data'!$C$11:$J$14,2)*'[2]Source Data'!C$6 -> 3.7934004 | D8: =HLOOKUP($A8,'[2]Source Data'!$C$11:$J$14,2)*'[2]Source Data'!D$6 -> 3.5532991 | E8: =HLOOKUP($A8,'[2]Source Data'!$C$11:$J$14,2)*'[2]Source Data'!E$6 -> 3.6452417 | F8: =HLOOKUP($A8,'[2]Source Data'!$C$11:$J$14,2)*'[2]Source Data'!F$6 -> 3.7397433 | G8: =HLOOKUP($A8,'[2]Source Data'!$C$11:$J$14,2)*'[2]Source Data'!G$6 -> 3.8021969 | H8: =HLOOKUP($A8,'[2]Source Data'!$C$11:$J$14,2)*'[2]Source Data'!H$6 -> 3.7144414 | I8: =HLOOKUP($A8,'[2]Source Data'!$C$11:$J$14,2)*'[2]Source Data'!I$6 -> 3.7677563 | ... M8: =HLOOKUP($A8,'[2]Source Data'!$C$11:$J$14,2)*'[2]Source Data'!M$6 -> 4.0628468 | N8: =AVERAGE(B8:M8) -> 3.803406
A9: 2026 | B9: =HLOOKUP($A9,'[2]Source Data'!$C$11:$J$14,2)*'[2]Source Data'!B$6 -> 3.5798923 | C9: =HLOOKUP($A9,'[2]Source Data'!$C$11:$J$14,2)*'[2]Source Data'!C$6 -> 3.4035227 | D9: =HLOOKUP($A9,'[2]Source Data'!$C$11:$J$14,2)*'[2]Source Data'!D$6 -> 3.1880986 | E9: =HLOOKUP($A9,'[2]Source Data'!$C$11:$J$14,2)*'[2]Source Data'!E$6 -> 3.2705915 | F9: =HLOOKUP($A9,'[2]Source Data'!$C$11:$J$14,2)*'[2]Source Data'!F$6 -> 3.3553804 | G9: =HLOOKUP($A9,'[2]Source Data'!$C$11:$J$14,2)*'[2]Source Data'!G$6 -> 3.4114152 | H9: =HLOOKUP($A9,'[2]Source Data'!$C$11:$J$14,2)*'[2]Source Data'!H$6 -> 3.332679 | I9: =HLOOKUP($A9,'[2]Source Data'!$C$11:$J$14,2)*'[2]Source Data'!I$6 -> 3.3805143 | ... M9: =HLOOKUP($A9,'[2]Source Data'!$C$11:$J$14,2)*'[2]Source Data'!M$6 -> 3.645276 | N9: =AVERAGE(B9:M9) -> 3.4125
A10: 2027 | B10: =HLOOKUP($A10,'[2]Source Data'!$C$11:$J$14,2)*'[2]Source Data'!B$6 -> 3.4036986 | C10: =HLOOKUP($A10,'[2]Source Data'!$C$11:$J$14,2)*'[2]Source Data'!C$6 -> 3.2360096 | D10: =HLOOKUP($A10,'[2]Source Data'!$C$11:$J$14,2)*'[2]Source Data'!D$6 -> 3.0311881 | E10: =HLOOKUP($A10,'[2]Source Data'!$C$11:$J$14,2)*'[2]Source Data'!E$6 -> 3.1096209 | F10: =HLOOKUP($A10,'[2]Source Data'!$C$11:$J$14,2)*'[2]Source Data'!F$6 -> 3.1902367 | G10: =HLOOKUP($A10,'[2]Source Data'!$C$11:$J$14,2)*'[2]Source Data'!G$6 -> 3.2435136 | H10: =HLOOKUP($A10,'[2]Source Data'!$C$11:$J$14,2)*'[2]Source Data'!H$6 -> 3.1686526 | I10: =HLOOKUP($A10,'[2]Source Data'!$C$11:$J$14,2)*'[2]Source Data'!I$6 -> 3.2141336 | ... M10: =HLOOKUP($A10,'[2]Source Data'!$C$11:$J$14,2)*'[2]Source Data'!M$6 -> 3.4658643 | N10: =AVERAGE(B10:M10) -> 3.244545
A11: 2028 | B11: =HLOOKUP($A11,'[2]Source Data'!$C$11:$J$14,2)*'[2]Source Data'!B$6 -> 3.4125212 | C11: =HLOOKUP($A11,'[2]Source Data'!$C$11:$J$14,2)*'[2]Source Data'!C$6 -> 3.2443974 | D11: =HLOOKUP($A11,'[2]Source Data'!$C$11:$J$14,2)*'[2]Source Data'!D$6 -> 3.0390451 | E11: =HLOOKUP($A11,'[2]Source Data'!$C$11:$J$14,2)*'[2]Source Data'!E$6 -> 3.1176812 | F11: =HLOOKUP($A11,'[2]Source Data'!$C$11:$J$14,2)*'[2]Source Data'!F$6 -> 3.1985059 | G11: =HLOOKUP($A11,'[2]Source Data'!$C$11:$J$14,2)*'[2]Source Data'!G$6 -> 3.2519209 | H11: =HLOOKUP($A11,'[2]Source Data'!$C$11:$J$14,2)*'[2]Source Data'!H$6 -> 3.1768658 | I11: =HLOOKUP($A11,'[2]Source Data'!$C$11:$J$14,2)*'[2]Source Data'!I$6 -> 3.2224648 | ... M11: =HLOOKUP($A11,'[2]Source Data'!$C$11:$J$14,2)*'[2]Source Data'!M$6 -> 3.474848 | N11: =AVERAGE(B11:M11) -> 3.252955
A12: 2029 | B12: =HLOOKUP($A12,'[2]Source Data'!$C$11:$J$14,2)*'[2]Source Data'!B$6 -> 3.5187409 | C12: =HLOOKUP($A12,'[2]Source Data'!$C$11:$J$14,2)*'[2]Source Data'!C$6 -> 3.3453841 | D12: =HLOOKUP($A12,'[2]Source Data'!$C$11:$J$14,2)*'[2]Source Data'!D$6 -> 3.1336398 | E12: =HLOOKUP($A12,'[2]Source Data'!$C$11:$J$14,2)*'[2]Source Data'!E$6 -> 3.2147236 | F12: =HLOOKUP($A12,'[2]Source Data'!$C$11:$J$14,2)*'[2]Source Data'!F$6 -> 3.2980641 | G12: =HLOOKUP($A12,'[2]Source Data'!$C$11:$J$14,2)*'[2]Source Data'!G$6 -> 3.3531417 | H12: =HLOOKUP($A12,'[2]Source Data'!$C$11:$J$14,2)*'[2]Source Data'!H$6 -> 3.2757504 | I12: =HLOOKUP($A12,'[2]Source Data'!$C$11:$J$14,2)*'[2]Source Data'!I$6 -> 3.3227687 | ... M12: =HLOOKUP($A12,'[2]Source Data'!$C$11:$J$14,2)*'[2]Source Data'!M$6 -> 3.5830077 | N12: =AVERAGE(B12:M12) -> 3.354208

Sheet Emission Cost Assumptions
A1: Date Last Updated: | B1: 45352 | C1: Back
A2: Status | B2: Final
A3: Source | B3: EIA AEO
A6: Emission | B6: $/ton
A7: Nox (Seasonal) | B7: 166
A8: SO2 | B8: 0
A9: CO2 | B9: 0

Sheet Economic Case-Load Forecast
A1: Date Last Updated: | B1: 45418 | C1: Back
A2: Status | B2: Final
A5: Load forecast (economic)
A6: Weather year assumption | B6: Base: 2013
A7: The peak and hourly profile information will be posted along with the case information
A9: Note that the 2013 weather scenario is the base weather scenario used as the starting point in the economic analysis.
