Workbook
Name AFT_DIST: 'II-I-Total'!#REF!
Name Assign_Tbl: #REF!
Name Assign_Tbl_2016: #REF!
Name DA: #REF!
Name DA_0222: #REF!
Name DA_2: #REF!
Name FactorTable: 'II-I-MET'!$G$1354:$T$1448
Name FactorTable: 'II-I-TBILLTDCS'!$G$1354:$T$1448
Name FactorTable: 'II-I-Total'!#REF!
Name FactorTable: 'II-I-DIST'!$G$1354:$T$1448
Name FFT_D: 'II-I-DIST'!$B$1042:$L$1195
Name x: 'II-I-TBILLTDCS'!$G$1354:$T$1448
Name xx: #REF!

Sheet LinkSheet
D4: Description | F4: Total | G4: Residential | H4: Secondary | I4: Secondary | J4: Primary DL | K4: Primary DL | L4: Primary | M4: Transmission | N4: Lighting | O4: Wholesale | P4: Wholesale
H5: <=10kW | I5: >10kW | J5: <=10kW | K5: >10kW | L5: Substation | O5: Substation | P5: DLS
D8: DIST Function Revenue ex 565 & A928 | F8: =SUM(G8:P8) -> 3.4592512e+09 | G8: ='WP II-I-1.7'!E23 -> 1.808863e+09 | H8: ='WP II-I-1.7'!F23 -> 51193085 | I8: ='WP II-I-1.7'!G23 -> 1.2075801e+09 | J8: ='WP II-I-1.7'!H23 -> 533883.98 | K8: ='WP II-I-1.7'!I23 -> 2.3514573e+08 | L8: ='WP II-I-1.7'!J23 -> 26160818 | M8: ='WP II-I-1.7'!K23 -> 26746602 | N8: ='WP II-I-1.7'!L23 -> 92687433 | ... P8: ='WP II-I-1.7'!N23 -> 8506147.8 | S8: =IF(ROUND(F45+F46+F8-'WP II-I-1.1'!G489,1)=0,TRUE,F45+F46+F8-'WP II-I-1.1'!G489) -> TRUE
D10: MET Function Revenue Req | F10: =SUM(G10:P10) -> 2.0524261e+08 | G10: ='WP II-I-1.7'!E25 -> 1.0712837e+08 | H10: ='WP II-I-1.7'!F25 -> 15024827 | I10: ='WP II-I-1.7'!G25 -> 59094145 | J10: ='WP II-I-1.7'!H25 -> 2487758.3 | K10: ='WP II-I-1.7'!I25 -> 19159478 | L10: ='WP II-I-1.7'!J25 -> 628890.65 | M10: ='WP II-I-1.7'!K25 -> 1312242.3 | N10: ='WP II-I-1.7'!L25 -> 144408.86 | ... P10: ='WP II-I-1.7'!N25 -> 188303.24 | S10: =IF(ROUND(F10-'WP II-I-1.1'!H489,1)=0,TRUE,F10-'WP II-I-1.1'!H489) -> TRUE
D12: CUSTOMER Function Revenue Req | F12: =SUM(G12:P12) -> 1.2166435e+08 | G12: ='WP II-I-1.7'!E27 -> 61413320 | H12: ='WP II-I-1.7'!F27 -> 8072044.4 | I12: ='WP II-I-1.7'!G27 -> 33901631 | J12: ='WP II-I-1.7'!H27 -> 1296712.2 | K12: ='WP II-I-1.7'!I27 -> 10639950 | L12: ='WP II-I-1.7'!J27 -> 465386.72 | M12: ='WP II-I-1.7'!K27 -> 1055899.5 | N12: ='WP II-I-1.7'!L27 -> 4692562 | ... P12: ='WP II-I-1.7'!N27 -> 90978.282 | S12: =IF(ROUND(F12-'WP II-I-1.1'!I489,1)=0,TRUE,F12-'WP II-I-1.1'!I489) -> TRUE
D14: DIST+MET+CUST:
D15: Total Plant: Gross | F15: =SUM(G15:P15) -> 2.1831887e+10 | G15: ='II-I-Total'!J60 -> 1.1697829e+10 | H15: ='II-I-Total'!K60 -> 4.4820417e+08 | I15: ='II-I-Total'!L60 -> 7.3425889e+09 | J15: ='II-I-Total'!M60 -> 17112245 | K15: ='II-I-Total'!N60 -> 1.3861023e+09 | L15: ='II-I-Total'!O60 -> 1.4192862e+08 | M15: ='II-I-Total'!P60 -> 31880329 | N15: ='II-I-Total'!Q60 -> 7.0647831e+08 | ... P15: ='II-I-Total'!S60 -> 49795240
D16: Return on Rate Base (cost-based) | F16: =SUM(G16:P16) -> 1.0591573e+09 | G16: ='II-I-Total'!J83 -> 5.7528199e+08 | H16: ='II-I-Total'!K83 -> 18004272 | I16: ='II-I-Total'!L83 -> 3.6570944e+08 | J16: ='II-I-Total'!M83 -> 698376.14 | K16: ='II-I-Total'!N83 -> 71151671 | L16: ='II-I-Total'!O83 -> 7977532.6 | M16: ='II-I-Total'!P83 -> 2278161.3 | N16: ='II-I-Total'!Q83 -> 14910476 | ... P16: ='II-I-Total'!S83 -> 2584084.4 | S16: =IF(F16-(SUM('WP II-I-1.1'!G494:I494))=0,TRUE,F16-(SUM('WP II-I-1.1'!G494:I494))) -> -1.1920929e-07
D17: Depreciation Expense | F17: =SUM(G17:P17) -> 7.6213691e+08 | G17: ='II-I-Total'!J22 -> 4.016133e+08 | H17: ='II-I-Total'!K22 -> 18899507 | I17: ='II-I-Total'!L22 -> 2.4937832e+08 | J17: ='II-I-Total'!M22 -> 1187788.3 | K17: ='II-I-Total'!N22 -> 49419746 | L17: ='II-I-Total'!O22 -> 4133939.8 | M17: ='II-I-Total'!P22 -> 1259119.8 | N17: ='II-I-Total'!Q22 -> 34303678 | ... P17: ='II-I-Total'!S22 -> 1644034.4
D18: Federal Income Tax (cost-based) | F18: =SUM(G18:P18) -> 1.4473902e+08 | G18: ='II-I-Total'!J25 -> 78668226 | H18: ='II-I-Total'!K25 -> 2333594.4 | I18: ='II-I-Total'!L25 -> 50108868 | J18: ='II-I-Total'!M25 -> 68143.324 | K18: ='II-I-Total'!N25 -> 9622190.5 | L18: ='II-I-Total'!O25 -> 1093406.3 | M18: ='II-I-Total'!P25 -> 303017.14 | N18: ='II-I-Total'!Q25 -> 2109357.1 | ... P18: ='II-I-Total'!S25 -> 355506.44 | S18: =IF(ROUND(F18-(SUM('WP II-I-1.1'!G498:I498)-'WP II-I-1.1'!F498),1)=0,TRUE,F18-(SUM('WP II-I-1.1'!G498:I498)-'WP II-I-1.1'!F39)) -> 0
D19: Taxes Other Than FIT | F19: =SUM(G19:P19) -> 4.9498676e+08 | G19: ='II-I-Total'!J24 -> 2.2223392e+08 | H19: ='II-I-Total'!K24 -> 7470560.3 | I19: ='II-I-Total'!L24 -> 1.9103386e+08 | J19: ='II-I-Total'!M24 -> 174043.73 | K19: ='II-I-Total'!N24 -> 33593410 | L19: ='II-I-Total'!O24 -> 5306944 | M19: ='II-I-Total'!P24 -> 27571464 | N19: ='II-I-Total'!Q24 -> 6397694.4 | ... P19: ='II-I-Total'!S24 -> 810743.42
C21: DIST Plant Function:
D22: Distribution Plant - Net | F22: =SUM(G22:P22) -> 1.3196087e+10 | G22: ='II-I-DIST'!J325 -> 7.2105294e+09 | H22: ='II-I-DIST'!K325 -> 1.9216964e+08 | I22: ='II-I-DIST'!L325 -> 4.5895967e+09 | J22: ='II-I-DIST'!M325 -> 1364418.2 | K22: ='II-I-DIST'!N325 -> 8.5765566e+08 | L22: ='II-I-DIST'!O325 -> 90070166 | M22: ='II-I-DIST'!P325 -> 17552732 | N22: ='II-I-DIST'!Q325 -> 1.980141e+08 | ... P22: ='II-I-DIST'!S325 -> 32908463
C23: A360 | D23: Land and Land Rights - Net | F23: =SUM(G23:P23) -> 16818708 | G23: ='II-I-DIST'!J136-'II-I-DIST'!J290 -> 9040973.5 | H23: ='II-I-DIST'!K136-'II-I-DIST'!K290 -> 296691.8 | I23: ='II-I-DIST'!L136-'II-I-DIST'!L290 -> 5713094.6 | J23: ='II-I-DIST'!M136-'II-I-DIST'!M290 -> 1626.3533 | K23: ='II-I-DIST'!N136-'II-I-DIST'!N290 -> 1022304.7 | L23: ='II-I-DIST'!O136-'II-I-DIST'!O290 -> 98265.926 | M23: ='II-I-DIST'!P136-'II-I-DIST'!P290 -> 19970.074 | N23: ='II-I-DIST'!Q136-'II-I-DIST'!Q290 -> 579762.97 | ... P23: ='II-I-DIST'!S136-'II-I-DIST'!S290 -> 39226.087
C24: A361 | D24: Structures and Improvements - Net | F24: =SUM(G24:P24) -> 2.1261803e+08 | G24: ='II-I-DIST'!J137-'II-I-DIST'!J291 -> 1.1429379e+08 | H24: ='II-I-DIST'!K137-'II-I-DIST'!K291 -> 3750705.8 | I24: ='II-I-DIST'!L137-'II-I-DIST'!L291 -> 72223556 | J24: ='II-I-DIST'!M137-'II-I-DIST'!M291 -> 20559.964 | K24: ='II-I-DIST'!N137-'II-I-DIST'!N291 -> 12923728 | L24: ='II-I-DIST'!O137-'II-I-DIST'!O291 -> 1242254 | M24: ='II-I-DIST'!P137-'II-I-DIST'!P291 -> 252456.83 | N24: ='II-I-DIST'!Q137-'II-I-DIST'!Q291 -> 7329222.9 | ... P24: ='II-I-DIST'!S137-'II-I-DIST'!S291 -> 495886.68
C25: A362 | D25: Station Equipment - Net | F25: =SUM(G25:P25) -> 1.9689289e+09 | G25: ='II-I-DIST'!J138-'II-I-DIST'!J292 -> 1.0096008e+09 | H25: ='II-I-DIST'!K138-'II-I-DIST'!K292 -> 19074051 | I25: ='II-I-DIST'!L138-'II-I-DIST'!L292 -> 6.4847084e+08 | J25: ='II-I-DIST'!M138-'II-I-DIST'!M292 -> 303445.91 | K25: ='II-I-DIST'!N138-'II-I-DIST'!N292 -> 1.9074218e+08 | L25: ='II-I-DIST'!O138-'II-I-DIST'!O292 -> 81984743 | M25: ='II-I-DIST'!P138-'II-I-DIST'!P292 -> 0 | N25: ='II-I-DIST'!Q138-'II-I-DIST'!Q292 -> 5766896 | ... P25: ='II-I-DIST'!S138-'II-I-DIST'!S292 -> 7318825.2
D26: 4CP Retail Allocation Factor | F26: =SUM(G26:P26) -> 1 | G26: ='II-I-DIST'!J1377 -> 0.43858854 | H26: ='II-I-DIST'!K1377 -> 0.0088416368 | I26: ='II-I-DIST'!L1377 -> 0.30533457 | J26: ='II-I-DIST'!M1377 -> 9.6594337e-05 | K26: ='II-I-DIST'!N1377 -> 0.094937872 | L26: ='II-I-DIST'!O1377 -> 0.034466235 | M26: ='II-I-DIST'!P1377 -> 0.11773456 | N26: ='II-I-DIST'!Q1377 -> 0 | O26: 0 | P26: 0
D28: NCP (kW) | G28: ='WP II-I-2.2'!E37 -> 15919714 | H28: ='WP II-I-2.2'!F37 -> 300765.85 | I28: ='WP II-I-2.2'!G37 -> 10225299 | J28: ='WP II-I-2.2'!H37 -> 4784.8339 | K28: ='WP II-I-2.2'!I37 -> 3007684.8 | L28: ='WP II-I-2.2'!J37 -> 1292762.1 | M28: ='WP II-I-2.2'!K37 -> 4728173.4 | N28: ='WP II-I-2.2'!L37 -> 90934.293 | ... P28: ='WP II-I-2.2'!N37 -> 115405.62
D30: DIST Function Revenue: Proposed | F30: =SUM(G30:P30) -> 5.5600926e+09 | G30: ='II-I-DIST'!J37 -> 2.730268e+09 | H30: ='II-I-DIST'!K37 -> 69767963 | I30: ='II-I-DIST'!L37 -> 1.8490396e+09 | J30: ='II-I-DIST'!M37 -> 736813.37 | K30: ='II-I-DIST'!N37 -> 4.3459515e+08 | L30: ='II-I-DIST'!O37 -> 98568914 | M30: ='II-I-DIST'!P37 -> 2.7408825e+08 | N30: ='II-I-DIST'!Q37 -> 92687433 | ... P30: ='II-I-DIST'!S37 -> 8506147.8 | S30: =IF(ROUND(F30-'WP II-I-1.1'!G489,2)=0,TRUE,F30-'WP II-I-1.1'!G489) -> TRUE
D31: TRAN Function Revenue Requirement | F31: ='WP II-I-1.1'!F489 -> 1.9114562e+09
C34: DIST Function:
D35: O&M Expenses | F35: =SUM(G35:P35) -> 2.4658459e+09 | G35: ='II-I-DIST'!J15 -> 1.1125812e+09 | H35: ='II-I-DIST'!K15 -> 22758119 | I35: ='II-I-DIST'!L15 -> 7.6382629e+08 | J35: ='II-I-DIST'!M15 -> 359979.97 | K35: ='II-I-DIST'!N15 -> 2.3027371e+08 | L35: ='II-I-DIST'!O15 -> 75448315 | M35: ='II-I-DIST'!P15 -> 2.4742689e+08 | N35: ='II-I-DIST'!Q15 -> 11812787 | ... P35: ='II-I-DIST'!S15 -> 1150425.1
D36: Customer Expenses | F36: =SUM(G36:P36) -> 339790.12 | G36: ='II-I-DIST'!J16 -> 254774.27 | H36: ='II-I-DIST'!K16 -> 24361.403 | I36: ='II-I-DIST'!L16 -> 44514.918 | J36: ='II-I-DIST'!M16 -> 1487.8884 | K36: ='II-I-DIST'!N16 -> 10475.931 | L36: ='II-I-DIST'!O16 -> 339.88168 | M36: ='II-I-DIST'!P16 -> 708.95565 | N36: ='II-I-DIST'!Q16 -> 2993.6929 | ... P36: ='II-I-DIST'!S16 -> 95.644139
D37: A&G Expenses | F37: =SUM(G37:P37) -> 8.6225408e+08 | G37: ='II-I-DIST'!J17 -> 4.5986261e+08 | H37: ='II-I-DIST'!K17 -> 13373498 | I37: ='II-I-DIST'!L17 -> 2.9176041e+08 | J37: ='II-I-DIST'!M17 -> 182914.3 | K37: ='II-I-DIST'!N17 -> 59664370 | L37: ='II-I-DIST'!O17 -> 6384539.4 | M37: ='II-I-DIST'!P17 -> 825460.58 | N37: ='II-I-DIST'!Q17 -> 27500799 | ... P37: ='II-I-DIST'!S17 -> 2260998.9
D38: Depreciation & Amortization Expense | F38: =SUM(G38:P38) -> 6.5141705e+08 | G38: ='II-I-DIST'!J20 -> 3.4461415e+08 | H38: ='II-I-DIST'!K20 -> 11876247 | I38: ='II-I-DIST'!L20 -> 2.1734221e+08 | J38: ='II-I-DIST'!M20 -> 63251.401 | K38: ='II-I-DIST'!N20 -> 39759013 | L38: ='II-I-DIST'!O20 -> 3731667.6 | M38: ='II-I-DIST'!P20 -> 647373.09 | N38: ='II-I-DIST'!Q20 -> 31599630 | ... P38: ='II-I-DIST'!S20 -> 1525563.3
D39: Other Expenses (II-E-4) | F39: =SUM(G39:P39) -> 15428626 | G39: ='II-I-DIST'!J21 -> 8417584.3 | H39: ='II-I-DIST'!K21 -> 222821.52 | I39: ='II-I-DIST'!L21 -> 5359035.8 | J39: ='II-I-DIST'!M21 -> 1614.6021 | K39: ='II-I-DIST'!N21 -> 1014918 | L39: ='II-I-DIST'!O21 -> 118589.03 | M39: ='II-I-DIST'!P21 -> 20014.916 | N39: ='II-I-DIST'!Q21 -> 226907.56 | ... P39: ='II-I-DIST'!S21 -> 38942.659
D40: Taxes Other Than Federal Income Tax | F40: =SUM(G40:P40) -> 4.8252028e+08 | G40: ='II-I-DIST'!J24 -> 2.1582799e+08 | H40: ='II-I-DIST'!K24 -> 6574075.1 | I40: ='II-I-DIST'!L24 -> 1.8750928e+08 | J40: ='II-I-DIST'!M24 -> 25914.634 | K40: ='II-I-DIST'!N24 -> 32451644 | L40: ='II-I-DIST'!O24 -> 5269286.3 | M40: ='II-I-DIST'!P24 -> 27492618 | N40: ='II-I-DIST'!Q24 -> 6179210.6 | ... P40: ='II-I-DIST'!S24 -> 800274.8 | S40: =IF(ROUND(F40-'WP II-I-1.1'!G497,2)=0,TRUE,F40-'WP II-I-1.1'!G497) -> TRUE
D41: Federal Income Tax | F41: =SUM(G41:P41) -> 1.4008147e+08 | G41: ='II-I-DIST'!J25 -> 76325937 | H41: ='II-I-DIST'!K25 -> 2004781.4 | I41: ='II-I-DIST'!L25 -> 48825552 | J41: ='II-I-DIST'!M25 -> 13856.399 | K41: ='II-I-DIST'!N25 -> 9205940.8 | L41: ='II-I-DIST'!O25 -> 1080092.5 | M41: ='II-I-DIST'!P25 -> 274962.9 | N41: ='II-I-DIST'!Q25 -> 1923365.5 | ... P41: ='II-I-DIST'!S25 -> 351755.95 | S41: =IF(ROUND(F41-'WP II-I-1.1'!G498,2)=0,TRUE,F41-'WP II-I-1.1'!G498) -> TRUE
D42: Return on Rate Base | F42: =SUM(G42:P42) -> 1.0090184e+09 | G42: ='II-I-DIST'!J27 -> 5.4961144e+08 | H42: ='II-I-DIST'!K27 -> 14413199 | I42: ='II-I-DIST'!L27 -> 3.5158328e+08 | J42: ='II-I-DIST'!M27 -> 105279.47 | K42: ='II-I-DIST'!N27 -> 66579264 | L42: ='II-I-DIST'!O27 -> 7827010.9 | M42: ='II-I-DIST'!P27 -> 1959955 | N42: ='II-I-DIST'!Q27 -> 13851283 | ... P42: ='II-I-DIST'!S27 -> 2542656.6
D43: Minus Other Revenues | F43: =SUM(G43:P43) -> 66812956 | G43: ='II-I-DIST'!J31 -> 37227660 | H43: ='II-I-DIST'!K31 -> 1479140 | I43: ='II-I-DIST'!L31 -> 17210937 | J43: ='II-I-DIST'!M31 -> 17485.299 | K43: ='II-I-DIST'!N31 -> 4364179.9 | L43: ='II-I-DIST'!O31 -> 1290926.5 | M43: ='II-I-DIST'!P31 -> 4559734.3 | N43: ='II-I-DIST'!Q31 -> 409541.83 | ... P43: ='II-I-DIST'!S31 -> 164565.08
D45: Rate Case Expense A928 | F45: =SUM(G45:P45) -> 0 | G45: ='WP II-I-1.7'!E21 -> 0 | H45: ='WP II-I-1.7'!F21 -> 0 | I45: ='WP II-I-1.7'!G21 -> 0 | J45: ='WP II-I-1.7'!H21 -> 0 | K45: ='WP II-I-1.7'!I21 -> 0 | L45: ='WP II-I-1.7'!J21 -> 0 | M45: ='WP II-I-1.7'!K21 -> 0 | N45: ='WP II-I-1.7'!L21 -> 0 | ... P45: ='WP II-I-1.7'!N21 -> 0
D46: A565 Transmission of Electricity by Others | F46: =SUM(G46:P46) -> 2.1008415e+09 | G46: ='II-I-DIST'!J645 -> 9.2140499e+08 | H46: ='II-I-DIST'!K645 -> 18574877 | I46: ='II-I-DIST'!L645 -> 6.4145952e+08 | J46: ='II-I-DIST'!M645 -> 202929.39 | K46: ='II-I-DIST'!N645 -> 1.9944942e+08 | L46: ='II-I-DIST'!O645 -> 72408096 | M46: ='II-I-DIST'!P645 -> 2.4734164e+08 | N46: ='II-I-DIST'!Q645 -> 0 | ... P46: ='II-I-DIST'!S645 -> 0
D47: Total Distribution Facilities Less A565 & A928 | F47: =SUM(G47:P47) -> 3.4592512e+09 | G47: ='WP II-I-1.7'!E23 -> 1.808863e+09 | H47: ='WP II-I-1.7'!F23 -> 51193085 | I47: ='WP II-I-1.7'!G23 -> 1.2075801e+09 | J47: ='WP II-I-1.7'!H23 -> 533883.98 | K47: ='WP II-I-1.7'!I23 -> 2.3514573e+08 | L47: ='WP II-I-1.7'!J23 -> 26160818 | M47: ='WP II-I-1.7'!K23 -> 26746602 | N47: ='WP II-I-1.7'!L23 -> 92687433 | ... P47: ='WP II-I-1.7'!N23 -> 8506147.8

Sheet WP II-I-1.1
B3: ='II-I-1'!B2 -> 2025 RATE CASE
B4: ='II-I-1'!B3 -> ONCOR ELECTRIC DELIVERY COMPANY LLC
B5: II-I-1: CLASS REVENUE REQUIREMENT ANALYSIS
B6: ='II-I-1'!B5 -> TEST YEAR ENDING 12/31/2024
B7: ='II-I-1'!B6 -> SPONSOR: MATTHEW A. TROXLE
B10: WORKPAPER 1.1 - CONSOLIDATION OF FUNCTIONALIZED COST OF SERVICE
B13: Line | C13: Account | D13: Description | E13: Reference | F13: TRAN | G13: DIST | H13: MET | I13: TDCS | J13: Total
C14: Number | E14: Schedule
C15: (a) | D15: (b) | E15: (c) | F15: (d) | G15: (e) | H15: (f) | I15: (i) | J15: (j)
B17: =B16+1 -> 1 | C17: Intangible Plant - Gross | E17: II-B-1
B18: 2 | C18: A301 | D18: Organization | F18: 0 | G18: 0 | H18: 0 | I18: 0 | J18: 0 | K18: =J18-SUM(F18:I18) -> 0
B19: 3 | C19: A302 | D19: Franchise & Consents | F19: 0 | G19: 0 | H19: 0 | I19: 0 | J19: 0 | K19: =J19-SUM(F19:I19) -> 0
B20: 4 | C20: A303 | D20: Miscellaneous Intangible Plant | F20: 6784530 | G20: 8645784 | H20: 324360 | I20: 145326 | J20: 15900000 | K20: =J20-SUM(F20:I20) -> 0
B21: 5 | C21: Intangible plant - Accumulated Depreciation | E21: II-B-5 | K21: =J21-SUM(F21:I21) -> 0
B22: 6 | C22: A301 | D22: Organization | F22: 0 | G22: 0 | H22: 0 | I22: 0 | J22: 0 | K22: =J22-SUM(F22:I22) -> 0
B23: 7 | C23: A302 | D23: Franchise and Consents | F23: 0 | G23: 0 | H23: 0 | I23: 0 | J23: 0 | K23: =J23-SUM(F23:I23) -> 0
B24: 8 | C24: A303 | D24: Miscellaneous Intangible Plant | F24: 2514612.3 | G24: 3204465.8 | H24: 120220.51 | I24: 53863.5 | J24: 5893162.1 | K24: =J24-SUM(F24:I24) -> 0
B25: 9 | C25: Transmission Plant - Gross | E25: II-B-1 | K25: =J25-SUM(F25:I25) -> 0
B26: 10 | C26: A349 | D26: Land Owned in Fee | F26: 1.5984856e+08 | G26: 0 | H26: 0 | I26: 0 | J26: 1.5984856e+08 | K26: =J26-SUM(F26:I26) -> 0
B27: 11 | C27: A350 | D27: Land and Land Rights | F27: 6.7572377e+08 | G27: 0 | H27: 0 | I27: 0 | J27: 6.7572377e+08 | K27: =J27-SUM(F27:I27) -> 0
B28: 12 | C28: A351.1 | D28: Computer Hardware | F28: 0 | G28: 0 | H28: 0 | I28: 0 | J28: 0 | K28: =J28-SUM(F28:I28) -> 0
B29: 13 | C29: A351.2 | D29: Computer Software | F29: 1.5082575e+08 | G29: 0 | H29: 0 | I29: 0 | J29: 1.5082575e+08 | K29: =J29-SUM(F29:I29) -> 0
B30: 14 | C30: A351.3 | D30: Communication Equipment | F30: 3528604.2 | G30: 0 | H30: 0 | I30: 0 | J30: 3528604.2 | K30: =J30-SUM(F30:I30) -> 0
B31: 15 | C31: A352 | D31: Structures and Improvements | F31: 6.5478537e+08 | G31: 0 | H31: 0 | I31: 0 | J31: 6.5478537e+08 | K31: =J31-SUM(F31:I31) -> 0
B32: 16 | C32: A353 | D32: Station Equipment | F32: 4.4997751e+09 | G32: 4.6897613e+08 | H32: 0 | I32: 0 | J32: 4.9687512e+09 | K32: =J32-SUM(F32:I32) -> 0
B33: 17 | C33: A354 | D33: Towers and Fixtures | F33: 2.1534233e+09 | G33: 0 | H33: 0 | I33: 0 | J33: 2.1534233e+09 | K33: =J33-SUM(F33:I33) -> 0
B34: 18 | C34: A355 | D34: Poles and Fixtures | F34: 4.0735736e+09 | G34: 0 | H34: 0 | I34: 0 | J34: 4.0735736e+09 | K34: =J34-SUM(F34:I34) -> 0
B35: 19 | C35: A356 | D35: Overhead Conductors and Devices | F35: 3.7347934e+09 | G35: 0 | H35: 0 | I35: 0 | J35: 3.7347934e+09 | K35: =J35-SUM(F35:I35) -> 0
B36: 20 | C36: A357 | D36: Underground Conduit | F36: 61796401 | G36: 0 | H36: 0 | I36: 0 | J36: 61796401 | K36: =J36-SUM(F36:I36) -> 0
B37: 21 | C37: A358 | D37: Underground Conductors and Devices | F37: 96633109 | G37: 0 | H37: 0 | I37: 0 | J37: 96633109 | K37: =J37-SUM(F37:I37) -> 0
B38: 22 | C38: A359 | D38: Roads and Trails | F38: 0 | G38: 0 | H38: 0 | I38: 0 | J38: 0 | K38: =J38-SUM(F38:I38) -> 0
B39: 23 | C39: Transmission Plant - Accumulated Depreciation | E39: II-B-5 | K39: =J39-SUM(F39:I39) -> 0
B40: 24 | C40: A349 | D40: Land Owned in Fee | F40: 0 | G40: 0 | H40: 0 | I40: 0 | J40: 0 | K40: =J40-SUM(F40:I40) -> 0
B41: 25 | C41: A350 | D41: Land and Land Rights | F41: 1.4077873e+08 | G41: 0 | H41: 0 | I41: 0 | J41: 1.4077873e+08 | K41: =J41-SUM(F41:I41) -> 0
B42: 26 | C42: A351.1 | D42: Computer Hardware | F42: 0 | G42: 0 | H42: 0 | I42: 0 | J42: 0 | K42: =J42-SUM(F42:I42) -> 0
B43: 27 | C43: A351.2 | D43: Computer Software | F43: 56291413 | G43: 0 | H43: 0 | I43: 0 | J43: 56291413 | K43: =J43-SUM(F43:I43) -> 0
B44: 28 | C44: A351.3 | D44: Communication Equipment | F44: 1213664.3 | G44: 0 | H44: 0 | I44: 0 | J44: 1213664.3 | K44: =J44-SUM(F44:I44) -> 0
B45: 29 | C45: A352 | D45: Structures and Improvements | F45: 1.6443899e+08 | G45: 0 | H45: 0 | I45: 0 | J45: 1.6443899e+08 | K45: =J45-SUM(F45:I45) -> 0
B46: 30 | C46: A353 | D46: Station Equipment | F46: 9.6296508e+08 | G46: 1.3442784e+08 | H46: 0 | I46: 0 | J46: 1.0973929e+09 | K46: =J46-SUM(F46:I46) -> 0
B47: 31 | C47: A354 | D47: Towers and Fixtures | F47: 6.4803222e+08 | G47: 0 | H47: 0 | I47: 0 | J47: 6.4803222e+08 | K47: =J47-SUM(F47:I47) -> 0
...

Sheet  WP II-I-1.4
M2: =" "
B4: ='WP II-I-1.1'!B3 -> 2025 RATE CASE
B5: ='WP II-I-1.1'!B4 -> ONCOR ELECTRIC DELIVERY COMPANY LLC
B6: CONSOLIDATED FUNCTIONALIZED COST OF SERVICE
B7: ='WP II-I-1.1'!B6 -> TEST YEAR ENDING 12/31/2024
B8: ='WP II-I-2.2'!$B$7 -> SPONSOR: MATTHEW A. TROXLE
F10: TRAN | G10: DIST | H10: MET | I10: TDCS | J10: Total | L10: DIST + MET
B11: Line | D11: Revenue Requirement | E11: Source | L11: + TBILLTDCS
B13: (a) | D13: (b) | E13: (c) | F13: (d) | G13: (e) | H13: (f) | I13: (i) | J13: (j) | L13: (l)
B15: =B14+1 -> 1 | D15: O&M Expenses | E15: II-D-2 | F15: =F661+F709 -> 1.4103893e+08 | G15: =G661+G709 -> 2.4658459e+09 | H15: =H661+H709 -> 61551893 | I15: =I661+I709 -> 189681.03 | J15: =SUM(F15:I15) -> 2.6686264e+09 | L15: =SUM(G15:I15) -> 2.5275875e+09
B16: =B15+1 -> 2 | D16: Customer Expenses | E16: II-D-2 | F16: =F729+F739+F749 -> -153231.79 | G16: =G729+G739+G749 -> 339790.12 | H16: =H729+H739+H749 -> 9809696.2 | I16: =I729+I739+I749 -> 17097126 | J16: =SUM(F16:I16) -> 27093381 | L16: =SUM(G16:I16) -> 27246613
B17: =B16+1 -> 3 | D17: A&G Expenses | E17: II-D-2 | F17: =F783 -> 1.4971493e+08 | G17: =G783 -> 8.6225408e+08 | H17: =H783 -> 49056190 | I17: =I783 -> 40849532 | J17: =SUM(F17:I17) -> 1.1018747e+09 | L17: =SUM(G17:I17) -> 9.521598e+08
B18: =B17+1 -> 4 | D18: O&M + Customer + A&G Expenses | F18: =SUM(F15:F17) -> 2.9060063e+08 | G18: =SUM(G15:G17) -> 3.3284398e+09 | H18: =SUM(H15:H17) -> 1.2041778e+08 | I18: =SUM(I15:I17) -> 58136339 | J18: =SUM(F18:I18) -> 3.7975946e+09 | L18: =SUM(G18:I18) -> 3.5069939e+09 | N18: ='WP II-I-1.1'!J495=J18 -> TRUE | P18: ='WP II-I-1.1'!F495=F18 -> TRUE | Q18: ='WP II-I-1.1'!G495=G18 -> TRUE | R18: ='WP II-I-1.1'!H495=H18 -> TRUE | S18: ='WP II-I-1.1'!I495=I18 -> TRUE | T18: ='WP II-I-1.1'!J495=J18 -> TRUE
B19: =B18+1 -> 5
B20: =B19+1 -> 6 | D20: Depreciation & Amortization (II-E-1) | E20: II-E-1 | F20: =F1065 -> 4.7003129e+08 | G20: =G1065 -> 6.5141705e+08 | H20: =H1065 -> 29837696 | I20: =I1065 -> 39993574 | J20: =SUM(F20:I20) -> 1.1912796e+09 | L20: =SUM(G20:I20) -> 7.2124832e+08
B21: =B20+1 -> 7 | D21: Other (II-E-4) | E21: II-E-4 | F21: =F1067+F1068 -> 10313432 | G21: =G1067+G1068 -> 15428626 | H21: =H1067+H1068 -> 25459958 | I21: =I1067+I1068 -> 0 | J21: =SUM(F21:I21) -> 51202016 | L21: =SUM(G21:I21) -> 40888584
B22: =B21+1 -> 8 | D22: Depreciation, Amortization & Other Expenses | F22: =SUM(F20:F21) -> 4.8034473e+08 | G22: =SUM(G20:G21) -> 6.6684568e+08 | H22: =SUM(H20:H21) -> 55297654 | I22: =SUM(I20:I21) -> 39993574 | J22: =SUM(F22:I22) -> 1.2424816e+09 | L22: =SUM(G22:I22) -> 7.6213691e+08 | N22: ='WP II-I-1.1'!J496=J22 -> TRUE | P22: ='WP II-I-1.1'!F496=F22 -> TRUE | Q22: ='WP II-I-1.1'!G496=G22 -> TRUE | R22: ='WP II-I-1.1'!H496=H22 -> TRUE | S22: ='WP II-I-1.1'!I496=I22 -> TRUE | T22: ='WP II-I-1.1'!J496=J22 -> TRUE
B23: =B22+1 -> 9
B24: =B23+1 -> 10 | D24: Taxes Other Than Federal Income Tax | E24: II-E-2 | F24: =+F1103 -> 1.4708187e+08 | G24: =+G1103 -> 4.8252028e+08 | H24: =+H1103 -> 8908968.6 | I24: =+I1103 -> 3557512.7 | J24: =SUM(F24:I24) -> 6.4206863e+08 | L24: =SUM(G24:I24) -> 4.9498676e+08 | N24: ='WP II-I-1.1'!J497=J24 -> TRUE | P24: ='WP II-I-1.1'!F497=F24 -> TRUE | Q24: ='WP II-I-1.1'!G497=G24 -> TRUE | R24: ='WP II-I-1.1'!H497=H24 -> TRUE | S24: ='WP II-I-1.1'!I497-I24 -> 0 | T24: ='WP II-I-1.1'!J497=J24 -> TRUE
B25: =B24+1 -> 11 | D25: Federal Income Tax | E25: II-E-3 | F25: =+F1163 -> 1.2867713e+08 | G25: =+G1163 -> 1.4008147e+08 | H25: =+H1163 -> 1780846.8 | I25: =+I1163 -> 2876698.2 | J25: =SUM(F25:I25) -> 2.7341615e+08 | L25: =SUM(G25:I25) -> 1.4473902e+08 | N25: ='WP II-I-1.1'!J498-J25 -> 0 | P25: ='WP II-I-1.1'!F498-F25 -> 0 | Q25: ='WP II-I-1.1'!G498-G25 -> 0 | R25: ='WP II-I-1.1'!H498-H25 -> 0 | S25: ='WP II-I-1.1'!I498-I25 -> 0 | T25: ='WP II-I-1.1'!J498-J25 -> 0
B26: =B25+1 -> 12
B27: =B26+1 -> 13 | D27: Return on Rate Base | E27: II-B | F27: =+F83 -> 9.1088358e+08 | G27: =+G83 -> 1.0090184e+09 | H27: =+H83 -> 32952956 | I27: =+I83 -> 17186005 | J27: =SUM(F27:I27) -> 1.9700409e+09 | L27: =SUM(G27:I27) -> 1.0591573e+09 | N27: ='WP II-I-1.1'!J494-J27 -> 0 | P27: ='WP II-I-1.1'!F494-F27 -> 0 | Q27: ='WP II-I-1.1'!G494-G27 -> 0 | R27: ='WP II-I-1.1'!H494-H27 -> 0 | S27: ='WP II-I-1.1'!I494-I27 -> 0 | T27: ='WP II-I-1.1'!J494-J27 -> 0
B28: =B27+1 -> 14
B29: =B28+1 -> 15 | D29: TOTAL COST OF SERVICE | F29: =+F18+F22+F24+F25+F27 -> 1.9575879e+09 | G29: =+G18+G22+G24+G25+G27 -> 5.6269056e+09 | H29: =+H18+H22+H24+H25+H27 -> 2.193582e+08 | I29: =+I18+I22+I24+I25+I27 -> 1.2175013e+08 | J29: =SUM(F29:I29) -> 7.9256019e+09 | L29: =SUM(G29:I29) -> 5.9680139e+09 | N29: =ROUND('WP II-I-1.1'!$J$509,0)=ROUND(J29,0) -> TRUE
B30: 16
B31: =B30+1 -> 17 | D31: Minus: Other Revenues | E31: II-E-5 | F31: =+F1223 -> 46131717 | G31: =+G1223 -> 66812956 | H31: =+H1223 -> 14115591 | I31: =+I1223 -> 85782 | J31: =SUM(F31:I31) -> 1.2714605e+08 | L31: =SUM(G31:I31) -> 81014329 | N31: ='WP II-I-1.1'!J499--J31 -> 0
B32: =B31+1 -> 18
B33: =B32+1 -> 19 | D33: COST-BASED Revenue Requirement | F33: =+F29-F31 -> 1.9114562e+09 | G33: =+G29-G31 -> 5.5600926e+09 | H33: =+H29-H31 -> 2.0524261e+08 | I33: =+I29-I31 -> 1.2166435e+08 | J33: =SUM(F33:I33) -> 7.7984558e+09 | L33: =G33+H33+I33 -> 5.8869996e+09 | N33: =ROUND('WP II-I-1.1'!$J$510,0)=ROUND(J33,0) -> TRUE | P33: ='WP II-I-1.1'!$G$489+'WP II-I-1.1'!$H$489+'WP II-I-1.1'!$I$489-L33 -> -0.0020475388
B42: =$B$4 -> 2025 RATE CASE
B43: =$B$5 -> ONCOR ELECTRIC DELIVERY COMPANY LLC
B44: =$B$6 -> CONSOLIDATED FUNCTIONALIZED COST OF SERVICE
B45: =$B$7 -> TEST YEAR ENDING 12/31/2024
B46: =$B$8 -> SPONSOR: MATTHEW A. TROXLE
F48: TRAN | G48: DIST | H48: MET | I48: TDCS | J48: Total | L48: =L$10 -> DIST + MET
B49: Line | D49: Return On Rate Base | E49: Source | L49: =L$11 -> + TBILLTDCS
B51: (a) | D51: (b) | E51: (c) | F51: (d) | G51: (e) | H51: (f) | I51: (i) | J51: (j) | L51: (l)
B53: =B52+1 -> 1 | D53: Intangible Plant: Original Cost | E53: II-B-1 | F53: =F106 -> 6784530 | G53: =G106 -> 8645784 | H53: =H106 -> 324360 | I53: =I106 -> 145326 | J53: =SUM(F53:I53) -> 15900000 | L53: =SUM(G53:I53) -> 9115470 | N53: =SUM('WP II-I-1.1'!F18:I20)=J53 -> TRUE
B54: =B53+1 -> 2 | D54: Transmission Plant: Original Cost | E54: II-B-1 | F54: =F121 -> 1.6264707e+10 | G54: =G121 -> 4.6897613e+08 | H54: =H121 -> 0 | I54: =I121 -> 0 | J54: =SUM(F54:I54) -> 1.6733683e+10 | L54: =SUM(G54:I54) -> 4.6897613e+08 | N54: =SUM('WP II-I-1.1'!F26:I38)=J54 -> TRUE
B55: =B54+1 -> 3 | D55: Distribution Plant: Original Cost | E55: II-B-1 | F55: =F159 -> 1.0831606e+09 | G55: =G159 -> 1.9438204e+10 | H55: =H159 -> 7.8498359e+08 | I55: =I159 -> 3.3487324e+08 | J55: =SUM(F55:I55) -> 2.1641222e+10 | L55: =SUM(G55:I55) -> 2.0558061e+10 | N55: =SUM('WP II-I-1.1'!F56:I72)=J55 -> TRUE
B56: =B55+1 -> 4 | D56: Intangible, Transmission, Distribution Plant: Original Cost | F56: =SUM(F53:F55) -> 1.7354652e+10 | G56: =SUM(G53:G55) -> 1.9915826e+10 | H56: =SUM(H53:H55) -> 7.8530795e+08 | I56: =SUM(I53:I55) -> 3.3501856e+08 | J56: =SUM(F56:I56) -> 3.8390805e+10 | L56: =SUM(G56:I56) -> 2.1036153e+10 | N56: =SUM(F56:I56)=J56 -> TRUE
...

Sheet II-I-DIST
B4: ='WP II-I-1.1'!B3 -> 2025 RATE CASE
B5: ='WP II-I-1.1'!B4 -> ONCOR ELECTRIC DELIVERY COMPANY LLC
B6: ="II-I-1-DIST: CLASS REVENUE REQUIREMENT" -> II-I-1-DIST: CLASS REVENUE REQUIREMENT
B7: ='WP II-I-1.1'!B6 -> TEST YEAR ENDING 12/31/2024
B8: ='WP II-I-2.2'!$B$7 -> SPONSOR: MATTHEW A. TROXLE
R10: =" "
B11: Line | D11: I-A-1 by Rate Class | E11: Source | F11: DIST | J11: Residential | K11: Secondary | L11: Secondary | M11: Primary | N11: Primary | O11: Primary | P11: Transmission | Q11: Lighting | R11: Wholesale | S11: Wholesale | U11: Total
K12: <=10 kW | L12: > 10 kW | M12: <=10 kW | N12: > 10 kW | O12: Substation | R12: XFMR | S12: DLS
F13: (a) | G13: (b) | H13: (c) | J13: (d) | K13: (e) | L13: (f) | M13: (g) | N13: (h) | O13: (i) | P13: (j) | Q13: (k) | R13: (l) | S13: (m) | U13: (n)
B15: =B14+1 -> 1 | D15: O&M Expenses | E15: II-D-2 | F15: =F661+F709 -> 2.4658459e+09 | J15: =J661+J709 -> 1.1125812e+09 | K15: =K661+K709 -> 22758119 | L15: =L661+L709 -> 7.6382629e+08 | M15: =M661+M709 -> 359979.97 | N15: =N661+N709 -> 2.3027371e+08 | O15: =O661+O709 -> 75448315 | P15: =P661+P709 -> 2.4742689e+08 | Q15: =Q661+Q709 -> 11812787 | ... S15: =S661+S709 -> 1150425.1 | U15: =SUM(I15:T15) -> 2.4658459e+09 | X15: =U15-F15 -> 0
B16: =B15+1 -> 2 | D16: Customer Expenses | E16: II-D-2 | F16: =F729+F739+F749 -> 339790.12 | J16: =J729+J739+J749 -> 254774.27 | K16: =K729+K739+K749 -> 24361.403 | L16: =L729+L739+L749 -> 44514.918 | M16: =M729+M739+M749 -> 1487.8884 | N16: =N729+N739+N749 -> 10475.931 | O16: =O729+O739+O749 -> 339.88168 | P16: =P729+P739+P749 -> 708.95565 | Q16: =Q729+Q739+Q749 -> 2993.6929 | ... S16: =S729+S739+S749 -> 95.644139 | U16: =SUM(I16:T16) -> 339790.12 | X16: =U16-F16 -> 0
B17: =B16+1 -> 3 | D17: A&G Expenses | E17: II-D-2 | F17: =F783 -> 8.6225408e+08 | J17: =J783 -> 4.5986261e+08 | K17: =K783 -> 13373498 | L17: =L783 -> 2.9176041e+08 | M17: =M783 -> 182914.3 | N17: =N783 -> 59664370 | O17: =O783 -> 6384539.4 | P17: =P783 -> 825460.58 | Q17: =Q783 -> 27500799 | ... S17: =S783 -> 2260998.9 | U17: =SUM(I17:T17) -> 8.6225408e+08 | X17: =U17-F17 -> 0
B18: =B17+1 -> 4 | D18: O&M + Customer + A&G Expenses | F18: =SUM(F15:F17) -> 3.3284398e+09 | J18: =SUM(J15:J17) -> 1.5726986e+09 | K18: =SUM(K15:K17) -> 36155979 | L18: =SUM(L15:L17) -> 1.0556312e+09 | M18: =SUM(M15:M17) -> 544382.16 | N18: =SUM(N15:N17) -> 2.8994855e+08 | O18: =SUM(O15:O17) -> 81833194 | P18: =SUM(P15:P17) -> 2.4825306e+08 | Q18: =SUM(Q15:Q17) -> 39316579 | ... S18: =SUM(S15:S17) -> 3411519.6 | U18: =SUM(I18:T18) -> 3.3284398e+09 | X18: =U18-F18 -> 0 | Y18: ='WP II-I-1.1'!$G$495=U18 -> TRUE | Z18: should match schedule D
B19: =B18+1 -> 5 | X19: =U19-F19 -> 0
B20: =B19+1 -> 6 | D20: Depreciation & Amortization (II-E-1) | E20: II-E-1 | F20: =F1065 -> 6.5141705e+08 | J20: =J1065 -> 3.4461415e+08 | K20: =K1065 -> 11876247 | L20: =L1065 -> 2.1734221e+08 | M20: =M1065 -> 63251.401 | N20: =N1065 -> 39759013 | O20: =O1065 -> 3731667.6 | P20: =P1065 -> 647373.09 | Q20: =Q1065 -> 31599630 | ... S20: =S1065 -> 1525563.3 | U20: =SUM(I20:T20) -> 6.5141705e+08 | X20: =U20-F20 -> 0
B21: =B20+1 -> 7 | D21: Other (II-E-4) | E21: II-E-4 | F21: =F1067+F1068 -> 15428626 | J21: =J1067+J1068 -> 8417584.3 | K21: =K1067+K1068 -> 222821.52 | L21: =L1067+L1068 -> 5359035.8 | M21: =M1067+M1068 -> 1614.6021 | N21: =N1067+N1068 -> 1014918 | O21: =O1067+O1068 -> 118589.03 | P21: =P1067+P1068 -> 20014.916 | Q21: =Q1067+Q1068 -> 226907.56 | ... S21: =S1067+S1068 -> 38942.659 | U21: =SUM(I21:T21) -> 15428626 | X21: =U21-F21 -> 0
B22: =B21+1 -> 8 | D22: Depreciation, Amortization & Other Expenses | F22: =SUM(F20:F21) -> 6.6684568e+08 | J22: =SUM(J20:J21) -> 3.5303173e+08 | K22: =SUM(K20:K21) -> 12099069 | L22: =SUM(L20:L21) -> 2.2270124e+08 | M22: =SUM(M20:M21) -> 64866.003 | N22: =SUM(N20:N21) -> 40773931 | O22: =SUM(O20:O21) -> 3850256.6 | P22: =SUM(P20:P21) -> 667388.01 | Q22: =SUM(Q20:Q21) -> 31826537 | ... S22: =SUM(S20:S21) -> 1564506 | U22: =SUM(I22:T22) -> 6.6684568e+08 | X22: =U22-F22 -> 0 | Y22: ='WP II-I-1.1'!$G$496=U22 -> TRUE
B23: =B22+1 -> 9 | X23: =U23-F23 -> 0
B24: =B23+1 -> 10 | D24: Taxes Other Than Federal Income Tax | E24: II-E-2 | F24: =+F1103 -> 4.8252028e+08 | J24: =+J1103 -> 2.1582799e+08 | K24: =+K1103 -> 6574075.1 | L24: =+L1103 -> 1.8750928e+08 | M24: =+M1103 -> 25914.634 | N24: =+N1103 -> 32451644 | O24: =+O1103 -> 5269286.3 | P24: =+P1103 -> 27492618 | Q24: =+Q1103 -> 6179210.6 | ... S24: =+S1103 -> 800274.8 | U24: =SUM(I24:T24) -> 4.8252028e+08 | X24: =U24-F24 -> 0 | Y24: ='WP II-I-1.1'!$G$497=U24 -> TRUE
B25: =B24+1 -> 11 | D25: Federal Income Tax | E25: II-E-3 | F25: =+F1162 -> 1.4008147e+08 | J25: =+J1162 -> 76325937 | K25: =+K1162 -> 2004781.4 | L25: =+L1162 -> 48825552 | M25: =+M1162 -> 13856.399 | N25: =+N1162 -> 9205940.8 | O25: =+O1162 -> 1080092.5 | P25: =+P1162 -> 274962.9 | Q25: =+Q1162 -> 1923365.5 | ... S25: =+S1162 -> 351755.95 | U25: =SUM(I25:T25) -> 1.4008147e+08 | X25: =U25-F25 -> 0 | Y25: ='WP II-I-1.1'!$G$498-U25 -> 0
B26: =B25+1 -> 12 | X26: =U26-F26 -> 0
B27: =B26+1 -> 13 | D27: Return on Rate Base | E27: II-B | F27: =+F83 -> 1.0090184e+09 | J27: =+J83 -> 5.4961144e+08 | K27: =+K83 -> 14413199 | L27: =+L83 -> 3.5158328e+08 | M27: =+M83 -> 105279.47 | N27: =+N83 -> 66579264 | O27: =+O83 -> 7827010.9 | P27: =+P83 -> 1959955 | Q27: =+Q83 -> 13851283 | ... S27: =+S83 -> 2542656.6 | U27: =SUM(I27:T27) -> 1.0090184e+09 | X27: =U27-F27 -> 0 | Y27: ='WP II-I-1.1'!$G$494=U27 -> TRUE
B28: =B27+1 -> 14 | X28: =U28-F28 -> 0
B29: =B28+1 -> 15 | D29: TOTAL COST OF SERVICE | F29: =+F18+F22+F24+F25+F27 -> 5.6269056e+09 | J29: =+J18+J22+J24+J25+J27 -> 2.7674957e+09 | K29: =+K18+K22+K24+K25+K27 -> 71247103 | L29: =+L18+L22+L24+L25+L27 -> 1.8662506e+09 | M29: =+M18+M22+M24+M25+M27 -> 754298.66 | N29: =+N18+N22+N24+N25+N27 -> 4.3895933e+08 | O29: =+O18+O22+O24+O25+O27 -> 99859840 | P29: =+P18+P22+P24+P25+P27 -> 2.7864798e+08 | Q29: =+Q18+Q22+Q24+Q25+Q27 -> 93096975 | ... S29: =+S18+S22+S24+S25+S27 -> 8670712.8 | U29: =SUM(I29:T29) -> 5.6269056e+09 | X29: =U29-F29 -> 0 | Y29: ='WP II-I-1.1'!$G$509=U29 -> TRUE
B30: =B29+1 -> 16 | X30: =U30-F30 -> 0
B31: =B30+1 -> 17 | D31: Minus: Other Revenues | E31: II-E-5 | F31: =+F1222 -> 66812956 | J31: =+J1222 -> 37227660 | K31: =+K1222 -> 1479140 | L31: =+L1222 -> 17210937 | M31: =+M1222 -> 17485.299 | N31: =+N1222 -> 4364179.9 | O31: =+O1222 -> 1290926.5 | P31: =+P1222 -> 4559734.3 | Q31: =+Q1222 -> 409541.83 | ... S31: =+S1222 -> 164565.08 | U31: =SUM(I31:T31) -> 66812956 | X31: =U31-F31 -> 0 | Y31: ='WP II-I-1.1'!$G$499=-U31 -> TRUE
B32: =B31+1 -> 18 | X32: =U32-F32 -> 0
B33: =B32+1 -> 19 | D33: COST-BASED Revenue Requirement | F33: =+F29-F31 -> 5.5600926e+09 | J33: =+J29-J31 -> 2.730268e+09 | K33: =+K29-K31 -> 69767963 | L33: =+L29-L31 -> 1.8490396e+09 | M33: =+M29-M31 -> 736813.37 | N33: =+N29-N31 -> 4.3459515e+08 | O33: =+O29-O31 -> 98568914 | P33: =+P29-P31 -> 2.7408825e+08 | Q33: =+Q29-Q31 -> 92687433 | ... S33: =+S29-S31 -> 8506147.8 | U33: =SUM(I33:T33) -> 5.5600926e+09 | W33: =IF(' WP II-I-1.4'!G33=U33,TRUE,' WP II-I-1.4'!G33-G33) -> TRUE | X33: =U33-F33 -> 0 | Y33: ='WP II-I-1.1'!$G$500=U33 -> TRUE
B34: =B33+1 -> 20 | X34: =U34-F34 -> 0
B35: =B34+1 -> 21 | X35: =U35-F35 -> 0
B36: =B35+1 -> 22 | X36: =U36-F36 -> 0
B37: =B36+1 -> 23 | D37: PROPOSED Revenue | F37: =F33 -> 5.5600926e+09 | J37: =J33 -> 2.730268e+09 | K37: =K33 -> 69767963 | L37: =L33 -> 1.8490396e+09 | M37: =M33 -> 736813.37 | N37: =N33 -> 4.3459515e+08 | O37: =O33 -> 98568914 | P37: =P33 -> 2.7408825e+08 | Q37: =Q33 -> 92687433 | ... S37: =S33 -> 8506147.8 | U37: =SUM(I37:T37) -> 5.5600926e+09 | X37: =U37-F37 -> 0
B38: =B37+1 -> 24 | X38: =U38-F38 -> 0 | Y38: ='WP II-I-2.2'!$P$45 -> 0
B39: =B38+1 -> 25 | D39: PROPOSED Revenue Excl 565 and A928 RCE | F39: =+F37-F645-('WP II-I-2.2'!$P$45)*F776 -> 3.4592512e+09 | J39: =+J37-J645-('WP II-I-2.2'!$P$45)*J776 -> 1.808863e+09 | K39: =+K37-K645-('WP II-I-2.2'!$P$45)*K776 -> 51193085 | L39: =+L37-L645-('WP II-I-2.2'!$P$45)*L776 -> 1.2075801e+09 | M39: =+M37-M645-('WP II-I-2.2'!$P$45)*M776 -> 533883.98 | N39: =+N37-N645-('WP II-I-2.2'!$P$45)*N776 -> 2.3514573e+08 | O39: =+O37-O645-('WP II-I-2.2'!$P$45)*O776 -> 26160818 | P39: =+P37-P645-('WP II-I-2.2'!$P$45)*P776 -> 26746602 | Q39: =+Q37-Q645-('WP II-I-2.2'!$P$45)*Q776 -> 92687433 | ... S39: =+S37-S645-('WP II-I-2.2'!$P$45)*S776 -> 8506147.8 | U39: =SUM(I39:T39) -> 3.4592512e+09 | X39: =U39-F39 -> 0 | Y39: =ROUND('WP II-I-1.1'!$G$500-'WP II-I-1.1'!$G$220-('WP II-I-1.1'!$G$279*'WP II-I-2.2'!$P$45),0)-U39 -> 0.40673065
W40: =U39-F39 -> 0 | X40: =U40-F40 -> 0
V41: =$H$2 -> 0
B42: =+$B$4 -> 2025 RATE CASE | X42: =U42-F42 -> 0
B43: =+$B$5 -> ONCOR ELECTRIC DELIVERY COMPANY LLC | X43: =U43-F43 -> 0
B44: =+$B$6 -> II-I-1-DIST: CLASS REVENUE REQUIREMENT | X44: =U44-F44 -> 0
B45: =+$B$7 -> TEST YEAR ENDING 12/31/2024 | X45: =U45-F45 -> 0
...

Sheet II-I-MET
B4: ='WP II-I-1.1'!B3 -> 2025 RATE CASE
B5: ='WP II-I-1.1'!B4 -> ONCOR ELECTRIC DELIVERY COMPANY LLC
B6: ="II-I-1-MET: CLASS REVENUE REQUIREMENT" -> II-I-1-MET: CLASS REVENUE REQUIREMENT
B7: ='WP II-I-1.1'!B6 -> TEST YEAR ENDING 12/31/2024
B8: ='WP II-I-2.2'!$B$7 -> SPONSOR: MATTHEW A. TROXLE
R10: =" "
B11: Line | D11: I-A-1 by Rate Class | E11: Source | F11: MET | J11: Residential | K11: Secondary | L11: Secondary | M11: Primary | N11: Primary | O11: Primary | P11: Transmission | Q11: Lighting | R11: Wholesale | S11: Wholesale | U11: Total
K12: <=10 kW | L12: > 10 kW | M12: <=10 kW | N12: > 10 kW | O12: Substation | R12: XFMR | S12: DLS
F13: (a) | G13: (b) | H13: (c) | J13: (d) | K13: (e) | L13: (f) | M13: (g) | N13: (h) | O13: (i) | P13: (j) | Q13: (k) | R13: (l) | S13: (m) | U13: (n)
B15: =B14+1 -> 1 | D15: O&M Expenses | E15: II-D-2 | F15: =F661+F709 -> 61551893 | J15: =J661+J709 -> 32121019 | K15: =K661+K709 -> 4505538.9 | L15: =L661+L709 -> 17721446 | M15: =M661+M709 -> 746162.92 | N15: =N661+N709 -> 5746710.5 | O15: =O661+O709 -> 188908.74 | P15: =P661+P709 -> 393260.2 | Q15: =Q661+Q709 -> 55113.711 | ... S15: =S661+S709 -> 52887.16 | U15: =SUM(I15:T15) -> 61551893 | W15: =U15-F15 -> 0
B16: =B15+1 -> 2 | D16: Customer Expenses | E16: II-D-2 | F16: =F729+F739+F749 -> 9809696.2 | J16: =J729+J739+J749 -> 5121177.3 | K16: =K729+K739+K749 -> 718411.62 | L16: =L729+L739+L749 -> 2825220.4 | M16: =M729+M739+M749 -> 118975.39 | N16: =N729+N739+N749 -> 916172.16 | O16: =O729+O739+O749 -> 30061.618 | P16: =P729+P739+P749 -> 62705.216 | Q16: =Q729+Q739+Q749 -> 5225.2973 | ... S16: =S729+S739+S749 -> 8427.5014 | U16: =SUM(I16:T16) -> 9809696.2 | W16: =U16-F16 -> 0
B17: =B16+1 -> 3 | D17: A&G Expenses | E17: II-D-2 | F17: =F783 -> 49056190 | J17: =J783 -> 25617232 | K17: =K783 -> 3591351.3 | L17: =L783 -> 14115714 | M17: =M783 -> 594305.55 | N17: =N783 -> 4576748.8 | O17: =O783 -> 150357.56 | P17: =P783 -> 313211.33 | Q17: =Q783 -> 38560.809 | ... S17: =S783 -> 42112.616 | U17: =SUM(I17:T17) -> 49056190 | W17: =U17-F17 -> 0
B18: =B17+1 -> 4 | D18: O&M + Customer + A&G Expenses | F18: =SUM(F15:F17) -> 1.2041778e+08 | J18: =SUM(J15:J17) -> 62859429 | K18: =SUM(K15:K17) -> 8815301.8 | L18: =SUM(L15:L17) -> 34662381 | M18: =SUM(M15:M17) -> 1459443.9 | N18: =SUM(N15:N17) -> 11239632 | O18: =SUM(O15:O17) -> 369327.91 | P18: =SUM(P15:P17) -> 769176.74 | Q18: =SUM(Q15:Q17) -> 98899.817 | ... S18: =SUM(S15:S17) -> 103427.28 | U18: =SUM(I18:T18) -> 1.2041778e+08 | W18: =U18-F18 -> 0 | X18: ='WP II-I-1.1'!$H$495=U18 -> TRUE
B19: =B18+1 -> 5 | W19: =U19-F19 -> 0
B20: =B19+1 -> 6 | D20: Depreciation & Amortization (II-E-1) | E20: II-E-1 | F20: =F1065 -> 29837696 | J20: =J1065 -> 15576574 | K20: =K1065 -> 2185161 | L20: =L1065 -> 8593528.8 | M20: =M1065 -> 361891.15 | N20: =N1065 -> 2786752.9 | O20: =O1065 -> 91439.488 | P20: =P1065 -> 190732.68 | Q20: =Q1065 -> 15883.657 | ... S20: =S1065 -> 25634.228 | U20: =SUM(I20:T20) -> 29837696 | W20: =U20-F20 -> 0
B21: =B20+1 -> 7 | D21: Other (II-E-4) | E21: II-E-4 | F21: =F1067+F1068 -> 25459958 | J21: =J1067+J1068 -> 13291205 | K21: =K1067+K1068 -> 1864557.8 | L21: =L1067+L1068 -> 7332700.4 | M21: =M1067+M1068 -> 308795.08 | N21: =N1067+N1068 -> 2377885.1 | O21: =O1067+O1068 -> 78023.637 | P21: =P1067+P1068 -> 162748.69 | Q21: =Q1067+Q1068 -> 13553.233 | ... S21: =S1067+S1068 -> 21873.216 | U21: =SUM(I21:T21) -> 25459958 | W21: =U21-F21 -> 0
B22: =B21+1 -> 8 | D22: Depreciation, Amortization & Other Expenses | F22: =SUM(F20:F21) -> 55297654 | J22: =SUM(J20:J21) -> 28867779 | K22: =SUM(K20:K21) -> 4049718.7 | L22: =SUM(L20:L21) -> 15926229 | M22: =SUM(M20:M21) -> 670686.22 | N22: =SUM(N20:N21) -> 5164638 | O22: =SUM(O20:O21) -> 169463.13 | P22: =SUM(P20:P21) -> 353481.37 | Q22: =SUM(Q20:Q21) -> 29436.89 | ... S22: =SUM(S20:S21) -> 47507.444 | U22: =SUM(I22:T22) -> 55297654 | W22: =U22-F22 -> 0 | X22: ='WP II-I-1.1'!$H$496=U22 -> TRUE
B23: =B22+1 -> 9 | W23: =U23-F23 -> 0
B24: =B23+1 -> 10 | D24: Taxes Other Than Federal Income Tax | E24: II-E-2 | F24: =+F1103 -> 8908968.6 | J24: =+J1103 -> 4650532.4 | K24: =+K1103 -> 652364.62 | L24: =+L1103 -> 2566000.3 | M24: =+M1103 -> 108037.54 | N24: =+N1103 -> 832005.46 | O24: =+O1103 -> 27294.193 | P24: =+P1103 -> 56980.518 | Q24: =+Q1103 -> 5090.8397 | ... S24: =+S1103 -> 7649.4534 | U24: =SUM(I24:T24) -> 8908968.6 | W24: =U24-F24 -> 0 | X24: ='WP II-I-1.1'!$H$497=U24 -> TRUE
B25: =B24+1 -> 11 | D25: Federal Income Tax | E25: II-E-3 | F25: =+F1162 -> 1780846.8 | J25: =+J1162 -> 929427.38 | K25: =+K1162 -> 130337.52 | L25: =+L1162 -> 513341.73 | M25: =+M1162 -> 21581.42 | N25: =+N1162 -> 166270 | O25: =+O1162 -> 5434.1612 | P25: =+P1162 -> 11447.121 | Q25: =+Q1162 -> 886.91611 | ... S25: =+S1162 -> 1521.5944 | U25: =SUM(I25:T25) -> 1780846.8 | W25: =U25-F25 -> 0 | X25: ='WP II-I-1.1'!$H$498-U25 -> 0
B26: =B25+1 -> 12 | W26: =U26-F26 -> 0
B27: =B26+1 -> 13 | D27: Return on Rate Base | E27: II-B | F27: =+F83 -> 32952956 | J27: =+J83 -> 17198989 | K27: =+K83 -> 2412097.9 | L27: =+L83 -> 9496486.7 | M27: =+M83 -> 399417.7 | N27: =+N83 -> 3076868.4 | O27: =+O83 -> 100681.23 | P27: =+P83 -> 211496.43 | Q27: =+Q83 -> 17617.634 | ... S27: =+S83 -> 28197.472 | U27: =SUM(I27:T27) -> 32952956 | W27: =U27-F27 -> 0 | X27: ='WP II-I-1.1'!$H$494-U27 -> 0
B28: =B27+1 -> 14 | W28: =U28-F28 -> 0
B29: =B28+1 -> 15 | D29: TOTAL COST OF SERVICE | F29: =+F18+F22+F24+F25+F27 -> 2.193582e+08 | J29: =+J18+J22+J24+J25+J27 -> 1.1450616e+08 | K29: =+K18+K22+K24+K25+K27 -> 16059821 | L29: =+L18+L22+L24+L25+L27 -> 63164439 | M29: =+M18+M22+M24+M25+M27 -> 2659166.7 | N29: =+N18+N22+N24+N25+N27 -> 20479413 | O29: =+O18+O22+O24+O25+O27 -> 672200.63 | P29: =+P18+P22+P24+P25+P27 -> 1402582.2 | Q29: =+Q18+Q22+Q24+Q25+Q27 -> 151932.1 | ... S29: =+S18+S22+S24+S25+S27 -> 188303.24 | U29: =SUM(I29:T29) -> 2.193582e+08 | W29: =U29-F29 -> 0 | X29: ='WP II-I-1.1'!$H$509=U29 -> TRUE
B30: =B29+1 -> 16
B31: =B30+1 -> 17 | D31: Minus: Other Revenues | E31: II-E-5 | F31: =+F1222 -> 14115591 | J31: =+J1222 -> 7377787.4 | K31: =+K1222 -> 1034993.5 | L31: =+L1222 -> 4070293.4 | M31: =+M1222 -> 171408.42 | N31: =+N1222 -> 1319935.3 | O31: =+O1222 -> 43309.979 | P31: =+P1222 -> 90339.832 | Q31: =+Q1222 -> 7523.236 | ... S31: =+S1222 -> 0 | U31: =SUM(I31:T31) -> 14115591 | X31: ='WP II-I-1.1'!$H$499=-U31 -> TRUE
B32: =B31+1 -> 18
B33: =B32+1 -> 19 | D33: COST-BASED Revenue Requirement | F33: =+F29-F31 -> 2.0524261e+08 | J33: =+J29-J31 -> 1.0712837e+08 | K33: =+K29-K31 -> 15024827 | L33: =+L29-L31 -> 59094145 | M33: =+M29-M31 -> 2487758.3 | N33: =+N29-N31 -> 19159478 | O33: =+O29-O31 -> 628890.65 | P33: =+P29-P31 -> 1312242.3 | Q33: =+Q29-Q31 -> 144408.86 | ... S33: =+S29-S31 -> 188303.24 | U33: =SUM(I33:T33) -> 2.0524261e+08 | W33: =IF(ROUND(U33-'WP II-I-1.1'!H500,2)=0,TRUE,U33-'WP II-I-1.1'!H500) -> TRUE | X33: ='WP II-I-1.1'!$H$500=U33 -> TRUE
B42: =+$B$4 -> 2025 RATE CASE
B43: =+$B$5 -> ONCOR ELECTRIC DELIVERY COMPANY LLC
B44: =+$B$6 -> II-I-1-MET: CLASS REVENUE REQUIREMENT
B45: =+$B$7 -> TEST YEAR ENDING 12/31/2024
B46: =+$B$8 -> SPONSOR: MATTHEW A. TROXLE
R48: =R$10
B49: Line | D49: II-B by Rate Class | E49: Source | F49: =F$11 -> MET | J49: Residential | K49: Secondary | L49: Secondary | M49: Primary | N49: Primary | O49: Primary | P49: Transmission | Q49: Lighting | R49: =R$11 -> Wholesale | S49: =S$11 -> Wholesale | U49: Total
K50: <=10 kW | L50: > 10 kW | M50: <=10 kW | N50: > 10 kW | O50: Substation | R50: =R$12 -> XFMR | S50: =S$12 -> DLS
F51: (a) | G51: (b) | H51: (c) | J51: =J$13 -> (d) | K51: =K$13 -> (e) | L51: =L$13 -> (f) | M51: =M$13 -> (g) | N51: =N$13 -> (h) | O51: =O$13 -> (i) | P51: =P$13 -> (j) | Q51: =Q$13 -> (k) | ... S51: =S$13 -> (m) | U51: (n)
B53: =B52+1 -> 1 | D53: Intangible Plant: Original Cost | E53: II-B-1 | F53: =F106 -> 324360 | J53: =J106 -> 169330.02 | K53: =K106 -> 23754.475 | L53: =L106 -> 93418.641 | M53: =M106 -> 3934.0509 | N53: =N106 -> 30294.268 | O53: =O106 -> 994.02154 | P53: =P106 -> 2073.4192 | Q53: =Q106 -> 172.66826 | ... S53: =S106 -> 278.66489 | U53: =SUM(I53:T53) -> 324360 | W53: =U53-F53 -> 0
B54: =B53+1 -> 2 | D54: Transmission Plant: Original Cost | E54: II-B-1 | F54: =F121 -> 0 | J54: =J121 -> 0 | K54: =K121 -> 0 | L54: =L121 -> 0 | M54: =M121 -> 0 | N54: =N121 -> 0 | O54: =O121 -> 0 | P54: =P121 -> 0 | Q54: =Q121 -> 0 | ... S54: =S121 -> 0 | U54: =SUM(I54:T54) -> 0 | W54: =U54-F54 -> 0
B55: =B54+1 -> 3 | D55: Distribution Plant: Original Cost | E55: II-B-1 | F55: =F159 -> 7.8498359e+08 | J55: =J159 -> 4.0979556e+08 | K55: =K159 -> 57488203 | L55: =L159 -> 2.2608244e+08 | M55: =M159 -> 9520796 | N55: =N159 -> 73315155 | O55: =O159 -> 2405631.4 | P55: =P159 -> 5017881.5 | Q55: =Q159 -> 417874.44 | ... S55: =S159 -> 674396.86 | U55: =SUM(I55:T55) -> 7.8498359e+08 | W55: =U55-F55 -> 0
...

Sheet II-I-TBILLTDCS
B4: ='WP II-I-1.1'!B3 -> 2025 RATE CASE
B5: ='WP II-I-1.1'!B4 -> ONCOR ELECTRIC DELIVERY COMPANY LLC
B6: ="II-I-1-TBILLTDCS: CLASS REVENUE REQUIREMENT" -> II-I-1-TBILLTDCS: CLASS REVENUE REQUIREMENT
B7: ='WP II-I-1.1'!B6 -> TEST YEAR ENDING 12/31/2024
B8: ='WP II-I-2.2'!$B$7 -> SPONSOR: MATTHEW A. TROXLE
R10: =" "
B11: Line | D11: I-A-1 by Rate Class | E11: Source | F11: TBILLTDCS | J11: Residential | K11: Secondary | L11: Secondary | M11: Primary | N11: Primary | O11: Primary | P11: Transmission | Q11: Lighting | R11: Wholesale | S11: Wholesale | U11: Total
K12: <=10 kW | L12: > 10 kW | M12: <=10 kW | N12: > 10 kW | O12: Substation | R12: XFMR | S12: DLS
F13: (a) | G13: (b) | H13: (c) | J13: (d) | K13: (e) | L13: (f) | M13: (g) | N13: (h) | O13: (i) | P13: (j) | Q13: (k) | R13: (l) | S13: (m) | U13: (n)
B15: =B14+1 -> 1 | D15: O&M Expenses | E15: II-D-2 | F15: =F661+F709 -> 189681.03 | J15: =J661+J709 -> 27.5612 | K15: =K661+K709 -> 0.52070457 | L15: =L661+L709 -> 17.702675 | M15: =M661+M709 -> 0.0082838025 | N15: =N661+N709 -> 5.2070912 | O15: =O661+O709 -> 2.2381103 | P15: =P661+P709 -> 0 | Q15: =Q661+Q709 -> 189627.44 | ... S15: =S661+S709 -> 0.19979739 | U15: =SUM(I15:T15) -> 189681.03 | W15: =F15-U15 -> 0
B16: =B15+1 -> 2 | D16: Customer Expenses | E16: II-D-2 | F16: =F729+F739+F749 -> 17097126 | J16: =J729+J739+J749 -> 8911343.2 | K16: =K729+K739+K749 -> 1100131.8 | L16: =L729+L739+L749 -> 5033112.3 | M16: =M729+M739+M749 -> 173119.83 | N16: =N729+N739+N749 -> 1530953.5 | O16: =O729+O739+O749 -> 85191.227 | P16: =P729+P739+P749 -> 202491.26 | Q16: =Q729+Q739+Q749 -> 43791.364 | ... S16: =S729+S739+S749 -> 12190.098 | U16: =SUM(I16:T16) -> 17097126 | W16: =F16-U16 -> 0
B17: =B16+1 -> 3 | D17: A&G Expenses | E17: II-D-2 | F17: =F783 -> 40849532 | J17: =J783 -> 21221743 | K17: =K783 -> 2605710 | L17: =L783 -> 11764409 | M17: =M783 -> 404946.71 | N17: =N783 -> 3572683.2 | O17: =O783 -> 197893.07 | P17: =P783 -> 469983.12 | Q17: =Q783 -> 572452.8 | ... S17: =S783 -> 28488.566 | U17: =SUM(I17:T17) -> 40849532 | W17: =F17-U17 -> 0
B18: =B17+1 -> 4 | D18: O&M + Customer + A&G Expenses | F18: =SUM(F15:F17) -> 58136339 | J18: =SUM(J15:J17) -> 30133114 | K18: =SUM(K15:K17) -> 3705842.3 | L18: =SUM(L15:L17) -> 16797539 | M18: =SUM(M15:M17) -> 578066.54 | N18: =SUM(N15:N17) -> 5103641.9 | O18: =SUM(O15:O17) -> 283086.53 | P18: =SUM(P15:P17) -> 672474.38 | Q18: =SUM(Q15:Q17) -> 805871.61 | ... S18: =SUM(S15:S17) -> 40678.863 | U18: =SUM(I18:T18) -> 58136339 | V18: ='WP II-I-1.1'!$I$495=U18 -> TRUE | W18: =F18-U18 -> 0
B19: =B18+1 -> 5 | W19: =F19-U19 -> 0
B20: =B19+1 -> 6 | D20: Depreciation & Amortization (II-E-1) | E20: II-E-1 | F20: =F1065 -> 39993574 | J20: =J1065 -> 19713789 | K20: =K1065 -> 2750719.8 | L20: =L1065 -> 10750843 | M20: =M1065 -> 452236.06 | N20: =N1065 -> 3481177.1 | O20: =O1065 -> 114220.05 | P20: =P1065 -> 238250.4 | Q20: =Q1065 -> 2447703.8 | ... S20: =S1065 -> 32021.021 | U20: =SUM(I20:T20) -> 39993573 | W20: =F20-U20 -> 0
B21: =B20+1 -> 7 | D21: Other (II-E-4) | E21: II-E-4 | F21: =F1067+F1068 -> 0 | J21: =J1067+J1068 -> 0 | K21: =K1067+K1068 -> 0 | L21: =L1067+L1068 -> 0 | M21: =M1067+M1068 -> 0 | N21: =N1067+N1068 -> 0 | O21: =O1067+O1068 -> 0 | P21: =P1067+P1068 -> 0 | Q21: =Q1067+Q1068 -> 0 | ... S21: =S1067+S1068 -> 0 | U21: =SUM(I21:T21) -> 0 | W21: =F21-U21 -> 0
B22: =B21+1 -> 8 | D22: Depreciation, Amortization & Other Expenses | F22: =SUM(F20:F21) -> 39993574 | J22: =SUM(J20:J21) -> 19713789 | K22: =SUM(K20:K21) -> 2750719.8 | L22: =SUM(L20:L21) -> 10750843 | M22: =SUM(M20:M21) -> 452236.06 | N22: =SUM(N20:N21) -> 3481177.1 | O22: =SUM(O20:O21) -> 114220.05 | P22: =SUM(P20:P21) -> 238250.4 | Q22: =SUM(Q20:Q21) -> 2447703.8 | ... S22: =SUM(S20:S21) -> 32021.021 | U22: =SUM(I22:T22) -> 39993573 | V22: ='WP II-I-1.1'!$I$496=U22 -> TRUE | W22: =F22-U22 -> 0
B23: =B22+1 -> 9 | W23: =F23-U23 -> 0
B24: =B23+1 -> 10 | D24: Taxes Other Than Federal Income Tax | E24: II-E-2 | F24: =+F1103 -> 3557512.7 | J24: =+J1103 -> 1755406.2 | K24: =+K1103 -> 244120.54 | L24: =+L1103 -> 958581.12 | M24: =+M1103 -> 40091.561 | N24: =+N1103 -> 309761.07 | O24: =+O1103 -> 10363.499 | P24: =+P1103 -> 21865.027 | Q24: =+Q1103 -> 213393.03 | ... S24: =+S1103 -> 2819.1681 | U24: =SUM(I24:T24) -> 3557512.7 | V24: ='WP II-I-1.1'!$I$497-U24 -> 0 | W24: =F24-U24 -> 0
B25: =B24+1 -> 11 | D25: Federal Income Tax | E25: II-E-3 | F25: =+F1162 -> 2876698.2 | J25: =+J1162 -> 1412861.3 | K25: =+K1162 -> 198475.47 | L25: =+L1162 -> 769974.22 | M25: =+M1162 -> 32705.505 | N25: =+N1162 -> 249979.64 | O25: =+O1162 -> 7879.6009 | P25: =+P1162 -> 16607.117 | Q25: =+Q1162 -> 185104.67 | ... S25: =+S1162 -> 2228.8905 | U25: =SUM(I25:T25) -> 2876698.2 | V25: ='WP II-I-1.1'!$I$498-U25 -> 0 | W25: =F25-U25 -> 0
B26: =B25+1 -> 12 | W26: =F26-U26 -> 0
B27: =B26+1 -> 13 | D27: Return on Rate Base | E27: II-B | F27: =+F83 -> 17186005 | J27: =+J83 -> 8471555.4 | K27: =+K83 -> 1178975.1 | L27: =+L83 -> 4629669 | M27: =+M83 -> 193678.98 | N27: =+N83 -> 1495538.9 | O27: =+O83 -> 49840.5 | P27: =+P83 -> 106709.79 | Q27: =+Q83 -> 1041574.9 | ... S27: =+S83 -> 13230.338 | U27: =SUM(I27:T27) -> 17186005 | V27: =ROUND('WP II-I-1.1'!$I$494,0)=ROUND(U27,0) -> TRUE | W27: =F27-U27 -> 0
B28: =B27+1 -> 14 | W28: =F28-U28 -> 0
B29: =B28+1 -> 15 | D29: TOTAL COST OF SERVICE | F29: =+F18+F22+F24+F25+F27 -> 1.2175013e+08 | J29: =+J18+J22+J24+J25+J27 -> 61486726 | K29: =+K18+K22+K24+K25+K27 -> 8078133.2 | L29: =+L18+L22+L24+L25+L27 -> 33906606 | M29: =+M18+M22+M24+M25+M27 -> 1296778.6 | N29: =+N18+N22+N24+N25+N27 -> 10640099 | O29: =+O18+O22+O24+O25+O27 -> 465390.18 | P29: =+P18+P22+P24+P25+P27 -> 1055906.7 | Q29: =+Q18+Q22+Q24+Q25+Q27 -> 4693648 | ... S29: =+S18+S22+S24+S25+S27 -> 90978.282 | U29: =SUM(I29:T29) -> 1.2175013e+08 | V29: ='WP II-I-1.1'!$I$509=U29 -> TRUE | W29: =F29-U29 -> 0
B30: =B29+1 -> 16
B31: =B30+1 -> 17 | D31: Minus: Other Revenues | E31: II-E-5 | F31: =+F1222 -> 85782 | J31: =+J1222 -> 73406.182 | K31: =+K1222 -> 6088.8709 | L31: =+L1222 -> 4974.9858 | M31: =+M1222 -> 66.470538 | N31: =+N1222 -> 148.80071 | O31: =+O1222 -> 3.4560439 | P31: =+P1222 -> 7.208926 | Q31: =+Q1222 -> 1086.0247 | ... S31: =+S1222 -> 0 | U31: =SUM(I31:T31) -> 85782 | V31: ='WP II-I-1.1'!$I$499=-U31 -> TRUE | W31: =F31-U31 -> 0
B32: =B31+1 -> 18
B33: =B32+1 -> 19 | D33: COST-BASED Revenue Requirement | F33: =+F29-F31 -> 1.2166435e+08 | J33: =+J29-J31 -> 61413320 | K33: =+K29-K31 -> 8072044.4 | L33: =+L29-L31 -> 33901631 | M33: =+M29-M31 -> 1296712.2 | N33: =+N29-N31 -> 10639950 | O33: =+O29-O31 -> 465386.72 | P33: =+P29-P31 -> 1055899.5 | Q33: =+Q29-Q31 -> 4692562 | ... S33: =+S29-S31 -> 90978.282 | U33: =SUM(I33:T33) -> 1.2166435e+08 | V33: ='WP II-I-1.1'!$I$500=U33 -> TRUE | W33: =F33-U33 -> 0
V41: =$H$2 -> 0
B42: =+$B$4 -> 2025 RATE CASE
B43: =+$B$5 -> ONCOR ELECTRIC DELIVERY COMPANY LLC
B44: =+$B$6 -> II-I-1-TBILLTDCS: CLASS REVENUE REQUIREMENT
B45: =+$B$7 -> TEST YEAR ENDING 12/31/2024
B46: =+$B$8 -> SPONSOR: MATTHEW A. TROXLE
R48: =R$10
B49: Line | D49: II-B by Rate Class | E49: Source | F49: =F$11 -> TBILLTDCS | J49: Residential | K49: Secondary | L49: Secondary | M49: Primary | N49: Primary | O49: Primary | P49: Transmission | Q49: Lighting | R49: =R$11 -> Wholesale | S49: =S$11 -> Wholesale | U49: Total
K50: <=10 kW | L50: > 10 kW | M50: <=10 kW | N50: > 10 kW | O50: Substation | R50: =R$12 -> XFMR | S50: =S$12 -> DLS
F51: (a) | G51: (b) | H51: (c) | J51: =J$13 -> (d) | K51: =K$13 -> (e) | L51: =L$13 -> (f) | M51: =M$13 -> (g) | N51: =N$13 -> (h) | O51: =O$13 -> (i) | P51: =P$13 -> (j) | Q51: =Q$13 -> (k) | ... S51: =S$13 -> (m) | U51: (n)
B53: =B52+1 -> 1 | D53: Intangible Plant: Original Cost | E53: II-B-1 | F53: =F106 -> 145326 | J53: =J106 -> 71634.663 | K53: =K106 -> 9995.3835 | L53: =L106 -> 39065.7 | M53: =M106 -> 1643.3054 | N53: =N106 -> 12649.671 | O53: =O106 -> 415.04525 | P53: =P106 -> 865.73855 | Q53: =Q106 -> 8894.304 | ... S53: =S106 -> 116.35587 | U53: =SUM(I53:T53) -> 145326 | W53: =F53-U53 -> 0
B54: =B53+1 -> 2 | D54: Transmission Plant: Original Cost | E54: II-B-1 | F54: =F121 -> 0 | J54: =J121 -> 0 | K54: =K121 -> 0 | L54: =L121 -> 0 | M54: =M121 -> 0 | N54: =N121 -> 0 | O54: =O121 -> 0 | P54: =P121 -> 0 | Q54: =Q121 -> 0 | ... S54: =S121 -> 0 | U54: =SUM(I54:T54) -> 0 | W54: =F54-U54 -> 0
...

Sheet II-I-Total
B4: ='WP II-I-1.1'!B3 -> 2025 RATE CASE
B5: ='WP II-I-1.1'!B4 -> ONCOR ELECTRIC DELIVERY COMPANY LLC
B6: ="II-I-1-TOT: CLASS REVENUE REQUIREMENT" -> II-I-1-TOT: CLASS REVENUE REQUIREMENT
B7: ='WP II-I-1.1'!B6 -> TEST YEAR ENDING 12/31/2024
B8: ='WP II-I-2.2'!$B$7 -> SPONSOR: MATTHEW A. TROXLE
R10: =" "
B11: Line | D11: I-A-1 by Rate Class | E11: Source | F11: TOTAL | J11: Residential | K11: Secondary | L11: Secondary | M11: Primary | N11: Primary | O11: Primary | P11: Transmission | Q11: Lighting | R11: Wholesale | S11: Wholesale | U11: Total
F12: (Dist+Met+Cust) | K12: <=10 kW | L12: > 10 kW | M12: <=10 kW | N12: > 10 kW | O12: Substation | R12: XFMR | S12: DLS
F13: (a) | G13: (b) | H13: (c) | J13: (d) | K13: (e) | L13: (f) | M13: (g) | N13: (h) | O13: (i) | P13: (j) | Q13: (k) | R13: (l) | S13: (m) | U13: (n)
B15: =B14+1 -> 1 | D15: O&M Expenses | E15: II-D-2 | F15: =F661+F709 -> 2.5275875e+09 | J15: =J661+J709 -> 1.1447022e+09 | K15: =K661+K709 -> 27263658 | L15: =L661+L709 -> 7.8154775e+08 | M15: =M661+M709 -> 1106142.9 | N15: =N661+N709 -> 2.3602042e+08 | O15: =O661+O709 -> 75637226 | P15: =P661+P709 -> 2.4782015e+08 | Q15: =Q661+Q709 -> 12057528 | ... S15: =S661+S709 -> 1203312.4 | U15: =SUM(I15:T15) -> 2.5275875e+09 | X15: =U15-F15 -> 0
B16: =B15+1 -> 2 | D16: Customer Expenses | E16: II-D-2 | F16: =F729+F739+F749 -> 27246613 | J16: =J729+J739+J749 -> 14287295 | K16: =K729+K739+K749 -> 1842904.8 | L16: =L729+L739+L749 -> 7902847.7 | M16: =M729+M739+M749 -> 293583.11 | N16: =N729+N739+N749 -> 2457601.6 | O16: =O729+O739+O749 -> 115592.73 | P16: =P729+P739+P749 -> 265905.43 | Q16: =Q729+Q739+Q749 -> 52010.354 | ... S16: =S729+S739+S749 -> 20713.243 | U16: =SUM(I16:T16) -> 27246613 | X16: =U16-F16 -> 0
B17: =B16+1 -> 3 | D17: A&G Expenses | E17: II-D-2 | F17: =F783 -> 9.521598e+08 | J17: =J783 -> 5.0670158e+08 | K17: =K783 -> 19570559 | L17: =L783 -> 3.1764053e+08 | M17: =M783 -> 1182166.6 | N17: =N783 -> 67813802 | O17: =O783 -> 6732790.1 | P17: =P783 -> 1608655 | Q17: =Q783 -> 28111812 | ... S17: =S783 -> 2331600 | U17: =SUM(I17:T17) -> 9.521598e+08 | X17: =U17-F17 -> 0
B18: =B17+1 -> 4 | D18: O&M + Customer + A&G Expenses | F18: =SUM(F15:F17) -> 3.5069939e+09 | J18: =SUM(J15:J17) -> 1.6656911e+09 | K18: =SUM(K15:K17) -> 48677123 | L18: =SUM(L15:L17) -> 1.1070911e+09 | M18: =SUM(M15:M17) -> 2581892.6 | N18: =SUM(N15:N17) -> 3.0629183e+08 | O18: =SUM(O15:O17) -> 82485609 | P18: =SUM(P15:P17) -> 2.4969471e+08 | Q18: =SUM(Q15:Q17) -> 40221350 | ... S18: =SUM(S15:S17) -> 3555625.7 | U18: =SUM(I18:T18) -> 3.5069939e+09 | W18: =' WP II-I-1.4'!$L$18=F18 -> TRUE | X18: =U18-F18 -> 0
B19: =B18+1 -> 5 | X19: =U19-F19 -> 0
B20: =B19+1 -> 6 | D20: Depreciation & Amortization (II-E-1) | E20: II-E-1 | F20: =F1065 -> 7.2124832e+08 | J20: =J1065 -> 3.7990451e+08 | K20: =K1065 -> 16812128 | L20: =L1065 -> 2.3668658e+08 | M20: =M1065 -> 877378.61 | N20: =N1065 -> 46026943 | O20: =O1065 -> 3937327.1 | P20: =P1065 -> 1076356.2 | Q20: =Q1065 -> 34063217 | ... S20: =S1065 -> 1583218.6 | U20: =SUM(I20:T20) -> 7.2124832e+08 | X20: =U20-F20 -> 0
B21: =B20+1 -> 7 | D21: Other (II-E-4) | E21: II-E-4 | F21: =F1067+F1068 -> 40888584 | J21: =J1067+J1068 -> 21708789 | K21: =K1067+K1068 -> 2087379.3 | L21: =L1067+L1068 -> 12691736 | M21: =M1067+M1068 -> 310409.68 | N21: =N1067+N1068 -> 3392803.1 | O21: =O1067+O1068 -> 196612.67 | P21: =P1067+P1068 -> 182763.61 | Q21: =Q1067+Q1068 -> 240460.8 | ... S21: =S1067+S1068 -> 60815.875 | U21: =SUM(I21:T21) -> 40888584 | X21: =U21-F21 -> 0
B22: =B21+1 -> 8 | D22: Depreciation, Amortization & Other Expenses | F22: =SUM(F20:F21) -> 7.6213691e+08 | J22: =SUM(J20:J21) -> 4.016133e+08 | K22: =SUM(K20:K21) -> 18899507 | L22: =SUM(L20:L21) -> 2.4937832e+08 | M22: =SUM(M20:M21) -> 1187788.3 | N22: =SUM(N20:N21) -> 49419746 | O22: =SUM(O20:O21) -> 4133939.8 | P22: =SUM(P20:P21) -> 1259119.8 | Q22: =SUM(Q20:Q21) -> 34303678 | ... S22: =SUM(S20:S21) -> 1644034.4 | U22: =SUM(I22:T22) -> 7.6213691e+08 | W22: =' WP II-I-1.4'!$L$22=F22 -> TRUE | X22: =U22-F22 -> 0
B23: =B22+1 -> 9 | X23: =U23-F23 -> 0
B24: =B23+1 -> 10 | D24: Taxes Other Than Federal Income Tax | E24: II-E-2 | F24: =+F1103 -> 4.9498676e+08 | J24: =+J1103 -> 2.2223392e+08 | K24: =+K1103 -> 7470560.3 | L24: =+L1103 -> 1.9103386e+08 | M24: =+M1103 -> 174043.73 | N24: =+N1103 -> 33593410 | O24: =+O1103 -> 5306944 | P24: =+P1103 -> 27571464 | Q24: =+Q1103 -> 6397694.4 | ... S24: =+S1103 -> 810743.42 | U24: =SUM(I24:T24) -> 4.9498676e+08 | W24: =' WP II-I-1.4'!$L$24=F24 -> TRUE | X24: =U24-F24 -> 0
B25: =B24+1 -> 11 | D25: Federal Income Tax | E25: II-E-3 | F25: =+F1162 -> 1.4473902e+08 | J25: =+J1162 -> 78668226 | K25: =+K1162 -> 2333594.4 | L25: =+L1162 -> 50108868 | M25: =+M1162 -> 68143.324 | N25: =+N1162 -> 9622190.5 | O25: =+O1162 -> 1093406.3 | P25: =+P1162 -> 303017.14 | Q25: =+Q1162 -> 2109357.1 | ... S25: =+S1162 -> 355506.44 | U25: =SUM(I25:T25) -> 1.4473902e+08 | W25: =' WP II-I-1.4'!$L$25-F25 -> 0 | X25: =U25-F25 -> 0
B26: =B25+1 -> 12 | X26: =U26-F26 -> 0
B27: =B26+1 -> 13 | D27: Return on Rate Base | E27: II-B | F27: =+F83 -> 1.0591573e+09 | J27: =+J83 -> 5.7528199e+08 | K27: =+K83 -> 18004272 | L27: =+L83 -> 3.6570944e+08 | M27: =+M83 -> 698376.14 | N27: =+N83 -> 71151671 | O27: =+O83 -> 7977532.6 | P27: =+P83 -> 2278161.3 | Q27: =+Q83 -> 14910476 | ... S27: =+S83 -> 2584084.4 | U27: =SUM(I27:T27) -> 1.0591573e+09 | W27: =' WP II-I-1.4'!$L$27=F27 -> TRUE | X27: =U27-F27 -> 0
B28: =B27+1 -> 14 | X28: =U28-F28 -> 0
B29: =B28+1 -> 15 | D29: TOTAL COST OF SERVICE | F29: =+F18+F22+F24+F25+F27 -> 5.9680139e+09 | J29: =+J18+J22+J24+J25+J27 -> 2.9434885e+09 | K29: =+K18+K22+K24+K25+K27 -> 95385056 | L29: =+L18+L22+L24+L25+L27 -> 1.9633216e+09 | M29: =+M18+M22+M24+M25+M27 -> 4710244 | N29: =+N18+N22+N24+N25+N27 -> 4.7007885e+08 | O29: =+O18+O22+O24+O25+O27 -> 1.0099743e+08 | P29: =+P18+P22+P24+P25+P27 -> 2.8110647e+08 | Q29: =+Q18+Q22+Q24+Q25+Q27 -> 97942555 | ... S29: =+S18+S22+S24+S25+S27 -> 8949994.4 | U29: =SUM(I29:T29) -> 5.9680139e+09 | W29: =' WP II-I-1.4'!$L$29-F29 -> 0 | X29: =U29-F29 -> 0
B30: =B29+1 -> 16 | X30: =U30-F30 -> 0
B31: =B30+1 -> 17 | D31: Minus: Other Revenues | E31: II-E-5 | F31: =+F1222 -> 81014329 | J31: =+J1222 -> 44678854 | K31: =+K1222 -> 2520222.3 | L31: =+L1222 -> 21286205 | M31: =+M1222 -> 188960.18 | N31: =+N1222 -> 5684264 | O31: =+O1222 -> 1334239.9 | P31: =+P1222 -> 4650081.3 | Q31: =+Q1222 -> 418151.09 | ... S31: =+S1222 -> 164565.08 | U31: =SUM(I31:T31) -> 81014329 | W31: =' WP II-I-1.4'!$L$31=F31 -> TRUE | X31: =U31-F31 -> 0
B32: =B31+1 -> 18 | X32: =U32-F32 -> 0
B33: =B32+1 -> 19 | D33: COST_BASED Revenue Requirement | F33: =+F29-F31 -> 5.8869996e+09 | J33: =+J29-J31 -> 2.8988097e+09 | K33: =+K29-K31 -> 92864834 | L33: =+L29-L31 -> 1.9420354e+09 | M33: =+M29-M31 -> 4521283.9 | N33: =+N29-N31 -> 4.6439458e+08 | O33: =+O29-O31 -> 99663191 | P33: =+P29-P31 -> 2.7645639e+08 | Q33: =+Q29-Q31 -> 97524404 | ... S33: =+S29-S31 -> 8785429.3 | U33: =SUM(I33:T33) -> 5.8869996e+09 | W33: =' WP II-I-1.4'!$L$33-F33 -> 0 | X33: =U33-F33 -> 0
B34: =B33+1 -> 20 | X34: =U34-F34 -> 0
B35: =B34+1 -> 21 | X35: =U35-F35 -> 0
B36: =B35+1 -> 22 | X36: =U36-F36 -> 0
B37: =B36+1 -> 23 | D37: PROPOSED Revenue | F37: =F33 -> 5.8869996e+09 | J37: =J33 -> 2.8988097e+09 | K37: =K33 -> 92864834 | L37: =L33 -> 1.9420354e+09 | M37: =M33 -> 4521283.9 | N37: =N33 -> 4.6439458e+08 | O37: =O33 -> 99663191 | P37: =P33 -> 2.7645639e+08 | Q37: =Q33 -> 97524404 | ... S37: =S33 -> 8785429.3 | U37: =SUM(I37:T37) -> 5.8869996e+09 | X37: =U37-F37 -> 0
B38: =B37+1 -> 24 | X38: =U38-F38 -> 0
B39: =B38+1 -> 25 | D39: PROPOSED Revenue Excl 565 & RCE A928 | F39: =+F37-F645-('II-I-DIST'!F776*('WP II-I-2.2'!$P$45)) -> 3.7861581e+09 | J39: =+J37-J645-('II-I-DIST'!J776*('WP II-I-2.2'!$P$45)) -> 1.9774047e+09 | K39: =+K37-K645-('II-I-DIST'!K776*('WP II-I-2.2'!$P$45)) -> 74289957 | L39: =+L37-L645-('II-I-DIST'!L776*('WP II-I-2.2'!$P$45)) -> 1.3005759e+09 | M39: =+M37-M645-('II-I-DIST'!M776*('WP II-I-2.2'!$P$45)) -> 4318354.5 | N39: =+N37-N645-('II-I-DIST'!N776*('WP II-I-2.2'!$P$45)) -> 2.6494516e+08 | O39: =+O37-O645-('II-I-DIST'!O776*('WP II-I-2.2'!$P$45)) -> 27255096 | P39: =+P37-P645-('II-I-DIST'!P776*('WP II-I-2.2'!$P$45)) -> 29114744 | Q39: =+Q37-Q645-('II-I-DIST'!Q776*('WP II-I-2.2'!$P$45)) -> 97524404 | ... S39: =+S37-S645-('II-I-DIST'!S776*('WP II-I-2.2'!$P$45)) -> 8785429.3 | U39: =SUM(I39:T39) -> 3.7861581e+09 | W39: ='II-I-DIST'!$J$39+'II-I-MET'!$J$33+'II-I-TBILLTDCS'!$J$33-J39 -> 0 | X39: =U39-F39 -> 0
X40: =U40-F40 -> 0
B42: =+$B$4 -> 2025 RATE CASE | X42: =U42-F42 -> 0
B43: =+$B$5 -> ONCOR ELECTRIC DELIVERY COMPANY LLC | X43: =U43-F43 -> 0
B44: =+$B$6 -> II-I-1-TOT: CLASS REVENUE REQUIREMENT | X44: =U44-F44 -> 0
B45: =+$B$7 -> TEST YEAR ENDING 12/31/2024 | X45: =U45-F45 -> 0
