Workbook

Sheet Base35
B1: PUC DOCKET NO.
B2: ONCOR ELECTRIC DELIVERY
B3: WEATHER STATION DATA
B4: FOR THE TEST YEAR ENDING DECEMBER 31, 2007
B6: SPONSOR: G. L. GOBLE
B9: Calendar Actual Heating Degree Days by Weather Sites (Base 35)
A10: Line No. | C10: Metroplex (MX) | D10: Lufkin (LU) | E10: Austin (AU) | F10: Killeen (KI) | G10: Longview (LO) | H10: Waco (WO) | I10: Abilene (AE) | J10: Wichita Falls (WF) | K10: Midland/ Odessa (MO) | L10: Denison (DE)
A11: 1 | B11: 39083 | C11: 22.749999 | D11: 7.38 | E11: 11.33333 | F11: 18.33 | G11: 14.24 | H11: 16.625 | I11: 47.24 | J11: 42.29 | K11: 54.03 | L11: 41.32
A12: 2 | B12: 39114 | C12: 14.958333 | D12: 3.5 | E12: 1.375 | F12: 10.83 | G12: 9.88 | H12: 6.875 | I12: 25.25 | J12: 27.71 | K12: 14.24 | L12: 29.95
A13: 3 | B13: 39142 | C13: 0 | D13: 0 | E13: 0 | F13: 0 | G13: 0 | H13: 0 | I13: 0 | J13: 0 | K13: 0 | L13: 0
A14: 4 | B14: 39173 | C14: 0 | D14: 0 | E14: 0 | F14: 0 | G14: 0 | H14: 0 | I14: 3.37 | J14: 0 | K14: 6.66 | L14: 0
A15: 5 | B15: 39203 | C15: 0 | D15: 0 | E15: 0 | F15: 0 | G15: 0 | H15: 0 | I15: 0 | J15: 0 | K15: 0 | L15: 0
A16: 6 | B16: 39234 | C16: 0 | D16: 0 | E16: 0 | F16: 0 | G16: 0 | H16: 0 | I16: 0 | J16: 0 | K16: 0 | L16: 0
A17: 7 | B17: 39264 | C17: 0 | D17: 0 | E17: 0 | F17: 0 | G17: 0 | H17: 0 | I17: 0 | J17: 0 | K17: 0 | L17: 0
A18: 8 | B18: 39295 | C18: 0 | D18: 0 | E18: 0 | F18: 0 | G18: 0 | H18: 0 | I18: 0 | J18: 0 | K18: 0 | L18: 0
A19: 9 | B19: 39326 | C19: 0 | D19: 0 | E19: 0 | F19: 0 | G19: 0 | H19: 0 | I19: 0 | J19: 0 | K19: 0 | L19: 0
A20: 10 | B20: 39356 | C20: 0 | D20: 0 | E20: 0 | F20: 0 | G20: 0 | H20: 0 | I20: 0 | J20: 0 | K20: 0 | L20: 0
A21: 11 | B21: 39387 | C21: 0 | D21: 0 | E21: 0 | F21: 0 | G21: 0 | H21: 0 | I21: 4.12 | J21: 0 | K21: 7.41 | L21: 0
A22: 12 | B22: 39417 | C22: 0 | D22: 0 | E22: 0 | F22: 0 | G22: 0 | H22: 0 | I22: 3.38 | J22: 6.25 | K22: 2.37 | L22: 1.29
A23: 13 | B23: Annual | C23: =SUM(C11:C22) -> 37.708332 | D23: =SUM(D11:D22) -> 10.88 | E23: =SUM(E11:E22) -> 12.70833 | F23: =SUM(F11:F22) -> 29.16 | G23: =SUM(G11:G22) -> 24.12 | H23: =SUM(H11:H22) -> 23.5 | I23: =SUM(I11:I22) -> 83.36 | J23: =SUM(J11:J22) -> 76.25 | ... L23: =SUM(L11:L22) -> 72.56
A24: 14
A25: 15 | B25: Calendar Actual Cooling Degree Days by Weather Sites (Base 35)
A26: 16 | C26: Metroplex (MX) | D26: Lufkin (LU) | E26: Austin (AU) | F26: Killeen (KI) | G26: Longview (LO) | H26: Waco (WO) | I26: Abilene (AE) | J26: Wichita Falls (WF) | K26: Midland/ Odessa (MO) | L26: Denison (DE)
A27: 17 | B27: 39083
A28: 18 | B28: 39114
A29: 19 | B29: 39142
A30: 20 | B30: 39173
A31: 21 | B31: 39203
A32: 22 | B32: 39234
A33: 23 | B33: 39264
A34: 24 | B34: 39295
A35: 25 | B35: 39326
A36: 26 | B36: 39356
A37: 27 | B37: 39387
A38: 28 | B38: 39417
A39: 29 | B39: Annual | C39: =SUM(C27:C38) -> 0 | D39: =SUM(D27:D38) -> 0 | E39: =SUM(E27:E38) -> 0 | F39: =SUM(F27:F38) -> 0 | G39: =SUM(G27:G38) -> 0 | H39: =SUM(H27:H38) -> 0 | I39: =SUM(I27:I38) -> 0 | J39: =SUM(J27:J38) -> 0 | ... L39: =SUM(L27:L38) -> 0
A40: 30
A41: 31 | B41: Calendar Normal Heating Degree Days by Weather Sites (Base 35)
A42: 32 | C42: Metroplex (MX) | D42: Lufkin (LU) | E42: Austin (AU) | F42: Killeen (KI) | G42: Longview (LO) | H42: Waco (WO) | I42: Abilene (AE) | J42: Wichita Falls (WF) | K42: Midland/ Odessa (MO) | L42: Denison (DE)
A43: 33 | B43: 39083 | C43: 18.940253 | D43: 6.5763019 | E43: 5.4461726 | F43: 10.407794 | G43: 14.486215 | H43: 12.030748 | I43: 27.387566 | J43: 39.312965 | K43: 24.323938 | L43: 32.56895
...

Sheet Base45h
B1: PUC DOCKET NO.
B2: ONCOR ELECTRIC DELIVERY COMPANY LLC
B3: WEATHER STATION DATA
B4: FOR THE TEST YEAR ENDING DECEMBER 31, 2024
B6: SPONSOR: D. E. NELSON
B9: Calendar Actual Heating Degree Days by Weather Sites (Base 45)
A10: Line No. | C10: Dallas/ Fort Worth (MX) | D10: Lufkin (LU) | E10: Austin (AU) | F10: Killeen (KI) | G10: Longview (LO) | H10: Waco (WO) | I10: Abilene (AE) | J10: Wichita Falls (WF) | K10: Midland/ Odessa (MO) | L10: Denison (DE)
A11: 1 | B11: 45292 | C11: 173.6 | D11: 98.3 | E11: 99.5 | F11: 129.6 | G11: 141.9 | H11: 146.3 | I11: 185.8 | J11: 248.4 | K11: 183.3 | L11: 226.1
A12: =+A11+1 -> 2 | B12: 45323 | C12: 10.4 | D12: 4.2 | E12: 3.9 | F12: 10 | G12: 7.6 | H12: 8.8 | I12: 30.9 | J12: 42.4 | K12: 29.7 | L12: 27.1
A13: =+A12+1 -> 3 | B13: 45352 | C13: 0 | D13: 0 | E13: 0 | F13: 0 | G13: 0 | H13: 0 | I13: 0 | J13: 1.7 | K13: 1.6 | L13: 0
A14: =+A13+1 -> 4 | B14: 45383 | C14: 0 | D14: 0 | E14: 0 | F14: 0 | G14: 0 | H14: 0 | I14: 0 | J14: 0 | K14: 0 | L14: 0
A15: =+A14+1 -> 5 | B15: 45413 | C15: 0 | D15: 0 | E15: 0 | F15: 0 | G15: 0 | H15: 0 | I15: 0 | J15: 0 | K15: 0 | L15: 0
A16: =+A15+1 -> 6 | B16: 45444 | C16: 0 | D16: 0 | E16: 0 | F16: 0 | G16: 0 | H16: 0 | I16: 0 | J16: 0 | K16: 0 | L16: 0
A17: =+A16+1 -> 7 | B17: 45474 | C17: 0 | D17: 0 | E17: 0 | F17: 0 | G17: 0 | H17: 0 | I17: 0 | J17: 0 | K17: 0 | L17: 0
A18: =+A17+1 -> 8 | B18: 45505 | C18: 0 | D18: 0 | E18: 0 | F18: 0 | G18: 0 | H18: 0 | I18: 0 | J18: 0 | K18: 0 | L18: 0
A19: =+A18+1 -> 9 | B19: 45536 | C19: 0 | D19: 0 | E19: 0 | F19: 0 | G19: 0 | H19: 0 | I19: 0 | J19: 0 | K19: 0 | L19: 0
A20: =+A19+1 -> 10 | B20: 45566 | C20: 0 | D20: 0 | E20: 0 | F20: 0 | G20: 0 | H20: 0 | I20: 0 | J20: 0 | K20: 0 | L20: 0
A21: =+A20+1 -> 11 | B21: 45597 | C21: 1.1 | D21: 2.9 | E21: 0 | F21: 0.1 | G21: 4.2 | H21: 0 | I21: 1.7 | J21: 7.9 | K21: 3.6 | L21: 4.1
A22: =+A21+1 -> 12 | B22: 45627 | C22: 4.8 | D22: 5.6 | E22: 0.1 | F22: 2.3 | G22: 14.3 | H22: 4.9 | I22: 7.3 | J22: 29.8 | K22: 9.2 | L22: 21.4
A23: =+A22+1 -> 13 | B23: Annual | C23: =SUM(C11:C22) -> 189.9 | D23: =SUM(D11:D22) -> 111 | E23: =SUM(E11:E22) -> 103.5 | F23: =SUM(F11:F22) -> 142 | G23: =SUM(G11:G22) -> 168 | H23: =SUM(H11:H22) -> 160 | I23: =SUM(I11:I22) -> 225.7 | J23: =SUM(J11:J22) -> 330.2 | ... L23: =SUM(L11:L22) -> 278.7
A24: =+A23+1 -> 14
A25: =+A24+1 -> 15
A26: =+A25+1 -> 16 | B26: Calendar Normal Heating Degree Days by Weather Sites (Base 45)
A27: =+A26+1 -> 17 | C27: Dallas/ Fort Worth (MX) | D27: Lufkin (LU) | E27: Austin (AU) | F27: Killeen (KI) | G27: Longview (LO) | H27: Waco (WO) | I27: Abilene (AE) | J27: Wichita Falls (WF) | K27: Midland/ Odessa (MO) | L27: Denison (DE)
A28: =+A27+1 -> 18 | B28: 45292 | C28: 87.887917 | D28: 56.637917 | E28: 49.730833 | F28: 67.992083 | G28: 84.268333 | H28: 78.415 | I28: 116.51833 | J28: 156.00958 | K28: 116.39375 | L28: 137.19917
A29: =+A28+1 -> 19 | B29: 45323 | C29: 73.315 | D29: 38.424167 | E29: 39.63375 | F29: 56.760417 | G29: 60.48875 | H29: 60.543333 | I29: 101.37167 | J29: 130.22167 | K29: 87.502917 | L29: 108.42792
A30: =+A29+1 -> 20 | B30: 45352 | C30: 11.575833 | D30: 5.2758333 | E30: 3.9041667 | F30: 7.39375 | G30: 10.43875 | H30: 8.6958333 | I30: 16.260833 | J30: 22.0475 | K30: 15.648333 | L30: 20.635
A31: =+A30+1 -> 21 | B31: 45383 | C31: 0.53583333 | D31: 0.37375 | E31: 0.4 | F31: 0.9325 | G31: 0.32166667 | H31: 0.65 | I31: 2.34625 | J31: 2.5533333 | K31: 1.55 | L31: 1.5775
A32: =+A31+1 -> 22 | B32: 45413 | C32: 0 | D32: 0 | E32: 0 | F32: 0 | G32: 0 | H32: 0 | I32: 0.01 | J32: 0.015 | K32: 0 | L32: 0
A33: =+A32+1 -> 23 | B33: 45444 | C33: 0 | D33: 0 | E33: 0 | F33: 0 | G33: 0 | H33: 0 | I33: 0 | J33: 0 | K33: 0 | L33: 0
A34: =+A33+1 -> 24 | B34: 45474 | C34: 0 | D34: 0 | E34: 0 | F34: 0 | G34: 0 | H34: 0 | I34: 0 | J34: 0 | K34: 0 | L34: 0
A35: =+A34+1 -> 25 | B35: 45505 | C35: 0 | D35: 0 | E35: 0 | F35: 0 | G35: 0 | H35: 0 | I35: 0 | J35: 0 | K35: 0 | L35: 0
A36: =+A35+1 -> 26 | B36: 45536 | C36: 0 | D36: 0 | E36: 0 | F36: 0 | G36: 0 | H36: 0 | I36: 0 | J36: 0 | K36: 0 | L36: 0
A37: =+A36+1 -> 27 | B37: 45566 | C37: 1.055 | D37: 0.155 | E37: 0.24 | F37: 0.98 | G37: 0.31 | H37: 0.81 | I37: 3.995 | J37: 4.24 | K37: 4.2 | L37: 1.795
A38: =+A37+1 -> 28 | B38: 45597 | C38: 12.894583 | D38: 7.26 | E38: 6.5704167 | F38: 11.864583 | G38: 14.0725 | H38: 12.858333 | I38: 24.36625 | J38: 28.7925 | K38: 26.357083 | L38: 19.990417
A39: =+A38+1 -> 29 | B39: 45627 | C39: 63.360833 | D39: 40.38625 | E39: 34.46375 | F39: 50.732917 | G39: 61.677083 | H39: 57.065 | I39: 102.18917 | J39: 132.99333 | K39: 101.135 | L39: 100.01583
A40: =+A39+1 -> 30 | B40: Annual | C40: =SUM(C28:C39) -> 250.625 | D40: =SUM(D28:D39) -> 148.51292 | E40: =SUM(E28:E39) -> 134.94292 | F40: =SUM(F28:F39) -> 196.65625 | G40: =SUM(G28:G39) -> 231.57708 | H40: =SUM(H28:H39) -> 219.0375 | I40: =SUM(I28:I39) -> 367.0575 | J40: =SUM(J28:J39) -> 476.87292 | ... L40: =SUM(L28:L39) -> 389.64083

Sheet Base55h
B1: =+Base45h!B1 -> PUC DOCKET NO.
B2: =+Base45h!B2 -> ONCOR ELECTRIC DELIVERY COMPANY LLC
B3: =+Base45h!B3 -> WEATHER STATION DATA
B4: =+Base45h!B4 -> FOR THE TEST YEAR ENDING DECEMBER 31, 2024
B6: =+Base45h!B6 -> SPONSOR: D. E. NELSON
B9: Calendar Actual Cooling Degree Days by Weather Sites (Base 55)
A10: Line No. | C10: Dallas/ Fort Worth (MX) | D10: Lufkin (LU) | E10: Austin (AU) | F10: Killeen (KI) | G10: Longview (LO) | H10: Waco (WO) | I10: Abilene (AE) | J10: Wichita Falls (WF) | K10: Midland/ Odessa (MO) | L10: Denison (DE)
A11: 1 | B11: =+Base45h!B11 -> 45292 | C11: 405.3 | D11: 284.3 | E11: 269.7 | F11: 331.1 | G11: 351.6 | H11: 374.2 | I11: 417.2 | J11: 514.6 | K11: 439.3 | L11: 485.8
A12: =+A11+1 -> 2 | B12: =+Base45h!B12 -> 45323 | C12: 78.1 | D12: 55.3 | E12: 57.1 | F12: 67.1 | G12: 70.9 | H12: 74.9 | I12: 106.2 | J12: 145.5 | K12: 128.1 | L12: 117.2
A13: =+A12+1 -> 3 | B13: =+Base45h!B13 -> 45352 | C13: 20.2 | D13: 7.5 | E13: 8.3 | F13: 14.8 | G13: 26.2 | H13: 24.4 | I13: 39.3 | J13: 65.4 | K13: 50.4 | L13: 46.2
A14: =+A13+1 -> 4 | B14: =+Base45h!B14 -> 45383 | C14: 0.7 | D14: 0 | E14: 0 | F14: 0 | G14: 0.5 | H14: 0 | I14: 4.3 | J14: 4.4 | K14: 12.7 | L14: 4.2
A15: =+A14+1 -> 5 | B15: =+Base45h!B15 -> 45413 | C15: 0 | D15: 0 | E15: 0 | F15: 0 | G15: 0 | H15: 0 | I15: 0 | J15: 0 | K15: 0 | L15: 0
A16: =+A15+1 -> 6 | B16: =+Base45h!B16 -> 45444 | C16: 0 | D16: 0 | E16: 0 | F16: 0 | G16: 0 | H16: 0 | I16: 0 | J16: 0 | K16: 0 | L16: 0
A17: =+A16+1 -> 7 | B17: =+Base45h!B17 -> 45474 | C17: 0 | D17: 0 | E17: 0 | F17: 0 | G17: 0 | H17: 0 | I17: 0 | J17: 0 | K17: 0 | L17: 0
A18: =+A17+1 -> 8 | B18: =+Base45h!B18 -> 45505 | C18: 0 | D18: 0 | E18: 0 | F18: 0 | G18: 0 | H18: 0 | I18: 0 | J18: 0 | K18: 0 | L18: 0
A19: =+A18+1 -> 9 | B19: =+Base45h!B19 -> 45536 | C19: 0 | D19: 0 | E19: 0 | F19: 0 | G19: 0 | H19: 0 | I19: 0 | J19: 0 | K19: 0 | L19: 0
A20: =+A19+1 -> 10 | B20: =+Base45h!B20 -> 45566 | C20: 0 | D20: 0 | E20: 0 | F20: 0 | G20: 0 | H20: 0 | I20: 0 | J20: 0 | K20: 0 | L20: 0
A21: =+A20+1 -> 11 | B21: =+Base45h!B21 -> 45597 | C21: 34.4 | D21: 33.9 | E21: 16.2 | F21: 27.4 | G21: 47 | H21: 36.2 | I21: 50 | J21: 71.6 | K21: 69.2 | L21: 56.8
A22: =+A21+1 -> 12 | B22: =+Base45h!B22 -> 45627 | C22: 107.2 | D22: 98.8 | E22: 55.7 | F22: 74.8 | G22: 135.1 | H22: 97.5 | I22: 120.2 | J22: 198 | K22: 142.3 | L22: 167.4
A23: =+A22+1 -> 13 | B23: Annual | C23: =SUM(C11:C22) -> 645.9 | D23: =SUM(D11:D22) -> 479.8 | E23: =SUM(E11:E22) -> 407 | F23: =SUM(F11:F22) -> 515.2 | G23: =SUM(G11:G22) -> 631.3 | H23: =SUM(H11:H22) -> 607.2 | I23: =SUM(I11:I22) -> 737.2 | J23: =SUM(J11:J22) -> 999.5 | ... L23: =SUM(L11:L22) -> 877.6
A24: =+A23+1 -> 14
A25: =+A24+1 -> 15
A26: =+A25+1 -> 16 | B26: Calendar Normal Cooling Degree Days by Weather Sites (Base 55)
A27: =+A26+1 -> 17 | C27: Dallas/ Fort Worth (MX) | D27: Lufkin (LU) | E27: Austin (AU) | F27: Killeen (KI) | G27: Longview (LO) | H27: Waco (WO) | I27: Abilene (AE) | J27: Wichita Falls (WF) | K27: Midland/ Odessa (MO) | L27: Denison (DE)
A28: =+A27+1 -> 18 | B28: =+Base45h!B28 -> 45292 | C28: 275.14833 | D28: 223.5125 | E28: 201.28292 | F28: 233.87125 | G28: 275.12958 | H28: 264.63083 | I28: 322.91292 | J28: 392.18042 | K28: 338.14542 | L28: 361.41083
A29: =+A28+1 -> 19 | B29: =+Base45h!B29 -> 45323 | C29: 215.81625 | D29: 153.15875 | E29: 143.5875 | F29: 178.33625 | G29: 202.37833 | H29: 194.63625 | I29: 256.32833 | J29: 313.16958 | K29: 241.84625 | L29: 282.02042
A30: =+A29+1 -> 20 | B30: =+Base45h!B30 -> 45352 | C30: 56.72125 | D30: 40.860417 | E30: 33.915417 | F30: 45.306667 | G30: 59.830833 | H30: 53.7175 | I30: 78.590417 | J30: 101.50667 | K30: 77.392083 | L30: 94.187083
A31: =+A30+1 -> 21 | B31: =+Base45h!B31 -> 45383 | C31: 10.32625 | D31: 5.8341667 | E31: 4.5845833 | F31: 8.2045833 | G31: 10.568333 | H31: 9.5725 | I31: 19.664167 | J31: 24.458333 | K31: 16.574167 | L31: 21.45375
A32: =+A31+1 -> 22 | B32: =+Base45h!B32 -> 45413 | C32: 0.63375 | D32: 0.05 | E32: 0.155 | F32: 0.46 | G32: 0.34 | H32: 0.415 | I32: 1.7795833 | J32: 2.0083333 | K32: 1.9283333 | L32: 2.3475
A33: =+A32+1 -> 23 | B33: =+Base45h!B33 -> 45444 | C33: 0 | D33: 0 | E33: 0 | F33: 0 | G33: 0 | H33: 0 | I33: 0 | J33: 0 | K33: 0 | L33: 0
A34: =+A33+1 -> 24 | B34: =+Base45h!B34 -> 45474 | C34: 0 | D34: 0 | E34: 0 | F34: 0 | G34: 0 | H34: 0 | I34: 0 | J34: 0 | K34: 0 | L34: 0
A35: =+A34+1 -> 25 | B35: =+Base45h!B35 -> 45505 | C35: 0 | D35: 0 | E35: 0 | F35: 0 | G35: 0 | H35: 0 | I35: 0 | J35: 0 | K35: 0 | L35: 0
A36: =+A35+1 -> 26 | B36: =+Base45h!B36 -> 45536 | C36: 0 | D36: 0 | E36: 0 | F36: 0 | G36: 0 | H36: 0 | I36: 0.35 | J36: 0.075 | K36: 0.69 | L36: 0
A37: =+A36+1 -> 27 | B37: =+Base45h!B37 -> 45566 | C37: 10.382083 | D37: 5.7229167 | E37: 5.4645833 | F37: 9.1991667 | G37: 10.168333 | H37: 9.6945833 | I37: 22.472917 | J37: 24.225 | K37: 21.649583 | L37: 18.150417
A38: =+A37+1 -> 28 | B38: =+Base45h!B38 -> 45597 | C38: 77.440833 | D38: 70.749167 | E38: 59.311667 | F38: 73.604583 | G38: 93.92625 | H38: 80.865833 | I38: 112.43625 | J38: 133.83333 | K38: 124.64 | L38: 109.07708
A39: =+A38+1 -> 29 | B39: =+Base45h!B39 -> 45627 | C39: 230.0575 | D39: 186.58167 | E39: 170.68458 | F39: 203.355 | G39: 232.59792 | H39: 224.46208 | I39: 286 | J39: 353.05208 | K39: 304.24333 | L39: 297.57958
A40: =+A39+1 -> 30 | B40: Annual | C40: =SUM(C28:C39) -> 876.52625 | D40: =SUM(D28:D39) -> 686.46958 | E40: =SUM(E28:E39) -> 618.98625 | F40: =SUM(F28:F39) -> 752.3375 | G40: =SUM(G28:G39) -> 884.93958 | H40: =SUM(H28:H39) -> 837.99458 | I40: =SUM(I28:I39) -> 1100.5346 | J40: =SUM(J28:J39) -> 1344.5088 | ... L40: =SUM(L28:L39) -> 1186.2267
Y44: =MONTH(B44)&YEAR(B44) -> 11900
Y45: =MONTH(B45)&YEAR(B45) -> 11900
Y46: =MONTH(B46)&YEAR(B46) -> 11900
...

Sheet Base60h
B1: =+Base45h!B1 -> PUC DOCKET NO.
B2: =+Base45h!B2 -> ONCOR ELECTRIC DELIVERY COMPANY LLC
B3: =+Base45h!B3 -> WEATHER STATION DATA
B4: =+Base45h!B4 -> FOR THE TEST YEAR ENDING DECEMBER 31, 2024
B6: =+Base45h!B6 -> SPONSOR: D. E. NELSON
B9: Calendar Actual Heating Degree Days by Weather Sites (Base 60)
A10: Line No. | C10: Dallas/ Fort Worth (MX) | D10: Lufkin (LU) | E10: Austin (AU) | F10: Killeen (KI) | G10: Longview (LO) | H10: Waco (WO) | I10: Abilene (AE) | J10: Wichita Falls (WF) | K10: Midland/ Odessa (MO) | L10: Denison (DE)
A11: 1 | B11: =+Base45h!B11 -> 45292 | C11: 550 | D11: 414.5 | E11: 419.3 | F11: 475.8 | G11: 487.4 | H11: 529.1 | I11: 568.2 | J11: 668.8 | K11: 594.3 | L11: 638.1
A12: =+A11+1 -> 2 | B12: =+Base45h!B12 -> 45323 | C12: 147.6 | D12: 109.6 | E12: 119.9 | F12: 128 | G12: 140.7 | H12: 147 | I12: 194.4 | J12: 247.6 | K12: 231.6 | L12: 200.1
A13: =+A12+1 -> 3 | B13: =+Base45h!B13 -> 45352 | C13: 62.9 | D13: 42.3 | E13: 39.3 | F13: 53.6 | G13: 75.2 | H13: 66.6 | I13: 104.7 | J13: 143.9 | K13: 116.4 | L13: 106.7
A14: =+A13+1 -> 4 | B14: =+Base45h!B14 -> 45383 | C14: 8.1 | D14: 3.5 | E14: 1.6 | F14: 4.9 | G14: 12.3 | H14: 6 | I14: 24 | J14: 31.2 | K14: 41.2 | L14: 29.2
A15: =+A14+1 -> 5 | B15: =+Base45h!B15 -> 45413 | C15: 0 | D15: 0 | E15: 0 | F15: 0 | G15: 0 | H15: 0 | I15: 0 | J15: 0 | K15: 0 | L15: 0
A16: =+A15+1 -> 6 | B16: =+Base45h!B16 -> 45444 | C16: 0 | D16: 0 | E16: 0 | F16: 0 | G16: 0 | H16: 0 | I16: 0 | J16: 0 | K16: 0 | L16: 0
A17: =+A16+1 -> 7 | B17: =+Base45h!B17 -> 45474 | C17: 0 | D17: 0 | E17: 0 | F17: 0 | G17: 0 | H17: 0 | I17: 0 | J17: 0 | K17: 0 | L17: 0
A18: =+A17+1 -> 8 | B18: =+Base45h!B18 -> 45505 | C18: 0 | D18: 0 | E18: 0 | F18: 0 | G18: 0 | H18: 0 | I18: 0 | J18: 0 | K18: 0 | L18: 0
A19: =+A18+1 -> 9 | B19: =+Base45h!B19 -> 45536 | C19: 0 | D19: 0 | E19: 0 | F19: 0 | G19: 0 | H19: 0 | I19: 0 | J19: 0 | K19: 0 | L19: 0
A20: =+A19+1 -> 10 | B20: =+Base45h!B20 -> 45566 | C20: 0 | D20: 4.6 | E20: 0 | F20: 0 | G20: 8 | H20: 1.4 | I20: 0 | J20: 9.1 | K20: 2.3 | L20: 4.4
A21: =+A20+1 -> 11 | B21: =+Base45h!B21 -> 45597 | C21: 76.6 | D21: 79.3 | E21: 56.9 | F21: 65.1 | G21: 96.1 | H21: 82.2 | I21: 104.1 | J21: 142.7 | K21: 151.6 | L21: 108.8
A22: =+A21+1 -> 12 | B22: =+Base45h!B22 -> 45627 | C22: 214.2 | D22: 187.4 | E22: 131.1 | F22: 157.8 | G22: 232.1 | H22: 191 | I22: 226.7 | J22: 331.4 | K22: 274.3 | L22: 291.8
A23: =+A22+1 -> 13 | B23: Annual | C23: =SUM(C11:C22) -> 1059.4 | D23: =SUM(D11:D22) -> 841.2 | E23: =SUM(E11:E22) -> 768.1 | F23: =SUM(F11:F22) -> 885.2 | G23: =SUM(G11:G22) -> 1051.8 | H23: =SUM(H11:H22) -> 1023.3 | I23: =SUM(I11:I22) -> 1222.1 | J23: =SUM(J11:J22) -> 1574.7 | ... L23: =SUM(L11:L22) -> 1379.1
A24: =+A23+1 -> 14
A25: =+A24+1 -> 15
A26: =+A25+1 -> 16 | B26: Calendar Normal Heating Degree Days by Weather Sites (Base 60)
A27: =+A26+1 -> 17 | C27: Dallas/ Fort Worth (MX) | D27: Lufkin (LU) | E27: Austin (AU) | F27: Killeen (KI) | G27: Longview (LO) | H27: Waco (WO) | I27: Abilene (AE) | J27: Wichita Falls (WF) | K27: Midland/ Odessa (MO) | L27: Denison (DE)
A28: =+A27+1 -> 18 | B28: =+Base45h!B28 -> 45292 | C28: 405.65875 | D28: 342.16625 | E28: 320.07583 | F28: 357.19333 | G28: 402.64208 | H28: 393.47375 | I28: 458.14708 | J28: 534.62167 | K28: 483.25167 | L28: 500.53333
A29: =+A28+1 -> 19 | B29: =+Base45h!B29 -> 45323 | C29: 318.68667 | D29: 245.81333 | E29: 234.44167 | F29: 274.31542 | G29: 306.21375 | H29: 295.77042 | I29: 364.28917 | J29: 434.52625 | K29: 355.93458 | L29: 398.28667
A30: =+A29+1 -> 20 | B30: =+Base45h!B30 -> 45352 | C30: 114.42958 | D30: 89.8 | E30: 76.62375 | F30: 94.947083 | G30: 122.01625 | H30: 109.03083 | I30: 148.77833 | J30: 185.94542 | K30: 148.035 | L30: 174.74083
A31: =+A30+1 -> 21 | B31: =+Base45h!B31 -> 45383 | C31: 28.0675 | D31: 20.742083 | E31: 17.025417 | F31: 23.6775 | G31: 31.901667 | H31: 27.290417 | I31: 46.68 | J31: 59.253333 | K31: 40.965417 | L31: 57.695833
A32: =+A31+1 -> 22 | B32: =+Base45h!B32 -> 45413 | C32: 3.1375 | D32: 0.69958333 | E32: 0.85708333 | F32: 1.99375 | G32: 1.9308333 | H32: 1.9458333 | I32: 6.9558333 | J32: 7.9625 | K32: 6.6958333 | L32: 8.23625
A33: =+A32+1 -> 23 | B33: =+Base45h!B33 -> 45444 | C33: 0 | D33: 0 | E33: 0 | F33: 0 | G33: 0 | H33: 0 | I33: 0 | J33: 0 | K33: 0 | L33: 0
A34: =+A33+1 -> 24 | B34: =+Base45h!B34 -> 45474 | C34: 0 | D34: 0 | E34: 0 | F34: 0 | G34: 0 | H34: 0 | I34: 0 | J34: 0 | K34: 0 | L34: 0
A35: =+A34+1 -> 25 | B35: =+Base45h!B35 -> 45505 | C35: 0 | D35: 0 | E35: 0 | F35: 0 | G35: 0 | H35: 0 | I35: 0 | J35: 0 | K35: 0 | L35: 0
A36: =+A35+1 -> 26 | B36: =+Base45h!B36 -> 45536 | C36: 0 | D36: 0 | E36: 0 | F36: 0.04 | G36: 0 | H36: 0 | I36: 1.1 | J36: 0.635 | K36: 1.705 | L36: 0.01
A37: =+A36+1 -> 27 | B37: =+Base45h!B37 -> 45566 | C37: 27.022083 | D37: 22.6825 | E37: 18.510833 | F37: 25.192917 | G37: 33.063333 | H37: 27.174583 | I37: 47.822083 | J37: 55.975417 | K37: 47.869583 | L37: 46.326667
A38: =+A37+1 -> 28 | B38: =+Base45h!B38 -> 45597 | C38: 148.89 | D38: 140.79208 | E38: 121.35167 | F38: 141.31833 | G38: 174.25917 | H38: 151.34542 | I38: 196.29917 | J38: 231.06625 | K38: 220.36792 | L38: 194.27542
A39: =+A38+1 -> 29 | B39: =+Base45h!B39 -> 45627 | C39: 350.60542 | D39: 294.06708 | E39: 277.81667 | F39: 316.19167 | G39: 347.85542 | H39: 342.06458 | I39: 414.43125 | J39: 493.71125 | K39: 442.71667 | L39: 429.12875
A40: =+A39+1 -> 30 | B40: Annual | C40: =SUM(C28:C39) -> 1396.4975 | D40: =SUM(D28:D39) -> 1156.7629 | E40: =SUM(E28:E39) -> 1066.7029 | F40: =SUM(F28:F39) -> 1234.87 | G40: =SUM(G28:G39) -> 1419.8825 | H40: =SUM(H28:H39) -> 1348.0958 | I40: =SUM(I28:I39) -> 1684.5029 | J40: =SUM(J28:J39) -> 2003.6971 | ... L40: =SUM(L28:L39) -> 1809.2337

Sheet Base65h
B1: =+Base45h!B1 -> PUC DOCKET NO.
B2: =+Base45h!B2 -> ONCOR ELECTRIC DELIVERY COMPANY LLC
B3: =+Base45h!B3 -> WEATHER STATION DATA
B4: =+Base45h!B4 -> FOR THE TEST YEAR ENDING DECEMBER 31, 2024
B6: =+Base45h!B6 -> SPONSOR: D. E. NELSON
B9: Calendar Actual Heating Degree Days by Weather Sites (Base 65)
A10: Line No. | C10: Dallas/ Fort Worth (MX) | D10: Lufkin (LU) | E10: Austin (AU) | F10: Killeen (KI) | G10: Longview (LO) | H10: Waco (WO) | I10: Abilene (AE) | J10: Wichita Falls (WF) | K10: Midland/ Odessa (MO) | L10: Denison (DE)
A11: 1 | B11: =+Base45h!B11 -> 45292 | C11: 704.3 | D11: 564.1 | E11: 574.3 | F11: 630.8 | G11: 642.4 | H11: 684.1 | I11: 723.2 | J11: 823.8 | K11: 749.3 | L11: 793.1
A12: =+A11+1 -> 2 | B12: =+Base45h!B12 -> 45323 | C12: 253.4 | D12: 207.4 | E12: 212.6 | F12: 229.9 | G12: 247.2 | H12: 258 | I12: 307 | J12: 370.5 | K12: 353.9 | L12: 319.8
A13: =+A12+1 -> 3 | B13: =+Base45h!B13 -> 45352 | C13: 153.1 | D13: 115.4 | E13: 104.6 | F13: 126.3 | G13: 161 | H13: 145.2 | I13: 206.6 | J13: 248.4 | K13: 218.9 | L13: 212
A14: =+A13+1 -> 4 | B14: =+Base45h!B14 -> 45383 | C14: 40.9 | D14: 29.4 | E14: 16.1 | F14: 29.7 | G14: 44.4 | H14: 43.6 | I14: 67.4 | J14: 82.5 | K14: 88.9 | L14: 76.7
A15: =+A14+1 -> 5 | B15: =+Base45h!B15 -> 45413 | C15: 0 | D15: 0 | E15: 0 | F15: 0 | G15: 0 | H15: 0 | I15: 0 | J15: 1.4 | K15: 1.5 | L15: 0
A16: =+A15+1 -> 6 | B16: =+Base45h!B16 -> 45444 | C16: 0 | D16: 0 | E16: 0 | F16: 0 | G16: 0 | H16: 0 | I16: 0 | J16: 0 | K16: 0 | L16: 0
A17: =+A16+1 -> 7 | B17: =+Base45h!B17 -> 45474 | C17: 0 | D17: 0 | E17: 0 | F17: 0 | G17: 0 | H17: 0 | I17: 0 | J17: 0 | K17: 0 | L17: 0
A18: =+A17+1 -> 8 | B18: =+Base45h!B18 -> 45505 | C18: 0 | D18: 0 | E18: 0 | F18: 0 | G18: 0 | H18: 0 | I18: 0 | J18: 0 | K18: 0 | L18: 0
A19: =+A18+1 -> 9 | B19: =+Base45h!B19 -> 45536 | C19: 0 | D19: 0 | E19: 0 | F19: 0 | G19: 0 | H19: 0 | I19: 0 | J19: 0 | K19: 0 | L19: 0
A20: =+A19+1 -> 10 | B20: =+Base45h!B20 -> 45566 | C20: 8.8 | D20: 19.6 | E20: 3.3 | F20: 6 | G20: 28.3 | H20: 9 | I20: 12.4 | J20: 24.1 | K20: 17.8 | L20: 17.4
A21: =+A20+1 -> 11 | B21: =+Base45h!B21 -> 45597 | C21: 148.6 | D21: 141.9 | E21: 115.6 | F21: 129 | G21: 167.9 | H21: 155 | I21: 202.6 | J21: 260.3 | K21: 264 | L21: 213.5
A22: =+A21+1 -> 12 | B22: =+Base45h!B22 -> 45627 | C22: 347.5 | D22: 304.9 | E22: 236.6 | F22: 268.6 | G22: 362.1 | H22: 312.4 | I22: 364.1 | J22: 481.4 | K22: 423.1 | L22: 436.7
A23: =+A22+1 -> 13 | B23: Annual | C23: =SUM(C11:C22) -> 1656.6 | D23: =SUM(D11:D22) -> 1382.7 | E23: =SUM(E11:E22) -> 1263.1 | F23: =SUM(F11:F22) -> 1420.3 | G23: =SUM(G11:G22) -> 1653.3 | H23: =SUM(H11:H22) -> 1607.3 | I23: =SUM(I11:I22) -> 1883.3 | J23: =SUM(J11:J22) -> 2292.4 | ... L23: =SUM(L11:L22) -> 2069.2
A24: =+A23+1 -> 14
A25: =+A24+1 -> 15
A26: =+A25+1 -> 16 | B26: Calendar Normal Heating Degree Days by Weather Sites (Base 65)
A27: =+A26+1 -> 17 | C27: Dallas/ Fort Worth (MX) | D27: Lufkin (LU) | E27: Austin (AU) | F27: Killeen (KI) | G27: Longview (LO) | H27: Waco (WO) | I27: Abilene (AE) | J27: Wichita Falls (WF) | K27: Midland/ Odessa (MO) | L27: Denison (DE)
A28: =+A27+1 -> 18 | B28: =+Base45h!B28 -> 45292 | C28: 549.265 | D28: 477.35875 | E28: 455.73625 | F28: 496.38792 | G28: 543.44333 | H28: 536.69458 | I28: 606.49375 | J28: 685.99125 | K28: 637.1175 | L28: 649.02958
A29: =+A28+1 -> 19 | B29: =+Base45h!B29 -> 45323 | C29: 439.97375 | D29: 359.36667 | E29: 344.97583 | F29: 388.73292 | G29: 428.10292 | H29: 416.21125 | I29: 492.33667 | J29: 570.97667 | K29: 488.87 | L29: 530.92625
A30: =+A29+1 -> 20 | B30: =+Base45h!B30 -> 45352 | C30: 203.15125 | D30: 170.41792 | E30: 150.72417 | F30: 177.35542 | G30: 215.97167 | H30: 196.99917 | I30: 246.8175 | J30: 296.81792 | K30: 248.69667 | L30: 285.47708
A31: =+A30+1 -> 21 | B31: =+Base45h!B31 -> 45383 | C31: 68.119583 | D31: 56.009167 | E31: 46.183333 | F31: 59.670833 | G31: 79.7625 | H31: 68.817917 | I31: 98.902917 | J31: 124.71292 | K31: 87.33875 | L31: 123.325
A32: =+A31+1 -> 22 | B32: =+Base45h!B32 -> 45413 | C32: 10.884583 | D32: 5.0233333 | E32: 4.4745833 | F32: 7.9079167 | G32: 10.304583 | H32: 8.4366667 | I32: 21.13625 | J32: 25.149167 | K32: 19.078333 | L32: 25.625833
A33: =+A32+1 -> 23 | B33: =+Base45h!B33 -> 45444 | C33: 0 | D33: 0 | E33: 0 | F33: 0 | G33: 0 | H33: 0 | I33: 0 | J33: 0 | K33: 0 | L33: 0
A34: =+A33+1 -> 24 | B34: =+Base45h!B34 -> 45474 | C34: 0 | D34: 0 | E34: 0 | F34: 0 | G34: 0 | H34: 0 | I34: 0 | J34: 0 | K34: 0.0875 | L34: 0
A35: =+A34+1 -> 25 | B35: =+Base45h!B35 -> 45505 | C35: 0 | D35: 0 | E35: 0 | F35: 0 | G35: 0 | H35: 0 | I35: 0 | J35: 0 | K35: 0 | L35: 0
A36: =+A35+1 -> 26 | B36: =+Base45h!B36 -> 45536 | C36: 0.37 | D36: 0.09 | E36: 0.4 | F36: 0.885 | G36: 0.425 | H36: 0.505 | I36: 4.6566667 | J36: 3.9220833 | K36: 6.045 | L36: 1.5208333
A37: =+A36+1 -> 27 | B37: =+Base45h!B37 -> 45566 | C37: 63.209583 | D37: 58.909167 | E37: 48.34875 | F37: 59.027917 | G37: 79.89125 | H37: 63.4725 | I37: 96.64625 | J37: 115.07 | K37: 98.08625 | L37: 98.635833
A38: =+A37+1 -> 28 | B38: =+Base45h!B38 -> 45597 | C38: 250.21167 | D38: 238.42333 | E38: 212.04583 | F38: 237.69917 | G38: 282.67708 | H38: 250.54042 | I38: 309.62542 | J38: 355.04917 | K38: 344.54333 | L38: 308.61667
A39: =+A38+1 -> 29 | B39: =+Base45h!B39 -> 45627 | C39: 488.51875 | D39: 419.45292 | E39: 404.695 | F39: 449.3 | G39: 480.93667 | H39: 478.19542 | I39: 557.61417 | J39: 643.64917 | K39: 593.71375 | L39: 574.10542
A40: =+A39+1 -> 30 | B40: Annual | C40: =SUM(C28:C39) -> 2073.7042 | D40: =SUM(D28:D39) -> 1785.0512 | E40: =SUM(E28:E39) -> 1667.5837 | F40: =SUM(F28:F39) -> 1876.9671 | G40: =SUM(G28:G39) -> 2121.515 | H40: =SUM(H28:H39) -> 2019.8729 | I40: =SUM(I28:I39) -> 2434.2296 | J40: =SUM(J28:J39) -> 2821.3383 | ... L40: =SUM(L28:L39) -> 2597.2625

Sheet Base50c
B1: =+Base45h!B1 -> PUC DOCKET NO.
B2: =+Base45h!B2 -> ONCOR ELECTRIC DELIVERY COMPANY LLC
B3: =+Base45h!B3 -> WEATHER STATION DATA
B4: =+Base45h!B4 -> FOR THE TEST YEAR ENDING DECEMBER 31, 2024
B6: =+Base45h!B6 -> SPONSOR: D. E. NELSON
B9: Calendar Actual Cooling Degree Days by Weather Sites (Base 50)
A10: Line No. | C10: Dallas/ Fort Worth (MX) | D10: Lufkin (LU) | E10: Austin (AU) | F10: Killeen (KI) | G10: Longview (LO) | H10: Waco (WO) | I10: Abilene (AE) | J10: Wichita Falls (WF) | K10: Midland/ Odessa (MO) | L10: Denison (DE)
A11: 1 | B11: =+Base45h!B11 -> 45292 | C11: 32.8 | D11: 74.9 | E11: 51.4 | F11: 41.4 | G11: 56.6 | H11: 20.5 | I11: 26 | J11: 14.8 | K11: 7.8 | L11: 20.4
A12: =+A11+1 -> 2 | B12: =+Base45h!B12 -> 45323 | C12: 246.6 | D12: 275.3 | E12: 265.1 | F12: 260.7 | G12: 250.3 | H12: 226.4 | I12: 222.6 | J12: 160.4 | K12: 155.8 | L12: 196.6
A13: =+A12+1 -> 3 | B13: =+Base45h!B13 -> 45352 | C13: 360.9 | D13: 410.3 | E13: 423.5 | F13: 395.5 | G13: 354.6 | H13: 366.9 | I13: 300.1 | J13: 260 | K13: 271.8 | L13: 297.5
A14: =+A13+1 -> 4 | B14: =+Base45h!B14 -> 45383 | C14: 561.6 | D14: 575.2 | E14: 612.4 | F14: 576.2 | G14: 548 | H14: 541 | I14: 544.4 | J14: 465.7 | K14: 495.7 | L14: 486.5
A15: =+A14+1 -> 5 | B15: =+Base45h!B15 -> 45413 | C15: 833.7 | D15: 809.6 | E15: 892.1 | F15: 817.3 | G15: 809.4 | H15: 805 | I15: 800.9 | J15: 744.1 | K15: 828.7 | L15: 762.4
A16: =+A15+1 -> 6 | B16: =+Base45h!B16 -> 45444 | C16: 1022.3 | D16: 953 | E16: 1012.2 | F16: 997.3 | G16: 943.9 | H16: 997.8 | I16: 1011.4 | J16: 890.9 | K16: 1024.6 | L16: 992.1
A17: =+A16+1 -> 7 | B17: =+Base45h!B17 -> 45474 | C17: 1078.3 | D17: 949 | E17: 1004.1 | F17: 1014.4 | G17: 958.8 | H17: 1031.2 | I17: 1071.5 | J17: 1046.7 | K17: 996.9 | L17: 1029.5
A18: =+A17+1 -> 8 | B18: =+Base45h!B18 -> 45505 | C18: 1195.3 | D18: 1055.8 | E18: 1095.5 | F18: 1134.1 | G18: 1047.2 | H18: 1137.4 | I18: 1205.8 | J18: 1191.1 | K18: 1125.9 | L18: 1115.1
A19: =+A18+1 -> 9 | B19: =+Base45h!B19 -> 45536 | C19: 877 | D19: 816.8 | E19: 931.9 | F19: 876.4 | G19: 793.7 | H19: 850.5 | I19: 796.1 | J19: 836 | K19: 740.9 | L19: 807.9
A20: =+A19+1 -> 10 | B20: =+Base45h!B20 -> 45566 | C20: 790.9 | D20: 671.9 | E20: 782.5 | F20: 787 | G20: 641 | H20: 757.6 | I20: 720.1 | J20: 703.8 | K20: 664.5 | L20: 717.7
A21: =+A20+1 -> 11 | B21: =+Base45h!B21 -> 45597 | C21: 356.6 | D21: 402.5 | E21: 432.7 | F21: 396.4 | G21: 343.6 | H21: 359.6 | I21: 281.1 | J21: 223.7 | K21: 222.5 | L21: 277.9
A22: =+A21+1 -> 12 | B22: =+Base45h!B22 -> 45627 | C22: 138.8 | D22: 201.5 | E22: 259.4 | F22: 223.8 | G22: 161.7 | H22: 181.2 | I22: 128.8 | J22: 61.5 | K22: 73.2 | L22: 91.4
A23: =+A22+1 -> 13 | B23: Annual | C23: =SUM(C11:C22) -> 7494.8 | D23: =SUM(D11:D22) -> 7195.8 | E23: =SUM(E11:E22) -> 7762.8 | F23: =SUM(F11:F22) -> 7520.5 | G23: =SUM(G11:G22) -> 6908.8 | H23: =SUM(H11:H22) -> 7275.1 | I23: =SUM(I11:I22) -> 7108.8 | J23: =SUM(J11:J22) -> 6598.7 | ... L23: =SUM(L11:L22) -> 6795
A24: =+A23+1 -> 14
A25: =+A24+1 -> 15
A26: =+A25+1 -> 16 | B26: Calendar Normal Cooling Degree Days by Weather Sites (Base 50)
A27: =+A26+1 -> 17 | C27: Dallas/ Fort Worth (MX) | D27: Lufkin (LU) | E27: Austin (AU) | F27: Killeen (KI) | G27: Longview (LO) | H27: Waco (WO) | I27: Abilene (AE) | J27: Wichita Falls (WF) | K27: Midland/ Odessa (MO) | L27: Denison (DE)
A28: =+A27+1 -> 18 | B28: =+Base45h!B28 -> 45292 | C28: 83.911667 | D28: 122.98292 | E28: 126.41 | F28: 108.12542 | G28: 93.79625 | H28: 87.374583 | I28: 65.456667 | J28: 41.679583 | K28: 41.4025 | L28: 54.042083
A29: =+A28+1 -> 19 | B29: =+Base45h!B29 -> 45323 | C29: 137.63125 | D29: 176.42375 | E29: 189.89292 | F29: 163.75083 | G29: 137.3725 | H29: 142.30583 | I29: 115.70667 | J29: 77.848333 | K29: 101.72792 | L29: 92.723333
A30: =+A29+1 -> 20 | B30: =+Base45h!B30 -> 45352 | C30: 336.67167 | D30: 366.065 | E30: 392.03208 | F30: 357.84292 | G30: 316.61458 | H30: 335.82625 | I30: 291.18083 | J30: 244.70583 | K30: 284.57792 | L30: 248.37792
A31: =+A30+1 -> 21 | B31: =+Base45h!B31 -> 45383 | C31: 499.44375 | D31: 515.5575 | E31: 546.61375 | F31: 514.8475 | G31: 467.45958 | H31: 498.94083 | I31: 467.27667 | J31: 416.375 | K31: 489.47875 | L31: 401.3425
A32: =+A31+1 -> 22 | B32: =+Base45h!B32 -> 45413 | C32: 763.28167 | D32: 756.34625 | E32: 788.43167 | F32: 751.98625 | G32: 722.05417 | H32: 757.725 | I32: 717.75 | J32: 691.5075 | K32: 755.78417 | L32: 660.775
A33: =+A32+1 -> 23 | B33: =+Base45h!B33 -> 45444 | C33: 996.71833 | D33: 932.3375 | E33: 966.51792 | F33: 958.32792 | G33: 921.55625 | H33: 979.61875 | I33: 933.02042 | J33: 939.8925 | K33: 972.55081 | L33: 917.34333
A34: =+A33+1 -> 24 | B34: =+Base45h!B34 -> 45474 | C34: 1127.5963 | D34: 1014.8317 | E34: 1052.3508 | F34: 1069.7254 | G34: 1026.6125 | H34: 1102.9029 | I34: 1048.7142 | J34: 1079.7013 | K34: 1036.2992 | L34: 1054.5658
A35: =+A34+1 -> 25 | B35: =+Base45h!B35 -> 45505 | C35: 1137.5504 | D35: 1030.9583 | E35: 1080.0346 | F35: 1086.57 | G35: 1037.4962 | H35: 1116.2929 | I35: 1042.9479 | J35: 1066.9421 | K35: 1011.4917 | L35: 1055.9663
A36: =+A35+1 -> 26 | B36: =+Base45h!B36 -> 45536 | C36: 900.20125 | D36: 842.16833 | E36: 877.4725 | F36: 860.82208 | G36: 826.06042 | H36: 881.95042 | I36: 796.8925 | J36: 806.47 | K36: 773.61042 | L36: 821.96917
A37: =+A36+1 -> 27 | B37: =+Base45h!B37 -> 45566 | C37: 582.83583 | D37: 570.13583 | E37: 613.57083 | F37: 586.30792 | G37: 524.54708 | H37: 583.16583 | I37: 512.22542 | J37: 471.70917 | K37: 493.85875 | L37: 499.14125
A38: =+A37+1 -> 28 | B38: =+Base45h!B38 -> 45597 | C38: 263.6725 | D38: 276.87125 | E38: 310.98542 | F38: 278.62875 | G38: 236.35208 | H38: 269.33417 | I38: 215.21125 | J38: 173.665 | K38: 175.8875 | L38: 210.01583
A39: =+A38+1 -> 29 | B39: =+Base45h!B39 -> 45627 | C39: 118.36042 | D39: 164.96125 | E39: 164.23833 | F39: 140.1825 | G39: 131.235 | H39: 124.24583 | I39: 92.296667 | J39: 53.294167 | K39: 58.870417 | L39: 80.635
A40: =+A39+1 -> 30 | B40: Annual | C40: =SUM(C28:C39) -> 6947.875 | D40: =SUM(D28:D39) -> 6769.6396 | E40: =SUM(E28:E39) -> 7108.5508 | F40: =SUM(F28:F39) -> 6877.1175 | G40: =SUM(G28:G39) -> 6441.1567 | H40: =SUM(H28:H39) -> 6879.6833 | I40: =SUM(I28:I39) -> 6298.6792 | J40: =SUM(J28:J39) -> 6063.7904 | ... L40: =SUM(L28:L39) -> 6096.8975

Sheet Base55c
B1: =+Base45h!B1 -> PUC DOCKET NO.
B2: =+Base45h!B2 -> ONCOR ELECTRIC DELIVERY COMPANY LLC
B3: =+Base45h!B3 -> WEATHER STATION DATA
B4: =+Base45h!B4 -> FOR THE TEST YEAR ENDING DECEMBER 31, 2024
B6: =+Base45h!B6 -> SPONSOR: D. E. NELSON
B9: Calendar Actual Cooling Degree Days by Weather Sites (Base 55)
A10: Line No. | C10: Dallas/ Fort Worth (MX) | D10: Lufkin (LU) | E10: Austin (AU) | F10: Killeen (KI) | G10: Longview (LO) | H10: Waco (WO) | I10: Abilene (AE) | J10: Wichita Falls (WF) | K10: Midland/ Odessa (MO) | L10: Denison (DE)
A11: 1 | B11: =+Base45h!B11 -> 45292 | C11: 11 | D11: 30.2 | E11: 5.4 | F11: 10.3 | G11: 19.2 | H11: 0.1 | I11: 4 | J11: 0.8 | K11: 0 | L11: 2.7
A12: =+A11+1 -> 2 | B12: =+Base45h!B12 -> 45323 | C12: 143.4 | D12: 163.6 | E12: 154.8 | F12: 154.3 | G12: 143.1 | H12: 125.9 | I12: 121.6 | J12: 80.4 | K12: 75.2 | L12: 106.5
A13: =+A12+1 -> 3 | B13: =+Base45h!B13 -> 45352 | C13: 224.5 | D13: 262.8 | E13: 276.8 | F13: 254.4 | G13: 224.9 | H13: 236 | I13: 174 | J13: 154.5 | K13: 155.5 | L13: 176.8
A14: =+A13+1 -> 4 | B14: =+Base45h!B14 -> 45383 | C14: 412.3 | D14: 425.2 | E14: 462.4 | F14: 426.2 | G14: 398.5 | H14: 391 | I14: 398.7 | J14: 320.1 | K14: 358.1 | L14: 340.7
A15: =+A14+1 -> 5 | B15: =+Base45h!B15 -> 45413 | C15: 678.7 | D15: 654.6 | E15: 737.1 | F15: 662.3 | G15: 654.4 | H15: 650 | I15: 645.9 | J15: 589.1 | K15: 673.7 | L15: 607.4
A16: =+A15+1 -> 6 | B16: =+Base45h!B16 -> 45444 | C16: 872.3 | D16: 803 | E16: 862.2 | F16: 847.3 | G16: 793.9 | H16: 847.8 | I16: 861.4 | J16: 755.9 | K16: 874.6 | L16: 842.1
A17: =+A16+1 -> 7 | B17: =+Base45h!B17 -> 45474 | C17: 923.3 | D17: 794 | E17: 849.1 | F17: 859.4 | G17: 803.8 | H17: 876.2 | I17: 916.5 | J17: 891.7 | K17: 841.9 | L17: 874.5
A18: =+A17+1 -> 8 | B18: =+Base45h!B18 -> 45505 | C18: 1040.3 | D18: 900.8 | E18: 940.5 | F18: 979.1 | G18: 892.2 | H18: 982.4 | I18: 1050.8 | J18: 1036.1 | K18: 970.9 | L18: 960.1
A19: =+A18+1 -> 9 | B19: =+Base45h!B19 -> 45536 | C19: 727 | D19: 666.8 | E19: 781.9 | F19: 726.4 | G19: 643.7 | H19: 700.5 | I19: 646.1 | J19: 686 | K19: 590.9 | L19: 657.9
A20: =+A19+1 -> 10 | B20: =+Base45h!B20 -> 45566 | C20: 635.9 | D20: 516.9 | E20: 627.5 | F20: 632 | G20: 486 | H20: 602.6 | I20: 565.1 | J20: 548.8 | K20: 509.5 | L20: 562.7
A21: =+A20+1 -> 11 | B21: =+Base45h!B21 -> 45597 | C21: 228.4 | D21: 274.7 | E21: 296.5 | F21: 267.7 | G21: 225.6 | H21: 236 | I21: 164.9 | J21: 115.1 | K21: 120.1 | L21: 163.2
A22: =+A21+1 -> 12 | B22: =+Base45h!B22 -> 45627 | C22: 62.9 | D22: 109.9 | E22: 149.4 | F22: 127.1 | G22: 85.4 | H22: 93.7 | I22: 56.1 | J22: 16.6 | K22: 19.2 | L22: 31.7
A23: =+A22+1 -> 13 | B23: Annual | C23: =SUM(C11:C22) -> 5960 | D23: =SUM(D11:D22) -> 5602.5 | E23: =SUM(E11:E22) -> 6143.6 | F23: =SUM(F11:F22) -> 5946.5 | G23: =SUM(G11:G22) -> 5370.7 | H23: =SUM(H11:H22) -> 5742.2 | I23: =SUM(I11:I22) -> 5605.1 | J23: =SUM(J11:J22) -> 5195.1 | ... L23: =SUM(L11:L22) -> 5326.3
A24: =+A23+1 -> 14
A25: =+A24+1 -> 15
A26: =+A25+1 -> 16 | B26: Calendar Normal Cooling Degree Days by Weather Sites (Base 55)
A27: =+A26+1 -> 17 | C27: Dallas/ Fort Worth (MX) | D27: Lufkin (LU) | E27: Austin (AU) | F27: Killeen (KI) | G27: Longview (LO) | H27: Waco (WO) | I27: Abilene (AE) | J27: Wichita Falls (WF) | K27: Midland/ Odessa (MO) | L27: Denison (DE)
A28: =+A27+1 -> 18 | B28: =+Base45h!B28 -> 45292 | C28: 39.593333 | D28: 65.260417 | E28: 63.51875 | F28: 52.130833 | G28: 47.009583 | H28: 41.225833 | I28: 26.79625 | J28: 16.6925 | K28: 11.027917 | L28: 23.476667
A29: =+A28+1 -> 19 | B29: =+Base45h!B29 -> 45323 | C29: 75.829167 | D29: 101.235 | E29: 108.44417 | F29: 92.06875 | G29: 75.66875 | H29: 76.795417 | I29: 58.535833 | J29: 35.132917 | K29: 45.25125 | L29: 44.605
A30: =+A29+1 -> 20 | B30: =+Base45h!B30 -> 45352 | C30: 211.12583 | D30: 236.30833 | E30: 258.42042 | F30: 228.22958 | G30: 195.62333 | H30: 211.12833 | I30: 177.81958 | J30: 141.74417 | K30: 170.95708 | L30: 142.48125
A31: =+A30+1 -> 21 | B31: =+Base45h!B31 -> 45383 | C31: 356.90958 | D31: 369.91792 | E31: 400.07333 | F31: 370.74708 | G31: 325.75208 | H31: 356.13333 | I31: 329.86958 | J31: 281.4325 | K31: 350.41708 | L31: 265.67375
A32: =+A31+1 -> 22 | B32: =+Base45h!B32 -> 45413 | C32: 608.85542 | D32: 601.39625 | E32: 633.58667 | F32: 597.36125 | G32: 567.39417 | H32: 603.14 | I32: 564.26958 | J32: 538.19042 | K32: 602.2575 | L32: 507.785
A33: =+A32+1 -> 23 | B33: =+Base45h!B33 -> 45444 | C33: 846.71833 | D33: 782.3375 | E33: 816.51792 | F33: 808.32792 | G33: 771.55625 | H33: 829.61875 | I33: 783.02042 | J33: 789.8925 | K33: 822.55081 | L33: 767.34333
A34: =+A33+1 -> 24 | B34: =+Base45h!B34 -> 45474 | C34: 972.59625 | D34: 859.83167 | E34: 897.35083 | F34: 914.72542 | G34: 871.6125 | H34: 947.90292 | I34: 893.71417 | J34: 924.70125 | K34: 881.29917 | L34: 899.56583
A35: =+A34+1 -> 25 | B35: =+Base45h!B35 -> 45505 | C35: 982.55042 | D35: 875.95833 | E35: 925.03458 | F35: 931.57 | G35: 882.49625 | H35: 961.29292 | I35: 887.94792 | J35: 911.94208 | K35: 856.49167 | L35: 900.96625
A36: =+A35+1 -> 26 | B36: =+Base45h!B36 -> 45536 | C36: 750.20125 | D36: 692.16833 | E36: 727.4725 | F36: 710.82208 | G36: 676.06042 | H36: 731.95042 | I36: 647.2425 | J36: 656.545 | K36: 624.23042 | L36: 671.96917
A37: =+A36+1 -> 27 | B37: =+Base45h!B37 -> 45566 | C37: 434.29792 | D37: 419.45875 | E37: 462.69542 | F37: 437.18208 | G37: 377.32833 | H37: 434.48542 | I37: 370.03542 | J37: 330.91875 | K37: 351.10042 | L37: 356.31167
A38: =+A37+1 -> 28 | B38: =+Base45h!B38 -> 45597 | C38: 157.47917 | D38: 169.49417 | E38: 196.78083 | F38: 170.39708 | G38: 137.97 | H38: 164.39042 | I38: 120.17208 | J38: 90.391667 | K38: 87.79 | L38: 117.16708
A39: =+A38+1 -> 29 | B39: =+Base45h!B39 -> 45627 | C39: 60.00875 | D39: 97.028333 | E39: 92.021667 | F39: 75.149583 | G39: 74.210833 | H39: 66.440833 | I39: 41.421667 | J39: 20.955 | K39: 20.78125 | L39: 36.83125
A40: =+A39+1 -> 30 | B40: Annual | C40: =SUM(C28:C39) -> 5496.1654 | D40: =SUM(D28:D39) -> 5270.395 | E40: =SUM(E28:E39) -> 5581.9171 | F40: =SUM(F28:F39) -> 5388.7117 | G40: =SUM(G28:G39) -> 5002.6825 | H40: =SUM(H28:H39) -> 5424.5046 | I40: =SUM(I28:I39) -> 4900.845 | J40: =SUM(J28:J39) -> 4738.5387 | ... L40: =SUM(L28:L39) -> 4734.1763

Sheet Base60c
B1: =+Base45h!B1 -> PUC DOCKET NO.
B2: =+Base45h!B2 -> ONCOR ELECTRIC DELIVERY COMPANY LLC
B3: =+Base45h!B3 -> WEATHER STATION DATA
B4: =+Base45h!B4 -> FOR THE TEST YEAR ENDING DECEMBER 31, 2024
B6: =+Base45h!B6 -> SPONSOR: D. E. NELSON
B9: Calendar Actual Cooling Degree Days by Weather Sites (Base 60)
A10: Line No. | C10: Dallas/ Fort Worth (MX) | D10: Lufkin (LU) | E10: Austin (AU) | F10: Killeen (KI) | G10: Longview (LO) | H10: Waco (WO) | I10: Abilene (AE) | J10: Wichita Falls (WF) | K10: Midland/ Odessa (MO) | L10: Denison (DE)
A11: 1 | B11: =+Base45h!B11 -> 45292 | C11: 0.7 | D11: 5.4 | E11: 0 | F11: 0 | G11: 0 | H11: 0 | I11: 0 | J11: 0 | K11: 0 | L11: 0
A12: =+A11+1 -> 2 | B12: =+Base45h!B12 -> 45323 | C12: 67.9 | D12: 72.9 | E12: 72.6 | F12: 70.2 | G12: 67.9 | H12: 53 | I12: 64.8 | J12: 37.5 | K12: 33.7 | L12: 44.4
A13: =+A12+1 -> 3 | B13: =+Base45h!B13 -> 45352 | C13: 112.2 | D13: 142.6 | E13: 152.8 | F13: 138.2 | G13: 118.9 | H13: 123.2 | I13: 84.4 | J13: 78 | K13: 66.5 | L13: 82.3
A14: =+A13+1 -> 4 | B14: =+Base45h!B14 -> 45383 | C14: 269.7 | D14: 278.7 | E14: 314 | F14: 281.1 | G14: 260.3 | H14: 247 | I14: 268.4 | J14: 196.9 | K14: 236.6 | L14: 215.7
A15: =+A14+1 -> 5 | B15: =+Base45h!B15 -> 45413 | C15: 523.7 | D15: 499.6 | E15: 582.1 | F15: 507.3 | G15: 499.4 | H15: 495 | I15: 490.9 | J15: 434.1 | K15: 518.7 | L15: 452.4
A16: =+A15+1 -> 6 | B16: =+Base45h!B16 -> 45444 | C16: 722.3 | D16: 653 | E16: 712.2 | F16: 697.3 | G16: 643.9 | H16: 697.8 | I16: 711.4 | J16: 620.9 | K16: 724.6 | L16: 692.1
A17: =+A16+1 -> 7 | B17: =+Base45h!B17 -> 45474 | C17: 768.3 | D17: 639 | E17: 694.1 | F17: 704.4 | G17: 648.8 | H17: 721.2 | I17: 761.5 | J17: 736.7 | K17: 686.9 | L17: 719.5
A18: =+A17+1 -> 8 | B18: =+Base45h!B18 -> 45505 | C18: 885.3 | D18: 745.8 | E18: 785.5 | F18: 824.1 | G18: 737.2 | H18: 827.4 | I18: 895.8 | J18: 881.1 | K18: 815.9 | L18: 805.1
A19: =+A18+1 -> 9 | B19: =+Base45h!B19 -> 45536 | C19: 577 | D19: 516.8 | E19: 631.9 | F19: 576.4 | G19: 493.7 | H19: 550.5 | I19: 496.1 | J19: 536 | K19: 440.9 | L19: 507.9
A20: =+A19+1 -> 10 | B20: =+Base45h!B20 -> 45566 | C20: 480.9 | D20: 366.5 | E20: 472.5 | F20: 477 | G20: 339 | H20: 449 | I20: 410.1 | J20: 402.9 | K20: 356.8 | L20: 412.1
A21: =+A20+1 -> 11 | B21: =+Base45h!B21 -> 45597 | C21: 120.6 | D21: 170.1 | E21: 187.2 | F21: 155.4 | G21: 124.7 | H21: 132 | I21: 69 | J21: 36.2 | K21: 52.5 | L21: 65.2
A22: =+A21+1 -> 12 | B22: =+Base45h!B22 -> 45627 | C22: 19.9 | D22: 48.5 | E22: 74.8 | F22: 60.1 | G22: 32.4 | H22: 37.2 | I22: 12.6 | J22: 0 | K22: 1.2 | L22: 6.1
A23: =+A22+1 -> 13 | B23: Annual | C23: =SUM(C11:C22) -> 4548.5 | D23: =SUM(D11:D22) -> 4138.9 | E23: =SUM(E11:E22) -> 4679.7 | F23: =SUM(F11:F22) -> 4491.5 | G23: =SUM(G11:G22) -> 3966.2 | H23: =SUM(H11:H22) -> 4333.3 | I23: =SUM(I11:I22) -> 4265 | J23: =SUM(J11:J22) -> 3960.3 | ... L23: =SUM(L11:L22) -> 4002.8
A24: =+A23+1 -> 14
A25: =+A24+1 -> 15
A26: =+A25+1 -> 16 | B26: Calendar Normal Cooling Degree Days by Weather Sites (Base 60)
A27: =+A26+1 -> 17 | C27: Dallas/ Fort Worth (MX) | D27: Lufkin (LU) | E27: Austin (AU) | F27: Killeen (KI) | G27: Longview (LO) | H27: Waco (WO) | I27: Abilene (AE) | J27: Wichita Falls (WF) | K27: Midland/ Odessa (MO) | L27: Denison (DE)
A28: =+A27+1 -> 18 | B28: =+Base45h!B28 -> 45292 | C28: 15.10375 | D28: 28.914167 | E28: 27.311667 | F28: 20.452917 | G28: 19.522083 | H28: 15.06875 | I28: 7.0304167 | J28: 4.13375 | K28: 1.1341667 | L28: 7.5991667
A29: =+A28+1 -> 19 | B29: =+Base45h!B29 -> 45323 | C29: 33.699583 | D29: 48.889583 | E29: 54.298333 | F29: 43.047917 | G29: 34.504167 | H29: 32.929583 | I29: 21.496667 | J29: 11.489583 | K29: 14.339583 | L29: 15.87125
A30: =+A29+1 -> 20 | B30: =+Base45h!B30 -> 45352 | C30: 113.83417 | D30: 130.24792 | E30: 146.12875 | F30: 122.87 | G30: 102.80875 | H30: 111.44167 | I30: 93.0075 | J30: 71.182917 | K30: 86.6 | L30: 68.035
A31: =+A30+1 -> 21 | B31: =+Base45h!B31 -> 45383 | C31: 224.65083 | D31: 234.82583 | E31: 262.51417 | F31: 236.22 | G31: 197.08542 | H31: 223.85125 | I31: 206.88542 | J31: 166.2275 | K31: 224.80833 | L31: 151.91583
A32: =+A31+1 -> 22 | B32: =+Base45h!B32 -> 45413 | C32: 456.35917 | D32: 447.04583 | E32: 479.28875 | F32: 443.895 | G32: 413.985 | H32: 449.67083 | I32: 414.44583 | J32: 389.14458 | K32: 452.025 | L32: 358.67375
A33: =+A32+1 -> 23 | B33: =+Base45h!B33 -> 45444 | C33: 696.71833 | D33: 632.3375 | E33: 666.51792 | F33: 658.32792 | G33: 621.55625 | H33: 679.61875 | I33: 633.02042 | J33: 639.8925 | K33: 672.55081 | L33: 617.34333
A34: =+A33+1 -> 24 | B34: =+Base45h!B34 -> 45474 | C34: 817.59625 | D34: 704.83167 | E34: 742.35083 | F34: 759.72542 | G34: 716.6125 | H34: 792.90292 | I34: 738.71417 | J34: 769.70125 | K34: 726.29917 | L34: 744.56583
A35: =+A34+1 -> 25 | B35: =+Base45h!B35 -> 45505 | C35: 827.55042 | D35: 720.95833 | E35: 770.03458 | F35: 776.57 | G35: 727.49625 | H35: 806.29292 | I35: 732.94792 | J35: 756.94208 | K35: 701.49167 | L35: 745.96625
A36: =+A35+1 -> 26 | B36: =+Base45h!B36 -> 45536 | C36: 600.20125 | D36: 542.16833 | E36: 577.4725 | F36: 560.86208 | G36: 526.06042 | H36: 581.95042 | I36: 497.9925 | J36: 507.105 | K36: 475.24542 | L36: 521.97917
A37: =+A36+1 -> 27 | B37: =+Base45h!B37 -> 45566 | C37: 295.93792 | D37: 281.41833 | E37: 320.74167 | F37: 298.17583 | G37: 245.22333 | H37: 296.96542 | I37: 240.38458 | J37: 207.66917 | K37: 222.32042 | L37: 229.48792
A38: =+A37+1 -> 28 | B38: =+Base45h!B38 -> 45597 | C38: 78.928333 | D38: 89.537083 | E38: 108.82083 | F38: 88.110833 | G38: 68.302917 | H38: 84.87 | I38: 54.035 | J38: 37.624583 | K38: 33.517917 | L38: 52.365417
A39: =+A38+1 -> 29 | B39: =+Base45h!B39 -> 45627 | C39: 25.556667 | D39: 49.51375 | E39: 44.15375 | F39: 32.98625 | G39: 34.468333 | H39: 29.043333 | I39: 14.852917 | J39: 6.6141667 | K39: 4.2545833 | L39: 13.380417
A40: =+A39+1 -> 30 | B40: Annual | C40: =SUM(C28:C39) -> 4186.1367 | D40: =SUM(D28:D39) -> 3910.6883 | E40: =SUM(E28:E39) -> 4199.6338 | F40: =SUM(F28:F39) -> 4041.2442 | G40: =SUM(G28:G39) -> 3707.6254 | H40: =SUM(H28:H39) -> 4104.6058 | I40: =SUM(I28:I39) -> 3654.8133 | J40: =SUM(J28:J39) -> 3567.7271 | ... L40: =SUM(L28:L39) -> 3527.1833

Sheet Base65c
B1: =+Base45h!B1 -> PUC DOCKET NO.
B2: =+Base45h!B2 -> ONCOR ELECTRIC DELIVERY COMPANY LLC
B3: =+Base45h!B3 -> WEATHER STATION DATA
B4: =+Base45h!B4 -> FOR THE TEST YEAR ENDING DECEMBER 31, 2024
B6: =+Base45h!B6 -> SPONSOR: D. E. NELSON
B9: Calendar Actual Cooling Degree Days by Weather Sites (Base 65)
A10: Line No. | C10: Dallas/ Fort Worth (MX) | D10: Lufkin (LU) | E10: Austin (AU) | F10: Killeen (KI) | G10: Longview (LO) | H10: Waco (WO) | I10: Abilene (AE) | J10: Wichita Falls (WF) | K10: Midland/ Odessa (MO) | L10: Denison (DE)
A11: 1 | B11: =+Base45h!B11 -> 45292 | C11: 0 | D11: 0 | E11: 0 | F11: 0 | G11: 0 | H11: 0 | I11: 0 | J11: 0 | K11: 0 | L11: 0
A12: =+A11+1 -> 2 | B12: =+Base45h!B12 -> 45323 | C12: 28.7 | D12: 25.7 | E12: 20.3 | F12: 27.1 | G12: 29.4 | H12: 19 | I12: 32.4 | J12: 15.4 | K12: 11 | L12: 19.1
A13: =+A12+1 -> 3 | B13: =+Base45h!B13 -> 45352 | C13: 47.4 | D13: 60.7 | E13: 63.1 | F13: 55.9 | G13: 49.7 | H13: 46.8 | I13: 31.3 | J13: 27.5 | K13: 14 | L13: 32.6
A14: =+A13+1 -> 4 | B14: =+Base45h!B14 -> 45383 | C14: 152.5 | D14: 154.6 | E14: 178.5 | F14: 155.9 | G14: 142.4 | H14: 134.6 | I14: 161.8 | J14: 98.2 | K14: 134.3 | L14: 113.2
A15: =+A14+1 -> 5 | B15: =+Base45h!B15 -> 45413 | C15: 368.7 | D15: 344.6 | E15: 427.1 | F15: 352.3 | G15: 344.4 | H15: 340 | I15: 335.9 | J15: 280.5 | K15: 365.2 | L15: 297.4
A16: =+A15+1 -> 6 | B16: =+Base45h!B16 -> 45444 | C16: 572.3 | D16: 503 | E16: 562.2 | F16: 547.3 | G16: 493.9 | H16: 547.8 | I16: 561.4 | J16: 485.9 | K16: 574.6 | L16: 542.1
A17: =+A16+1 -> 7 | B17: =+Base45h!B17 -> 45474 | C17: 613.3 | D17: 484 | E17: 539.1 | F17: 549.4 | G17: 493.8 | H17: 566.2 | I17: 606.5 | J17: 581.7 | K17: 531.9 | L17: 564.5
A18: =+A17+1 -> 8 | B18: =+Base45h!B18 -> 45505 | C18: 730.3 | D18: 590.8 | E18: 630.5 | F18: 669.1 | G18: 582.2 | H18: 672.4 | I18: 740.8 | J18: 726.1 | K18: 660.9 | L18: 650.1
A19: =+A18+1 -> 9 | B19: =+Base45h!B19 -> 45536 | C19: 427 | D19: 366.8 | E19: 481.9 | F19: 426.4 | G19: 343.7 | H19: 400.5 | I19: 346.1 | J19: 386 | K19: 290.9 | L19: 357.9
A20: =+A19+1 -> 10 | B20: =+Base45h!B20 -> 45566 | C20: 334.7 | D20: 226.5 | E20: 320.8 | F20: 328 | G20: 204.3 | H20: 301.6 | I20: 267.5 | J20: 262.9 | K20: 217.3 | L20: 270.1
A21: =+A20+1 -> 11 | B21: =+Base45h!B21 -> 45597 | C21: 42.6 | D21: 82.7 | E21: 95.9 | F21: 69.3 | G21: 46.5 | H21: 54.8 | I21: 17.5 | J21: 3.8 | K21: 14.9 | L21: 19.9
A22: =+A21+1 -> 12 | B22: =+Base45h!B22 -> 45627 | C22: 3.2 | D22: 16 | E22: 30.3 | F22: 20.9 | G22: 12.4 | H22: 8.6 | I22: 0 | J22: 0 | K22: 0 | L22: 1
A23: =+A22+1 -> 13 | B23: Annual | C23: =SUM(C11:C22) -> 3320.7 | D23: =SUM(D11:D22) -> 2855.4 | E23: =SUM(E11:E22) -> 3349.7 | F23: =SUM(F11:F22) -> 3201.6 | G23: =SUM(G11:G22) -> 2742.7 | H23: =SUM(H11:H22) -> 3092.3 | I23: =SUM(I11:I22) -> 3101.2 | J23: =SUM(J11:J22) -> 2868 | ... L23: =SUM(L11:L22) -> 2867.9
A24: =+A23+1 -> 14
A25: =+A24+1 -> 15
A26: =+A25+1 -> 16 | B26: Calendar Normal Cooling Degree Days by Weather Sites (Base 65)
A27: =+A26+1 -> 17 | C27: Dallas/ Fort Worth (MX) | D27: Lufkin (LU) | E27: Austin (AU) | F27: Killeen (KI) | G27: Longview (LO) | H27: Waco (WO) | I27: Abilene (AE) | J27: Wichita Falls (WF) | K27: Midland/ Odessa (MO) | L27: Denison (DE)
A28: =+A27+1 -> 18 | B28: =+Base45h!B28 -> 45292 | C28: 3.71 | D28: 9.1066667 | E28: 7.9720833 | F28: 4.6475 | G28: 5.3233333 | H28: 3.2895833 | I28: 0.37708333 | J28: 0.50333333 | K28: 0 | L28: 1.0954167
A29: =+A28+1 -> 19 | B29: =+Base45h!B29 -> 45323 | C29: 9.9866667 | D29: 17.442917 | E29: 19.8325 | F29: 12.465417 | G29: 11.393333 | H29: 8.3704167 | I29: 4.5441667 | J29: 2.94 | K29: 2.275 | L29: 3.5108333
A30: =+A29+1 -> 20 | B30: =+Base45h!B30 -> 45352 | C30: 47.555833 | D30: 55.865833 | E30: 65.229167 | F30: 50.278333 | G30: 41.764167 | H30: 44.41 | I30: 36.046667 | J30: 27.055417 | K30: 32.261667 | L30: 23.77125
A31: =+A30+1 -> 21 | B31: =+Base45h!B31 -> 45383 | C31: 114.70292 | D31: 120.09292 | E31: 141.67208 | F31: 122.21333 | G31: 94.94625 | H31: 115.37875 | I31: 109.10833 | J31: 81.687083 | K31: 121.18167 | L31: 67.545
A32: =+A31+1 -> 22 | B32: =+Base45h!B32 -> 45413 | C32: 309.10625 | D32: 296.36958 | E32: 327.90625 | F32: 294.80917 | G32: 267.35875 | H32: 301.16167 | I32: 273.62625 | J32: 251.33125 | K32: 309.4075 | L32: 221.06333
A33: =+A32+1 -> 23 | B33: =+Base45h!B33 -> 45444 | C33: 546.71833 | D33: 482.3375 | E33: 516.51792 | F33: 508.32792 | G33: 471.55625 | H33: 529.61875 | I33: 483.02042 | J33: 489.8925 | K33: 522.55081 | L33: 467.34333
A34: =+A33+1 -> 24 | B34: =+Base45h!B34 -> 45474 | C34: 662.59625 | D34: 549.83167 | E34: 587.35083 | F34: 604.72542 | G34: 561.6125 | H34: 637.90292 | I34: 583.71417 | J34: 614.70125 | K34: 571.38667 | L34: 589.56583
A35: =+A34+1 -> 25 | B35: =+Base45h!B35 -> 45505 | C35: 672.55042 | D35: 565.95833 | E35: 615.03458 | F35: 621.57 | G35: 572.49625 | H35: 651.29292 | I35: 577.94792 | J35: 601.94208 | K35: 546.49167 | L35: 590.96625
A36: =+A35+1 -> 26 | B36: =+Base45h!B36 -> 45536 | C36: 450.57125 | D36: 392.25833 | E36: 427.8725 | F36: 411.70708 | G36: 376.48542 | H36: 432.45542 | I36: 351.54917 | J36: 360.39208 | K36: 329.58542 | L36: 373.49
A37: =+A36+1 -> 27 | B37: =+Base45h!B37 -> 45566 | C37: 177.12542 | D37: 162.645 | E37: 195.57958 | F37: 177.01083 | G37: 137.05125 | H37: 178.26333 | I37: 134.20875 | J37: 111.76375 | K37: 117.53708 | L37: 126.79708
A38: =+A37+1 -> 28 | B38: =+Base45h!B38 -> 45597 | C38: 30.25 | D38: 37.168333 | E38: 49.515 | F38: 34.491667 | G38: 26.720833 | H38: 34.065 | I38: 17.36125 | J38: 11.6075 | K38: 7.6933333 | L38: 16.706667
A39: =+A38+1 -> 29 | B39: =+Base45h!B39 -> 45627 | C39: 8.47 | D39: 19.899583 | E39: 16.032083 | F39: 11.094583 | G39: 12.549583 | H39: 10.174167 | I39: 3.0358333 | J39: 1.5520833 | K39: 0.25166667 | L39: 3.3570833
A40: =+A39+1 -> 30 | B40: Annual | C40: =SUM(C28:C39) -> 3033.3433 | D40: =SUM(D28:D39) -> 2708.9767 | E40: =SUM(E28:E39) -> 2970.5146 | F40: =SUM(F28:F39) -> 2853.3413 | G40: =SUM(G28:G39) -> 2579.2579 | H40: =SUM(H28:H39) -> 2946.3829 | I40: =SUM(I28:I39) -> 2574.54 | J40: =SUM(J28:J39) -> 2555.3683 | ... L40: =SUM(L28:L39) -> 2485.2121

Sheet Base70c
B1: =+Base45h!B1 -> PUC DOCKET NO.
B2: =+Base45h!B2 -> ONCOR ELECTRIC DELIVERY COMPANY LLC
B3: =+Base45h!B3 -> WEATHER STATION DATA
B4: =+Base45h!B4 -> FOR THE TEST YEAR ENDING DECEMBER 31, 2024
B6: =+Base45h!B6 -> SPONSOR: D. E. NELSON
B9: Calendar Actual Cooling Degree Days by Weather Sites (Base 70)
A10: Line No. | C10: Dallas/ Fort Worth (MX) | D10: Lufkin (LU) | E10: Austin (AU) | F10: Killeen (KI) | G10: Longview (LO) | H10: Waco (WO) | I10: Abilene (AE) | J10: Wichita Falls (WF) | K10: Midland/ Odessa (MO) | L10: Denison (DE)
A11: 1 | B11: =+Base45h!B11 -> 45292 | C11: 0 | D11: 0 | E11: 0 | F11: 0 | G11: 0 | H11: 0 | I11: 0 | J11: 0 | K11: 0 | L11: 0
A12: =+A11+1 -> 2 | B12: =+Base45h!B12 -> 45323 | C12: 6.9 | D12: 8.1 | E12: 3.5 | F12: 5 | G12: 8.8 | H12: 1 | I12: 12.1 | J12: 3.2 | K12: 0.2 | L12: 2.7
A13: =+A12+1 -> 3 | B13: =+Base45h!B13 -> 45352 | C13: 11.1 | D13: 13.9 | E13: 11.9 | F13: 11.4 | G13: 10.4 | H13: 6.9 | I13: 1.9 | J13: 1.9 | K13: 0.5 | L13: 5.4
A14: =+A13+1 -> 4 | B14: =+Base45h!B14 -> 45383 | C14: 58 | D14: 58.9 | E14: 82.5 | F14: 60.2 | G14: 53.9 | H14: 46.9 | I14: 65.9 | J14: 26.5 | K14: 53.3 | L14: 33.3
A15: =+A14+1 -> 5 | B15: =+Base45h!B15 -> 45413 | C15: 217.5 | D15: 194.4 | E15: 272.1 | F15: 204.4 | G15: 193.6 | H15: 189.8 | I15: 193.6 | J15: 142.4 | K15: 227 | L15: 154.1
A16: =+A15+1 -> 6 | B16: =+Base45h!B16 -> 45444 | C16: 422.3 | D16: 353 | E16: 412.2 | F16: 397.3 | G16: 343.9 | H16: 397.8 | I16: 411.4 | J16: 350.9 | K16: 424.6 | L16: 392.1
A17: =+A16+1 -> 7 | B17: =+Base45h!B17 -> 45474 | C17: 458.3 | D17: 329 | E17: 384.1 | F17: 394.4 | G17: 338.8 | H17: 411.2 | I17: 451.5 | J17: 426.7 | K17: 377.5 | L17: 409.5
A18: =+A17+1 -> 8 | B18: =+Base45h!B18 -> 45505 | C18: 575.3 | D18: 435.8 | E18: 475.5 | F18: 514.1 | G18: 427.2 | H18: 517.4 | I18: 585.8 | J18: 571.1 | K18: 505.9 | L18: 495.1
A19: =+A18+1 -> 9 | B19: =+Base45h!B19 -> 45536 | C19: 277 | D19: 216.8 | E19: 331.9 | F19: 276.4 | G19: 194.1 | H19: 251.2 | I19: 200.3 | J19: 237.7 | K19: 152.1 | L19: 207.9
A20: =+A19+1 -> 10 | B20: =+Base45h!B20 -> 45566 | C20: 199.7 | D20: 107.6 | E20: 179.8 | F20: 187.3 | G20: 87.7 | H20: 166.8 | I20: 138.4 | J20: 142.5 | K20: 93.8 | L20: 142
A21: =+A20+1 -> 11 | B21: =+Base45h!B21 -> 45597 | C21: 10.8 | D21: 23.7 | E21: 40.9 | F21: 17.4 | G21: 13.3 | H21: 17.4 | I21: 2.5 | J21: 0 | K21: 2.4 | L21: 1.4
A22: =+A21+1 -> 12 | B22: =+Base45h!B22 -> 45627 | C22: 0 | D22: 1 | E22: 3 | F22: 0.2 | G22: 0 | H22: 0 | I22: 0 | J22: 0 | K22: 0 | L22: 0
A23: =+A22+1 -> 13 | B23: Annual | C23: =SUM(C11:C22) -> 2236.9 | D23: =SUM(D11:D22) -> 1742.2 | E23: =SUM(E11:E22) -> 2197.4 | F23: =SUM(F11:F22) -> 2068.1 | G23: =SUM(G11:G22) -> 1671.7 | H23: =SUM(H11:H22) -> 2006.4 | I23: =SUM(I11:I22) -> 2063.4 | J23: =SUM(J11:J22) -> 1902.9 | ... L23: =SUM(L11:L22) -> 1843.5
A24: =+A23+1 -> 14
A25: =+A24+1 -> 15
A26: =+A25+1 -> 16 | B26: Calendar Normal Cooling Degree Days by Weather Sites (Base 70)
A27: =+A26+1 -> 17 | C27: Dallas/ Fort Worth (MX) | D27: Lufkin (LU) | E27: Austin (AU) | F27: Killeen (KI) | G27: Longview (LO) | H27: Waco (WO) | I27: Abilene (AE) | J27: Wichita Falls (WF) | K27: Midland/ Odessa (MO) | L27: Denison (DE)
A28: =+A27+1 -> 18 | B28: =+Base45h!B28 -> 45292 | C28: 0.315 | D28: 1.31875 | E28: 1.09125 | F28: 0.31875 | G28: 0.195 | H28: 0.085 | I28: 0 | J28: 0 | K28: 0 | L28: 0
A29: =+A28+1 -> 19 | B29: =+Base45h!B29 -> 45323 | C29: 1.7491667 | D29: 2.8 | E29: 3.24125 | F29: 0.97 | G29: 1.5675 | H29: 0.575 | I29: 0.39 | J29: 0.2 | K29: 0.01 | L29: 0.215
A30: =+A29+1 -> 20 | B30: =+Base45h!B30 -> 45352 | C30: 11.882917 | D30: 13.0075 | E30: 16.854167 | F30: 9.4279167 | G30: 8.53375 | H30: 8.5833333 | I30: 7.3695833 | J30: 5.6154167 | K30: 6.3504167 | L30: 3.7141667
A31: =+A30+1 -> 21 | B31: =+Base45h!B31 -> 45383 | C31: 41.924167 | D31: 43.18875 | E31: 57.089583 | F31: 45.024167 | G31: 30.6575 | H31: 42.055833 | I31: 44.4975 | J31: 29.981667 | K31: 48.72875 | L31: 19.164167
A32: =+A31+1 -> 22 | B32: =+Base45h!B32 -> 45413 | C32: 173.93542 | D32: 159.24917 | E32: 186.45167 | F32: 159.44542 | G32: 138.32708 | H32: 167.12333 | I32: 153.24708 | J32: 134.44417 | K32: 184.95875 | L32: 107.90708
A33: =+A32+1 -> 23 | B33: =+Base45h!B33 -> 45444 | C33: 396.80333 | D33: 332.3375 | E33: 366.71792 | F33: 358.46292 | G33: 321.55625 | H33: 379.61875 | I33: 333.78417 | J33: 340.4825 | K33: 373.35581 | L33: 318.19833
A34: =+A33+1 -> 24 | B34: =+Base45h!B34 -> 45474 | C34: 507.59625 | D34: 394.83167 | E34: 432.35083 | F34: 449.75042 | G34: 406.7175 | H34: 482.90292 | I34: 429.15542 | J34: 460.22125 | K34: 417.64625 | L34: 434.98708
A35: =+A34+1 -> 25 | B35: =+Base45h!B35 -> 45505 | C35: 517.55042 | D35: 411.00833 | E35: 460.03458 | F35: 466.57 | G35: 417.49625 | H35: 496.29292 | I35: 423.12375 | J35: 446.96917 | K35: 391.66458 | L35: 435.96625
A36: =+A35+1 -> 26 | B36: =+Base45h!B36 -> 45536 | C36: 304.24292 | D36: 245.51167 | E36: 280.7025 | F36: 265.97375 | G36: 233.00792 | H36: 286.4625 | I36: 216.6125 | J36: 222.8275 | K36: 195.38125 | L36: 234.9775
A37: =+A36+1 -> 27 | B37: =+Base45h!B37 -> 45566 | C37: 86.375 | D37: 73.815 | E37: 95.365833 | F37: 80.95625 | G37: 59.44625 | H37: 85.214583 | I37: 55.192083 | J37: 46.088333 | K37: 46.264167 | L37: 54.293333
A38: =+A37+1 -> 28 | B38: =+Base45h!B38 -> 45597 | C38: 8.4958333 | D38: 9.4425 | E38: 15.199167 | F38: 8.55125 | G38: 6.5008333 | H38: 8.25875 | I38: 3.1195833 | J38: 2.1545833 | K38: 1.035 | L38: 3.1825
A39: =+A38+1 -> 29 | B39: =+Base45h!B39 -> 45627 | C39: 1.4683333 | D39: 3.8979167 | E39: 3.5225 | F39: 1.7154167 | G39: 1.7325 | H39: 1.5875 | I39: 0.335 | J39: 0.19 | K39: 0 | L39: 0.22
A40: =+A39+1 -> 30 | B40: Annual | C40: =SUM(C28:C39) -> 2052.3388 | D40: =SUM(D28:D39) -> 1690.4088 | E40: =SUM(E28:E39) -> 1918.6213 | F40: =SUM(F28:F39) -> 1847.1663 | G40: =SUM(G28:G39) -> 1625.7383 | H40: =SUM(H28:H39) -> 1958.7604 | I40: =SUM(I28:I39) -> 1666.8267 | J40: =SUM(J28:J39) -> 1689.1746 | ... L40: =SUM(L28:L39) -> 1612.8254

Sheet Base75c
B1: =+Base45h!B1 -> PUC DOCKET NO.
B2: =+Base45h!B2 -> ONCOR ELECTRIC DELIVERY COMPANY LLC
B3: =+Base45h!B3 -> WEATHER STATION DATA
B4: =+Base45h!B4 -> FOR THE TEST YEAR ENDING DECEMBER 31, 2024
B6: =+Base45h!B6 -> SPONSOR: D. E. NELSON
B9: Calendar Actual Cooling Degree Days by Weather Sites (Base 75)
A10: Line No. | C10: Dallas/ Fort Worth (MX) | D10: Lufkin (LU) | E10: Austin (AU) | F10: Killeen (KI) | G10: Longview (LO) | H10: Waco (WO) | I10: Abilene (AE) | J10: Wichita Falls (WF) | K10: Midland/ Odessa (MO) | L10: Denison (DE)
A11: 1 | B11: =+Base45h!B11 -> 45292 | C11: 0 | D11: 0 | E11: 0 | F11: 0 | G11: 0 | H11: 0 | I11: 0 | J11: 0 | K11: 0 | L11: 0
A12: =+A11+1 -> 2 | B12: =+Base45h!B12 -> 45323 | C12: 0 | D12: 0.1 | E12: 0 | F12: 0 | G12: 0 | H12: 0 | I12: 0 | J12: 0 | K12: 0 | L12: 0
A13: =+A12+1 -> 3 | B13: =+Base45h!B13 -> 45352 | C13: 0 | D13: 1.8 | E13: 0 | F13: 0 | G13: 1.1 | H13: 0 | I13: 0 | J13: 0 | K13: 0 | L13: 0
A14: =+A13+1 -> 4 | B14: =+Base45h!B14 -> 45383 | C14: 6.2 | D14: 4.7 | E14: 15.1 | F14: 6.9 | G14: 7 | H14: 4.4 | I14: 10.6 | J14: 0.6 | K14: 7.6 | L14: 0.5
A15: =+A14+1 -> 5 | B15: =+Base45h!B15 -> 45413 | C15: 91.2 | D15: 74.8 | E15: 137.3 | F15: 96 | G15: 75 | H15: 83.4 | I15: 88.6 | J15: 52.2 | K15: 107.8 | L15: 56.8
A16: =+A15+1 -> 6 | B16: =+Base45h!B16 -> 45444 | C16: 274.4 | D16: 203 | E16: 262.2 | F16: 247.3 | G16: 197.1 | H16: 247.8 | I16: 261.4 | J16: 224 | K16: 277.1 | L16: 246.9
A17: =+A16+1 -> 7 | B17: =+Base45h!B17 -> 45474 | C17: 303.3 | D17: 174.8 | E17: 229.1 | F17: 239.4 | G17: 186.8 | H17: 256.2 | I17: 296.5 | J17: 275.3 | K17: 227.7 | L17: 255.1
A18: =+A17+1 -> 8 | B18: =+Base45h!B18 -> 45505 | C18: 420.3 | D18: 280.8 | E18: 320.5 | F18: 359.1 | G18: 272.2 | H18: 362.4 | I18: 430.8 | J18: 416.1 | K18: 350.9 | L18: 340.1
A19: =+A18+1 -> 9 | B19: =+Base45h!B19 -> 45536 | C19: 133.1 | D19: 83.1 | E19: 184.6 | F19: 136.4 | G19: 67.5 | H19: 119.7 | I19: 84.3 | J19: 108.1 | K19: 53.1 | L19: 90.1
A20: =+A19+1 -> 10 | B20: =+Base45h!B20 -> 45566 | C20: 80.3 | D20: 23.6 | E20: 59.5 | F20: 65.6 | G20: 11.7 | H20: 50 | I20: 39.3 | J20: 49 | K20: 15.6 | L20: 42.2
A21: =+A20+1 -> 11 | B21: =+Base45h!B21 -> 45597 | C21: 0 | D21: 2.3 | E21: 9.5 | F21: 2 | G21: 1.8 | H21: 1.8 | I21: 0 | J21: 0 | K21: 0 | L21: 0
A22: =+A21+1 -> 12 | B22: =+Base45h!B22 -> 45627 | C22: 0 | D22: 0 | E22: 0 | F22: 0 | G22: 0 | H22: 0 | I22: 0 | J22: 0 | K22: 0 | L22: 0
A23: =+A22+1 -> 13 | B23: Annual | C23: =SUM(C11:C22) -> 1308.8 | D23: =SUM(D11:D22) -> 849 | E23: =SUM(E11:E22) -> 1217.8 | F23: =SUM(F11:F22) -> 1152.7 | G23: =SUM(G11:G22) -> 820.2 | H23: =SUM(H11:H22) -> 1125.7 | I23: =SUM(I11:I22) -> 1211.5 | J23: =SUM(J11:J22) -> 1125.3 | ... L23: =SUM(L11:L22) -> 1031.7
A24: =+A23+1 -> 14
A25: =+A24+1 -> 15
A26: =+A25+1 -> 16 | B26: Calendar Normal Cooling Degree Days by Weather Sites (Base 75)
A27: =+A26+1 -> 17 | C27: Dallas/ Fort Worth (MX) | D27: Lufkin (LU) | E27: Austin (AU) | F27: Killeen (KI) | G27: Longview (LO) | H27: Waco (WO) | I27: Abilene (AE) | J27: Wichita Falls (WF) | K27: Midland/ Odessa (MO) | L27: Denison (DE)
A28: =+A27+1 -> 18 | B28: =+Base45h!B28 -> 45292 | C28: 0 | D28: 0 | E28: 0 | F28: 0 | G28: 0 | H28: 0 | I28: 0 | J28: 0 | K28: 0 | L28: 0
