Workbook

Sheet RES Model
B1: PUC DOCKET NO.
B2: ONCOR ELECTRIC DELIVERY COMPANY LLC
B3: MODEL INFORMATION
B4: FOR THE TEST YEAR ENDING DECEMBER 31, 2024
B6: SPONSOR: D. E. NELSON
B8: RESIDENTIAL MODEL
A9: Line
A10: No. | B10: (a) | C10: (b) | D10: (c) | E10: (d) | F10: (e)
A11: 1 | B11: After Corrective Procedures for Autocorrelation
A12: =+A11+1 -> 2 | B12: Dependent Variable: | C12: Res_UPC_Day
A13: =+A12+1 -> 3 | B13: Estimation Begin Date: | C13: 40179
A14: =+A13+1 -> 4 | B14: Estimation End Date: | C14: 45444
A15: =+A14+1 -> 5
A16: =+A15+1 -> 6 | B16: Variable | C16: Coefficient | D16: StdErr | E16: T-Stat | F16: P-Value
A17: =+A16+1 -> 7 | B17: Cyc_WthrT.XHeat | C17: 1.939 | D17: 0.068 | E17: 28.696 | F17: 0
A18: =+A17+1 -> 8 | B18: Cyc_WthrT.XCool | C18: 2.164 | D18: 0.056 | E18: 38.78 | F18: 0
A19: =+A18+1 -> 9 | B19: ResVars.XOther | C19: 0.416 | D19: 0.314 | E19: 1.325 | F19: 0.1872
A20: =+A19+1 -> 10 | B20: CalVars.Jan | C20: 15.92 | D20: 8.231 | E20: 1.934 | F20: 0.055
A21: =+A20+1 -> 11 | B21: CalVars.Feb | C21: 15.577 | D21: 8.195 | E21: 1.901 | F21: 0.0593
A22: =+A21+1 -> 12 | B22: CalVars.Mar | C22: 14.507 | D22: 8.148 | E22: 1.78 | F22: 0.0771
A23: =+A22+1 -> 13 | B23: CalVars.Apr | C23: 14.054 | D23: 8.032 | E23: 1.75 | F23: 0.0822
A24: =+A23+1 -> 14 | B24: CalVars.May | C24: 14.773 | D24: 7.995 | E24: 1.848 | F24: 0.0666
A25: =+A24+1 -> 15 | B25: CalVars.Jun | C25: 16.756 | D25: 8.003 | E25: 2.094 | F25: 0.038
A26: =+A25+1 -> 16 | B26: CalVars.Jul | C26: 18.231 | D26: 7.879 | E26: 2.314 | F26: 0.0221
A27: =+A26+1 -> 17 | B27: CalVars.Aug | C27: 18.373 | D27: 7.839 | E27: 2.344 | F27: 0.0204
A28: =+A27+1 -> 18 | B28: CalVars.Sep | C28: 17.953 | D28: 7.873 | E28: 2.28 | F28: 0.024
... A39: =+A38+1 -> 29 | B39: AR(4) | C39: -0.177 | D39: 0.08 | E39: -2.204 | F39: 0.0291
A40: =+A39+1 -> 30
A41: =+A40+1 -> 31 | B41: Model Statistics
A42: =+A41+1 -> 32 | B42: Adjusted Observations | C42: 170
A43: =+A42+1 -> 33 | B43: Deg. of Freedom for Error | C43: 147
A44: =+A43+1 -> 34 | B44: R-Squared | C44: 0.997
A45: =+A44+1 -> 35 | B45: Adjusted R-Squared | C45: 0.997
A46: =+A45+1 -> 36 | B46: F-Statistic | C46: 2440.805
A47: =+A46+1 -> 37 | B47: Prob (F-Statistic) | C47: 0
A48: =+A47+1 -> 38 | B48: Model Sum of Squares | C48: 19493.3
A49: =+A48+1 -> 39 | B49: Sum of Squared Errors | C49: 53.36
A50: =+A49+1 -> 40 | B50: Mean Squared Error | C50: 0.36
A51: =+A50+1 -> 41 | B51: Std. Error of Regression | C51: 0.6
A52: =+A51+1 -> 42 | B52: Mean Abs. Dev. (MAD) | C52: 0.46
...

Sheet RES Model Graph
B1: =+'RES Model'!B1:F1 -> PUC DOCKET NO.
B2: =+'RES Model'!B2:F2 -> ONCOR ELECTRIC DELIVERY COMPANY LLC
B3: =+'RES Model'!B3:F3 -> MODEL INFORMATION
B4: =+'RES Model'!B4:F4 -> FOR THE TEST YEAR ENDING DECEMBER 31, 2024
B6: =+'RES Model'!B6:F6 -> SPONSOR: D. E. NELSON
A8: Line
A9: No.
A10: 1 | B10: Residential Model
A11: =+A10+1 -> 2 | B11: After Corrective Procedures for Autocorrelation
A12: =+A11+1 -> 3
A13: =+A12+1 -> 4
A14: =+A13+1 -> 5
A15: =+A14+1 -> 6
A16: =+A15+1 -> 7
A17: =+A16+1 -> 8
A18: =+A17+1 -> 9
A19: =+A18+1 -> 10
A20: =+A19+1 -> 11
A21: =+A20+1 -> 12
A22: =+A21+1 -> 13
A23: =+A22+1 -> 14
... A37: =+A36+1 -> 28

Sheet SECLE10KW Model
B1: =+'RES Model'!B1:F1 -> PUC DOCKET NO.
B2: =+'RES Model'!B2:F2 -> ONCOR ELECTRIC DELIVERY COMPANY LLC
B3: =+'RES Model'!B3:F3 -> MODEL INFORMATION
B4: =+'RES Model'!B4:F4 -> FOR THE TEST YEAR ENDING DECEMBER 31, 2024
B6: =+'RES Model'!B6:F6 -> SPONSOR: D. E. NELSON
B8: SECONDARY SERVICE LESS THAN OR EQUAL TO 10 KW MODEL
A9: Line
A10: No. | B10: (a) | C10: (b) | D10: (c) | E10: (d) | F10: (e)
A11: 1 | B11: After Corrective Procedures for Autocorrelation
A12: =+A11+1 -> 2 | B12: Dependent Variable: | C12: SS_UPC_Day
A13: =+A12+1 -> 3 | B13: Estimation Begin Date: | C13: =+'RES Model'!C13 -> 40179
A14: =+A13+1 -> 4 | B14: Estimation End Date: | C14: =+'RES Model'!C14 -> 45444
A15: =+A14+1 -> 5
A16: =+A15+1 -> 6 | B16: Variable | C16: Coefficient | D16: StdErr | E16: T-Stat | F16: P-Value
A17: =+A16+1 -> 7 | B17: Cyc_WthrT.SS_HDD | C17: 0.368 | D17: 0.023 | E17: 15.841 | F17: 0
A18: =+A17+1 -> 8 | B18: Cyc_WthrT.SS_CDD | C18: 0.318 | D18: 0.025 | E18: 12.78 | F18: 0
A19: =+A18+1 -> 9 | B19: CalVars.Jan | C19: 24.824 | D19: 83.313 | E19: 0.298 | F19: 0.7662
A20: =+A19+1 -> 10 | B20: CalVars.Feb | C20: 25.038 | D20: 83.313 | E20: 0.301 | F20: 0.7642
A21: =+A20+1 -> 11 | B21: CalVars.Mar | C21: 24.659 | D21: 83.31 | E21: 0.296 | F21: 0.7677
A22: =+A21+1 -> 12 | B22: CalVars.Apr | C22: 24.304 | D22: 83.307 | E22: 0.292 | F22: 0.7709
A23: =+A22+1 -> 13 | B23: CalVars.May | C23: 24.363 | D23: 83.305 | E23: 0.292 | F23: 0.7704
A24: =+A23+1 -> 14 | B24: CalVars.Jun | C24: 24.491 | D24: 83.302 | E24: 0.294 | F24: 0.7692
A25: =+A24+1 -> 15 | B25: CalVars.Jul | C25: 25.019 | D25: 83.306 | E25: 0.3 | F25: 0.7644
A26: =+A25+1 -> 16 | B26: CalVars.Aug | C26: 25.374 | D26: 83.308 | E26: 0.305 | F26: 0.7611
A27: =+A26+1 -> 17 | B27: CalVars.Sep | C27: 25.31 | D27: 83.309 | E27: 0.304 | F27: 0.7617
A28: =+A27+1 -> 18 | B28: CalVars.Oct | C28: 25.167 | D28: 83.309 | E28: 0.302 | F28: 0.763
... A40: =+A39+1 -> 30 | B40: AR(9) | C40: 0.169 | D40: 0.082 | E40: 2.066 | F40: 0.0407
A41: =+A40+1 -> 31
A42: =+A41+1 -> 32 | B42: Model Statistics
A43: =+A42+1 -> 33 | B43: Adjusted Observations | C43: 165
A44: =+A43+1 -> 34 | B44: Deg. of Freedom for Error | C44: 141
A45: =+A44+1 -> 35 | B45: R-Squared | C45: 0.968
A46: =+A45+1 -> 36 | B46: Adjusted R-Squared | C46: 0.962
A47: =+A46+1 -> 37 | B47: F-Statistic | C47: 183.179
A48: =+A47+1 -> 38 | B48: Prob (F-Statistic) | C48: 0
A49: =+A48+1 -> 39 | B49: Model Sum of Squares | C49: 656.15
A50: =+A49+1 -> 40 | B50: Sum of Squared Errors | C50: 21.96
A51: =+A50+1 -> 41 | B51: Mean Squared Error | C51: 0.16
A52: =+A51+1 -> 42 | B52: Std. Error of Regression | C52: 0.39
A53: =+A52+1 -> 43 | B53: Mean Abs. Dev. (MAD) | C53: 0.28
...

Sheet SECLE10KW Model Graph
B1: =+'RES Model'!B1:F1 -> PUC DOCKET NO.
B2: =+'RES Model'!B2:F2 -> ONCOR ELECTRIC DELIVERY COMPANY LLC
B3: =+'RES Model'!B3:F3 -> MODEL INFORMATION
B4: =+'RES Model'!B4:F4 -> FOR THE TEST YEAR ENDING DECEMBER 31, 2024
B6: =+'RES Model'!B6:F6 -> SPONSOR: D. E. NELSON
A8: Line
A9: No.
A10: 1 | B10: Secondary Service Less Than or Equal to 10 KW Model
A11: =+A10+1 -> 2 | B11: After Corrective Procedures for Autocorrelation
A12: =+A11+1 -> 3
A13: =+A12+1 -> 4
A14: =+A13+1 -> 5
A15: =+A14+1 -> 6
A16: =+A15+1 -> 7
A17: =+A16+1 -> 8
A18: =+A17+1 -> 9
A19: =+A18+1 -> 10
A20: =+A19+1 -> 11
A21: =+A20+1 -> 12
A22: =+A21+1 -> 13
A23: =+A22+1 -> 14
... A37: =+A36+1 -> 28

Sheet SECGT10KW Model
B1: =+'RES Model'!B1:F1 -> PUC DOCKET NO.
B2: =+'RES Model'!B2:F2 -> ONCOR ELECTRIC DELIVERY COMPANY LLC
B3: =+'RES Model'!B3:F3 -> MODEL INFORMATION
B4: =+'RES Model'!B4:F4 -> FOR THE TEST YEAR ENDING DECEMBER 31, 2024
B6: =+'RES Model'!B6:F6 -> SPONSOR: D. E. NELSON
B8: SECONDARY SERVICE GREATER THAN 10 KW MODEL
A9: Line
A10: No. | B10: (a) | C10: (b) | D10: (c) | E10: (d) | F10: (e)
A11: 1 | B11: After Corrective Procedures for Autocorrelation
A12: =+A11+1 -> 2 | B12: Dependent Variable: | C12: LS_UPC_Day
A13: =+A12+1 -> 3 | B13: Estimation Begin Date: | C13: =+'RES Model'!C13 -> 40179
A14: =+A13+1 -> 4 | B14: Estimation End Date: | C14: =+'RES Model'!C14 -> 45444
A15: =+A14+1 -> 5
A16: =+A15+1 -> 6 | B16: Variable | C16: Coefficient | D16: StdErr | E16: T-Stat | F16: P-Value
A17: =+A16+1 -> 7 | B17: Cyc_WthrT.LS_CDD | C17: 10.476 | D17: 0.488 | E17: 21.477 | F17: 0
A18: =+A17+1 -> 8 | B18: Cyc_WthrT.LS_HDD | C18: 5.685 | D18: 0.462 | E18: 12.302 | F18: 0
A19: =+A18+1 -> 9 | B19: Economic_Demogr_Data.EMFGONCOR | C19: 1.299 | D19: 0.061 | E19: 21.373 | F19: 0
A20: =+A19+1 -> 10 | B20: CalVars.Feb | C20: 13.352 | D20: 2.553 | E20: 5.23 | F20: 0
A21: =+A20+1 -> 11 | B21: CalVars.Mar | C21: 6.428 | D21: 2.601 | E21: 2.471 | F21: 0.0147
A22: =+A21+1 -> 12 | B22: CalVars.May | C22: 9.267 | D22: 2.822 | E22: 3.284 | F22: 0.0013
A23: =+A22+1 -> 13 | B23: CalVars.Jun | C23: 20.647 | D23: 5.202 | E23: 3.969 | F23: 0.0001
A24: =+A23+1 -> 14 | B24: CalVars.Jul | C24: 30.338 | D24: 7.974 | E24: 3.805 | F24: 0.0002
A25: =+A24+1 -> 15 | B25: CalVars.Aug | C25: 43.481 | D25: 9.253 | E25: 4.699 | F25: 0
A26: =+A25+1 -> 16 | B26: CalVars.Sep | C26: 50.271 | D26: 8.2 | E26: 6.131 | F26: 0
A27: =+A26+1 -> 17 | B27: CalVars.Oct | C27: 41.629 | D27: 5.337 | E27: 7.799 | F27: 0
A28: =+A27+1 -> 18 | B28: CalVars.Nov | C28: 19.026 | D28: 2.822 | E28: 6.741 | F28: 0
... A43: =+A42+1 -> 33 | B43: AR(14) | C43: -0.234 | D43: 0.081 | E43: -2.874 | F43: 0.0047
A44: =+A43+1 -> 34
A45: =+A44+1 -> 35 | B45: Model Statistics
A46: =+A45+1 -> 36 | B46: Adjusted Observations | C46: 160
A47: =+A46+1 -> 37 | B47: Deg. of Freedom for Error | C47: 133
A48: =+A47+1 -> 38 | B48: R-Squared | C48: 0.992
A49: =+A48+1 -> 39 | B49: Adjusted R-Squared | C49: 0.99
A50: =+A49+1 -> 40 | B50: F-Statistic | C50: 126.92
A51: =+A50+1 -> 41 | B51: Prob (F-Statistic) | C51: 0
A52: =+A51+1 -> 42 | B52: Model Sum of Squares | C52: 1202203.9
A53: =+A52+1 -> 43 | B53: Sum of Squared Errors | C53: 9949.94
A54: =+A53+1 -> 44 | B54: Mean Squared Error | C54: 74.81
A55: =+A54+1 -> 45 | B55: Std. Error of Regression | C55: 8.65
A56: =+A55+1 -> 46 | B56: Mean Abs. Dev. (MAD) | C56: 6.19
...

Sheet SECGT10KW Model Graph
B1: =+'RES Model'!B1:F1 -> PUC DOCKET NO.
B2: =+'RES Model'!B2:F2 -> ONCOR ELECTRIC DELIVERY COMPANY LLC
B3: =+'RES Model'!B3:F3 -> MODEL INFORMATION
B4: =+'RES Model'!B4:F4 -> FOR THE TEST YEAR ENDING DECEMBER 31, 2024
B6: =+'RES Model'!B6:F6 -> SPONSOR: D. E. NELSON
A8: Line
A9: No.
A10: 1 | B10: Secondary Service Greater Than 10 KW Model
A11: =+A10+1 -> 2 | B11: After Corrective Procedures for Autocorrelation
A12: =+A11+1 -> 3
A13: =+A12+1 -> 4
A14: =+A13+1 -> 5
A15: =+A14+1 -> 6
A16: =+A15+1 -> 7
A17: =+A16+1 -> 8
A18: =+A17+1 -> 9
A19: =+A18+1 -> 10
A20: =+A19+1 -> 11
A21: =+A20+1 -> 12
A22: =+A21+1 -> 13
A23: =+A22+1 -> 14
... A37: =+A36+1 -> 28

Sheet PRMGT10KWD Model
B1: =+'RES Model'!B1:F1 -> PUC DOCKET NO.
B2: =+'RES Model'!B2:F2 -> ONCOR ELECTRIC DELIVERY COMPANY LLC
B3: =+'RES Model'!B3:F3 -> MODEL INFORMATION
B4: =+'RES Model'!B4:F4 -> FOR THE TEST YEAR ENDING DECEMBER 31, 2024
B6: =+'RES Model'!B6:F6 -> SPONSOR: D. E. NELSON
B8: PRIMARY SERVICE GREATER THAN 10 KW Distribution Line MODEL
A9: Line
A10: No. | B10: (a) | C10: (b) | D10: (c) | E10: (d) | F10: (e)
A11: 1 | B11: Before Corrective Procedures for Autocorrelation
A12: =+A11+1 -> 2 | B12: Dependent Variable: | C12: DP_UPD
A13: =+A12+1 -> 3 | B13: Estimation Begin Date: | C13: 40544
A14: =+A13+1 -> 4 | B14: Estimation End Date: | C14: =+'RES Model'!C14 -> 45444
A15: =+A14+1 -> 5
A16: =+A15+1 -> 6 | B16: Variable | C16: Coefficient | D16: StdErr | E16: T-Stat | F16: P-Value
A17: =+A16+1 -> 7 | B17: Cyc_WthrT.LP_CDD | C17: 243.325 | D17: 71.92 | E17: 3.383 | F17: 0.001
A18: =+A17+1 -> 8 | B18: DATAforSales4cast.GMPR | C18: 0.13 | D18: 0.014 | E18: 9.196 | F18: 0
A19: =+A18+1 -> 9 | B19: CalVars.Jan | C19: -66236.248 | D19: 11473.197 | E19: -5.773 | F19: 0
A20: =+A19+1 -> 10 | B20: CalVars.Feb | C20: -64961.021 | D20: 11475.908 | E20: -5.661 | F20: 0
A21: =+A20+1 -> 11 | B21: CalVars.Mar | C21: -66821.578 | D21: 11470.351 | E21: -5.826 | F21: 0
A22: =+A21+1 -> 12 | B22: CalVars.Apr | C22: -65744.882 | D22: 11492.948 | E22: -5.72 | F22: 0
A23: =+A22+1 -> 13 | B23: CalVars.May | C23: -67142.332 | D23: 11534.073 | E23: -5.821 | F23: 0
A24: =+A23+1 -> 14 | B24: CalVars.Jun | C24: -67758.433 | D24: 11598.73 | E24: -5.842 | F24: 0
A25: =+A24+1 -> 15 | B25: CalVars.Jul | C25: -67970.7 | D25: 11667.68 | E25: -5.826 | F25: 0
A26: =+A25+1 -> 16 | B26: CalVars.Aug | C26: -67812.862 | D26: 11694.776 | E26: -5.799 | F26: 0
A27: =+A26+1 -> 17 | B27: CalVars.Sep | C27: -67344.825 | D27: 11652.293 | E27: -5.78 | F27: 0
A28: =+A27+1 -> 18 | B28: CalVars.Oct | C28: -66203.999 | D28: 11573.861 | E28: -5.72 | F28: 0
... A48: =+A47+1 -> 38 | B48: AR(14) | C48: 0.136 | D48: 0.091 | E48: 1.491 | F48: 0.1387
A49: =+A48+1 -> 39
A50: =+A49+1 -> 40 | B50: Model Statistics
A51: =+A50+1 -> 41 | B51: Adjusted Observations | C51: 148
A52: =+A51+1 -> 42 | B52: Deg. of Freedom for Error | C52: 116
A53: =+A52+1 -> 43 | B53: R-Squared | C53: 0.983
A54: =+A53+1 -> 44 | B54: Adjusted R-Squared | C54: 0.978
A55: =+A54+1 -> 45 | B55: F-Statistic | C55: 212.946
A56: =+A55+1 -> 46 | B56: Prob (F-Statistic) | C56: 0
A57: =+A56+1 -> 47 | B57: Model Sum of Squares | C57: 1.3457392e+10
A58: =+A57+1 -> 48 | B58: Sum of Squared Errors | C58: 2.3647657e+08
A59: =+A58+1 -> 49 | B59: Mean Squared Error | C59: 2038591.1
A60: =+A59+1 -> 50 | B60: Std. Error of Regression | C60: 1427.79
A61: =+A60+1 -> 51 | B61: Mean Abs. Dev. (MAD) | C61: 922.04
...

Sheet PRMGT10KWD Model Graph
B1: =+'RES Model'!B1:F1 -> PUC DOCKET NO.
B2: =+'RES Model'!B2:F2 -> ONCOR ELECTRIC DELIVERY COMPANY LLC
B3: =+'RES Model'!B3:F3 -> MODEL INFORMATION
B4: =+'RES Model'!B4:F4 -> FOR THE TEST YEAR ENDING DECEMBER 31, 2024
B6: =+'RES Model'!B6:F6 -> SPONSOR: D. E. NELSON
A8: Line
A9: No.
A10: 1 | B10: Primary Service Greater Than 10 KW Distribution Line Model
A11: =+A10+1 -> 2 | B11: Before Corrective Procedures for Autocorrelation
A12: =+A11+1 -> 3
A13: =+A12+1 -> 4
A14: =+A13+1 -> 5
A15: =+A14+1 -> 6
A16: =+A15+1 -> 7
A17: =+A16+1 -> 8
A18: =+A17+1 -> 9
A19: =+A18+1 -> 10
A20: =+A19+1 -> 11
A21: =+A20+1 -> 12
A22: =+A21+1 -> 13
A23: =+A22+1 -> 14
... A37: =+A36+1 -> 28

Sheet SUB Model
B1: =+'RES Model'!B1:F1 -> PUC DOCKET NO.
B2: =+'RES Model'!B2:F2 -> ONCOR ELECTRIC DELIVERY COMPANY LLC
B3: =+'RES Model'!B3:F3 -> MODEL INFORMATION
B4: =+'RES Model'!B4:F4 -> FOR THE TEST YEAR ENDING DECEMBER 31, 2024
B6: =+'RES Model'!B6:F6 -> SPONSOR: D. E. NELSON
B8: PRIMARY SERVICE GREATER THAN 10 KW SUBSTATION MODEL
A9: Line
A10: No. | B10: (a) | C10: (b) | D10: (c) | E10: (d) | F10: (e)
A11: 1 | B11: After Corrective Procedures for Autocorrelation
A12: =+A11+1 -> 2 | B12: Dependent Variable: | C12: SUB_UPD
A13: =+A12+1 -> 3 | B13: Estimation Begin Date: | C13: 40909
A14: =+A13+1 -> 4 | B14: Estimation End Date: | C14: =+'RES Model'!C14 -> 45444
A15: =+A14+1 -> 5
A16: =+A15+1 -> 6 | B16: Variable | C16: Coefficient | D16: StdErr | E16: T-Stat | F16: P-Value
A17: =+A16+1 -> 7 | B17: Cyc_WthrT.SUB_CDD | C17: 2.772 | D17: 0.657 | E17: 4.219 | F17: 0.0001
A18: =+A17+1 -> 8 | B18: DATAforSales4cast.GMPR | C18: 0.007 | D18: 0.003 | E18: 2.063 | F18: 0.0413
A19: =+A18+1 -> 9 | B19: CalVars.Jan | C19: -1071.598 | D19: 372.023 | E19: -2.88 | F19: 0.0047
A20: =+A19+1 -> 10 | B20: CalVars.Mar | C20: -591.776 | D20: 305.311 | E20: -1.938 | F20: 0.055
A21: =+A20+1 -> 11 | B21: CalVars.Apr | C21: -930.741 | D21: 316.103 | E21: -2.944 | F21: 0.0039
A22: =+A21+1 -> 12 | B22: CalVars.May | C22: -1047.208 | D22: 256.676 | E22: -4.08 | F22: 0.0001
A23: =+A22+1 -> 13 | B23: CalVars.Jun | C23: -1025.054 | D23: 393.454 | E23: -2.605 | F23: 0.0104
A24: =+A23+1 -> 14 | B24: CalVars.Jul | C24: -861.995 | D24: 395.708 | E24: -2.178 | F24: 0.0314
A25: =+A24+1 -> 15 | B25: CalVars.Oct | C25: -783.624 | D25: 389.15 | E25: -2.014 | F25: 0.0463
A26: =+A25+1 -> 16 | B26: CalVars.Sep | C26: -772.566 | D26: 409.912 | E26: -1.885 | F26: 0.0619
A27: =+A26+1 -> 17 | B27: Constant_Shifts.NOV2015 | C27: 9873.909 | D27: 804.448 | E27: 12.274 | F27: 0
A28: =+A27+1 -> 18 | B28: Covid.Covid | C28: -916.478 | D28: 671.701 | E28: -1.364 | F28: 0.175
... A38: =+A37+1 -> 28 | B38: AR(10) | C38: -0.386 | D38: 0.118 | E38: -3.277 | F38: 0.0014
A39: =+A38+1 -> 29
A40: =+A39+1 -> 30 | B40: Model Statistics
A41: =+A40+1 -> 31 | B41: Adjusted Observations | C41: 140
A42: =+A41+1 -> 32 | B42: Deg. of Freedom for Error | C42: 118
A43: =+A42+1 -> 33 | B43: R-Squared | C43: 0.948
A44: =+A43+1 -> 34 | B44: Adjusted R-Squared | C44: 0.939
A45: =+A44+1 -> 35 | B45: F-Statistic | C45: 98.281
A46: =+A45+1 -> 36 | B46: Prob (F-Statistic) | C46: 0
A47: =+A46+1 -> 37 | B47: Model Sum of Squares | C47: 3.0900417e+09
A48: =+A47+1 -> 38 | B48: Sum of Squared Errors | C48: 1.68778e+08
A49: =+A48+1 -> 39 | B49: Mean Squared Error | C49: 1430322
A50: =+A49+1 -> 40 | B50: Std. Error of Regression | C50: 1195.96
A51: =+A50+1 -> 41 | B51: Mean Abs. Dev. (MAD) | C51: 760.52
...

Sheet SUB Model Graph
B1: =+'RES Model'!B1:F1 -> PUC DOCKET NO.
B2: =+'RES Model'!B2:F2 -> ONCOR ELECTRIC DELIVERY COMPANY LLC
B3: =+'RES Model'!B3:F3 -> MODEL INFORMATION
B4: =+'RES Model'!B4:F4 -> FOR THE TEST YEAR ENDING DECEMBER 31, 2024
B6: =+'RES Model'!B6:F6 -> SPONSOR: D. E. NELSON
A8: Line
A9: No.
A10: 1 | B10: Primary Service Greater Than 10 KW Substation Model
A11: =+A10+1 -> 2 | B11: After Corrective Procedures for Autocorrelation
A12: =+A11+1 -> 3
A13: =+A12+1 -> 4
A14: =+A13+1 -> 5
A15: =+A14+1 -> 6
A16: =+A15+1 -> 7
A17: =+A16+1 -> 8
A18: =+A17+1 -> 9
A19: =+A18+1 -> 10
A20: =+A19+1 -> 11
A21: =+A20+1 -> 12
A22: =+A21+1 -> 13
A23: =+A22+1 -> 14
... A37: =+A36+1 -> 28

Sheet RES B Model
B1: =+'RES Model'!B1:F1 -> PUC DOCKET NO.
B2: =+'RES Model'!B2:F2 -> ONCOR ELECTRIC DELIVERY COMPANY LLC
B3: =+'RES Model'!B3:F3 -> MODEL INFORMATION
B4: =+'RES Model'!B4:F4 -> FOR THE TEST YEAR ENDING DECEMBER 31, 2024
B6: =+'RES Model'!B6:F6 -> SPONSOR: D. E. NELSON
B8: RESIDENTIAL (B) MODEL
A9: Line
A10: No. | B10: (a) | C10: (b) | D10: (c) | E10: (d) | F10: (e)
A11: 1 | B11: Before Corrective Procedures for Autocorrelation
A12: =+A11+1 -> 2 | B12: Dependent Variable: | C12: Res_UPC_Day
A13: =+A12+1 -> 3 | B13: Estimation Begin Date: | C13: =+'RES Model'!C13 -> 40179
A14: =+A13+1 -> 4 | B14: Estimation End Date: | C14: =+'RES Model'!C14 -> 45444
A15: =+A14+1 -> 5
A16: =+A15+1 -> 6 | B16: Variable | C16: Coefficient | D16: StdErr | E16: T-Stat | F16: P-Value
A17: =+A16+1 -> 7 | B17: Cyc_WthrT.XHeat | C17: 1.889 | D17: 0.065 | E17: 29.208 | F17: 0
A18: =+A17+1 -> 8 | B18: Cyc_WthrT.XCool | C18: 2.101 | D18: 0.053 | E18: 39.325 | F18: 0
A19: =+A18+1 -> 9 | B19: ResVars.XOther | C19: 0.53 | D19: 0.158 | E19: 3.351 | F19: 0.001
A20: =+A19+1 -> 10 | B20: CalVars.Jan | C20: 13.302 | D20: 4.187 | E20: 3.177 | F20: 0.0018
A21: =+A20+1 -> 11 | B21: CalVars.Feb | C21: 12.969 | D21: 4.166 | E21: 3.113 | F21: 0.0022
A22: =+A21+1 -> 12 | B22: CalVars.Mar | C22: 11.997 | D22: 4.129 | E22: 2.906 | F22: 0.0042
A23: =+A22+1 -> 13 | B23: CalVars.Apr | C23: 11.402 | D23: 4.06 | E23: 2.808 | F23: 0.0056
A24: =+A23+1 -> 14 | B24: CalVars.May | C24: 12.168 | D24: 4.055 | E24: 3.001 | F24: 0.0031
A25: =+A24+1 -> 15 | B25: CalVars.Jun | C25: 14.435 | D25: 4.098 | E25: 3.523 | F25: 0.0006
A26: =+A25+1 -> 16 | B26: CalVars.Jul | C26: 16.289 | D26: 4.09 | E26: 3.983 | F26: 0.0001
A27: =+A26+1 -> 17 | B27: CalVars.Aug | C27: 16.547 | D27: 4.098 | E27: 4.038 | F27: 0.0001
A28: =+A27+1 -> 18 | B28: CalVars.Sep | C28: 16.002 | D28: 4.091 | E28: 3.912 | F28: 0.0001
... A35: =+A34+1 -> 25 | B35: Covid.Covid | C35: 1.943 | D35: 0.353 | E35: 5.504 | F35: 0
A36: =+A35+1 -> 26
A37: =+A36+1 -> 27 | B37: Model Statistics
A38: =+A37+1 -> 28 | B38: Adjusted Observations | C38: 174
A39: =+A38+1 -> 29 | B39: Deg. of Freedom for Error | C39: 155
A40: =+A39+1 -> 30 | B40: R-Squared | C40: 0.996
A41: =+A40+1 -> 31 | B41: Adjusted R-Squared | C41: 0.995
A42: =+A41+1 -> 32 | B42: F-Statistic | C42: 2111.073
A43: =+A42+1 -> 33 | B43: Prob (F-Statistic) | C43: 0
A44: =+A43+1 -> 34 | B44: Model Sum of Squares | C44: 19715.7
A45: =+A44+1 -> 35 | B45: Sum of Squared Errors | C45: 80.42
A46: =+A45+1 -> 36 | B46: Mean Squared Error | C46: 0.52
A47: =+A46+1 -> 37 | B47: Std. Error of Regression | C47: 0.72
A48: =+A47+1 -> 38 | B48: Mean Abs. Dev. (MAD) | C48: 0.52
...

Sheet RES B Model Graph
B1: =+'RES Model'!B1:F1 -> PUC DOCKET NO.
B2: =+'RES Model'!B2:F2 -> ONCOR ELECTRIC DELIVERY COMPANY LLC
B3: =+'RES Model'!B3:F3 -> MODEL INFORMATION
B4: =+'RES Model'!B4:F4 -> FOR THE TEST YEAR ENDING DECEMBER 31, 2024
B6: =+'RES Model'!B6:F6 -> SPONSOR: D. E. NELSON
A8: Line
A9: No.
A10: 1 | B10: Residential B Model
A11: =+A10+1 -> 2 | B11: Before Corrective Procedures for Autocorrelation
A12: =+A11+1 -> 3
A13: =+A12+1 -> 4
A14: =+A13+1 -> 5
A15: =+A14+1 -> 6
A16: =+A15+1 -> 7
A17: =+A16+1 -> 8
A18: =+A17+1 -> 9
A19: =+A18+1 -> 10
A20: =+A19+1 -> 11
A21: =+A20+1 -> 12
A22: =+A21+1 -> 13
A23: =+A22+1 -> 14
... A37: =+A36+1 -> 28

Sheet SECLE10KW B Model
B1: =+'RES Model'!B1:F1 -> PUC DOCKET NO.
B2: =+'RES Model'!B2:F2 -> ONCOR ELECTRIC DELIVERY COMPANY LLC
B3: =+'RES Model'!B3:F3 -> MODEL INFORMATION
B4: =+'RES Model'!B4:F4 -> FOR THE TEST YEAR ENDING DECEMBER 31, 2024
B6: =+'RES Model'!B6:F6 -> SPONSOR: D. E. NELSON
B8: SECONDARY SERVICE LESS THAN OR EQUAL TO 10 KW (B) MODEL
A9: Line
A10: No. | B10: (a) | C10: (b) | D10: (c) | E10: (d) | F10: (e)
A11: 1 | B11: Before Corrective Procedures for Autocorrelation
A12: =+A11+1 -> 2 | B12: Dependent Variable: | C12: SS_UPC_Day
A13: =+A12+1 -> 3 | B13: Estimation Begin Date: | C13: =+'RES Model'!C13 -> 40179
A14: =+A13+1 -> 4 | B14: Estimation End Date: | C14: =+'RES Model'!C14 -> 45444
A15: =+A14+1 -> 5
A16: =+A15+1 -> 6 | B16: Variable | C16: Coefficient | D16: StdErr | E16: T-Stat | F16: P-Value
A17: =+A16+1 -> 7 | B17: Cyc_WthrT.SS_HDD | C17: 0.423 | D17: 0.053 | E17: 7.969 | F17: 0
A18: =+A17+1 -> 8 | B18: Cyc_WthrT.SS_CDD | C18: 0.153 | D18: 0.049 | E18: 3.133 | F18: 0.0021
A19: =+A18+1 -> 9 | B19: Economic_Demogr_Data.DFW_ESRV | C19: -0.048 | D19: 0.007 | E19: -6.932 | F19: 0
A20: =+A19+1 -> 10 | B20: CalVars.Jan | C20: 22.459 | D20: 1.243 | E20: 18.074 | F20: 0
A21: =+A20+1 -> 11 | B21: CalVars.Feb | C21: 22.629 | D21: 1.245 | E21: 18.177 | F21: 0
A22: =+A21+1 -> 12 | B22: CalVars.Mar | C22: 22.414 | D22: 1.195 | E22: 18.756 | F22: 0
A23: =+A22+1 -> 13 | B23: CalVars.Apr | C23: 22.383 | D23: 1.139 | E23: 19.651 | F23: 0
A24: =+A23+1 -> 14 | B24: CalVars.May | C24: 22.78 | D24: 1.142 | E24: 19.944 | F24: 0
A25: =+A24+1 -> 15 | B25: CalVars.Jun | C25: 23.762 | D25: 1.204 | E25: 19.743 | F25: 0
A26: =+A25+1 -> 16 | B26: CalVars.Jul | C26: 25.401 | D26: 1.322 | E26: 19.207 | F26: 0
A27: =+A26+1 -> 17 | B27: CalVars.Aug | C27: 26.166 | D27: 1.394 | E27: 18.765 | F27: 0
A28: =+A27+1 -> 18 | B28: CalVars.Sep | C28: 25.663 | D28: 1.329 | E28: 19.309 | F28: 0
... A32: =+A31+1 -> 22 | B32: Covid.Covid | C32: -0.461 | D32: 0.42 | E32: -1.098 | F32: 0.2739
A33: =+A32+1 -> 23
A34: =+A33+1 -> 24 | B34: Model Statistics
A35: =+A34+1 -> 25 | B35: Adjusted Observations | C35: 174
A36: =+A35+1 -> 26 | B36: Deg. of Freedom for Error | C36: 158
A37: =+A36+1 -> 27 | B37: R-Squared | C37: 0.839
A38: =+A37+1 -> 28 | B38: Adjusted R-Squared | C38: 0.824
A39: =+A38+1 -> 29 | B39: F-Statistic | C39: 55.029
A40: =+A39+1 -> 30 | B40: Prob (F-Statistic) | C40: 0
A41: =+A40+1 -> 31 | B41: Model Sum of Squares | C41: 614.89
A42: =+A41+1 -> 32 | B42: Sum of Squared Errors | C42: 117.7
A43: =+A42+1 -> 33 | B43: Mean Squared Error | C43: 0.74
A44: =+A43+1 -> 34 | B44: Std. Error of Regression | C44: 0.86
A45: =+A44+1 -> 35 | B45: Mean Abs. Dev. (MAD) | C45: 0.68
...

Sheet SECLE10KW B Model Graph
B1: =+'RES Model'!B1:F1 -> PUC DOCKET NO.
B2: =+'RES Model'!B2:F2 -> ONCOR ELECTRIC DELIVERY COMPANY LLC
B3: =+'RES Model'!B3:F3 -> MODEL INFORMATION
B4: =+'RES Model'!B4:F4 -> FOR THE TEST YEAR ENDING DECEMBER 31, 2024
B6: =+'RES Model'!B6:F6 -> SPONSOR: D. E. NELSON
A8: Line
A9: No.
A10: 1 | B10: Secondary Service Less Than or Equal to 10 KW B Model
A11: =+A10+1 -> 2 | B11: Before Corrective Procedures for Autocorrelation
A12: =+A11+1 -> 3
A13: =+A12+1 -> 4
A14: =+A13+1 -> 5
A15: =+A14+1 -> 6
A16: =+A15+1 -> 7
A17: =+A16+1 -> 8
A18: =+A17+1 -> 9
A19: =+A18+1 -> 10
A20: =+A19+1 -> 11
A21: =+A20+1 -> 12
A22: =+A21+1 -> 13
A23: =+A22+1 -> 14
... A37: =+A36+1 -> 28

Sheet SECGT10KW B Model
B1: =+'RES Model'!B1:F1 -> PUC DOCKET NO.
B2: =+'RES Model'!B2:F2 -> ONCOR ELECTRIC DELIVERY COMPANY LLC
B3: =+'RES Model'!B3:F3 -> MODEL INFORMATION
B4: =+'RES Model'!B4:F4 -> FOR THE TEST YEAR ENDING DECEMBER 31, 2024
B6: =+'RES Model'!B6:F6 -> SPONSOR: D. E. NELSON
B8: SECONDARY SERVICE GREATER THAN 10 KW (B) MODEL
A9: Line
A10: No. | B10: (a) | C10: (b) | D10: (c) | E10: (d) | F10: (e)
A11: 1 | B11: Before Corrective Procedures for Autocorrelation
A12: =+A11+1 -> 2 | B12: Dependent Variable: | C12: LS_UPC_Day
A13: =+A12+1 -> 3 | B13: Estimation Begin Date: | C13: =+'RES Model'!C13 -> 40179
A14: =+A13+1 -> 4 | B14: Estimation End Date: | C14: =+'RES Model'!C14 -> 45444
A15: =+A14+1 -> 5
A16: =+A15+1 -> 6 | B16: Variable | C16: Coefficient | D16: StdErr | E16: T-Stat | F16: P-Value
A17: =+A16+1 -> 7 | B17: Cyc_WthrT.LS_CDD | C17: 8.515 | D17: 1.347 | E17: 6.321 | F17: 0
A18: =+A17+1 -> 8 | B18: Cyc_WthrT.LS_HDD | C18: 8.165 | D18: 1.691 | E18: 4.829 | F18: 0
A19: =+A18+1 -> 9 | B19: Economic_Demogr_Data.EMFGONCOR | C19: 0.945 | D19: 0.173 | E19: 5.456 | F19: 0
A20: =+A19+1 -> 10 | B20: CalVars.Jan | C20: 139.358 | D20: 71.11 | E20: 1.96 | F20: 0.0518
A21: =+A20+1 -> 11 | B21: CalVars.Feb | C21: 154.492 | D21: 71.127 | E21: 2.172 | F21: 0.0313
A22: =+A21+1 -> 12 | B22: CalVars.Mar | C22: 155.25 | D22: 70.772 | E22: 2.194 | F22: 0.0297
A23: =+A22+1 -> 13 | B23: CalVars.Apr | C23: 161.397 | D23: 70.735 | E23: 2.282 | F23: 0.0238
A24: =+A23+1 -> 14 | B24: CalVars.May | C24: 176.258 | D24: 71.16 | E24: 2.477 | F24: 0.0143
A25: =+A24+1 -> 15 | B25: CalVars.Jun | C25: 197.85 | D25: 72.813 | E25: 2.717 | F25: 0.0073
A26: =+A25+1 -> 16 | B26: CalVars.Jul | C26: 223.733 | D26: 75.546 | E26: 2.962 | F26: 0.0035
A27: =+A26+1 -> 17 | B27: CalVars.Aug | C27: 241.71 | D27: 76.934 | E27: 3.142 | F27: 0.002
A28: =+A27+1 -> 18 | B28: CalVars.Sep | C28: 243.173 | D28: 75.668 | E28: 3.214 | F28: 0.0016
... A32: =+A31+1 -> 22 | B32: Covid.Covid | C32: -64.535 | D32: 12.236 | E32: -5.274 | F32: 0
A33: =+A32+1 -> 23
A34: =+A33+1 -> 24 | B34: Model Statistics
A35: =+A34+1 -> 25 | B35: Adjusted Observations | C35: 174
A36: =+A35+1 -> 26 | B36: Deg. of Freedom for Error | C36: 158
A37: =+A36+1 -> 27 | B37: R-Squared | C37: 0.923
A38: =+A37+1 -> 28 | B38: Adjusted R-Squared | C38: 0.916
A39: =+A38+1 -> 29 | B39: F-Statistic | C39: 613.612
A40: =+A39+1 -> 30 | B40: Prob (F-Statistic) | C40: 0
A41: =+A40+1 -> 31 | B41: Model Sum of Squares | C41: 1212172.6
A42: =+A41+1 -> 32 | B42: Sum of Squared Errors | C42: 100600.19
A43: =+A42+1 -> 33 | B43: Mean Squared Error | C43: 636.71
A44: =+A43+1 -> 34 | B44: Std. Error of Regression | C44: 25.23
A45: =+A44+1 -> 35 | B45: Mean Abs. Dev. (MAD) | C45: 19.09
...

Sheet SECGT10KW B Model Graph
B1: =+'RES Model'!B1:F1 -> PUC DOCKET NO.
B2: =+'RES Model'!B2:F2 -> ONCOR ELECTRIC DELIVERY COMPANY LLC
B3: =+'RES Model'!B3:F3 -> MODEL INFORMATION
B4: =+'RES Model'!B4:F4 -> FOR THE TEST YEAR ENDING DECEMBER 31, 2024
B6: =+'RES Model'!B6:F6 -> SPONSOR: D. E. NELSON
A8: Line
A9: No.
A10: 1 | B10: Secondary Service Greater Than 10 KW B Model
A11: =+A10+1 -> 2 | B11: Before Corrective Procedures for Autocorrelation
A12: =+A11+1 -> 3
A13: =+A12+1 -> 4
A14: =+A13+1 -> 5
A15: =+A14+1 -> 6
A16: =+A15+1 -> 7
A17: =+A16+1 -> 8
A18: =+A17+1 -> 9
A19: =+A18+1 -> 10
A20: =+A19+1 -> 11
A21: =+A20+1 -> 12
A22: =+A21+1 -> 13
A23: =+A22+1 -> 14
... A37: =+A36+1 -> 28

Sheet PRMGT10KWD B Model
B1: =+'RES Model'!B1:F1 -> PUC DOCKET NO.
B2: =+'RES Model'!B2:F2 -> ONCOR ELECTRIC DELIVERY COMPANY LLC
B3: =+'RES Model'!B3:F3 -> MODEL INFORMATION
B4: =+'RES Model'!B4:F4 -> FOR THE TEST YEAR ENDING DECEMBER 31, 2024
B6: =+'RES Model'!B6:F6 -> SPONSOR: D. E. NELSON
B8: PRIMARY SERVICE GREATER THAN 10 KW Distribution Line (B) MODEL
A9: Line
A10: No. | B10: (a) | C10: (b) | D10: (c) | E10: (d) | F10: (e)
A11: 1 | B11: Before Corrective Procedures for Autocorrelation
A12: =+A11+1 -> 2 | B12: Dependent Variable: | C12: DP_UPD
A13: =+A12+1 -> 3 | B13: Estimation Begin Date: | C13: 40544
A14: =+A13+1 -> 4 | B14: Estimation End Date: | C14: =+'RES Model'!C14 -> 45444
A15: =+A14+1 -> 5
A16: =+A15+1 -> 6 | B16: Variable | C16: Coefficient | D16: StdErr | E16: T-Stat | F16: P-Value
A17: =+A16+1 -> 7 | B17: Cyc_WthrT.LP_CDD | C17: 459.511 | D17: 156.822 | E17: 2.93 | F17: 0.0039
A18: =+A17+1 -> 8 | B18: DATAforSales4cast.GMPR | C18: 0.123 | D18: 0.004 | E18: 34.101 | F18: 0
A19: =+A18+1 -> 9 | B19: CalVars.Jan | C19: -60255.86 | D19: 2994.645 | E19: -20.121 | F19: 0
A20: =+A19+1 -> 10 | B20: CalVars.Feb | C20: -59397.554 | D20: 3001.296 | E20: -19.791 | F20: 0
A21: =+A20+1 -> 11 | B21: CalVars.Mar | C21: -61212.675 | D21: 3018.299 | E21: -20.281 | F21: 0
A22: =+A21+1 -> 12 | B22: CalVars.Apr | C22: -61342.408 | D22: 3179.543 | E22: -19.293 | F22: 0
A23: =+A22+1 -> 13 | B23: CalVars.May | C23: -63368.737 | D23: 3488.957 | E23: -18.163 | F23: 0
A24: =+A23+1 -> 14 | B24: CalVars.Jun | C24: -65498.262 | D24: 4175.185 | E24: -15.688 | F24: 0
A25: =+A24+1 -> 15 | B25: CalVars.Jul | C25: -67543.624 | D25: 4842.457 | E25: -13.948 | F25: 0
A26: =+A25+1 -> 16 | B26: CalVars.Aug | C26: -67337.633 | D26: 5146.743 | E26: -13.084 | F26: 0
A27: =+A26+1 -> 17 | B27: CalVars.Sep | C27: -66652.908 | D27: 4781.446 | E27: -13.94 | F27: 0
A28: =+A27+1 -> 18 | B28: CalVars.Oct | C28: -63728.34 | D28: 3968.561 | E28: -16.058 | F28: 0
... A34: =+A33+1 -> 24 | B34: Constant_Shifts.Mar2024 | C34: -6953.814 | D34: 3488.425 | E34: -1.993 | F34: 0.0481
A35: =+A34+1 -> 25
A36: =+A35+1 -> 26 | B36: Model Statistics
A37: =+A36+1 -> 27 | B37: Adjusted Observations | C37: 162
A38: =+A37+1 -> 28 | B38: Deg. of Freedom for Error | C38: 144
A39: =+A38+1 -> 29 | B39: R-Squared | C39: 0.897
A40: =+A39+1 -> 30 | B40: Adjusted R-Squared | C40: 0.885
A41: =+A40+1 -> 31 | B41: F-Statistic | C41: 73.847
A42: =+A41+1 -> 32 | B42: Prob (F-Statistic) | C42: 0
A43: =+A42+1 -> 33 | B43: Model Sum of Squares | C43: 1.3850366e+10
A44: =+A43+1 -> 34 | B44: Sum of Squared Errors | C44: 1.5887064e+09
A45: =+A44+1 -> 35 | B45: Mean Squared Error | C45: 11032683
A46: =+A45+1 -> 36 | B46: Std. Error of Regression | C46: 3321.55
A47: =+A46+1 -> 37 | B47: Mean Abs. Dev. (MAD) | C47: 2511.28
...

Sheet PRMGT10KWD B Model Graph
B1: =+'RES Model'!B1:F1 -> PUC DOCKET NO.
B2: =+'RES Model'!B2:F2 -> ONCOR ELECTRIC DELIVERY COMPANY LLC
B3: =+'RES Model'!B3:F3 -> MODEL INFORMATION
B4: =+'RES Model'!B4:F4 -> FOR THE TEST YEAR ENDING DECEMBER 31, 2024
B6: =+'RES Model'!B6:F6 -> SPONSOR: D. E. NELSON
A8: Line
A9: No.
A10: 1 | B10: Primary Service Greater Than 10 KW Distribution Line B Model
A11: =+A10+1 -> 2 | B11: Before Corrective Procedures for Autocorrelation
A12: =+A11+1 -> 3
A13: =+A12+1 -> 4
A14: =+A13+1 -> 5
A15: =+A14+1 -> 6
A16: =+A15+1 -> 7
A17: =+A16+1 -> 8
A18: =+A17+1 -> 9
A19: =+A18+1 -> 10
A20: =+A19+1 -> 11
A21: =+A20+1 -> 12
A22: =+A21+1 -> 13
A23: =+A22+1 -> 14
... A37: =+A36+1 -> 28

Sheet SUB B Model
B1: =+'RES Model'!B1:F1 -> PUC DOCKET NO.
B2: =+'RES Model'!B2:F2 -> ONCOR ELECTRIC DELIVERY COMPANY LLC
B3: =+'RES Model'!B3:F3 -> MODEL INFORMATION
B4: =+'RES Model'!B4:F4 -> FOR THE TEST YEAR ENDING DECEMBER 31, 2024
B6: =+'RES Model'!B6:F6 -> SPONSOR: D. E. NELSON
B8: PRIMARY SERVICE GREATER THAN 10 KW SUBSTATION B MODEL
A9: Line
A10: No. | B10: (a) | C10: (b) | D10: (c) | E10: (d) | F10: (e)
A11: 1 | B11: Before Corrective Procedures for Autocorrelation
A12: =+A11+1 -> 2 | B12: Dependent Variable: | C12: SUB_UPD
A13: =+A12+1 -> 3 | B13: Estimation Begin Date: | C13: 40909
A14: =+A13+1 -> 4 | B14: Estimation End Date: | C14: =+'RES Model'!C14 -> 45444
A15: =+A14+1 -> 5
A16: =+A15+1 -> 6 | B16: Variable | C16: Coefficient | D16: StdErr | E16: T-Stat | F16: P-Value
A17: =+A16+1 -> 7 | B17: Cyc_WthrT.SUB_CDD | C17: 8.057 | D17: 5.379 | E17: 1.498 | F17: 0.1366
A18: =+A17+1 -> 8 | B18: DATAforSales4cast.GMPR | C18: 0.063 | D18: 0.002 | E18: 25.4 | F18: 0
A19: =+A18+1 -> 9 | B19: CalVars.Jan | C19: -40519.337 | D19: 2079.589 | E19: -19.484 | F19: 0
A20: =+A19+1 -> 10 | B20: CalVars.Feb | C20: -40247.696 | D20: 2085.349 | E20: -19.3 | F20: 0
A21: =+A20+1 -> 11 | B21: CalVars.Mar | C21: -40554.424 | D21: 2174.759 | E21: -18.648 | F21: 0
A22: =+A21+1 -> 12 | B22: CalVars.Apr | C22: -41643.543 | D22: 2488.63 | E22: -16.734 | F22: 0
A23: =+A22+1 -> 13 | B23: CalVars.May | C23: -42203.269 | D23: 2949.868 | E23: -14.307 | F23: 0
A24: =+A23+1 -> 14 | B24: CalVars.Jun | C24: -43358.4 | D24: 3524.327 | E24: -12.303 | F24: 0
A25: =+A24+1 -> 15 | B25: CalVars.Jul | C25: -44147.878 | D25: 3847.157 | E25: -11.475 | F25: 0
A26: =+A25+1 -> 16 | B26: CalVars.Aug | C26: -42691.241 | D26: 3894.174 | E26: -10.963 | F26: 0
A27: =+A26+1 -> 17 | B27: CalVars.Oct | C27: -43250.88 | D27: 3390.921 | E27: -12.755 | F27: 0
A28: =+A27+1 -> 18 | B28: CalVars.Sep | C28: -43469.061 | D28: 3808.202 | E28: -11.415 | F28: 0
... A32: =+A31+1 -> 22 | B32: Covid.Covid | C32: -2297.768 | D32: 1016.059 | E32: -2.261 | F32: 0.0253
A33: =+A32+1 -> 23
A34: =+A33+1 -> 24 | B34: Model Statistics
A35: =+A34+1 -> 25 | B35: Adjusted Observations | C35: 150
A36: =+A35+1 -> 26 | B36: Deg. of Freedom for Error | C36: 134
A37: =+A36+1 -> 27 | B37: R-Squared | C37: 0.833
A38: =+A37+1 -> 28 | B38: Adjusted R-Squared | C38: 0.815
A39: =+A38+1 -> 29 | B39: F-Statistic | C39: 44.665
A40: =+A39+1 -> 30 | B40: Prob (F-Statistic) | C40: 0
A41: =+A40+1 -> 31 | B41: Model Sum of Squares | C41: 2.9400597e+09
A42: =+A41+1 -> 32 | B42: Sum of Squared Errors | C42: 5.8803331e+08
A43: =+A42+1 -> 33 | B43: Mean Squared Error | C43: 4388308.2
A44: =+A43+1 -> 34 | B44: Std. Error of Regression | C44: 2094.83
A45: =+A44+1 -> 35 | B45: Mean Abs. Dev. (MAD) | C45: 1392.14
...

Sheet SUB B Model Graph
B1: =+'RES Model'!B1:F1 -> PUC DOCKET NO.
B2: =+'RES Model'!B2:F2 -> ONCOR ELECTRIC DELIVERY COMPANY LLC
B3: =+'RES Model'!B3:F3 -> MODEL INFORMATION
B4: =+'RES Model'!B4:F4 -> FOR THE TEST YEAR ENDING DECEMBER 31, 2024
B6: =+'RES Model'!B6:F6 -> SPONSOR: D. E. NELSON
A8: Line
A9: No.
A10: 1 | B10: Primary Service Greater Than 10 KW Substation B Model
A11: =+A10+1 -> 2 | B11: Before Corrective Procedures for Autocorrelation
A12: =+A11+1 -> 3
A13: =+A12+1 -> 4
A14: =+A13+1 -> 5
A15: =+A14+1 -> 6
A16: =+A15+1 -> 7
A17: =+A16+1 -> 8
A18: =+A17+1 -> 9
A19: =+A18+1 -> 10
A20: =+A19+1 -> 11
A21: =+A20+1 -> 12
A22: =+A21+1 -> 13
A23: =+A22+1 -> 14
... A37: =+A36+1 -> 28
