Workbook
Name HOURLY: [1]HOURLY!$A$1:$G$745
Name OLE_LINK2: 'PRMGT10KWD Seasonal Weights'!$B$25
Name OLE_LINK2: 'Res Seasonal Weights'!$B$25
Name OLE_LINK2: 'SECGT10KW Seasonal Weights'!$B$25
Name OLE_LINK2: 'SECTE10KW Seasonal Weights'!$B$25
Name OLE_LINK2: 'Substation Seasonal Weights'!$B$25
Name rngBilled: OFFSET([2]Sheet2!$A$2,0,0,[2]Sheet2!$B$1,9)
Name rngYear: OFFSET('[3]Daily Actual_August'!$A$2,0,0,'[3]Daily Actual_August'!$C$1,8)

Sheet RES
B1: PUC DOCKET NO.
B2: ONCOR ELECTRIC DELIVERY COMPANY LLC
B3: ADJUSTED WEATHER STATION DATA
B4: FOR THE TEST YEAR ENDING DECEMBER 31, 2024
B6: SPONSOR: D. E. NELSON
B8: RESIDENTIAL
B9: SYSTEM WEIGHTED BILLING CYCLE ADJUSTED
A10: Line | C10: (a) | D10: (b) | E10: (c) | F10: (d)
A11: No. | C11: Actual | E11: Normal
A12: 1 | C12: HDD | D12: CDD | E12: HDD | F12: CDD
A13: 2 | B13: 45292 | C13: 192.04714 | D13: 0.50931182 | E13: 213.47102 | F13: 2.4932806
A14: 3 | B14: 45323 | C14: 260.83933 | D14: 0.071189207 | E14: 221.3909 | F14: 1.5673923
A15: 4 | B15: 45352 | C15: 65.576036 | D15: 14.582078 | E15: 149.60668 | F15: 6.3552179
A16: 5 | B16: 45383 | C16: 25.940125 | D16: 23.336796 | E16: 45.106131 | F16: 25.375167
A17: 6 | B17: 45413 | C17: 4.9216689 | D17: 87.833335 | E17: 10.403559 | F17: 71.734338
A18: 7 | B18: 45444 | C18: 0.005868752 | D18: 238.2623 | E18: 1.0969641 | F18: 214.65969
A19: 8 | B19: 45474 | C19: 0 | D19: 413.76616 | E19: 0.0087872204 | F19: 376.74149
A20: 9 | B20: 45505 | C20: 0 | D20: 407.79058 | E20: 0.00033797379 | F20: 441.87555
A21: 10 | B21: 45536 | C21: 0 | D21: 427.48317 | E21: 0.035522034 | F21: 397.57148
A22: 11 | B22: 45566 | C22: 0.16908013 | D22: 239.2824 | E22: 1.9478264 | F22: 220.30252
A23: 12 | B23: 45597 | C23: 2.4301902 | D23: 119.20832 | E23: 27.452626 | F23: 65.768035
A24: 13 | B24: 45627 | C24: 68.297777 | D24: 14.298436 | E24: 111.01776 | F24: 10.052167
A25: 14 | B25: Annual | C25: =SUM(C13:C24) -> 620.22722 | D25: =SUM(D13:D24) -> 1986.4241 | E25: =SUM(E13:E24) -> 781.53812 | F25: =SUM(F13:F24) -> 1834.4963

Sheet SECLE10KW
B1: =+RES!B1 -> PUC DOCKET NO.
B2: =+RES!B2 -> ONCOR ELECTRIC DELIVERY COMPANY LLC
B3: =+RES!B3 -> ADJUSTED WEATHER STATION DATA
B4: =+RES!B4 -> FOR THE TEST YEAR ENDING DECEMBER 31, 2024
B6: =+RES!B6 -> SPONSOR: D. E. NELSON
B8: SECONDARY SERVICE LESS THAN OR EQUAL TO 10 KW
B9: SYSTEM WEIGHTED BILLING CYCLE ADJUSTED
A10: Line | C10: (a) | D10: (b) | E10: (c) | F10: (d)
A11: No. | C11: Actual | E11: Normal
A12: 1 | C12: HDD | D12: CDD | E12: HDD | F12: CDD
A13: 2 | B13: =+RES!B13 -> 45292 | C13: 184.63353 | D13: 0.45216727 | E13: 225.91363 | F13: 2.2527213
A14: 3 | B14: =+RES!B14 -> 45323 | C14: 220.18738 | D14: 0.070489242 | E14: 232.76225 | F14: 1.4051948
A15: 4 | B15: =+RES!B15 -> 45352 | C15: 75.450549 | D15: 13.519447 | E15: 158.52179 | F15: 5.9059238
A16: 5 | B16: =+RES!B16 -> 45383 | C16: 37.755317 | D16: 22.347901 | E16: 50.898509 | F16: 24.813946
A17: 6 | B17: =+RES!B17 -> 45413 | C17: 7.0957272 | D17: 87.941602 | E17: 13.010937 | F17: 72.778808
A18: 7 | B18: =+RES!B18 -> 45444 | C18: 0.02147368 | D18: 245.16695 | E18: 1.6240948 | F18: 218.87911
A19: 8 | B19: =+RES!B19 -> 45474 | C19: 0 | D19: 419.56965 | E19: 0.018058367 | F19: 381.68579
A20: 9 | B20: =+RES!B20 -> 45505 | C20: 0 | D20: 413.22416 | E20: 0.001338283 | F20: 443.70545
A21: 10 | B21: =+RES!B21 -> 45536 | C21: 0 | D21: 430.61029 | E21: 0.077369928 | F21: 396.93673
A22: 11 | B22: =+RES!B22 -> 45566 | C22: 0.30823941 | D22: 235.33203 | E22: 2.6285157 | F22: 218.36059
A23: 12 | B23: =+RES!B23 -> 45597 | C23: 5.7396961 | D23: 116.06745 | E23: 32.083725 | F23: 63.917958
A24: 13 | B24: =+RES!B24 -> 45627 | C24: 98.109658 | D24: 13.342508 | E24: 120.77429 | F24: 9.3192345
A25: 14 | B25: Annual | C25: =SUM(C13:C24) -> 629.30157 | D25: =SUM(D13:D24) -> 1997.6446 | E25: =SUM(E13:E24) -> 838.31451 | F25: =SUM(F13:F24) -> 1839.9614

Sheet SECGT10KW
B1: =+RES!B1 -> PUC DOCKET NO.
B2: =+RES!B2 -> ONCOR ELECTRIC DELIVERY COMPANY LLC
B3: =+RES!B3 -> ADJUSTED WEATHER STATION DATA
B4: =+RES!B4 -> FOR THE TEST YEAR ENDING DECEMBER 31, 2024
B6: =+RES!B6 -> SPONSOR: D. E. NELSON
B8: SECONDARY SERVICE GREATER THAN 10 KW
B9: SYSTEM WEIGHTED BILLING CYCLE ADJUSTED
A10: Line | C10: (a) | D10: (b) | E10: (c) | F10: (d)
A11: No. | C11: Actual | E11: Normal
A12: 1 | C12: HDD | D12: CDD | E12: HDD | F12: CDD
A13: 2 | B13: =+RES!B13 -> 45292 | C13: 140.09371 | D13: 4.3887641 | E13: 164.03554 | F13: 9.3847032
A14: 3 | B14: =+RES!B14 -> 45323 | C14: 211.10812 | D14: 3.3728813 | E14: 172.42221 | F14: 7.1464836
A15: 4 | B15: =+RES!B15 -> 45352 | C15: 39.382808 | D15: 39.813945 | E15: 111.47031 | F15: 20.492493
A16: 5 | B16: =+RES!B16 -> 45383 | C16: 9.546344 | D16: 57.995994 | E16: 25.537347 | F16: 59.47417
A17: 6 | B17: =+RES!B17 -> 45413 | C17: 0.86870109 | D17: 153.60589 | E17: 3.8708013 | F17: 128.11467
A18: 7 | B18: =+RES!B18 -> 45444 | C18: 0 | D18: 331.913 | E18: 0.2074887 | F18: 303.08085
A19: 8 | B19: =+RES!B19 -> 45474 | C19: 0 | D19: 517.14279 | E19: 0.00033281218 | F19: 478.72574
A20: 9 | B20: =+RES!B20 -> 45505 | C20: 0 | D20: 509.54026 | E20: 0 | F20: 543.1316
A21: 10 | B21: =+RES!B21 -> 45536 | C21: 0 | D21: 528.77976 | E21: 0.011748856 | F21: 498.18344
A22: 11 | B22: =+RES!B22 -> 45566 | C22: 0 | D22: 331.75949 | E22: 0.65737564 | F22: 305.33115
A23: 12 | B23: =+RES!B23 -> 45597 | C23: 0.20066932 | D23: 192.26682 | E23: 14.27543 | F23: 114.57722
A24: 13 | B24: =+RES!B24 -> 45627 | C24: 37.982957 | D24: 35.279521 | E24: 75.667317 | F24: 26.948599
A25: 14 | B25: Annual | C25: =SUM(C13:C24) -> 439.18331 | D25: =SUM(D13:D24) -> 2705.8591 | E25: =SUM(E13:E24) -> 568.15591 | F25: =SUM(F13:F24) -> 2494.5911

Sheet PRMGT10KWD
B1: =+RES!B1 -> PUC DOCKET NO.
B2: =+RES!B2 -> ONCOR ELECTRIC DELIVERY COMPANY LLC
B3: =+RES!B3 -> ADJUSTED WEATHER STATION DATA
B4: =+RES!B4 -> FOR THE TEST YEAR ENDING DECEMBER 31, 2024
B6: =+RES!B6 -> SPONSOR: D. E. NELSON
B8: PRIMARY SERVICE GREATER THAN 10 KW
B9: SYSTEM WEIGHTED BILLING CYCLE ADJUSTED
A10: Line | C10: (a) | D10: (b) | E10: (c) | F10: (d)
A11: No. | C11: Actual | E11: Normal
A12: 1 | C12: HDD | D12: CDD | E12: HDD | F12: CDD
A13: 2 | B13: =+RES!B13 -> 45292 | C13: 0 | D13: 18.25326 | E13: 0 | F13: 27.948273
A14: 3 | B14: =+RES!B14 -> 45323 | C14: 0 | D14: 16.187227 | E14: 0 | F14: 24.967937
A15: 4 | B15: =+RES!B15 -> 45352 | C15: 0 | D15: 101.50797 | E15: 0 | F15: 65.516252
A16: 5 | B16: =+RES!B16 -> 45383 | C16: 0 | D16: 150.68135 | E16: 0 | F16: 161.82127
A17: 6 | B17: =+RES!B17 -> 45413 | C17: 0 | D17: 314.73688 | E17: 0 | F17: 284.92909
A18: 7 | B18: =+RES!B18 -> 45444 | C18: 0 | D18: 562.82289 | E18: 0 | F18: 508.22517
A19: 8 | B19: =+RES!B19 -> 45474 | C19: 0 | D19: 719.07335 | E19: 0 | F19: 680.56823
A20: 9 | B20: =+RES!B20 -> 45505 | C20: 0 | D20: 701.83339 | E20: 0 | F20: 716.95231
A21: 10 | B21: =+RES!B21 -> 45536 | C21: 0 | D21: 711.48424 | E21: 0 | F21: 660.97514
A22: 11 | B22: =+RES!B22 -> 45566 | C22: 0 | D22: 482.30674 | E22: 0 | F22: 455.23582
A23: 12 | B23: =+RES!B23 -> 45597 | C23: 0 | D23: 330.3157 | E23: 0 | F23: 223.18775
A24: 13 | B24: =+RES!B24 -> 45627 | C24: 0 | D24: 87.53754 | E24: 0 | F24: 71.812991
A25: 14 | B25: Annual | C25: =SUM(C13:C24) -> 0 | D25: =SUM(D13:D24) -> 4196.7405 | E25: =SUM(E13:E24) -> 0 | F25: =SUM(F13:F24) -> 3882.1402

Sheet SUBSTATION
B1: =+RES!B1 -> PUC DOCKET NO.
B2: =+RES!B2 -> ONCOR ELECTRIC DELIVERY COMPANY LLC
B3: =+RES!B3 -> ADJUSTED WEATHER STATION DATA
B4: =+RES!B4 -> FOR THE TEST YEAR ENDING DECEMBER 31, 2024
B6: =+RES!B6 -> SPONSOR: D. E. NELSON
B8: SUBSTATION
B9: SYSTEM WEIGHTED BILLING CYCLE ADJUSTED
A10: Line | C10: (a) | D10: (b) | E10: (c) | F10: (d)
A11: No. | C11: Actual | E11: Normal
A12: 1 | C12: HDD | D12: CDD | E12: HDD | F12: CDD
A13: 2 | B13: =+RES!B13 -> 45292 | C13: 0 | D13: 1049.0964 | E13: 0 | F13: 1493.6885
A14: 3 | B14: =+RES!B14 -> 45323 | C14: 0 | D14: 972.31565 | E14: 0 | F14: 1392.5959
A15: 4 | B15: =+RES!B15 -> 45352 | C15: 0 | D15: 4875.9487 | E15: 0 | F15: 3363.3761
A16: 5 | B16: =+RES!B16 -> 45383 | C16: 0 | D16: 6989.1382 | E16: 0 | F16: 7264.5748
A17: 6 | B17: =+RES!B17 -> 45413 | C17: 0 | D17: 11689.546 | E17: 0 | F17: 10881.657
A18: 7 | B18: =+RES!B18 -> 45444 | C18: 0 | D18: 16841.949 | E18: 0 | F18: 15592.114
A19: 8 | B19: =+RES!B19 -> 45474 | C19: 0 | D19: 18170.696 | E19: 0 | F19: 17844.104
A20: 9 | B20: =+RES!B20 -> 45505 | C20: 0 | D20: 17795.668 | E20: 0 | F20: 17746.488
A21: 10 | B21: =+RES!B21 -> 45536 | C21: 0 | D21: 17486.875 | E21: 0 | F21: 17452.47
A22: 11 | B22: =+RES!B22 -> 45566 | C22: 0 | D22: 15355.602 | E22: 0 | F22: 14419.208
A23: 12 | B23: =+RES!B23 -> 45597 | C23: 0 | D23: 12171.405 | E23: 0 | F23: 8905.8351
A24: 13 | B24: =+RES!B24 -> 45627 | C24: 0 | D24: 4181.414 | E24: 0 | F24: 3537.6547
A25: 14 | B25: Annual | C25: =SUM(C13:C24) -> 0 | D25: =SUM(D13:D24) -> 127579.65 | E25: =SUM(E13:E24) -> 0 | F25: =SUM(F13:F24) -> 119893.77

Sheet COOLING Weighting
B1: =+RES!B1 -> PUC DOCKET NO.
B2: =+RES!B2 -> ONCOR ELECTRIC DELIVERY COMPANY LLC
B3: =+RES!B3 -> ADJUSTED WEATHER STATION DATA
B4: =+RES!B4 -> FOR THE TEST YEAR ENDING DECEMBER 31, 2024
B6: =+RES!B6 -> SPONSOR: D. E. NELSON
B8: RESIDENTIAL CLASS WEIGHTING FOR DAILY COOLING DEGREE DAYS FOR JULY 20, 2023
A9: Line
A10: No.
A11: 1 | B11: Cooling Degree Days by Station (a)
A12: =+A11+1 -> 2 | B12: Date | C12: CDD | D12: {=TRANSPOSE('[4]July 20 23 bySite'!$B$11:$B$20)} -> Abilene | E12: Austin | F12: Dallas-Ft. Worth | G12: Kileen-Temple | H12: Longview | I12: Lufkin | J12: Midland-Odessa | K12: Sherman-Denison | L12: Waco | M12: Wichita Falls
A13: =+A12+1 -> 3 | B13: 45127 | C13: Base65 | D13: {=TRANSPOSE('[4]July 20 23 bySite'!$O$24:$O$33)} -> 25.3 | E13: 23.5 | F13: 27.4 | G13: 25.7 | H13: 22 | I13: 23.3 | J13: 23.3 | K13: 23.8 | L13: 26.2 | M13: 26.3 | O13: a1
A14: =+A13+1 -> 4 | B14: =+B13 -> 45127 | C14: Base70 | D14: {=TRANSPOSE('[4]July 20 23 bySite'!$P$24:$P$33)} -> 20.3 | E14: 18.5 | F14: 22.4 | G14: 20.7 | H14: 17 | I14: 18.3 | J14: 18.3 | K14: 18.8 | L14: 21.2 | M14: 21.3 | O14: a2
A15: =+A14+1 -> 5 | B15: =+B14 -> 45127 | C15: Base75 | D15: {=TRANSPOSE('[4]July 20 23 bySite'!$Q$24:$Q$33)} -> 15.3 | E15: 13.5 | F15: 17.4 | G15: 15.7 | H15: 12 | I15: 13.3 | J15: 13.3 | K15: 13.8 | L15: 16.2 | M15: 16.3 | O15: a3
A16: =+A15+1 -> 6 | B16: =+B14 -> 45127 | C16: Base80 | D16: {=TRANSPOSE('[4]July 20 23 bySite'!$R$24:$R$33)} -> 10.3 | E16: 8.5 | F16: 12.4 | G16: 10.7 | H16: 7 | I16: 8.3 | J16: 8.3 | K16: 8.8 | L16: 11.2 | M16: 11.3 | O16: a4
A17: =+A16+1 -> 7
A18: =+A17+1 -> 8 | B18: Weather Weights by Station (b)
A19: =+A18+1 -> 9 | C19: CDD | D19: =+'Res Seasonal Weights'!F30 -> 0.012 | E19: =+'Res Seasonal Weights'!F36 -> 0.048 | F19: =+'Res Seasonal Weights'!F27 -> 0.702 | G19: =+'Res Seasonal Weights'!F32 -> 0.046 | H19: =+'Res Seasonal Weights'!F35 -> 0.036 | I19: =+'Res Seasonal Weights'!F29 -> 0.026 | J19: =+'Res Seasonal Weights'!F28 -> 0.054 | K19: =+'Res Seasonal Weights'!F31 -> 0.023 | L19: =+'Res Seasonal Weights'!F33 -> 0.036 | M19: =+'Res Seasonal Weights'!F34 -> 0.018 | O19: b
A22: =+A19+1 -> 10 | B22: Residential Cooling Degree Days Contribution by Station (c = a*b)
A23: =+A22+1 -> 11
A24: =+A23+1 -> 12 | B24: Date | C24: CDD | D24: {=TRANSPOSE('[4]July 20 23 bySite'!$B$11:$B$20)} -> Abilene | E24: Austin | F24: Dallas-Ft. Worth | G24: Kileen-Temple | H24: Longview | I24: Lufkin | J24: Midland-Odessa | K24: Sherman-Denison | L24: Waco | M24: Wichita Falls | N24: Residential Class
A25: =+A24+1 -> 13 | B25: =+B13 -> 45127 | C25: =+C13 -> Base65 | D25: =+D13*D$19 -> 0.3036 | E25: =+E13*E$19 -> 1.128 | F25: =+F13*F$19 -> 19.2348 | G25: =+G13*G$19 -> 1.1822 | H25: =+H13*H$19 -> 0.792 | I25: =+I13*I$19 -> 0.6058 | J25: =+J13*J$19 -> 1.2582 | K25: =+K13*K$19 -> 0.5474 | ... M25: =+M13*M$19 -> 0.4734 | N25: =SUM(D25:M25) -> 26.4686 | O25: c1 = a1*b
A26: =+A25+1 -> 14 | B26: =+B14 -> 45127 | C26: =+C14 -> Base70 | D26: =+D14*D$19 -> 0.2436 | E26: =+E14*E$19 -> 0.888 | F26: =+F14*F$19 -> 15.7248 | G26: =+G14*G$19 -> 0.9522 | H26: =+H14*H$19 -> 0.612 | I26: =+I14*I$19 -> 0.4758 | J26: =+J14*J$19 -> 0.9882 | K26: =+K14*K$19 -> 0.4324 | ... M26: =+M14*M$19 -> 0.3834 | N26: =SUM(D26:M26) -> 21.4636 | O26: c2 = a2*b
A27: =+A26+1 -> 15 | B27: =+B15 -> 45127 | C27: =+C15 -> Base75 | D27: =+D15*D$19 -> 0.1836 | E27: =+E15*E$19 -> 0.648 | F27: =+F15*F$19 -> 12.2148 | G27: =+G15*G$19 -> 0.7222 | H27: =+H15*H$19 -> 0.432 | I27: =+I15*I$19 -> 0.3458 | J27: =+J15*J$19 -> 0.7182 | K27: =+K15*K$19 -> 0.3174 | ... M27: =+M15*M$19 -> 0.2934 | N27: =SUM(D27:M27) -> 16.4586 | O27: c3 = a3*b
A28: =+A27+1 -> 16 | B28: =+B16 -> 45127 | C28: =+C16 -> Base80 | D28: =+D16*D$19 -> 0.1236 | E28: =+E16*E$19 -> 0.408 | F28: =+F16*F$19 -> 8.7048 | G28: =+G16*G$19 -> 0.4922 | H28: =+H16*H$19 -> 0.252 | I28: =+I16*I$19 -> 0.2158 | J28: =+J16*J$19 -> 0.4482 | K28: =+K16*K$19 -> 0.2024 | ... M28: =+M16*M$19 -> 0.2034 | N28: =SUM(D28:M28) -> 11.4536 | O28: c4 = a4*b

Sheet COOLING Weighting (2)
B1: =+RES!B1 -> PUC DOCKET NO.
B2: =+RES!B2 -> ONCOR ELECTRIC DELIVERY COMPANY LLC
B3: =+RES!B3 -> ADJUSTED WEATHER STATION DATA
B4: =+RES!B4 -> FOR THE TEST YEAR ENDING DECEMBER 31, 2024
B6: =+RES!B6 -> SPONSOR: D. E. NELSON
B8: RESIDENTIAL CLASS WEIGHTING FOR DAILY COOLING DEGREE DAYS FOR JULY 14, 2024
A9: Line
A10: No.
A11: 1 | B11: Cooling Degree Days by Station (a)
A12: =+A11+1 -> 2 | B12: Date | C12: CDD | D12: {=TRANSPOSE('[4]July 14 24 bySite'!$B$11:$B$20)} -> Abilene | E12: Austin | F12: Dallas-Ft. Worth | G12: Kileen-Temple | H12: Longview | I12: Lufkin | J12: Midland-Odessa | K12: Sherman-Denison | L12: Waco | M12: Wichita Falls
A13: =+A12+1 -> 3 | B13: 44391 | C13: Base65 | D13: {=TRANSPOSE('[4]July 14 24 bySite'!$O$24:$O$33)} -> 22.4 | E13: 16.4 | F13: 22.5 | G13: 19 | H13: 17.7 | I13: 15.6 | J13: 17.3 | K13: 21.7 | L13: 20.1 | M13: 21.5 | O13: a1
A14: =+A13+1 -> 4 | B14: =+B13 -> 44391 | C14: Base70 | D14: {=TRANSPOSE('[4]July 14 24 bySite'!$P$24:$P$33)} -> 17.4 | E14: 11.4 | F14: 17.5 | G14: 14 | H14: 12.7 | I14: 10.6 | J14: 12.3 | K14: 16.7 | L14: 15.1 | M14: 16.5 | O14: a2
A15: =+A14+1 -> 5 | B15: =+B14 -> 44391 | C15: Base75 | D15: {=TRANSPOSE('[4]July 14 24 bySite'!$Q$24:$Q$33)} -> 12.4 | E15: 6.4 | F15: 12.5 | G15: 9 | H15: 7.7 | I15: 5.6 | J15: 7.3 | K15: 11.7 | L15: 10.1 | M15: 11.5 | O15: a3
A16: =+A15+1 -> 6 | B16: =+B14 -> 44391 | C16: Base80 | D16: {=TRANSPOSE('[4]July 14 24 bySite'!$R$24:$R$33)} -> 7.4 | E16: 1.4 | F16: 7.5 | G16: 4 | H16: 2.7 | I16: 0.6 | J16: 2.3 | K16: 6.7 | L16: 5.1 | M16: 6.5 | O16: a4
A17: =+A16+1 -> 7
A18: =+A17+1 -> 8 | B18: Weather Weights by Station (b)
A19: =+A18+1 -> 9 | C19: CDD | D19: =+'Res Seasonal Weights'!F30 -> 0.012 | E19: =+'Res Seasonal Weights'!F36 -> 0.048 | F19: =+'Res Seasonal Weights'!F27 -> 0.702 | G19: =+'Res Seasonal Weights'!F32 -> 0.046 | H19: =+'Res Seasonal Weights'!F35 -> 0.036 | I19: =+'Res Seasonal Weights'!F29 -> 0.026 | J19: =+'Res Seasonal Weights'!F28 -> 0.054 | K19: =+'Res Seasonal Weights'!F31 -> 0.023 | L19: =+'Res Seasonal Weights'!F33 -> 0.036 | M19: =+'Res Seasonal Weights'!F34 -> 0.018 | O19: b
A22: =+A19+1 -> 10 | B22: Residential Cooling Degree Days Contribution by Station (c = a*b)
A23: =+A22+1 -> 11
A24: =+A23+1 -> 12 | B24: Date | C24: CDD | D24: {=TRANSPOSE('[4]July 14 24 bySite'!$B$11:$B$20)} -> Abilene | E24: Austin | F24: Dallas-Ft. Worth | G24: Kileen-Temple | H24: Longview | I24: Lufkin | J24: Midland-Odessa | K24: Sherman-Denison | L24: Waco | M24: Wichita Falls | N24: Residential Class
A25: =+A24+1 -> 13 | B25: =+B13 -> 44391 | C25: =+C13 -> Base65 | D25: =+D13*D$19 -> 0.2688 | E25: =+E13*E$19 -> 0.7872 | F25: =+F13*F$19 -> 15.795 | G25: =+G13*G$19 -> 0.874 | H25: =+H13*H$19 -> 0.6372 | I25: =+I13*I$19 -> 0.4056 | J25: =+J13*J$19 -> 0.9342 | K25: =+K13*K$19 -> 0.4991 | ... M25: =+M13*M$19 -> 0.387 | N25: =SUM(D25:M25) -> 21.3117 | O25: c1 = a1*b
A26: =+A25+1 -> 14 | B26: =+B14 -> 44391 | C26: =+C14 -> Base70 | D26: =+D14*D$19 -> 0.2088 | E26: =+E14*E$19 -> 0.5472 | F26: =+F14*F$19 -> 12.285 | G26: =+G14*G$19 -> 0.644 | H26: =+H14*H$19 -> 0.4572 | I26: =+I14*I$19 -> 0.2756 | J26: =+J14*J$19 -> 0.6642 | K26: =+K14*K$19 -> 0.3841 | ... M26: =+M14*M$19 -> 0.297 | N26: =SUM(D26:M26) -> 16.3067 | O26: c2 = a2*b
A27: =+A26+1 -> 15 | B27: =+B15 -> 44391 | C27: =+C15 -> Base75 | D27: =+D15*D$19 -> 0.1488 | E27: =+E15*E$19 -> 0.3072 | F27: =+F15*F$19 -> 8.775 | G27: =+G15*G$19 -> 0.414 | H27: =+H15*H$19 -> 0.2772 | I27: =+I15*I$19 -> 0.1456 | J27: =+J15*J$19 -> 0.3942 | K27: =+K15*K$19 -> 0.2691 | ... M27: =+M15*M$19 -> 0.207 | N27: =SUM(D27:M27) -> 11.3017 | O27: c3 = a3*b
A28: =+A27+1 -> 16 | B28: =+B16 -> 44391 | C28: =+C16 -> Base80 | D28: =+D16*D$19 -> 0.0888 | E28: =+E16*E$19 -> 0.0672 | F28: =+F16*F$19 -> 5.265 | G28: =+G16*G$19 -> 0.184 | H28: =+H16*H$19 -> 0.0972 | I28: =+I16*I$19 -> 0.0156 | J28: =+J16*J$19 -> 0.1242 | K28: =+K16*K$19 -> 0.1541 | ... M28: =+M16*M$19 -> 0.117 | N28: =SUM(D28:M28) -> 6.2967 | O28: c4 = a4*b

Sheet HEATING Weighting
B1: =+RES!B1 -> PUC DOCKET NO.
B2: =+RES!B2 -> ONCOR ELECTRIC DELIVERY COMPANY LLC
B3: =+RES!B3 -> ADJUSTED WEATHER STATION DATA
B4: =+RES!B4 -> FOR THE TEST YEAR ENDING DECEMBER 31, 2024
B6: =+RES!B6 -> SPONSOR: D. E. NELSON
B8: RESIDENTIAL CLASS WEIGHTING FOR DAILY HEATING DEGREE DAYS FOR JANUARY 21, 2023
A9: Line
A10: No.
A11: 1 | B11: Heating Degree Days by Station (a)
A12: =+A11+1 -> 2 | B12: Date | C12: HDD | D12: {=TRANSPOSE('[4]January 21 23 bySite'!$B$11:$B$20)} -> Abilene | E12: Austin | F12: Dallas-Ft. Worth | G12: Kileen-Temple | H12: Longview | I12: Lufkin | J12: Midland-Odessa | K12: Sherman-Denison | L12: Waco | M12: Wichita Falls
A13: =+A12+1 -> 3 | B13: 44947 | C13: Base45 | D13: {=TRANSPOSE('[4]January 21 23 bySite'!$H$24:$H$33)} -> 0 | E13: 0 | F13: 0 | G13: 0 | H13: 0 | I13: 0 | J13: 0.1 | K13: 0 | L13: 0 | M13: 0 | O13: a1
A14: =+A13+1 -> 4 | B14: =+B13 -> 44947 | C14: Base55 | D14: {=TRANSPOSE('[4]January 21 23 bySite'!$I$24:$I$33)} -> 3 | E14: 3.8 | F14: 4.6 | G14: 2.6 | H14: 7.2 | I14: 5.4 | J14: 10.1 | K14: 6.8 | L14: 6.2 | M14: 4.3 | O14: a2
A15: =+A14+1 -> 5 | B15: =+B13 -> 44947 | C15: Base60 | D15: {=TRANSPOSE('[4]January 21 23 bySite'!$J$24:$J$33)} -> 8 | E15: 8.8 | F15: 9.6 | G15: 7.6 | H15: 12.2 | I15: 10.4 | J15: 15.1 | K15: 11.8 | L15: 11.2 | M15: 9.3 | O15: a3
A16: =+A15+1 -> 6 | B16: =+B13 -> 44947 | C16: Base65 | D16: {=TRANSPOSE('[4]January 21 23 bySite'!$K$24:$K$33)} -> 13 | E16: 13.8 | F16: 14.6 | G16: 12.6 | H16: 17.2 | I16: 15.4 | J16: 20.1 | K16: 16.8 | L16: 16.2 | M16: 14.3 | O16: a4
A17: =+A16+1 -> 7
A18: =+A17+1 -> 8 | B18: Weather Weights (b)
A19: =+A18+1 -> 9 | C19: HDD | D19: =+'Res Seasonal Weights'!D30 -> 0.014 | E19: =+'Res Seasonal Weights'!D36 -> 0.04 | F19: =+'Res Seasonal Weights'!D27 -> 0.686 | G19: =+'Res Seasonal Weights'!D32 -> 0.052 | H19: =+'Res Seasonal Weights'!D35 -> 0.039 | I19: =+'Res Seasonal Weights'!D29 -> 0.028 | J19: =+'Res Seasonal Weights'!D28 -> 0.056 | K19: =+'Res Seasonal Weights'!D31 -> 0.027 | L19: =+'Res Seasonal Weights'!D33 -> 0.039 | M19: =+'Res Seasonal Weights'!D34 -> 0.019 | O19: b
A22: =+A19+1 -> 10 | B22: Residential Heating Degree Days Contribution by Station (c = a*b)
A23: =+A22+1 -> 11
A24: =+A23+1 -> 12 | B24: Date | C24: HDD | D24: {=TRANSPOSE('[4]January 21 23 bySite'!$B$11:$B$20)} -> Abilene | E24: Austin | F24: Dallas-Ft. Worth | G24: Kileen-Temple | H24: Longview | I24: Lufkin | J24: Midland-Odessa | K24: Sherman-Denison | L24: Waco | M24: Wichita Falls | N24: Residential Class
A25: =+A24+1 -> 13 | B25: =+B13 -> 44947 | C25: =+C13 -> Base45 | D25: =+D13*D$19 -> 0 | E25: =+E13*E$19 -> 0 | F25: =+F13*F$19 -> 0 | G25: =+G13*G$19 -> 0 | H25: =+H13*H$19 -> 0 | I25: =+I13*I$19 -> 0 | J25: =+J13*J$19 -> 0.0056 | K25: =+K13*K$19 -> 0 | ... M25: =+M13*M$19 -> 0 | N25: =SUM(D25:M25) -> 0.0056 | O25: c1 = a1*b
A26: =+A25+1 -> 14 | B26: =+B14 -> 44947 | C26: =+C14 -> Base55 | D26: =+D14*D$19 -> 0.042 | E26: =+E14*E$19 -> 0.152 | F26: =+F14*F$19 -> 3.1556 | G26: =+G14*G$19 -> 0.1352 | H26: =+H14*H$19 -> 0.2808 | I26: =+I14*I$19 -> 0.1512 | J26: =+J14*J$19 -> 0.5656 | K26: =+K14*K$19 -> 0.1836 | ... M26: =+M14*M$19 -> 0.0817 | N26: =SUM(D26:M26) -> 4.9895 | O26: c2 = a2*b
A27: =+A26+1 -> 15 | B27: =+B15 -> 44947 | C27: =+C15 -> Base60 | D27: =+D15*D$19 -> 0.112 | E27: =+E15*E$19 -> 0.352 | F27: =+F15*F$19 -> 6.5856 | G27: =+G15*G$19 -> 0.3952 | H27: =+H15*H$19 -> 0.4758 | I27: =+I15*I$19 -> 0.2912 | J27: =+J15*J$19 -> 0.8456 | K27: =+K15*K$19 -> 0.3186 | ... M27: =+M15*M$19 -> 0.1767 | N27: =SUM(D27:M27) -> 9.9895 | O27: c2 = a3*b
A28: =+A27+1 -> 16 | B28: =+B16 -> 44947 | C28: =+C16 -> Base65 | D28: =+D16*D$19 -> 0.182 | E28: =+E16*E$19 -> 0.552 | F28: =+F16*F$19 -> 10.0156 | G28: =+G16*G$19 -> 0.6552 | H28: =+H16*H$19 -> 0.6708 | I28: =+I16*I$19 -> 0.4312 | J28: =+J16*J$19 -> 1.1256 | K28: =+K16*K$19 -> 0.4536 | ... M28: =+M16*M$19 -> 0.2717 | N28: =SUM(D28:M28) -> 14.9895 | O28: c3 = a4*b

Sheet HEATING Weighting (2)
B1: =+RES!B1 -> PUC DOCKET NO.
B2: =+RES!B2 -> ONCOR ELECTRIC DELIVERY COMPANY LLC
B3: =+RES!B3 -> ADJUSTED WEATHER STATION DATA
B4: =+RES!B4 -> FOR THE TEST YEAR ENDING DECEMBER 31, 2024
B6: =+RES!B6 -> SPONSOR: D. E. NELSON
B8: RESIDENTIAL CLASS WEIGHTING FOR DAILY HEATING DEGREE DAYS FOR JANUARY 14, 2024
A9: Line
A10: No.
A11: 1 | B11: Heating Degree Days by Station (a)
A12: =+A11+1 -> 2 | B12: Date | C12: HDD | D12: {=TRANSPOSE('[4]January 14 24 bySite'!$B$11:$B$20)} -> Abilene | E12: Austin | F12: Dallas-Ft. Worth | G12: Kileen-Temple | H12: Longview | I12: Lufkin | J12: Midland-Odessa | K12: Sherman-Denison | L12: Waco | M12: Wichita Falls
A13: =+A12+1 -> 3 | B13: 45305 | C13: Base45 | D13: {=TRANSPOSE('[4]January 14 24 bySite'!$H$24:$H$33)} -> 32.9 | E13: 18.4 | F13: 29.7 | G13: 24.9 | H13: 20 | I13: 10.7 | J13: 28.5 | K13: 33.4 | L13: 25.1 | M13: 35 | O13: a1
A14: =+A13+1 -> 4 | B14: =+B13 -> 45305 | C14: Base55 | D14: {=TRANSPOSE('[4]January 14 24 bySite'!$I$24:$I$33)} -> 42.9 | E14: 28.4 | F14: 39.7 | G14: 34.9 | H14: 30 | I14: 20.7 | J14: 38.5 | K14: 43.4 | L14: 35.1 | M14: 45 | O14: a2
A15: =+A14+1 -> 5 | B15: =+B13 -> 45305 | C15: Base60 | D15: {=TRANSPOSE('[4]January 14 24 bySite'!$J$24:$J$33)} -> 47.9 | E15: 33.4 | F15: 44.7 | G15: 39.9 | H15: 35 | I15: 25.7 | J15: 43.5 | K15: 48.4 | L15: 40.1 | M15: 50 | O15: a3
A16: =+A15+1 -> 6 | B16: =+B13 -> 45305 | C16: Base65 | D16: {=TRANSPOSE('[4]January 14 24 bySite'!$K$24:$K$33)} -> 52.9 | E16: 38.4 | F16: 49.7 | G16: 44.9 | H16: 40 | I16: 30.7 | J16: 48.5 | K16: 53.4 | L16: 45.1 | M16: 55 | O16: a4
A17: =+A16+1 -> 7
A18: =+A17+1 -> 8 | B18: Weather Weights (b)
A19: =+A18+1 -> 9 | C19: HDD | D19: =+'Res Seasonal Weights'!D30 -> 0.014 | E19: =+'Res Seasonal Weights'!D36 -> 0.04 | F19: =+'Res Seasonal Weights'!D27 -> 0.686 | G19: =+'Res Seasonal Weights'!D32 -> 0.052 | H19: =+'Res Seasonal Weights'!D35 -> 0.039 | I19: =+'Res Seasonal Weights'!D29 -> 0.028 | J19: =+'Res Seasonal Weights'!D28 -> 0.056 | K19: =+'Res Seasonal Weights'!D31 -> 0.027 | L19: =+'Res Seasonal Weights'!D33 -> 0.039 | M19: =+'Res Seasonal Weights'!D34 -> 0.019 | O19: b
A22: =+A19+1 -> 10 | B22: Residential Heating Degree Days Contribution by Station (c = a*b)
A23: =+A22+1 -> 11
A24: =+A23+1 -> 12 | B24: Date | C24: HDD | D24: {=TRANSPOSE('[4]January 14 24 bySite'!$B$11:$B$20)} -> Abilene | E24: Austin | F24: Dallas-Ft. Worth | G24: Kileen-Temple | H24: Longview | I24: Lufkin | J24: Midland-Odessa | K24: Sherman-Denison | L24: Waco | M24: Wichita Falls | N24: Residential Class
A25: =+A24+1 -> 13 | B25: =+B13 -> 45305 | C25: =+C13 -> Base45 | D25: =+D13*D$19 -> 0.4606 | E25: =+E13*E$19 -> 0.736 | F25: =+F13*F$19 -> 20.3742 | G25: =+G13*G$19 -> 1.2948 | H25: =+H13*H$19 -> 0.78 | I25: =+I13*I$19 -> 0.2996 | J25: =+J13*J$19 -> 1.596 | K25: =+K13*K$19 -> 0.9018 | ... M25: =+M13*M$19 -> 0.665 | N25: =SUM(D25:M25) -> 28.0869 | O25: c1 = a1*b
A26: =+A25+1 -> 14 | B26: =+B14 -> 45305 | C26: =+C14 -> Base55 | D26: =+D14*D$19 -> 0.6006 | E26: =+E14*E$19 -> 1.136 | F26: =+F14*F$19 -> 27.2342 | G26: =+G14*G$19 -> 1.8148 | H26: =+H14*H$19 -> 1.17 | I26: =+I14*I$19 -> 0.5796 | J26: =+J14*J$19 -> 2.156 | K26: =+K14*K$19 -> 1.1718 | ... M26: =+M14*M$19 -> 0.855 | N26: =SUM(D26:M26) -> 38.0869 | O26: c2 = a2*b
A27: =+A26+1 -> 15 | B27: =+B15 -> 45305 | C27: =+C15 -> Base60 | D27: =+D15*D$19 -> 0.6706 | E27: =+E15*E$19 -> 1.336 | F27: =+F15*F$19 -> 30.6642 | G27: =+G15*G$19 -> 2.0748 | H27: =+H15*H$19 -> 1.365 | I27: =+I15*I$19 -> 0.7196 | J27: =+J15*J$19 -> 2.436 | K27: =+K15*K$19 -> 1.3068 | ... M27: =+M15*M$19 -> 0.95 | N27: =SUM(D27:M27) -> 43.0869 | O27: c3 = a3*b
A28: =+A27+1 -> 16 | B28: =+B16 -> 45305 | C28: =+C16 -> Base65 | D28: =+D16*D$19 -> 0.7406 | E28: =+E16*E$19 -> 1.536 | F28: =+F16*F$19 -> 34.0942 | G28: =+G16*G$19 -> 2.3348 | H28: =+H16*H$19 -> 1.56 | I28: =+I16*I$19 -> 0.8596 | J28: =+J16*J$19 -> 2.716 | K28: =+K16*K$19 -> 1.4418 | ... M28: =+M16*M$19 -> 1.045 | N28: =SUM(D28:M28) -> 48.0869 | O28: c4 = a4*b

Sheet Simple Averages_0121
B1: =+RES!B1 -> PUC DOCKET NO.
B2: =+RES!B2 -> ONCOR ELECTRIC DELIVERY COMPANY LLC
B3: =+RES!B3 -> ADJUSTED WEATHER STATION DATA
B4: =+RES!B4 -> FOR THE TEST YEAR ENDING DECEMBER 31, 2024
B6: =+RES!B6 -> SPONSOR: D. E. NELSON
B8: RESIDENTIAL SIMPLE TWENTY YEAR AVERAGE CALCULATION FOR JANUARY 21ST
A9: Line No.
A10: 1 | B10: Year | C10: Month | D10: Day | E10: HDD45 | F10: HDD55 | G10: HDD60 | H10: HDD65 | I10: CDD65 | J10: CDD70 | K10: CDD75 | L10: CDD80
A11: =+A10+1 -> 2 | B11: 2004 | C11: 1 | D11: 21 | E11: 3.123625 | F11: 12.963625 | G11: 17.963625 | H11: 22.963625 | I11: 0 | J11: 0 | K11: 0 | L11: 0
A12: =+A11+1 -> 3 | B12: =+B11+1 -> 2005 | C12: =+C11 -> 1 | D12: =+D11 -> 21 | E12: 0 | F12: 0.27533333 | G12: 1.128 | H12: 6.0988333 | I12: 0 | J12: 0 | K12: 0 | L12: 0
A13: =+A12+1 -> 4 | B13: =+B12+1 -> 2006 | C13: =+C12 -> 1 | D13: =+D12 -> 21 | E13: 0.396625 | F13: 7.9460833 | G13: 12.946083 | H13: 17.946083 | I13: 0 | J13: 0 | K13: 0 | L13: 0
A14: =+A13+1 -> 5 | B14: =+B13+1 -> 2007 | C14: =+C13 -> 1 | D14: =+D13 -> 21 | E14: 0.68991667 | F14: 10.386667 | G14: 15.386667 | H14: 20.386667 | I14: 0 | J14: 0 | K14: 0 | L14: 0
A15: =+A14+1 -> 6 | B15: =+B14+1 -> 2008 | C15: =+C14 -> 1 | D15: =+D14 -> 21 | E15: 2.3198 | F15: 11.9099 | G15: 16.9099 | H15: 21.9099 | I15: 0 | J15: 0 | K15: 0 | L15: 0
A16: =+A15+1 -> 7 | B16: =+B15+1 -> 2009 | C16: =+C15 -> 1 | D16: =+D15 -> 21 | E16: 0.173 | F16: 5.066 | G16: 10.066 | H16: 15.066 | I16: 0 | J16: 0 | K16: 0 | L16: 0
A17: =+A16+1 -> 8 | B17: =+B16+1 -> 2010 | C17: =+C16 -> 1 | D17: =+D16 -> 21 | E17: 0 | F17: 0.3627 | G17: 3.1752 | H17: 8.1181 | I17: 0 | J17: 0 | K17: 0 | L17: 0
A18: =+A17+1 -> 9 | B18: =+B17+1 -> 2011 | C18: =+C17 -> 1 | D18: =+D17 -> 21 | E18: 12.7045 | F18: 22.7045 | G18: 27.7045 | H18: 32.7045 | I18: 0 | J18: 0 | K18: 0 | L18: 0
A19: =+A18+1 -> 10 | B19: =+B18+1 -> 2012 | C19: =+C18 -> 1 | D19: =+D18 -> 21 | E19: 1.5125 | F19: 10.1797 | G19: 15.0397 | H19: 20.0257 | I19: 0 | J19: 0 | K19: 0 | L19: 0
A20: =+A19+1 -> 11 | B20: =+B19+1 -> 2013 | C20: =+C19 -> 1 | D20: =+D19 -> 21 | E20: 0.6286 | F20: 8.4728 | G20: 13.456 | H20: 18.456 | I20: 0 | J20: 0 | K20: 0 | L20: 0
A21: =+A20+1 -> 12 | B21: =+B20+1 -> 2014 | C21: =+C20 -> 1 | D21: =+D20 -> 21 | E21: 1.208 | F21: 10.632 | G21: 15.632 | H21: 20.632 | I21: 0 | J21: 0 | K21: 0 | L21: 0
A22: =+A21+1 -> 13 | B22: =+B21+1 -> 2015 | C22: =+C21 -> 1 | D22: =+D21 -> 21 | E22: 0.2258 | F22: 5.5547 | G22: 10.4763 | H22: 15.4763 | I22: 0 | J22: 0 | K22: 0 | L22: 0
A23: =+A22+1 -> 14 | B23: =+B22+1 -> 2016 | C23: =+C22 -> 1 | D23: =+D22 -> 21 | E23: 0.3704 | F23: 9.1041 | G23: 14.1041 | H23: 19.1041 | I23: 0 | J23: 0 | K23: 0 | L23: 0
... A30: =+A29+1 -> 21 | B30: =+B29+1 -> 2023 | C30: =+C29 -> 1 | D30: =+D29 -> 21 | E30: 0.0056 | F30: 4.9895 | G30: 9.9895 | H30: 14.9895 | I30: 0 | J30: 0 | K30: 0 | L30: 0
A31: =+A30+1 -> 22 | B31: 1/21 | E31: =AVERAGE(E11:E30) -> 1.8834333 | F31: =AVERAGE(F11:F30) -> 8.3457204 | G31: =AVERAGE(G11:G30) -> 12.613924 | H31: =AVERAGE(H11:H30) -> 17.374625 | I31: =AVERAGE(I11:I30) -> 0.09785 | J31: =AVERAGE(J11:J30) -> 0 | K31: =AVERAGE(K11:K30) -> 0 | L31: =AVERAGE(L11:L30) -> 0

Sheet Simple Averages_0720
B1: =+RES!B1 -> PUC DOCKET NO.
B2: =+RES!B2 -> ONCOR ELECTRIC DELIVERY COMPANY LLC
B3: =+RES!B3 -> ADJUSTED WEATHER STATION DATA
B4: =+RES!B4 -> FOR THE TEST YEAR ENDING DECEMBER 31, 2024
B6: =+RES!B6 -> SPONSOR: D. E. NELSON
B8: RESIDENTIAL SIMPLE TWENTY YEAR AVERAGE CALCULATION FOR JULY 20TH
A9: Line No.
A10: 1 | B10: Year | C10: Month | D10: Day | E10: HDD45 | F10: HDD55 | G10: HDD60 | H10: HDD65 | I10: CDD65 | J10: CDD70 | K10: CDD75 | L10: CDD80
A11: =+A10+1 -> 2 | B11: 2004 | C11: 7 | D11: 20 | E11: 0 | F11: 0 | G11: 0 | H11: 0 | I11: 18.936708 | J11: 13.931708 | K11: 8.9267083 | L11: 3.9794583
A12: =+A11+1 -> 3 | B12: =+B11+1 -> 2005 | C12: =+C11 -> 7 | D12: =+D11 -> 20 | E12: 0 | F12: 0 | G12: 0 | H12: 0 | I12: 19.823167 | J12: 14.818167 | K12: 9.8131667 | L12: 4.8426667
A13: =+A12+1 -> 4 | B13: =+B12+1 -> 2006 | C13: =+C12 -> 7 | D13: =+D12 -> 20 | E13: 0 | F13: 0 | G13: 0 | H13: 0 | I13: 25.705792 | J13: 20.700792 | K13: 15.695792 | L13: 10.690792
A14: =+A13+1 -> 5 | B14: =+B13+1 -> 2007 | C14: =+C13 -> 7 | D14: =+D13 -> 20 | E14: 0 | F14: 0 | G14: 0 | H14: 0 | I14: 14.462417 | J14: 9.4574167 | K14: 4.5264167 | L14: 0.52725
A15: =+A14+1 -> 6 | B15: =+B14+1 -> 2008 | C15: =+C14 -> 7 | D15: =+D14 -> 20 | E15: 0 | F15: 0 | G15: 0 | H15: 0 | I15: 23.8137 | J15: 18.8087 | K15: 13.8037 | L15: 8.7987
A16: =+A15+1 -> 7 | B16: =+B15+1 -> 2009 | C16: =+C15 -> 7 | D16: =+D15 -> 20 | E16: 0 | F16: 0 | G16: 0 | H16: 0 | I16: 16.114 | J16: 11.109 | K16: 6.104 | L16: 1.154
A17: =+A16+1 -> 8 | B17: =+B16+1 -> 2010 | C17: =+C16 -> 7 | D17: =+D16 -> 20 | E17: 0 | F17: 0 | G17: 0 | H17: 0 | I17: 21.196 | J17: 16.191 | K17: 11.186 | L17: 6.181
A18: =+A17+1 -> 9 | B18: =+B17+1 -> 2011 | C18: =+C17 -> 7 | D18: =+D17 -> 20 | E18: 0 | F18: 0 | G18: 0 | H18: 0 | I18: 24.0557 | J18: 19.0507 | K18: 14.0457 | L18: 9.0407
A19: =+A18+1 -> 10 | B19: =+B18+1 -> 2012 | C19: =+C18 -> 7 | D19: =+D18 -> 20 | E19: 0 | F19: 0 | G19: 0 | H19: 0 | I19: 23.204 | J19: 18.199 | K19: 13.194 | L19: 8.189
A20: =+A19+1 -> 11 | B20: =+B19+1 -> 2013 | C20: =+C19 -> 7 | D20: =+D19 -> 20 | E20: 0 | F20: 0 | G20: 0 | H20: 0 | I20: 16.6549 | J20: 11.6499 | K20: 6.6449 | L20: 1.7181
A21: =+A20+1 -> 12 | B21: =+B20+1 -> 2014 | C21: =+C20 -> 7 | D21: =+D20 -> 20 | E21: 0 | F21: 0 | G21: 0 | H21: 0 | I21: 14.4386 | J21: 9.4336 | K21: 4.4286 | L21: 0.5472
A22: =+A21+1 -> 13 | B22: =+B21+1 -> 2015 | C22: =+C21 -> 7 | D22: =+D21 -> 20 | E22: 0 | F22: 0 | G22: 0 | H22: 0 | I22: 23.8924 | J22: 18.8874 | K22: 13.8824 | L22: 8.8774
A23: =+A22+1 -> 14 | B23: =+B22+1 -> 2016 | C23: =+C22 -> 7 | D23: =+D22 -> 20 | E23: 0 | F23: 0 | G23: 0 | H23: 0 | I23: 23.1655 | J23: 18.1605 | K23: 13.1555 | L23: 8.1505
... A30: =+A29+1 -> 21 | B30: =+B29+1 -> 2023 | C30: =+C29 -> 7 | D30: =+D29 -> 20 | E30: 0 | F30: 0 | G30: 0 | H30: 0 | I30: 26.4686 | J30: 21.4636 | K30: 16.4586 | L30: 11.4536
A31: =+A30+1 -> 22 | B31: 7/20 | E31: =AVERAGE(E11:E30) -> 0 | F31: =AVERAGE(F11:F30) -> 0 | G31: =AVERAGE(G11:G30) -> 0 | H31: =AVERAGE(H11:H30) -> 0 | I31: =AVERAGE(I11:I30) -> 21.644244 | J31: =AVERAGE(J11:J30) -> 16.639244 | K31: =AVERAGE(K11:K30) -> 11.637944 | L31: =AVERAGE(L11:L30) -> 6.7842983

Sheet Simple Averages_0114
B1: =+RES!B1 -> PUC DOCKET NO.
B2: =+RES!B2 -> ONCOR ELECTRIC DELIVERY COMPANY LLC
B3: =+RES!B3 -> ADJUSTED WEATHER STATION DATA
B4: =+RES!B4 -> FOR THE TEST YEAR ENDING DECEMBER 31, 2024
B6: =+RES!B6 -> SPONSOR: D. E. NELSON
B8: RESIDENTIAL SIMPLE TWENTY YEAR AVERAGE CALCULATION FOR JANUARY 14TH
A9: Line No.
A10: 1 | B10: Year | C10: Month | D10: Day | E10: HDD45 | F10: HDD55 | G10: HDD60 | H10: HDD65 | I10: CDD65 | J10: CDD70 | K10: CDD75 | L10: CDD80
A11: =+A10+1 -> 2 | B11: 2004 | C11: 1 | D11: 14 | E11: 0 | F11: 0.51458333 | G11: 3.1735833 | H11: 8.0565833 | I11: 0 | J11: 0 | K11: 0 | L11: 0
A12: =+A11+1 -> 3 | B12: =+B11+1 -> 2005 | C12: =+C11 -> 1 | D12: =+D11 -> 14 | E12: 3.4289583 | F12: 13.407958 | G12: 18.407958 | H12: 23.407958 | I12: 0 | J12: 0 | K12: 0 | L12: 0
A13: =+A12+1 -> 4 | B13: =+B12+1 -> 2006 | C13: =+C12 -> 1 | D13: =+D12 -> 14 | E13: 0 | F13: 5.4309167 | G13: 10.430917 | H13: 15.430917 | I13: 0 | J13: 0 | K13: 0 | L13: 0
A14: =+A13+1 -> 5 | B14: =+B13+1 -> 2007 | C14: =+C13 -> 1 | D14: =+D13 -> 14 | E14: 11.868708 | F14: 21.710042 | G14: 26.710042 | H14: 31.710042 | I14: 0 | J14: 0 | K14: 0 | L14: 0
A15: =+A14+1 -> 6 | B15: =+B14+1 -> 2008 | C15: =+C14 -> 1 | D15: =+D14 -> 14 | E15: 0.4611 | F15: 6.5628 | G15: 11.5628 | H15: 16.5628 | I15: 0 | J15: 0 | K15: 0 | L15: 0
A16: =+A15+1 -> 7 | B16: =+B15+1 -> 2009 | C16: =+C15 -> 1 | D16: =+D15 -> 14 | E16: 1.061 | F16: 11.061 | G16: 16.061 | H16: 21.061 | I16: 0 | J16: 0 | K16: 0 | L16: 0
A17: =+A16+1 -> 8 | B17: =+B16+1 -> 2010 | C17: =+C16 -> 1 | D17: =+D16 -> 14 | E17: 0 | F17: 3.3524 | G17: 8.3524 | H17: 13.3524 | I17: 0 | J17: 0 | K17: 0 | L17: 0
A18: =+A17+1 -> 9 | B18: =+B17+1 -> 2011 | C18: =+C17 -> 1 | D18: =+D17 -> 14 | E18: 4.5829 | F18: 14.5829 | G18: 19.5829 | H18: 24.5829 | I18: 0 | J18: 0 | K18: 0 | L18: 0
A19: =+A18+1 -> 10 | B19: =+B18+1 -> 2012 | C19: =+C18 -> 1 | D19: =+D18 -> 14 | E19: 0.1148 | F19: 6.5702 | G19: 11.5702 | H19: 16.5702 | I19: 0 | J19: 0 | K19: 0 | L19: 0
A20: =+A19+1 -> 11 | B20: =+B19+1 -> 2013 | C20: =+C19 -> 1 | D20: =+D19 -> 14 | E20: 9.9001 | F20: 19.9001 | G20: 24.9001 | H20: 29.9001 | I20: 0 | J20: 0 | K20: 0 | L20: 0
A21: =+A20+1 -> 12 | B21: =+B20+1 -> 2014 | C21: =+C20 -> 1 | D21: =+D20 -> 14 | E21: 0.0152 | F21: 6.2174 | G21: 11.2174 | H21: 16.2174 | I21: 0 | J21: 0 | K21: 0 | L21: 0
A22: =+A21+1 -> 13 | B22: =+B21+1 -> 2015 | C22: =+C21 -> 1 | D22: =+D21 -> 14 | E22: 7.4059 | F22: 17.4059 | G22: 22.4059 | H22: 27.4059 | I22: 0 | J22: 0 | K22: 0 | L22: 0
A23: =+A22+1 -> 14 | B23: =+B22+1 -> 2016 | C23: =+C22 -> 1 | D23: =+D22 -> 14 | E23: 0 | F23: 1.057 | G23: 6.029 | H23: 11.029 | I23: 0 | J23: 0 | K23: 0 | L23: 0
... A30: =+A29+1 -> 21 | B30: =+B29+1 -> 2023 | C30: =+C29 -> 1 | D30: =+D29 -> 14 | E30: 0.0858 | F30: 5.4562 | G30: 10.4562 | H30: 15.4562 | I30: 0 | J30: 0 | K30: 0 | L30: 0
A31: =+A30+1 -> 22 | B31: 1/14 | E31: =AVERAGE(E11:E30) -> 2.6445733 | F31: =AVERAGE(F11:F30) -> 9.072895 | G31: =AVERAGE(G11:G30) -> 13.555835 | H31: =AVERAGE(H11:H30) -> 18.424665 | I31: =AVERAGE(I11:I30) -> 0.00385 | J31: =AVERAGE(J11:J30) -> 0 | K31: =AVERAGE(K11:K30) -> 0 | L31: =AVERAGE(L11:L30) -> 0

Sheet Simple Averages_0714
B1: =+RES!B1 -> PUC DOCKET NO.
B2: =+RES!B2 -> ONCOR ELECTRIC DELIVERY COMPANY LLC
B3: =+RES!B3 -> ADJUSTED WEATHER STATION DATA
B4: =+RES!B4 -> FOR THE TEST YEAR ENDING DECEMBER 31, 2024
B6: =+RES!B6 -> SPONSOR: D. E. NELSON
B8: RESIDENTIAL SIMPLE TWENTY YEAR AVERAGE CALCULATION FOR JULY 14TH
A9: Line No.
A10: 1 | B10: Year | C10: Month | D10: Day | E10: HDD45 | F10: HDD55 | G10: HDD60 | H10: HDD65 | I10: CDD65 | J10: CDD70 | K10: CDD75 | L10: CDD80
A11: =+A10+1 -> 2 | B11: 2004 | C11: 7 | D11: 14 | E11: 0 | F11: 0 | G11: 0 | H11: 0 | I11: 21.069083 | J11: 16.064083 | K11: 11.059083 | L11: 6.0540833
A12: =+A11+1 -> 3 | B12: =+B11+1 -> 2005 | C12: =+C11 -> 7 | D12: =+D11 -> 14 | E12: 0 | F12: 0 | G12: 0 | H12: 0 | I12: 18.426292 | J12: 13.421292 | K12: 8.4162917 | L12: 3.53475
A13: =+A12+1 -> 4 | B13: =+B12+1 -> 2006 | C13: =+C12 -> 7 | D13: =+D12 -> 14 | E13: 0 | F13: 0 | G13: 0 | H13: 0 | I13: 24.193708 | J13: 19.188708 | K13: 14.183708 | L13: 9.1787083
A14: =+A13+1 -> 5 | B14: =+B13+1 -> 2007 | C14: =+C13 -> 7 | D14: =+D13 -> 14 | E14: 0 | F14: 0 | G14: 0 | H14: 0 | I14: 15.370583 | J14: 10.365583 | K14: 5.3665833 | L14: 1.08225
A15: =+A14+1 -> 6 | B15: =+B14+1 -> 2008 | C15: =+C14 -> 7 | D15: =+D14 -> 14 | E15: 0 | F15: 0 | G15: 0 | H15: 0 | I15: 20.7078 | J15: 15.7028 | K15: 10.6978 | L15: 5.7506
A16: =+A15+1 -> 7 | B16: =+B15+1 -> 2009 | C16: =+C15 -> 7 | D16: =+D15 -> 14 | E16: 0 | F16: 0 | G16: 0 | H16: 0 | I16: 26.9627 | J16: 21.9577 | K16: 16.9527 | L16: 11.9477
A17: =+A16+1 -> 8 | B17: =+B16+1 -> 2010 | C17: =+C16 -> 7 | D17: =+D16 -> 14 | E17: 0 | F17: 0 | G17: 0 | H17: 0 | I17: 22.2678 | J17: 17.2628 | K17: 12.2578 | L17: 7.2528
A18: =+A17+1 -> 9 | B18: =+B17+1 -> 2011 | C18: =+C17 -> 7 | D18: =+D17 -> 14 | E18: 0 | F18: 0 | G18: 0 | H18: 0 | I18: 27.2984 | J18: 22.2934 | K18: 17.2884 | L18: 12.2834
A19: =+A18+1 -> 10 | B19: =+B18+1 -> 2012 | C19: =+C18 -> 7 | D19: =+D18 -> 14 | E19: 0 | F19: 0 | G19: 0 | H19: 0 | I19: 18.5879 | J19: 13.5829 | K19: 8.5779 | L19: 3.7203
A20: =+A19+1 -> 11 | B20: =+B19+1 -> 2013 | C20: =+C19 -> 7 | D20: =+D19 -> 14 | E20: 0 | F20: 0 | G20: 0 | H20: 0 | I20: 10.1887 | J20: 5.1837 | K20: 1.341 | L20: 0.5742
A21: =+A20+1 -> 12 | B21: =+B20+1 -> 2014 | C21: =+C20 -> 7 | D21: =+D20 -> 14 | E21: 0 | F21: 0 | G21: 0 | H21: 0 | I21: 21.1745 | J21: 16.1695 | K21: 11.1645 | L21: 6.1595
A22: =+A21+1 -> 13 | B22: =+B21+1 -> 2015 | C22: =+C21 -> 7 | D22: =+D21 -> 14 | E22: 0 | F22: 0 | G22: 0 | H22: 0 | I22: 22.4871 | J22: 17.4821 | K22: 12.4771 | L22: 7.4721
A23: =+A22+1 -> 14 | B23: =+B22+1 -> 2016 | C23: =+C22 -> 7 | D23: =+D22 -> 14 | E23: 0 | F23: 0 | G23: 0 | H23: 0 | I23: 23.1467 | J23: 18.1417 | K23: 13.1367 | L23: 8.1317
... A30: =+A29+1 -> 21 | B30: =+B29+1 -> 2023 | C30: =+C29 -> 7 | D30: =+D29 -> 14 | E30: 0 | F30: 0 | G30: 0 | H30: 0 | I30: 27.4015 | J30: 22.3965 | K30: 17.3915 | L30: 12.3865
A31: =+A30+1 -> 22 | B31: 7/14 | E31: =AVERAGE(E11:E30) -> 0 | F31: =AVERAGE(F11:F30) -> 0 | G31: =AVERAGE(G11:G30) -> 0 | H31: =AVERAGE(H11:H30) -> 0 | I31: =AVERAGE(I11:I30) -> 21.122223 | J31: =AVERAGE(J11:J30) -> 16.117223 | K31: =AVERAGE(K11:K30) -> 11.170898 | L31: =AVERAGE(L11:L30) -> 6.4770196

Sheet Smoothed Normal for 0121
B1: =+RES!B1 -> PUC DOCKET NO.
B2: =+RES!B2 -> ONCOR ELECTRIC DELIVERY COMPANY LLC
B3: =+RES!B3 -> ADJUSTED WEATHER STATION DATA
B4: =+RES!B4 -> FOR THE TEST YEAR ENDING DECEMBER 31, 2024
B6: =+RES!B6 -> SPONSOR: D. E. NELSON
B8: RESIDENTIAL SMOOTHED NORMAL CALCULATION FOR JANUARY 21ST
A9: Line
A10: No.
A11: 1
A12: =+A11+1 -> 2 | C12: Base45 | D12: Base55 | E12: Base60 | F12: Base65 | H12: Base50 | I12: Base55 | J12: Base60 | K12: Base61
A13: =+A12+1 -> 3 | C13: c1 | D13: c2 | E13: c3 | F13: c4 | H13: c1 | I13: c2 | J13: c3 | K13: c4
A14: =+A13+1 -> 4 | B14: 44932 | C14: 4.6288212 | D14: 11.118305 | E14: 15.547275 | F14: 20.29292 | L14: 2023
A15: =+A14+1 -> 5 | B15: 44933 | C15: 4.2516246 | D15: 10.163279 | E15: 14.334045 | F15: 18.874335 | L15: 2023
A16: =+A15+1 -> 6 | B16: 44934 | C16: 2.9502671 | D16: 8.8375779 | E16: 13.272103 | F16: 18.065582 | L16: 2023
A17: =+A16+1 -> 7 | B17: 44935 | C17: 2.6962492 | D17: 8.6153471 | E17: 12.978053 | F17: 17.55415 | L17: 2023
A18: =+A17+1 -> 8 | B18: 44936 | C18: 3.4781725 | D18: 9.2984829 | E18: 13.147601 | F18: 17.285702 | L18: 2023
A19: =+A18+1 -> 9 | B19: 44937 | C19: 2.7265208 | D19: 8.4658258 | E19: 12.323492 | F19: 16.594989 | L19: 2023
A20: =+A19+1 -> 10 | B20: 44938 | C20: 2.7419062 | D20: 8.3260933 | E20: 12.28223 | F20: 16.617758 | L20: 2023
A21: =+A20+1 -> 11 | B21: 44939 | C21: 3.5559333 | D21: 10.796014 | E21: 15.554621 | F21: 20.51963 | L21: 2023
A22: =+A21+1 -> 12 | B22: 44940 | C22: 2.6445733 | D22: 9.072895 | E22: 13.555835 | F22: 18.424665 | L22: 2023
A23: =+A22+1 -> 13 | B23: 44941 | C23: 2.7843421 | D23: 9.0963175 | E23: 13.321189 | F23: 18.075486 | L23: 2023
A24: =+A23+1 -> 14 | B24: 44942 | C24: 3.8984662 | D24: 10.00951 | E24: 14.037984 | F24: 18.427909 | L24: 2023
A25: =+A24+1 -> 15 | B25: 44943 | C25: 3.2186975 | D25: 9.4241504 | E25: 13.876725 | F25: 18.712027 | L25: 2023
... A28: =+A27+1 -> 18 | B28: 44946 | C28: 2.7300421 | D28: 8.0240421 | E28: 11.787138 | F28: 16.452998 | L28: 2023
A29: =+A28+1 -> 19 | B29: 44947 | C29: 1.8834333 | D29: 8.3457204 | E29: 12.613924 | F29: 17.374625 | H29: =AVERAGE(C14:C44) -> 2.8364909 | I29: =AVERAGE(D14:D44) -> 8.8027258 | J29: =AVERAGE(E14:E44) -> 12.990098 | K29: =AVERAGE(F14:F44) -> 17.652691 | L29: 2023
A30: =+A29+1 -> 20 | B30: 44948 | C30: 1.8464867 | D30: 7.9793146 | E30: 12.312161 | F30: 17.265261 | L30: 2023
A31: =+A30+1 -> 21 | B31: 44949 | C31: 2.9007646 | D31: 9.5898562 | E31: 14.005923 | F31: 18.823203 | L31: 2023
A32: =+A31+1 -> 22 | B32: 44950 | C32: 2.2217458 | D32: 8.5479342 | E32: 12.891653 | F32: 17.5886 | L32: 2023
A33: =+A32+1 -> 23 | B33: 44951 | C33: 1.1359679 | D33: 6.6714767 | E33: 10.79376 | F33: 15.663288 | L33: 2023
A34: =+A33+1 -> 24 | B34: 44952 | C34: 0.987175 | D34: 7.1878371 | E34: 11.788153 | F34: 16.76265 | L34: 2023
A35: =+A34+1 -> 25 | B35: 44953 | C35: 2.0498454 | D35: 8.2504242 | E35: 12.544341 | F35: 17.402636 | L35: 2023
A36: =+A35+1 -> 26 | B36: 44954 | C36: 2.8576379 | D36: 8.3134104 | E36: 12.340545 | F36: 16.930312 | L36: 2023
A37: =+A36+1 -> 27 | B37: 44955 | C37: 2.4565558 | D37: 8.3907513 | E37: 12.41259 | F37: 17.151895 | L37: 2023
A38: =+A37+1 -> 28 | B38: 44956 | C38: 2.7504533 | D38: 8.861895 | E38: 13.05853 | F38: 17.83448 | L38: 2023
A39: =+A38+1 -> 29 | B39: 44957 | C39: 2.3379487 | D39: 7.4892971 | E39: 11.261496 | F39: 15.720051 | L39: 2023
A40: =+A39+1 -> 30 | B40: 44958 | C40: 2.8921267 | D40: 7.8024533 | E40: 11.586372 | F40: 16.191221 | L40: 2023
A41: =+A40+1 -> 31 | B41: 44959 | C41: 4.3572408 | D41: 10.339349 | E41: 14.312637 | F41: 19.179377 | L41: 2023
... A44: =+A43+1 -> 34 | B44: 44962 | C44: 3.51337 | D44: 9.5175096 | E44: 13.568479 | F44: 18.092034 | L44: 2023

Sheet Smoothed Normal for 0720
B1: =+RES!B1 -> PUC DOCKET NO.
B2: =+RES!B2 -> ONCOR ELECTRIC DELIVERY COMPANY LLC
B3: =+RES!B3 -> ADJUSTED WEATHER STATION DATA
B4: =+RES!B4 -> FOR THE TEST YEAR ENDING DECEMBER 31, 2024
B6: =+RES!B6 -> SPONSOR: D. E. NELSON
B8: RESIDENTIAL SMOOTHED NORMAL CALCULATION FOR JULY 20TH
A9: Line
A10: No.
A11: 1 | C11: Residential Raw Normal Cooling Degree Days | H11: Residential Smoothed Normal cooling Degree Days
A12: =+A11+1 -> 2 | C12: Base65 | D12: Base70 | E12: Base75 | F12: Base80 | H12: Base65 | I12: Base70 | J12: Base75 | K12: Base80
A13: =+A12+1 -> 3 | C13: c1 | D13: c2 | E13: c3 | F13: c4 | H13: c1 | I13: c2 | J13: c3 | K13: c4
A14: =+A13+1 -> 4 | B14: 45112 | C14: 19.185319 | D14: 14.180319 | E14: 9.1824667 | F14: 4.4964967
A15: =+A14+1 -> 5 | B15: 45113 | C15: 19.316142 | D15: 14.311142 | E15: 9.3078671 | F15: 4.4542733
A16: =+A15+1 -> 6 | B16: 45114 | C16: 19.419275 | D16: 14.414275 | E16: 9.4118721 | F16: 4.6258921
A17: =+A16+1 -> 7 | B17: 45115 | C17: 19.926172 | D17: 14.921172 | E17: 9.9209117 | F17: 5.0389671
A18: =+A17+1 -> 8 | B18: 45116 | C18: 19.953765 | D18: 14.948765 | E18: 9.9490754 | F18: 5.1373533
A19: =+A18+1 -> 9 | B19: 45117 | C19: 20.483313 | D19: 15.478313 | E19: 10.473313 | F19: 5.5429525
A20: =+A19+1 -> 10 | B20: 45118 | C20: 21.300015 | D20: 16.295015 | E20: 11.290015 | F20: 6.3497513
A21: =+A20+1 -> 11 | B21: 45119 | C21: 21.694723 | D21: 16.689723 | E21: 11.691263 | F21: 6.767885
A22: =+A21+1 -> 12 | B22: 45120 | C22: 22.289024 | D22: 17.284024 | E22: 12.281997 | F22: 7.3480167
A23: =+A22+1 -> 13 | B23: 45121 | C23: 21.122223 | D23: 16.117223 | E23: 11.170898 | F23: 6.4770196
A24: =+A23+1 -> 14 | B24: 45122 | C24: 19.958697 | D24: 14.970657 | E24: 10.152408 | F24: 5.4873192
A25: =+A24+1 -> 15 | B25: 45123 | C25: 20.734817 | D25: 15.739807 | E25: 10.751997 | F25: 5.9898654
... A28: =+A27+1 -> 18 | B28: 45126 | C28: 21.653783 | D28: 16.649683 | E28: 11.748153 | F28: 7.0542275
A29: =+A28+1 -> 19 | B29: 45127 | C29: 21.644244 | D29: 16.639244 | E29: 11.637944 | F29: 6.7842983 | H29: =AVERAGE(C14:C44) -> 21.119502 | I29: =AVERAGE(D14:D44) -> 16.11764 | J29: =AVERAGE(E14:E44) -> 11.143891 | K29: =AVERAGE(F14:F44) -> 6.3552013
A30: =+A29+1 -> 20 | B30: 45128 | C30: 22.096014 | D30: 17.091014 | E30: 12.093551 | F30: 7.1533433
A31: =+A30+1 -> 21 | B31: 45129 | C31: 21.993009 | D31: 16.988009 | E31: 11.990974 | F31: 7.0465621
A32: =+A31+1 -> 22 | B32: 45130 | C32: 21.347233 | D32: 16.342233 | E32: 11.352953 | F32: 6.417125
A33: =+A32+1 -> 23 | B33: 45131 | C33: 21.086017 | D33: 16.081017 | E33: 11.078537 | F33: 6.2208475
A34: =+A33+1 -> 24 | B34: 45132 | C34: 21.315808 | D34: 16.328026 | E34: 11.374524 | F34: 6.7531138
A35: =+A34+1 -> 25 | B35: 45133 | C35: 21.087732 | D35: 16.096483 | E35: 11.124573 | F35: 6.4987671
A36: =+A35+1 -> 26 | B36: 45134 | C36: 20.50346 | D36: 15.515035 | E36: 10.556535 | F36: 6.0619829
A37: =+A36+1 -> 27 | B37: 45135 | C37: 20.770107 | D37: 15.770319 | E37: 10.789675 | F37: 6.1373517
A38: =+A37+1 -> 28 | B38: 45136 | C38: 21.192769 | D38: 16.187769 | E38: 11.190846 | F38: 6.40888
A39: =+A38+1 -> 29 | B39: 45137 | C39: 21.426153 | D39: 16.421153 | E39: 11.419026 | F39: 6.5592733
A40: =+A39+1 -> 30 | B40: 45138 | C40: 21.487102 | D40: 16.482102 | E40: 11.489527 | F40: 6.7437129
A41: =+A40+1 -> 31 | B41: 45139 | C41: 21.603304 | D41: 16.598304 | E41: 11.626584 | F41: 6.9276321
... A44: =+A43+1 -> 34 | B44: 45142 | C44: 22.757325 | D44: 17.752325 | E44: 12.747325 | F44: 7.8104988

Sheet Smoothed Normal for 0114
B1: =+RES!B1 -> PUC DOCKET NO.
B2: =+RES!B2 -> ONCOR ELECTRIC DELIVERY COMPANY LLC
B3: =+RES!B3 -> ADJUSTED WEATHER STATION DATA
B4: =+RES!B4 -> FOR THE TEST YEAR ENDING DECEMBER 31, 2024
B6: =+RES!B6 -> SPONSOR: D. E. NELSON
B8: RESIDENTIAL SMOOTHED NORMAL CALCULATION FOR JANUARY 20TH
A9: Line
A10: No.
A11: 1
A12: =+A11+1 -> 2 | C12: Base45 | D12: Base55 | E12: Base60 | F12: Base65 | H12: Base45 | I12: Base55 | J12: Base60 | K12: Base65
A13: =+A12+1 -> 3 | C13: c1 | D13: c2 | E13: c3 | F13: c4 | H13: c1 | I13: c2 | J13: c3 | K13: c4
A14: =+A13+1 -> 4 | B14: 45656 | C14: 1.7915833 | D14: 7.4957704 | E14: 11.592848 | F14: 16.148031 | L14: 2024
A15: =+A14+1 -> 5 | B15: 45657 | C15: 2.4575762 | D15: 8.2663588 | E15: 12.263591 | F15: 16.835471 | L15: 2024
A16: =+A15+1 -> 6 | B16: 45292 | C16: 4.0084179 | D16: 10.205673 | E16: 14.136857 | F16: 18.228001 | L16: 2024
A17: =+A16+1 -> 7 | B17: 45293 | C17: 5.4418213 | D17: 11.989223 | E17: 15.604783 | F17: 19.571576 | L17: 2024
A18: =+A17+1 -> 8 | B18: 45294 | C18: 2.9665979 | D18: 9.5934179 | E18: 13.408082 | F18: 17.522461 | L18: 2024
A19: =+A18+1 -> 9 | B19: 45295 | C19: 2.3703183 | D19: 8.994195 | E19: 13.465339 | F19: 18.227789 | L19: 2024
A20: =+A19+1 -> 10 | B20: 45296 | C20: 3.7155771 | D20: 10.69837 | E20: 15.368198 | F20: 20.134233 | L20: 2024
A21: =+A20+1 -> 11 | B21: 45297 | C21: 4.6288212 | D21: 11.118305 | E21: 15.547275 | F21: 20.29292 | L21: 2024
A22: =+A21+1 -> 12 | B22: 45298 | C22: 4.2516246 | D22: 10.163279 | E22: 14.334045 | F22: 18.874335 | L22: 2024
A23: =+A22+1 -> 13 | B23: 45299 | C23: 2.9502671 | D23: 8.8375779 | E23: 13.272103 | F23: 18.065582 | L23: 2024
A24: =+A23+1 -> 14 | B24: 45300 | C24: 2.6962492 | D24: 8.6153471 | E24: 12.978053 | F24: 17.55415 | L24: 2024
A25: =+A24+1 -> 15 | B25: 45301 | C25: 3.4781725 | D25: 9.2984829 | E25: 13.147601 | F25: 17.285702 | L25: 2024
... A28: =+A27+1 -> 18 | B28: 45304 | C28: 3.5559333 | D28: 10.796014 | E28: 15.554621 | F28: 20.51963 | L28: 2024
A29: =+A28+1 -> 19 | B29: 45305 | C29: 2.6445733 | D29: 9.072895 | E29: 13.555835 | F29: 18.424665 | H29: =AVERAGE(C14:C44) -> 2.8298409 | I29: =AVERAGE(D14:D44) -> 8.9145408 | J29: =AVERAGE(E14:E44) -> 13.128159 | K29: =AVERAGE(F14:F44) -> 17.757578 | L29: 2024
A30: =+A29+1 -> 20 | B30: 45306 | C30: 2.7843421 | D30: 9.0963175 | E30: 13.321189 | F30: 18.075486 | L30: 2024
A31: =+A30+1 -> 21 | B31: 45307 | C31: 3.8984662 | D31: 10.00951 | E31: 14.037984 | F31: 18.427909 | L31: 2024
A32: =+A31+1 -> 22 | B32: 45308 | C32: 3.2186975 | D32: 9.4241504 | E32: 13.876725 | F32: 18.712027 | L32: 2024
A33: =+A32+1 -> 23 | B33: 45309 | C33: 2.5321621 | D33: 7.8339083 | E33: 12.282903 | F33: 17.086428 | L33: 2024
A34: =+A33+1 -> 24 | B34: 45310 | C34: 1.795785 | D34: 6.7492842 | E34: 11.128992 | F34: 15.870317 | L34: 2024
A35: =+A34+1 -> 25 | B35: 45311 | C35: 2.7300421 | D35: 8.0240421 | E35: 11.787138 | F35: 16.452998 | L35: 2024
A36: =+A35+1 -> 26 | B36: 45312 | C36: 1.8834333 | D36: 8.3457204 | E36: 12.613924 | F36: 17.374625 | L36: 2024
A37: =+A36+1 -> 27 | B37: 45313 | C37: 1.8464867 | D37: 7.9793146 | E37: 12.312161 | F37: 17.265261 | L37: 2024
A38: =+A37+1 -> 28 | B38: 45314 | C38: 2.9007646 | D38: 9.5898562 | E38: 14.005923 | F38: 18.823203 | L38: 2024
A39: =+A38+1 -> 29 | B39: 45315 | C39: 2.2217458 | D39: 8.5479342 | E39: 12.891653 | F39: 17.5886 | L39: 2024
A40: =+A39+1 -> 30 | B40: 45316 | C40: 1.1359679 | D40: 6.6714767 | E40: 10.79376 | F40: 15.663288 | L40: 2024
A41: =+A40+1 -> 31 | B41: 45317 | C41: 0.987175 | D41: 7.1878371 | E41: 11.788153 | F41: 16.76265 | L41: 2024
... A44: =+A43+1 -> 34 | B44: 45320 | C44: 2.4565558 | D44: 8.3907513 | E44: 12.41259 | F44: 17.151895 | L44: 2024

Sheet Smoothed Normal for 0714
B1: =+RES!B1 -> PUC DOCKET NO.
B2: =+RES!B2 -> ONCOR ELECTRIC DELIVERY COMPANY LLC
B3: =+RES!B3 -> ADJUSTED WEATHER STATION DATA
B4: =+RES!B4 -> FOR THE TEST YEAR ENDING DECEMBER 31, 2024
B6: =+RES!B6 -> SPONSOR: D. E. NELSON
B8: RESIDENTIAL SMOOTHED NORMAL CALCULATION FOR JULY 14TH
A9: Line
A10: No.
A11: 1 | C11: Residential Raw Normal Cooling Degree Days | H11: Residential Smoothed Normal cooling Degree Days
A12: =+A11+1 -> 2 | C12: Base65 | D12: Base70 | E12: Base75 | F12: Base80 | H12: Base65 | I12: Base70 | J12: Base75 | K12: Base80
A13: =+A12+1 -> 3 | C13: c1 | D13: c2 | E13: c3 | F13: c4 | H13: c1 | I13: c2 | J13: c3 | K13: c4
A14: =+A13+1 -> 4 | B14: 45472 | C14: 18.819833 | D14: 13.814833 | E14: 8.8883117 | F14: 4.3190479 | L14: 2024
A15: =+A14+1 -> 5 | B15: 45473 | C15: 18.826203 | D15: 13.821203 | E15: 8.8442408 | F15: 4.2623025 | L15: 2024
A16: =+A15+1 -> 6 | B16: 45474 | C16: 17.983882 | D16: 12.978882 | E16: 7.9868521 | F16: 3.40848 | L16: 2024
A17: =+A16+1 -> 7 | B17: 45475 | C17: 18.616444 | D17: 13.611444 | E17: 8.6204879 | F17: 4.0253687 | L17: 2024
A18: =+A17+1 -> 8 | B18: 45476 | C18: 19.299404 | D18: 14.294404 | E18: 9.30215 | F18: 4.6519692 | L18: 2024
A19: =+A18+1 -> 9 | B19: 45477 | C19: 19.449454 | D19: 14.444454 | E19: 9.4432292 | F19: 4.6715504 | L19: 2024
A20: =+A19+1 -> 10 | B20: 45478 | C20: 19.185319 | D20: 14.180319 | E20: 9.1824667 | F20: 4.4964967 | L20: 2024
A21: =+A20+1 -> 11 | B21: 45479 | C21: 19.316142 | D21: 14.311142 | E21: 9.3078671 | F21: 4.4542733 | L21: 2024
A22: =+A21+1 -> 12 | B22: 45480 | C22: 19.419275 | D22: 14.414275 | E22: 9.4118721 | F22: 4.6258921 | L22: 2024
A23: =+A22+1 -> 13 | B23: 45481 | C23: 19.926172 | D23: 14.921172 | E23: 9.9209117 | F23: 5.0389671 | L23: 2024
A24: =+A23+1 -> 14 | B24: 45482 | C24: 19.953765 | D24: 14.948765 | E24: 9.9490754 | F24: 5.1373533 | L24: 2024
A25: =+A24+1 -> 15 | B25: 45483 | C25: 20.483313 | D25: 15.478313 | E25: 10.473313 | F25: 5.5429525 | L25: 2024
... A28: =+A27+1 -> 18 | B28: 45486 | C28: 22.289024 | D28: 17.284024 | E28: 12.281997 | F28: 7.3480167 | L28: 2024
A29: =+A28+1 -> 19 | B29: 45487 | C29: 21.122223 | D29: 16.117223 | E29: 11.170898 | F29: 6.4770196 | H29: =AVERAGE(C14:C44) -> 20.51122 | I29: =AVERAGE(D14:D44) -> 15.509359 | J29: =AVERAGE(E14:E44) -> 10.538287 | K29: =AVERAGE(F14:F44) -> 5.7843436 | L29: 2024
A30: =+A29+1 -> 20 | B30: 45488 | C30: 19.958697 | D30: 14.970657 | E30: 10.152408 | F30: 5.4873192 | L30: 2024
A31: =+A30+1 -> 21 | B31: 45489 | C31: 20.734817 | D31: 15.739807 | E31: 10.751997 | F31: 5.9898654 | L31: 2024
A32: =+A31+1 -> 22 | B32: 45490 | C32: 21.226501 | D32: 16.229416 | E32: 11.324726 | F32: 6.6671592 | L32: 2024
A33: =+A32+1 -> 23 | B33: 45491 | C33: 21.552442 | D33: 16.556212 | E33: 11.754542 | F33: 7.0564821 | L33: 2024
A34: =+A33+1 -> 24 | B34: 45492 | C34: 21.653783 | D34: 16.649683 | E34: 11.748153 | F34: 7.0542275 | L34: 2024
A35: =+A34+1 -> 25 | B35: 45493 | C35: 21.644244 | D35: 16.639244 | E35: 11.637944 | F35: 6.7842983 | L35: 2024
A36: =+A35+1 -> 26 | B36: 45494 | C36: 22.096014 | D36: 17.091014 | E36: 12.093551 | F36: 7.1533433 | L36: 2024
A37: =+A36+1 -> 27 | B37: 45495 | C37: 21.993009 | D37: 16.988009 | E37: 11.990974 | F37: 7.0465621 | L37: 2024
A38: =+A37+1 -> 28 | B38: 45496 | C38: 21.347233 | D38: 16.342233 | E38: 11.352953 | F38: 6.417125 | L38: 2024
A39: =+A38+1 -> 29 | B39: 45497 | C39: 21.086017 | D39: 16.081017 | E39: 11.078537 | F39: 6.2208475 | L39: 2024
A40: =+A39+1 -> 30 | B40: 45498 | C40: 21.315808 | D40: 16.328026 | E40: 11.374524 | F40: 6.7531138 | L40: 2024
A41: =+A40+1 -> 31 | B41: 45499 | C41: 21.087732 | D41: 16.096483 | E41: 11.124573 | F41: 6.4987671 | L41: 2024
... A44: =+A43+1 -> 34 | B44: 45502 | C44: 21.192769 | D44: 16.187769 | E44: 11.190846 | F44: 6.40888 | L44: 2024

Sheet Cycle 20 HDD Feb 23
B1: =+RES!B1 -> PUC DOCKET NO.
B2: =+RES!B2 -> ONCOR ELECTRIC DELIVERY COMPANY LLC
B3: =+RES!B3 -> ADJUSTED WEATHER STATION DATA
B4: =+RES!B4 -> FOR THE TEST YEAR ENDING DECEMBER 31, 2024
B6: =+RES!B6 -> SPONSOR: D. E. NELSON
B8: RESIDENTIAL FEBRUARY 2023 CYCLE 20 HEATING DEGREE DAYS
A9: Line
A10: No.
A11: 1 | B11: Billing | C11: Read | D11: Prior Month
A12: =+A11+1 -> 2 | B12: Cycle | C12: Day | D12: Read Day
A13: =+A12+1 -> 3 | B13: Cycle 20 | C13: 44978 | D13: 44947
A15: =+A13+1 -> 4 | C15: Normal Heating Degree Days | H15: Actual Heating Degree Days
A16: =+A15+1 -> 5 | C16: Base45 | D16: Base55 | E16: Base60 | F16: Base65 | H16: Base45 | I16: Base55 | J16: Base60 | K16: Base65
A17: =+A16+1 -> 6 | C17: c2 | D17: c3 | E17: c4 | F17: c5 | H17: c2 | I17: c3 | J17: c4 | K17: c5
A18: =+A17+1 -> 7 | B18: =+D13 -> 44947 | C18: 2.8364909 | D18: 8.8027258 | E18: 12.990098 | F18: 17.652691 | H18: 0.0056 | I18: 4.9895 | J18: 9.9895 | K18: 14.9895
A19: =+A18+1 -> 8 | B19: =+B18+1 -> 44948 | C19: 2.781751 | D19: 8.7332284 | E19: 12.896659 | F19: 17.5378 | H19: 0.7255 | I19: 10.2111 | J19: 15.2111 | K19: 20.2111
A20: =+A19+1 -> 9 | B20: =+B19+1 -> 44949 | C20: 2.7134874 | D20: 8.6683861 | E20: 12.825759 | F20: 17.458491 | H20: 1.2267 | I20: 11.2267 | J20: 16.2267 | K20: 21.2267
A21: =+A20+1 -> 10 | B21: =+B20+1 -> 44950 | C21: 2.67292 | D21: 8.6293112 | E21: 12.779806 | F21: 17.410326 | H21: 2.6533 | I21: 12.4317 | J21: 17.4317 | K21: 22.4317
A22: =+A21+1 -> 11 | B22: =+B21+1 -> 44951 | C22: 2.6827541 | D22: 8.6350263 | E22: 12.778308 | F22: 17.417048 | H22: 4.8945 | I22: 14.8745 | J22: 19.8745 | K22: 24.8745
A23: =+A22+1 -> 12 | B23: =+B22+1 -> 44952 | C23: 2.686513 | D23: 8.6493236 | E23: 12.79417 | F23: 17.448551 | H23: 2.9598 | I23: 12.9598 | J23: 17.9598 | K23: 22.9598
A24: =+A23+1 -> 13 | B24: =+B23+1 -> 44953 | C24: 2.7421731 | D24: 8.7169831 | E24: 12.863959 | F24: 17.528048 | H24: 0.4327 | I24: 9.0169 | J24: 14.0169 | K24: 19.0169
A25: =+A24+1 -> 14 | B25: =+B24+1 -> 44954 | C25: 2.7659315 | D25: 8.7783767 | E25: 12.944055 | F25: 17.622281 | H25: 0 | I25: 0.7067 | J25: 5.1113 | K25: 10.1113
A26: =+A25+1 -> 15 | B26: =+B25+1 -> 44955 | C26: 2.7419068 | D26: 8.7249747 | E26: 12.874948 | F26: 17.541018 | H26: 2.7525 | I26: 11.1287 | J26: 15.7112 | K26: 20.6104
A27: =+A26+1 -> 16 | B27: =+B26+1 -> 44956 | C27: 2.7699035 | D27: 8.6687208 | E27: 12.780041 | F27: 17.439332 | H27: 16.4549 | I27: 26.4549 | J27: 31.4549 | K27: 36.4549
A28: =+A27+1 -> 17 | B28: =+B27+1 -> 44957 | C28: 2.7880481 | D28: 8.6017918 | E28: 12.667505 | F28: 17.292958 | H28: 17.8135 | I28: 27.8135 | J28: 32.8135 | K28: 37.8135
A29: =+A28+1 -> 18 | B29: =+B28+1 -> 44958 | C29: 2.7791881 | D29: 8.5651933 | E29: 12.611482 | F29: 17.229194 | H29: 15.6314 | I29: 25.6314 | J29: 30.6314 | K29: 35.6314
A30: =+A29+1 -> 19 | B30: =+B29+1 -> 44959 | C30: 2.7496304 | D30: 8.4952748 | E30: 12.522511 | F30: 17.123418 | H30: 11.4579 | I30: 21.4579 | J30: 26.4579 | K30: 31.4579
... A48: =+A47+1 -> 37 | B48: =+B47+1 -> 44977 | C48: 2.1354945 | D48: 6.572631 | E48: 9.9622081 | F48: 14.027412 | H48: 0 | I48: 0 | J48: 0 | K48: 0.0392
A49: =+A48+1 -> 38 | B49: Total | C49: =SUM(C18:C48) -> 81.57085 | D49: =SUM(D18:D48) -> 251.37731 | E49: =SUM(E18:E48) -> 371.76027 | F49: =SUM(F18:F48) -> 509.82719 | H49: =SUM(H18:H48) -> 96.0083 | I49: =SUM(I18:I48) -> 299.839 | J49: =SUM(J18:J48) -> 431.2998 | K49: =SUM(K18:K48) -> 573.6593

Sheet Cycle 18 CDD Aug 23
B1: =+RES!B1 -> PUC DOCKET NO.
B2: =+RES!B2 -> ONCOR ELECTRIC DELIVERY COMPANY LLC
B3: =+RES!B3 -> ADJUSTED WEATHER STATION DATA
B4: =+RES!B4 -> FOR THE TEST YEAR ENDING DECEMBER 31, 2024
B6: =+RES!B6 -> SPONSOR: D. E. NELSON
B8: RESIDENTIAL AUGUST 2023 CYCLE 18 COOLING DEGREE DAYS
A9: Line
A10: No.
A11: 1 | B11: Billing | C11: Read | D11: Prior Month
A12: =+A11+1 -> 2 | B12: Cycle | C12: Day | D12: Read Day
A13: =+A12+1 -> 3 | B13: Cycle 18 | C13: 45156 | D13: 45127
A15: =+A13+1 -> 4 | C15: Normal Cooling Degree Days | H15: Actual Cooling Degree Days
A16: =+A15+1 -> 5 | C16: Base65 | D16: Base70 | E16: Base75 | F16: Base80 | H16: Base65 | I16: Base70 | J16: Base75 | K16: Base80
A17: =+A16+1 -> 6 | C17: c1 | D17: c2 | E17: c3 | F17: c4 | H17: c1 | I17: c2 | J17: c3 | K17: c4
A18: =+A17+1 -> 7 | B18: =+D13 -> 45127 | C18: 21.119502 | D18: 16.11764 | E18: 11.143891 | F18: 6.3552013 | H18: 26.4686 | I18: 21.4636 | J18: 16.4586 | K18: 11.4536
A19: =+A18+1 -> 8 | B19: =+B18+1 -> 45128 | C19: 21.246661 | D19: 16.2448 | E19: 11.271074 | F19: 6.4744422 | H19: 24.8461 | I19: 19.8411 | J19: 14.8361 | K19: 9.8311
A20: =+A19+1 -> 9 | B20: =+B19+1 -> 45129 | C20: 21.360266 | D20: 16.358405 | E20: 11.384624 | F20: 6.5838745 | H20: 19.8563 | I20: 14.8513 | J20: 9.8463 | K20: 4.8482
A21: =+A20+1 -> 10 | B21: =+B20+1 -> 45130 | C21: 21.468464 | D21: 16.466602 | E21: 11.492737 | F21: 6.6883806 | H21: 20.959 | I21: 15.954 | J21: 10.949 | K21: 5.944
A22: =+A21+1 -> 11 | B22: =+B21+1 -> 45131 | C22: 21.557145 | D22: 16.555284 | E22: 11.58135 | F22: 6.7753186 | H22: 23.8667 | I22: 18.8617 | J22: 13.8567 | K22: 8.8517
A23: =+A22+1 -> 12 | B23: =+B22+1 -> 45132 | C23: 21.654166 | D23: 16.652305 | E23: 11.67836 | F23: 6.8683555 | H23: 25.8773 | I23: 20.8723 | J23: 15.8673 | K23: 10.8623
A24: =+A23+1 -> 13 | B24: =+B23+1 -> 45133 | C24: 21.729393 | D24: 16.727532 | E24: 11.753759 | F24: 6.946421 | H24: 25.6391 | I24: 20.6341 | J24: 15.6291 | K24: 10.6241
A25: =+A24+1 -> 14 | B25: =+B24+1 -> 45134 | C25: 21.757447 | D25: 16.755586 | E25: 11.783186 | F25: 6.9819352 | H25: 25.5462 | I25: 20.5412 | J25: 15.5362 | K25: 10.5312
A26: =+A25+1 -> 15 | B26: =+B25+1 -> 45135 | C26: 21.759576 | D26: 16.757714 | E26: 11.785759 | F26: 6.9946652 | H26: 25.3639 | I26: 20.3589 | J26: 15.3539 | K26: 10.3489
A27: =+A26+1 -> 16 | B27: =+B26+1 -> 45136 | C27: 21.723283 | D27: 16.721421 | E27: 11.750055 | F27: 6.9693767 | H27: 25.5035 | I27: 20.4985 | J27: 15.4935 | K27: 10.4885
A28: =+A27+1 -> 17 | B28: =+B27+1 -> 45137 | C28: 21.702159 | D28: 16.700298 | E28: 11.728067 | F28: 6.9459179 | H28: 26.2958 | I28: 21.2908 | J28: 16.2858 | K28: 11.2808
A29: =+A28+1 -> 18 | B29: =+B28+1 -> 45138 | C29: 21.70791 | D29: 16.705517 | E29: 11.728795 | F29: 6.9497667 | H29: 27.9494 | I29: 22.9444 | J29: 17.9394 | K29: 12.9344
A30: =+A29+1 -> 19 | B30: =+B29+1 -> 45139 | C30: 21.689073 | D30: 16.686418 | E30: 11.710498 | F30: 6.9399065 | H30: 28.6274 | I30: 23.6224 | J30: 18.6174 | K30: 13.6124
... A46: =+A45+1 -> 35 | B46: =+B45+1 -> 45155 | C46: 20.876652 | D46: 15.87214 | E46: 10.897365 | F46: 6.2001844 | H46: 26.8751 | I46: 21.8701 | J46: 16.8651 | K46: 11.8601
A47: =+A46+1 -> 36 | B47: Total | C47: =SUM(C18:C46) -> 621.08456 | D47: =SUM(D18:D46) -> 475.99951 | E47: =SUM(E18:E46) -> 331.70974 | F47: =SUM(F18:F46) -> 193.89484 | H47: =SUM(H18:H46) -> 765.0264 | I47: =SUM(I18:I46) -> 619.8814 | J47: =SUM(J18:J46) -> 474.7364 | K47: =SUM(K18:K46) -> 329.6199

Sheet Cycle 14 HDD Feb 24
B1: =+RES!B1 -> PUC DOCKET NO.
B2: =+RES!B2 -> ONCOR ELECTRIC DELIVERY COMPANY LLC
B3: =+RES!B3 -> ADJUSTED WEATHER STATION DATA
B4: =+RES!B4 -> FOR THE TEST YEAR ENDING DECEMBER 31, 2024
B6: =+RES!B6 -> SPONSOR: D. E. NELSON
B8: RESIDENTIAL FEBRUARY 2024 CYCLE 14 HEATING DEGREE DAYS
A9: Line
A10: No.
A11: 1 | B11: Billing | C11: Read | D11: Prior Month
