Workbook

Sheet V-K-1
B1: 2022 RATE CASE
B2: ONCOR ELECTRIC DELIVERY COMPANY LLC
B3: V-K-1 AFFILIATE EXPENSES BY FERC ACCOUNT
B4: FOR THE TEST YEAR ENDING DECEMBER 31, 2021
B5: SPONSORS: M. G. GRABLE & W. A. LEDBETTER
D7: FERC | E7: FERC Account
A8: Line No. | B8: Class of Items | C8: Sub-Class | D8: Account | E8: Description | F8: Total
B9: (a) | C9: (b) | D9: (c) | E9: (d) | F9: (e)
A10: 1 | B10: TAX SERVICES
A11: =+A10+1 -> 2 | C11: Consulting-Uncertain tax positions | D11: 9230000 | E11: Outside Services Employed | F11: 27000
A12: =+A11+1 -> 3 | C12: Annual Tax Return Review | D12: 9230000 | E12: Outside Services Employed | F12: 67250
A13: =+A12+1 -> 4 | C13: Annual Corptax Access | D13: 9230000 | E13: Outside Services Employed | F13: 25750
A14: =+A13+1 -> 5 | B14: Total Sempra Energy | F14: =SUM(F10:F13) -> 120000
A15: =+A14+1 -> 6 | B15: SOFTWARE & DATA SUPPORT
A16: =+A15+1 -> 7 | C16: Ultimate Kronos Group Inc | D16: 9210000 | E16: Office Supplies and Expenses | F16: 34
A17: =+A16+1 -> 8 | D17: 9230000 | E17: Outside Services Employed | F17: 2896938
A18: =+A17+1 -> 9 | B18: Total Ultimate Kronos Group Inc | F18: =SUM(F16:F17) -> 2896972
A19: =+A18+1 -> 10 | C19: Veritas Technologies LLC | D19: 9230000 | E19: Outside Services Employed | F19: =467026+226820 -> 693846
A20: =+A19+1 -> 11 | D20: 1070000 | E20: Construction Work in Progress | F20: 45700
A21: =+A20+1 -> 12 | B21: Total Veritas Technologies LLC | F21: =+F19+F20 -> 739546
A22: =+A21+1 -> 13 | B22: TARIFFED SERVICES
A23: =+A22+1 -> 14 | C23: Sharyland NTS | D23: 5650000 | E23: Trans Exp - Electricity by Others | F23: 9498427
A24: =+A23+1 -> 15 | B24: Total Sharyland Utilities, L.L.C. | F24: =+F23 -> 9498427
A25: =+A24+1 -> 16 | C25: Oncor NTU NTS | D25: 5650000 | E25: Trans Exp - Electricity by Others | F25: 80434328
A26: =+A25+1 -> 17 | C26: Oncor NTU WDSS | D26: 1824300 | E26: Reg Asset - WDSS | F26: 20879874
A27: =+A26+1 -> 18 | B27: Total Oncor Electric Delivery Co. NTU LLC | F27: =+F25+F26 -> 101314202
A28: =+A27+1 -> 19 | B28: CONTRIBUTIONS
A29: =+A28+1 -> 20 | C29: Oncor Cares Foundation | D29: 9210000 | E29: Office Supplies and Expenses | F29: 37
A30: =+A29+1 -> 21 | D30: 9302000 | E30: Misc. General Expense | F30: 26503
A31: =+A30+1 -> 22 | D31: 9302000 | E31: Misc. General Exp. (contribution) | F31: 250000
A32: =+A31+1 -> 23 | B32: Total Oncor Cares Foundation | F32: =+F29+F30+F31 -> 276540
A33: =+A32+1 -> 24
A34: =+A33+1 -> 25 | B34: Total Affiliate Expenses | F34: =+F14+F18+F21+F24+F27+F32 -> 114845687

Sheet V-K-2
B1: 2022 RATE CASE
B2: ONCOR ELECTRIC DELIVERY COMPANY LLC
B3: V-K-2 ADJUSTED AFFILIATE EXPENSES BY FERC ACCOUNT
B4: FOR THE TEST YEAR ENDING DECEMBER 31, 2021
B5: SPONSORS: M. G. GRABLE & W. A. LEDBETTER
D7: FERC | E7: FERC Account | G7: Pro-forma | H7: Adjusted
A8: Line No. | B8: Class of Items | C8: Sub-Class | D8: Account | E8: Description | F8: Total | G8: Adjustments | H8: Historic Year
B9: (a) | C9: (b) | D9: (c) | E9: (d) | F9: (e) | G9: (f) | H9: (g)
A10: 1 | B10: TAX SERVICES
A11: =+A10+1 -> 2 | C11: =+'V-K-1'!C11 -> Consulting-Uncertain tax positions | D11: =+'V-K-1'!D11 -> 9230000 | E11: =+'V-K-1'!E11 -> Outside Services Employed | F11: =+'V-K-1'!F11 -> 27000 | G11: 0 | H11: =+F11+G11 -> 27000
A12: =+A11+1 -> 3 | C12: =+'V-K-1'!C12 -> Annual Tax Return Review | D12: =+'V-K-1'!D12 -> 9230000 | E12: =+'V-K-1'!E12 -> Outside Services Employed | F12: =+'V-K-1'!F12 -> 67250 | G12: -4250 | H12: =+F12+G12 -> 63000
A13: =+A12+1 -> 4 | C13: =+'V-K-1'!C13 -> Annual Corptax Access | D13: =+'V-K-1'!D13 -> 9230000 | E13: =+'V-K-1'!E13 -> Outside Services Employed | F13: =+'V-K-1'!F13 -> 25750 | G13: 0 | H13: =+F13+G13 -> 25750
A14: =+A13+1 -> 5 | B14: Total Sempra Energy | F14: =SUM(F11:F13) -> 120000 | G14: =SUM(G11:G13) -> -4250 | H14: =SUM(H11:H13) -> 115750
A15: =+A14+1 -> 6 | B15: SOFTWARE & DATA SUPPORT
A16: =+A15+1 -> 7 | C16: =+'V-K-1'!C16 -> Ultimate Kronos Group Inc | D16: =+'V-K-1'!D16 -> 9210000 | E16: =+'V-K-1'!E16 -> Office Supplies and Expenses | F16: =+'V-K-1'!F16 -> 34 | G16: 0 | H16: =+F16+G16 -> 34
A17: =+A16+1 -> 8 | D17: =+'V-K-1'!D17 -> 9230000 | E17: =+'V-K-1'!E17 -> Outside Services Employed | F17: =+'V-K-1'!F17 -> 2896938 | G17: -382923 | H17: =+F17+G17 -> 2514015
A18: =+A17+1 -> 9 | B18: Total Ultimate Kronos Group Inc | F18: =SUM(F16:F17) -> 2896972 | G18: =SUM(G16:G17) -> -382923 | H18: =SUM(H16:H17) -> 2514049
A19: =+A18+1 -> 10 | C19: =+'V-K-1'!C19 -> Veritas Technologies LLC | D19: =+'V-K-1'!D19 -> 9230000 | E19: =+'V-K-1'!E19 -> Outside Services Employed | F19: =+'V-K-1'!F19 -> 693846 | G19: =111+22028 -> 22139 | H19: =+F19+G19 -> 715985
A20: =+A19+1 -> 11 | D20: =+'V-K-1'!D20 -> 1070000 | E20: =+'V-K-1'!E20 -> Construction Work in Progress | F20: =+'V-K-1'!F20 -> 45700 | G20: 0 | H20: =+F20+G20 -> 45700
A21: =+A20+1 -> 12 | B21: Total Veritas Technologies LLC | F21: =+F19+F20 -> 739546 | G21: =+G19 -> 22139 | H21: =+H19+H20 -> 761685
A22: =+A21+1 -> 13 | B22: TARIFFED SERVICES
A23: =+A22+1 -> 14 | C23: =+'V-K-1'!C23 -> Sharyland NTS | D23: =+'V-K-1'!D23 -> 5650000 | E23: =+'V-K-1'!E23 -> Trans Exp - Electricity by Others | F23: =+'V-K-1'!F23 -> 9498427 | G23: =+H23-F23 -> 5119968 | H23: 14618395
A24: =+A23+1 -> 15 | B24: Total Sharyland Utilities, L.L.C. | F24: =+F23 -> 9498427 | G24: =+G23 -> 5119968 | H24: =+H23 -> 14618395
A25: =+A24+1 -> 16 | C25: =+'V-K-1'!C25 -> Oncor NTU NTS | D25: =+'V-K-1'!D25 -> 5650000 | E25: =+'V-K-1'!E25 -> Trans Exp - Electricity by Others | F25: =+'V-K-1'!F25 -> 80434328 | G25: =+H25-F25 -> -18507479 | H25: 61926849
A26: =+A25+1 -> 17 | C26: =+'V-K-1'!C26 -> Oncor NTU WDSS | D26: =+'V-K-1'!D26 -> 1824300 | E26: =+'V-K-1'!E26 -> Reg Asset - WDSS | F26: =+'V-K-1'!F26 -> 20879874 | G26: =+H26-F26 -> -7584188 | H26: 13295686 | I26: (1)
A27: =+A26+1 -> 18 | B27: Total Oncor Electric Delivery Co. NTU LLC | F27: =+F25+F26 -> 101314202 | G27: =+G25+G26 -> -26091667 | H27: =+H25+H26 -> 75222535
A28: =+A27+1 -> 19 | B28: CONTRIBUTIONS
A29: =+A28+1 -> 20 | C29: =+'V-K-1'!C29 -> Oncor Cares Foundation | D29: =+'V-K-1'!D29 -> 9210000 | E29: =+'V-K-1'!E29 -> Office Supplies and Expenses | F29: =+'V-K-1'!F29 -> 37 | G29: 0 | H29: =+F29+G29 -> 37
A30: =+A29+1 -> 21 | D30: =+'V-K-1'!D30 -> 9302000 | E30: =+'V-K-1'!E30 -> Misc. General Expense | F30: =+'V-K-1'!F30 -> 26503 | G30: 0 | H30: =+F30+G30 -> 26503
A31: =+A30+1 -> 22 | D31: =+'V-K-1'!D31 -> 9302000 | E31: =+'V-K-1'!E31 -> Misc. General Exp. (contribution) | F31: =+'V-K-1'!F31 -> 250000 | G31: 0 | H31: =+F31+G31 -> 250000
A32: =+A31+1 -> 23 | B32: Total Oncor Cares Foundation | F32: =SUM(F29:F31) -> 276540 | G32: =+G31 -> 0 | H32: =SUM(H29:H31) -> 276540
A33: =+A32+1 -> 24
A34: =+A33+1 -> 25 | B34: Total Affiliate Expenses | F34: =+F14+F18+F21+F24+F27+F32 -> 114845687 | G34: =+G14+G18+G21+G24+G27+G32 -> -21336733 | H34: =+H14+H18+H21+H24+H27+H32 -> 93508954
B36: Note:
B37: (1) Wholesale Distribution Substation Service (WDSS) charges from Oncor NTU were recorded as a Regulatory Asset (FERC account 1824300); pending approval in this case, WDSS provided by Oncor NTU to Oncor will be reflected in Oncor's base rates and will be expensed in FERC account 5880000.

Sheet V-K-3
B1: 2022 RATE CASE
B2: ONCOR ELECTRIC DELIVERY COMPANY LLC
B3: V-K-3 ORGANIZATION CHART
B4: FOR THE TEST YEAR ENDING DECEMBER 31, 2021
B5: SPONSOR: M. G. GRABLE
B10: See PDF

Sheet V-K-4
A1: 2022 RATE CASE
A2: ONCOR ELECTRIC DELIVERY COMPANY LLC
A3: V-K-4 DESCRIPTION OF SERVICES
A4: FOR THE TEST YEAR ENDING DECEMBER 31, 2021
A5: SPONSOR: M. G. GRABLE
A7: Affiliate | B7: Class of Items | C7: Description of Services
A8: TAX SERVICES
A9: Sempra Energy | B9: Tax Services - Consulting-Uncertain Tax Positions | C9: Sempra provides assistance to Oncor with its quarterly updates on uncertain tax positions based on Accounting Standards Codification (ASC) 740, "Income Taxes" for calendar quarters ending each March 31, June 30, September 30, and December 31.
B10: Tax Services - Annual Tax Return Review | C10: Services include review of the annual Federal Tax Returns of Oncor and all affiliates within the Oncor ring fence.
B11: Tax Services - Annual CorpTax Access | C11: Provision of Sempra's license and access to CorpTax software for Oncor's use in preparing, printing, and data storage for the annual Federal Income Tax Returns.
A12: SOFTWARE & DATA SUPPORT
A13: Ultimate Kronos Group Inc | B13: Software and Data Support | C13: Services include ongoing payroll administration and other human resource services by Ultimate. The Ultimate system (Ultipro) includes full responsibility and accountability for payroll-related tax calculations, payment and filing, all wage garnishment disbursement services, and all benefit calculations and payments.
A14: Veritas Technologies LLC | B14: Software and Data Support | C14: Services include enterprise data protection, data storage, data back-up, and disaster recovery.
A15: TARIFFED SERVICES
A16: Sharyland Utilities, L.L.C. | B16: Tariffed Services - Network Transmission Service (NTS) | C16: Services include tariffed network transmission service rated at 60 kV and above.
A17: Oncor Electric Delivery Co. NTU LLC | B17: Tariffed Services - Network Transmission Service (NTS) | C17: Services include tariffed network transmission service rated at 60 kV and above.
B18: Tariffed Services - Wholesale Distribution Substation Service (WDSS) | C18: All transformation service supplied in connection with the delivery of electric power and energy to a Point of Interconnection, measured through one meter provided through tariffed wholesale distribution substation service.
A19: CONTRIBUTIONS
A20: Oncor Cares Foundation | B20: Contributions | C20: Oncor Cares Foundation was formed to make grants for charitable purposes and to direct resources in furtherance of such purposes.

Sheet V-K-5
B1: 2022 RATE CASE
B2: ONCOR ELECTRIC DELIVERY COMPANY LLC
B3: V-K-5 CAPITAL PROJECTS
B4: FOR THE TEST YEAR ENDING DECEMBER 31, 2021
B5: SPONSORS: M. G. GRABLE & W. A. LEDBETTER
D7: Total | E7: Closed to
A8: Line No. | B8: Project ID | C8: Project Description | D8: Capitalized | E8: Plant-in-Service
B9: (a) | C9: (b) | D9: (c) | E9: (d)
A10: 1 | B10: IGCS2100 | C10: TMS Replacement - Phase II (Veritas) | D10: 45700 | E10: February 2022
A11: =+A10+1 -> 2
A12: =+A11+1 -> 3 | C12: Total | D12: =+D10+D11 -> 45700
B16: NOTE:
B17: Except for the portion of the TMS replacement performed by Veritas Technologies LLC, Oncor Electric Delivery Company LLC's (Oncor) affiliates did not perform any specific capital projects on behalf of Oncor during the test year ended December 31, 2021. Schedules V-K-1 and V-K-2 of this rate filing package provide all charges, by FERC account, from affiliates to Oncor.

Sheet V-K-6
B1: 2022 RATE CASE
B2: ONCOR ELECTRIC DELIVERY COMPANY LLC
B3: V-K-6 ADJUSTMENTS TO TEST YEAR EXPENSES
B4: FOR THE TEST YEAR ENDING DECEMBER 31, 2021
B5: SPONSORS: M. G. GRABLE & W. A. LEDBETTER
D7: Total
A8: Line No. | B8: Description | C8: Purpose | D8: Adjustment
B9: (a) | C9: (b) | D9: (c)
A10: 1 | B10: Sempra Energy
A11: =A10+1 -> 2 | B11: Credit for over-accrual in 2021 | C11: Eliminate the impact of the 2021 over-accrual for tax | D11: =+'V-K-2'!G14 -> -4250
A12: =A11+1 -> 3 | C12: services
A13: =A12+1 -> 4
A14: =A13+1 -> 5 | B14: Ultimate Kronos Group Inc
A15: =A14+1 -> 6 | B15: Remove 2022 expenses paid in 2021 | C15: Remove Jan-Feb 2022 services paid in 2021 | D15: =+'V-K-2'!G17 -> -382923
A16: =A15+1 -> 7
A17: =A16+1 -> 8 | B17: Veritas Technologies LLC
A18: =A17+1 -> 9 | B18: Software maintenance annual increase | C18: Add of annual software maintenance price increase | D18: =+'V-K-2'!G19 -> 22139
A19: =A18+1 -> 10
A20: =A19+1 -> 11 | B20: Sharyland Utilities, L.L.C.
A21: =A20+1 -> 12 | B21: Tariff rate change and four coincident peak | C21: Restate 2021 with full year impact of NTS tariff rate | D21: =+'V-K-2'!G23 -> 5119968
A22: =A21+1 -> 13 | B22: ("4CP") load change | C22: change and 4CP load change
A23: =A22+1 -> 14
A24: =A23+1 -> 15 | B24: Oncor Electric Delivery Co. NTU LLC
A25: =A24+1 -> 16 | B25: Tariff rate change and 4CP load change | C25: Restate 2021 with full year impact of NTS tariff rate | D25: =+'V-K-2'!G25 -> -18507479
A26: =A25+1 -> 17 | C26: change and 4CP load change
A27: =A26+1 -> 18 | B27: Tariff rate change | C27: Restate 2021 with full year impact of WDSS tariff rate | D27: =+'V-K-2'!G26 -> -7584188
A28: =A27+1 -> 19 | C28: change
A29: =A28+1 -> 20 | D29: =SUM(D10:D27) -> -21336733

Sheet V-K-7
B1: 2022 RATE CASE
B2: ONCOR ELECTRIC DELIVERY COMPANY LLC
B3: V-K-7 STATUTORY REQUIREMENTS
B4: FOR THE TEST YEAR ENDING DECEMBER 31, 2021
B5: SPONSOR: M. G. GRABLE
B10: See Word File

Sheet V-K-8
B1: 2022 RATE CASE
B2: ONCOR ELECTRIC DELIVERY COMPANY LLC
B3: V-K-8 SERVICES PROVIDED TO AFFILIATES
B4: FOR THE TEST YEAR ENDING DECEMBER 31, 2021
B5: SPONSORS: M. G. GRABLE & W. A. LEDBETTER
B7: FERC | D7: Affiliate Company | F7: Amount
A8: Line No. | B8: Account | C8: FERC Account Description | D8: Receiving Service | E8: Description of Service | F8: Per Book
B9: (a) | C9: (b) | D9: (c) | E9: (d) | F9: (e)
A10: 1 | C10: Operations and Metering Services
A11: =A10+1 -> 2 | B11: 4569000 | C11: Other Revenue-Other | D11: Sharyland Utilities | E11: Operations services (monitoring, controlling, etc.) | F11: 229346
A12: =A11+1 -> 3 | B12: 4569000 | C12: Other Revenue-Other | D12: Sharyland Utilities | E12: DC Tie operations | F12: 202037
A13: =A12+1 -> 4 | B13: 4569000 | C13: Other Revenue-Other | D13: Sharyland Utilities | E13: ERCOT-Polled Settlement (EPS) metering services | F13: 9895
A14: =A13+1 -> 5 | B14: 4569000 | C14: Other Revenue-Other | D14: Sharyland Utilities | E14: Wholesale metering service | F14: 119
A15: =A14+1 -> 6 | B15: 4569000 | C15: Other Revenue-Other | D15: Sharyland Utilities | E15: Corporate Support Service loading rate | F15: 116529
A16: =A15+1 -> 7 | B16: 4569000 | C16: Other Revenue-Other | D16: Sharyland Utilities | E16: Carrying costs | F16: 5189
A17: =A16+1 -> 8 | B17: 4549000 | C17: Rent-Elec Prop-Other | D17: Sharyland Utilities | E17: Total Cost of Ownership (TCO) | F17: 49531
A18: =A17+1 -> 9 | B18: 2539000 | C18: Other Deferred Credit | D18: Sharyland Utilities | E18: Gross Margin Tax | F18: 3216
A19: =A18+1 -> 10 | B19: 2412700 | C19: State-Other-Accrual | D19: Sharyland Utilities | E19: Sales tax | F19: 10972
A20: =A19+1 -> 11 | D20: Total Sharyland Utilities | F20: =SUM(F11:F19) -> 626834
A21: =A20+1 -> 12 | C21: Transmission System Operation, Maintenance and Metering Support and O & M Services
A22: =A21+1 -> 13 | B22: 4569000 | C22: Other Revenue-Other | D22: Oncor NTU | E22: Operations services (monitoring, controlling, etc.) | F22: =1441691+101990 -> 1543681 | G22: (1)
A23: =A22+1 -> 14 | B23: 4569000 | C23: Other Revenue-Other | D23: Oncor NTU | E23: Wholesale metering service | F23: 1347
A24: =A23+1 -> 15 | B24: 4569000 | C24: Other Revenue-Other | D24: Oncor NTU | E24: Corporate Support Service loading rate | F24: 380962
A25: =A24+1 -> 16 | B25: 4549000 | C25: Rent-Elect Prop-Other | D25: Oncor NTU | E25: Total Cost of Ownership (TCO) | F25: 407363
A26: =A25+1 -> 17 | B26: 4569000 | C26: Other Revenue-Other | D26: Oncor NTU | E26: Sales tax | F26: 45449
A27: =A26+1 -> 18 | B27: 4569000 | C27: Other Revenue-Other | D27: Oncor NTU | E27: Direct-billed O&M svcs (veg. mgmt., circuit maint. etc.) | F27: 7312175
A28: =A27+1 -> 19 | C28: Interest on Debt
A29: =A28+1 -> 20 | B29: 4190200 | C29: Interest Inc-Assoc Cos | D29: Oncor NTU | E29: Interest on long-term note payable | F29: 39891860
A30: =A29+1 -> 21 | C30: Capital Projects
A31: =A30+1 -> 22 | B31: 1010### | C31: Plant in Service (Various) | D31: Oncor NTU | E31: Capital projects (see Oncor RFP Schedule V-K-8.1) | F31: =+'V-K-8.1'!D20 -> 646528
A32: =A31+1 -> 23 | D32: Total Oncor NTU | F32: =SUM(F22:F31) -> 50229365
A33: =A32+1 -> 24 | C33: To, From & Over (TFO)
A34: =A33+1 -> 25 | B34: 4569000 | C34: Other Revenue-Other | D34: Sempra Gas & Power Mktg | E34: Whls trans svc provided under the TFO Tariff | F34: 13297
A35: =A34+1 -> 26 | C35: Transmission Service
A36: =A35+1 -> 27 | B36: 4569000 | C36: Other Revenue-Other | D36: Sempra Gas & Power Mktg | E36: Export svcs billed under the NTU Tariff for Trans Svc | F36: 2810
A37: =A36+1 -> 28 | D37: Total Sempra Gas & Power Marketing | F37: =+F34+F36 -> 16107
A38: =A37+1 -> 29 | C38: Miscellaneous Services
A39: =A38+1 -> 30 | B39: 1070000 | C39: Capital Work in Process | D39: YES! Communities LLC | E39: Convert overhead poles to underground | F39: =34926+2246 -> 37172
A40: =A39+1 -> 31 | B40: 2412460 | C40: Gross Receipts - CIAC | D40: YES! Communities LLC | E40: Convert overhead poles to underground | F40: =1397+90 -> 1487
A41: =A40+1 -> 32 | D41: Total YES! Communities LLC | F41: =+F39+F40 -> 38659
...

Sheet V-K-8.1
B1: 2022 RATE CASE
B2: ONCOR ELECTRIC DELIVERY COMPANY LLC
B3: V-K-8.1 ONCOR NTU CAPITAL PROJECTS
B4: FOR THE TEST YEAR ENDING DECEMBER 31, 2021
B5: SPONSORS: M. G. GRABLE & W. A. LEDBETTER
D7: Total | E7: Closed to
A8: Line No. | B8: Project ID | C8: Project Title | D8: Capitalized | E8: Plant-in-Service
B9: (a) | C9: (b) | D9: (c) | E9: (d)
A10: 1 | B10: OPT44827 | C10: Alibates Station Replacement | D10: 9064 | E10: 44321
A11: =+A10+A10 -> 2 | B11: OPT45599 | C11: Vealmoore Switch | D11: 172592 | E11: 44378
A12: =+A11+1 -> 3 | B12: OPT45619 | C12: Bulldog - Coyote 138 kV | D12: 130494 | E12: 44453
A13: =+A12+1 -> 4 | B13: OPT46104 | C13: Windmill Station | D13: 15489 | E13: 44461
A14: =+A13+1 -> 5 | B14: OPT46121 | C14: Driver 138 - 25 kV | D14: 93439 | E14: 44470
A15: =+A14+1 -> 6 | B15: OPT45710 | C15: Salt Mine 138 - 25 kV | D15: 31103 | E15: 44484
A16: =+A15+1 -> 7 | B16: OPT43682 | C16: Salt Mine 138 - 25 kV | D16: 30985 | E16: 44508
A17: =+A16+1 -> 8 | B17: OPT46376 | C17: Ringo 138 - 25 kV | D17: 46563 | E17: 44543
A18: =+A17+1 -> 9 | B18: OPT46630 | C18: Salt Mine 138 - 25 kV | D18: 116799 | E18: 44544
A19: =+A18+1 -> 10
A20: =+A19+1 -> 11 | C20: Total | D20: =SUM(D10:D19) -> 646528

Sheet V-K-9
B1: 2022 RATE CASE
B2: ONCOR ELECTRIC DELIVERY COMPANY LLC
B3: V-K-9 ALLOCATION OF AFFILIATE COSTS
B4: FOR THE TEST YEAR ENDING DECEMBER 31, 2021
B5: SPONSORS: M. G. GRABLE & W. A. LEDBETTER
B10: See Word File

Sheet V-K-10
B1: 2022 RATE CASE
B2: ONCOR ELECTRIC DELIVERY COMPANY LLC
B3: V-K-10 CONTROLS
B4: FOR THE TEST YEAR ENDING DECEMBER 31, 2021
B5: SPONSORS: M. G. GRABLE & W. A. LEDBETTER
B10: See Word File

Sheet V-K-11
A1: 2022 RATE CASE
A2: ONCOR ELECTRIC DELIVERY COMPANY LLC
A3: V-K-11 DESCRIPTION OF AFFILIATE BILLING METHODS
A4: FOR THE TEST YEAR ENDING DECEMBER 31, 2021
A5: SPONSOR: M. G. GRABLE
C7: Billing Metric
C8: Update | D8: Billing Methodology
A9: Class of Items | B9: Billing Methodology | C9: Frequency | D9: Update Frequency
A10: Tax Services - Consulting-Uncertain Tax Positions - Sempra | B10: Assignment of costs based on an evaluation of the time and effort spent by Sempra Tax personnel on behalf of Oncor. Time and effort spent is a reasonable approach for assigning costs to Oncor. | C10: Annually | D10: Annually
A11: Tax Services - Annual Tax Return Review - Sempra | B11: Assignment of costs based on an evaluation of the time and effort spent by Sempra Tax personnel on behalf of Oncor. Time and effort spent is a reasonable approach for assigning costs to Oncor. | C11: Annually | D11: Annually
A12: Tax Services - Annual CorpTax Access - Sempra | B12: Assignment of costs based on the number of entities, users, and archival services specific to Oncor. This methodology is a reasonable approach for assigning costs to Oncor. | C12: Annually | D12: Annually
A13: Human Resources Software Support - Ultimate Kronos Group Inc. | B13: Direct billing based on costs and fees contained in the negotiated contract and additional Statements of Work. | C13: Annually | D13: Annually
A14: Data Storage and Back-up - Veritas Technologies LLC | B14: Direct billing based on costs and fees contained in the negotiated contract, contract addenda, and additional Statements of Work. | C14: Annually | D14: Annually
A15: NTS Tariff - Sharyland Utilities | B15: Monthly charges are based on an access charge multiplied by the customer's preceding calendar year average 4CP load. The access charge is, as approved, in the most recent revision of the Wholesale Transmission Service Tariff for Sharyland Utilities. | C15: Semi-annually | D15: Semi-annually
A16: NTS Tariff - Oncor NTU | B16: Monthly charges are based on an access charge multiplied by the customer's preceding calendar year average 4CP load. The access charge is, as approved, in the most recent revision of the Wholesale Transmission Service Tariff for Oncor NTU. | C16: Semi-annually | D16: Semi-annually
A17: WDSS Tariff - Oncor NTU | B17: The monthly bill for WDSS is the sum of the Transmission Service Customer Charge, Metering Charge, Demand Charge, and any applicable riders - all rates set in Oncor NTU's Wholesale Transmission Service Tariff. The billing kW used for determining the Demand Charge for a month is Oncor's highest measured 15-minute kW recorded at the Point of Interconnection in the 12-month period ended with the current month. | C17: Base Rate Case | D17: Base Rate Case
A18: Oncor Cares Foundation | B18: Oncor's Senior Leadership Team determines the level of contributions to be made to the Foundation for charitable purposes. The amounts contributed are discretionary and, therefore, independent of any other party making contributions to the Foundation. | C18: Annually | D18: Annually

Sheet V-K-12
B1: 2022 RATE CASE
B2: ONCOR ELECTRIC DELIVERY COMPANY LLC
B3: V-K-12 AMOUNTS BILLED TO EACH AFFILIATE
B4: FOR THE TEST YEAR ENDING DECEMBER 31, 2021
B5: SPONSORS: M. G. GRABLE & W. A. LEDBETTER
F7: Oncor
D8: Oncor | E8: Oncor | F8: Transmission/
D9: Distribution | E9: Transmission | F9: Distribution | G9: Total
A10: Line No. | B10: Class of Items | C10: Sub-Class | D10: (ESD) | E10: (TRN) | F10: (TRNDS) | G10: Oncor
B11: TAX SERVICES | C11: Consulting - Uncertain Tax Position | D11: =+'V-K-1'!F11 -> 27000 | G11: =SUM(D11:F11) -> 27000
A12: 1 | C12: Annual Tax Return Review | D12: =+'V-K-1'!F12 -> 67250 | G12: =SUM(D12:F12) -> 67250
A13: =A12+1 -> 2 | C13: Corptax Access | D13: =+'V-K-1'!F13 -> 25750 | G13: =SUM(D13:F13) -> 25750
A14: =A13+1 -> 3 | C14: Total Tax Services | D14: =+D11+D12+D13 -> 120000 | G14: =+G11+G12+G13 -> 120000
A15: =A14+1 -> 4
A16: =A15+1 -> 5 | B16: SOFTWARE & DATA SUPPORT | C16: Ultimate Kronos Group | D16: =+'V-K-1'!F18 -> 2896972 | G16: =SUM(D16:F16) -> 2896972
A17: =A16+1 -> 6 | C17: Total Ultimate Software Group Inc | D17: =+D16 -> 2896972 | G17: =+G16 -> 2896972
A18: =A17+1 -> 7
A19: =A18+1 -> 8 | B19: SOFTWARE & DATA SUPPORT | C19: Veritas Technologies LLC | D19: =+'V-K-1'!F21-E19 -> 685233 | E19: =45700+8613 -> 54313 | G19: =+D19+E19+F19 -> 739546
A20: =A19+1 -> 9 | C20: Total Veritas Technologies LLC | D20: =+D19 -> 685233 | E20: =+E19 -> 54313 | G20: =+G19 -> 739546
A21: =A20+1 -> 10
A22: =A21+1 -> 11
A23: =A22+1 -> 12 | B23: TARIFFED SERVICES | C23: Sharyland NTS | D23: =+'V-K-1'!F23 -> 9498427 | G23: =SUM(D23:F23) -> 9498427
A24: =A23+1 -> 13 | C24: Total Sharyland Utilities, L.L.C. | D24: =+D23 -> 9498427 | G24: =+G23 -> 9498427
A25: =A24+1 -> 14
A26: =A25+1 -> 15 | B26: TARIFFED SERVICES | C26: NTU NTS | D26: =+'V-K-1'!F25 -> 80434328 | G26: =SUM(D26:F26) -> 80434328
A27: =A26+1 -> 16 | C27: NTU WDSS | D27: =+'V-K-1'!F26 -> 20879874 | G27: =SUM(D27:F27) -> 20879874
A28: =A27+1 -> 17 | C28: Total Oncor NTU LLC | D28: =+D26+D27 -> 101314202 | G28: =+G26+G27 -> 101314202
A29: =A28+1 -> 18
A30: =A29+1 -> 19 | B30: CONTRIBUTIONS | C30: Oncor Cares Foundation | D30: =+'V-K-1'!F32 -> 276540 | G30: =SUM(D30:F30) -> 276540
A31: =A30+1 -> 20 | C31: Total Oncor Cares Foundation | D31: =+D30 -> 276540 | G31: =+G30 -> 276540
A32: =A31+1 -> 21
A33: =A32+1 -> 22 | B33: TOTAL | D33: =+D14+D17+D20+D24+D28+D31 -> 114791374 | E33: =+E14+E17+E20+E24+E28+E31 -> 54313 | F33: =+F14+F17+F20+F24+F28+F31 -> 0 | G33: =+G14+G17+G20+G24+G28+G31 -> 114845687

Sheet V-K-13
A1: 2022 RATE CASE
A2: ONCOR ELECTRIC DELIVERY COMPANY LLC
A3: V-K-13 AFFILIATE PROJECT CODES CREATED/CLOSED
A4: FOR THE TEST YEAR ENDING DECEMBER 31, 2021
A5: SPONSORS: M. G. GRABLE & W. A. LEDBETTER
B7: Created/ | D7: Affiliate
A8: Project Title | B8: Closed | C8: Date | D8: Used For
A9: (a) | B9: (c) | C9: (d) | D9: (f)
A10: Tax Services - Consulting-Uncertain Tax Positions | B10: Created | C10: 43769 | D10: Sempra
A11: Tax Services - Annual Tax Return Review | B11: Created | C11: 43769 | D11: Sempra
A12: Tax Services - Annual CorpTax Access | B12: Created | C12: 43769 | D12: Sempra
A13: Software and Data Support | B13: Created | C13: 43591 | D13: Ultimate Kronos Group Inc
A14: Software and Data Support | B14: Created | C14: 42282 | D14: Veritas Technologies LLC
A15: Tariffed Services | B15: Created | C15: 43602 | D15: Sharyland Utilities
A16: Tariffed Services | B16: Created | C16: 43602 | D16: Oncor NTU
A17: Contributions | B17: Created | C17: 43983 | D17: Oncor Cares Foundation

Sheet V-K-14
B1: 2022 RATE CASE
B2: ONCOR ELECTRIC DELIVERY COMPANY LLC
B3: V-K-14 AFFILIATE PAYROLL
B4: FOR THE TEST YEAR ENDING DECEMBER 31, 2021
B5: SPONSORS: M. G. GRABLE & W. A. LEDBETTER
B7: Class of | D7: FERC | E7: FERC Account
A8: Line No. | B8: Items | C8: Sub-Class | D8: Account | E8: Description | F8: Amount
A10: 1 | B10: Tax Services | C10: Consulting-Uncertain tax positions
A11: =+A10+1 -> 2 | C11: Annual Tax Return Review
A12: =+A11+1 -> 3 | C12: Annual Corptax Access | D12: 9200000 | E12: Administrative & Gen Salaries | F12: 90000
A13: =+A12+1 -> 4
A14: =+A13+1 -> 5 | B14: Total Affiliate Payroll Expenses | F14: =+F12 -> 90000
B19: Note: Software & Data Support and Tariffed Services are billed to Oncor in compliance with arm’s-length negotiated contracts or Commission approved tariffs, respectively. The amounts billed to Oncor through these contracts and tariffs are based on a compilation of all expenses required to provide these services. The individual component costs for these services, including payroll, are not separately identifiable to Oncor. There are no payroll costs in those amounts contributed to Oncor Cares Foundation.
