Workbook
Name \B: [1]BILLING!#REF!
Name \D: #REF!
Name \E: [1]BILLING!#REF!
Name \J: #REF!
Name \K: [1]BILLING!#REF!
Name \M: [1]BILLING!#REF!
Name \P: [1]BILLING!#REF!
Name \S: [1]BILLING!#REF!
Name \T: [1]BILLING!#REF!
Name \U: [1]BILLING!#REF!
Name \Z: [1]BILLING!#REF!
Name akdsfja: '[2]PGA Calc'!#REF!
Name Diesel_BGS: #REF!
Name DLOV_oracle_apps_financials_generalLedger_journals_desktopEntry_di_FinGlDesktopMultibatchEntryPageDef_PeriodName_LedgerId_0: [3]_ADFDI_LOV!$C$30:$DC$30
Name DLOV_oracle_apps_financials_generalLedger_journals_desktopEntry_di_FinGlDesktopMultibatchEntryPageDef_ReversalPeriodName_LedgerId_0: [3]_ADFDI_LOV!$C$32:$DC$32
Name fasdjfklasd: [4]Prior!#REF!
Name gcdmsales: #REF!
Name gigo: #REF!
Name ID_sorted: #REF!
Name IQ_CH: 110000
Name IQ_CQ: 5000
Name IQ_CY: 10000
Name IQ_DAILY: 500000
Name IQ_FH: 100000
Name IQ_FQ: 500
Name IQ_FY: 1000
Name IQ_LTM: 2000
Name IQ_MONTH: 15000
Name IQ_NTM: 6000
Name IQ_WEEK: 50000
Name IQ_YTD: 3000
Name m: [4]Prior!#REF!
Name Mo_Day_Yr: '[6]Gas Trans'!$W$2
Name Month_table: [7]Misc!#REF!
Name Month_Yr: [8]InputEst!$C$4
Name Natural_Gas_BGS: #REF!
Name NvsAnswerCol: "[Drill1]JRNLLAYOUT!$A$4:$A$54"
Name NvsASD: "V2012-12-31"
Name NvsAutoDrillOk: "VN"
Name NvsDateToNumber: "Y"
Name NvsElapsedTime: 0.0000347222230629995
Name NvsEndTime: 41353.6898148148
Name NvsInstLang: "VENG"
Name NvsInstSpec: "%,LACTUALS,UPOSTED_TOTAL_AMT,SYTD,FACCOUNT,V001154,FDEPTID,V0231"
Name NvsInstSpec1: ","
Name NvsInstSpec2: ","
Name NvsInstSpec3: ","
Name NvsInstSpec4: ","
Name NvsInstSpec5: ","
Name NvsInstSpec6: ","
Name NvsInstSpec7: ","
Name NvsInstSpec8: ","
Name NvsInstSpec9: ","
Name NvsLayoutType: "M3"
Name NvsParentRef: "[F_WASUM0231.xls]Sheet1!$J$22"
Name NvsReqBU: "V10100"
Name NvsReqBUOnly: "VY"
Name NvsTransLed: "VN"
Name NvsTreeASD: "V2012-12-31"
Name o: '[2]PGA Calc'!#REF!

Sheet Cover Sheet
B1: Madison Gas and Electric Company
B2: MGE-Response-Data Request-PSC-Meulemans-1
B4: Docket Number: | D4: 3270-FR-2021
B5: Date of Request: | D5: May 3, 2022 (PSC REF#: 437399)
B6: Requestor: | D6: Tyler Meulemans
B7: Date of Response: | D7: 44691
B8: Respondents: | D8: Carl Weinert and John Krueger
B11: Public Service Commission (Commission) staff is reviewing the March 31, 2022 application of Madison Gas and Electric Company (applicant) and needs additional information to process the application. Provide responses to TCM-1.1 and TCM-1.2 and its sub-questions within five days of the date of this request. Provide responses to TCM-1.3 and TCM-1.4 by May 18, 2022. If an extension is needed to provide adequate responses, please contact me immediately.
B13: The applicant's responses should include the original numbers and items below and be followed by the responses. Please upload the responses and any supporting documentation directly to the Commission's Electronic Records Filing (ERF) system under the docket number 3270-FR-2021 and using the document type Data Request/Response. When uploading the document, the ERF description must be "Response-Data Request-PSC-Meulemans-1." Commission staff will continue review of the application once responses are received.
B15: TCM-1.1 | C15: Using the fuel numbers as filed in the application, demonstrate what a class-based surcharge allocation, with per kWh surcharge values, would look like if the deferred account balance were recovered in:
C16: a. | D16: September 2022;
C17: b. | D17: October 2022;
C18: c. | D18: September 2022 through December 2022; and
C19: d. | D19: The calendar year of 2023.
B21: Response
C23: See Tab TCM-1.1 Surcharge Allocation.
B25: TCM-1.2 | C25: Provide any workbooks, with formulas intact, used to respond to TCM-1.1.
B27: Response
C29: See Tabs TCM-1.2 2022 Sales by Class, TCM-1.2 2021 Sales by Class, and TCM-1.2 Interest Calc.
B31: TCM-1.3 | C31: Using the final fuel audit numbers, demonstrate what a class-based surcharge allocation, with per kWh surcharge values, would look like if the deferred account balance were recovered in:
C32: a. | D32: September 2022;
C33: b. | D33: October 2022;
C34: c. | D34: September 2022 through December 2022; and
C35: d. | D35: The calendar year of 2023.
B37: Response
C39: MGE will respond to this request by May 18, 2022, unless an extension is requested by MGE and granted by Commission staff.
B41: TCM-1.4 | C41: Provide any workbooks, with formulas intact, used to respond to TCM-1.3.
B43: Response
C45: MGE will respond to this request by May 18, 2022, unless an extension is requested by MGE and granted by Commission staff.

Sheet TCM-1.1 Surcharge Allocation
B1: Docket 3270-FR-2021
B2: Madison Gas and Electric Company
B3: Electric Fuel Reconciliation Summary
G4: Sep 2022 | H4: Oct 2022 | I4: Sep-Dec 2022 | J4: 2023
B5: Rate Class | C5: 2021 Sales - kWh | D5: 2021 Renewable Sales | E5: 2021 Net of Renewable Sales | F5: Allocation % | G5: Surcharge Allocation | H5: Surcharge Allocation | I5: Surcharge Allocation | J5: Surcharge Allocation
B6: Residential | C6: ='TCM-1.2 2021 Sales by Class'!E7 -> 897584653 | D6: ='TCM-1.2 2021 Sales by Class'!D7 -> 63598526 | E6: =C6-D6 -> 833986127 | F6: =E6/$E$12 -> 0.27405526 | G6: =$F6*G$16 -> 908824.31 | H6: =$F6*H$16 -> 909581.66 | I6: =$F6*I$16 -> 908824.31 | J6: =$F6*J$16 -> 911098.26
B7: Small Commercial | C7: ='TCM-1.2 2021 Sales by Class'!E8 -> 210721722 | D7: ='TCM-1.2 2021 Sales by Class'!D8 -> 2764289 | E7: =C7-D7 -> 207957433 | F7: =E7/$E$12 -> 0.068336662 | G7: =$F7*G$16 -> 226618.6 | H7: =$F7*H$16 -> 226807.45 | I7: =$F7*I$16 -> 226618.6 | J7: =$F7*J$16 -> 227185.62
B8: Medium and Large Commercial & Industrial | C8: ='TCM-1.2 2021 Sales by Class'!E9 -> 1613950317 | D8: ='TCM-1.2 2021 Sales by Class'!D9 -> 45359518 | E8: =C8-D8 -> 1568590799 | F8: =E8/$E$12 -> 0.51545289 | G8: =$F8*G$16 -> 1709349.1 | H8: =$F8*H$16 -> 1710773.6 | I8: =$F8*I$16 -> 1709349.1 | J8: =$F8*J$16 -> 1713626.1
B9: Contract | C9: ='TCM-1.2 2021 Sales by Class'!E10 -> 431670123 | D9: ='TCM-1.2 2021 Sales by Class'!D10 -> 10424813 | E9: =C9-D9 -> 421245310 | F9: =E9/$E$12 -> 0.13842496 | G9: =$F9*G$16 -> 459045.98 | H9: =$F9*H$16 -> 459428.52 | I9: =$F9*I$16 -> 459045.98 | J9: =$F9*J$16 -> 460194.55
B10: Miscellaneous | C10: ='TCM-1.2 2021 Sales by Class'!E11 -> 3805741 | D10: ='TCM-1.2 2021 Sales by Class'!D11 -> 0 | E10: =C10-D10 -> 3805741 | F10: =E10/$E$12 -> 0.0012506003 | G10: =$F10*G$16 -> 4147.2512 | H10: =$F10*H$16 -> 4150.7072 | I10: =$F10*I$16 -> 4147.2512 | J10: =$F10*J$16 -> 4157.6279
B11: Streetlighting | C11: ='TCM-1.2 2021 Sales by Class'!E12 -> 7546140 | D11: ='TCM-1.2 2021 Sales by Class'!D12 -> 285 | E11: =C11-D11 -> 7545855 | F11: =E11/$E$12 -> 0.0024796351 | G11: =$F11*G$16 -> 8222.9863 | H11: =$F11*H$16 -> 8229.8387 | I11: =$F11*I$16 -> 8222.9863 | J11: =$F11*J$16 -> 8243.5609
C12: =SUM(C6:C11) -> 3165278696 | D12: =SUM(D6:D11) -> 122147431 | E12: =SUM(E6:E11) -> 3043131265 | F12: =SUM(F6:F11) -> 1 | G12: =SUM(G6:G11) -> 3316208.2 | H12: =SUM(H6:H11) -> 3318971.8 | I12: =SUM(I6:I11) -> 3316208.2 | J12: =SUM(J6:J11) -> 3324505.7
B14: Undercollection Amount | G14: 3291440 | H14: 3291440 | I14: 3291440 | J14: 3291440
B15: Interest Charge | G15: ='TCM-1.2 Interest Calc'!D20 -> 24768.246 | H15: ='TCM-1.2 Interest Calc'!D21 -> 27531.753 | I15: ='TCM-1.2 Interest Calc'!D20 -> 24768.246 | J15: ='TCM-1.2 Interest Calc'!D23 -> 33065.678
B16: Undercollection Amount with Interest | G16: =G14+G15 -> 3316208.2 | H16: =H14+H15 -> 3318971.8 | I16: =I14+I15 -> 3316208.2 | J16: =J14+J15 -> 3324505.7
A18: a | C18: Sep 2022 | D18: Sep 2022 | E18: Sep 2022 | F18: Credit Rate
B19: Rate Class | C19: Forecasted kWh | D19: Forecasted Renewables | E19: Net Sales for Refund | F19: per kWh
B20: Residential | C20: ='TCM-1.2 2022 Sales by Class'!L16 -> 72780150 | D20: ='TCM-1.2 2022 Sales by Class'!L25+'TCM-1.2 2022 Sales by Class'!L34+'TCM-1.2 2022 Sales by Class'!L43 -> 5784774.7 | E20: =C20-D20 -> 66995376 | F20: =ROUND(G6/E20,5) -> 0.01357
B21: Small Commercial | C21: ='TCM-1.2 2022 Sales by Class'!L17 -> 17250275 | D21: ='TCM-1.2 2022 Sales by Class'!L26+'TCM-1.2 2022 Sales by Class'!L35+'TCM-1.2 2022 Sales by Class'!L44 -> 229824.07 | E21: =C21-D21 -> 17020451 | F21: =ROUND(G7/E21,5) -> 0.01331
B22: Medium and Large Commercial & Industrial | C22: ='TCM-1.2 2022 Sales by Class'!L18 -> 1.5211571e+08 | D22: ='TCM-1.2 2022 Sales by Class'!L27+'TCM-1.2 2022 Sales by Class'!L36+'TCM-1.2 2022 Sales by Class'!L45 -> 6985510.6 | E22: =C22-D22 -> 1.451302e+08 | F22: =ROUND(G8/E22,5) -> 0.01178
B23: Contract | C23: ='TCM-1.2 2022 Sales by Class'!L19 -> 40917524 | D23: ='TCM-1.2 2022 Sales by Class'!L28+'TCM-1.2 2022 Sales by Class'!L37+'TCM-1.2 2022 Sales by Class'!L46 -> 1887297.7 | E23: =C23-D23 -> 39030226 | F23: =ROUND(G9/E23,5) -> 0.01176
B24: Miscellaneous | C24: ='TCM-1.2 2022 Sales by Class'!L20 -> 336061.65 | D24: ='TCM-1.2 2022 Sales by Class'!L29+'TCM-1.2 2022 Sales by Class'!L38+'TCM-1.2 2022 Sales by Class'!L47 -> 17044 | E24: =C24-D24 -> 319017.65 | F24: =ROUND(G10/E24,5) -> 0.013
B25: Streetlighting | C25: ='TCM-1.2 2022 Sales by Class'!L21 -> 733891.4 | D25: ='TCM-1.2 2022 Sales by Class'!L30+'TCM-1.2 2022 Sales by Class'!L39+'TCM-1.2 2022 Sales by Class'!L48 -> 0 | E25: =C25-D25 -> 733891.4 | F25: =ROUND(G11/E25,5) -> 0.0112
C26: =SUM(C20:C25) -> 2.8413362e+08 | D26: =SUM(D20:D25) -> 14904451 | E26: =SUM(E20:E25) -> 2.6922916e+08
A28: b | C28: Oct 2022 | D28: Oct 2022 | E28: Oct 2022 | F28: Credit Rate
B29: Rate Class | C29: Forecasted kWh | D29: Forecasted Renewables | E29: Net Sales for Refund | F29: per kWh
B30: Residential | C30: ='TCM-1.2 2022 Sales by Class'!M16 -> 58595786 | D30: ='TCM-1.2 2022 Sales by Class'!M25+'TCM-1.2 2022 Sales by Class'!M34+'TCM-1.2 2022 Sales by Class'!M43 -> 4476144.8 | E30: =C30-D30 -> 54119641 | F30: =ROUND(H6/E30,5) -> 0.01681
B31: Small Commercial | C31: ='TCM-1.2 2022 Sales by Class'!M17 -> 14462183 | D31: ='TCM-1.2 2022 Sales by Class'!M26+'TCM-1.2 2022 Sales by Class'!M35+'TCM-1.2 2022 Sales by Class'!M44 -> 196052.24 | E31: =C31-D31 -> 14266131 | F31: =ROUND(H7/E31,5) -> 0.0159
B32: Medium and Large Commercial & Industrial | C32: ='TCM-1.2 2022 Sales by Class'!M18 -> 1.3363437e+08 | D32: ='TCM-1.2 2022 Sales by Class'!M27+'TCM-1.2 2022 Sales by Class'!M36+'TCM-1.2 2022 Sales by Class'!M45 -> 5200396.7 | E32: =C32-D32 -> 1.2843398e+08 | F32: =ROUND(H8/E32,5) -> 0.01332
B33: Contract | C33: ='TCM-1.2 2022 Sales by Class'!M19 -> 36899204 | D33: ='TCM-1.2 2022 Sales by Class'!M28+'TCM-1.2 2022 Sales by Class'!M37+'TCM-1.2 2022 Sales by Class'!M46 -> 1339210.6 | E33: =C33-D33 -> 35559993 | F33: =ROUND(H9/E33,5) -> 0.01292
B34: Miscellaneous | C34: ='TCM-1.2 2022 Sales by Class'!M20 -> 369984.11 | D34: ='TCM-1.2 2022 Sales by Class'!M29+'TCM-1.2 2022 Sales by Class'!M38+'TCM-1.2 2022 Sales by Class'!M47 -> 17044 | E34: =C34-D34 -> 352940.11 | F34: =ROUND(H10/E34,5) -> 0.01176
B35: Streetlighting | C35: ='TCM-1.2 2022 Sales by Class'!M21 -> 733891.4 | D35: ='TCM-1.2 2022 Sales by Class'!M30+'TCM-1.2 2022 Sales by Class'!M39+'TCM-1.2 2022 Sales by Class'!M48 -> 0 | E35: =C35-D35 -> 733891.4 | F35: =ROUND(H11/E35,5) -> 0.01121
C36: =SUM(C30:C35) -> 2.4469542e+08 | D36: =SUM(D30:D35) -> 11228848 | E36: =SUM(E30:E35) -> 2.3346657e+08
A38: c | C38: Sep-Dec 2022 | D38: Sep-Dec 2022 | E38: Sep-Dec 2022 | F38: Credit Rate
B39: Rate Class | C39: Forecasted kWh | D39: Forecasted Renewables | E39: Net Sales for Refund | F39: per kWh
B40: Residential | C40: =SUM('TCM-1.2 2022 Sales by Class'!L16:O16) -> 2.6407587e+08 | D40: =SUM('TCM-1.2 2022 Sales by Class'!L25:O25,'TCM-1.2 2022 Sales by Class'!L34:O34,'TCM-1.2 2022 Sales by Class'!L43:O43) -> 19717786 | E40: =C40-D40 -> 2.4435809e+08 | F40: =ROUND(I6/E40,5) -> 0.00372
B41: Small Commercial | C41: =SUM('TCM-1.2 2022 Sales by Class'!L17:O17) -> 65542764 | D41: =SUM('TCM-1.2 2022 Sales by Class'!L26:O26,'TCM-1.2 2022 Sales by Class'!L35:O35,'TCM-1.2 2022 Sales by Class'!L44:O44) -> 823387.99 | E41: =C41-D41 -> 64719376 | F41: =ROUND(I7/E41,5) -> 0.0035
B42: Medium and Large Commercial & Industrial | C42: =SUM('TCM-1.2 2022 Sales by Class'!L18:O18) -> 5.4471325e+08 | D42: =SUM('TCM-1.2 2022 Sales by Class'!L27:O27,'TCM-1.2 2022 Sales by Class'!L36:O36,'TCM-1.2 2022 Sales by Class'!L45:O45) -> 20561040 | E42: =C42-D42 -> 5.2415221e+08 | F42: =ROUND(I8/E42,5) -> 0.00326
B43: Contract | C43: =SUM('TCM-1.2 2022 Sales by Class'!L19:O19) -> 1.4204261e+08 | D43: =SUM('TCM-1.2 2022 Sales by Class'!L28:O28,'TCM-1.2 2022 Sales by Class'!L37:O37,'TCM-1.2 2022 Sales by Class'!L46:O46) -> 5181558.6 | E43: =C43-D43 -> 1.3686105e+08 | F43: =ROUND(I9/E43,5) -> 0.00335
B44: Miscellaneous | C44: =SUM('TCM-1.2 2022 Sales by Class'!L20:O20) -> 1451606.8 | D44: =SUM('TCM-1.2 2022 Sales by Class'!L29:O29,'TCM-1.2 2022 Sales by Class'!L38:O38,'TCM-1.2 2022 Sales by Class'!L47:O47) -> 68176 | E44: =C44-D44 -> 1383430.8 | F44: =ROUND(I10/E44,5) -> 0.003
...

Sheet TCM-1.2 2022 Sales by Class
A1: 2022 Electric Sales Forecast
A2: Per PSC REF #s 434074 and 434075
D4: Total Sales KWH Net of Renewables
D5: January | E5: February | F5: March | G5: April | H5: May | I5: June | J5: July | K5: August | L5: September | M5: October | N5: November | O5: December | P5: UR-124 2022 TY2022 Forecast Total
A6: Residential | D6: =D16-D25-D34-D43 -> 73616041 | E6: =E16-E25-E34-E43 -> 63032509 | F6: =F16-F25-F34-F43 -> 62469047 | G6: =G16-G25-G34-G43 -> 52962717 | H6: =H16-H25-H34-H43 -> 53964441 | I6: =I16-I25-I34-I43 -> 65934890 | J6: =J16-J25-J34-J43 -> 84776530 | K6: =K16-K25-K34-K43 -> 82549519 | ... P6: =P16-P25-P34-P43 -> 7.8366378e+08
A7: Small Commercial | D7: =D17-D26-D35-D44 -> 19502021 | E7: =E17-E26-E35-E44 -> 17391416 | F7: =F17-F26-F35-F44 -> 17806553 | G7: =G17-G26-G35-G44 -> 15533490 | H7: =H17-H26-H35-H44 -> 15851361 | I7: =I17-I26-I35-I44 -> 16988304 | J7: =J17-J26-J35-J44 -> 18836963 | K7: =K17-K26-K35-K44 -> 17809499 | ... P7: =P17-P26-P35-P44 -> 2.0443898e+08
A8: Medium and Large C&I | D8: =D18-D27-D36-D45 -> 1.3344421e+08 | E8: =E18-E27-E36-E45 -> 1.1812767e+08 | F8: =F18-F27-F36-F45 -> 1.2574193e+08 | G8: =G18-G27-G36-G45 -> 1.1643214e+08 | H8: =H18-H27-H36-H45 -> 1.2510024e+08 | I8: =I18-I27-I36-I45 -> 1.4106542e+08 | J8: =J18-J27-J36-J45 -> 1.540314e+08 | K8: =K18-K27-K36-K45 -> 1.4665525e+08 | ... P8: =P18-P27-P36-P45 -> 1.5847505e+09
A9: Contract | D9: =D19-D28-D37-D46 -> 32149428 | E9: =E19-E28-E37-E46 -> 30534190 | F9: =F19-F28-F37-F46 -> 31335581 | G9: =G19-G28-G37-G46 -> 30575117 | H9: =H19-H28-H37-H46 -> 32896893 | I9: =I19-I28-I37-I46 -> 34185875 | J9: =J19-J28-J37-J46 -> 34185497 | K9: =K19-K28-K37-K46 -> 38865484 | ... P9: =P19-P28-P37-P46 -> 4.0158912e+08
A10: Miscellaneous | D10: =D20-D29-D38-D47 -> 348219.89 | E10: =E20-E29-E38-E47 -> 318062.35 | F10: =F20-F29-F38-F47 -> 300661.53 | G10: =G20-G29-G38-G47 -> 296319.06 | H10: =H20-H29-H38-H47 -> 300635.25 | I10: =I20-I29-I38-I47 -> 317587.69 | J10: =J20-J29-J38-J47 -> 305536.43 | K10: =K20-K29-K38-K47 -> 280561.62 | ... P10: =P20-P29-P38-P47 -> 3851014.6
A11: Streetlighting | D11: =D21-D30-D39-D48 -> 733891.4 | E11: =E21-E30-E39-E48 -> 733891.4 | F11: =F21-F30-F39-F48 -> 733891.4 | G11: =G21-G30-G39-G48 -> 733891.4 | H11: =H21-H30-H39-H48 -> 733891.4 | I11: =I21-I30-I39-I48 -> 733891.4 | J11: =J21-J30-J39-J48 -> 733891.4 | K11: =K21-K30-K39-K48 -> 733891.4 | ... P11: =P21-P30-P39-P48 -> 8806696.8
A12: Total | D12: =SUM(D6:D11) -> 2.5979381e+08 | E12: =SUM(E6:E11) -> 2.3013774e+08 | F12: =SUM(F6:F11) -> 2.3838766e+08 | G12: =SUM(G6:G11) -> 2.1653367e+08 | H12: =SUM(H6:H11) -> 2.2884746e+08 | I12: =SUM(I6:I11) -> 2.5922597e+08 | J12: =SUM(J6:J11) -> 2.9286982e+08 | K12: =SUM(K6:K11) -> 2.868942e+08 | ... P12: =SUM(P6:P11) -> 2.9871001e+09
D14: Total Sales KWH with Renewables
D15: January | E15: February | F15: March | G15: April | H15: May | I15: June | J15: July | K15: August | L15: September | M15: October | N15: November | O15: December | P15: UR-124 2022 TY2022 Forecast Total
A16: Residential | D16: 78565953 | E16: 67759395 | F16: 67031226 | G16: 57862185 | H16: 58617808 | I16: 71477216 | J16: 92045427 | K16: 89576066 | L16: 72780150 | M16: 58595786 | N16: 60900788 | O16: 71799150 | P16: 8.4701115e+08
A17: Small Commercial | D17: 19755890 | E17: 17644634 | F17: 18054621 | G17: 15759174 | H17: 16055255 | I17: 17194501 | J17: 19091682 | K17: 18055766 | L17: 17250275 | M17: 14462183 | N17: 15886366 | O17: 17943941 | P17: 2.0715429e+08
A18: Medium and Large C&I | D18: 1.3759881e+08 | E18: 1.235151e+08 | F18: 1.3216316e+08 | G18: 1.2305881e+08 | H18: 1.3257932e+08 | I18: 1.492885e+08 | J18: 1.6238118e+08 | K18: 1.5423399e+08 | L18: 1.5211571e+08 | M18: 1.3363437e+08 | N18: 1.2802173e+08 | O18: 1.3094143e+08 | P18: 1.6595321e+09
A19: Contract | D19: 33065728 | E19: 31890615 | F19: 33057445 | G19: 32402505 | H19: 35024575 | I19: 36487655 | J19: 36474073 | K19: 40899177 | L19: 40917524 | M19: 36899204 | N19: 32864633 | O19: 31361251 | P19: 4.2134438e+08
A20: Miscellaneous | D20: 365263.89 | E20: 335106.35 | F20: 317705.53 | G20: 313363.06 | H20: 317679.25 | I20: 334631.69 | J20: 322580.43 | K20: 297605.62 | L20: 336061.65 | M20: 369984.11 | N20: 377433.37 | O20: 368127.67 | P20: 4055542.6
A21: Streetlighting | D21: 733891.4 | E21: 733891.4 | F21: 733891.4 | G21: 733891.4 | H21: 733891.4 | I21: 733891.4 | J21: 733891.4 | K21: 733891.4 | L21: 733891.4 | M21: 733891.4 | N21: 733891.4 | O21: 733891.4 | P21: 8806696.8
A22: Total | D22: =SUM(D16:D21) -> 2.7008554e+08 | E22: =SUM(E16:E21) -> 2.4187874e+08 | F22: =SUM(F16:F21) -> 2.5135805e+08 | G22: =SUM(G16:G21) -> 2.3012993e+08 | H22: =SUM(H16:H21) -> 2.4332853e+08 | I22: =SUM(I16:I21) -> 2.7551639e+08 | J22: =SUM(J16:J21) -> 3.1104883e+08 | K22: =SUM(K16:K21) -> 3.037965e+08 | ... P22: =SUM(P16:P21) -> 3.1479042e+09
D24: GPT
A25: Residential | D25: 4821439.3 | E25: 4520001 | F25: 4103544.7 | G25: 4375110.8 | H25: 4012137.4 | I25: 4841957 | J25: 6550480.9 | K25: 6408085.7 | L25: 5261571.7 | M25: 4148255 | N25: 4168513.5 | O25: 4914691.6 | P25: 58125789
A26: Small Commercial | D26: 243246.69 | E26: 236113.15 | F26: 210149.82 | G26: 182332.25 | H26: 150878.57 | I26: 167510.42 | J26: 215036.16 | K26: 214022.11 | L26: 191584.34 | M26: 163966.77 | N26: 169227.98 | O26: 198044.52 | P26: 2342112.8
A27: Medium and Large C&I | D27: 1416613.4 | E27: 1349785 | F27: 1246866.3 | G27: 1105921.4 | H27: 1012661.1 | I27: 1238249.6 | J27: 1398296.5 | K27: 1451631.1 | L27: 1254114.2 | M27: 1142564.5 | N27: 1114743.9 | O27: 1373093.3 | P27: 15104540
A28: Contract
A29: Miscellaneous | D29: 17044 | E29: 17044 | F29: 17044 | G29: 17044 | H29: 17044 | I29: 17044 | J29: 17044 | K29: 17044 | L29: 17044 | M29: 17044 | N29: 17044 | O29: 17044 | P29: 204528
A30: Streetlighting
A31: Total | D31: =SUM(D25:D30) -> 6498343.4 | E31: =SUM(E25:E30) -> 6122943.2 | F31: =SUM(F25:F30) -> 5577604.8 | G31: =SUM(G25:G30) -> 5680408.4 | H31: =SUM(H25:H30) -> 5192721.1 | I31: =SUM(I25:I30) -> 6264761.1 | J31: =SUM(J25:J30) -> 8180857.6 | K31: =SUM(K25:K30) -> 8090782.9 | ... P31: =SUM(P25:P30) -> 75776970
D33: CS1
A34: Residential | D34: 128472.77 | E34: 206884.36 | F34: 458633.65 | G34: 524356.99 | H34: 641229.65 | I34: 700369.71 | J34: 718416.57 | K34: 618461.09 | L34: 523203.02 | M34: 327889.8 | N34: 213123.42 | O34: 160537.64 | P34: 5221578.7
A35: Small Commercial | D35: 10621.776 | E35: 17104.632 | F35: 37918.572 | G35: 43352.397 | H35: 53015.108 | I35: 38685.986 | J35: 39682.831 | K35: 32245.791 | L35: 38239.724 | M35: 32085.469 | N35: 18280.177 | O35: 11959.006 | P35: 373191.47
A36: Medium and Large C&I | D36: 37696.474 | E36: 60704.001 | F36: 134572.26 | G36: 153856.8 | H36: 188149.57 | I36: 180127.27 | J36: 184768.72 | K36: 115456.41 | L36: 152474.75 | M36: 99076.15 | N36: 58842.211 | O36: 49252.289 | P36: 1414976.9
A37: Contract
A38: Miscellaneous
A39: Streetlighting
A40: Total | D40: =SUM(D34:D39) -> 176791.02 | E40: =SUM(E34:E39) -> 284693 | F40: =SUM(F34:F39) -> 631124.48 | G40: =SUM(G34:G39) -> 721566.19 | H40: =SUM(H34:H39) -> 882394.33 | I40: =SUM(I34:I39) -> 919182.97 | J40: =SUM(J34:J39) -> 942868.12 | K40: =SUM(K34:K39) -> 766163.3 | ... P40: =SUM(P34:P39) -> 7009747.1
D42: RER
A43: Residential
A44: Small Commercial
A45: Medium and Large C&I | D45: 2700292.3 | E45: 3976933 | F45: 5039794.1 | G45: 5366894.4 | H45: 6278271.2 | I45: 6804700.6 | J45: 6766708.8 | K45: 6011658.8 | L45: 5578921.7 | M45: 3958756 | N45: 3332223.3 | O45: 2446977.6 | P45: 58262132
...

Sheet TCM-1.2 2021 Sales by Class
A1: 2021 Electric Sales Estimate
A2: Per PSC REF #s 434074 and 434075
C5: KWH | D5: KWH | E5: KWH
A6: Rate Class | C6: Net Renewable | D6: Renewable | E6: Total Sales
A7: Residential | C7: 833986127 | D7: 63598526 | E7: =C7+D7 -> 897584653
A8: Small Commercial | C8: 207957433 | D8: 2764289 | E8: =C8+D8 -> 210721722
A9: Medium and Large C&I | C9: 1568590799 | D9: 45359518 | E9: =C9+D9 -> 1613950317
A10: Contract | C10: 421245310 | D10: 10424813 | E10: =C10+D10 -> 431670123
A11: Miscellaneous (1) | C11: 3805741 | E11: 3805741
A12: Streetlighting (1) | C12: 7545855 | D12: 285 | E12: 7546140
A13: Total | C13: =SUM(C7:C12) -> 3043131265 | D13: =SUM(D7:D9) -> 111722333 | E13: =SUM(E7:E12) -> 3165278696
A16: (1) Part of Streetlighting was included in Miscellaneous in the original response and is now reclassified to accurately account for these two classes.
A17: Note: Actual 2021 sales are a work in progress due to year-end closing; therefore, the sales above are estimated based on billed data. Unbilled sales are not included.

Sheet TCM-1.2 Interest Calc
A1: Madison Gas and Electric Company
A2: Estimated Interest Earned on Fuel Rules Surcharge
A5: ESTIMATE
B6: 2022
A7: Fuel Surcharge | B7: 3291440
A8: WC STI | B8: 0.01 | C8: 3270-UR-124 REF # 410794
A9: ST Int/Month | B9: =B8/12 -> 0.00083333333
B11: Interest Calc | C11: YTD | D11: YTD Interest
A12: Jan | B12: =B7*B9 -> 2742.8667 | C12: =B12+B7 -> 3294182.9 | D12: =B12 -> 2742.8667
A13: Feb | B13: =C12*$B$9 -> 2745.1524 | C13: =C12+B13 -> 3296928 | D13: =D12+B13 -> 5488.0191
A14: Mar | B14: =C13*$B$9 -> 2747.44 | C14: =C13+B14 -> 3299675.5 | D14: =D13+B14 -> 8235.4591
A15: Apr | B15: =C14*$B$9 -> 2749.7295 | C15: =C14+B15 -> 3302425.2 | D15: =D14+B15 -> 10985.189
A16: May | B16: =C15*$B$9 -> 2752.021 | C16: =C15+B16 -> 3305177.2 | D16: =D15+B16 -> 13737.21
A17: Jun | B17: =C16*$B$9 -> 2754.3143 | C17: =C16+B17 -> 3307931.5 | D17: =D16+B17 -> 16491.524
A18: Jul | B18: =C17*$B$9 -> 2756.6096 | C18: =C17+B18 -> 3310688.1 | D18: =D17+B18 -> 19248.134
A19: Aug | B19: =C18*$B$9 -> 2758.9068 | C19: =C18+B19 -> 3313447 | D19: =D18+B19 -> 22007.04
A20: Sep | B20: =C19*$B$9 -> 2761.2059 | C20: =C19+B20 -> 3316208.2 | D20: =D19+B20 -> 24768.246
A21: Oct | B21: =C20*$B$9 -> 2763.5069 | C21: =C20+B21 -> 3318971.8 | D21: =D20+B21 -> 27531.753
A22: Nov | B22: =C21*$B$9 -> 2765.8098 | C22: =C21+B22 -> 3321737.6 | D22: =D21+B22 -> 30297.563
A23: Dec | B23: =C22*$B$9 -> 2768.1146 | C23: =C22+B23 -> 3324505.7 | D23: =D22+B23 -> 33065.678
C24: Check | D24: =C20-B7-D20 -> -3.7107384e-10
