Workbook
Name _31_Dec_00: #REF!
Name _31_Jan_01: #REF!
Name _A77777: #REF!
Name _JE1: #REF!
Name _JE2: #REF!
Name _JE3: #REF!
Name _JE4: #REF!
Name _JE5: #REF!
Name _JE6: #REF!
Name _JE7: #REF!
Name _JE8: #REF!
Name _JE9: #REF!
Name \A: #REF!
Name \B: [1]BILLING!#REF!
Name \B: [1]BILLING!#REF!
Name \B: [1]BILLING!#REF!
Name \B: [1]BILLING!#REF!
Name \B: [1]BILLING!#REF!
Name \C: #REF!
Name \D: #REF!
Name \D: #REF!
Name \D: #REF!
Name \D: #REF!
Name \D: #REF!
Name \E: [1]BILLING!#REF!
Name \E: [1]BILLING!#REF!
Name \E: [1]BILLING!#REF!
Name \E: [1]BILLING!#REF!
Name \E: [1]BILLING!#REF!
Name \J: #REF!
Name \J: #REF!
Name \J: #REF!
Name \J: #REF!
Name \J: #REF!
Name \K: [1]BILLING!#REF!
Name \K: [1]BILLING!#REF!
Name \K: [1]BILLING!#REF!
Name \K: [1]BILLING!#REF!
Name \K: [1]BILLING!#REF!
Name \L: '[2]ST Debt_Int'!#REF!
Name \M: [1]BILLING!#REF!
Name \M: [1]BILLING!#REF!
Name \M: [1]BILLING!#REF!
Name \M: [1]BILLING!#REF!
Name \M: [1]BILLING!#REF!
Name \P: [1]BILLING!#REF!
Name \S: [1]BILLING!#REF!
Name \T: [1]BILLING!#REF!
Name \U: [1]BILLING!#REF!
Name \Z: [1]BILLING!#REF!
Name aBlackAECostRecov_IPL: '[4]Risk Drivers-Input'!#REF!
Name aBlackAECostRecov_WPL: '[4]Risk Drivers-Input'!#REF!
Name aBlackAELegalRecov_IPL: '[4]Risk Drivers-Input'!#REF!
Name aBlackAELegalRecov_WPL: '[4]Risk Drivers-Input'!#REF!
Name aBlackOthCostRecov_IPL: '[4]Risk Drivers-Input'!#REF!
Name aBlackOthCostRecov_WPL: '[4]Risk Drivers-Input'!#REF!
Name aBlackOthLegalRecov_IPL: '[4]Risk Drivers-Input'!#REF!
Name aBlackOthLegalRecov_WPL: '[4]Risk Drivers-Input'!#REF!
Name aBoilerLossRecov_6th: '[4]Risk Drivers-Input'!#REF!
Name aBoilerLossRecov_PC: '[4]Risk Drivers-Input'!#REF!

Sheet Cover Sheet
A2: Madison Gas and Electric Company
A4: MGE-Response-Data Request-PSC-Garcia-1
A6: Docket Number: | C6: 3270-FR-2023
A7: Date of Request: | C7: May 1, 2024 (PSC REF # 500025)
A8: Requestor: | C8: Michael Garcia
A9: Date of Response: | C9: May 8, 2024
A10: Respondent: | C10: Riley Denu
A13: PSCW-MMG-1.1 | B13: For all responses to this data request, provide the monthly sales volumes the applicant proposes to use for the development of the credit rate. In the response, be sure to indicate if the sales are based on a Commission authorized sales forecast, or if the sales will be subject to change based on the Commission's final decision in any pending dockets.
A15: Response
A17: See Tab MMG-1.1b for the requested monthly electric sales volumes. All sales volumes used in this response are net of renewables. The monthly electric sales volumes for 2024 are based on the Commission authorized sales forecast that is included in MGE's response to data request PSC-Corbeil-1.36 (PSC REF # 494665). Also see Tab MMG-1.1a for the actual electric sales volumes by rate class for the 2023 Fuel Plan Year for use in the development of a class-based allocation as requested in MMG-1.3 and MMG-1.5. Additionally, a Bill Factor Codes tab is included. MGE respectfully requests that the information on that tab be included as an appendix in the Final Decision of this proceeding. The authorized rates on that tab are currently populated with the rates resulting from an October through December flat-rate credit.
A20: PSCW-MMG-1.2 | B20: Would the applicant be able to implement any bill credit as a result of this proceeding in September 2024. If not, provide justification why this is not possible.
A22: Response
A24: MGE will be unable to implement any bill credit as a result of this proceeding in September 2024. MGE's billing system is currently configured for only two types of fuel cost adjustment, a multiple month adjustment ("annual") and an October-only adjustment. Each adjustment is capable of supporting only a single value for any given month. The annual adjustment is currently set to a surcharge of $0.00291/kWh through September 30, 2024, as ordered in Docket 3270-UR-125. Additionally, MGE would like to respectfully inform you that an October-only bill credit, while feasible, would create inconsistencies. MGE's annual adjustment uses proration for bills that include both days where the adjustment is in effect and days where it is not. Proration is used even when AMI meters are present. In contrast, MGE's October-only adjustment uses the exact monthly data from AMI meters when they are present and proration otherwise. If an October-only adjustment is approved, it will create an inconsistency on October 2024 bills for customers with AMI meters. On these bills, the September kWh for the current bill surcharge will be calculated via proration while the October kWh for the proposed bill credit would be calculated using exact AMI data. The two parts being calculated with different methodologies could create results that are inconsistent with the customer's total usage on that bill.
A27: PSCW-MMG-1.3 | B27: Using the fuel numbers as filed in the application, demonstrate what a flat-rate and class-based credit allocation, with per kilowatt-hour (kWh) credit values, would look like if the deferred account balance were refunded in: a. September 2024; b. October 2024; c. September 2024 through December 2024; and d. October 2024 through December 2024.
A29: Response
A31: See Tabs MMG-1.3a, MMG-1.3b, MMG-1.3c, and MMG-1.3d for the requested allocations and per kilowatt-hour (kWh) values.
A34: PSCW-MMG-1.4: | B34: Provide any workbooks, with formulas intact, used to respond to PSCW-MMG-1.3.
A36: Response
A38: See Tabs MMG-1.3a, MMG-1.3b, MMG-1.3c, and MMG-1.3d.
A41: PSCW-MMG-1.5 | B41: Using the final fuel audit numbers, demonstrate what a flat-rate and class-based credit allocation, with per kWh credit values, would look like if the deferred account balance were refunded in: a. September 2024; b. October 2024; c. September 2024 through December 2024; and d. October 2024 through December 2024.
A43: Response
A45: As of the date of this response, PSCW staff has not notified MGE of any audit adjustments. If any audit adjustments that affect the credit amount are provided, MGE will respond to this request.
A48: PSCW-MMG-1.6 | B48: Provide any workbooks, with formulas intact, used to respond to PSCW-MMG-1.5.
A50: Response
A52: If MGE responds to MMG-1.5 as described above, the response will include any supporting workbooks with formulas intact.
A55: PSCW-MMG-1.7 | B55: Provide the bill impacts from the calculated fuel credit amounts for the average residential customer using 500 kWh monthly, and the average general service customer using 1,100 kWh, for the following time periods: a. September 2024; b. October 2024; c. September 2024 through December 2024; and d. October 2024 through December 2024.
A57: Response
A59: See Tabs MMG-1.3a, MMG-1.3b, MMG-1.3c, and MMG-1.3d for the requested bill impacts.

Sheet MMG-1.1a
A1: Madison Gas and Electric Company
A2: 2023 Fuel Reconciliation Audit (3270-FR-2023)
A3: MMG-1.1a - Actual kWh by Rate Class for 2023 Fuel Plan Year
A6: 2023 Calendar Electric Sales
C8: KWH | D8: KWH | E8: KWH | G8: Allocators
A9: Rate Class | C9: Net Renewable | D9: Renewable | E9: Total Sales | G9: Net Renewable
A10: Residential | C10: =E10-D10 -> 8.0295904e+08 | D10: 68598504 | E10: 8.7155755e+08 | G10: =C10/C$16 -> 0.26869974
A11: Small Commercial | C11: =E11-D11 -> 2.076735e+08 | D11: 3111218 | E11: 2.1078472e+08 | G11: =C11/C$16 -> 0.069495221
A12: Medium and Large C&I | C12: =E12-D12 -> 1.5377977e+09 | D12: 78863661 | E12: 1616661406 | G12: =C12/C$16 -> 0.5146039
A13: Contract | C13: =E13-D13 -> 4.2751697e+08 | D13: 20172300 | E13: 447689269 | G13: =C13/C$16 -> 0.14306296
A14: Miscellaneous | C14: =E14-D14 -> 3943390.7 | D14: 0 | E14: 3943390.7 | G14: =C14/C$16 -> 0.0013196041
A15: Streetlighting | C15: =E15-D15 -> 8422780 | D15: 1140 | E15: 8423920 | G15: =C15/C$16 -> 0.0028185732
A16: Total | C16: =SUM(C10:C15) -> 2.9883134e+09 | D16: =SUM(D10:D15) -> 1.7074682e+08 | E16: =SUM(E10:E15) -> 3159060253 | G16: =SUM(G10:G15) -> 1

Sheet MMG-1.1b
A1: Madison Gas and Electric Company
A2: 2023 Fuel Reconciliation Audit (3270-FR-2023)
A3: MMG-1.1b - Authorized Monthly kWh by Rate Class for 2024
A6: 2024 Electric Sales Forecast per 3270-UR-125
D8: Total Sales KWH Net of Renewables
D9: January | E9: February | F9: March | G9: April | H9: May | I9: June | J9: July | K9: August | L9: September | M9: October | N9: November | O9: December | P9: UR-125 2024 Total
A10: Residential | D10: =D20-D29-D38-D47 -> 77736606 | E10: =E20-E29-E38-E47 -> 64871019 | F10: =F20-F29-F38-F47 -> 62171469 | G10: =G20-G29-G38-G47 -> 52408843 | H10: =H20-H29-H38-H47 -> 57190438 | I10: =I20-I29-I38-I47 -> 72993427 | J10: =J20-J29-J38-J47 -> 87393998 | K10: =K20-K29-K38-K47 -> 86573424 | ... P10: =P20-P29-P38-P47 -> 8.1064029e+08
A11: Small Commercial | D11: =D21-D30-D39-D48 -> 21630960 | E11: =E21-E30-E39-E48 -> 19051867 | F11: =F21-F30-F39-F48 -> 19024187 | G11: =G21-G30-G39-G48 -> 16318639 | H11: =H21-H30-H39-H48 -> 17814910 | I11: =I21-I30-I39-I48 -> 19351395 | J11: =J21-J30-J39-J48 -> 19997271 | K11: =K21-K30-K39-K48 -> 19642526 | ... P11: =P21-P30-P39-P48 -> 2.2193577e+08
A12: Medium and Large C&I | D12: =D22-D31-D40-D49 -> 1.3117601e+08 | E12: =E22-E31-E40-E49 -> 1.2125815e+08 | F12: =F22-F31-F40-F49 -> 1.2011071e+08 | G12: =G22-G31-G40-G49 -> 1.1291914e+08 | H12: =H22-H31-H40-H49 -> 1.2749232e+08 | I12: =I22-I31-I40-I49 -> 1.4480833e+08 | J12: =J22-J31-J40-J49 -> 1.5462178e+08 | K12: =K22-K31-K40-K49 -> 1.5056479e+08 | ... P12: =P22-P31-P40-P49 -> 1.5648039e+09
A13: Contract | D13: =D23-D32-D41-D50 -> 32062217 | E13: =E23-E32-E41-E50 -> 29856616 | F13: =F23-F32-F41-F50 -> 33005059 | G13: =G23-G32-G41-G50 -> 34171251 | H13: =H23-H32-H41-H50 -> 36377706 | I13: =I23-I32-I41-I50 -> 36759875 | J13: =J23-J32-J41-J50 -> 38973501 | K13: =K23-K32-K41-K50 -> 40017839 | ... P13: =P23-P32-P41-P50 -> 4.2277129e+08
A14: Miscellaneous | D14: =D24-D33-D42-D51 -> 338109.09 | E14: =E24-E33-E42-E51 -> 295082.99 | F14: =F24-F33-F42-F51 -> 301785.74 | G14: =G24-G33-G42-G51 -> 314163.61 | H14: =H24-H33-H42-H51 -> 316442.58 | I14: =I24-I33-I42-I51 -> 304880.6 | J14: =J24-J33-J42-J51 -> 296962.22 | K14: =K24-K33-K42-K51 -> 267594.1 | ... P14: =P24-P33-P42-P51 -> 3852309.4
A15: Streetlighting | D15: =D25-D34-D43-D52 -> 758951 | E15: =E25-E34-E43-E52 -> 556120 | F15: =F25-F34-F43-F52 -> 817843 | G15: =G25-G34-G43-G52 -> 713452 | H15: =H25-H34-H43-H52 -> 727704 | I15: =I25-I34-I43-I52 -> 719790 | J15: =J25-J34-J43-J52 -> 719670 | K15: =K25-K34-K43-K52 -> 719520 | ... P15: =P25-P34-P43-P52 -> 8598210
A16: Total | D16: =SUM(D10:D15) -> 2.6370285e+08 | E16: =SUM(E10:E15) -> 2.3588885e+08 | F16: =SUM(F10:F15) -> 2.3543105e+08 | G16: =SUM(G10:G15) -> 2.1684549e+08 | H16: =SUM(H10:H15) -> 2.3991952e+08 | I16: =SUM(I10:I15) -> 2.7493769e+08 | J16: =SUM(J10:J15) -> 3.0200318e+08 | K16: =SUM(K10:K15) -> 2.9778569e+08 | ... P16: =SUM(P10:P15) -> 3.0326018e+09
D18: Total Sales KWH with Renewables
D19: January | E19: February | F19: March | G19: April | H19: May | I19: June | J19: July | K19: August | L19: September | M19: October | N19: November | O19: December | P19: UR-125 2024 Total
A20: Residential | D20: 82392558 | E20: 69267509 | F20: 66265838 | G20: 56420620 | H20: 61052546 | I20: 77452287 | J20: 92964469 | K20: 91904919 | L20: 72546406 | M20: 59906926 | N20: 61027037 | O20: 72418020 | P20: 8.6361914e+08
A21: Small Commercial | D21: 21848274 | E21: 19260239 | F21: 19217361 | G21: 16527418 | H21: 18002469 | I21: 19551831 | J21: 20240458 | K21: 19859780 | L21: 17135620 | M21: 16414173 | N21: 17114177 | O21: 19181030 | P21: 2.2435283e+08
A22: Medium and Large C&I | D22: 1.3479331e+08 | E22: 1.2590812e+08 | F22: 1.2563139e+08 | G22: 1.1861116e+08 | H22: 1.3456864e+08 | I22: 1.535204e+08 | J22: 1.6347322e+08 | K22: 1.5833583e+08 | L22: 1.3606332e+08 | M22: 1.3041891e+08 | N22: 1.2250235e+08 | O22: 1.3203285e+08 | P22: 1.6358595e+09
A23: Contract | D23: 33035314 | E23: 31143137 | F23: 34517122 | G23: 35763505 | H23: 38278431 | I23: 39294903 | J23: 41610452 | K23: 42171945 | L23: 41010801 | M23: 38349689 | N23: 33079821 | O23: 33688446 | P23: 4.4194357e+08
A24: Miscellaneous | D24: 338109.09 | E24: 295082.99 | F24: 301785.74 | G24: 314163.61 | H24: 316442.58 | I24: 304880.6 | J24: 296962.22 | K24: 267594.1 | L24: 350416.35 | M24: 356463.43 | N24: 364312.45 | O24: 346096.2 | P24: 3852309.4
A25: Streetlighting | D25: 758951 | E25: 556120 | F25: 817843 | G25: 713452 | H25: 727704 | I25: 719790 | J25: 719670 | K25: 719520 | L25: 711169 | M25: 673055 | N25: 734546 | O25: 746390 | P25: 8598210
A26: Total | D26: =SUM(D20:D25) -> 2.7316651e+08 | E26: =SUM(E20:E25) -> 2.4643021e+08 | F26: =SUM(F20:F25) -> 2.4675134e+08 | G26: =SUM(G20:G25) -> 2.2835032e+08 | H26: =SUM(H20:H25) -> 2.5294623e+08 | I26: =SUM(I20:I25) -> 2.9084409e+08 | J26: =SUM(J20:J25) -> 3.1930523e+08 | K26: =SUM(K20:K25) -> 3.1325959e+08 | ... P26: =SUM(P20:P25) -> 3.1782255e+09
D28: GPT
A29: Residential | D29: 4557202.3 | E29: 4222767.4 | F29: 3794397.6 | G29: 3636563.4 | H29: 3450913.2 | I29: 3943694.1 | J29: 4995426.7 | K29: 4765405.9 | L29: 4488316.3 | M29: 3393358.5 | N29: 3323246.3 | O29: 4095618.9 | P29: 48666911
A30: Small Commercial | D30: 208831.37 | E30: 194361.49 | F30: 172630.31 | G30: 184643.96 | H30: 160884.69 | I30: 169096.95 | J30: 205812.67 | K30: 188065.99 | L30: 186784.9 | M30: 147524.28 | N30: 155016.24 | O30: 181878.12 | P30: 2155531
A31: Medium and Large C&I | D31: 1053242.1 | E31: 1168577.6 | F31: 964055.27 | G31: 956857.77 | H31: 1143889.6 | I31: 1239805.3 | J31: 1421749.3 | K31: 1455552.3 | L31: 1599608 | M31: 1360139 | N31: 1290944 | O31: 1365177.6 | P31: 15019598
A32: Contract
A33: Miscellaneous
A34: Streetlighting
A35: Total | D35: =SUM(D29:D34) -> 5819275.7 | E35: =SUM(E29:E34) -> 5585706.5 | F35: =SUM(F29:F34) -> 4931083.1 | G35: =SUM(G29:G34) -> 4778065.1 | H35: =SUM(H29:H34) -> 4755687.5 | I35: =SUM(I29:I34) -> 5352596.4 | J35: =SUM(J29:J34) -> 6622988.7 | K35: =SUM(K29:K34) -> 6409024.2 | ... P35: =SUM(P29:P34) -> 65842039
D37: CS1
A38: Residential | D38: 98749.77 | E38: 173723.02 | F38: 299971.6 | G38: 375214.5 | H38: 411194.69 | I38: 515166.22 | J38: 575044.33 | K38: 566089.33 | L38: 502919.77 | M38: 403368.03 | N38: 272624.03 | O38: 117870.68 | P38: 4311936
A39: Small Commercial | D39: 8482.375 | E39: 14010.595 | F39: 20543.765 | G39: 24135.715 | H39: 26673.96 | I39: 31338.52 | J39: 37374.19 | K39: 29188.325 | L39: 26966.49 | M39: 20917.885 | N39: 15756.82 | O39: 6137.16 | P39: 261525.8
A40: Medium and Large C&I | D40: 32942.46 | E40: 62298.94 | F40: 87340.105 | G40: 122058.64 | H40: 134446.39 | I40: 166773.94 | J40: 196108.53 | K40: 194924.48 | L40: 179239.3 | M40: 109282.84 | N40: 73146.43 | O40: 29301.755 | P40: 1387863.8
A41: Contract
A42: Miscellaneous
A43: Streetlighting
A44: Total | D44: =SUM(D38:D43) -> 140174.61 | E44: =SUM(E38:E43) -> 250032.55 | F44: =SUM(F38:F43) -> 407855.47 | G44: =SUM(G38:G43) -> 521408.85 | H44: =SUM(H38:H43) -> 572315.04 | I44: =SUM(I38:I43) -> 713278.69 | J44: =SUM(J38:J43) -> 808527.05 | K44: =SUM(K38:K43) -> 790202.13 | ... P44: =SUM(P38:P43) -> 5961325.6
D46: RER
A47: Residential
...

Sheet MMG-1.3a
A1: Madison Gas and Electric Company
A2: 2023 Fuel Reconciliation Audit (3270-FR-2023)
A3: MMG-1.3a - Allocations and per kWh values for September 2024
A6: Deferred Balance | B6: -7219332
A7: Interest Amount | B7: -241762
A8: Deferred Balance with Interest | B8: =B6+B7 -> -7461094
B11: Sep 2024 Forecasted Sales (kWh)1 | E11: Allocation and Adjustment Rate
A12: Adjustment Period: | D12: Net Sales | F12: Adjustment Rate
A13: September 2024 | B13: Total kWh | C13: Renewables2 | D13: for Adjustment | E13: $ Allocation3 | F13: per kWh | G13: $ Adjustment4
A14: Class-Based
A15: Residential | B15: =SUM('MMG-1.1b'!L20) -> 72546406 | C15: =SUM('MMG-1.1b'!L29)+SUM('MMG-1.1b'!L38)+SUM('MMG-1.1b'!L47) -> 4991236 | D15: =B15-C15 -> 67555170 | E15: =B$8*'MMG-1.1a'!G10 -> -2004794 | F15: =ROUND(E15/D15,5) -> -0.02968 | G15: =ROUND(F15*D15,2) -> -2005037.4
A16: Small Commercial | B16: =SUM('MMG-1.1b'!L21) -> 17135620 | C16: =SUM('MMG-1.1b'!L30)+SUM('MMG-1.1b'!L39)+SUM('MMG-1.1b'!L48) -> 213751.39 | D16: =B16-C16 -> 16921868 | E16: =B$8*'MMG-1.1a'!G11 -> -518510.38 | F16: =ROUND(E16/D16,5) -> -0.03064 | G16: =ROUND(F16*D16,2) -> -518486.04
A17: Large Commercial & Industrial | B17: =SUM('MMG-1.1b'!L22) -> 1.3606332e+08 | C17: =SUM('MMG-1.1b'!L31)+SUM('MMG-1.1b'!L40)+SUM('MMG-1.1b'!L49) -> 6566071.8 | D17: =B17-C17 -> 1.2949725e+08 | E17: =B$8*'MMG-1.1a'!G12 -> -3839508.1 | F17: =ROUND(E17/D17,5) -> -0.02965 | G17: =ROUND(F17*D17,2) -> -3839593.4
A18: Contract | B18: =SUM('MMG-1.1b'!L23) -> 41010801 | C18: =SUM('MMG-1.1b'!L32)+SUM('MMG-1.1b'!L41)+SUM('MMG-1.1b'!L50) -> 1684546.9 | D18: =B18-C18 -> 39326254 | E18: =B$8*'MMG-1.1a'!G13 -> -1067406.2 | F18: =ROUND(E18/D18,5) -> -0.02714 | G18: =ROUND(F18*D18,2) -> -1067314.5
A19: Miscellaneous | B19: =SUM('MMG-1.1b'!L24) -> 350416.35 | C19: =SUM('MMG-1.1b'!L33)+SUM('MMG-1.1b'!L42)+SUM('MMG-1.1b'!L51) -> 0 | D19: =B19-C19 -> 350416.35 | E19: =B$8*'MMG-1.1a'!G14 -> -9845.6903 | F19: =ROUND(E19/D19,5) -> -0.0281 | G19: =ROUND(F19*D19,2) -> -9846.7
A20: Streetlighting | B20: =SUM('MMG-1.1b'!L25) -> 711169 | C20: =SUM('MMG-1.1b'!L34)+SUM('MMG-1.1b'!L43)+SUM('MMG-1.1b'!L52) -> 0 | D20: =B20-C20 -> 711169 | E20: =B$8*'MMG-1.1a'!G15 -> -21029.639 | F20: =ROUND(E20/D20,5) -> -0.02957 | G20: =ROUND(F20*D20,2) -> -21029.27
A21: Class-Based Totals | B21: =SUM(B15:B20) -> 2.6781773e+08 | C21: =SUM(C15:C20) -> 13455606 | D21: =SUM(D15:D20) -> 2.5436213e+08 | E21: =SUM(E15:E20) -> -7461094 | G21: =SUM(G15:G20) -> -7461307.4
A22: Flat-Rate | B22: =B21 -> 2.6781773e+08 | C22: =C21 -> 13455606 | D22: =D21 -> 2.5436213e+08 | E22: =E21 -> -7461094 | F22: =ROUND(E22/D22,5) -> -0.02933 | G22: =ROUND(F22*D22,2) -> -7460441.2
A23: 1 Authorized in docket 3270-UR-125.
A24: 2 Renewables includes sales associated with MGE's Green Power Tomorrow, Shared Solar, and Renewable Energy Rider programs.
A25: 3 The deferred balance with interest is allocated according to relative share of kWh sales during the 2023 calendar year.
A26: 4 The difference between the deferred balance with interest and the total adjustment is due to rounding the adjustment rate to the nearest thousandth of a cent.
A29: =A12 -> Adjustment Period: | B29: Est. Monthly | C29: Adjustment Rate | D29: Est. Monthly
A30: =A13 -> September 2024 | B30: kWh | C30: per kWh | D30: Bill Impact
A31: Residential
A32: Flat-Rate | B32: 500 | C32: =F22 -> -0.02933 | D32: =ROUND(B32*C32,2) -> -14.67
A33: Class-Based | B33: 500 | C33: =F15 -> -0.02968 | D33: =ROUND(B33*C33,2) -> -14.84
A34: General Service
A35: Flat-Rate | B35: 1100 | C35: =F22 -> -0.02933 | D35: =ROUND(B35*C35,2) -> -32.26
A36: Class-Based | B36: 1100 | C36: =F16 -> -0.03064 | D36: =ROUND(B36*C36,2) -> -33.7
A38: Residential: | B38: Rg-1, Rg-2, Rg-2A, RW-1, Rg-7
A39: Small Commercial: | B39: Cg-5, Cg-3, Cg-7
A40: Large Commercial and Industrial: | B40: Cg-8, Cg-4, Cg-2, Cg-6
A41: Contract: | B41: Cp-1, SP-3, DC-1
A42: Miscellaneous: | B42: Gf-1, Mg-2, OL-1, MLS
A43: Streetlighting | B43: GSL-1

Sheet MMG-1.3b
A1: Madison Gas and Electric Company
A2: 2023 Fuel Reconciliation Audit (3270-FR-2023)
A3: MMG-1.3b - Allocations and per kWh values for October 2024
A6: Deferred Balance | B6: -7219332
A7: Interest Amount | B7: -269120
A8: Deferred Balance with Interest | B8: =B6+B7 -> -7488452
B11: Oct 2024 Forecasted Sales (kWh)1 | E11: Allocation and Adjustment Rate
A12: Adjustment Period: | D12: Net Sales | F12: Adjustment Rate
A13: October 2024 | B13: Total kWh | C13: Renewables2 | D13: for Adjustment | E13: $ Allocation3 | F13: per kWh | G13: $ Adjustment4
A14: Class-Based
A15: Residential | B15: =SUM('MMG-1.1b'!M20) -> 59906926 | C15: =SUM('MMG-1.1b'!M29)+SUM('MMG-1.1b'!M38)+SUM('MMG-1.1b'!M47) -> 3796726.5 | D15: =B15-C15 -> 56110199 | E15: =B$8*'MMG-1.1a'!G10 -> -2012145.1 | F15: =ROUND(E15/D15,5) -> -0.03586 | G15: =ROUND(F15*D15,2) -> -2012111.7
A16: Small Commercial | B16: =SUM('MMG-1.1b'!M21) -> 16414173 | C16: =SUM('MMG-1.1b'!M30)+SUM('MMG-1.1b'!M39)+SUM('MMG-1.1b'!M48) -> 168442.16 | D16: =B16-C16 -> 16245731 | E16: =B$8*'MMG-1.1a'!G11 -> -520411.63 | F16: =ROUND(E16/D16,5) -> -0.03203 | G16: =ROUND(F16*D16,2) -> -520350.77
A17: Large Commercial & Industrial | B17: =SUM('MMG-1.1b'!M22) -> 1.3041891e+08 | C17: =SUM('MMG-1.1b'!M31)+SUM('MMG-1.1b'!M40)+SUM('MMG-1.1b'!M49) -> 5854872.7 | D17: =B17-C17 -> 1.2456404e+08 | E17: =B$8*'MMG-1.1a'!G12 -> -3853586.6 | F17: =ROUND(E17/D17,5) -> -0.03094 | G17: =ROUND(F17*D17,2) -> -3854011.5
A18: Contract | B18: =SUM('MMG-1.1b'!M23) -> 38349689 | C18: =SUM('MMG-1.1b'!M32)+SUM('MMG-1.1b'!M41)+SUM('MMG-1.1b'!M50) -> 1559735.1 | D18: =B18-C18 -> 36789954 | E18: =B$8*'MMG-1.1a'!G13 -> -1071320.1 | F18: =ROUND(E18/D18,5) -> -0.02912 | G18: =ROUND(F18*D18,2) -> -1071323.4
A19: Miscellaneous | B19: =SUM('MMG-1.1b'!M24) -> 356463.43 | C19: =SUM('MMG-1.1b'!M33)+SUM('MMG-1.1b'!M42)+SUM('MMG-1.1b'!M51) -> 0 | D19: =B19-C19 -> 356463.43 | E19: =B$8*'MMG-1.1a'!G14 -> -9881.7921 | F19: =ROUND(E19/D19,5) -> -0.02772 | G19: =ROUND(F19*D19,2) -> -9881.17
A20: Streetlighting | B20: =SUM('MMG-1.1b'!M25) -> 673055 | C20: =SUM('MMG-1.1b'!M34)+SUM('MMG-1.1b'!M43)+SUM('MMG-1.1b'!M52) -> 0 | D20: =B20-C20 -> 673055 | E20: =B$8*'MMG-1.1a'!G15 -> -21106.75 | F20: =ROUND(E20/D20,5) -> -0.03136 | G20: =ROUND(F20*D20,2) -> -21107
A21: Class-Based Totals | B21: =SUM(B15:B20) -> 2.4611922e+08 | C21: =SUM(C15:C20) -> 11379777 | D21: =SUM(D15:D20) -> 2.3473944e+08 | E21: =SUM(E15:E20) -> -7488452 | G21: =SUM(G15:G20) -> -7488785.6
A22: Flat-Rate | B22: =B21 -> 2.4611922e+08 | C22: =C21 -> 11379777 | D22: =D21 -> 2.3473944e+08 | E22: =E21 -> -7488452 | F22: =ROUND(E22/D22,5) -> -0.0319 | G22: =ROUND(F22*D22,2) -> -7488188.3
A23: 1 Authorized in docket 3270-UR-125.
A24: 2 Renewables includes sales associated with MGE's Green Power Tomorrow, Shared Solar, and Renewable Energy Rider programs.
A25: 3 The deferred balance with interest is allocated according to relative share of kWh sales during the 2023 calendar year.
A26: 4 The difference between the deferred balance with interest and the total adjustment is due to rounding the adjustment rate to the nearest thousandth of a cent.
A29: =A12 -> Adjustment Period: | B29: Est. Monthly | C29: Adjustment Rate | D29: Est. Monthly
A30: =A13 -> October 2024 | B30: kWh | C30: per kWh | D30: Bill Impact
A31: Residential
A32: Flat-Rate | B32: 500 | C32: =F22 -> -0.0319 | D32: =ROUND(B32*C32,2) -> -15.95
A33: Class-Based | B33: 500 | C33: =F15 -> -0.03586 | D33: =ROUND(B33*C33,2) -> -17.93
A34: General Service
A35: Flat-Rate | B35: 1100 | C35: =F22 -> -0.0319 | D35: =ROUND(B35*C35,2) -> -35.09
A36: Class-Based | B36: 1100 | C36: =F16 -> -0.03203 | D36: =ROUND(B36*C36,2) -> -35.23
A38: Residential: | B38: Rg-1, Rg-2, Rg-2A, RW-1, Rg-7
A39: Small Commercial: | B39: Cg-5, Cg-3, Cg-7
A40: Large Commercial and Industrial: | B40: Cg-8, Cg-4, Cg-2, Cg-6
A41: Contract: | B41: Cp-1, SP-3, DC-1
A42: Miscellaneous: | B42: Gf-1, Mg-2, OL-1, MLS
A43: Streetlighting | B43: GSL-1

Sheet MMG-1.3c
A1: Madison Gas and Electric Company
A2: 2023 Fuel Reconciliation Audit (3270-FR-2023)
A3: MMG-1.3c - Allocations and per kWh values for September 2024 through December 2024
A6: Deferred Balance | B6: -7219332
A7: Interest Amount | B7: -282798
A8: Deferred Balance with Interest | B8: =B6+B7 -> -7502130
B11: Sep 2024 - Dec 2024 Forecasted Sales (kWh)1 | E11: Allocation and Adjustment Rate
A12: Adjustment Period: | D12: Net Sales | F12: Adjustment Rate
A13: Sep 2024 - Dec 2024 | B13: Total kWh | C13: Renewables2 | D13: for Adjustment | E13: $ Allocation3 | F13: per kWh | G13: $ Adjustment4
A14: Class-Based
A15: Residential | B15: =SUM('MMG-1.1b'!L20:O20) -> 2.6589839e+08 | C15: =SUM('MMG-1.1b'!L29:O29)+SUM('MMG-1.1b'!L38:O38)+SUM('MMG-1.1b'!L47:O47) -> 16597322 | D15: =B15-C15 -> 2.4930107e+08 | E15: =B$8*'MMG-1.1a'!G10 -> -2015820.4 | F15: =ROUND(E15/D15,5) -> -0.00809 | G15: =ROUND(F15*D15,2) -> -2016845.6
A16: Small Commercial | B16: =SUM('MMG-1.1b'!L21:O21) -> 69845000 | C16: =SUM('MMG-1.1b'!L30:O30)+SUM('MMG-1.1b'!L39:O39)+SUM('MMG-1.1b'!L48:O48) -> 740981.89 | D16: =B16-C16 -> 69104019 | E16: =B$8*'MMG-1.1a'!G11 -> -521362.18 | F16: =ROUND(E16/D16,5) -> -0.00754 | G16: =ROUND(F16*D16,2) -> -521044.3
A17: Large Commercial & Industrial | B17: =SUM('MMG-1.1b'!L22:O22) -> 5.2101743e+08 | C17: =SUM('MMG-1.1b'!L31:O31)+SUM('MMG-1.1b'!L40:O40)+SUM('MMG-1.1b'!L49:O49) -> 19164713 | D17: =B17-C17 -> 5.0185272e+08 | E17: =B$8*'MMG-1.1a'!G12 -> -3860625.4 | F17: =ROUND(E17/D17,5) -> -0.00769 | G17: =ROUND(F17*D17,2) -> -3859247.4
A18: Contract | B18: =SUM('MMG-1.1b'!L23:O23) -> 1.4612876e+08 | C18: =SUM('MMG-1.1b'!L32:O32)+SUM('MMG-1.1b'!L41:O41)+SUM('MMG-1.1b'!L50:O50) -> 4581530 | D18: =B18-C18 -> 1.4154723e+08 | E18: =B$8*'MMG-1.1a'!G13 -> -1073276.9 | F18: =ROUND(E18/D18,5) -> -0.00758 | G18: =ROUND(F18*D18,2) -> -1072928
A19: Miscellaneous | B19: =SUM('MMG-1.1b'!L24:O24) -> 1417288.4 | C19: =SUM('MMG-1.1b'!L33:O33)+SUM('MMG-1.1b'!L42:O42)+SUM('MMG-1.1b'!L51:O51) -> 0 | D19: =B19-C19 -> 1417288.4 | E19: =B$8*'MMG-1.1a'!G14 -> -9899.8416 | F19: =ROUND(E19/D19,5) -> -0.00699 | G19: =ROUND(F19*D19,2) -> -9906.85
A20: Streetlighting | B20: =SUM('MMG-1.1b'!L25:O25) -> 2865160 | C20: =SUM('MMG-1.1b'!L34:O34)+SUM('MMG-1.1b'!L43:O43)+SUM('MMG-1.1b'!L52:O52) -> 0 | D20: =B20-C20 -> 2865160 | E20: =B$8*'MMG-1.1a'!G15 -> -21145.302 | F20: =ROUND(E20/D20,5) -> -0.00738 | G20: =ROUND(F20*D20,2) -> -21144.88
A21: Class-Based Totals | B21: =SUM(B15:B20) -> 1.007172e+09 | C21: =SUM(C15:C20) -> 41084547 | D21: =SUM(D15:D20) -> 9.6608748e+08 | E21: =SUM(E15:E20) -> -7502130 | G21: =SUM(G15:G20) -> -7501117
A22: Flat-Rate | B22: =B21 -> 1.007172e+09 | C22: =C21 -> 41084547 | D22: =D21 -> 9.6608748e+08 | E22: =E21 -> -7502130 | F22: =ROUND(E22/D22,5) -> -0.00777 | G22: =ROUND(F22*D22,2) -> -7506499.7
A23: 1 Authorized in docket 3270-UR-125.
A24: 2 Renewables includes sales associated with MGE's Green Power Tomorrow, Shared Solar, and Renewable Energy Rider programs.
A25: 3 The deferred balance with interest is allocated according to relative share of kWh sales during the 2023 calendar year.
A26: 4 The difference between the deferred balance with interest and the total adjustment is due to rounding the adjustment rate to the nearest thousandth of a cent.
A29: =A12 -> Adjustment Period: | B29: Est. Monthly | C29: Adjustment Rate | D29: Est. Monthly
A30: =A13 -> Sep 2024 - Dec 2024 | B30: kWh | C30: per kWh | D30: Bill Impact
A31: Residential
A32: Flat-Rate | B32: 500 | C32: =F22 -> -0.00777 | D32: =ROUND(B32*C32,2) -> -3.89
A33: Class-Based | B33: 500 | C33: =F15 -> -0.00809 | D33: =ROUND(B33*C33,2) -> -4.05
A34: General Service
A35: Flat-Rate | B35: 1100 | C35: =F22 -> -0.00777 | D35: =ROUND(B35*C35,2) -> -8.55
A36: Class-Based | B36: 1100 | C36: =F16 -> -0.00754 | D36: =ROUND(B36*C36,2) -> -8.29
A38: Residential: | B38: Rg-1, Rg-2, Rg-2A, RW-1, Rg-7
A39: Small Commercial: | B39: Cg-5, Cg-3, Cg-7
A40: Large Commercial and Industrial: | B40: Cg-8, Cg-4, Cg-2, Cg-6
A41: Contract: | B41: Cp-1, SP-3, DC-1
A42: Miscellaneous: | B42: Gf-1, Mg-2, OL-1, MLS
A43: Streetlighting | B43: GSL-1

Sheet MMG-1.3d
A1: Madison Gas and Electric Company
A2: 2023 Fuel Reconciliation Audit (3270-FR-2023)
A3: MMG-1.3d - Allocations and per kWh values for October 2024 through December 2024
A6: Deferred Balance | B6: -7219332
A7: Interest Amount | B7: -296577
A8: Deferred Balance with Interest | B8: =B6+B7 -> -7515909
B11: Oct 2024 - Dec 2024 Forecasted Sales (kWh)1 | E11: Allocation and Adjustment Rate
A12: Adjustment Period: | D12: Net Sales | F12: Adjustment Rate
A13: Oct 2024 - Dec 2024 | B13: Total kWh | C13: Renewables2 | D13: for Adjustment | E13: $ Allocation3 | F13: per kWh | G13: $ Adjustment4
A14: Class-Based
A15: Residential | B15: =SUM('MMG-1.1b'!M20:O20) -> 1.9335198e+08 | C15: =SUM('MMG-1.1b'!M29:O29)+SUM('MMG-1.1b'!M38:O38)+SUM('MMG-1.1b'!M47:O47) -> 11606086 | D15: =B15-C15 -> 1.817459e+08 | E15: =B$8*'MMG-1.1a'!G10 -> -2019522.8 | F15: =ROUND(E15/D15,5) -> -0.01111 | G15: =ROUND(F15*D15,2) -> -2019196.9
A16: Small Commercial | B16: =SUM('MMG-1.1b'!M21:O21) -> 52709381 | C16: =SUM('MMG-1.1b'!M30:O30)+SUM('MMG-1.1b'!M39:O39)+SUM('MMG-1.1b'!M48:O48) -> 527230.5 | D16: =B16-C16 -> 52182150 | E16: =B$8*'MMG-1.1a'!G11 -> -522319.76 | F16: =ROUND(E16/D16,5) -> -0.01001 | G16: =ROUND(F16*D16,2) -> -522343.32
A17: Large Commercial & Industrial | B17: =SUM('MMG-1.1b'!M22:O22) -> 3.8495411e+08 | C17: =SUM('MMG-1.1b'!M31:O31)+SUM('MMG-1.1b'!M40:O40)+SUM('MMG-1.1b'!M49:O49) -> 12598641 | D17: =B17-C17 -> 3.7235547e+08 | E17: =B$8*'MMG-1.1a'!G12 -> -3867716.1 | F17: =ROUND(E17/D17,5) -> -0.01039 | G17: =ROUND(F17*D17,2) -> -3868773.3
A18: Contract | B18: =SUM('MMG-1.1b'!M23:O23) -> 1.0511796e+08 | C18: =SUM('MMG-1.1b'!M32:O32)+SUM('MMG-1.1b'!M41:O41)+SUM('MMG-1.1b'!M50:O50) -> 2896983.1 | D18: =B18-C18 -> 1.0222097e+08 | E18: =B$8*'MMG-1.1a'!G13 -> -1075248.2 | F18: =ROUND(E18/D18,5) -> -0.01052 | G18: =ROUND(F18*D18,2) -> -1075364.6
A19: Miscellaneous | B19: =SUM('MMG-1.1b'!M24:O24) -> 1066872.1 | C19: =SUM('MMG-1.1b'!M33:O33)+SUM('MMG-1.1b'!M42:O42)+SUM('MMG-1.1b'!M51:O51) -> 0 | D19: =B19-C19 -> 1066872.1 | E19: =B$8*'MMG-1.1a'!G14 -> -9918.0244 | F19: =ROUND(E19/D19,5) -> -0.0093 | G19: =ROUND(F19*D19,2) -> -9921.91
A20: Streetlighting | B20: =SUM('MMG-1.1b'!M25:O25) -> 2153991 | C20: =SUM('MMG-1.1b'!M34:O34)+SUM('MMG-1.1b'!M43:O43)+SUM('MMG-1.1b'!M52:O52) -> 0 | D20: =B20-C20 -> 2153991 | E20: =B$8*'MMG-1.1a'!G15 -> -21184.139 | F20: =ROUND(E20/D20,5) -> -0.00983 | G20: =ROUND(F20*D20,2) -> -21173.73
A21: Class-Based Totals | B21: =SUM(B15:B20) -> 7.3935429e+08 | C21: =SUM(C15:C20) -> 27628941 | D21: =SUM(D15:D20) -> 7.1172535e+08 | E21: =SUM(E15:E20) -> -7515909 | G21: =SUM(G15:G20) -> -7516773.8
A22: Flat-Rate | B22: =B21 -> 7.3935429e+08 | C22: =C21 -> 27628941 | D22: =D21 -> 7.1172535e+08 | E22: =E21 -> -7515909 | F22: =ROUND(E22/D22,5) -> -0.01056 | G22: =ROUND(F22*D22,2) -> -7515819.7
A23: 1 Authorized in docket 3270-UR-125.
A24: 2 Renewables includes sales associated with MGE's Green Power Tomorrow, Shared Solar, and Renewable Energy Rider programs.
A25: 3 The deferred balance with interest is allocated according to relative share of kWh sales during the 2023 calendar year.
A26: 4 The difference between the deferred balance with interest and the total adjustment is due to rounding the adjustment rate to the nearest thousandth of a cent.
A29: =A12 -> Adjustment Period: | B29: Est. Monthly | C29: Adjustment Rate | D29: Est. Monthly
A30: =A13 -> Oct 2024 - Dec 2024 | B30: kWh | C30: per kWh | D30: Bill Impact
A31: Residential
A32: Flat-Rate | B32: 500 | C32: =F22 -> -0.01056 | D32: =ROUND(B32*C32,2) -> -5.28
A33: Class-Based | B33: 500 | C33: =F15 -> -0.01111 | D33: =ROUND(B33*C33,2) -> -5.56
A34: General Service
A35: Flat-Rate | B35: 1100 | C35: =F22 -> -0.01056 | D35: =ROUND(B35*C35,2) -> -11.62
A36: Class-Based | B36: 1100 | C36: =F16 -> -0.01001 | D36: =ROUND(B36*C36,2) -> -11.01
A38: Residential: | B38: Rg-1, Rg-2, Rg-2A, RW-1, Rg-7
A39: Small Commercial: | B39: Cg-5, Cg-3, Cg-7
A40: Large Commercial and Industrial: | B40: Cg-8, Cg-4, Cg-2, Cg-6
A41: Contract: | B41: Cp-1, SP-3, DC-1
A42: Miscellaneous: | B42: Gf-1, Mg-2, OL-1, MLS
A43: Streetlighting | B43: GSL-1

Sheet Bill Factor Codes
A1: Madison Gas and Electric Co.
A2: Docket 3270-FR-2023
A3: Electric Bill Factor Codes with Present and Authorized Rates
A4: Summary for the Period October 1 - December 31, 2024
A7: ANNUAL FUEL COST (AFC) | D7: Bill Factor Code | E7: Present Rates | F7: Authorized Rates | G7: Units | H7: Rate Change
B8: AFC | C8: Annual Fuel Cost for Residential | D8: AFCRES | E8: 0.00291 | F8: -0.01056 | G8: per kWh | H8: =IF(E8="","",IF(E8=F8,"N","Y")) -> Y
B9: AFC | C9: Annual Fuel Cost for Small Commercial | D9: AFCSCOM | E9: 0.00291 | F9: -0.01056 | G9: per kWh | H9: =IF(E9="","",IF(E9=F9,"N","Y")) -> Y
B10: AFC | C10: Annual Fuel Cost for Medium and Large Com/Ind | D10: AFCMLCI | E10: 0.00291 | F10: -0.01056 | G10: per kWh | H10: =IF(E10="","",IF(E10=F10,"N","Y")) -> Y
B11: AFC | C11: Annual Fuel Cost for Contract (CP-1/SP-3) | D11: AFCCONT | E11: 0.00291 | F11: -0.01056 | G11: per kWh | H11: =IF(E11="","",IF(E11=F11,"N","Y")) -> Y
B12: AFC | C12: Annual Fuel Cost for Street Light | D12: AFCSL | E12: 0.00291 | F12: -0.01056 | G12: per kWh | H12: =IF(E12="","",IF(E12=F12,"N","Y")) -> Y
B13: AFC | C13: Annual Fuel Cost for Miscellaneous | D13: AFCMISC | E13: 0.00291 | F13: -0.01056 | G13: per kWh | H13: =IF(E13="","",IF(E13=F13,"N","Y")) -> Y
