Workbook
Name \B: [1]BILLING!#REF!
Name \B: [1]BILLING!#REF!
Name \D: #REF!
Name \D: #REF!
Name \E: [1]BILLING!#REF!
Name \E: [1]BILLING!#REF!
Name \J: #REF!
Name \J: #REF!
Name \K: [1]BILLING!#REF!
Name \K: [1]BILLING!#REF!
Name \M: [1]BILLING!#REF!
Name \M: [1]BILLING!#REF!
Name \P: [1]BILLING!#REF!
Name \P: [1]BILLING!#REF!
Name \S: [1]BILLING!#REF!
Name \S: [1]BILLING!#REF!
Name \T: [1]BILLING!#REF!
Name \T: [1]BILLING!#REF!
Name \U: [1]BILLING!#REF!
Name \Z: [1]BILLING!#REF!
Name akdsfja: '[2]PGA Calc'!#REF!
Name Diesel_BGS: #REF!
Name fasdjfklasd: [3]Prior!#REF!
Name gcdmsales: #REF!
Name gigo: #REF!
Name IQ_CH: 110000
Name IQ_CQ: 5000
Name IQ_CY: 10000
Name IQ_DAILY: 500000
Name IQ_FH: 100000
Name IQ_FQ: 500
Name IQ_FY: 1000
Name IQ_LTM: 2000
Name IQ_MONTH: 15000
Name IQ_NTM: 6000
Name IQ_WEEK: 50000
Name IQ_YTD: 3000
Name m: [3]Prior!#REF!
Name Mo_Day_Yr: '[4]Gas Trans'!$W$2
Name Month_table: [5]Misc!#REF!
Name Month_Yr: [6]InputEst!$C$4
Name Natural_Gas_BGS: #REF!
Name NvsAnswerCol: "[Drill1]JRNLLAYOUT!$A$4:$A$54"
Name NvsASD: "V2012-12-31"
Name NvsAutoDrillOk: "VN"
Name NvsDateToNumber: "Y"
Name NvsElapsedTime: 0.0000347222230629995
Name NvsEndTime: 41353.6898148148
Name NvsInstLang: "VENG"
Name NvsInstSpec: "%,LACTUALS,UPOSTED_TOTAL_AMT,SYTD,FACCOUNT,V001154,FDEPTID,V0231"
Name NvsInstSpec1: ","
Name NvsInstSpec2: ","
Name NvsInstSpec3: ","
Name NvsInstSpec4: ","
Name NvsInstSpec5: ","
Name NvsInstSpec6: ","
Name NvsInstSpec7: ","
Name NvsInstSpec8: ","
Name NvsInstSpec9: ","
Name NvsLayoutType: "M3"

Sheet Cover Sheet
A2: Madison Gas and Electric Company
A4: MGE-Response-Data Request-PSC-Eiter-1
A6: Docket Number: | C6: 3270-FR-2022
A7: Date of Request: | C7: May 10, 2023 (PSC REF # 467696)
A8: Requestor: | C8: Andrew Eiter
A9: Date of Response: | C9: May 18, 2023
A10: Respondent: | C10: Carl Weinert
A13: PSCW-ACE-1.1 | B13: In the application filing, the applicant indicated its request to recover a deferred account balance over a 12-month period (October 2023 to September 2024). Provide the monthly sales volumes the applicant proposes to use for the development of the surcharge rate. In your response, be sure to indicate if the sales are based on a Commission authorized sales forecast, or if the sales will be subject to change based on the Commission's final decision in docket 3270-UR-125.
A15: Response
A17: See Tab ACE-1.1 for the requested monthly electric sales volumes. All sales volumes used in this response are net of renewables. The monthly electric sales volumes for 2023 are based on the Commission authorized sales forecast that is included in MGE's response to data request PSC-Field-1.36 (PSC REF # 463133). The monthly electric sales volumes for 2024 are based on MGE's filed sales forecast that is included in MGE's response to data request PSC-Field-4 (PSC REF # 467538) and are subject to change based on the Commission's final decision in docket 3270-UR-125. Also included are the actual electric sales volumes by rate class for the 2022 Fuel Plan Year for use in the development of a class-based surcharge allocation as requested in ACE-1.2 and ACE-1.4.
A20: PSCW-ACE-1.2 | B20: Using the fuel numbers as filed in the application, demonstrate what a flat-rate and class-based surcharge allocation, with per kilowatt-hour (kWh) surcharge values, would look like if the deferred account balance were recovered in: a. September 2023; b. October 2023; c. October 2023 through December 2023; d. October 2023 through September 2024; and e. The calendar year of 2024.
A22: Response
A24: See Tab ACE-1.2 for the requested sucharge allocations and per kilowatt-hour (kWh) surcharge values.
A26: For your consideration, MGE would like to respectfully inform you that some of the fuel surcharge scenarios in ACE-1.2 will require significant lead time to configure MGE's billing system. Any single-month recovery period, other than the month of October, will require a minimum lead time of 2 months between the date of the written order and the effective date of the fuel surcharge. Specifically, for scenario a, MGE would need a written order issued on or before June 30 to configure a September fuel surcharge. Additionally, MGE would require a minimum lead time of 1 month for any multi-month recovery period utilizing the class-based methodology.
A29: PSCW-ACE-1.3 | B29: Provide any workbooks, with formulas intact, used to respond to PSCW-ACE-1.2.
A31: Response
A33: See Tab ACE-1.2.
A36: PSCW-ACE-1.4 | B36: Using the final fuel audit numbers, demonstrate what a flat-rate and class-based surcharge allocation, with per kWh surcharge values, would look like if the deferred account balance were recovered in: a. September 2023; b. October 2023; c. October 2023 through December 2023; d. October 2023 through September 2024; and e. The calendar year of 2024.
A38: Response
A40: As of the date of this response, PSCW staff has not notified MGE of any audit adjustments. If any audit adjustments that affect the surcharge amount are provided, MGE will respond to this request.
A43: PSCW-ACE-1.5 | B43: Provide any workbooks, with formulas intact, used to respond to PSCW-ACE-1.4.
A45: Response
A47: If MGE responds to ACE-1.4 as described above, the response will include any supporting workbooks with formulas intact.
A50: PSCW-ACE-1.6 | B50: Provide the bill impacts from the calculated fuel surcharge amounts for the average residential customer using 500 kWh monthly, and the average general service customer using 1,100 kWh, for the following time periods: a. September 2023; b. October 2023; c. October 2023 through December 2023; d. October 2023 through September 2024; and e. The calendar year of 2024.
A52: Response
A54: See Tab ACE-1.6 for the requested bill impacts.

Sheet ACE-1.1
A1: Madison Gas and Electric Company
A2: 2022 Fuel Reconciliation Audit (3270-FR-2022)
A3: ACE-1.1 - Monthly Electric Sales Volumes used for the Development of the Surcharge Rate
A6: Authorized 2023 Electric Sales Forecast per 3270-UR-124 Reopener
A8: Total Sales KWH Net of Renewables
B9: September | C9: October | D9: November | E9: December
A10: Residential | B10: 66995376 | C10: 54119641 | D10: 56519151 | E10: 66723921
A11: Small Commercial | B11: 17020451 | C11: 14266131 | D11: 15698857 | E11: 17733938
A12: Medium and Large C&I | B12: 145130203 | C12: 128433977 | D12: 123515919 | E12: 127072108
A13: Contract | B13: 39030226 | C13: 35559993 | D13: 31737373 | E13: 30533461
A14: Miscellaneous | B14: 336062 | C14: 369984 | D14: 377433 | E14: 368128
A15: Streetlighting | B15: 733891 | C15: 733891 | D15: 733891 | E15: 733891
A16: Total | B16: =SUM(B10:B15) -> 269246209 | C16: =SUM(C10:C15) -> 233483617 | D16: =SUM(D10:D15) -> 228582624 | E16: =SUM(E10:E15) -> 243165447
A18: Company Submitted 2024 Electric Sales Forecast per 3270-UR-125 Submission
A20: Total Sales KWH Net of Renewables
B21: January | C21: February | D21: March | E21: April | F21: May | G21: June | H21: July | I21: August | J21: September | K21: October | L21: November | M21: December
A22: Residential | B22: 75649896 | C22: 63038655 | D22: 60469067 | E22: 50878750 | F22: 55632420 | G22: 71100377 | H22: 85065008 | I22: 84305777 | J22: 65621055 | K22: 54577668 | L22: 55896137 | M22: 66347473
A23: Small Commercial | B23: 23138766 | C23: 20378746 | D23: 20352596 | E23: 17450257 | F23: 19057872 | G23: 20707551 | H23: 21396500 | I23: 21019666 | J23: 18102515 | K23: 17379868 | L23: 18124890 | M23: 20314837
A24: Medium and Large C&I | B24: 1.3216317e+08 | C24: 1.2214389e+08 | D24: 1.21039e+08 | E24: 1.138074e+08 | F24: 1.2851516e+08 | G24: 1.4601634e+08 | H24: 1.5590468e+08 | I24: 1.5180644e+08 | J24: 1.3050705e+08 | K24: 1.2553628e+08 | L24: 1.1959021e+08 | M24: 1.3004951e+08
A25: Contract | B25: 32062217 | C25: 29856616 | D25: 33005059 | E25: 34171251 | F25: 36377706 | G25: 36759875 | H25: 38973501 | I25: 40017839 | J25: 39326254 | K25: 36789954 | L25: 32245839 | M25: 33185180
A26: Miscellaneous | B26: 338109.09 | C26: 295082.99 | D26: 301785.74 | E26: 314163.61 | F26: 316442.58 | G26: 304880.6 | H26: 296962.22 | I26: 267594.1 | J26: 350416.35 | K26: 356463.43 | L26: 364312.45 | M26: 346096.2
A27: Streetlighting | B27: 758951 | C27: 556120 | D27: 817843 | E27: 713452 | F27: 727704 | G27: 719790 | H27: 719670 | I27: 719520 | J27: 711169 | K27: 673055 | L27: 734546 | M27: 746390
A28: Total | B28: =SUM(B22:B27) -> 2.6411111e+08 | C28: =SUM(C22:C27) -> 2.3626911e+08 | D28: =SUM(D22:D27) -> 2.3598535e+08 | E28: =SUM(E22:E27) -> 2.1733527e+08 | F28: =SUM(F22:F27) -> 2.4062731e+08 | G28: =SUM(G22:G27) -> 2.7560881e+08 | H28: =SUM(H22:H27) -> 3.0235632e+08 | I28: =SUM(I22:I27) -> 2.9813684e+08 | ... M28: =SUM(M22:M27) -> 2.5098948e+08
A30: 2022 Calendar Electric Sales
A32: Total Sales KWH Net of Renewables
B33: Amount | C33: Percent
A34: Residential | B34: 822244059 | C34: =B34/B$40 -> 0.2711078
A35: Small Commercial | B35: 210231502 | C35: =B35/B$40 -> 0.069316888
A36: Medium and Large C&I | B36: 1564365033 | C36: =B36/B$40 -> 0.51579765
A37: Contract | B37: 423335214 | C37: =B37/B$40 -> 0.13958079
A38: Miscellaneous | B38: 4013337 | C38: =B38/B$40 -> 0.0013232652
A39: Streetlighting | B39: 8715371 | C39: =B39/B$40 -> 0.0028736055
A40: Total | B40: =SUM(B34:B39) -> 3032904516 | C40: =B40/B$40 -> 1

Sheet ACE-1.2
A1: Madison Gas and Electric Company
A2: 2022 Fuel Reconciliation Audit (3270-FR-2022)
A3: ACE-1.2 - Flat-Rate and Class-Based Surcharge Allocations
A6: Surcharge Allocations for Recovery Period of September 2023
A8: Deferred Account Balance | B8: 8742612
A9: Interest | B9: 65789
A10: Total | B10: =B8+B9 -> 8808401
B12: Recovery | D12: Flat | G12: Class-Based
B13: kWh | D13: Allocation | E13: Rate | G13: Allocation | H13: Rate
A14: Residential | B14: =SUM(_xlfn.XLOOKUP(A14,'ACE-1.1'!$A$10:$A$15,'ACE-1.1'!$B$10:$B$15)) -> 66995376 | D14: =B$10*B14/B$20 -> 2191756.5 | E14: =ROUND(D14/B14,5) -> 0.03272 | G14: =B$10*_xlfn.XLOOKUP(A14,'ACE-1.1'!$A$34:$A$39,'ACE-1.1'!$C$34:$C$39) -> 2388026.2 | H14: =ROUND(G14/B14,5) -> 0.03564
A15: Small Commercial | B15: =SUM(_xlfn.XLOOKUP(A15,'ACE-1.1'!$A$10:$A$15,'ACE-1.1'!$B$10:$B$15)) -> 17020451 | D15: =B$10*B15/B$20 -> 556824.77 | E15: =ROUND(D15/B15,5) -> 0.03272 | G15: =B$10*_xlfn.XLOOKUP(A15,'ACE-1.1'!$A$34:$A$39,'ACE-1.1'!$C$34:$C$39) -> 610570.94 | H15: =ROUND(G15/B15,5) -> 0.03587
A16: Medium and Large C&I | B16: =SUM(_xlfn.XLOOKUP(A16,'ACE-1.1'!$A$10:$A$15,'ACE-1.1'!$B$10:$B$15)) -> 145130203 | D16: =B$10*B16/B$20 -> 4747940.7 | E16: =ROUND(D16/B16,5) -> 0.03272 | G16: =B$10*_xlfn.XLOOKUP(A16,'ACE-1.1'!$A$34:$A$39,'ACE-1.1'!$C$34:$C$39) -> 4543352.6 | H16: =ROUND(G16/B16,5) -> 0.03131
A17: Contract | B17: =SUM(_xlfn.XLOOKUP(A17,'ACE-1.1'!$A$10:$A$15,'ACE-1.1'!$B$10:$B$15)) -> 39030226 | D17: =B$10*B17/B$20 -> 1276875.5 | E17: =ROUND(D17/B17,5) -> 0.03272 | G17: =B$10*_xlfn.XLOOKUP(A17,'ACE-1.1'!$A$34:$A$39,'ACE-1.1'!$C$34:$C$39) -> 1229483.6 | H17: =ROUND(G17/B17,5) -> 0.0315
A18: Miscellaneous | B18: =SUM(_xlfn.XLOOKUP(A18,'ACE-1.1'!$A$10:$A$15,'ACE-1.1'!$B$10:$B$15)) -> 336062 | D18: =B$10*B18/B$20 -> 10994.282 | E18: =ROUND(D18/B18,5) -> 0.03272 | G18: =B$10*_xlfn.XLOOKUP(A18,'ACE-1.1'!$A$34:$A$39,'ACE-1.1'!$C$34:$C$39) -> 11655.851 | H18: =ROUND(G18/B18,5) -> 0.03468
A19: Streetlighting | B19: =SUM(_xlfn.XLOOKUP(A19,'ACE-1.1'!$A$10:$A$15,'ACE-1.1'!$B$10:$B$15)) -> 733891 | D19: =B$10*B19/B$20 -> 24009.275 | E19: =ROUND(D19/B19,5) -> 0.03272 | G19: =B$10*_xlfn.XLOOKUP(A19,'ACE-1.1'!$A$34:$A$39,'ACE-1.1'!$C$34:$C$39) -> 25311.869 | H19: =ROUND(G19/B19,5) -> 0.03449
A20: Total | B20: =SUM(B14:B19) -> 269246209 | D20: =SUM(D14:D19) -> 8808401 | G20: =SUM(G14:G19) -> 8808401
A23: Surcharge Allocations for Recovery Period of October 2023
A25: Deferred Account Balance | B25: 8742612
A26: Interest | B26: 73129
A27: Total | B27: =B25+B26 -> 8815741
B29: Recovery | D29: Flat | G29: Class-Based
B30: kWh | D30: Allocation | E30: Rate | G30: Allocation | H30: Rate
A31: Residential | B31: =SUM(_xlfn.XLOOKUP(A31,'ACE-1.1'!$A$10:$A$15,'ACE-1.1'!$C$10:$C$15)) -> 54119641 | D31: =B$27*B31/B$37 -> 2043418.5 | E31: =ROUND(D31/B31,5) -> 0.03776 | G31: =B$27*_xlfn.XLOOKUP(A31,'ACE-1.1'!$A$34:$A$39,'ACE-1.1'!$C$34:$C$39) -> 2390016.1 | H31: =ROUND(G31/B31,5) -> 0.04416
A32: Small Commercial | B32: =SUM(_xlfn.XLOOKUP(A32,'ACE-1.1'!$A$10:$A$15,'ACE-1.1'!$C$10:$C$15)) -> 14266131 | D32: =B$27*B32/B$37 -> 538652.42 | E32: =ROUND(D32/B32,5) -> 0.03776 | G32: =B$27*_xlfn.XLOOKUP(A32,'ACE-1.1'!$A$34:$A$39,'ACE-1.1'!$C$34:$C$39) -> 611079.73 | H32: =ROUND(G32/B32,5) -> 0.04283
A33: Medium and Large C&I | B33: =SUM(_xlfn.XLOOKUP(A33,'ACE-1.1'!$A$10:$A$15,'ACE-1.1'!$C$10:$C$15)) -> 128433977 | D33: =B$27*B33/B$37 -> 4849336.7 | E33: =ROUND(D33/B33,5) -> 0.03776 | G33: =B$27*_xlfn.XLOOKUP(A33,'ACE-1.1'!$A$34:$A$39,'ACE-1.1'!$C$34:$C$39) -> 4547138.5 | H33: =ROUND(G33/B33,5) -> 0.0354
A34: Contract | B34: =SUM(_xlfn.XLOOKUP(A34,'ACE-1.1'!$A$10:$A$15,'ACE-1.1'!$C$10:$C$15)) -> 35559993 | D34: =B$27*B34/B$37 -> 1342653.9 | E34: =ROUND(D34/B34,5) -> 0.03776 | G34: =B$27*_xlfn.XLOOKUP(A34,'ACE-1.1'!$A$34:$A$39,'ACE-1.1'!$C$34:$C$39) -> 1230508.1 | H34: =ROUND(G34/B34,5) -> 0.0346
A35: Miscellaneous | B35: =SUM(_xlfn.XLOOKUP(A35,'ACE-1.1'!$A$10:$A$15,'ACE-1.1'!$C$10:$C$15)) -> 369984 | D35: =B$27*B35/B$37 -> 13969.644 | E35: =ROUND(D35/B35,5) -> 0.03776 | G35: =B$27*_xlfn.XLOOKUP(A35,'ACE-1.1'!$A$34:$A$39,'ACE-1.1'!$C$34:$C$39) -> 11665.563 | H35: =ROUND(G35/B35,5) -> 0.03153
A36: Streetlighting | B36: =SUM(_xlfn.XLOOKUP(A36,'ACE-1.1'!$A$10:$A$15,'ACE-1.1'!$C$10:$C$15)) -> 733891 | D36: =B$27*B36/B$37 -> 27709.837 | E36: =ROUND(D36/B36,5) -> 0.03776 | G36: =B$27*_xlfn.XLOOKUP(A36,'ACE-1.1'!$A$34:$A$39,'ACE-1.1'!$C$34:$C$39) -> 25332.962 | H36: =ROUND(G36/B36,5) -> 0.03452
A37: Total | B37: =SUM(B31:B36) -> 233483617 | D37: =SUM(D31:D36) -> 8815741 | G37: =SUM(G31:G36) -> 8815741
A40: Surcharge Allocations for Recovery Period of October 2023 through December 2023
A42: Deferred Account Balance | B42: 8742612
A43: Interest | B43: 80520
A44: Total | B44: =B42+B43 -> 8823132
B46: Recovery | D46: Flat | G46: Class-Based
B47: kWh | D47: Allocation | E47: Rate | G47: Allocation | H47: Rate
A48: Residential | B48: =SUM(_xlfn.XLOOKUP(A48,'ACE-1.1'!$A$10:$A$15,'ACE-1.1'!$C$10:$E$15)) -> 177362713 | D48: =B$44*B48/B$54 -> 2218979.5 | E48: =ROUND(D48/B48,5) -> 0.01251 | G48: =B$44*_xlfn.XLOOKUP(A48,'ACE-1.1'!$A$34:$A$39,'ACE-1.1'!$C$34:$C$39) -> 2392019.9 | H48: =ROUND(G48/B48,5) -> 0.01349
A49: Small Commercial | B49: =SUM(_xlfn.XLOOKUP(A49,'ACE-1.1'!$A$10:$A$15,'ACE-1.1'!$C$10:$E$15)) -> 47698926 | D49: =B$44*B49/B$54 -> 596759.8 | E49: =ROUND(D49/B49,5) -> 0.01251 | G49: =B$44*_xlfn.XLOOKUP(A49,'ACE-1.1'!$A$34:$A$39,'ACE-1.1'!$C$34:$C$39) -> 611592.05 | H49: =ROUND(G49/B49,5) -> 0.01282
A50: Medium and Large C&I | B50: =SUM(_xlfn.XLOOKUP(A50,'ACE-1.1'!$A$10:$A$15,'ACE-1.1'!$C$10:$E$15)) -> 379022004 | D50: =B$44*B50/B$54 -> 4741932.7 | E50: =ROUND(D50/B50,5) -> 0.01251 | G50: =B$44*_xlfn.XLOOKUP(A50,'ACE-1.1'!$A$34:$A$39,'ACE-1.1'!$C$34:$C$39) -> 4550950.8 | H50: =ROUND(G50/B50,5) -> 0.01201
A51: Contract | B51: =SUM(_xlfn.XLOOKUP(A51,'ACE-1.1'!$A$10:$A$15,'ACE-1.1'!$C$10:$E$15)) -> 97830827 | D51: =B$44*B51/B$54 -> 1223958.5 | E51: =ROUND(D51/B51,5) -> 0.01251 | G51: =B$44*_xlfn.XLOOKUP(A51,'ACE-1.1'!$A$34:$A$39,'ACE-1.1'!$C$34:$C$39) -> 1231539.8 | H51: =ROUND(G51/B51,5) -> 0.01259
A52: Miscellaneous | B52: =SUM(_xlfn.XLOOKUP(A52,'ACE-1.1'!$A$10:$A$15,'ACE-1.1'!$C$10:$E$15)) -> 1115545 | D52: =B$44*B52/B$54 -> 13956.549 | E52: =ROUND(D52/B52,5) -> 0.01251 | G52: =B$44*_xlfn.XLOOKUP(A52,'ACE-1.1'!$A$34:$A$39,'ACE-1.1'!$C$34:$C$39) -> 11675.344 | H52: =ROUND(G52/B52,5) -> 0.01047
...

Sheet ACE-1.6
A1: Madison Gas and Electric Company
A2: 2022 Fuel Reconciliation Audit (3270-FR-2022)
A3: ACE-1.6 - Average Monthly Bill Impacts for Residential and General Service Customers
A6: Authorized Electric Rates per 3270-UR-124 Reopener
A8: Average Monthly Bills for Residential Customers
B9: Rg-1 Rate | C9: Billing Units | D9: Monthly Charge
A10: Grid Connection | B10: 0.049315 | C10: =365/12 -> 30.416667 | D10: =ROUND(B10*C10,2) -> 1.5
A11: Distribution Service | B11: 0.0551 | C11: 500 | D11: =ROUND(B11*C11,2) -> 27.55
A12: Electricity Service | B12: 0.11118 | C12: 500 | D12: =ROUND(B12*C12,2) -> 55.59
A13: Average Monthly Bill | D13: =SUM(D10:D12) -> 84.64
A15: Average Monthly Bills for General Service Customers
B16: Cg-5 Rate | C16: Billing Units | D16: Monthly Charge
A17: Grid Connection | B17: 0.78584 | C17: =365/12 -> 30.416667 | D17: =ROUND(B17*C17,2) -> 23.9
A18: Distribution Service | B18: 0.03115 | C18: 1100 | D18: =ROUND(B18*C18,2) -> 34.27
A19: Electricity Service | B19: 0.10704 | C19: 1100 | D19: =ROUND(B19*C19,2) -> 117.74
A20: Average Monthly Bill | D20: =SUM(D17:D19) -> 175.91
A22: Estimated Bill Impacts
A24: Estimated Residential Bill Impacts
B25: Current | C25: Flat-Rate Surcharge | F25: Class-Based Surcharge
A26: Recovery Period | B26: Monthly Bill | C26: Monthly Bill | D26: Increase | E26: Percent | F26: Monthly Bill | G26: Increase | H26: Percent
A27: September 2023 | B27: =D$13 -> 84.64 | C27: =B27+D27 -> 101 | D27: =ROUND(C12*'[9]ACE-1.2'!E15,2) -> 16.36 | E27: =C27/B27-1 -> 0.19328922 | F27: =B27+G27 -> 102.46 | G27: =ROUND(C12*'[9]ACE-1.2'!H15,2) -> 17.82 | H27: =F27/B27-1 -> 0.21053875
A28: October 2023 | B28: =D$13 -> 84.64 | C28: =B28+D28 -> 103.52 | D28: =ROUND(C12*'[9]ACE-1.2'!E32,2) -> 18.88 | E28: =C28/B28-1 -> 0.22306238 | F28: =B28+G28 -> 106.72 | G28: =ROUND(C12*'[9]ACE-1.2'!H32,2) -> 22.08 | H28: =F28/B28-1 -> 0.26086957
A29: October 2023 through December 2023 | B29: =D$13 -> 84.64 | C29: =B29+D29 -> 90.9 | D29: =ROUND(C12*'[9]ACE-1.2'!E49,2) -> 6.26 | E29: =C29/B29-1 -> 0.073960302 | F29: =B29+G29 -> 91.39 | G29: =ROUND(C12*'[9]ACE-1.2'!H49,2) -> 6.75 | H29: =F29/B29-1 -> 0.079749527
A30: October 2023 through September 2024 | B30: =D$13 -> 84.64 | C30: =B30+D30 -> 86.12 | D30: =ROUND(C12*'[9]ACE-1.2'!E66,2) -> 1.48 | E30: =C30/B30-1 -> 0.017485822 | F30: =B30+G30 -> 86.18 | G30: =ROUND(C12*'[9]ACE-1.2'!H66,2) -> 1.54 | H30: =F30/B30-1 -> 0.018194707
A31: The calendar year of 2024 | B31: =D$13 -> 84.64 | C31: =B31+D31 -> 86.13 | D31: =ROUND(C12*'[9]ACE-1.2'!E83,2) -> 1.49 | E31: =C31/B31-1 -> 0.01760397 | F31: =B31+G31 -> 86.19 | G31: =ROUND(C12*'[9]ACE-1.2'!H83,2) -> 1.55 | H31: =F31/B31-1 -> 0.018312854
A33: Estimated General Service Bill Impacts
B34: Current | C34: Flat-Rate Surcharge | F34: Class-Based Surcharge
A35: Recovery Period | B35: Monthly Bill | C35: Monthly Bill | D35: Increase | E35: Percent | F35: Monthly Bill | G35: Increase | H35: Percent
A36: September 2023 | B36: =D$20 -> 175.91 | C36: =B36+D36 -> 211.9 | D36: =ROUND(C19*'[9]ACE-1.2'!E16,2) -> 35.99 | E36: =C36/B36-1 -> 0.20459326 | F36: =B36+G36 -> 215.37 | G36: =ROUND(C19*'[9]ACE-1.2'!H16,2) -> 39.46 | H36: =F36/B36-1 -> 0.22431925
A37: October 2023 | B37: =D$20 -> 175.91 | C37: =B37+D37 -> 217.45 | D37: =ROUND(C19*'[9]ACE-1.2'!E33,2) -> 41.54 | E37: =C37/B37-1 -> 0.23614348 | F37: =B37+G37 -> 223.02 | G37: =ROUND(C19*'[9]ACE-1.2'!H33,2) -> 47.11 | H37: =F37/B37-1 -> 0.2678074
A38: October 2023 through December 2023 | B38: =D$20 -> 175.91 | C38: =B38+D38 -> 189.67 | D38: =ROUND(C19*'[9]ACE-1.2'!E50,2) -> 13.76 | E38: =C38/B38-1 -> 0.078221818 | F38: =B38+G38 -> 190.01 | G38: =ROUND(C19*'[9]ACE-1.2'!H50,2) -> 14.1 | H38: =F38/B38-1 -> 0.080154625
A39: October 2023 through September 2024 | B39: =D$20 -> 175.91 | C39: =B39+D39 -> 179.16 | D39: =ROUND(C19*'[9]ACE-1.2'!E67,2) -> 3.25 | E39: =C39/B39-1 -> 0.018475357 | F39: =B39+G39 -> 178.89 | G39: =ROUND(C19*'[9]ACE-1.2'!H67,2) -> 2.98 | H39: =F39/B39-1 -> 0.016940481
A40: The calendar year of 2024 | B40: =D$20 -> 175.91 | C40: =B40+D40 -> 179.18 | D40: =ROUND(C19*'[9]ACE-1.2'!E84,2) -> 3.27 | E40: =C40/B40-1 -> 0.018589051 | F40: =B40+G40 -> 178.8 | G40: =ROUND(C19*'[9]ACE-1.2'!H84,2) -> 2.89 | H40: =F40/B40-1 -> 0.016428856
