Workbook

Sheet Cost by Light Type - IV-J-7|5
C3: 2022 RATE CASE
C4: ONCOR ELECTRIC DELIVERY COMPANY LLC
C5: INSTALLED COST OF STREET LIGHTS BY TYPE, WATTAGE, & SCHEDULE
C6: FOR THE TEST YEAR ENDING DECEMBER 31, 2021
C8: SPONSOR : Matthew A. Troxle
B11: Line # | C11: [A] | D11: [B] | E11: [C] | F11: [D]
C12: SCHEDULE A
C13: Light Type | D13: Wattage | E13: Installed Cost | F13: Basis1
B14: 1 | C14: LED Cobra Head | D14: 0 - 56 W | E14: ='Scenarios-IV-J-7|6'!H17 -> 2393.65 | F14: Scenario 22.01 ; standard installation on a 35' wood pole.
B15: =1+B14 -> 2 | C15: LED Cobra Head | D15: 56- 100 W | E15: ='Scenarios-IV-J-7|6'!H18 -> 2429.43 | F15: Scenario 22.02 ; standard installation on a 35' wood pole.
B16: =1+B15 -> 3 | C16: LED Cobra Head | D16: 101 - 140 W | E16: ='Scenarios-IV-J-7|6'!H19 -> 2635.87 | F16: Scenario 22.03 ; standard installation on a 35' wood pole.
B17: =1+B16 -> 4 | C17: LED Cobra Head | D17: 141 - 180 W | E17: ='Scenarios-IV-J-7|6'!H20 -> 2812.62 | F17: Scenario 22.04 ; standard installation on a 35' wood pole.
B18: =1+B17 -> 5 | C18: LED Cobra Head | D18: 181 - 265 W | E18: ='Scenarios-IV-J-7|6'!H21 -> 2980.99 | F18: Scenario 22.05 ; standard installation on a 35' wood pole.
B19: =1+B18 -> 6
B20: =1+B19 -> 7 | C20: MV | D20: 175 W | E20: =E14 -> 2393.65 | F20: same as Scenario 22.01
B21: =1+B20 -> 8 | C21: MV | D21: 400 W | E21: =E16 -> 2635.87 | F21: same as Scenario 22.03
B22: =1+B21 -> 9 | C22: MV | D22: 1000 W | E22: =E18 -> 2980.99 | F22: same as Scenario 22.05
B23: =1+B22 -> 10
B24: =1+B23 -> 11 | C24: HPS | D24: 100 W | E24: =E14 -> 2393.65 | F24: same as Scenario 22.01
B25: =1+B24 -> 12 | C25: HPS | D25: 150 W | E25: =E15 -> 2429.43 | F25: same as Scenario 22.02
B26: =1+B25 -> 13 | C26: HPS | D26: 200 W | E26: =E16 -> 2635.87 | F26: same as Scenario 22.03
B27: =1+B26 -> 14 | C27: HPS | D27: 250 W | E27: =E17 -> 2812.62 | F27: same as Scenario 22.04
B28: =1+B27 -> 15 | C28: HPS | D28: 400 W | E28: =E18 -> 2980.99 | F28: same as Scenario 22.05
B29: =1+B28 -> 16 | C29: HPS | D29: 1000 W | E29: =E18 -> 2980.99 | F29: same as Scenario 22.05
B30: =1+B29 -> 17
B31: =1+B30 -> 18 | C31: MH | D31: 150 W | E31: =E15 -> 2429.43 | F31: same as Scenario 22.02
B32: =1+B31 -> 19 | C32: MH | D32: 175 W | E32: =E15 -> 2429.43 | F32: same as Scenario 22.02
B33: =1+B32 -> 20 | C33: MH | D33: 250 W | E33: =E17 -> 2812.62 | F33: same as Scenario 22.04
B34: =1+B33 -> 21 | C34: MH | D34: 400 W | E34: =E18 -> 2980.99 | F34: same as Scenario 22.05
B35: =1+B34 -> 22 | C35: MH | D35: 1000 W | E35: =E18 -> 2980.99 | F35: same as Scenario 22.05
C39: 1 - The installed costs for Non-LED lights are based on the equivalent LED lights as shown in the Mercury Vapor and Metal Halide Conversion Table in the Company's Lighting Service Tariff.
H40: page break
B42: Line # | C42: [A] | D42: [B] | E42: [C] | F42: [D]
C43: HISTORICAL, RECTANGULAR, POST-TOP, and INCANDESCENT
C44: Light Type | D44: Wattage | E44: Installed Cost | F44: Basis
C47: RECTANGULAR:
B49: 23 | C49: LED Rectangular | D49: 0 - 56 W | E49: ='Scenarios-IV-J-7|6'!H24 -> 5415.74 | F49: Scenario 22.06 ; standard installation on a 30' steel pole.
B50: =1+B49 -> 24 | C50: LED Rectangular | D50: 56- 100 W | E50: ='Scenarios-IV-J-7|6'!H25 -> 5586.31 | F50: Scenario 22.07 ; standard installation on a 30' steel pole.
B51: =1+B50 -> 25 | C51: LED Rectangular | D51: 101 - 140 W | E51: ='Scenarios-IV-J-7|6'!H26 -> 5661.8 | F51: Scenario 22.08 ; standard installation on a 30' steel pole.
B52: =1+B51 -> 26 | C52: MV | D52: 175 W | E52: =E49 -> 5415.74 | F52: same as Scenario 22.06
...

Sheet Scenarios-IV-J-7|6
C5: 2022 RATE CASE
C6: ONCOR ELECTRIC DELIVERY COMPANY LLC
C7: INSTALLED COST OF STREET LIGHTS BY TYPE, WATTAGE, & SCHEDULE - INSTALLATION COST SCENARIOS
C8: FOR THE TEST YEAR ENDING DECEMBER 31, 2021
C10: SPONSOR : Matthew A. Troxle
B11: Line # | C11: [A] | D11: [B] | E11: [C] | F11: [D] | G11: [E] | H11: [F]
C12: STREET LIGHT INSTALLED COST ESTIMATES
E13: - - - - - Costs - - - - -
C14: DESCRIPTION | D14: Scenario # | E14: Material | F14: Labor | G14: 30% OH | H14: Total
B16: 1 | C16: LED Cobra Head
B17: =1+1 -> 2 | C17: 0 - 55W, LED, cobra, with arm, fuse, photocell, 35' wood pole and 120' span of 4 AL duplex | D17: 22.01 | E17: =434.62+217.14 -> 651.76 | F17: =122+1067.51 -> 1189.51 | G17: =ROUND((F17+E17)*0.3,2) -> 552.38 | H17: =SUM(E17:G17) -> 2393.65
B18: =1+B17 -> 3 | C18: 56 - 100W, LED, cobra, with arm, fuse, photocell, 35' wood pole and 120' span of 4 AL duplex | D18: 22.02 | E18: =434.62+244.66 -> 679.28 | F18: =F17 -> 1189.51 | G18: =ROUND((F18+E18)*0.3,2) -> 560.64 | H18: =SUM(E18:G18) -> 2429.43
B19: =1+B18 -> 4 | C19: 101 - 140W, LED, cobra, with arm, fuse, photocell, 35' wood pole and 120' span of 4 AL duplex | D19: 22.03 | E19: =434.62+403.46 -> 838.08 | F19: =F17 -> 1189.51 | G19: =ROUND((F19+E19)*0.3,2) -> 608.28 | H19: =SUM(E19:G19) -> 2635.87
B20: =1+B19 -> 5 | C20: 141 - 180W, LED, cobra, with arm, fuse, photocell, 35' wood pole and 120' span of 4 AL duplex | D20: 22.04 | E20: =434.62+539.42 -> 974.04 | F20: =F17 -> 1189.51 | G20: =ROUND((F20+E20)*0.3,2) -> 649.07 | H20: =SUM(E20:G20) -> 2812.62
B21: =1+B20 -> 6 | C21: 181 - 265W, LED, cobra, with arm, fuse, photocell, 35' wood pole and 120' span of 4 AL duplex | D21: 22.05 | E21: =434.62+668.94 -> 1103.56 | F21: =F17 -> 1189.51 | G21: =ROUND((F21+E21)*0.3,2) -> 687.92 | H21: =SUM(E21:G21) -> 2980.99
B23: 7 | C23: LED Rectangular
B24: =1+B23 -> 8 | C24: 0 - 55W, LED, Rectangular with fuse, photocell, 25' square steel anchor based pole, 120' span of 4 AL duplex w/ trench and conduit | D24: 22.06 | E24: =2341.96+482.83 -> 2824.79 | F24: =122+1219.16 -> 1341.16 | G24: =ROUND((F24+E24)*0.3,2) -> 1249.79 | H24: =SUM(E24:G24) -> 5415.74
B25: =1+B24 -> 9 | C25: 56- 100W, LED, Rectangular with fuse, photocell, 25' square steel anchor based pole, 120' span of 4 AL duplex w/ trench and conduit | D25: 22.07 | E25: =2341.96+614.04 -> 2956 | F25: =F24 -> 1341.16 | G25: =ROUND((F25+E25)*0.3,2) -> 1289.15 | H25: =SUM(E25:G25) -> 5586.31
B26: =1+B25 -> 10 | C26: 101 - 140W, LED, Rectangular with fuse, photocell, 25' square steel anchor based pole, 120' span of 4 AL duplex w/ trench and conduit | D26: 22.08 | E26: =2341.96+672.11 -> 3014.07 | F26: =F24 -> 1341.16 | G26: =ROUND((F26+E26)*0.3,2) -> 1306.57 | H26: =SUM(E26:G26) -> 5661.8
B28: 11 | C28: LED Post Top
B29: =1+B28 -> 12 | C29: 0 - 55W, LED, Post Top with fuse, photocell, 20' fiberglass pole, 120' span of 4 AL duplex w/ trench and conduit | D29: 22.09 | E29: =966.05+446.48 -> 1412.53 | F29: =122+1056.72 -> 1178.72 | G29: =ROUND((F29+E29)*0.3,2) -> 777.38 | H29: =SUM(E29:G29) -> 3368.63
B30: =1+B29 -> 13 | C30: 56 - 100W, LED, Post Top with fuse, photocell, 20' fiberglass pole, 120' span of 4 AL duplex w/ trench and conduit | D30: 22.10 | E30: =966.05+460.54 -> 1426.59 | F30: =F29 -> 1178.72 | G30: =ROUND((F30+E30)*0.3,2) -> 781.59 | H30: =SUM(E30:G30) -> 3386.9
B32: 14 | C32: LED Historical
B33: =1+B32 -> 15 | C33: 0 - 55W, LED, Historical with fuse, photocell, 11' AL Historical anchor based pole, 120' span of 4 AL duplex w/ trench and conduit | D33: 22.11 | E33: =2887.1+1398.96 -> 4286.06 | F33: =122+1219.16 -> 1341.16 | G33: =ROUND((F33+E33)*0.3,2) -> 1688.17 | H33: =SUM(E33:G33) -> 7315.39
B34: =1+B33 -> 16 | C34: 56 - 100W, LED, Historical with fuse, photocell, 11' AL Historical anchor based pole, 120' span of 4 AL duplex w/ trench and conduit | D34: 22.12 | E34: =MAX((2887.1+1246.56),E33) -> 4286.06 | F34: =122+1219.16 -> 1341.16 | G34: =ROUND((F34+E34)*0.3,2) -> 1688.17 | H34: =SUM(E34:G34) -> 7315.39
B36: 17 | C36: Schedule B Installations
B37: =1+B36 -> 18 | C37: 100W HPS1 (using 0-55W LED Cobra Head costs) mounted on a 30' round, steel, anchor base pole & 120' of 4 Al duplex | D37: 22.13 | E37: =2299.82+217.14 -> 2516.96 | F37: =122+1219.16 -> 1341.16 | G37: =ROUND((E37+F37)*0.3,2) -> 1157.44 | H37: =SUM(E37:G37) -> 5015.56
B38: =1+B37 -> 19 | C38: 100W HPS1 (using 0-55W LED Cobra Head costs) mounted on a 20' fiberglass base pole & 120' of 4 Al duplex w/ trench & conduit | D38: 22.14 | E38: =966.05+217.14 -> 1183.19 | F38: =122+1056.72 -> 1178.72 | G38: =ROUND((E38+F38)*0.3,2) -> 708.57 | H38: =SUM(E38:G38) -> 3070.48
B39: =1+B38 -> 20 | C39: 150W HPS1 (using 56-100W LED Cobra Head costs) mounted on a 30' round, steel, anchor base pole & 120' of 4 Al duplex | D39: 22.15 | E39: =2299.82+244.66 -> 2544.48 | F39: =122+1219.16 -> 1341.16 | G39: =ROUND((E39+F39)*0.3,2) -> 1165.69 | H39: =SUM(E39:G39) -> 5051.33
B40: =1+B39 -> 21 | C40: 200W HPS1 (using 101-140W LED Cobra Head costs) mounted on a 30' round, steel, anchor base pole & 120' of 4 Al duplex | D40: 22.16 | E40: =2299.82+403.46 -> 2703.28 | F40: =122+1219.16 -> 1341.16 | G40: =ROUND((E40+F40)*0.3,2) -> 1213.33 | H40: =SUM(E40:G40) -> 5257.77
B41: =1+B40 -> 22 | C41: 250W HPS1 (using 141-180W LED Cobra Head costs) mounted on a 30' round, steel, anchor base pole & 120' of 4 Al duplex | D41: 22.17 | E41: =2299.82+539.42 -> 2839.24 | F41: =122+1219.16 -> 1341.16 | G41: =ROUND((E41+F41)*0.3,2) -> 1254.12 | H41: =SUM(E41:G41) -> 5434.52
B42: =1+B41 -> 23 | C42: 400W HPS1 (using 181-265W LED Cobra Head costs) mounted on a 30' round, steel, anchor base pole & 120' of 4 Al duplex | D42: 22.18 | E42: =2299.82+668.94 -> 2968.76 | F42: =122+1219.16 -> 1341.16 | G42: =ROUND((E42+F42)*0.3,2) -> 1292.98 | H42: =SUM(E42:G42) -> 5602.9
C44: 1 - Also applicable to comparable non-LED lights as shown in the Mercury Vapor and Metal Halide Conversion Table in the Company's Lighting Service Tariff.
