Workbook

Sheet SL Rate Design Sch. A&B
A3: Line # | B3: [A] | C3: [B] | E3: [C] | G3: [D] | H3: [E] | I3: [F] | J3: [G] | K3: [H] | M3: [I] | N3: [J] | O3: [K] | Q3: [L] | R3: [M] | T3: [N] | U3: [O] | W3: [P] | X3: [Q] | Y3: [R] | Z3: [S] | AA3: [T] | AB3: [U] | AC3: [V] | AD3: [W] | AE3: [X] | AF3: [Y] | AG3: [Z] | AH3: [AA] | AI3: [AB] | AJ3: [AC] | AK3: [AD] | AL3: [AE] | AM3: [AF] | AN3: [AG] | AO3: [AH] | AP3: [AI] | AQ3: [AJ] | AR3: [AK] | AS3: [AL] | AT3: [AM] | AU3: [AN] | AV3: [AO] | AW3: [AP] | AX3: [AQ] | AZ3: [AR] | BA3: [AS] | BB3: [AT] | BC3: [AU] | BD3: [AV] | BE3: [AW] | BF3: [AX] | BG3: [AY] | BH3: [AZ] | BI3: [BA] | BJ3: [BB] | BK3: [BC] | BM3: [BD]
A5: 1 | G5: Schedule A | M5: Schedule A | Q5: Schedule A | T5: Schedule A | W5: Schedule A | Z5: Schedule A | AF5: Schedule A | AK5: Schedule B | AN5: Schedule B | AT5: Schedule B | AZ5: Historical | BD5: Incandescent | BE5: Rectangular | BJ5: Post Top
A6: =1+A5 -> 2 | G6: LED Cobra Head | M6: LED Rectangular | Q6: LED Post Top | T6: LED Historical | W6: Mercury Vapor | Z6: Sodium Vapor | AF6: Metal Halide | AK6: Mercury Vapor | AN6: Sodium Vapor | AT6: Metal Halide | AZ6: MV | BA6: SV | BB6: SV | BC6: MH | BE6: MV | BF6: SV | BG6: SV | BH6: MH | BI6: MH | BJ6: MV | BK6: SV
A8: 3 | C8: Line Reference | E8: Line Description | G8: 0 - 55 w | H8: 56 - 100 w | I8: 101 - 140 w | J8: 141 - 180 w | K8: 181 - 265 w | M8: 0 - 55 w | N8: 56 - 100 w | O8: 101 - 140 w | Q8: 0 - 55 w | R8: 56 - 100 w | T8: 0 - 55 w | U8: 56 - 100 w | W8: 175 w | X8: 400 w | Y8: 1000 w | Z8: 100 | AA8: 150 | AB8: 200 | AC8: 250 | AD8: 400 | AE8: 1000 | AF8: 150 | AG8: 175 | AH8: 250 | AI8: 400 | AJ8: 1000 | AK8: 175 | AL8: 400 | AM8: 1000 | AN8: 100 | AO8: 150 | AP8: 200 | AQ8: 250 | AR8: 400 | AS8: 1000 | AT8: 150 | AU8: 175 | AV8: 250 | AW8: 400 | AX8: 1000 | AZ8: 175 | BA8: 100 | BB8: 150 | BC8: 175 | BD8: all | BE8: 175 | BF8: 100 | BG8: 250 | BH8: 400 | BI8: 1000 | BJ8: 175 | BK8: 100 | BM8: Row Totals
A10: 4 | C10: [a] | E10: # of Lights on 01/03/22 | G10: 42710 | H10: 1112 | I10: 12071 | J10: 5886 | K10: 780 | M10: 57 | N10: 215 | O10: 176 | Q10: 2809 | R10: 64 | T10: 644 | U10: 1432 | W10: 6886 | X10: 1484 | Y10: 5 | Z10: 167799 | AA10: 10319 | AB10: 30851 | AC10: 35305 | AD10: 1375 | AE10: 4 | AF10: 3833 | AG10: 2234 | AH10: 1376 | AI10: 584 | AJ10: 251 | AK10: 58 | AL10: 272 | AM10: 1 | AN10: 2084 | AO10: 2001 | AP10: 5608 | AQ10: 4817 | AR10: 348 | AS10: 1 | AT10: 0 | AU10: 8 | AV10: 0 | AW10: 109 | AX10: 16 | AZ10: 32 | BA10: 254 | BB10: 62 | BC10: 14 | BD10: 23 | BE10: 40 | BF10: 58 | BG10: 31 | BH10: 58 | BI10: 92 | BJ10: 3 | BK10: 111 | BM10: =SUM(G10:BK10) -> 346363
A11: =1+A10 -> 5 | C11: [b] | E11: Fully Loaded Installed Cost | G11: ='[1]Cost by Light Type - IV-J-7|5'!$E$14 -> 2393.65 | H11: ='[1]Cost by Light Type - IV-J-7|5'!$E$15 -> 2429.43 | I11: ='[1]Cost by Light Type - IV-J-7|5'!$E$16 -> 2635.87 | J11: ='[1]Cost by Light Type - IV-J-7|5'!$E$17 -> 2812.62 | K11: ='[1]Cost by Light Type - IV-J-7|5'!$E$18 -> 2980.99 | M11: ='[1]Cost by Light Type - IV-J-7|5'!$E$49 -> 5415.74 | N11: ='[1]Cost by Light Type - IV-J-7|5'!$E$50 -> 5586.31 | O11: ='[1]Cost by Light Type - IV-J-7|5'!$E$51 -> 5661.8 | Q11: ='[1]Cost by Light Type - IV-J-7|5'!$E$60 -> 3368.63 | R11: ='[1]Cost by Light Type - IV-J-7|5'!$E$61 -> 3386.9 | T11: ='[1]Cost by Light Type - IV-J-7|5'!$E$68 -> 7315.39 | U11: ='[1]Cost by Light Type - IV-J-7|5'!$E$69 -> 7315.39 | W11: =G11 -> 2393.65 | X11: =I11 -> 2635.87 | Y11: =K11 -> 2980.99 | Z11: =G11 -> 2393.65 | AA11: =H11 -> 2429.43 | AB11: =I11 -> 2635.87 | AC11: =J11 -> 2812.62 | AD11: =K11 -> 2980.99 | AE11: =K11 -> 2980.99 | AF11: =H11 -> 2429.43 | AG11: =H11 -> 2429.43 | AH11: =J11 -> 2812.62 | AI11: =K11 -> 2980.99 | AJ11: =K11 -> 2980.99 | AK11: =AN11 -> 4238 | AL11: =AP11 -> 5257.77 | AM11: =AR11 -> 5602.9 | AN11: ='[1]Cost by Light Type - IV-J-7|5'!$E$85 -> 4238 | AO11: ='[1]Cost by Light Type - IV-J-7|5'!$E$86 -> 5051.33 | AP11: ='[1]Cost by Light Type - IV-J-7|5'!$E$87 -> 5257.77 | AQ11: ='[1]Cost by Light Type - IV-J-7|5'!$E$88 -> 5434.52 | AR11: ='[1]Cost by Light Type - IV-J-7|5'!$E$89 -> 5602.9 | AS11: ='[1]Cost by Light Type - IV-J-7|5'!$E$90 -> 5602.9 | AT11: =AO11 -> 5051.33 | AU11: =AO11 -> 5051.33 | AV11: =AQ11 -> 5434.52 | AW11: =AR11 -> 5602.9 | AX11: =AS11 -> 5602.9 | AZ11: =T11 -> 7315.39 | BA11: =T11 -> 7315.39 | BB11: =U11 -> 7315.39 | BC11: =U11 -> 7315.39 | BD11: =G11 -> 2393.65 | BE11: =M11 -> 5415.74 | BF11: =M11 -> 5415.74 | BG11: =O11 -> 5661.8 | BH11: =O11 -> 5661.8 | BI11: =O11 -> 5661.8 | BJ11: =Q11 -> 3368.63 | BK11: =BJ11 -> 3368.63
A12: =1+A11 -> 6 | C12: [c] | E12: Monthly kWh Usage | G12: 15 | H12: 30 | I12: 45 | J12: 55 | K12: 80 | M12: 15 | N12: 30 | O12: 45 | Q12: 15 | R12: 30 | T12: 15 | U12: 30 | W12: 70 | X12: 150 | Y12: 370 | Z12: 40 | AA12: 70 | AB12: 80 | AC12: 100 | AD12: 160 | AE12: 375 | AF12: 65 | AG12: 65 | AH12: 100 | AI12: 160 | AJ12: 370 | AK12: 70 | AL12: 150 | AM12: 370 | AN12: 40 | AO12: 70 | AP12: 80 | AQ12: 100 | AR12: 160 | AS12: 375 | AT12: 65 | AU12: 65 | AV12: 100 | AW12: 160 | AX12: 370 | AZ12: =+W12 -> 70 | BA12: =+Z12 -> 40 | BB12: =+AA12 -> 70 | BC12: =+AG12 -> 65 | BD12: =+BA12 -> 40 | BE12: =+AZ12 -> 70 | BF12: =+BA12 -> 40 | BG12: =+AC12 -> 100 | BH12: =+AI12 -> 160 | BI12: =+AJ12 -> 370 | BJ12: =+BE12 -> 70 | BK12: =+BF12 -> 40
A14: 7 | B14: Allocation of the Unmetered SL Rev. Requirement to each light type and wattage - by Cost Component :
A16: 8 | B16: Installed Cost - Based Revenue Requirement :
A18: 9 | C18: [d] = [b] / [b55w LED_CH] | E18: Normalization Factor (NF)1 | G18: 1 | H18: =ROUND(H11/$G$11,6) -> 1.014948 | I18: =ROUND(I11/$G$11,6) -> 1.101193 | J18: =ROUND(J11/$G$11,6) -> 1.175034 | K18: =ROUND(K11/$G$11,6) -> 1.245374 | M18: =ROUND(M11/$G$11,6) -> 2.262545 | N18: =ROUND(N11/$G$11,6) -> 2.333804 | O18: =ROUND(O11/$G$11,6) -> 2.365342 | Q18: =ROUND(Q11/$G$11,6) -> 1.407319 | R18: =ROUND(R11/$G$11,6) -> 1.414952 | T18: =ROUND(T11/$G$11,6) -> 3.056165 | U18: =ROUND(U11/$G$11,6) -> 3.056165 | W18: =ROUND(W11/$G$11,6) -> 1 | X18: =ROUND(X11/$G$11,6) -> 1.101193 | Y18: =ROUND(Y11/$G$11,6) -> 1.245374 | Z18: =ROUND(Z11/$G$11,6) -> 1 | AA18: =ROUND(AA11/$G$11,6) -> 1.014948 | AB18: =ROUND(AB11/$G$11,6) -> 1.101193 | AC18: =ROUND(AC11/$G$11,6) -> 1.175034 | AD18: =ROUND(AD11/$G$11,6) -> 1.245374 | ... AX18: =ROUND(AX11/$G$11,6) -> 2.340735 | AZ18: =ROUND(AZ11/$G$11,6) -> 3.056165 | BA18: =ROUND(BA11/$G$11,6) -> 3.056165 | BB18: =ROUND(BB11/$G$11,6) -> 3.056165 | BC18: =ROUND(BC11/$G$11,6) -> 3.056165 | BD18: =ROUND(BD11/$G$11,6) -> 1 | BE18: =ROUND(BE11/$G$11,6) -> 2.262545 | BF18: =ROUND(BF11/$G$11,6) -> 2.262545 | BG18: =ROUND(BG11/$G$11,6) -> 2.365342 | ... BK18: =ROUND(BK11/$G$11,6) -> 1.407319
A19: =1+A18 -> 10 | C19: [d1] = [a] * [d] | E19: Weighted NF | G19: =ROUND(G10*G18,4) -> 42710 | H19: =ROUND(H10*H18,4) -> 1128.6222 | I19: =ROUND(I10*I18,4) -> 13292.501 | J19: =ROUND(J10*J18,4) -> 6916.2501 | K19: =ROUND(K10*K18,4) -> 971.3917 | M19: =ROUND(M10*M18,4) -> 128.9651 | N19: =ROUND(N10*N18,4) -> 501.7679 | O19: =ROUND(O10*O18,4) -> 416.3002 | Q19: =ROUND(Q10*Q18,4) -> 3953.1591 | R19: =ROUND(R10*R18,4) -> 90.5569 | T19: =ROUND(T10*T18,4) -> 1968.1703 | U19: =ROUND(U10*U18,4) -> 4376.4283 | W19: =ROUND(W10*W18,4) -> 6886 | X19: =ROUND(X10*X18,4) -> 1634.1704 | Y19: =ROUND(Y10*Y18,4) -> 6.2269 | Z19: =ROUND(Z10*Z18,4) -> 167799 | AA19: =ROUND(AA10*AA18,4) -> 10473.248 | AB19: =ROUND(AB10*AB18,4) -> 33972.905 | AC19: =ROUND(AC10*AC18,4) -> 41484.575 | AD19: =ROUND(AD10*AD18,4) -> 1712.3893 | ... AX19: =ROUND(AX10*AX18,4) -> 37.4518 | AZ19: =ROUND(AZ10*AZ18,4) -> 97.7973 | BA19: =ROUND(BA10*BA18,4) -> 776.2659 | BB19: =ROUND(BB10*BB18,4) -> 189.4822 | BC19: =ROUND(BC10*BC18,4) -> 42.7863 | BD19: =ROUND(BD10*BD18,4) -> 23 | BE19: =ROUND(BE10*BE18,4) -> 90.5018 | BF19: =ROUND(BF10*BF18,4) -> 131.2276 | BG19: =ROUND(BG10*BG18,4) -> 73.3256 | ... BK19: =ROUND(BK10*BK18,4) -> 156.2124 | BM19: =SUM(G19:BK19) -> 384177.73
A20: =1+A19 -> 11 | C20: [d2] = [d1] / ∑[d1] | E20: % of Total Weighted NF | G20: =ROUND(G19/$BM$19,6) -> 0.111173 | H20: =ROUND(H19/$BM$19,6) -> 0.002938 | I20: =ROUND(I19/$BM$19,6) -> 0.0346 | J20: =ROUND(J19/$BM$19,6) -> 0.018003 | K20: =ROUND(K19/$BM$19,6) -> 0.002528 | M20: =ROUND(M19/$BM$19,6) -> 0.000336 | N20: =ROUND(N19/$BM$19,6) -> 0.001306 | O20: =ROUND(O19/$BM$19,6) -> 0.001084 | Q20: =ROUND(Q19/$BM$19,6) -> 0.01029 | R20: =ROUND(R19/$BM$19,6) -> 0.000236 | T20: =ROUND(T19/$BM$19,6) -> 0.005123 | U20: =ROUND(U19/$BM$19,6) -> 0.011392 | W20: =ROUND(W19/$BM$19,6) -> 0.017924 | X20: =ROUND(X19/$BM$19,6) -> 0.004254 | Y20: =ROUND(Y19/$BM$19,6) -> 1.6e-05 | Z20: =ROUND(Z19/$BM$19,6) -> 0.436774 | AA20: =ROUND(AA19/$BM$19,6) -> 0.027261 | AB20: =ROUND(AB19/$BM$19,6) -> 0.08843 | AC20: =ROUND(AC19/$BM$19,6) -> 0.107983 | AD20: =ROUND(AD19/$BM$19,6) -> 0.004457 | ... AX20: =ROUND(AX19/$BM$19,6) -> 9.7e-05 | AZ20: =ROUND(AZ19/$BM$19,6) -> 0.000255 | BA20: =ROUND(BA19/$BM$19,6) -> 0.002021 | BB20: =ROUND(BB19/$BM$19,6) -> 0.000493 | BC20: =ROUND(BC19/$BM$19,6) -> 0.000111 | BD20: =ROUND(BD19/$BM$19,6) -> 6e-05 | BE20: =ROUND(BE19/$BM$19,6) -> 0.000236 | BF20: =ROUND(BF19/$BM$19,6) -> 0.000342 | BG20: =ROUND(BG19/$BM$19,6) -> 0.000191 | ... BK20: =ROUND(BK19/$BM$19,6) -> 0.000407 | BM20: =SUM(G20:BK20) -> 1.000001 | BN20: check - cells below should be less than $100 +/-
A21: =1+A20 -> 12 | C21: [d3] = [d2] * Installed Cost-Based Rev. Req.2 | E21: Weighted Cost | G21: =ROUND(G20*'Revenue Req.'!$H$28,0) -> 3649672 | H21: =ROUND(H20*'Revenue Req.'!$H$28,0) -> 96451 | I21: =ROUND(I20*'Revenue Req.'!$H$28,0) -> 1135875 | J21: =ROUND(J20*'Revenue Req.'!$H$28,0) -> 591016 | K21: =ROUND(K20*'Revenue Req.'!$H$28,0) -> 82991 | M21: =ROUND(M20*'Revenue Req.'!$H$28,0) -> 11030 | N21: =ROUND(N20*'Revenue Req.'!$H$28,0) -> 42874 | O21: =ROUND(O20*'Revenue Req.'!$H$28,0) -> 35586 | Q21: =ROUND(Q20*'Revenue Req.'!$H$28,0) -> 337808 | R21: =ROUND(R20*'Revenue Req.'!$H$28,0) -> 7748 | T21: =ROUND(T20*'Revenue Req.'!$H$28,0) -> 168182 | U21: =ROUND(U20*'Revenue Req.'!$H$28,0) -> 373985 | W21: =ROUND(W20*'Revenue Req.'!$H$28,0) -> 588423 | X21: =ROUND(X20*'Revenue Req.'!$H$28,0) -> 139654 | Y21: =ROUND(Y20*'Revenue Req.'!$H$28,0) -> 525 | Z21: =ROUND(Z20*'Revenue Req.'!$H$28,0) -> 14338750 | AA21: =ROUND(AA20*'Revenue Req.'!$H$28,0) -> 894945 | AB21: =ROUND(AB20*'Revenue Req.'!$H$28,0) -> 2903048 | AC21: =ROUND(AC20*'Revenue Req.'!$H$28,0) -> 3544948 | AD21: =ROUND(AD20*'Revenue Req.'!$H$28,0) -> 146318 | ... AX21: =ROUND(AX20*'Revenue Req.'!$H$28,0) -> 3184 | AZ21: =ROUND(AZ20*'Revenue Req.'!$H$28,0) -> 8371 | BA21: =ROUND(BA20*'Revenue Req.'!$H$28,0) -> 66347 | BB21: =ROUND(BB20*'Revenue Req.'!$H$28,0) -> 16185 | BC21: =ROUND(BC20*'Revenue Req.'!$H$28,0) -> 3644 | BD21: =ROUND(BD20*'Revenue Req.'!$H$28,0) -> 1970 | BE21: =ROUND(BE20*'Revenue Req.'!$H$28,0) -> 7748 | BF21: =ROUND(BF20*'Revenue Req.'!$H$28,0) -> 11227 | BG21: =ROUND(BG20*'Revenue Req.'!$H$28,0) -> 6270 | ... BK21: =ROUND(BK20*'Revenue Req.'!$H$28,0) -> 13361 | BM21: =SUM(G21:BK21) -> 32828793 | BN21: =+BM21-'Revenue Req.'!H28 -> 30
A23: 13 | B23: Load - Based Revenue Requirement :
A24: =1+A23 -> 14
A25: 14 | C25: [e] = [c] / [c55w LED_CH] | E25: Normalization Factor (NF)3 | G25: 1 | H25: =ROUND(H12/$G$12,6) -> 2 | I25: =ROUND(I12/$G$12,6) -> 3 | J25: =ROUND(J12/$G$12,6) -> 3.666667 | K25: =ROUND(K12/$G$12,6) -> 5.333333 | M25: =ROUND(M12/$G$12,6) -> 1 | N25: =ROUND(N12/$G$12,6) -> 2 | O25: =ROUND(O12/$G$12,6) -> 3 | P25: =ROUND(P12/$G$12,6) -> 0 | Q25: =ROUND(Q12/$G$12,6) -> 1 | R25: =ROUND(R12/$G$12,6) -> 2 | T25: =ROUND(T12/$G$12,6) -> 1 | U25: =ROUND(U12/$G$12,6) -> 2 | W25: =ROUND(W12/$G$12,6) -> 4.666667 | X25: =ROUND(X12/$G$12,6) -> 10 | Y25: =ROUND(Y12/$G$12,6) -> 24.666667 | Z25: =ROUND(Z12/$G$12,6) -> 2.666667 | AA25: =ROUND(AA12/$G$12,6) -> 4.666667 | AB25: =ROUND(AB12/$G$12,6) -> 5.333333 | AC25: =ROUND(AC12/$G$12,6) -> 6.666667 | AD25: =ROUND(AD12/$G$12,6) -> 10.666667 | ... AX25: =ROUND(AX12/$G$12,6) -> 24.666667 | AZ25: =ROUND(AZ12/$G$12,6) -> 4.666667 | BA25: =ROUND(BA12/$G$12,6) -> 2.666667 | BB25: =ROUND(BB12/$G$12,6) -> 4.666667 | BC25: =ROUND(BC12/$G$12,6) -> 4.333333 | BD25: =ROUND(BD12/$G$12,6) -> 2.666667 | BE25: =ROUND(BE12/$G$12,6) -> 4.666667 | BF25: =ROUND(BF12/$G$12,6) -> 2.666667 | BG25: =ROUND(BG12/$G$12,6) -> 6.666667 | ... BK25: =ROUND(BK12/$G$12,6) -> 2.666667
A26: =1+A25 -> 15 | C26: [e1] = [a] * [e] | E26: Weighted NF | G26: =ROUND(G10*G25,4) -> 42710 | H26: =ROUND(H10*H25,4) -> 2224 | I26: =ROUND(I10*I25,4) -> 36213 | J26: =ROUND(J10*J25,4) -> 21582.002 | K26: =ROUND(K10*K25,4) -> 4159.9997 | M26: =ROUND(M10*M25,4) -> 57 | N26: =ROUND(N10*N25,4) -> 430 | O26: =ROUND(O10*O25,4) -> 528 | Q26: =ROUND(Q10*Q25,4) -> 2809 | R26: =ROUND(R10*R25,4) -> 128 | T26: =ROUND(T10*T25,4) -> 644 | U26: =ROUND(U10*U25,4) -> 2864 | W26: =ROUND(W10*W25,4) -> 32134.669 | X26: =ROUND(X10*X25,4) -> 14840 | Y26: =ROUND(Y10*Y25,4) -> 123.3333 | Z26: =ROUND(Z10*Z25,4) -> 447464.06 | AA26: =ROUND(AA10*AA25,4) -> 48155.337 | AB26: =ROUND(AB10*AB25,4) -> 164538.66 | AC26: =ROUND(AC10*AC25,4) -> 235366.68 | AD26: =ROUND(AD10*AD25,4) -> 14666.667 | ... AX26: =ROUND(AX10*AX25,4) -> 394.6667 | AZ26: =ROUND(AZ10*AZ25,4) -> 149.3333 | BA26: =ROUND(BA10*BA25,4) -> 677.3334 | BB26: =ROUND(BB10*BB25,4) -> 289.3334 | BC26: =ROUND(BC10*BC25,4) -> 60.6667 | BD26: =ROUND(BD10*BD25,4) -> 61.3333 | BE26: =ROUND(BE10*BE25,4) -> 186.6667 | BF26: =ROUND(BF10*BF25,4) -> 154.6667 | BG26: =ROUND(BG10*BG25,4) -> 206.6667 | ... BK26: =ROUND(BK10*BK25,4) -> 296 | BM26: =SUM(G26:BK26) -> 1209869.1
A27: =1+A26 -> 16 | C27: [e2] = [e1] / ∑[e1] | E27: % of Total Weighted NF | G27: =ROUND(G26/$BM26,6) -> 0.035301 | H27: =ROUND(H26/$BM26,6) -> 0.001838 | I27: =ROUND(I26/$BM26,6) -> 0.029931 | J27: =ROUND(J26/$BM26,6) -> 0.017838 | K27: =ROUND(K26/$BM26,6) -> 0.003438 | M27: =ROUND(M26/$BM26,6) -> 4.7e-05 | N27: =ROUND(N26/$BM26,6) -> 0.000355 | O27: =ROUND(O26/$BM26,6) -> 0.000436 | Q27: =ROUND(Q26/$BM26,6) -> 0.002322 | R27: =ROUND(R26/$BM26,6) -> 0.000106 | T27: =ROUND(T26/$BM26,6) -> 0.000532 | U27: =ROUND(U26/$BM26,6) -> 0.002367 | W27: =ROUND(W26/$BM26,6) -> 0.02656 | X27: =ROUND(X26/$BM26,6) -> 0.012266 | Y27: =ROUND(Y26/$BM26,6) -> 0.000102 | Z27: =ROUND(Z26/$BM26,6) -> 0.369845 | AA27: =ROUND(AA26/$BM26,6) -> 0.039802 | AB27: =ROUND(AB26/$BM26,6) -> 0.135997 | AC27: =ROUND(AC26/$BM26,6) -> 0.194539 | AD27: =ROUND(AD26/$BM26,6) -> 0.012123 | ... AX27: =ROUND(AX26/$BM26,6) -> 0.000326 | AZ27: =ROUND(AZ26/$BM26,6) -> 0.000123 | BA27: =ROUND(BA26/$BM26,6) -> 0.00056 | BB27: =ROUND(BB26/$BM26,6) -> 0.000239 | BC27: =ROUND(BC26/$BM26,6) -> 5e-05 | BD27: =ROUND(BD26/$BM26,6) -> 5.1e-05 | BE27: =ROUND(BE26/$BM26,6) -> 0.000154 | BF27: =ROUND(BF26/$BM26,6) -> 0.000128 | BG27: =ROUND(BG26/$BM26,6) -> 0.000171 | ... BK27: =ROUND(BK26/$BM26,6) -> 0.000245 | BM27: =SUM(G27:BK27) -> 0.999997
A28: =1+A27 -> 17 | C28: [e3] = [e2] * Load-Based Rev. Req.2 | E28: Weighted Cost | G28: =ROUND(G27*'Revenue Req.'!$J$28,0) -> 117577 | H28: =ROUND(H27*'Revenue Req.'!$J$28,0) -> 6122 | I28: =ROUND(I27*'Revenue Req.'!$J$28,0) -> 99691 | J28: =ROUND(J27*'Revenue Req.'!$J$28,0) -> 59413 | K28: =ROUND(K27*'Revenue Req.'!$J$28,0) -> 11451 | M28: =ROUND(M27*'Revenue Req.'!$J$28,0) -> 157 | N28: =ROUND(N27*'Revenue Req.'!$J$28,0) -> 1182 | O28: =ROUND(O27*'Revenue Req.'!$J$28,0) -> 1452 | Q28: =ROUND(Q27*'Revenue Req.'!$J$28,0) -> 7734 | R28: =ROUND(R27*'Revenue Req.'!$J$28,0) -> 353 | T28: =ROUND(T27*'Revenue Req.'!$J$28,0) -> 1772 | U28: =ROUND(U27*'Revenue Req.'!$J$28,0) -> 7884 | W28: =ROUND(W27*'Revenue Req.'!$J$28,0) -> 88463 | X28: =ROUND(X27*'Revenue Req.'!$J$28,0) -> 40854 | Y28: =ROUND(Y27*'Revenue Req.'!$J$28,0) -> 340 | Z28: =ROUND(Z27*'Revenue Req.'!$J$28,0) -> 1231841 | AA28: =ROUND(AA27*'Revenue Req.'!$J$28,0) -> 132568 | AB28: =ROUND(AB27*'Revenue Req.'!$J$28,0) -> 452965 | AC28: =ROUND(AC27*'Revenue Req.'!$J$28,0) -> 647950 | AD28: =ROUND(AD27*'Revenue Req.'!$J$28,0) -> 40378 | ... AX28: =ROUND(AX27*'Revenue Req.'!$J$28,0) -> 1086 | AZ28: =ROUND(AZ27*'Revenue Req.'!$J$28,0) -> 410 | BA28: =ROUND(BA27*'Revenue Req.'!$J$28,0) -> 1865 | BB28: =ROUND(BB27*'Revenue Req.'!$J$28,0) -> 796 | BC28: =ROUND(BC27*'Revenue Req.'!$J$28,0) -> 167 | BD28: =ROUND(BD27*'Revenue Req.'!$J$28,0) -> 170 | BE28: =ROUND(BE27*'Revenue Req.'!$J$28,0) -> 513 | BF28: =ROUND(BF27*'Revenue Req.'!$J$28,0) -> 426 | BG28: =ROUND(BG27*'Revenue Req.'!$J$28,0) -> 570 | ... BK28: =ROUND(BK27*'Revenue Req.'!$J$28,0) -> 816 | BM28: =SUM(G28:BK28) -> 3330687 | BN28: =+BM28-'Revenue Req.'!J28 -> -8
A30: 18 | B30: Maintenance - Based Revenue Requirement :
A31: =1+A30 -> 19
A32: 19 | C32: [f] | E32: Normalization Factor (NF)4 | G32: 1 | H32: =ROUND(0.6*$G$32+0.4*H11/$G$11,6) -> 1.005979 | I32: =ROUND(0.6*$G$32+0.4*I11/$G$11,6) -> 1.040477 | J32: =ROUND(0.6*$G$32+0.4*J11/$G$11,6) -> 1.070014 | K32: =ROUND(0.6*$G$32+0.4*K11/$G$11,6) -> 1.09815 | M32: =ROUND(0.6*$G$32+0.4*M11/$G$11,6) -> 1.505018 | N32: =ROUND(0.6*$G$32+0.4*N11/$G$11,6) -> 1.533522 | O32: =ROUND(0.6*$G$32+0.4*O11/$G$11,6) -> 1.546137 | P32: =ROUND(0.6*$G$32+0.4*P11/$G$11,6) -> 0.6 | Q32: =ROUND(0.6*$G$32+0.4*Q11/$G$11,6) -> 1.162928 | R32: =ROUND(0.6*$G$32+0.4*R11/$G$11,6) -> 1.165981 | T32: =ROUND(0.6*$G$32+0.4*T11/$G$11,6) -> 1.822466 | U32: =ROUND(0.6*$G$32+0.4*U11/$G$11,6) -> 1.822466 | W32: =ROUND(0.6*$G$32+0.4*W11/$G$11,6) -> 1 | X32: =ROUND(0.6*$G$32+0.4*X11/$G$11,6) -> 1.040477 | Y32: =ROUND(0.6*$G$32+0.4*Y11/$G$11,6) -> 1.09815 | Z32: =ROUND(0.6*$G$32+0.4*Z11/$G$11,6) -> 1 | AA32: =ROUND(0.6*$G$32+0.4*AA11/$G$11,6) -> 1.005979 | AB32: =ROUND(0.6*$G$32+0.4*AB11/$G$11,6) -> 1.040477 | AC32: =ROUND(0.6*$G$32+0.4*AC11/$G$11,6) -> 1.070014 | AD32: =ROUND(0.6*$G$32+0.4*AD11/$G$11,6) -> 1.09815 | ... AX32: =ROUND(0.6*$G$32+0.4*AX11/$G$11,6) -> 1.536294 | AZ32: =ROUND(0.6*$G$32+0.4*AZ11/$G$11,6) -> 1.822466 | BA32: =ROUND(0.6*$G$32+0.4*BA11/$G$11,6) -> 1.822466 | BB32: =ROUND(0.6*$G$32+0.4*BB11/$G$11,6) -> 1.822466 | BC32: =ROUND(0.6*$G$32+0.4*BC11/$G$11,6) -> 1.822466 | BD32: =ROUND(0.6*$G$32+0.4*BD11/$G$11,6) -> 1 | BE32: =ROUND(0.6*$G$32+0.4*BE11/$G$11,6) -> 1.505018 | BF32: =ROUND(0.6*$G$32+0.4*BF11/$G$11,6) -> 1.505018 | BG32: =ROUND(0.6*$G$32+0.4*BG11/$G$11,6) -> 1.546137 | ... BK32: =ROUND(0.6*$G$32+0.4*BK11/$G$11,6) -> 1.162928 | BM32: =SUM(G32:BK32) -> 69.970776
A33: =1+A32 -> 20 | C33: [f1] = [a] * [f] | E33: Weighted NF | G33: =ROUND(G$10*G32,4) -> 42710 | H33: =ROUND(H$10*H32,4) -> 1118.6486 | I33: =ROUND(I$10*I32,4) -> 12559.598 | J33: =ROUND(J$10*J32,4) -> 6298.1024 | K33: =ROUND(K$10*K32,4) -> 856.557 | M33: =ROUND(M$10*M32,4) -> 85.786 | N33: =ROUND(N$10*N32,4) -> 329.7072 | O33: =ROUND(O$10*O32,4) -> 272.1201 | Q33: =ROUND(Q$10*Q32,4) -> 3266.6648 | R33: =ROUND(R$10*R32,4) -> 74.6228 | T33: =ROUND(T$10*T32,4) -> 1173.6681 | U33: =ROUND(U$10*U32,4) -> 2609.7713 | W33: =ROUND(W$10*W32,4) -> 6886 | X33: =ROUND(X$10*X32,4) -> 1544.0679 | Y33: =ROUND(Y$10*Y32,4) -> 5.4908 | Z33: =ROUND(Z$10*Z32,4) -> 167799 | AA33: =ROUND(AA$10*AA32,4) -> 10380.697 | AB33: =ROUND(AB$10*AB32,4) -> 32099.756 | AC33: =ROUND(AC$10*AC32,4) -> 37776.844 | AD33: =ROUND(AD$10*AD32,4) -> 1509.9563 | ... AX33: =ROUND(AX$10*AX32,4) -> 24.5807 | AZ33: =ROUND(AZ$10*AZ32,4) -> 58.3189 | BA33: =ROUND(BA$10*BA32,4) -> 462.9064 | BB33: =ROUND(BB$10*BB32,4) -> 112.9929 | BC33: =ROUND(BC$10*BC32,4) -> 25.5145 | BD33: =ROUND(BD$10*BD32,4) -> 23 | BE33: =ROUND(BE$10*BE32,4) -> 60.2007 | BF33: =ROUND(BF$10*BF32,4) -> 87.291 | BG33: =ROUND(BG$10*BG32,4) -> 47.9302 | ... BK33: =ROUND(BK$10*BK32,4) -> 129.085 | BM33: =SUM(G33:BK33) -> 361488.9
A34: =1+A33 -> 21 | C34: [f2] = [f1] / ∑[f1] | E34: % of Total Weighted NF | G34: =ROUND(G33/$BM33,6) -> 0.11815 | H34: =ROUND(H33/$BM33,6) -> 0.003095 | I34: =ROUND(I33/$BM33,6) -> 0.034744 | J34: =ROUND(J33/$BM33,6) -> 0.017423 | K34: =ROUND(K33/$BM33,6) -> 0.00237 | M34: =ROUND(M33/$BM33,6) -> 0.000237 | N34: =ROUND(N33/$BM33,6) -> 0.000912 | O34: =ROUND(O33/$BM33,6) -> 0.000753 | Q34: =ROUND(Q33/$BM33,6) -> 0.009037 | R34: =ROUND(R33/$BM33,6) -> 0.000206 | T34: =ROUND(T33/$BM33,6) -> 0.003247 | U34: =ROUND(U33/$BM33,6) -> 0.00722 | W34: =ROUND(W33/$BM33,6) -> 0.019049 | X34: =ROUND(X33/$BM33,6) -> 0.004271 | Y34: =ROUND(Y33/$BM33,6) -> 1.5e-05 | Z34: =ROUND(Z33/$BM33,6) -> 0.464189 | AA34: =ROUND(AA33/$BM33,6) -> 0.028717 | AB34: =ROUND(AB33/$BM33,6) -> 0.088799 | AC34: =ROUND(AC33/$BM33,6) -> 0.104503 | AD34: =ROUND(AD33/$BM33,6) -> 0.004177 | ... AX34: =ROUND(AX33/$BM33,6) -> 6.8e-05 | AZ34: =ROUND(AZ33/$BM33,6) -> 0.000161 | BA34: =ROUND(BA33/$BM33,6) -> 0.001281 | BB34: =ROUND(BB33/$BM33,6) -> 0.000313 | BC34: =ROUND(BC33/$BM33,6) -> 7.1e-05 | BD34: =ROUND(BD33/$BM33,6) -> 6.4e-05 | BE34: =ROUND(BE33/$BM33,6) -> 0.000167 | BF34: =ROUND(BF33/$BM33,6) -> 0.000241 | BG34: =ROUND(BG33/$BM33,6) -> 0.000133 | ... BK34: =ROUND(BK33/$BM33,6) -> 0.000357 | BM34: =SUM(G34:BK34) -> 1.000004
A35: =1+A34 -> 22 | C35: [f3] = [f2] * Maint-Based Rev. Req.2 | E35: Weighted Cost | G35: =ROUND(G34*'Revenue Req.'!$P$28,0) -> 935433 | H35: =ROUND(H34*'Revenue Req.'!$P$28,0) -> 24504 | I35: =ROUND(I34*'Revenue Req.'!$P$28,0) -> 275080 | J35: =ROUND(J34*'Revenue Req.'!$P$28,0) -> 137944 | K35: =ROUND(K34*'Revenue Req.'!$P$28,0) -> 18764 | M35: =ROUND(M34*'Revenue Req.'!$P$28,0) -> 1876 | N35: =ROUND(N34*'Revenue Req.'!$P$28,0) -> 7221 | O35: =ROUND(O34*'Revenue Req.'!$P$28,0) -> 5962 | Q35: =ROUND(Q34*'Revenue Req.'!$P$28,0) -> 71549 | R35: =ROUND(R34*'Revenue Req.'!$P$28,0) -> 1631 | T35: =ROUND(T34*'Revenue Req.'!$P$28,0) -> 25708 | U35: =ROUND(U34*'Revenue Req.'!$P$28,0) -> 57163 | W35: =ROUND(W34*'Revenue Req.'!$P$28,0) -> 150817 | X35: =ROUND(X34*'Revenue Req.'!$P$28,0) -> 33815 | Y35: =ROUND(Y34*'Revenue Req.'!$P$28,0) -> 119 | Z35: =ROUND(Z34*'Revenue Req.'!$P$28,0) -> 3675139 | AA35: =ROUND(AA34*'Revenue Req.'!$P$28,0) -> 227362 | AB35: =ROUND(AB34*'Revenue Req.'!$P$28,0) -> 703051 | AC35: =ROUND(AC34*'Revenue Req.'!$P$28,0) -> 827385 | AD35: =ROUND(AD34*'Revenue Req.'!$P$28,0) -> 33071 | ... AX35: =ROUND(AX34*'Revenue Req.'!$P$28,0) -> 538 | AZ35: =ROUND(AZ34*'Revenue Req.'!$P$28,0) -> 1275 | BA35: =ROUND(BA34*'Revenue Req.'!$P$28,0) -> 10142 | BB35: =ROUND(BB34*'Revenue Req.'!$P$28,0) -> 2478 | BC35: =ROUND(BC34*'Revenue Req.'!$P$28,0) -> 562 | BD35: =ROUND(BD34*'Revenue Req.'!$P$28,0) -> 507 | BE35: =ROUND(BE34*'Revenue Req.'!$P$28,0) -> 1322 | BF35: =ROUND(BF34*'Revenue Req.'!$P$28,0) -> 1908 | BG35: =ROUND(BG34*'Revenue Req.'!$P$28,0) -> 1053 | ... BK35: =ROUND(BK34*'Revenue Req.'!$P$28,0) -> 2826 | BM35: =SUM(G35:BK35) -> 7917366 | BN35: =+BM35-'Revenue Req.'!P28 -> 32
A37: 23 | B37: Per Light - Based Revenue Requirement :
A39: 24 | C39: [g] = [a] / ∑[a] | E39: % of Total # of Lights | G39: =ROUND(G10/$BM10,6) -> 0.12331 | H39: =ROUND(H10/$BM10,6) -> 0.003211 | I39: =ROUND(I10/$BM10,6) -> 0.034851 | J39: =ROUND(J10/$BM10,6) -> 0.016994 | K39: =ROUND(K10/$BM10,6) -> 0.002252 | M39: =ROUND(M10/$BM10,6) -> 0.000165 | N39: =ROUND(N10/$BM10,6) -> 0.000621 | O39: =ROUND(O10/$BM10,6) -> 0.000508 | Q39: =ROUND(Q10/$BM10,6) -> 0.00811 | R39: =ROUND(R10/$BM10,6) -> 0.000185 | T39: =ROUND(T10/$BM10,6) -> 0.001859 | U39: =ROUND(U10/$BM10,6) -> 0.004134 | W39: =ROUND(W10/$BM10,6) -> 0.019881 | X39: =ROUND(X10/$BM10,6) -> 0.004285 | Y39: =ROUND(Y10/$BM10,6) -> 1.4e-05 | Z39: =ROUND(Z10/$BM10,6) -> 0.48446 | AA39: =ROUND(AA10/$BM10,6) -> 0.029792 | AB39: =ROUND(AB10/$BM10,6) -> 0.089071 | AC39: =ROUND(AC10/$BM10,6) -> 0.101931 | AD39: =ROUND(AD10/$BM10,6) -> 0.00397 | ... AX39: =ROUND(AX10/$BM10,6) -> 4.6e-05 | AZ39: =ROUND(AZ10/$BM10,6) -> 9.2e-05 | BA39: =ROUND(BA10/$BM10,6) -> 0.000733 | BB39: =ROUND(BB10/$BM10,6) -> 0.000179 | BC39: =ROUND(BC10/$BM10,6) -> 4e-05 | BD39: =ROUND(BD10/$BM10,6) -> 6.6e-05 | BE39: =ROUND(BE10/$BM10,6) -> 0.000115 | BF39: =ROUND(BF10/$BM10,6) -> 0.000167 | BG39: =ROUND(BG10/$BM10,6) -> 9e-05 | ... BK39: =ROUND(BK10/$BM10,6) -> 0.00032 | BM39: =SUM(G39:BK39) -> 0.999999
A40: =1+A39 -> 25 | C40: [g1] = [g] * Per Light-Based Rev. Req.2 | E40: Weighted Cost | G40: =ROUND(G39*'Revenue Req.'!$L$28,0) -> 1022659 | H40: =ROUND(H39*'Revenue Req.'!$L$28,0) -> 26630 | I40: =ROUND(I39*'Revenue Req.'!$L$28,0) -> 289033 | J40: =ROUND(J39*'Revenue Req.'!$L$28,0) -> 140938 | K40: =ROUND(K39*'Revenue Req.'!$L$28,0) -> 18677 | M40: =ROUND(M39*'Revenue Req.'!$L$28,0) -> 1368 | N40: =ROUND(N39*'Revenue Req.'!$L$28,0) -> 5150 | O40: =ROUND(O39*'Revenue Req.'!$L$28,0) -> 4213 | Q40: =ROUND(Q39*'Revenue Req.'!$L$28,0) -> 67259 | R40: =ROUND(R39*'Revenue Req.'!$L$28,0) -> 1534 | T40: =ROUND(T39*'Revenue Req.'!$L$28,0) -> 15417 | U40: =ROUND(U39*'Revenue Req.'!$L$28,0) -> 34285 | W40: =ROUND(W39*'Revenue Req.'!$L$28,0) -> 164881 | X40: =ROUND(X39*'Revenue Req.'!$L$28,0) -> 35537 | Y40: =ROUND(Y39*'Revenue Req.'!$L$28,0) -> 116 | Z40: =ROUND(Z39*'Revenue Req.'!$L$28,0) -> 4017820 | AA40: =ROUND(AA39*'Revenue Req.'!$L$28,0) -> 247077 | AB40: =ROUND(AB39*'Revenue Req.'!$L$28,0) -> 738701 | AC40: =ROUND(AC39*'Revenue Req.'!$L$28,0) -> 845354 | AD40: =ROUND(AD39*'Revenue Req.'!$L$28,0) -> 32925 | ... AX40: =ROUND(AX39*'Revenue Req.'!$L$28,0) -> 381 | AZ40: =ROUND(AZ39*'Revenue Req.'!$L$28,0) -> 763 | BA40: =ROUND(BA39*'Revenue Req.'!$L$28,0) -> 6079 | BB40: =ROUND(BB39*'Revenue Req.'!$L$28,0) -> 1485 | BC40: =ROUND(BC39*'Revenue Req.'!$L$28,0) -> 332 | BD40: =ROUND(BD39*'Revenue Req.'!$L$28,0) -> 547 | BE40: =ROUND(BE39*'Revenue Req.'!$L$28,0) -> 954 | BF40: =ROUND(BF39*'Revenue Req.'!$L$28,0) -> 1385 | BG40: =ROUND(BG39*'Revenue Req.'!$L$28,0) -> 746 | ... BK40: =ROUND(BK39*'Revenue Req.'!$L$28,0) -> 2654 | BM40: =SUM(G40:BK40) -> 8293388 | BN40: =+BM40-'Revenue Req.'!L28 -> -11
A42: 26 | C42: [h] = [d3]+[e3]+[f3]+[g1] | E42: Wt. Cost Subtotals | G42: =+G40+G35+G28+G21 -> 5725341 | H42: =+H40+H35+H28+H21 -> 153707 | I42: =+I40+I35+I28+I21 -> 1799679 | J42: =+J40+J35+J28+J21 -> 929311 | K42: =+K40+K35+K28+K21 -> 131883 | M42: =+M40+M35+M28+M21 -> 14431 | N42: =+N40+N35+N28+N21 -> 56427 | O42: =+O40+O35+O28+O21 -> 47213 | Q42: =+Q40+Q35+Q28+Q21 -> 484350 | R42: =+R40+R35+R28+R21 -> 11266 | T42: =+T40+T35+T28+T21 -> 211079 | U42: =+U40+U35+U28+U21 -> 473317 | W42: =+W40+W35+W28+W21 -> 992584 | X42: =+X40+X35+X28+X21 -> 249860 | Y42: =+Y40+Y35+Y28+Y21 -> 1100 | Z42: =+Z40+Z35+Z28+Z21 -> 23263550 | AA42: =+AA40+AA35+AA28+AA21 -> 1501952 | AB42: =+AB40+AB35+AB28+AB21 -> 4797765 | AC42: =+AC40+AC35+AC28+AC21 -> 5865637 | AD42: =+AD40+AD35+AD28+AD21 -> 252692 | ... AX42: =+AX40+AX35+AX28+AX21 -> 5189 | AZ42: =+AZ40+AZ35+AZ28+AZ21 -> 10819 | BA42: =+BA40+BA35+BA28+BA21 -> 84433 | BB42: =+BB40+BB35+BB28+BB21 -> 20944 | BC42: =+BC40+BC35+BC28+BC21 -> 4705 | BD42: =+BD40+BD35+BD28+BD21 -> 3194 | BE42: =+BE40+BE35+BE28+BE21 -> 10537 | BF42: =+BF40+BF35+BF28+BF21 -> 14946 | BG42: =+BG40+BG35+BG28+BG21 -> 8639 | ... BK42: =+BK40+BK35+BK28+BK21 -> 19657 | BM42: =SUM(G42:BK42) -> 52370234
A44: 27 | B44: Revenue - Based Revenue Requirement :
A46: 28 | C46: [k] = [h] / ∑[h] | E46: % of Total Weighted Cost | G46: =ROUND(G42/$BM42,6) -> 0.109324 | H46: =ROUND(H42/$BM42,6) -> 0.002935 | I46: =ROUND(I42/$BM42,6) -> 0.034365 | J46: =ROUND(J42/$BM42,6) -> 0.017745 | K46: =ROUND(K42/$BM42,6) -> 0.002518 | M46: =ROUND(M42/$BM42,6) -> 0.000276 | N46: =ROUND(N42/$BM42,6) -> 0.001077 | O46: =ROUND(O42/$BM42,6) -> 0.000902 | Q46: =ROUND(Q42/$BM42,6) -> 0.009249 | R46: =ROUND(R42/$BM42,6) -> 0.000215 | T46: =ROUND(T42/$BM42,6) -> 0.004031 | U46: =ROUND(U42/$BM42,6) -> 0.009038 | W46: =ROUND(W42/$BM42,6) -> 0.018953 | X46: =ROUND(X42/$BM42,6) -> 0.004771 | Y46: =ROUND(Y42/$BM42,6) -> 2.1e-05 | Z46: =ROUND(Z42/$BM42,6) -> 0.444213 | AA46: =ROUND(AA42/$BM42,6) -> 0.028679 | AB46: =ROUND(AB42/$BM42,6) -> 0.091612 | AC46: =ROUND(AC42/$BM42,6) -> 0.112003 | AD46: =ROUND(AD42/$BM42,6) -> 0.004825 | ... AX46: =ROUND(AX42/$BM42,6) -> 9.9e-05 | AZ46: =ROUND(AZ42/$BM42,6) -> 0.000207 | BA46: =ROUND(BA42/$BM42,6) -> 0.001612 | BB46: =ROUND(BB42/$BM42,6) -> 0.0004 | BC46: =ROUND(BC42/$BM42,6) -> 9e-05 | BD46: =ROUND(BD42/$BM42,6) -> 6.1e-05 | BE46: =ROUND(BE42/$BM42,6) -> 0.000201 | BF46: =ROUND(BF42/$BM42,6) -> 0.000285 | BG46: =ROUND(BG42/$BM42,6) -> 0.000165 | ... BK46: =ROUND(BK42/$BM42,6) -> 0.000375 | BM46: =SUM(G46:BK46) -> 1.000001
A47: =1+A46 -> 29 | C47: [k1] = [k] * Revenue-Based Rev. Req.2 | E47: Weighted Cost | G47: =ROUND(G46*'Revenue Req.'!$N$28,0) -> -361252 | H47: =ROUND(H46*'Revenue Req.'!$N$28,0) -> -9698 | I47: =ROUND(I46*'Revenue Req.'!$N$28,0) -> -113556 | J47: =ROUND(J46*'Revenue Req.'!$N$28,0) -> -58637 | K47: =ROUND(K46*'Revenue Req.'!$N$28,0) -> -8321 | M47: =ROUND(M46*'Revenue Req.'!$N$28,0) -> -912 | N47: =ROUND(N46*'Revenue Req.'!$N$28,0) -> -3559 | O47: =ROUND(O46*'Revenue Req.'!$N$28,0) -> -2981 | Q47: =ROUND(Q46*'Revenue Req.'!$N$28,0) -> -30563 | R47: =ROUND(R46*'Revenue Req.'!$N$28,0) -> -710 | T47: =ROUND(T46*'Revenue Req.'!$N$28,0) -> -13320 | U47: =ROUND(U46*'Revenue Req.'!$N$28,0) -> -29865 | W47: =ROUND(W46*'Revenue Req.'!$N$28,0) -> -62629 | X47: =ROUND(X46*'Revenue Req.'!$N$28,0) -> -15765 | Y47: =ROUND(Y46*'Revenue Req.'!$N$28,0) -> -69 | Z47: =ROUND(Z46*'Revenue Req.'!$N$28,0) -> -1467863 | AA47: =ROUND(AA46*'Revenue Req.'!$N$28,0) -> -94767 | AB47: =ROUND(AB46*'Revenue Req.'!$N$28,0) -> -302724 | AC47: =ROUND(AC46*'Revenue Req.'!$N$28,0) -> -370104 | AD47: =ROUND(AD46*'Revenue Req.'!$N$28,0) -> -15944 | ... AX47: =ROUND(AX46*'Revenue Req.'!$N$28,0) -> -327 | AZ47: =ROUND(AZ46*'Revenue Req.'!$N$28,0) -> -684 | BA47: =ROUND(BA46*'Revenue Req.'!$N$28,0) -> -5327 | BB47: =ROUND(BB46*'Revenue Req.'!$N$28,0) -> -1322 | BC47: =ROUND(BC46*'Revenue Req.'!$N$28,0) -> -297 | BD47: =ROUND(BD46*'Revenue Req.'!$N$28,0) -> -202 | BE47: =ROUND(BE46*'Revenue Req.'!$N$28,0) -> -664 | BF47: =ROUND(BF46*'Revenue Req.'!$N$28,0) -> -942 | BG47: =ROUND(BG46*'Revenue Req.'!$N$28,0) -> -545 | ... BK47: =ROUND(BK46*'Revenue Req.'!$N$28,0) -> -1239 | BM47: =SUM(G47:BK47) -> -3304417 | BN47: =+BM47-'Revenue Req.'!N28 -> -5
A49: 30 | C49: [m] = [h] + [k1] | E49: Total Cost | G49: =+G47+G42 -> 5364089 | H49: =+H47+H42 -> 144009 | I49: =+I47+I42 -> 1686123 | J49: =+J47+J42 -> 870674 | K49: =+K47+K42 -> 123562 | M49: =+M47+M42 -> 13519 | N49: =+N47+N42 -> 52868 | O49: =+O47+O42 -> 44232 | Q49: =+Q47+Q42 -> 453787 | R49: =+R47+R42 -> 10556 | T49: =+T47+T42 -> 197759 | U49: =+U47+U42 -> 443452 | W49: =+W47+W42 -> 929955 | X49: =+X47+X42 -> 234095 | Y49: =+Y47+Y42 -> 1031 | Z49: =+Z47+Z42 -> 21795687 | AA49: =+AA47+AA42 -> 1407185 | AB49: =+AB47+AB42 -> 4495041 | AC49: =+AC47+AC42 -> 5495533 | AD49: =+AD47+AD42 -> 236748 | ... AX49: =+AX47+AX42 -> 4862 | AZ49: =+AZ47+AZ42 -> 10135 | BA49: =+BA47+BA42 -> 79106 | BB49: =+BB47+BB42 -> 19622 | BC49: =+BC47+BC42 -> 4408 | BD49: =+BD47+BD42 -> 2992 | BE49: =+BE47+BE42 -> 9873 | BF49: =+BF47+BF42 -> 14004 | BG49: =+BG47+BG42 -> 8094 | ... BK49: =+BK47+BK42 -> 18418 | BM49: =SUM(G49:BK49) -> 49065817 | BN49: =+BM49-'Revenue Req.'!J44 -> 37.609873
A51: 31 | C51: [p] = [m] / ( [a]* 12) | E51: Monthly Rate | G51: =ROUND(G49/G10/12,2) -> 10.47 | H51: =ROUND(H49/H10/12,2) -> 10.79 | I51: =ROUND(I49/I10/12,2) -> 11.64 | J51: =ROUND(J49/J10/12,2) -> 12.33 | K51: =ROUND(K49/K10/12,2) -> 13.2 | L51: =ROUND(L49/L10/12,2) -> #DIV/0! | M51: =ROUND(M49/M10/12,2)+0.3 -> 20.06 | N51: =ROUND(N49/N10/12,2)+0.35 -> 20.84 | O51: =ROUND(O49/O10/12,2)+0.5 -> 21.44 | P51: =ROUND(P49/P10/12,2) -> #DIV/0! | Q51: =ROUND(Q49/Q10/12,2) -> 13.46 | R51: =ROUND(R49/R10/12,2) -> 13.74 | T51: =ROUND(T49/T10/12,2) -> 25.59 | U51: =ROUND(U49/U10/12,2) -> 25.81 | W51: =ROUND(W49/W10/12,2) -> 11.25 | X51: =ROUND(X49/X10/12,2) -> 13.15 | Y51: =ROUND(Y49/Y10/12,2) -> 17.18 | Z51: =ROUND(Z49/Z10/12,2) -> 10.82 | AA51: =ROUND(AA49/AA10/12,2) -> 11.36 | AB51: =ROUND(AB49/AB10/12,2) -> 12.14 | AC51: =ROUND(AC49/AC10/12,2) -> 12.97 | AD51: =ROUND(AD49/AD10/12,2) -> 14.35 | AE51: =ROUND(AE49/AE10/12,2) -> 17.54 | AF51: =ROUND(AF49/AF10/12,2)+0.42 -> 11.71 | AG51: =ROUND(AG49/AG10/12,2)+0.42 -> 11.71 | AH51: =ROUND(AH49/AH10/12,2)+0.37 -> 13.34 | AI51: =ROUND(AI49/AI10/12,2) -> 14.35 | AJ51: =ROUND(AJ49/AJ10/12,2) -> 17.36 | AK51: =ROUND(AK49/AK10/12,2) -> 16.91 | AL51: =ROUND(AL49/AL10/12,2) -> 21.2 | AM51: =ROUND(AM49/AM10/12,2) -> 25.08 | AN51: =ROUND(AN49/AN10/12,2) -> 16.49 | AO51: =ROUND(AO49/AO10/12,2) -> 19.42 | AP51: =ROUND(AP49/AP10/12,2) -> 20.2 | ... AS51: =ROUND(AS49/AS10/12,2) -> 25.33 | AT51: =IF(AT10=0,"N/A",ROUND(AT49/AT10/12,2)) -> N/A | AU51: =ROUND(AU49/AU10/12,2) -> 19.36 | AV51: =IF(AV10=0,"N/A",ROUND(AV49/AV10/12,2)) -> N/A | AW51: =ROUND(AW49/AW10/12,2) -> 22.4 | AX51: =ROUND(AX49/AX10/12,2) -> 25.32 | AZ51: =ROUND(AZ49/AZ10/12,2)-12 -> 14.39 | BA51: =ROUND(BA49/BA10/12,2)-12 -> 13.95 | BB51: =ROUND(BB49/BB10/12,2)-12 -> 14.37 | BC51: =ROUND(BC49/BC10/12,2)-9 -> 17.24 | BD51: =ROUND(BD49/BD10/12,2) -> 10.84 | BE51: =ROUND(BE49/BE10/12,2)+4 -> 24.57 | BF51: =ROUND(BF49/BF10/12,2)+4 -> 24.12 | BG51: =ROUND(BG49/BG10/12,2)+2 -> 23.76 | BH51: =ROUND(BH49/BH10/12,2)+11 -> 33.58 | BI51: =ROUND(BI49/BI10/12,2)+11 -> 36.58 | BJ51: =ROUND(BJ49/BJ10/12,2)-2 -> 12.42 | BK51: =ROUND(BK49/BK10/12,2)-2 -> 11.83
A53: 32 | C53: [r] | E53: Current Rate | G53: 11.52 | H53: 11.91 | I53: 12.71 | J53: 13.3 | K53: 15.4 | M53: 25.14 | N53: 25.99 | O53: 27.28 | Q53: 13.92 | R53: 14.3 | T53: 28.59 | U53: 29.76 | W53: 10.65 | X53: 11.86 | Y53: 15 | Z53: 10.31 | AA53: 10.86 | AB53: 10.99 | AC53: 11.21 | AD53: 12.6 | AE53: 14.78 | AF53: 12.42 | AG53: =+AF53 -> 12.42 | AH53: 14.15 | AI53: 14.6 | AJ53: 17.86 | AK53: 14.88 | AL53: 19.7 | AM53: 23.73 | AN53: 14.84 | AO53: 16.7 | AP53: 19.39 | AQ53: 19.63 | AR53: 22.25 | AS53: 23.72 | AT53: =+AU53 -> 19.33 | AU53: 19.33 | AV53: 22.54 | AW53: 22.54 | AX53: 25.77 | AZ53: 10.64 | BA53: 10.31 | BB53: 10.86 | BC53: 12.47 | BD53: 10.31 | BE53: 26.53 | BF53: 25.97 | BG53: =BF53 -> 25.97 | BH53: 36.19 | BI53: 40.18 | BJ53: 10.23 | BK53: 9.87 | BN53: =SUM(G53:BK53) -> 923.41
A55: 33 | C55: [s] = [p]/[r] - 1 | E55: % Increase (Decr) 5 | G55: =ROUND(G51/G53-1,4) -> -0.0911 | H55: =ROUND(H51/H53-1,4) -> -0.094 | I55: =ROUND(I51/I53-1,4) -> -0.0842 | J55: =ROUND(J51/J53-1,4) -> -0.0729 | K55: =ROUND(K51/K53-1,4) -> -0.1429 | M55: =ROUND(M51/M53-1,4) -> -0.2021 | N55: =ROUND(N51/N53-1,4) -> -0.1982 | O55: =ROUND(O51/O53-1,4) -> -0.2141 | Q55: =ROUND(Q51/Q53-1,4) -> -0.033 | R55: =ROUND(R51/R53-1,4) -> -0.0392 | T55: =ROUND(T51/T53-1,4) -> -0.1049 | U55: =ROUND(U51/U53-1,4) -> -0.1327 | W55: =ROUND(W51/W53-1,4) -> 0.0563 | X55: =ROUND(X51/X53-1,4) -> 0.1088 | Y55: =ROUND(Y51/Y53-1,4) -> 0.1453 | Z55: =ROUND(Z51/Z53-1,4) -> 0.0495 | AA55: =ROUND(AA51/AA53-1,4) -> 0.046 | AB55: =ROUND(AB51/AB53-1,4) -> 0.1046 | AC55: =ROUND(AC51/AC53-1,4) -> 0.157 | AD55: =ROUND(AD51/AD53-1,4) -> 0.1389 | ... AS55: =ROUND(AS51/AS53-1,4) -> 0.0679 | AT55: =IF(AT10=0,"N/A",ROUND(AT51/AT53-1,4)) -> N/A | AU55: =ROUND(AU51/AU53-1,4) -> 0.0016 | AV55: =IF(AV10=0,"N/A",ROUND(AV51/AV53-1,4)) -> N/A | AW55: =ROUND(AW51/AW53-1,4) -> -0.0062 | AX55: =ROUND(AX51/AX53-1,4) -> -0.0175 | AZ55: =ROUND(AZ51/AZ53-1,4) -> 0.3524 | BA55: =ROUND(BA51/BA53-1,4) -> 0.3531 | BB55: =ROUND(BB51/BB53-1,4) -> 0.3232 | BC55: =ROUND(BC51/BC53-1,4) -> 0.3825 | BD55: =ROUND(BD51/BD53-1,4) -> 0.0514 | BE55: =ROUND(BE51/BE53-1,4) -> -0.0739 | BF55: =ROUND(BF51/BF53-1,4) -> -0.0712 | BG55: =ROUND(BG51/BG53-1,4) -> -0.0851 | ... BK55: =ROUND(BK51/BK53-1,4) -> 0.1986
A59: 34 | C59: 1 - Normalized to the "Fully Loaded Installed Cost" of a 0-55
A60: =1+A59 -> 35 | C60: watt LED Cobra Head light on Schedule A.
A61: =1+A60 -> 36 | C61: 2 - Refer to tab entitled "Revenue Req."
A62: =1+A61 -> 37 | C62: 3 - Normalized to the "Monthly kWh Usage" of a 0-55 watt
...

Sheet Revenue Req.
P1: WP/IV-J-7/3
P2: Page 1 of 1
C4: 2022 RATE CASE
C5: ONCOR ELECTRIC DELIVERY COMPANY LLC
C6: CALCULATION OF REVENUE REQUIREMENT FOR UNMETERED STREET LIGHTING - SCHEDULES A & B
C7: FOR THE TEST YEAR ENDING DECEMBER 31, 2021
C9: SPONSOR: MATTHEW A. TROXLE
B10: Line # | C10: [A] | D10: [B] | H10: [C] | J10: [D] | L10: [E] | N10: [F] | P10: [G]
C12: ASSIGNMENT OF COSTS ALLOCATED TO THE LIGHTING CLASS TO UNMETERED SLs
B13: 1 | D13: Cost Category | H13: Based on Installed Cost | J13: Based on Load | L13: Per Light Basis | N13: Based on Relative Revenue by Light Type | P13: Based on Maintenance Cost Wt. | R13: Total Lighting Costs | T13: check input: | U13: check:
B15: 2 | D15: Return on Rate Base | H15: ='[2]Cost Assignments by Group'!H$62 -> 3167791 | J15: ='[2]Cost Assignments by Group'!I$62 -> 2417640 | L15: ='[2]Cost Assignments by Group'!J$62 -> 2485641 | N15: ='[2]Cost Assignments by Group'!K$62 -> -4195338 | P15: ='[2]Cost Assignments by Group'!L$62 -> 0 | R15: =SUM(H15:P15) -> 3875734
B16: =1+B15 -> 3 | D16: Depr, Amort, and Other Exp. | H16: ='[4]II-I-DIST'!$Q$22 -> 25182582 | J16: 0 | L16: 0 | N16: 0 | P16: 0 | R16: =SUM(H16:P16) -> 25182582
B17: =1+B16 -> 4 | D17: O&M and Customer Expenses | H17: ='[2]Cost Assignments by Group'!H$128 -> 0 | J17: ='[2]Cost Assignments by Group'!I$128 -> 696825.77 | L17: ='[2]Cost Assignments by Group'!J$128 -> 508815.24 | N17: ='[2]Cost Assignments by Group'!K$128 -> 0 | P17: ='[2]Cost Assignments by Group'!L$128 -> 9755171.8 | R17: =SUM(H17:P17) -> 10960813
B18: =1+B17 -> 5 | D18: A&G Expenses | H18: ='[2]Cost Assignments by Group'!H$154 -> 7988641.1 | J18: ='[2]Cost Assignments by Group'!I$154 -> 0 | L18: ='[2]Cost Assignments by Group'!J$154 -> 5743014.5 | N18: ='[2]Cost Assignments by Group'!K$154 -> 0 | P18: ='[2]Cost Assignments by Group'!L$154 -> 0 | R18: =SUM(H18:P18) -> 13731656 | T18: <--- excludes A928
B19: =1+B18 -> 6 | D19: Taxes | H19: ='[2]Cost Assignments by Group'!H$178 -> 4666686.8 | J19: ='[2]Cost Assignments by Group'!I$178 -> 1045833.6 | L19: ='[2]Cost Assignments by Group'!J$178 -> 7000 | N19: ='[2]Cost Assignments by Group'!K$178 -> 595769.28 | P19: ='[2]Cost Assignments by Group'!L$178 -> 134199.63 | R19: =SUM(H19:P19) -> 6449489.3
B20: =1+B19 -> 7 | D20: Plus : MET & CUST Function Costs | L20: =[4]LinkSheet!$N$10+[4]LinkSheet!$N$12 -> 1614635 | R20: =SUM(H20:P20) -> 1614635
B21: =1+B20 -> 8 | D21: Less : Other Revenue | N21: ='[4]II-I-DIST'!$Q$31 -> 527901.22 | R21: =N21 -> 527901.22
B22: =1+B21 -> 9 | R22: =SUM(AF22:AN22) -> 0 | AB22: Settlement-Related Adjustment | AF22: 0 | AH22: 0 | AJ22: 0 | AL22: 0 | AN22: 0
B23: =1+B22 -> 10 | D23: Sub Totals | H23: =SUM(H15:H21) -> 41005701 | J23: =SUM(J15:J21) -> 4160299.4 | L23: =SUM(L15:L21) -> 10359106 | N23: =SUM(N15:N20)-N21 -> -4127469.9 | P23: =SUM(P15:P21) -> 9889371.5 | R23: =SUM(H23:P23) -> 61287007 | U23: =SUM(R15:R22)-R23 -> 1055802.4
B24: =1+B23 -> 11
B25: =1+B24 -> 12 | D25: Percentage of Class Rev. Req. | H25: =+$J$47 -> 0.80059023 | J25: =+$J$47 -> 0.80059023 | L25: =+$J$47 -> 0.80059023 | N25: =+$J$47 -> 0.80059023 | P25: =+$J$47 -> 0.80059023
B26: =1+B25 -> 13 | D26: from unmetered SL facilities
B28: 14 | C28: Total Rev. Req. - Unmetered Service | H28: =ROUND(H23*H25,0) -> 32828763 | J28: =ROUND(J23*J25,0) -> 3330695 | L28: =ROUND(L23*L25,0) -> 8293399 | N28: =ROUND(N23*N25,0) -> -3304412 | P28: =ROUND(P23*P25,0) -> 7917334 | R28: =SUM(H28:P28) -> 49065779
C29: for Schedule A & B Lights
B31: 15 | D31: * - based on the ratio of unmetered SL revenue requirement to the total lighting class revenue requirement
B34: 16 | C34: Total Lighting Class Revenue Requirement (DIST Function + MET Function + Customer Function) = | J34: =[4]LinkSheet!$N$8+[4]LinkSheet!$N$10+[4]LinkSheet!$N$12 -> 61287007 | K34: (a)
B36: 17 | E36: Less:
B38: 18 | E38: Outdoor Lighting Revenue = | J38: =[3]OL!$O$75 -> 10121742 | S38: - | T38: =+R28-J44 -> -0.39012659
B39: =1+B38 -> 19 | E39: Metered Lighting (Co.-owned) Rev = | J39: =[3]SL!$I$203 -> 38502
B40: =1+B39 -> 20 | E40: Unmetered SL POD Charges | J40: =[3]SL!$I$19 -> 349044
B41: =1+B40 -> 21 | E41: Metered Lighting (Non Co.-owned) Rev = | J41: =[3]SL!$I$197 -> 273124
B42: =1+B41 -> 22 | E42: Schedule C & D Revenue = | J42: =[3]SL!$I$181+[3]SL!$I$182 -> 1438816
B44: 23 | D44: Total Unmetered SL Revenue Req (Sch A&B)# = | J44: =$J$34-SUM(J38:J43) -> 49065779 | K44: (b) | T44: =+J44/J34 -> 0.80059023
B45: =1+B44 -> 24
B46: =1+B45 -> 25 | D46: Ratio of Total Unmetered SL Revenue Req (Sch A&B)
B47: =1+B46 -> 26 | D47: to Total Lighting Class Revenue Requirement = | J47: =ROUND(J44/J34,8) -> 0.80059023 | K47: = (b)/(a)
B49: 27 | D49: # - Also includes Rectangular, Post Top, Incandescent, and Historical lights.
