Workbook
Name Load_Forecast__Economic__Weather_Year_Assumption: Index!$B$16

Sheet Index
A1: RTP Scope Section Number | B1: Input Assumption | C1: Status | D1: Date
A2: Transmission Topology
A3: 4.3 | B3: Start Cases | C3: ='Start Cases'!B2 -> Final | D3: =IF('Start Cases'!B1= "","N/A",'Start Cases'!B1) -> 45711
A4: 4.3 | B4: Recently Approved RPG Projects | C4: ='Recently Approved RPG Projects'!C2 -> Final | D4: ='Recently Approved RPG Projects'!C1 -> 45973
A5: 4.3 | B5: Model Updates/Corrections | C5: ='Model Updates & Corrections'!B2 -> Final | D5: ='Model Updates & Corrections'!B1 -> 45941
A6: 3.1.3 | B6: Transmission & Generation Outages | C6: ='Transmission & Gen Outages'!B2 -> Final | D6: =IF('Transmission & Gen Outages'!B1= "","N/A",'Transmission & Gen Outages'!B1) -> 45804
A7: Generation
A8: 3.2.1 | B8: Generation Additions, Retirements and Mothballs | C8: ='Gen Add, Ret. and Mothball'!B2 -> Final | D8: ='Gen Add, Ret. and Mothball'!B1 -> 45900
A9: 3.2.2 | B9: Renewable Generation Dispatch | C9: ='Renewable Generation Dispatch'!B2 -> Final | D9: =IF('Renewable Generation Dispatch'!B1= "","N/A",'Renewable Generation Dispatch'!B1) -> 45711
A10: 3.2.3 | B10: Switchable Generation | C10: ='Switchable Generation'!B2 -> Final | D10: =IF('Switchable Generation'!B1= "","N/A",'Switchable Generation'!B1) -> 45800
A11: 3.2.4 | B11: DC Tie Modeling and Dispatch | C11: ='DC Tie Modeling & Dispatch'!B2 -> Final | D11: =IF('DC Tie Modeling & Dispatch'!B1= "","N/A",'DC Tie Modeling & Dispatch'!B1) -> 45711
A12: 3.2.5 | B12: Reserve Requirements | C12: ='Reserve Requirement'!B2 -> Final | D12: =IF('Reserve Requirement'!B1= "","N/A",'Reserve Requirement'!B1) -> 45721
A13: 3.2.6 | B13: Fuel Price Assumptions | C13: ='Fuel Price Assumptions'!B2 -> Final | D13: =IF('Fuel Price Assumptions'!B1= "","N/A",'Fuel Price Assumptions'!B1) -> 45859
A14: 3.2.6 | B14: Emission Cost Assumptions | C14: ='Emission Cost Assumptions'!B2 -> Final | D14: =IF('Emission Cost Assumptions'!B1= "","N/A",'Emission Cost Assumptions'!B1) -> 45839
A15: Demand
A16: 3.3 | B16: Load Forecast Weather Year | C16: ='Load Forecast Weather Year'!B2 -> Final | D16: =IF('Load Forecast Weather Year'!B1= "","N/A",'Load Forecast Weather Year'!B1) -> 45839

Sheet Start Cases
A1: Date Last Updated: | B1: 45711 | C1: Back
A2: Status | B2: Final
A5: Based on 2024 RTP final summer peak reliability cases for years 2027 and 2030*
A6: *765-kV case for 2030

Sheet Recently Approved RPG Projects
B1: Date Last Updated: | C1: 45973 | D1: Back
B2: Status | C2: Final
A5: RPG Project ID | B5: Project Name | C5: TDSP | D5: Approve Date | E5: 2027 | F5: 2030
A6: 23RPG032 | B6: San Antonio South Reliability II Project * | C6: BEC | D6: 2024 | E6: X
A7: 24RPG010 | B7: Delaware Basin Stages 3 and 4 Project | C7: Oncor | D7: 2024 | E7: X | F7: X
A8: 24RPG015 | B8: Delaware Basin Stage 5 Project | C8: Oncor | D8: 2025 | F8: X
A9: 24RPG008 | B9: Brownsville Area Improvements Transmission Project | C9: AEPSC | D9: 2024 | E9: X | F9: X
A10: 24RPG038 | B10: Bergheim Substation Upgrade Project | C10: LCRA TSC, PEC | D10: 2025 | F10: X
A11: 24RPG017 | B11: Venus Switch to Sam Switch 345-kV Line Project | C11: Oncor | D11: 2024 | E11: X | F11: X
A12: 24RPG007 | B12: P.H. Robinson to WA Parish 345-kV Hardening Project | C12: CNP | D12: 2025 | F12: X
A14: Notes: | B14: *Part of the San Antonio South Reliability II Project is accelerated to be in service by 2027. The project is already in 2030 RTP case.

Sheet Model Updates & Corrections
A1: Date Last Updated: | B1: 45941 | C1: Back
A2: Status | B2: Final
A5: Model Corrections/Updates Made to the 2024 RTP Cases
A6: Transmission Changes | B6: TO | C6: 2027 | D6: 2030 | E6: Comments
A8: Updated line ratings for Navarro (68091) - Big Brown (3380 & 3381) 345-kV lines | B8: LSTR/ONCOR | C8: X | D8: X | E8: Based on NMMS ratings
A9: Updated line ratings for Weatherford Switch (1592) - Flat Rock Tap (15015) 138-kV line | B9: ONCOR | C9: X | D9: X | E9: Based on NMMS ratings
A10: Updated line ratings for Fisher Road Switch (1425) - Riley (6101) 345-kV line | B10: ONCOR/AEP | C10: X | D10: X | E10: Based on NMMS ratings
A11: Updated line ratings for Westside (8485) - Mckenzie (8858) 138-kV line | B11: AEP | C11: X | D11: X | E11: MOD Project 86882 (Tier 4)
A12: Updated line ratings for Wharton (43570) - Caney (44132) 138-kV line | B12: CNP | C12: X | D12: X | E12: Based on NMMS ratings
A13: Updated line ratings for Bell County (132) - Fryers Creek (Boggy) (3493) 138-kV line based on the latest submission in MOD (MOD Project 87675) | B13: ONCOR | C13: X | E13: Updated to reflect the most current information related to the Temple Area Project (24RPG001)
A14: Updated line ratings for Bell County (132) - Salado (3640) 138-kV line based on the latest submission in MOD (MOD Project 87673) | B14: ONCOR | C14: X
A15: Updated line ratings for Temple Switch (3415) - Fryers Creek (Boggy) (3493) 138-kV line based on the latest submission in MOD (MOD Project 87677) | B15: ONCOR | C15: X | D15: X
A16: Updated line ratings for South Texas Project (5915) - WA Parish (44000) 345-kV line | B16: CNP | C16: X | D16: X | E16: Based on NMMS ratings
A17: Updated line ratings for Georgetown (7343) - Rivery (7347) 138-kV line | B17: LCRA | C17: X | D17: X | E17: MOD Project 85973 (Tier 4)
A18: Updated line ratings for Reiter (18545) - Yarbrough Sub (11111) 138-kV line based on the latest submission in MOD (MOD Project 81418) | B18: ONCOR | C18: X | D18: X | E18: Updated to reflect the most current information related to the Wolf Switch to Reiter Switch 138-kV Line Project (25RPG008)
A19: Updated line ratings for Cedar Crest (2486) - Buntin Drive (2985) 138-kV line | B19: ONCOR | C19: X | D19: X | E19: MOD 98739 (NOMCR)
A20: Updated line ratings for Angstrom (8249) - Static (8676) - Haber (81003) 345-kV lines | B20: AEP | C20: X | D20: X | E20: MOD Project 80630 (Tier 4)
A21: Updated line ratings for Lon Hill (8452) - Saxet (78568) 138-kV line | B21: LCRA | D21: X | E21: MOD Project 86043 (Tier 4)
A22: Updated line ratings for Abilene Mulberry Creek (6235) - Bluff Creek (60040) 345-kV line | B22: AEP | C22: X | E22: MOD Project 48816 (Tier 4)
A23: Bypassed Edison series capacitors | B23: AEP | D23: X | E23: ERCOT Permian Basin Reliability Plan Study (Project ID: Import A1)
A26: Generation Changes | B26: TO | C26: 2027 | D26: 2030 | E26: Comments
A28: Changed POI for ElDora Solar (24INR0337) and BESS (24INR0338) to HICKL_RD (9063) | B28: Austin Energy | C28: X | D28: X | E28: Based on latest information in RIOO as of 8/1/2025
A30: Phase Shifters | B30: TO | C30: 2027 | D30: 2030 | E30: Comments

Sheet Transmission & Gen Outages
A1: Date Last Updated: | B1: 45804 | C1: Back
A2: Status | B2: Final
A5: Outaged Element | B5: Associated TO/RE | C5: 2027 | D5: 2030 | E5: Notes
A6: Spencer Unit 4 | B6: City of Garland | C6: X | D6: X | E6: (AS OF 10/24/2022, AVAILABLE 3/1 THROUGH 11/30)
A7: Spencer Unit 5 | B7: City of Garland | C7: X | D7: X | E7: (AS OF 10/24/2022, AVAILABLE 3/1 THROUGH 11/30)
A8: R W MILLER STG 1 | B8: BEPC | C8: X | D8: X | E8: EXT-OUT
A9: Powerlane Plant STG 1 | B9: GEUS | C9: X | D9: X | E9: (AS OF 10/1/2022, AVAILABLE 5/1 THROUGH 9/30)
A10: CHISHOLM GRID BAT | B10: Chisholm Grid, LLC/Able Grid | C10: X | E10: NSO posted (EXT-OUT)
A12: Automated maintenance schedules modeled by UPLAN

Sheet Renewable Generation Dispatch
A1: Date Last Updated: | B1: 45711 | C1: Back
A2: Status | B2: Final
A5: Solar
A6: http://www.ercot.com/gridinfo/resource
A7: Weather years used for analysis:
A8: Base/Sensitivity | B8: 2013
A11: Wind
A12: http://www.ercot.com/gridinfo/resource
A13: Weather years used for analysis:
A14: Base/Sensitivity | B14: 2013
A16: Hydro
A17: Unit specific monthly capacity factors modeled based on historical dispatch levels during the last three years.

Sheet Gen Add, Ret. and Mothball
A1: Date Last Updated: | B1: 45900 | C1: Back
A2: Status | B2: Final
A3: 6.9(1) conditions met as of: | B3: 45807
A6: New generators that met PG 6.9(1) requirements
A7: GINR Reference Number | B7: Project Name | C7: County | D7: Projected Date | E7: Fuel | F7: MW For Grid | G7: Changes From Last Report | H7: Meets Section 6.9 Requirements (1)(b) through (1)(d) | I7: 2027 | J7: 2027 Sensitivity | K7: 2030 | L7: 2030 Sensitivity | M7: Comments
A8: 23INR0372 | B8: Cross Trails Storage | C8: Scurry | D8: 45807 | E8: Battery Storage | F8: 58.29 | H8: 45499 | I8: X | J8: X | K8: X | L8: X
A9: 25INR0231 | B9: Apache Hill BESS | C9: Hood | D9: 46341 | E9: Battery Storage | F9: 201.15 | H9: 45490 | I9: X | J9: X | K9: X | L9: X
A10: 22INR0525 | B10: St. Gall II Energy Storage | C10: Pecos | D10: 45869 | E10: Battery Storage | F10: 100.24 | H10: 45597 | I10: X | J10: X | K10: X | L10: X
A11: 24INR0493 | B11: Crowned Heron BESS 2 | C11: Fort Bend | D11: 46112 | E11: Battery Storage | F11: 154.2 | H11: 45575 | I11: X | J11: X | K11: X | L11: X
A12: 24INR0631 | B12: Radian Storage SLF | C12: Brown | D12: 45852 | E12: Battery Storage | F12: 160.25 | H12: 45497 | I12: X | J12: X | K12: X | L12: X
A13: 23INR0539 | B13: Gregory BESS | C13: San Patricio | D13: 45607 | E13: Battery Storage | F13: 9.9 | H13: 45352 | I13: X | J13: X | K13: X | L13: X
A14: 24INR0610 | B14: Century BESS | C14: Tarrant | D14: 45653 | E14: Battery Storage | F14: 9.88 | H14: 45385 | I14: X | J14: X | K14: X | L14: X
A15: 23INR0807 | B15: Mayberry II BESS | C15: Hidalgo | D15: 45677 | E15: Battery Storage | F15: 9.95 | H15: 45411 | I15: X | J15: X | K15: X | L15: X
A16: 22INR0602 | B16: Regis Palacios BESS | C16: Matagorda | D16: 45618 | E16: Battery Storage | F16: 9.9 | H16: 45352 | I16: X | J16: X | K16: X | L16: X
A17: 24INR0586 | B17: Judkins BESS | C17: Ector | D17: 45351 | E17: Battery Storage | F17: 9.95 | H17: 45231 | I17: X | J17: X | K17: X | L17: X
A18: 24INR0614 | B18: Russek Street BESS | C18: Reagan | D18: 45646 | E18: Battery Storage | F18: 9.9 | H18: 45295 | I18: X | J18: X | K18: X | L18: X
A19: 24INR0624 | B19: Mainland BESS | C19: Galveston | D19: 45464 | E19: Battery Storage | F19: 9.9 | H19: 45295 | I19: X | J19: X | K19: X | L19: X
... A27: 23INR0244 | B27: Tiger Solar | C27: Jones | D27: 46568 | E27: Solar | F27: 255 | H27: 45700 | I27: X | J27: X | K27: X | L27: X
A28: 24INR0126 | B28: High Noon Storage | C28: Hill | D28: 46882 | E28: Battery Storage | F28: 94 | H28: 45700 | K28: X | L28: X
A29: 24INR0201 | B29: Short Creek Solar | C29: Wichita | D29: 47179 | E29: Solar | F29: 625 | H29: 45700 | K29: X | L29: X
A30: 24INR0305 | B30: MRG Goody Storage | C30: Lamar | D30: 46144 | E30: Battery Storage | F30: 52.29 | H30: 45700 | I30: X | J30: X | K30: X | L30: X
A31: 24INR0355 | B31: Anatole Renewable Energy Storage | C31: Henderson | D31: 46477 | E31: Battery Storage | F31: 207.82 | H31: 45700 | I31: X | J31: X | K31: X | L31: X
A32: 24INR0364 | B32: Pitts Dudik II | C32: Hill | D32: 46057 | E32: Solar | F32: 30.23 | H32: 45700 | I32: X | J32: X | K32: X | L32: X
A33: 24INR0386 | B33: Black & Gold Energy Storage | C33: Menard | D33: 46568 | E33: Battery Storage | F33: 254.58 | H33: 45701 | I33: X | J33: X | K33: X | L33: X
A34: 24INR0498 | B34: Fort Watt Storage | C34: Tarrant | D34: 46629 | E34: Battery Storage | F34: 205.4 | H34: 45700 | I34: X | J34: X | K34: X | L34: X
A35: 24INR0528 | B35: Blanquilla BESS | C35: Nueces | D35: 46157 | E35: Battery Storage | F35: 200.78 | H35: 45701 | I35: X | J35: X | K35: X | L35: X
A36: 24INR0584 | B36: Houston IV BESS | C36: Harris | D36: 46176 | E36: Battery Storage | F36: 164.6 | H36: 45700 | I36: X | J36: X | K36: X | L36: X
A37: 25INR0018 | B37: Yellow Cat Wind | C37: Navarro | D37: 46478 | E37: Wind | F37: 262 | H37: 45700 | I37: X | J37: X | K37: X | L37: X
A38: 25INR0046 | B38: Blue Skies BESS | C38: Hill | D38: 46752 | E38: Battery Storage | F38: 306.26 | H38: 45700 | I38: X | J38: X | K38: X | L38: X
A39: 25INR0103 | B39: Elio BESS | C39: Brazoria | D39: 46604 | E39: Battery Storage | F39: 317.2 | H39: 45700 | I39: X | J39: X | K39: X | L39: X
A40: 25INR0282 | B40: Hornet Solar II SLF | C40: Swisher | D40: 46539 | E40: Solar | F40: 208.95 | H40: 45700 | I40: X | J40: X | K40: X | L40: X
A41: 25INR0283 | B41: Hornet Storage II SLF | C41: Swisher | D41: 46539 | E41: Battery Storage | F41: 207.96 | H41: 45700 | I41: X | J41: X | K41: X | L41: X
... A52: 26INR0447 | B52: Honey Mesquite Wind Farm | C52: Glasscock | D52: 46371 | E52: Wind | F52: 180.48 | H52: 45700 | I52: X | J52: X | K52: X | L52: X
A53: 26INR0452 | B53: Cannibal Draw Solar | C53: Glasscock | D53: 46853 | E53: Solar | F53: 149.5 | H53: 45700 | K53: X | L53: X
A54: 26INR0453 | B54: Cannibal Draw Storage | C54: Glasscock | D54: 46853 | E54: Battery Storage | F54: 98.6 | H54: 45700 | K54: X | L54: X
A55: 26INR0543 | B55: Three Canes Solar SLF | C55: Navarro | D55: 46456 | E55: Solar | F55: 333 | H55: 45700 | I55: X | J55: X | K55: X | L55: X
A56: 24INR0188 | B56: Tehuacana Creek Solar SLF | C56: Navarro | D56: 46456 | E56: Solar | F56: 505.5 | H56: 45700 | I56: X | J56: X | K56: X | L56: X
A57: 24INR0189 | B57: Tehuacana Creek BESS SLF | C57: Navarro | D57: 46456 | E57: Battery Storage | F57: 419 | H57: 45700 | I57: X | J57: X | K57: X | L57: X
A58: 23INR0618 | B58: Farmersville West BESS 2 | C58: Collin | D58: 45626 | E58: Battery Storage | F58: 9.9 | H58: 45371 | I58: X | J58: X | K58: X | L58: X
A59: 26INR0189 | B59: Skipjack Energy Storage | C59: Brazoria | D59: 46482 | E59: Battery Storage | F59: 154 | H59: 45712 | I59: X | J59: X | K59: X | L59: X
...

Sheet Switchable Generation
A1: Date Last Updated: | B1: 45800 | C1: Back
A2: Status | B2: Final
A5: Operational Resources (Switchable)
A7: Unavailable to ERCOT during summer 6/1-9/30
A9: UNIT NAME | B9: UNIT CODE | C9: COUNTY | D9: FUEL | E9: ZONE | F9: IN SERVICE | G9: 2027 | H9: 2030
A10: ANTELOPE IC 1 | B10: ANTLP_G1 | C10: HALE | D10: GAS | E10: WEST | F10: 2016 | G10: 54 | H10: 54
A11: ANTELOPE IC 2 | B11: ANTLP_G2 | C11: HALE | D11: GAS | E11: WEST | F11: 2016 | G11: 54 | H11: 54
A12: ANTELOPE IC 3 | B12: ANTLP_G3 | C12: HALE | D12: GAS | E12: WEST | F12: 2016 | G12: 54 | H12: 54
A13: ELK STATION CTG 1 | B13: AEEC_ELK_1 | C13: HALE | D13: GAS | E13: WEST | F13: 2016 | G13: 190 | H13: 190
A14: ELK STATION CTG 2 | B14: AEEC_ELK_2 | C14: HALE | D14: GAS | E14: WEST | F14: 2016 | G14: 190 | H14: 190
A15: ELK STATION CTG 3 | B15: AEEC_ELK_3 | C15: HALE | D15: GAS | E15: WEST | F15: 2016 | G15: 190 | H15: 190
A16: TENASKA GATEWAY STATION CTG 1 | B16: TGCCS_CT1 | C16: RUSK | D16: GAS-CC | E16: NORTH | F16: 2001 | G16: 156 | H16: -
A17: TENASKA GATEWAY STATION CTG 2 | B17: TGCCS_CT2 | C17: RUSK | D17: GAS-CC | E17: NORTH | F17: 2001 | G17: 135 | H17: 135
A18: TENASKA GATEWAY STATION CTG 3 | B18: TGCCS_CT3 | C18: RUSK | D18: GAS-CC | E18: NORTH | F18: 2001 | G18: 153 | H18: -
A19: TENASKA GATEWAY STATION STG 4 | B19: TGCCS_UNIT4 | C19: RUSK | D19: GAS-CC | E19: NORTH | F19: 2001 | G19: 400 | H19: 400
A20: TENASKA KIAMICHI STATION 2CT101 | B20: KMCHI_2CT101 | C20: FANNIN | D20: GAS-CC | E20: NORTH | F20: 2003 | G20: 150 | H20: 150
A21: TENASKA KIAMICHI STATION 2CT201 | B21: KMCHI_2CT201 | C21: FANNIN | D21: GAS-CC | E21: NORTH | F21: 2003 | G21: 152 | H21: 152
A22: TENASKA KIAMICHI STATION 2ST | B22: KMCHI_2ST | C22: FANNIN | D22: GAS-CC | E22: NORTH | F22: 2003 | G22: 311 | H22: 311
A23: Switchable Capacity Unavailable to ERCOT | B23: SWITCH_UNAVAIL | D23: GAS | G23: =SUM(G10:G22) -> 2189 | H23: =SUM(H10:H22) -> 1880
A25: Unavailable to ERCOT during winter 12/1-2/28
A27: UNIT NAME | B27: UNIT CODE | C27: COUNTY | D27: FUEL | E27: ZONE | F27: IN SERVICE | G27: 2026/2027 | H27: 2027/2028 | I27: 2029/2030 | J27: 2030/2031
A28: ANTELOPE IC 1 | B28: ANTLP_G1 | C28: HALE | D28: GAS | E28: WEST | F28: 2016 | G28: 56 | H28: 56 | I28: 56 | J28: 56
A29: ANTELOPE IC 2 | B29: ANTLP_G2 | C29: HALE | D29: GAS | E29: WEST | F29: 2016 | G29: - | H29: - | I29: 56 | J29: 56
A30: ELK STATION CTG 1 | B30: AEEC_ELK_1 | C30: HALE | D30: GAS | E30: WEST | F30: 2016 | G30: 200 | H30: 200 | I30: 200 | J30: 200
A31: ELK STATION CTG 2 | B31: AEEC_ELK_2 | C31: HALE | D31: GAS | E31: WEST | F31: 2016 | G31: 200 | H31: 200 | I31: 200 | J31: 200
A32: TENASKA GATEWAY STATION CTG 1 | B32: TGCCS_CT1 | C32: RUSK | D32: GAS-CC | E32: NORTH | F32: 2001 | G32: - | H32: 162 | I32: 162 | J32: -
A33: TENASKA GATEWAY STATION CTG 2 | B33: TGCCS_CT2 | C33: RUSK | D33: GAS-CC | E33: NORTH | F33: 2001 | G33: 179 | H33: 179 | I33: 179 | J33: 179
A34: TENASKA GATEWAY STATION CTG 3 | B34: TGCCS_CT3 | C34: RUSK | D34: GAS-CC | E34: NORTH | F34: 2001 | G34: - | H34: - | I34: 178 | J34: -
A35: TENASKA GATEWAY STATION STG 4 | B35: TGCCS_UNIT4 | C35: RUSK | D35: GAS-CC | E35: NORTH | F35: 2001 | G35: 389 | H35: 389 | I35: 389 | J35: 389
A36: TENASKA KIAMICHI STATION 2CT101 | B36: KMCHI_2CT101 | C36: FANNIN | D36: GAS-CC | E36: NORTH | F36: 2003 | G36: 185 | H36: 185 | I36: 185 | J36: 185
A37: TENASKA KIAMICHI STATION 2CT201 | B37: =VLOOKUP(A37,$A$10:$B$22,2,0) -> KMCHI_2CT201 | C37: =VLOOKUP(A37,$A$10:$C$22,3,0) -> FANNIN | D37: =VLOOKUP(A37,$A$10:$D$22,4,0) -> GAS-CC | E37: =VLOOKUP(A37,$A$10:$E$22,5,0) -> NORTH | F37: =VLOOKUP(A37,$A$10:$F$22,6,0) -> 2003 | G37: - | H37: - | I37: 152 | J37: 152
A38: TENASKA KIAMICHI STATION 2ST | B38: =VLOOKUP(A38,$A$10:$B$22,2,0) -> KMCHI_2ST | C38: =VLOOKUP(A38,$A$10:$C$22,3,0) -> FANNIN | D38: =VLOOKUP(A38,$A$10:$D$22,4,0) -> GAS-CC | E38: =VLOOKUP(A38,$A$10:$E$22,5,0) -> NORTH | F38: =VLOOKUP(A38,$A$10:$F$22,6,0) -> 2003 | G38: - | H38: - | I38: 311 | J38: 311
A39: Switchable Capacity Unavailable to ERCOT | B39: SWITCH_UNAVAIL | D39: GAS | G39: =SUM(G28:G36) -> 1209 | H39: =SUM(H28:H36) -> 1371 | I39: =SUM(I28:I36) -> 1605 | J39: =SUM(J28:J36) -> 1265
A41: Unavailable to ERCOT during Spring 3/1-5/30
A43: UNIT NAME | B43: UNIT CODE | C43: COUNTY | D43: FUEL | E43: ZONE | F43: IN SERVICE | G43: 2027 | H43: 2030
A44: ANTELOPE IC 1 | B44: =VLOOKUP(A44,$A$10:$B$22,2,0) -> ANTLP_G1 | C44: =VLOOKUP(A44,$A$10:$C$22,3,0) -> HALE | D44: =VLOOKUP(A44,$A$10:$D$22,4,0) -> GAS | E44: =VLOOKUP(A44,$A$10:$E$22,5,0) -> WEST | F44: =VLOOKUP(A44,$A$10:$F$22,6,0) -> 2016 | G44: 56 | H44: 56
A45: ANTELOPE IC 2 | B45: =VLOOKUP(A45,$A$10:$B$22,2,0) -> ANTLP_G2 | C45: =VLOOKUP(A45,$A$10:$C$22,3,0) -> HALE | D45: =VLOOKUP(A45,$A$10:$D$22,4,0) -> GAS | E45: =VLOOKUP(A45,$A$10:$E$22,5,0) -> WEST | F45: =VLOOKUP(A45,$A$10:$F$22,6,0) -> 2016 | G45: - | H45: 56
A46: ELK STATION CTG 1 | B46: =VLOOKUP(A46,$A$10:$B$22,2,0) -> AEEC_ELK_1 | C46: =VLOOKUP(A46,$A$10:$C$22,3,0) -> HALE | D46: =VLOOKUP(A46,$A$10:$D$22,4,0) -> GAS | E46: =VLOOKUP(A46,$A$10:$E$22,5,0) -> WEST | F46: =VLOOKUP(A46,$A$10:$F$22,6,0) -> 2016 | G46: 195 | H46: 195
A47: ELK STATION CTG 2 | B47: =VLOOKUP(A47,$A$10:$B$22,2,0) -> AEEC_ELK_2 | C47: =VLOOKUP(A47,$A$10:$C$22,3,0) -> HALE | D47: =VLOOKUP(A47,$A$10:$D$22,4,0) -> GAS | E47: =VLOOKUP(A47,$A$10:$E$22,5,0) -> WEST | F47: =VLOOKUP(A47,$A$10:$F$22,6,0) -> 2016 | G47: 195 | H47: 195
A48: TENASKA GATEWAY STATION CTG 1 | B48: =VLOOKUP(A48,$A$10:$B$22,2,0) -> TGCCS_CT1 | C48: =VLOOKUP(A48,$A$10:$C$22,3,0) -> RUSK | D48: =VLOOKUP(A48,$A$10:$D$22,4,0) -> GAS-CC | E48: =VLOOKUP(A48,$A$10:$E$22,5,0) -> NORTH | F48: =VLOOKUP(A48,$A$10:$F$22,6,0) -> 2001 | G48: - | H48: 162
...

Sheet DC Tie Modeling & Dispatch
A1: Date Last Updated: | B1: 45711 | C1: Back
A2: Status | B2: Final
A5: Economic Analysis
A6: DC Tie Dispatch - 8760-hour Assumptions
A7: DC_E | B7: Import + Export | C7: Mapped to hourly generation and demand profiles based on historical operational data.
A8: DC_N | B8: Import + Export | C8: Mapped to hourly generation and demand profiles based on historical operational data.
A9: DC_L | B9: Import + Export | C9: Mapped to hourly generation and demand profiles based on historical operational data.
A10: DC_R | B10: Import + Export | C10: Mapped to hourly generation and demand profiles based on historical operational data.

Sheet Reserve Requirement
A1: Date Last Updated: | B1: 45721 | C1: Back
A2: Status | B2: Final
A5: Economic Analysis | B5: 1801
A6: The reserve requirement used in the economic models are based on a review of ERCOT’s 2025 Responsive Reserve and Regulation Up requirements. Note that the MW contribution of load resources is not an input into the economic model.

Sheet Fuel Price Assumptions
A1: Date Last Updated: | B1: 45859 | C1: Back
A2: Status | B2: Final
A3: Source | B3: EIA 2025 AEO Reference Case
B5: Natural Gas Price Forecast ($/MMBtu)
A6: Year | B6: Jan | C6: Feb | D6: Mar | E6: Apr | F6: May | G6: Jun | H6: Jul | I6: Aug | J6: Sep | K6: Oct | L6: Nov | M6: Dec | N6: Average
A7: 2025 | B7: 3.1245888 | C7: 2.9082924 | D7: 2.718418 | E7: 2.7921721 | F7: 2.8874514 | G7: 2.9540664 | H7: 2.8656951 | I7: 2.9021233 | J7: 2.914329 | K7: 3.0189808 | L7: 3.0033759 | M7: 3.1702508 | N7: =AVERAGE(B7:M7) -> 2.938312
A8: 2026 | B8: 3.0206578 | C8: 2.8115559 | D8: 2.6279972 | E8: 2.699298 | F8: 2.7914081 | G8: 2.8558074 | H8: 2.7703755 | I8: 2.805592 | J8: 2.8173917 | K8: 2.9185626 | L8: 2.9034768 | M8: 3.064801 | N8: =AVERAGE(B8:M8) -> 2.840577
A9: 2027 | B9: 2.9374482 | C9: 2.7341064 | D9: 2.5556041 | E9: 2.6249408 | F9: 2.7145136 | G9: 2.7771388 | H9: 2.6940603 | I9: 2.7283068 | J9: 2.7397814 | K9: 2.8381653 | L9: 2.8234951 | M9: 2.9803753 | N9: =AVERAGE(B9:M9) -> 2.762328
A10: 2028 | B10: 3.1185062 | C10: 2.9026309 | D10: 2.7131261 | E10: 2.7867366 | F10: 2.8818304 | G10: 2.9483157 | H10: 2.8601164 | I10: 2.8964738 | J10: 2.9086557 | K10: 3.0131038 | L10: 2.9975293 | M10: 3.1640793 | N10: =AVERAGE(B10:M10) -> 2.932592
A11: 2029 | B11: 3.3651236 | C11: 3.1321765 | D11: 2.9276853 | E11: 3.007117 | F11: 3.1097311 | G11: 3.1814742 | H11: 3.0862999 | I11: 3.1255325 | J11: 3.1386778 | K11: 3.2513858 | L11: 3.2345796 | M11: 3.4143007 | N11: =AVERAGE(B11:M11) -> 3.164507
A12: 2030 | B12: 3.6498383 | C12: 3.3971821 | D12: 3.1753894 | E12: 3.2615417 | F12: 3.3728376 | G12: 3.4506507 | H12: 3.347424 | I12: 3.3899759 | J12: 3.4042334 | K12: 3.5264774 | L12: 3.5082493 | M12: 3.7031761 | N12: =AVERAGE(B12:M12) -> 3.432248
A13: 2031 | B13: 3.9020258 | C13: 3.6319122 | D13: 3.3947947 | E13: 3.4868996 | F13: 3.6058856 | G13: 3.6890753 | H13: 3.578716 | I13: 3.6242081 | J13: 3.6394507 | K13: 3.7701412 | L13: 3.7506537 | M13: 3.9590491 | N13: =AVERAGE(B13:M13) -> 3.669401
A14: 2032 | B14: 4.5735858 | C14: 4.2569841 | D14: 3.9790574 | E14: 4.0870141 | F14: 4.2264783 | G14: 4.3239853 | H14: 4.1946327 | I14: 4.2479542 | J14: 4.2658201 | K14: 4.4190032 | L14: 4.3961617 | M14: 4.6404231 | N14: =AVERAGE(B14:M14) -> 4.300925

Sheet Emission Cost Assumptions
A1: Date Last Updated: | B1: 45839 | C1: Back
A2: Status | B2: Final
A3: Source | B3: EIA AEO
A6: Emission | B6: $/ton
A7: Nox (Seasonal) | B7: 166
A8: SO2 | B8: 0
A9: CO2 | B9: 0

Sheet Load Forecast Weather Year
A1: Date Last Updated: | B1: 45839 | C1: Back
A2: Status | B2: Final
A5: Load forecast
A6: Weather year assumption | B6: Base: 2013
A7: The peak and hourly profile information is included in Appendix D along with the case information
A9: Note that the 2013 weather scenario is the base weather scenario used as the starting point in the economic analysis.
