Workbook

Sheet Index
A1: RTP Scope Section Number | B1: Input Assumption | C1: Status | D1: Date
A2: Transmission Topology
A3: 3.1.1 | B3: Start Cases | C3: ='Start Cases'!B2 -> Final | D3: =IF('Start Cases'!B1= "","N/A",'Start Cases'!B1) -> 45874
A4: 3.1.2 | B4: RPG Projects Backed Out For Lack of Approval or Moved Due to ISD Change | C4: ='RPG Projects Removed or Moved'!B2 -> Final | D4: =IF('RPG Projects Removed or Moved'!B1 ="","N/A",'RPG Projects Removed or Moved'!B1) -> 46009
A5: 3.1.2 | B5: Recently Approved RPG Projects | C5: ='Recently Approved RPG Projects'!B2 -> Final | D5: =IF('Recently Approved RPG Projects'!B1= "","N/A",'Recently Approved RPG Projects'!B1) -> 45994
A6: 3.1.2 | B6: Model Updates & Corrections | C6: ='Model Updates & Corrections'!B2 -> Final | D6: =IF('Model Updates & Corrections'!B1= "","N/A",'Model Updates & Corrections'!B1) -> 46009
A7: 3.1.3 | B7: Transmission & Generation Outages | C7: ='Transmission & Gen Outages'!B2 -> Final | D7: =IF('Transmission & Gen Outages'!B1= "","N/A",'Transmission & Gen Outages'!B1) -> 46010
A8: 3.1.5 | B8: Temperatures Used in Dynamic Rating Calculation | C8: ='Temp. for Dynamic Ratings'!B2 -> Final | D8: =IF('Temp. for Dynamic Ratings'!B1 ="","N/A",'Temp. for Dynamic Ratings'!B1) -> 45874
A9: Generation
A10: 3.2.1 | B10: Generation Additions, Retirements and Mothballs | C10: ='Gen Add. Ret. and Mothball'!B2 -> Final | D10: =IF('Gen Add. Ret. and Mothball'!B1= "","N/A",'Gen Add. Ret. and Mothball'!B1) -> 46010
A11: 3.2.2 | B11: Renewable Generation Dispatch | C11: ='Renewable Generation Dispatch'!B2 -> Final | D11: =IF('Renewable Generation Dispatch'!B1= "","N/A",'Renewable Generation Dispatch'!B1) -> 45874
A12: 3.2.3 | B12: Switchable Generation | C12: ='Switchable Generation'!B2 -> Final | D12: =IF('Switchable Generation'!B1= "","N/A",'Switchable Generation'!B1) -> 45874
A13: 3.2.4 | B13: DC Tie Modeling and Dispatch | C13: ='DC Tie Modeling & Dispatch'!B2 -> Final | D13: =IF('DC Tie Modeling & Dispatch'!B1= "","N/A",'DC Tie Modeling & Dispatch'!B1) -> 45874
A14: 3.2.5 | B14: Reserve Requirement | C14: ='Reserve Requirement'!B2 -> Final | D14: =IF('Reserve Requirement'!B1= "","N/A",'Reserve Requirement'!B1) -> 45874
A15: 3.2.6 | B15: Fuel Price Assumptions | C15: ='Fuel Price Assumptions'!B2 -> Final | D15: =IF('Fuel Price Assumptions'!B1= "","N/A",'Fuel Price Assumptions'!B1) -> 45874
A16: Demand
A17: 3.3 | B17: SSWG Forecast 90/10 Forecast RTP Summer Peak Case Forecast RTP Min Load Case Forecast | C17: ='Reliability Case-Load Forecast'!B2 -> Final | D17: =IF('Reliability Case-Load Forecast'!B1= "","N/A",'Reliability Case-Load Forecast'!B1) -> 45874
A18: Other Studies
A19: 4.2.2 | B19: Sensitivity Analysis | C19: ='Sensitivity Analysis'!B2 -> Final | D19: =IF('Sensitivity Analysis'!B1 ="","N/A",'Sensitivity Analysis'!B1) -> 46013

Sheet Start Cases
A1: Date Last Updated: | B1: 45874 | C1: Back
A2: Status: | B2: Final
A4: SSWG Case Version: | B4: 24SSWG Update 1 Final - October 14, 2022
A6: On Peak Cases:
A7: 24SSWG_2027_SUM1_U1_Final_10142024.raw
A8: 24SSWG_2028_SUM1_U1_Final_10142024.raw
A9: 24SSWG_2030_SUM1_U1_Final_10142024.raw
A10: 24SSWG_2031_SUM1_U1_Final_10142024.raw
A12: Off Peak Case:
A13: 24SSWG_2028_MIN_U1_Final_10142024.raw

Sheet RPG Projects Removed or Moved
A1: Date Last Updated: | B1: 46009 | C1: Back
A2: Status: | B2: Final
A3: Based on TPIT dated: | B3: 45566
A5: RPG Projects Removed from the RTP Cases
A6: ERCOT Project Number | B6: Project Title | C6: Project Description | D6: "from" Location | E6: "to" Location | F6: Associated Projects | G6: Transmission Owner | H6: TSP Contact | I6: Transmission Owner Project Number (Optional) | J6: Projected In-Service Date (Month/Yr) | K6: Service Level kV | L6: Planning Charter Tier | M6: Date Submitted TO ERCOT for RPG Review (Month/Yr) | N6: Date RPG Review Completed (Month/Yr) | O6: Date ERCOT BOD Review Completed (Month/Yr) | P6: SSWG Base Case Related Bus Numbers (If applicable) (CSV) | Q6: Is the project reflected in SSWG Base Cases? (Y/N) | R6: Phase Number | S6: MOD Project Number
A7: 70710 | B7: Eden to Yellowjacket: Rebuild 69 kV Line | C7: Rehab the Eden to Yellowjacket 69kV line. | D7: Eden | E7: Yellowjacket | G7: AEP TCC | H7: Damian Raab twang1@aep.com 918-599-2635 | I7: TA2021119 | J7: 46721 | K7: 69 | L7: Tier 3 | M7: Not Submitted | N7: NA | O7: NA | P7: 6363, 6372 | Q7: Y | R7: 70711 | S7: 70710
A8: 67915 | B8: Asherton to West Batesville: Rebuild 138 kV Line | C8: Rehab Asherton to West Batesville 138 kV line. | D8: Asherton | E8: West Batesville | G8: AEP TCC/ETT | H8: John Solis jsolis@aep.com 361-881-5574 | J8: 47117 | K8: 138 | L8: Tier 3 | M8: NA | N8: NA | O8: NA | P8: 8236, 8283, 8285 | Q8: Y | R8: 67916 | S8: 67915
A9: 78473A | B9: Odin (ODI) 138kV CEHE Substation | C9: Loop new CEHE 138kV substation Odin (ODI) into Ckt. 36 to create new Ckt. 36 COPPER to Odin to Booster tap to Jones Creek. | D9: Odin | E9: Brazosport/Booster | G9: CNP | H9: Wesley Woitt wesley.woitt@centerpointenergy.com 713-207-2760 | J9: 46053 | K9: 138 | L9: Tier 3 | M9: NA | N9: NA | O9: NA | P9: 42199, 42215, 42280 | Q9: Y | R9: 87133 | S9: 78473
A10: 78473B | B10: Odin (ODI) 138kV CEHE Substation | C10: Install one generator lead from CEHE 138kV substation Odin (ODI) to VALHAL (VAL) / Valhalla Solar (26INR0042) | D10: Odin | E10: VALHAL | G10: CNP | H10: Wesley Woitt wesley.woitt@centerpointenergy.com 713-207-2760 | J10: 46053 | K10: 138 | L10: Tier 3 | M10: NA | N10: NA | O10: NA | P10: 42280, 113811 | Q10: Y | R10: 87134 | S10: 78473
A11: 76654 | B11: Establish Voss Lake 345/138 kV Switch | C11: Establish Voss Lake 345/138 kV Switch | D11: Voss Lake | E11: Voss Lake | G11: ONCOR | H11: Jared Gurley jared.gurley@oncor.com 817-215-6079 | I11: R6278 | J11: 46371 | K11: 345 | L11: Tier 3 | M11: 45715 | P11: 3675, 3678, 3687, 3717, 3740, 3750, 3751, 3752, 3761, 13429, 13430 | Q11: Y | R11: 76655 | S11: 76654
A12: 76728 | B12: Skyview 345/138 kV Switch | C12: Establish Skyview 345/138 kV Switch | D12: Skyview | G12: ONCOR | H12: Jared Gurley jared.gurley@oncor.com 817-215-6079 | I12: M4350 | J12: 46522 | K12: 138 | L12: Tier 3 | M12: Not Submitted | N12: NA | O12: NA | P12: 1922, 1924, 1927, 2119, 2120, 2123, 2124, 2125, 2127, 2128, 2129, 2130, 2131, 2132, 2134, 2231, 2243, 2244, 11938 | Q12: Y | R12: 76831 | S12: 76728
A13: 71910 | B13: Rebuild the Hillsboro - Elm Mott 69 kV Line | C13: Rebuild the Hillsboro - Elm Mott 68 kV Line | D13: Hillsboro | E13: Elm Mott | G13: ONCOR | H13: Jared Gurley jared.gurley@oncor.com 817-215-6079 | I13: R6221 | J13: 47102 | K13: 69 | L13: Tier 3 | M13: Not Submitted | N13: NA | O13: NA | P13: 3408, 3523, 3524, 3525, 3526, 3527, 3528, 3529, 13525 | Q13: Y | R13: 71911 | S13: 71910
A14: 6287 | B14: Sherry Sw. - Webb/Kennedale 345 kV DCKT Line | C14: Upgrade existing 345 kV Line | D14: Sherry | E14: Webb/Kennedale | G14: ONCOR | H14: Jared Gurley jared.gurley@oncor.com 817-215-6079 | I14: M4252 | K14: 345 | L14: Tier 3 | M14: Not Submitted | N14: NA | O14: NA | P14: 1911, 1918, 1929, 1930, 1932, 1934 | Q14: Y | R14: 14016 | S14: 6287
A15: 76669 | B15: Rebuild Elbow to Redberry to Bulldog 138 kV Line | C15: Rebuild Elbow to Redberry to Bulldog 138 kV Line | D15: Elbow | E15: Bulldog | G15: ONCOR | H15: Jared Gurley jared.gurley@oncor.com 817-215-6079 | I15: R8666 | J15: 46371 | K15: 138 | L15: Tier 3 | M15: Not Submitted | N15: NA | O15: NA | P15: 10080, 23833, 23834 | Q15: Y | R15: 77043 | S15: 76669
A16: 76696 | B16: Construct a new Border – Shifting Sands 138 kV Line | C16: Construct a new Border – Shifting Sands 138 kV Line | D16: Atchison | E16: Shifting Sands | G16: ONCOR | H16: Jared Gurley jared.gurley@oncor.com 817-215-6079 | I16: R8628 | J16: 46371 | K16: 138 | L16: Tier 3 | M16: Permian Basin Reliability Plan (common local transmission upgrade L1C) | P16: 11089, 11189, 11392, 18672, 18705 | Q16: Y | R16: 87872 | S16: 76696
A17: 76712 | B17: Bluff Creek to China Grove Line Rebuild | C17: Rebuild existing 138 kV Line | D17: Bluff Creek 138 kV Switch | E17: China Grove Switch | G17: ONCOR | H17: Jared Gurley jared.gurley@oncor.com 817-215-6079 | I17: R8655 | J17: 46371 | K17: 138 | L17: Tier 3 | M17: Not Submitted | P17: 1309, 1318 | Q17: Y | R17: 87645 | S17: 76712
A18: 81034 | B18: Lamesa - Willow Valley 138 kV Line | C18: Rebuild Lamesa to Willow Valley 138 kV line. | D18: Lamesa Switch | E18: Willow Valley Switch | G18: ONCOR | H18: Jared Gurley jared.gurley@oncor.com 817-215-6079 | I18: R8654 | J18: 46386 | K18: 138 | L18: Tier 3 | M18: Not Submitted | P18: 1163, 1301, 1307, 1308 | Q18: Y | R18: 81035 | S18: 81034
A19: 81152 | B19: China Grove to Tributary Line Rebuild | C19: China Grove to Tributary Line Rebuild | D19: China Grove | E19: Tributary Switch | G19: ONCOR | H19: Jared Gurley jared.gurley@oncor.com 817-215-6079 | I19: R8656 | J19: 46371 | K19: 138 | L19: Tier 3 | M19: Not Submitted | P19: 1318, 1394 | Q19: Y | R19: 87650 | S19: 81152
A20: 81175 | B20: Salt Flat Road 138 kV Switch and Salt Flat Road - Barr Ranch - Reiter 138 kV Second Circuit | C20: Add Salt Flat Road 138 kV Switch and Salt Flat Road - Barr Ranch - Reiter 138 kV Second Circuit | D20: Reiter | E20: Salt Flat Road | G20: ONCOR | H20: Jared Gurley jared.gurley@oncor.com 817-215-6079 | I20: R8704 | J20: 46006 | K20: 138 | L20: Tier 3 | M20: 45716 | P20: 1027, 1111, 1193, 1234, 1276, 11111, 11217, 11235, 11344, 18545, 18701, 23859 | Q20: Y | R20: 87224 | S20: 81175
A21: 81418 | B21: Reiter to Yarbrough 138 kV Line Rebuild | C21: 138 kV existing line rebuild. | D21: Reiter | E21: Yarbrough | G21: ONCOR | H21: Jared Gurley jared.gurley@oncor.com 817-215-6079 | I21: R8527 | J21: 46372 | K21: 138 | L21: Tier 3 | M21: 45716 | P21: 11111, 18545 | Q21: Y | R21: 81419 | S21: 81418
A22: 87653 | B22: Bluff Creek to Scurry Chevron Line Rebuild | C22: Rebuild Bluff Creek to Scurry Chevron | D22: Bluff Creek | E22: Scurry Chevron | G22: ONCOR | H22: Jared Gurley jared.gurley@oncor.com 817-215-6079 | I22: R9002 | J22: 46371 | K22: 138 | L22: Tier 3 | M22: Not Submitted | P22: 1309, 1310, 1312 | Q22: Y | R22: 87654 | S22: 5526
A23: 81305 | B23: Oncor_FW_Expanse - Tredway 138 kV Line | C23: Rebuild the existing Expanse – Vealmoor 138 kV Line with both circuits in place. | D23: Expanse | E23: Tredway | G23: ONCOR | H23: Jared Gurley jared.gurley@oncor.com 817-215-6079 | I23: R8681 | J23: 46157 | K23: 345 | L23: Tier 3 | M23: 45198 | P23: 1355, 10032, 10090, 10097, 10098, 10110, 10112, 10113, 11006, 11338, 11348, 11349, 11368, 11383, 23829, 23835, 23838, 23849, 23880 | Q23: Y | R23: 87873 | S23: 81305
A24: 73436 | B24: Rockhound - Connell 345 kV Double-Circuit Line | C24: Construct a new 345 kV Double-Circuit Line and establish a 345/138 kV Switch | D24: Rockhound | E24: Connell | G24: ONCOR | H24: Jared Gurley jared.gurley@oncor.com 817-215-6079 | I24: R8718, R8807 | J24: 46372 | K24: 345 | L24: Tier 2 | M24: 45461 | P24: 10033, 10036, 10062, 10085, 10086, 10087, 10088, 10089, 11371, 23840, 23841, 23855 | Q24: Y | R24: 81403 | S24: 73436
A25: 81440 | B25: Wolf to Monahan to Pecos / Odessa EHV to Reiter138 kV Line Rebuild | C25: 138 kV existing line rebuild. | D25: Wolf/Odessa EHV | E25: Pecos/Reiter | G25: ONCOR | H25: Jared Gurley jared.gurley@oncor.com 817-215-6079 | I25: R8527, R8629 | J25: 46737 | K25: 138 | L25: Tier 3 | M25: 45716 | P25: 1013, 1027, 1107, 11117, 18545 | Q25: Y | R25: 81441 | S25: 81440
A26: 72457 | B26: AddKiowaToQuinlanLine | C26: Add 138kV line from Kiowa to Quinlan | D26: Kiowa | E26: Quinlan | G26: RCEC | H26: Scott Donhamsdonham@rayburnelectric.com_x000D_ 469-402-2024 | J26: 46753 | K26: 138 | L26: Tier 2 | M26: Not Submitted | N26: NA | O26: NA | P26: 6796, 6884 | Q26: Y | R26: 72458 | S26: 72457
A28: RPG Projects With ISD Changes
A29: ERCOT Project Number | B29: Project Title | C29: Project Description | D29: "from" Location | E29: "to" Location | F29: Associated Projects | G29: Transmission Owner | H29: TSP Contact | I29: Transmission Owner Project Number (Optional) | J29: Original Projected In-Service Date (Month/Yr) | K29: New Projected In-Service Date (Month/Yr) | L29: Service Level kV | M29: Planning Charter Tier | N29: Date Submitted TO ERCOT for RPG Review (Month/Yr) | O29: Date RPG Review Completed (Month/Yr) | P29: Date ERCOT BOD Review Completed (Month/Yr) | Q29: SSWG Base Case Related Bus Numbers (If applicable) (CSV) | R29: Is the project reflected in SSWG Base Cases? (Y/N) | S29: Phase Number | T29: MOD Project Number
A30: 17TPIT0031 | B30: Elkton 345/138 kV Autotransformer | C30: Replace existing autotransformer | D30: Elkton | E30: Elkton | G30: ONCOR | H30: Jared Gurley jared.gurley@oncor.com 817-215-6079 | I30: R6023-E | K30: 47618 | L30: 345 | M30: Tier 3 | N30: Not Submitted | Q30: 3105, 3106, 29150 | R30: Y | S30: 10501 | T30: 3155
A31: 5981 | B31: Shamburger North 345/138 kV Switching Station | C31: Establish Shamburger North 345/138 kV Switching Station | D31: Shamburger North | E31: Shamburger North | G31: ONCOR | H31: Jared Gurley jared.gurley@oncor.com 817-215-6079 | I31: R6083 | K31: 47618 | L31: 345 | M31: Tier 3 | N31: Not Submitted | Q31: 2485, 3103, 3201, 3206, 3217, 3223, 3226 | R31: Y | S31: 13696 | T31: 5981
A32: 6304 | B32: Shamburger North - Shamburger 345 kV Line | C32: Upgrade existing 345 kV Line | D32: Shamburger North | E32: Shamburger | G32: ONCOR | H32: Jared Gurley jared.gurley@oncor.com 817-215-6079 | I32: R6085 | K32: 47618 | L32: 345 | M32: Tier 3 | N32: Not Submitted | Q32: 3103, 3223 | R32: Y | S32: 14033 | T32: 6304

Sheet Recently Approved RPG Projects
A1: Date Last Updated: | B1: 45994 | C1: Back
A2: Status: | B2: Final
A4: RPG Project ID | B4: RPG Project Name | C4: TDSP | D4: Approve Date
A5: 24RPG001 | B5: Temple Area Project | C5: ONCOR | D5: 2024
A6: 24RPG002 | B6: Rockhound 345/138-kV Switch and Grey Well Draw to Buffalo 2nd 138-kV Circuit Project | C6: ONCOR | D6: 2024
A7: 24RPG003 | B7: Eastside 345/138-kV Switching Station Project | C7: CPS | D7: 2024
A8: 24RPG004 | B8: Omicron Reliability Project | C8: CPS | D8: 2024
A9: 24RPG005 | B9: Montfort Switch to Shankle Switch 138-kV Line Project | C9: ONCOR | D9: 2024
A10: 24RPG006 | B10: Prairieland 345/138-kV Switch and Prairieland Switch to Quartz Sand Switch/Hog Mountain Pod 138-kV Line Project | C10: ONCOR | D10: 2024
A11: 24RPG008 | B11: Brownsville Area Improvements Transmission Project | C11: AEP | D11: 2024
A12: 24RPG010 | B12: Delaware Basin Stage 3 and 4 Project | C12: ONCOR | D12: 2024
A13: 24RPG014 | B13: Sim Gideon to Cedar Hill Transmission Line Upgrade Project | C13: LCRA | D13: 2024
A14: 24RPG015 | B14: Delaware Basin Stage 5 Project | C14: ONCOR | D14: 2025
A15: 24RPG017 | B15: Venus Switch to Sam Switch 345-kV Line Project | C15: ONCOR | D15: 2024
A16: 24RPG018 | B16: Salado Switch to Hutto Switch 138-kV Line Project | C16: ONCOR | D16: 2024
... A26: 24RPG035 | B26: Aransas Pass to Rincon 69-kV Line Rebuild Project | C26: AEP | D26: 2025
A27: 24RPG037 | B27: Partial Rebuild of 138-kV Ckt.63 West Galveston to Moody Project | C27: CNP | D27: Reclassified as Tier 4
A28: 24RPG038 | B28: Bergheim Substation Upgrade Project | C28: LCRA/PEC | D28: 2025
A29: 24RPG040 | B29: Roscoe Area Upgrades Project | C29: ONCOR | D29: 2025
A30: 24RPG041 | B30: Buck Canyon and Binturong 345-kV Synchronous Condenser Stations Project | C30: WETT | D30: 2025
A31: 25RPG001 | B31: Texas A&M University System RELLIS Campus Reliability Project | C31: BTU | D31: 2025
A32: 25RPG002 | B32: East Munday 138-kV Station Rebuild Project | C32: AEP | D32: Reclassified as Tier 4
A33: 25RPG003 | B33: Hamilton County Conversion Project | C33: BEC | D33: 2025
A34: 25RPG005 | B34: Pitchfork 345-kV Substation Addition Project | C34: WETT | D34: 2025
A35: 25RPG006 | B35: Salado Switch to Hutto Switch 138-kV Line Project | C35: ONCOR | D35: 2025
A36: 25RPG007 | B36: Salt Flat Road to Barr Ranch to Reiter 138-kV Second Circuit Project | C36: ONCOR | D36: 2025
A37: 25RPG008 | B37: Wolf Switch to Reiter Switch 138-kV Line Project | C37: ONCOR | D37: 2025
A38: 25RPG010 | B38: 138-kV Flewellen to Fort Bend Upgrades Project | C38: CNP | D38: 2025
A39: 25RPG011 | B39: 138-kV West Columbia to Needville Upgrades | C39: CNP | D39: 2025
A40: 25RPG014 | B40: Cedar Bayou Autotransformer Upgrades Project | C40: CNP | D40: 2025
A41: 25RPG019 | B41: Lamesa Switch to Willow Valley Switch 138-kV Line Rebuild Project | C41: ONCOR | D41: 2025
A42: 25RPG021 | B42: AEPSC Victoria to Warburton 138-kV Line Rebuild Project | C42: AEP | D42: 2025
A43: 25RPG022 | B43: Oncor and AEPSC Drill Hole to Sand Lake to Solstice 765-kV Line Project | C43: AEPSC/ONCOR | D43: 2025
A44: 25RPG025 | B44: AEP Texas, CPS Energy, Oncor, and CNP Texas 765-kV-STEP Eastern Backbone Project | C44: AEP Texas/CPS/Oncor/CNP | D44: 2025
A45: 25RPG027 | B45: Royse Switch to Edgewood 69-kV Line Conversion to 138-kV Project | C45: ONCOR | D45: Reclassified as Tier 4
A46: 25RPG029 | B46: Hillsboro Switch to Elm Mott Switch 69-kV Line Rebuild Project | C46: ONCOR | D46: Reclassified as Tier 4
A47: 25RPG030 | B47: Bonham Switch to Toco Switch 69-kV Line Rebuild Project | C47: ONCOR | D47: Reclassified as Tier 4
A48: 25RPG031 | B48: Sam Switch Resiliency Project | C48: LST | D48: 2025
A49: 25RPG032 | B49: Fort Stockton Plant 138-kV Transmission Station Rebuild Project | C49: AEP | D49: 2025

Sheet Model Updates & Corrections
A1: Date Last Updated: | B1: 46009 | C1: Back
A2: Status: | B2: Final
A4: Model Corrections/Updates Made to the 2025 RTP Cases
A5: Transmission Changes | B5: TO | H5: Comments
C6: 2027 SUM | D6: 2028 MIN | E6: 2028 SUM | F6: 2030 SUM | G6: 2031 SUM
A7: Applied model update to update ratings, impedances, and line lengths on lines connected to Progress Park 138-kV Switch | B7: ONCOR | C7: X | D7: X | E7: X | F7: X | G7: X | H7: MOD 90069 - SSWG Incremental Update
A8: Added the LCRATSC Bastrop West Bluebonnet Transmission Line Upgrade MOD project to upgrade ratings on Bastrop West to Bluebonnet | B8: LCRA TSC | E8: X | F8: X | G8: X | H8: MOD 92602
A9: Added the LCRATSC Bluebonnet Wyldwood Transmission Line Overhaul MOD project to upgrade ratings on Wyldwood to Bluebonnet | B9: LCRA TSC | C9: X | D9: X | E9: X | F9: X | G9: X | H9: MOD 92598
A10: Added the LCRATSC Colton Elroy Transmission Line Overhaul MOD project to upgrade ratings on Colton to Elroy | B10: LCRA TSC | C10: X | D10: X | E10: X | F10: X | G10: X | H10: MOD 92561
A11: Added the LCRATSC Colton Mendoza Transmission Line Upgrade MOD project to upgrade ratings on Colton to Mendoza | B11: LCRA TSC | C11: X | D11: X | E11: X | F11: X | G11: X | H11: MOD 92627
A12: Added the LCRATSC Elroy Wolf Lane Transmission Line Overhaul MOD project to upgrade ratings on Elroy to County Line to Wolf Lane | B12: LCRA TSC | C12: X | D12: X | E12: X | F12: X | G12: X | H12: MOD 92622
A13: Added the LCRATSC Lockhart Mendoza Transmission Line Overhaul MOD project to upgrade ratings on Lockhart to Mendoza | B13: LCRA TSC | E13: X | F13: X | G13: X | H13: MOD 92572
A14: Added the LCRATSC Wolf Lane Wyldwood Transmission Line Overhaul MOD project to upgrade ratings on Wolf Lane to County Line to Wyldwood | B14: LCRA TSC | C14: X | D14: X | E14: X | F14: X | G14: X | H14: MOD 91397
A15: Added the ONCOR Watermill Reindeer Line Upgrade MOD project to upgrade ratings on the Watermill to Reindeer Line | B15: ONCOR | C15: X | D15: X | E15: X | F15: X | G15: X | H15: MOD 92845
A16: Applied topology update to the 138-kV path from TNMP Amoco to MPL Tank Farm to be Amoco to Spoonbill to MPL Tank Farm. | B16: TNMP | C16: X | D16: X | E16: X | F16: X | G16: X | H16: Confirmed by TNMP
A17: Added the ONCOR Tonkawa to Ranger Camp 345-kV Line Rebuild MOD project since the in-service MOD date has been updated | B17: ONCOR | C17: X | H17: MOD 72011
A18: Updated load interconnection topology which included relocating load from bus 8759 to bus 8318. | B18: AEPSC | C18: X | D18: X | E18: X | F18: X | G18: X | H18: Provided by AEPSC
A19: Updated load interconnection topology which included relocating load from bus 40170 to bus 940000. | B19: CNP | F19: X | G19: X | H19: Provided by CNP
A20: Updated load interconnection topology which included relocating load from bus 40700 to bus 940450. | B20: CNP | G20: X | H20: Provided by CNP
A21: Applied topology update to remove the Haber substation. | B21: AEPSC | C21: X | D21: X | H21: Confirmed by AEPSC
A22: Added the LCRATSC Canyon to San Marcos Transmission Line Upgrade MOD project to upgrade ratings on Canyon to San Marcos | B22: LCRA TSC | C22: X | D22: X | E22: X | F22: X | G22: X | H22: MOD 92575
A23: Added the LCRATSC Gabriel to Rivery MLSE Upgrade MOD project to upgrade ratings on Gabriel to Rivery | B23: LCRA TSC | C23: X | D23: X | E23: X | F23: X | G23: X | H23: MOD 92629
A24: Added the LCRATSC Howard Lane to Wells Branch Transmission Line Upgrade MOD project to upgrade ratings on Howard Lane to Wells Branch | B24: LCRA TSC | C24: X | D24: X | E24: X | F24: X | G24: X | H24: MOD 91404
A25: Added the LCRATSC Lytton Springs to Mendoza Transmission Line Upgrade MOD project to upgrade ratings on Lytton Springs to Mendoza | B25: LCRA TSC | C25: X | D25: X | E25: X | F25: X | G25: X | H25: MOD 100184
A26: Added the LCRATSC Georgetown to Rivery Transmission Line Upgrade MOD project to upgrade ratings on Georgetown to Rivery | B26: LCRA TSC | C26: X | D26: X | E26: X | F26: X | G26: X | H26: MOD 85973
A27: Holly (8486) bus tie breaker ratings upgrade. | B27: AEPSC | C27: X | D27: X | E27: X | F27: X | G27: X | H27: Updated ratings based on current operations model.
A31: Transformer Changes | B31: TO/GO | H31: Comments
C32: 2027 SUM | D32: 2028 MIN | E32: 2028 SUM | F32: 2030 SUM | G32: 2031 SUM
A33: Removed the branch connecting the Jordan transformer to Philip transformer. | B33: CNP | C33: X | H33: The connecting branch caused an violation on the Philip transformer (modeling error).
A34: Updated the voltage limits on the Cedar Bayou ckt. A3 transformer | B34: CNP | C34: X | D34: X | E34: X | F34: X | G34: X | H34: Confirmed by CNP
A35: Turned on North Edinburg transformer #2 | B35: AEPSC | C35: X | D35: X | E35: X | F35: X | G35: X | H35: SSWG modeling error
A36: Opened Kendal (7046) 345/138-kV AT#3 (N.O. in operations) | B36: LCRA TSC | C36: X | D36: X | E36: X | F36: X | G36: X | H36: Node breaker to bus branch modeling error; confirmed by LCRA TSC
A40: Generation Changes | B40: TO/GO | H40: Comments
C41: 2027 SUM | D41: 2028 MIN | E41: 2028 SUM | F41: 2030 SUM | G41: 2031 SUM
A42: Removed Garcitas Solar Unit on bus 113051 | B42: AEP | C42: X | D42: X | E42: X | F42: X | G42: X | H42: AEP confirmed that this solar site project has been cancelled
A46: Load Changes | B46: TO | H46: Comments
C47: 2027 SUM | D47: 2028 MIN | E47: 2028 SUM | F47: 2030 SUM | G47: 2031 SUM
A48: Moved/Adjusted Network-served and Self-Serve Loads at all buses within the DOWGEN PUN facility | B48: CNP | C48: X | D48: X | E48: X | F48: X | G48: X | H48: This self-serve adjustment was to account for the mothballing of DOWGEN units G66 and ST64.
A52: Bus Voltage Changes | B52: TO | H52: Comments
C53: 2027 SUM | D53: 2028 MIN | E53: 2028 SUM | F53: 2030 SUM | G53: 2031 SUM
...

Sheet Transmission & Gen Outages
A1: Date Last Updated: | B1: 46010 | C1: Back
A2: Status: | B2: Final
D4: Case
A5: Outaged Elements | B5: Outage Description | C5: Associated TO/RE | D5: 2027 SUM | E5: 2028 MIN | F5: 2028 SUM | G5: 2030 SUM | H5: 2031 SUM | I5: Notes
A7: Known outages collected by ERCOT from TSPs and Resource Entities were incorporated based on the TSP and ERCOT technical rationale into the known outages impact studies.

Sheet Temp. for Dynamic Ratings
A1: Date Last Updated: | B1: 45874 | C1: Back
A2: Status: | B2: Final
A4: Weather Zone | B4: 90th Percentile Temperature (degree F)
A5: Coast | B5: 105
A6: East | B6: 110
A7: Far West | B7: 115
A8: North Central | B8: 110
A9: North | B9: 110
A10: South Central | B10: 110
A11: South | B11: 105
A12: West | B12: 110

Sheet Gen Add. Ret. and Mothball
A1: Date Last Updated: | B1: 46010 | C1: Back
A2: Status: | B2: Final
A5: New generators that met PG Section 6.9 requirements (1)(b) through (1)(d) by 5/31/2025 in FULL LOAD CASES. New generators that met PG Section 6.9 requirements (1)(b) through (1)(d) by 9/30/2025 in SENSITIVITY CASES.
A7: GINR Reference Number | B7: Project Name | C7: County | D7: Projected COD | E7: Fuel | F7: MW For Grid | G7: Meets Section 6.9 Requirements (1)(b) through (1)(d) | H7: 2027 SUM | I7: 2027 SUM SENS | J7: 2028 MIN | K7: 2028 MIN SENS | L7: 2028 SUM | M7: 2030 SUM | N7: 2030 SUM SENS | O7: 2031 SUM | P7: Comments
A8: 22INR0540 | B8: Walstrom BESS | C8: Austin | D8: 45827 | E8: Battery | F8: 205.31 | G8: Y | H8: Y | I8: Y | J8: Y | K8: Y | L8: Y | M8: Y | N8: Y | O8: Y
A9: 22INR0517 | B9: Lane City Wind | C9: Wharton | D9: 45838 | E9: Wind | F9: 199.5 | G9: Y | H9: Y | I9: Y | J9: Y | K9: Y | L9: Y | M9: Y | N9: Y | O9: Y
A10: 23INR0079 | B10: Chillingham Storage | C10: Bell | D10: 45853 | E10: Battery | F10: 153.93 | G10: Y | H10: Y | I10: Y | J10: Y | K10: Y | L10: Y | M10: Y | N10: Y | O10: Y
A11: 24INR0456 | B11: FRIENDSWOOD ENERGY GENCO | C11: Harris | D11: 45856 | E11: Gas | F11: 143.7 | G11: Y | H11: Y | I11: Y | J11: Y | K11: Y | L11: Y | M11: Y | N11: Y | O11: Y
A12: 21INR0517 | B12: Tidwell Prairie Storage 1 | C12: Robertson | D12: 45869 | E12: Battery | F12: 204 | G12: Y | H12: Y | I12: Y | J12: Y | K12: Y | L12: Y | M12: Y | N12: Y | O12: Y
A13: 22INR0525 | B13: St. Gall II Energy Storage | C13: Pecos | D13: 45869 | E13: Battery | F13: 100.24 | G13: Y | H13: Y | I13: Y | J13: Y | K13: Y | L13: Y | M13: Y | N13: Y | O13: Y
A14: 19INR0054 | B14: Monte Cristo 1 Wind | C14: Hidalgo | D14: 45889 | E14: Wind | F14: 234.5 | G14: Y | H14: Y | I14: Y | J14: Y | K14: Y | L14: Y | M14: Y | N14: Y | O14: Y
A15: 25INR0467 | B15: Bocanova Power | C15: Brazoria | D15: 45895 | E15: Battery | F15: 150.46 | G15: Y | H15: Y | I15: Y | J15: Y | K15: Y | L15: Y | M15: Y | N15: Y | O15: Y
A16: 25INR0389 | B16: Stoneridge BESS | C16: Milam | D16: 45901 | E16: Battery | F16: 101.9 | G16: Y | H16: Y | I16: Y | J16: Y | K16: Y | L16: Y | M16: Y | N16: Y | O16: Y
A17: 24INR0166 | B17: Stillhouse Solar | C17: Bell | D17: 45902 | E17: Solar | F17: 210.8 | G17: Y | H17: Y | I17: Y | J17: Y | K17: Y | L17: Y | M17: Y | N17: Y | O17: Y
A18: 23INR0364 | B18: Tierra Seca BESS | C18: Val Verde | D18: 45903 | E18: Battery | F18: 102.7 | G18: Y | H18: Y | I18: Y | J18: Y | K18: Y | L18: Y | M18: Y | N18: Y | O18: Y
A19: 25INR0672 | B19: Fagus Solar Park 2 SLF | C19: Childress | D19: 45926 | E19: Solar | F19: 166.57 | G19: Y | H19: Y | I19: Y | J19: Y | K19: Y | L19: Y | M19: Y | N19: Y | O19: Y | P19: Split INR fix for Fagus Solar Park 1
A20: 26INR0669 | B20: Greyhound Solar - Phase E | C20: Ector | D20: 45926 | E20: Solar | F20: 150.71 | G20: Y | H20: Y | I20: Y | J20: Y | K20: Y | L20: Y | M20: Y | N20: Y | O20: Y
A21: 23INR0494 | B21: Cartwheel BESS 1 | C21: Hopkins | D21: 45930 | E21: Battery | F21: 154.2 | G21: Y | H21: Y | I21: Y | J21: Y | K21: Y | L21: Y | M21: Y | N21: Y | O21: Y
A22: 24INR0302 | B22: Pintail Pass BESS | C22: San Patricio | D22: 45930 | E22: Battery | F22: 207.25 | G22: Y | H22: Y | I22: Y | J22: Y | K22: Y | L22: Y | M22: Y | N22: Y | O22: Y
A23: 16INR0104 | B23: Big Sampson Wind | C23: Crockett | D23: 45934 | E23: Wind | F23: 265.4 | G23: Y | H23: Y | I23: Y | J23: Y | K23: Y | L23: Y | M23: Y | N23: Y | O23: Y
A24: 24INR0116 | B24: Hart Wind | C24: Castro | D24: 45961 | E24: Wind | F24: 163.4 | G24: Y | H24: Y | I24: Y | J24: Y | K24: Y | L24: Y | M24: Y | N24: Y | O24: Y
A25: 26INR0670 | B25: Greyhound Solar - Phase F | C25: Ector | D25: 45961 | E25: Solar | F25: 101.6 | G25: Y | H25: Y | I25: Y | J25: Y | K25: Y | L25: Y | M25: Y | N25: Y | O25: Y
A26: 24INR0181 | B26: Bynum Solar Project | C26: Coryell | D26: 45992 | E26: Solar | F26: 56 | G26: Y | H26: Y | I26: Y | J26: Y | K26: Y | L26: Y | M26: Y | N26: Y | O26: Y
A27: 23INR0351 | B27: Seven Flags BESS | C27: Webb | D27: 46003 | E27: Battery | F27: 102.7 | G27: Y | H27: Y | I27: Y | J27: Y | K27: Y | L27: Y | M27: Y | N27: Y | O27: Y
A28: 25INR0578 | B28: Forest Creek Wind Repower | C28: Glasscock | D28: 46006 | E28: Wind | F28: 125.1 | G28: Y | H28: Y | I28: Y | J28: Y | K28: Y | L28: Y | M28: Y | N28: Y | O28: Y | P28: Repower
A29: 23INR0501 | B29: Soda Lake BESS 1 | C29: Crane | D29: 46008 | E29: Battery | F29: 203.87 | G29: Y | H29: Y | I29: Y | J29: Y | K29: Y | L29: Y | M29: Y | N29: Y | O29: Y
A30: 23INR0344 | B30: Hermes Solar | C30: Bell | D30: 46021 | E30: Solar | F30: 100.36 | G30: Y | H30: Y | I30: Y | J30: Y | K30: Y | L30: Y | M30: Y | N30: Y | O30: Y
A31: 24INR0365 | B31: Hermes Storage | C31: Bell | D31: 46021 | E31: Battery | F31: 100.42 | G31: Y | H31: Y | I31: Y | J31: Y | K31: Y | L31: Y | M31: Y | N31: Y | O31: Y
A32: 20INR0242 | B32: Anson Solar 2 | C32: Jones | D32: 46022 | E32: Solar | F32: 200.9 | G32: Y | H32: Y | I32: Y | J32: Y | K32: Y | L32: Y | M32: Y | N32: Y | O32: Y
A33: 23INR0150 | B33: Cradle Solar | C33: Brazoria | D33: 46022 | E33: Solar | F33: 200.85 | G33: Y | H33: Y | I33: Y | J33: Y | K33: Y | L33: Y | M33: Y | N33: Y | O33: Y
A34: 23INR0249 | B34: Limewood Solar | C34: Bell | D34: 46022 | E34: Solar | F34: 204.6 | G34: Y | H34: Y | I34: Y | J34: Y | K34: Y | L34: Y | M34: Y | N34: Y | O34: Y
A35: 23INR0358 | B35: Castor BESS | C35: Brazoria | D35: 46022 | E35: Battery | F35: 205.39 | G35: Y | H35: Y | I35: Y | J35: Y | K35: Y | L35: Y | M35: Y | N35: Y | O35: Y
A36: 23INR0538 | B36: Roadrunner Crossing BESS SLF | C36: Eastland | D36: 46022 | E36: Battery | F36: 150.4 | G36: Y | H36: Y | I36: Y | J36: Y | K36: Y | L36: Y | M36: Y | N36: Y | O36: Y
A37: 24INR0472 | B37: Amador Storage | C37: Van Zandt | D37: 46022 | E37: Battery | F37: 102.41 | G37: Y | H37: Y | I37: Y | J37: Y | K37: Y | L37: Y | M37: Y | N37: Y | O37: Y
A38: 23INR0286 | B38: Dry Creek Solar I | C38: Rusk | D38: 46023 | E38: Solar | F38: 201.06 | G38: Y | H38: Y | I38: Y | J38: Y | K38: Y | L38: Y | M38: Y | N38: Y | O38: Y
A39: 24INR0453 | B39: Longfellow BESS I | C39: Pecos | D39: 46053 | E39: Battery | F39: 54.99 | G39: Y | H39: Y | I39: Y | J39: Y | K39: Y | L39: Y | M39: Y | N39: Y | O39: Y
A40: 24INR0455 | B40: Longfellow BESS II | C40: Pecos | D40: 46053 | E40: Battery | F40: 105.75 | G40: Y | H40: Y | I40: Y | J40: Y | K40: Y | L40: Y | M40: Y | N40: Y | O40: Y
... A51: 19INR0042 | B51: Long Point Solar | C51: Brazoria | D51: 46113 | E51: Solar | F51: 120.7 | G51: Y | H51: Y | I51: Y | J51: Y | K51: Y | L51: Y | M51: Y | N51: Y | O51: Y
A52: 24INR0044 | B52: Millers Branch Solar II | C52: Haskell | D52: 46113 | E52: Solar | F52: 178 | G52: Y | H52: Y | I52: Y | J52: Y | K52: Y | L52: Y | M52: Y | N52: Y | O52: Y | P52: Split INR fix for Millers Branch Solar 1
A53: 26INR0524 | B53: Fagus Solar Park 3 SLF | C53: Childress | D53: 46113 | E53: Solar | F53: 186.83 | G53: Y | H53: Y | I53: Y | J53: Y | K53: Y | L53: Y | M53: Y | N53: Y | O53: Y | P53: Split INR fix for Fagus Solar Park 1
...

Sheet Renewable Generation Dispatch
A1: Date Last Updated: | B1: 45874 | C1: Back
A2: Status: | B2: Final
A5: Solar
A6: Solar maximum capacity percentage based on historical Settlements HSL dispatch levels during the top 20 load hours of the last five years for summer peak conditions. Note: All solar units are offline in the MIN case.
A9: Summer Peak, Solar | B9: 0.73
A11: Wind
A12: Wind region maximum capacity percentages based on historical Settlements HSL dispatch levels during the top 20 load hours of the last ten years for summer peak conditions and three years for minimum load conditions. Each wind region was then scaled up 4% in the minimum load case to allow Quick Start units to be turned off.
A15: Summer Peak, Coastal | B15: Summer Peak, Panhandle | C15: Summer Peak, Other
A16: 0.55 | B16: 0.28 | C16: 0.21
A18: Min Case, Coastal | B18: Min Case, Panhandle | C18: Min Case, Other
A19: 0.36 | B19: 0.54 | C19: 0.48
A21: Hydro
A22: Unit specific generation MW dispatch modeled based on historical Settlements HSL dispatch levels during the top 20 load hours of the last three years. Note: All Hydro units are offline in the MIN case.
A25: AMI_AMISTAG1 (H1) | B25: 15.966667
A26: AMI_AMISTAG2 (H2) | B26: 16.141667
A27: AUS_AUSTING1 (H2) | B27: 8.0971666
A28: AUS_AUSTING1 (H1) | B28: 7.9999998
A29: BUC_BUCHANG1 (H1) | B29: 15.225833
A30: BUC_BUCHANG2 (H2) | B30: 15.192
A31: BUC_BUCHANG3 (H3) | B31: 16.143833
A32: CAN_CANYHYG1 (H1) | B32: 0
A33: CAN_CANYHYG1 (H2) | B33: 0
A34: DND_DENISOG1 (H1) | B34: 44.666667
A35: DND_DENISOG2 (H2) | B35: 40.166667
A36: EA_EAGLE_HY1 (H3) | B36: 0
... A51: WND_WHITNEY2 (H2) | B51: 19.793333

Sheet Switchable Generation
A1: Date Last Updated: | B1: 45874 | C1: Back
A2: Status: | B2: Final
A5: Operational Resources Unavailable to ERCOT (Switchable) | G5: Summer | H5: Winter | I5: Summer | J5: Summer | K5: Summer
A6: UNIT NAME | B6: UNIT CODE | C6: COUNTY | D6: FUEL | E6: ZONE | F6: IN SERVICE | G6: 2027 | H6: 2027/2028 | I6: 2028 | J6: 2030 | K6: 2031
A7: ANTELOPE IC 1 | B7: AEEC_ANTLP_1_UNAVAIL | C7: HALE | D7: GAS | E7: PANHANDLE | F7: 2016 | G7: -54 | H7: -56 | I7: -54 | J7: -54 | K7: -54
A8: ANTELOPE IC 2 | B8: AEEC_ANTLP_2_UNAVAIL | C8: HALE | D8: GAS | E8: PANHANDLE | F8: 2016 | G8: -54 | H8: 0 | I8: -54 | J8: -54 | K8: -54
A9: ANTELOPE IC 3 | B9: AEEC_ANTLP_3_UNAVAIL | C9: HALE | D9: GAS | E9: PANHANDLE | F9: 2016 | G9: -54 | H9: 0 | I9: -54 | J9: -54 | K9: -54
A10: ELK STATION CTG 1 | B10: AEEC_ELK_1_UNAVAIL | C10: HALE | D10: GAS | E10: PANHANDLE | F10: 2016 | G10: -190 | H10: -200 | I10: -190 | J10: -190 | K10: -190
A11: ELK STATION CTG 2 | B11: AEEC_ELK_2_UNAVAIL | C11: HALE | D11: GAS | E11: PANHANDLE | F11: 2016 | G11: -190 | H11: -200 | I11: -190 | J11: -190 | K11: -190
A12: ELK STATION CTG 3 | B12: AEEC_ELK_3_UNAVAIL | C12: HALE | D12: GAS | E12: PANHANDLE | F12: 2001 | G12: -190 | H12: 0 | I12: -190 | J12: -190 | K12: -190
A13: TENASKA GATEWAY STATION CTG 1 | B13: TGCCS_CT1_UNAVAIL | C13: RUSK | D13: GAS | E13: NORTH | F13: 2001 | G13: -156 | H13: -162 | I13: -156 | J13: 0 | K13: 0
A14: TENASKA GATEWAY STATION CTG 2 | B14: TGCCS_CT2_UNAVAIL | C14: RUSK | D14: GAS | E14: NORTH | F14: 2001 | G14: -135 | H14: -179 | I14: -135 | J14: -135 | K14: -135
A15: TENASKA GATEWAY STATION CTG 3 | B15: TGCCS_CT3_UNAVAIL | C15: RUSK | D15: GAS | E15: NORTH | F15: 2001 | G15: -153 | H15: -178 | I15: -153 | J15: 0 | K15: -153
A16: TENASKA GATEWAY STATION STG 4 | B16: TGCCS_UNIT4_UNAVAIL | C16: RUSK | D16: GAS | E16: NORTH | F16: 2001 | G16: -400 | H16: -389 | I16: -400 | J16: -400 | K16: 0
A17: TENASKA KIAMICHI STATION 2CT101 | B17: KMCHI_2CT101_UNAVAIL | C17: FANNIN | D17: GAS | E17: NORTH | F17: 2003 | G17: -150 | H17: 0 | I17: -150 | J17: -150 | K17: 0
A18: TENASKA KIAMICHI STATION 2CT201 | B18: KMCHI_2CT201_UNAVAIL | C18: FANNIN | D18: GAS | E18: NORTH | F18: 2003 | G18: -152 | H18: 0 | I18: 0 | J18: 0 | K18: 0
A19: TENASKA KIAMICHI STATION 2ST | B19: KMCHI_2ST_UNAVAIL | C19: FANNIN | D19: GAS | E19: NORTH | F19: 2003 | G19: -311 | H19: 0 | I19: 0 | J19: 0 | K19: 0
A20: Switchable Capacity Unavailable to ERCOT Total | G20: =SUM(G7:G19) -> -2189 | H20: =SUM(H7:H19) -> -1364 | I20: =SUM(I7:I19) -> -1726 | J20: =SUM(J7:J19) -> -1417 | K20: =SUM(K7:K19) -> -1020

Sheet DC Tie Modeling & Dispatch
A1: Date Last Updated: | B1: 45874 | C1: Back
A2: Status: | B2: Final
A5: Reliability Analysis
A6: DC Tie Dispatch - Summer Peak Conditions (MW)
A7: DC_E | B7: 600 | C7: Import
A8: DC_N | B8: 220 | C8: Import
A9: DC_L | B9: 0
A10: DC_R | B10: 0
A12: DC Tie Dispatch - Minimum Load Conditions (MW)
A13: DC_E | B13: 0
A14: DC_N | B14: 0
A15: DC_L | B15: 0
A16: DC_R | B16: 0

Sheet Reserve Requirement
A1: Date Last Updated: | B1: 45874 | C1: Back
A2: Status: | B2: Final
A5: Reliability Cases | B5: 3,000 MW
A6: The reserve requirements used in the reliability models account for the outage of ERCOT's two largest units as well as the increased losses observed during such an G-1 & N-1 outage. The reserves target is an approximation and will fluctuate with losses in the cases.

Sheet Fuel Price Assumptions
A1: Date Last Updated: | B1: 45874 | C1: Back
A2: Status: | B2: Final
A5: Source: | B5: Annual Energy Outlook 2025 was incorporated into a longer-term historical analysis of natural gas prices
B6: https://www.eia.gov/outlooks/aeo/
B8: Natural Gas Price Forecast ($/MMBtu)
A9: Year | B9: Jan | C9: Feb | D9: Mar | E9: Apr | F9: May | G9: Jun | H9: Jul | I9: Aug | J9: Sep | K9: Oct | L9: Nov | M9: Dec | N9: Average
A10: 2025 | B10: 3.12 | C10: 2.91 | D10: 2.72 | E10: 2.79 | F10: 2.89 | G10: 2.95 | H10: 2.87 | I10: 2.9 | J10: 2.91 | K10: 3.02 | L10: 3 | M10: 3.17 | N10: =AVERAGE(B10:M10) -> 2.9375
A11: 2026 | B11: 3.02 | C11: 2.81 | D11: 2.63 | E11: 2.7 | F11: 2.79 | G11: 2.86 | H11: 2.77 | I11: 2.81 | J11: 2.82 | K11: 2.92 | L11: 2.9 | M11: 3.06 | N11: =AVERAGE(B11:M11) -> 2.8408333
A12: 2027 | B12: 2.94 | C12: 2.73 | D12: 2.56 | E12: 2.62 | F12: 2.71 | G12: 2.78 | H12: 2.69 | I12: 2.73 | J12: 2.74 | K12: 2.84 | L12: 2.82 | M12: 2.98 | N12: =AVERAGE(B12:M12) -> 2.7616667
A13: 2028 | B13: 3.12 | C13: 2.9 | D13: 2.71 | E13: 2.79 | F13: 2.88 | G13: 2.95 | H13: 2.86 | I13: 2.9 | J13: 2.91 | K13: 3.01 | L13: 3 | M13: 3.16 | N13: =AVERAGE(B13:M13) -> 2.9325
A14: 2029 | B14: 3.37 | C14: 3.13 | D14: 2.93 | E14: 3.01 | F14: 3.11 | G14: 3.18 | H14: 3.09 | I14: 3.13 | J14: 3.14 | K14: 3.25 | L14: 3.23 | M14: 3.41 | N14: =AVERAGE(B14:M14) -> 3.165
A15: 2030 | B15: 3.65 | C15: 3.4 | D15: 3.18 | E15: 3.26 | F15: 3.37 | G15: 3.45 | H15: 3.35 | I15: 3.39 | J15: 3.4 | K15: 3.53 | L15: 3.51 | M15: 3.7 | N15: =AVERAGE(B15:M15) -> 3.4325
A16: 2031 | B16: 3.9 | C16: 3.63 | D16: 3.39 | E16: 3.49 | F16: 3.61 | G16: 3.69 | H16: 3.58 | I16: 3.62 | J16: 3.64 | K16: 3.77 | L16: 3.75 | M16: 3.96 | N16: =AVERAGE(B16:M16) -> 3.6691667

Sheet Reliability Case-Load Forecast
A1: Date Last Updated: | B1: 45874 | C1: Back
A2: Status: | B2: Final
A5: SSWG load based on 24 SSWG cases posted on 10/14/2024 less self-served load and losses (MW)
A6: Year | B6: Coast | C6: East | D6: Far West | E6: North | F6: North Central | G6: South Central | H6: South | I6: West | J6: NCP Total
A7: 2027 | B7: 27267.43 | C7: 4134.24 | D7: 16443.58 | E7: 6982.63 | F7: 36710.49 | G7: 20420.4 | H7: 10445.95 | I7: 5319.66 | J7: 127724.38
A8: 2028 | B8: 29416.83 | C8: 4213.67 | D8: 16874.29 | E8: 7072.26 | F8: 38024.5 | G8: 21259.51 | H8: 11570 | I8: 5459.22 | J8: 133890.28
A9: 2030 | B9: 29825.1 | C9: 4343.36 | D9: 17283.28 | E9: 7442.79 | F9: 39843.96 | G9: 22112.19 | H9: 11782.62 | I9: 5922.12 | J9: 138555.42
A10: 2031 | B10: 30032.33 | C10: 4428.7 | D10: 17493.73 | E10: 7482.23 | F10: 40474.49 | G10: 22481 | H10: 11849.33 | I10: 5970.21 | J10: 140212.02
A12: ERCOT 90th percentile coincident peak load forecast less self-served and losses (MW)
A13: Year | B13: Coast | C13: East | D13: Far West | E13: North | F13: North Central | G13: South Central | H13: South | I13: West | J13: CP Total
A14: 2027 | B14: 23425.166 | C14: 2910.0746 | D14: 6958.808 | E14: 1953.632 | F14: 27794.292 | G14: 15092.218 | H14: 6444.8791 | I14: 1998.3519 | J14: 86577.422
A15: 2028 | B15: 23440.037 | C15: 2939.4465 | D15: 7203.9919 | E15: 1996.9663 | F15: 28032.962 | G15: 15287.491 | H15: 6638.1939 | I15: 2113.4374 | J15: 87652.527
A16: 2030 | B16: 24096.805 | C16: 2998.9795 | D16: 7688.6187 | E16: 2089.2479 | F16: 28459.524 | G16: 15641.074 | H16: 6650.8034 | I16: 2140.9541 | J16: 89766.006
A17: 2031 | B17: 24297.11 | C17: 3026.0566 | D17: 7922.5139 | E17: 2159.7223 | F17: 27813.903 | G17: 15457.803 | H17: 6501.497 | I17: 2179.0934 | J17: 89357.699
A19: 2025 RTP load level with self-served load and less losses (MW) - based on ERCOT large load incorporation of the PUC-approved Good Cause Exception, the incorporation of the S&P Global Permian Basin load forecast, EV load adoption, and rooftop PV growth forecast contribution
A20: Year | B20: Coast | C20: East | D20: Far West | E20: North | F20: North Central | G20: South Central | H20: South | I20: West | J20: Total
A21: 2027 | B21: 28437.82 | C21: 3267.07 | D21: 15273.67 | E21: 10554.36 | F21: 32574.55 | G21: 21902.55 | H21: 9107.15 | I21: 4744.98 | J21: 125862.15
A22: 2028 | B22: 32385.8 | C22: 3338.45 | D22: 16743.87 | E22: 12158.85 | F22: 35486.03 | G22: 24869.71 | H22: 13259.08 | I22: 7022.98 | J22: 145264.77
A23: 2030 | B23: 35004.82 | C23: 3430.61 | D23: 18915.93 | E23: 12480.07 | F23: 38184.96 | G23: 28515.12 | H23: 14972.22 | I23: 7575.09 | J23: 159078.82
A24: 2031 | B24: 36160.15 | C24: 3501.33 | D24: 19921.75 | E24: 12529.83 | F24: 39822.59 | G24: 29324.92 | H24: 15346.38 | I24: 7900.56 | J24: 164507.51
A27: 2025 RTP load level with self-served load and less losses for Off-Peak Case (MW) - based on 2026 SSWG Min Case, ERCOT large load incorporation of the PUC-approved Good Cause Exception, the incorporation of the S&P Global Permian Basin load forecast, and EV load adoption
A28: Year | B28: Coast | C28: East | D28: Far West | E28: North | F28: North Central | G28: South Central | H28: South | I28: West | J28: Total
A29: 2028 | B29: 18692.03 | C29: 1655.02 | D29: 12512.73 | E29: 10653.44 | F29: 17226.91 | G29: 14385.59 | H29: 10086.88 | I29: 5707.36 | J29: 90919.96

Sheet Sensitivity Analysis
A1: Date Last Updated: | B1: 46013 | C1: Back
A2: Status: | B2: Final
A4: Sensitivity 1 and Sensitivity 2 were used to meet NERC TPL sensitivity requirements, while Sensitivity 3(a) was developed as the basis for Sensitivity 3(b), which was used for Minimum Deliverability analysis.
A6: Sensitivity 1: | B6: The summer peak load cases were modeled with load substantiated by TSP officer letters reduced to zero and included only generators compliant with ERCOT Planning Guide 6.9(1) requirements.
A8: Year | B8: ERCOT Load (MW) | C8: DC Tie Export* (MW) | D8: Wind Output (MW) | H8: Solar Output (MW) | I8: Total Renewable Output (MW)
D9: South Wind (Coastal) | E9: South Wind (Non-Coastal) | F9: Panhandle | G9: Other
A10: 2030 | B10: 129170.34 | C10: -820 | D10: 3302.86 | E10: 884.56 | F10: 1471.03 | G10: 7066.13 | H10: 47662.6 | I10: 59503
A11: 2027 | B11: 111120.89 | C11: -820 | D11: 3225.04 | E11: 801.5 | F11: 1471.03 | G11: 6702.01 | H11: 39948.19 | I11: 51346
A13: Sensitivity 2: | B13: The minimum load case was modeled with load substantiated by TSP officer letters reduced to zero and included only generators compliant with ERCOT Planning Guide 6.9(1) requirements.
A15: Year | B15: ERCOT Load (MW) | C15: DC Tie Export* (MW) | D15: Wind Output (MW) | H15: Solar Output (MW) | I15: Total Renewable Output (MW)
D16: South Wind (Coastal) | E16: South Wind (Non-Coastal) | F16: Panhandle | G16: Other
A17: 2028MIN | B17: 71735.57 | C17: 0 | D17: 1055.49 | E17: 1019.58 | F17: 1576.13 | G17: 8026.52 | H17: 0 | I17: 10658
A19: Sensitivity 3(a): | B19: The peak net load case was modeled with generation dispatch and load updated to represent "sunset" conditions typically observed during the 7–8 PM time period. Load substantiated by TSP officer letters was reduced to zero, and only generators compliant with ERCOT Planning Guide 6.9(1) requirements were included.
A21: Year | B21: ERCOT Load (MW) | C21: DC Tie Export* (MW) | D21: Wind Output (MW) | H21: Solar Output (MW) | I21: Total Renewable Output (MW)
D22: South Wind (Coastal) | E22: South Wind (Non-Coastal) | F22: Panhandle | G22: Other
A23: 2027 | B23: 106261.22 | C23: -820 | D23: 3711.74 | E23: 2706.05 | F23: 630.46 | G23: 12146.73 | H23: 7278.28 | I23: 23767
A25: Sensitivity 3(b): | B25: The peak net load ("sunset") case was modeled with generation dispatch updated to reflect the Minimum Deliverability Criteria outlined in Planning Guide Section 4.1.1.7. Load substantiated by TSP officer letters was reduced to zero, and only generators compliant with ERCOT Planning Guide 6.9(1) requirements were included.
A27: Year | B27: ERCOT Load (MW) | C27: DC Tie Export* (MW) | D27: Wind Output (MW) | H27: Solar Output (MW) | I27: Total Renewable Output (MW)
D28: South Wind (Coastal) | E28: South Wind (Non-Coastal) | F28: Panhandle | G28: Other
A29: 2027 | B29: 106261.22 | C29: -820 | D29: 3711.74 | E29: 2706.05 | F29: 630.46 | G29: 12146.72 | H29: 7278.28 | I29: 23767
A31: * negative sign indicating DC tie import.
