Workbook

Sheet WP II-E-3.3
A1: 2025 RATE CASE
A2: ONCOR ELECTRIC DELIVERY COMPANY LLC
A3: PLANT ADJUSTMENTS
A4: TEST YEAR ENDING DECEMBER 31, 2024
A5: SPONSOR: B. L. CLUTTER
A10: Line No. | B10: Tax Class | D10: Rate | E10: Convention | F10: 2022 Oncor Tax Additions | G10: 2022 NTU Tax Additions | H10: 2023 Oncor Tax Additions | I10: 2023 NTU Tax Additions | J10: 2024 Oncor Tax Additions | K10: 2024 NTU Tax Additions | L10: Total Tax Depr Basis | M10: 2024 Oncor Depr on V2022-V2024 | N10: 2024 NTU Depr on all Vintages | O10: 2025 Oncor Forecast Depr on V2022-V2024 | P10: 2025 NTU Forecast Depr on all Vintages | Q10: 2026 Oncor Forecast Depr on V2022-V2024 | R10: 2026 NTU Forecast Depr on all Vintages | S10: Oncor V2022-V2024 ADFIT at 12/31/2024 | T10: NTU ADFIT at 12/31/2024
B11: (a) | D11: (b) | E11: (c) | F11: (d) | G11: (e) | H11: (f) | I11: (g) | J11: (h) | K11: (i) | L11: (j) | M11: (k) | N11: (l) | O11: (m) | P11: (n) | Q11: (o) | R11: (p) | S11: (q) | T11: (r)
A12: 1 | B12: TOTAL
A13: =+A12+1 -> 2 | B13: 00.11 | C13: 00.11: Furn, Fixt, Equip | D13: MACRS 7 | E13: HY | F13: =IFERROR(VLOOKUP(C13,'[1]B-1 2022 Adds'!$B$5:$F$161,5,FALSE),0) -> 4692717.6 | G13: =IFERROR(VLOOKUP(C13,'[1]B-2 2022 NTU Adds'!$B$5:$F$61,5,FALSE),0) -> 0 | H13: =IFERROR(VLOOKUP(C13,'[1]B-3 2023 Adds'!$B$5:$F$53,5,FALSE),0) -> 1238582.9 | I13: =IFERROR(VLOOKUP(C13,'[1]B-4 2023 NTU Adds'!$B$5:$F$61,5,FALSE),0) -> 0 | J13: =IFERROR(VLOOKUP(C13,'[1]B-5 2024 Adds'!$B$5:$F$91,5,FALSE),0) -> 3989751.5 | K13: =IFERROR(VLOOKUP(C13,'[1]B-6 2024 NTU Adds'!$B$5:$F$61,5,FALSE),0) -> 0 | L13: =SUM(F13:K13) -> 9921052.1 | M13: =IFERROR(VLOOKUP(C13,'[1]C-1 TY2024 Depr'!$B$4:$I$220,8,FALSE),0) -> 1434597.9 | N13: =IFERROR(VLOOKUP(C13,'[1]C-4 TY2024 Depr NTU'!$B$4:$I$96,8,FALSE),0) -> 0 | O13: =IFERROR(VLOOKUP(C13,'[1]C-2 TY2025 Depr'!$B$4:$I$220,8,FALSE),0) -> 1893928.7 | P13: =IFERROR(VLOOKUP(C13,'[1]C-5 TY2025 Depr NTU'!$B$4:$I$96,8,FALSE),0) -> 0 | Q13: =IFERROR(VLOOKUP(C13,'[1]C-3 TY2026 Depr'!$B$4:$I$220,8,FALSE),0) -> 1364613.1 | R13: =IFERROR(VLOOKUP(C13,'[1]C-6 TY2026 Depr NTU'!$B$4:$I$96,8,FALSE),0) -> 0
A14: =+A13+1 -> 3 | B14: 00.12 | C14: 00.12: Info Systems | D14: MACRS 5 | E14: HY | F14: =IFERROR(VLOOKUP(C14,'[1]B-1 2022 Adds'!$B$5:$F$161,5,FALSE),0) -> 23674330 | G14: =IFERROR(VLOOKUP(C14,'[1]B-2 2022 NTU Adds'!$B$5:$F$61,5,FALSE),0) -> 0 | H14: =IFERROR(VLOOKUP(C14,'[1]B-3 2023 Adds'!$B$5:$F$53,5,FALSE),0) -> 12545498 | I14: =IFERROR(VLOOKUP(C14,'[1]B-4 2023 NTU Adds'!$B$5:$F$61,5,FALSE),0) -> 0 | J14: =IFERROR(VLOOKUP(C14,'[1]B-5 2024 Adds'!$B$5:$F$91,5,FALSE),0) -> 21554113 | K14: =IFERROR(VLOOKUP(C14,'[1]B-6 2024 NTU Adds'!$B$5:$F$61,5,FALSE),0) -> 0 | L14: =SUM(F14:K14) -> 57773941 | M14: =IFERROR(VLOOKUP(C14,'[1]C-1 TY2024 Depr'!$B$4:$I$220,8,FALSE),0) -> 11358967 | N14: =IFERROR(VLOOKUP(C14,'[1]C-4 TY2024 Depr NTU'!$B$4:$I$96,8,FALSE),0) -> 0 | O14: =IFERROR(VLOOKUP(C14,'[1]C-2 TY2025 Depr'!$B$4:$I$220,8,FALSE),0) -> 13179844 | P14: =IFERROR(VLOOKUP(C14,'[1]C-5 TY2025 Depr NTU'!$B$4:$I$96,8,FALSE),0) -> 0 | Q14: =IFERROR(VLOOKUP(C14,'[1]C-3 TY2026 Depr'!$B$4:$I$220,8,FALSE),0) -> 8681611.3 | R14: =IFERROR(VLOOKUP(C14,'[1]C-6 TY2026 Depr NTU'!$B$4:$I$96,8,FALSE),0) -> 0
A15: =+A14+1 -> 4 | B15: 00.13 | C15: 00.13: Data Handling Eq | D15: MACRS 5 | E15: HY | F15: =IFERROR(VLOOKUP(C15,'[1]B-1 2022 Adds'!$B$5:$F$161,5,FALSE),0) -> 0 | G15: =IFERROR(VLOOKUP(C15,'[1]B-2 2022 NTU Adds'!$B$5:$F$61,5,FALSE),0) -> 0 | H15: =IFERROR(VLOOKUP(C15,'[1]B-3 2023 Adds'!$B$5:$F$53,5,FALSE),0) -> 0 | I15: =IFERROR(VLOOKUP(C15,'[1]B-4 2023 NTU Adds'!$B$5:$F$61,5,FALSE),0) -> 0 | J15: =IFERROR(VLOOKUP(C15,'[1]B-5 2024 Adds'!$B$5:$F$91,5,FALSE),0) -> 6980.12 | K15: =IFERROR(VLOOKUP(C15,'[1]B-6 2024 NTU Adds'!$B$5:$F$61,5,FALSE),0) -> 0 | L15: =SUM(F15:K15) -> 6980.12 | M15: =IFERROR(VLOOKUP(C15,'[1]C-1 TY2024 Depr'!$B$4:$I$220,8,FALSE),0) -> 2519.53 | N15: =IFERROR(VLOOKUP(C15,'[1]C-4 TY2024 Depr NTU'!$B$4:$I$96,8,FALSE),0) -> 0 | O15: =IFERROR(VLOOKUP(C15,'[1]C-2 TY2025 Depr'!$B$4:$I$220,8,FALSE),0) -> 1784.23 | P15: =IFERROR(VLOOKUP(C15,'[1]C-5 TY2025 Depr NTU'!$B$4:$I$96,8,FALSE),0) -> 0 | Q15: =IFERROR(VLOOKUP(C15,'[1]C-3 TY2026 Depr'!$B$4:$I$220,8,FALSE),0) -> 1070.54 | R15: =IFERROR(VLOOKUP(C15,'[1]C-6 TY2026 Depr NTU'!$B$4:$I$96,8,FALSE),0) -> 0
A16: =+A15+1 -> 5 | B16: 00.21 | C16: 00.21: Airplanes | D16: MACRS 5 | E16: HY | F16: =IFERROR(VLOOKUP(C16,'[1]B-1 2022 Adds'!$B$5:$F$161,5,FALSE),0) -> 0 | G16: =IFERROR(VLOOKUP(C16,'[1]B-2 2022 NTU Adds'!$B$5:$F$61,5,FALSE),0) -> 0 | H16: =IFERROR(VLOOKUP(C16,'[1]B-3 2023 Adds'!$B$5:$F$53,5,FALSE),0) -> 0 | I16: =IFERROR(VLOOKUP(C16,'[1]B-4 2023 NTU Adds'!$B$5:$F$61,5,FALSE),0) -> 0 | J16: =IFERROR(VLOOKUP(C16,'[1]B-5 2024 Adds'!$B$5:$F$91,5,FALSE),0) -> 0 | K16: =IFERROR(VLOOKUP(C16,'[1]B-6 2024 NTU Adds'!$B$5:$F$61,5,FALSE),0) -> 0 | L16: =SUM(F16:K16) -> 0 | M16: =IFERROR(VLOOKUP(C16,'[1]C-1 TY2024 Depr'!$B$4:$I$220,8,FALSE),0) -> 0 | N16: =IFERROR(VLOOKUP(C16,'[1]C-4 TY2024 Depr NTU'!$B$4:$I$96,8,FALSE),0) -> 0 | O16: =IFERROR(VLOOKUP(C16,'[1]C-2 TY2025 Depr'!$B$4:$I$220,8,FALSE),0) -> 0 | P16: =IFERROR(VLOOKUP(C16,'[1]C-5 TY2025 Depr NTU'!$B$4:$I$96,8,FALSE),0) -> 0 | Q16: =IFERROR(VLOOKUP(C16,'[1]C-3 TY2026 Depr'!$B$4:$I$220,8,FALSE),0) -> 0 | R16: =IFERROR(VLOOKUP(C16,'[1]C-6 TY2026 Depr NTU'!$B$4:$I$96,8,FALSE),0) -> 0
A17: =+A16+1 -> 6 | B17: 00.22 | C17: 00.22: Automobiles | D17: MACRS 5 | E17: HY | F17: =IFERROR(VLOOKUP(C17,'[1]B-1 2022 Adds'!$B$5:$F$161,5,FALSE),0) -> 677282.05 | G17: =IFERROR(VLOOKUP(C17,'[1]B-2 2022 NTU Adds'!$B$5:$F$61,5,FALSE),0) -> 0 | H17: =IFERROR(VLOOKUP(C17,'[1]B-3 2023 Adds'!$B$5:$F$53,5,FALSE),0) -> 663246.96 | I17: =IFERROR(VLOOKUP(C17,'[1]B-4 2023 NTU Adds'!$B$5:$F$61,5,FALSE),0) -> 0 | J17: =IFERROR(VLOOKUP(C17,'[1]B-5 2024 Adds'!$B$5:$F$91,5,FALSE),0) -> 217945.44 | K17: =IFERROR(VLOOKUP(C17,'[1]B-6 2024 NTU Adds'!$B$5:$F$61,5,FALSE),0) -> 0 | L17: =SUM(F17:K17) -> 1558474.4 | M17: =IFERROR(VLOOKUP(C17,'[1]C-1 TY2024 Depr'!$B$4:$I$220,8,FALSE),0) -> 378563.76 | N17: =IFERROR(VLOOKUP(C17,'[1]C-4 TY2024 Depr NTU'!$B$4:$I$96,8,FALSE),0) -> 0 | O17: =IFERROR(VLOOKUP(C17,'[1]C-2 TY2025 Depr'!$B$4:$I$220,8,FALSE),0) -> 297804.36 | P17: =IFERROR(VLOOKUP(C17,'[1]C-5 TY2025 Depr NTU'!$B$4:$I$96,8,FALSE),0) -> 0 | Q17: =IFERROR(VLOOKUP(C17,'[1]C-3 TY2026 Depr'!$B$4:$I$220,8,FALSE),0) -> 199019.56 | R17: =IFERROR(VLOOKUP(C17,'[1]C-6 TY2026 Depr NTU'!$B$4:$I$96,8,FALSE),0) -> 0
A18: =+A17+1 -> 7 | B18: 00.241 | C18: 00.241: Light Trucks | D18: MACRS 5 | E18: HY | F18: =IFERROR(VLOOKUP(C18,'[1]B-1 2022 Adds'!$B$5:$F$161,5,FALSE),0) -> 0 | G18: =IFERROR(VLOOKUP(C18,'[1]B-2 2022 NTU Adds'!$B$5:$F$61,5,FALSE),0) -> 0 | H18: =IFERROR(VLOOKUP(C18,'[1]B-3 2023 Adds'!$B$5:$F$53,5,FALSE),0) -> 0 | I18: =IFERROR(VLOOKUP(C18,'[1]B-4 2023 NTU Adds'!$B$5:$F$61,5,FALSE),0) -> 0 | J18: =IFERROR(VLOOKUP(C18,'[1]B-5 2024 Adds'!$B$5:$F$91,5,FALSE),0) -> 0 | K18: =IFERROR(VLOOKUP(C18,'[1]B-6 2024 NTU Adds'!$B$5:$F$61,5,FALSE),0) -> 0 | L18: =SUM(F18:K18) -> 0 | M18: =IFERROR(VLOOKUP(C18,'[1]C-1 TY2024 Depr'!$B$4:$I$220,8,FALSE),0) -> 0 | N18: =IFERROR(VLOOKUP(C18,'[1]C-4 TY2024 Depr NTU'!$B$4:$I$96,8,FALSE),0) -> 0 | O18: =IFERROR(VLOOKUP(C18,'[1]C-2 TY2025 Depr'!$B$4:$I$220,8,FALSE),0) -> 0 | P18: =IFERROR(VLOOKUP(C18,'[1]C-5 TY2025 Depr NTU'!$B$4:$I$96,8,FALSE),0) -> 0 | Q18: =IFERROR(VLOOKUP(C18,'[1]C-3 TY2026 Depr'!$B$4:$I$220,8,FALSE),0) -> 0 | R18: =IFERROR(VLOOKUP(C18,'[1]C-6 TY2026 Depr NTU'!$B$4:$I$96,8,FALSE),0) -> 0
A19: =+A18+1 -> 8 | B19: 00.242 | C19: 00.242: Heavy Trucks | D19: MACRS 5 | E19: HY | F19: =IFERROR(VLOOKUP(C19,'[1]B-1 2022 Adds'!$B$5:$F$161,5,FALSE),0) -> 68342.2 | G19: =IFERROR(VLOOKUP(C19,'[1]B-2 2022 NTU Adds'!$B$5:$F$61,5,FALSE),0) -> 0 | H19: =IFERROR(VLOOKUP(C19,'[1]B-3 2023 Adds'!$B$5:$F$53,5,FALSE),0) -> 200634.54 | I19: =IFERROR(VLOOKUP(C19,'[1]B-4 2023 NTU Adds'!$B$5:$F$61,5,FALSE),0) -> 0 | J19: =IFERROR(VLOOKUP(C19,'[1]B-5 2024 Adds'!$B$5:$F$91,5,FALSE),0) -> 2630423.9 | K19: =IFERROR(VLOOKUP(C19,'[1]B-6 2024 NTU Adds'!$B$5:$F$61,5,FALSE),0) -> 0 | L19: =SUM(F19:K19) -> 2899400.6 | M19: =IFERROR(VLOOKUP(C19,'[1]C-1 TY2024 Depr'!$B$4:$I$220,8,FALSE),0) -> 210639.38 | N19: =IFERROR(VLOOKUP(C19,'[1]C-4 TY2024 Depr NTU'!$B$4:$I$96,8,FALSE),0) -> 0 | O19: =IFERROR(VLOOKUP(C19,'[1]C-2 TY2025 Depr'!$B$4:$I$220,8,FALSE),0) -> 1046842.1 | P19: =IFERROR(VLOOKUP(C19,'[1]C-5 TY2025 Depr NTU'!$B$4:$I$96,8,FALSE),0) -> 0 | Q19: =IFERROR(VLOOKUP(C19,'[1]C-3 TY2026 Depr'!$B$4:$I$220,8,FALSE),0) -> 630368.38 | R19: =IFERROR(VLOOKUP(C19,'[1]C-6 TY2026 Depr NTU'!$B$4:$I$96,8,FALSE),0) -> 0
A20: =+A19+1 -> 9 | B20: 00.27 | C20: 00.27: Trailers | D20: MACRS 5 | E20: HY | F20: =IFERROR(VLOOKUP(C20,'[1]B-1 2022 Adds'!$B$5:$F$161,5,FALSE),0) -> 399386.19 | G20: =IFERROR(VLOOKUP(C20,'[1]B-2 2022 NTU Adds'!$B$5:$F$61,5,FALSE),0) -> 0 | H20: =IFERROR(VLOOKUP(C20,'[1]B-3 2023 Adds'!$B$5:$F$53,5,FALSE),0) -> 1055510.3 | I20: =IFERROR(VLOOKUP(C20,'[1]B-4 2023 NTU Adds'!$B$5:$F$61,5,FALSE),0) -> 0 | J20: =IFERROR(VLOOKUP(C20,'[1]B-5 2024 Adds'!$B$5:$F$91,5,FALSE),0) -> 573641.64 | K20: =IFERROR(VLOOKUP(C20,'[1]B-6 2024 NTU Adds'!$B$5:$F$61,5,FALSE),0) -> 0 | L20: =SUM(F20:K20) -> 2028538.2 | M20: =IFERROR(VLOOKUP(C20,'[1]C-1 TY2024 Depr'!$B$4:$I$220,8,FALSE),0) -> 469304.66 | N20: =IFERROR(VLOOKUP(C20,'[1]C-4 TY2024 Depr NTU'!$B$4:$I$96,8,FALSE),0) -> 0 | O20: =IFERROR(VLOOKUP(C20,'[1]C-2 TY2025 Depr'!$B$4:$I$220,8,FALSE),0) -> 462920.41 | P20: =IFERROR(VLOOKUP(C20,'[1]C-5 TY2025 Depr NTU'!$B$4:$I$96,8,FALSE),0) -> 0 | Q20: =IFERROR(VLOOKUP(C20,'[1]C-3 TY2026 Depr'!$B$4:$I$220,8,FALSE),0) -> 291778.33 | R20: =IFERROR(VLOOKUP(C20,'[1]C-6 TY2026 Depr NTU'!$B$4:$I$96,8,FALSE),0) -> 0
A21: =+A20+1 -> 10 | B21: 00.28 | C21: 00.28: Boats | D21: MACRS 10 | E21: HY | F21: =IFERROR(VLOOKUP(C21,'[1]B-1 2022 Adds'!$B$5:$F$161,5,FALSE),0) -> 0 | G21: =IFERROR(VLOOKUP(C21,'[1]B-2 2022 NTU Adds'!$B$5:$F$61,5,FALSE),0) -> 0 | H21: =IFERROR(VLOOKUP(C21,'[1]B-3 2023 Adds'!$B$5:$F$53,5,FALSE),0) -> 0 | I21: =IFERROR(VLOOKUP(C21,'[1]B-4 2023 NTU Adds'!$B$5:$F$61,5,FALSE),0) -> 0 | J21: =IFERROR(VLOOKUP(C21,'[1]B-5 2024 Adds'!$B$5:$F$91,5,FALSE),0) -> 2118 | K21: =IFERROR(VLOOKUP(C21,'[1]B-6 2024 NTU Adds'!$B$5:$F$61,5,FALSE),0) -> 0 | L21: =SUM(F21:K21) -> 2118 | M21: =IFERROR(VLOOKUP(C21,'[1]C-1 TY2024 Depr'!$B$4:$I$220,8,FALSE),0) -> 52.95 | N21: =IFERROR(VLOOKUP(C21,'[1]C-4 TY2024 Depr NTU'!$B$4:$I$96,8,FALSE),0) -> 0 | O21: =IFERROR(VLOOKUP(C21,'[1]C-2 TY2025 Depr'!$B$4:$I$220,8,FALSE),0) -> 413.01 | P21: =IFERROR(VLOOKUP(C21,'[1]C-5 TY2025 Depr NTU'!$B$4:$I$96,8,FALSE),0) -> 0 | Q21: =IFERROR(VLOOKUP(C21,'[1]C-3 TY2026 Depr'!$B$4:$I$220,8,FALSE),0) -> 330.41 | R21: =IFERROR(VLOOKUP(C21,'[1]C-6 TY2026 Depr NTU'!$B$4:$I$96,8,FALSE),0) -> 0
A22: =+A21+1 -> 11 | B22: 00.3 | C22: 00.3: Land Improv | D22: MACRS 15 | E22: HY | F22: =IFERROR(VLOOKUP(C22,'[1]B-1 2022 Adds'!$B$5:$F$161,5,FALSE),0) -> 54961503 | G22: =IFERROR(VLOOKUP(C22,'[1]B-2 2022 NTU Adds'!$B$5:$F$61,5,FALSE),0) -> 0 | H22: =IFERROR(VLOOKUP(C22,'[1]B-3 2023 Adds'!$B$5:$F$53,5,FALSE),0) -> 89391026 | I22: =IFERROR(VLOOKUP(C22,'[1]B-4 2023 NTU Adds'!$B$5:$F$61,5,FALSE),0) -> 0 | J22: =IFERROR(VLOOKUP(C22,'[1]B-5 2024 Adds'!$B$5:$F$91,5,FALSE),0) -> 1.3885479e+08 | K22: =IFERROR(VLOOKUP(C22,'[1]B-6 2024 NTU Adds'!$B$5:$F$61,5,FALSE),0) -> 0 | L22: =SUM(F22:K22) -> 2.8320732e+08 | M22: =IFERROR(VLOOKUP(C22,'[1]C-1 TY2024 Depr'!$B$4:$I$220,8,FALSE),0) -> 18206271 | N22: =IFERROR(VLOOKUP(C22,'[1]C-4 TY2024 Depr NTU'!$B$4:$I$96,8,FALSE),0) -> 0 | O22: =IFERROR(VLOOKUP(C22,'[1]C-2 TY2025 Depr'!$B$4:$I$220,8,FALSE),0) -> 25302446 | P22: =IFERROR(VLOOKUP(C22,'[1]C-5 TY2025 Depr NTU'!$B$4:$I$96,8,FALSE),0) -> 0 | Q22: =IFERROR(VLOOKUP(C22,'[1]C-3 TY2026 Depr'!$B$4:$I$220,8,FALSE),0) -> 22816136 | R22: =IFERROR(VLOOKUP(C22,'[1]C-6 TY2026 Depr NTU'!$B$4:$I$96,8,FALSE),0) -> 0
A23: =+A22+1 -> 12 | B23: 40.4 | C23: 40.4: Railroad Track | D23: MACRS 7 | E23: HY | F23: =IFERROR(VLOOKUP(C23,'[1]B-1 2022 Adds'!$B$5:$F$161,5,FALSE),0) -> 0 | G23: =IFERROR(VLOOKUP(C23,'[1]B-2 2022 NTU Adds'!$B$5:$F$61,5,FALSE),0) -> 0 | H23: =IFERROR(VLOOKUP(C23,'[1]B-3 2023 Adds'!$B$5:$F$53,5,FALSE),0) -> 0 | I23: =IFERROR(VLOOKUP(C23,'[1]B-4 2023 NTU Adds'!$B$5:$F$61,5,FALSE),0) -> 0 | J23: =IFERROR(VLOOKUP(C23,'[1]B-5 2024 Adds'!$B$5:$F$91,5,FALSE),0) -> 0 | K23: =IFERROR(VLOOKUP(C23,'[1]B-6 2024 NTU Adds'!$B$5:$F$61,5,FALSE),0) -> 0 | L23: =SUM(F23:K23) -> 0 | M23: =IFERROR(VLOOKUP(C23,'[1]C-1 TY2024 Depr'!$B$4:$I$220,8,FALSE),0) -> 0 | N23: =IFERROR(VLOOKUP(C23,'[1]C-4 TY2024 Depr NTU'!$B$4:$I$96,8,FALSE),0) -> 0 | O23: =IFERROR(VLOOKUP(C23,'[1]C-2 TY2025 Depr'!$B$4:$I$220,8,FALSE),0) -> 0 | P23: =IFERROR(VLOOKUP(C23,'[1]C-5 TY2025 Depr NTU'!$B$4:$I$96,8,FALSE),0) -> 0 | Q23: =IFERROR(VLOOKUP(C23,'[1]C-3 TY2026 Depr'!$B$4:$I$220,8,FALSE),0) -> 0 | R23: =IFERROR(VLOOKUP(C23,'[1]C-6 TY2026 Depr NTU'!$B$4:$I$96,8,FALSE),0) -> 0
A24: =+A23+1 -> 13 | B24: 49.14 | C24: 49.14: Trans & Dist Plnt | D24: MACRS 20 | E24: HY | F24: =IFERROR(VLOOKUP(C24,'[1]B-1 2022 Adds'!$B$5:$F$161,5,FALSE),0) -> 1.0269887e+09 | G24: =IFERROR(VLOOKUP(C24,'[1]B-2 2022 NTU Adds'!$B$5:$F$61,5,FALSE),0) -> 39518.47 | H24: =IFERROR(VLOOKUP(C24,'[1]B-3 2023 Adds'!$B$5:$F$53,5,FALSE),0) -> 1.3766837e+09 | I24: =IFERROR(VLOOKUP(C24,'[1]B-4 2023 NTU Adds'!$B$5:$F$61,5,FALSE),0) -> 5597.83 | J24: =IFERROR(VLOOKUP(C24,'[1]B-5 2024 Adds'!$B$5:$F$91,5,FALSE),0) -> 1.6822051e+09 | K24: =IFERROR(VLOOKUP(C24,'[1]B-6 2024 NTU Adds'!$B$5:$F$61,5,FALSE),0) -> 60362.08 | L24: =SUM(F24:K24) -> 4.0859829e+09 | M24: =IFERROR(VLOOKUP(C24,'[1]C-1 TY2024 Depr'!$B$4:$I$220,8,FALSE),0) -> 2.2831831e+08 | N24: =IFERROR(VLOOKUP(C24,'[1]C-4 TY2024 Depr NTU'!$B$4:$I$96,8,FALSE),0) -> 5334.93 | O24: =IFERROR(VLOOKUP(C24,'[1]C-2 TY2025 Depr'!$B$4:$I$220,8,FALSE),0) -> 2.7614191e+08 | P24: =IFERROR(VLOOKUP(C24,'[1]C-5 TY2025 Depr NTU'!$B$4:$I$96,8,FALSE),0) -> 7751.56 | Q24: =IFERROR(VLOOKUP(C24,'[1]C-3 TY2026 Depr'!$B$4:$I$220,8,FALSE),0) -> 2.5543174e+08 | R24: =IFERROR(VLOOKUP(C24,'[1]C-6 TY2026 Depr NTU'!$B$4:$I$96,8,FALSE),0) -> 7095.32
... A33: =+A32+1 -> 22 | B33: LR84 | C33: LR84: Easements 84 Yr | D33: SL 84 | E33: HY | F33: =IFERROR(VLOOKUP(C33,'[1]B-1 2022 Adds'!$B$5:$F$161,5,FALSE),0) -> 18459035 | G33: =IFERROR(VLOOKUP(C33,'[1]B-2 2022 NTU Adds'!$B$5:$F$61,5,FALSE),0) -> 0 | H33: =IFERROR(VLOOKUP(C33,'[1]B-3 2023 Adds'!$B$5:$F$53,5,FALSE),0) -> 12247564 | I33: =IFERROR(VLOOKUP(C33,'[1]B-4 2023 NTU Adds'!$B$5:$F$61,5,FALSE),0) -> 0 | J33: =IFERROR(VLOOKUP(C33,'[1]B-5 2024 Adds'!$B$5:$F$91,5,FALSE),0) -> 18938360 | K33: =IFERROR(VLOOKUP(C33,'[1]B-6 2024 NTU Adds'!$B$5:$F$61,5,FALSE),0) -> 0 | L33: =SUM(F33:K33) -> 49644959 | M33: =IFERROR(VLOOKUP(C33,'[1]C-1 TY2024 Depr'!$B$4:$I$220,8,FALSE),0) -> 1798550.2 | N33: =IFERROR(VLOOKUP(C33,'[1]C-4 TY2024 Depr NTU'!$B$4:$I$96,8,FALSE),0) -> 0 | O33: =IFERROR(VLOOKUP(C33,'[1]C-2 TY2025 Depr'!$B$4:$I$220,8,FALSE),0) -> 1825924.4 | P33: =IFERROR(VLOOKUP(C33,'[1]C-5 TY2025 Depr NTU'!$B$4:$I$96,8,FALSE),0) -> 0 | Q33: =IFERROR(VLOOKUP(C33,'[1]C-3 TY2026 Depr'!$B$4:$I$220,8,FALSE),0) -> 1680668 | R33: =IFERROR(VLOOKUP(C33,'[1]C-6 TY2026 Depr NTU'!$B$4:$I$96,8,FALSE),0) -> 0
A34: =+A33+1 -> 23 | B34: ND | C34: ND: Non Depr | D34: None | F34: =IFERROR(VLOOKUP(C34,'[1]B-1 2022 Adds'!$B$5:$F$161,5,FALSE),0) -> 44367822 | G34: =IFERROR(VLOOKUP(C34,'[1]B-2 2022 NTU Adds'!$B$5:$F$61,5,FALSE),0) -> 17357.6 | H34: =IFERROR(VLOOKUP(C34,'[1]B-3 2023 Adds'!$B$5:$F$53,5,FALSE),0) -> 42579589 | I34: =IFERROR(VLOOKUP(C34,'[1]B-4 2023 NTU Adds'!$B$5:$F$61,5,FALSE),0) -> 8572.8 | J34: =IFERROR(VLOOKUP(C34,'[1]B-5 2024 Adds'!$B$5:$F$91,5,FALSE),0) -> 4488514.4 | K34: =IFERROR(VLOOKUP(C34,'[1]B-6 2024 NTU Adds'!$B$5:$F$61,5,FALSE),0) -> 8817.63 | L34: =SUM(F34:K34) -> 91470673 | M34: =IFERROR(VLOOKUP(C34,'[1]C-1 TY2024 Depr'!$B$4:$I$220,8,FALSE),0) -> 0 | N34: =IFERROR(VLOOKUP(C34,'[1]C-4 TY2024 Depr NTU'!$B$4:$I$96,8,FALSE),0) -> 0 | O34: =IFERROR(VLOOKUP(C34,'[1]C-2 TY2025 Depr'!$B$4:$I$220,8,FALSE),0) -> 0 | P34: =IFERROR(VLOOKUP(C34,'[1]C-5 TY2025 Depr NTU'!$B$4:$I$96,8,FALSE),0) -> 0 | Q34: =IFERROR(VLOOKUP(C34,'[1]C-3 TY2026 Depr'!$B$4:$I$220,8,FALSE),0) -> 0 | R34: =IFERROR(VLOOKUP(C34,'[1]C-6 TY2026 Depr NTU'!$B$4:$I$96,8,FALSE),0) -> 0
A35: =+A34+1 -> 24 | B35: RP | C35: RP: RP 81-86 & Post92 | D35: MACRS 39 | E35: MM | F35: =IFERROR(VLOOKUP(C35,'[1]B-1 2022 Adds'!$B$5:$F$161,5,FALSE),0) -> 58823486 | G35: =IFERROR(VLOOKUP(C35,'[1]B-2 2022 NTU Adds'!$B$5:$F$61,5,FALSE),0) -> 116760.6 | H35: =IFERROR(VLOOKUP(C35,'[1]B-3 2023 Adds'!$B$5:$F$53,5,FALSE),0) -> 79021989 | I35: =IFERROR(VLOOKUP(C35,'[1]B-4 2023 NTU Adds'!$B$5:$F$61,5,FALSE),0) -> 30221.3 | J35: =IFERROR(VLOOKUP(C35,'[1]B-5 2024 Adds'!$B$5:$F$91,5,FALSE),0) -> 1.0857807e+08 | K35: =IFERROR(VLOOKUP(C35,'[1]B-6 2024 NTU Adds'!$B$5:$F$61,5,FALSE),0) -> 123771.8 | L35: =SUM(F35:K35) -> 2.466943e+08 | M35: =IFERROR(VLOOKUP(C35,'[1]C-1 TY2024 Depr'!$B$4:$I$220,8,FALSE),0) -> 4196377.6 | N35: =IFERROR(VLOOKUP(C35,'[1]C-4 TY2024 Depr NTU'!$B$4:$I$96,8,FALSE),0) -> 4287.33 | O35: =IFERROR(VLOOKUP(C35,'[1]C-2 TY2025 Depr'!$B$4:$I$220,8,FALSE),0) -> 6318140.2 | P35: =IFERROR(VLOOKUP(C35,'[1]C-5 TY2025 Depr NTU'!$B$4:$I$96,8,FALSE),0) -> 6751.53 | Q35: =IFERROR(VLOOKUP(C35,'[1]C-3 TY2026 Depr'!$B$4:$I$220,8,FALSE),0) -> 6318181.9 | R35: =IFERROR(VLOOKUP(C35,'[1]C-6 TY2026 Depr NTU'!$B$4:$I$96,8,FALSE),0) -> 6751.59
A36: =+A35+1 -> 25 | B36: TOTAL | F36: =SUM(F13:F35) -> 2.1789998e+09 | G36: =SUM(G13:G35) -> 675019.46 | H36: =SUM(H13:H35) -> 2.9470166e+09 | I36: =SUM(I13:I35) -> 733126.07 | J36: =SUM(J13:J35) -> 3.8820859e+09 | K36: =SUM(K13:K35) -> 657058.22 | L36: =SUM(L13:L35) -> 9.0101676e+09 | M36: =SUM(M13:M35) -> 5.6995776e+08 | ... R36: =SUM(R13:R35) -> 144289.28 | S36: =+'[1]D-1 ADFIT V2022+'!N31 -> 5998427 | T36: =+'[1]D-2 NTU ADFIT V2022+'!N22 -> -24006691
A37: =+A36+1 -> 26
A38: =+A37+1 -> 27 | B38: TRAN | E38: =+'[2]II-F Alloc_Factor'!$E$38 -> 0.45458274
A39: =+A38+1 -> 28 | B39: 00.11 | C39: 00.11: Furn, Fixt, Equip | D39: MACRS 7 | E39: HY | F39: =ROUND(+'WP II-E-3.3'!F13*$E$38,2) -> 2133228.4 | G39: 0 | H39: =ROUND(+'WP II-E-3.3'!H13*$E$38,2) -> 563038.41 | I39: 0 | J39: =ROUND(+'WP II-E-3.3'!J13*$E$38,2) -> 1813672.2 | K39: 0 | L39: =SUM(F39:K39) -> 4509939 | M39: =ROUND(+'WP II-E-3.3'!M13*$E$38,2) -> 652143.46 | N39: 0 | O39: =ROUND(+'WP II-E-3.3'!O13*$E$38,2) -> 860947.32 | P39: 0 | Q39: =ROUND(+'WP II-E-3.3'!Q13*$E$38,2) -> 620329.55 | R39: 0 | S39: =+'WP II-E-3.3'!S13*$E$38 -> 0 | T39: =+'WP II-E-3.3'!T13*$E$38 -> 0
A40: =+A39+1 -> 29 | B40: 00.12 | C40: 00.12: Info Systems | D40: MACRS 5 | E40: HY | F40: =ROUND(+'WP II-E-3.3'!F14*$E$38,2) -> 10761942 | G40: 0 | H40: =ROUND(+'WP II-E-3.3'!H14*$E$38,2) -> 5702966.6 | I40: 0 | J40: =ROUND(+'WP II-E-3.3'!J14*$E$38,2) -> 9798127.8 | K40: 0 | L40: =SUM(F40:K40) -> 26263036 | M40: =ROUND(+'WP II-E-3.3'!M14*$E$38,2) -> 5163590.5 | N40: 0 | O40: =ROUND(+'WP II-E-3.3'!O14*$E$38,2) -> 5991329.8 | P40: 0 | Q40: =ROUND(+'WP II-E-3.3'!Q14*$E$38,2) -> 3946510.7 | R40: 0 | S40: =+'WP II-E-3.3'!S14*$E$38 -> 0 | T40: =+'WP II-E-3.3'!T14*$E$38 -> 0
A41: =+A40+1 -> 30 | B41: 00.13 | C41: 00.13: Data Handling Eq | D41: MACRS 5 | E41: HY | F41: =ROUND(+'WP II-E-3.3'!F15*$E$38,2) -> 0 | G41: 0 | H41: =ROUND(+'WP II-E-3.3'!H15*$E$38,2) -> 0 | I41: 0 | J41: =ROUND(+'WP II-E-3.3'!J15*$E$38,2) -> 3173.04 | K41: 0 | L41: =SUM(F41:K41) -> 3173.04 | M41: =ROUND(+'WP II-E-3.3'!M15*$E$38,2) -> 1145.33 | N41: 0 | O41: =ROUND(+'WP II-E-3.3'!O15*$E$38,2) -> 811.08 | P41: 0 | Q41: =ROUND(+'WP II-E-3.3'!Q15*$E$38,2) -> 486.65 | R41: 0 | S41: =+'WP II-E-3.3'!S15*$E$38 -> 0 | T41: =+'WP II-E-3.3'!T15*$E$38 -> 0
A42: =+A41+1 -> 31 | B42: 00.21 | C42: 00.21: Airplanes | D42: MACRS 5 | E42: HY | F42: =ROUND(+'WP II-E-3.3'!F16*$E$38,2) -> 0 | G42: 0 | H42: =ROUND(+'WP II-E-3.3'!H16*$E$38,2) -> 0 | I42: 0 | J42: =ROUND(+'WP II-E-3.3'!J16*$E$38,2) -> 0 | K42: 0 | L42: =SUM(F42:K42) -> 0 | M42: =ROUND(+'WP II-E-3.3'!M16*$E$38,2) -> 0 | N42: 0 | O42: =ROUND(+'WP II-E-3.3'!O16*$E$38,2) -> 0 | P42: 0 | Q42: =ROUND(+'WP II-E-3.3'!Q16*$E$38,2) -> 0 | R42: 0 | S42: =+'WP II-E-3.3'!S16*$E$38 -> 0 | T42: =+'WP II-E-3.3'!T16*$E$38 -> 0
A43: =+A42+1 -> 32 | B43: 00.22 | C43: 00.22: Automobiles | D43: MACRS 5 | E43: HY | F43: =ROUND(+'WP II-E-3.3'!F17*$E$38,2) -> 307880.73 | G43: 0 | H43: =ROUND(+'WP II-E-3.3'!H17*$E$38,2) -> 301500.62 | I43: 0 | J43: =ROUND(+'WP II-E-3.3'!J17*$E$38,2) -> 99074.24 | K43: 0 | L43: =SUM(F43:K43) -> 708455.59 | M43: =ROUND(+'WP II-E-3.3'!M17*$E$38,2) -> 172088.55 | N43: 0 | O43: =ROUND(+'WP II-E-3.3'!O17*$E$38,2) -> 135376.72 | P43: 0 | Q43: =ROUND(+'WP II-E-3.3'!Q17*$E$38,2) -> 90470.86 | R43: 0 | S43: =+'WP II-E-3.3'!S17*$E$38 -> 0 | T43: =+'WP II-E-3.3'!T17*$E$38 -> 0
A44: =+A43+1 -> 33 | B44: 00.241 | C44: 00.241: Light Trucks | D44: MACRS 5 | E44: HY | F44: =ROUND(+'WP II-E-3.3'!F18*$E$38,2) -> 0 | G44: 0 | H44: =ROUND(+'WP II-E-3.3'!H18*$E$38,2) -> 0 | I44: 0 | J44: =ROUND(+'WP II-E-3.3'!J18*$E$38,2) -> 0 | K44: 0 | L44: =SUM(F44:K44) -> 0 | M44: =ROUND(+'WP II-E-3.3'!M18*$E$38,2) -> 0 | N44: 0 | O44: =ROUND(+'WP II-E-3.3'!O18*$E$38,2) -> 0 | P44: 0 | Q44: =ROUND(+'WP II-E-3.3'!Q18*$E$38,2) -> 0 | R44: 0 | S44: =+'WP II-E-3.3'!S18*$E$38 -> 0 | T44: =+'WP II-E-3.3'!T18*$E$38 -> 0
A45: =+A44+1 -> 34 | B45: 00.242 | C45: 00.242: Heavy Trucks | D45: MACRS 5 | E45: HY | F45: =ROUND(+'WP II-E-3.3'!F19*$E$38,2) -> 31067.18 | G45: 0 | H45: =ROUND(+'WP II-E-3.3'!H19*$E$38,2) -> 91205 | I45: 0 | J45: =ROUND(+'WP II-E-3.3'!J19*$E$38,2) -> 1195745.3 | K45: 0 | L45: =SUM(F45:K45) -> 1318017.5 | M45: =ROUND(+'WP II-E-3.3'!M19*$E$38,2) -> 95753.03 | N45: 0 | O45: =ROUND(+'WP II-E-3.3'!O19*$E$38,2) -> 475876.33 | P45: 0 | Q45: =ROUND(+'WP II-E-3.3'!Q19*$E$38,2) -> 286554.59 | R45: 0 | S45: =+'WP II-E-3.3'!S19*$E$38 -> 0 | T45: =+'WP II-E-3.3'!T19*$E$38 -> 0
A46: =+A45+1 -> 35 | B46: 00.27 | C46: 00.27: Trailers | D46: MACRS 5 | E46: HY | F46: =ROUND(+'WP II-E-3.3'!F20*$E$38,2) -> 181554.07 | G46: 0 | H46: =ROUND(+'WP II-E-3.3'!H20*$E$38,2) -> 479816.78 | I46: 0 | J46: =ROUND(+'WP II-E-3.3'!J20*$E$38,2) -> 260767.59 | K46: 0 | L46: =SUM(F46:K46) -> 922138.44 | M46: =ROUND(+'WP II-E-3.3'!M20*$E$38,2) -> 213337.8 | N46: 0 | O46: =ROUND(+'WP II-E-3.3'!O20*$E$38,2) -> 210435.63 | P46: 0 | Q46: =ROUND(+'WP II-E-3.3'!Q20*$E$38,2) -> 132637.39 | R46: 0 | S46: =+'WP II-E-3.3'!S20*$E$38 -> 0 | T46: =+'WP II-E-3.3'!T20*$E$38 -> 0
A47: =+A46+1 -> 36 | B47: 00.28 | C47: 00.28: Boats | D47: MACRS 10 | E47: HY | F47: =ROUND(+'WP II-E-3.3'!F21*$E$38,2) -> 0 | G47: 0 | H47: =ROUND(+'WP II-E-3.3'!H21*$E$38,2) -> 0 | I47: 0 | J47: =ROUND(+'WP II-E-3.3'!J21*$E$38,2) -> 962.81 | K47: 0 | L47: =SUM(F47:K47) -> 962.81 | M47: =ROUND(+'WP II-E-3.3'!M21*$E$38,2) -> 24.07 | N47: 0 | O47: =ROUND(+'WP II-E-3.3'!O21*$E$38,2) -> 187.75 | P47: 0 | Q47: =ROUND(+'WP II-E-3.3'!Q21*$E$38,2) -> 150.2 | R47: 0 | S47: =+'WP II-E-3.3'!S21*$E$38 -> 0 | T47: =+'WP II-E-3.3'!T21*$E$38 -> 0
A48: =+A47+1 -> 37 | B48: 00.3 | C48: 00.3: Land Improv | D48: MACRS 15 | E48: HY | F48: =ROUND(+'WP II-E-3.3'!F22*$E$38,2) -> 24984551 | G48: 0 | H48: =ROUND(+'WP II-E-3.3'!H22*$E$38,2) -> 40635617 | I48: 0 | J48: =ROUND(+'WP II-E-3.3'!J22*$E$38,2) -> 63120990 | K48: 0 | L48: =SUM(F48:K48) -> 1.2874116e+08 | M48: =ROUND(+'WP II-E-3.3'!M22*$E$38,2) -> 8276256.5 | N48: 0 | O48: =ROUND(+'WP II-E-3.3'!O22*$E$38,2) -> 11502055 | P48: 0 | Q48: =ROUND(+'WP II-E-3.3'!Q22*$E$38,2) -> 10371822 | R48: 0 | S48: =+'WP II-E-3.3'!S22*$E$38 -> 0 | T48: =+'WP II-E-3.3'!T22*$E$38 -> 0
A49: =+A48+1 -> 38 | B49: 40.4 | C49: 40.4: Railroad Track | D49: MACRS 7 | E49: HY | F49: =ROUND(+'WP II-E-3.3'!F23*$E$38,2) -> 0 | G49: 0 | H49: =ROUND(+'WP II-E-3.3'!H23*$E$38,2) -> 0 | I49: 0 | J49: =ROUND(+'WP II-E-3.3'!J23*$E$38,2) -> 0 | K49: 0 | L49: =SUM(F49:K49) -> 0 | M49: =ROUND(+'WP II-E-3.3'!M23*$E$38,2) -> 0 | N49: 0 | O49: =ROUND(+'WP II-E-3.3'!O23*$E$38,2) -> 0 | P49: 0 | Q49: =ROUND(+'WP II-E-3.3'!Q23*$E$38,2) -> 0 | R49: 0 | S49: =+'WP II-E-3.3'!S23*$E$38 -> 0 | T49: =+'WP II-E-3.3'!T23*$E$38 -> 0
A50: =+A49+1 -> 39 | B50: 49.14 | C50: 49.14: Trans & Dist Plnt | D50: MACRS 20 | E50: HY | F50: =ROUND(+'WP II-E-3.3'!F24*$E$38,2) -> 4.6685132e+08 | G50: 0 | H50: =ROUND(+'WP II-E-3.3'!H24*$E$38,2) -> 6.2581665e+08 | I50: 0 | J50: =ROUND(+'WP II-E-3.3'!J24*$E$38,2) -> 7.6470139e+08 | K50: 0 | L50: =SUM(F50:K50) -> 1.8573694e+09 | M50: =ROUND(+'WP II-E-3.3'!M24*$E$38,2) -> 1.0378956e+08 | N50: 0 | O50: =ROUND(+'WP II-E-3.3'!O24*$E$38,2) -> 1.2552934e+08 | P50: 0 | Q50: =ROUND(+'WP II-E-3.3'!Q24*$E$38,2) -> 1.1611486e+08 | R50: 0 | S50: =+'WP II-E-3.3'!S24*$E$38 -> 0 | T50: =+'WP II-E-3.3'!T24*$E$38 -> 0
... A59: =+A58+1 -> 48 | B59: LR84 | C59: LR84: Easements 84 Yr | D59: SL 84 | E59: HY | F59: =ROUND(+'WP II-E-3.3'!F33*$E$38,2) -> 8391158.5 | G59: 0 | H59: =ROUND(+'WP II-E-3.3'!H33*$E$38,2) -> 5567531.4 | I59: 0 | J59: =ROUND(+'WP II-E-3.3'!J33*$E$38,2) -> 8609051.8 | K59: 0 | L59: =SUM(F59:K59) -> 22567742 | M59: =ROUND(+'WP II-E-3.3'!M33*$E$38,2) -> 817589.9 | N59: 0 | O59: =ROUND(+'WP II-E-3.3'!O33*$E$38,2) -> 830033.71 | P59: 0 | Q59: =ROUND(+'WP II-E-3.3'!Q33*$E$38,2) -> 764002.65 | R59: 0 | S59: =+'WP II-E-3.3'!S33*$E$38 -> 0 | T59: =+'WP II-E-3.3'!T33*$E$38 -> 0
A60: =+A59+1 -> 49 | B60: ND | C60: ND: Non Depr | D60: None | F60: =ROUND(+'WP II-E-3.3'!F34*$E$38,2) -> 20168846 | G60: 0 | H60: =ROUND(+'WP II-E-3.3'!H34*$E$38,2) -> 19355946 | I60: 0 | J60: =ROUND(+'WP II-E-3.3'!J34*$E$38,2) -> 2040401.2 | K60: 0 | L60: =SUM(F60:K60) -> 41565193 | M60: =ROUND(+'WP II-E-3.3'!M34*$E$38,2) -> 0 | N60: 0 | O60: =ROUND(+'WP II-E-3.3'!O34*$E$38,2) -> 0 | P60: 0 | Q60: =ROUND(+'WP II-E-3.3'!Q34*$E$38,2) -> 0 | R60: 0 | S60: =+'WP II-E-3.3'!S34*$E$38 -> 0 | T60: =+'WP II-E-3.3'!T34*$E$38 -> 0
...
