Workbook

Sheet Op Income
H1: WP/II-E-3/1
H2: Page 1 of 1
A4: 2025 RATE CASE
A5: ONCOR ELECTRIC DELIVERY COMPANY LLC
A6: OPERATING INCOME AS REPORTED IN FINANCIAL STATEMENTS
A7: TEST YEAR ENDING DECEMBER 31, 2024
A8: SPONSOR: B. L. CLUTTER
C11: TOTAL | E11: OPERATING | G11: NON-OPERATING
A13: 1 | B13: Income Before Tax | C13: =+E13+G13 -> 1.1736217e+09 | E13: 1.1104084e+09 | G13: 63213310
A14: =A13+1 -> 2
A15: =A14+1 -> 3 | B15: Income Taxes:
A16: =A15+1 -> 4 | B16: Federal | C16: =+E16+G16 -> 1.7438016e+08 | E16: 1.769176e+08 | G16: -2537439.1
A17: =A16+1 -> 5 | B17: State | C17: =+E17+G17 -> 31954540 | E17: 31866850 | G17: 87689.72
A18: =A17+1 -> 6 | B18: ITC | C18: =+E18+G18 -> -479524.92 | E18: -479524.92 | G18: 0
A19: =A18+1 -> 7 | C19: =SUM(C16:C18) -> 2.0585517e+08 | E19: =SUM(E16:E18) -> 2.0830492e+08 | G19: =SUM(G16:G18) -> -2449749.4
A20: =A19+1 -> 8
A21: =A20+1 -> 9 | B21: Net Income | C21: =C13-C19 -> 9.6776655e+08 | E21: =E13-E19 -> 9.0210349e+08 | G21: =+C21-E21 -> 65663059
A22: =A21+1 -> 10
A23: =A22+1 -> 11 | B23: Federal Income Taxes | C23: =C16+C18 -> 1.7390063e+08 | E23: =E16+E18 -> 1.7643807e+08 | G23: =C23-E23 -> -2537439.1
A24: =A23+1 -> 12
A25: =A24+1 -> 13 | B25: Interest Expense | C25: =+E25+G25 -> 6.5354073e+08 | E25: 6.5354073e+08 | G25: 0
A26: =A25+1 -> 14
A27: =A26+1 -> 15
A28: =A27+1 -> 16 | B28: Return on Rate Base | E28: =ROUND(+E21+E25,2) -> 1.5556442e+09
A29: =A28+1 -> 17
A30: =A29+1 -> 18 | B30: Federal Income Taxes
A31: =A30+1 -> 19 | B31: Current | C31: =+E31+G31 -> 19455481 | E31: 23858182 | G31: -4402700.6
A32: =A31+1 -> 20 | B32: Deferred | C32: =+E32+G32 -> 1.5444515e+08 | E32: 1.5257989e+08 | G32: 1865261.5
A33: =A32+1 -> 21 | C33: =SUM(C31:C32) -> 1.7390063e+08 | E33: =SUM(E31:E32) -> 1.7643807e+08 | G33: =SUM(G31:G32) -> -2537439.1

Sheet Op ETR
M1: WP/II-E-3/2
M2: Page 1 of 1
A4: 2025 RATE CASE
A5: ONCOR ELECTRIC DELIVERY COMPANY LLC
A6: TAX EXPENSE RECONCILIATION AS REPORTED IN FINANCIAL STATEMENTS
A7: TEST YEAR ENDING DECEMBER 31, 2024
A8: SPONSOR: B. L. CLUTTER
C11: Total | F11: Operating | I11: Non-Operating | L11: Adjusted Non-Operating*
C12: Pre-Yax | D12: Tax | F12: Pre-Yax | G12: Tax | I12: Pre-Yax | J12: Tax | L12: Pre-Yax | M12: Tax
A13: 1 | B13: Operating PTBI | C13: =+F13+I13 -> 1.1736217e+09 | D13: =ROUND(C13*0.21,2) -> 2.4646056e+08 | F13: =+'Op Income'!E13 -> 1.1104084e+09 | G13: =ROUND(F13*0.21,2) -> 2.3318577e+08 | I13: =+'Op Income'!G13 -> 63213310 | J13: =+ROUND(I13*0.21,2) -> 13274795 | L13: =+I13+'NonOp Adj'!D25 -> 80729690 | M13: =+ROUND(L13*0.21,2) -> 16953235
A14: =1+A13 -> 2
A15: =1+A14 -> 3 | B15: Meals & Entertainment | C15: =+F15+I15 -> 4310520.8 | D15: =+ROUND(C15*0.21,2) -> 905209.37 | F15: 4310520.8 | G15: =ROUND(F15*0.21,2) -> 905209.37 | I15: 0 | J15: =ROUND(+I15*0.21,2) -> 0 | L15: =+I15 -> 0 | M15: =ROUND(+L15*0.21,2) -> 0
A16: =1+A15 -> 4 | B16: AFUDC Equity | C16: =+F16+I16 -> -59648129 | D16: =+ROUND(C16*0.21,2) -> -12526107 | F16: 0 | G16: =ROUND(F16*0.21,2) -> 0 | I16: -59648129 | J16: =ROUND(+I16*0.21,2) -> -12526107 | L16: =+I16 -> -59648129 | M16: =ROUND(+L16*0.21,2) -> -12526107
A17: =1+A16 -> 5 | B17: Nondeductible Penalties & Fines | C17: =+F17+I17 -> 636895.62 | D17: =+ROUND(C17*0.21,2) -> 133748.08 | F17: 0 | G17: =ROUND(F17*0.21,2) -> 0 | I17: 636895.62 | J17: =ROUND(+I17*0.21,2) -> 133748.08 | L17: =+I17 -> 636895.62 | M17: =ROUND(+L17*0.21,2) -> 133748.08
A18: =1+A17 -> 6 | B18: Social Club Dues and Fees | C18: =+F18+I18 -> 267483.76 | D18: =+ROUND(C18*0.21,2) -> 56171.59 | F18: 267483.76 | G18: =ROUND(F18*0.21,2) -> 56171.59 | I18: 0 | J18: =ROUND(+I18*0.21,2) -> 0 | L18: =+I18 -> 0 | M18: =ROUND(+L18*0.21,2) -> 0
A19: =1+A18 -> 7 | B19: Commuter Expenses | C19: =+F19+I19 -> 1524901.5 | D19: =+ROUND(C19*0.21,2) -> 320229.32 | F19: 1524901.5 | G19: =ROUND(F19*0.21,2) -> 320229.32 | I19: 0 | J19: =ROUND(+I19*0.21,2) -> 0 | L19: =+I19 -> 0 | M19: =ROUND(+L19*0.21,2) -> 0
A20: =1+A19 -> 8 | B20: Civic and Political Activities | C20: =+F20+I20 -> 1026500.1 | D20: =+ROUND(C20*0.21,2) -> 215565.03 | F20: 0 | G20: =ROUND(F20*0.21,2) -> 0 | I20: 1026500.1 | J20: =ROUND(+I20*0.21,2) -> 215565.03 | L20: =+I20 -> 1026500.1 | M20: =ROUND(+L20*0.21,2) -> 215565.03
A21: =1+A20 -> 9 | B21: Supplemental Retirement Insurance Premium | C21: =+F21+I21 -> -14371822 | D21: =+ROUND(C21*0.21,2) -> -3018082.6 | F21: -14221770 | G21: =ROUND(F21*0.21,2) -> -2986571.7 | I21: -150051.81 | J21: =ROUND(+I21*0.21,2) -> -31510.88 | L21: =+I21 -> -150051.81 | M21: =ROUND(+L21*0.21,2) -> -31510.88
A22: =1+A21 -> 10 | B22: Salary Deferral Trust Interest & Dividend Income | C22: =+F22+I22 -> -11813882 | D22: =+ROUND(C22*0.21,2) -> -2480915.2 | F22: 0 | G22: =ROUND(F22*0.21,2) -> 0 | I22: -11813882 | J22: =ROUND(+I22*0.21,2) -> -2480915.2 | L22: =+I22 -> -11813882 | M22: =ROUND(+L22*0.21,2) -> -2480915.2
A23: =1+A22 -> 11 | B23: Salary Deferral Insurance Premium Benefit Expense | C23: =+F23+I23 -> -5647247.9 | D23: =+ROUND(C23*0.21,2) -> -1185922.1 | F23: 0 | G23: =ROUND(F23*0.21,2) -> 0 | I23: -5647247.9 | J23: =ROUND(+I23*0.21,2) -> -1185922.1 | L23: =+I23 -> -5647247.9 | M23: =ROUND(+L23*0.21,2) -> -1185922.1
A24: =1+A23 -> 12 | B24: Non-recoverable Pension & OPEBs | C24: =+F24+I24 -> 5144129 | D24: =+ROUND(C24*0.21,2) -> 1080267.1 | F24: 5716651 | G24: =ROUND(F24*0.21,2) -> 1200496.7 | I24: -572522 | J24: =ROUND(+I24*0.21,2) -> -120229.62 | L24: =+I24 -> -572522 | M24: =ROUND(+L24*0.21,2) -> -120229.62
A25: =1+A24 -> 13 | B25: SARs Capitalized | C25: =+F25+I25 -> 353019.05 | D25: =+ROUND(C25*0.21,2) -> 74134 | F25: 0 | G25: =ROUND(F25*0.21,2) -> 0 | I25: 353019.05 | J25: =ROUND(+I25*0.21,2) -> 74134 | L25: =+I25 -> 353019.05 | M25: =ROUND(+L25*0.21,2) -> 74134
A26: =1+A25 -> 14 | B26: Federal Benefit of State | C26: =+F26+I26 -> -31954540 | D26: =+ROUND(C26*0.21,2) -> -6710453.4 | F26: =-G27 -> -31866850 | G26: =ROUND(F26*0.21,2) -> -6692038.5 | I26: =-J27 -> -87689.72 | J26: =ROUND(+I26*0.21,2) -> -18414.84 | L26: =+I26 -> -87689.72 | M26: =ROUND(+L26*0.21,2) -> -18414.84
A27: =1+A26 -> 15 | B27: TGMT | D27: =+'Op Income'!C17 -> 31954540 | G27: ='Op Income'!E17 -> 31866850 | J27: =+'Op Income'!G17 -> 87689.72 | M27: =+J27 -> 87689.72
A28: =1+A27 -> 16 | B28: Total Perms | C28: =SUM(C15:C27) -> -1.1017217e+08 | D28: =SUM(D15:D27) -> 8818384.1 | F28: =SUM(F15:F27) -> -34269063 | G28: =SUM(G15:G27) -> 24670347 | I28: =SUM(I15:I27) -> -75903107 | J28: =SUM(J15:J27) -> -15851963 | L28: =SUM(L15:L27) -> -75903107 | M28: =SUM(M15:M27) -> -15851963
A29: =1+A28 -> 17 | B29: Protected Excess DFIT Amortization | D29: =+G29+J29 -> -16233756 | G29: =-16233763.56+7.15 -> -16233756 | J29: 0 | M29: 0
A30: =1+A29 -> 18 | B30: Non-protected Excess DFIT Amortization | D30: =+G30+J30 -> -36089814 | G30: =-34480878.24-7-G31 -> -36089814 | J30: 0 | M30: 0
A31: =1+A30 -> 19 | B31: Excess Reserve DFIT Amortization | D31: =+G31+J31 -> 1608928.6 | G31: 1608928.6 | J31: 0 | M31: 0
A32: =1+A31 -> 20 | B32: Reverse Flow Through | D32: =+G32+J32 -> 884662.91 | G32: 884662.91 | J32: 0 | M32: 0
A33: =1+A32 -> 21 | B33: Tax Expense Before Discretes | D33: =SUM(D13,D28:D32) -> 2.0544897e+08 | G33: =SUM(G13,G28:G32) -> 2.0802614e+08 | J33: =SUM(J13,J28:J32) -> -2577167.8 | M33: =SUM(M13,M28:M32) -> 1101272.1
A34: =1+A33 -> 22
A35: =1+A34 -> 23 | B35: Discretes
A36: =1+A35 -> 24 | B36: ITC | D36: =+G36+J36 -> -479524.92 | G36: -479524.92 | J36: 0 | M36: =+J36 -> 0
A37: =1+A36 -> 25 | B37: General Business Credit | D37: =+G37+J37 -> -79367.46 | G37: -79367.46 | J37: 0 | M37: =+J37 -> 0
A38: =1+A37 -> 26 | B38: FIN48 Tax and Interest | D38: =+G38+J38 -> -19042 | G38: =697078-716120 -> -19042 | J38: 0 | M38: =+J38 -> 0
A39: =1+A38 -> 27 | B39: Prior Period and Other Adjustments | D39: =+G39+J39 -> 984140.37 | G39: 856722.03 | J39: 127418.34 | M39: =+J39 -> 127418.34
A40: =1+A39 -> 28 | B40: YTD Discrete Items | D40: =SUM(D36:D39) -> 406205.99 | G40: =SUM(G36:G39) -> 278787.65 | J40: =SUM(J36:J39) -> 127418.34 | M40: =SUM(M36:M39) -> 127418.34
A41: =1+A40 -> 29
A42: =1+A41 -> 30 | B42: Taxes Calculated | D42: =+D33+D40 -> 2.0585517e+08 | G42: =+G33+G40 -> 2.0830492e+08 | J42: =+J33+J40 -> -2449749.4 | M42: =+M33+M40 -> 1228690.5
A43: =1+A42 -> 31 | B43: Federal Only | D43: =+D42-D27 -> 1.7390063e+08 | G43: =+G42-G27 -> 1.7643807e+08 | J43: =+J42-J27 -> -2537439.1 | M43: =+M42-M27 -> 1141000.7
...

Sheet NonOp Adj
F1: WP/II-E-3/3
F2: Page 1 of 1
A4: 2025 RATE CASE
A5: ONCOR ELECTRIC DELIVERY COMPANY LLC
A6: BELOW THE LINE TAX EXPENSE
A7: TEST YEAR ENDING DECEMBER 31, 2024
A8: SPONSOR: B. L. CLUTTER
D11: Total Company | E11: Adjustments | F11: Total
B12: Non-Operating Income Taxes:
B13: 4092000 | C13: Current FIT - Other Income | D13: -4402700.8 | E13: =ROUND((+D22+D24)*0.21,2) -> 3200496.8 | F13: =SUM(D13:E13)+1 -> -1202203
B14: 4092100 | C14: State - Income Taxes-Non Oper | D14: 87689.72 | F14: =SUM(D14:E14) -> 87689.72
B15: 4102000 | C15: Def FIT - Other Income | D15: 1865261.5 | E15: =ROUND(+D23*0.21,2) -> 477943.07 | F15: =SUM(D15:E15) -> 2343204.5
B16: 4112000 | C16: Def FIT - Non Operating Income | D16: 0 | F16: =SUM(D16:E16) -> 0
D17: =SUM(D13:D16) -> -2449749.6 | E17: =SUM(E13:E16) -> 3678439.9 | F17: =SUM(F13:F16) -> 1228691.3
B21: Other Deductions: | D21: Pre-tax Adjustments | E21: Tax Effect | F21: Tax Account
B22: 4210200 | C22: Disposition of Property-Loss | D22: 78007.33 | E22: =ROUND(+D22*0.21,2) -> 16381.54 | F22: 4092000
B23: 4253800 | C23: Reg Asset Amortization | D23: 2275919.4 | E23: =ROUND(+D23*0.21,2) -> 477943.07 | F23: 4102000
B24: 4265500 | C24: Other Deductions-Non Operating | D24: 15162454 | E24: =ROUND(+D24*0.21,2) -> 3184115.3 | F24: 4092000
D25: =SUM(D22:D24) -> 17516380 | E25: =SUM(E22:E24) -> 3678439.9

Sheet Ret & Int
Q1: WP/II-E-3/4
Q2: Page 1 of 1
A4: 2025 RATE CASE
A5: ONCOR ELECTRIC DELIVERY COMPANY LLC
A6: RETURN ON RATE BASE & SYNCHRONIZED INTEREST
A7: TEST YEAR ENDING DECEMBER 31, 2024
A8: SPONSOR: B. L. CLUTTER
E11: Known &
A12: Line | D12: Amount Per | E12: Measurable | F12: Adjusted | H12: NTU | I12: DC | J12: Consol | L12: NTU | M12: Consol | Q12: Schedule
A13: No. | B13: Description | D13: Books | E13: Changes | F13: T&D | G13: TRAN | H13: TRAN | I13: TIE | J13: TRAN | K13: DIST | L13: DIST | M13: DIST | N13: MET | O13: TDCS | P13: TOTAL | Q13: Reference
A15: 1 | B15: Total WACC | C15: =+'[2]Link Sheet'!$D$7 -> 0.0747 | Q15: II-C-1.1
A16: 2 | B16: Debt WACC | C16: =+'[2]Link Sheet'!$D$5 -> 0.0272 | Q16: II-C-1.1
A17: 3
A18: 4
A19: 5 | B19: Total Rate Base | F19: =ROUND('[1]II-B-12'!$K$106,2) -> 2.6462045e+10 | G19: =ROUND('[1]II-B-12'!N106,2) -> 1.1074905e+10 | H19: =ROUND('[1]II-B-12'!O106,2) -> 1.1097471e+09 | I19: =ROUND('[1]II-B-12'!P106,2) -> 9238090.4 | J19: =+G19+H19+I19 -> 1.219389e+10 | K19: =ROUND('[1]II-B-12'!R106,2) -> 1.3507609e+10 | L19: =ROUND('[1]II-B-12'!S106,2) -> 89342107 | M19: =+K19+L19 -> 1.3596951e+10 | N19: =ROUND('[1]II-B-12'!U106,2) -> 4.4113729e+08 | O19: =ROUND('[1]II-B-12'!V106,2) -> 2.3006701e+08 | P19: =+G19+H19+I19+K19+L19+N19+O19 -> 2.6462045e+10 | Q19: II-B | R19: =+P19-F19 -> 0 | S19: =+F19=P19 -> TRUE
A20: 6
A21: 7
A22: 8
A23: 9 | B23: Return on Rate Base | D23: =ROUND('Op Income'!E28,2) -> 1.5556442e+09 | E23: =ROUND(F23-D23,2) -> 4.2107053e+08 | F23: =ROUND($C$15*F19,2) -> 1.9767148e+09 | G23: =ROUND($C$15*G19,2) -> 8.2729539e+08 | H23: =ROUND($C$15*H19,2) -> 82898106 | I23: =ROUND($C$15*I19,2) -> 690085.35 | J23: =+G23+H23+I23 -> 9.1088358e+08 | K23: =ROUND($C$15*K19,2) -> 1.0090184e+09 | L23: =ROUND($C$15*L19,2) -> 6673855.4 | M23: =+K23+L23 -> 1.0156922e+09 | N23: =ROUND($C$15*N19,2) -> 32952956 | O23: =ROUND($C$15*O19,2) -> 17186005 | P23: =+G23+H23+I23+K23+L23+N23+O23 -> 1.9767148e+09 | R23: =+P23-F23 -> 0 | S23: =+F23=P23 -> TRUE
A24: 10
A25: 11
A26: 12 | B26: Synchronized Interest | D26: =+'Op Income'!E25 -> 6.5354073e+08 | E26: =F26-D26 -> 66226888 | F26: =ROUND($C$16*F19,2) -> 7.1976762e+08 | G26: =ROUND($C$16*G19,2) -> 3.0123741e+08 | H26: =ROUND($C$16*H19,2) -> 30185120 | I26: =ROUND($C$16*I19,2) -> 251276.06 | J26: =ROUND($C$16*J19,2) -> 3.3167381e+08 | K26: =ROUND($C$16*K19,2) -> 3.6740695e+08 | L26: =ROUND($C$16*L19,2) -> 2430105.3 | M26: =ROUND($C$16*M19,2) -> 3.6983706e+08 | ... P26: =ROUND($C$16*P19,2) -> 7.1976762e+08 | R26: =+P26-F26 -> 0 | S26: =+F26=P26 -> TRUE
