Workbook

Sheet V-K-1
B1: 2025 RATE CASE
B2: ONCOR ELECTRIC DELIVERY COMPANY LLC
B3: V-K-1 AFFILIATE EXPENSES BY FERC ACCOUNT
B4: FOR THE TEST YEAR ENDING DECEMBER 31, 2024
B5: SPONSORS: V. F. SNOW & R. A. PRACHYL
D7: FERC | E7: FERC Account
A8: Line No. | B8: Class of Items | C8: Sub-Class | D8: Account | E8: Description | F8: Total
B9: (a) | C9: (b) | D9: (c) | E9: (d) | F9: (e)
A10: 1 | B10: TAX SERVICES
A11: =+A10+1 -> 2 | C11: Consulting-Uncertain tax positions | D11: 9230000 | E11: Outside Services Employed | F11: 30000
A12: =+A11+1 -> 3 | C12: Annual Tax Return Review | D12: 9230000 | E12: Outside Services Employed | F12: 48000
A13: =+A12+1 -> 4 | C13: Annual Corptax Access | D13: 9230000 | E13: Outside Services Employed | F13: 30000
A14: =+A13+1 -> 5 | B14: Total Sempra | F14: =SUM(F10:F13) -> 108000
A15: =+A14+1 -> 6 | B15: SOFTWARE & DATA SUPPORT
A16: =+A15+1 -> 7 | C16: Ultimate Software Group Inc | D16: 9210000 | E16: Office Supplies and Expenses | F16: 250
A17: =+A16+1 -> 8 | D17: 9230000 | E17: Outside Services Employed | F17: 1380452
A18: =+A17+1 -> 9 | D18: 5660000 | E18: Misc. Transmission Expense | F18: 546
A19: =+A18+1 -> 10 | D19: 1070000 | E19: Construction Work in Progress | F19: 5404
A20: =+A19+1 -> 11 | B20: Total Ultimate Software Group Inc | F20: =SUM(F16:F19) -> 1386652
A21: =+A20+1 -> 12 | C21: Veritas Technologies LLC | D21: 9230000 | E21: Outside Services Employed | F21: 216838
A22: =+A21+1 -> 13 | B22: Total Veritas Technologies LLC | F22: =+F21 -> 216838
A23: =+A22+1 -> 14 | B23: TARIFFED SERVICES
A24: =+A23+1 -> 15 | C24: Sharyland NTS | D24: 5650000 | E24: Trans Exp - Electricity by Others | F24: 16670575
A25: =+A24+1 -> 16 | B25: Total Sharyland Utilities, L.L.C. | F25: =+F24 -> 16670575
A26: =+A25+1 -> 17 | C26: Oncor NTU NTS | D26: 5650000 | E26: Trans Exp - Electricity by Others | F26: 58040589
A27: =+A26+1 -> 18 | C27: Oncor NTU WDSS | D27: 5881008 | E27: Wholesale Distribution Expense | F27: 15382470
A28: =+A27+1 -> 19 | B28: Total Oncor Electric Delivery Co. NTU LLC | F28: =+F26+F27 -> 73423060
A29: =+A28+1 -> 20 | B29: G&W RAILROAD AGREEMENTS
A30: =+A29+1 -> 21 | C30: Dallas Garland & Northeastern RR | D30: 5890000 | E30: Rents | F30: -2806
A31: =+A30+1 -> 22 | C31: Genesee & Wyoming | D31: 1070000 | E31: Construction Work in Progress | F31: 4750
A32: =+A31+1 -> 23 | C32: Kiamichi Railroad | D32: 1070000 | E32: Construction Work in Progress | F32: 33640
A33: =+A32+1 -> 24 | D33: 5880000 | E33: Misc. Distribution Expense | F33: 1750
A34: =+A33+1 -> 25 | C34: Texas Northeastern Railroad | D34: 5670000 | E34: Rents | F34: 1323
A35: =+A34+1 -> 26 | B35: Total G&W Railroad | F35: =SUM(F30:F34) -> 38657
A36: =+A35+1 -> 27 | B36: LOAD MANAGEMENT
A37: =+A36+1 -> 28 | C37: Lineage Logistics Holdings, LLC | D37: 2284000 | E37: Accum. Prov. - Misc. Operations | F37: =96850+58653 -> 155503
A38: =+A37+1 -> 29 | B38: Total Lineage Logistics Holdings, LLC | F38: =+F37 -> 155503
A39: =+A38+1 -> 30 | B39: CONTRIBUTIONS
A40: =+A39+1 -> 31 | C40: Oncor Cares Foundation | D40: 9302000 | E40: Misc. General Expense | F40: 17227
A41: =+A40+1 -> 32 | D41: 9302000 | E41: Misc. General Exp. (contribution) | F41: 60000
...

Sheet V-K-2
B1: 2025 RATE CASE
B2: ONCOR ELECTRIC DELIVERY COMPANY LLC
B3: V-K-2 ADJUSTED AFFILIATE EXPENSES BY FERC ACCOUNT
B4: FOR THE TEST YEAR ENDING DECEMBER 31, 2024
B5: SPONSORS: V. F. SNOW & R. A. PRACHYL
D7: FERC | E7: FERC Account | G7: Pro-forma | H7: Adjusted
A8: Line No. | B8: Class of Items | C8: Sub-Class | D8: Account | E8: Description | F8: Total | G8: Adjustments | H8: Historic Year
B9: (a) | C9: (b) | D9: (c) | E9: (d) | F9: (e) | G9: (f) | H9: (g)
A10: 1 | B10: TAX SERVICES
A11: =+A10+1 -> 2 | C11: =+'V-K-1'!C11 -> Consulting-Uncertain tax positions | D11: =+'V-K-1'!D11 -> 9230000 | E11: =+'V-K-1'!E11 -> Outside Services Employed | F11: =+'V-K-1'!F11 -> 30000 | G11: 0 | H11: =+F11+G11 -> 30000
A12: =+A11+1 -> 3 | C12: =+'V-K-1'!C12 -> Annual Tax Return Review | D12: =+'V-K-1'!D12 -> 9230000 | E12: =+'V-K-1'!E12 -> Outside Services Employed | F12: =+'V-K-1'!F12 -> 48000 | G12: 0 | H12: =+F12+G12 -> 48000
A13: =+A12+1 -> 4 | C13: =+'V-K-1'!C13 -> Annual Corptax Access | D13: =+'V-K-1'!D13 -> 9230000 | E13: =+'V-K-1'!E13 -> Outside Services Employed | F13: =+'V-K-1'!F13 -> 30000 | G13: 0 | H13: =+F13+G13 -> 30000
A14: =+A13+1 -> 5 | B14: Total Sempra | F14: =SUM(F11:F13) -> 108000 | G14: =SUM(G11:G13) -> 0 | H14: =SUM(H11:H13) -> 108000
A15: =+A14+1 -> 6 | B15: SOFTWARE & DATA SUPPORT
A16: =+A15+1 -> 7 | C16: =+'V-K-1'!C16 -> Ultimate Software Group Inc | D16: =+'V-K-1'!D16 -> 9210000 | E16: =+'V-K-1'!E16 -> Office Supplies and Expenses | F16: =+'V-K-1'!F16 -> 250 | G16: 0 | H16: =+F16+G16 -> 250
A17: =+A16+1 -> 8 | D17: =+'V-K-1'!D17 -> 9230000 | E17: =+'V-K-1'!E17 -> Outside Services Employed | F17: =+'V-K-1'!F17 -> 1380452 | G17: 0 | H17: =+F17+G17 -> 1380452
A18: =+A17+1 -> 9 | D18: =+'V-K-1'!D18 -> 5660000 | E18: =+'V-K-1'!E18 -> Misc. Transmission Expense | F18: =+'V-K-1'!F18 -> 546 | G18: 0 | H18: =+F18+G18 -> 546
A19: =+A18+1 -> 10 | D19: =+'V-K-1'!D19 -> 1070000 | E19: =+'V-K-1'!E19 -> Construction Work in Progress | F19: =+'V-K-1'!F19 -> 5404 | G19: 0 | H19: =+F19+G19 -> 5404
A20: =+A19+1 -> 11 | B20: Total Ultimate Software Group Inc | F20: =SUM(F16:F19) -> 1386652 | G20: =SUM(G16:G19) -> 0 | H20: =SUM(H16:H19) -> 1386652
A21: =+A20+1 -> 12 | C21: =+'V-K-1'!C21 -> Veritas Technologies LLC | D21: =+'V-K-1'!D21 -> 9230000 | E21: =+'V-K-1'!E21 -> Outside Services Employed | F21: =+'V-K-1'!F21 -> 216838 | G21: =-113349+201020 -> 87671 | H21: =+F21+G21 -> 304509
A22: =+A21+1 -> 13 | B22: Total Veritas Technologies LLC | F22: =+F21 -> 216838 | G22: =+G21 -> 87671 | H22: =+H21 -> 304509
A23: =+A22+1 -> 14 | B23: TARIFFED SERVICES
A24: =+A23+1 -> 15 | C24: =+'V-K-1'!C24 -> Sharyland NTS | D24: =+'V-K-1'!D24 -> 5650000 | E24: =+'V-K-1'!E24 -> Trans Exp - Electricity by Others | F24: =+'V-K-1'!F24 -> 16670575 | G24: =+H24-F24 -> -382282 | H24: =+K24 -> 16288293 | K24: 16288293
A25: =+A24+1 -> 16 | B25: Total Sharyland Utilities, L.L.C. | F25: =+F24 -> 16670575 | G25: =+G24 -> -382282 | H25: =+H24 -> 16288293
A26: =+A25+1 -> 17 | C26: =+'V-K-1'!C26 -> Oncor NTU NTS | D26: =+'V-K-1'!D26 -> 5650000 | E26: =+'V-K-1'!E26 -> Trans Exp - Electricity by Others | F26: =+'V-K-1'!F26 -> 58040589 | G26: =+H26-F26 -> -3321511 | H26: 54719078
A27: =+A26+1 -> 18 | C27: =+'V-K-1'!C27 -> Oncor NTU WDSS | D27: =+'V-K-1'!D27 -> 5881008 | E27: =+'V-K-1'!E27 -> Wholesale Distribution Expense | F27: =+'V-K-1'!F27 -> 15382470 | G27: =+H27-F27 -> -2691289.5 | H27: 12691181
A28: =+A27+1 -> 19 | B28: Total Oncor Electric Delivery Co. NTU LLC | F28: =+F26+F27 -> 73423060 | G28: =+G26+G27 -> -6012800.5 | H28: =+H26+H27 -> 67410259
A29: =+A28+1 -> 20 | B29: G&W RAILROAD AGREEMENTS
A30: =+A29+1 -> 21 | C30: =+'V-K-1'!C30 -> Dallas Garland & Northeastern RR | D30: =+'V-K-1'!D30 -> 5890000 | E30: =+'V-K-1'!E30 -> Rents | F30: =+'V-K-1'!F30 -> -2806 | G30: 0 | H30: =+F30+G30 -> -2806
A31: =+A30+1 -> 22 | C31: =+'V-K-1'!C31 -> Genesee & Wyoming | D31: =+'V-K-1'!D31 -> 1070000 | E31: =+'V-K-1'!E31 -> Construction Work in Progress | F31: =+'V-K-1'!F31 -> 4750 | G31: 0 | H31: =+F31+G31 -> 4750
A32: =+A31+1 -> 23 | C32: =+'V-K-1'!C32 -> Kiamichi Railroad | D32: =+'V-K-1'!D32 -> 1070000 | E32: =+'V-K-1'!E32 -> Construction Work in Progress | F32: =+'V-K-1'!F32 -> 33640 | G32: 0 | H32: =+F32+G32 -> 33640
A33: =+A32+1 -> 24 | D33: =+'V-K-1'!D33 -> 5880000 | E33: =+'V-K-1'!E33 -> Misc. Distribution Expense | F33: =+'V-K-1'!F33 -> 1750 | G33: 0 | H33: =+F33+G33 -> 1750
A34: =+A33+1 -> 25 | C34: =+'V-K-1'!C34 -> Texas Northeastern Railroad | D34: =+'V-K-1'!D34 -> 5670000 | E34: =+'V-K-1'!E34 -> Rents | F34: =+'V-K-1'!F34 -> 1323 | G34: 0 | H34: =+F34+G34 -> 1323
A35: =+A34+1 -> 26 | B35: Total G&W Railroad | F35: =SUM(F30:F34) -> 38657 | G35: =SUM(G30:G34) -> 0 | H35: =SUM(H30:H34) -> 38657
A36: =+A35+1 -> 27 | B36: LOAD MANAGEMENT
A37: =+A36+1 -> 28 | C37: =+'V-K-1'!C37 -> Lineage Logistics Holdings, LLC | D37: =+'V-K-1'!D37 -> 2284000 | E37: =+'V-K-1'!E37 -> Accum. Prov. - Misc. Operations | F37: =+'V-K-1'!F37 -> 155503 | G37: 0 | H37: =+F37+G37 -> 155503
A38: =+A37+1 -> 29 | B38: Total Lineage Logistics Holdings, LLC | F38: =+F37 -> 155503 | G38: =+G37 -> 0 | H38: =+H37 -> 155503
A39: =+A38+1 -> 30 | B39: CONTRIBUTIONS
A40: =+A39+1 -> 31 | C40: =+'V-K-1'!C40 -> Oncor Cares Foundation | D40: =+'V-K-1'!D40 -> 9302000 | E40: =+'V-K-1'!E40 -> Misc. General Expense | F40: =+'V-K-1'!F40 -> 17227 | G40: 0 | H40: =+F40+G40 -> 17227
A41: =+A40+1 -> 32 | D41: =+'V-K-1'!D41 -> 9302000 | E41: =+'V-K-1'!E41 -> Misc. General Exp. (contribution) | F41: =+'V-K-1'!F41 -> 60000 | G41: 0 | H41: =+F41+G41 -> 60000
...

Sheet V-K-3
B1: 2025 RATE CASE
B2: ONCOR ELECTRIC DELIVERY COMPANY LLC
B3: V-K-3 ORGANIZATION CHART
B4: FOR THE TEST YEAR ENDING DECEMBER 31, 2024
B5: SPONSOR: V. F. SNOW
B10: See PDF

Sheet V-K-4
B1: 2025 RATE CASE
B2: ONCOR ELECTRIC DELIVERY COMPANY LLC
B3: V-K-4 DESCRIPTION OF SERVICES
B4: FOR THE TEST YEAR ENDING DECEMBER 31, 2024
B5: SPONSOR: V. F. SNOW
A7: Line No. | B7: Affiliate | C7: Class of Items | D7: Description of Services
A8: 1 | B8: TAX SERVICES
A9: =+A8+1 -> 2 | B9: Sempra | C9: Tax Services - Consulting-Uncertain Tax Positions | D9: Sempra provides assistance to Oncor with its quarterly updates on uncertain tax positions based on Accounting Standards Codification (ASC) 740, "Income Taxes" for calendar quarters ending each March 31, June 30, September 30, and December 31.
A10: =A9+1 -> 3 | C10: Tax Services - Annual Tax Return Review | D10: Services include review of the annual Federal Tax Returns of Oncor and all affiliates within the Oncor ring fence.
A11: =A10+1 -> 4 | C11: Tax Services - Annual CorpTax Access | D11: Provision of Sempra's license and access to CorpTax software for Oncor's use in preparing, printing, and data storage for the annual Federal Income Tax Returns.
A12: =A11+1 -> 5 | B12: SOFTWARE & DATA SUPPORT
A13: =A12+1 -> 6 | B13: Ultimate Software Group Inc | C13: Software and Data Support | D13: Services include ongoing payroll administration and other human resource services by Ultimate. The Ultimate system (MyHR Connection) includes full responsibility and accountability for payroll-related tax calculations, payment and filing, all wage garnishment disbursement services, and all benefit calculations and payments.
A14: =A13+1 -> 7 | B14: Veritas Technologies LLC | C14: Software and Data Support | D14: Services include enterprise data protection, data storage, data back-up, and disaster recovery.
A15: =A14+1 -> 8 | B15: TARIFFED SERVICES
A16: =A15+1 -> 9 | B16: Sharyland Utilities, L.L.C. | C16: Tariffed Services - Network Transmission Service (NTS) | D16: Services include tariffed network transmission service rated at 60 kV and above.
A17: =A16+1 -> 10 | B17: Oncor Electric Delivery Co. NTU LLC | C17: Tariffed Services - Network Transmission Service (NTS) | D17: Services include tariffed network transmission service rated at 60 kV and above.
A18: =A17+1 -> 11 | C18: Tariffed Services - Wholesale Distribution Substation Service (WDSS) | D18: All transformation service supplied in connection with the delivery of electric power and energy to a Point of Interconnection, measured through one meter provided through tariffed wholesale distribution substation service.
A19: =A18+1 -> 12 | B19: G&W RAILROAD AGREEMENTS
A20: =A19+1 -> 13 | B20: Genesee & Wyoming | C20: G&W Railroad Agreements | D20: Railroad power line crossings and right of entries through Occupancy License Agreements.
A21: =A20+1 -> 14 | B21: LOAD MANAGEMENT
A22: =A21+1 -> 15 | B22: Lineage Logistics Holdings, LLC | C22: Load Management | D22: Lineage Logistics Holdings, LLC is a participant in Oncor’s Winter Emergency Load Management energy efficiency program, and received payments through that program in accordance with the terms of its Texas Energy Efficiency Market Agreement and Winter Emergency Load Management Program Reservation of Funds Agreement with Oncor.
A23: =A22+1 -> 16 | B23: CONTRIBUTIONS
A24: =A23+1 -> 17 | B24: Oncor Cares Foundation | C24: Contributions | D24: Oncor Cares Foundation was formed to make grants for charitable purposes and to direct resources in furtherance of such purposes.
A25: =A24+1 -> 18 | B25: A/R FACILITY
A26: =A25+1 -> 19 | B26: Oncor Receivables LLC | C26: Oncor Receivables LLC | D26: Oncor contributes to Oncor Receivables LLC the amounts equal to the principal amount of borrowings to be repaid under the AR Facility as well as amounts payable for interest and fees.

Sheet V-K-5
B1: 2025 RATE CASE
B2: ONCOR ELECTRIC DELIVERY COMPANY LLC
B3: V-K-5 CAPITAL PROJECTS
B4: FOR THE TEST YEAR ENDING DECEMBER 31, 2024
B5: SPONSORS: V. F. SNOW & R. A. PRACHYL
D7: Total | E7: Closed to
A8: Line No. | B8: Project ID | C8: Project Description | D8: Capitalized | E8: Plant-in-Service
B9: (a) | C9: (b) | D9: (c) | E9: (d)
A10: 1 | B10: IWHC2400 | C10: New Interface File | D10: 5000 | E10: In Progress
A11: =+A10+1 -> 2 | B11: INDCONOH | C11: HCM Enhancements | D11: 404 | E11: In Progress
A12: =+A11+1 -> 3 | B12: OPT46977 | C12: Payne-Valley 138kV Crossing | D12: 4750 | E12: In Progress
A13: =+A12+1 -> 4 | B13: 1112472W | C13: Kiamichi Easement Renewal | D13: 33640 | E13: In Progress
A14: =+A13+1 -> 5 | C14: Total | D14: =SUM(D10:D13) -> 43794

Sheet V-K-6
B1: 2025 RATE CASE
B2: ONCOR ELECTRIC DELIVERY COMPANY LLC
B3: V-K-6 ADJUSTMENTS TO TEST YEAR EXPENSES
B4: FOR THE TEST YEAR ENDING DECEMBER 31, 2024
B5: SPONSORS: V. F. SNOW
D7: Total
A8: Line No. | B8: Description | C8: Purpose | D8: Adjustment
B9: (a) | C9: (b) | D9: (c)
A10: 1 | B10: Veritas Technologies LLC
A11: =A10+1 -> 2 | B11: Software maintenance annual increase | C11: Add of annual software maintenance price increase | D11: =+'V-K-2'!G21 -> 87671
A12: =A11+1 -> 3 | B12: Sharyland Utilities, L.L.C.
A13: =A12+1 -> 4 | B13: Rate change and load change | C13: Restate 2024 with full year impact of NTS rate change and 4CP load change | D13: =+'V-K-2'!G24 -> -382282
A14: =A13+1 -> 5 | B14: Oncor Electric Delivery Co. NTU LLC
A15: =A14+1 -> 6 | B15: Rate change and load change | C15: Restate 2024 with full year impact of NTS rate change and 4CP load change | D15: =+'V-K-2'!G26 -> -3321511
A16: =A15+1 -> 7 | B16: Rate change and load change | C16: Restate 2024 with full year impact of NTS rate change and 4CP load change | D16: =+'V-K-2'!G27 -> -2691289.5
A17: =A16+1 -> 8 | B17: Oncor Receivables LLC
A18: =A17+1 -> 9 | B18: Financial consolidation | C18: Elimination of contributions for consolidated results | D18: =+'V-K-2'!G44 -> -6733012
A19: =A18+1 -> 10
A20: =A19+1 -> 11 | B20: Total | D20: =SUM(D10:D19) -> -13040424

Sheet V-K-7
B1: 2025 RATE CASE
B2: ONCOR ELECTRIC DELIVERY COMPANY LLC
B3: V-K-7 STATUTORY REQUIREMENTS
B4: FOR THE TEST YEAR ENDING DECEMBER 31, 2024
B5: SPONSOR: V. F. SNOW
B10: See Word File

Sheet V-K-8
B1: 2025 RATE CASE
B2: ONCOR ELECTRIC DELIVERY COMPANY LLC
B3: V-K-8 SERVICES PROVIDED TO AFFILIATES
B4: FOR THE TEST YEAR ENDING DECEMBER 31, 2024
B5: SPONSORS: V. F. SNOW & R. A. PRACHYL
B7: FERC | D7: Affiliate Company | F7: Amount
A8: Line No. | B8: Account | C8: FERC Account Description | D8: Receiving Service | E8: Description of Service | F8: Per Book
B9: (a) | C9: (b) | D9: (c) | E9: (d) | F9: (e)
A10: 1 | C10: Operations and Metering Services
A11: =A10+1 -> 2 | B11: 4569000 | C11: Other Revenue-Other | D11: Sharyland Utilities | E11: Operations services (monitoring, controlling, etc.) | F11: =170970+48850 -> 219820
A12: =A11+1 -> 3 | B12: 4569000 | C12: Other Revenue-Other | D12: Sharyland Utilities | E12: DC Tie operations | F12: 210948
A13: =A12+1 -> 4 | B13: 4569000 | C13: Other Revenue-Other | D13: Sharyland Utilities | E13: ERCOT-Polled Settlement (EPS) metering services | F13: 19134
A14: =A13+1 -> 5 | B14: 4569000 | C14: Other Revenue-Other | D14: Sharyland Utilities | E14: Wholesale metering service | F14: 631
A15: =A14+1 -> 6 | B15: 4569000 | C15: Other Revenue-Other | D15: Sharyland Utilities | E15: Corporate Support Service loading rate | F15: 163994
A16: =A15+1 -> 7 | B16: 4569000 | C16: Other Revenue-Other | D16: Sharyland Utilities | E16: Carrying costs | F16: 5109
A17: =A16+1 -> 8 | B17: 4549000 | C17: Rent-Elec Prop-Other | D17: Sharyland Utilities | E17: Total Cost of Ownership (TCO) | F17: =10479+44585 -> 55064
A18: =A17+1 -> 9 | B18: 2539000 | C18: Other Deferred Credit | D18: Sharyland Utilities | E18: Gross Margin Tax | F18: 3542
A19: =A18+1 -> 10 | B19: 2412700 | C19: State-Other-Accrual | D19: Sharyland Utilities | E19: Sales tax | F19: =8407+1304 -> 9711
A20: =A19+1 -> 11 | D20: Total Sharyland Utilities | F20: =SUM(F11:F19) -> 687953
A21: =A20+1 -> 12 | C21: Transmission System Operation, Maintenance and Metering Support and O & M Services
A22: =A21+1 -> 13 | B22: 4569000 | C22: Other Revenue-Other | D22: Oncor NTU | E22: Operations services (monitoring, controlling, etc.) | F22: =743999+386873 -> 1130872
A23: =A22+1 -> 14 | B23: 4569000 | C23: Other Revenue-Other | D23: Oncor NTU | E23: Wholesale metering service | F23: 6937
A24: =A23+1 -> 15 | B24: 4569000 | C24: Other Revenue-Other | D24: Oncor NTU | E24: Corporate Support Service loading rate | F24: 414163
A25: =A24+1 -> 16 | B25: 4549000 | C25: Rent-Elect Prop-Other | D25: Oncor NTU | E25: Total Cost of Ownership (TCO) | F25: =82998+353145 -> 436143
A26: =A25+1 -> 17 | B26: 4569000 | C26: Other Revenue-Other | D26: Oncor NTU | E26: Sales tax | F26: =16248+458 -> 16706
A27: =A26+1 -> 18 | B27: 4569000 | C27: Other Revenue-Other | D27: Oncor NTU | E27: Direct-billed O&M svcs (veg. mgmt., circuit maint. etc.) | F27: =6830300-G22 -> 6830300
A28: =A27+1 -> 19 | C28: Interest on Debt
A29: =A28+1 -> 20 | B29: 4190200 | C29: Interest Inc-Assoc Cos | D29: Oncor NTU | E29: Interest on long-term note payable | F29: 43042436
A30: =A29+1 -> 21 | C30: Capital Projects
A31: =A30+1 -> 22 | B31: 1010### | C31: Plant in Service (Various) | D31: Oncor NTU | E31: Capital projects (see Oncor RFP Schedule V-K-8.1) | F31: =+'V-K-8.1'!D35 -> 617230.29
A32: =A31+1 -> 23 | D32: Total Oncor NTU | F32: =SUM(F22:F31) -> 52494787
A33: =A32+1 -> 24 | C33: To, From & Over (TFO)
A34: =A33+1 -> 25 | B34: 4569000 | C34: Other Revenue-Other | D34: Sempra Gas & Power Mktg | E34: Whls trans svc provided under the TFO Tariff | F34: 32538
A35: =A34+1 -> 26 | C35: Transmission Service
A36: =A35+1 -> 27 | B36: 4569000 | C36: Other Revenue-Other | D36: Sempra Gas & Power Mktg | E36: Export svcs billed under the NTU Tariff for Trans Svc | F36: 4311
A37: =A36+1 -> 28 | D37: Total Sempra Gas & Power Marketing | F37: =+F34+F36 -> 36849
A38: =A37+1 -> 29 | C38: Miscellaneous Services
A39: =A38+1 -> 30 | B39: 1439000 | C39: Miscellaneous Receivables | D39: Cyrusone Inc | E39: Processing fees for easement encroachment | F39: 500
A40: =A39+1 -> 31 | D40: Total Cyrusone Inc | F40: =+F39 -> 500
A41: =A40+1 -> 32 | C41: AR Facility
...

Sheet V-K-8.1
B1: 2025 RATE CASE
B2: ONCOR ELECTRIC DELIVERY COMPANY LLC
B3: V-K-8.1 ONCOR NTU CAPITAL PROJECTS
B4: FOR THE TEST YEAR ENDING DECEMBER 31, 2024
B5: SPONSORS: V. F. SNOW & R. A. PRACHYL
D7: Total | E7: Closed to
A8: Line No. | B8: Project ID | C8: Project Title | D8: Capitalized | E8: Plant-in-Service
B9: (a) | C9: (b) | D9: (c) | E9: (d)
A10: 1 | B10: 0PT53772 | C10: Brown 138 - 12.5KV | D10: 12630.58 | E10: 45406
A11: =+A10+A10 -> 2 | B11: 0PT53000 | C11: NTUSU DeltaStar Mob XFMR MT35 | D11: 4112.93 | E11: 45407
A12: =+A11+1 -> 3 | B12: 0PT53002 | C12: NTUSU HK Porter XFMR MT36 | D12: 3996.22 | E12: 45407
A13: =+A12+1 -> 4 | B13: 0PT53260 | C13: Driver 138 - 25KV | D13: 17841.4 | E13: 45436
A14: =+A13+1 -> 5 | B14: 0PT55065 | C14: Windmill 345 kV | D14: 2009.99 | E14: 45444
A15: =+A14+1 -> 6 | B15: 0PT54368 | C15: Glass Ranch 138 - 25KV | D15: 12408.64 | E15: 45502
A16: =+A15+1 -> 7 | B16: 0PT55360 | C16: Windmill 345 kV | D16: 5584.91 | E16: 45509
A17: =+A16+1 -> 8 | B17: 0PT55495 | C17: Pecan Grove 138 - 25KV | D17: 9371.46 | E17: 45513
A18: =+A17+1 -> 9 | B18: 0PT54460 | C18: St. Lawrence 138 - 25KV | D18: 22962.97 | E18: 45540
A19: =+A18+1 -> 10 | B19: 0PT55206 | C19: Longdraw - Vealmoor 345 kV | D19: 23689.3 | E19: 45541
A20: =+A19+1 -> 11 | B20: 0PT55380 | C20: Farmland - Longdraw 345 kV | D20: 2807.82 | E20: 45568
A21: =+A20+1 -> 12 | B21: 0PT54216 | C21: AJ Swope 345 kV | D21: 57906.05 | E21: 45590
A22: =+A21+1 -> 13 | B22: 0PT56205 | C22: Windmill 345 kV | D22: 18549.66 | E22: 45590
A23: =+A22+1 -> 14 | B23: 0PT52861 | C23: Alibates Synchronous Condenser | D23: 76000.88 | E23: 45599
... A33: =+A32+1 -> 24 | B33: 0PT56861 | C33: Alibates 345 kV | D33: 18209.04 | E33: 45649
A34: =+A33+1 -> 25
A35: =+A34+1 -> 26 | C35: Total | D35: =SUM(D10:D34) -> 617230.29

Sheet V-K-9
B1: 2025 RATE CASE
B2: ONCOR ELECTRIC DELIVERY COMPANY LLC
B3: V-K-9 ALLOCATION OF AFFILIATE COSTS
B4: FOR THE TEST YEAR ENDING DECEMBER 31, 2024
B5: SPONSORS: V. F. SNOW & R. A. PRACHYL
B10: See Word File

Sheet V-K-10
B1: 2025 RATE CASE
B2: ONCOR ELECTRIC DELIVERY COMPANY LLC
B3: V-K-10 CONTROLS
B4: FOR THE TEST YEAR ENDING DECEMBER 31, 2024
B5: SPONSORS: V. F. SNOW & R. A. PRACHYL
B10: See Word File

Sheet V-K-11
B1: 2025 RATE CASE
B2: ONCOR ELECTRIC DELIVERY COMPANY LLC
B3: V-K-11 DESCRIPTION OF AFFILIATE BILLING METHODS
B4: FOR THE TEST YEAR ENDING DECEMBER 31, 2024
B5: SPONSOR: V. F. SNOW
D7: Billing Metric | E7: Billing
D8: Update | E8: Methodology
A9: Line No. | B9: Class of Items | C9: Billing Methodology | D9: Frequency | E9: Update Frequency
A10: 1 | B10: Tax Services - Consulting-Uncertain Tax Positions - Sempra | C10: Assignment of costs based on an evaluation of the time and effort spent by Sempra Tax personnel on behalf of Oncor. Time and effort spent is a reasonable approach for assigning costs to Oncor. | D10: Annually | E10: Annually
A11: =+A10+1 -> 2 | B11: Tax Services - Annual Tax Return Review - Sempra | C11: Assignment of costs based on an evaluation of the time and effort spent by Sempra Tax personnel on behalf of Oncor. Time and effort spent is a reasonable approach for assigning costs to Oncor. | D11: Annually | E11: Annually
A12: =A11+1 -> 3 | B12: Tax Services - Annual CorpTax Access - Sempra | C12: Assignment of costs based on the number of entities, users, and archival services specific to Oncor. This methodology is a reasonable approach for assigning costs to Oncor. | D12: Annually | E12: Annually
A13: =A12+1 -> 4 | B13: Human Resources Software Support - Ultimate Software Group Inc. | C13: Direct billing based on costs and fees contained in the negotiated contract and additional Statements of Work. | D13: Annually | E13: Annually
A14: =A13+1 -> 5 | B14: Data Storage and Back-up - Veritas Technologies LLC | C14: Direct billing based on costs and fees contained in the negotiated contract, contract addenda, and additional Statements of Work. | D14: Annually | E14: Annually
A15: =A14+1 -> 6 | B15: NTS Tariff - Sharyland Utilities, L.L.C. | C15: Monthly charges are based on an access charge multiplied by the customer's preceding calendar year average 4CP load. The access charge is, as approved, in the most recent revision of the Wholesale Transmission Service Tariff for Sharyland Utilities. | D15: Semi-annually | E15: Semi-annually
A16: =A15+1 -> 7 | B16: NTS Tariff - Oncor NTU | C16: Monthly charges are based on an access charge multiplied by the customer's preceding calendar year average 4CP load. The access charge is, as approved, in the most recent revision of the Wholesale Transmission Service Tariff for Oncor NTU. | D16: Semi-annually | E16: Semi-annually
A17: =A16+1 -> 8 | B17: WDSS Tariff - Oncor NTU | C17: The monthly bill for WDSS is the sum of the Transmission Service Customer Charge, Metering Charge, Demand Charge, and any applicable riders - all rates set in Oncor NTU's Wholesale Transmission Service Tariff. The billing kW used for determining the Demand Charge for a month is Oncor's highest measured 15-minute kW recorded at the Point of Interconnection in the 12-month period ended with the current month. | D17: Base Rate Case | E17: Base Rate Case
A18: =A17+1 -> 9 | B18: G&W Railroad Agreements | C18: Railroad power line crossings and right of entries through Occupancy License Agreements. | D18: As Needed | E18: As Needed
A19: =A18+1 -> 10 | B19: Load Management | C19: Lineage Logistics Holdings, LLC is a participant in Oncor’s Winter Emergency Load Management Energy Efficiency Program and Commercial Load Management Program, and received payments through those programs in accordance with the terms of its Texas Energy Efficiency Market Agreement. | D19: As Needed | E19: As Needed
A20: =A19+1 -> 11 | B20: Oncor Cares Foundation | C20: Oncor's Senior Leadership Team determines the level of contributions to be made to the Foundation for charitable purposes. The amounts contributed are discretionary and, therefore, independent of any other party making contributions to the Foundation. | D20: Annually | E20: Annually
A21: =A20+1 -> 12 | B21: Oncor Receivables LLC | C21: Oncor contributes to Oncor Receivables LLC the amounts equal to the principal amount of borrowings to be repaid under the AR Facility as well as amounts payable for interest and fees. | D21: Annually | E21: Annually

Sheet V-K-12
B1: 2025 RATE CASE
B2: ONCOR ELECTRIC DELIVERY COMPANY LLC
B3: V-K-12 AMOUNTS BILLED TO EACH AFFILIATE
B4: FOR THE TEST YEAR ENDING DECEMBER 31, 2024
B5: SPONSORS: V. F. SNOW & R. A. PRACHYL
F7: Oncor
D8: Oncor | E8: Oncor | F8: Transmission/
D9: Distribution | E9: Transmission | F9: Distribution | G9: Total
A10: Line No. | B10: Class of Items | C10: Sub-Class | D10: (ESD) | E10: (TRN) | F10: (TRNDS) | G10: Oncor
A11: 1 | B11: TAX SERVICES | C11: Consulting - Uncertain Tax Position | D11: =+'V-K-1'!F11 -> 30000 | G11: =SUM(D11:F11) -> 30000
A12: =A11+1 -> 2 | C12: Annual Tax Return Review | D12: =+'V-K-1'!F12 -> 48000 | G12: =SUM(D12:F12) -> 48000
A13: =A12+1 -> 3 | C13: Corptax Access | D13: =+'V-K-1'!F13 -> 30000 | G13: =SUM(D13:F13) -> 30000
A14: =A13+1 -> 4 | C14: Total Sempra | D14: =+D11+D12+D13 -> 108000 | E14: =+E11+E12+E13 -> 0 | F14: =+F11+F12+F13 -> 0 | G14: =+G11+G12+G13 -> 108000
A15: =A14+1 -> 5
A16: =A15+1 -> 6 | B16: SOFTWARE & DATA SUPPORT | C16: Ultimate Software Group | D16: =+'V-K-1'!F20 -> 1386652 | G16: =SUM(D16:F16) -> 1386652
A17: =A16+1 -> 7 | C17: Total Ultimate Software Group Inc | D17: =+D16 -> 1386652 | E17: =+E16 -> 0 | F17: =+F16 -> 0 | G17: =+G16 -> 1386652
A18: =A17+1 -> 8
A19: =A18+1 -> 9 | B19: SOFTWARE & DATA SUPPORT | C19: Veritas Technologies LLC | D19: =+'V-K-1'!F22 -> 216838 | G19: =+D19+E19+F19 -> 216838
A20: =A19+1 -> 10 | C20: Total Veritas Technologies LLC | D20: =+D19 -> 216838 | E20: =+E19 -> 0 | F20: =+F19 -> 0 | G20: =+G19 -> 216838
A21: =A20+1 -> 11
A22: =A21+1 -> 12 | B22: TARIFFED SERVICES | C22: Sharyland NTS | D22: =+'V-K-1'!F24 -> 16670575 | G22: =SUM(D22:F22) -> 16670575
A23: =A22+1 -> 13 | C23: Total Sharyland Utilities, L.L.C. | D23: =+D22 -> 16670575 | E23: =+E22 -> 0 | F23: =+F22 -> 0 | G23: =+G22 -> 16670575
A24: =A23+1 -> 14
A25: =A24+1 -> 15 | B25: TARIFFED SERVICES | C25: NTU NTS | D25: =+'V-K-1'!F26 -> 58040589 | G25: =SUM(D25:F25) -> 58040589
A26: =A25+1 -> 16 | C26: NTU WDSS | D26: =+'V-K-1'!F27 -> 15382470 | G26: =SUM(D26:F26) -> 15382470
A27: =A26+1 -> 17 | C27: Total Oncor NTU LLC | D27: =+D25+D26 -> 73423060 | E27: =+E25+E26 -> 0 | F27: =+F25+F26 -> 0 | G27: =+G25+G26 -> 73423060
A28: =A27+1 -> 18
A29: =A28+1 -> 19 | B29: G&W RAILROAD AGREEMENTS | C29: G&W Railroad | D29: =+'V-K-1'!F35-4750-1323+4250 -> 36834 | E29: =4750+1323-4250 -> 1823 | G29: =SUM(D29:F29) -> 38657
A30: =A29+1 -> 20 | C30: Total G&W Railroad | D30: =+D29 -> 36834 | E30: =+E29 -> 1823 | F30: =+F29 -> 0 | G30: =+G29 -> 38657
A31: =A30+1 -> 21
A32: =A31+1 -> 22 | B32: LOAD MANAGEMENT | C32: Lineage Logistics Holdings, LLC | D32: =+'V-K-1'!F38 -> 155503 | G32: =SUM(D32:F32) -> 155503
A33: =A32+1 -> 23 | C33: Total Lineage Logistics Holdings, LLC | D33: =+D32 -> 155503 | E33: =+E32 -> 0 | F33: =+F32 -> 0 | G33: =+G32 -> 155503
A34: =A33+1 -> 24
A35: =A34+1 -> 25 | B35: CONTRIBUTIONS | C35: Oncor Cares Foundation | D35: =+'V-K-1'!F42 -> 77227 | G35: =SUM(D35:F35) -> 77227
A36: =A35+1 -> 26 | C36: Total Oncor Cares Foundation | D36: =+D35 -> 77227 | E36: =+E35 -> 0 | F36: =+F35 -> 0 | G36: =+G35 -> 77227
A37: =A36+1 -> 27
A38: =A37+1 -> 28 | B38: A/R FACILITY | C38: Oncor Receivables LLC | D38: =+'V-K-1'!F45 -> 6733012 | G38: =SUM(D38:F38) -> 6733012
A39: =A38+1 -> 29 | C39: Total Oncor Receivables LLC | D39: =+D38 -> 6733012 | E39: 0 | F39: 0 | G39: =+G38 -> 6733012
A40: =A39+1 -> 30
A41: =A40+1 -> 31 | B41: TOTAL | D41: =+D14+D17+D20+D23+D27+D30+D36+D39+D33 -> 98807700 | E41: =+E14+E17+E20+E23+E27+E30+E36+E39+E33 -> 1823 | F41: =+F14+F17+F20+F23+F27+F30+F36+F39+F33 -> 0 | G41: =+G14+G17+G20+G23+G27+G30+G36+G39+G33 -> 98809524

Sheet V-K-13
A1: 2025 RATE CASE
A2: ONCOR ELECTRIC DELIVERY COMPANY LLC
A3: V-K-13 AFFILIATE PROJECT CODES CREATED/CLOSED
A4: FOR THE TEST YEAR ENDING DECEMBER 31, 2024
A5: SPONSORS: V. F. SNOW & R. A. PRACHYL
B7: Created/ | D7: Affiliate
A8: Project Title | B8: Closed | C8: Date | D8: Used For
A9: (a) | B9: (b) | C9: (c) | D9: (d)
A10: Tax Services - Consulting-Uncertain Tax Positions | B10: Created | C10: 43769 | D10: Sempra
A11: Tax Services - Annual Tax Return Review | B11: Created | C11: 43769 | D11: Sempra
A12: Tax Services - Annual CorpTax Access | B12: Created | C12: 43769 | D12: Sempra
A13: Software and Data Support | B13: Created | C13: 43591 | D13: Ultimate Kronos Group Inc
A14: Software and Data Support | B14: Created | C14: 42282 | D14: Veritas Technologies LLC
A15: Tariffed Services | B15: Created | C15: 43602 | D15: Sharyland Utilities, L.L.C.
A16: Tariffed Services | B16: Created | C16: 43602 | D16: Oncor NTU
A17: G&W Railroad Agreements | B17: Created | C17: 43603 | D17: G&W
A18: Load Management | B18: Created | C18: 44509 | D18: Lineage Logistics Holdings, LLC
A19: Contributions | B19: Created | C19: 43983 | D19: Oncor Cares Foundation
A20: A/R Facility | B20: Created | C20: 45044 | D20: Oncor Receivables LLC

Sheet V-K-14
B1: 2025 RATE CASE
B2: ONCOR ELECTRIC DELIVERY COMPANY LLC
B3: V-K-14 AFFILIATE PAYROLL
B4: FOR THE TEST YEAR ENDING DECEMBER 31, 2024
B5: SPONSORS: V. F. SNOW & R. A. PRACHYL
B7: Class of | D7: FERC | E7: FERC Account
A8: Line No. | B8: Items | C8: Sub-Class | D8: Account | E8: Description | F8: Amount
A10: 1 | B10: Tax Services | C10: Consulting-Uncertain tax positions
A11: =+A10+1 -> 2 | C11: Annual Tax Return Review
A12: =+A11+1 -> 3 | C12: Annual Corptax Access | D12: 9200000 | E12: Administrative & Gen Salaries | F12: 78000
A13: =+A12+1 -> 4
A14: =+A13+1 -> 5 | B14: Total Affiliate Payroll Expenses | F14: =+F12 -> 78000
B18: Note: Software & Data Support, G&W Railroad Agreements, Load Management and Tariffed Services are billed to Oncor in compliance with arm’s-length negotiated contracts or Commission approved tariffs. The amounts billed to Oncor through these contracts and tariffs are based on a compilation of all expenses required to provide these services. The individual component costs for these services, including payroll, are not separately identifiable to Oncor. There are no payroll costs in those amounts contributed to Oncor Cares Foundation and Oncor Receivables.
