Workbook
Name HOURLY: [1]HOURLY!$A$1:$G$745
Name OLE_LINK2: 'PRMGT10KWD Seasonal Weights'!$B$25
Name OLE_LINK2: 'Res Seasonal Weights'!$B$25
Name OLE_LINK2: 'SECGT10KW Seasonal Weights'!$B$25
Name OLE_LINK2: 'SECTE10KW Seasonal Weights'!$B$25
Name OLE_LINK2: 'Substation Seasonal Weights'!$B$25
Name rngBilled: OFFSET([2]Sheet2!$A$2,0,0,[2]Sheet2!$B$1,9)
Name rngYear: OFFSET('[3]Daily Actual_August'!$A$2,0,0,'[3]Daily Actual_August'!$C$1,8)

Sheet RES
B1: PUC DOCKET NO.
B2: ONCOR ELECTRIC DELIVERY COMPANY LLC
B3: ADJUSTED WEATHER STATION DATA
B4: FOR THE TEST YEAR ENDING DECEMBER 31, 2021
B6: SPONSOR: D. E. NELSON
B8: RESIDENTIAL
B9: SYSTEM WEIGHTED BILLING CYCLE ADJUSTED
A10: Line | C10: (a) | D10: (b) | E10: (c) | F10: (d)
A11: No. | C11: Actual | E11: Normal
A12: 1 | C12: HDD | D12: CDD | E12: HDD | F12: CDD
A13: 2 | B13: 44197 | C13: 198.48036 | D13: 0.053063947 | E13: 222.1387 | F13: 1.8172962
A14: 3 | B14: 44228 | C14: 234.81781 | D14: 0.072720485 | E14: 221.20776 | F14: 1.346646
A15: 4 | B15: 44256 | C15: 311.73519 | D15: 3.3796202 | E15: 159.63419 | F15: 5.1496534
A16: 5 | B16: 44287 | C16: 25.418094 | D16: 15.688378 | E16: 54.518173 | F16: 22.956112
A17: 6 | B17: 44317 | C17: 15.068166 | D17: 41.607224 | E17: 12.330437 | F17: 76.128551
A18: 7 | B18: 44348 | C18: 1.1050971 | D18: 140.65521 | E18: 1.0484189 | F18: 214.74852
A19: 8 | B19: 44378 | C19: 0.000573952 | D19: 352.36394 | E19: 0.01068507 | F19: 383.15429
A20: 9 | B20: 44409 | C20: 0 | D20: 386.17883 | E20: 0.00028478566 | F20: 444.56857
A21: 10 | B21: 44440 | C21: 0 | D21: 385.15065 | E21: 0.040852734 | F21: 383.9392
A22: 11 | B22: 44470 | C22: 0.23066282 | D22: 218.24743 | E22: 2.2969845 | F22: 204.8806
A23: 12 | B23: 44501 | C23: 16.472715 | D23: 70.42355 | E23: 26.81967 | F23: 57.398906
A24: 13 | B24: 44531 | C24: 59.033664 | D24: 7.754457 | E24: 119.80532 | F24: 9.7282243
A25: 14 | B25: Annual | C25: =SUM(C13:C24) -> 862.36233 | D25: =SUM(D13:D24) -> 1621.5751 | E25: =SUM(E13:E24) -> 819.85148 | F25: =SUM(F13:F24) -> 1805.8166

Sheet SECLE10KW
B1: =+RES!B1 -> PUC DOCKET NO.
B2: =+RES!B2 -> ONCOR ELECTRIC DELIVERY COMPANY LLC
B3: =+RES!B3 -> ADJUSTED WEATHER STATION DATA
B4: =+RES!B4 -> FOR THE TEST YEAR ENDING DECEMBER 31, 2021
B6: =+RES!B6 -> SPONSOR: D. E. NELSON
B8: SECONDARY SERVICE LESS THAN OR EQUAL TO 10 KW
B9: SYSTEM WEIGHTED BILLING CYCLE ADJUSTED
A10: Line | C10: (a) | D10: (b) | E10: (c) | F10: (d)
A11: No. | C11: Actual | E11: Normal
A12: 1 | C12: HDD | D12: CDD | E12: HDD | F12: CDD
A13: 2 | B13: =+RES!B13 -> 44197 | C13: 227.60778 | D13: 0.030233678 | E13: 249.97401 | F13: 1.1572295
A14: 3 | B14: =+RES!B14 -> 44228 | C14: 260.63814 | D14: 0.048966797 | E14: 247.18635 | F14: 0.85820086
A15: 4 | B15: =+RES!B15 -> 44256 | C15: 335.05091 | D15: 2.2314074 | E15: 176.7001 | F15: 3.3974681
A16: 5 | B16: =+RES!B16 -> 44287 | C16: 27.542777 | D16: 10.407034 | E16: 59.318213 | F16: 16.036376
A17: 6 | B17: =+RES!B17 -> 44317 | C17: 17.076908 | D17: 29.707023 | E17: 12.705528 | F17: 55.888986
A18: 7 | B18: =+RES!B18 -> 44348 | C18: 0.76411786 | D18: 104.49326 | E18: 0.93800258 | F18: 162.59546
A19: 8 | B19: =+RES!B19 -> 44378 | C19: 0 | D19: 264.9267 | E19: 0.0056579716 | F19: 295.55719
A20: 9 | B20: =+RES!B20 -> 44409 | C20: 0 | D20: 291.07938 | E20: 0 | F20: 347.2864
A21: 10 | B21: =+RES!B21 -> 44440 | C21: 0 | D21: 290.82404 | E21: 0.053763679 | F21: 295.00143
A22: 11 | B22: =+RES!B22 -> 44470 | C22: 0.14014841 | D22: 160.55565 | E22: 2.3127376 | F22: 150.60567
A23: 12 | B23: =+RES!B23 -> 44501 | C23: 17.173434 | D23: 49.788205 | E23: 29.299255 | F23: 40.273432
A24: 13 | B24: =+RES!B24 -> 44531 | C24: 64.302669 | D24: 5.0759949 | E24: 134.72215 | F24: 6.3991376
A25: 14 | B25: Annual | C25: =SUM(C13:C24) -> 950.29688 | D25: =SUM(D13:D24) -> 1209.1679 | E25: =SUM(E13:E24) -> 913.21576 | F25: =SUM(F13:F24) -> 1375.057

Sheet SECGT10KW
B1: =+RES!B1 -> PUC DOCKET NO.
B2: =+RES!B2 -> ONCOR ELECTRIC DELIVERY COMPANY LLC
B3: =+RES!B3 -> ADJUSTED WEATHER STATION DATA
B4: =+RES!B4 -> FOR THE TEST YEAR ENDING DECEMBER 31, 2021
B6: =+RES!B6 -> SPONSOR: D. E. NELSON
B8: SECONDARY SERVICE GREATER THAN 10 KW
B9: SYSTEM WEIGHTED BILLING CYCLE ADJUSTED
A10: Line | C10: (a) | D10: (b) | E10: (c) | F10: (d)
A11: No. | C11: Actual | E11: Normal
A12: 1 | C12: HDD | D12: CDD | E12: HDD | F12: CDD
A13: 2 | B13: =+RES!B13 -> 44197 | C13: 134.51539 | D13: 0.6271704 | E13: 162.21444 | F13: 6.1106059
A14: 3 | B14: =+RES!B14 -> 44228 | C14: 171.54456 | D14: 0.92251588 | E14: 164.21034 | F14: 4.9269095
A15: 4 | B15: =+RES!B15 -> 44256 | C15: 264.56696 | D15: 10.113474 | E15: 112.33559 | F15: 15.108543
A16: 5 | B16: =+RES!B16 -> 44287 | C16: 6.917914 | D16: 41.906624 | E16: 30.226601 | F16: 50.859093
A17: 6 | B17: =+RES!B17 -> 44317 | C17: 3.5402955 | D17: 83.825441 | E17: 4.6883675 | F17: 131.16836
A18: 7 | B18: =+RES!B18 -> 44348 | C18: 0.0073839905 | D18: 215.24178 | E18: 0.19474972 | F18: 298.31217
A19: 8 | B19: =+RES!B19 -> 44378 | C19: 0 | D19: 453.60494 | E19: 0.00027694168 | F19: 483.81602
A20: 9 | B20: =+RES!B20 -> 44409 | C20: 0 | D20: 485.78196 | E20: 0 | F20: 542.70056
A21: 10 | B21: =+RES!B21 -> 44440 | C21: 0 | D21: 482.78489 | E21: 0.01116731 | F21: 478.81686
A22: 11 | B22: =+RES!B22 -> 44470 | C22: 0.0014767981 | D22: 304.8849 | E22: 0.6810983 | F22: 283.02325
A23: 12 | B23: =+RES!B23 -> 44501 | C23: 5.8355129 | D23: 119.77918 | E23: 12.540238 | F23: 98.325128
A24: 13 | B24: =+RES!B24 -> 44531 | C24: 23.978954 | D24: 23.960054 | E24: 77.271534 | F24: 23.726328
A25: 14 | B25: Annual | C25: =SUM(C13:C24) -> 610.90844 | D25: =SUM(D13:D24) -> 2223.4329 | E25: =SUM(E13:E24) -> 564.37441 | F25: =SUM(F13:F24) -> 2416.8938

Sheet PRMGT10KWD
B1: =+RES!B1 -> PUC DOCKET NO.
B2: =+RES!B2 -> ONCOR ELECTRIC DELIVERY COMPANY LLC
B3: =+RES!B3 -> ADJUSTED WEATHER STATION DATA
B4: =+RES!B4 -> FOR THE TEST YEAR ENDING DECEMBER 31, 2021
B6: =+RES!B6 -> SPONSOR: D. E. NELSON
B8: PRIMARY SERVICE GREATER THAN 10 KW
B9: SYSTEM WEIGHTED BILLING CYCLE ADJUSTED
A10: Line | C10: (a) | D10: (b) | E10: (c) | F10: (d)
A11: No. | C11: Actual | E11: Normal
A12: 1 | C12: HDD | D12: CDD | E12: HDD | F12: CDD
A13: 2 | B13: =+RES!B13 -> 44197 | C13: 0 | D13: 6.5122245 | E13: 0 | F13: 13.627014
A14: 3 | B14: =+RES!B14 -> 44228 | C14: 0 | D14: 6.8640992 | E14: 0 | F14: 12.41712
A15: 4 | B15: =+RES!B15 -> 44256 | C15: 0 | D15: 25.659032 | E15: 0 | F15: 36.04058
A16: 5 | B16: =+RES!B16 -> 44287 | C16: 0 | D16: 87.5291 | E16: 0 | F16: 103.37533
A17: 6 | B17: =+RES!B17 -> 44317 | C17: 0 | D17: 154.03262 | E17: 0 | F17: 223.89384
A18: 7 | B18: =+RES!B18 -> 44348 | C18: 0 | D18: 323.06793 | E18: 0 | F18: 416.32365
A19: 8 | B19: =+RES!B19 -> 44378 | C19: 0 | D19: 539.6715 | E19: 0 | F19: 599.49521
A20: 9 | B20: =+RES!B20 -> 44409 | C20: 0 | D20: 544.17115 | E20: 0 | F20: 631.84016
A21: 10 | B21: =+RES!B21 -> 44440 | C21: 0 | D21: 548.05561 | E21: 0 | F21: 556.22387
A22: 11 | B22: =+RES!B22 -> 44470 | C22: 0 | D22: 386.99919 | E22: 0 | F22: 354.87605
A23: 12 | B23: =+RES!B23 -> 44501 | C23: 0 | D23: 181.66234 | E23: 0 | F23: 151.58817
A24: 13 | B24: =+RES!B24 -> 44531 | C24: 0 | D24: 53.942642 | E24: 0 | F24: 46.60844
A25: 14 | B25: Annual | C25: =SUM(C13:C24) -> 0 | D25: =SUM(D13:D24) -> 2858.1674 | E25: =SUM(E13:E24) -> 0 | F25: =SUM(F13:F24) -> 3146.3094

Sheet SUBSTATION
B1: =+RES!B1 -> PUC DOCKET NO.
B2: =+RES!B2 -> ONCOR ELECTRIC DELIVERY COMPANY LLC
B3: =+RES!B3 -> ADJUSTED WEATHER STATION DATA
B4: =+RES!B4 -> FOR THE TEST YEAR ENDING DECEMBER 31, 2021
B6: =+RES!B6 -> SPONSOR: D. E. NELSON
B8: SUBSTATION
B9: SYSTEM WEIGHTED BILLING CYCLE ADJUSTED
A10: Line | C10: (a) | D10: (b) | E10: (c) | F10: (d)
A11: No. | C11: Actual | E11: Normal
A12: 1 | C12: HDD | D12: CDD | E12: HDD | F12: CDD
A13: 2 | B13: =+RES!B13 -> 44197 | C13: 0 | D13: 94.536927 | E13: 0 | F13: 145.63196
A14: 3 | B14: =+RES!B14 -> 44228 | C14: 0 | D14: 99.827905 | E14: 0 | F14: 137.45867
A15: 4 | B15: =+RES!B15 -> 44256 | C15: 0 | D15: 252.48839 | E15: 0 | F15: 325.10782
A16: 5 | B16: =+RES!B16 -> 44287 | C16: 0 | D16: 689.61252 | E16: 0 | F16: 765.98734
A17: 6 | B17: =+RES!B17 -> 44317 | C17: 0 | D17: 1056.0721 | E17: 0 | F17: 1450.9738
A18: 7 | B18: =+RES!B18 -> 44348 | C18: 0 | D18: 1964.4827 | E18: 0 | F18: 2443.7062
A19: 8 | B19: =+RES!B19 -> 44378 | C19: 0 | D19: 3047.9861 | E19: 0 | F19: 3324.5036
A20: 9 | B20: =+RES!B20 -> 44409 | C20: 0 | D20: 3026.7058 | E20: 0 | F20: 3385.8608
A21: 10 | B21: =+RES!B21 -> 44440 | C21: 0 | D21: 3069.8193 | E21: 0 | F21: 3040.771
A22: 11 | B22: =+RES!B22 -> 44470 | C22: 0 | D22: 2261.9473 | E22: 0 | F22: 2078.7577
A23: 12 | B23: =+RES!B23 -> 44501 | C23: 0 | D23: 1184.539 | E23: 0 | F23: 1015.6095
A24: 13 | B24: =+RES!B24 -> 44531 | C24: 0 | D24: 492.34084 | E24: 0 | F24: 394.99947
A25: 14 | B25: Annual | C25: =SUM(C13:C24) -> 0 | D25: =SUM(D13:D24) -> 17240.359 | E25: =SUM(E13:E24) -> 0 | F25: =SUM(F13:F24) -> 18509.368

Sheet COOLING Weighting
B1: =+RES!B1 -> PUC DOCKET NO.
B2: =+RES!B2 -> ONCOR ELECTRIC DELIVERY COMPANY LLC
B3: =+RES!B3 -> ADJUSTED WEATHER STATION DATA
B4: =+RES!B4 -> FOR THE TEST YEAR ENDING DECEMBER 31, 2021
B6: =+RES!B6 -> SPONSOR: D. E. NELSON
B8: RESIDENTIAL CLASS WEIGHTING FOR DAILY COOLING DEGREE DAYS FOR JULY 20, 2020
A9: Line
A10: No.
A11: 1 | B11: Cooling Degree Days by Station (a)
A12: =+A11+1 -> 2 | B12: Date | C12: CDD | D12: {=TRANSPOSE('[4]July 20 20 bySite'!$B$11:$B$20)} -> Abilene | E12: Austin | F12: Dallas-Ft. Worth | G12: Kileen-Temple | H12: Longview | I12: Lufkin | J12: Midland-Odessa | K12: Sherman-Denison | L12: Waco | M12: Wichita Falls
A13: =+A12+1 -> 3 | B13: 44032 | C13: Base65 | D13: {=TRANSPOSE('[4]July 20 20 bySite'!$Q$24:$Q$33)} -> 20.8 | E13: 20.1 | F13: 21.7 | G13: 21.2 | H13: 16.3 | I13: 15.4 | J13: 19.9 | K13: 21.2 | L13: 21 | M13: 20.3 | O13: a1
A14: =+A13+1 -> 4 | B14: =+B13 -> 44032 | C14: Base70 | D14: {=TRANSPOSE('[4]July 20 20 bySite'!$R$24:$R$33)} -> 15.8 | E14: 15.1 | F14: 16.7 | G14: 16.2 | H14: 11.3 | I14: 10.4 | J14: 14.9 | K14: 16.2 | L14: 16 | M14: 15.3 | O14: a2
A15: =+A14+1 -> 5 | B15: =+B14 -> 44032 | C15: Base75 | D15: {=TRANSPOSE('[4]July 20 20 bySite'!$S$24:$S$33)} -> 10.8 | E15: 10.1 | F15: 11.7 | G15: 11.2 | H15: 6.3 | I15: 5.4 | J15: 9.9 | K15: 11.2 | L15: 11 | M15: 10.3 | O15: a3
A16: =+A15+1 -> 6 | B16: =+B14 -> 44032 | C16: Base80 | D16: {=TRANSPOSE('[4]July 20 20 bySite'!$T$24:$T$33)} -> 5.8 | E16: 5.1 | F16: 6.7 | G16: 6.2 | H16: 1.3 | I16: 0.4 | J16: 4.9 | K16: 6.2 | L16: 6 | M16: 5.3 | O16: a4
A17: =+A16+1 -> 7
A18: =+A17+1 -> 8 | B18: Weather Weights by Station (b)
A19: =+A18+1 -> 9 | C19: CDD | D19: =+'Res Seasonal Weights'!F30 -> 0.012 | E19: =+'Res Seasonal Weights'!F36 -> 0.044 | F19: =+'Res Seasonal Weights'!F27 -> 0.705 | G19: =+'Res Seasonal Weights'!F32 -> 0.045 | H19: =+'Res Seasonal Weights'!F35 -> 0.035 | I19: =+'Res Seasonal Weights'!F29 -> 0.026 | J19: =+'Res Seasonal Weights'!F28 -> 0.056 | K19: =+'Res Seasonal Weights'!F31 -> 0.023 | L19: =+'Res Seasonal Weights'!F33 -> 0.036 | M19: =+'Res Seasonal Weights'!F34 -> 0.019 | O19: b
A22: =+A19+1 -> 10 | B22: Residential Cooling Degree Days Contribution by Station (c = a*b)
A23: =+A22+1 -> 11
A24: =+A23+1 -> 12 | B24: Date | C24: CDD | D24: {=TRANSPOSE('[4]July 20 20 bySite'!$B$11:$B$20)} -> Abilene | E24: Austin | F24: Dallas-Ft. Worth | G24: Kileen-Temple | H24: Longview | I24: Lufkin | J24: Midland-Odessa | K24: Sherman-Denison | L24: Waco | M24: Wichita Falls | N24: Residential Class
A25: =+A24+1 -> 13 | B25: =+B13 -> 44032 | C25: =+C13 -> Base65 | D25: =+D13*D$19 -> 0.2496 | E25: =+E13*E$19 -> 0.8844 | F25: =+F13*F$19 -> 15.2985 | G25: =+G13*G$19 -> 0.954 | H25: =+H13*H$19 -> 0.5705 | I25: =+I13*I$19 -> 0.4004 | J25: =+J13*J$19 -> 1.1144 | K25: =+K13*K$19 -> 0.4876 | ... M25: =+M13*M$19 -> 0.3857 | N25: =SUM(D25:M25) -> 21.1011 | O25: c1 = a1*b
A26: =+A25+1 -> 14 | B26: =+B14 -> 44032 | C26: =+C14 -> Base70 | D26: =+D14*D$19 -> 0.1896 | E26: =+E14*E$19 -> 0.6644 | F26: =+F14*F$19 -> 11.7735 | G26: =+G14*G$19 -> 0.729 | H26: =+H14*H$19 -> 0.3955 | I26: =+I14*I$19 -> 0.2704 | J26: =+J14*J$19 -> 0.8344 | K26: =+K14*K$19 -> 0.3726 | ... M26: =+M14*M$19 -> 0.2907 | N26: =SUM(D26:M26) -> 16.0961 | O26: c2 = a2*b
A27: =+A26+1 -> 15 | B27: =+B15 -> 44032 | C27: =+C15 -> Base75 | D27: =+D15*D$19 -> 0.1296 | E27: =+E15*E$19 -> 0.4444 | F27: =+F15*F$19 -> 8.2485 | G27: =+G15*G$19 -> 0.504 | H27: =+H15*H$19 -> 0.2205 | I27: =+I15*I$19 -> 0.1404 | J27: =+J15*J$19 -> 0.5544 | K27: =+K15*K$19 -> 0.2576 | ... M27: =+M15*M$19 -> 0.1957 | N27: =SUM(D27:M27) -> 11.0911 | O27: c3 = a3*b
A28: =+A27+1 -> 16 | B28: =+B16 -> 44032 | C28: =+C16 -> Base80 | D28: =+D16*D$19 -> 0.0696 | E28: =+E16*E$19 -> 0.2244 | F28: =+F16*F$19 -> 4.7235 | G28: =+G16*G$19 -> 0.279 | H28: =+H16*H$19 -> 0.0455 | I28: =+I16*I$19 -> 0.0104 | J28: =+J16*J$19 -> 0.2744 | K28: =+K16*K$19 -> 0.1426 | ... M28: =+M16*M$19 -> 0.1007 | N28: =SUM(D28:M28) -> 6.0861 | O28: c4 = a4*b

Sheet COOLING Weighting (2)
B1: =+RES!B1 -> PUC DOCKET NO.
B2: =+RES!B2 -> ONCOR ELECTRIC DELIVERY COMPANY LLC
B3: =+RES!B3 -> ADJUSTED WEATHER STATION DATA
B4: =+RES!B4 -> FOR THE TEST YEAR ENDING DECEMBER 31, 2021
B6: =+RES!B6 -> SPONSOR: D. E. NELSON
B8: RESIDENTIAL CLASS WEIGHTING FOR DAILY COOLING DEGREE DAYS FOR JULY 14, 2021
A9: Line
A10: No.
A11: 1 | B11: Cooling Degree Days by Station (a)
A12: =+A11+1 -> 2 | B12: Date | C12: CDD | D12: {=TRANSPOSE('[4]July 14 21 bySite'!$B$11:$B$20)} -> Abilene | E12: Austin | F12: Dallas-Ft. Worth | G12: Kileen-Temple | H12: Longview | I12: Lufkin | J12: Midland-Odessa | K12: Sherman-Denison | L12: Waco | M12: Wichita Falls
A13: =+A12+1 -> 3 | B13: 44391 | C13: Base65 | D13: {=TRANSPOSE('[4]July 14 21 bySite'!$Q$24:$Q$33)} -> 15 | E13: 11.1 | F13: 16.2 | G13: 12.2 | H13: 13.7 | I13: 13.6 | J13: 12.3 | K13: 16.4 | L13: 13.8 | M13: 16.1 | O13: a1
A14: =+A13+1 -> 4 | B14: =+B13 -> 44391 | C14: Base70 | D14: {=TRANSPOSE('[4]July 14 21 bySite'!$R$24:$R$33)} -> 10 | E14: 6.1 | F14: 11.2 | G14: 7.2 | H14: 8.7 | I14: 8.6 | J14: 7.3 | K14: 11.4 | L14: 8.8 | M14: 11.1 | O14: a2
A15: =+A14+1 -> 5 | B15: =+B14 -> 44391 | C15: Base75 | D15: {=TRANSPOSE('[4]July 14 21 bySite'!$S$24:$S$33)} -> 5 | E15: 1.1 | F15: 6.2 | G15: 2.2 | H15: 3.7 | I15: 3.6 | J15: 2.3 | K15: 6.4 | L15: 3.8 | M15: 6.1 | O15: a3
A16: =+A15+1 -> 6 | B16: =+B14 -> 44391 | C16: Base80 | D16: {=TRANSPOSE('[4]July 14 21 bySite'!$T$24:$T$33)} -> 0 | E16: 0 | F16: 1.2 | G16: 0 | H16: 0 | I16: 0 | J16: 0 | K16: 1.4 | L16: 0 | M16: 1.1 | O16: a4
A17: =+A16+1 -> 7
A18: =+A17+1 -> 8 | B18: Weather Weights by Station (b)
A19: =+A18+1 -> 9 | C19: CDD | D19: =+'Res Seasonal Weights'!F30 -> 0.012 | E19: =+'Res Seasonal Weights'!F36 -> 0.044 | F19: =+'Res Seasonal Weights'!F27 -> 0.705 | G19: =+'Res Seasonal Weights'!F32 -> 0.045 | H19: =+'Res Seasonal Weights'!F35 -> 0.035 | I19: =+'Res Seasonal Weights'!F29 -> 0.026 | J19: =+'Res Seasonal Weights'!F28 -> 0.056 | K19: =+'Res Seasonal Weights'!F31 -> 0.023 | L19: =+'Res Seasonal Weights'!F33 -> 0.036 | M19: =+'Res Seasonal Weights'!F34 -> 0.019 | O19: b
A22: =+A19+1 -> 10 | B22: Residential Cooling Degree Days Contribution by Station (c = a*b)
A23: =+A22+1 -> 11
A24: =+A23+1 -> 12 | B24: Date | C24: CDD | D24: {=TRANSPOSE('[4]July 14 21 bySite'!$B$11:$B$20)} -> Abilene | E24: Austin | F24: Dallas-Ft. Worth | G24: Kileen-Temple | H24: Longview | I24: Lufkin | J24: Midland-Odessa | K24: Sherman-Denison | L24: Waco | M24: Wichita Falls | N24: Residential Class
A25: =+A24+1 -> 13 | B25: =+B13 -> 44391 | C25: =+C13 -> Base65 | D25: =+D13*D$19 -> 0.18 | E25: =+E13*E$19 -> 0.4884 | F25: =+F13*F$19 -> 11.421 | G25: =+G13*G$19 -> 0.549 | H25: =+H13*H$19 -> 0.4795 | I25: =+I13*I$19 -> 0.3536 | J25: =+J13*J$19 -> 0.6888 | K25: =+K13*K$19 -> 0.3772 | ... M25: =+M13*M$19 -> 0.3059 | N25: =SUM(D25:M25) -> 15.3402 | O25: c1 = a1*b
A26: =+A25+1 -> 14 | B26: =+B14 -> 44391 | C26: =+C14 -> Base70 | D26: =+D14*D$19 -> 0.12 | E26: =+E14*E$19 -> 0.2684 | F26: =+F14*F$19 -> 7.896 | G26: =+G14*G$19 -> 0.324 | H26: =+H14*H$19 -> 0.3045 | I26: =+I14*I$19 -> 0.2236 | J26: =+J14*J$19 -> 0.4088 | K26: =+K14*K$19 -> 0.2622 | ... M26: =+M14*M$19 -> 0.2109 | N26: =SUM(D26:M26) -> 10.3352 | O26: c2 = a2*b
A27: =+A26+1 -> 15 | B27: =+B15 -> 44391 | C27: =+C15 -> Base75 | D27: =+D15*D$19 -> 0.06 | E27: =+E15*E$19 -> 0.0484 | F27: =+F15*F$19 -> 4.371 | G27: =+G15*G$19 -> 0.099 | H27: =+H15*H$19 -> 0.1295 | I27: =+I15*I$19 -> 0.0936 | J27: =+J15*J$19 -> 0.1288 | K27: =+K15*K$19 -> 0.1472 | ... M27: =+M15*M$19 -> 0.1159 | N27: =SUM(D27:M27) -> 5.3302 | O27: c3 = a3*b
A28: =+A27+1 -> 16 | B28: =+B16 -> 44391 | C28: =+C16 -> Base80 | D28: =+D16*D$19 -> 0 | E28: =+E16*E$19 -> 0 | F28: =+F16*F$19 -> 0.846 | G28: =+G16*G$19 -> 0 | H28: =+H16*H$19 -> 0 | I28: =+I16*I$19 -> 0 | J28: =+J16*J$19 -> 0 | K28: =+K16*K$19 -> 0.0322 | ... M28: =+M16*M$19 -> 0.0209 | N28: =SUM(D28:M28) -> 0.8991 | O28: c4 = a4*b

Sheet HEATING Weighting
B1: =+RES!B1 -> PUC DOCKET NO.
B2: =+RES!B2 -> ONCOR ELECTRIC DELIVERY COMPANY LLC
B3: =+RES!B3 -> ADJUSTED WEATHER STATION DATA
B4: =+RES!B4 -> FOR THE TEST YEAR ENDING DECEMBER 31, 2021
B6: =+RES!B6 -> SPONSOR: D. E. NELSON
B8: RESIDENTIAL CLASS WEIGHTING FOR DAILY HEATING DEGREE DAYS FOR JANUARY 21, 2020
A9: Line
A10: No.
A11: 1 | B11: Heating Degree Days by Station (a)
A12: =+A11+1 -> 2 | B12: Date | C12: HDD | D12: {=TRANSPOSE('[4]January 21 20 bySite'!$B$11:$B$20)} -> Abilene | E12: Austin | F12: Dallas-Ft. Worth | G12: Kileen-Temple | H12: Longview | I12: Lufkin | J12: Midland-Odessa | K12: Sherman-Denison | L12: Waco | M12: Wichita Falls
A13: =+A12+1 -> 3 | B13: 43851 | C13: Base40 | D13: {=TRANSPOSE('[4]January 21 20 bySite'!$H$24:$H$33)} -> 0 | E13: 0 | F13: 0 | G13: 0 | H13: 1.2 | I13: 0 | J13: 0 | K13: 2 | L13: 0 | M13: 0 | O13: a1
A14: =+A13+1 -> 4 | B14: =+B13 -> 43851 | C14: Base45 | D14: {=TRANSPOSE('[4]January 21 20 bySite'!$I$24:$I$33)} -> 0 | E14: 0 | F14: 1.3 | G14: 0 | H14: 6.2 | I14: 3.5 | J14: 0 | K14: 7 | L14: 0 | M14: 4 | O14: a2
A15: =+A14+1 -> 5 | B15: =+B14 -> 43851 | C15: Base55 | D15: {=TRANSPOSE('[4]January 21 20 bySite'!$K$24:$K$33)} -> 6.9 | E15: 4.2 | F15: 11.3 | G15: 6.6 | H15: 16.2 | I15: 13.5 | J15: 9.2 | K15: 17 | L15: 9.7 | M15: 14 | O15: a3
A16: =+A14+1 -> 5 | B16: =+B14 -> 43851 | C16: Base60 | D16: {=TRANSPOSE('[4]January 21 20 bySite'!$L$24:$L$33)} -> 11.9 | E16: 9.2 | F16: 16.3 | G16: 11.6 | H16: 21.2 | I16: 18.5 | J16: 14.2 | K16: 22 | L16: 14.7 | M16: 19 | O16: a4
A17: =+A14+1 -> 5 | B17: =+B14 -> 43851 | C17: Base65 | D17: {=TRANSPOSE('[4]January 21 20 bySite'!$M$24:$M$33)} -> 16.9 | E17: 14.2 | F17: 21.3 | G17: 16.6 | H17: 26.2 | I17: 23.5 | J17: 19.2 | K17: 27 | L17: 19.7 | M17: 24 | O17: a5
A18: =+A17+1 -> 6
A19: =+A18+1 -> 7 | B19: Weather Weights (b)
A20: =+A19+1 -> 8 | C20: HDD | D20: =+'Res Seasonal Weights'!D30 -> 0.014 | E20: =+'Res Seasonal Weights'!D36 -> 0.036 | F20: =+'Res Seasonal Weights'!D27 -> 0.689 | G20: =+'Res Seasonal Weights'!D32 -> 0.051 | H20: =+'Res Seasonal Weights'!D35 -> 0.038 | I20: =+'Res Seasonal Weights'!D29 -> 0.029 | J20: =+'Res Seasonal Weights'!D28 -> 0.057 | K20: =+'Res Seasonal Weights'!D31 -> 0.027 | L20: =+'Res Seasonal Weights'!D33 -> 0.039 | M20: =+'Res Seasonal Weights'!D34 -> 0.02 | O20: b
A23: =+A20+1 -> 9 | B23: Residential Heating Degree Days Contribution by Station (c = a*b)
A24: =+A23+1 -> 10
A25: =+A24+1 -> 11 | B25: Date | C25: HDD | D25: {=TRANSPOSE('[4]January 21 20 bySite'!$B$11:$B$20)} -> Abilene | E25: Austin | F25: Dallas-Ft. Worth | G25: Kileen-Temple | H25: Longview | I25: Lufkin | J25: Midland-Odessa | K25: Sherman-Denison | L25: Waco | M25: Wichita Falls | N25: Residential Class
A26: =+A25+1 -> 12 | B26: =+B13 -> 43851 | C26: =+C13 -> Base40 | D26: =+D13*D$20 -> 0 | E26: =+E13*E$20 -> 0 | F26: =+F13*F$20 -> 0 | G26: =+G13*G$20 -> 0 | H26: =+H13*H$20 -> 0.0456 | I26: =+I13*I$20 -> 0 | J26: =+J13*J$20 -> 0 | K26: =+K13*K$20 -> 0.054 | ... M26: =+M13*M$20 -> 0 | N26: =SUM(D26:M26) -> 0.0996 | O26: c1 = a1*b
A27: =+A26+1 -> 13 | B27: =+B14 -> 43851 | C27: =+C14 -> Base45 | D27: =+D14*D$20 -> 0 | E27: =+E14*E$20 -> 0 | F27: =+F14*F$20 -> 0.8957 | G27: =+G14*G$20 -> 0 | H27: =+H14*H$20 -> 0.2356 | I27: =+I14*I$20 -> 0.1015 | J27: =+J14*J$20 -> 0 | K27: =+K14*K$20 -> 0.189 | ... M27: =+M14*M$20 -> 0.08 | N27: =SUM(D27:M27) -> 1.5018 | O27: c2 = a2*b
A28: =+A27+1 -> 14 | B28: =+B15 -> 43851 | C28: =+C15 -> Base55 | D28: =+D15*D$20 -> 0.0966 | E28: =+E15*E$20 -> 0.1512 | F28: =+F15*F$20 -> 7.7857 | G28: =+G15*G$20 -> 0.3366 | H28: =+H15*H$20 -> 0.6156 | I28: =+I15*I$20 -> 0.3915 | J28: =+J15*J$20 -> 0.5244 | K28: =+K15*K$20 -> 0.459 | ... M28: =+M15*M$20 -> 0.28 | N28: =SUM(D28:M28) -> 11.0189 | O28: c2 = a3*b
A29: =+A27+1 -> 14 | B29: =+B16 -> 43851 | C29: =+C16 -> Base60 | D29: =+D16*D$20 -> 0.1666 | E29: =+E16*E$20 -> 0.3312 | F29: =+F16*F$20 -> 11.2307 | G29: =+G16*G$20 -> 0.5916 | H29: =+H16*H$20 -> 0.8056 | I29: =+I16*I$20 -> 0.5365 | J29: =+J16*J$20 -> 0.8094 | K29: =+K16*K$20 -> 0.594 | ... M29: =+M16*M$20 -> 0.38 | N29: =SUM(D29:M29) -> 16.0189 | O29: c3 = a4*b
A30: =+A29+1 -> 15 | B30: =+B17 -> 43851 | C30: =+C17 -> Base65 | D30: =+D17*D$20 -> 0.2366 | E30: =+E17*E$20 -> 0.5112 | F30: =+F17*F$20 -> 14.6757 | G30: =+G17*G$20 -> 0.8466 | H30: =+H17*H$20 -> 0.9956 | I30: =+I17*I$20 -> 0.6815 | J30: =+J17*J$20 -> 1.0944 | K30: =+K17*K$20 -> 0.729 | ... M30: =+M17*M$20 -> 0.48 | N30: =SUM(D30:M30) -> 21.0189 | O30: c4 = a5*b

Sheet HEATING Weighting (2)
B1: =+RES!B1 -> PUC DOCKET NO.
B2: =+RES!B2 -> ONCOR ELECTRIC DELIVERY COMPANY LLC
B3: =+RES!B3 -> ADJUSTED WEATHER STATION DATA
B4: =+RES!B4 -> FOR THE TEST YEAR ENDING DECEMBER 31, 2021
B6: =+RES!B6 -> SPONSOR: D. E. NELSON
B8: RESIDENTIAL CLASS WEIGHTING FOR DAILY HEATING DEGREE DAYS FOR JANUARY 14, 2021
A9: Line
A10: No.
A11: 1 | B11: Heating Degree Days by Station (a)
A12: =+A11+1 -> 2 | B12: Date | C12: HDD | D12: {=TRANSPOSE('[4]January 14 21 bySite'!$B$11:$B$20)} -> Abilene | E12: Austin | F12: Dallas-Ft. Worth | G12: Kileen-Temple | H12: Longview | I12: Lufkin | J12: Midland-Odessa | K12: Sherman-Denison | L12: Waco | M12: Wichita Falls
A13: =+A12+1 -> 3 | B13: 44210 | C13: Base40 | D13: {=TRANSPOSE('[4]January 14 21 bySite'!$H$24:$H$33)} -> 0 | E13: 0 | F13: 0 | G13: 0 | H13: 0 | I13: 0 | J13: 0 | K13: 0 | L13: 0 | M13: 0 | O13: a1
A14: =+A13+1 -> 4 | B14: =+B13 -> 44210 | C14: Base45 | D14: {=TRANSPOSE('[4]January 14 21 bySite'!$I$24:$I$33)} -> 0 | E14: 0 | F14: 0 | G14: 0 | H14: 0 | I14: 0 | J14: 0 | K14: 0 | L14: 0 | M14: 0 | O14: a2
A15: =+A14+1 -> 5 | B15: =+B14 -> 44210 | C15: Base55 | D15: {=TRANSPOSE('[4]January 14 21 bySite'!$K$24:$K$33)} -> 6.9 | E15: 1.5 | F15: 4.9 | G15: 3.1 | H15: 4.9 | I15: 3.9 | J15: 9.2 | K15: 7.4 | L15: 3.9 | M15: 8.8 | O15: a3
A16: =+A14+1 -> 5 | B16: =+B14 -> 44210 | C16: Base60 | D16: {=TRANSPOSE('[4]January 14 21 bySite'!$L$24:$L$33)} -> 11.9 | E16: 6.5 | F16: 9.9 | G16: 8.1 | H16: 9.9 | I16: 8.9 | J16: 14.2 | K16: 12.4 | L16: 8.9 | M16: 13.8 | O16: a4
A17: =+A14+1 -> 5 | B17: =+B14 -> 44210 | C17: Base65 | D17: {=TRANSPOSE('[4]January 14 21 bySite'!$M$24:$M$33)} -> 16.9 | E17: 11.5 | F17: 14.9 | G17: 13.1 | H17: 14.9 | I17: 13.9 | J17: 19.2 | K17: 17.4 | L17: 13.9 | M17: 18.8 | O17: a5
A18: =+A17+1 -> 6
A19: =+A18+1 -> 7 | B19: Weather Weights (b)
A20: =+A19+1 -> 8 | C20: HDD | D20: =+'Res Seasonal Weights'!D30 -> 0.014 | E20: =+'Res Seasonal Weights'!D36 -> 0.036 | F20: =+'Res Seasonal Weights'!D27 -> 0.689 | G20: =+'Res Seasonal Weights'!D32 -> 0.051 | H20: =+'Res Seasonal Weights'!D35 -> 0.038 | I20: =+'Res Seasonal Weights'!D29 -> 0.029 | J20: =+'Res Seasonal Weights'!D28 -> 0.057 | K20: =+'Res Seasonal Weights'!D31 -> 0.027 | L20: =+'Res Seasonal Weights'!D33 -> 0.039 | M20: =+'Res Seasonal Weights'!D34 -> 0.02 | O20: b
A23: =+A20+1 -> 9 | B23: Residential Heating Degree Days Contribution by Station (c = a*b)
A24: =+A23+1 -> 10
A25: =+A24+1 -> 11 | B25: Date | C25: HDD | D25: {=TRANSPOSE('[4]January 14 21 bySite'!$B$11:$B$20)} -> Abilene | E25: Austin | F25: Dallas-Ft. Worth | G25: Kileen-Temple | H25: Longview | I25: Lufkin | J25: Midland-Odessa | K25: Sherman-Denison | L25: Waco | M25: Wichita Falls | N25: Residential Class
A26: =+A25+1 -> 12 | B26: =+B13 -> 44210 | C26: =+C13 -> Base40 | D26: =+D13*D$20 -> 0 | E26: =+E13*E$20 -> 0 | F26: =+F13*F$20 -> 0 | G26: =+G13*G$20 -> 0 | H26: =+H13*H$20 -> 0 | I26: =+I13*I$20 -> 0 | J26: =+J13*J$20 -> 0 | K26: =+K13*K$20 -> 0 | ... M26: =+M13*M$20 -> 0 | N26: =SUM(D26:M26) -> 0 | O26: c1 = a1*b
A27: =+A26+1 -> 13 | B27: =+B14 -> 44210 | C27: =+C14 -> Base45 | D27: =+D14*D$20 -> 0 | E27: =+E14*E$20 -> 0 | F27: =+F14*F$20 -> 0 | G27: =+G14*G$20 -> 0 | H27: =+H14*H$20 -> 0 | I27: =+I14*I$20 -> 0 | J27: =+J14*J$20 -> 0 | K27: =+K14*K$20 -> 0 | ... M27: =+M14*M$20 -> 0 | N27: =SUM(D27:M27) -> 0 | O27: c2 = a2*b
A28: =+A27+1 -> 14 | B28: =+B15 -> 44210 | C28: =+C15 -> Base55 | D28: =+D15*D$20 -> 0.0966 | E28: =+E15*E$20 -> 0.054 | F28: =+F15*F$20 -> 3.3761 | G28: =+G15*G$20 -> 0.1581 | H28: =+H15*H$20 -> 0.1862 | I28: =+I15*I$20 -> 0.1131 | J28: =+J15*J$20 -> 0.5244 | K28: =+K15*K$20 -> 0.1998 | ... M28: =+M15*M$20 -> 0.176 | N28: =SUM(D28:M28) -> 5.0364 | O28: c2 = a3*b
A29: =+A28+1 -> 15 | B29: =+B16 -> 44210 | C29: =+C16 -> Base60 | D29: =+D16*D$20 -> 0.1666 | E29: =+E16*E$20 -> 0.234 | F29: =+F16*F$20 -> 6.8211 | G29: =+G16*G$20 -> 0.4131 | H29: =+H16*H$20 -> 0.3762 | I29: =+I16*I$20 -> 0.2581 | J29: =+J16*J$20 -> 0.8094 | K29: =+K16*K$20 -> 0.3348 | ... M29: =+M16*M$20 -> 0.276 | N29: =SUM(D29:M29) -> 10.0364 | O29: c3 = a4*b
A30: =+A29+1 -> 16 | B30: =+B17 -> 44210 | C30: =+C17 -> Base65 | D30: =+D17*D$20 -> 0.2366 | E30: =+E17*E$20 -> 0.414 | F30: =+F17*F$20 -> 10.2661 | G30: =+G17*G$20 -> 0.6681 | H30: =+H17*H$20 -> 0.5662 | I30: =+I17*I$20 -> 0.4031 | J30: =+J17*J$20 -> 1.0944 | K30: =+K17*K$20 -> 0.4698 | ... M30: =+M17*M$20 -> 0.376 | N30: =SUM(D30:M30) -> 15.0364 | O30: c4 = a5*b

Sheet Simple Averages_0121
B1: =+RES!B1 -> PUC DOCKET NO.
B2: =+RES!B2 -> ONCOR ELECTRIC DELIVERY COMPANY LLC
B3: =+RES!B3 -> ADJUSTED WEATHER STATION DATA
B4: =+RES!B4 -> FOR THE TEST YEAR ENDING DECEMBER 31, 2021
B6: =+RES!B6 -> SPONSOR: D. E. NELSON
B8: RESIDENTIAL SIMPLE TWENTY YEAR AVERAGE CALCULATION FOR JANUARY 21ST
A9: Line No.
A10: 1 | B10: Year | C10: Month | D10: Day | E10: HDD40 | F10: HDD45 | G10: HDD55 | H10: HDD60 | I10: HDD65 | J10: CDD65 | K10: CDD70 | L10: CDD75 | M10: CDD80
A11: =+A10+1 -> 2 | B11: 2001 | C11: 1 | D11: 21 | E11: 1.505875 | F11: 6.41525 | G11: 16.41525 | H11: 21.41525 | I11: 26.41525 | J11: 0 | K11: 0 | L11: 0 | M11: 0
A12: =+A11+1 -> 3 | B12: =+B11+1 -> 2002 | C12: =+C11 -> 1 | D12: =+D11 -> 21 | E12: 0 | F12: 0 | G12: 6.3614583 | H12: 11.361458 | I12: 16.361458 | J12: 0 | K12: 0 | L12: 0 | M12: 0
A13: =+A12+1 -> 4 | B13: =+B12+1 -> 2003 | C13: =+C12 -> 1 | D13: =+D12 -> 21 | E13: 0 | F13: 0.084166667 | G13: 3.0657083 | H13: 6.9415833 | I13: 11.387375 | J13: 0.06825 | K13: 0 | L13: 0 | M13: 0
A14: =+A13+1 -> 5 | B14: =+B13+1 -> 2004 | C14: =+C13 -> 1 | D14: =+D13 -> 21 | E14: 0.22341667 | F14: 3.1399583 | G14: 12.995958 | H14: 17.995958 | I14: 22.995958 | J14: 0 | K14: 0 | L14: 0 | M14: 0
A15: =+A14+1 -> 6 | B15: =+B14+1 -> 2005 | C15: =+C14 -> 1 | D15: =+D14 -> 21 | E15: 0 | F15: 0 | G15: 0.28025 | H15: 1.131875 | I15: 6.1016667 | J15: 0 | K15: 0 | L15: 0 | M15: 0
A16: =+A15+1 -> 7 | B16: =+B15+1 -> 2006 | C16: =+C15 -> 1 | D16: =+D15 -> 21 | E16: 0 | F16: 0.404125 | G16: 7.980625 | H16: 12.980625 | I16: 17.980625 | J16: 0 | K16: 0 | L16: 0 | M16: 0
A17: =+A16+1 -> 8 | B17: =+B16+1 -> 2007 | C17: =+C16 -> 1 | D17: =+D16 -> 21 | E17: 0.011666667 | F17: 0.70029167 | G17: 10.395875 | H17: 15.395875 | I17: 20.395875 | J17: 0 | K17: 0 | L17: 0 | M17: 0
A18: =+A17+1 -> 9 | B18: =+B17+1 -> 2008 | C18: =+C17 -> 1 | D18: =+D17 -> 21 | E18: 0.1899 | F18: 2.3236 | G18: 11.9301 | H18: 16.9301 | I18: 21.9301 | J18: 0 | K18: 0 | L18: 0 | M18: 0
A19: =+A18+1 -> 10 | B19: =+B18+1 -> 2009 | C19: =+C18 -> 1 | D19: =+D18 -> 21 | E19: 0 | F19: 0.172 | G19: 5.0641 | H19: 10.0641 | I19: 15.0641 | J19: 0 | K19: 0 | L19: 0 | M19: 0
A20: =+A19+1 -> 11 | B20: =+B19+1 -> 2010 | C20: =+C19 -> 1 | D20: =+D19 -> 21 | E20: 0 | F20: 0 | G20: 0.3726 | H20: 3.1908 | I20: 8.1319 | J20: 0 | K20: 0 | L20: 0 | M20: 0
A21: =+A20+1 -> 12 | B21: =+B20+1 -> 2011 | C21: =+C20 -> 1 | D21: =+D20 -> 21 | E21: 7.7109 | F21: 12.7109 | G21: 22.7109 | H21: 27.7109 | I21: 32.7109 | J21: 0 | K21: 0 | L21: 0 | M21: 0
A22: =+A21+1 -> 13 | B22: =+B21+1 -> 2012 | C22: =+C21 -> 1 | D22: =+D21 -> 21 | E22: 0.1422 | F22: 1.5286 | G22: 10.2179 | H22: 15.0729 | I22: 20.0584 | J22: 0 | K22: 0 | L22: 0 | M22: 0
A23: =+A22+1 -> 14 | B23: =+B22+1 -> 2013 | C23: =+C22 -> 1 | D23: =+D22 -> 21 | E23: 0.0839 | F23: 0.6415 | G23: 8.5184 | H23: 13.501 | I23: 18.501 | J23: 0 | K23: 0 | L23: 0 | M23: 0
... A30: =+A29+1 -> 21 | B30: =+B29+1 -> 2020 | C30: =+C29 -> 1 | D30: =+D29 -> 21 | E30: 0.0996 | F30: 1.5018 | G30: 11.0189 | H30: 16.0189 | I30: 21.0189 | J30: 0 | K30: 0 | L30: 0 | M30: 0
A31: =+A30+1 -> 22 | B31: 1/21 | E31: =AVERAGE(E11:E30) -> 0.50562792 | F31: =AVERAGE(F11:F30) -> 1.5805746 | G31: =AVERAGE(G11:G30) -> 8.0570712 | H31: =AVERAGE(H11:H30) -> 12.282746 | I31: =AVERAGE(I11:I30) -> 17.01764 | J31: =AVERAGE(J11:J30) -> 0.1015525 | K31: =AVERAGE(K11:K30) -> 0 | L31: =AVERAGE(L11:L30) -> 0 | M31: =AVERAGE(M11:M30) -> 0

Sheet Simple Averages_0720
B1: =+RES!B1 -> PUC DOCKET NO.
B2: =+RES!B2 -> ONCOR ELECTRIC DELIVERY COMPANY LLC
B3: =+RES!B3 -> ADJUSTED WEATHER STATION DATA
B4: =+RES!B4 -> FOR THE TEST YEAR ENDING DECEMBER 31, 2021
B6: =+RES!B6 -> SPONSOR: D. E. NELSON
B8: RESIDENTIAL SIMPLE TWENTY YEAR AVERAGE CALCULATION FOR JULY 20TH
A9: Line No.
A10: 1 | B10: Year | C10: Month | D10: Day | E10: HDD40 | F10: HDD45 | G10: HDD55 | H10: HDD60 | I10: HDD65 | J10: CDD65 | K10: CDD70 | L10: CDD75 | M10: CDD80
A11: =+A10+1 -> 2 | B11: 2001 | C11: 7 | D11: 20 | E11: 0 | F11: 0 | G11: 0 | H11: 0 | I11: 0 | J11: 22.284708 | K11: 17.279708 | L11: 12.274708 | M11: 7.2697083
A12: =+A11+1 -> 3 | B12: =+B11+1 -> 2002 | C12: =+C11 -> 7 | D12: =+D11 -> 20 | E12: 0 | F12: 0 | G12: 0 | H12: 0 | I12: 0 | J12: 18.917958 | K12: 13.912958 | L12: 8.9079583 | M12: 3.9029583
A13: =+A12+1 -> 4 | B13: =+B12+1 -> 2003 | C13: =+C12 -> 7 | D13: =+D12 -> 20 | E13: 0 | F13: 0 | G13: 0 | H13: 0 | I13: 0 | J13: 23.660208 | K13: 18.655208 | L13: 13.650208 | M13: 8.6452083
A14: =+A13+1 -> 5 | B14: =+B13+1 -> 2004 | C14: =+C13 -> 7 | D14: =+D13 -> 20 | E14: 0 | F14: 0 | G14: 0 | H14: 0 | I14: 0 | J14: 18.968917 | K14: 13.963917 | L14: 8.9589167 | M14: 4.0101667
A15: =+A14+1 -> 6 | B15: =+B14+1 -> 2005 | C15: =+C14 -> 7 | D15: =+D14 -> 20 | E15: 0 | F15: 0 | G15: 0 | H15: 0 | I15: 0 | J15: 19.848167 | K15: 14.843167 | L15: 9.8381667 | M15: 4.8669167
A16: =+A15+1 -> 7 | B16: =+B15+1 -> 2006 | C16: =+C15 -> 7 | D16: =+D15 -> 20 | E16: 0 | F16: 0 | G16: 0 | H16: 0 | I16: 0 | J16: 25.741792 | K16: 20.736792 | L16: 15.731792 | M16: 10.726792
A17: =+A16+1 -> 8 | B17: =+B16+1 -> 2007 | C17: =+C16 -> 7 | D17: =+D16 -> 20 | E17: 0 | F17: 0 | G17: 0 | H17: 0 | I17: 0 | J17: 14.491375 | K17: 9.486375 | L17: 4.5492083 | M17: 0.53104167
A18: =+A17+1 -> 9 | B18: =+B17+1 -> 2008 | C18: =+C17 -> 7 | D18: =+D17 -> 20 | E18: 0 | F18: 0 | G18: 0 | H18: 0 | I18: 0 | J18: 23.8224 | K18: 18.8174 | L18: 13.8124 | M18: 8.8074
A19: =+A18+1 -> 10 | B19: =+B18+1 -> 2009 | C19: =+C18 -> 7 | D19: =+D18 -> 20 | E19: 0 | F19: 0 | G19: 0 | H19: 0 | I19: 0 | J19: 16.1048 | K19: 11.0998 | L19: 6.0948 | M19: 1.1446
A20: =+A19+1 -> 11 | B20: =+B19+1 -> 2010 | C20: =+C19 -> 7 | D20: =+D19 -> 20 | E20: 0 | F20: 0 | G20: 0 | H20: 0 | I20: 0 | J20: 21.202 | K20: 16.197 | L20: 11.192 | M20: 6.187
A21: =+A20+1 -> 12 | B21: =+B20+1 -> 2011 | C21: =+C20 -> 7 | D21: =+D20 -> 20 | E21: 0 | F21: 0 | G21: 0 | H21: 0 | I21: 0 | J21: 24.0742 | K21: 19.0692 | L21: 14.0642 | M21: 9.0592
A22: =+A21+1 -> 13 | B22: =+B21+1 -> 2012 | C22: =+C21 -> 7 | D22: =+D21 -> 20 | E22: 0 | F22: 0 | G22: 0 | H22: 0 | I22: 0 | J22: 23.2162 | K22: 18.2112 | L22: 13.2062 | M22: 8.2012
A23: =+A22+1 -> 14 | B23: =+B22+1 -> 2013 | C23: =+C22 -> 7 | D23: =+D22 -> 20 | E23: 0 | F23: 0 | G23: 0 | H23: 0 | I23: 0 | J23: 16.6588 | K23: 11.6538 | L23: 6.6488 | M23: 1.7222
... A30: =+A29+1 -> 21 | B30: =+B29+1 -> 2020 | C30: =+C29 -> 7 | D30: =+D29 -> 20 | E30: 0 | F30: 0 | G30: 0 | H30: 0 | I30: 0 | J30: 21.1011 | K30: 16.0961 | L30: 11.0911 | M30: 6.0861
A31: =+A30+1 -> 22 | B31: 7/20 | E31: =AVERAGE(E11:E30) -> 0 | F31: =AVERAGE(F11:F30) -> 0 | G31: =AVERAGE(G11:G30) -> 0 | H31: =AVERAGE(H11:H30) -> 0 | I31: =AVERAGE(I11:I30) -> 0 | J31: =AVERAGE(J11:J30) -> 21.353391 | K31: =AVERAGE(K11:K30) -> 16.348391 | L31: =AVERAGE(L11:L30) -> 11.346783 | M31: =AVERAGE(M11:M30) -> 6.4583646

Sheet Simple Averages_0114
B1: =+RES!B1 -> PUC DOCKET NO.
B2: =+RES!B2 -> ONCOR ELECTRIC DELIVERY COMPANY LLC
B3: =+RES!B3 -> ADJUSTED WEATHER STATION DATA
B4: =+RES!B4 -> FOR THE TEST YEAR ENDING DECEMBER 31, 2021
B6: =+RES!B6 -> SPONSOR: D. E. NELSON
B8: RESIDENTIAL SIMPLE TWENTY YEAR AVERAGE CALCULATION FOR JANUARY 14TH
A9: Line No.
A10: 1 | B10: Year | C10: Month | D10: Day | E10: HDD40 | F10: HDD45 | G10: HDD55 | H10: HDD60 | I10: HDD65 | J10: CDD65 | K10: CDD70 | L10: CDD75 | M10: CDD80
A11: =+A10+1 -> 2 | B11: 2001 | C11: 1 | D11: 14 | E11: 0 | F11: 0.259125 | G11: 9.4281667 | H11: 14.428167 | I11: 19.428167 | J11: 0 | K11: 0 | L11: 0 | M11: 0
A12: =+A11+1 -> 3 | B12: =+B11+1 -> 2002 | C12: =+C11 -> 1 | D12: =+D11 -> 14 | E12: 0 | F12: 0.16645833 | G12: 6.153625 | H12: 11.153625 | I12: 16.153625 | J12: 0 | K12: 0 | L12: 0 | M12: 0
A13: =+A12+1 -> 4 | B13: =+B12+1 -> 2003 | C13: =+C12 -> 1 | D13: =+D12 -> 14 | E13: 0.053333333 | F13: 1.28225 | G13: 11.26275 | H13: 16.26275 | I13: 21.26275 | J13: 0 | K13: 0 | L13: 0 | M13: 0
A14: =+A13+1 -> 5 | B14: =+B13+1 -> 2004 | C14: =+C13 -> 1 | D14: =+D13 -> 14 | E14: 0 | F14: 0 | G14: 0.523875 | H14: 3.1921667 | I14: 8.0774167 | J14: 0 | K14: 0 | L14: 0 | M14: 0
A15: =+A14+1 -> 6 | B15: =+B14+1 -> 2005 | C15: =+C14 -> 1 | D15: =+D14 -> 14 | E15: 0.075833333 | F15: 3.4368333 | G15: 13.415083 | H15: 18.415083 | I15: 23.415083 | J15: 0 | K15: 0 | L15: 0 | M15: 0
A16: =+A15+1 -> 7 | B16: =+B15+1 -> 2006 | C16: =+C15 -> 1 | D16: =+D15 -> 14 | E16: 0 | F16: 0 | G16: 5.4265417 | H16: 10.426542 | I16: 15.426542 | J16: 0 | K16: 0 | L16: 0 | M16: 0
A17: =+A16+1 -> 8 | B17: =+B16+1 -> 2007 | C17: =+C16 -> 1 | D17: =+D16 -> 14 | E17: 7.1078333 | F17: 11.901083 | G17: 21.73675 | H17: 26.73675 | I17: 31.73675 | J17: 0 | K17: 0 | L17: 0 | M17: 0
A18: =+A17+1 -> 9 | B18: =+B17+1 -> 2008 | C18: =+C17 -> 1 | D18: =+D17 -> 14 | E18: 0.0912 | F18: 0.4657 | G18: 6.5523 | H18: 11.5523 | I18: 16.5523 | J18: 0 | K18: 0 | L18: 0 | M18: 0
A19: =+A18+1 -> 10 | B19: =+B18+1 -> 2009 | C19: =+C18 -> 1 | D19: =+D18 -> 14 | E19: 0 | F19: 1.0528 | G19: 11.0528 | H19: 16.0528 | I19: 21.0528 | J19: 0 | K19: 0 | L19: 0 | M19: 0
A20: =+A19+1 -> 11 | B20: =+B19+1 -> 2010 | C20: =+C19 -> 1 | D20: =+D19 -> 14 | E20: 0 | F20: 0 | G20: 3.3614 | H20: 8.3614 | I20: 13.3614 | J20: 0 | K20: 0 | L20: 0 | M20: 0
A21: =+A20+1 -> 12 | B21: =+B20+1 -> 2011 | C21: =+C20 -> 1 | D21: =+D20 -> 14 | E21: 0.1807 | F21: 4.5952 | G21: 14.5952 | H21: 19.5952 | I21: 24.5952 | J21: 0 | K21: 0 | L21: 0 | M21: 0
A22: =+A21+1 -> 13 | B22: =+B21+1 -> 2012 | C22: =+C21 -> 1 | D22: =+D21 -> 14 | E22: 0 | F22: 0.115 | G22: 6.5632 | H22: 11.5632 | I22: 16.5632 | J22: 0 | K22: 0 | L22: 0 | M22: 0
A23: =+A22+1 -> 14 | B23: =+B22+1 -> 2013 | C23: =+C22 -> 1 | D23: =+D22 -> 14 | E23: 4.9532 | F23: 9.9316 | G23: 19.9316 | H23: 24.9316 | I23: 29.9316 | J23: 0 | K23: 0 | L23: 0 | M23: 0
... A30: =+A29+1 -> 21 | B30: =+B29+1 -> 2020 | C30: =+C29 -> 1 | D30: =+D29 -> 14 | E30: 0 | F30: 0 | G30: 0.1209 | H30: 0.5954 | I30: 3.4368 | J30: 0.0088 | K30: 0 | L30: 0 | M30: 0
A31: =+A30+1 -> 22 | B31: 1/14 | E31: =AVERAGE(E11:E30) -> 0.87003 | F31: =AVERAGE(F11:F30) -> 2.7327575 | G31: =AVERAGE(G11:G30) -> 9.8971946 | H31: =AVERAGE(H11:H30) -> 14.536324 | I31: =AVERAGE(I11:I30) -> 19.405907 | J31: =AVERAGE(J11:J30) -> 0.003785 | K31: =AVERAGE(K11:K30) -> 0 | L31: =AVERAGE(L11:L30) -> 0 | M31: =AVERAGE(M11:M30) -> 0

Sheet Simple Averages_0714
B1: =+RES!B1 -> PUC DOCKET NO.
B2: =+RES!B2 -> ONCOR ELECTRIC DELIVERY COMPANY LLC
B3: =+RES!B3 -> ADJUSTED WEATHER STATION DATA
B4: =+RES!B4 -> FOR THE TEST YEAR ENDING DECEMBER 31, 2021
B6: =+RES!B6 -> SPONSOR: D. E. NELSON
B8: RESIDENTIAL SIMPLE TWENTY YEAR AVERAGE CALCULATION FOR JULY 14TH
A9: Line No.
A10: 1 | B10: Year | C10: Month | D10: Day | E10: HDD40 | F10: HDD45 | G10: HDD55 | H10: HDD60 | I10: HDD65 | J10: CDD65 | K10: CDD70 | L10: CDD75 | M10: CDD80
A11: =+A10+1 -> 2 | B11: 2001 | C11: 7 | D11: 14 | E11: 0 | F11: 0 | G11: 0 | H11: 0 | I11: 0 | J11: 20.575792 | K11: 15.570792 | L11: 10.565792 | M11: 5.6450833
A12: =+A11+1 -> 3 | B12: =+B11+1 -> 2002 | C12: =+C11 -> 7 | D12: =+D11 -> 14 | E12: 0 | F12: 0 | G12: 0 | H12: 0 | I12: 0 | J12: 15.983417 | K12: 10.978417 | L12: 6.00375 | M12: 1.62225
A13: =+A12+1 -> 4 | B13: =+B12+1 -> 2003 | C13: =+C12 -> 7 | D13: =+D12 -> 14 | E13: 0 | F13: 0 | G13: 0 | H13: 0 | I13: 0 | J13: 22.290792 | K13: 17.285792 | L13: 12.280792 | M13: 7.2757917
A14: =+A13+1 -> 5 | B14: =+B13+1 -> 2004 | C14: =+C13 -> 7 | D14: =+D13 -> 14 | E14: 0 | F14: 0 | G14: 0 | H14: 0 | I14: 0 | J14: 21.090875 | K14: 16.085875 | L14: 11.080875 | M14: 6.075875
A15: =+A14+1 -> 6 | B15: =+B14+1 -> 2005 | C15: =+C14 -> 7 | D15: =+D14 -> 14 | E15: 0 | F15: 0 | G15: 0 | H15: 0 | I15: 0 | J15: 18.440583 | K15: 13.435583 | L15: 8.4305833 | M15: 3.5484167
A16: =+A15+1 -> 7 | B16: =+B15+1 -> 2006 | C16: =+C15 -> 7 | D16: =+D15 -> 14 | E16: 0 | F16: 0 | G16: 0 | H16: 0 | I16: 0 | J16: 24.224667 | K16: 19.219667 | L16: 14.214667 | M16: 9.2096667
A17: =+A16+1 -> 8 | B17: =+B16+1 -> 2007 | C17: =+C16 -> 7 | D17: =+D16 -> 14 | E17: 0 | F17: 0 | G17: 0 | H17: 0 | I17: 0 | J17: 15.384875 | K17: 10.379875 | L17: 5.3807083 | M17: 1.086875
A18: =+A17+1 -> 9 | B18: =+B17+1 -> 2008 | C18: =+C17 -> 7 | D18: =+D17 -> 14 | E18: 0 | F18: 0 | G18: 0 | H18: 0 | I18: 0 | J18: 20.7216 | K18: 15.7166 | L18: 10.7116 | M18: 5.7639
A19: =+A18+1 -> 10 | B19: =+B18+1 -> 2009 | C19: =+C18 -> 7 | D19: =+D18 -> 14 | E19: 0 | F19: 0 | G19: 0 | H19: 0 | I19: 0 | J19: 26.9771 | K19: 21.9721 | L19: 16.9671 | M19: 11.9621
A20: =+A19+1 -> 11 | B20: =+B19+1 -> 2010 | C20: =+C19 -> 7 | D20: =+D19 -> 14 | E20: 0 | F20: 0 | G20: 0 | H20: 0 | I20: 0 | J20: 22.2696 | K20: 17.2646 | L20: 12.2596 | M20: 7.2546
A21: =+A20+1 -> 12 | B21: =+B20+1 -> 2011 | C21: =+C20 -> 7 | D21: =+D20 -> 14 | E21: 0 | F21: 0 | G21: 0 | H21: 0 | I21: 0 | J21: 27.3277 | K21: 22.3227 | L21: 17.3177 | M21: 12.3127
A22: =+A21+1 -> 13 | B22: =+B21+1 -> 2012 | C22: =+C21 -> 7 | D22: =+D21 -> 14 | E22: 0 | F22: 0 | G22: 0 | H22: 0 | I22: 0 | J22: 18.61 | K22: 13.605 | L22: 8.6 | M22: 3.7404
A23: =+A22+1 -> 14 | B23: =+B22+1 -> 2013 | C23: =+C22 -> 7 | D23: =+D22 -> 14 | E23: 0 | F23: 0 | G23: 0 | H23: 0 | I23: 0 | J23: 10.1649 | K23: 5.1599 | L23: 1.3244 | M23: 0.5704
... A30: =+A29+1 -> 21 | B30: =+B29+1 -> 2020 | C30: =+C29 -> 7 | D30: =+D29 -> 14 | E30: 0 | F30: 0 | G30: 0 | H30: 0 | I30: 0 | J30: 24.358 | K30: 19.353 | L30: 14.348 | M30: 9.343
A31: =+A30+1 -> 22 | B31: 7/14 | E31: =AVERAGE(E11:E30) -> 0 | F31: =AVERAGE(F11:F30) -> 0 | G31: =AVERAGE(G11:G30) -> 0 | H31: =AVERAGE(H11:H30) -> 0 | I31: =AVERAGE(I11:I30) -> 0 | J31: =AVERAGE(J11:J30) -> 20.840025 | K31: =AVERAGE(K11:K30) -> 15.835025 | L31: =AVERAGE(L11:L30) -> 10.890568 | M31: =AVERAGE(M11:M30) -> 6.2025679

Sheet Smoothed Normal for 0121
B1: =+RES!B1 -> PUC DOCKET NO.
B2: =+RES!B2 -> ONCOR ELECTRIC DELIVERY COMPANY LLC
B3: =+RES!B3 -> ADJUSTED WEATHER STATION DATA
B4: =+RES!B4 -> FOR THE TEST YEAR ENDING DECEMBER 31, 2021
B6: =+RES!B6 -> SPONSOR: D. E. NELSON
B8: RESIDENTIAL SMOOTHED NORMAL CALCULATION FOR JANUARY 21ST
A9: Line
A10: No.
A11: 1 | C11: Residential Raw Normal Heating Degree Days | I11: Residential Smoothed Normal Heating Degree Days
A12: =+A11+1 -> 2 | C12: Base40 | D12: Base45 | E12: Base55 | F12: Base60 | G12: Base65 | I12: Base40 | J12: Base50 | K12: Base55 | L12: Base60 | M12: Base61
A13: =+A12+1 -> 3 | C13: c1 | D13: c2 | E13: c3 | F13: c4 | G13: c5 | I13: c1 | J13: c2 | K13: c3 | L13: c4 | M13: c5
A14: =+A13+1 -> 4 | B14: 43836 | C14: 2.7376817 | D14: 4.2694679 | E14: 11.330455 | F14: 15.876883 | G14: 20.628218
A15: =+A14+1 -> 5 | B15: 43837 | C15: 2.2045975 | D15: 4.2459112 | E15: 10.454895 | F15: 14.713921 | G15: 19.288956
A16: =+A15+1 -> 6 | B16: 43838 | C16: 1.7599808 | D16: 2.8745458 | E16: 8.8068354 | F16: 13.25188 | G16: 18.046888
A17: =+A16+1 -> 7 | B17: 43839 | C17: 1.2740813 | D17: 2.3929088 | E17: 8.0467975 | F17: 12.147236 | G17: 16.721201
A18: =+A17+1 -> 8 | B18: 43840 | C18: 1.5745908 | D18: 3.2886225 | E18: 9.1320196 | F18: 13.190074 | G18: 17.450201
A19: =+A18+1 -> 9 | B19: 43841 | C19: 1.0507579 | D19: 2.759265 | E19: 8.8208508 | F19: 12.923607 | G19: 17.427534
A20: =+A19+1 -> 10 | B20: 43842 | C20: 1.31195 | D20: 3.0319883 | E20: 9.1228421 | F20: 13.094368 | G20: 17.43408
A21: =+A20+1 -> 11 | B21: 43843 | C21: 1.6392846 | D21: 3.8540508 | E21: 11.32771 | F21: 16.108993 | G21: 21.074737
A22: =+A21+1 -> 12 | B22: 43844 | C22: 0.87003 | D22: 2.7327575 | E22: 9.8971946 | F22: 14.536324 | G22: 19.405907
A23: =+A22+1 -> 13 | B23: 43845 | C23: 1.1505904 | D23: 2.5924008 | E23: 9.2810167 | F23: 13.704125 | G23: 18.45932
A24: =+A23+1 -> 14 | B24: 43846 | C24: 2.2673604 | D24: 3.9788612 | E24: 10.125539 | F24: 14.371525 | G24: 18.996145
A25: =+A24+1 -> 15 | B25: 43847 | C25: 2.5203067 | D25: 4.3869775 | E25: 11.252776 | F25: 15.942891 | G25: 20.898357
... A28: =+A27+1 -> 18 | B28: 43850 | C28: 1.090735 | D28: 2.7228587 | E28: 7.8265158 | F28: 11.364989 | G28: 16.012055
A29: =+A28+1 -> 19 | B29: 43851 | C29: 0.50562792 | D29: 1.5805746 | E29: 8.0570712 | F29: 12.282746 | G29: 17.01764 | I29: =AVERAGE(C14:C44) -> 1.291398 | J29: =AVERAGE(D14:D44) -> 2.8323715 | K29: =AVERAGE(E14:E44) -> 8.9643462 | L29: =AVERAGE(F14:F44) -> 13.192346 | M29: =AVERAGE(G14:G44) -> 17.87253
A30: =+A29+1 -> 20 | B30: 43852 | C30: 0.39942042 | D30: 2.0066958 | E30: 7.9411725 | F30: 12.22226 | G30: 17.179061
A31: =+A30+1 -> 21 | B31: 43853 | C31: 1.8199158 | D31: 3.7236771 | E31: 10.273205 | F31: 14.459267 | G31: 19.059586
A32: =+A31+1 -> 22 | B32: 43854 | C32: 1.3769592 | D32: 2.9617333 | E32: 9.8430504 | F32: 14.236817 | G32: 18.957397
A33: =+A32+1 -> 23 | B33: 43855 | C33: 0.32308583 | D33: 1.3864396 | E33: 7.4994962 | F33: 11.848882 | G33: 16.77251
A34: =+A33+1 -> 24 | B34: 43856 | C34: 0.18302833 | D34: 0.93456667 | E34: 6.7110192 | F34: 11.248135 | G34: 16.223185
A35: =+A34+1 -> 25 | B35: 43857 | C35: 1.0102337 | D35: 2.3051129 | E35: 8.1609154 | F35: 12.455232 | G35: 17.314682
A36: =+A35+1 -> 26 | B36: 43858 | C36: 1.3617067 | D36: 2.5127933 | E36: 7.2209129 | F36: 10.935456 | G36: 15.45056
A37: =+A36+1 -> 27 | B37: 43859 | C37: 0.83407208 | D37: 2.3328892 | E37: 7.7769462 | F37: 11.566196 | G37: 16.081313
A38: =+A37+1 -> 28 | B38: 43860 | C38: 0.70785208 | D38: 2.0097267 | E38: 8.3383971 | F38: 12.716356 | G38: 17.549026
A39: =+A38+1 -> 29 | B39: 43861 | C39: 0.59451375 | D39: 1.696385 | E39: 7.0351892 | F39: 10.879263 | G39: 15.339313
A40: =+A39+1 -> 30 | B40: 43862 | C40: 1.1564512 | D40: 2.5468208 | E40: 7.5359042 | F40: 11.530692 | G40: 16.190902
A41: =+A40+1 -> 31 | B41: 43863 | C41: 2.1501754 | D41: 4.1920546 | E41: 10.006214 | F41: 13.742272 | G41: 18.52857
... A44: =+A43+1 -> 34 | B44: 43866 | C44: 1.6335921 | D44: 3.4567804 | E44: 9.780705 | F44: 13.836381 | G44: 18.360886

Sheet Smoothed Normal for 0720
B1: =+RES!B1 -> PUC DOCKET NO.
B2: =+RES!B2 -> ONCOR ELECTRIC DELIVERY COMPANY LLC
B3: =+RES!B3 -> ADJUSTED WEATHER STATION DATA
B4: =+RES!B4 -> FOR THE TEST YEAR ENDING DECEMBER 31, 2021
B6: =+RES!B6 -> SPONSOR: D. E. NELSON
B8: RESIDENTIAL SMOOTHED NORMAL CALCULATION FOR JULY 20TH
A9: Line
A10: No.
A11: 1 | C11: Residential Raw Normal Cooling Degree Days | H11: Residential Smoothed Normal cooling Degree Days
A12: =+A11+1 -> 2 | C12: Base65 | D12: Base70 | E12: Base75 | F12: Base80 | H12: Base65 | I12: Base70 | J12: Base75 | K12: Base80
A13: =+A12+1 -> 3 | C13: c1 | D13: c2 | E13: c3 | F13: c4 | H13: c1 | I13: c2 | J13: c3 | K13: c4
A14: =+A13+1 -> 4 | B14: 44017 | C14: 18.519245 | D14: 13.514245 | E14: 8.517185 | F14: 3.8345917
A15: =+A14+1 -> 5 | B15: 44018 | C15: 18.78914 | D15: 13.78414 | E15: 8.7843417 | F15: 3.9405996
A16: =+A15+1 -> 6 | B16: 44019 | C16: 19.029334 | D16: 14.024334 | E16: 9.0265363 | F16: 4.2523317
A17: =+A16+1 -> 7 | B17: 44020 | C17: 19.228614 | D17: 14.223614 | E17: 9.2235488 | F17: 4.3628604
A18: =+A17+1 -> 8 | B18: 44021 | C18: 19.809484 | D18: 14.804484 | E18: 9.8049987 | F18: 4.9610333
A19: =+A18+1 -> 9 | B19: 44022 | C19: 20.16724 | D19: 15.16224 | E19: 10.15724 | F19: 5.2248467
A20: =+A19+1 -> 10 | B20: 44023 | C20: 21.111847 | D20: 16.106847 | E20: 11.101956 | F20: 6.1504737
A21: =+A20+1 -> 11 | B21: 44024 | C21: 21.222945 | D21: 16.217945 | E21: 11.213205 | F21: 6.2357313
A22: =+A21+1 -> 12 | B22: 44025 | C22: 21.772275 | D22: 16.767275 | E22: 11.764288 | F22: 6.8203204
A23: =+A22+1 -> 13 | B23: 44026 | C23: 20.840025 | D23: 15.835025 | E23: 10.890568 | F23: 6.2025679
A24: =+A23+1 -> 14 | B24: 44027 | C24: 19.478254 | D24: 14.490704 | E24: 9.6740558 | F24: 5.0767708
A25: =+A24+1 -> 15 | B25: 44028 | C25: 20.320134 | D25: 15.325494 | E25: 10.339612 | F25: 5.7648313
... A28: =+A27+1 -> 18 | B28: 44031 | C28: 21.264559 | D28: 16.260434 | E28: 11.357879 | F28: 6.647795
A29: =+A28+1 -> 19 | B29: 44032 | C29: 21.353391 | D29: 16.348391 | E29: 11.346783 | F29: 6.4583646 | H29: =AVERAGE(C14:C44) -> 20.723996 | I29: =AVERAGE(D14:D44) -> 15.722228 | J29: =AVERAGE(E14:E44) -> 10.748525 | K29: =AVERAGE(F14:F44) -> 5.9633742
A30: =+A29+1 -> 20 | B30: 44033 | C30: 22.120598 | D30: 17.115598 | E30: 12.118415 | F30: 7.1517863
A31: =+A30+1 -> 21 | B31: 44034 | C31: 22.273468 | D31: 17.268468 | E31: 12.271728 | F31: 7.3116246
A32: =+A31+1 -> 22 | B32: 44035 | C32: 21.303435 | D32: 16.298435 | E32: 11.309622 | F32: 6.3770729
A33: =+A32+1 -> 23 | B33: 44036 | C33: 20.684162 | D33: 15.679162 | E33: 10.676732 | F33: 5.8190192
A34: =+A33+1 -> 24 | B34: 44037 | C34: 20.811248 | D34: 15.824067 | E34: 10.870791 | F34: 6.2494117
A35: =+A34+1 -> 25 | B35: 44038 | C35: 20.589458 | D35: 15.598708 | E35: 10.6271 | F35: 6.0008554
A36: =+A35+1 -> 26 | B36: 44039 | C36: 19.862823 | D36: 14.87499 | E36: 9.9176704 | F36: 5.4272358
A37: =+A36+1 -> 27 | B37: 44040 | C37: 20.343246 | D37: 15.343646 | E37: 10.362869 | F37: 5.6992204
A38: =+A37+1 -> 28 | B38: 44041 | C38: 20.741252 | D38: 15.736252 | E38: 10.73963 | F38: 5.962545
A39: =+A38+1 -> 29 | B39: 44042 | C39: 20.895485 | D39: 15.890485 | E39: 10.888441 | F39: 6.034405
A40: =+A39+1 -> 30 | B40: 44043 | C40: 20.824738 | D40: 15.819738 | E40: 10.827143 | F40: 6.0833542
A41: =+A40+1 -> 31 | B41: 44044 | C41: 21.431187 | D41: 16.426187 | E41: 11.454372 | F41: 6.7509179
... A44: =+A43+1 -> 34 | B44: 44047 | C44: 22.498252 | D44: 17.493252 | E44: 12.488252 | F44: 7.5335037

Sheet Smoothed Normal for 0114
B1: =+RES!B1 -> PUC DOCKET NO.
B2: =+RES!B2 -> ONCOR ELECTRIC DELIVERY COMPANY LLC
B3: =+RES!B3 -> ADJUSTED WEATHER STATION DATA
B4: =+RES!B4 -> FOR THE TEST YEAR ENDING DECEMBER 31, 2021
B6: =+RES!B6 -> SPONSOR: D. E. NELSON
B8: RESIDENTIAL SMOOTHED NORMAL CALCULATION FOR JANUARY 20TH
A9: Line
A10: No.
A11: 1 | C11: Residential Raw Normal Cooling Degree Days | I11: Residential Smoothed Normal cooling Degree Days
A12: =+A11+1 -> 2 | C12: Base40 | D12: Base45 | E12: Base55 | F12: Base60 | G12: Base65 | I12: Base40 | J12: Base45 | K12: Base55 | L12: Base60 | M12: Base65
A13: =+A12+1 -> 3 | C13: c1 | D13: c2 | E13: c3 | F13: c4 | G13: c5 | I13: c1 | J13: c2 | K13: c3 | L13: c4 | M13: c5
A14: =+A13+1 -> 4 | B14: 44195 | C14: 0.85487708 | D14: 2.3651383 | E14: 8.5820358 | F14: 12.704922 | G14: 17.302401
A15: =+A14+1 -> 5 | B15: 44196 | C15: 1.39572 | D15: 3.0935762 | E15: 9.6284225 | F15: 14.057381 | G15: 18.803961
A16: =+A15+1 -> 6 | B16: 44197 | C16: 2.5101692 | D16: 4.9909896 | E16: 12.018464 | F16: 16.249842 | G16: 20.583749
A17: =+A16+1 -> 7 | B17: 44198 | C17: 3.3227017 | D17: 6.255605 | E17: 13.305824 | F17: 17.163716 | G17: 21.364635
A18: =+A17+1 -> 8 | B18: 44199 | C18: 1.8910921 | D18: 4.0868167 | E18: 11.372382 | F18: 15.404927 | G18: 19.606929
A19: =+A18+1 -> 9 | B19: 44200 | C19: 1.12371 | D19: 2.7394042 | E19: 9.6863512 | F19: 14.163644 | G19: 18.927675
A20: =+A19+1 -> 10 | B20: 44201 | C20: 1.8994871 | D20: 3.8078958 | E20: 11.038282 | F20: 15.721923 | G20: 20.487988
A21: =+A20+1 -> 11 | B21: 44202 | C21: 2.7376817 | D21: 4.2694679 | E21: 11.330455 | F21: 15.876883 | G21: 20.628218
A22: =+A21+1 -> 12 | B22: 44203 | C22: 2.2045975 | D22: 4.2459112 | E22: 10.454895 | F22: 14.713921 | G22: 19.288956
A23: =+A22+1 -> 13 | B23: 44204 | C23: 1.7599808 | D23: 2.8745458 | E23: 8.8068354 | F23: 13.25188 | G23: 18.046888
A24: =+A23+1 -> 14 | B24: 44205 | C24: 1.2740813 | D24: 2.3929088 | E24: 8.0467975 | F24: 12.147236 | G24: 16.721201
A25: =+A24+1 -> 15 | B25: 44206 | C25: 1.5745908 | D25: 3.2886225 | E25: 9.1320196 | F25: 13.190074 | G25: 17.450201
... A28: =+A27+1 -> 18 | B28: 44209 | C28: 1.6392846 | D28: 3.8540508 | E28: 11.32771 | F28: 16.108993 | G28: 21.074737
A29: =+A28+1 -> 19 | B29: 44210 | C29: 0.87003 | D29: 2.7327575 | E29: 9.8971946 | F29: 14.536324 | G29: 19.405907 | I29: =AVERAGE(C14:C44) -> 1.4348824 | J29: =AVERAGE(D14:D44) -> 3.100101 | K29: =AVERAGE(E14:E44) -> 9.4520964 | L29: =AVERAGE(F14:F44) -> 13.734244 | M29: =AVERAGE(G14:G44) -> 18.404572
A30: =+A29+1 -> 20 | B30: 44211 | C30: 1.1505904 | D30: 2.5924008 | E30: 9.2810167 | F30: 13.704125 | G30: 18.45932
A31: =+A30+1 -> 21 | B31: 44212 | C31: 2.2673604 | D31: 3.9788612 | E31: 10.125539 | F31: 14.371525 | G31: 18.996145
A32: =+A31+1 -> 22 | B32: 44213 | C32: 2.5203067 | D32: 4.3869775 | E32: 11.252776 | F32: 15.942891 | G32: 20.898357
A33: =+A32+1 -> 23 | B33: 44214 | C33: 1.3406079 | D33: 3.5168946 | E33: 10.088042 | F33: 14.978547 | G33: 19.968282
A34: =+A33+1 -> 24 | B34: 44215 | C34: 0.87699333 | D34: 2.3717125 | E34: 8.3859458 | F34: 12.834861 | G34: 17.596577
A35: =+A34+1 -> 25 | B35: 44216 | C35: 1.090735 | D35: 2.7228587 | E35: 7.8265158 | F35: 11.364989 | G35: 16.012055
A36: =+A35+1 -> 26 | B36: 44217 | C36: 0.50562792 | D36: 1.5805746 | E36: 8.0570712 | F36: 12.282746 | G36: 17.01764
A37: =+A36+1 -> 27 | B37: 44218 | C37: 0.39942042 | D37: 2.0066958 | E37: 7.9411725 | F37: 12.22226 | G37: 17.179061
A38: =+A37+1 -> 28 | B38: 44219 | C38: 1.8199158 | D38: 3.7236771 | E38: 10.273205 | F38: 14.459267 | G38: 19.059586
A39: =+A38+1 -> 29 | B39: 44220 | C39: 1.3769592 | D39: 2.9617333 | E39: 9.8430504 | F39: 14.236817 | G39: 18.957397
A40: =+A39+1 -> 30 | B40: 44221 | C40: 0.32308583 | D40: 1.3864396 | E40: 7.4994962 | F40: 11.848882 | G40: 16.77251
A41: =+A40+1 -> 31 | B41: 44222 | C41: 0.18302833 | D41: 0.93456667 | E41: 6.7110192 | F41: 11.248135 | G41: 16.223185
... A44: =+A43+1 -> 34 | B44: 44225 | C44: 0.83407208 | D44: 2.3328892 | E44: 7.7769462 | F44: 11.566196 | G44: 16.081313

Sheet Smoothed Normal for 0714
B1: =+RES!B1 -> PUC DOCKET NO.
B2: =+RES!B2 -> ONCOR ELECTRIC DELIVERY COMPANY LLC
B3: =+RES!B3 -> ADJUSTED WEATHER STATION DATA
B4: =+RES!B4 -> FOR THE TEST YEAR ENDING DECEMBER 31, 2021
B6: =+RES!B6 -> SPONSOR: D. E. NELSON
B8: RESIDENTIAL SMOOTHED NORMAL CALCULATION FOR JULY 14TH
A9: Line
A10: No.
A11: 1 | C11: Residential Raw Normal Cooling Degree Days | H11: Residential Smoothed Normal cooling Degree Days
A12: =+A11+1 -> 2 | C12: Base65 | D12: Base70 | E12: Base75 | F12: Base80 | H12: Base65 | I12: Base70 | J12: Base75 | K12: Base80
A13: =+A12+1 -> 3 | C13: c1 | D13: c2 | E13: c3 | F13: c4 | H13: c1 | I13: c2 | J13: c3 | K13: c4
A14: =+A13+1 -> 4 | B14: 44376 | C14: 18.300136 | D14: 13.295136 | E14: 8.3645692 | F14: 3.8778833
A15: =+A14+1 -> 5 | B15: 44377 | C15: 17.849634 | D15: 12.844634 | E15: 7.9022829 | F15: 3.6315625
A16: =+A15+1 -> 6 | B16: 44378 | C16: 17.071832 | D16: 12.066832 | E16: 7.1181083 | F16: 2.9004442
A17: =+A16+1 -> 7 | B17: 44379 | C17: 18.013682 | D17: 13.008682 | E17: 8.0262379 | F17: 3.7118458
A18: =+A17+1 -> 8 | B18: 44380 | C18: 18.81917 | D18: 13.81417 | E18: 8.8231004 | F18: 4.2687717
A19: =+A18+1 -> 9 | B19: 44381 | C19: 18.977143 | D19: 13.972143 | E19: 8.9723117 | F19: 4.2034212
A20: =+A19+1 -> 10 | B20: 44382 | C20: 18.519245 | D20: 13.514245 | E20: 8.517185 | F20: 3.8345917
A21: =+A20+1 -> 11 | B21: 44383 | C21: 18.78914 | D21: 13.78414 | E21: 8.7843417 | F21: 3.9405996
A22: =+A21+1 -> 12 | B22: 44384 | C22: 19.029334 | D22: 14.024334 | E22: 9.0265363 | F22: 4.2523317
A23: =+A22+1 -> 13 | B23: 44385 | C23: 19.228614 | D23: 14.223614 | E23: 9.2235488 | F23: 4.3628604
A24: =+A23+1 -> 14 | B24: 44386 | C24: 19.809484 | D24: 14.804484 | E24: 9.8049987 | F24: 4.9610333
A25: =+A24+1 -> 15 | B25: 44387 | C25: 20.16724 | D25: 15.16224 | E25: 10.15724 | F25: 5.2248467
... A28: =+A27+1 -> 18 | B28: 44390 | C28: 21.772275 | D28: 16.767275 | E28: 11.764288 | F28: 6.8203204
A29: =+A28+1 -> 19 | B29: 44391 | C29: 20.840025 | D29: 15.835025 | E29: 10.890568 | F29: 6.2025679 | H29: =AVERAGE(C14:C44) -> 20.061013 | I29: =AVERAGE(D14:D44) -> 15.059246 | J29: =AVERAGE(E14:E44) -> 10.09125 | K29: =AVERAGE(F14:F44) -> 5.3802641
A30: =+A29+1 -> 20 | B30: 44392 | C30: 19.478254 | D30: 14.490704 | E30: 9.6740558 | F30: 5.0767708
A31: =+A30+1 -> 21 | B31: 44393 | C31: 20.320134 | D31: 15.325494 | E31: 10.339612 | F31: 5.7648313
A32: =+A31+1 -> 22 | B32: 44394 | C32: 20.409394 | D32: 15.412474 | E32: 10.508499 | F32: 5.9411679
A33: =+A32+1 -> 23 | B33: 44395 | C33: 20.814248 | D33: 15.818048 | E33: 11.016878 | F33: 6.3212008
A34: =+A33+1 -> 24 | B34: 44396 | C34: 21.264559 | D34: 16.260434 | E34: 11.357879 | F34: 6.647795
A35: =+A34+1 -> 25 | B35: 44397 | C35: 21.353391 | D35: 16.348391 | E35: 11.346783 | F35: 6.4583646
A36: =+A35+1 -> 26 | B36: 44398 | C36: 22.120598 | D36: 17.115598 | E36: 12.118415 | F36: 7.1517863
A37: =+A36+1 -> 27 | B37: 44399 | C37: 22.273468 | D37: 17.268468 | E37: 12.271728 | F37: 7.3116246
A38: =+A37+1 -> 28 | B38: 44400 | C38: 21.303435 | D38: 16.298435 | E38: 11.309622 | F38: 6.3770729
A39: =+A38+1 -> 29 | B39: 44401 | C39: 20.684162 | D39: 15.679162 | E39: 10.676732 | F39: 5.8190192
A40: =+A39+1 -> 30 | B40: 44402 | C40: 20.811248 | D40: 15.824067 | E40: 10.870791 | F40: 6.2494117
A41: =+A40+1 -> 31 | B41: 44403 | C41: 20.589458 | D41: 15.598708 | E41: 10.6271 | F41: 6.0008554
... A44: =+A43+1 -> 34 | B44: 44406 | C44: 20.741252 | D44: 15.736252 | E44: 10.73963 | F44: 5.962545

Sheet Cycle 18 HDD Feb 20
B1: =+RES!B1 -> PUC DOCKET NO.
B2: =+RES!B2 -> ONCOR ELECTRIC DELIVERY COMPANY LLC
B3: =+RES!B3 -> ADJUSTED WEATHER STATION DATA
B4: =+RES!B4 -> FOR THE TEST YEAR ENDING DECEMBER 31, 2021
B6: =+RES!B6 -> SPONSOR: D. E. NELSON
B8: RESIDENTIAL FEBRUARY 2020 CYCLE 18 HEATING DEGREE DAYS
A9: Line
A10: No.
A11: 1 | B11: Billing | C11: Read | D11: Prior Month
A12: =+A11+1 -> 2 | B12: Cycle | C12: Day | D12: Read Day
A13: =+A12+1 -> 3 | B13: Cycle 18 | C13: 43880 | D13: 43851
A15: =+A13+1 -> 4 | C15: Normal Heating Degree Days | I15: Actual Heating Degree Days
A16: =+A15+1 -> 5 | C16: Base40 | D16: Base45 | E16: Base55 | F16: Base60 | G16: Base65 | I16: Base40 | J16: Base45 | K16: Base55 | L16: Base60 | M16: Base65
A17: =+A16+1 -> 6 | C17: c1 | D17: c2 | E17: c3 | F17: c4 | G17: c5 | I17: c1 | J17: c2 | K17: c3 | L17: c4 | M17: c5
A18: =+A17+1 -> 7 | B18: =+D13 -> 43851 | C18: 1.291398 | D18: 2.8323715 | E18: 8.9643462 | F18: 13.192346 | G18: 17.87253 | I18: 0.0996 | J18: 1.5018 | K18: 11.0189 | L18: 16.0189 | M18: 21.0189
A19: =+A18+1 -> 8 | B19: =+B18+1 -> 43852 | C19: 1.2524192 | D19: 2.8062483 | E19: 8.9110169 | F19: 13.116271 | G19: 17.778674 | I19: 0.0867 | J19: 3.0011 | K19: 11.9812 | L19: 16.9812 | M19: 21.9812
A20: =+A19+1 -> 9 | B20: =+B19+1 -> 43853 | C20: 1.2216714 | D20: 2.7623729 | E20: 8.8626656 | F20: 13.053438 | G20: 17.704846 | I20: 0 | J20: 0.0351 | K20: 6.2501 | L20: 11.2501 | M20: 16.2501
A21: =+A20+1 -> 10 | B21: =+B20+1 -> 43854 | C21: 1.187164 | D21: 2.7371312 | E21: 8.8386493 | F21: 13.016031 | G21: 17.657783 | I21: 0 | J21: 0.0881 | K21: 7.383 | L21: 12.383 | M21: 17.383
A22: =+A21+1 -> 11 | B22: =+B21+1 -> 43855 | C22: 1.1868859 | D22: 2.7483743 | E22: 8.8575569 | F22: 13.036365 | G22: 17.686458 | I22: 0 | J22: 0 | K22: 2.8554 | L22: 7.8554 | M22: 12.8554
A23: =+A22+1 -> 12 | B23: =+B22+1 -> 43856 | C23: 1.1914169 | D23: 2.7549949 | E23: 8.8875092 | F23: 13.06118 | G23: 17.722997 | I23: 0 | J23: 0 | K23: 0.3111 | L23: 4.3856 | M23: 9.2731
A24: =+A23+1 -> 13 | B24: =+B23+1 -> 43857 | C24: 1.213366 | D24: 2.7923249 | E24: 8.9325109 | F24: 13.106411 | G24: 17.770557 | I24: 0 | J24: 0 | K24: 3.6151 | L24: 8.4121 | M24: 13.4121
A25: =+A24+1 -> 14 | B25: =+B24+1 -> 43858 | C25: 1.2016357 | D25: 2.774715 | E25: 8.9287586 | F25: 13.120044 | G25: 17.798178 | I25: 0 | J25: 0 | K25: 3.6239 | L25: 8.4943 | M25: 13.4943
A26: =+A25+1 -> 15 | B26: =+B25+1 -> 43859 | C26: 1.1681156 | D26: 2.7080593 | E26: 8.8111721 | F26: 12.97653 | G26: 17.640003 | I26: 0.02 | J26: 3.0496 | K26: 12.6403 | L26: 17.6403 | M26: 22.6403
A27: =+A26+1 -> 16 | B27: =+B26+1 -> 43860 | C27: 1.1743942 | D27: 2.6879476 | E27: 8.6757659 | F27: 12.789092 | G27: 17.433635 | I27: 0.1087 | J27: 2.8959 | K27: 12.6922 | L27: 17.6922 | M27: 22.6922
A28: =+A27+1 -> 17 | B28: =+B27+1 -> 43861 | C28: 1.1626387 | D28: 2.657613 | E28: 8.5573845 | F28: 12.629684 | G28: 17.244405 | I28: 0.0112 | J28: 0.3113 | K28: 8.4482 | L28: 13.4482 | M28: 18.4482
A29: =+A28+1 -> 18 | B29: =+B28+1 -> 43862 | C29: 1.1194566 | D29: 2.6112079 | E29: 8.4938778 | F29: 12.547948 | G29: 17.155158 | I29: 0 | J29: 0 | K29: 5.5912 | L29: 10.5912 | M29: 15.5912
A30: =+A29+1 -> 19 | B30: =+B29+1 -> 43863 | C30: 1.0507632 | D30: 2.5164781 | E30: 8.3301462 | F30: 12.358041 | G30: 16.944696 | I30: 0 | J30: 0 | K30: 0 | L30: 0.6488 | M30: 4.9037
... A46: =+A45+1 -> 35 | B46: =+B45+1 -> 43879 | C46: 0.94586552 | D46: 2.0787618 | E46: 6.8589333 | F46: 10.399995 | G46: 14.555134 | I46: 0 | J46: 0 | K46: 0.962 | L46: 5.1398 | M46: 9.8382
A47: =+A46+1 -> 36 | B47: Total | C47: =SUM(C18:C46) -> 31.107107 | D47: =SUM(D18:D46) -> 71.237615 | E47: =SUM(E18:E46) -> 233.33715 | F47: =SUM(F18:F46) -> 347.30789 | G47: =SUM(G18:G46) -> 477.29918 | I47: =SUM(I18:I46) -> 12.5271 | J47: =SUM(J18:J46) -> 47.013 | K47: =SUM(K18:K46) -> 212.1216 | L47: =SUM(L18:L46) -> 329.8455 | M47: =SUM(M18:M46) -> 462.6481

Sheet Cycle 17 CDD Aug 20
B1: =+RES!B1 -> PUC DOCKET NO.
B2: =+RES!B2 -> ONCOR ELECTRIC DELIVERY COMPANY LLC
B3: =+RES!B3 -> ADJUSTED WEATHER STATION DATA
B4: =+RES!B4 -> FOR THE TEST YEAR ENDING DECEMBER 31, 2021
B6: =+RES!B6 -> SPONSOR: D. E. NELSON
B8: RESIDENTIAL AUGUST 2020 CYCLE 17 COOLING DEGREE DAYS
A9: Line
A10: No.
A11: 1 | B11: Billing | C11: Read | D11: Prior Month
A12: =+A11+1 -> 2 | B12: Cycle | C12: Day | D12: Read Day
A13: =+A12+1 -> 3 | B13: Cycle 17 | C13: 44061 | D13: 44032
A15: =+A13+1 -> 4 | C15: Normal Cooling Degree Days | H15: Actual Cooling Degree Days
A16: =+A15+1 -> 5 | C16: Base65 | D16: Base70 | E16: Base75 | F16: Base80 | H16: Base65 | I16: Base70 | J16: Base75 | K16: Base80
A17: =+A16+1 -> 6 | C17: c1 | D17: c2 | E17: c3 | F17: c4 | H17: c1 | I17: c2 | J17: c3 | K17: c4
A18: =+A17+1 -> 7 | B18: =+D13 -> 44032 | C18: 20.723996 | D18: 15.722228 | E18: 10.748525 | F18: 5.9633742 | H18: 21.1011 | I18: 16.0961 | J18: 11.0911 | K18: 6.0861
A19: =+A18+1 -> 8 | B19: =+B18+1 -> 44033 | C19: 20.869169 | D19: 15.867401 | E19: 10.893705 | F19: 6.0996533 | H19: 17.6577 | I19: 12.6527 | J19: 7.6477 | K19: 2.6801
