Workbook

Sheet Base35
B1: PUC DOCKET NO.
B2: ONCOR ELECTRIC DELIVERY
B3: WEATHER STATION DATA
B4: FOR THE TEST YEAR ENDING DECEMBER 31, 2007
B6: SPONSOR: G. L. GOBLE
B9: Calendar Actual Heating Degree Days by Weather Sites (Base 35)
A10: Line No. | C10: Metroplex (MX) | D10: Lufkin (LU) | E10: Austin (AU) | F10: Killeen (KI) | G10: Longview (LO) | H10: Waco (WO) | I10: Abilene (AE) | J10: Wichita Falls (WF) | K10: Midland/ Odessa (MO) | L10: Denison (DE)
A11: 1 | B11: 39083 | C11: 22.749999 | D11: 7.38 | E11: 11.33333 | F11: 18.33 | G11: 14.24 | H11: 16.625 | I11: 47.24 | J11: 42.29 | K11: 54.03 | L11: 41.32
A12: 2 | B12: 39114 | C12: 14.958333 | D12: 3.5 | E12: 1.375 | F12: 10.83 | G12: 9.88 | H12: 6.875 | I12: 25.25 | J12: 27.71 | K12: 14.24 | L12: 29.95
A13: 3 | B13: 39142 | C13: 0 | D13: 0 | E13: 0 | F13: 0 | G13: 0 | H13: 0 | I13: 0 | J13: 0 | K13: 0 | L13: 0
A14: 4 | B14: 39173 | C14: 0 | D14: 0 | E14: 0 | F14: 0 | G14: 0 | H14: 0 | I14: 3.37 | J14: 0 | K14: 6.66 | L14: 0
A15: 5 | B15: 39203 | C15: 0 | D15: 0 | E15: 0 | F15: 0 | G15: 0 | H15: 0 | I15: 0 | J15: 0 | K15: 0 | L15: 0
A16: 6 | B16: 39234 | C16: 0 | D16: 0 | E16: 0 | F16: 0 | G16: 0 | H16: 0 | I16: 0 | J16: 0 | K16: 0 | L16: 0
A17: 7 | B17: 39264 | C17: 0 | D17: 0 | E17: 0 | F17: 0 | G17: 0 | H17: 0 | I17: 0 | J17: 0 | K17: 0 | L17: 0
A18: 8 | B18: 39295 | C18: 0 | D18: 0 | E18: 0 | F18: 0 | G18: 0 | H18: 0 | I18: 0 | J18: 0 | K18: 0 | L18: 0
A19: 9 | B19: 39326 | C19: 0 | D19: 0 | E19: 0 | F19: 0 | G19: 0 | H19: 0 | I19: 0 | J19: 0 | K19: 0 | L19: 0
A20: 10 | B20: 39356 | C20: 0 | D20: 0 | E20: 0 | F20: 0 | G20: 0 | H20: 0 | I20: 0 | J20: 0 | K20: 0 | L20: 0
A21: 11 | B21: 39387 | C21: 0 | D21: 0 | E21: 0 | F21: 0 | G21: 0 | H21: 0 | I21: 4.12 | J21: 0 | K21: 7.41 | L21: 0
A22: 12 | B22: 39417 | C22: 0 | D22: 0 | E22: 0 | F22: 0 | G22: 0 | H22: 0 | I22: 3.38 | J22: 6.25 | K22: 2.37 | L22: 1.29
A23: 13 | B23: Annual | C23: =SUM(C11:C22) -> 37.708332 | D23: =SUM(D11:D22) -> 10.88 | E23: =SUM(E11:E22) -> 12.70833 | F23: =SUM(F11:F22) -> 29.16 | G23: =SUM(G11:G22) -> 24.12 | H23: =SUM(H11:H22) -> 23.5 | I23: =SUM(I11:I22) -> 83.36 | J23: =SUM(J11:J22) -> 76.25 | ... L23: =SUM(L11:L22) -> 72.56
A24: 14
A25: 15 | B25: Calendar Actual Cooling Degree Days by Weather Sites (Base 35)
A26: 16 | C26: Metroplex (MX) | D26: Lufkin (LU) | E26: Austin (AU) | F26: Killeen (KI) | G26: Longview (LO) | H26: Waco (WO) | I26: Abilene (AE) | J26: Wichita Falls (WF) | K26: Midland/ Odessa (MO) | L26: Denison (DE)
A27: 17 | B27: 39083
A28: 18 | B28: 39114
A29: 19 | B29: 39142
A30: 20 | B30: 39173
A31: 21 | B31: 39203
A32: 22 | B32: 39234
A33: 23 | B33: 39264
A34: 24 | B34: 39295
A35: 25 | B35: 39326
A36: 26 | B36: 39356
A37: 27 | B37: 39387
A38: 28 | B38: 39417
A39: 29 | B39: Annual | C39: =SUM(C27:C38) -> 0 | D39: =SUM(D27:D38) -> 0 | E39: =SUM(E27:E38) -> 0 | F39: =SUM(F27:F38) -> 0 | G39: =SUM(G27:G38) -> 0 | H39: =SUM(H27:H38) -> 0 | I39: =SUM(I27:I38) -> 0 | J39: =SUM(J27:J38) -> 0 | ... L39: =SUM(L27:L38) -> 0
A40: 30
A41: 31 | B41: Calendar Normal Heating Degree Days by Weather Sites (Base 35)
A42: 32 | C42: Metroplex (MX) | D42: Lufkin (LU) | E42: Austin (AU) | F42: Killeen (KI) | G42: Longview (LO) | H42: Waco (WO) | I42: Abilene (AE) | J42: Wichita Falls (WF) | K42: Midland/ Odessa (MO) | L42: Denison (DE)
A43: 33 | B43: 39083 | C43: 18.940253 | D43: 6.5763019 | E43: 5.4461726 | F43: 10.407794 | G43: 14.486215 | H43: 12.030748 | I43: 27.387566 | J43: 39.312965 | K43: 24.323938 | L43: 32.56895
...

Sheet Base40h
B1: PUC DOCKET NO.
B2: ONCOR ELECTRIC DELIVERY COMPANY LLC
B3: WEATHER STATION DATA
B4: FOR THE TEST YEAR ENDING DECEMBER 31, 2021
B6: SPONSOR: D. E. NELSON
B9: Calendar Actual Heating Degree Days by Weather Sites (Base 40)
A10: Line No. | C10: Dallas/ Fort Worth (MX) | D10: Lufkin (LU) | E10: Austin (AU) | F10: Killeen (KI) | G10: Longview (LO) | H10: Waco (WO) | I10: Abilene (AE) | J10: Wichita Falls (WF) | K10: Midland/ Odessa (MO) | L10: Denison (DE)
A11: 1 | B11: 44197 | C11: 10.4 | D11: 12.2 | E11: 4.6 | F11: 12.9 | G11: 19.3 | H11: 10.8 | I11: 24.4 | J11: 34.8 | K11: 51.9 | L11: 21.3
A12: =+A11+1 -> 2 | B12: 44228 | C12: 192.3 | D12: 96.2 | E12: 115.8 | F12: 158.3 | G12: 141.1 | H12: 155.7 | I12: 226.9 | J12: 272.9 | K12: 205.2 | L12: 214.7
A13: =+A12+1 -> 3 | B13: 44256 | C13: 0 | D13: 0 | E13: 0 | F13: 0 | G13: 0 | H13: 0 | I13: 0 | J13: 0 | K13: 0 | L13: 0
A14: =+A13+1 -> 4 | B14: 44287 | C14: 0 | D14: 0 | E14: 0 | F14: 0 | G14: 0 | H14: 0 | I14: 0 | J14: 0 | K14: 0 | L14: 0
A15: =+A14+1 -> 5 | B15: 44317 | C15: 0 | D15: 0 | E15: 0 | F15: 0 | G15: 0 | H15: 0 | I15: 0 | J15: 0 | K15: 0 | L15: 0
A16: =+A15+1 -> 6 | B16: 44348 | C16: 0 | D16: 0 | E16: 0 | F16: 0 | G16: 0 | H16: 0 | I16: 0 | J16: 0 | K16: 0 | L16: 0
A17: =+A16+1 -> 7 | B17: 44378 | C17: 0 | D17: 0 | E17: 0 | F17: 0 | G17: 0 | H17: 0 | I17: 0 | J17: 0 | K17: 0 | L17: 0
A18: =+A17+1 -> 8 | B18: 44409 | C18: 0 | D18: 0 | E18: 0 | F18: 0 | G18: 0 | H18: 0 | I18: 0 | J18: 0 | K18: 0 | L18: 0
A19: =+A18+1 -> 9 | B19: 44440 | C19: 0 | D19: 0 | E19: 0 | F19: 0 | G19: 0 | H19: 0 | I19: 0 | J19: 0 | K19: 0 | L19: 0
A20: =+A19+1 -> 10 | B20: 44470 | C20: 0 | D20: 0 | E20: 0 | F20: 0 | G20: 0 | H20: 0 | I20: 0 | J20: 0 | K20: 0 | L20: 0
A21: =+A20+1 -> 11 | B21: 44501 | C21: 0 | D21: 0 | E21: 0 | F21: 0 | G21: 0 | H21: 0 | I21: 0 | J21: 0 | K21: 0 | L21: 0
A22: =+A21+1 -> 12 | B22: 44531 | C22: 0 | D22: 0 | E22: 0 | F22: 0 | G22: 0 | H22: 0 | I22: 0.9 | J22: 7.6 | K22: 0 | L22: 4.5
A23: =+A22+1 -> 13 | B23: Annual | C23: =SUM(C11:C22) -> 202.7 | D23: =SUM(D11:D22) -> 108.4 | E23: =SUM(E11:E22) -> 120.4 | F23: =SUM(F11:F22) -> 171.2 | G23: =SUM(G11:G22) -> 160.4 | H23: =SUM(H11:H22) -> 166.5 | I23: =SUM(I11:I22) -> 252.2 | J23: =SUM(J11:J22) -> 315.3 | ... L23: =SUM(L11:L22) -> 240.5
A24: =+A23+1 -> 14
A25: =+A24+1 -> 15
A26: =+A25+1 -> 16 | B26: Calendar Normal Heating Degree Days by Weather Sites (Base 40)
A27: =+A26+1 -> 17 | C27: Dallas/ Fort Worth (MX) | D27: Lufkin (LU) | E27: Austin (AU) | F27: Killeen (KI) | G27: Longview (LO) | H27: Waco (WO) | I27: Abilene (AE) | J27: Wichita Falls (WF) | K27: Midland/ Odessa (MO) | L27: Denison (DE)
A28: =+A27+1 -> 18 | B28: =+B11 -> 44197 | C28: 43.91125 | D28: 24.92875 | E28: 19.689167 | F28: 29.414167 | G28: 39.202083 | H28: 33.99625 | I28: 59.99 | J28: 84.2075 | K28: 52.667083 | L28: 74.253333
A29: =+A28+1 -> 19 | B29: =+B12 -> 44228 | C29: 29.354167 | D29: 10.48375 | E29: 11.603333 | F29: 19.974167 | G29: 19.882917 | H29: 21.0625 | I29: 45.69875 | J29: 60.548333 | K29: 35.3175 | L29: 47.4725
A30: =+A29+1 -> 20 | B30: =+B13 -> 44256 | C30: 5.5858333 | D30: 2.26 | E30: 1.7945833 | F30: 3.1970833 | G30: 4.16 | H30: 3.6533333 | I30: 8.195 | J30: 10.971667 | K30: 6.5383333 | L30: 9.6091667
A31: =+A30+1 -> 21 | B31: =+B14 -> 44287 | C31: 0 | D31: 0 | E31: 0.022916667 | F31: 0.2875 | G31: 0 | H31: 0.14375 | I31: 0.80916667 | J31: 0.45083333 | K31: 0.83333333 | L31: 0.22208333
A32: =+A31+1 -> 22 | B32: =+B15 -> 44317 | C32: 0 | D32: 0 | E32: 0 | F32: 0 | G32: 0 | H32: 0 | I32: 0 | J32: 0 | K32: 0 | L32: 0
A33: =+A32+1 -> 23 | B33: =+B16 -> 44348 | C33: 0 | D33: 0 | E33: 0 | F33: 0 | G33: 0 | H33: 0 | I33: 0 | J33: 0 | K33: 0 | L33: 0
A34: =+A33+1 -> 24 | B34: =+B17 -> 44378 | C34: 0 | D34: 0 | E34: 0 | F34: 0 | G34: 0 | H34: 0 | I34: 0 | J34: 0 | K34: 0 | L34: 0
A35: =+A34+1 -> 25 | B35: =+B18 -> 44409 | C35: 0 | D35: 0 | E35: 0 | F35: 0 | G35: 0 | H35: 0 | I35: 0 | J35: 0 | K35: 0 | L35: 0
A36: =+A35+1 -> 26 | B36: =+B19 -> 44440 | C36: 0 | D36: 0 | E36: 0 | F36: 0 | G36: 0 | H36: 0 | I36: 0 | J36: 0 | K36: 0 | L36: 0
A37: =+A36+1 -> 27 | B37: =+B20 -> 44470 | C37: 0.08 | D37: 0 | E37: 0 | F37: 0.14 | G37: 0 | H37: 0.05 | I37: 1.18 | J37: 1.34 | K37: 1.49 | L37: 0.175
A38: =+A37+1 -> 28 | B38: =+B21 -> 44501 | C38: 5.0425 | D38: 1.61125 | E38: 1.3495833 | F38: 3.5345833 | G38: 3.4475 | H38: 3.9320833 | I38: 10.9275 | J38: 12.3325 | K38: 10.655417 | L38: 6.8645833
A39: =+A38+1 -> 29 | B39: =+B22 -> 44531 | C39: 24.895 | D39: 9.355 | E39: 8.5829167 | F39: 16.3225 | G39: 18.818333 | H39: 18.553333 | I39: 49.452917 | J39: 66.209167 | K39: 45.097917 | L39: 43.57125
A40: =+A39+1 -> 30 | B40: Annual | C40: =SUM(C28:C39) -> 108.86875 | D40: =SUM(D28:D39) -> 48.63875 | E40: =SUM(E28:E39) -> 43.0425 | F40: =SUM(F28:F39) -> 72.87 | G40: =SUM(G28:G39) -> 85.510833 | H40: =SUM(H28:H39) -> 81.39125 | I40: =SUM(I28:I39) -> 176.25333 | J40: =SUM(J28:J39) -> 236.06 | ... L40: =SUM(L28:L39) -> 182.16792

Sheet Base45h
B1: =+Base40h!B1 -> PUC DOCKET NO.
B2: =+Base40h!B2 -> ONCOR ELECTRIC DELIVERY COMPANY LLC
B3: =+Base40h!B3 -> WEATHER STATION DATA
B4: =+Base40h!B4 -> FOR THE TEST YEAR ENDING DECEMBER 31, 2021
B6: =+Base40h!B6 -> SPONSOR: D. E. NELSON
B9: Calendar Actual Heating Degree Days by Weather Sites (Base 45)
A10: Line No. | C10: Dallas/ Fort Worth (MX) | D10: Lufkin (LU) | E10: Austin (AU) | F10: Killeen (KI) | G10: Longview (LO) | H10: Waco (WO) | I10: Abilene (AE) | J10: Wichita Falls (WF) | K10: Midland/ Odessa (MO) | L10: Denison (DE)
A11: 1 | B11: =+Base40h!B11 -> 44197 | C11: 46.3 | D11: 41.3 | E11: 29.1 | F11: 48.4 | G11: 62.2 | H11: 45.5 | I11: 74.3 | J11: 102.6 | K11: 117.3 | L11: 78.2
A12: =+A11+1 -> 2 | B12: =+Base40h!B12 -> 44228 | C12: 252.6 | D12: 146 | E12: 167 | F12: 212.9 | G12: 197.3 | H12: 213.2 | I12: 282.5 | J12: 349 | K12: 263.5 | L12: 285.4
A13: =+A12+1 -> 3 | B13: =+Base40h!B13 -> 44256 | C13: 0 | D13: 0 | E13: 0 | F13: 0 | G13: 0 | H13: 0 | I13: 0 | J13: 0 | K13: 8.3 | L13: 0
A14: =+A13+1 -> 4 | B14: =+Base40h!B14 -> 44287 | C14: 0 | D14: 0 | E14: 0 | F14: 0 | G14: 0 | H14: 0 | I14: 0 | J14: 0 | K14: 1 | L14: 0
A15: =+A14+1 -> 5 | B15: =+Base40h!B15 -> 44317 | C15: 0 | D15: 0 | E15: 0 | F15: 0 | G15: 0 | H15: 0 | I15: 0 | J15: 0 | K15: 0 | L15: 0
A16: =+A15+1 -> 6 | B16: =+Base40h!B16 -> 44348 | C16: 0 | D16: 0 | E16: 0 | F16: 0 | G16: 0 | H16: 0 | I16: 0 | J16: 0 | K16: 0 | L16: 0
A17: =+A16+1 -> 7 | B17: =+Base40h!B17 -> 44378 | C17: 0 | D17: 0 | E17: 0 | F17: 0 | G17: 0 | H17: 0 | I17: 0 | J17: 0 | K17: 0 | L17: 0
A18: =+A17+1 -> 8 | B18: =+Base40h!B18 -> 44409 | C18: 0 | D18: 0 | E18: 0 | F18: 0 | G18: 0 | H18: 0 | I18: 0 | J18: 0 | K18: 0 | L18: 0
A19: =+A18+1 -> 9 | B19: =+Base40h!B19 -> 44440 | C19: 0 | D19: 0 | E19: 0 | F19: 0 | G19: 0 | H19: 0 | I19: 0 | J19: 0 | K19: 0 | L19: 0
A20: =+A19+1 -> 10 | B20: =+Base40h!B20 -> 44470 | C20: 0 | D20: 0 | E20: 0 | F20: 0 | G20: 0 | H20: 0 | I20: 0 | J20: 0 | K20: 0 | L20: 0
A21: =+A20+1 -> 11 | B21: =+Base40h!B21 -> 44501 | C21: 0 | D21: 0 | E21: 0 | F21: 0 | G21: 3.9 | H21: 0 | I21: 0 | J21: 0.3 | K21: 0.3 | L21: 2.5
A22: =+A21+1 -> 12 | B22: =+Base40h!B22 -> 44531 | C22: 4.5 | D22: 3.5 | E22: 2.1 | F22: 1.6 | G22: 14.1 | H22: 2.4 | I22: 5.9 | J22: 23.6 | K22: 8.4 | L22: 17.6
A23: =+A22+1 -> 13 | B23: Annual | C23: =SUM(C11:C22) -> 303.4 | D23: =SUM(D11:D22) -> 190.8 | E23: =SUM(E11:E22) -> 198.2 | F23: =SUM(F11:F22) -> 262.9 | G23: =SUM(G11:G22) -> 277.5 | H23: =SUM(H11:H22) -> 261.1 | I23: =SUM(I11:I22) -> 362.7 | J23: =SUM(J11:J22) -> 475.5 | ... L23: =SUM(L11:L22) -> 383.7
A24: =+A23+1 -> 14
A25: =+A24+1 -> 15
A26: =+A25+1 -> 16 | B26: Calendar Normal Heating Degree Days by Weather Sites (Base 45)
A27: =+A26+1 -> 17 | C27: Dallas/ Fort Worth (MX) | D27: Lufkin (LU) | E27: Austin (AU) | F27: Killeen (KI) | G27: Longview (LO) | H27: Waco (WO) | I27: Abilene (AE) | J27: Wichita Falls (WF) | K27: Midland/ Odessa (MO) | L27: Denison (DE)
A28: =+A27+1 -> 18 | B28: =+Base40h!B28 -> 44197 | C28: 94.3925 | D28: 64.134583 | E28: 51.95875 | F28: 69.138333 | G28: 91.707083 | H28: 79.694583 | I28: 120.59583 | J28: 160.25375 | K28: 116.05333 | L28: 146.52625
A29: =+A28+1 -> 19 | B29: =+Base40h!B29 -> 44228 | C29: 64.487917 | D29: 32.882917 | E29: 30.8425 | F29: 45.677083 | G29: 53.985417 | H29: 50.068333 | I29: 88.742083 | J29: 115.36625 | K29: 74.188333 | L29: 99.828333
A30: =+A29+1 -> 20 | B30: =+Base40h!B30 -> 44256 | C30: 14.125417 | D30: 6.315 | E30: 5.00625 | F30: 8.5725 | G30: 11.453333 | H30: 9.8583333 | I30: 19.604167 | J30: 26.457083 | K30: 17.26125 | L30: 23.472917
A31: =+A30+1 -> 21 | B31: =+Base40h!B31 -> 44287 | C31: 0.53583333 | D31: 0.37375 | E31: 0.4 | F31: 0.9325 | G31: 0.32166667 | H31: 0.65 | I31: 2.34625 | J31: 2.5533333 | K31: 1.44 | L31: 1.5775
A32: =+A31+1 -> 22 | B32: =+Base40h!B32 -> 44317 | C32: 0 | D32: 0 | E32: 0 | F32: 0 | G32: 0 | H32: 0 | I32: 0.01 | J32: 0.015 | K32: 0 | L32: 0
A33: =+A32+1 -> 23 | B33: =+Base40h!B33 -> 44348 | C33: 0 | D33: 0 | E33: 0 | F33: 0 | G33: 0 | H33: 0 | I33: 0 | J33: 0 | K33: 0 | L33: 0
A34: =+A33+1 -> 24 | B34: =+Base40h!B34 -> 44378 | C34: 0 | D34: 0 | E34: 0 | F34: 0 | G34: 0 | H34: 0 | I34: 0 | J34: 0 | K34: 0 | L34: 0
A35: =+A34+1 -> 25 | B35: =+Base40h!B35 -> 44409 | C35: 0 | D35: 0 | E35: 0 | F35: 0 | G35: 0 | H35: 0 | I35: 0 | J35: 0 | K35: 0 | L35: 0
A36: =+A35+1 -> 26 | B36: =+Base40h!B36 -> 44440 | C36: 0 | D36: 0 | E36: 0 | F36: 0 | G36: 0 | H36: 0 | I36: 0 | J36: 0 | K36: 0 | L36: 0
A37: =+A36+1 -> 27 | B37: =+Base40h!B37 -> 44470 | C37: 0.98 | D37: 0.155 | E37: 0.215 | F37: 0.83 | G37: 0.31 | H37: 0.675 | I37: 3.6191667 | J37: 3.56875 | K37: 3.5941667 | L37: 1.4
A38: =+A37+1 -> 28 | B38: =+Base40h!B38 -> 44501 | C38: 13.988333 | D38: 8.3916667 | E38: 7.4066667 | F38: 12.07125 | G38: 14.272917 | H38: 12.771667 | I38: 27.08 | J38: 30.873333 | K38: 27.917083 | L38: 20.366667
A39: =+A38+1 -> 29 | B39: =+Base40h!B39 -> 44531 | C39: 64.8225 | D39: 40.487083 | E39: 33.533333 | F39: 49.815 | G39: 61.520417 | H39: 55.47375 | I39: 105.96875 | J39: 136.73792 | K39: 106.67375 | L39: 103.21542
A40: =+A39+1 -> 30 | B40: Annual | C40: =SUM(C28:C39) -> 253.3325 | D40: =SUM(D28:D39) -> 152.74 | E40: =SUM(E28:E39) -> 129.3625 | F40: =SUM(F28:F39) -> 187.03667 | G40: =SUM(G28:G39) -> 233.57083 | H40: =SUM(H28:H39) -> 209.19167 | I40: =SUM(I28:I39) -> 367.96625 | J40: =SUM(J28:J39) -> 475.82542 | ... L40: =SUM(L28:L39) -> 396.38708

Sheet Base50h
B1: =+Base40h!B1 -> PUC DOCKET NO.
B2: =+Base40h!B2 -> ONCOR ELECTRIC DELIVERY COMPANY LLC
B3: =+Base40h!B3 -> WEATHER STATION DATA
B4: =+Base40h!B4 -> FOR THE TEST YEAR ENDING DECEMBER 31, 2021
B6: =+Base40h!B6 -> SPONSOR: D. E. NELSON
B9: Calendar Actual Cooling Degree Days by Weather Sites (Base 50)
A10: Line No. | C10: Dallas/ Fort Worth (MX) | D10: Lufkin (LU) | E10: Austin (AU) | F10: Killeen (KI) | G10: Longview (LO) | H10: Waco (WO) | I10: Abilene (AE) | J10: Wichita Falls (WF) | K10: Midland/ Odessa (MO) | L10: Denison (DE)
A11: 1 | B11: =+Base40h!B11 -> 44197 | C11: 124.2 | D11: 105.1 | E11: 73.8 | F11: 106.2 | G11: 143.2 | H11: 114.2 | I11: 169.1 | J11: 225.8 | K11: 225.3 | L11: 177.2
A12: =+A11+1 -> 2 | B12: =+Base40h!B12 -> 44228 | C12: 330.4 | D12: 204.8 | E12: 222.1 | F12: 276.7 | G12: 279.3 | H12: 281 | I12: 354.8 | J12: 443.4 | K12: 335.2 | L12: 377.6
A13: =+A12+1 -> 3 | B13: =+Base40h!B13 -> 44256 | C13: 0 | D13: 1.7 | E13: 0 | F13: 0.7 | G13: 4.4 | H13: 0.2 | I13: 8.6 | J13: 12 | K13: 21.6 | L13: 1.7
A14: =+A13+1 -> 4 | B14: =+Base40h!B14 -> 44287 | C14: 0 | D14: 0 | E14: 0 | F14: 0 | G14: 0.7 | H14: 0.3 | I14: 5.3 | J14: 5.4 | K14: 10.5 | L14: 3
A15: =+A14+1 -> 5 | B15: =+Base40h!B15 -> 44317 | C15: 0 | D15: 0 | E15: 0 | F15: 0 | G15: 0 | H15: 0 | I15: 0 | J15: 0 | K15: 0 | L15: 0
A16: =+A15+1 -> 6 | B16: =+Base40h!B16 -> 44348 | C16: 0 | D16: 0 | E16: 0 | F16: 0 | G16: 0 | H16: 0 | I16: 0 | J16: 0 | K16: 0 | L16: 0
A17: =+A16+1 -> 7 | B17: =+Base40h!B17 -> 44378 | C17: 0 | D17: 0 | E17: 0 | F17: 0 | G17: 0 | H17: 0 | I17: 0 | J17: 0 | K17: 0 | L17: 0
A18: =+A17+1 -> 8 | B18: =+Base40h!B18 -> 44409 | C18: 0 | D18: 0 | E18: 0 | F18: 0 | G18: 0 | H18: 0 | I18: 0 | J18: 0 | K18: 0 | L18: 0
A19: =+A18+1 -> 9 | B19: =+Base40h!B19 -> 44440 | C19: 0 | D19: 0 | E19: 0 | F19: 0 | G19: 0 | H19: 0 | I19: 0 | J19: 0 | K19: 0 | L19: 0
A20: =+A19+1 -> 10 | B20: =+Base40h!B20 -> 44470 | C20: 0 | D20: 0 | E20: 0 | F20: 0 | G20: 0 | H20: 0 | I20: 0 | J20: 0 | K20: 0 | L20: 0
A21: =+A20+1 -> 11 | B21: =+Base40h!B21 -> 44501 | C21: 7.1 | D21: 7.4 | E21: 1.9 | F21: 6.5 | G21: 28.5 | H21: 6.3 | I21: 9.6 | J21: 20.7 | K21: 22.9 | L21: 23.2
A22: =+A21+1 -> 12 | B22: =+Base40h!B22 -> 44531 | C22: 25.9 | D22: 20.9 | E22: 13.3 | F22: 14.1 | G22: 37.9 | H22: 19.8 | I22: 28.1 | J22: 72 | K22: 37.7 | L22: 53.4
A23: =+A22+1 -> 13 | B23: Annual | C23: =SUM(C11:C22) -> 487.6 | D23: =SUM(D11:D22) -> 339.9 | E23: =SUM(E11:E22) -> 311.1 | F23: =SUM(F11:F22) -> 404.2 | G23: =SUM(G11:G22) -> 494 | H23: =SUM(H11:H22) -> 421.8 | I23: =SUM(I11:I22) -> 575.5 | J23: =SUM(J11:J22) -> 779.3 | ... L23: =SUM(L11:L22) -> 636.1
A24: =+A23+1 -> 14
A25: =+A24+1 -> 15
A26: =+A25+1 -> 16 | B26: Calendar Normal Cooling Degree Days by Weather Sites (Base 50)
A27: =+A26+1 -> 17 | C27: Dallas/ Fort Worth (MX) | D27: Lufkin (LU) | E27: Austin (AU) | F27: Killeen (KI) | G27: Longview (LO) | H27: Waco (WO) | I27: Abilene (AE) | J27: Wichita Falls (WF) | K27: Midland/ Odessa (MO) | L27: Denison (DE)
A28: =+A27+1 -> 18 | B28: =+Base40h!B28 -> 44197 | C28: 176.15667 | D28: 137.08958 | E28: 115.21 | F28: 138.88042 | G28: 177.65458 | H28: 160.41167 | I28: 214.56625 | J28: 268.72167 | K28: 216.15917 | L28: 250.83292
A29: =+A28+1 -> 19 | B29: =+Base40h!B29 -> 44228 | C29: 123.71917 | D29: 77.6125 | E29: 70.7625 | F29: 92.99375 | G29: 112.39167 | H29: 103.86708 | I29: 156.41708 | J29: 196.17792 | K29: 139.09792 | L29: 176.73958
A30: =+A29+1 -> 20 | B30: =+Base40h!B30 -> 44256 | C30: 33.154583 | D30: 17.543333 | E30: 14.8 | F30: 22.646667 | G30: 28.805 | H30: 26.325833 | I30: 43.97625 | J30: 58.06875 | K30: 40.26 | L30: 52.845417
A31: =+A30+1 -> 21 | B31: =+Base40h!B31 -> 44287 | C31: 2.9125 | D31: 1.5904167 | E31: 1.125 | F31: 2.305 | G31: 2.3825 | H31: 2.3470833 | I31: 7.0770833 | J31: 9.7475 | K31: 5.1925 | L31: 7.2370833
A32: =+A31+1 -> 22 | B32: =+Base40h!B32 -> 44317 | C32: 0.06 | D32: 0 | E32: 0 | F32: 0.085 | G32: 0 | H32: 0 | I32: 0.26 | J32: 0.32541667 | K32: 0.455 | L32: 0.3375
A33: =+A32+1 -> 23 | B33: =+Base40h!B33 -> 44348 | C33: 0 | D33: 0 | E33: 0 | F33: 0 | G33: 0 | H33: 0 | I33: 0 | J33: 0 | K33: 0 | L33: 0
A34: =+A33+1 -> 24 | B34: =+Base40h!B34 -> 44378 | C34: 0 | D34: 0 | E34: 0 | F34: 0 | G34: 0 | H34: 0 | I34: 0 | J34: 0 | K34: 0 | L34: 0
A35: =+A34+1 -> 25 | B35: =+Base40h!B35 -> 44409 | C35: 0 | D35: 0 | E35: 0 | F35: 0 | G35: 0 | H35: 0 | I35: 0 | J35: 0 | K35: 0 | L35: 0
A36: =+A35+1 -> 26 | B36: =+Base40h!B36 -> 44440 | C36: 0 | D36: 0 | E36: 0 | F36: 0 | G36: 0 | H36: 0 | I36: 0 | J36: 0 | K36: 0.07 | L36: 0
A37: =+A36+1 -> 27 | B37: =+Base40h!B37 -> 44470 | C37: 3.3020833 | D37: 1.105 | E37: 1.045 | F37: 2.765 | G37: 1.8116667 | H37: 2.775 | I37: 9.2745833 | J37: 9.205 | K37: 8.6354167 | L37: 5.02875
A38: =+A37+1 -> 28 | B38: =+Base40h!B38 -> 44501 | C38: 34.4575 | D38: 28.715417 | E38: 24.178333 | F38: 31.548333 | G38: 40.593333 | H38: 34.036667 | I38: 60.42125 | J38: 69.022917 | K38: 63.99125 | L38: 51.802917
A39: =+A38+1 -> 29 | B39: =+Base40h!B39 -> 44531 | C39: 140.26708 | D39: 103.74583 | E39: 91.394583 | F39: 115.09667 | G39: 139.90708 | H39: 128.92208 | I39: 191.4175 | J39: 238.015 | K39: 200.04833 | L39: 194.68875
A40: =+A39+1 -> 30 | B40: Annual | C40: =SUM(C28:C39) -> 514.02958 | D40: =SUM(D28:D39) -> 367.40208 | E40: =SUM(E28:E39) -> 318.51542 | F40: =SUM(F28:F39) -> 406.32083 | G40: =SUM(G28:G39) -> 503.54583 | H40: =SUM(H28:H39) -> 458.68542 | I40: =SUM(I28:I39) -> 683.41 | J40: =SUM(J28:J39) -> 849.28417 | ... L40: =SUM(L28:L39) -> 739.51292
Z44: =MONTH(B44)&YEAR(B44) -> 11900
Z45: =MONTH(B45)&YEAR(B45) -> 11900
Z46: =MONTH(B46)&YEAR(B46) -> 11900
...

Sheet Base55h
B1: =+Base40h!B1 -> PUC DOCKET NO.
B2: =+Base40h!B2 -> ONCOR ELECTRIC DELIVERY COMPANY LLC
B3: =+Base40h!B3 -> WEATHER STATION DATA
B4: =+Base40h!B4 -> FOR THE TEST YEAR ENDING DECEMBER 31, 2021
B6: =+Base40h!B6 -> SPONSOR: D. E. NELSON
B9: Calendar Actual Cooling Degree Days by Weather Sites (Base 55)
A10: Line No. | C10: Dallas/ Fort Worth (MX) | D10: Lufkin (LU) | E10: Austin (AU) | F10: Killeen (KI) | G10: Longview (LO) | H10: Waco (WO) | I10: Abilene (AE) | J10: Wichita Falls (WF) | K10: Midland/ Odessa (MO) | L10: Denison (DE)
A11: 1 | B11: =+Base40h!B11 -> 44197 | C11: 255.4 | D11: 197.2 | E11: 149.5 | F11: 206.6 | G11: 270 | H11: 226.3 | I11: 305.6 | J11: 372.6 | K11: 364.8 | L11: 320.2
A12: =+A11+1 -> 2 | B12: =+Base40h!B12 -> 44228 | C12: 430 | D12: 289.3 | E12: 290.3 | F12: 365.1 | G12: 385 | H12: 373.4 | I12: 450.3 | J12: 558.4 | K12: 430.6 | L12: 489.1
A13: =+A12+1 -> 3 | B13: =+Base40h!B13 -> 44256 | C13: 18.1 | D13: 29 | E13: 6.7 | F13: 20 | G13: 47.6 | H13: 26.4 | I13: 37.1 | J13: 54.9 | K13: 60.1 | L13: 27.6
A14: =+A13+1 -> 4 | B14: =+Base40h!B14 -> 44287 | C14: 4.7 | D14: 5.6 | E14: 4.8 | F14: 7.2 | G14: 16.8 | H14: 8.4 | I14: 25.9 | J14: 34.6 | K14: 42.4 | L14: 21.9
A15: =+A14+1 -> 5 | B15: =+Base40h!B15 -> 44317 | C15: 0 | D15: 0 | E15: 0 | F15: 0 | G15: 0 | H15: 0 | I15: 0 | J15: 0 | K15: 0 | L15: 0
A16: =+A15+1 -> 6 | B16: =+Base40h!B16 -> 44348 | C16: 0 | D16: 0 | E16: 0 | F16: 0 | G16: 0 | H16: 0 | I16: 0 | J16: 0 | K16: 0 | L16: 0
A17: =+A16+1 -> 7 | B17: =+Base40h!B17 -> 44378 | C17: 0 | D17: 0 | E17: 0 | F17: 0 | G17: 0 | H17: 0 | I17: 0 | J17: 0 | K17: 0 | L17: 0
A18: =+A17+1 -> 8 | B18: =+Base40h!B18 -> 44409 | C18: 0 | D18: 0 | E18: 0 | F18: 0 | G18: 0 | H18: 0 | I18: 0 | J18: 0 | K18: 0 | L18: 0
A19: =+A18+1 -> 9 | B19: =+Base40h!B19 -> 44440 | C19: 0 | D19: 0 | E19: 0 | F19: 0 | G19: 0 | H19: 0 | I19: 0 | J19: 0 | K19: 0 | L19: 0
A20: =+A19+1 -> 10 | B20: =+Base40h!B20 -> 44470 | C20: 0 | D20: 0 | E20: 0 | F20: 0 | G20: 0 | H20: 0 | I20: 0 | J20: 0 | K20: 0.2 | L20: 0.5
A21: =+A20+1 -> 11 | B21: =+Base40h!B21 -> 44501 | C21: 44.5 | D21: 53.1 | E21: 35.3 | F21: 42.9 | G21: 79.2 | H21: 47.6 | I21: 55.4 | J21: 85 | K21: 73.3 | L21: 86.6
A22: =+A21+1 -> 12 | B22: =+Base40h!B22 -> 44531 | C22: 67.6 | D22: 49.8 | E22: 39 | F22: 44.7 | G22: 81.1 | H22: 51.8 | I22: 72.9 | J22: 127 | K22: 83.8 | L22: 103.7
A23: =+A22+1 -> 13 | B23: Annual | C23: =SUM(C11:C22) -> 820.3 | D23: =SUM(D11:D22) -> 624 | E23: =SUM(E11:E22) -> 525.6 | F23: =SUM(F11:F22) -> 686.5 | G23: =SUM(G11:G22) -> 879.7 | H23: =SUM(H11:H22) -> 733.9 | I23: =SUM(I11:I22) -> 947.2 | J23: =SUM(J11:J22) -> 1232.5 | ... L23: =SUM(L11:L22) -> 1049.6
A24: =+A23+1 -> 14
A25: =+A24+1 -> 15
A26: =+A25+1 -> 16 | B26: Calendar Normal Cooling Degree Days by Weather Sites (Base 55)
A27: =+A26+1 -> 17 | C27: Dallas/ Fort Worth (MX) | D27: Lufkin (LU) | E27: Austin (AU) | F27: Killeen (KI) | G27: Longview (LO) | H27: Waco (WO) | I27: Abilene (AE) | J27: Wichita Falls (WF) | K27: Midland/ Odessa (MO) | L27: Denison (DE)
A28: =+A27+1 -> 18 | B28: =+Base40h!B28 -> 44197 | C28: 289.56083 | D28: 237.87625 | E28: 211.74 | F28: 240.79917 | G28: 287.72125 | H28: 271.49125 | I28: 332.82208 | J28: 400.49167 | K28: 342.01875 | L28: 377.145
A29: =+A28+1 -> 19 | B29: =+Base40h!B29 -> 44228 | C29: 207.96542 | D29: 147.835 | E29: 135.40917 | F29: 165.83708 | G29: 196.53083 | H29: 182.65833 | I29: 245.205 | J29: 299.75458 | K29: 227.67417 | L29: 274.65375
A30: =+A29+1 -> 20 | B30: =+Base40h!B30 -> 44256 | C30: 69.079167 | D30: 46.106667 | E30: 40.985417 | F30: 52.040833 | G30: 66.74625 | H30: 60.724583 | I30: 90.530833 | J30: 113.99667 | K30: 85.0475 | L30: 107.85375
A31: =+A30+1 -> 21 | B31: =+Base40h!B31 -> 44287 | C31: 10.954583 | D31: 5.8816667 | E31: 4.08 | F31: 7.41625 | G31: 9.8995833 | H31: 8.8733333 | I31: 19.83625 | J31: 24.455833 | K31: 15.49 | L31: 21.653333
A32: =+A31+1 -> 22 | B32: =+Base40h!B32 -> 44317 | C32: 0.63375 | D32: 0.05 | E32: 0.155 | F32: 0.46 | G32: 0.34 | H32: 0.415 | I32: 1.7795833 | J32: 2.0083333 | K32: 1.9283333 | L32: 2.3475
A33: =+A32+1 -> 23 | B33: =+Base40h!B33 -> 44348 | C33: 0 | D33: 0 | E33: 0 | F33: 0 | G33: 0 | H33: 0 | I33: 0 | J33: 0 | K33: 0 | L33: 0
A34: =+A33+1 -> 24 | B34: =+Base40h!B34 -> 44378 | C34: 0 | D34: 0 | E34: 0 | F34: 0 | G34: 0 | H34: 0 | I34: 0 | J34: 0 | K34: 0 | L34: 0
A35: =+A34+1 -> 25 | B35: =+Base40h!B35 -> 44409 | C35: 0 | D35: 0 | E35: 0 | F35: 0 | G35: 0 | H35: 0 | I35: 0 | J35: 0 | K35: 0 | L35: 0
A36: =+A35+1 -> 26 | B36: =+Base40h!B36 -> 44440 | C36: 0 | D36: 0 | E36: 0 | F36: 0 | G36: 0 | H36: 0 | I36: 0.35 | J36: 0.075 | K36: 0.69 | L36: 0
A37: =+A36+1 -> 27 | B37: =+Base40h!B37 -> 44470 | C37: 9.45375 | D37: 5.2008333 | E37: 4.7133333 | F37: 8.2666667 | G37: 9.7175 | H37: 8.5229167 | I37: 23.305417 | J37: 24.138333 | K37: 21.615833 | L37: 16.919583
A38: =+A37+1 -> 28 | B38: =+Base40h!B38 -> 44501 | C38: 77.803333 | D38: 70.17125 | E38: 58.626667 | F38: 71.315417 | G38: 91.634167 | H38: 76.76875 | I38: 116.2775 | J38: 135.31125 | K38: 125.77625 | L38: 107.54417
A39: =+A38+1 -> 29 | B39: =+Base40h!B39 -> 44531 | C39: 242.80042 | D39: 196.65542 | E39: 180.095 | F39: 210.93667 | G39: 243.44417 | H39: 230.64583 | I39: 301.31833 | J39: 365.3925 | K39: 323.65375 | L39: 310.85083
A40: =+A39+1 -> 30 | B40: Annual | C40: =SUM(C28:C39) -> 908.25125 | D40: =SUM(D28:D39) -> 709.77708 | E40: =SUM(E28:E39) -> 635.80458 | F40: =SUM(F28:F39) -> 757.07208 | G40: =SUM(G28:G39) -> 906.03375 | H40: =SUM(H28:H39) -> 840.1 | I40: =SUM(I28:I39) -> 1131.425 | J40: =SUM(J28:J39) -> 1365.6242 | ... L40: =SUM(L28:L39) -> 1218.9679
Z44: =MONTH(B44)&YEAR(B44) -> 11900
Z45: =MONTH(B45)&YEAR(B45) -> 11900
Z46: =MONTH(B46)&YEAR(B46) -> 11900
...

Sheet Base60h
B1: =+Base40h!B1 -> PUC DOCKET NO.
B2: =+Base40h!B2 -> ONCOR ELECTRIC DELIVERY COMPANY LLC
B3: =+Base40h!B3 -> WEATHER STATION DATA
B4: =+Base40h!B4 -> FOR THE TEST YEAR ENDING DECEMBER 31, 2021
B6: =+Base40h!B6 -> SPONSOR: D. E. NELSON
B9: Calendar Actual Heating Degree Days by Weather Sites (Base 60)
A10: Line No. | C10: Dallas/ Fort Worth (MX) | D10: Lufkin (LU) | E10: Austin (AU) | F10: Killeen (KI) | G10: Longview (LO) | H10: Waco (WO) | I10: Abilene (AE) | J10: Wichita Falls (WF) | K10: Midland/ Odessa (MO) | L10: Denison (DE)
A11: 1 | B11: =+Base40h!B11 -> 44197 | C11: 400.4 | D11: 317.9 | E11: 257.2 | F11: 344.1 | G11: 417.1 | H11: 364.2 | I11: 450.9 | J11: 523.3 | K11: 515.3 | L11: 469.5
A12: =+A11+1 -> 2 | B12: =+Base40h!B12 -> 44228 | C12: 547.3 | D12: 392 | E12: 391.8 | F12: 470.9 | G12: 501.8 | H12: 481.8 | I12: 568.6 | J12: 696.6 | K12: 550.2 | L12: 614.5
A13: =+A12+1 -> 3 | B13: =+Base40h!B13 -> 44256 | C13: 66.1 | D13: 88.4 | E13: 44.3 | F13: 63.8 | G13: 111.5 | H13: 73.6 | I13: 107.7 | J13: 138.7 | K13: 140.8 | L13: 95.7
A14: =+A13+1 -> 4 | B14: =+Base40h!B14 -> 44287 | C14: 31.5 | D14: 35.6 | E14: 34.7 | F14: 37.5 | G14: 59.8 | H14: 37.8 | I14: 79 | J14: 89 | K14: 103 | L14: 72.1
A15: =+A14+1 -> 5 | B15: =+Base40h!B15 -> 44317 | C15: 3.2 | D15: 0 | E15: 0 | F15: 0.1 | G15: 0.8 | H15: 0 | I15: 8.5 | J15: 11 | K15: 3.2 | L15: 10.2
A16: =+A15+1 -> 6 | B16: =+Base40h!B16 -> 44348 | C16: 0 | D16: 0 | E16: 0 | F16: 0 | G16: 0 | H16: 0 | I16: 0 | J16: 0 | K16: 0 | L16: 0
A17: =+A16+1 -> 7 | B17: =+Base40h!B17 -> 44378 | C17: 0 | D17: 0 | E17: 0 | F17: 0 | G17: 0 | H17: 0 | I17: 0 | J17: 0 | K17: 0 | L17: 0
A18: =+A17+1 -> 8 | B18: =+Base40h!B18 -> 44409 | C18: 0 | D18: 0 | E18: 0 | F18: 0 | G18: 0 | H18: 0 | I18: 0 | J18: 0 | K18: 0 | L18: 0
A19: =+A18+1 -> 9 | B19: =+Base40h!B19 -> 44440 | C19: 0 | D19: 0 | E19: 0 | F19: 0 | G19: 0 | H19: 0 | I19: 0 | J19: 0 | K19: 0 | L19: 0
A20: =+A19+1 -> 10 | B20: =+Base40h!B20 -> 44470 | C20: 0 | D20: 5.1 | E20: 2.1 | F20: 2.3 | G20: 7.3 | H20: 4.3 | I20: 6.2 | J20: 12 | K20: 14.6 | L20: 11.1
A21: =+A20+1 -> 11 | B21: =+Base40h!B21 -> 44501 | C21: 125.1 | D21: 133.5 | E21: 109.6 | F21: 121.4 | G21: 171.4 | H21: 124.1 | I21: 134.5 | J21: 186 | K21: 169.5 | L21: 179
A22: =+A21+1 -> 12 | B22: =+Base40h!B22 -> 44531 | C22: 122.6 | D22: 93.2 | E22: 78.1 | F22: 92.7 | G22: 127.6 | H22: 101.9 | I22: 126.3 | J22: 211.2 | K22: 169.1 | L22: 164
A23: =+A22+1 -> 13 | B23: Annual | C23: =SUM(C11:C22) -> 1296.2 | D23: =SUM(D11:D22) -> 1065.7 | E23: =SUM(E11:E22) -> 917.8 | F23: =SUM(F11:F22) -> 1132.8 | G23: =SUM(G11:G22) -> 1397.3 | H23: =SUM(H11:H22) -> 1187.7 | I23: =SUM(I11:I22) -> 1481.7 | J23: =SUM(J11:J22) -> 1867.8 | ... L23: =SUM(L11:L22) -> 1616.1
A24: =+A23+1 -> 14
A25: =+A24+1 -> 15
A26: =+A25+1 -> 16 | B26: Calendar Normal Heating Degree Days by Weather Sites (Base 60)
A27: =+A26+1 -> 17 | C27: Dallas/ Fort Worth (MX) | D27: Lufkin (LU) | E27: Austin (AU) | F27: Killeen (KI) | G27: Longview (LO) | H27: Waco (WO) | I27: Abilene (AE) | J27: Wichita Falls (WF) | K27: Midland/ Odessa (MO) | L27: Denison (DE)
A28: =+A27+1 -> 18 | B28: =+Base40h!B28 -> 44197 | C28: 422.05 | D28: 358.51958 | E28: 333.15625 | F28: 365.81875 | G28: 416.26125 | H28: 401.88708 | I28: 469.92042 | J28: 543.745 | K28: 488.29875 | L28: 517.65375
A29: =+A28+1 -> 19 | B29: =+Base40h!B29 -> 44228 | C29: 311.41875 | D29: 240.46667 | E29: 224.87625 | F29: 260.35458 | G29: 299.57375 | H29: 283.05208 | I29: 352.43792 | J29: 418.81333 | K29: 339.43 | L29: 390.84667
A30: =+A29+1 -> 20 | B30: =+Base40h!B30 -> 44256 | C30: 133.27792 | D30: 100.0925 | E30: 90.1375 | F30: 107.80833 | G30: 133.90208 | H30: 121.6575 | I30: 165.19958 | J30: 201.70125 | K30: 159.39875 | L30: 193.21917
A31: =+A30+1 -> 21 | B31: =+Base40h!B31 -> 44287 | C31: 28.71625 | D31: 19.366667 | E31: 15.212083 | F31: 22.008333 | G31: 29.399583 | H31: 25.416667 | I31: 46.258333 | J31: 57.04625 | K31: 38.06125 | L31: 55.709167
A32: =+A31+1 -> 22 | B32: =+Base40h!B32 -> 44317 | C32: 2.9775 | D32: 0.69958333 | E32: 0.85708333 | F32: 1.98875 | G32: 1.8908333 | H32: 1.9458333 | I32: 6.90375 | J32: 7.33375 | K32: 6.8316667 | L32: 7.57125
A33: =+A32+1 -> 23 | B33: =+Base40h!B33 -> 44348 | C33: 0 | D33: 0 | E33: 0 | F33: 0 | G33: 0 | H33: 0 | I33: 0 | J33: 0 | K33: 0 | L33: 0
A34: =+A33+1 -> 24 | B34: =+Base40h!B34 -> 44378 | C34: 0 | D34: 0 | E34: 0 | F34: 0 | G34: 0 | H34: 0 | I34: 0 | J34: 0 | K34: 0 | L34: 0
A35: =+A34+1 -> 25 | B35: =+Base40h!B35 -> 44409 | C35: 0 | D35: 0 | E35: 0 | F35: 0 | G35: 0 | H35: 0 | I35: 0 | J35: 0 | K35: 0 | L35: 0
A36: =+A35+1 -> 26 | B36: =+Base40h!B36 -> 44440 | C36: 0 | D36: 0 | E36: 0 | F36: 0.04 | G36: 0.014583333 | H36: 0 | I36: 1.1208333 | J36: 0.635 | K36: 1.705 | L36: 0.020416667
A37: =+A36+1 -> 27 | B37: =+Base40h!B37 -> 44470 | C37: 27.217083 | D37: 23.285833 | E37: 18.54 | F37: 24.920417 | G37: 33.739583 | H37: 26.334167 | I37: 50.305417 | J37: 57.410833 | K37: 48.0175 | L37: 47.377917
A38: =+A37+1 -> 28 | B38: =+Base40h!B38 -> 44501 | C38: 148.22792 | D38: 139.53 | E38: 120.18625 | F38: 136.95792 | G38: 169.98792 | H38: 145.605 | I38: 199.66625 | J38: 230.91625 | K38: 221.16375 | L38: 190.95042
A39: =+A38+1 -> 29 | B39: =+Base40h!B39 -> 44531 | C39: 368.51167 | D39: 311.00875 | E39: 292.84875 | F39: 328.21917 | G39: 364.96333 | H39: 352.45625 | I39: 435.15333 | J39: 509.58375 | K39: 466.97417 | L39: 447.11542
A40: =+A39+1 -> 30 | B40: Annual | C40: =SUM(C28:C39) -> 1442.3971 | D40: =SUM(D28:D39) -> 1192.9696 | E40: =SUM(E28:E39) -> 1095.8142 | F40: =SUM(F28:F39) -> 1248.1163 | G40: =SUM(G28:G39) -> 1449.7329 | H40: =SUM(H28:H39) -> 1358.3546 | I40: =SUM(I28:I39) -> 1726.9658 | J40: =SUM(J28:J39) -> 2027.1854 | ... L40: =SUM(L28:L39) -> 1850.4642

Sheet Base65h
B1: =+Base40h!B1 -> PUC DOCKET NO.
B2: =+Base40h!B2 -> ONCOR ELECTRIC DELIVERY COMPANY LLC
B3: =+Base40h!B3 -> WEATHER STATION DATA
B4: =+Base40h!B4 -> FOR THE TEST YEAR ENDING DECEMBER 31, 2021
B6: =+Base40h!B6 -> SPONSOR: D. E. NELSON
B9: Calendar Actual Heating Degree Days by Weather Sites (Base 65)
A10: Line No. | C10: Dallas/ Fort Worth (MX) | D10: Lufkin (LU) | E10: Austin (AU) | F10: Killeen (KI) | G10: Longview (LO) | H10: Waco (WO) | I10: Abilene (AE) | J10: Wichita Falls (WF) | K10: Midland/ Odessa (MO) | L10: Denison (DE)
A11: 1 | B11: =+Base40h!B11 -> 44197 | C11: 553 | D11: 464.7 | E11: 392.3 | F11: 487.5 | G11: 567.8 | H11: 510.5 | I11: 605.3 | J11: 678.3 | K11: 670.3 | L11: 624.5
A12: =+A11+1 -> 2 | B12: =+Base40h!B12 -> 44228 | C12: 679.4 | D12: 508.7 | E12: 511.6 | F12: 590.8 | G12: 631.8 | H12: 605 | I12: 699.8 | J12: 836.6 | K12: 687.3 | L12: 752.2
A13: =+A12+1 -> 3 | B13: =+Base40h!B13 -> 44256 | C13: 156.4 | D13: 161.8 | E13: 115.3 | F13: 154.4 | G13: 210.7 | H13: 165.4 | I13: 205.8 | J13: 254.9 | K13: 249.5 | L13: 205.1
A14: =+A13+1 -> 4 | B14: =+Base40h!B14 -> 44287 | C14: 86.3 | D14: 87.8 | E14: 86.8 | F14: 92.8 | G14: 125.5 | H14: 94.2 | I14: 159.9 | J14: 178 | K14: 186.3 | L14: 149.5
A15: =+A14+1 -> 5 | B15: =+Base40h!B15 -> 44317 | C15: 18.2 | D15: 2 | E15: 1.8 | F15: 10.3 | G15: 11.2 | H15: 8.4 | I15: 30.1 | J15: 35.8 | K15: 25.3 | L15: 33.8
A16: =+A15+1 -> 6 | B16: =+Base40h!B16 -> 44348 | C16: 0 | D16: 0 | E16: 0 | F16: 0 | G16: 0 | H16: 0 | I16: 0 | J16: 0 | K16: 0 | L16: 0
A17: =+A16+1 -> 7 | B17: =+Base40h!B17 -> 44378 | C17: 0 | D17: 0 | E17: 0 | F17: 0 | G17: 0 | H17: 0 | I17: 0 | J17: 0 | K17: 0 | L17: 0
A18: =+A17+1 -> 8 | B18: =+Base40h!B18 -> 44409 | C18: 0 | D18: 0 | E18: 0 | F18: 0 | G18: 0 | H18: 0 | I18: 0 | J18: 0 | K18: 0 | L18: 0
A19: =+A18+1 -> 9 | B19: =+Base40h!B19 -> 44440 | C19: 0 | D19: 0 | E19: 0 | F19: 0 | G19: 0 | H19: 0 | I19: 0 | J19: 0 | K19: 0 | L19: 0
A20: =+A19+1 -> 10 | B20: =+Base40h!B20 -> 44470 | C20: 16.7 | D20: 31 | E20: 25.6 | F20: 24.2 | G20: 37.3 | H20: 29.4 | I20: 35.7 | J20: 52.9 | K20: 52.9 | L20: 44.1
A21: =+A20+1 -> 11 | B21: =+Base40h!B21 -> 44501 | C21: 238.5 | D21: 248.8 | E21: 216.9 | F21: 227.6 | G21: 295.5 | H21: 231.4 | I21: 245.9 | J21: 317.4 | K21: 295.1 | L21: 305.2
A22: =+A21+1 -> 12 | B22: =+Base40h!B22 -> 44531 | C22: 191.1 | D22: 153.3 | E22: 144.6 | F22: 153.7 | G22: 195.5 | H22: 167.2 | I22: 208.6 | J22: 332.5 | K22: 293 | L22: 248.7
A23: =+A22+1 -> 13 | B23: Annual | C23: =SUM(C11:C22) -> 1939.6 | D23: =SUM(D11:D22) -> 1658.1 | E23: =SUM(E11:E22) -> 1494.9 | F23: =SUM(F11:F22) -> 1741.3 | G23: =SUM(G11:G22) -> 2075.3 | H23: =SUM(H11:H22) -> 1811.5 | I23: =SUM(I11:I22) -> 2191.1 | J23: =SUM(J11:J22) -> 2686.4 | ... L23: =SUM(L11:L22) -> 2363.1
A24: =+A23+1 -> 14
A25: =+A24+1 -> 15
A26: =+A25+1 -> 16 | B26: Calendar Normal Heating Degree Days by Weather Sites (Base 65)
A27: =+A26+1 -> 17 | C27: Dallas/ Fort Worth (MX) | D27: Lufkin (LU) | E27: Austin (AU) | F27: Killeen (KI) | G27: Longview (LO) | H27: Waco (WO) | I27: Abilene (AE) | J27: Wichita Falls (WF) | K27: Midland/ Odessa (MO) | L27: Denison (DE)
A28: =+A27+1 -> 18 | B28: =+Base40h!B28 -> 44197 | C28: 566.79167 | D28: 495.52875 | E28: 470.44167 | F28: 506.27875 | G28: 558.14375 | H28: 545.70667 | I28: 618.85708 | J28: 695.58625 | K28: 642.16458 | L28: 666.91375
A29: =+A28+1 -> 19 | B29: =+Base40h!B29 -> 44228 | C29: 430.95167 | D29: 353.00333 | E29: 334.22125 | F29: 373.92417 | G29: 420.02917 | H29: 401.7625 | I29: 476.39958 | J29: 550.77667 | K29: 468.56292 | L29: 519.885
A30: =+A29+1 -> 20 | B30: =+Base40h!B30 -> 44256 | C30: 227.32167 | D30: 186.77208 | E30: 170.67333 | F30: 195.14542 | G30: 232.28375 | H30: 213.16458 | I30: 267.49083 | J30: 314.52125 | K30: 261.92875 | L30: 306.66625
A31: =+A30+1 -> 21 | B31: =+Base40h!B31 -> 44287 | C31: 66.95875 | D31: 52.867917 | E31: 42.144167 | F31: 55.312917 | G31: 73.14375 | H31: 63.385 | I31: 97.125833 | J31: 117.465 | K31: 81.672917 | L31: 116.63875
A32: =+A31+1 -> 22 | B32: =+Base40h!B32 -> 44317 | C32: 10.463333 | D32: 5.24 | E32: 4.48875 | F32: 7.5554167 | G32: 10.41 | H32: 8.4120833 | I32: 21.141667 | J32: 24.033333 | K32: 18.655417 | L32: 24.057917
A33: =+A32+1 -> 23 | B33: =+Base40h!B33 -> 44348 | C33: 0 | D33: 0 | E33: 0 | F33: 0 | G33: 0 | H33: 0 | I33: 0 | J33: 0 | K33: 0 | L33: 0
A34: =+A33+1 -> 24 | B34: =+Base40h!B34 -> 44378 | C34: 0 | D34: 0 | E34: 0 | F34: 0 | G34: 0 | H34: 0 | I34: 0 | J34: 0 | K34: 0.0875 | L34: 0
A35: =+A34+1 -> 25 | B35: =+Base40h!B35 -> 44409 | C35: 0 | D35: 0 | E35: 0 | F35: 0 | G35: 0 | H35: 0 | I35: 0 | J35: 0 | K35: 0 | L35: 0
A36: =+A35+1 -> 26 | B36: =+Base40h!B36 -> 44440 | C36: 0.57 | D36: 0.715 | E36: 0.87291667 | F36: 0.9725 | G36: 1.2675 | H36: 0.76333333 | I36: 5.3295833 | J36: 4.3554167 | K36: 6.345 | L36: 2.5229167
A37: =+A36+1 -> 27 | B37: =+Base40h!B37 -> 44470 | C37: 66.47 | D37: 61.117083 | E37: 50.815417 | F37: 60.362917 | G37: 82.42625 | H37: 64.225 | I37: 103.22208 | J37: 119.99917 | K37: 99.53125 | L37: 104.39625
A38: =+A37+1 -> 28 | B38: =+Base40h!B38 -> 44501 | C38: 248.14583 | D38: 235.93083 | E38: 209.74667 | F38: 231.74708 | G38: 277.64708 | H38: 243.3775 | I38: 312.58875 | J38: 353.61875 | K38: 345.30167 | L38: 304.16875
A39: =+A38+1 -> 29 | B39: =+Base40h!B39 -> 44531 | C39: 510.84333 | D39: 442.82 | E39: 423.94583 | F39: 465.82875 | G39: 503.35667 | H39: 493.19167 | I39: 582.505 | J39: 660.83583 | K39: 619.83875 | L39: 595.30125
A40: =+A39+1 -> 30 | B40: Annual | C40: =SUM(C28:C39) -> 2128.5162 | D40: =SUM(D28:D39) -> 1833.995 | E40: =SUM(E28:E39) -> 1707.35 | F40: =SUM(F28:F39) -> 1897.1279 | G40: =SUM(G28:G39) -> 2158.7079 | H40: =SUM(H28:H39) -> 2033.9883 | I40: =SUM(I28:I39) -> 2484.6604 | J40: =SUM(J28:J39) -> 2841.1917 | ... L40: =SUM(L28:L39) -> 2640.5508

Sheet Base50c
B1: =+Base40h!B1 -> PUC DOCKET NO.
B2: =+Base40h!B2 -> ONCOR ELECTRIC DELIVERY COMPANY LLC
B3: =+Base40h!B3 -> WEATHER STATION DATA
B4: =+Base40h!B4 -> FOR THE TEST YEAR ENDING DECEMBER 31, 2021
B6: =+Base40h!B6 -> SPONSOR: D. E. NELSON
B9: Calendar Actual Cooling Degree Days by Weather Sites (Base 50)
A10: Line No. | C10: Dallas/ Fort Worth (MX) | D10: Lufkin (LU) | E10: Austin (AU) | F10: Killeen (KI) | G10: Longview (LO) | H10: Waco (WO) | I10: Abilene (AE) | J10: Wichita Falls (WF) | K10: Midland/ Odessa (MO) | L10: Denison (DE)
A11: 1 | B11: =+Base40h!B11 -> 44197 | C11: 36.2 | D11: 108.7 | E11: 149.3 | F11: 83.9 | G11: 40.4 | H11: 68.7 | I11: 28.8 | J11: 12.5 | K11: 20 | L11: 17.7
A12: =+A11+1 -> 2 | B12: =+Base40h!B12 -> 44228 | C12: 71 | D12: 133.8 | E12: 149.2 | F12: 109.2 | G12: 73.8 | H12: 97.5 | I12: 75 | J12: 26.8 | K12: 67.9 | L12: 45.4
A13: =+A12+1 -> 3 | B13: =+Base40h!B13 -> 44256 | C13: 346.8 | D13: 357.6 | E13: 406.1 | F13: 346.4 | G13: 291.5 | H13: 337.4 | I13: 285 | J13: 235.3 | K13: 249 | L13: 282.7
A14: =+A13+1 -> 4 | B14: =+Base40h!B14 -> 44287 | C14: 441.9 | D14: 456.8 | E14: 462.4 | F14: 450.7 | G14: 381.9 | H14: 449 | I14: 369.3 | J14: 313.7 | K14: 346.7 | L14: 338.2
A15: =+A14+1 -> 5 | B15: =+Base40h!B15 -> 44317 | C15: 656.1 | D15: 699.6 | E15: 678.9 | F15: 652.6 | G15: 624.9 | H15: 676.1 | I15: 614.8 | J15: 568.4 | K15: 646.5 | L15: 560.4
A16: =+A15+1 -> 6 | B16: =+Base40h!B16 -> 44348 | C16: 957 | D16: 930.2 | E16: 888.4 | F16: 897.1 | G16: 876.9 | H16: 934.4 | I16: 894.2 | J16: 870.8 | K16: 890.4 | L16: 878.8
A17: =+A16+1 -> 7 | B17: =+Base40h!B17 -> 44378 | C17: 1067.6 | D17: 972.2 | E17: 925 | F17: 952.8 | G17: 939.8 | H17: 1004.8 | I17: 983.4 | J17: 980.7 | K17: 897.2 | L17: 988.2
A18: =+A17+1 -> 8 | B18: =+Base40h!B18 -> 44409 | C18: 1074.4 | D18: 1024.9 | E18: 974.1 | F18: 1025.9 | G18: 964.3 | H18: 1055 | I18: 1019.6 | J18: 998.4 | K18: 900.2 | L18: 993.3
A19: =+A18+1 -> 9 | B19: =+Base40h!B19 -> 44440 | C19: 914.4 | D19: 840.7 | E19: 841.6 | F19: 880.8 | G19: 783.1 | H19: 886 | I19: 875.9 | J19: 842.2 | K19: 825.4 | L19: 836
A20: =+A19+1 -> 10 | B20: =+Base40h!B20 -> 44470 | C20: 675.3 | D20: 678.5 | E20: 651.1 | F20: 651.4 | G20: 641.7 | H20: 661.5 | I20: 615.2 | J20: 551.9 | K20: 566.1 | L20: 562.6
A21: =+A20+1 -> 11 | B21: =+Base40h!B21 -> 44501 | C21: 231.3 | D21: 218.5 | E21: 252.1 | F21: 242.4 | G21: 193.5 | H21: 243.1 | I21: 223.8 | J21: 157.7 | K21: 179.1 | L21: 173.2
A22: =+A21+1 -> 12 | B22: =+Base40h!B22 -> 44531 | C22: 357.3 | D22: 435.4 | E22: 403.9 | F22: 393.4 | G22: 386.9 | H22: 394.7 | I22: 324.8 | J22: 223.9 | K22: 213.4 | L22: 294.5
A23: =+A22+1 -> 13 | B23: Annual | C23: =SUM(C11:C22) -> 6829.3 | D23: =SUM(D11:D22) -> 6856.9 | E23: =SUM(E11:E22) -> 6782.1 | F23: =SUM(F11:F22) -> 6686.6 | G23: =SUM(G11:G22) -> 6198.7 | H23: =SUM(H11:H22) -> 6808.2 | I23: =SUM(I11:I22) -> 6309.8 | J23: =SUM(J11:J22) -> 5782.3 | ... L23: =SUM(L11:L22) -> 5971
A24: =+A23+1 -> 14
A25: =+A24+1 -> 15
A26: =+A25+1 -> 16 | B26: Calendar Normal Cooling Degree Days by Weather Sites (Base 50)
A27: =+A26+1 -> 17 | C27: Dallas/ Fort Worth (MX) | D27: Lufkin (LU) | E27: Austin (AU) | F27: Killeen (KI) | G27: Longview (LO) | H27: Waco (WO) | I27: Abilene (AE) | J27: Wichita Falls (WF) | K27: Midland/ Odessa (MO) | L27: Denison (DE)
A28: =+A27+1 -> 18 | B28: =+Base40h!B28 -> 44197 | C28: 77.799583 | D28: 115.20167 | E28: 117.70917 | F28: 102.36708 | G28: 89.903333 | H28: 83.234583 | I28: 61.088333 | J28: 38.63875 | K28: 38.994583 | L28: 49.829583
A29: =+A28+1 -> 19 | B29: =+Base40h!B29 -> 44228 | C29: 121.67208 | D29: 157.71542 | E29: 173.88 | F29: 149.58167 | G29: 121.60167 | H29: 130.19625 | I29: 104.11167 | J29: 68.349583 | K29: 92.795 | L29: 80.1575
A30: =+A29+1 -> 20 | B30: =+Base40h!B30 -> 44256 | C30: 313.63542 | D30: 345.06292 | E30: 367.99333 | F30: 337.78 | G30: 298.15042 | H30: 318.26792 | I30: 274.66875 | J30: 234.75208 | K30: 273.86167 | L30: 232.48625
A31: =+A30+1 -> 21 | B31: =+Base40h!B31 -> 44287 | C31: 504.86625 | D31: 525.31083 | E31: 558.50375 | F31: 528.66167 | G31: 481.90167 | H31: 512.11208 | I31: 468.83958 | J31: 428.88125 | K31: 497.21417 | L31: 414.49917
A32: =+A31+1 -> 22 | B32: =+Base40h!B32 -> 44317 | C32: 759.13792 | D32: 754.18583 | E32: 793.68958 | F32: 759.36417 | G32: 724.2825 | H32: 760.32917 | I32: 711.87333 | J32: 692.08375 | K32: 759.47792 | L32: 664.00875
A33: =+A32+1 -> 23 | B33: =+Base40h!B33 -> 44348 | C33: 976.7675 | D33: 911.6175 | E33: 957.34792 | F33: 945.775 | G33: 905.61333 | H33: 964.25417 | I33: 915.5775 | J33: 927.98458 | K33: 967.6154 | L33: 904.12292
A34: =+A33+1 -> 24 | B34: =+Base40h!B34 -> 44378 | C34: 1111.9583 | D34: 997.52125 | E34: 1039.9596 | F34: 1057.315 | G34: 1018.3888 | H34: 1091.3571 | I34: 1032.4404 | J34: 1077.7796 | K34: 1032.6067 | L34: 1047.5158
A35: =+A34+1 -> 25 | B35: =+Base40h!B35 -> 44409 | C35: 1123.5142 | D35: 1012.0125 | E35: 1069.1804 | F35: 1078.5837 | G35: 1026.1329 | H35: 1105.6271 | I35: 1027.0542 | J35: 1061.8908 | K35: 1013.7554 | L35: 1045.59
A36: =+A35+1 -> 26 | B36: =+Base40h!B36 -> 44440 | C36: 874.33833 | D36: 824.6425 | E36: 854.985 | F36: 840.75042 | G36: 813.57167 | H36: 860.3875 | I36: 765.62292 | J36: 781.94708 | K36: 757.84958 | L36: 791.89
A37: =+A36+1 -> 27 | B37: =+Base40h!B37 -> 44470 | C37: 564.31917 | D37: 554.23125 | E37: 599.21125 | F37: 574.05 | G37: 510.30833 | H37: 570.545 | I37: 491.24542 | J37: 456.93708 | K37: 486.73208 | L37: 481.17833
A38: =+A37+1 -> 28 | B38: =+Base40h!B38 -> 44501 | C38: 266.60333 | D38: 279.56417 | E38: 315.15708 | F38: 286.26833 | G38: 240.00333 | H38: 275.61625 | I38: 214.17292 | J38: 177.33333 | K38: 176.82833 | L38: 214.40167
A39: =+A38+1 -> 29 | B39: =+Base40h!B39 -> 44531 | C39: 100.28167 | D39: 139.13583 | E39: 144.17375 | F39: 121.32375 | G39: 109.17333 | H39: 106.81542 | I39: 74.954583 | J39: 42.94375 | K39: 45.27625 | L39: 66.677083
A40: =+A39+1 -> 30 | B40: Annual | C40: =SUM(C28:C39) -> 6794.8937 | D40: =SUM(D28:D39) -> 6616.2017 | E40: =SUM(E28:E39) -> 6991.7908 | F40: =SUM(F28:F39) -> 6781.8208 | G40: =SUM(G28:G39) -> 6339.0312 | H40: =SUM(H28:H39) -> 6778.7425 | I40: =SUM(I28:I39) -> 6141.6496 | J40: =SUM(J28:J39) -> 5989.5217 | ... L40: =SUM(L28:L39) -> 5992.3571

Sheet Base55c
B1: =+Base40h!B1 -> PUC DOCKET NO.
B2: =+Base40h!B2 -> ONCOR ELECTRIC DELIVERY COMPANY LLC
B3: =+Base40h!B3 -> WEATHER STATION DATA
B4: =+Base40h!B4 -> FOR THE TEST YEAR ENDING DECEMBER 31, 2021
B6: =+Base40h!B6 -> SPONSOR: D. E. NELSON
B9: Calendar Actual Cooling Degree Days by Weather Sites (Base 55)
A10: Line No. | C10: Dallas/ Fort Worth (MX) | D10: Lufkin (LU) | E10: Austin (AU) | F10: Killeen (KI) | G10: Longview (LO) | H10: Waco (WO) | I10: Abilene (AE) | J10: Wichita Falls (WF) | K10: Midland/ Odessa (MO) | L10: Denison (DE)
A11: 1 | B11: =+Base40h!B11 -> 44197 | C11: 12.4 | D11: 45.8 | E11: 70 | F11: 29.3 | G11: 12.2 | H11: 25.8 | I11: 10.3 | J11: 4.3 | K11: 4.5 | L11: 5.7
A12: =+A11+1 -> 2 | B12: =+Base40h!B12 -> 44228 | C12: 30.6 | D12: 78.3 | E12: 77.4 | F12: 57.6 | G12: 39.5 | H12: 49.9 | I12: 30.5 | J12: 1.8 | K12: 23.3 | L12: 16.9
A13: =+A12+1 -> 3 | B13: =+Base40h!B13 -> 44256 | C13: 209.9 | D13: 229.9 | E13: 257.8 | F13: 210.7 | G13: 179.7 | H13: 208.6 | I13: 158.5 | J13: 123.2 | K13: 132.5 | L13: 153.6
A14: =+A13+1 -> 4 | B14: =+Base40h!B14 -> 44287 | C14: 296.6 | D14: 312.4 | E14: 317.2 | F14: 307.9 | G14: 248 | H14: 307.1 | I14: 239.9 | J14: 192.9 | K14: 228.6 | L14: 207.1
A15: =+A14+1 -> 5 | B15: =+Base40h!B15 -> 44317 | C15: 501.1 | D15: 544.6 | E15: 523.9 | F15: 497.6 | G15: 469.9 | H15: 521.1 | I15: 459.8 | J15: 413.4 | K15: 491.5 | L15: 405.4
A16: =+A15+1 -> 6 | B16: =+Base40h!B16 -> 44348 | C16: 807 | D16: 780.2 | E16: 738.4 | F16: 747.1 | G16: 726.9 | H16: 784.4 | I16: 744.2 | J16: 720.8 | K16: 740.4 | L16: 728.8
A17: =+A16+1 -> 7 | B17: =+Base40h!B17 -> 44378 | C17: 912.6 | D17: 817.2 | E17: 770 | F17: 797.8 | G17: 784.8 | H17: 849.8 | I17: 828.4 | J17: 825.7 | K17: 742.2 | L17: 833.2
A18: =+A17+1 -> 8 | B18: =+Base40h!B18 -> 44409 | C18: 919.4 | D18: 869.9 | E18: 819.1 | F18: 870.9 | G18: 809.3 | H18: 900 | I18: 864.6 | J18: 843.4 | K18: 745.2 | L18: 838.3
A19: =+A18+1 -> 9 | B19: =+Base40h!B19 -> 44440 | C19: 764.4 | D19: 690.7 | E19: 691.6 | F19: 730.8 | G19: 633.1 | H19: 736 | I19: 725.9 | J19: 692.2 | K19: 675.4 | L19: 686
A20: =+A19+1 -> 10 | B20: =+Base40h!B20 -> 44470 | C20: 520.3 | D20: 523.5 | E20: 496.1 | F20: 496.4 | G20: 486.7 | H20: 506.5 | I20: 460.2 | J20: 396.9 | K20: 411.3 | L20: 408.1
A21: =+A20+1 -> 11 | B21: =+Base40h!B21 -> 44501 | C21: 118.7 | D21: 114.2 | E21: 135.5 | F21: 128.8 | G21: 94.2 | H21: 134.4 | I21: 119.6 | J21: 72 | K21: 79.5 | L21: 86.6
A22: =+A21+1 -> 12 | B22: =+Base40h!B22 -> 44531 | C22: 244 | D22: 309.3 | E22: 274.6 | F22: 269 | G22: 275.1 | H22: 271.7 | I22: 214.6 | J22: 123.9 | K22: 104.5 | L22: 189.8
A23: =+A22+1 -> 13 | B23: Annual | C23: =SUM(C11:C22) -> 5337 | D23: =SUM(D11:D22) -> 5316 | E23: =SUM(E11:E22) -> 5171.6 | F23: =SUM(F11:F22) -> 5143.9 | G23: =SUM(G11:G22) -> 4759.4 | H23: =SUM(H11:H22) -> 5295.3 | I23: =SUM(I11:I22) -> 4856.5 | J23: =SUM(J11:J22) -> 4410.5 | ... L23: =SUM(L11:L22) -> 4559.5
A24: =+A23+1 -> 14
A25: =+A24+1 -> 15
A26: =+A25+1 -> 16 | B26: Calendar Normal Cooling Degree Days by Weather Sites (Base 55)
A27: =+A26+1 -> 17 | C27: Dallas/ Fort Worth (MX) | D27: Lufkin (LU) | E27: Austin (AU) | F27: Killeen (KI) | G27: Longview (LO) | H27: Waco (WO) | I27: Abilene (AE) | J27: Wichita Falls (WF) | K27: Midland/ Odessa (MO) | L27: Denison (DE)
A28: =+A27+1 -> 18 | B28: =+Base40h!B28 -> 44197 | C28: 36.20375 | D28: 60.988333 | E28: 59.239167 | F28: 49.285833 | G28: 44.97 | H28: 39.314167 | I28: 24.344167 | J28: 15.40875 | K28: 9.8541667 | L28: 21.141667
A29: =+A28+1 -> 19 | B29: =+Base40h!B29 -> 44228 | C29: 65.918333 | D29: 87.937917 | E29: 98.526667 | F29: 82.425 | G29: 65.740833 | H29: 68.9875 | I29: 52.899583 | J29: 31.92625 | K29: 41.37125 | L29: 38.071667
A30: =+A29+1 -> 20 | B30: =+Base40h!B30 -> 44256 | C30: 194.56 | D30: 218.62625 | E30: 239.17875 | F30: 212.17417 | G30: 181.09167 | H30: 197.66667 | I30: 166.22333 | J30: 135.68 | K30: 163.64917 | L30: 132.49458
A31: =+A30+1 -> 21 | B31: =+Base40h!B31 -> 44287 | C31: 362.90833 | D31: 379.60208 | E31: 411.45875 | F31: 383.77292 | G31: 339.41875 | H31: 368.63833 | I31: 331.59875 | J31: 293.58958 | K31: 357.51167 | L31: 278.91542
A32: =+A31+1 -> 22 | B32: =+Base40h!B32 -> 44317 | C32: 604.71167 | D32: 599.23583 | E32: 638.84458 | F32: 604.73917 | G32: 569.6225 | H32: 605.74417 | I32: 558.39292 | J32: 538.76667 | K32: 605.95125 | L32: 511.01875
A33: =+A32+1 -> 23 | B33: =+Base40h!B33 -> 44348 | C33: 826.7675 | D33: 761.6175 | E33: 807.34792 | F33: 795.775 | G33: 755.61333 | H33: 814.25417 | I33: 765.5775 | J33: 777.98458 | K33: 817.6154 | L33: 754.12292
A34: =+A33+1 -> 24 | B34: =+Base40h!B34 -> 44378 | C34: 956.95833 | D34: 842.52125 | E34: 884.95958 | F34: 902.315 | G34: 863.38875 | H34: 936.35708 | I34: 877.44042 | J34: 922.77958 | K34: 877.60667 | L34: 892.51583
A35: =+A34+1 -> 25 | B35: =+Base40h!B35 -> 44409 | C35: 968.51417 | D35: 857.0125 | E35: 914.18042 | F35: 923.58375 | G35: 871.13292 | H35: 950.62708 | I35: 872.05417 | J35: 906.89083 | K35: 858.75542 | L35: 890.59
A36: =+A35+1 -> 26 | B36: =+Base40h!B36 -> 44440 | C36: 724.33833 | D36: 674.6425 | E36: 704.985 | F36: 690.75042 | G36: 663.57167 | H36: 710.3875 | I36: 615.97292 | J36: 632.02208 | K36: 608.46958 | L36: 641.89
A37: =+A36+1 -> 27 | B37: =+Base40h!B37 -> 44470 | C37: 415.47083 | D37: 403.32708 | E37: 447.87958 | F37: 424.55167 | G37: 363.21417 | H37: 421.29292 | I37: 350.27625 | J37: 316.87042 | K37: 344.7125 | L37: 338.06917
A38: =+A37+1 -> 28 | B38: =+Base40h!B38 -> 44501 | C38: 159.94917 | D38: 171.02 | E38: 199.60542 | F38: 176.03542 | G38: 141.04417 | H38: 168.34833 | I38: 120.02917 | J38: 93.621667 | K38: 88.613333 | L38: 120.14292
A39: =+A38+1 -> 29 | B39: =+Base40h!B39 -> 44531 | C39: 47.815 | D39: 77.045417 | E39: 77.874167 | F39: 62.16375 | G39: 57.710417 | H39: 53.539167 | I39: 29.855417 | J39: 15.32125 | K39: 13.881667 | L39: 27.839167
A40: =+A39+1 -> 30 | B40: Annual | C40: =SUM(C28:C39) -> 5364.1154 | D40: =SUM(D28:D39) -> 5133.5767 | E40: =SUM(E28:E39) -> 5484.08 | F40: =SUM(F28:F39) -> 5307.5721 | G40: =SUM(G28:G39) -> 4916.5192 | H40: =SUM(H28:H39) -> 5335.1571 | I40: =SUM(I28:I39) -> 4764.6646 | J40: =SUM(J28:J39) -> 4680.8617 | ... L40: =SUM(L28:L39) -> 4646.8121

Sheet Base60c
B1: =+Base40h!B1 -> PUC DOCKET NO.
B2: =+Base40h!B2 -> ONCOR ELECTRIC DELIVERY COMPANY LLC
B3: =+Base40h!B3 -> WEATHER STATION DATA
B4: =+Base40h!B4 -> FOR THE TEST YEAR ENDING DECEMBER 31, 2021
B6: =+Base40h!B6 -> SPONSOR: D. E. NELSON
B9: Calendar Actual Cooling Degree Days by Weather Sites (Base 60)
A10: Line No. | C10: Dallas/ Fort Worth (MX) | D10: Lufkin (LU) | E10: Austin (AU) | F10: Killeen (KI) | G10: Longview (LO) | H10: Waco (WO) | I10: Abilene (AE) | J10: Wichita Falls (WF) | K10: Midland/ Odessa (MO) | L10: Denison (DE)
A11: 1 | B11: =+Base40h!B11 -> 44197 | C11: 2.4 | D11: 11.5 | E11: 22.7 | F11: 11.8 | G11: 4.3 | H11: 8.7 | I11: 0.6 | J11: 0 | K11: 0 | L11: 0
A12: =+A11+1 -> 2 | B12: =+Base40h!B12 -> 44228 | C12: 7.9 | D12: 41 | E12: 38.9 | F12: 23.4 | G12: 16.3 | H12: 18.3 | I12: 8.8 | J12: 0 | K12: 2.9 | L12: 2.3
A13: =+A12+1 -> 3 | B13: =+Base40h!B13 -> 44256 | C13: 102.9 | D13: 134.3 | E13: 140.4 | F13: 99.5 | G13: 88.6 | H13: 100.8 | I13: 74.1 | J13: 52 | K13: 58.2 | L13: 66.7
A14: =+A13+1 -> 4 | B14: =+Base40h!B14 -> 44287 | C14: 173.4 | D14: 192.4 | E14: 197.1 | F14: 188.2 | G14: 141 | H14: 186.5 | I14: 143 | J14: 97.3 | K14: 139.2 | L14: 107.3
A15: =+A14+1 -> 5 | B15: =+Base40h!B15 -> 44317 | C15: 349.3 | D15: 389.6 | E15: 368.9 | F15: 342.7 | G15: 315.7 | H15: 366.1 | I15: 313.3 | J15: 269.4 | K15: 339.7 | L15: 260.6
A16: =+A15+1 -> 6 | B16: =+Base40h!B16 -> 44348 | C16: 657 | D16: 630.2 | E16: 588.4 | F16: 597.1 | G16: 576.9 | H16: 634.4 | I16: 594.2 | J16: 570.8 | K16: 590.4 | L16: 578.8
A17: =+A16+1 -> 7 | B17: =+Base40h!B17 -> 44378 | C17: 757.6 | D17: 662.2 | E17: 615 | F17: 642.8 | G17: 629.8 | H17: 694.8 | I17: 673.4 | J17: 670.7 | K17: 587.2 | L17: 678.2
A18: =+A17+1 -> 8 | B18: =+Base40h!B18 -> 44409 | C18: 764.4 | D18: 714.9 | E18: 664.1 | F18: 715.9 | G18: 654.3 | H18: 745 | I18: 709.6 | J18: 688.4 | K18: 590.2 | L18: 683.3
A19: =+A18+1 -> 9 | B19: =+Base40h!B19 -> 44440 | C19: 614.4 | D19: 540.7 | E19: 541.6 | F19: 580.8 | G19: 483.1 | H19: 586 | I19: 575.9 | J19: 542.2 | K19: 525.4 | L19: 536
A20: =+A19+1 -> 10 | B20: =+Base40h!B20 -> 44470 | C20: 365.3 | D20: 373.6 | E20: 343.2 | F20: 343.7 | G20: 339 | H20: 355.8 | I20: 311.4 | J20: 253.9 | K20: 270.7 | L20: 263.7
A21: =+A20+1 -> 11 | B21: =+Base40h!B21 -> 44501 | C21: 49.3 | D21: 44.6 | E21: 59.8 | F21: 57.3 | G21: 36.4 | H21: 60.9 | I21: 48.7 | J21: 23 | K21: 25.7 | L21: 29
A22: =+A21+1 -> 12 | B22: =+Base40h!B22 -> 44531 | C22: 144 | D22: 197.7 | E22: 158.7 | F22: 162 | G22: 166.6 | H22: 166.8 | I22: 113 | J22: 53.1 | K22: 34.8 | L22: 95.1
A23: =+A22+1 -> 13 | B23: Annual | C23: =SUM(C11:C22) -> 3987.9 | D23: =SUM(D11:D22) -> 3932.7 | E23: =SUM(E11:E22) -> 3738.8 | F23: =SUM(F11:F22) -> 3765.2 | G23: =SUM(G11:G22) -> 3452 | H23: =SUM(H11:H22) -> 3924.1 | I23: =SUM(I11:I22) -> 3566 | J23: =SUM(J11:J22) -> 3220.8 | ... L23: =SUM(L11:L22) -> 3301
A24: =+A23+1 -> 14
A25: =+A24+1 -> 15
A26: =+A25+1 -> 16 | B26: Calendar Normal Cooling Degree Days by Weather Sites (Base 60)
A27: =+A26+1 -> 17 | C27: Dallas/ Fort Worth (MX) | D27: Lufkin (LU) | E27: Austin (AU) | F27: Killeen (KI) | G27: Longview (LO) | H27: Waco (WO) | I27: Abilene (AE) | J27: Wichita Falls (WF) | K27: Midland/ Odessa (MO) | L27: Denison (DE)
A28: =+A27+1 -> 18 | B28: =+Base40h!B28 -> 44197 | C28: 13.692917 | D28: 26.631667 | E28: 25.655417 | F28: 19.305417 | G28: 18.51 | H28: 14.71 | I28: 6.4425 | J28: 3.6620833 | K28: 1.1341667 | L28: 6.6504167
A29: =+A28+1 -> 19 | B29: =+Base40h!B29 -> 44228 | C29: 29.371667 | D29: 40.569583 | E29: 47.99375 | F29: 36.9425 | G29: 28.78375 | H29: 29.38125 | I29: 20.1325 | J29: 10.985 | K29: 13.127083 | L29: 14.264583
A30: =+A29+1 -> 20 | B30: =+Base40h!B30 -> 44256 | C30: 103.75875 | D30: 117.61208 | E30: 133.33083 | F30: 112.94167 | G30: 93.2475 | H30: 103.59958 | I30: 85.892083 | J30: 68.384583 | K30: 83.000417 | L30: 62.86
A31: =+A30+1 -> 21 | B31: =+Base40h!B31 -> 44287 | C31: 230.67 | D31: 243.08708 | E31: 272.59083 | F31: 248.365 | G31: 208.91875 | H31: 235.18167 | I31: 208.02083 | J31: 176.18 | K31: 230.08292 | L31: 162.97125
A32: =+A31+1 -> 22 | B32: =+Base40h!B32 -> 44317 | C32: 452.05542 | D32: 444.88542 | E32: 484.54667 | F32: 451.26792 | G32: 416.17333 | H32: 452.275 | I32: 408.51708 | J32: 389.09208 | K32: 455.85458 | L32: 361.2425
A33: =+A32+1 -> 23 | B33: =+Base40h!B33 -> 44348 | C33: 676.7675 | D33: 611.6175 | E33: 657.34792 | F33: 645.775 | G33: 605.61333 | H33: 664.25417 | I33: 615.5775 | J33: 627.98458 | K33: 667.6154 | L33: 604.12292
A34: =+A33+1 -> 24 | B34: =+Base40h!B34 -> 44378 | C34: 801.95833 | D34: 687.52125 | E34: 729.95958 | F34: 747.315 | G34: 708.38875 | H34: 781.35708 | I34: 722.44042 | J34: 767.77958 | K34: 722.60667 | L34: 737.51583
A35: =+A34+1 -> 25 | B35: =+Base40h!B35 -> 44409 | C35: 813.51417 | D35: 702.0125 | E35: 759.18042 | F35: 768.58375 | G35: 716.13292 | H35: 795.62708 | I35: 717.05417 | J35: 751.89083 | K35: 703.75542 | L35: 735.59
A36: =+A35+1 -> 26 | B36: =+Base40h!B36 -> 44440 | C36: 574.33833 | D36: 524.6425 | E36: 554.985 | F36: 540.79042 | G36: 513.58625 | H36: 560.3875 | I36: 466.74375 | J36: 482.58208 | K36: 459.48458 | L36: 491.91042
A37: =+A36+1 -> 27 | B37: =+Base40h!B37 -> 44470 | C37: 278.23417 | D37: 266.41208 | E37: 306.70625 | F37: 286.20542 | G37: 232.23625 | H37: 284.10417 | I37: 222.27625 | J37: 195.14292 | K37: 216.11417 | L37: 213.5275
A38: =+A37+1 -> 28 | B38: =+Base40h!B38 -> 44501 | C38: 80.37375 | D38: 90.37875 | E38: 111.165 | F38: 91.677917 | G38: 69.397917 | H38: 87.184583 | I38: 53.417917 | J38: 39.226667 | K38: 34.000833 | L38: 53.549167
A39: =+A38+1 -> 29 | B39: =+Base40h!B39 -> 44531 | C39: 18.52625 | D39: 36.39875 | E39: 35.627917 | F39: 24.44625 | G39: 24.229583 | H39: 20.349583 | I39: 8.6904167 | J39: 4.5125 | K39: 2.2020833 | L39: 9.10375
A40: =+A39+1 -> 30 | B40: Annual | C40: =SUM(C28:C39) -> 4073.2613 | D40: =SUM(D28:D39) -> 3791.7692 | E40: =SUM(E28:E39) -> 4119.0896 | F40: =SUM(F28:F39) -> 3973.6163 | G40: =SUM(G28:G39) -> 3635.2183 | H40: =SUM(H28:H39) -> 4028.4117 | I40: =SUM(I28:I39) -> 3535.2054 | J40: =SUM(J28:J39) -> 3517.4229 | ... L40: =SUM(L28:L39) -> 3453.3083

Sheet Base65c
B1: =+Base40h!B1 -> PUC DOCKET NO.
B2: =+Base40h!B2 -> ONCOR ELECTRIC DELIVERY COMPANY LLC
B3: =+Base40h!B3 -> WEATHER STATION DATA
B4: =+Base40h!B4 -> FOR THE TEST YEAR ENDING DECEMBER 31, 2021
B6: =+Base40h!B6 -> SPONSOR: D. E. NELSON
B9: Calendar Actual Cooling Degree Days by Weather Sites (Base 65)
A10: Line No. | C10: Dallas/ Fort Worth (MX) | D10: Lufkin (LU) | E10: Austin (AU) | F10: Killeen (KI) | G10: Longview (LO) | H10: Waco (WO) | I10: Abilene (AE) | J10: Wichita Falls (WF) | K10: Midland/ Odessa (MO) | L10: Denison (DE)
A11: 1 | B11: =+Base40h!B11 -> 44197 | C11: 0 | D11: 3.3 | E11: 2.8 | F11: 0.2 | G11: 0 | H11: 0 | I11: 0 | J11: 0 | K11: 0 | L11: 0
A12: =+A11+1 -> 2 | B12: =+Base40h!B12 -> 44228 | C12: 0 | D12: 17.7 | E12: 18.7 | F12: 3.3 | G12: 6.3 | H12: 1.5 | I12: 0 | J12: 0 | K12: 0 | L12: 0
A13: =+A12+1 -> 3 | B13: =+Base40h!B13 -> 44256 | C13: 38.2 | D13: 52.7 | E13: 56.4 | F13: 35.1 | G13: 32.8 | H13: 37.6 | I13: 17.2 | J13: 13.2 | K13: 11.9 | L13: 21.1
A14: =+A13+1 -> 4 | B14: =+Base40h!B14 -> 44287 | C14: 78.2 | D14: 94.6 | E14: 99.2 | F14: 93.5 | G14: 56.7 | H14: 92.9 | I14: 73.9 | J14: 36.3 | K14: 72.5 | L14: 34.7
A15: =+A14+1 -> 5 | B15: =+Base40h!B15 -> 44317 | C15: 209.3 | D15: 236.6 | E15: 215.7 | F15: 197.9 | G15: 171.1 | H15: 219.5 | I15: 179.9 | J15: 139.2 | K15: 206.8 | L15: 129.2
A16: =+A15+1 -> 6 | B16: =+Base40h!B16 -> 44348 | C16: 507 | D16: 480.2 | E16: 438.4 | F16: 447.1 | G16: 426.9 | H16: 484.4 | I16: 444.2 | J16: 420.8 | K16: 440.4 | L16: 428.8
A17: =+A16+1 -> 7 | B17: =+Base40h!B17 -> 44378 | C17: 602.6 | D17: 507.2 | E17: 460 | F17: 487.8 | G17: 474.8 | H17: 539.8 | I17: 518.4 | J17: 515.7 | K17: 432.2 | L17: 523.2
A18: =+A17+1 -> 8 | B18: =+Base40h!B18 -> 44409 | C18: 609.4 | D18: 559.9 | E18: 509.1 | F18: 560.9 | G18: 499.3 | H18: 590 | I18: 554.6 | J18: 533.4 | K18: 435.2 | L18: 528.3
A19: =+A18+1 -> 9 | B19: =+Base40h!B19 -> 44440 | C19: 464.4 | D19: 390.7 | E19: 391.6 | F19: 430.8 | G19: 333.1 | H19: 436 | I19: 425.9 | J19: 392.2 | K19: 375.4 | L19: 386
A20: =+A19+1 -> 10 | B20: =+Base40h!B20 -> 44470 | C20: 227 | D20: 244.5 | E20: 211.7 | F20: 210.6 | G20: 214 | H20: 225.9 | I20: 185.9 | J20: 139.8 | K20: 154 | L20: 141.7
A21: =+A20+1 -> 11 | B21: =+Base40h!B21 -> 44501 | C21: 12.7 | D21: 9.9 | E21: 17.1 | F21: 13.5 | G21: 10.5 | H21: 18.2 | I21: 10.1 | J21: 4.4 | K21: 1.3 | L21: 5.2
A22: =+A21+1 -> 12 | B22: =+Base40h!B22 -> 44531 | C22: 57.5 | D22: 102.8 | E22: 70.2 | F22: 68 | G22: 79.5 | H22: 77.1 | I22: 40.3 | J22: 19.4 | K22: 3.7 | L22: 24.8
A23: =+A22+1 -> 13 | B23: Annual | C23: =SUM(C11:C22) -> 2806.3 | D23: =SUM(D11:D22) -> 2700.1 | E23: =SUM(E11:E22) -> 2490.9 | F23: =SUM(F11:F22) -> 2548.7 | G23: =SUM(G11:G22) -> 2305 | H23: =SUM(H11:H22) -> 2722.9 | I23: =SUM(I11:I22) -> 2450.4 | J23: =SUM(J11:J22) -> 2214.4 | ... L23: =SUM(L11:L22) -> 2223
A24: =+A23+1 -> 14
A25: =+A24+1 -> 15
A26: =+A25+1 -> 16 | B26: Calendar Normal Cooling Degree Days by Weather Sites (Base 65)
A27: =+A26+1 -> 17 | C27: Dallas/ Fort Worth (MX) | D27: Lufkin (LU) | E27: Austin (AU) | F27: Killeen (KI) | G27: Longview (LO) | H27: Waco (WO) | I27: Abilene (AE) | J27: Wichita Falls (WF) | K27: Midland/ Odessa (MO) | L27: Denison (DE)
A28: =+A27+1 -> 18 | B28: =+Base40h!B28 -> 44197 | C28: 3.4345833 | D28: 8.6408333 | E28: 7.9408333 | F28: 4.7654167 | G28: 5.3925 | H28: 3.5295833 | I28: 0.37916667 | J28: 0.50333333 | K28: 0 | L28: 0.91041667
A29: =+A28+1 -> 19 | B29: =+Base40h!B29 -> 44228 | C29: 8.9045833 | D29: 13.10625 | E29: 17.33875 | F29: 10.512083 | G29: 9.2391667 | H29: 8.0916667 | I29: 4.0941667 | J29: 2.9483333 | K29: 2.26 | L29: 3.3029167
A30: =+A29+1 -> 20 | B30: =+Base40h!B30 -> 44256 | C30: 42.8025 | D30: 49.291667 | E30: 58.866667 | F30: 45.27875 | G30: 36.629167 | H30: 40.106667 | I30: 33.183333 | J30: 26.204583 | K30: 30.530417 | L30: 21.307083
A31: =+A30+1 -> 21 | B31: =+Base40h!B31 -> 44287 | C31: 118.9125 | D31: 126.58833 | E31: 149.52292 | F31: 131.66958 | G31: 102.66292 | H31: 123.15 | I31: 108.88833 | J31: 86.59875 | K31: 123.69458 | L31: 73.900833
