Workbook
Name I: "a1..m50"

Sheet Weather Adjustment
AA1: WP/II-H-1.2/1
AA2: Page 1 of 8
A4: PUC DOCKET NO
A5: ONCOR ELECTRIC DELIVERY COMPANY LLC
A6: MONTHLY SALES DATA
A7: TEST YEAR ENDING December 31, 2021
A9: SPONSOR: D. E. NELSON
A11: Weather Adjustment (MWH) By Class (based on 20-year average weather 2001-2020)
A13: Line | C13: Year | E13: Month | G13: Residential | I13: SECLE10 | K13: SECGT10_IDR | M13: SECGT10_NIDR | O13: PRMLE10 | Q13: PRMGT10_IDR_NoSUB | S13: PRMGT10_IDR_SUB | U13: PRMGT10_NIDR | W13: Transmission | Y13: Lighting | AA13: Total
A14: No. | G14: (a) | I14: (b) | K14: (c) | M14: (d) | O14: (e) | Q14: (f) | S14: (g) | U14: (h) | W14: (i) | Y14: (j) | AA14: (k)
A16: 1 | C16: 2021 | E16: 1 | G16: =+Residential!Z52 -> 176298.76 | I16: =+SecLE10!W52 -> 2131.2128 | K16: =+SGT10_IDR_NIDR!J34 -> 18422.359 | M16: =+SGT10_IDR_NIDR!M34 -> 27239.946 | O16: 0 | Q16: =+'PrmGT10D IDR_NIDR'!J34 -> 1234.7506 | S16: =+Substation!Q52 -> 450.96477 | U16: =+'PrmGT10D IDR_NIDR'!M34 -> 146.728 | W16: 0 | Y16: 0 | AA16: =SUM(G16,I16,K16,M16,O16,Q16,S16,U16,W16,Y16,) -> 225924.72
A17: =+A16+1 -> 2 | C17: =C16 -> 2021 | E17: 2 | G17: =+Residential!Z53 -> -86661.269 | I17: =+SecLE10!W53 -> -1079.941 | K17: =+SGT10_IDR_NIDR!J35 -> 207.85351 | M17: =+SGT10_IDR_NIDR!M35 -> 309.89139 | O17: 0 | Q17: =+'PrmGT10D IDR_NIDR'!J35 -> 964.1974 | S17: =+Substation!Q53 -> 332.12909 | U17: =+'PrmGT10D IDR_NIDR'!M35 -> 114.03265 | W17: 0 | Y17: 0 | AA17: =SUM(G17,I17,K17,M17,O17,Q17,S17,U17,W17,Y17,) -> -85813.106
A18: =+A17+1 -> 3 | C18: =C17 -> 2021 | E18: 3 | G18: =+Residential!Z54 -> -1051980.6 | I18: =+SecLE10!W54 -> -13874.231 | K18: =+SGT10_IDR_NIDR!J36 -> -64738.651 | M18: =+SGT10_IDR_NIDR!M36 -> -106379.32 | O18: 0 | Q18: =+'PrmGT10D IDR_NIDR'!J36 -> 1793.8895 | S18: =+Substation!Q54 -> 640.93907 | U18: =+'PrmGT10D IDR_NIDR'!M36 -> 221.89575 | W18: 0 | Y18: 0 | AA18: =SUM(G18,I18,K18,M18,O18,Q18,S18,U18,W18,Y18,) -> -1234316
A19: =+A18+1 -> 4 | C19: =C18 -> 2021 | E19: 4 | G19: =+Residential!Z55 -> 251522.97 | I19: =+SecLE10!W55 -> 3604.2533 | K19: =+SGT10_IDR_NIDR!J37 -> 20895.177 | M19: =+SGT10_IDR_NIDR!M37 -> 27938.6 | O19: 0 | Q19: =+'PrmGT10D IDR_NIDR'!J37 -> 2738.384 | S19: =+Substation!Q55 -> 674.08414 | U19: =+'PrmGT10D IDR_NIDR'!M37 -> 338.4786 | W19: 0 | Y19: 0 | AA19: =SUM(G19,I19,K19,M19,O19,Q19,S19,U19,W19,Y19,) -> 307711.95
A20: =+A19+1 -> 5 | C20: =C19 -> 2021 | E20: 5 | G20: =+Residential!Z56 -> 207360.01 | I20: =+SecLE10!W56 -> 3212.1834 | K20: =+SGT10_IDR_NIDR!J38 -> 45779.345 | M20: =+SGT10_IDR_NIDR!M38 -> 66059.327 | O20: 0 | Q20: =+'PrmGT10D IDR_NIDR'!J38 -> 11950.055 | S20: =+Substation!Q56 -> 3485.4023 | U20: =+'PrmGT10D IDR_NIDR'!M38 -> 1614.8991 | W20: 0 | Y20: 0 | AA20: =SUM(G20,I20,K20,M20,O20,Q20,S20,U20,W20,Y20,) -> 339461.22
A21: =+A20+1 -> 6 | C21: =C20 -> 2021 | E21: 6 | G21: =+Residential!Z57 -> 486767.93 | I21: =+SecLE10!W57 -> 8032.3579 | K21: =+SGT10_IDR_NIDR!J39 -> 75907.148 | M21: =+SGT10_IDR_NIDR!M39 -> 118460.35 | O21: 0 | Q21: =+'PrmGT10D IDR_NIDR'!J39 -> 15923.729 | S21: =+Substation!Q57 -> 4229.6259 | U21: =+'PrmGT10D IDR_NIDR'!M39 -> 2183.7351 | W21: 0 | Y21: 0 | AA21: =SUM(G21,I21,K21,M21,O21,Q21,S21,U21,W21,Y21,) -> 711504.88
A22: =+A21+1 -> 7 | C22: =C21 -> 2021 | E22: 7 | G22: =+Residential!Z58 -> 202638.35 | I22: =+SecLE10!W58 -> 4236.2373 | K22: =+SGT10_IDR_NIDR!J40 -> 26843.365 | M22: =+SGT10_IDR_NIDR!M40 -> 43905.024 | O22: 0 | Q22: =+'PrmGT10D IDR_NIDR'!J40 -> 10225.081 | S22: =+Substation!Q58 -> 2440.5433 | U22: =+'PrmGT10D IDR_NIDR'!M40 -> 1390.8891 | W22: 0 | Y22: 0 | AA22: =SUM(G22,I22,K22,M22,O22,Q22,S22,U22,W22,Y22,) -> 291679.49
A23: =+A22+1 -> 8 | C23: =C22 -> 2021 | E23: 8 | G23: =+Residential!Z59 -> 384606.1 | I23: =+SecLE10!W59 -> 7778.8953 | K23: =+SGT10_IDR_NIDR!J41 -> 50242.585 | M23: =+SGT10_IDR_NIDR!M41 -> 83302.947 | O23: 0 | Q23: =+'PrmGT10D IDR_NIDR'!J41 -> 15625.553 | S23: =+Substation!Q59 -> 3169.9025 | U23: =+'PrmGT10D IDR_NIDR'!M41 -> 1397.14 | W23: 0 | Y23: 0 | AA23: =SUM(G23,I23,K23,M23,O23,Q23,S23,U23,W23,Y23,) -> 546123.12
A24: =+A23+1 -> 9 | C24: =C23 -> 2021 | E24: 9 | G24: =+Residential!Z60 -> -7699.5544 | I24: =+SecLE10!W60 -> 584.81074 | K24: =+SGT10_IDR_NIDR!J42 -> -3452.8303 | M24: =+SGT10_IDR_NIDR!M42 -> -5837.4615 | O24: 0 | Q24: =+'PrmGT10D IDR_NIDR'!J42 -> 1403.4564 | S24: =+Substation!Q60 -> -256.38065 | U24: =+'PrmGT10D IDR_NIDR'!M42 -> 182.57513 | W24: 0 | Y24: 0 | AA24: =SUM(G24,I24,K24,M24,O24,Q24,S24,U24,W24,Y24,) -> -15075.385
A25: =+A24+1 -> 10 | C25: =C24 -> 2021 | E25: 10 | G25: =+Residential!Z61 -> -73526.666 | I25: =+SecLE10!W61 -> -1188.0654 | K25: =+SGT10_IDR_NIDR!J43 -> -19582.441 | M25: =+SGT10_IDR_NIDR!M43 -> -30868.92 | O25: 0 | Q25: =+'PrmGT10D IDR_NIDR'!J43 -> -5348.4668 | S25: =+Substation!Q61 -> -1616.8314 | U25: =+'PrmGT10D IDR_NIDR'!M43 -> -888.88427 | W25: 0 | Y25: 0 | AA25: =SUM(G25,I25,K25,M25,O25,Q25,S25,U25,W25,Y25,) -> -133020.28
A26: =+A25+1 -> 11 | C26: =C25 -> 2021 | E26: 11 | G26: =+Residential!Z62 -> -12177.803 | I26: =+SecLE10!W62 -> -229.0213 | K26: =+SGT10_IDR_NIDR!J44 -> -17501.262 | M26: =+SGT10_IDR_NIDR!M44 -> -24696.879 | O26: 0 | Q26: =+'PrmGT10D IDR_NIDR'!J44 -> -5189.2665 | S26: =+Substation!Q62 -> -1490.9712 | U26: =+'PrmGT10D IDR_NIDR'!M44 -> -650.2354 | W26: 0 | Y26: 0 | AA26: =SUM(G26,I26,K26,M26,O26,Q26,S26,U26,W26,Y26,) -> -61935.438
A27: =+A26+1 -> 12 | C27: =C26 -> 2021 | E27: 12 | G27: =+Residential!Z63 -> 448145 | I27: =+SecLE10!W63 -> 6573.3521 | K27: =+SGT10_IDR_NIDR!J45 -> 26972.04 | M27: =+SGT10_IDR_NIDR!M45 -> 36980.866 | O27: 0 | Q27: =+'PrmGT10D IDR_NIDR'!J45 -> -1264.2725 | S27: =+Substation!Q63 -> -859.13496 | U27: =+'PrmGT10D IDR_NIDR'!M45 -> -159.8095 | W27: 0 | Y27: 0 | AA27: =SUM(G27,I27,K27,M27,O27,Q27,S27,U27,W27,Y27,) -> 516388.04
A28: =+A27+1 -> 13 | C28: Total | G28: =SUM(G16:G27) -> 925293.26 | I28: =SUM(I16:I27) -> 19782.044 | K28: =SUM(K16:K27) -> 159994.69 | M28: =SUM(M16:M27) -> 236414.37 | O28: =SUM(O16:O27) -> 0 | Q28: =SUM(Q16:Q27) -> 50057.09 | S28: =SUM(S16:S27) -> 11200.273 | U28: =SUM(U16:U27) -> 5891.4443 | W28: =SUM(W16:W27) -> 0 | Y28: =SUM(Y16:Y27) -> 0 | AA28: =SUM(AA16:AA27) -> 1408633.2
A29: =+A28+1 -> 14
A30: =+A29+1 -> 15 | C30: Customer Count
A31: =+A30+1 -> 16
A32: =+A31+1 -> 17 | C32: Year | E32: Month | G32: Residential | I32: SECLE10 | K32: SECGT10_IDR | M32: SECGT10_NIDR | O32: PRMLE10 | Q32: PRMGT10_IDR_NoSUB | S32: PRMGT10_IDR_SUB | U32: PRMGT10_NIDR | W32: Transmission | Y32: Lighting | AA32: Total
A33: =+A32+1 -> 18 | G33: (l) | I33: (m) | K33: (n) | M33: (o) | O33: (p) | Q33: (q) | S33: (r) | U33: (s) | W33: (t) | Y33: (u) | AA33: (v)
A34: =+A33+1 -> 19
A35: =+A34+1 -> 20 | C35: =+C16 -> 2021 | E35: =+E16 -> 1 | G35: =+[1]RES!E16 -> 3202892 | I35: =+'[1]GS SEC SMALL'!E16 -> 296726 | K35: =+'[1]GS SEC LRG IDR '!E16 -> 5289 | M35: =+'[1]GS SEC LRG NONIDR'!E16 -> 195067 | O35: =+'[1]GS PRI SMALL'!E16 -> 2979 | Q35: =+'[1]GS PRI LRG IDR '!E16 -> 1521 | S35: =+'[1]GS PRI LRG SUB'!E16 -> 121 | U35: =+'[1]GS PRI LRG NONIDR'!E16 -> 5712 | W35: =+[1]TRANSMISSION!E16 -> 268 | Y35: =+'[1]SL - UNMETERED'!E16+'[1]SL - METERED NON CO'!E16+'[1]SL - METERED CO OWNED'!E16+'[1]OUTDOOR LIGHTING'!E16 -> 56343 | AA35: =SUM(G35:Y35) -> 3766918
A36: =+A35+1 -> 21 | C36: =+C17 -> 2021 | E36: =+E17 -> 2 | G36: =+[1]RES!E18 -> 3208216 | I36: =+'[1]GS SEC SMALL'!E18 -> 296916 | K36: =+'[1]GS SEC LRG IDR '!E18 -> 5291 | M36: =+'[1]GS SEC LRG NONIDR'!E18 -> 195641 | O36: =+'[1]GS PRI SMALL'!E18 -> 2976 | Q36: =+'[1]GS PRI LRG IDR '!E18 -> 1525 | S36: =+'[1]GS PRI LRG SUB'!E18 -> 121 | U36: =+'[1]GS PRI LRG NONIDR'!E18 -> 5688 | W36: =+[1]TRANSMISSION!E18 -> 269 | Y36: =+'[1]SL - UNMETERED'!E18+'[1]SL - METERED NON CO'!E18+'[1]SL - METERED CO OWNED'!E18+'[1]OUTDOOR LIGHTING'!E18 -> 56263 | AA36: =SUM(G36:Y36) -> 3772906
A37: =+A36+1 -> 22 | C37: =+C18 -> 2021 | E37: =+E18 -> 3 | G37: =+[1]RES!E20 -> 3214871 | I37: =+'[1]GS SEC SMALL'!E20 -> 297390 | K37: =+'[1]GS SEC LRG IDR '!E20 -> 5289 | M37: =+'[1]GS SEC LRG NONIDR'!E20 -> 196641 | O37: =+'[1]GS PRI SMALL'!E20 -> 3005 | Q37: =+'[1]GS PRI LRG IDR '!E20 -> 1522 | S37: =+'[1]GS PRI LRG SUB'!E20 -> 122 | U37: =+'[1]GS PRI LRG NONIDR'!E20 -> 5669 | W37: =+[1]TRANSMISSION!E20 -> 270 | Y37: =+'[1]SL - UNMETERED'!E20+'[1]SL - METERED NON CO'!E20+'[1]SL - METERED CO OWNED'!E20+'[1]OUTDOOR LIGHTING'!E20 -> 56215 | AA37: =SUM(G37:Y37) -> 3780994
A38: =+A37+1 -> 23 | C38: =+C19 -> 2021 | E38: =+E19 -> 4 | G38: =+[1]RES!E22 -> 3221873 | I38: =+'[1]GS SEC SMALL'!E22 -> 299035 | K38: =+'[1]GS SEC LRG IDR '!E22 -> 5290 | M38: =+'[1]GS SEC LRG NONIDR'!E22 -> 196661 | O38: =+'[1]GS PRI SMALL'!E22 -> 3034 | Q38: =+'[1]GS PRI LRG IDR '!E22 -> 1519 | S38: =+'[1]GS PRI LRG SUB'!E22 -> 122 | U38: =+'[1]GS PRI LRG NONIDR'!E22 -> 5641 | W38: =+[1]TRANSMISSION!E22 -> 275 | Y38: =+'[1]SL - UNMETERED'!E22+'[1]SL - METERED NON CO'!E22+'[1]SL - METERED CO OWNED'!E22+'[1]OUTDOOR LIGHTING'!E22 -> 56208 | AA38: =SUM(G38:Y38) -> 3789658
A39: =+A38+1 -> 24 | C39: =+C20 -> 2021 | E39: =+E20 -> 5 | G39: =+[1]RES!E24 -> 3228777 | I39: =+'[1]GS SEC SMALL'!E24 -> 299788 | K39: =+'[1]GS SEC LRG IDR '!E24 -> 5309 | M39: =+'[1]GS SEC LRG NONIDR'!E24 -> 197010 | O39: =+'[1]GS PRI SMALL'!E24 -> 3065 | Q39: =+'[1]GS PRI LRG IDR '!E24 -> 1531 | S39: =+'[1]GS PRI LRG SUB'!E24 -> 122 | U39: =+'[1]GS PRI LRG NONIDR'!E24 -> 5598 | W39: =+[1]TRANSMISSION!E24 -> 277 | Y39: =+'[1]SL - UNMETERED'!E24+'[1]SL - METERED NON CO'!E24+'[1]SL - METERED CO OWNED'!E24+'[1]OUTDOOR LIGHTING'!E24 -> 56134 | AA39: =SUM(G39:Y39) -> 3797611
A40: =+A39+1 -> 25 | C40: =+C21 -> 2021 | E40: =+E21 -> 6 | G40: =+[1]RES!E26 -> 3234379 | I40: =+'[1]GS SEC SMALL'!E26 -> 300604 | K40: =+'[1]GS SEC LRG IDR '!E26 -> 5371 | M40: =+'[1]GS SEC LRG NONIDR'!E26 -> 197289 | O40: =+'[1]GS PRI SMALL'!E26 -> 3069 | Q40: =+'[1]GS PRI LRG IDR '!E26 -> 1565 | S40: =+'[1]GS PRI LRG SUB'!E26 -> 124 | U40: =+'[1]GS PRI LRG NONIDR'!E26 -> 5545 | W40: =+[1]TRANSMISSION!E26 -> 278 | Y40: =+'[1]SL - UNMETERED'!E26+'[1]SL - METERED NON CO'!E26+'[1]SL - METERED CO OWNED'!E26+'[1]OUTDOOR LIGHTING'!E26 -> 56089 | AA40: =SUM(G40:Y40) -> 3804313
A41: =+A40+1 -> 26 | C41: =+C22 -> 2021 | E41: =+E22 -> 7 | G41: =+[1]RES!E28 -> 3236273 | I41: =+'[1]GS SEC SMALL'!E28 -> 301274 | K41: =+'[1]GS SEC LRG IDR '!E28 -> 5367 | M41: =+'[1]GS SEC LRG NONIDR'!E28 -> 197702 | O41: =+'[1]GS PRI SMALL'!E28 -> 3081 | Q41: =+'[1]GS PRI LRG IDR '!E28 -> 1564 | S41: =+'[1]GS PRI LRG SUB'!E28 -> 124 | U41: =+'[1]GS PRI LRG NONIDR'!E28 -> 5545 | W41: =+[1]TRANSMISSION!E28 -> 282 | Y41: =+'[1]SL - UNMETERED'!E28+'[1]SL - METERED NON CO'!E28+'[1]SL - METERED CO OWNED'!E28+'[1]OUTDOOR LIGHTING'!E28 -> 55909 | AA41: =SUM(G41:Y41) -> 3807121
A42: =+A41+1 -> 27 | C42: =+C23 -> 2021 | E42: =+E23 -> 8 | G42: =+[1]RES!E30 -> 3240184 | I42: =+'[1]GS SEC SMALL'!E30 -> 301519 | K42: =+'[1]GS SEC LRG IDR '!E30 -> 5364 | M42: =+'[1]GS SEC LRG NONIDR'!E30 -> 198092 | O42: =+'[1]GS PRI SMALL'!E30 -> 3093 | Q42: =+'[1]GS PRI LRG IDR '!E30 -> 1560 | S42: =+'[1]GS PRI LRG SUB'!E30 -> 128 | U42: =+'[1]GS PRI LRG NONIDR'!E30 -> 5534 | W42: =+[1]TRANSMISSION!E30 -> 282 | Y42: =+'[1]SL - UNMETERED'!E30+'[1]SL - METERED NON CO'!E30+'[1]SL - METERED CO OWNED'!E30+'[1]OUTDOOR LIGHTING'!E30 -> 55731 | AA42: =SUM(G42:Y42) -> 3811487
A43: =+A42+1 -> 28 | C43: =+C24 -> 2021 | E43: =+E24 -> 9 | G43: =+[1]RES!E32 -> 3244734 | I43: =+'[1]GS SEC SMALL'!E32 -> 302471 | K43: =+'[1]GS SEC LRG IDR '!E32 -> 5374 | M43: =+'[1]GS SEC LRG NONIDR'!E32 -> 197946 | O43: =+'[1]GS PRI SMALL'!E32 -> 3096 | Q43: =+'[1]GS PRI LRG IDR '!E32 -> 1556 | S43: =+'[1]GS PRI LRG SUB'!E32 -> 129 | U43: =+'[1]GS PRI LRG NONIDR'!E32 -> 5544 | W43: =+[1]TRANSMISSION!E32 -> 283 | Y43: =+'[1]SL - UNMETERED'!E32+'[1]SL - METERED NON CO'!E32+'[1]SL - METERED CO OWNED'!E32+'[1]OUTDOOR LIGHTING'!E32 -> 55596 | AA43: =SUM(G43:Y43) -> 3816729
A44: =+A43+1 -> 29 | C44: =+C25 -> 2021 | E44: =+E25 -> 10 | G44: =+[1]RES!E34 -> 3248681 | I44: =+'[1]GS SEC SMALL'!E34 -> 303108 | K44: =+'[1]GS SEC LRG IDR '!E34 -> 5455 | M44: =+'[1]GS SEC LRG NONIDR'!E34 -> 197922 | O44: =+'[1]GS PRI SMALL'!E34 -> 3111 | Q44: =+'[1]GS PRI LRG IDR '!E34 -> 1600 | S44: =+'[1]GS PRI LRG SUB'!E34 -> 129 | U44: =+'[1]GS PRI LRG NONIDR'!E34 -> 5543 | W44: =+[1]TRANSMISSION!E34 -> 283 | Y44: =+'[1]SL - UNMETERED'!E34+'[1]SL - METERED NON CO'!E34+'[1]SL - METERED CO OWNED'!E34+'[1]OUTDOOR LIGHTING'!E34 -> 55408 | AA44: =SUM(G44:Y44) -> 3821240
A45: =+A44+1 -> 30 | C45: =+C26 -> 2021 | E45: =+E26 -> 11 | G45: =+[1]RES!E36 -> 3253575 | I45: =+'[1]GS SEC SMALL'!E36 -> 303828 | K45: =+'[1]GS SEC LRG IDR '!E36 -> 5449 | M45: =+'[1]GS SEC LRG NONIDR'!E36 -> 197868 | O45: =+'[1]GS PRI SMALL'!E36 -> 3103 | Q45: =+'[1]GS PRI LRG IDR '!E36 -> 1597 | S45: =+'[1]GS PRI LRG SUB'!E36 -> 129 | U45: =+'[1]GS PRI LRG NONIDR'!E36 -> 5551 | W45: =+[1]TRANSMISSION!E36 -> 283 | Y45: =+'[1]SL - UNMETERED'!E36+'[1]SL - METERED NON CO'!E36+'[1]SL - METERED CO OWNED'!E36+'[1]OUTDOOR LIGHTING'!E36 -> 55288 | AA45: =SUM(G45:Y45) -> 3826671
...

Sheet Residential
Z1: WP/II-H-1.2/1
Z2: Page 2 of 8
A4: =+'Weather Adjustment'!A4 -> PUC DOCKET NO
A5: =+'Weather Adjustment'!A5 -> ONCOR ELECTRIC DELIVERY COMPANY LLC
A6: =+'Weather Adjustment'!A6 -> MONTHLY SALES DATA
A7: =+'Weather Adjustment'!A7 -> TEST YEAR ENDING December 31, 2021
A9: =+'Weather Adjustment'!A9 -> SPONSOR: D. E. NELSON
A11: Residential Weather Adjustment (MWH)
G12: CDD Model | I12: CDD Model Scaler | Z12: CDD MWH
A13: Line | C13: Year | E13: Month | G13: Coefficient | I13: CoolIndex | K13: CoolUse | M13: Customer | O13: Total GSL | P13: CDD Coefficient | R13: Actual CDD | T13: Normal CDD | V13: Total GPL | X13: CDD Deviation | Z13: Adjustment
G14: (a) | I14: (b) | K14: (c) | M14: (d) | P14: (e) = (a*b*c*d)/1000 | R14: (f) | T14: (g) | X14: (h)=g-f | Z14: (i)=e*h
A16: 1 | C16: =+'Weather Adjustment'!C16 -> 2021 | E16: =+'Weather Adjustment'!E16 -> 1 | G16: =+'[2]RES Model'!$C$18 -> 2.289 | I16: 0.83 | K16: 1.07 | M16: =+'Weather Adjustment'!G35 -> 3202892 | O16: =SUM(K16,M16) -> 3202893.1 | P16: =PRODUCT(G16,I16,K16,M16)/1000 -> 6511.0339 | R16: =+[3]RES!D13 -> 0.053063947 | T16: =+[3]RES!F13 -> 1.8172962 | V16: =SUM(R16,T16) -> 1.8703602 | X16: =+T16-R16 -> 1.7642323 | Z16: =+P16*X16 -> 11486.976
A17: =+A16+1 -> 2 | C17: =+'Weather Adjustment'!C17 -> 2021 | E17: =+'Weather Adjustment'!E17 -> 2 | G17: =+G16 -> 2.289 | I17: 0.83 | K17: 1.07 | M17: =+'Weather Adjustment'!G36 -> 3208216 | O17: =SUM(K17,M17) -> 3208217.1 | P17: =PRODUCT(G17,I17,K17,M17)/1000 -> 6521.8569 | R17: =+[3]RES!D14 -> 0.072720485 | T17: =+[3]RES!F14 -> 1.346646 | V17: =SUM(R17,T17) -> 1.4193665 | X17: =+T17-R17 -> 1.2739255 | Z17: =+P17*X17 -> 8308.36
A18: =+A17+1 -> 3 | C18: =+'Weather Adjustment'!C18 -> 2021 | E18: =+'Weather Adjustment'!E18 -> 3 | G18: =+G17 -> 2.289 | I18: 0.83 | K18: 1.07 | M18: =+'Weather Adjustment'!G37 -> 3214871 | O18: =SUM(K18,M18) -> 3214872.1 | P18: =PRODUCT(G18,I18,K18,M18)/1000 -> 6535.3856 | R18: =+[3]RES!D15 -> 3.3796202 | T18: =+[3]RES!F15 -> 5.1496534 | V18: =SUM(R18,T18) -> 8.5292736 | X18: =+T18-R18 -> 1.7700332 | Z18: =+P18*X18 -> 11567.85
A19: =+A18+1 -> 4 | C19: =+'Weather Adjustment'!C19 -> 2021 | E19: =+'Weather Adjustment'!E19 -> 4 | G19: =+G18 -> 2.289 | I19: 0.83 | K19: 1.07 | M19: =+'Weather Adjustment'!G38 -> 3221873 | O19: =SUM(K19,M19) -> 3221874.1 | P19: =PRODUCT(G19,I19,K19,M19)/1000 -> 6549.6196 | R19: =+[3]RES!D16 -> 15.688378 | T19: =+[3]RES!F16 -> 22.956112 | V19: =SUM(R19,T19) -> 38.64449 | X19: =+T19-R19 -> 7.2677343 | Z19: =+P19*X19 -> 47600.895
A20: =+A19+1 -> 5 | C20: =+'Weather Adjustment'!C20 -> 2021 | E20: =+'Weather Adjustment'!E20 -> 5 | G20: =+G19 -> 2.289 | I20: 0.83 | K20: 1.07 | M20: =+'Weather Adjustment'!G39 -> 3228777 | O20: =SUM(K20,M20) -> 3228778.1 | P20: =PRODUCT(G20,I20,K20,M20)/1000 -> 6563.6545 | R20: =+[3]RES!D17 -> 41.607224 | T20: =+[3]RES!F17 -> 76.128551 | V20: =SUM(R20,T20) -> 117.73578 | X20: =+T20-R20 -> 34.521327 | Z20: =+P20*X20 -> 226586.06
A21: =+A20+1 -> 6 | C21: =+'Weather Adjustment'!C21 -> 2021 | E21: =+'Weather Adjustment'!E21 -> 6 | G21: =+G20 -> 2.289 | I21: 0.83 | K21: 1.07 | M21: =+'Weather Adjustment'!G40 -> 3234379 | O21: =SUM(K21,M21) -> 3234380.1 | P21: =PRODUCT(G21,I21,K21,M21)/1000 -> 6575.0426 | R21: =+[3]RES!D18 -> 140.65521 | T21: =+[3]RES!F18 -> 214.74852 | V21: =SUM(R21,T21) -> 355.40373 | X21: =+T21-R21 -> 74.093307 | Z21: =+P21*X21 -> 487166.65
A22: =+A21+1 -> 7 | C22: =+'Weather Adjustment'!C22 -> 2021 | E22: =+'Weather Adjustment'!E22 -> 7 | G22: =+G21 -> 2.289 | I22: 0.83 | K22: 1.07 | M22: =+'Weather Adjustment'!G41 -> 3236273 | O22: =SUM(K22,M22) -> 3236274.1 | P22: =PRODUCT(G22,I22,K22,M22)/1000 -> 6578.8928 | R22: =+[3]RES!D19 -> 352.36394 | T22: =+[3]RES!F19 -> 383.15429 | V22: =SUM(R22,T22) -> 735.51823 | X22: =+T22-R22 -> 30.790357 | Z22: =+P22*X22 -> 202566.46
A23: =+A22+1 -> 8 | C23: =+'Weather Adjustment'!C23 -> 2021 | E23: =+'Weather Adjustment'!E23 -> 8 | G23: =+G22 -> 2.289 | I23: 0.83 | K23: 1.07 | M23: =+'Weather Adjustment'!G42 -> 3240184 | O23: =SUM(K23,M23) -> 3240185.1 | P23: =PRODUCT(G23,I23,K23,M23)/1000 -> 6586.8434 | R23: =+[3]RES!D20 -> 386.17883 | T23: =+[3]RES!F20 -> 444.56857 | V23: =SUM(R23,T23) -> 830.7474 | X23: =+T23-R23 -> 58.38974 | Z23: =+P23*X23 -> 384604.07
A24: =+A23+1 -> 9 | C24: =+'Weather Adjustment'!C24 -> 2021 | E24: =+'Weather Adjustment'!E24 -> 9 | G24: =+G23 -> 2.289 | I24: 0.83 | K24: 1.07 | M24: =+'Weather Adjustment'!G43 -> 3244734 | O24: =SUM(K24,M24) -> 3244735.1 | P24: =PRODUCT(G24,I24,K24,M24)/1000 -> 6596.0929 | R24: =+[3]RES!D21 -> 385.15065 | T24: =+[3]RES!F21 -> 383.9392 | V24: =SUM(R24,T24) -> 769.08985 | X24: =+T24-R24 -> -1.2114456 | Z24: =+P24*X24 -> -7990.8078
A25: =+A24+1 -> 10 | C25: =+'Weather Adjustment'!C25 -> 2021 | E25: =+'Weather Adjustment'!E25 -> 10 | G25: =+G24 -> 2.289 | I25: 0.83 | K25: 1.07 | M25: =+'Weather Adjustment'!G44 -> 3248681 | O25: =SUM(K25,M25) -> 3248682.1 | P25: =PRODUCT(G25,I25,K25,M25)/1000 -> 6604.1166 | R25: =+[3]RES!D22 -> 218.24743 | T25: =+[3]RES!F22 -> 204.8806 | V25: =SUM(R25,T25) -> 423.12803 | X25: =+T25-R25 -> -13.366832 | Z25: =+P25*X25 -> -88276.114
A26: =+A25+1 -> 11 | C26: =+'Weather Adjustment'!C26 -> 2021 | E26: =+'Weather Adjustment'!E26 -> 11 | G26: =+G25 -> 2.289 | I26: 0.83 | K26: 1.07 | M26: =+'Weather Adjustment'!G45 -> 3253575 | O26: =SUM(K26,M26) -> 3253576.1 | P26: =PRODUCT(G26,I26,K26,M26)/1000 -> 6614.0654 | R26: =+[3]RES!D23 -> 70.42355 | T26: =+[3]RES!F23 -> 57.398906 | V26: =SUM(R26,T26) -> 127.82246 | X26: =+T26-R26 -> -13.024644 | Z26: =+P26*X26 -> -86145.847
A27: =+A26+1 -> 12 | C27: =+'Weather Adjustment'!C27 -> 2021 | E27: =+'Weather Adjustment'!E27 -> 12 | G27: =+G26 -> 2.289 | I27: 0.83 | K27: 1.07 | M27: =+'Weather Adjustment'!G46 -> 3258283 | O27: =SUM(K27,M27) -> 3258284.1 | P27: =PRODUCT(G27,I27,K27,M27)/1000 -> 6623.6361 | R27: =+[3]RES!D24 -> 7.754457 | T27: =+[3]RES!F24 -> 9.7282243 | V27: =SUM(R27,T27) -> 17.482681 | X27: =+T27-R27 -> 1.9737674 | Z27: =+P27*X27 -> 13073.517
A28: =+A27+1 -> 13 | C28: Total | O28: =SUM(O22:O27) -> 19481736 | R28: =SUM(R16:R27) -> 1621.5751 | T28: =SUM(T16:T27) -> 1805.8166 | V28: =SUM(V22:V27) -> 2903.7887 | X28: =+T28-R28 -> 184.2415 | Z28: =SUM(Z16:Z27) -> 1210548.1
A29: =+A28+1 -> 14
A30: =+A29+1 -> 15 | G30: HDD Model | I30: HDD Model Scaler | Z30: HDD MWH
A31: =+A30+1 -> 16 | C31: Year | E31: Month | G31: Coefficient | I31: HeatIndex | K31: HeatUse | M31: Customer | O31: Total GSL | P31: HDD Coefficient | R31: Actual HDD | T31: Normal HDD | V31: Total GPL | X31: HDD Deviation | Z31: Adjustment
A32: =+A31+1 -> 17 | G32: (j) | I32: (k) | K32: (l) | M32: (m) | P32: (n) = (j*k*l*m)/1000 | R32: (o) | T32: (p) | X32: (q)=p-o | Z32: (r)=n*q
A33: =+A32+1 -> 18
A34: =+A33+1 -> 19 | C34: =+C16 -> 2021 | E34: =+E16 -> 1 | G34: =+'[2]RES Model'!$C$17 -> 2.055 | I34: 0.98 | K34: 1.08 | M34: =M16 -> 3202892 | P34: =PRODUCT(G34,I34,K34,M34)/1000 -> 6966.3285 | R34: =+[3]RES!C13 -> 198.48036 | S34: =S16 -> 0 | T34: =+[3]RES!E13 -> 222.1387 | X34: =+T34-R34 -> 23.658342 | Z34: =+P34*X34 -> 164811.78
A35: =+A34+1 -> 20 | C35: =+C17 -> 2021 | E35: =+E17 -> 2 | G35: =+G34 -> 2.055 | I35: 0.98 | K35: 1.08 | M35: =M17 -> 3208216 | P35: =PRODUCT(G35,I35,K35,M35)/1000 -> 6977.9083 | R35: =+[3]RES!C14 -> 234.81781 | S35: =S17 -> 0 | T35: =+[3]RES!E14 -> 221.20776 | X35: =+T35-R35 -> -13.610043 | Z35: =+P35*X35 -> -94969.629
A36: =+A35+1 -> 21 | C36: =+C18 -> 2021 | E36: =+E18 -> 3 | G36: =+G35 -> 2.055 | I36: 0.98 | K36: 1.08 | M36: =M18 -> 3214871 | P36: =PRODUCT(G36,I36,K36,M36)/1000 -> 6992.383 | R36: =+[3]RES!C15 -> 311.73519 | S36: =S18 -> 0 | T36: =+[3]RES!E15 -> 159.63419 | X36: =+T36-R36 -> -152.101 | Z36: =+P36*X36 -> -1063548.4
A37: =+A36+1 -> 22 | C37: =+C19 -> 2021 | E37: =+E19 -> 4 | G37: =+G36 -> 2.055 | I37: 0.98 | K37: 1.08 | M37: =M19 -> 3221873 | P37: =PRODUCT(G37,I37,K37,M37)/1000 -> 7007.6124 | R37: =+[3]RES!C16 -> 25.418094 | S37: =S19 -> 0 | T37: =+[3]RES!E16 -> 54.518173 | X37: =+T37-R37 -> 29.100079 | Z37: =+P37*X37 -> 203922.07
A38: =+A37+1 -> 23 | C38: =+C20 -> 2021 | E38: =+E20 -> 5 | G38: =+G37 -> 2.055 | I38: 0.98 | K38: 1.08 | M38: =M20 -> 3228777 | P38: =PRODUCT(G38,I38,K38,M38)/1000 -> 7022.6287 | R38: =+[3]RES!C17 -> 15.068166 | S38: =S20 -> 0 | T38: =+[3]RES!E17 -> 12.330437 | X38: =+T38-R38 -> -2.737729 | Z38: =+P38*X38 -> -19226.054
A39: =+A38+1 -> 24 | C39: =+C21 -> 2021 | E39: =+E21 -> 6 | G39: =+G38 -> 2.055 | I39: 0.98 | K39: 1.08 | M39: =M21 -> 3234379 | P39: =PRODUCT(G39,I39,K39,M39)/1000 -> 7034.8131 | R39: =+[3]RES!C18 -> 1.1050971 | S39: =S21 -> 0 | T39: =+[3]RES!E18 -> 1.0484189 | X39: =+T39-R39 -> -0.056678215 | Z39: =+P39*X39 -> -398.72065
A40: =+A39+1 -> 25 | C40: =+C22 -> 2021 | E40: =+E22 -> 7 | G40: =+G39 -> 2.055 | I40: 0.99 | K40: 1.08 | M40: =M22 -> 3236273 | P40: =PRODUCT(G40,I40,K40,M40)/1000 -> 7110.7585 | R40: =+[3]RES!C19 -> 0.000573952 | S40: =S22 -> 0 | T40: =+[3]RES!E19 -> 0.01068507 | X40: =+T40-R40 -> 0.010111118 | Z40: =+P40*X40 -> 71.897718
A41: =+A40+1 -> 26 | C41: =+C23 -> 2021 | E41: =+E23 -> 8 | G41: =+G40 -> 2.055 | I41: 0.99 | K41: 1.08 | M41: =M23 -> 3240184 | P41: =PRODUCT(G41,I41,K41,M41)/1000 -> 7119.3517 | R41: =+[3]RES!C20 -> 0 | S41: =S23 -> 0 | T41: =+[3]RES!E20 -> 0.00028478566 | X41: =+T41-R41 -> 0.00028478566 | Z41: =+P41*X41 -> 2.0274893
A42: =+A41+1 -> 27 | C42: =+C24 -> 2021 | E42: =+E24 -> 9 | G42: =+G41 -> 2.055 | I42: 0.99 | K42: 1.08 | M42: =M24 -> 3244734 | P42: =PRODUCT(G42,I42,K42,M42)/1000 -> 7129.349 | R42: =+[3]RES!C21 -> 0 | S42: =S24 -> 0 | T42: =+[3]RES!E21 -> 0.040852734 | X42: =+T42-R42 -> 0.040852734 | Z42: =+P42*X42 -> 291.2534
A43: =+A42+1 -> 28 | C43: =+C25 -> 2021 | E43: =+E25 -> 10 | G43: =+G42 -> 2.055 | I43: 0.99 | K43: 1.08 | M43: =M25 -> 3248681 | P43: =PRODUCT(G43,I43,K43,M43)/1000 -> 7138.0214 | R43: =+[3]RES!C22 -> 0.23066282 | S43: =S25 -> 0 | T43: =+[3]RES!E22 -> 2.2969845 | X43: =+T43-R43 -> 2.0663217 | Z43: =+P43*X43 -> 14749.448
A44: =+A43+1 -> 29 | C44: =+C26 -> 2021 | E44: =+E26 -> 11 | G44: =+G43 -> 2.055 | I44: 0.99 | K44: 1.08 | M44: =M26 -> 3253575 | P44: =PRODUCT(G44,I44,K44,M44)/1000 -> 7148.7745 | R44: =+[3]RES!C23 -> 16.472715 | S44: =S26 -> 0 | T44: =+[3]RES!E23 -> 26.81967 | X44: =+T44-R44 -> 10.346954 | Z44: =+P44*X44 -> 73968.044
...

Sheet SecLE10
W1: WP/II-H-1.2/1
W2: Page 3 of 8
A4: =+'Weather Adjustment'!A4 -> PUC DOCKET NO
A5: =+'Weather Adjustment'!A5 -> ONCOR ELECTRIC DELIVERY COMPANY LLC
A6: =+'Weather Adjustment'!A6 -> MONTHLY SALES DATA
A7: =+'Weather Adjustment'!A7 -> TEST YEAR ENDING December 31, 2021
A9: =+'Weather Adjustment'!A9 -> SPONSOR: D. E. NELSON
A11: Secondary Service Less Than or Equal to 10 KW Weather Adjustment (MWH)
G12: CDD Model | W12: CDD MWH
A13: Line | C13: Year | E13: Month | G13: Coefficient | J13: Customer | L13: Total GSL | M13: CDD Coefficient | O13: Actual CDD | Q13: Normal CDD | S13: Total GPL | U13: CDD Deviation | W13: Adjustment
A14: No. | G14: (a) | J14: (b) | M14: (c) = (a*b)/1000 | O14: (d) | Q14: (e) | U14: (f)=e-d | W14: (g)=c*f
A16: 1 | C16: =+'Weather Adjustment'!C16 -> 2021 | E16: =+'Weather Adjustment'!E16 -> 1 | G16: =+'[2]SECLE10KW Model'!$C$18 -> 0.459 | J16: =+'Weather Adjustment'!I35 -> 296726 | L16: =SUM(#REF!,J16) -> #REF! | M16: =PRODUCT(G16,J16)/1000 -> 136.19723 | O16: =+[3]SECLE10KW!D13 -> 0.030233678 | Q16: =+[3]SECLE10KW!F13 -> 1.1572295 | S16: =SUM(O16,Q16) -> 1.1874632 | U16: =+Q16-O16 -> 1.1269958 | W16: =+M16*U16 -> 153.49372
A17: =+A16+1 -> 2 | C17: =+'Weather Adjustment'!C17 -> 2021 | E17: =+'Weather Adjustment'!E17 -> 2 | G17: =+G16 -> 0.459 | J17: =+'Weather Adjustment'!I36 -> 296916 | L17: =SUM(#REF!,J17) -> #REF! | M17: =PRODUCT(G17,J17)/1000 -> 136.28444 | O17: =+[3]SECLE10KW!D14 -> 0.048966797 | Q17: =+[3]SECLE10KW!F14 -> 0.85820086 | S17: =SUM(O17,Q17) -> 0.90716765 | U17: =+Q17-O17 -> 0.80923406 | W17: =+M17*U17 -> 110.28601
A18: =+A17+1 -> 3 | C18: =+'Weather Adjustment'!C18 -> 2021 | E18: =+'Weather Adjustment'!E18 -> 3 | G18: =+G17 -> 0.459 | J18: =+'Weather Adjustment'!I37 -> 297390 | L18: =SUM(#REF!,J18) -> #REF! | M18: =PRODUCT(G18,J18)/1000 -> 136.50201 | O18: =+[3]SECLE10KW!D15 -> 2.2314074 | Q18: =+[3]SECLE10KW!F15 -> 3.3974681 | S18: =SUM(O18,Q18) -> 5.6288756 | U18: =+Q18-O18 -> 1.1660607 | W18: =+M18*U18 -> 159.16963
A19: =+A18+1 -> 4 | C19: =+'Weather Adjustment'!C19 -> 2021 | E19: =+'Weather Adjustment'!E19 -> 4 | G19: =+G18 -> 0.459 | J19: =+'Weather Adjustment'!I38 -> 299035 | L19: =SUM(#REF!,J19) -> #REF! | M19: =PRODUCT(G19,J19)/1000 -> 137.25707 | O19: =+[3]SECLE10KW!D16 -> 10.407034 | Q19: =+[3]SECLE10KW!F16 -> 16.036376 | S19: =SUM(O19,Q19) -> 26.44341 | U19: =+Q19-O19 -> 5.6293421 | W19: =+M19*U19 -> 772.66697
A20: =+A19+1 -> 5 | C20: =+'Weather Adjustment'!C20 -> 2021 | E20: =+'Weather Adjustment'!E20 -> 5 | G20: =+G19 -> 0.459 | J20: =+'Weather Adjustment'!I39 -> 299788 | L20: =SUM(#REF!,J20) -> #REF! | M20: =PRODUCT(G20,J20)/1000 -> 137.60269 | O20: =+[3]SECLE10KW!D17 -> 29.707023 | Q20: =+[3]SECLE10KW!F17 -> 55.888986 | S20: =SUM(O20,Q20) -> 85.59601 | U20: =+Q20-O20 -> 26.181963 | W20: =+M20*U20 -> 3602.7086
A21: =+A20+1 -> 6 | C21: =+'Weather Adjustment'!C21 -> 2021 | E21: =+'Weather Adjustment'!E21 -> 6 | G21: =+G20 -> 0.459 | J21: =+'Weather Adjustment'!I40 -> 300604 | L21: =SUM(#REF!,J21) -> #REF! | M21: =PRODUCT(G21,J21)/1000 -> 137.97724 | O21: =+[3]SECLE10KW!D18 -> 104.49326 | Q21: =+[3]SECLE10KW!F18 -> 162.59546 | S21: =SUM(O21,Q21) -> 267.08871 | U21: =+Q21-O21 -> 58.102203 | W21: =+M21*U21 -> 8016.7814
A22: =+A21+1 -> 7 | C22: =+'Weather Adjustment'!C22 -> 2021 | E22: =+'Weather Adjustment'!E22 -> 7 | G22: =+G21 -> 0.459 | J22: =+'Weather Adjustment'!I41 -> 301274 | L22: =SUM(#REF!,J22) -> #REF! | M22: =PRODUCT(G22,J22)/1000 -> 138.28477 | O22: =+[3]SECLE10KW!D19 -> 264.9267 | Q22: =+[3]SECLE10KW!F19 -> 295.55719 | S22: =SUM(O22,Q22) -> 560.48389 | U22: =+Q22-O22 -> 30.630484 | W22: =+M22*U22 -> 4235.7293
A23: =+A22+1 -> 8 | C23: =+'Weather Adjustment'!C23 -> 2021 | E23: =+'Weather Adjustment'!E23 -> 8 | G23: =+G22 -> 0.459 | J23: =+'Weather Adjustment'!I42 -> 301519 | L23: =SUM(#REF!,J23) -> #REF! | M23: =PRODUCT(G23,J23)/1000 -> 138.39722 | O23: =+[3]SECLE10KW!D20 -> 291.07938 | Q23: =+[3]SECLE10KW!F20 -> 347.2864 | S23: =SUM(O23,Q23) -> 638.36577 | U23: =+Q23-O23 -> 56.20702 | W23: =+M23*U23 -> 7778.8953
A24: =+A23+1 -> 9 | C24: =+'Weather Adjustment'!C24 -> 2021 | E24: =+'Weather Adjustment'!E24 -> 9 | G24: =+G23 -> 0.459 | J24: =+'Weather Adjustment'!I43 -> 302471 | L24: =SUM(#REF!,J24) -> #REF! | M24: =PRODUCT(G24,J24)/1000 -> 138.83419 | O24: =+[3]SECLE10KW!D21 -> 290.82404 | Q24: =+[3]SECLE10KW!F21 -> 295.00143 | S24: =SUM(O24,Q24) -> 585.82546 | U24: =+Q24-O24 -> 4.1773909 | W24: =+M24*U24 -> 579.96468
A25: =+A24+1 -> 10 | C25: =+'Weather Adjustment'!C25 -> 2021 | E25: =+'Weather Adjustment'!E25 -> 10 | G25: =+G24 -> 0.459 | J25: =+'Weather Adjustment'!I44 -> 303108 | L25: =SUM(#REF!,J25) -> #REF! | M25: =PRODUCT(G25,J25)/1000 -> 139.12657 | O25: =+[3]SECLE10KW!D22 -> 160.55565 | Q25: =+[3]SECLE10KW!F22 -> 150.60567 | S25: =SUM(O25,Q25) -> 311.16132 | U25: =+Q25-O25 -> -9.9499835 | W25: =+M25*U25 -> -1384.3071
A26: =+A25+1 -> 11 | C26: =+'Weather Adjustment'!C26 -> 2021 | E26: =+'Weather Adjustment'!E26 -> 11 | G26: =+G25 -> 0.459 | J26: =+'Weather Adjustment'!I45 -> 303828 | L26: =SUM(#REF!,J26) -> #REF! | M26: =PRODUCT(G26,J26)/1000 -> 139.45705 | O26: =+[3]SECLE10KW!D23 -> 49.788205 | Q26: =+[3]SECLE10KW!F23 -> 40.273432 | S26: =SUM(O26,Q26) -> 90.061637 | U26: =+Q26-O26 -> -9.5147727 | W26: =+M26*U26 -> -1326.9021
A27: =+A26+1 -> 12 | C27: =+'Weather Adjustment'!C27 -> 2021 | E27: =+'Weather Adjustment'!E27 -> 12 | G27: =+G26 -> 0.459 | J27: =+'Weather Adjustment'!I46 -> 304430 | L27: =SUM(#REF!,J27) -> #REF! | M27: =PRODUCT(G27,J27)/1000 -> 139.73337 | O27: =+[3]SECLE10KW!D24 -> 5.0759949 | Q27: =+[3]SECLE10KW!F24 -> 6.3991376 | S27: =SUM(O27,Q27) -> 11.475132 | U27: =+Q27-O27 -> 1.3231427 | W27: =+M27*U27 -> 184.88719
A28: =+A27+1 -> 13 | C28: Total | L28: =SUM(L22:L27) -> #REF! | O28: =SUM(O16:O27) -> 1209.1679 | Q28: =SUM(Q16:Q27) -> 1375.057 | S28: =SUM(S22:S27) -> 2197.3732 | U28: =+Q28-O28 -> 165.88908 | W28: =SUM(W16:W27) -> 22883.374
A29: =+A28+1 -> 14
A30: =+A29+1 -> 15 | G30: HDD Model | W30: HDD MWH
A31: =+A30+1 -> 16 | C31: Year | E31: Month | G31: Coefficient | J31: Customer | L31: Total GSL | M31: HDD Coefficient | O31: Actual HDD | Q31: Normal HDD | S31: Total GPL | U31: HDD Deviation | W31: Adjustment
A32: =+A31+1 -> 17 | G32: (h) | J32: (i) | M32: (j) = (h*i)/1000 | O32: (k) | Q32: (l) | U32: (m)=l-k | W32: (n)=j*m
A33: =+A32+1 -> 18
A34: =+A33+1 -> 19 | C34: =+C16 -> 2021 | E34: =+E16 -> 1 | G34: =+'[2]SECLE10KW Model'!$C$17 -> 0.298 | J34: =J16 -> 296726 | M34: =PRODUCT(G34,J34)/1000 -> 88.424348 | O34: =+[3]SECLE10KW!C13 -> 227.60778 | Q34: =+[3]SECLE10KW!E13 -> 249.97401 | U34: =+Q34-O34 -> 22.366228 | W34: =+M34*U34 -> 1977.7191
A35: =+A34+1 -> 20 | C35: =+C17 -> 2021 | E35: =+E17 -> 2 | G35: =+G34 -> 0.298 | J35: =J17 -> 296916 | M35: =PRODUCT(G35,J35)/1000 -> 88.480968 | O35: =+[3]SECLE10KW!C14 -> 260.63814 | Q35: =+[3]SECLE10KW!E14 -> 247.18635 | U35: =+Q35-O35 -> -13.451785 | W35: =+M35*U35 -> -1190.227
A36: =+A35+1 -> 21 | C36: =+C18 -> 2021 | E36: =+E18 -> 3 | G36: =+G35 -> 0.298 | J36: =J18 -> 297390 | M36: =PRODUCT(G36,J36)/1000 -> 88.62222 | O36: =+[3]SECLE10KW!C15 -> 335.05091 | Q36: =+[3]SECLE10KW!E15 -> 176.7001 | U36: =+Q36-O36 -> -158.35081 | W36: =+M36*U36 -> -14033.401
A37: =+A36+1 -> 22 | C37: =+C19 -> 2021 | E37: =+E19 -> 4 | G37: =+G36 -> 0.298 | J37: =J19 -> 299035 | M37: =PRODUCT(G37,J37)/1000 -> 89.11243 | O37: =+[3]SECLE10KW!C16 -> 27.542777 | Q37: =+[3]SECLE10KW!E16 -> 59.318213 | U37: =+Q37-O37 -> 31.775436 | W37: =+M37*U37 -> 2831.5863
A38: =+A37+1 -> 23 | C38: =+C20 -> 2021 | E38: =+E20 -> 5 | G38: =+G37 -> 0.298 | J38: =J20 -> 299788 | M38: =PRODUCT(G38,J38)/1000 -> 89.336824 | O38: =+[3]SECLE10KW!C17 -> 17.076908 | Q38: =+[3]SECLE10KW!E17 -> 12.705528 | U38: =+Q38-O38 -> -4.3713792 | W38: =+M38*U38 -> -390.52513
A39: =+A38+1 -> 24 | C39: =+C21 -> 2021 | E39: =+E21 -> 6 | G39: =+G38 -> 0.298 | J39: =J21 -> 300604 | M39: =PRODUCT(G39,J39)/1000 -> 89.579992 | O39: =+[3]SECLE10KW!C18 -> 0.76411786 | Q39: =+[3]SECLE10KW!E18 -> 0.93800258 | U39: =+Q39-O39 -> 0.17388472 | W39: =+M39*U39 -> 15.576592
A40: =+A39+1 -> 25 | C40: =+C22 -> 2021 | E40: =+E22 -> 7 | G40: =+G39 -> 0.298 | J40: =J22 -> 301274 | M40: =PRODUCT(G40,J40)/1000 -> 89.779652 | O40: =+[3]SECLE10KW!C19 -> 0 | Q40: =+[3]SECLE10KW!E19 -> 0.0056579716 | U40: =+Q40-O40 -> 0.0056579716 | W40: =+M40*U40 -> 0.50797072
A41: =+A40+1 -> 26 | C41: =+C23 -> 2021 | E41: =+E23 -> 8 | G41: =+G40 -> 0.298 | J41: =J23 -> 301519 | M41: =PRODUCT(G41,J41)/1000 -> 89.852662 | O41: =+[3]SECLE10KW!C20 -> 0 | Q41: =+[3]SECLE10KW!E20 -> 0 | U41: =+Q41-O41 -> 0 | W41: =+M41*U41 -> 0
A42: =+A41+1 -> 27 | C42: =+C24 -> 2021 | E42: =+E24 -> 9 | G42: =+G41 -> 0.298 | J42: =J24 -> 302471 | M42: =PRODUCT(G42,J42)/1000 -> 90.136358 | O42: =+[3]SECLE10KW!C21 -> 0 | Q42: =+[3]SECLE10KW!E21 -> 0.053763679 | U42: =+Q42-O42 -> 0.053763679 | W42: =+M42*U42 -> 4.8460622
A43: =+A42+1 -> 28 | C43: =+C25 -> 2021 | E43: =+E25 -> 10 | G43: =+G42 -> 0.298 | J43: =J25 -> 303108 | M43: =PRODUCT(G43,J43)/1000 -> 90.326184 | O43: =+[3]SECLE10KW!C22 -> 0.14014841 | Q43: =+[3]SECLE10KW!E22 -> 2.3127376 | U43: =+Q43-O43 -> 2.1725892 | W43: =+M43*U43 -> 196.24169
A44: =+A43+1 -> 29 | C44: =+C26 -> 2021 | E44: =+E26 -> 11 | G44: =+G43 -> 0.298 | J44: =J26 -> 303828 | M44: =PRODUCT(G44,J44)/1000 -> 90.540744 | O44: =+[3]SECLE10KW!C23 -> 17.173434 | Q44: =+[3]SECLE10KW!E23 -> 29.299255 | U44: =+Q44-O44 -> 12.125821 | W44: =+M44*U44 -> 1097.8808
...

Sheet SecGT10
W1: WP/II-H-1.2/1
W2: Page 4 of 8
A4: =+'Weather Adjustment'!A4 -> PUC DOCKET NO
A5: =+'Weather Adjustment'!A5 -> ONCOR ELECTRIC DELIVERY COMPANY LLC
A6: =+'Weather Adjustment'!A6 -> MONTHLY SALES DATA
A7: =+'Weather Adjustment'!A7 -> TEST YEAR ENDING December 31, 2021
A9: =+'Weather Adjustment'!A9 -> SPONSOR: D. E. NELSON
A11: Secondary Service Greater Than 10 KW Weather Adjustment (MWH)
G12: CDD Model | W12: CDD MWH
A13: Line | C13: Year | E13: Month | G13: Coefficient | J13: Customer | L13: Total GSL | M13: CDD Coefficient | O13: Actual CDD | Q13: Normal CDD | S13: Total GPL | U13: CDD Deviation | W13: Adjustment
A14: No. | G14: (a) | J14: (b) | M14: (c) = (a*b)/1000 | O14: (d) | Q14: (e) | U14: (f)=e-d | W14: (g)=c*f
A16: 1 | C16: =+'Weather Adjustment'!C16 -> 2021 | E16: =+'Weather Adjustment'!E16 -> 1 | G16: =+'[2]SECGT10KW Model'!$C$18 -> 11.532 | J16: =SUM('Weather Adjustment'!K35,'Weather Adjustment'!M35) -> 200356 | L16: =SUM(#REF!,J16) -> #REF! | M16: =PRODUCT(G16,J16)/1000 -> 2310.5054 | O16: =+[3]SECGT10KW!D13 -> 0.6271704 | Q16: =+[3]SECGT10KW!F13 -> 6.1106059 | S16: =SUM(O16,Q16) -> 6.7377763 | U16: =+Q16-O16 -> 5.4834355 | W16: =+M16*U16 -> 12669.507
A17: =+A16+1 -> 2 | C17: =+'Weather Adjustment'!C17 -> 2021 | E17: =+'Weather Adjustment'!E17 -> 2 | G17: =+G16 -> 11.532 | J17: =SUM('Weather Adjustment'!K36,'Weather Adjustment'!M36) -> 200932 | L17: =SUM(#REF!,J17) -> #REF! | M17: =PRODUCT(G17,J17)/1000 -> 2317.1478 | O17: =+[3]SECGT10KW!D14 -> 0.92251588 | Q17: =+[3]SECGT10KW!F14 -> 4.9269095 | S17: =SUM(O17,Q17) -> 5.8494254 | U17: =+Q17-O17 -> 4.0043937 | W17: =+M17*U17 -> 9278.7721
A18: =+A17+1 -> 3 | C18: =+'Weather Adjustment'!C18 -> 2021 | E18: =+'Weather Adjustment'!E18 -> 3 | G18: =+G17 -> 11.532 | J18: =SUM('Weather Adjustment'!K37,'Weather Adjustment'!M37) -> 201930 | L18: =SUM(#REF!,J18) -> #REF! | M18: =PRODUCT(G18,J18)/1000 -> 2328.6568 | O18: =+[3]SECGT10KW!D15 -> 10.113474 | Q18: =+[3]SECGT10KW!F15 -> 15.108543 | S18: =SUM(O18,Q18) -> 25.222017 | U18: =+Q18-O18 -> 4.9950686 | W18: =+M18*U18 -> 11631.8
A19: =+A18+1 -> 4 | C19: =+'Weather Adjustment'!C19 -> 2021 | E19: =+'Weather Adjustment'!E19 -> 4 | G19: =+G18 -> 11.532 | J19: =SUM('Weather Adjustment'!K38,'Weather Adjustment'!M38) -> 201951 | L19: =SUM(#REF!,J19) -> #REF! | M19: =PRODUCT(G19,J19)/1000 -> 2328.8989 | O19: =+[3]SECGT10KW!D16 -> 41.906624 | Q19: =+[3]SECGT10KW!F16 -> 50.859093 | S19: =SUM(O19,Q19) -> 92.765717 | U19: =+Q19-O19 -> 8.9524696 | W19: =+M19*U19 -> 20849.397
A20: =+A19+1 -> 5 | C20: =+'Weather Adjustment'!C20 -> 2021 | E20: =+'Weather Adjustment'!E20 -> 5 | G20: =+G19 -> 11.532 | J20: =SUM('Weather Adjustment'!K39,'Weather Adjustment'!M39) -> 202319 | L20: =SUM(#REF!,J20) -> #REF! | M20: =PRODUCT(G20,J20)/1000 -> 2333.1427 | O20: =+[3]SECGT10KW!D17 -> 83.825441 | Q20: =+[3]SECGT10KW!F17 -> 131.16836 | S20: =SUM(O20,Q20) -> 214.9938 | U20: =+Q20-O20 -> 47.342919 | W20: =+M20*U20 -> 110457.79
A21: =+A20+1 -> 6 | C21: =+'Weather Adjustment'!C21 -> 2021 | E21: =+'Weather Adjustment'!E21 -> 6 | G21: =+G20 -> 11.532 | J21: =SUM('Weather Adjustment'!K40,'Weather Adjustment'!M40) -> 202660 | L21: =SUM(#REF!,J21) -> #REF! | M21: =PRODUCT(G21,J21)/1000 -> 2337.0751 | O21: =+[3]SECGT10KW!D18 -> 215.24178 | Q21: =+[3]SECGT10KW!F18 -> 298.31217 | S21: =SUM(O21,Q21) -> 513.55395 | U21: =+Q21-O21 -> 83.070398 | W21: =+M21*U21 -> 194141.76
A22: =+A21+1 -> 7 | C22: =+'Weather Adjustment'!C22 -> 2021 | E22: =+'Weather Adjustment'!E22 -> 7 | G22: =+G21 -> 11.532 | J22: =SUM('Weather Adjustment'!K41,'Weather Adjustment'!M41) -> 203069 | L22: =SUM(#REF!,J22) -> #REF! | M22: =PRODUCT(G22,J22)/1000 -> 2341.7917 | O22: =+[3]SECGT10KW!D19 -> 453.60494 | Q22: =+[3]SECGT10KW!F19 -> 483.81602 | S22: =SUM(O22,Q22) -> 937.42097 | U22: =+Q22-O22 -> 30.211079 | W22: =+M22*U22 -> 70748.055
A23: =+A22+1 -> 8 | C23: =+'Weather Adjustment'!C23 -> 2021 | E23: =+'Weather Adjustment'!E23 -> 8 | G23: =+G22 -> 11.532 | J23: =SUM('Weather Adjustment'!K42,'Weather Adjustment'!M42) -> 203456 | L23: =SUM(#REF!,J23) -> #REF! | M23: =PRODUCT(G23,J23)/1000 -> 2346.2546 | O23: =+[3]SECGT10KW!D20 -> 485.78196 | Q23: =+[3]SECGT10KW!F20 -> 542.70056 | S23: =SUM(O23,Q23) -> 1028.4825 | U23: =+Q23-O23 -> 56.918602 | W23: =+M23*U23 -> 133545.53
A24: =+A23+1 -> 9 | C24: =+'Weather Adjustment'!C24 -> 2021 | E24: =+'Weather Adjustment'!E24 -> 9 | G24: =+G23 -> 11.532 | J24: =SUM('Weather Adjustment'!K43,'Weather Adjustment'!M43) -> 203320 | L24: =SUM(#REF!,J24) -> #REF! | M24: =PRODUCT(G24,J24)/1000 -> 2344.6862 | O24: =+[3]SECGT10KW!D21 -> 482.78489 | Q24: =+[3]SECGT10KW!F21 -> 478.81686 | S24: =SUM(O24,Q24) -> 961.60176 | U24: =+Q24-O24 -> -3.9680321 | W24: =+M24*U24 -> -9303.7902
A25: =+A24+1 -> 10 | C25: =+'Weather Adjustment'!C25 -> 2021 | E25: =+'Weather Adjustment'!E25 -> 10 | G25: =+G24 -> 11.532 | J25: =SUM('Weather Adjustment'!K44,'Weather Adjustment'!M44) -> 203377 | L25: =SUM(#REF!,J25) -> #REF! | M25: =PRODUCT(G25,J25)/1000 -> 2345.3436 | O25: =+[3]SECGT10KW!D22 -> 304.8849 | Q25: =+[3]SECGT10KW!F22 -> 283.02325 | S25: =SUM(O25,Q25) -> 587.90816 | U25: =+Q25-O25 -> -21.861648 | W25: =+M25*U25 -> -51273.076
A26: =+A25+1 -> 11 | C26: =+'Weather Adjustment'!C26 -> 2021 | E26: =+'Weather Adjustment'!E26 -> 11 | G26: =+G25 -> 11.532 | J26: =SUM('Weather Adjustment'!K45,'Weather Adjustment'!M45) -> 203317 | L26: =SUM(#REF!,J26) -> #REF! | M26: =PRODUCT(G26,J26)/1000 -> 2344.6516 | O26: =+[3]SECGT10KW!D23 -> 119.77918 | Q26: =+[3]SECGT10KW!F23 -> 98.325128 | S26: =SUM(O26,Q26) -> 218.10431 | U26: =+Q26-O26 -> -21.45405 | W26: =+M26*U26 -> -50302.273
A27: =+A26+1 -> 12 | C27: =+'Weather Adjustment'!C27 -> 2021 | E27: =+'Weather Adjustment'!E27 -> 12 | G27: =+G26 -> 11.532 | J27: =SUM('Weather Adjustment'!K46,'Weather Adjustment'!M46) -> 203588 | L27: =SUM(#REF!,J27) -> #REF! | M27: =PRODUCT(G27,J27)/1000 -> 2347.7768 | O27: =+[3]SECGT10KW!D24 -> 23.960054 | Q27: =+[3]SECGT10KW!F24 -> 23.726328 | S27: =SUM(O27,Q27) -> 47.686382 | U27: =+Q27-O27 -> -0.23372626 | W27: =+M27*U27 -> -548.73709
A28: =+A27+1 -> 13 | C28: Total | L28: =SUM(L22:L27) -> #REF! | O28: =SUM(O16:O27) -> 2223.4329 | Q28: =SUM(Q16:Q27) -> 2416.8938 | S28: =SUM(S22:S27) -> 3781.2041 | U28: =+Q28-O28 -> 193.46091 | W28: =SUM(W16:W27) -> 451894.73
A29: =+A28+1 -> 14
A30: =+A29+1 -> 15 | G30: HDD Model | W30: HDD MWH
A31: =+A30+1 -> 16 | C31: Year | E31: Month | G31: Coefficient | J31: Customer | L31: Total GSL | M31: HDD Coefficient | O31: Actual HDD | Q31: Normal HDD | S31: Total GPL | U31: HDD Deviation | W31: Adjustment
A32: =+A31+1 -> 17 | G32: (h) | J32: (i) | M32: (j) = (h*i)/1000 | O32: (k) | Q32: (l) | U32: (m)=l-k | W32: (n)=j*m
A33: =+A32+1 -> 18
A34: =+A33+1 -> 19 | C34: =+C16 -> 2021 | E34: =+E16 -> 1 | G34: =+'[2]SECGT10KW Model'!$C$17 -> 5.945 | J34: =J16 -> 200356 | M34: =PRODUCT(G34,J34)/1000 -> 1191.1164 | O34: =+[3]SECGT10KW!C13 -> 134.51539 | Q34: =+[3]SECGT10KW!E13 -> 162.21444 | U34: =+Q34-O34 -> 27.699054 | W34: =+M34*U34 -> 32992.798
A35: =+A34+1 -> 20 | C35: =+C17 -> 2021 | E35: =+E17 -> 2 | G35: =+G34 -> 5.945 | J35: =J17 -> 200932 | M35: =PRODUCT(G35,J35)/1000 -> 1194.5407 | O35: =+[3]SECGT10KW!C14 -> 171.54456 | Q35: =+[3]SECGT10KW!E14 -> 164.21034 | U35: =+Q35-O35 -> -7.3342222 | W35: =+M35*U35 -> -8761.0272
A36: =+A35+1 -> 21 | C36: =+C18 -> 2021 | E36: =+E18 -> 3 | G36: =+G35 -> 5.945 | J36: =J18 -> 201930 | M36: =PRODUCT(G36,J36)/1000 -> 1200.4739 | O36: =+[3]SECGT10KW!C15 -> 264.56696 | Q36: =+[3]SECGT10KW!E15 -> 112.33559 | U36: =+Q36-O36 -> -152.23136 | W36: =+M36*U36 -> -182749.77
A37: =+A36+1 -> 22 | C37: =+C19 -> 2021 | E37: =+E19 -> 4 | G37: =+G36 -> 5.945 | J37: =J19 -> 201951 | M37: =PRODUCT(G37,J37)/1000 -> 1200.5987 | O37: =+[3]SECGT10KW!C16 -> 6.917914 | Q37: =+[3]SECGT10KW!E16 -> 30.226601 | U37: =+Q37-O37 -> 23.308687 | W37: =+M37*U37 -> 27984.38
A38: =+A37+1 -> 23 | C38: =+C20 -> 2021 | E38: =+E20 -> 5 | G38: =+G37 -> 5.945 | J38: =J20 -> 202319 | M38: =PRODUCT(G38,J38)/1000 -> 1202.7865 | O38: =+[3]SECGT10KW!C17 -> 3.5402955 | Q38: =+[3]SECGT10KW!E17 -> 4.6883675 | U38: =+Q38-O38 -> 1.148072 | W38: =+M38*U38 -> 1380.8854
A39: =+A38+1 -> 24 | C39: =+C21 -> 2021 | E39: =+E21 -> 6 | G39: =+G38 -> 5.945 | J39: =J21 -> 202660 | M39: =PRODUCT(G39,J39)/1000 -> 1204.8137 | O39: =+[3]SECGT10KW!C18 -> 0.0073839905 | Q39: =+[3]SECGT10KW!E18 -> 0.19474972 | U39: =+Q39-O39 -> 0.18736573 | W39: =+M39*U39 -> 225.7408
A40: =+A39+1 -> 25 | C40: =+C22 -> 2021 | E40: =+E22 -> 7 | G40: =+G39 -> 5.945 | J40: =J22 -> 203069 | M40: =PRODUCT(G40,J40)/1000 -> 1207.2452 | O40: =+[3]SECGT10KW!C19 -> 0 | Q40: =+[3]SECGT10KW!E19 -> 0.00027694168 | U40: =+Q40-O40 -> 0.00027694168 | W40: =+M40*U40 -> 0.33433651
A41: =+A40+1 -> 26 | C41: =+C23 -> 2021 | E41: =+E23 -> 8 | G41: =+G40 -> 5.945 | J41: =J23 -> 203456 | M41: =PRODUCT(G41,J41)/1000 -> 1209.5459 | O41: =+[3]SECGT10KW!C20 -> 0 | Q41: =+[3]SECGT10KW!E20 -> 0 | U41: =+Q41-O41 -> 0 | W41: =+M41*U41 -> 0
A42: =+A41+1 -> 27 | C42: =+C24 -> 2021 | E42: =+E24 -> 9 | G42: =+G41 -> 5.945 | J42: =J24 -> 203320 | M42: =PRODUCT(G42,J42)/1000 -> 1208.7374 | O42: =+[3]SECGT10KW!C21 -> 0 | Q42: =+[3]SECGT10KW!E21 -> 0.01116731 | U42: =+Q42-O42 -> 0.01116731 | W42: =+M42*U42 -> 13.498346
A43: =+A42+1 -> 28 | C43: =+C25 -> 2021 | E43: =+E25 -> 10 | G43: =+G42 -> 5.945 | J43: =J25 -> 203377 | M43: =PRODUCT(G43,J43)/1000 -> 1209.0763 | O43: =+[3]SECGT10KW!C22 -> 0.0014767981 | Q43: =+[3]SECGT10KW!E22 -> 0.6810983 | U43: =+Q43-O43 -> 0.6796215 | W43: =+M43*U43 -> 821.71423
A44: =+A43+1 -> 29 | C44: =+C26 -> 2021 | E44: =+E26 -> 11 | G44: =+G43 -> 5.945 | J44: =J26 -> 203317 | M44: =PRODUCT(G44,J44)/1000 -> 1208.7196 | O44: =+[3]SECGT10KW!C23 -> 5.8355129 | Q44: =+[3]SECGT10KW!E23 -> 12.540238 | U44: =+Q44-O44 -> 6.7047254 | W44: =+M44*U44 -> 8104.1328
...

Sheet SGT10_IDR_NIDR
Q1: WP/II-H-1.2/1
Q2: Page 5 of 8
A4: =+'Weather Adjustment'!A4 -> PUC DOCKET NO
A5: =+'Weather Adjustment'!A5 -> ONCOR ELECTRIC DELIVERY COMPANY LLC
A6: =+'Weather Adjustment'!A6 -> MONTHLY SALES DATA
A7: =+'Weather Adjustment'!A7 -> TEST YEAR ENDING December 31, 2021
A9: =+'Weather Adjustment'!A9 -> SPONSOR: D. E. NELSON
C11: Secondary Service Greater Than 10 KW IDR and Non-IDR Weather Adjustment (MWH)
G12: SECGT10 | J12: SECGT10 | M12: SECGT10 | O12: SECGT10 | Q12: SECGT10
A13: Line | C13: Year | E13: Month | G13: IDR KWH | J13: NIDR KWH | L13: Total GSL | M13: Large KWH | O13: IDR KWH Share | Q13: NIDR KWH Share
G14: (a) | J14: (b) | M14: (c) | O14: (d)=a/c | Q14: (e)=b/c
A16: 1 | C16: =+'Weather Adjustment'!C16 -> 2021 | E16: =+'Weather Adjustment'!E16 -> 1 | G16: =+'[1]GS SEC LRG IDR '!I16 -> 1351918368 | J16: =+'[1]GS SEC LRG NONIDR'!I16 -> 1998993921 | L16: =SUM(#REF!,J16) -> #REF! | M16: =SUM(G16,J16) -> 3350912289 | O16: =+G16/M16 -> 0.40344785 | Q16: =+J16/M16 -> 0.59655215
A17: =+A16+1 -> 2 | C17: =+'Weather Adjustment'!C17 -> 2021 | E17: =+'Weather Adjustment'!E17 -> 2 | G17: =+'[1]GS SEC LRG IDR '!I18 -> 1326371430 | J17: =+'[1]GS SEC LRG NONIDR'!I18 -> 1977503676 | L17: =SUM(#REF!,J17) -> #REF! | M17: =SUM(G17,J17) -> 3303875106 | O17: =+G17/M17 -> 0.40145931 | Q17: =+J17/M17 -> 0.59854069
A18: =+A17+1 -> 3 | C18: =+'Weather Adjustment'!C18 -> 2021 | E18: =+'Weather Adjustment'!E18 -> 3 | G18: =+'[1]GS SEC LRG IDR '!I20 -> 1339560309 | J18: =+'[1]GS SEC LRG NONIDR'!I20 -> 2201181387 | L18: =SUM(#REF!,J18) -> #REF! | M18: =SUM(G18,J18) -> 3540741696 | O18: =+G18/M18 -> 0.3783276 | Q18: =+J18/M18 -> 0.6216724
A19: =+A18+1 -> 4 | C19: =+'Weather Adjustment'!C19 -> 2021 | E19: =+'Weather Adjustment'!E19 -> 4 | G19: =+'[1]GS SEC LRG IDR '!I22 -> 1346806153 | J19: =+'[1]GS SEC LRG NONIDR'!I22 -> 1800792498 | L19: =SUM(#REF!,J19) -> #REF! | M19: =SUM(G19,J19) -> 3147598651 | O19: =+G19/M19 -> 0.4278837 | Q19: =+J19/M19 -> 0.5721163
A20: =+A19+1 -> 5 | C20: =+'Weather Adjustment'!C20 -> 2021 | E20: =+'Weather Adjustment'!E20 -> 5 | G20: =+'[1]GS SEC LRG IDR '!I24 -> 1406273540 | J20: =+'[1]GS SEC LRG NONIDR'!I24 -> 2029244473 | L20: =SUM(#REF!,J20) -> #REF! | M20: =SUM(G20,J20) -> 3435518013 | O20: =+G20/M20 -> 0.40933377 | Q20: =+J20/M20 -> 0.59066623
A21: =+A20+1 -> 6 | C21: =+'Weather Adjustment'!C21 -> 2021 | E21: =+'Weather Adjustment'!E21 -> 6 | G21: =+'[1]GS SEC LRG IDR '!I26 -> 1462016083 | J21: =+'[1]GS SEC LRG NONIDR'!I26 -> 2281615721 | L21: =SUM(#REF!,J21) -> #REF! | M21: =SUM(G21,J21) -> 3743631804 | O21: =+G21/M21 -> 0.39053415 | Q21: =+J21/M21 -> 0.60946585
A22: =+A21+1 -> 7 | C22: =+'Weather Adjustment'!C22 -> 2021 | E22: =+'Weather Adjustment'!E22 -> 7 | G22: =+'[1]GS SEC LRG IDR '!I28 -> 1695733062 | J22: =+'[1]GS SEC LRG NONIDR'!I28 -> 2773542025 | L22: =SUM(#REF!,J22) -> #REF! | M22: =SUM(G22,J22) -> 4469275087 | O22: =+G22/M22 -> 0.37942016 | Q22: =+J22/M22 -> 0.62057984
A23: =+A22+1 -> 8 | C23: =+'Weather Adjustment'!C23 -> 2021 | E23: =+'Weather Adjustment'!E23 -> 8 | G23: =+'[1]GS SEC LRG IDR '!I30 -> 1697138007 | J23: =+'[1]GS SEC LRG NONIDR'!I30 -> 2813879859 | L23: =SUM(#REF!,J23) -> #REF! | M23: =SUM(G23,J23) -> 4511017866 | O23: =+G23/M23 -> 0.37622064 | Q23: =+J23/M23 -> 0.62377936
A24: =+A23+1 -> 9 | C24: =+'Weather Adjustment'!C24 -> 2021 | E24: =+'Weather Adjustment'!E24 -> 9 | G24: =+'[1]GS SEC LRG IDR '!I32 -> 1692406091 | J24: =+'[1]GS SEC LRG NONIDR'!I32 -> 2861233955 | L24: =SUM(#REF!,J24) -> #REF! | M24: =SUM(G24,J24) -> 4553640046 | O24: =+G24/M24 -> 0.37166005 | Q24: =+J24/M24 -> 0.62833995
A25: =+A24+1 -> 10 | C25: =+'Weather Adjustment'!C25 -> 2021 | E25: =+'Weather Adjustment'!E25 -> 10 | G25: =+'[1]GS SEC LRG IDR '!I34 -> 1554722199 | J25: =+'[1]GS SEC LRG NONIDR'!I34 -> 2450797322 | L25: =SUM(#REF!,J25) -> #REF! | M25: =SUM(G25,J25) -> 4005519521 | O25: =+G25/M25 -> 0.38814496 | Q25: =+J25/M25 -> 0.61185504
A26: =+A25+1 -> 11 | C26: =+'Weather Adjustment'!C26 -> 2021 | E26: =+'Weather Adjustment'!E26 -> 11 | G26: =+'[1]GS SEC LRG IDR '!I36 -> 1463865882 | J26: =+'[1]GS SEC LRG NONIDR'!I36 -> 2065732092 | L26: =SUM(#REF!,J26) -> #REF! | M26: =SUM(G26,J26) -> 3529597974 | O26: =+G26/M26 -> 0.41474012 | Q26: =+J26/M26 -> 0.58525988
A27: =+A26+1 -> 12 | C27: =+'Weather Adjustment'!C27 -> 2021 | E27: =+'Weather Adjustment'!E27 -> 12 | G27: =+'[1]GS SEC LRG IDR '!I38 -> 1408196282 | J27: =+'[1]GS SEC LRG NONIDR'!I38 -> 1930751950 | L27: =SUM(#REF!,J27) -> #REF! | M27: =SUM(G27,J27) -> 3338948232 | O27: =+G27/M27 -> 0.42174846 | Q27: =+J27/M27 -> 0.57825154
A28: =+A27+1 -> 13 | C28: Total | G28: =SUM(G16:G27) -> 17745007406 | J28: =SUM(J16:J27) -> 27185268879 | L28: =SUM(L22:L27) -> #REF! | M28: =SUM(M16:M27) -> 44930276285
A29: =+A28+1 -> 14
A30: =+A29+1 -> 15 | G30: SECGT10 | J30: SECGT10 | M30: SECGT10
A31: =+A30+1 -> 16 | C31: Year | E31: Month | G31: KWH Adjustment | J31: IDR KWH Adjustment | L31: Total GSL | M31: NIDR KWH Adjustment
A32: =+A31+1 -> 17 | G32: (f) | J32: (g)=f*d | M32: (h)=f-g
A33: =+A32+1 -> 18
A34: =+A33+1 -> 19 | C34: =+C16 -> 2021 | E34: =+E16 -> 1 | G34: =+SecGT10!W52 -> 45662.305 | J34: =+G34*O16 -> 18422.359 | M34: =+G34-J34 -> 27239.946
A35: =+A34+1 -> 20 | C35: =+C17 -> 2021 | E35: =+E17 -> 2 | G35: =+SecGT10!W53 -> 517.7449 | J35: =+G35*O17 -> 207.85351 | M35: =+G35-J35 -> 309.89139
A36: =+A35+1 -> 21 | C36: =+C18 -> 2021 | E36: =+E18 -> 3 | G36: =+SecGT10!W54 -> -171117.97 | J36: =+G36*O18 -> -64738.651 | M36: =+G36-J36 -> -106379.32
A37: =+A36+1 -> 22 | C37: =+C19 -> 2021 | E37: =+E19 -> 4 | G37: =+SecGT10!W55 -> 48833.776 | J37: =+G37*O19 -> 20895.177 | M37: =+G37-J37 -> 27938.6
A38: =+A37+1 -> 23 | C38: =+C20 -> 2021 | E38: =+E20 -> 5 | G38: =+SecGT10!W56 -> 111838.67 | J38: =+G38*O20 -> 45779.345 | M38: =+G38-J38 -> 66059.327
A39: =+A38+1 -> 24 | C39: =+C21 -> 2021 | E39: =+E21 -> 6 | G39: =+SecGT10!W57 -> 194367.5 | J39: =+G39*O21 -> 75907.148 | M39: =+G39-J39 -> 118460.35
A40: =+A39+1 -> 25 | C40: =+C22 -> 2021 | E40: =+E22 -> 7 | G40: =+SecGT10!W58 -> 70748.389 | J40: =+G40*O22 -> 26843.365 | M40: =+G40-J40 -> 43905.024
A41: =+A40+1 -> 26 | C41: =+C23 -> 2021 | E41: =+E23 -> 8 | G41: =+SecGT10!W59 -> 133545.53 | J41: =+G41*O23 -> 50242.585 | M41: =+G41-J41 -> 83302.947
A42: =+A41+1 -> 27 | C42: =+C24 -> 2021 | E42: =+E24 -> 9 | G42: =+SecGT10!W60 -> -9290.2918 | J42: =+G42*O24 -> -3452.8303 | M42: =+G42-J42 -> -5837.4615
A43: =+A42+1 -> 28 | C43: =+C25 -> 2021 | E43: =+E25 -> 10 | G43: =+SecGT10!W61 -> -50451.361 | J43: =+G43*O25 -> -19582.441 | M43: =+G43-J43 -> -30868.92
A44: =+A43+1 -> 29 | C44: =+C26 -> 2021 | E44: =+E26 -> 11 | G44: =+SecGT10!W62 -> -42198.14 | J44: =+G44*O26 -> -17501.262 | M44: =+G44-J44 -> -24696.879
...

Sheet PrmGT10D
Q1: WP/II-H-1.2/1
Q2: Page 6 of 8
A4: =+'Weather Adjustment'!A4 -> PUC DOCKET NO
A5: =+'Weather Adjustment'!A5 -> ONCOR ELECTRIC DELIVERY COMPANY LLC
A6: =+'Weather Adjustment'!A6 -> MONTHLY SALES DATA
A7: =+'Weather Adjustment'!A7 -> TEST YEAR ENDING December 31, 2021
A9: =+'Weather Adjustment'!A9 -> SPONSOR: D. E. NELSON
A11: Primary Service Greater Than 10 KW Weather Adjustment (MWH)
G12: CDD Model | Q12: CDD MWH
A13: Line | C13: Year | E13: Month | G13: Coefficient | I13: Actual CDD | K13: Normal CDD | M13: Total GPL | O13: CDD Deviation | Q13: Adjustment | R13: Total GPL
G14: (a) | I14: (b) | K14: (c) | O14: (d)=c-b | Q14: (e)=a*d
A16: 1 | C16: =+'Weather Adjustment'!C16 -> 2021 | E16: =+'Weather Adjustment'!E16 -> 1 | G16: =+'[2]PRMGT10KWD Model'!$C$17 -> 194.17 | I16: =+[3]PRMGT10KWD!D13 -> 6.5122245 | K16: =+[3]PRMGT10KWD!F13 -> 13.627014 | M16: =SUM(I16,K16) -> 20.139238 | O16: =+K16-I16 -> 7.1147891 | Q16: =+G16*O16 -> 1381.4786 | R16: =SUM(N16,P16) -> 0
A17: =+A16+1 -> 2 | C17: =+'Weather Adjustment'!C17 -> 2021 | E17: =+'Weather Adjustment'!E17 -> 2 | G17: =+G16 -> 194.17 | I17: =+[3]PRMGT10KWD!D14 -> 6.8640992 | K17: =+[3]PRMGT10KWD!F14 -> 12.41712 | M17: =SUM(I17,K17) -> 19.281219 | O17: =+K17-I17 -> 5.5530208 | Q17: =+G17*O17 -> 1078.2301 | R17: =SUM(N17,P17) -> 0
A18: =+A17+1 -> 3 | C18: =+'Weather Adjustment'!C18 -> 2021 | E18: =+'Weather Adjustment'!E18 -> 3 | G18: =+G17 -> 194.17 | I18: =+[3]PRMGT10KWD!D15 -> 25.659032 | K18: =+[3]PRMGT10KWD!F15 -> 36.04058 | M18: =SUM(I18,K18) -> 61.699612 | O18: =+K18-I18 -> 10.381549 | Q18: =+G18*O18 -> 2015.7853 | R18: =SUM(N18,P18) -> 0
A19: =+A18+1 -> 4 | C19: =+'Weather Adjustment'!C19 -> 2021 | E19: =+'Weather Adjustment'!E19 -> 4 | G19: =+G18 -> 194.17 | I19: =+[3]PRMGT10KWD!D16 -> 87.5291 | K19: =+[3]PRMGT10KWD!F16 -> 103.37533 | M19: =SUM(I19,K19) -> 190.90443 | O19: =+K19-I19 -> 15.84623 | Q19: =+G19*O19 -> 3076.8626 | R19: =SUM(N19,P19) -> 0
A20: =+A19+1 -> 5 | C20: =+'Weather Adjustment'!C20 -> 2021 | E20: =+'Weather Adjustment'!E20 -> 5 | G20: =+G19 -> 194.17 | I20: =+[3]PRMGT10KWD!D17 -> 154.03262 | K20: =+[3]PRMGT10KWD!F17 -> 223.89384 | M20: =SUM(I20,K20) -> 377.92646 | O20: =+K20-I20 -> 69.861223 | Q20: =+G20*O20 -> 13564.954 | R20: =SUM(N20,P20) -> 0
A21: =+A20+1 -> 6 | C21: =+'Weather Adjustment'!C21 -> 2021 | E21: =+'Weather Adjustment'!E21 -> 6 | G21: =+G20 -> 194.17 | I21: =+[3]PRMGT10KWD!D18 -> 323.06793 | K21: =+[3]PRMGT10KWD!F18 -> 416.32365 | M21: =SUM(I21,K21) -> 739.39158 | O21: =+K21-I21 -> 93.255725 | Q21: =+G21*O21 -> 18107.464 | R21: =SUM(N21,P21) -> 0
A22: =+A21+1 -> 7 | C22: =+'Weather Adjustment'!C22 -> 2021 | E22: =+'Weather Adjustment'!E22 -> 7 | G22: =+G21 -> 194.17 | I22: =+[3]PRMGT10KWD!D19 -> 539.6715 | K22: =+[3]PRMGT10KWD!F19 -> 599.49521 | M22: =SUM(I22,K22) -> 1139.1667 | O22: =+K22-I22 -> 59.823713 | Q22: =+G22*O22 -> 11615.97 | R22: =SUM(N22,P22) -> 0
A23: =+A22+1 -> 8 | C23: =+'Weather Adjustment'!C23 -> 2021 | E23: =+'Weather Adjustment'!E23 -> 8 | G23: =+G22 -> 194.17 | I23: =+[3]PRMGT10KWD!D20 -> 544.17115 | K23: =+[3]PRMGT10KWD!F20 -> 631.84016 | M23: =SUM(I23,K23) -> 1176.0113 | O23: =+K23-I23 -> 87.669016 | Q23: =+G23*O23 -> 17022.693 | R23: =SUM(N23,P23) -> 0
A24: =+A23+1 -> 9 | C24: =+'Weather Adjustment'!C24 -> 2021 | E24: =+'Weather Adjustment'!E24 -> 9 | G24: =+G23 -> 194.17 | I24: =+[3]PRMGT10KWD!D21 -> 548.05561 | K24: =+[3]PRMGT10KWD!F21 -> 556.22387 | M24: =SUM(I24,K24) -> 1104.2795 | O24: =+K24-I24 -> 8.1682628 | Q24: =+G24*O24 -> 1586.0316 | R24: =SUM(N24,P24) -> 0
A25: =+A24+1 -> 10 | C25: =+'Weather Adjustment'!C25 -> 2021 | E25: =+'Weather Adjustment'!E25 -> 10 | G25: =+G24 -> 194.17 | I25: =+[3]PRMGT10KWD!D22 -> 386.99919 | K25: =+[3]PRMGT10KWD!F22 -> 354.87605 | M25: =SUM(I25,K25) -> 741.87524 | O25: =+K25-I25 -> -32.123145 | Q25: =+G25*O25 -> -6237.351 | R25: =SUM(N25,P25) -> 0
A26: =+A25+1 -> 11 | C26: =+'Weather Adjustment'!C26 -> 2021 | E26: =+'Weather Adjustment'!E26 -> 11 | G26: =+G25 -> 194.17 | I26: =+[3]PRMGT10KWD!D23 -> 181.66234 | K26: =+[3]PRMGT10KWD!F23 -> 151.58817 | M26: =SUM(I26,K26) -> 333.25052 | O26: =+K26-I26 -> -30.074172 | Q26: =+G26*O26 -> -5839.5019 | R26: =SUM(N26,P26) -> 0
A27: =+A26+1 -> 12 | C27: =+'Weather Adjustment'!C27 -> 2021 | E27: =+'Weather Adjustment'!E27 -> 12 | G27: =+G26 -> 194.17 | I27: =+[3]PRMGT10KWD!D24 -> 53.942642 | K27: =+[3]PRMGT10KWD!F24 -> 46.60844 | M27: =SUM(I27,K27) -> 100.55108 | O27: =+K27-I27 -> -7.3342017 | Q27: =+G27*O27 -> -1424.082 | R27: =SUM(N27,P27) -> 0
A28: =+A27+1 -> 13 | C28: Total | I28: =SUM(I16:I27) -> 2858.1674 | K28: =SUM(K16:K27) -> 3146.3094 | M28: =SUM(M22:M27) -> 4595.1343 | O28: =+K28-I28 -> 288.14201 | Q28: =SUM(Q16:Q27) -> 55948.534 | R28: =SUM(R22:R27) -> 0
A29: =+A28+1 -> 14
A30: =+A29+1 -> 15 | G30: HDD Model | Q30: HDD MWH
A31: =+A30+1 -> 16 | C31: Year | E31: Month | G31: Coefficient | I31: Actual HDD | K31: Normal HDD | M31: Total GPL | O31: HDD Deviation | Q31: Adjustment | R31: Total GPL
A32: =+A31+1 -> 17 | G32: (f) | I32: (g) | K32: (h) | O32: (i)=h-g | Q32: (j)=f*i
A33: =+A32+1 -> 18
A34: =+A33+1 -> 19 | C34: =+C16 -> 2021 | E34: =+E16 -> 1 | G34: 0 | I34: 0 | J34: =J16 -> 0 | K34: 0 | O34: =+K34-I34 -> 0 | Q34: =+G34*O34 -> 0
A35: =+A34+1 -> 20 | C35: =+C17 -> 2021 | E35: =+E17 -> 2 | G35: 0 | I35: 0 | J35: =J17 -> 0 | K35: 0 | O35: =+K35-I35 -> 0 | Q35: =+G35*O35 -> 0
A36: =+A35+1 -> 21 | C36: =+C18 -> 2021 | E36: =+E18 -> 3 | G36: 0 | I36: 0 | J36: =J18 -> 0 | K36: 0 | O36: =+K36-I36 -> 0 | Q36: =+G36*O36 -> 0
A37: =+A36+1 -> 22 | C37: =+C19 -> 2021 | E37: =+E19 -> 4 | G37: 0 | I37: 0 | J37: =J19 -> 0 | K37: 0 | O37: =+K37-I37 -> 0 | Q37: =+G37*O37 -> 0
A38: =+A37+1 -> 23 | C38: =+C20 -> 2021 | E38: =+E20 -> 5 | G38: 0 | I38: 0 | J38: =J20 -> 0 | K38: 0 | O38: =+K38-I38 -> 0 | Q38: =+G38*O38 -> 0
A39: =+A38+1 -> 24 | C39: =+C21 -> 2021 | E39: =+E21 -> 6 | G39: 0 | I39: 0 | J39: =J21 -> 0 | K39: 0 | O39: =+K39-I39 -> 0 | Q39: =+G39*O39 -> 0
A40: =+A39+1 -> 25 | C40: =+C22 -> 2021 | E40: =+E22 -> 7 | G40: 0 | I40: 0 | J40: =J22 -> 0 | K40: 0 | O40: =+K40-I40 -> 0 | Q40: =+G40*O40 -> 0
A41: =+A40+1 -> 26 | C41: =+C23 -> 2021 | E41: =+E23 -> 8 | G41: 0 | I41: 0 | J41: =J23 -> 0 | K41: 0 | O41: =+K41-I41 -> 0 | Q41: =+G41*O41 -> 0
A42: =+A41+1 -> 27 | C42: =+C24 -> 2021 | E42: =+E24 -> 9 | G42: 0 | I42: 0 | J42: =J24 -> 0 | K42: 0 | O42: =+K42-I42 -> 0 | Q42: =+G42*O42 -> 0
A43: =+A42+1 -> 28 | C43: =+C25 -> 2021 | E43: =+E25 -> 10 | G43: 0 | I43: 0 | J43: =J25 -> 0 | K43: 0 | O43: =+K43-I43 -> 0 | Q43: =+G43*O43 -> 0
A44: =+A43+1 -> 29 | C44: =+C26 -> 2021 | E44: =+E26 -> 11 | G44: 0 | I44: 0 | J44: =J26 -> 0 | K44: 0 | O44: =+K44-I44 -> 0 | Q44: =+G44*O44 -> 0
...

Sheet PrmGT10D IDR_NIDR
Q1: WP/II-H-1.2/1
Q2: Page 7 of 8
A4: =+'Weather Adjustment'!A4 -> PUC DOCKET NO
A5: =+'Weather Adjustment'!A5 -> ONCOR ELECTRIC DELIVERY COMPANY LLC
A6: =+'Weather Adjustment'!A6 -> MONTHLY SALES DATA
A7: =+'Weather Adjustment'!A7 -> TEST YEAR ENDING December 31, 2021
A9: =+'Weather Adjustment'!A9 -> SPONSOR: D. E. NELSON
C11: Primary Service Greater Than 10 KW IDR and Non-IDR Weather Adjustment (MWH)
G12: PRMGT10_IDR | J12: PRMGT10 | M12: PRMGT10 | O12: PRMGT10 | Q12: PRMGT10
A13: Line | C13: Year | E13: Month | G13: _NoSUB KWH | J13: NIDR KWH | L13: Total GSL | M13: Large KWH | O13: IDR KWH Share | Q13: NIDR KWH Share
A14: No. | G14: (a) | J14: (b) | M14: (c) | O14: (d)=a/c | Q14: (e)=b/c
A16: 1 | C16: =+'Weather Adjustment'!C16 -> 2021 | E16: =+'Weather Adjustment'!E16 -> 1 | G16: =+'[1]GS PRI LRG IDR '!I16 -> 1196329426 | J16: =+'[1]GS PRI LRG NONIDR'!I16 -> 142162335 | L16: =SUM(#REF!,J16) -> #REF! | M16: =SUM(G16,J16) -> 1338491761 | O16: =+G16/M16 -> 0.89378916 | Q16: =+J16/M16 -> 0.10621084
A17: =+A16+1 -> 2 | C17: =+'Weather Adjustment'!C17 -> 2021 | E17: =+'Weather Adjustment'!E17 -> 2 | G17: =+'[1]GS PRI LRG IDR '!I18 -> 1150822551 | J17: =+'[1]GS PRI LRG NONIDR'!I18 -> 136104227 | L17: =SUM(#REF!,J17) -> #REF! | M17: =SUM(G17,J17) -> 1286926778 | O17: =+G17/M17 -> 0.89424089 | Q17: =+J17/M17 -> 0.10575911
A18: =+A17+1 -> 3 | C18: =+'Weather Adjustment'!C18 -> 2021 | E18: =+'Weather Adjustment'!E18 -> 3 | G18: =+'[1]GS PRI LRG IDR '!I20 -> 1014192818 | J18: =+'[1]GS PRI LRG NONIDR'!I20 -> 125450911 | L18: =SUM(#REF!,J18) -> #REF! | M18: =SUM(G18,J18) -> 1139643729 | O18: =+G18/M18 -> 0.88992094 | Q18: =+J18/M18 -> 0.11007906
A19: =+A18+1 -> 4 | C19: =+'Weather Adjustment'!C19 -> 2021 | E19: =+'Weather Adjustment'!E19 -> 4 | G19: =+'[1]GS PRI LRG IDR '!I22 -> 1181580735 | J19: =+'[1]GS PRI LRG NONIDR'!I22 -> 146049568 | L19: =SUM(#REF!,J19) -> #REF! | M19: =SUM(G19,J19) -> 1327630303 | O19: =+G19/M19 -> 0.88999229 | Q19: =+J19/M19 -> 0.11000771
A20: =+A19+1 -> 5 | C20: =+'Weather Adjustment'!C20 -> 2021 | E20: =+'Weather Adjustment'!E20 -> 5 | G20: =+'[1]GS PRI LRG IDR '!I24 -> 1246661858 | J20: =+'[1]GS PRI LRG NONIDR'!I24 -> 168470619 | L20: =SUM(#REF!,J20) -> #REF! | M20: =SUM(G20,J20) -> 1415132477 | O20: =+G20/M20 -> 0.88095064 | Q20: =+J20/M20 -> 0.11904936
A21: =+A20+1 -> 6 | C21: =+'Weather Adjustment'!C21 -> 2021 | E21: =+'Weather Adjustment'!E21 -> 6 | G21: =+'[1]GS PRI LRG IDR '!I26 -> 1284301945 | J21: =+'[1]GS PRI LRG NONIDR'!I26 -> 176125535 | L21: =SUM(#REF!,J21) -> #REF! | M21: =SUM(G21,J21) -> 1460427480 | O21: =+G21/M21 -> 0.87940138 | Q21: =+J21/M21 -> 0.12059862
A22: =+A21+1 -> 7 | C22: =+'Weather Adjustment'!C22 -> 2021 | E22: =+'Weather Adjustment'!E22 -> 7 | G22: =+'[1]GS PRI LRG IDR '!I28 -> 1342534030 | J22: =+'[1]GS PRI LRG NONIDR'!I28 -> 182621139 | L22: =SUM(#REF!,J22) -> #REF! | M22: =SUM(G22,J22) -> 1525155169 | O22: =+G22/M22 -> 0.88026062 | Q22: =+J22/M22 -> 0.11973938
A23: =+A22+1 -> 8 | C23: =+'Weather Adjustment'!C23 -> 2021 | E23: =+'Weather Adjustment'!E23 -> 8 | G23: =+'[1]GS PRI LRG IDR '!I30 -> 1253721174 | J23: =+'[1]GS PRI LRG NONIDR'!I30 -> 112099971 | L23: =SUM(#REF!,J23) -> #REF! | M23: =SUM(G23,J23) -> 1365821145 | O23: =+G23/M23 -> 0.91792485 | Q23: =+J23/M23 -> 0.082075147
A24: =+A23+1 -> 9 | C24: =+'Weather Adjustment'!C24 -> 2021 | E24: =+'Weather Adjustment'!E24 -> 9 | G24: =+'[1]GS PRI LRG IDR '!I32 -> 1307569606 | J24: =+'[1]GS PRI LRG NONIDR'!I32 -> 170101246 | L24: =SUM(#REF!,J24) -> #REF! | M24: =SUM(G24,J24) -> 1477670852 | O24: =+G24/M24 -> 0.88488556 | Q24: =+J24/M24 -> 0.11511444
