Workbook
Name HOURLY: [1]HOURLY!$A$1:$G$745
Name OLE_LINK2: 'PRMDIST Seasonal Weights'!$B$24
Name rngBilled: OFFSET([2]Sheet2!$A$2,0,0,[2]Sheet2!$B$1,9)
Name rngYear: OFFSET('[3]Daily Actual_August'!$A$2,0,0,'[3]Daily Actual_August'!$C$1,8)

Sheet PRMDIST Seasonal Weights
B1: PUC DOCKET NO.
B2: ONCOR ELECTRIC DELIVERY COMPANY LLC
B3: WEATHER WEIGHTS
B4: FOR THE TEST YEAR ENDING DECEMBER 31, 2021
B6: SPONSOR: D. E. NELSON
B8: PRIMARY SERVICE GREATER THAN 10 KW DISTRIBUTION LINE MONTHLY WEIGHTS
A9: Line | B9: (a) | D9: (b) | E9: (c) | F9: (d) | G9: (e) | H9: (f) | I9: (g) | J9: (h) | K9: (i) | L9: (j) | M9: (k) | N9: (l) | O9: (m) | P9: (n)
A10: No. | B10: Weather Station | D10: 36892 | E10: 36923 | F10: 36951 | G10: 36982 | H10: 37012 | I10: 37043 | J10: 37073 | K10: 37104 | L10: 37135 | M10: 37165 | N10: 37196 | O10: 37226 | P10: Annual
A11: 1 | B11: Dallas-Fort Worth | D11: =+'PRMDIST Monthly Weather Weights'!C11 -> 0.328226 | E11: =+'PRMDIST Monthly Weather Weights'!D11 -> 0.32266191 | F11: =+'PRMDIST Monthly Weather Weights'!E11 -> 0.32732932 | G11: =+'PRMDIST Monthly Weather Weights'!F11 -> 0.31714974 | H11: =+'PRMDIST Monthly Weather Weights'!G11 -> 0.32321905 | I11: =+'PRMDIST Monthly Weather Weights'!H11 -> 0.3450813 | J11: =+'PRMDIST Monthly Weather Weights'!I11 -> 0.33935886 | K11: =+'PRMDIST Monthly Weather Weights'!J11 -> 0.34128748 | ... P11: =+'PRMDIST Monthly Weather Weights'!O11 -> 0.32848884
A12: =+A11+1 -> 2 | B12: Midland-Odessa | D12: =+'PRMDIST Monthly Weather Weights'!C12 -> 0.48668399 | E12: =+'PRMDIST Monthly Weather Weights'!D12 -> 0.50187124 | F12: =+'PRMDIST Monthly Weather Weights'!E12 -> 0.48972573 | G12: =+'PRMDIST Monthly Weather Weights'!F12 -> 0.50500125 | H12: =+'PRMDIST Monthly Weather Weights'!G12 -> 0.50046587 | I12: =+'PRMDIST Monthly Weather Weights'!H12 -> 0.4680114 | J12: =+'PRMDIST Monthly Weather Weights'!I12 -> 0.47795834 | K12: =+'PRMDIST Monthly Weather Weights'!J12 -> 0.47488034 | ... P12: =+'PRMDIST Monthly Weather Weights'!O12 -> 0.49306163
A13: =+A12+1 -> 3 | B13: Lufkin | D13: =+'PRMDIST Monthly Weather Weights'!C13 -> 0.027254216 | E13: =+'PRMDIST Monthly Weather Weights'!D13 -> 0.024839491 | F13: =+'PRMDIST Monthly Weather Weights'!E13 -> 0.027407058 | G13: =+'PRMDIST Monthly Weather Weights'!F13 -> 0.026148179 | H13: =+'PRMDIST Monthly Weather Weights'!G13 -> 0.025656084 | I13: =+'PRMDIST Monthly Weather Weights'!H13 -> 0.025877507 | J13: =+'PRMDIST Monthly Weather Weights'!I13 -> 0.025826648 | K13: =+'PRMDIST Monthly Weather Weights'!J13 -> 0.025426618 | ... P13: =+'PRMDIST Monthly Weather Weights'!O13 -> 0.025709103
A14: =+A13+1 -> 4 | B14: Abilene | D14: =+'PRMDIST Monthly Weather Weights'!C14 -> 0.061071093 | E14: =+'PRMDIST Monthly Weather Weights'!D14 -> 0.054992027 | F14: =+'PRMDIST Monthly Weather Weights'!E14 -> 0.060247628 | G14: =+'PRMDIST Monthly Weather Weights'!F14 -> 0.056754361 | H14: =+'PRMDIST Monthly Weather Weights'!G14 -> 0.052662538 | I14: =+'PRMDIST Monthly Weather Weights'!H14 -> 0.05773936 | J14: =+'PRMDIST Monthly Weather Weights'!I14 -> 0.053860932 | K14: =+'PRMDIST Monthly Weather Weights'!J14 -> 0.052131199 | ... P14: =+'PRMDIST Monthly Weather Weights'!O14 -> 0.053856814
A15: =+A14+1 -> 5 | B15: Sherman-Denison | D15: =+'PRMDIST Monthly Weather Weights'!C15 -> 0.019398925 | E15: =+'PRMDIST Monthly Weather Weights'!D15 -> 0.019138918 | F15: =+'PRMDIST Monthly Weather Weights'!E15 -> 0.019108258 | G15: =+'PRMDIST Monthly Weather Weights'!F15 -> 0.018649098 | H15: =+'PRMDIST Monthly Weather Weights'!G15 -> 0.01954551 | I15: =+'PRMDIST Monthly Weather Weights'!H15 -> 0.020949493 | J15: =+'PRMDIST Monthly Weather Weights'!I15 -> 0.020971536 | K15: =+'PRMDIST Monthly Weather Weights'!J15 -> 0.02273271 | ... P15: =+'PRMDIST Monthly Weather Weights'!O15 -> 0.020227917
A16: =+A15+1 -> 6 | B16: Killeen-Temple | D16: =+'PRMDIST Monthly Weather Weights'!C16 -> 0.012577132 | E16: =+'PRMDIST Monthly Weather Weights'!D16 -> 0.012373842 | F16: =+'PRMDIST Monthly Weather Weights'!E16 -> 0.012683625 | G16: =+'PRMDIST Monthly Weather Weights'!F16 -> 0.012975132 | H16: =+'PRMDIST Monthly Weather Weights'!G16 -> 0.013003348 | I16: =+'PRMDIST Monthly Weather Weights'!H16 -> 0.014023058 | J16: =+'PRMDIST Monthly Weather Weights'!I16 -> 0.014092221 | K16: =+'PRMDIST Monthly Weather Weights'!J16 -> 0.014653302 | ... P16: =+'PRMDIST Monthly Weather Weights'!O16 -> 0.013350299
A17: =+A16+1 -> 7 | B17: Waco | D17: =+'PRMDIST Monthly Weather Weights'!C17 -> 0.028808675 | E17: =+'PRMDIST Monthly Weather Weights'!D17 -> 0.029460354 | F17: =+'PRMDIST Monthly Weather Weights'!E17 -> 0.029088941 | G17: =+'PRMDIST Monthly Weather Weights'!F17 -> 0.030734966 | H17: =+'PRMDIST Monthly Weather Weights'!G17 -> 0.031197155 | I17: =+'PRMDIST Monthly Weather Weights'!H17 -> 0.033201741 | J17: =+'PRMDIST Monthly Weather Weights'!I17 -> 0.032984262 | K17: =+'PRMDIST Monthly Weather Weights'!J17 -> 0.033798245 | ... P17: =+'PRMDIST Monthly Weather Weights'!O17 -> 0.031367603
A18: =+A17+1 -> 8 | B18: Wichita Falls. | D18: =+'PRMDIST Monthly Weather Weights'!C18 -> 0.012713329 | E18: =+'PRMDIST Monthly Weather Weights'!D18 -> 0.011436721 | F18: =+'PRMDIST Monthly Weather Weights'!E18 -> 0.011571006 | G18: =+'PRMDIST Monthly Weather Weights'!F18 -> 0.01157421 | H18: =+'PRMDIST Monthly Weather Weights'!G18 -> 0.011072984 | I18: =+'PRMDIST Monthly Weather Weights'!H18 -> 0.010975502 | J18: =+'PRMDIST Monthly Weather Weights'!I18 -> 0.011263686 | K18: =+'PRMDIST Monthly Weather Weights'!J18 -> 0.011365939 | ... P18: =+'PRMDIST Monthly Weather Weights'!O18 -> 0.011387239
A19: =+A18+1 -> 9 | B19: Longview | D19: =+'PRMDIST Monthly Weather Weights'!C19 -> 0.015893352 | E19: =+'PRMDIST Monthly Weather Weights'!D19 -> 0.016296942 | F19: =+'PRMDIST Monthly Weather Weights'!E19 -> 0.016137419 | G19: =+'PRMDIST Monthly Weather Weights'!F19 -> 0.014301341 | H19: =+'PRMDIST Monthly Weather Weights'!G19 -> 0.016392524 | I19: =+'PRMDIST Monthly Weather Weights'!H19 -> 0.017297406 | J19: =+'PRMDIST Monthly Weather Weights'!I19 -> 0.017462035 | K19: =+'PRMDIST Monthly Weather Weights'!J19 -> 0.017903039 | ... P19: =+'PRMDIST Monthly Weather Weights'!O19 -> 0.016506774
A20: =+A19+1 -> 10 | B20: Austin | D20: =+'PRMDIST Monthly Weather Weights'!C20 -> 0.0073732915 | E20: =+'PRMDIST Monthly Weather Weights'!D20 -> 0.0069285604 | F20: =+'PRMDIST Monthly Weather Weights'!E20 -> 0.0067010191 | G20: =+'PRMDIST Monthly Weather Weights'!F20 -> 0.0067117279 | H20: =+'PRMDIST Monthly Weather Weights'!G20 -> 0.0067849373 | I20: =+'PRMDIST Monthly Weather Weights'!H20 -> 0.0068432254 | J20: =+'PRMDIST Monthly Weather Weights'!I20 -> 0.006221479 | K20: =+'PRMDIST Monthly Weather Weights'!J20 -> 0.0058211239 | ... P20: =+'PRMDIST Monthly Weather Weights'!O20 -> 0.0060437824
A21: =+A20+1 -> 11 | D21: =SUM(D11:D20) -> 1 | E21: =SUM(E11:E20) -> 1 | F21: =SUM(F11:F20) -> 1 | G21: =SUM(G11:G20) -> 1 | H21: =SUM(H11:H20) -> 1 | I21: =SUM(I11:I20) -> 1 | J21: =SUM(J11:J20) -> 1 | K21: =SUM(K11:K20) -> 1 | ... P21: =SUM(P11:P20) -> 1
A22: =+A21+1 -> 12
A23: =+A22+1 -> 13 | D23: SEASONAL WEIGHTS
A24: =+A23+1 -> 14 | D24: Nov to Mar | F24: May to Sep
A25: =+A24+1 -> 15 | B25: Weather Station | D25: HDD | F25: CDD
A26: =+A25+1 -> 16 | B26: Dallas-Fort Worth | D26: =ROUND(AVERAGE(D11:F11,N11:O11),3) -> 0.32 | F26: =ROUND(AVERAGE(H11:L11),3) -> 0.338
A27: =+A26+1 -> 17 | B27: Midland-Odessa | D27: =ROUND(AVERAGE(D12:F12,N12:O12),3) -> 0.504 | F27: =ROUND(AVERAGE(H12:L12),3) -> 0.48
A28: =+A27+1 -> 18 | B28: Lufkin | D28: =ROUND(AVERAGE(D13:F13,N13:O13),3) -> 0.026 | F28: =ROUND(AVERAGE(H13:L13),3) -> 0.026
A29: =+A28+1 -> 19 | B29: Abilene | D29: =ROUND(AVERAGE(D14:F14,N14:O14),3) -> 0.055 | F29: =ROUND(AVERAGE(H14:L14),3) -> 0.053
A30: =+A29+1 -> 20 | B30: Sherman-Denison | D30: =ROUND(AVERAGE(D15:F15,N15:O15),3) -> 0.019 | F30: =ROUND(AVERAGE(H15:L15),3) -> 0.021
A31: =+A30+1 -> 21 | B31: Killeen-Temple | D31: =ROUND(AVERAGE(D16:F16,N16:O16),3) -> 0.013 | F31: =ROUND(AVERAGE(H16:L16),3) -> 0.014
A32: =+A31+1 -> 22 | B32: Waco | D32: =ROUND(AVERAGE(D17:F17,N17:O17),3) -> 0.03 | F32: =ROUND(AVERAGE(H17:L17),3) -> 0.033
A33: =+A32+1 -> 23 | B33: Wichita Falls. | D33: =ROUND(AVERAGE(D18:F18,N18:O18),3) -> 0.012 | F33: =ROUND(AVERAGE(H18:L18),3) -> 0.011
A34: =+A33+1 -> 24 | B34: Longview | D34: =ROUND(AVERAGE(D19:F19,N19:O19),3) -> 0.016 | F34: =ROUND(AVERAGE(H19:L19),3) -> 0.017
A35: =+A34+1 -> 25 | B35: Austin | D35: =ROUND(AVERAGE(D20:F20,N20:O20),3) -> 0.006 | F35: =ROUND(AVERAGE(H20:L20),3) -> 0.006
A36: =+A35+1 -> 26 | D36: =AVERAGE(D21:F21,N21:O21) -> 1 | F36: =AVERAGE(H21:L21) -> 1

Sheet PRMDIST Monthly Weather Weights
B1: PUC DOCKET NO.
B2: ONCOR ELECTRIC DELIVERY COMPANY
B3: WEATHER WEIGHTS
B4: =+'PRMDIST Seasonal Weights'!B4:P4 -> FOR THE TEST YEAR ENDING DECEMBER 31, 2021
B6: SPONSOR: D. E. NELSON
B8: PRIMARY SERVICE GREATER THAN 10 KW DISTRIBUTION LINE MONTHLY WEIGHTS
A9: Line | B9: (a) | C9: (b) | D9: (c) | E9: (d) | F9: (e) | G9: (f) | H9: (g) | I9: (h) | J9: (i) | K9: (j) | L9: (k) | M9: (l) | N9: (m) | O9: (n)
A10: No. | B10: Weather Station | C10: 36892 | D10: 36923 | E10: 36951 | F10: 36982 | G10: 37012 | H10: 37043 | I10: 37073 | J10: 37104 | K10: 37135 | L10: 37165 | M10: 37196 | N10: 37226 | O10: Annual
A11: 1 | B11: Dallas-Fort Worth | C11: =+'PRMDIST Weights by Year (18-20)'!D14 -> 0.328226 | D11: =+'PRMDIST Weights by Year (18-20)'!E14 -> 0.32266191 | E11: =+'PRMDIST Weights by Year (18-20)'!F14 -> 0.32732932 | F11: =+'PRMDIST Weights by Year (18-20)'!G14 -> 0.31714974 | G11: =+'PRMDIST Weights by Year (18-20)'!H14 -> 0.32321905 | H11: =+'PRMDIST Weights by Year (18-20)'!I14 -> 0.3450813 | I11: =+'PRMDIST Weights by Year (18-20)'!J14 -> 0.33935886 | J11: =+'PRMDIST Weights by Year (18-20)'!K14 -> 0.34128748 | ... O11: =+'PRMDIST Weights by Year (18-20)'!P14 -> 0.32848884
A12: =+A11+1 -> 2 | B12: Midland-Odessa | C12: =+'PRMDIST Weights by Year (18-20)'!D54 -> 0.48668399 | D12: =+'PRMDIST Weights by Year (18-20)'!E54 -> 0.50187124 | E12: =+'PRMDIST Weights by Year (18-20)'!F54 -> 0.48972573 | F12: =+'PRMDIST Weights by Year (18-20)'!G54 -> 0.50500125 | G12: =+'PRMDIST Weights by Year (18-20)'!H54 -> 0.50046587 | H12: =+'PRMDIST Weights by Year (18-20)'!I54 -> 0.4680114 | I12: =+'PRMDIST Weights by Year (18-20)'!J54 -> 0.47795834 | J12: =+'PRMDIST Weights by Year (18-20)'!K54 -> 0.47488034 | ... O12: =+'PRMDIST Weights by Year (18-20)'!P54 -> 0.49306163
A13: =+A12+1 -> 3 | B13: Lufkin | C13: =+'PRMDIST Weights by Year (18-20)'!D19 -> 0.027254216 | D13: =+'PRMDIST Weights by Year (18-20)'!E19 -> 0.024839491 | E13: =+'PRMDIST Weights by Year (18-20)'!F19 -> 0.027407058 | F13: =+'PRMDIST Weights by Year (18-20)'!G19 -> 0.026148179 | G13: =+'PRMDIST Weights by Year (18-20)'!H19 -> 0.025656084 | H13: =+'PRMDIST Weights by Year (18-20)'!I19 -> 0.025877507 | I13: =+'PRMDIST Weights by Year (18-20)'!J19 -> 0.025826648 | J13: =+'PRMDIST Weights by Year (18-20)'!K19 -> 0.025426618 | ... O13: =+'PRMDIST Weights by Year (18-20)'!P19 -> 0.025709103
A14: =+A13+1 -> 4 | B14: Abilene | C14: =+'PRMDIST Weights by Year (18-20)'!D44 -> 0.061071093 | D14: =+'PRMDIST Weights by Year (18-20)'!E44 -> 0.054992027 | E14: =+'PRMDIST Weights by Year (18-20)'!F44 -> 0.060247628 | F14: =+'PRMDIST Weights by Year (18-20)'!G44 -> 0.056754361 | G14: =+'PRMDIST Weights by Year (18-20)'!H44 -> 0.052662538 | H14: =+'PRMDIST Weights by Year (18-20)'!I44 -> 0.05773936 | I14: =+'PRMDIST Weights by Year (18-20)'!J44 -> 0.053860932 | J14: =+'PRMDIST Weights by Year (18-20)'!K44 -> 0.052131199 | ... O14: =+'PRMDIST Weights by Year (18-20)'!P44 -> 0.053856814
A15: =+A14+1 -> 5 | B15: Sherman-Denison | C15: =+'PRMDIST Weights by Year (18-20)'!D59 -> 0.019398925 | D15: =+'PRMDIST Weights by Year (18-20)'!E59 -> 0.019138918 | E15: =+'PRMDIST Weights by Year (18-20)'!F59 -> 0.019108258 | F15: =+'PRMDIST Weights by Year (18-20)'!G59 -> 0.018649098 | G15: =+'PRMDIST Weights by Year (18-20)'!H59 -> 0.01954551 | H15: =+'PRMDIST Weights by Year (18-20)'!I59 -> 0.020949493 | I15: =+'PRMDIST Weights by Year (18-20)'!J59 -> 0.020971536 | J15: =+'PRMDIST Weights by Year (18-20)'!K59 -> 0.02273271 | ... O15: =+'PRMDIST Weights by Year (18-20)'!P59 -> 0.020227917
A16: =+A15+1 -> 6 | B16: Killeen-Temple | C16: =+'PRMDIST Weights by Year (18-20)'!D29 -> 0.012577132 | D16: =+'PRMDIST Weights by Year (18-20)'!E29 -> 0.012373842 | E16: =+'PRMDIST Weights by Year (18-20)'!F29 -> 0.012683625 | F16: =+'PRMDIST Weights by Year (18-20)'!G29 -> 0.012975132 | G16: =+'PRMDIST Weights by Year (18-20)'!H29 -> 0.013003348 | H16: =+'PRMDIST Weights by Year (18-20)'!I29 -> 0.014023058 | I16: =+'PRMDIST Weights by Year (18-20)'!J29 -> 0.014092221 | J16: =+'PRMDIST Weights by Year (18-20)'!K29 -> 0.014653302 | ... O16: =+'PRMDIST Weights by Year (18-20)'!P29 -> 0.013350299
A17: =+A16+1 -> 7 | B17: Waco | C17: =+'PRMDIST Weights by Year (18-20)'!D39 -> 0.028808675 | D17: =+'PRMDIST Weights by Year (18-20)'!E39 -> 0.029460354 | E17: =+'PRMDIST Weights by Year (18-20)'!F39 -> 0.029088941 | F17: =+'PRMDIST Weights by Year (18-20)'!G39 -> 0.030734966 | G17: =+'PRMDIST Weights by Year (18-20)'!H39 -> 0.031197155 | H17: =+'PRMDIST Weights by Year (18-20)'!I39 -> 0.033201741 | I17: =+'PRMDIST Weights by Year (18-20)'!J39 -> 0.032984262 | J17: =+'PRMDIST Weights by Year (18-20)'!K39 -> 0.033798245 | ... O17: =+'PRMDIST Weights by Year (18-20)'!P39 -> 0.031367603
A18: =+A17+1 -> 8 | B18: Wichita Falls. | C18: =+'PRMDIST Weights by Year (18-20)'!D49 -> 0.012713329 | D18: =+'PRMDIST Weights by Year (18-20)'!E49 -> 0.011436721 | E18: =+'PRMDIST Weights by Year (18-20)'!F49 -> 0.011571006 | F18: =+'PRMDIST Weights by Year (18-20)'!G49 -> 0.01157421 | G18: =+'PRMDIST Weights by Year (18-20)'!H49 -> 0.011072984 | H18: =+'PRMDIST Weights by Year (18-20)'!I49 -> 0.010975502 | I18: =+'PRMDIST Weights by Year (18-20)'!J49 -> 0.011263686 | J18: =+'PRMDIST Weights by Year (18-20)'!K49 -> 0.011365939 | ... O18: =+'PRMDIST Weights by Year (18-20)'!P49 -> 0.011387239
A19: =+A18+1 -> 9 | B19: Longview | C19: =+'PRMDIST Weights by Year (18-20)'!D34 -> 0.015893352 | D19: =+'PRMDIST Weights by Year (18-20)'!E34 -> 0.016296942 | E19: =+'PRMDIST Weights by Year (18-20)'!F34 -> 0.016137419 | F19: =+'PRMDIST Weights by Year (18-20)'!G34 -> 0.014301341 | G19: =+'PRMDIST Weights by Year (18-20)'!H34 -> 0.016392524 | H19: =+'PRMDIST Weights by Year (18-20)'!I34 -> 0.017297406 | I19: =+'PRMDIST Weights by Year (18-20)'!J34 -> 0.017462035 | J19: =+'PRMDIST Weights by Year (18-20)'!K34 -> 0.017903039 | ... O19: =+'PRMDIST Weights by Year (18-20)'!P34 -> 0.016506774
A20: =+A19+1 -> 10 | B20: Austin | C20: =+'PRMDIST Weights by Year (18-20)'!D24 -> 0.0073732915 | D20: =+'PRMDIST Weights by Year (18-20)'!E24 -> 0.0069285604 | E20: =+'PRMDIST Weights by Year (18-20)'!F24 -> 0.0067010191 | F20: =+'PRMDIST Weights by Year (18-20)'!G24 -> 0.0067117279 | G20: =+'PRMDIST Weights by Year (18-20)'!H24 -> 0.0067849373 | H20: =+'PRMDIST Weights by Year (18-20)'!I24 -> 0.0068432254 | I20: =+'PRMDIST Weights by Year (18-20)'!J24 -> 0.006221479 | J20: =+'PRMDIST Weights by Year (18-20)'!K24 -> 0.0058211239 | ... O20: =+'PRMDIST Weights by Year (18-20)'!P24 -> 0.0060437824
C21: =SUM(C11:C20) -> 1 | D21: =SUM(D11:D20) -> 1 | E21: =SUM(E11:E20) -> 1 | F21: =SUM(F11:F20) -> 1 | G21: =SUM(G11:G20) -> 1 | H21: =SUM(H11:H20) -> 1 | I21: =SUM(I11:I20) -> 1 | J21: =SUM(J11:J20) -> 1 | ... O21: =SUM(O11:O20) -> 1

Sheet PRMDIST Weights by Year (18-20)
B1: PUC DOCKET NO.
B2: ONCOR ELECTRIC DELIVERY COMPANY
B3: WEATHER WEIGHTS
B4: =+'PRMDIST Seasonal Weights'!B4:P4 -> FOR THE TEST YEAR ENDING DECEMBER 31, 2021
B6: SPONSOR: D. E. NELSON
B8: PRIMARY SERVICE GREATER THAN 10 KW DISTRIBUTION LINE WEIGHTS BY YEAR
A9: Line | B9: (a) | C9: (b) | D9: (c) | E9: (d) | F9: (e) | G9: (f) | H9: (g) | I9: (h) | J9: (i) | K9: (j) | L9: (k) | M9: (l) | N9: (m) | O9: (n) | P9: (o)
A10: No. | B10: Weather Station | C10: Year | D10: 36892 | E10: 36923 | F10: 36951 | G10: 36982 | H10: 37012 | I10: 37043 | J10: 37073 | K10: 37104 | L10: 37135 | M10: 37165 | N10: 37196 | O10: 37226 | P10: Annual
A11: 1 | B11: Dallas-Fort Worth | C11: 2018 | D11: ='PRMDIST Sales by Year (18-20)'!D11/'PRMDIST Sales by Year (18-20)'!D61 -> 0.39915364 | E11: ='PRMDIST Sales by Year (18-20)'!E11/'PRMDIST Sales by Year (18-20)'!E$61 -> 0.37386021 | F11: ='PRMDIST Sales by Year (18-20)'!F11/'PRMDIST Sales by Year (18-20)'!F$61 -> 0.36332811 | G11: ='PRMDIST Sales by Year (18-20)'!G11/'PRMDIST Sales by Year (18-20)'!G$61 -> 0.35004343 | H11: ='PRMDIST Sales by Year (18-20)'!H11/'PRMDIST Sales by Year (18-20)'!H$61 -> 0.35855523 | I11: ='PRMDIST Sales by Year (18-20)'!I11/'PRMDIST Sales by Year (18-20)'!I$61 -> 0.38947544 | J11: ='PRMDIST Sales by Year (18-20)'!J11/'PRMDIST Sales by Year (18-20)'!J$61 -> 0.35592263 | K11: ='PRMDIST Sales by Year (18-20)'!K11/'PRMDIST Sales by Year (18-20)'!K$61 -> 0.36392006 | L11: ='PRMDIST Sales by Year (18-20)'!L11/'PRMDIST Sales by Year (18-20)'!L$61 -> 0.35600519 | ... P11: ='PRMDIST Sales by Year (18-20)'!P11/'PRMDIST Sales by Year (18-20)'!P$61 -> 0.3562767
A12: =+A11+1 -> 2 | B12: Dallas-Fort Worth | C12: 2019 | D12: ='PRMDIST Sales by Year (18-20)'!D12/'PRMDIST Sales by Year (18-20)'!D62 -> 0.31523137 | E12: ='PRMDIST Sales by Year (18-20)'!E12/'PRMDIST Sales by Year (18-20)'!E$62 -> 0.30613221 | F12: ='PRMDIST Sales by Year (18-20)'!F12/'PRMDIST Sales by Year (18-20)'!F$62 -> 0.31282333 | G12: ='PRMDIST Sales by Year (18-20)'!G12/'PRMDIST Sales by Year (18-20)'!G$62 -> 0.30990754 | H12: ='PRMDIST Sales by Year (18-20)'!H12/'PRMDIST Sales by Year (18-20)'!H$62 -> 0.31958353 | I12: ='PRMDIST Sales by Year (18-20)'!I12/'PRMDIST Sales by Year (18-20)'!I$62 -> 0.31475162 | J12: ='PRMDIST Sales by Year (18-20)'!J12/'PRMDIST Sales by Year (18-20)'!J$62 -> 0.32594363 | K12: ='PRMDIST Sales by Year (18-20)'!K12/'PRMDIST Sales by Year (18-20)'!K$62 -> 0.33497921 | L12: ='PRMDIST Sales by Year (18-20)'!L12/'PRMDIST Sales by Year (18-20)'!L$62 -> 0.33109812 | ... P12: ='PRMDIST Sales by Year (18-20)'!P12/'PRMDIST Sales by Year (18-20)'!P$62 -> 0.31741121
A13: =+A12+1 -> 3 | B13: Dallas-Fort Worth | C13: 2020 | D13: ='PRMDIST Sales by Year (18-20)'!D13/'PRMDIST Sales by Year (18-20)'!D63 -> 0.287025 | E13: ='PRMDIST Sales by Year (18-20)'!E13/'PRMDIST Sales by Year (18-20)'!E63 -> 0.2986453 | F13: ='PRMDIST Sales by Year (18-20)'!F13/'PRMDIST Sales by Year (18-20)'!F63 -> 0.31163637 | G13: ='PRMDIST Sales by Year (18-20)'!G13/'PRMDIST Sales by Year (18-20)'!G63 -> 0.29500817 | H13: ='PRMDIST Sales by Year (18-20)'!H13/'PRMDIST Sales by Year (18-20)'!H63 -> 0.29646974 | I13: ='PRMDIST Sales by Year (18-20)'!I13/'PRMDIST Sales by Year (18-20)'!I63 -> 0.33578586 | J13: ='PRMDIST Sales by Year (18-20)'!J13/'PRMDIST Sales by Year (18-20)'!J63 -> 0.33641704 | K13: ='PRMDIST Sales by Year (18-20)'!K13/'PRMDIST Sales by Year (18-20)'!K63 -> 0.32648213 | ... P13: ='PRMDIST Sales by Year (18-20)'!P13/'PRMDIST Sales by Year (18-20)'!P63 -> 0.31456474
A14: =+A13+1 -> 4 | B14: Dallas-Fort Worth | C14: Total | D14: ='PRMDIST Sales by Year (18-20)'!D14/'PRMDIST Sales by Year (18-20)'!D64 -> 0.328226 | E14: ='PRMDIST Sales by Year (18-20)'!E14/'PRMDIST Sales by Year (18-20)'!E64 -> 0.32266191 | F14: ='PRMDIST Sales by Year (18-20)'!F14/'PRMDIST Sales by Year (18-20)'!F64 -> 0.32732932 | G14: ='PRMDIST Sales by Year (18-20)'!G14/'PRMDIST Sales by Year (18-20)'!G64 -> 0.31714974 | H14: ='PRMDIST Sales by Year (18-20)'!H14/'PRMDIST Sales by Year (18-20)'!H64 -> 0.32321905 | I14: ='PRMDIST Sales by Year (18-20)'!I14/'PRMDIST Sales by Year (18-20)'!I64 -> 0.3450813 | J14: ='PRMDIST Sales by Year (18-20)'!J14/'PRMDIST Sales by Year (18-20)'!J64 -> 0.33935886 | K14: ='PRMDIST Sales by Year (18-20)'!K14/'PRMDIST Sales by Year (18-20)'!K64 -> 0.34128748 | ... P14: ='PRMDIST Sales by Year (18-20)'!P14/'PRMDIST Sales by Year (18-20)'!P64 -> 0.32848884
A15: =+A14+1 -> 5
A16: =+A15+1 -> 6 | B16: Lufkin | C16: =+C11 -> 2018 | D16: ='PRMDIST Sales by Year (18-20)'!D16/'PRMDIST Sales by Year (18-20)'!D61 -> 0.035233753 | E16: ='PRMDIST Sales by Year (18-20)'!E16/'PRMDIST Sales by Year (18-20)'!E$61 -> 0.025530131 | F16: ='PRMDIST Sales by Year (18-20)'!F16/'PRMDIST Sales by Year (18-20)'!F$61 -> 0.034445812 | G16: ='PRMDIST Sales by Year (18-20)'!G16/'PRMDIST Sales by Year (18-20)'!G$61 -> 0.029095312 | H16: ='PRMDIST Sales by Year (18-20)'!H16/'PRMDIST Sales by Year (18-20)'!H$61 -> 0.029753646 | I16: ='PRMDIST Sales by Year (18-20)'!I16/'PRMDIST Sales by Year (18-20)'!I$61 -> 0.027981757 | J16: ='PRMDIST Sales by Year (18-20)'!J16/'PRMDIST Sales by Year (18-20)'!J$61 -> 0.027670656 | K16: ='PRMDIST Sales by Year (18-20)'!K16/'PRMDIST Sales by Year (18-20)'!K$61 -> 0.027330725 | L16: ='PRMDIST Sales by Year (18-20)'!L16/'PRMDIST Sales by Year (18-20)'!L$61 -> 0.026526666 | ... P16: ='PRMDIST Sales by Year (18-20)'!P16/'PRMDIST Sales by Year (18-20)'!P$61 -> 0.028244485
A17: =+A16+1 -> 7 | B17: Lufkin | C17: =+C12 -> 2019 | D17: ='PRMDIST Sales by Year (18-20)'!D17/'PRMDIST Sales by Year (18-20)'!D62 -> 0.024967462 | E17: ='PRMDIST Sales by Year (18-20)'!E17/'PRMDIST Sales by Year (18-20)'!E$62 -> 0.025466384 | F17: ='PRMDIST Sales by Year (18-20)'!F17/'PRMDIST Sales by Year (18-20)'!F$62 -> 0.024828003 | G17: ='PRMDIST Sales by Year (18-20)'!G17/'PRMDIST Sales by Year (18-20)'!G$62 -> 0.024647258 | H17: ='PRMDIST Sales by Year (18-20)'!H17/'PRMDIST Sales by Year (18-20)'!H$62 -> 0.024650003 | I17: ='PRMDIST Sales by Year (18-20)'!I17/'PRMDIST Sales by Year (18-20)'!I$62 -> 0.024157669 | J17: ='PRMDIST Sales by Year (18-20)'!J17/'PRMDIST Sales by Year (18-20)'!J$62 -> 0.024578289 | K17: ='PRMDIST Sales by Year (18-20)'!K17/'PRMDIST Sales by Year (18-20)'!K$62 -> 0.024765225 | L17: ='PRMDIST Sales by Year (18-20)'!L17/'PRMDIST Sales by Year (18-20)'!L$62 -> 0.024109691 | ... P17: ='PRMDIST Sales by Year (18-20)'!P17/'PRMDIST Sales by Year (18-20)'!P$62 -> 0.024439343
A18: =+A17+1 -> 8 | B18: Lufkin | C18: =+C13 -> 2020 | D18: ='PRMDIST Sales by Year (18-20)'!D18/'PRMDIST Sales by Year (18-20)'!D63 -> 0.023348748 | E18: ='PRMDIST Sales by Year (18-20)'!E18/'PRMDIST Sales by Year (18-20)'!E63 -> 0.023690624 | F18: ='PRMDIST Sales by Year (18-20)'!F18/'PRMDIST Sales by Year (18-20)'!F63 -> 0.024102461 | G18: ='PRMDIST Sales by Year (18-20)'!G18/'PRMDIST Sales by Year (18-20)'!G63 -> 0.024994429 | H18: ='PRMDIST Sales by Year (18-20)'!H18/'PRMDIST Sales by Year (18-20)'!H63 -> 0.023142168 | I18: ='PRMDIST Sales by Year (18-20)'!I18/'PRMDIST Sales by Year (18-20)'!I63 -> 0.025760912 | J18: ='PRMDIST Sales by Year (18-20)'!J18/'PRMDIST Sales by Year (18-20)'!J63 -> 0.025245641 | K18: ='PRMDIST Sales by Year (18-20)'!K18/'PRMDIST Sales by Year (18-20)'!K63 -> 0.024311315 | ... P18: ='PRMDIST Sales by Year (18-20)'!P18/'PRMDIST Sales by Year (18-20)'!P63 -> 0.024701788
A19: =+A18+1 -> 9 | B19: Lufkin | C19: Total | D19: ='PRMDIST Sales by Year (18-20)'!D19/'PRMDIST Sales by Year (18-20)'!D64 -> 0.027254216 | E19: ='PRMDIST Sales by Year (18-20)'!E19/'PRMDIST Sales by Year (18-20)'!E64 -> 0.024839491 | F19: ='PRMDIST Sales by Year (18-20)'!F19/'PRMDIST Sales by Year (18-20)'!F64 -> 0.027407058 | G19: ='PRMDIST Sales by Year (18-20)'!G19/'PRMDIST Sales by Year (18-20)'!G64 -> 0.026148179 | H19: ='PRMDIST Sales by Year (18-20)'!H19/'PRMDIST Sales by Year (18-20)'!H64 -> 0.025656084 | I19: ='PRMDIST Sales by Year (18-20)'!I19/'PRMDIST Sales by Year (18-20)'!I64 -> 0.025877507 | J19: ='PRMDIST Sales by Year (18-20)'!J19/'PRMDIST Sales by Year (18-20)'!J64 -> 0.025826648 | K19: ='PRMDIST Sales by Year (18-20)'!K19/'PRMDIST Sales by Year (18-20)'!K64 -> 0.025426618 | ... P19: ='PRMDIST Sales by Year (18-20)'!P19/'PRMDIST Sales by Year (18-20)'!P64 -> 0.025709103
A20: =+A19+1 -> 10
A21: =+A20+1 -> 11 | B21: Austin | C21: =+C16 -> 2018 | D21: ='PRMDIST Sales by Year (18-20)'!D21/'PRMDIST Sales by Year (18-20)'!D61 -> 0.0098520205 | E21: ='PRMDIST Sales by Year (18-20)'!E21/'PRMDIST Sales by Year (18-20)'!E$61 -> 0.0098199941 | F21: ='PRMDIST Sales by Year (18-20)'!F21/'PRMDIST Sales by Year (18-20)'!F$61 -> 0.0087402784 | G21: ='PRMDIST Sales by Year (18-20)'!G21/'PRMDIST Sales by Year (18-20)'!G$61 -> 0.0087082229 | H21: ='PRMDIST Sales by Year (18-20)'!H21/'PRMDIST Sales by Year (18-20)'!H$61 -> 0.0089991243 | I21: ='PRMDIST Sales by Year (18-20)'!I21/'PRMDIST Sales by Year (18-20)'!I$61 -> 0.0089702694 | J21: ='PRMDIST Sales by Year (18-20)'!J21/'PRMDIST Sales by Year (18-20)'!J$61 -> 0.008013136 | K21: ='PRMDIST Sales by Year (18-20)'!K21/'PRMDIST Sales by Year (18-20)'!K$61 -> 0.0074375728 | L21: ='PRMDIST Sales by Year (18-20)'!L21/'PRMDIST Sales by Year (18-20)'!L$61 -> 0.0082132459 | ... P21: ='PRMDIST Sales by Year (18-20)'!P21/'PRMDIST Sales by Year (18-20)'!P$61 -> 0.0085502018
A22: =+A21+1 -> 12 | B22: Austin | C22: =+C17 -> 2019 | D22: ='PRMDIST Sales by Year (18-20)'!D22/'PRMDIST Sales by Year (18-20)'!D62 -> 0.0089699813 | E22: ='PRMDIST Sales by Year (18-20)'!E22/'PRMDIST Sales by Year (18-20)'!E$62 -> 0.0075526151 | F22: ='PRMDIST Sales by Year (18-20)'!F22/'PRMDIST Sales by Year (18-20)'!F$62 -> 0.0080233293 | G22: ='PRMDIST Sales by Year (18-20)'!G22/'PRMDIST Sales by Year (18-20)'!G$62 -> 0.0080269803 | H22: ='PRMDIST Sales by Year (18-20)'!H22/'PRMDIST Sales by Year (18-20)'!H$62 -> 0.0079580571 | I22: ='PRMDIST Sales by Year (18-20)'!I22/'PRMDIST Sales by Year (18-20)'!I$62 -> 0.0073302515 | J22: ='PRMDIST Sales by Year (18-20)'!J22/'PRMDIST Sales by Year (18-20)'!J$62 -> 0.006807325 | K22: ='PRMDIST Sales by Year (18-20)'!K22/'PRMDIST Sales by Year (18-20)'!K$62 -> 0.0066686053 | L22: ='PRMDIST Sales by Year (18-20)'!L22/'PRMDIST Sales by Year (18-20)'!L$62 -> 0.0010652604 | ... P22: ='PRMDIST Sales by Year (18-20)'!P22/'PRMDIST Sales by Year (18-20)'!P$62 -> 0.0060356102
A23: =+A22+1 -> 13 | B23: Austin | C23: =+C18 -> 2020 | D23: ='PRMDIST Sales by Year (18-20)'!D23/'PRMDIST Sales by Year (18-20)'!D63 -> 0.0041190115 | E23: ='PRMDIST Sales by Year (18-20)'!E23/'PRMDIST Sales by Year (18-20)'!E63 -> 0.0040604176 | F23: ='PRMDIST Sales by Year (18-20)'!F23/'PRMDIST Sales by Year (18-20)'!F63 -> 0.0038435928 | G23: ='PRMDIST Sales by Year (18-20)'!G23/'PRMDIST Sales by Year (18-20)'!G63 -> 0.0036583526 | H23: ='PRMDIST Sales by Year (18-20)'!H23/'PRMDIST Sales by Year (18-20)'!H63 -> 0.0036997216 | I23: ='PRMDIST Sales by Year (18-20)'!I23/'PRMDIST Sales by Year (18-20)'!I63 -> 0.0041705019 | J23: ='PRMDIST Sales by Year (18-20)'!J23/'PRMDIST Sales by Year (18-20)'!J63 -> 0.0037967547 | K23: ='PRMDIST Sales by Year (18-20)'!K23/'PRMDIST Sales by Year (18-20)'!K63 -> 0.0034694804 | ... P23: ='PRMDIST Sales by Year (18-20)'!P23/'PRMDIST Sales by Year (18-20)'!P63 -> 0.0037811634
A24: =+A23+1 -> 14 | B24: Austin | C24: Total | D24: ='PRMDIST Sales by Year (18-20)'!D24/'PRMDIST Sales by Year (18-20)'!D64 -> 0.0073732915 | E24: ='PRMDIST Sales by Year (18-20)'!E24/'PRMDIST Sales by Year (18-20)'!E64 -> 0.0069285604 | F24: ='PRMDIST Sales by Year (18-20)'!F24/'PRMDIST Sales by Year (18-20)'!F64 -> 0.0067010191 | G24: ='PRMDIST Sales by Year (18-20)'!G24/'PRMDIST Sales by Year (18-20)'!G64 -> 0.0067117279 | H24: ='PRMDIST Sales by Year (18-20)'!H24/'PRMDIST Sales by Year (18-20)'!H64 -> 0.0067849373 | I24: ='PRMDIST Sales by Year (18-20)'!I24/'PRMDIST Sales by Year (18-20)'!I64 -> 0.0068432254 | J24: ='PRMDIST Sales by Year (18-20)'!J24/'PRMDIST Sales by Year (18-20)'!J64 -> 0.006221479 | K24: ='PRMDIST Sales by Year (18-20)'!K24/'PRMDIST Sales by Year (18-20)'!K64 -> 0.0058211239 | ... P24: ='PRMDIST Sales by Year (18-20)'!P24/'PRMDIST Sales by Year (18-20)'!P64 -> 0.0060437824
A25: =+A24+1 -> 15
A26: =+A25+1 -> 16 | B26: Killeen | C26: =+C21 -> 2018 | D26: ='PRMDIST Sales by Year (18-20)'!D26/'PRMDIST Sales by Year (18-20)'!D61 -> 0.015487705 | E26: ='PRMDIST Sales by Year (18-20)'!E26/'PRMDIST Sales by Year (18-20)'!E$61 -> 0.013832198 | F26: ='PRMDIST Sales by Year (18-20)'!F26/'PRMDIST Sales by Year (18-20)'!F$61 -> 0.01422023 | G26: ='PRMDIST Sales by Year (18-20)'!G26/'PRMDIST Sales by Year (18-20)'!G$61 -> 0.014084308 | H26: ='PRMDIST Sales by Year (18-20)'!H26/'PRMDIST Sales by Year (18-20)'!H$61 -> 0.014478004 | I26: ='PRMDIST Sales by Year (18-20)'!I26/'PRMDIST Sales by Year (18-20)'!I$61 -> 0.014922143 | J26: ='PRMDIST Sales by Year (18-20)'!J26/'PRMDIST Sales by Year (18-20)'!J$61 -> 0.014323225 | K26: ='PRMDIST Sales by Year (18-20)'!K26/'PRMDIST Sales by Year (18-20)'!K$61 -> 0.015792041 | L26: ='PRMDIST Sales by Year (18-20)'!L26/'PRMDIST Sales by Year (18-20)'!L$61 -> 0.015000681 | ... P26: ='PRMDIST Sales by Year (18-20)'!P26/'PRMDIST Sales by Year (18-20)'!P$61 -> 0.014337793
A27: =+A26+1 -> 17 | B27: Killeen | C27: =+C22 -> 2019 | D27: ='PRMDIST Sales by Year (18-20)'!D27/'PRMDIST Sales by Year (18-20)'!D62 -> 0.012496463 | E27: ='PRMDIST Sales by Year (18-20)'!E27/'PRMDIST Sales by Year (18-20)'!E$62 -> 0.012184986 | F27: ='PRMDIST Sales by Year (18-20)'!F27/'PRMDIST Sales by Year (18-20)'!F$62 -> 0.012712865 | G27: ='PRMDIST Sales by Year (18-20)'!G27/'PRMDIST Sales by Year (18-20)'!G$62 -> 0.012226506 | H27: ='PRMDIST Sales by Year (18-20)'!H27/'PRMDIST Sales by Year (18-20)'!H$62 -> 0.012869952 | I27: ='PRMDIST Sales by Year (18-20)'!I27/'PRMDIST Sales by Year (18-20)'!I$62 -> 0.013017046 | J27: ='PRMDIST Sales by Year (18-20)'!J27/'PRMDIST Sales by Year (18-20)'!J$62 -> 0.01361564 | K27: ='PRMDIST Sales by Year (18-20)'!K27/'PRMDIST Sales by Year (18-20)'!K$62 -> 0.013935941 | L27: ='PRMDIST Sales by Year (18-20)'!L27/'PRMDIST Sales by Year (18-20)'!L$62 -> 0.01370399 | ... P27: ='PRMDIST Sales by Year (18-20)'!P27/'PRMDIST Sales by Year (18-20)'!P$62 -> 0.012935713
A28: =+A27+1 -> 18 | B28: Killeen | C28: =+C23 -> 2020 | D28: ='PRMDIST Sales by Year (18-20)'!D28/'PRMDIST Sales by Year (18-20)'!D63 -> 0.01048601 | E28: ='PRMDIST Sales by Year (18-20)'!E28/'PRMDIST Sales by Year (18-20)'!E63 -> 0.011416044 | F28: ='PRMDIST Sales by Year (18-20)'!F28/'PRMDIST Sales by Year (18-20)'!F63 -> 0.01141845 | G28: ='PRMDIST Sales by Year (18-20)'!G28/'PRMDIST Sales by Year (18-20)'!G63 -> 0.012719906 | H28: ='PRMDIST Sales by Year (18-20)'!H28/'PRMDIST Sales by Year (18-20)'!H63 -> 0.011868613 | I28: ='PRMDIST Sales by Year (18-20)'!I28/'PRMDIST Sales by Year (18-20)'!I63 -> 0.014284549 | J28: ='PRMDIST Sales by Year (18-20)'!J28/'PRMDIST Sales by Year (18-20)'!J63 -> 0.014350571 | K28: ='PRMDIST Sales by Year (18-20)'!K28/'PRMDIST Sales by Year (18-20)'!K63 -> 0.014307177 | ... P28: ='PRMDIST Sales by Year (18-20)'!P28/'PRMDIST Sales by Year (18-20)'!P63 -> 0.012876732
A29: =+A28+1 -> 19 | B29: Killeen | C29: Total | D29: ='PRMDIST Sales by Year (18-20)'!D29/'PRMDIST Sales by Year (18-20)'!D64 -> 0.012577132 | E29: ='PRMDIST Sales by Year (18-20)'!E29/'PRMDIST Sales by Year (18-20)'!E64 -> 0.012373842 | F29: ='PRMDIST Sales by Year (18-20)'!F29/'PRMDIST Sales by Year (18-20)'!F64 -> 0.012683625 | G29: ='PRMDIST Sales by Year (18-20)'!G29/'PRMDIST Sales by Year (18-20)'!G64 -> 0.012975132 | H29: ='PRMDIST Sales by Year (18-20)'!H29/'PRMDIST Sales by Year (18-20)'!H64 -> 0.013003348 | I29: ='PRMDIST Sales by Year (18-20)'!I29/'PRMDIST Sales by Year (18-20)'!I64 -> 0.014023058 | J29: ='PRMDIST Sales by Year (18-20)'!J29/'PRMDIST Sales by Year (18-20)'!J64 -> 0.014092221 | K29: ='PRMDIST Sales by Year (18-20)'!K29/'PRMDIST Sales by Year (18-20)'!K64 -> 0.014653302 | ... P29: ='PRMDIST Sales by Year (18-20)'!P29/'PRMDIST Sales by Year (18-20)'!P64 -> 0.013350299
A30: =+A29+1 -> 20
A31: =+A30+1 -> 21 | B31: Longview | C31: =+C26 -> 2018 | D31: ='PRMDIST Sales by Year (18-20)'!D31/'PRMDIST Sales by Year (18-20)'!D61 -> 0.019394764 | E31: ='PRMDIST Sales by Year (18-20)'!E31/'PRMDIST Sales by Year (18-20)'!E$61 -> 0.018495635 | F31: ='PRMDIST Sales by Year (18-20)'!F31/'PRMDIST Sales by Year (18-20)'!F$61 -> 0.017540681 | G31: ='PRMDIST Sales by Year (18-20)'!G31/'PRMDIST Sales by Year (18-20)'!G$61 -> 0.017547951 | H31: ='PRMDIST Sales by Year (18-20)'!H31/'PRMDIST Sales by Year (18-20)'!H$61 -> 0.018763194 | I31: ='PRMDIST Sales by Year (18-20)'!I31/'PRMDIST Sales by Year (18-20)'!I$61 -> 0.018589249 | J31: ='PRMDIST Sales by Year (18-20)'!J31/'PRMDIST Sales by Year (18-20)'!J$61 -> 0.018250498 | K31: ='PRMDIST Sales by Year (18-20)'!K31/'PRMDIST Sales by Year (18-20)'!K$61 -> 0.020231714 | L31: ='PRMDIST Sales by Year (18-20)'!L31/'PRMDIST Sales by Year (18-20)'!L$61 -> 0.019736881 | ... P31: ='PRMDIST Sales by Year (18-20)'!P31/'PRMDIST Sales by Year (18-20)'!P$61 -> 0.018279722
A32: =+A31+1 -> 22 | B32: Longview | C32: =+C27 -> 2019 | D32: ='PRMDIST Sales by Year (18-20)'!D32/'PRMDIST Sales by Year (18-20)'!D62 -> 0.015708828 | E32: ='PRMDIST Sales by Year (18-20)'!E32/'PRMDIST Sales by Year (18-20)'!E$62 -> 0.016674003 | F32: ='PRMDIST Sales by Year (18-20)'!F32/'PRMDIST Sales by Year (18-20)'!F$62 -> 0.017000543 | G32: ='PRMDIST Sales by Year (18-20)'!G32/'PRMDIST Sales by Year (18-20)'!G$62 -> 0.010988329 | H32: ='PRMDIST Sales by Year (18-20)'!H32/'PRMDIST Sales by Year (18-20)'!H$62 -> 0.015852391 | I32: ='PRMDIST Sales by Year (18-20)'!I32/'PRMDIST Sales by Year (18-20)'!I$62 -> 0.016147954 | J32: ='PRMDIST Sales by Year (18-20)'!J32/'PRMDIST Sales by Year (18-20)'!J$62 -> 0.016860271 | K32: ='PRMDIST Sales by Year (18-20)'!K32/'PRMDIST Sales by Year (18-20)'!K$62 -> 0.016381497 | L32: ='PRMDIST Sales by Year (18-20)'!L32/'PRMDIST Sales by Year (18-20)'!L$62 -> 0.016961664 | ... P32: ='PRMDIST Sales by Year (18-20)'!P32/'PRMDIST Sales by Year (18-20)'!P$62 -> 0.015812877
A33: =+A32+1 -> 23 | B33: Longview | C33: =+C28 -> 2020 | D33: ='PRMDIST Sales by Year (18-20)'!D33/'PRMDIST Sales by Year (18-20)'!D63 -> 0.013455131 | E33: ='PRMDIST Sales by Year (18-20)'!E33/'PRMDIST Sales by Year (18-20)'!E63 -> 0.014210575 | F33: ='PRMDIST Sales by Year (18-20)'!F33/'PRMDIST Sales by Year (18-20)'!F63 -> 0.014214115 | G33: ='PRMDIST Sales by Year (18-20)'!G33/'PRMDIST Sales by Year (18-20)'!G63 -> 0.014647049 | H33: ='PRMDIST Sales by Year (18-20)'!H33/'PRMDIST Sales by Year (18-20)'!H63 -> 0.014895897 | I33: ='PRMDIST Sales by Year (18-20)'!I33/'PRMDIST Sales by Year (18-20)'!I63 -> 0.017333286 | J33: ='PRMDIST Sales by Year (18-20)'!J33/'PRMDIST Sales by Year (18-20)'!J63 -> 0.017283917 | K33: ='PRMDIST Sales by Year (18-20)'!K33/'PRMDIST Sales by Year (18-20)'!K63 -> 0.017249639 | ... P33: ='PRMDIST Sales by Year (18-20)'!P33/'PRMDIST Sales by Year (18-20)'!P63 -> 0.015605282
A34: =+A33+1 -> 24 | B34: Longview | C34: Total | D34: ='PRMDIST Sales by Year (18-20)'!D34/'PRMDIST Sales by Year (18-20)'!D64 -> 0.015893352 | E34: ='PRMDIST Sales by Year (18-20)'!E34/'PRMDIST Sales by Year (18-20)'!E64 -> 0.016296942 | F34: ='PRMDIST Sales by Year (18-20)'!F34/'PRMDIST Sales by Year (18-20)'!F64 -> 0.016137419 | G34: ='PRMDIST Sales by Year (18-20)'!G34/'PRMDIST Sales by Year (18-20)'!G64 -> 0.014301341 | H34: ='PRMDIST Sales by Year (18-20)'!H34/'PRMDIST Sales by Year (18-20)'!H64 -> 0.016392524 | I34: ='PRMDIST Sales by Year (18-20)'!I34/'PRMDIST Sales by Year (18-20)'!I64 -> 0.017297406 | J34: ='PRMDIST Sales by Year (18-20)'!J34/'PRMDIST Sales by Year (18-20)'!J64 -> 0.017462035 | K34: ='PRMDIST Sales by Year (18-20)'!K34/'PRMDIST Sales by Year (18-20)'!K64 -> 0.017903039 | ... P34: ='PRMDIST Sales by Year (18-20)'!P34/'PRMDIST Sales by Year (18-20)'!P64 -> 0.016506774
A35: =+A34+1 -> 25
A36: =+A35+1 -> 26 | B36: Waco | C36: =+C31 -> 2018 | D36: ='PRMDIST Sales by Year (18-20)'!D36/'PRMDIST Sales by Year (18-20)'!D61 -> 0.034143226 | E36: ='PRMDIST Sales by Year (18-20)'!E36/'PRMDIST Sales by Year (18-20)'!E$61 -> 0.033220517 | F36: ='PRMDIST Sales by Year (18-20)'!F36/'PRMDIST Sales by Year (18-20)'!F$61 -> 0.032613183 | G36: ='PRMDIST Sales by Year (18-20)'!G36/'PRMDIST Sales by Year (18-20)'!G$61 -> 0.032796981 | H36: ='PRMDIST Sales by Year (18-20)'!H36/'PRMDIST Sales by Year (18-20)'!H$61 -> 0.034813032 | I36: ='PRMDIST Sales by Year (18-20)'!I36/'PRMDIST Sales by Year (18-20)'!I$61 -> 0.037579918 | J36: ='PRMDIST Sales by Year (18-20)'!J36/'PRMDIST Sales by Year (18-20)'!J$61 -> 0.035124176 | K36: ='PRMDIST Sales by Year (18-20)'!K36/'PRMDIST Sales by Year (18-20)'!K$61 -> 0.037412403 | L36: ='PRMDIST Sales by Year (18-20)'!L36/'PRMDIST Sales by Year (18-20)'!L$61 -> 0.036005926 | ... P36: ='PRMDIST Sales by Year (18-20)'!P36/'PRMDIST Sales by Year (18-20)'!P$61 -> 0.034398255
A37: =+A36+1 -> 27 | B37: Waco | C37: =+C32 -> 2019 | D37: ='PRMDIST Sales by Year (18-20)'!D37/'PRMDIST Sales by Year (18-20)'!D62 -> 0.028691198 | E37: ='PRMDIST Sales by Year (18-20)'!E37/'PRMDIST Sales by Year (18-20)'!E$62 -> 0.028970275 | F37: ='PRMDIST Sales by Year (18-20)'!F37/'PRMDIST Sales by Year (18-20)'!F$62 -> 0.029729536 | G37: ='PRMDIST Sales by Year (18-20)'!G37/'PRMDIST Sales by Year (18-20)'!G$62 -> 0.03015932 | H37: ='PRMDIST Sales by Year (18-20)'!H37/'PRMDIST Sales by Year (18-20)'!H$62 -> 0.030792778 | I37: ='PRMDIST Sales by Year (18-20)'!I37/'PRMDIST Sales by Year (18-20)'!I$62 -> 0.030637624 | J37: ='PRMDIST Sales by Year (18-20)'!J37/'PRMDIST Sales by Year (18-20)'!J$62 -> 0.031515235 | K37: ='PRMDIST Sales by Year (18-20)'!K37/'PRMDIST Sales by Year (18-20)'!K$62 -> 0.031556328 | L37: ='PRMDIST Sales by Year (18-20)'!L37/'PRMDIST Sales by Year (18-20)'!L$62 -> 0.031090392 | ... P37: ='PRMDIST Sales by Year (18-20)'!P37/'PRMDIST Sales by Year (18-20)'!P$62 -> 0.030277052
A38: =+A37+1 -> 28 | B38: Waco | C38: =+C33 -> 2020 | D38: ='PRMDIST Sales by Year (18-20)'!D38/'PRMDIST Sales by Year (18-20)'!D63 -> 0.024949154 | E38: ='PRMDIST Sales by Year (18-20)'!E38/'PRMDIST Sales by Year (18-20)'!E63 -> 0.026993861 | F38: ='PRMDIST Sales by Year (18-20)'!F38/'PRMDIST Sales by Year (18-20)'!F63 -> 0.025660672 | G38: ='PRMDIST Sales by Year (18-20)'!G38/'PRMDIST Sales by Year (18-20)'!G63 -> 0.02946548 | H38: ='PRMDIST Sales by Year (18-20)'!H38/'PRMDIST Sales by Year (18-20)'!H63 -> 0.028492508 | I38: ='PRMDIST Sales by Year (18-20)'!I38/'PRMDIST Sales by Year (18-20)'!I63 -> 0.031794805 | J38: ='PRMDIST Sales by Year (18-20)'!J38/'PRMDIST Sales by Year (18-20)'!J63 -> 0.03233106 | K38: ='PRMDIST Sales by Year (18-20)'!K38/'PRMDIST Sales by Year (18-20)'!K63 -> 0.032664949 | ... P38: ='PRMDIST Sales by Year (18-20)'!P38/'PRMDIST Sales by Year (18-20)'!P63 -> 0.029729506
A39: =+A38+1 -> 29 | B39: Waco | C39: Total | D39: ='PRMDIST Sales by Year (18-20)'!D39/'PRMDIST Sales by Year (18-20)'!D64 -> 0.028808675 | E39: ='PRMDIST Sales by Year (18-20)'!E39/'PRMDIST Sales by Year (18-20)'!E64 -> 0.029460354 | F39: ='PRMDIST Sales by Year (18-20)'!F39/'PRMDIST Sales by Year (18-20)'!F64 -> 0.029088941 | G39: ='PRMDIST Sales by Year (18-20)'!G39/'PRMDIST Sales by Year (18-20)'!G64 -> 0.030734966 | H39: ='PRMDIST Sales by Year (18-20)'!H39/'PRMDIST Sales by Year (18-20)'!H64 -> 0.031197155 | I39: ='PRMDIST Sales by Year (18-20)'!I39/'PRMDIST Sales by Year (18-20)'!I64 -> 0.033201741 | J39: ='PRMDIST Sales by Year (18-20)'!J39/'PRMDIST Sales by Year (18-20)'!J64 -> 0.032984262 | K39: ='PRMDIST Sales by Year (18-20)'!K39/'PRMDIST Sales by Year (18-20)'!K64 -> 0.033798245 | ... P39: ='PRMDIST Sales by Year (18-20)'!P39/'PRMDIST Sales by Year (18-20)'!P64 -> 0.031367603
A40: =+A39+1 -> 30
A41: =+A40+1 -> 31 | B41: Abilene | C41: =+C36 -> 2018 | D41: ='PRMDIST Sales by Year (18-20)'!D41/'PRMDIST Sales by Year (18-20)'!D61 -> 0.086461055 | E41: ='PRMDIST Sales by Year (18-20)'!E41/'PRMDIST Sales by Year (18-20)'!E$61 -> 0.055108901 | F41: ='PRMDIST Sales by Year (18-20)'!F41/'PRMDIST Sales by Year (18-20)'!F$61 -> 0.071066718 | G41: ='PRMDIST Sales by Year (18-20)'!G41/'PRMDIST Sales by Year (18-20)'!G$61 -> 0.07465278 | H41: ='PRMDIST Sales by Year (18-20)'!H41/'PRMDIST Sales by Year (18-20)'!H$61 -> 0.054852845 | I41: ='PRMDIST Sales by Year (18-20)'!I41/'PRMDIST Sales by Year (18-20)'!I$61 -> 0.075436143 | J41: ='PRMDIST Sales by Year (18-20)'!J41/'PRMDIST Sales by Year (18-20)'!J$61 -> 0.056734186 | K41: ='PRMDIST Sales by Year (18-20)'!K41/'PRMDIST Sales by Year (18-20)'!K$61 -> 0.060841882 | L41: ='PRMDIST Sales by Year (18-20)'!L41/'PRMDIST Sales by Year (18-20)'!L$61 -> 0.059487927 | ... P41: ='PRMDIST Sales by Year (18-20)'!P41/'PRMDIST Sales by Year (18-20)'!P$61 -> 0.063862182
A42: =+A41+1 -> 32 | B42: Abilene | C42: =+C37 -> 2019 | D42: ='PRMDIST Sales by Year (18-20)'!D42/'PRMDIST Sales by Year (18-20)'!D62 -> 0.048930156 | E42: ='PRMDIST Sales by Year (18-20)'!E42/'PRMDIST Sales by Year (18-20)'!E$62 -> 0.067388342 | F42: ='PRMDIST Sales by Year (18-20)'!F42/'PRMDIST Sales by Year (18-20)'!F$62 -> 0.056689178 | G42: ='PRMDIST Sales by Year (18-20)'!G42/'PRMDIST Sales by Year (18-20)'!G$62 -> 0.057542353 | H42: ='PRMDIST Sales by Year (18-20)'!H42/'PRMDIST Sales by Year (18-20)'!H$62 -> 0.046847801 | I42: ='PRMDIST Sales by Year (18-20)'!I42/'PRMDIST Sales by Year (18-20)'!I$62 -> 0.061538586 | J42: ='PRMDIST Sales by Year (18-20)'!J42/'PRMDIST Sales by Year (18-20)'!J$62 -> 0.055098474 | K42: ='PRMDIST Sales by Year (18-20)'!K42/'PRMDIST Sales by Year (18-20)'!K$62 -> 0.053590228 | L42: ='PRMDIST Sales by Year (18-20)'!L42/'PRMDIST Sales by Year (18-20)'!L$62 -> 0.051190539 | ... P42: ='PRMDIST Sales by Year (18-20)'!P42/'PRMDIST Sales by Year (18-20)'!P$62 -> 0.053210866
...

Sheet PRMDIST Sales by Year (18-20)
B1: PUC DOCKET NO.
B2: ONCOR ELECTRIC DELIVERY COMPANY
B3: WEATHER WEIGHTS
B4: =+'PRMDIST Seasonal Weights'!B4:P4 -> FOR THE TEST YEAR ENDING DECEMBER 31, 2021
B6: SPONSOR: D. E. NELSON
B8: PRIMARY SERVICE GREATER THAN 10 KW DISTRIBUTION LINE SALES BY YEAR
A9: Line | B9: (a) | C9: (b) | D9: (c) | E9: (d) | F9: (e) | G9: (f) | H9: (g) | I9: (h) | J9: (i) | K9: (j) | L9: (k) | M9: (l) | N9: (m) | O9: (n) | P9: (o)
A10: No. | B10: Weather Station | C10: Year | D10: 36892 | E10: 36923 | F10: 36951 | G10: 36982 | H10: 37012 | I10: 37043 | J10: 37073 | K10: 37104 | L10: 37135 | M10: 37165 | N10: 37196 | O10: 37226 | P10: Annual
A11: 1 | B11: Dallas-Fort Worth | C11: =+'PRMDIST Weights by Year (18-20)'!C11 -> 2018 | D11: 419741.23 | E11: 402068.73 | F11: 403936.99 | G11: 416953.6 | H11: 410283.52 | I11: 482247.94 | J11: 499940.08 | K11: 492263.52 | L11: 489784.63 | M11: 449913.69 | N11: 415400.76 | O11: 399893.11 | P11: =SUM(D11:O11) -> 5282427.8
A12: =+A11+1 -> 2 | B12: Dallas-Fort Worth | C12: =+'PRMDIST Weights by Year (18-20)'!C12 -> 2019 | D12: 394734.32 | E12: 408399.32 | F12: 396215.21 | G12: 405144.51 | H12: 427460.95 | I12: 450246.06 | J12: 466387.4 | K12: 484716.24 | L12: 507613.13 | M12: 478965.3 | N12: 443768.94 | O12: 412731.81 | P12: =SUM(D12:O12) -> 5276383.2
A13: =+A12+1 -> 3 | B13: Dallas-Fort Worth | C13: =+'PRMDIST Weights by Year (18-20)'!C13 -> 2020 | D13: 406242.17 | E13: 410473.77 | F13: 429921.48 | G13: 395894.35 | H13: 394247.25 | I13: 418410.65 | J13: 465473.1 | K13: 473808.2 | L13: 482962.2 | M13: 448978.62 | N13: 419839.86 | O13: 401386.37 | P13: =SUM(D13:O13) -> 5147638
A14: =+A13+1 -> 4 | B14: Dallas-Fort Worth | C14: Total | D14: =SUM(D11:D13) -> 1220717.7 | E14: =SUM(E11:E13) -> 1220941.8 | F14: =SUM(F11:F13) -> 1230073.7 | G14: =SUM(G11:G13) -> 1217992.5 | H14: =SUM(H11:H13) -> 1231991.7 | I14: =SUM(I11:I13) -> 1350904.6 | J14: =SUM(J11:J13) -> 1431800.6 | K14: =SUM(K11:K13) -> 1450788 | ... O14: =SUM(O11:O13) -> 1214011.3 | P14: =SUM(D14:O14) -> 15706449
A15: =+A14+1 -> 5
A16: =+A15+1 -> 6 | B16: Lufkin | C16: =+C11 -> 2018 | D16: 37051.043 | E16: 27456.432 | F16: 38295.792 | G16: 34656.828 | H16: 34046.165 | I16: 34646.973 | J16: 38867.07 | K16: 36969.435 | L16: 36494.843 | M16: 33947.54 | N16: 33975.26 | O16: 32366.704 | P16: =SUM(D16:O16) -> 418774.09
A17: =+A16+1 -> 7 | B17: Lufkin | C17: =+C12 -> 2019 | D17: 31264.382 | E17: 33973.732 | F17: 31446.608 | G17: 32221.549 | H17: 32970.765 | I17: 34557.075 | J17: 35168.672 | K17: 35835.378 | L17: 36963.049 | M17: 35712.535 | N17: 30888.287 | O17: 35257.529 | P17: =SUM(D17:O17) -> 406259.56
A18: =+A17+1 -> 8 | B18: Lufkin | C18: =+C13 -> 2020 | D18: 33046.759 | E18: 32561.637 | F18: 33250.823 | G18: 33541.963 | H18: 30774.594 | I18: 32099.744 | J18: 34930.355 | K18: 35281.87 | L18: 36492.183 | M18: 35675.186 | N18: 34637.714 | O18: 31935.133 | P18: =SUM(D18:O18) -> 404227.96
A19: =+A18+1 -> 9 | B19: Lufkin | C19: Total | D19: =SUM(D16:D18) -> 101362.18 | E19: =SUM(E16:E18) -> 93991.801 | F19: =SUM(F16:F18) -> 102993.22 | G19: =SUM(G16:G18) -> 100420.34 | H19: =SUM(H16:H18) -> 97791.524 | I19: =SUM(I16:I18) -> 101303.79 | J19: =SUM(J16:J18) -> 108966.1 | K19: =SUM(K16:K18) -> 108086.68 | ... O19: =SUM(O16:O18) -> 99559.366 | P19: =SUM(D19:O19) -> 1229261.6
A20: =+A19+1 -> 10
A21: =+A20+1 -> 11 | B21: Austin | C21: =+C16 -> 2018 | D21: 10360.169 | E21: 10560.933 | F21: 9717.172 | G21: 10372.784 | H21: 10297.416 | I21: 11106.975 | J21: 11255.502 | K21: 10060.577 | L21: 11299.615 | M21: 10740.658 | N21: 10468.481 | O21: 10531.475 | P21: =SUM(D21:O21) -> 126771.76
A22: =+A21+1 -> 12 | B22: Austin | C22: =+C17 -> 2019 | D22: 11232.256 | E22: 10075.656 | F22: 10162.174 | G22: 10493.733 | H22: 10644.349 | I22: 10485.782 | J22: 9740.49 | K22: 9649.498 | L22: 1633.172 | M22: 5635.417 | N22: 5089.644 | O22: 5488.856 | P22: =SUM(D22:O22) -> 100331.03
A23: =+A22+1 -> 13 | B23: Austin | C23: =+C18 -> 2020 | D23: 5829.862 | E23: 5580.851 | F23: 5302.472 | G23: 4909.427 | H23: 4919.912 | I23: 5196.712 | J23: 5253.263 | K23: 5035.094 | L23: 4825.243 | M23: 4648.641 | N23: 5351.317 | O23: 5023.374 | P23: =SUM(D23:O23) -> 61876.168
A24: =+A23+1 -> 14 | B24: Austin | C24: Total | D24: =SUM(D21:D23) -> 27422.287 | E24: =SUM(E21:E23) -> 26217.44 | F24: =SUM(F21:F23) -> 25181.818 | G24: =SUM(G21:G23) -> 25775.944 | H24: =SUM(H21:H23) -> 25861.677 | I24: =SUM(I21:I23) -> 26789.469 | J24: =SUM(J21:J23) -> 26249.255 | K24: =SUM(K21:K23) -> 24745.169 | ... O24: =SUM(O21:O23) -> 21043.705 | P24: =SUM(D24:O24) -> 288978.95
A25: =+A24+1 -> 15
A26: =+A25+1 -> 16 | B26: Killeen | C26: =+C21 -> 2018 | D26: 16286.531 | E26: 14875.866 | F26: 15809.613 | G26: 16776.498 | H26: 16566.726 | I26: 18476.577 | J26: 20118.851 | K26: 21361.411 | L26: 20637.629 | M26: 19543.786 | N26: 16397.554 | O26: 15731.921 | P26: =SUM(D26:O26) -> 212582.96
A27: =+A26+1 -> 17 | B27: Killeen | C27: =+C22 -> 2019 | D27: 15648.134 | E27: 16255.526 | F27: 16101.838 | G27: 15983.805 | H27: 17214.285 | I27: 18620.631 | J27: 19482.396 | K27: 20165.361 | L27: 21009.86 | M27: 20458.09 | N27: 17009.998 | O27: 17082.736 | P27: =SUM(D27:O27) -> 215032.66
A28: =+A27+1 -> 18 | B28: Killeen | C28: =+C23 -> 2020 | D28: 14841.423 | E28: 15690.81 | F28: 15752.452 | G28: 17069.828 | H28: 15782.953 | I28: 17799.462 | J28: 19855.726 | K28: 20763.335 | L28: 20323.794 | M28: 18935.828 | N28: 17429.412 | O28: 16473.933 | P28: =SUM(D28:O28) -> 210718.96
A29: =+A28+1 -> 19 | B29: Killeen | C29: Total | D29: =SUM(D26:D28) -> 46776.088 | E29: =SUM(E26:E28) -> 46822.202 | F29: =SUM(F26:F28) -> 47663.903 | G29: =SUM(G26:G28) -> 49830.131 | H29: =SUM(H26:H28) -> 49563.964 | I29: =SUM(I26:I28) -> 54896.67 | J29: =SUM(J26:J28) -> 59456.973 | K29: =SUM(K26:K28) -> 62290.107 | ... O29: =SUM(O26:O28) -> 49288.59 | P29: =SUM(D29:O29) -> 638334.58
A30: =+A29+1 -> 20
A31: =+A30+1 -> 21 | B31: Longview | C31: =+C26 -> 2018 | D31: 20395.109 | E31: 19891.169 | F31: 19501.188 | G31: 20902.21 | H31: 21470.135 | I31: 23017.182 | J31: 25635.222 | K31: 27366.82 | L31: 27153.596 | M31: 24816.184 | N31: 20728.965 | O31: 20151.195 | P31: =SUM(D31:O31) -> 271028.97
A32: =+A31+1 -> 22 | B32: Longview | C32: =+C27 -> 2019 | D32: 19670.674 | E32: 22244.152 | F32: 21532.517 | G32: 14365.127 | H32: 21203.464 | I32: 23099.334 | J32: 24125.086 | K32: 23704.091 | L32: 26004.266 | M32: 24081.009 | N32: 20669.045 | O32: 22161.514 | P32: =SUM(D32:O32) -> 262860.28
A33: =+A32+1 -> 23 | B33: Longview | C33: =+C28 -> 2020 | D33: 19043.782 | E33: 19531.76 | F33: 19609.244 | G33: 19656.011 | H33: 19808.654 | I33: 21598.383 | J33: 23914.36 | K33: 25033.591 | L33: 24541.817 | M33: 22667.286 | N33: 20997.917 | O33: 18967.024 | P33: =SUM(D33:O33) -> 255369.83
A34: =+A33+1 -> 24 | B34: Longview | C34: Total | D34: =SUM(D31:D33) -> 59109.565 | E34: =SUM(E31:E33) -> 61667.081 | F34: =SUM(F31:F33) -> 60642.949 | G34: =SUM(G31:G33) -> 54923.348 | H34: =SUM(H31:H33) -> 62482.253 | I34: =SUM(I31:I33) -> 67714.899 | J34: =SUM(J31:J33) -> 73674.668 | K34: =SUM(K31:K33) -> 76104.502 | ... O34: =SUM(O31:O33) -> 61279.733 | P34: =SUM(D34:O34) -> 789259.08
A35: =+A34+1 -> 25
A36: =+A35+1 -> 26 | B36: Waco | C36: =+C31 -> 2018 | D36: 35904.269 | E36: 35727.074 | F36: 36258.331 | G36: 39066.065 | H36: 39835.462 | I36: 46531.402 | J36: 49336.518 | K36: 50606.612 | L36: 49536.214 | M36: 46398.304 | N36: 41905.22 | O36: 38909.067 | P36: =SUM(D36:O36) -> 510014.54
A37: =+A36+1 -> 27 | B37: Waco | C37: =+C32 -> 2019 | D37: 35927.263 | E37: 38648.14 | F37: 37654.782 | G37: 39427.511 | H37: 41187.073 | I37: 43826.524 | J37: 45094.635 | K37: 45662.13 | L37: 47665.301 | M37: 48679.61 | N37: 41524.857 | O37: 38003.024 | P37: =SUM(D37:O37) -> 503300.85
A38: =+A37+1 -> 28 | B38: Waco | C38: =+C33 -> 2020 | D38: 35311.901 | E38: 37101.778 | F38: 35400.471 | G38: 39542.013 | H38: 37889.508 | I38: 39618.36 | J38: 44733.878 | K38: 47405.107 | L38: 45505.866 | M38: 43842.597 | N38: 41684.348 | O38: 38467.32 | P38: =SUM(D38:O38) -> 486503.15
A39: =+A38+1 -> 29 | B39: Waco | C39: Total | D39: =SUM(D36:D38) -> 107143.43 | E39: =SUM(E36:E38) -> 111476.99 | F39: =SUM(F36:F38) -> 109313.58 | G39: =SUM(G36:G38) -> 118035.59 | H39: =SUM(H36:H38) -> 118912.04 | I39: =SUM(I36:I38) -> 129976.29 | J39: =SUM(J36:J38) -> 139165.03 | K39: =SUM(K36:K38) -> 143673.85 | ... O39: =SUM(O36:O38) -> 115379.41 | P39: =SUM(D39:O39) -> 1499818.5
A40: =+A39+1 -> 30
A41: =+A40+1 -> 31 | B41: Abilene | C41: =+C36 -> 2018 | D41: 90920.552 | E41: 59266.982 | F41: 79009.786 | G41: 88922.524 | H41: 62766.392 | I41: 93404.927 | J41: 79690.616 | K41: 82298.951 | L41: 81842.268 | M41: 76739.97 | N41: 63105.07 | O41: 88900.967 | P41: =SUM(D41:O41) -> 946869.01
A42: =+A41+1 -> 32 | B42: Abilene | C42: =+C37 -> 2019 | D42: 61270.589 | E42: 89900.219 | F42: 71801.277 | G42: 75225.56 | H42: 62661.568 | I42: 88029.749 | J42: 78839.505 | K42: 77545.271 | L42: 78481.238 | M42: 73120.288 | N42: 68646.229 | O42: 59012.245 | P42: =SUM(D42:O42) -> 884533.74
...
