Workbook
Name HOURLY: [1]HOURLY!$A$1:$G$745
Name OLE_LINK2: 'SECGT10 Seasonal Weights'!$B$24
Name rngBilled: OFFSET([2]Sheet2!$A$2,0,0,[2]Sheet2!$B$1,9)
Name rngYear: OFFSET('[3]Daily Actual_August'!$A$2,0,0,'[3]Daily Actual_August'!$C$1,8)

Sheet SECGT10 Seasonal Weights
B1: PUC DOCKET NO.
B2: ONCOR ELECTRIC DELIVERY COMPANY LLC
B3: WEATHER WEIGHTS
B4: FOR THE TEST YEAR ENDING DECEMBER 31, 2021
B6: SPONSOR: D. E. NELSON
B8: SECONDARY SERVICE GREATER THAN 10 KW MONTHLY WEIGHTS
A9: Line | B9: (a) | D9: (b) | E9: (c) | F9: (d) | G9: (e) | H9: (f) | I9: (g) | J9: (h) | K9: (i) | L9: (j) | M9: (k) | N9: (l) | O9: (m) | P9: (n)
A10: No. | B10: Weather Station | D10: 36892 | E10: 36923 | F10: 36951 | G10: 36982 | H10: 37012 | I10: 37043 | J10: 37073 | K10: 37104 | L10: 37135 | M10: 37165 | N10: 37196 | O10: 37226 | P10: Annual
A11: 1 | B11: Dallas-Fort Worth | D11: =+'SECGT10 Monthly Weather Weights'!C11 -> 0.74552691 | E11: =+'SECGT10 Monthly Weather Weights'!D11 -> 0.74153345 | F11: =+'SECGT10 Monthly Weather Weights'!E11 -> 0.74096418 | G11: =+'SECGT10 Monthly Weather Weights'!F11 -> 0.74302556 | H11: =+'SECGT10 Monthly Weather Weights'!G11 -> 0.73915397 | I11: =+'SECGT10 Monthly Weather Weights'!H11 -> 0.73998801 | J11: =+'SECGT10 Monthly Weather Weights'!I11 -> 0.74219828 | K11: =+'SECGT10 Monthly Weather Weights'!J11 -> 0.74106369 | ... P11: =+'SECGT10 Monthly Weather Weights'!O11 -> 0.74136424
A12: =+A11+1 -> 2 | B12: Midland-Odessa | D12: =+'SECGT10 Monthly Weather Weights'!C12 -> 0.066043751 | E12: =+'SECGT10 Monthly Weather Weights'!D12 -> 0.06679345 | F12: =+'SECGT10 Monthly Weather Weights'!E12 -> 0.068866567 | G12: =+'SECGT10 Monthly Weather Weights'!F12 -> 0.066298383 | H12: =+'SECGT10 Monthly Weather Weights'!G12 -> 0.068585498 | I12: =+'SECGT10 Monthly Weather Weights'!H12 -> 0.064345197 | J12: =+'SECGT10 Monthly Weather Weights'!I12 -> 0.064017834 | K12: =+'SECGT10 Monthly Weather Weights'!J12 -> 0.064223839 | ... P12: =+'SECGT10 Monthly Weather Weights'!O12 -> 0.065594632
A13: =+A12+1 -> 3 | B13: Lufkin | D13: =+'SECGT10 Monthly Weather Weights'!C13 -> 0.023953034 | E13: =+'SECGT10 Monthly Weather Weights'!D13 -> 0.024662487 | F13: =+'SECGT10 Monthly Weather Weights'!E13 -> 0.024329972 | G13: =+'SECGT10 Monthly Weather Weights'!F13 -> 0.025018733 | H13: =+'SECGT10 Monthly Weather Weights'!G13 -> 0.025282669 | I13: =+'SECGT10 Monthly Weather Weights'!H13 -> 0.026001271 | J13: =+'SECGT10 Monthly Weather Weights'!I13 -> 0.025020173 | K13: =+'SECGT10 Monthly Weather Weights'!J13 -> 0.024899329 | ... P13: =+'SECGT10 Monthly Weather Weights'!O13 -> 0.02493313
A14: =+A13+1 -> 4 | B14: Abilene | D14: =+'SECGT10 Monthly Weather Weights'!C14 -> 0.012101426 | E14: =+'SECGT10 Monthly Weather Weights'!D14 -> 0.012052904 | F14: =+'SECGT10 Monthly Weather Weights'!E14 -> 0.011455309 | G14: =+'SECGT10 Monthly Weather Weights'!F14 -> 0.011337875 | H14: =+'SECGT10 Monthly Weather Weights'!G14 -> 0.011309753 | I14: =+'SECGT10 Monthly Weather Weights'!H14 -> 0.011395411 | J14: =+'SECGT10 Monthly Weather Weights'!I14 -> 0.011711666 | K14: =+'SECGT10 Monthly Weather Weights'!J14 -> 0.011923687 | ... P14: =+'SECGT10 Monthly Weather Weights'!O14 -> 0.01156842
A15: =+A14+1 -> 5 | B15: Sherman-Denison | D15: =+'SECGT10 Monthly Weather Weights'!C15 -> 0.024012628 | E15: =+'SECGT10 Monthly Weather Weights'!D15 -> 0.024553924 | F15: =+'SECGT10 Monthly Weather Weights'!E15 -> 0.024123748 | G15: =+'SECGT10 Monthly Weather Weights'!F15 -> 0.023995124 | H15: =+'SECGT10 Monthly Weather Weights'!G15 -> 0.023672116 | I15: =+'SECGT10 Monthly Weather Weights'!H15 -> 0.023556244 | J15: =+'SECGT10 Monthly Weather Weights'!I15 -> 0.023693416 | K15: =+'SECGT10 Monthly Weather Weights'!J15 -> 0.024092846 | ... P15: =+'SECGT10 Monthly Weather Weights'!O15 -> 0.023949324
A16: =+A15+1 -> 6 | B16: Killeen-Temple | D16: =+'SECGT10 Monthly Weather Weights'!C16 -> 0.026053194 | E16: =+'SECGT10 Monthly Weather Weights'!D16 -> 0.026280249 | F16: =+'SECGT10 Monthly Weather Weights'!E16 -> 0.02621685 | G16: =+'SECGT10 Monthly Weather Weights'!F16 -> 0.026140089 | H16: =+'SECGT10 Monthly Weather Weights'!G16 -> 0.026454499 | I16: =+'SECGT10 Monthly Weather Weights'!H16 -> 0.027186127 | J16: =+'SECGT10 Monthly Weather Weights'!I16 -> 0.02689005 | K16: =+'SECGT10 Monthly Weather Weights'!J16 -> 0.026900894 | ... P16: =+'SECGT10 Monthly Weather Weights'!O16 -> 0.026768723
A17: =+A16+1 -> 7 | B17: Waco | D17: =+'SECGT10 Monthly Weather Weights'!C17 -> 0.032013123 | E17: =+'SECGT10 Monthly Weather Weights'!D17 -> 0.032544375 | F17: =+'SECGT10 Monthly Weather Weights'!E17 -> 0.032828373 | G17: =+'SECGT10 Monthly Weather Weights'!F17 -> 0.032679163 | H17: =+'SECGT10 Monthly Weather Weights'!G17 -> 0.033036355 | I17: =+'SECGT10 Monthly Weather Weights'!H17 -> 0.033837914 | J17: =+'SECGT10 Monthly Weather Weights'!I17 -> 0.033421467 | K17: =+'SECGT10 Monthly Weather Weights'!J17 -> 0.033803454 | ... P17: =+'SECGT10 Monthly Weather Weights'!O17 -> 0.033291602
A18: =+A17+1 -> 8 | B18: Wichita Falls. | D18: =+'SECGT10 Monthly Weather Weights'!C18 -> 0.014676124 | E18: =+'SECGT10 Monthly Weather Weights'!D18 -> 0.015001919 | F18: =+'SECGT10 Monthly Weather Weights'!E18 -> 0.014789395 | G18: =+'SECGT10 Monthly Weather Weights'!F18 -> 0.01458159 | H18: =+'SECGT10 Monthly Weather Weights'!G18 -> 0.014554373 | I18: =+'SECGT10 Monthly Weather Weights'!H18 -> 0.014841545 | J18: =+'SECGT10 Monthly Weather Weights'!I18 -> 0.015216227 | K18: =+'SECGT10 Monthly Weather Weights'!J18 -> 0.015331513 | ... P18: =+'SECGT10 Monthly Weather Weights'!O18 -> 0.014879542
A19: =+A18+1 -> 9 | B19: Longview | D19: =+'SECGT10 Monthly Weather Weights'!C19 -> 0.03028191 | E19: =+'SECGT10 Monthly Weather Weights'!D19 -> 0.030772472 | F19: =+'SECGT10 Monthly Weather Weights'!E19 -> 0.030429795 | G19: =+'SECGT10 Monthly Weather Weights'!F19 -> 0.03050628 | H19: =+'SECGT10 Monthly Weather Weights'!G19 -> 0.031158835 | I19: =+'SECGT10 Monthly Weather Weights'!H19 -> 0.031539096 | J19: =+'SECGT10 Monthly Weather Weights'!I19 -> 0.031544031 | K19: =+'SECGT10 Monthly Weather Weights'!J19 -> 0.031362229 | ... P19: =+'SECGT10 Monthly Weather Weights'!O19 -> 0.031062164
A20: =+A19+1 -> 10 | B20: Austin | D20: =+'SECGT10 Monthly Weather Weights'!C20 -> 0.025337905 | E20: =+'SECGT10 Monthly Weather Weights'!D20 -> 0.025804772 | F20: =+'SECGT10 Monthly Weather Weights'!E20 -> 0.02599581 | G20: =+'SECGT10 Monthly Weather Weights'!F20 -> 0.026417204 | H20: =+'SECGT10 Monthly Weather Weights'!G20 -> 0.026791936 | I20: =+'SECGT10 Monthly Weather Weights'!H20 -> 0.027309184 | J20: =+'SECGT10 Monthly Weather Weights'!I20 -> 0.026286856 | K20: =+'SECGT10 Monthly Weather Weights'!J20 -> 0.026398516 | ... P20: =+'SECGT10 Monthly Weather Weights'!O20 -> 0.026588223
A21: =+A20+1 -> 11 | D21: =SUM(D11:D20) -> 1 | E21: =SUM(E11:E20) -> 1 | F21: =SUM(F11:F20) -> 1 | G21: =SUM(G11:G20) -> 1 | H21: =SUM(H11:H20) -> 1 | I21: =SUM(I11:I20) -> 1 | J21: =SUM(J11:J20) -> 1 | K21: =SUM(K11:K20) -> 1 | ... P21: =SUM(P11:P20) -> 1
A22: =+A21+1 -> 12
A23: =+A22+1 -> 13 | D23: SEASONAL WEIGHTS
A24: =+A23+1 -> 14 | D24: Nov to Mar | F24: May to Sep
A25: =+A24+1 -> 15 | B25: Weather Station | D25: HDD | F25: CDD
A26: =+A25+1 -> 16 | B26: Dallas-Fort Worth | D26: =ROUND(AVERAGE(D11:F11,N11:O11),3) -> 0.741 | F26: =ROUND(AVERAGE(H11:L11),3) -> 0.74
A27: =+A26+1 -> 17 | B27: Midland-Odessa | D27: =ROUND(AVERAGE(D12:F12,N12:O12),3) -> 0.068 | F27: =ROUND(AVERAGE(H12:L12),3) -> 0.065
A28: =+A27+1 -> 18 | B28: Lufkin | D28: =ROUND(AVERAGE(D13:F13,N13:O13),3) -> 0.024 | F28: =ROUND(AVERAGE(H13:L13),3) -> 0.025
A29: =+A28+1 -> 19 | B29: Abilene | D29: =ROUND(AVERAGE(D14:F14,N14:O14),3) -> 0.012 | F29: =ROUND(AVERAGE(H14:L14),3) -> 0.012
A30: =+A29+1 -> 20 | B30: Sherman-Denison | D30: =ROUND(AVERAGE(D15:F15,N15:O15),3) -> 0.024 | F30: =ROUND(AVERAGE(H15:L15),3) -> 0.024
A31: =+A30+1 -> 21 | B31: Killeen-Temple | D31: =ROUND(AVERAGE(D16:F16,N16:O16),3) -> 0.026 | F31: =ROUND(AVERAGE(H16:L16),3) -> 0.027
A32: =+A31+1 -> 22 | B32: Waco | D32: =ROUND(AVERAGE(D17:F17,N17:O17),3) -> 0.033 | F32: =ROUND(AVERAGE(H17:L17),3) -> 0.034
A33: =+A32+1 -> 23 | B33: Wichita Falls. | D33: =ROUND(AVERAGE(D18:F18,N18:O18),3) -> 0.015 | F33: =ROUND(AVERAGE(H18:L18),3) -> 0.015
A34: =+A33+1 -> 24 | B34: Longview | D34: =ROUND(AVERAGE(D19:F19,N19:O19),3) -> 0.031 | F34: =ROUND(AVERAGE(H19:L19),3) -> 0.031
A35: =+A34+1 -> 25 | B35: Austin | D35: =ROUND(AVERAGE(D20:F20,N20:O20),3) -> 0.026 | F35: =ROUND(AVERAGE(H20:L20),3) -> 0.027
A36: =+A35+1 -> 26 | D36: =AVERAGE(D21:F21,N21:O21) -> 1 | F36: =AVERAGE(H21:L21) -> 1

Sheet SECGT10 Monthly Weather Weights
B1: PUC DOCKET NO.
B2: ONCOR ELECTRIC DELIVERY COMPANY
B3: WEATHER WEIGHTS
B4: =+'SECGT10 Seasonal Weights'!B4:P4 -> FOR THE TEST YEAR ENDING DECEMBER 31, 2021
B6: SPONSOR: D. E. NELSON
B8: SECONDARY SERVICE GREATER THAN 10 KW MONTHLY WEIGHTS
A9: Line | B9: (a) | C9: (b) | D9: (c) | E9: (d) | F9: (e) | G9: (f) | H9: (g) | I9: (h) | J9: (i) | K9: (j) | L9: (k) | M9: (l) | N9: (m) | O9: (n)
A10: No. | B10: Weather Station | C10: 36892 | D10: 36923 | E10: 36951 | F10: 36982 | G10: 37012 | H10: 37043 | I10: 37073 | J10: 37104 | K10: 37135 | L10: 37165 | M10: 37196 | N10: 37226 | O10: Annual
A11: 1 | B11: Dallas-Fort Worth | C11: =+'SECGT10 Weights by Year (18-20)'!D14 -> 0.74552691 | D11: =+'SECGT10 Weights by Year (18-20)'!E14 -> 0.74153345 | E11: =+'SECGT10 Weights by Year (18-20)'!F14 -> 0.74096418 | F11: =+'SECGT10 Weights by Year (18-20)'!G14 -> 0.74302556 | G11: =+'SECGT10 Weights by Year (18-20)'!H14 -> 0.73915397 | H11: =+'SECGT10 Weights by Year (18-20)'!I14 -> 0.73998801 | I11: =+'SECGT10 Weights by Year (18-20)'!J14 -> 0.74219828 | J11: =+'SECGT10 Weights by Year (18-20)'!K14 -> 0.74106369 | ... O11: =+'SECGT10 Weights by Year (18-20)'!P14 -> 0.74136424
A12: =+A11+1 -> 2 | B12: Midland-Odessa | C12: =+'SECGT10 Weights by Year (18-20)'!D54 -> 0.066043751 | D12: =+'SECGT10 Weights by Year (18-20)'!E54 -> 0.06679345 | E12: =+'SECGT10 Weights by Year (18-20)'!F54 -> 0.068866567 | F12: =+'SECGT10 Weights by Year (18-20)'!G54 -> 0.066298383 | G12: =+'SECGT10 Weights by Year (18-20)'!H54 -> 0.068585498 | H12: =+'SECGT10 Weights by Year (18-20)'!I54 -> 0.064345197 | I12: =+'SECGT10 Weights by Year (18-20)'!J54 -> 0.064017834 | J12: =+'SECGT10 Weights by Year (18-20)'!K54 -> 0.064223839 | ... O12: =+'SECGT10 Weights by Year (18-20)'!P54 -> 0.065594632
A13: =+A12+1 -> 3 | B13: Lufkin | C13: =+'SECGT10 Weights by Year (18-20)'!D19 -> 0.023953034 | D13: =+'SECGT10 Weights by Year (18-20)'!E19 -> 0.024662487 | E13: =+'SECGT10 Weights by Year (18-20)'!F19 -> 0.024329972 | F13: =+'SECGT10 Weights by Year (18-20)'!G19 -> 0.025018733 | G13: =+'SECGT10 Weights by Year (18-20)'!H19 -> 0.025282669 | H13: =+'SECGT10 Weights by Year (18-20)'!I19 -> 0.026001271 | I13: =+'SECGT10 Weights by Year (18-20)'!J19 -> 0.025020173 | J13: =+'SECGT10 Weights by Year (18-20)'!K19 -> 0.024899329 | ... O13: =+'SECGT10 Weights by Year (18-20)'!P19 -> 0.02493313
A14: =+A13+1 -> 4 | B14: Abilene | C14: =+'SECGT10 Weights by Year (18-20)'!D44 -> 0.012101426 | D14: =+'SECGT10 Weights by Year (18-20)'!E44 -> 0.012052904 | E14: =+'SECGT10 Weights by Year (18-20)'!F44 -> 0.011455309 | F14: =+'SECGT10 Weights by Year (18-20)'!G44 -> 0.011337875 | G14: =+'SECGT10 Weights by Year (18-20)'!H44 -> 0.011309753 | H14: =+'SECGT10 Weights by Year (18-20)'!I44 -> 0.011395411 | I14: =+'SECGT10 Weights by Year (18-20)'!J44 -> 0.011711666 | J14: =+'SECGT10 Weights by Year (18-20)'!K44 -> 0.011923687 | ... O14: =+'SECGT10 Weights by Year (18-20)'!P44 -> 0.01156842
A15: =+A14+1 -> 5 | B15: Sherman-Denison | C15: =+'SECGT10 Weights by Year (18-20)'!D59 -> 0.024012628 | D15: =+'SECGT10 Weights by Year (18-20)'!E59 -> 0.024553924 | E15: =+'SECGT10 Weights by Year (18-20)'!F59 -> 0.024123748 | F15: =+'SECGT10 Weights by Year (18-20)'!G59 -> 0.023995124 | G15: =+'SECGT10 Weights by Year (18-20)'!H59 -> 0.023672116 | H15: =+'SECGT10 Weights by Year (18-20)'!I59 -> 0.023556244 | I15: =+'SECGT10 Weights by Year (18-20)'!J59 -> 0.023693416 | J15: =+'SECGT10 Weights by Year (18-20)'!K59 -> 0.024092846 | ... O15: =+'SECGT10 Weights by Year (18-20)'!P59 -> 0.023949324
A16: =+A15+1 -> 6 | B16: Killeen-Temple | C16: =+'SECGT10 Weights by Year (18-20)'!D29 -> 0.026053194 | D16: =+'SECGT10 Weights by Year (18-20)'!E29 -> 0.026280249 | E16: =+'SECGT10 Weights by Year (18-20)'!F29 -> 0.02621685 | F16: =+'SECGT10 Weights by Year (18-20)'!G29 -> 0.026140089 | G16: =+'SECGT10 Weights by Year (18-20)'!H29 -> 0.026454499 | H16: =+'SECGT10 Weights by Year (18-20)'!I29 -> 0.027186127 | I16: =+'SECGT10 Weights by Year (18-20)'!J29 -> 0.02689005 | J16: =+'SECGT10 Weights by Year (18-20)'!K29 -> 0.026900894 | ... O16: =+'SECGT10 Weights by Year (18-20)'!P29 -> 0.026768723
A17: =+A16+1 -> 7 | B17: Waco | C17: =+'SECGT10 Weights by Year (18-20)'!D39 -> 0.032013123 | D17: =+'SECGT10 Weights by Year (18-20)'!E39 -> 0.032544375 | E17: =+'SECGT10 Weights by Year (18-20)'!F39 -> 0.032828373 | F17: =+'SECGT10 Weights by Year (18-20)'!G39 -> 0.032679163 | G17: =+'SECGT10 Weights by Year (18-20)'!H39 -> 0.033036355 | H17: =+'SECGT10 Weights by Year (18-20)'!I39 -> 0.033837914 | I17: =+'SECGT10 Weights by Year (18-20)'!J39 -> 0.033421467 | J17: =+'SECGT10 Weights by Year (18-20)'!K39 -> 0.033803454 | ... O17: =+'SECGT10 Weights by Year (18-20)'!P39 -> 0.033291602
A18: =+A17+1 -> 8 | B18: Wichita Falls. | C18: =+'SECGT10 Weights by Year (18-20)'!D49 -> 0.014676124 | D18: =+'SECGT10 Weights by Year (18-20)'!E49 -> 0.015001919 | E18: =+'SECGT10 Weights by Year (18-20)'!F49 -> 0.014789395 | F18: =+'SECGT10 Weights by Year (18-20)'!G49 -> 0.01458159 | G18: =+'SECGT10 Weights by Year (18-20)'!H49 -> 0.014554373 | H18: =+'SECGT10 Weights by Year (18-20)'!I49 -> 0.014841545 | I18: =+'SECGT10 Weights by Year (18-20)'!J49 -> 0.015216227 | J18: =+'SECGT10 Weights by Year (18-20)'!K49 -> 0.015331513 | ... O18: =+'SECGT10 Weights by Year (18-20)'!P49 -> 0.014879542
A19: =+A18+1 -> 9 | B19: Longview | C19: =+'SECGT10 Weights by Year (18-20)'!D34 -> 0.03028191 | D19: =+'SECGT10 Weights by Year (18-20)'!E34 -> 0.030772472 | E19: =+'SECGT10 Weights by Year (18-20)'!F34 -> 0.030429795 | F19: =+'SECGT10 Weights by Year (18-20)'!G34 -> 0.03050628 | G19: =+'SECGT10 Weights by Year (18-20)'!H34 -> 0.031158835 | H19: =+'SECGT10 Weights by Year (18-20)'!I34 -> 0.031539096 | I19: =+'SECGT10 Weights by Year (18-20)'!J34 -> 0.031544031 | J19: =+'SECGT10 Weights by Year (18-20)'!K34 -> 0.031362229 | ... O19: =+'SECGT10 Weights by Year (18-20)'!P34 -> 0.031062164
A20: =+A19+1 -> 10 | B20: Austin | C20: =+'SECGT10 Weights by Year (18-20)'!D24 -> 0.025337905 | D20: =+'SECGT10 Weights by Year (18-20)'!E24 -> 0.025804772 | E20: =+'SECGT10 Weights by Year (18-20)'!F24 -> 0.02599581 | F20: =+'SECGT10 Weights by Year (18-20)'!G24 -> 0.026417204 | G20: =+'SECGT10 Weights by Year (18-20)'!H24 -> 0.026791936 | H20: =+'SECGT10 Weights by Year (18-20)'!I24 -> 0.027309184 | I20: =+'SECGT10 Weights by Year (18-20)'!J24 -> 0.026286856 | J20: =+'SECGT10 Weights by Year (18-20)'!K24 -> 0.026398516 | ... O20: =+'SECGT10 Weights by Year (18-20)'!P24 -> 0.026588223
C21: =SUM(C11:C20) -> 1 | D21: =SUM(D11:D20) -> 1 | E21: =SUM(E11:E20) -> 1 | F21: =SUM(F11:F20) -> 1 | G21: =SUM(G11:G20) -> 1 | H21: =SUM(H11:H20) -> 1 | I21: =SUM(I11:I20) -> 1 | J21: =SUM(J11:J20) -> 1 | ... O21: =SUM(O11:O20) -> 1

Sheet SECGT10 Weights by Year (18-20)
B1: PUC DOCKET NO.
B2: ONCOR ELECTRIC DELIVERY COMPANY
B3: WEATHER WEIGHTS
B4: =+'SECGT10 Seasonal Weights'!B4:P4 -> FOR THE TEST YEAR ENDING DECEMBER 31, 2021
B6: SPONSOR: D. E. NELSON
B8: SECONDARY SERVICE GREATER THAN 10 KW WEIGHTS BY YEAR
A9: Line | B9: (a) | C9: (b) | D9: (c) | E9: (d) | F9: (e) | G9: (f) | H9: (g) | I9: (h) | J9: (i) | K9: (j) | L9: (k) | M9: (l) | N9: (m) | O9: (n) | P9: (o)
A10: No. | B10: Weather Station | C10: Year | D10: 36892 | E10: 36923 | F10: 36951 | G10: 36982 | H10: 37012 | I10: 37043 | J10: 37073 | K10: 37104 | L10: 37135 | M10: 37165 | N10: 37196 | O10: 37226 | P10: Annual
A11: 1 | B11: Dallas-Fort Worth | C11: 2018 | D11: ='SECGT10 Sales by Year (18-20)'!D11/'SECGT10 Sales by Year (18-20)'!D61 -> 0.75512091 | E11: ='SECGT10 Sales by Year (18-20)'!E11/'SECGT10 Sales by Year (18-20)'!E$61 -> 0.74004021 | F11: ='SECGT10 Sales by Year (18-20)'!F11/'SECGT10 Sales by Year (18-20)'!F$61 -> 0.74574222 | G11: ='SECGT10 Sales by Year (18-20)'!G11/'SECGT10 Sales by Year (18-20)'!G$61 -> 0.7425472 | H11: ='SECGT10 Sales by Year (18-20)'!H11/'SECGT10 Sales by Year (18-20)'!H$61 -> 0.73956959 | I11: ='SECGT10 Sales by Year (18-20)'!I11/'SECGT10 Sales by Year (18-20)'!I$61 -> 0.74136974 | J11: ='SECGT10 Sales by Year (18-20)'!J11/'SECGT10 Sales by Year (18-20)'!J$61 -> 0.74438451 | K11: ='SECGT10 Sales by Year (18-20)'!K11/'SECGT10 Sales by Year (18-20)'!K$61 -> 0.74357627 | L11: ='SECGT10 Sales by Year (18-20)'!L11/'SECGT10 Sales by Year (18-20)'!L$61 -> 0.74075163 | ... P11: ='SECGT10 Sales by Year (18-20)'!P11/'SECGT10 Sales by Year (18-20)'!P$61 -> 0.74400555
A12: =+A11+1 -> 2 | B12: Dallas-Fort Worth | C12: 2019 | D12: ='SECGT10 Sales by Year (18-20)'!D12/'SECGT10 Sales by Year (18-20)'!D62 -> 0.74150461 | E12: ='SECGT10 Sales by Year (18-20)'!E12/'SECGT10 Sales by Year (18-20)'!E$62 -> 0.74184499 | F12: ='SECGT10 Sales by Year (18-20)'!F12/'SECGT10 Sales by Year (18-20)'!F$62 -> 0.74154055 | G12: ='SECGT10 Sales by Year (18-20)'!G12/'SECGT10 Sales by Year (18-20)'!G$62 -> 0.74764793 | H12: ='SECGT10 Sales by Year (18-20)'!H12/'SECGT10 Sales by Year (18-20)'!H$62 -> 0.7410801 | I12: ='SECGT10 Sales by Year (18-20)'!I12/'SECGT10 Sales by Year (18-20)'!I$62 -> 0.73975044 | J12: ='SECGT10 Sales by Year (18-20)'!J12/'SECGT10 Sales by Year (18-20)'!J$62 -> 0.74283986 | K12: ='SECGT10 Sales by Year (18-20)'!K12/'SECGT10 Sales by Year (18-20)'!K$62 -> 0.74082655 | L12: ='SECGT10 Sales by Year (18-20)'!L12/'SECGT10 Sales by Year (18-20)'!L$62 -> 0.74032477 | ... P12: ='SECGT10 Sales by Year (18-20)'!P12/'SECGT10 Sales by Year (18-20)'!P$62 -> 0.74162363
A13: =+A12+1 -> 3 | B13: Dallas-Fort Worth | C13: 2020 | D13: ='SECGT10 Sales by Year (18-20)'!D13/'SECGT10 Sales by Year (18-20)'!D63 -> 0.73898388 | E13: ='SECGT10 Sales by Year (18-20)'!E13/'SECGT10 Sales by Year (18-20)'!E63 -> 0.74267939 | F13: ='SECGT10 Sales by Year (18-20)'!F13/'SECGT10 Sales by Year (18-20)'!F63 -> 0.73552074 | G13: ='SECGT10 Sales by Year (18-20)'!G13/'SECGT10 Sales by Year (18-20)'!G63 -> 0.73859671 | H13: ='SECGT10 Sales by Year (18-20)'!H13/'SECGT10 Sales by Year (18-20)'!H63 -> 0.73646467 | I13: ='SECGT10 Sales by Year (18-20)'!I13/'SECGT10 Sales by Year (18-20)'!I63 -> 0.73861611 | J13: ='SECGT10 Sales by Year (18-20)'!J13/'SECGT10 Sales by Year (18-20)'!J63 -> 0.73908662 | K13: ='SECGT10 Sales by Year (18-20)'!K13/'SECGT10 Sales by Year (18-20)'!K63 -> 0.73858778 | ... P13: ='SECGT10 Sales by Year (18-20)'!P13/'SECGT10 Sales by Year (18-20)'!P63 -> 0.73822688
A14: =+A13+1 -> 4 | B14: Dallas-Fort Worth | C14: Total | D14: ='SECGT10 Sales by Year (18-20)'!D14/'SECGT10 Sales by Year (18-20)'!D64 -> 0.74552691 | E14: ='SECGT10 Sales by Year (18-20)'!E14/'SECGT10 Sales by Year (18-20)'!E64 -> 0.74153345 | F14: ='SECGT10 Sales by Year (18-20)'!F14/'SECGT10 Sales by Year (18-20)'!F64 -> 0.74096418 | G14: ='SECGT10 Sales by Year (18-20)'!G14/'SECGT10 Sales by Year (18-20)'!G64 -> 0.74302556 | H14: ='SECGT10 Sales by Year (18-20)'!H14/'SECGT10 Sales by Year (18-20)'!H64 -> 0.73915397 | I14: ='SECGT10 Sales by Year (18-20)'!I14/'SECGT10 Sales by Year (18-20)'!I64 -> 0.73998801 | J14: ='SECGT10 Sales by Year (18-20)'!J14/'SECGT10 Sales by Year (18-20)'!J64 -> 0.74219828 | K14: ='SECGT10 Sales by Year (18-20)'!K14/'SECGT10 Sales by Year (18-20)'!K64 -> 0.74106369 | ... P14: ='SECGT10 Sales by Year (18-20)'!P14/'SECGT10 Sales by Year (18-20)'!P64 -> 0.74136424
A15: =+A14+1 -> 5
A16: =+A15+1 -> 6 | B16: Lufkin | C16: =+C11 -> 2018 | D16: ='SECGT10 Sales by Year (18-20)'!D16/'SECGT10 Sales by Year (18-20)'!D61 -> 0.023886337 | E16: ='SECGT10 Sales by Year (18-20)'!E16/'SECGT10 Sales by Year (18-20)'!E$61 -> 0.02490883 | F16: ='SECGT10 Sales by Year (18-20)'!F16/'SECGT10 Sales by Year (18-20)'!F$61 -> 0.024266287 | G16: ='SECGT10 Sales by Year (18-20)'!G16/'SECGT10 Sales by Year (18-20)'!G$61 -> 0.024981314 | H16: ='SECGT10 Sales by Year (18-20)'!H16/'SECGT10 Sales by Year (18-20)'!H$61 -> 0.025021057 | I16: ='SECGT10 Sales by Year (18-20)'!I16/'SECGT10 Sales by Year (18-20)'!I$61 -> 0.025413419 | J16: ='SECGT10 Sales by Year (18-20)'!J16/'SECGT10 Sales by Year (18-20)'!J$61 -> 0.024646586 | K16: ='SECGT10 Sales by Year (18-20)'!K16/'SECGT10 Sales by Year (18-20)'!K$61 -> 0.024691792 | L16: ='SECGT10 Sales by Year (18-20)'!L16/'SECGT10 Sales by Year (18-20)'!L$61 -> 0.025423638 | ... P16: ='SECGT10 Sales by Year (18-20)'!P16/'SECGT10 Sales by Year (18-20)'!P$61 -> 0.024845268
A17: =+A16+1 -> 7 | B17: Lufkin | C17: =+C12 -> 2019 | D17: ='SECGT10 Sales by Year (18-20)'!D17/'SECGT10 Sales by Year (18-20)'!D62 -> 0.023799944 | E17: ='SECGT10 Sales by Year (18-20)'!E17/'SECGT10 Sales by Year (18-20)'!E$62 -> 0.02443208 | F17: ='SECGT10 Sales by Year (18-20)'!F17/'SECGT10 Sales by Year (18-20)'!F$62 -> 0.024287073 | G17: ='SECGT10 Sales by Year (18-20)'!G17/'SECGT10 Sales by Year (18-20)'!G$62 -> 0.024928924 | H17: ='SECGT10 Sales by Year (18-20)'!H17/'SECGT10 Sales by Year (18-20)'!H$62 -> 0.025269064 | I17: ='SECGT10 Sales by Year (18-20)'!I17/'SECGT10 Sales by Year (18-20)'!I$62 -> 0.026817498 | J17: ='SECGT10 Sales by Year (18-20)'!J17/'SECGT10 Sales by Year (18-20)'!J$62 -> 0.025240705 | K17: ='SECGT10 Sales by Year (18-20)'!K17/'SECGT10 Sales by Year (18-20)'!K$62 -> 0.024974047 | L17: ='SECGT10 Sales by Year (18-20)'!L17/'SECGT10 Sales by Year (18-20)'!L$62 -> 0.025111514 | ... P17: ='SECGT10 Sales by Year (18-20)'!P17/'SECGT10 Sales by Year (18-20)'!P$62 -> 0.024876095
A18: =+A17+1 -> 8 | B18: Lufkin | C18: =+C13 -> 2020 | D18: ='SECGT10 Sales by Year (18-20)'!D18/'SECGT10 Sales by Year (18-20)'!D63 -> 0.024181102 | E18: ='SECGT10 Sales by Year (18-20)'!E18/'SECGT10 Sales by Year (18-20)'!E63 -> 0.02466257 | F18: ='SECGT10 Sales by Year (18-20)'!F18/'SECGT10 Sales by Year (18-20)'!F63 -> 0.024439342 | G18: ='SECGT10 Sales by Year (18-20)'!G18/'SECGT10 Sales by Year (18-20)'!G63 -> 0.025156472 | H18: ='SECGT10 Sales by Year (18-20)'!H18/'SECGT10 Sales by Year (18-20)'!H63 -> 0.025595285 | I18: ='SECGT10 Sales by Year (18-20)'!I18/'SECGT10 Sales by Year (18-20)'!I63 -> 0.025804137 | J18: ='SECGT10 Sales by Year (18-20)'!J18/'SECGT10 Sales by Year (18-20)'!J63 -> 0.025217721 | K18: ='SECGT10 Sales by Year (18-20)'!K18/'SECGT10 Sales by Year (18-20)'!K63 -> 0.02504591 | ... P18: ='SECGT10 Sales by Year (18-20)'!P18/'SECGT10 Sales by Year (18-20)'!P63 -> 0.025089778
A19: =+A18+1 -> 9 | B19: Lufkin | C19: Total | D19: ='SECGT10 Sales by Year (18-20)'!D19/'SECGT10 Sales by Year (18-20)'!D64 -> 0.023953034 | E19: ='SECGT10 Sales by Year (18-20)'!E19/'SECGT10 Sales by Year (18-20)'!E64 -> 0.024662487 | F19: ='SECGT10 Sales by Year (18-20)'!F19/'SECGT10 Sales by Year (18-20)'!F64 -> 0.024329972 | G19: ='SECGT10 Sales by Year (18-20)'!G19/'SECGT10 Sales by Year (18-20)'!G64 -> 0.025018733 | H19: ='SECGT10 Sales by Year (18-20)'!H19/'SECGT10 Sales by Year (18-20)'!H64 -> 0.025282669 | I19: ='SECGT10 Sales by Year (18-20)'!I19/'SECGT10 Sales by Year (18-20)'!I64 -> 0.026001271 | J19: ='SECGT10 Sales by Year (18-20)'!J19/'SECGT10 Sales by Year (18-20)'!J64 -> 0.025020173 | K19: ='SECGT10 Sales by Year (18-20)'!K19/'SECGT10 Sales by Year (18-20)'!K64 -> 0.024899329 | ... P19: ='SECGT10 Sales by Year (18-20)'!P19/'SECGT10 Sales by Year (18-20)'!P64 -> 0.02493313
A20: =+A19+1 -> 10
A21: =+A20+1 -> 11 | B21: Austin | C21: =+C16 -> 2018 | D21: ='SECGT10 Sales by Year (18-20)'!D21/'SECGT10 Sales by Year (18-20)'!D61 -> 0.024759403 | E21: ='SECGT10 Sales by Year (18-20)'!E21/'SECGT10 Sales by Year (18-20)'!E$61 -> 0.025620441 | F21: ='SECGT10 Sales by Year (18-20)'!F21/'SECGT10 Sales by Year (18-20)'!F$61 -> 0.025608787 | G21: ='SECGT10 Sales by Year (18-20)'!G21/'SECGT10 Sales by Year (18-20)'!G$61 -> 0.025941568 | H21: ='SECGT10 Sales by Year (18-20)'!H21/'SECGT10 Sales by Year (18-20)'!H$61 -> 0.026187715 | I21: ='SECGT10 Sales by Year (18-20)'!I21/'SECGT10 Sales by Year (18-20)'!I$61 -> 0.026407632 | J21: ='SECGT10 Sales by Year (18-20)'!J21/'SECGT10 Sales by Year (18-20)'!J$61 -> 0.024972912 | K21: ='SECGT10 Sales by Year (18-20)'!K21/'SECGT10 Sales by Year (18-20)'!K$61 -> 0.025824704 | L21: ='SECGT10 Sales by Year (18-20)'!L21/'SECGT10 Sales by Year (18-20)'!L$61 -> 0.026401178 | ... P21: ='SECGT10 Sales by Year (18-20)'!P21/'SECGT10 Sales by Year (18-20)'!P$61 -> 0.02586864
A22: =+A21+1 -> 12 | B22: Austin | C22: =+C17 -> 2019 | D22: ='SECGT10 Sales by Year (18-20)'!D22/'SECGT10 Sales by Year (18-20)'!D62 -> 0.025419948 | E22: ='SECGT10 Sales by Year (18-20)'!E22/'SECGT10 Sales by Year (18-20)'!E$62 -> 0.025695627 | F22: ='SECGT10 Sales by Year (18-20)'!F22/'SECGT10 Sales by Year (18-20)'!F$62 -> 0.025432684 | G22: ='SECGT10 Sales by Year (18-20)'!G22/'SECGT10 Sales by Year (18-20)'!G$62 -> 0.026720158 | H22: ='SECGT10 Sales by Year (18-20)'!H22/'SECGT10 Sales by Year (18-20)'!H$62 -> 0.026802755 | I22: ='SECGT10 Sales by Year (18-20)'!I22/'SECGT10 Sales by Year (18-20)'!I$62 -> 0.027723752 | J22: ='SECGT10 Sales by Year (18-20)'!J22/'SECGT10 Sales by Year (18-20)'!J$62 -> 0.026453606 | K22: ='SECGT10 Sales by Year (18-20)'!K22/'SECGT10 Sales by Year (18-20)'!K$62 -> 0.026491278 | L22: ='SECGT10 Sales by Year (18-20)'!L22/'SECGT10 Sales by Year (18-20)'!L$62 -> 0.026844409 | ... P22: ='SECGT10 Sales by Year (18-20)'!P22/'SECGT10 Sales by Year (18-20)'!P$62 -> 0.026536189
A23: =+A22+1 -> 13 | B23: Austin | C23: =+C18 -> 2020 | D23: ='SECGT10 Sales by Year (18-20)'!D23/'SECGT10 Sales by Year (18-20)'!D63 -> 0.025894289 | E23: ='SECGT10 Sales by Year (18-20)'!E23/'SECGT10 Sales by Year (18-20)'!E63 -> 0.026102179 | F23: ='SECGT10 Sales by Year (18-20)'!F23/'SECGT10 Sales by Year (18-20)'!F63 -> 0.026976643 | G23: ='SECGT10 Sales by Year (18-20)'!G23/'SECGT10 Sales by Year (18-20)'!G63 -> 0.026618546 | H23: ='SECGT10 Sales by Year (18-20)'!H23/'SECGT10 Sales by Year (18-20)'!H63 -> 0.02746532 | I23: ='SECGT10 Sales by Year (18-20)'!I23/'SECGT10 Sales by Year (18-20)'!I63 -> 0.027920934 | J23: ='SECGT10 Sales by Year (18-20)'!J23/'SECGT10 Sales by Year (18-20)'!J63 -> 0.027597935 | K23: ='SECGT10 Sales by Year (18-20)'!K23/'SECGT10 Sales by Year (18-20)'!K63 -> 0.026923392 | ... P23: ='SECGT10 Sales by Year (18-20)'!P23/'SECGT10 Sales by Year (18-20)'!P63 -> 0.02742282
A24: =+A23+1 -> 14 | B24: Austin | C24: Total | D24: ='SECGT10 Sales by Year (18-20)'!D24/'SECGT10 Sales by Year (18-20)'!D64 -> 0.025337905 | E24: ='SECGT10 Sales by Year (18-20)'!E24/'SECGT10 Sales by Year (18-20)'!E64 -> 0.025804772 | F24: ='SECGT10 Sales by Year (18-20)'!F24/'SECGT10 Sales by Year (18-20)'!F64 -> 0.02599581 | G24: ='SECGT10 Sales by Year (18-20)'!G24/'SECGT10 Sales by Year (18-20)'!G64 -> 0.026417204 | H24: ='SECGT10 Sales by Year (18-20)'!H24/'SECGT10 Sales by Year (18-20)'!H64 -> 0.026791936 | I24: ='SECGT10 Sales by Year (18-20)'!I24/'SECGT10 Sales by Year (18-20)'!I64 -> 0.027309184 | J24: ='SECGT10 Sales by Year (18-20)'!J24/'SECGT10 Sales by Year (18-20)'!J64 -> 0.026286856 | K24: ='SECGT10 Sales by Year (18-20)'!K24/'SECGT10 Sales by Year (18-20)'!K64 -> 0.026398516 | ... P24: ='SECGT10 Sales by Year (18-20)'!P24/'SECGT10 Sales by Year (18-20)'!P64 -> 0.026588223
A25: =+A24+1 -> 15
A26: =+A25+1 -> 16 | B26: Killeen | C26: =+C21 -> 2018 | D26: ='SECGT10 Sales by Year (18-20)'!D26/'SECGT10 Sales by Year (18-20)'!D61 -> 0.026258854 | E26: ='SECGT10 Sales by Year (18-20)'!E26/'SECGT10 Sales by Year (18-20)'!E$61 -> 0.026822359 | F26: ='SECGT10 Sales by Year (18-20)'!F26/'SECGT10 Sales by Year (18-20)'!F$61 -> 0.025558414 | G26: ='SECGT10 Sales by Year (18-20)'!G26/'SECGT10 Sales by Year (18-20)'!G$61 -> 0.026240203 | H26: ='SECGT10 Sales by Year (18-20)'!H26/'SECGT10 Sales by Year (18-20)'!H$61 -> 0.026643223 | I26: ='SECGT10 Sales by Year (18-20)'!I26/'SECGT10 Sales by Year (18-20)'!I$61 -> 0.027013217 | J26: ='SECGT10 Sales by Year (18-20)'!J26/'SECGT10 Sales by Year (18-20)'!J$61 -> 0.026429989 | K26: ='SECGT10 Sales by Year (18-20)'!K26/'SECGT10 Sales by Year (18-20)'!K$61 -> 0.027043847 | L26: ='SECGT10 Sales by Year (18-20)'!L26/'SECGT10 Sales by Year (18-20)'!L$61 -> 0.027291431 | ... P26: ='SECGT10 Sales by Year (18-20)'!P26/'SECGT10 Sales by Year (18-20)'!P$61 -> 0.026532891
A27: =+A26+1 -> 17 | B27: Killeen | C27: =+C22 -> 2019 | D27: ='SECGT10 Sales by Year (18-20)'!D27/'SECGT10 Sales by Year (18-20)'!D62 -> 0.025800482 | E27: ='SECGT10 Sales by Year (18-20)'!E27/'SECGT10 Sales by Year (18-20)'!E$62 -> 0.025610398 | F27: ='SECGT10 Sales by Year (18-20)'!F27/'SECGT10 Sales by Year (18-20)'!F$62 -> 0.026077432 | G27: ='SECGT10 Sales by Year (18-20)'!G27/'SECGT10 Sales by Year (18-20)'!G$62 -> 0.025855499 | H27: ='SECGT10 Sales by Year (18-20)'!H27/'SECGT10 Sales by Year (18-20)'!H$62 -> 0.026343626 | I27: ='SECGT10 Sales by Year (18-20)'!I27/'SECGT10 Sales by Year (18-20)'!I$62 -> 0.026879357 | J27: ='SECGT10 Sales by Year (18-20)'!J27/'SECGT10 Sales by Year (18-20)'!J$62 -> 0.026487073 | K27: ='SECGT10 Sales by Year (18-20)'!K27/'SECGT10 Sales by Year (18-20)'!K$62 -> 0.026194246 | L27: ='SECGT10 Sales by Year (18-20)'!L27/'SECGT10 Sales by Year (18-20)'!L$62 -> 0.02703649 | ... P27: ='SECGT10 Sales by Year (18-20)'!P27/'SECGT10 Sales by Year (18-20)'!P$62 -> 0.026507236
A28: =+A27+1 -> 18 | B28: Killeen | C28: =+C23 -> 2020 | D28: ='SECGT10 Sales by Year (18-20)'!D28/'SECGT10 Sales by Year (18-20)'!D63 -> 0.02608083 | E28: ='SECGT10 Sales by Year (18-20)'!E28/'SECGT10 Sales by Year (18-20)'!E63 -> 0.026452445 | F28: ='SECGT10 Sales by Year (18-20)'!F28/'SECGT10 Sales by Year (18-20)'!F63 -> 0.027029698 | G28: ='SECGT10 Sales by Year (18-20)'!G28/'SECGT10 Sales by Year (18-20)'!G63 -> 0.026334573 | H28: ='SECGT10 Sales by Year (18-20)'!H28/'SECGT10 Sales by Year (18-20)'!H63 -> 0.02636793 | I28: ='SECGT10 Sales by Year (18-20)'!I28/'SECGT10 Sales by Year (18-20)'!I63 -> 0.027725198 | J28: ='SECGT10 Sales by Year (18-20)'!J28/'SECGT10 Sales by Year (18-20)'!J63 -> 0.027816077 | K28: ='SECGT10 Sales by Year (18-20)'!K28/'SECGT10 Sales by Year (18-20)'!K63 -> 0.02748834 | ... P28: ='SECGT10 Sales by Year (18-20)'!P28/'SECGT10 Sales by Year (18-20)'!P63 -> 0.027306275
A29: =+A28+1 -> 19 | B29: Killeen | C29: Total | D29: ='SECGT10 Sales by Year (18-20)'!D29/'SECGT10 Sales by Year (18-20)'!D64 -> 0.026053194 | E29: ='SECGT10 Sales by Year (18-20)'!E29/'SECGT10 Sales by Year (18-20)'!E64 -> 0.026280249 | F29: ='SECGT10 Sales by Year (18-20)'!F29/'SECGT10 Sales by Year (18-20)'!F64 -> 0.02621685 | G29: ='SECGT10 Sales by Year (18-20)'!G29/'SECGT10 Sales by Year (18-20)'!G64 -> 0.026140089 | H29: ='SECGT10 Sales by Year (18-20)'!H29/'SECGT10 Sales by Year (18-20)'!H64 -> 0.026454499 | I29: ='SECGT10 Sales by Year (18-20)'!I29/'SECGT10 Sales by Year (18-20)'!I64 -> 0.027186127 | J29: ='SECGT10 Sales by Year (18-20)'!J29/'SECGT10 Sales by Year (18-20)'!J64 -> 0.02689005 | K29: ='SECGT10 Sales by Year (18-20)'!K29/'SECGT10 Sales by Year (18-20)'!K64 -> 0.026900894 | ... P29: ='SECGT10 Sales by Year (18-20)'!P29/'SECGT10 Sales by Year (18-20)'!P64 -> 0.026768723
A30: =+A29+1 -> 20
A31: =+A30+1 -> 21 | B31: Longview | C31: =+C26 -> 2018 | D31: ='SECGT10 Sales by Year (18-20)'!D31/'SECGT10 Sales by Year (18-20)'!D61 -> 0.030270107 | E31: ='SECGT10 Sales by Year (18-20)'!E31/'SECGT10 Sales by Year (18-20)'!E$61 -> 0.03132244 | F31: ='SECGT10 Sales by Year (18-20)'!F31/'SECGT10 Sales by Year (18-20)'!F$61 -> 0.03051576 | G31: ='SECGT10 Sales by Year (18-20)'!G31/'SECGT10 Sales by Year (18-20)'!G$61 -> 0.030685661 | H31: ='SECGT10 Sales by Year (18-20)'!H31/'SECGT10 Sales by Year (18-20)'!H$61 -> 0.030955841 | I31: ='SECGT10 Sales by Year (18-20)'!I31/'SECGT10 Sales by Year (18-20)'!I$61 -> 0.031551428 | J31: ='SECGT10 Sales by Year (18-20)'!J31/'SECGT10 Sales by Year (18-20)'!J$61 -> 0.031532291 | K31: ='SECGT10 Sales by Year (18-20)'!K31/'SECGT10 Sales by Year (18-20)'!K$61 -> 0.031533953 | L31: ='SECGT10 Sales by Year (18-20)'!L31/'SECGT10 Sales by Year (18-20)'!L$61 -> 0.031729915 | ... P31: ='SECGT10 Sales by Year (18-20)'!P31/'SECGT10 Sales by Year (18-20)'!P$61 -> 0.03118652
A32: =+A31+1 -> 22 | B32: Longview | C32: =+C27 -> 2019 | D32: ='SECGT10 Sales by Year (18-20)'!D32/'SECGT10 Sales by Year (18-20)'!D62 -> 0.030195324 | E32: ='SECGT10 Sales by Year (18-20)'!E32/'SECGT10 Sales by Year (18-20)'!E$62 -> 0.030808807 | F32: ='SECGT10 Sales by Year (18-20)'!F32/'SECGT10 Sales by Year (18-20)'!F$62 -> 0.030363644 | G32: ='SECGT10 Sales by Year (18-20)'!G32/'SECGT10 Sales by Year (18-20)'!G$62 -> 0.030561451 | H32: ='SECGT10 Sales by Year (18-20)'!H32/'SECGT10 Sales by Year (18-20)'!H$62 -> 0.031164639 | I32: ='SECGT10 Sales by Year (18-20)'!I32/'SECGT10 Sales by Year (18-20)'!I$62 -> 0.031510065 | J32: ='SECGT10 Sales by Year (18-20)'!J32/'SECGT10 Sales by Year (18-20)'!J$62 -> 0.031233181 | K32: ='SECGT10 Sales by Year (18-20)'!K32/'SECGT10 Sales by Year (18-20)'!K$62 -> 0.030890538 | L32: ='SECGT10 Sales by Year (18-20)'!L32/'SECGT10 Sales by Year (18-20)'!L$62 -> 0.031518727 | ... P32: ='SECGT10 Sales by Year (18-20)'!P32/'SECGT10 Sales by Year (18-20)'!P$62 -> 0.030895651
A33: =+A32+1 -> 23 | B33: Longview | C33: =+C28 -> 2020 | D33: ='SECGT10 Sales by Year (18-20)'!D33/'SECGT10 Sales by Year (18-20)'!D63 -> 0.030382267 | E33: ='SECGT10 Sales by Year (18-20)'!E33/'SECGT10 Sales by Year (18-20)'!E63 -> 0.030190794 | F33: ='SECGT10 Sales by Year (18-20)'!F33/'SECGT10 Sales by Year (18-20)'!F63 -> 0.030411858 | G33: ='SECGT10 Sales by Year (18-20)'!G33/'SECGT10 Sales by Year (18-20)'!G63 -> 0.03024861 | H33: ='SECGT10 Sales by Year (18-20)'!H33/'SECGT10 Sales by Year (18-20)'!H63 -> 0.031382566 | I33: ='SECGT10 Sales by Year (18-20)'!I33/'SECGT10 Sales by Year (18-20)'!I63 -> 0.031556233 | J33: ='SECGT10 Sales by Year (18-20)'!J33/'SECGT10 Sales by Year (18-20)'!J63 -> 0.031871882 | K33: ='SECGT10 Sales by Year (18-20)'!K33/'SECGT10 Sales by Year (18-20)'!K63 -> 0.031671595 | ... P33: ='SECGT10 Sales by Year (18-20)'!P33/'SECGT10 Sales by Year (18-20)'!P63 -> 0.031107505
A34: =+A33+1 -> 24 | B34: Longview | C34: Total | D34: ='SECGT10 Sales by Year (18-20)'!D34/'SECGT10 Sales by Year (18-20)'!D64 -> 0.03028191 | E34: ='SECGT10 Sales by Year (18-20)'!E34/'SECGT10 Sales by Year (18-20)'!E64 -> 0.030772472 | F34: ='SECGT10 Sales by Year (18-20)'!F34/'SECGT10 Sales by Year (18-20)'!F64 -> 0.030429795 | G34: ='SECGT10 Sales by Year (18-20)'!G34/'SECGT10 Sales by Year (18-20)'!G64 -> 0.03050628 | H34: ='SECGT10 Sales by Year (18-20)'!H34/'SECGT10 Sales by Year (18-20)'!H64 -> 0.031158835 | I34: ='SECGT10 Sales by Year (18-20)'!I34/'SECGT10 Sales by Year (18-20)'!I64 -> 0.031539096 | J34: ='SECGT10 Sales by Year (18-20)'!J34/'SECGT10 Sales by Year (18-20)'!J64 -> 0.031544031 | K34: ='SECGT10 Sales by Year (18-20)'!K34/'SECGT10 Sales by Year (18-20)'!K64 -> 0.031362229 | ... P34: ='SECGT10 Sales by Year (18-20)'!P34/'SECGT10 Sales by Year (18-20)'!P64 -> 0.031062164
A35: =+A34+1 -> 25
A36: =+A35+1 -> 26 | B36: Waco | C36: =+C31 -> 2018 | D36: ='SECGT10 Sales by Year (18-20)'!D36/'SECGT10 Sales by Year (18-20)'!D61 -> 0.031784388 | E36: ='SECGT10 Sales by Year (18-20)'!E36/'SECGT10 Sales by Year (18-20)'!E$61 -> 0.033675021 | F36: ='SECGT10 Sales by Year (18-20)'!F36/'SECGT10 Sales by Year (18-20)'!F$61 -> 0.033119793 | G36: ='SECGT10 Sales by Year (18-20)'!G36/'SECGT10 Sales by Year (18-20)'!G$61 -> 0.03288616 | H36: ='SECGT10 Sales by Year (18-20)'!H36/'SECGT10 Sales by Year (18-20)'!H$61 -> 0.032861996 | I36: ='SECGT10 Sales by Year (18-20)'!I36/'SECGT10 Sales by Year (18-20)'!I$61 -> 0.033824728 | J36: ='SECGT10 Sales by Year (18-20)'!J36/'SECGT10 Sales by Year (18-20)'!J$61 -> 0.033772557 | K36: ='SECGT10 Sales by Year (18-20)'!K36/'SECGT10 Sales by Year (18-20)'!K$61 -> 0.034072088 | L36: ='SECGT10 Sales by Year (18-20)'!L36/'SECGT10 Sales by Year (18-20)'!L$61 -> 0.034787787 | ... P36: ='SECGT10 Sales by Year (18-20)'!P36/'SECGT10 Sales by Year (18-20)'!P$61 -> 0.033581267
A37: =+A36+1 -> 27 | B37: Waco | C37: =+C32 -> 2019 | D37: ='SECGT10 Sales by Year (18-20)'!D37/'SECGT10 Sales by Year (18-20)'!D62 -> 0.03249336 | E37: ='SECGT10 Sales by Year (18-20)'!E37/'SECGT10 Sales by Year (18-20)'!E$62 -> 0.032300206 | F37: ='SECGT10 Sales by Year (18-20)'!F37/'SECGT10 Sales by Year (18-20)'!F$62 -> 0.032699046 | G37: ='SECGT10 Sales by Year (18-20)'!G37/'SECGT10 Sales by Year (18-20)'!G$62 -> 0.032758483 | H37: ='SECGT10 Sales by Year (18-20)'!H37/'SECGT10 Sales by Year (18-20)'!H$62 -> 0.033275806 | I37: ='SECGT10 Sales by Year (18-20)'!I37/'SECGT10 Sales by Year (18-20)'!I$62 -> 0.033946982 | J37: ='SECGT10 Sales by Year (18-20)'!J37/'SECGT10 Sales by Year (18-20)'!J$62 -> 0.033044041 | K37: ='SECGT10 Sales by Year (18-20)'!K37/'SECGT10 Sales by Year (18-20)'!K$62 -> 0.033332301 | L37: ='SECGT10 Sales by Year (18-20)'!L37/'SECGT10 Sales by Year (18-20)'!L$62 -> 0.034568923 | ... P37: ='SECGT10 Sales by Year (18-20)'!P37/'SECGT10 Sales by Year (18-20)'!P$62 -> 0.033187156
A38: =+A37+1 -> 28 | B38: Waco | C38: =+C33 -> 2020 | D38: ='SECGT10 Sales by Year (18-20)'!D38/'SECGT10 Sales by Year (18-20)'!D63 -> 0.031781533 | E38: ='SECGT10 Sales by Year (18-20)'!E38/'SECGT10 Sales by Year (18-20)'!E63 -> 0.031685436 | F38: ='SECGT10 Sales by Year (18-20)'!F38/'SECGT10 Sales by Year (18-20)'!F63 -> 0.032668327 | G38: ='SECGT10 Sales by Year (18-20)'!G38/'SECGT10 Sales by Year (18-20)'!G63 -> 0.032365034 | H38: ='SECGT10 Sales by Year (18-20)'!H38/'SECGT10 Sales by Year (18-20)'!H63 -> 0.032958589 | I38: ='SECGT10 Sales by Year (18-20)'!I38/'SECGT10 Sales by Year (18-20)'!I63 -> 0.0337344 | J38: ='SECGT10 Sales by Year (18-20)'!J38/'SECGT10 Sales by Year (18-20)'!J63 -> 0.033408057 | K38: ='SECGT10 Sales by Year (18-20)'!K38/'SECGT10 Sales by Year (18-20)'!K63 -> 0.03400715 | ... P38: ='SECGT10 Sales by Year (18-20)'!P38/'SECGT10 Sales by Year (18-20)'!P63 -> 0.03309108
A39: =+A38+1 -> 29 | B39: Waco | C39: Total | D39: ='SECGT10 Sales by Year (18-20)'!D39/'SECGT10 Sales by Year (18-20)'!D64 -> 0.032013123 | E39: ='SECGT10 Sales by Year (18-20)'!E39/'SECGT10 Sales by Year (18-20)'!E64 -> 0.032544375 | F39: ='SECGT10 Sales by Year (18-20)'!F39/'SECGT10 Sales by Year (18-20)'!F64 -> 0.032828373 | G39: ='SECGT10 Sales by Year (18-20)'!G39/'SECGT10 Sales by Year (18-20)'!G64 -> 0.032679163 | H39: ='SECGT10 Sales by Year (18-20)'!H39/'SECGT10 Sales by Year (18-20)'!H64 -> 0.033036355 | I39: ='SECGT10 Sales by Year (18-20)'!I39/'SECGT10 Sales by Year (18-20)'!I64 -> 0.033837914 | J39: ='SECGT10 Sales by Year (18-20)'!J39/'SECGT10 Sales by Year (18-20)'!J64 -> 0.033421467 | K39: ='SECGT10 Sales by Year (18-20)'!K39/'SECGT10 Sales by Year (18-20)'!K64 -> 0.033803454 | ... P39: ='SECGT10 Sales by Year (18-20)'!P39/'SECGT10 Sales by Year (18-20)'!P64 -> 0.033291602
A40: =+A39+1 -> 30
A41: =+A40+1 -> 31 | B41: Abilene | C41: =+C36 -> 2018 | D41: ='SECGT10 Sales by Year (18-20)'!D41/'SECGT10 Sales by Year (18-20)'!D61 -> 0.012477414 | E41: ='SECGT10 Sales by Year (18-20)'!E41/'SECGT10 Sales by Year (18-20)'!E$61 -> 0.012498043 | F41: ='SECGT10 Sales by Year (18-20)'!F41/'SECGT10 Sales by Year (18-20)'!F$61 -> 0.01156789 | G41: ='SECGT10 Sales by Year (18-20)'!G41/'SECGT10 Sales by Year (18-20)'!G$61 -> 0.011704398 | H41: ='SECGT10 Sales by Year (18-20)'!H41/'SECGT10 Sales by Year (18-20)'!H$61 -> 0.011532998 | I41: ='SECGT10 Sales by Year (18-20)'!I41/'SECGT10 Sales by Year (18-20)'!I$61 -> 0.011704817 | J41: ='SECGT10 Sales by Year (18-20)'!J41/'SECGT10 Sales by Year (18-20)'!J$61 -> 0.012101306 | K41: ='SECGT10 Sales by Year (18-20)'!K41/'SECGT10 Sales by Year (18-20)'!K$61 -> 0.011730493 | L41: ='SECGT10 Sales by Year (18-20)'!L41/'SECGT10 Sales by Year (18-20)'!L$61 -> 0.011712971 | ... P41: ='SECGT10 Sales by Year (18-20)'!P41/'SECGT10 Sales by Year (18-20)'!P$61 -> 0.011810698
A42: =+A41+1 -> 32 | B42: Abilene | C42: =+C37 -> 2019 | D42: ='SECGT10 Sales by Year (18-20)'!D42/'SECGT10 Sales by Year (18-20)'!D62 -> 0.012181416 | E42: ='SECGT10 Sales by Year (18-20)'!E42/'SECGT10 Sales by Year (18-20)'!E$62 -> 0.011911705 | F42: ='SECGT10 Sales by Year (18-20)'!F42/'SECGT10 Sales by Year (18-20)'!F$62 -> 0.011452179 | G42: ='SECGT10 Sales by Year (18-20)'!G42/'SECGT10 Sales by Year (18-20)'!G$62 -> 0.01143529 | H42: ='SECGT10 Sales by Year (18-20)'!H42/'SECGT10 Sales by Year (18-20)'!H$62 -> 0.010879611 | I42: ='SECGT10 Sales by Year (18-20)'!I42/'SECGT10 Sales by Year (18-20)'!I$62 -> 0.010736197 | J42: ='SECGT10 Sales by Year (18-20)'!J42/'SECGT10 Sales by Year (18-20)'!J$62 -> 0.011258812 | K42: ='SECGT10 Sales by Year (18-20)'!K42/'SECGT10 Sales by Year (18-20)'!K$62 -> 0.01219366 | L42: ='SECGT10 Sales by Year (18-20)'!L42/'SECGT10 Sales by Year (18-20)'!L$62 -> 0.01186676 | ... P42: ='SECGT10 Sales by Year (18-20)'!P42/'SECGT10 Sales by Year (18-20)'!P$62 -> 0.011483703
...

Sheet SECGT10 Sales by Year (18-20)
B1: PUC DOCKET NO.
B2: ONCOR ELECTRIC DELIVERY COMPANY
B3: WEATHER WEIGHTS
B4: =+'SECGT10 Seasonal Weights'!B4:P4 -> FOR THE TEST YEAR ENDING DECEMBER 31, 2021
B6: SPONSOR: D. E. NELSON
B8: SECONDARY SERVICEGREATER THAN 10 KW SALES BY YEAR
A9: Line | B9: (a) | C9: (b) | D9: (c) | E9: (d) | F9: (e) | G9: (f) | H9: (g) | I9: (h) | J9: (i) | K9: (j) | L9: (k) | M9: (l) | N9: (m) | O9: (n) | P9: (o)
A10: No. | B10: Weather Station | C10: Year | D10: 36892 | E10: 36923 | F10: 36951 | G10: 36982 | H10: 37012 | I10: 37043 | J10: 37073 | K10: 37104 | L10: 37135 | M10: 37165 | N10: 37196 | O10: 37226 | P10: Annual
A11: 1 | B11: Dallas-Fort Worth | C11: =+'SECGT10 Weights by Year (18-20)'!C11 -> 2018 | D11: 2884611.1 | E11: 2512393.6 | F11: 2505538.1 | G11: 2540384.9 | H11: 2597710 | I11: 3210130 | J11: 3592280.1 | K11: 3592769.2 | L11: 3482194.6 | M11: 2991198.3 | N11: 2511123.6 | O11: 2572145.8 | P11: =SUM(D11:O11) -> 34992479
A12: =+A11+1 -> 2 | B12: Dallas-Fort Worth | C12: =+'SECGT10 Weights by Year (18-20)'!C12 -> 2019 | D12: 2585591.9 | E12: 2693623.4 | F12: 2570853.5 | G12: 2479519.7 | H12: 2640178 | I12: 2962184.2 | J12: 3221605.7 | K12: 3467745.1 | L12: 3686692.4 | M12: 3329873.3 | N12: 2626178.1 | O12: 2565568.2 | P12: =SUM(D12:O12) -> 34829613
A13: =+A12+1 -> 3 | B13: Dallas-Fort Worth | C13: =+'SECGT10 Weights by Year (18-20)'!C13 -> 2020 | D13: 2555222.5 | E13: 2552360.2 | F13: 2439121.6 | G13: 2283607.6 | H13: 2278958 | I13: 2708960.3 | J13: 3166836.7 | K13: 3290383.3 | L13: 3180956.3 | M13: 2719445 | N13: 2546853.6 | O13: 2374761.8 | P13: =SUM(D13:O13) -> 32097467
A14: =+A13+1 -> 4 | B14: Dallas-Fort Worth | C14: Total | D14: =SUM(D11:D13) -> 8025425.4 | E14: =SUM(E11:E13) -> 7758377.2 | F14: =SUM(F11:F13) -> 7515513.2 | G14: =SUM(G11:G13) -> 7303512.2 | H14: =SUM(H11:H13) -> 7516846 | I14: =SUM(I11:I13) -> 8881274.5 | J14: =SUM(J11:J13) -> 9980722.5 | K14: =SUM(K11:K13) -> 10350898 | ... O14: =SUM(O11:O13) -> 7512475.8 | P14: =SUM(D14:O14) -> 1.0191956e+08
A15: =+A14+1 -> 5
A16: =+A15+1 -> 6 | B16: Lufkin | C16: =+C11 -> 2018 | D16: 91247.362 | E16: 84564.034 | F16: 81529.656 | G16: 85465.482 | H16: 87885.51 | I16: 110040.07 | J16: 118940.47 | K16: 119304.38 | L16: 119513.81 | M16: 101196.06 | N16: 84275.479 | O16: 84574.026 | P16: =SUM(D16:O16) -> 1168536.3
A17: =+A16+1 -> 7 | B17: Lufkin | C17: =+C12 -> 2019 | D17: 82989.29 | E17: 88712.364 | F17: 84201.068 | G17: 82674.952 | H17: 90023.773 | I17: 107385.36 | J17: 109465.85 | K17: 116901.36 | L17: 125051.1 | M17: 110027.98 | N17: 87651.418 | O17: 83196.435 | P17: =SUM(D17:O17) -> 1168280.9
A18: =+A17+1 -> 8 | B18: Lufkin | C18: =+C13 -> 2020 | D18: 83612.238 | E18: 84757.654 | F18: 81045.339 | G18: 77779.265 | H18: 79203.498 | I18: 94639.664 | J18: 108052.84 | K18: 111578.68 | L18: 111121.33 | M18: 94410.836 | N18: 86761.689 | O18: 77918.861 | P18: =SUM(D18:O18) -> 1090881.9
A19: =+A18+1 -> 9 | B19: Lufkin | C19: Total | D19: =SUM(D16:D18) -> 257848.89 | E19: =SUM(E16:E18) -> 258034.05 | F19: =SUM(F16:F18) -> 246776.06 | G19: =SUM(G16:G18) -> 245919.7 | H19: =SUM(H16:H18) -> 257112.78 | I19: =SUM(I16:I18) -> 312065.09 | J19: =SUM(J16:J18) -> 336459.16 | K19: =SUM(K16:K18) -> 347784.42 | ... O19: =SUM(O16:O18) -> 245689.32 | P19: =SUM(D19:O19) -> 3427699.2
A20: =+A19+1 -> 10
A21: =+A20+1 -> 11 | B21: Austin | C21: =+C16 -> 2018 | D21: 94582.533 | E21: 86979.912 | F21: 86040.174 | G21: 88750.68 | H21: 91983.351 | I21: 114345.01 | J21: 120515.27 | K21: 124778.32 | L21: 124109.13 | M21: 105370.05 | N21: 89583.401 | O21: 89630.3 | P21: =SUM(D21:O21) -> 1216668.1
A22: =+A21+1 -> 12 | B22: Austin | C22: =+C17 -> 2019 | D22: 88638.169 | E22: 93300.274 | F22: 88172.796 | G22: 88615.45 | H22: 95487.713 | I22: 111014.27 | J22: 114726.06 | K22: 124003.39 | L22: 133680.62 | M22: 121241.61 | N22: 94775.503 | O22: 92589.796 | P22: =SUM(D22:O22) -> 1246245.6
A23: =+A22+1 -> 13 | B23: Austin | C23: =+C18 -> 2020 | D23: 89536.013 | E23: 89705.146 | F23: 89459.493 | G23: 82299.734 | H23: 84990.242 | I23: 102403.26 | J23: 118251.57 | K23: 119942.79 | L23: 121700.58 | M23: 104138.54 | N23: 99371.684 | O23: 90521.444 | P23: =SUM(D23:O23) -> 1192320.5
A24: =+A23+1 -> 14 | B24: Austin | C24: Total | D24: =SUM(D21:D23) -> 272756.71 | E24: =SUM(E21:E23) -> 269985.33 | F24: =SUM(F21:F23) -> 263672.46 | G24: =SUM(G21:G23) -> 259665.86 | H24: =SUM(H21:H23) -> 272461.31 | I24: =SUM(I21:I23) -> 327762.55 | J24: =SUM(J21:J23) -> 353492.89 | K24: =SUM(K21:K23) -> 368724.5 | ... O24: =SUM(O21:O23) -> 272741.54 | P24: =SUM(D24:O24) -> 3655234.3
A25: =+A24+1 -> 15
A26: =+A25+1 -> 16 | B26: Killeen | C26: =+C21 -> 2018 | D26: 100310.53 | E26: 91060.354 | F26: 85870.932 | G26: 89772.364 | H26: 93583.306 | I26: 116967.19 | J26: 127546.88 | K26: 130668.91 | L26: 128294.11 | M26: 107085.08 | N26: 87891.045 | O26: 88858.848 | P26: =SUM(D26:O26) -> 1247909.6
A27: =+A26+1 -> 17 | B27: Killeen | C27: =+C22 -> 2019 | D27: 89965.073 | E27: 92990.809 | F27: 90408.08 | G27: 85747.871 | H27: 93852.018 | I27: 107633.06 | J27: 114871.2 | K27: 122613.01 | L27: 134637.15 | M27: 122820.1 | N27: 96347.844 | O27: 92999.661 | P27: =SUM(D27:O27) -> 1244885.9
A28: =+A27+1 -> 18 | B28: Killeen | C28: =+C23 -> 2020 | D28: 90181.027 | E28: 90908.904 | F28: 89635.434 | G28: 81421.742 | H28: 81594.415 | I28: 101685.38 | J28: 119186.27 | K28: 122459.61 | L28: 124142.78 | M28: 101733.6 | N28: 95342.497 | O28: 88961.582 | P28: =SUM(D28:O28) -> 1187253.2
A29: =+A28+1 -> 19 | B29: Killeen | C29: Total | D29: =SUM(D26:D28) -> 280456.63 | E29: =SUM(E26:E28) -> 274960.07 | F29: =SUM(F26:F28) -> 265914.45 | G29: =SUM(G26:G28) -> 256941.98 | H29: =SUM(H26:H28) -> 269029.74 | I29: =SUM(I26:I28) -> 326285.64 | J29: =SUM(J26:J28) -> 361604.35 | K29: =SUM(K26:K28) -> 375741.53 | ... O29: =SUM(O26:O28) -> 270820.09 | P29: =SUM(D29:O29) -> 3680048.7
A30: =+A29+1 -> 20
A31: =+A30+1 -> 21 | B31: Longview | C31: =+C26 -> 2018 | D31: 115633.78 | E31: 106337.87 | F31: 102526.58 | G31: 104981.06 | H31: 108731.21 | I31: 136617.64 | J31: 152169.77 | K31: 152363.95 | L31: 149158.95 | M31: 126688.76 | N31: 104985.39 | O31: 106586.62 | P31: =SUM(D31:O31) -> 1466781.6
A32: =+A31+1 -> 22 | B32: Longview | C32: =+C27 -> 2019 | D32: 105289.68 | E32: 111866.12 | F32: 105267.99 | G32: 101354.82 | H32: 111027.4 | I32: 126175.82 | J32: 135454.49 | K32: 144595.94 | L32: 156957.94 | M32: 139518.81 | N32: 108255.58 | O32: 105218.83 | P32: =SUM(D32:O32) -> 1450983.4
A33: =+A32+1 -> 23 | B33: Longview | C33: =+C28 -> 2020 | D33: 105054.32 | E33: 103756.46 | F33: 100851.29 | G33: 93523.236 | H33: 97111.991 | I33: 115736.15 | J33: 136564.57 | K33: 141095.87 | L33: 137784.92 | M33: 116299.68 | N33: 106427.78 | O33: 98321.178 | P33: =SUM(D33:O33) -> 1352527.5
A34: =+A33+1 -> 24 | B34: Longview | C34: Total | D34: =SUM(D31:D33) -> 325977.79 | E34: =SUM(E31:E33) -> 321960.45 | F34: =SUM(F31:F33) -> 308645.86 | G34: =SUM(G31:G33) -> 299859.11 | H34: =SUM(H31:H33) -> 316870.6 | I34: =SUM(I31:I33) -> 378529.6 | J34: =SUM(J31:J33) -> 424188.83 | K34: =SUM(K31:K33) -> 438055.77 | ... O34: =SUM(O31:O33) -> 310126.63 | P34: =SUM(D34:O34) -> 4270292.5
A35: =+A34+1 -> 25
A36: =+A35+1 -> 26 | B36: Waco | C36: =+C31 -> 2018 | D36: 121418.43 | E36: 114324.74 | F36: 111275.59 | G36: 112509.35 | H36: 115426.51 | I36: 146461.03 | J36: 162980.94 | K36: 164627.56 | L36: 163533.68 | M36: 139192.81 | N36: 113912.57 | O36: 113749.45 | P36: =SUM(D36:O36) -> 1579412.7
A37: =+A36+1 -> 27 | B37: Waco | C37: =+C32 -> 2019 | D37: 113302.82 | E37: 117281.36 | F37: 113364.61 | G37: 108641.11 | H37: 118548.66 | I37: 135933.97 | J37: 143307.97 | K37: 156025.62 | L37: 172147.4 | M37: 149432.45 | N37: 118375.29 | O37: 112240.4 | P37: =SUM(D37:O37) -> 1558601.7
A38: =+A37+1 -> 28 | B38: Waco | C38: =+C33 -> 2020 | D38: 109892.64 | E38: 108893.08 | F38: 108334.16 | G38: 100066.84 | H38: 101988.92 | I38: 123724.83 | J38: 143146.77 | K38: 151500.69 | L38: 148544.88 | M38: 124593.17 | N38: 115339.06 | O38: 102746.52 | P38: =SUM(D38:O38) -> 1438771.5
A39: =+A38+1 -> 29 | B39: Waco | C39: Total | D39: =SUM(D36:D38) -> 344613.9 | E39: =SUM(E36:E38) -> 340499.18 | F39: =SUM(F36:F38) -> 332974.36 | G39: =SUM(G36:G38) -> 321217.3 | H39: =SUM(H36:H38) -> 335964.09 | I39: =SUM(I36:I38) -> 406119.82 | J39: =SUM(J36:J38) -> 449435.67 | K39: =SUM(K36:K38) -> 472153.87 | ... O39: =SUM(O36:O38) -> 328736.37 | P39: =SUM(D39:O39) -> 4576785.9
A40: =+A39+1 -> 30
A41: =+A40+1 -> 31 | B41: Abilene | C41: =+C36 -> 2018 | D41: 47664.535 | E41: 42430.132 | F41: 38865.694 | G41: 40042.811 | H41: 40509.215 | I41: 50681.843 | J41: 58398.962 | K41: 56678.725 | L41: 55061.428 | M41: 44323.719 | N41: 40298.008 | O41: 40532.185 | P41: =SUM(D41:O41) -> 555487.26
A42: =+A41+1 -> 32 | B42: Abilene | C42: =+C37 -> 2019 | D42: 42476.029 | E42: 43251.146 | F42: 39703.66 | G42: 37924.303 | H42: 38759.79 | I42: 42990.975 | J42: 48828.091 | K42: 57077.471 | L42: 59094.46 | M42: 48803.182 | N42: 39903.828 | O42: 40507.73 | P42: =SUM(D42:O42) -> 539320.67
...
