Workbook

Sheet Energy Loss Factor
E1: WP/II-H-1.3/1
E2: Page 1 of 3
C4: 2021 TEST YEAR DATA
C5: Oncor Electric Delivery Company LLC
C6: Unadjusted Test Year Load Data
C7: For the Test Year Ended December 31, 2021
C8: Sponsor: D.E. Nelson
C10: System Line Loss Calculation
C11: Energy Loss Factor Calculation
A13: Line
A14: No.
A15: (a) | C15: (b) | E15: (c) | G15: (d)
A16: 1 | C16: System Net Consumed, MWh (as Calculated page 3) | G16: ='2021 Stats'!C32 -> 1.1925813e+08
A17: 2
A18: 3 | C18: Booked Sales and Energy Losses by Voltage Level, MWh
A19: 4 | C19: (Booked Sales and Energy Losses Page 3):
A20: 5 | E20: Energy | G20: Booked
A21: 6 | E21: Losses | G21: Sales
A22: 7 | C22: Substation | E22: =('2021 Stats'!C32-'2021 Stats'!C30) -> 680634.83 | G22: ='2021 Stats'!C29 -> 6412195
A23: 8 | C23: Primary | E23: =('2021 Stats'!C28-'2021 Stats'!C26) -> 1030222.2 | G23: ='2021 Stats'!C25 -> 17209450
A24: 9 | C24: Secondary | E24: ='2021 Stats'!C24-'2021 Stats'!C18 -> 2002628.5 | G24: ='2021 Stats'!C18 -> 91923000
A25: 10 | C25: Total | E25: =SUM(E22:E24) -> 3713485.5 | G25: =SUM(G22:G24) -> 115544645
A26: 11
A27: 12 | C27: Percent Losses Calculation Procedure
A28: 13 | C28: Substation:
A29: 14 | C29: Input to Distribution Substation Transformation System, MWh | G29: =G16 -> 1.1925813e+08
A30: 15 | C30: Substation Losses, MWh | G30: =E22 -> 680634.83
A31: 16 | C31: Substation Sales, MWh | G31: =G22 -> 6412195
A32: 17 | C32: Remainder to Distribution Primary System, MWh | G32: =G29-G30-G31 -> 1.121653e+08
A33: 18 | C33: Percent Losses (Line 15/Line14) | G33: =G30/G29 -> 0.0057072404
A34: 19 | C34: Primary:
A35: 20 | C35: Input to Distribution Primary System, MWh | G35: =G32 -> 1.121653e+08
A36: 21 | C36: Primary Losses, MWh | G36: =E23 -> 1030222.2
A37: 22 | C37: Primary Sales, MWh | G37: =G23 -> 17209450
A38: 23 | C38: Remainder to Distribution Secondary System, MWh | G38: =G35-G36-G37 -> 93925629
A39: 24 | C39: Percent Losses (Line 21/Line 20) | G39: =G36/G35 -> 0.0091848564
A40: 25 | C40: Secondary:
A41: 26 | C41: Input to Distribution Secondary System, MWh | G41: =G38 -> 93925629
A42: 27 | C42: Secondary Losses, MWh | G42: =E24 -> 2002628.5
A43: 28 | C43: Secondary Sales, MWh | G43: =G41-G42 -> 91923000
...

Sheet Demand Loss Factor
E1: WP/II-H-1.3/1
E2: Page 2 of 3
C4: 2021 TEST YEAR DATA
C5: Oncor Electric Delivery Company LLC
C6: Unadjusted Test Year Load Data
C7: For the Test Year Ended December 31, 2021
C8: Sponsor: D.E. Nelson
C10: System Line Loss Calculation
C11: Demand Loss Factor Calculation
A13: Line
A14: No.
A15: (a) | C15: (b) | E15: (c) | G15: (d)
A16: 1 | C16: System Peak Demand, MW (as Calculated Page 3) | G16: ='2021 Stats'!F32 -> 23735.752
A17: 2
A18: 3 | C18: Coincident Demand and Demand Losses, MW
A19: 4 | C19: (Coincident Demands and Demand Losses Page 3):
A20: 5 | E20: Demand | G20: Coincident
A21: 6 | E21: Losses | G21: Demand
A22: 7 | C22: Substation | E22: ='2021 Stats'!F32-'2021 Stats'!F30 -> 150.23971 | G22: ='2021 Stats'!F29 -> 766.781
A23: 8 | C23: Primary | E23: ='2021 Stats'!F28-'2021 Stats'!F26 -> 309.27986 | G23: ='2021 Stats'!F25 -> 2197.9
A24: 9 | C24: Secondary | E24: ='2021 Stats'!F24-'2021 Stats'!F18 -> 364.60114 | G24: ='2021 Stats'!F18 -> 19946.95
A25: 10 | C25: Total | E25: =SUM(E22:E24) -> 824.12071 | G25: =SUM(G22:G24) -> 22911.631
A26: 11
A27: 12 | C27: Percent Losses Calculation Procedure
A28: 13 | C28: Substation:
A29: 14 | C29: Input to Distribution Substation System, MW | G29: =G16 -> 23735.752
A30: 15 | C30: Substation Losses, MW | G30: =E22 -> 150.23971
A31: 16 | C31: Substation Demand, MW | G31: =G22 -> 766.781
A32: 17 | C32: Remainder to Distribution Primary System, MW | G32: =G29-G30-G31 -> 22818.731
A33: 18 | C33: Percent Losses (Line 15/Line 14) | G33: =G30/G29 -> 0.0063296799
A34: 19 | C34: Primary:
A35: 20 | C35: Input to Distribution Primary System, MW | G35: =G32 -> 22818.731
A36: 21 | C36: Primary Losses, MW | G36: =E23 -> 309.27986
A37: 22 | C37: Primary Demand, MW | G37: =G23 -> 2197.9
A38: 23 | C38: Remainder to Distribution Secondary System, MW | G38: =G35-G36-G37 -> 20311.551
A39: 24 | C39: Percent Losses (Line 21/Line 20) | G39: =G36/G35 -> 0.013553771
A40: 25 | C40: Secondary:
A41: 26 | C41: Input to Distribution Secondary System, MW | G41: =G38 -> 20311.551
A42: 27 | C42: Secondary Losses, MW | G42: =E24 -> 364.60114
A43: 28 | C43: Secondary Demand, MW | G43: =G41-G42 -> 19946.95
...

Sheet 2021 Stats
D1: WP/II-H-1.3/1
D2: Page 3 of 3
A6: 2021 TEST YEAR DATA
A7: Oncor Electric Delivery Company LLC
A8: Unadjusted Test Year Load Data
A9: For the Test Year Ending December 31, 2021
A10: Sponsor: D.E. Nelson
A12: 2021 Analysis of System Losses
A14: Calculated Losses Using 2015 Oncor Integrated Power System Loss Analysis
C17: MWh | F17: MW
A18: Retail Sales from Service Drop | C18: 91923000 | F18: 19946.95
A19: Service Drop Factor * | C19: 1.00314 | F19: 1.00381
A20: Output from Secondary | C20: =C18*C19 -> 92211638 | F20: =F18*F19 -> 20022.948
A21: Secondary Conductor Loss Factor * | C21: 1.001 | F21: 1.00189
A22: Output from Line Transformers | C22: =C20*C21 -> 92303850 | F22: =F20*F21 -> 20060.791
A23: Line Transformer Loss Factor * | C23: 1.01757 | F23: 1.0125
A24: Input to Line Transformers | C24: =C22*C23 -> 93925629 | F24: =F22*F23 -> 20311.551
A25: Sales from Primary | C25: 17209450 | F25: 2197.9
A26: Output from Primary Lines | C26: =C24+C25 -> 1.1113508e+08 | F26: =F24+F25 -> 22509.451
A27: Primary Line Loss Factor * | C27: 1.00927 | F27: 1.01374
A28: Output from Distribution Substations | C28: =C26*C27 -> 1.121653e+08 | F28: =F26*F27 -> 22818.731
A29: Sales from Substations | C29: 6412195 | F29: 766.781
A30: Total Output from Distribution Substations | C30: =C28+C29 -> 1.185775e+08 | F30: =F28+F29 -> 23585.512
A31: Distribution Substation Loss Factor * | C31: 1.00574 | F31: 1.00637
A32: Input to Distribution Substations | C32: =C30*C31 -> 1.1925813e+08 | F32: =F30*F31 -> 23735.752
A34: Total System Losses | C34: =C32-C29-C25-C18 -> 3713485.5 | F34: =F32-F29-F25-F18 -> 824.12071
A36: NOTE:
A37: 2021 Annual Energy from company records and Demand at ERCOT's 2021 annual peak
A39: * For Loss Factors, refer to WP/II-H-1.3/2
