Workbook
Name HOURLY: [1]HOURLY!$A$1:$G$745
Name OLE_LINK2: 'SECLE10 Seasonal Weights'!$B$24
Name rngBilled: OFFSET([2]Sheet2!$A$2,0,0,[2]Sheet2!$B$1,9)
Name rngYear: OFFSET('[3]Daily Actual_August'!$A$2,0,0,'[3]Daily Actual_August'!$C$1,8)

Sheet SECLE10 Seasonal Weights
B1: PUC DOCKET NO.
B2: ONCOR ELECTRIC DELIVERY COMPANY LLC
B3: WEATHER WEIGHTS
B4: FOR THE TEST YEAR ENDING DECEMBER 31, 2021
B6: SPONSOR: D. E. NELSON
B8: SECONDARY SERVICE LESS THAN OR EQUAL TO 10 KW MONTHLY WEIGHTS
A9: Line | B9: (a) | D9: (b) | E9: (c) | F9: (d) | G9: (e) | H9: (f) | I9: (g) | J9: (h) | K9: (i) | L9: (j) | M9: (k) | N9: (l) | O9: (m) | P9: (n)
A10: No. | B10: Weather Station | D10: 36892 | E10: 36923 | F10: 36951 | G10: 36982 | H10: 37012 | I10: 37043 | J10: 37073 | K10: 37104 | L10: 37135 | M10: 37165 | N10: 37196 | O10: 37226 | P10: Annual
A11: 1 | B11: Dallas-Fort Worth | D11: =+'SECLE10 Monthly Weather Weights'!C11 -> 0.60953941 | E11: =+'SECLE10 Monthly Weather Weights'!D11 -> 0.59423142 | F11: =+'SECLE10 Monthly Weather Weights'!E11 -> 0.59932853 | G11: =+'SECLE10 Monthly Weather Weights'!F11 -> 0.60208915 | H11: =+'SECLE10 Monthly Weather Weights'!G11 -> 0.59998678 | I11: =+'SECLE10 Monthly Weather Weights'!H11 -> 0.60037932 | J11: =+'SECLE10 Monthly Weather Weights'!I11 -> 0.59108746 | K11: =+'SECLE10 Monthly Weather Weights'!J11 -> 0.5922319 | ... P11: =+'SECLE10 Monthly Weather Weights'!O11 -> 0.60037359
A12: =+A11+1 -> 2 | B12: Midland-Odessa | D12: =+'SECLE10 Monthly Weather Weights'!C12 -> 0.11458138 | E12: =+'SECLE10 Monthly Weather Weights'!D12 -> 0.13197133 | F12: =+'SECLE10 Monthly Weather Weights'!E12 -> 0.13293848 | G12: =+'SECLE10 Monthly Weather Weights'!F12 -> 0.13200134 | H12: =+'SECLE10 Monthly Weather Weights'!G12 -> 0.13229046 | I12: =+'SECLE10 Monthly Weather Weights'!H12 -> 0.1221432 | J12: =+'SECLE10 Monthly Weather Weights'!I12 -> 0.12920341 | K12: =+'SECLE10 Monthly Weather Weights'!J12 -> 0.12387508 | ... P12: =+'SECLE10 Monthly Weather Weights'!O12 -> 0.12362936
A13: =+A12+1 -> 3 | B13: Lufkin | D13: =+'SECLE10 Monthly Weather Weights'!C13 -> 0.036713347 | E13: =+'SECLE10 Monthly Weather Weights'!D13 -> 0.036716392 | F13: =+'SECLE10 Monthly Weather Weights'!E13 -> 0.034617192 | G13: =+'SECLE10 Monthly Weather Weights'!F13 -> 0.035303155 | H13: =+'SECLE10 Monthly Weather Weights'!G13 -> 0.035966962 | I13: =+'SECLE10 Monthly Weather Weights'!H13 -> 0.038726462 | J13: =+'SECLE10 Monthly Weather Weights'!I13 -> 0.038550932 | K13: =+'SECLE10 Monthly Weather Weights'!J13 -> 0.038655974 | ... P13: =+'SECLE10 Monthly Weather Weights'!O13 -> 0.03717003
A14: =+A13+1 -> 4 | B14: Abilene | D14: =+'SECLE10 Monthly Weather Weights'!C14 -> 0.029957457 | E14: =+'SECLE10 Monthly Weather Weights'!D14 -> 0.029259608 | F14: =+'SECLE10 Monthly Weather Weights'!E14 -> 0.028472731 | G14: =+'SECLE10 Monthly Weather Weights'!F14 -> 0.028638881 | H14: =+'SECLE10 Monthly Weather Weights'!G14 -> 0.029352259 | I14: =+'SECLE10 Monthly Weather Weights'!H14 -> 0.029471808 | J14: =+'SECLE10 Monthly Weather Weights'!I14 -> 0.030757833 | K14: =+'SECLE10 Monthly Weather Weights'!J14 -> 0.031116751 | ... P14: =+'SECLE10 Monthly Weather Weights'!O14 -> 0.029650474
A15: =+A14+1 -> 5 | B15: Sherman-Denison | D15: =+'SECLE10 Monthly Weather Weights'!C15 -> 0.033218802 | E15: =+'SECLE10 Monthly Weather Weights'!D15 -> 0.033547987 | F15: =+'SECLE10 Monthly Weather Weights'!E15 -> 0.032622487 | G15: =+'SECLE10 Monthly Weather Weights'!F15 -> 0.03118848 | H15: =+'SECLE10 Monthly Weather Weights'!G15 -> 0.030826125 | I15: =+'SECLE10 Monthly Weather Weights'!H15 -> 0.032127344 | J15: =+'SECLE10 Monthly Weather Weights'!I15 -> 0.033447646 | K15: =+'SECLE10 Monthly Weather Weights'!J15 -> 0.034146939 | ... P15: =+'SECLE10 Monthly Weather Weights'!O15 -> 0.032716091
A16: =+A15+1 -> 6 | B16: Killeen-Temple | D16: =+'SECLE10 Monthly Weather Weights'!C16 -> 0.033840666 | E16: =+'SECLE10 Monthly Weather Weights'!D16 -> 0.033122569 | F16: =+'SECLE10 Monthly Weather Weights'!E16 -> 0.032911985 | G16: =+'SECLE10 Monthly Weather Weights'!F16 -> 0.032995359 | H16: =+'SECLE10 Monthly Weather Weights'!G16 -> 0.033300037 | I16: =+'SECLE10 Monthly Weather Weights'!H16 -> 0.034121209 | J16: =+'SECLE10 Monthly Weather Weights'!I16 -> 0.033384502 | K16: =+'SECLE10 Monthly Weather Weights'!J16 -> 0.033927507 | ... P16: =+'SECLE10 Monthly Weather Weights'!O16 -> 0.033789271
A17: =+A16+1 -> 7 | B17: Waco | D17: =+'SECLE10 Monthly Weather Weights'!C17 -> 0.037485931 | E17: =+'SECLE10 Monthly Weather Weights'!D17 -> 0.037241356 | F17: =+'SECLE10 Monthly Weather Weights'!E17 -> 0.037928951 | G17: =+'SECLE10 Monthly Weather Weights'!F17 -> 0.037019603 | H17: =+'SECLE10 Monthly Weather Weights'!G17 -> 0.037391153 | I17: =+'SECLE10 Monthly Weather Weights'!H17 -> 0.038489288 | J17: =+'SECLE10 Monthly Weather Weights'!I17 -> 0.038256567 | K17: =+'SECLE10 Monthly Weather Weights'!J17 -> 0.039297679 | ... P17: =+'SECLE10 Monthly Weather Weights'!O17 -> 0.038338298
A18: =+A17+1 -> 8 | B18: Wichita Falls. | D18: =+'SECLE10 Monthly Weather Weights'!C18 -> 0.026890517 | E18: =+'SECLE10 Monthly Weather Weights'!D18 -> 0.02634851 | F18: =+'SECLE10 Monthly Weather Weights'!E18 -> 0.026137524 | G18: =+'SECLE10 Monthly Weather Weights'!F18 -> 0.025726933 | H18: =+'SECLE10 Monthly Weather Weights'!G18 -> 0.025561565 | I18: =+'SECLE10 Monthly Weather Weights'!H18 -> 0.025771814 | J18: =+'SECLE10 Monthly Weather Weights'!I18 -> 0.02636846 | K18: =+'SECLE10 Monthly Weather Weights'!J18 -> 0.026701485 | ... P18: =+'SECLE10 Monthly Weather Weights'!O18 -> 0.026145269
A19: =+A18+1 -> 9 | B19: Longview | D19: =+'SECLE10 Monthly Weather Weights'!C19 -> 0.043330201 | E19: =+'SECLE10 Monthly Weather Weights'!D19 -> 0.043711486 | F19: =+'SECLE10 Monthly Weather Weights'!E19 -> 0.042054132 | G19: =+'SECLE10 Monthly Weather Weights'!F19 -> 0.041448919 | H19: =+'SECLE10 Monthly Weather Weights'!G19 -> 0.041557383 | I19: =+'SECLE10 Monthly Weather Weights'!H19 -> 0.044453719 | J19: =+'SECLE10 Monthly Weather Weights'!I19 -> 0.045476405 | K19: =+'SECLE10 Monthly Weather Weights'!J19 -> 0.046203535 | ... P19: =+'SECLE10 Monthly Weather Weights'!O19 -> 0.043940015
A20: =+A19+1 -> 10 | B20: Austin | D20: =+'SECLE10 Monthly Weather Weights'!C20 -> 0.034442291 | E20: =+'SECLE10 Monthly Weather Weights'!D20 -> 0.033849341 | F20: =+'SECLE10 Monthly Weather Weights'!E20 -> 0.03298799 | G20: =+'SECLE10 Monthly Weather Weights'!F20 -> 0.033588186 | H20: =+'SECLE10 Monthly Weather Weights'!G20 -> 0.033767276 | I20: =+'SECLE10 Monthly Weather Weights'!H20 -> 0.034315832 | J20: =+'SECLE10 Monthly Weather Weights'!I20 -> 0.033466783 | K20: =+'SECLE10 Monthly Weather Weights'!J20 -> 0.033843151 | ... P20: =+'SECLE10 Monthly Weather Weights'!O20 -> 0.034247599
A21: =+A20+1 -> 11 | D21: =SUM(D11:D20) -> 1 | E21: =SUM(E11:E20) -> 1 | F21: =SUM(F11:F20) -> 1 | G21: =SUM(G11:G20) -> 1 | H21: =SUM(H11:H20) -> 1 | I21: =SUM(I11:I20) -> 1 | J21: =SUM(J11:J20) -> 1 | K21: =SUM(K11:K20) -> 1 | ... P21: =SUM(P11:P20) -> 1
A22: =+A21+1 -> 12
A23: =+A22+1 -> 13 | D23: SEASONAL WEIGHTS
A24: =+A23+1 -> 14 | D24: Nov to Mar | F24: May to Sep
A25: =+A24+1 -> 15 | B25: Weather Station | D25: HDD | F25: CDD
A26: =+A25+1 -> 16 | B26: Dallas-Fort Worth | D26: =ROUND(AVERAGE(D11:F11,N11:O11),3) -> 0.604 | F26: =ROUND(AVERAGE(H11:L11),3) -> 0.596
A27: =+A26+1 -> 17 | B27: Midland-Odessa | D27: =ROUND(AVERAGE(D12:F12,N12:O12),3) -> 0.123 | F27: =ROUND(AVERAGE(H12:L12),3) -> 0.125
A28: =+A27+1 -> 18 | B28: Lufkin | D28: =ROUND(AVERAGE(D13:F13,N13:O13),3) -> 0.036 | F28: =ROUND(AVERAGE(H13:L13),3) -> 0.038
A29: =+A28+1 -> 19 | B29: Abilene | D29: =ROUND(AVERAGE(D14:F14,N14:O14),3) -> 0.029 | F29: =ROUND(AVERAGE(H14:L14),3) -> 0.03
A30: =+A29+1 -> 20 | B30: Sherman-Denison | D30: =ROUND(AVERAGE(D15:F15,N15:O15),3) -> 0.033 | F30: =ROUND(AVERAGE(H15:L15),3) -> 0.033
A31: =+A30+1 -> 21 | B31: Killeen-Temple | D31: =ROUND(AVERAGE(D16:F16,N16:O16),3) -> 0.034 | F31: =ROUND(AVERAGE(H16:L16),3) -> 0.034
A32: =+A31+1 -> 22 | B32: Waco | D32: =ROUND(AVERAGE(D17:F17,N17:O17),3) -> 0.038 | F32: =ROUND(AVERAGE(H17:L17),3) -> 0.039
A33: =+A32+1 -> 23 | B33: Wichita Falls. | D33: =ROUND(AVERAGE(D18:F18,N18:O18),3) -> 0.026 | F33: =ROUND(AVERAGE(H18:L18),3) -> 0.026
A34: =+A33+1 -> 24 | B34: Longview | D34: =ROUND(AVERAGE(D19:F19,N19:O19),3) -> 0.043 | F34: =ROUND(AVERAGE(H19:L19),3) -> 0.045
A35: =+A34+1 -> 25 | B35: Austin | D35: =ROUND(AVERAGE(D20:F20,N20:O20),3) -> 0.034 | F35: =ROUND(AVERAGE(H20:L20),3) -> 0.034
A36: =+A35+1 -> 26 | D36: =AVERAGE(D21:F21,N21:O21) -> 1 | F36: =AVERAGE(H21:L21) -> 1

Sheet SECLE10 Monthly Weather Weights
B1: PUC DOCKET NO.
B2: ONCOR ELECTRIC DELIVERY COMPANY
B3: WEATHER WEIGHTS
B4: =+'SECLE10 Seasonal Weights'!B4:P4 -> FOR THE TEST YEAR ENDING DECEMBER 31, 2021
B6: SPONSOR: D. E. NELSON
B8: SECONDARY SERVICE LESS THAN OR EQUAL TO 10 KW MONTHLY WEIGHTS
A9: Line | B9: (a) | C9: (b) | D9: (c) | E9: (d) | F9: (e) | G9: (f) | H9: (g) | I9: (h) | J9: (i) | K9: (j) | L9: (k) | M9: (l) | N9: (m) | O9: (n)
A10: No. | B10: Weather Station | C10: 36892 | D10: 36923 | E10: 36951 | F10: 36982 | G10: 37012 | H10: 37043 | I10: 37073 | J10: 37104 | K10: 37135 | L10: 37165 | M10: 37196 | N10: 37226 | O10: Annual
A11: 1 | B11: Dallas-Fort Worth | C11: =+'SECLE10 Weights by Year (18-20)'!D14 -> 0.60953941 | D11: =+'SECLE10 Weights by Year (18-20)'!E14 -> 0.59423142 | E11: =+'SECLE10 Weights by Year (18-20)'!F14 -> 0.59932853 | F11: =+'SECLE10 Weights by Year (18-20)'!G14 -> 0.60208915 | G11: =+'SECLE10 Weights by Year (18-20)'!H14 -> 0.59998678 | H11: =+'SECLE10 Weights by Year (18-20)'!I14 -> 0.60037932 | I11: =+'SECLE10 Weights by Year (18-20)'!J14 -> 0.59108746 | J11: =+'SECLE10 Weights by Year (18-20)'!K14 -> 0.5922319 | ... O11: =+'SECLE10 Weights by Year (18-20)'!P14 -> 0.60037359
A12: =+A11+1 -> 2 | B12: Midland-Odessa | C12: =+'SECLE10 Weights by Year (18-20)'!D54 -> 0.11458138 | D12: =+'SECLE10 Weights by Year (18-20)'!E54 -> 0.13197133 | E12: =+'SECLE10 Weights by Year (18-20)'!F54 -> 0.13293848 | F12: =+'SECLE10 Weights by Year (18-20)'!G54 -> 0.13200134 | G12: =+'SECLE10 Weights by Year (18-20)'!H54 -> 0.13229046 | H12: =+'SECLE10 Weights by Year (18-20)'!I54 -> 0.1221432 | I12: =+'SECLE10 Weights by Year (18-20)'!J54 -> 0.12920341 | J12: =+'SECLE10 Weights by Year (18-20)'!K54 -> 0.12387508 | ... O12: =+'SECLE10 Weights by Year (18-20)'!P54 -> 0.12362936
A13: =+A12+1 -> 3 | B13: Lufkin | C13: =+'SECLE10 Weights by Year (18-20)'!D19 -> 0.036713347 | D13: =+'SECLE10 Weights by Year (18-20)'!E19 -> 0.036716392 | E13: =+'SECLE10 Weights by Year (18-20)'!F19 -> 0.034617192 | F13: =+'SECLE10 Weights by Year (18-20)'!G19 -> 0.035303155 | G13: =+'SECLE10 Weights by Year (18-20)'!H19 -> 0.035966962 | H13: =+'SECLE10 Weights by Year (18-20)'!I19 -> 0.038726462 | I13: =+'SECLE10 Weights by Year (18-20)'!J19 -> 0.038550932 | J13: =+'SECLE10 Weights by Year (18-20)'!K19 -> 0.038655974 | ... O13: =+'SECLE10 Weights by Year (18-20)'!P19 -> 0.03717003
A14: =+A13+1 -> 4 | B14: Abilene | C14: =+'SECLE10 Weights by Year (18-20)'!D44 -> 0.029957457 | D14: =+'SECLE10 Weights by Year (18-20)'!E44 -> 0.029259608 | E14: =+'SECLE10 Weights by Year (18-20)'!F44 -> 0.028472731 | F14: =+'SECLE10 Weights by Year (18-20)'!G44 -> 0.028638881 | G14: =+'SECLE10 Weights by Year (18-20)'!H44 -> 0.029352259 | H14: =+'SECLE10 Weights by Year (18-20)'!I44 -> 0.029471808 | I14: =+'SECLE10 Weights by Year (18-20)'!J44 -> 0.030757833 | J14: =+'SECLE10 Weights by Year (18-20)'!K44 -> 0.031116751 | ... O14: =+'SECLE10 Weights by Year (18-20)'!P44 -> 0.029650474
A15: =+A14+1 -> 5 | B15: Sherman-Denison | C15: =+'SECLE10 Weights by Year (18-20)'!D59 -> 0.033218802 | D15: =+'SECLE10 Weights by Year (18-20)'!E59 -> 0.033547987 | E15: =+'SECLE10 Weights by Year (18-20)'!F59 -> 0.032622487 | F15: =+'SECLE10 Weights by Year (18-20)'!G59 -> 0.03118848 | G15: =+'SECLE10 Weights by Year (18-20)'!H59 -> 0.030826125 | H15: =+'SECLE10 Weights by Year (18-20)'!I59 -> 0.032127344 | I15: =+'SECLE10 Weights by Year (18-20)'!J59 -> 0.033447646 | J15: =+'SECLE10 Weights by Year (18-20)'!K59 -> 0.034146939 | ... O15: =+'SECLE10 Weights by Year (18-20)'!P59 -> 0.032716091
A16: =+A15+1 -> 6 | B16: Killeen-Temple | C16: =+'SECLE10 Weights by Year (18-20)'!D29 -> 0.033840666 | D16: =+'SECLE10 Weights by Year (18-20)'!E29 -> 0.033122569 | E16: =+'SECLE10 Weights by Year (18-20)'!F29 -> 0.032911985 | F16: =+'SECLE10 Weights by Year (18-20)'!G29 -> 0.032995359 | G16: =+'SECLE10 Weights by Year (18-20)'!H29 -> 0.033300037 | H16: =+'SECLE10 Weights by Year (18-20)'!I29 -> 0.034121209 | I16: =+'SECLE10 Weights by Year (18-20)'!J29 -> 0.033384502 | J16: =+'SECLE10 Weights by Year (18-20)'!K29 -> 0.033927507 | ... O16: =+'SECLE10 Weights by Year (18-20)'!P29 -> 0.033789271
A17: =+A16+1 -> 7 | B17: Waco | C17: =+'SECLE10 Weights by Year (18-20)'!D39 -> 0.037485931 | D17: =+'SECLE10 Weights by Year (18-20)'!E39 -> 0.037241356 | E17: =+'SECLE10 Weights by Year (18-20)'!F39 -> 0.037928951 | F17: =+'SECLE10 Weights by Year (18-20)'!G39 -> 0.037019603 | G17: =+'SECLE10 Weights by Year (18-20)'!H39 -> 0.037391153 | H17: =+'SECLE10 Weights by Year (18-20)'!I39 -> 0.038489288 | I17: =+'SECLE10 Weights by Year (18-20)'!J39 -> 0.038256567 | J17: =+'SECLE10 Weights by Year (18-20)'!K39 -> 0.039297679 | ... O17: =+'SECLE10 Weights by Year (18-20)'!P39 -> 0.038338298
A18: =+A17+1 -> 8 | B18: Wichita Falls. | C18: =+'SECLE10 Weights by Year (18-20)'!D49 -> 0.026890517 | D18: =+'SECLE10 Weights by Year (18-20)'!E49 -> 0.02634851 | E18: =+'SECLE10 Weights by Year (18-20)'!F49 -> 0.026137524 | F18: =+'SECLE10 Weights by Year (18-20)'!G49 -> 0.025726933 | G18: =+'SECLE10 Weights by Year (18-20)'!H49 -> 0.025561565 | H18: =+'SECLE10 Weights by Year (18-20)'!I49 -> 0.025771814 | I18: =+'SECLE10 Weights by Year (18-20)'!J49 -> 0.02636846 | J18: =+'SECLE10 Weights by Year (18-20)'!K49 -> 0.026701485 | ... O18: =+'SECLE10 Weights by Year (18-20)'!P49 -> 0.026145269
A19: =+A18+1 -> 9 | B19: Longview | C19: =+'SECLE10 Weights by Year (18-20)'!D34 -> 0.043330201 | D19: =+'SECLE10 Weights by Year (18-20)'!E34 -> 0.043711486 | E19: =+'SECLE10 Weights by Year (18-20)'!F34 -> 0.042054132 | F19: =+'SECLE10 Weights by Year (18-20)'!G34 -> 0.041448919 | G19: =+'SECLE10 Weights by Year (18-20)'!H34 -> 0.041557383 | H19: =+'SECLE10 Weights by Year (18-20)'!I34 -> 0.044453719 | I19: =+'SECLE10 Weights by Year (18-20)'!J34 -> 0.045476405 | J19: =+'SECLE10 Weights by Year (18-20)'!K34 -> 0.046203535 | ... O19: =+'SECLE10 Weights by Year (18-20)'!P34 -> 0.043940015
A20: =+A19+1 -> 10 | B20: Austin | C20: =+'SECLE10 Weights by Year (18-20)'!D24 -> 0.034442291 | D20: =+'SECLE10 Weights by Year (18-20)'!E24 -> 0.033849341 | E20: =+'SECLE10 Weights by Year (18-20)'!F24 -> 0.03298799 | F20: =+'SECLE10 Weights by Year (18-20)'!G24 -> 0.033588186 | G20: =+'SECLE10 Weights by Year (18-20)'!H24 -> 0.033767276 | H20: =+'SECLE10 Weights by Year (18-20)'!I24 -> 0.034315832 | I20: =+'SECLE10 Weights by Year (18-20)'!J24 -> 0.033466783 | J20: =+'SECLE10 Weights by Year (18-20)'!K24 -> 0.033843151 | ... O20: =+'SECLE10 Weights by Year (18-20)'!P24 -> 0.034247599
C21: =SUM(C11:C20) -> 1 | D21: =SUM(D11:D20) -> 1 | E21: =SUM(E11:E20) -> 1 | F21: =SUM(F11:F20) -> 1 | G21: =SUM(G11:G20) -> 1 | H21: =SUM(H11:H20) -> 1 | I21: =SUM(I11:I20) -> 1 | J21: =SUM(J11:J20) -> 1 | ... O21: =SUM(O11:O20) -> 1

Sheet SECLE10 Weights by Year (18-20)
B1: PUC DOCKET NO.
B2: ONCOR ELECTRIC DELIVERY COMPANY
B3: WEATHER WEIGHTS
B4: =+'SECLE10 Seasonal Weights'!B4:P4 -> FOR THE TEST YEAR ENDING DECEMBER 31, 2021
B6: SPONSOR: D. E. NELSON
B8: SECONDARY SERVICE LESS THAN OR EQUAL TO 10 KW WEIGHTS BY YEAR
A9: Line | B9: (a) | C9: (b) | D9: (c) | E9: (d) | F9: (e) | G9: (f) | H9: (g) | I9: (h) | J9: (i) | K9: (j) | L9: (k) | M9: (l) | N9: (m) | O9: (n) | P9: (o)
A10: No. | B10: Weather Station | C10: Year | D10: 36892 | E10: 36923 | F10: 36951 | G10: 36982 | H10: 37012 | I10: 37043 | J10: 37073 | K10: 37104 | L10: 37135 | M10: 37165 | N10: 37196 | O10: 37226 | P10: Annual
A11: 1 | B11: Dallas-Fort Worth | C11: 2018 | D11: ='SECLE10 Sales by Year (18-20)'!D11/'SECLE10 Sales by Year (18-20)'!D61 -> 0.61717048 | E11: ='SECLE10 Sales by Year (18-20)'!E11/'SECLE10 Sales by Year (18-20)'!E$61 -> 0.58994277 | F11: ='SECLE10 Sales by Year (18-20)'!F11/'SECLE10 Sales by Year (18-20)'!F$61 -> 0.59717291 | G11: ='SECLE10 Sales by Year (18-20)'!G11/'SECLE10 Sales by Year (18-20)'!G$61 -> 0.60974421 | H11: ='SECLE10 Sales by Year (18-20)'!H11/'SECLE10 Sales by Year (18-20)'!H$61 -> 0.60175722 | I11: ='SECLE10 Sales by Year (18-20)'!I11/'SECLE10 Sales by Year (18-20)'!I$61 -> 0.60039158 | J11: ='SECLE10 Sales by Year (18-20)'!J11/'SECLE10 Sales by Year (18-20)'!J$61 -> 0.5913743 | K11: ='SECLE10 Sales by Year (18-20)'!K11/'SECLE10 Sales by Year (18-20)'!K$61 -> 0.59689093 | L11: ='SECLE10 Sales by Year (18-20)'!L11/'SECLE10 Sales by Year (18-20)'!L$61 -> 0.602015 | ... P11: ='SECLE10 Sales by Year (18-20)'!P11/'SECLE10 Sales by Year (18-20)'!P$61 -> 0.60269574
A12: =+A11+1 -> 2 | B12: Dallas-Fort Worth | C12: 2019 | D12: ='SECLE10 Sales by Year (18-20)'!D12/'SECLE10 Sales by Year (18-20)'!D62 -> 0.60926963 | E12: ='SECLE10 Sales by Year (18-20)'!E12/'SECLE10 Sales by Year (18-20)'!E$62 -> 0.59135001 | F12: ='SECLE10 Sales by Year (18-20)'!F12/'SECLE10 Sales by Year (18-20)'!F$62 -> 0.59970014 | G12: ='SECLE10 Sales by Year (18-20)'!G12/'SECLE10 Sales by Year (18-20)'!G$62 -> 0.592495 | H12: ='SECLE10 Sales by Year (18-20)'!H12/'SECLE10 Sales by Year (18-20)'!H$62 -> 0.59529512 | I12: ='SECLE10 Sales by Year (18-20)'!I12/'SECLE10 Sales by Year (18-20)'!I$62 -> 0.59829159 | J12: ='SECLE10 Sales by Year (18-20)'!J12/'SECLE10 Sales by Year (18-20)'!J$62 -> 0.58680943 | K12: ='SECLE10 Sales by Year (18-20)'!K12/'SECLE10 Sales by Year (18-20)'!K$62 -> 0.5836347 | L12: ='SECLE10 Sales by Year (18-20)'!L12/'SECLE10 Sales by Year (18-20)'!L$62 -> 0.5894887 | ... P12: ='SECLE10 Sales by Year (18-20)'!P12/'SECLE10 Sales by Year (18-20)'!P$62 -> 0.59554326
A13: =+A12+1 -> 3 | B13: Dallas-Fort Worth | C13: 2020 | D13: ='SECLE10 Sales by Year (18-20)'!D13/'SECLE10 Sales by Year (18-20)'!D63 -> 0.60122849 | E13: ='SECLE10 Sales by Year (18-20)'!E13/'SECLE10 Sales by Year (18-20)'!E63 -> 0.60196739 | F13: ='SECLE10 Sales by Year (18-20)'!F13/'SECLE10 Sales by Year (18-20)'!F63 -> 0.60120112 | G13: ='SECLE10 Sales by Year (18-20)'!G13/'SECLE10 Sales by Year (18-20)'!G63 -> 0.60414859 | H13: ='SECLE10 Sales by Year (18-20)'!H13/'SECLE10 Sales by Year (18-20)'!H63 -> 0.60304603 | I13: ='SECLE10 Sales by Year (18-20)'!I13/'SECLE10 Sales by Year (18-20)'!I63 -> 0.60244349 | J13: ='SECLE10 Sales by Year (18-20)'!J13/'SECLE10 Sales by Year (18-20)'!J63 -> 0.59487237 | K13: ='SECLE10 Sales by Year (18-20)'!K13/'SECLE10 Sales by Year (18-20)'!K63 -> 0.59600473 | ... P13: ='SECLE10 Sales by Year (18-20)'!P13/'SECLE10 Sales by Year (18-20)'!P63 -> 0.60297378
A14: =+A13+1 -> 4 | B14: Dallas-Fort Worth | C14: Total | D14: ='SECLE10 Sales by Year (18-20)'!D14/'SECLE10 Sales by Year (18-20)'!D64 -> 0.60953941 | E14: ='SECLE10 Sales by Year (18-20)'!E14/'SECLE10 Sales by Year (18-20)'!E64 -> 0.59423142 | F14: ='SECLE10 Sales by Year (18-20)'!F14/'SECLE10 Sales by Year (18-20)'!F64 -> 0.59932853 | G14: ='SECLE10 Sales by Year (18-20)'!G14/'SECLE10 Sales by Year (18-20)'!G64 -> 0.60208915 | H14: ='SECLE10 Sales by Year (18-20)'!H14/'SECLE10 Sales by Year (18-20)'!H64 -> 0.59998678 | I14: ='SECLE10 Sales by Year (18-20)'!I14/'SECLE10 Sales by Year (18-20)'!I64 -> 0.60037932 | J14: ='SECLE10 Sales by Year (18-20)'!J14/'SECLE10 Sales by Year (18-20)'!J64 -> 0.59108746 | K14: ='SECLE10 Sales by Year (18-20)'!K14/'SECLE10 Sales by Year (18-20)'!K64 -> 0.5922319 | ... P14: ='SECLE10 Sales by Year (18-20)'!P14/'SECLE10 Sales by Year (18-20)'!P64 -> 0.60037359
A15: =+A14+1 -> 5
A16: =+A15+1 -> 6 | B16: Lufkin | C16: =+C11 -> 2018 | D16: ='SECLE10 Sales by Year (18-20)'!D16/'SECLE10 Sales by Year (18-20)'!D61 -> 0.039006998 | E16: ='SECLE10 Sales by Year (18-20)'!E16/'SECLE10 Sales by Year (18-20)'!E$61 -> 0.035713548 | F16: ='SECLE10 Sales by Year (18-20)'!F16/'SECLE10 Sales by Year (18-20)'!F$61 -> 0.032982533 | G16: ='SECLE10 Sales by Year (18-20)'!G16/'SECLE10 Sales by Year (18-20)'!G$61 -> 0.035458252 | H16: ='SECLE10 Sales by Year (18-20)'!H16/'SECLE10 Sales by Year (18-20)'!H$61 -> 0.035964622 | I16: ='SECLE10 Sales by Year (18-20)'!I16/'SECLE10 Sales by Year (18-20)'!I$61 -> 0.039089231 | J16: ='SECLE10 Sales by Year (18-20)'!J16/'SECLE10 Sales by Year (18-20)'!J$61 -> 0.037964274 | K16: ='SECLE10 Sales by Year (18-20)'!K16/'SECLE10 Sales by Year (18-20)'!K$61 -> 0.039141682 | L16: ='SECLE10 Sales by Year (18-20)'!L16/'SECLE10 Sales by Year (18-20)'!L$61 -> 0.039532656 | ... P16: ='SECLE10 Sales by Year (18-20)'!P16/'SECLE10 Sales by Year (18-20)'!P$61 -> 0.037423436
A17: =+A16+1 -> 7 | B17: Lufkin | C17: =+C12 -> 2019 | D17: ='SECLE10 Sales by Year (18-20)'!D17/'SECLE10 Sales by Year (18-20)'!D62 -> 0.035120818 | E17: ='SECLE10 Sales by Year (18-20)'!E17/'SECLE10 Sales by Year (18-20)'!E$62 -> 0.037875932 | F17: ='SECLE10 Sales by Year (18-20)'!F17/'SECLE10 Sales by Year (18-20)'!F$62 -> 0.03512732 | G17: ='SECLE10 Sales by Year (18-20)'!G17/'SECLE10 Sales by Year (18-20)'!G$62 -> 0.034732994 | H17: ='SECLE10 Sales by Year (18-20)'!H17/'SECLE10 Sales by Year (18-20)'!H$62 -> 0.035952162 | I17: ='SECLE10 Sales by Year (18-20)'!I17/'SECLE10 Sales by Year (18-20)'!I$62 -> 0.03925185 | J17: ='SECLE10 Sales by Year (18-20)'!J17/'SECLE10 Sales by Year (18-20)'!J$62 -> 0.038553164 | K17: ='SECLE10 Sales by Year (18-20)'!K17/'SECLE10 Sales by Year (18-20)'!K$62 -> 0.037960352 | L17: ='SECLE10 Sales by Year (18-20)'!L17/'SECLE10 Sales by Year (18-20)'!L$62 -> 0.038157257 | ... P17: ='SECLE10 Sales by Year (18-20)'!P17/'SECLE10 Sales by Year (18-20)'!P$62 -> 0.036863472
A18: =+A17+1 -> 8 | B18: Lufkin | C18: =+C13 -> 2020 | D18: ='SECLE10 Sales by Year (18-20)'!D18/'SECLE10 Sales by Year (18-20)'!D63 -> 0.035798409 | E18: ='SECLE10 Sales by Year (18-20)'!E18/'SECLE10 Sales by Year (18-20)'!E63 -> 0.036623062 | F18: ='SECLE10 Sales by Year (18-20)'!F18/'SECLE10 Sales by Year (18-20)'!F63 -> 0.035794795 | G18: ='SECLE10 Sales by Year (18-20)'!G18/'SECLE10 Sales by Year (18-20)'!G63 -> 0.035741747 | H18: ='SECLE10 Sales by Year (18-20)'!H18/'SECLE10 Sales by Year (18-20)'!H63 -> 0.035984829 | I18: ='SECLE10 Sales by Year (18-20)'!I18/'SECLE10 Sales by Year (18-20)'!I63 -> 0.037808405 | J18: ='SECLE10 Sales by Year (18-20)'!J18/'SECLE10 Sales by Year (18-20)'!J63 -> 0.039185558 | K18: ='SECLE10 Sales by Year (18-20)'!K18/'SECLE10 Sales by Year (18-20)'!K63 -> 0.038849716 | ... P18: ='SECLE10 Sales by Year (18-20)'!P18/'SECLE10 Sales by Year (18-20)'!P63 -> 0.037223776
A19: =+A18+1 -> 9 | B19: Lufkin | C19: Total | D19: ='SECLE10 Sales by Year (18-20)'!D19/'SECLE10 Sales by Year (18-20)'!D64 -> 0.036713347 | E19: ='SECLE10 Sales by Year (18-20)'!E19/'SECLE10 Sales by Year (18-20)'!E64 -> 0.036716392 | F19: ='SECLE10 Sales by Year (18-20)'!F19/'SECLE10 Sales by Year (18-20)'!F64 -> 0.034617192 | G19: ='SECLE10 Sales by Year (18-20)'!G19/'SECLE10 Sales by Year (18-20)'!G64 -> 0.035303155 | H19: ='SECLE10 Sales by Year (18-20)'!H19/'SECLE10 Sales by Year (18-20)'!H64 -> 0.035966962 | I19: ='SECLE10 Sales by Year (18-20)'!I19/'SECLE10 Sales by Year (18-20)'!I64 -> 0.038726462 | J19: ='SECLE10 Sales by Year (18-20)'!J19/'SECLE10 Sales by Year (18-20)'!J64 -> 0.038550932 | K19: ='SECLE10 Sales by Year (18-20)'!K19/'SECLE10 Sales by Year (18-20)'!K64 -> 0.038655974 | ... P19: ='SECLE10 Sales by Year (18-20)'!P19/'SECLE10 Sales by Year (18-20)'!P64 -> 0.03717003
A20: =+A19+1 -> 10
A21: =+A20+1 -> 11 | B21: Austin | C21: =+C16 -> 2018 | D21: ='SECLE10 Sales by Year (18-20)'!D21/'SECLE10 Sales by Year (18-20)'!D61 -> 0.035705182 | E21: ='SECLE10 Sales by Year (18-20)'!E21/'SECLE10 Sales by Year (18-20)'!E$61 -> 0.033414173 | F21: ='SECLE10 Sales by Year (18-20)'!F21/'SECLE10 Sales by Year (18-20)'!F$61 -> 0.031606535 | G21: ='SECLE10 Sales by Year (18-20)'!G21/'SECLE10 Sales by Year (18-20)'!G$61 -> 0.03348399 | H21: ='SECLE10 Sales by Year (18-20)'!H21/'SECLE10 Sales by Year (18-20)'!H$61 -> 0.033217866 | I21: ='SECLE10 Sales by Year (18-20)'!I21/'SECLE10 Sales by Year (18-20)'!I$61 -> 0.033676751 | J21: ='SECLE10 Sales by Year (18-20)'!J21/'SECLE10 Sales by Year (18-20)'!J$61 -> 0.032480906 | K21: ='SECLE10 Sales by Year (18-20)'!K21/'SECLE10 Sales by Year (18-20)'!K$61 -> 0.033783616 | L21: ='SECLE10 Sales by Year (18-20)'!L21/'SECLE10 Sales by Year (18-20)'!L$61 -> 0.035527776 | ... P21: ='SECLE10 Sales by Year (18-20)'!P21/'SECLE10 Sales by Year (18-20)'!P$61 -> 0.034040407
A22: =+A21+1 -> 12 | B22: Austin | C22: =+C17 -> 2019 | D22: ='SECLE10 Sales by Year (18-20)'!D22/'SECLE10 Sales by Year (18-20)'!D62 -> 0.033657161 | E22: ='SECLE10 Sales by Year (18-20)'!E22/'SECLE10 Sales by Year (18-20)'!E$62 -> 0.034892985 | F22: ='SECLE10 Sales by Year (18-20)'!F22/'SECLE10 Sales by Year (18-20)'!F$62 -> 0.033243298 | G22: ='SECLE10 Sales by Year (18-20)'!G22/'SECLE10 Sales by Year (18-20)'!G$62 -> 0.03346068 | H22: ='SECLE10 Sales by Year (18-20)'!H22/'SECLE10 Sales by Year (18-20)'!H$62 -> 0.034094533 | I22: ='SECLE10 Sales by Year (18-20)'!I22/'SECLE10 Sales by Year (18-20)'!I$62 -> 0.034692312 | J22: ='SECLE10 Sales by Year (18-20)'!J22/'SECLE10 Sales by Year (18-20)'!J$62 -> 0.033936642 | K22: ='SECLE10 Sales by Year (18-20)'!K22/'SECLE10 Sales by Year (18-20)'!K$62 -> 0.033689309 | L22: ='SECLE10 Sales by Year (18-20)'!L22/'SECLE10 Sales by Year (18-20)'!L$62 -> 0.034014428 | ... P22: ='SECLE10 Sales by Year (18-20)'!P22/'SECLE10 Sales by Year (18-20)'!P$62 -> 0.03410656
A23: =+A22+1 -> 13 | B23: Austin | C23: =+C18 -> 2020 | D23: ='SECLE10 Sales by Year (18-20)'!D23/'SECLE10 Sales by Year (18-20)'!D63 -> 0.033842459 | E23: ='SECLE10 Sales by Year (18-20)'!E23/'SECLE10 Sales by Year (18-20)'!E63 -> 0.033248028 | F23: ='SECLE10 Sales by Year (18-20)'!F23/'SECLE10 Sales by Year (18-20)'!F63 -> 0.03416985 | G23: ='SECLE10 Sales by Year (18-20)'!G23/'SECLE10 Sales by Year (18-20)'!G63 -> 0.033832732 | H23: ='SECLE10 Sales by Year (18-20)'!H23/'SECLE10 Sales by Year (18-20)'!H63 -> 0.033995421 | I23: ='SECLE10 Sales by Year (18-20)'!I23/'SECLE10 Sales by Year (18-20)'!I63 -> 0.034637477 | J23: ='SECLE10 Sales by Year (18-20)'!J23/'SECLE10 Sales by Year (18-20)'!J63 -> 0.034086964 | K23: ='SECLE10 Sales by Year (18-20)'!K23/'SECLE10 Sales by Year (18-20)'!K63 -> 0.034057241 | ... P23: ='SECLE10 Sales by Year (18-20)'!P23/'SECLE10 Sales by Year (18-20)'!P63 -> 0.034612121
A24: =+A23+1 -> 14 | B24: Austin | C24: Total | D24: ='SECLE10 Sales by Year (18-20)'!D24/'SECLE10 Sales by Year (18-20)'!D64 -> 0.034442291 | E24: ='SECLE10 Sales by Year (18-20)'!E24/'SECLE10 Sales by Year (18-20)'!E64 -> 0.033849341 | F24: ='SECLE10 Sales by Year (18-20)'!F24/'SECLE10 Sales by Year (18-20)'!F64 -> 0.03298799 | G24: ='SECLE10 Sales by Year (18-20)'!G24/'SECLE10 Sales by Year (18-20)'!G64 -> 0.033588186 | H24: ='SECLE10 Sales by Year (18-20)'!H24/'SECLE10 Sales by Year (18-20)'!H64 -> 0.033767276 | I24: ='SECLE10 Sales by Year (18-20)'!I24/'SECLE10 Sales by Year (18-20)'!I64 -> 0.034315832 | J24: ='SECLE10 Sales by Year (18-20)'!J24/'SECLE10 Sales by Year (18-20)'!J64 -> 0.033466783 | K24: ='SECLE10 Sales by Year (18-20)'!K24/'SECLE10 Sales by Year (18-20)'!K64 -> 0.033843151 | ... P24: ='SECLE10 Sales by Year (18-20)'!P24/'SECLE10 Sales by Year (18-20)'!P64 -> 0.034247599
A25: =+A24+1 -> 15
A26: =+A25+1 -> 16 | B26: Killeen | C26: =+C21 -> 2018 | D26: ='SECLE10 Sales by Year (18-20)'!D26/'SECLE10 Sales by Year (18-20)'!D61 -> 0.03398257 | E26: ='SECLE10 Sales by Year (18-20)'!E26/'SECLE10 Sales by Year (18-20)'!E$61 -> 0.031594726 | F26: ='SECLE10 Sales by Year (18-20)'!F26/'SECLE10 Sales by Year (18-20)'!F$61 -> 0.031119905 | G26: ='SECLE10 Sales by Year (18-20)'!G26/'SECLE10 Sales by Year (18-20)'!G$61 -> 0.032106356 | H26: ='SECLE10 Sales by Year (18-20)'!H26/'SECLE10 Sales by Year (18-20)'!H$61 -> 0.031991254 | I26: ='SECLE10 Sales by Year (18-20)'!I26/'SECLE10 Sales by Year (18-20)'!I$61 -> 0.033016264 | J26: ='SECLE10 Sales by Year (18-20)'!J26/'SECLE10 Sales by Year (18-20)'!J$61 -> 0.032038725 | K26: ='SECLE10 Sales by Year (18-20)'!K26/'SECLE10 Sales by Year (18-20)'!K$61 -> 0.033415959 | L26: ='SECLE10 Sales by Year (18-20)'!L26/'SECLE10 Sales by Year (18-20)'!L$61 -> 0.034717598 | ... P26: ='SECLE10 Sales by Year (18-20)'!P26/'SECLE10 Sales by Year (18-20)'!P$61 -> 0.033157978
A27: =+A26+1 -> 17 | B27: Killeen | C27: =+C22 -> 2019 | D27: ='SECLE10 Sales by Year (18-20)'!D27/'SECLE10 Sales by Year (18-20)'!D62 -> 0.033611329 | E27: ='SECLE10 Sales by Year (18-20)'!E27/'SECLE10 Sales by Year (18-20)'!E$62 -> 0.034893515 | F27: ='SECLE10 Sales by Year (18-20)'!F27/'SECLE10 Sales by Year (18-20)'!F$62 -> 0.033987485 | G27: ='SECLE10 Sales by Year (18-20)'!G27/'SECLE10 Sales by Year (18-20)'!G$62 -> 0.033606537 | H27: ='SECLE10 Sales by Year (18-20)'!H27/'SECLE10 Sales by Year (18-20)'!H$62 -> 0.034055668 | I27: ='SECLE10 Sales by Year (18-20)'!I27/'SECLE10 Sales by Year (18-20)'!I$62 -> 0.035171204 | J27: ='SECLE10 Sales by Year (18-20)'!J27/'SECLE10 Sales by Year (18-20)'!J$62 -> 0.034233139 | K27: ='SECLE10 Sales by Year (18-20)'!K27/'SECLE10 Sales by Year (18-20)'!K$62 -> 0.034249452 | L27: ='SECLE10 Sales by Year (18-20)'!L27/'SECLE10 Sales by Year (18-20)'!L$62 -> 0.034279364 | ... P27: ='SECLE10 Sales by Year (18-20)'!P27/'SECLE10 Sales by Year (18-20)'!P$62 -> 0.034194747
A28: =+A27+1 -> 18 | B28: Killeen | C28: =+C23 -> 2020 | D28: ='SECLE10 Sales by Year (18-20)'!D28/'SECLE10 Sales by Year (18-20)'!D63 -> 0.033921068 | E28: ='SECLE10 Sales by Year (18-20)'!E28/'SECLE10 Sales by Year (18-20)'!E63 -> 0.032975841 | F28: ='SECLE10 Sales by Year (18-20)'!F28/'SECLE10 Sales by Year (18-20)'!F63 -> 0.033654853 | G28: ='SECLE10 Sales by Year (18-20)'!G28/'SECLE10 Sales by Year (18-20)'!G63 -> 0.033287435 | H28: ='SECLE10 Sales by Year (18-20)'!H28/'SECLE10 Sales by Year (18-20)'!H63 -> 0.033868498 | I28: ='SECLE10 Sales by Year (18-20)'!I28/'SECLE10 Sales by Year (18-20)'!I63 -> 0.034280198 | J28: ='SECLE10 Sales by Year (18-20)'!J28/'SECLE10 Sales by Year (18-20)'!J63 -> 0.034032636 | K28: ='SECLE10 Sales by Year (18-20)'!K28/'SECLE10 Sales by Year (18-20)'!K63 -> 0.034131964 | ... P28: ='SECLE10 Sales by Year (18-20)'!P28/'SECLE10 Sales by Year (18-20)'!P63 -> 0.034028953
A29: =+A28+1 -> 19 | B29: Killeen | C29: Total | D29: ='SECLE10 Sales by Year (18-20)'!D29/'SECLE10 Sales by Year (18-20)'!D64 -> 0.033840666 | E29: ='SECLE10 Sales by Year (18-20)'!E29/'SECLE10 Sales by Year (18-20)'!E64 -> 0.033122569 | F29: ='SECLE10 Sales by Year (18-20)'!F29/'SECLE10 Sales by Year (18-20)'!F64 -> 0.032911985 | G29: ='SECLE10 Sales by Year (18-20)'!G29/'SECLE10 Sales by Year (18-20)'!G64 -> 0.032995359 | H29: ='SECLE10 Sales by Year (18-20)'!H29/'SECLE10 Sales by Year (18-20)'!H64 -> 0.033300037 | I29: ='SECLE10 Sales by Year (18-20)'!I29/'SECLE10 Sales by Year (18-20)'!I64 -> 0.034121209 | J29: ='SECLE10 Sales by Year (18-20)'!J29/'SECLE10 Sales by Year (18-20)'!J64 -> 0.033384502 | K29: ='SECLE10 Sales by Year (18-20)'!K29/'SECLE10 Sales by Year (18-20)'!K64 -> 0.033927507 | ... P29: ='SECLE10 Sales by Year (18-20)'!P29/'SECLE10 Sales by Year (18-20)'!P64 -> 0.033789271
A30: =+A29+1 -> 20
A31: =+A30+1 -> 21 | B31: Longview | C31: =+C26 -> 2018 | D31: ='SECLE10 Sales by Year (18-20)'!D31/'SECLE10 Sales by Year (18-20)'!D61 -> 0.044826888 | E31: ='SECLE10 Sales by Year (18-20)'!E31/'SECLE10 Sales by Year (18-20)'!E$61 -> 0.042836708 | F31: ='SECLE10 Sales by Year (18-20)'!F31/'SECLE10 Sales by Year (18-20)'!F$61 -> 0.040353123 | G31: ='SECLE10 Sales by Year (18-20)'!G31/'SECLE10 Sales by Year (18-20)'!G$61 -> 0.041162917 | H31: ='SECLE10 Sales by Year (18-20)'!H31/'SECLE10 Sales by Year (18-20)'!H$61 -> 0.041330817 | I31: ='SECLE10 Sales by Year (18-20)'!I31/'SECLE10 Sales by Year (18-20)'!I$61 -> 0.045020182 | J31: ='SECLE10 Sales by Year (18-20)'!J31/'SECLE10 Sales by Year (18-20)'!J$61 -> 0.045840673 | K31: ='SECLE10 Sales by Year (18-20)'!K31/'SECLE10 Sales by Year (18-20)'!K$61 -> 0.047095414 | L31: ='SECLE10 Sales by Year (18-20)'!L31/'SECLE10 Sales by Year (18-20)'!L$61 -> 0.048127112 | ... P31: ='SECLE10 Sales by Year (18-20)'!P31/'SECLE10 Sales by Year (18-20)'!P$61 -> 0.04419387
A32: =+A31+1 -> 22 | B32: Longview | C32: =+C27 -> 2019 | D32: ='SECLE10 Sales by Year (18-20)'!D32/'SECLE10 Sales by Year (18-20)'!D62 -> 0.042069685 | E32: ='SECLE10 Sales by Year (18-20)'!E32/'SECLE10 Sales by Year (18-20)'!E$62 -> 0.044700703 | F32: ='SECLE10 Sales by Year (18-20)'!F32/'SECLE10 Sales by Year (18-20)'!F$62 -> 0.043231106 | G32: ='SECLE10 Sales by Year (18-20)'!G32/'SECLE10 Sales by Year (18-20)'!G$62 -> 0.041704675 | H32: ='SECLE10 Sales by Year (18-20)'!H32/'SECLE10 Sales by Year (18-20)'!H$62 -> 0.041528085 | I32: ='SECLE10 Sales by Year (18-20)'!I32/'SECLE10 Sales by Year (18-20)'!I$62 -> 0.044252704 | J32: ='SECLE10 Sales by Year (18-20)'!J32/'SECLE10 Sales by Year (18-20)'!J$62 -> 0.044524978 | K32: ='SECLE10 Sales by Year (18-20)'!K32/'SECLE10 Sales by Year (18-20)'!K$62 -> 0.04537869 | L32: ='SECLE10 Sales by Year (18-20)'!L32/'SECLE10 Sales by Year (18-20)'!L$62 -> 0.046668498 | ... P32: ='SECLE10 Sales by Year (18-20)'!P32/'SECLE10 Sales by Year (18-20)'!P$62 -> 0.04381438
A33: =+A32+1 -> 23 | B33: Longview | C33: =+C28 -> 2020 | D33: ='SECLE10 Sales by Year (18-20)'!D33/'SECLE10 Sales by Year (18-20)'!D63 -> 0.042964994 | E33: ='SECLE10 Sales by Year (18-20)'!E33/'SECLE10 Sales by Year (18-20)'!E63 -> 0.043653158 | F33: ='SECLE10 Sales by Year (18-20)'!F33/'SECLE10 Sales by Year (18-20)'!F63 -> 0.042593472 | G33: ='SECLE10 Sales by Year (18-20)'!G33/'SECLE10 Sales by Year (18-20)'!G63 -> 0.041480432 | H33: ='SECLE10 Sales by Year (18-20)'!H33/'SECLE10 Sales by Year (18-20)'!H63 -> 0.041822822 | I33: ='SECLE10 Sales by Year (18-20)'!I33/'SECLE10 Sales by Year (18-20)'!I63 -> 0.044036584 | J33: ='SECLE10 Sales by Year (18-20)'!J33/'SECLE10 Sales by Year (18-20)'!J63 -> 0.045992028 | K33: ='SECLE10 Sales by Year (18-20)'!K33/'SECLE10 Sales by Year (18-20)'!K63 -> 0.046109204 | ... P33: ='SECLE10 Sales by Year (18-20)'!P33/'SECLE10 Sales by Year (18-20)'!P63 -> 0.043804617
A34: =+A33+1 -> 24 | B34: Longview | C34: Total | D34: ='SECLE10 Sales by Year (18-20)'!D34/'SECLE10 Sales by Year (18-20)'!D64 -> 0.043330201 | E34: ='SECLE10 Sales by Year (18-20)'!E34/'SECLE10 Sales by Year (18-20)'!E64 -> 0.043711486 | F34: ='SECLE10 Sales by Year (18-20)'!F34/'SECLE10 Sales by Year (18-20)'!F64 -> 0.042054132 | G34: ='SECLE10 Sales by Year (18-20)'!G34/'SECLE10 Sales by Year (18-20)'!G64 -> 0.041448919 | H34: ='SECLE10 Sales by Year (18-20)'!H34/'SECLE10 Sales by Year (18-20)'!H64 -> 0.041557383 | I34: ='SECLE10 Sales by Year (18-20)'!I34/'SECLE10 Sales by Year (18-20)'!I64 -> 0.044453719 | J34: ='SECLE10 Sales by Year (18-20)'!J34/'SECLE10 Sales by Year (18-20)'!J64 -> 0.045476405 | K34: ='SECLE10 Sales by Year (18-20)'!K34/'SECLE10 Sales by Year (18-20)'!K64 -> 0.046203535 | ... P34: ='SECLE10 Sales by Year (18-20)'!P34/'SECLE10 Sales by Year (18-20)'!P64 -> 0.043940015
A35: =+A34+1 -> 25
A36: =+A35+1 -> 26 | B36: Waco | C36: =+C31 -> 2018 | D36: ='SECLE10 Sales by Year (18-20)'!D36/'SECLE10 Sales by Year (18-20)'!D61 -> 0.037832806 | E36: ='SECLE10 Sales by Year (18-20)'!E36/'SECLE10 Sales by Year (18-20)'!E$61 -> 0.035900831 | F36: ='SECLE10 Sales by Year (18-20)'!F36/'SECLE10 Sales by Year (18-20)'!F$61 -> 0.037091846 | G36: ='SECLE10 Sales by Year (18-20)'!G36/'SECLE10 Sales by Year (18-20)'!G$61 -> 0.035825327 | H36: ='SECLE10 Sales by Year (18-20)'!H36/'SECLE10 Sales by Year (18-20)'!H$61 -> 0.03586488 | I36: ='SECLE10 Sales by Year (18-20)'!I36/'SECLE10 Sales by Year (18-20)'!I$61 -> 0.037665026 | J36: ='SECLE10 Sales by Year (18-20)'!J36/'SECLE10 Sales by Year (18-20)'!J$61 -> 0.037643783 | K36: ='SECLE10 Sales by Year (18-20)'!K36/'SECLE10 Sales by Year (18-20)'!K$61 -> 0.039406027 | L36: ='SECLE10 Sales by Year (18-20)'!L36/'SECLE10 Sales by Year (18-20)'!L$61 -> 0.040164529 | ... P36: ='SECLE10 Sales by Year (18-20)'!P36/'SECLE10 Sales by Year (18-20)'!P$61 -> 0.037827418
A37: =+A36+1 -> 27 | B37: Waco | C37: =+C32 -> 2019 | D37: ='SECLE10 Sales by Year (18-20)'!D37/'SECLE10 Sales by Year (18-20)'!D62 -> 0.037328712 | E37: ='SECLE10 Sales by Year (18-20)'!E37/'SECLE10 Sales by Year (18-20)'!E$62 -> 0.038876107 | F37: ='SECLE10 Sales by Year (18-20)'!F37/'SECLE10 Sales by Year (18-20)'!F$62 -> 0.038344606 | G37: ='SECLE10 Sales by Year (18-20)'!G37/'SECLE10 Sales by Year (18-20)'!G$62 -> 0.037359441 | H37: ='SECLE10 Sales by Year (18-20)'!H37/'SECLE10 Sales by Year (18-20)'!H$62 -> 0.037633937 | I37: ='SECLE10 Sales by Year (18-20)'!I37/'SECLE10 Sales by Year (18-20)'!I$62 -> 0.038585281 | J37: ='SECLE10 Sales by Year (18-20)'!J37/'SECLE10 Sales by Year (18-20)'!J$62 -> 0.038041864 | K37: ='SECLE10 Sales by Year (18-20)'!K37/'SECLE10 Sales by Year (18-20)'!K$62 -> 0.038395869 | L37: ='SECLE10 Sales by Year (18-20)'!L37/'SECLE10 Sales by Year (18-20)'!L$62 -> 0.039767062 | ... P37: ='SECLE10 Sales by Year (18-20)'!P37/'SECLE10 Sales by Year (18-20)'!P$62 -> 0.038406801
A38: =+A37+1 -> 28 | B38: Waco | C38: =+C33 -> 2020 | D38: ='SECLE10 Sales by Year (18-20)'!D38/'SECLE10 Sales by Year (18-20)'!D63 -> 0.037259976 | E38: ='SECLE10 Sales by Year (18-20)'!E38/'SECLE10 Sales by Year (18-20)'!E63 -> 0.037028646 | F38: ='SECLE10 Sales by Year (18-20)'!F38/'SECLE10 Sales by Year (18-20)'!F63 -> 0.038368038 | G38: ='SECLE10 Sales by Year (18-20)'!G38/'SECLE10 Sales by Year (18-20)'!G63 -> 0.037920189 | H38: ='SECLE10 Sales by Year (18-20)'!H38/'SECLE10 Sales by Year (18-20)'!H63 -> 0.038720111 | I38: ='SECLE10 Sales by Year (18-20)'!I38/'SECLE10 Sales by Year (18-20)'!I63 -> 0.039291804 | J38: ='SECLE10 Sales by Year (18-20)'!J38/'SECLE10 Sales by Year (18-20)'!J63 -> 0.039127267 | K38: ='SECLE10 Sales by Year (18-20)'!K38/'SECLE10 Sales by Year (18-20)'!K63 -> 0.040083572 | ... P38: ='SECLE10 Sales by Year (18-20)'!P38/'SECLE10 Sales by Year (18-20)'!P63 -> 0.038803015
A39: =+A38+1 -> 29 | B39: Waco | C39: Total | D39: ='SECLE10 Sales by Year (18-20)'!D39/'SECLE10 Sales by Year (18-20)'!D64 -> 0.037485931 | E39: ='SECLE10 Sales by Year (18-20)'!E39/'SECLE10 Sales by Year (18-20)'!E64 -> 0.037241356 | F39: ='SECLE10 Sales by Year (18-20)'!F39/'SECLE10 Sales by Year (18-20)'!F64 -> 0.037928951 | G39: ='SECLE10 Sales by Year (18-20)'!G39/'SECLE10 Sales by Year (18-20)'!G64 -> 0.037019603 | H39: ='SECLE10 Sales by Year (18-20)'!H39/'SECLE10 Sales by Year (18-20)'!H64 -> 0.037391153 | I39: ='SECLE10 Sales by Year (18-20)'!I39/'SECLE10 Sales by Year (18-20)'!I64 -> 0.038489288 | J39: ='SECLE10 Sales by Year (18-20)'!J39/'SECLE10 Sales by Year (18-20)'!J64 -> 0.038256567 | K39: ='SECLE10 Sales by Year (18-20)'!K39/'SECLE10 Sales by Year (18-20)'!K64 -> 0.039297679 | ... P39: ='SECLE10 Sales by Year (18-20)'!P39/'SECLE10 Sales by Year (18-20)'!P64 -> 0.038338298
A40: =+A39+1 -> 30
A41: =+A40+1 -> 31 | B41: Abilene | C41: =+C36 -> 2018 | D41: ='SECLE10 Sales by Year (18-20)'!D41/'SECLE10 Sales by Year (18-20)'!D61 -> 0.030279246 | E41: ='SECLE10 Sales by Year (18-20)'!E41/'SECLE10 Sales by Year (18-20)'!E$61 -> 0.028242975 | F41: ='SECLE10 Sales by Year (18-20)'!F41/'SECLE10 Sales by Year (18-20)'!F$61 -> 0.027952919 | G41: ='SECLE10 Sales by Year (18-20)'!G41/'SECLE10 Sales by Year (18-20)'!G$61 -> 0.028268815 | H41: ='SECLE10 Sales by Year (18-20)'!H41/'SECLE10 Sales by Year (18-20)'!H$61 -> 0.030050432 | I41: ='SECLE10 Sales by Year (18-20)'!I41/'SECLE10 Sales by Year (18-20)'!I$61 -> 0.03051303 | J41: ='SECLE10 Sales by Year (18-20)'!J41/'SECLE10 Sales by Year (18-20)'!J$61 -> 0.031075552 | K41: ='SECLE10 Sales by Year (18-20)'!K41/'SECLE10 Sales by Year (18-20)'!K$61 -> 0.030553026 | L41: ='SECLE10 Sales by Year (18-20)'!L41/'SECLE10 Sales by Year (18-20)'!L$61 -> 0.029581242 | ... P41: ='SECLE10 Sales by Year (18-20)'!P41/'SECLE10 Sales by Year (18-20)'!P$61 -> 0.029509556
A42: =+A41+1 -> 32 | B42: Abilene | C42: =+C37 -> 2019 | D42: ='SECLE10 Sales by Year (18-20)'!D42/'SECLE10 Sales by Year (18-20)'!D62 -> 0.029432448 | E42: ='SECLE10 Sales by Year (18-20)'!E42/'SECLE10 Sales by Year (18-20)'!E$62 -> 0.02964315 | F42: ='SECLE10 Sales by Year (18-20)'!F42/'SECLE10 Sales by Year (18-20)'!F$62 -> 0.02827076 | G42: ='SECLE10 Sales by Year (18-20)'!G42/'SECLE10 Sales by Year (18-20)'!G$62 -> 0.028471199 | H42: ='SECLE10 Sales by Year (18-20)'!H42/'SECLE10 Sales by Year (18-20)'!H$62 -> 0.028458161 | I42: ='SECLE10 Sales by Year (18-20)'!I42/'SECLE10 Sales by Year (18-20)'!I$62 -> 0.027782379 | J42: ='SECLE10 Sales by Year (18-20)'!J42/'SECLE10 Sales by Year (18-20)'!J$62 -> 0.029639292 | K42: ='SECLE10 Sales by Year (18-20)'!K42/'SECLE10 Sales by Year (18-20)'!K$62 -> 0.031753512 | L42: ='SECLE10 Sales by Year (18-20)'!L42/'SECLE10 Sales by Year (18-20)'!L$62 -> 0.030186607 | ... P42: ='SECLE10 Sales by Year (18-20)'!P42/'SECLE10 Sales by Year (18-20)'!P$62 -> 0.029477077
...

Sheet SECLE10 Sales by Year (18-20)
B1: PUC DOCKET NO.
B2: ONCOR ELECTRIC DELIVERY COMPANY
B3: WEATHER WEIGHTS
B4: =+'SECLE10 Seasonal Weights'!B4:P4 -> FOR THE TEST YEAR ENDING DECEMBER 31, 2021
B6: SPONSOR: D. E. NELSON
B8: SECONDARY SERVICE LESS THAN OR EQUAL TO 10 KW SALES BY YEAR
A9: Line | B9: (a) | C9: (b) | D9: (c) | E9: (d) | F9: (e) | G9: (f) | H9: (g) | I9: (h) | J9: (i) | K9: (j) | L9: (k) | M9: (l) | N9: (m) | O9: (n) | P9: (o)
A10: No. | B10: Weather Station | C10: Year | D10: 36892 | E10: 36923 | F10: 36951 | G10: 36982 | H10: 37012 | I10: 37043 | J10: 37073 | K10: 37104 | L10: 37135 | M10: 37165 | N10: 37196 | O10: 37226 | P10: Annual
A11: 1 | B11: Dallas-Fort Worth | C11: =+'SECLE10 Weights by Year (18-20)'!C11 -> 2018 | D11: 106704.65 | E11: 98569.826 | F11: 89926.302 | G11: 82140.841 | H11: 80006.008 | I11: 97041.623 | J11: 110777.14 | K11: 109709.39 | L11: 103271.13 | M11: 89470.744 | N11: 79562.5 | O11: 89506.525 | P11: =SUM(D11:O11) -> 1136686.7
A12: =+A11+1 -> 2 | B12: Dallas-Fort Worth | C12: =+'SECLE10 Weights by Year (18-20)'!C12 -> 2019 | D12: 97973.462 | E12: 92638.84 | F12: 91168.667 | G12: 79931.245 | H12: 79649.588 | I12: 88323.492 | J12: 96969.843 | K12: 104030.23 | L12: 111369 | M12: 100336.73 | N12: 84564.349 | O12: 89131.052 | P12: =SUM(D12:O12) -> 1116086.5
A13: =+A12+1 -> 3 | B13: Dallas-Fort Worth | C13: =+'SECLE10 Weights by Year (18-20)'!C13 -> 2020 | D13: 92306.882 | E13: 90883.33 | F13: 86078.602 | G13: 77172.508 | H13: 77341.101 | I13: 89373.61 | J13: 102664.33 | K13: 106801.64 | L13: 102271.47 | M13: 87699.781 | N13: 85845.558 | O13: 85161.572 | P13: =SUM(D13:O13) -> 1083600.4
A14: =+A13+1 -> 4 | B14: Dallas-Fort Worth | C14: Total | D14: =SUM(D11:D13) -> 296984.99 | E14: =SUM(E11:E13) -> 282092 | F14: =SUM(F11:F13) -> 267173.57 | G14: =SUM(G11:G13) -> 239244.59 | H14: =SUM(H11:H13) -> 236996.7 | I14: =SUM(I11:I13) -> 274738.73 | J14: =SUM(J11:J13) -> 310411.31 | K14: =SUM(K11:K13) -> 320541.26 | ... O14: =SUM(O11:O13) -> 263799.15 | P14: =SUM(D14:O14) -> 3336373.6
A15: =+A14+1 -> 5
A16: =+A15+1 -> 6 | B16: Lufkin | C16: =+C11 -> 2018 | D16: 6744.049 | E16: 5967.152 | F16: 4966.731 | G16: 4776.709 | H16: 4781.639 | I16: 6318.014 | J16: 7111.526 | K16: 7194.296 | L16: 6781.529 | M16: 5681.549 | N16: 4761.498 | O16: 5496.064 | P16: =SUM(D16:O16) -> 70580.756
A17: =+A16+1 -> 7 | B17: Lufkin | C17: =+C12 -> 2019 | D17: 5647.595 | E17: 5933.512 | F17: 5340.187 | G17: 4685.696 | H17: 4810.345 | I17: 5794.6 | J17: 6370.883 | K17: 6766.26 | L17: 7208.85 | M17: 6289.772 | N17: 4977.742 | O17: 5259.084 | P17: =SUM(D17:O17) -> 69084.526
A18: =+A17+1 -> 8 | B18: Lufkin | C18: =+C13 -> 2020 | D18: 5496.146 | E18: 5529.246 | F18: 5125.017 | G18: 4565.566 | H18: 4615.081 | I18: 5608.947 | J18: 6762.726 | K18: 6961.712 | L18: 6777.979 | M18: 5426.508 | N18: 5033.961 | O18: 4991.725 | P18: =SUM(D18:O18) -> 66894.614
A19: =+A18+1 -> 9 | B19: Lufkin | C19: Total | D19: =SUM(D16:D18) -> 17887.79 | E19: =SUM(E16:E18) -> 17429.91 | F19: =SUM(F16:F18) -> 15431.935 | G19: =SUM(G16:G18) -> 14027.971 | H19: =SUM(H16:H18) -> 14207.065 | I19: =SUM(I16:I18) -> 17721.561 | J19: =SUM(J16:J18) -> 20245.135 | K19: =SUM(K16:K18) -> 20922.268 | ... O19: =SUM(O16:O18) -> 15746.873 | P19: =SUM(D19:O19) -> 206559.9
A20: =+A19+1 -> 10
A21: =+A20+1 -> 11 | B21: Austin | C21: =+C16 -> 2018 | D21: 6173.187 | E21: 5582.964 | F21: 4759.524 | G21: 4510.749 | H21: 4416.447 | I21: 5443.192 | J21: 6084.373 | K21: 6209.476 | L21: 6094.522 | M21: 5158.475 | N21: 4607.055 | O21: 5160.386 | P21: =SUM(D21:O21) -> 64200.35
A22: =+A21+1 -> 12 | B22: Austin | C22: =+C17 -> 2019 | D22: 5412.232 | E22: 5466.214 | F22: 5053.771 | G22: 4514.053 | H22: 4561.797 | I22: 5121.493 | J22: 5608.006 | K22: 6004.966 | L22: 6426.167 | M22: 5811.483 | N22: 4908.522 | O22: 5029.19 | P22: =SUM(D22:O22) -> 63917.894
A23: =+A22+1 -> 13 | B23: Austin | C23: =+C18 -> 2020 | D23: 5195.848 | E23: 5019.693 | F23: 4892.361 | G23: 4321.713 | H23: 4359.938 | I23: 5138.534 | J23: 5882.8 | K23: 6102.92 | L23: 6113.986 | M23: 5135.74 | N23: 5081.602 | O23: 4956.089 | P23: =SUM(D23:O23) -> 62201.224
A24: =+A23+1 -> 14 | B24: Austin | C24: Total | D24: =SUM(D21:D23) -> 16781.267 | E24: =SUM(E21:E23) -> 16068.871 | F24: =SUM(F21:F23) -> 14705.656 | G24: =SUM(G21:G23) -> 13346.515 | H24: =SUM(H21:H23) -> 13338.182 | I24: =SUM(I21:I23) -> 15703.219 | J24: =SUM(J21:J23) -> 17575.179 | K24: =SUM(K21:K23) -> 18317.362 | ... O24: =SUM(O21:O23) -> 15145.665 | P24: =SUM(D24:O24) -> 190319.47
A25: =+A24+1 -> 15
A26: =+A25+1 -> 16 | B26: Killeen | C26: =+C21 -> 2018 | D26: 5875.359 | E26: 5278.964 | F26: 4686.244 | G26: 4325.163 | H26: 4253.364 | I26: 5336.437 | J26: 6001.543 | K26: 6141.9 | L26: 5955.542 | M26: 5061.751 | N26: 4487.947 | O26: 5131.87 | P26: =SUM(D26:O26) -> 62536.084
A27: =+A26+1 -> 17 | B27: Killeen | C27: =+C22 -> 2019 | D27: 5404.862 | E27: 5466.297 | F27: 5166.905 | G27: 4533.73 | H27: 4556.597 | I27: 5192.19 | J27: 5657.002 | K27: 6104.809 | L27: 6476.22 | M27: 5757.149 | N27: 4798.95 | O27: 4968.452 | P27: =SUM(D27:O27) -> 64083.163
A28: =+A27+1 -> 18 | B28: Killeen | C28: =+C23 -> 2020 | D28: 5207.917 | E28: 4978.599 | F28: 4818.625 | G28: 4252.058 | H28: 4343.66 | I28: 5085.531 | J28: 5873.424 | K28: 6116.31 | L28: 5991.203 | M28: 4926.503 | N28: 4862.943 | O28: 4696.445 | P28: =SUM(D28:O28) -> 61153.218
A29: =+A28+1 -> 19 | B29: Killeen | C29: Total | D29: =SUM(D26:D28) -> 16488.138 | E29: =SUM(E26:E28) -> 15723.86 | F29: =SUM(F26:F28) -> 14671.774 | G29: =SUM(G26:G28) -> 13110.951 | H29: =SUM(H26:H28) -> 13153.621 | I29: =SUM(I26:I28) -> 15614.158 | J29: =SUM(J26:J28) -> 17531.969 | K29: =SUM(K26:K28) -> 18363.019 | ... O29: =SUM(O26:O28) -> 14796.767 | P29: =SUM(D29:O29) -> 187772.46
A30: =+A29+1 -> 20
A31: =+A30+1 -> 21 | B31: Longview | C31: =+C26 -> 2018 | D31: 7750.269 | E31: 7157.316 | F31: 6076.644 | G31: 5545.205 | H31: 5495.096 | I31: 7276.637 | J31: 8586.945 | K31: 8656.203 | L31: 8255.843 | M31: 6655.019 | N31: 5536.999 | O31: 6357.647 | P31: =SUM(D31:O31) -> 83349.823
A32: =+A31+1 -> 22 | B32: Longview | C32: =+C27 -> 2019 | D32: 6765.006 | E32: 7002.657 | F32: 6572.155 | G32: 5626.219 | H32: 5556.395 | I32: 6532.857 | J32: 7357.721 | K32: 8088.545 | L32: 8816.834 | M32: 7671.879 | N32: 5913.327 | O32: 6207.381 | P32: =SUM(D32:O32) -> 82110.976
A33: =+A32+1 -> 23 | B33: Longview | C33: =+C28 -> 2020 | D33: 6596.435 | E33: 6590.63 | F33: 6098.436 | G33: 5298.612 | H33: 5363.808 | I33: 6532.909 | J33: 7937.401 | K33: 8262.583 | L33: 7899.172 | M33: 6301.444 | N33: 5910.081 | O33: 5929.49 | P33: =SUM(D33:O33) -> 78721.001
A34: =+A33+1 -> 24 | B34: Longview | C34: Total | D34: =SUM(D31:D33) -> 21111.71 | E34: =SUM(E31:E33) -> 20750.603 | F34: =SUM(F31:F33) -> 18747.235 | G34: =SUM(G31:G33) -> 16470.036 | H34: =SUM(H31:H33) -> 16415.299 | I34: =SUM(I31:I33) -> 20342.403 | J34: =SUM(J31:J33) -> 23882.067 | K34: =SUM(K31:K33) -> 25007.331 | ... O34: =SUM(O31:O33) -> 18494.518 | P34: =SUM(D34:O34) -> 244181.8
A35: =+A34+1 -> 25
A36: =+A35+1 -> 26 | B36: Waco | C36: =+C31 -> 2018 | D36: 6541.039 | E36: 5998.444 | F36: 5585.539 | G36: 4826.159 | H36: 4768.378 | I36: 6087.819 | J36: 7051.491 | K36: 7242.883 | L36: 6889.922 | M36: 5775.266 | N36: 4984.813 | O36: 5590.916 | P36: =SUM(D36:O36) -> 71342.669
A37: =+A36+1 -> 27 | B37: Waco | C37: =+C32 -> 2019 | D37: 6002.635 | E37: 6090.196 | F37: 5829.291 | G37: 5040.02 | H37: 5035.364 | I37: 5696.197 | J37: 6286.391 | K37: 6843.889 | L37: 7512.982 | M37: 6685.215 | N37: 5371.891 | O37: 5582.753 | P37: =SUM(D37:O37) -> 71976.824
A38: =+A37+1 -> 28 | B38: Waco | C38: =+C33 -> 2020 | D38: 5720.541 | E38: 5590.48 | F38: 5493.448 | G38: 4843.835 | H38: 4965.883 | I38: 5829.012 | J38: 6752.666 | K38: 7182.814 | L38: 6941.62 | M38: 5696.162 | N38: 5467.482 | O38: 5248.711 | P38: =SUM(D38:O38) -> 69732.654
A39: =+A38+1 -> 29 | B39: Waco | C39: Total | D39: =SUM(D36:D38) -> 18264.215 | E39: =SUM(E36:E38) -> 17679.12 | F39: =SUM(F36:F38) -> 16908.278 | G39: =SUM(G36:G38) -> 14710.014 | H39: =SUM(H36:H38) -> 14769.625 | I39: =SUM(I36:I38) -> 17613.028 | J39: =SUM(J36:J38) -> 20090.548 | K39: =SUM(K36:K38) -> 21269.586 | ... O39: =SUM(O36:O38) -> 16422.38 | P39: =SUM(D39:O39) -> 213052.15
A40: =+A39+1 -> 30
A41: =+A40+1 -> 31 | B41: Abilene | C41: =+C36 -> 2018 | D41: 5235.079 | E41: 4718.941 | F41: 4209.338 | G41: 3808.194 | H41: 3995.324 | I41: 4931.838 | J41: 5821.12 | K41: 5615.689 | L41: 5074.439 | M41: 4106.95 | N41: 3800.796 | O41: 4337.437 | P41: =SUM(D41:O41) -> 55655.145
A42: =+A41+1 -> 32 | B42: Abilene | C42: =+C37 -> 2019 | D42: 4732.878 | E42: 4643.793 | F42: 4297.827 | G42: 3840.941 | H42: 3807.659 | I42: 4101.406 | J42: 4897.872 | K42: 5659.919 | L42: 5702.997 | M42: 4849.788 | N42: 4239.761 | O42: 4467.103 | P42: =SUM(D42:O42) -> 55241.944
...
