Workbook
Name a: #REF!
Name HOURLY: [1]HOURLY!$A$1:$G$745
Name rngBilled: OFFSET([2]Sheet2!$A$2,0,0,[2]Sheet2!$B$1,9)
Name rngYear: OFFSET('[3]Daily Actual_August'!$A$2,0,0,'[3]Daily Actual_August'!$C$1,8)

Sheet RES Spline Model
B1: 2022 RATE CASE
B2: ONCOR ELECTRIC DELIVERY COMPANY LLC
B3: ADJUSTED WEATHER STATION DATA
B4: FOR THE TEST YEAR ENDING DECEMBER 31, 2021
B6: SPONSOR: D. E. NELSON
A8: Line
A9: No. | B9: (a) | C9: (b) | D9: (c) | E9: (d) | F9: (e)
A10: 1 | B10: Model: | C10: Residential Spline
A11: =+A10+1 -> 2 | B11: After Corrective Procedures for Autocorrelation
A12: =+A11+1 -> 3 | B12: Dependent Variable: | C12: ResDMWH
A13: =+A12+1 -> 4 | B13: Estimation Begin Date: | C13: 43101
A14: =+A13+1 -> 5 | B14: Estimation End Date: | C14: 44196
A15: =+A14+1 -> 6
A16: =+A15+1 -> 7 | B16: Variable | C16: Coefficient | D16: StdErr | E16: T-Stat | F16: P-Value
A17: =+A16+1 -> 8 | B17: CONST | C17: 86138.925 | D17: 3082.935 | E17: 27.941 | F17: 0
A18: =+A17+1 -> 9 | B18: Calendar_18_20.DLSav | C18: -3331.062 | D18: 1639.162 | E18: -2.032 | F18: 0.0424
A19: =+A18+1 -> 10 | B19: Calendar_18_20.Monday | C19: -6077.632 | D19: 519.686 | E19: -11.695 | F19: 0
A20: =+A19+1 -> 11 | B20: Calendar_18_20.Tuesday | C20: -6407.28 | D20: 630.287 | E20: -10.166 | F20: 0
A21: =+A20+1 -> 12 | B21: Calendar_18_20.Wednesday | C21: -5849.677 | D21: 650.302 | E21: -8.995 | F21: 0
A22: =+A21+1 -> 13 | B22: Calendar_18_20.Thursday | C22: -5547.793 | D22: 651.998 | E22: -8.509 | F22: 0
A23: =+A22+1 -> 14 | B23: Calendar_18_20.Friday | C23: -8280.867 | D23: 634.038 | E23: -13.061 | F23: 0
A24: =+A23+1 -> 15 | B24: Calendar_18_20.Saturday | C24: -3571.486 | D24: 502.676 | E24: -7.105 | F24: 0
A25: =+A24+1 -> 16 | B25: Calendar_18_20.MLK | C25: 9616.119 | D25: 3001.039 | E25: 3.204 | F25: 0.0014
A26: =+A25+1 -> 17 | B26: Calendar_18_20.PresDay | C26: -7757.525 | D26: 2989.484 | E26: -2.595 | F26: 0.0096
A27: =+A26+1 -> 18 | B27: Calendar_18_20.MemDay | C27: 7467.642 | D27: 2953.308 | E27: 2.529 | F27: 0.0116
A28: =+A27+1 -> 19 | B28: Calendar_18_20.LaborDay | C28: 8351.514 | D28: 2956.906 | E28: 2.824 | F28: 0.0048
... A63: =+A62+1 -> 54 | B63: AR(8) | C63: 0.098 | D63: 0.031 | E63: 3.15 | F63: 0.0017
A64: =+A63+1 -> 55
A65: =+A64+1 -> 56 | B65: Model Statistics
A66: =+A65+1 -> 57 | B66: Adjusted Observations | C66: 1088
A67: =+A66+1 -> 58 | B67: Deg. of Freedom for Error | C67: 1041
A68: =+A67+1 -> 59 | B68: R-Squared | C68: 0.98
A69: =+A68+1 -> 60 | B69: Adjusted R-Squared | C69: 0.979
A70: =+A69+1 -> 61 | B70: F-Statistic | C70: 1112.298
A71: =+A70+1 -> 62 | B71: Prob (F-Statistic) | C71: 0
A72: =+A71+1 -> 63 | B72: Model Sum of Squares | C72: 1.6609065e+12
A73: =+A72+1 -> 64 | B73: Sum of Squared Errors | C73: 3.3792246e+10
A74: =+A73+1 -> 65 | B74: Mean Squared Error | C74: 32461332
A75: =+A74+1 -> 66 | B75: Std. Error of Regression | C75: 5697.48
A76: =+A75+1 -> 67 | B76: Mean Abs. Dev. (MAD) | C76: 4229.55
...

Sheet RES Spline Graph
B1: =+'RES Spline Model'!B1:F1 -> 2022 RATE CASE
B2: =+'RES Spline Model'!B2:F2 -> ONCOR ELECTRIC DELIVERY COMPANY LLC
B3: =+'RES Spline Model'!B3:F3 -> ADJUSTED WEATHER STATION DATA
B4: =+'RES Spline Model'!B4:F4 -> FOR THE TEST YEAR ENDING DECEMBER 31, 2021
B6: =+'RES Spline Model'!B6:F6 -> SPONSOR: D. E. NELSON
A8: Line
A9: No.
A10: 1 | B10: Residential Spline Model
A11: =+A10+1 -> 2 | B11: After Corrective Procedures for Autocorrelation
A12: =+A11+1 -> 3
A13: =+A12+1 -> 4
A14: =+A13+1 -> 5
A15: =+A14+1 -> 6
A16: =+A15+1 -> 7
A17: =+A16+1 -> 8
A18: =+A17+1 -> 9
A19: =+A18+1 -> 10
A20: =+A19+1 -> 11
A21: =+A20+1 -> 12
A22: =+A21+1 -> 13
A23: =+A22+1 -> 14
... A37: =+A36+1 -> 28

Sheet GSS Spline Model
B1: =+'RES Spline Model'!B1:F1 -> 2022 RATE CASE
B2: =+'RES Spline Model'!B2:F2 -> ONCOR ELECTRIC DELIVERY COMPANY LLC
B3: =+'RES Spline Model'!B3:F3 -> ADJUSTED WEATHER STATION DATA
B4: =+'RES Spline Model'!B4:F4 -> FOR THE TEST YEAR ENDING DECEMBER 31, 2021
B6: =+'RES Spline Model'!B6:F6 -> SPONSOR: D. E. NELSON
A8: Line
A9: No. | B9: (a) | C9: (b) | D9: (c) | E9: (d) | F9: (e)
A10: 1 | B10: Model: | C10: Secondary Service Less Than or Equal to 10 KW Spline
A11: =+A10+1 -> 2 | B11: =+'RES Spline Model'!B11 -> After Corrective Procedures for Autocorrelation
A12: =+A11+1 -> 3 | B12: Dependent Variable: | C12: GSSDMWH
A13: =+A12+1 -> 4 | B13: Estimation Begin Date: | C13: =+'RES Spline Model'!C13 -> 43101
A14: =+A13+1 -> 5 | B14: Estimation End Date: | C14: =+'RES Spline Model'!C14 -> 44196
A15: =+A14+1 -> 6
A16: =+A15+1 -> 7 | B16: Variable | C16: Coefficient | D16: StdErr | E16: T-Stat | F16: P-Value
A17: =+A16+1 -> 8 | B17: CONST | C17: 4400.03 | D17: 79.943 | E17: 55.039 | F17: 0
A18: =+A17+1 -> 9 | B18: Calendar_18_20.DLSav | C18: -90.67 | D18: 44.611 | E18: -2.032 | F18: 0.0424
A19: =+A18+1 -> 10 | B19: Calendar_18_20.Monday | C19: 460.652 | D19: 21.255 | E19: 21.673 | F19: 0
A20: =+A19+1 -> 11 | B20: Calendar_18_20.Tuesday | C20: 512.407 | D20: 29.529 | E20: 17.353 | F20: 0
A21: =+A20+1 -> 12 | B21: Calendar_18_20.Wednesday | C21: 553.968 | D21: 32.214 | E21: 17.197 | F21: 0
A22: =+A21+1 -> 13 | B22: Calendar_18_20.Thursday | C22: 559.887 | D22: 32.224 | E22: 17.375 | F22: 0
A23: =+A22+1 -> 14 | B23: Calendar_18_20.Friday | C23: 518.592 | D23: 29.571 | E23: 17.537 | F23: 0
A24: =+A23+1 -> 15 | B24: Calendar_18_20.Saturday | C24: 194.073 | D24: 21.123 | E24: 9.188 | F24: 0
A25: =+A24+1 -> 16 | B25: Calendar_18_20.MLK | C25: 118.848 | D25: 63.142 | E25: 1.882 | F25: 0.0601
A26: =+A25+1 -> 17 | B26: Calendar_18_20.PresDay | C26: -171.739 | D26: 52.902 | E26: -3.246 | F26: 0.0012
A27: =+A26+1 -> 18 | B27: Calendar_18_20.GoodFri | C27: -113.063 | D27: 51.779 | E27: -2.184 | F27: 0.0292
A28: =+A27+1 -> 19 | B28: Calendar_18_20.MemDay | C28: -391.889 | D28: 51.626 | E28: -7.591 | F28: 0
... A74: =+A73+1 -> 65 | B74: AR(22) | C74: -0.177 | D74: 0.03 | E74: -5.859 | F74: 0
A75: =+A74+1 -> 66
A76: =+A75+1 -> 67 | B76: Model Statistics
A77: =+A76+1 -> 68 | B77: Adjusted Observations | C77: 1074
A78: =+A77+1 -> 69 | B78: Deg. of Freedom for Error | C78: 1016
A79: =+A78+1 -> 70 | B79: R-Squared | C79: 0.968
A80: =+A79+1 -> 71 | B80: Adjusted R-Squared | C80: 0.966
A81: =+A80+1 -> 72 | B81: F-Statistic | C81: 540.323
A82: =+A81+1 -> 73 | B82: Prob (F-Statistic) | C82: 0
A83: =+A82+1 -> 74 | B83: Model Sum of Squares | C83: 4.5005898e+08
A84: =+A83+1 -> 75 | B84: Sum of Squared Errors | C84: 14846862
A85: =+A84+1 -> 76 | B85: Mean Squared Error | C85: 14613.05
A86: =+A85+1 -> 77 | B86: Std. Error of Regression | C86: 120.88
A87: =+A86+1 -> 78 | B87: Mean Abs. Dev. (MAD) | C87: 89.79
...

Sheet GSS Spline Graph
B1: =+'RES Spline Model'!B1:F1 -> 2022 RATE CASE
B2: =+'RES Spline Model'!B2:F2 -> ONCOR ELECTRIC DELIVERY COMPANY LLC
B3: =+'RES Spline Model'!B3:F3 -> ADJUSTED WEATHER STATION DATA
B4: =+'RES Spline Model'!B4:F4 -> FOR THE TEST YEAR ENDING DECEMBER 31, 2021
B6: =+'RES Spline Model'!B6:F6 -> SPONSOR: D. E. NELSON
A8: Line
A9: No.
A10: 1 | B10: Secondary Service Less Than or Equal to 10 KW Spline Model
A11: =+A10+1 -> 2 | B11: =+'RES Spline Graph'!B11:H11 -> After Corrective Procedures for Autocorrelation
A12: =+A11+1 -> 3
A13: =+A12+1 -> 4
A14: =+A13+1 -> 5
A15: =+A14+1 -> 6
A16: =+A15+1 -> 7
A17: =+A16+1 -> 8
A18: =+A17+1 -> 9
A19: =+A18+1 -> 10
A20: =+A19+1 -> 11
A21: =+A20+1 -> 12
A22: =+A21+1 -> 13
A23: =+A22+1 -> 14
... A37: =+A36+1 -> 28

Sheet GSL Spline Model
B1: =+'RES Spline Model'!B1:F1 -> 2022 RATE CASE
B2: =+'RES Spline Model'!B2:F2 -> ONCOR ELECTRIC DELIVERY COMPANY LLC
B3: =+'RES Spline Model'!B3:F3 -> ADJUSTED WEATHER STATION DATA
B4: =+'RES Spline Model'!B4:F4 -> FOR THE TEST YEAR ENDING DECEMBER 31, 2021
B6: =+'RES Spline Model'!B6:F6 -> SPONSOR: D. E. NELSON
A8: Line
A9: No. | B9: (a) | C9: (b) | D9: (c) | E9: (d) | F9: (e)
A10: 1 | B10: Model: | C10: Secondary Service Greater Than 10 KW Spline
A11: =+A10+1 -> 2 | B11: =+'RES Spline Model'!B11 -> After Corrective Procedures for Autocorrelation
A12: =+A11+1 -> 3 | B12: Dependent Variable: | C12: GSLDMWH
A13: =+A12+1 -> 4 | B13: Estimation Begin Date: | C13: =+'RES Spline Model'!C13 -> 43101
A14: =+A13+1 -> 5 | B14: Estimation End Date: | C14: =+'RES Spline Model'!C14 -> 44196
A15: =+A14+1 -> 6
A16: =+A15+1 -> 7 | B16: Variable | C16: Coefficient | D16: StdErr | E16: T-Stat | F16: P-Value
A17: =+A16+1 -> 8 | B17: CONST | C17: 107015.55 | D17: 7293.871 | E17: 14.672 | F17: 0
A18: =+A17+1 -> 9 | B18: Calendar_18_20.DLSav | C18: -1871.515 | D18: 1094.891 | E18: -1.709 | F18: 0.0877
A19: =+A18+1 -> 10 | B19: Calendar_18_20.Monday | C19: 20859.367 | D19: 297.762 | E19: 70.054 | F19: 0
A20: =+A19+1 -> 11 | B20: Calendar_18_20.Tuesday | C20: 22225.522 | D20: 398.717 | E20: 55.743 | F20: 0
A21: =+A20+1 -> 12 | B21: Calendar_18_20.Wednesday | C21: 23029.763 | D21: 414.797 | E21: 55.52 | F21: 0
A22: =+A21+1 -> 13 | B22: Calendar_18_20.Thursday | C22: 22817.796 | D22: 414.796 | E22: 55.01 | F22: 0
A23: =+A22+1 -> 14 | B23: Calendar_18_20.Friday | C23: 20521.407 | D23: 400.103 | E23: 51.29 | F23: 0
A24: =+A23+1 -> 15 | B24: Calendar_18_20.Saturday | C24: 5694.621 | D24: 291.946 | E24: 19.506 | F24: 0
A25: =+A24+1 -> 16 | B25: Calendar_18_20.MLK | C25: -2403.636 | D25: 1309.612 | E25: -1.835 | F25: 0.0667
A26: =+A25+1 -> 17 | B26: Calendar_18_20.PresDay | C26: -7309.616 | D26: 1297.599 | E26: -5.633 | F26: 0
A27: =+A26+1 -> 18 | B27: Calendar_18_20.GoodFri | C27: -6366.088 | D27: 1290.057 | E27: -4.935 | F27: 0
A28: =+A27+1 -> 19 | B28: Calendar_18_20.MemDay | C28: -18357.56 | D28: 1281.845 | E28: -14.321 | F28: 0
... A62: =+A61+1 -> 53 | B62: AR(10) | C62: 0.077 | D62: 0.031 | E62: 2.429 | F62: 0.0153
A63: =+A62+1 -> 54
A64: =+A63+1 -> 55 | B64: Model Statistics
A65: =+A64+1 -> 56 | B65: Adjusted Observations | C65: 1086
A66: =+A65+1 -> 57 | B66: Deg. of Freedom for Error | C66: 1040
A67: =+A66+1 -> 58 | B67: R-Squared | C67: 0.985
A68: =+A67+1 -> 59 | B68: Adjusted R-Squared | C68: 0.984
A69: =+A68+1 -> 60 | B69: F-Statistic | C69: 1470.775
A70: =+A69+1 -> 61 | B70: Prob (F-Statistic) | C70: 0
A71: =+A70+1 -> 62 | B71: Model Sum of Squares | C71: 5.2153382e+11
A72: =+A71+1 -> 63 | B72: Sum of Squared Errors | C72: 8.1951511e+09
A73: =+A72+1 -> 64 | B73: Mean Squared Error | C73: 7879953
A74: =+A73+1 -> 65 | B74: Std. Error of Regression | C74: 2807.13
A75: =+A74+1 -> 66 | B75: Mean Abs. Dev. (MAD) | C75: 2126.17
...

Sheet GSL Spline Graph
B1: =+'RES Spline Model'!B1:F1 -> 2022 RATE CASE
B2: =+'RES Spline Model'!B2:F2 -> ONCOR ELECTRIC DELIVERY COMPANY LLC
B3: =+'RES Spline Model'!B3:F3 -> ADJUSTED WEATHER STATION DATA
B4: =+'RES Spline Model'!B4:F4 -> FOR THE TEST YEAR ENDING DECEMBER 31, 2021
B6: =+'RES Spline Model'!B6:F6 -> SPONSOR: D. E. NELSON
A8: Line
A9: No.
A10: 1 | B10: Secondary Service Greater Than 10 KW Spline Model
A11: =+A10+1 -> 2 | B11: =+'RES Spline Graph'!B11:H11 -> After Corrective Procedures for Autocorrelation
A12: =+A11+1 -> 3
A13: =+A12+1 -> 4
A14: =+A13+1 -> 5
A15: =+A14+1 -> 6
A16: =+A15+1 -> 7
A17: =+A16+1 -> 8
A18: =+A17+1 -> 9
A19: =+A18+1 -> 10
A20: =+A19+1 -> 11
A21: =+A20+1 -> 12
A22: =+A21+1 -> 13
A23: =+A22+1 -> 14
... A37: =+A36+1 -> 28

Sheet GPLD Spline Model
B1: =+'RES Spline Model'!B1:F1 -> 2022 RATE CASE
B2: =+'RES Spline Model'!B2:F2 -> ONCOR ELECTRIC DELIVERY COMPANY LLC
B3: =+'RES Spline Model'!B3:F3 -> ADJUSTED WEATHER STATION DATA
B4: =+'RES Spline Model'!B4:F4 -> FOR THE TEST YEAR ENDING DECEMBER 31, 2021
B6: =+'RES Spline Model'!B6:F6 -> SPONSOR: D. E. NELSON
A8: Line
A9: No. | B9: (a) | C9: (b) | D9: (c) | E9: (d) | F9: (e)
A10: 1 | B10: Model: | C10: Primary Service Greater Than 10 KW Distribution Spline
A11: =+A10+1 -> 2 | B11: =+'RES Spline Model'!B11 -> After Corrective Procedures for Autocorrelation
A12: =+A11+1 -> 3 | B12: Dependent Variable: | C12: GPLDDMWH
A13: =+A12+1 -> 4 | B13: Estimation Begin Date: | C13: =+'RES Spline Model'!C13 -> 43101
A14: =+A13+1 -> 5 | B14: Estimation End Date: | C14: =+'RES Spline Model'!C14 -> 44196
A15: =+A14+1 -> 6
A16: =+A15+1 -> 7 | B16: Variable | C16: Coefficient | D16: StdErr | E16: T-Stat | F16: P-Value
A17: =+A16+1 -> 8 | B17: CONST | C17: 39076.143 | D17: 813.607 | E17: 48.028 | F17: 0
A18: =+A17+1 -> 9 | B18: Calendar_18_20.DLSav | C18: -872.352 | D18: 242.923 | E18: -3.591 | F18: 0.0004
A19: =+A18+1 -> 10 | B19: Calendar_18_20.Monday | C19: 2557.518 | D19: 53.807 | E19: 47.531 | F19: 0
A20: =+A19+1 -> 11 | B20: Calendar_18_20.Tuesday | C20: 3071.2 | D20: 66.49 | E20: 46.19 | F20: 0
A21: =+A20+1 -> 12 | B21: Calendar_18_20.Wednesday | C21: 3085.973 | D21: 68.938 | E21: 44.764 | F21: 0
A22: =+A21+1 -> 13 | B22: Calendar_18_20.Thursday | C22: 3116.763 | D22: 69.113 | E22: 45.097 | F22: 0
A23: =+A22+1 -> 14 | B23: Calendar_18_20.Friday | C23: 2889.223 | D23: 67.02 | E23: 43.11 | F23: 0
A24: =+A23+1 -> 15 | B24: Calendar_18_20.Saturday | C24: 1161.891 | D24: 52.837 | E24: 21.99 | F24: 0
A25: =+A24+1 -> 16 | B25: Calendar_18_20.MLK | C25: -812.829 | D25: 276.555 | E25: -2.939 | F25: 0.0034
A26: =+A25+1 -> 17 | B26: Calendar_18_20.GoodFri | C26: -410.777 | D26: 277.472 | E26: -1.48 | F26: 0.1391
A27: =+A26+1 -> 18 | B27: Calendar_18_20.MemDay | C27: -2901.889 | D27: 276.961 | E27: -10.478 | F27: 0
A28: =+A27+1 -> 19 | B28: Calendar_18_20.July4th | C28: -2398.616 | D28: 274.363 | E28: -8.742 | F28: 0
... A57: =+A56+1 -> 48 | B57: AR(7) | C57: 0.095 | D57: 0.031 | E57: 3.099 | F57: 0.002
A58: =+A57+1 -> 49
A59: =+A58+1 -> 50 | B59: Model Statistics
A60: =+A59+1 -> 51 | B60: Adjusted Observations | C60: 1089
A61: =+A60+1 -> 52 | B61: Deg. of Freedom for Error | C61: 1048
A62: =+A61+1 -> 53 | B62: R-Squared | C62: 0.953
A63: =+A62+1 -> 54 | B63: Adjusted R-Squared | C63: 0.951
A64: =+A63+1 -> 55 | B64: F-Statistic | C64: 527.706
A65: =+A64+1 -> 56 | B65: Prob (F-Statistic) | C65: 0
A66: =+A65+1 -> 57 | B66: Model Sum of Squares | C66: 7.6615468e+09
A67: =+A66+1 -> 58 | B67: Sum of Squared Errors | C67: 3.8038712e+08
A68: =+A67+1 -> 59 | B68: Mean Squared Error | C68: 362964.81
A69: =+A68+1 -> 60 | B69: Std. Error of Regression | C69: 602.47
A70: =+A69+1 -> 61 | B70: Mean Abs. Dev. (MAD) | C70: 452.2
...

Sheet GPLD Spline Graph
B1: =+'RES Spline Model'!B1:F1 -> 2022 RATE CASE
B2: =+'RES Spline Model'!B2:F2 -> ONCOR ELECTRIC DELIVERY COMPANY LLC
B3: =+'RES Spline Model'!B3:F3 -> ADJUSTED WEATHER STATION DATA
B4: =+'RES Spline Model'!B4:F4 -> FOR THE TEST YEAR ENDING DECEMBER 31, 2021
B6: =+'RES Spline Model'!B6:F6 -> SPONSOR: D. E. NELSON
A8: Line
A9: No.
A10: 1 | B10: Primary Service Greater Than 10 KW Distribution Spline Model
A11: =+A10+1 -> 2 | B11: =+'RES Spline Graph'!B11:H11 -> After Corrective Procedures for Autocorrelation
A12: =+A11+1 -> 3
A13: =+A12+1 -> 4
A14: =+A13+1 -> 5
A15: =+A14+1 -> 6
A16: =+A15+1 -> 7
A17: =+A16+1 -> 8
A18: =+A17+1 -> 9
A19: =+A18+1 -> 10
A20: =+A19+1 -> 11
A21: =+A20+1 -> 12
A22: =+A21+1 -> 13
A23: =+A22+1 -> 14
... A37: =+A36+1 -> 28

Sheet SUBS Spline Model
B1: =+'RES Spline Model'!B1:F1 -> 2022 RATE CASE
B2: =+'RES Spline Model'!B2:F2 -> ONCOR ELECTRIC DELIVERY COMPANY LLC
B3: =+'RES Spline Model'!B3:F3 -> ADJUSTED WEATHER STATION DATA
B4: =+'RES Spline Model'!B4:F4 -> FOR THE TEST YEAR ENDING DECEMBER 31, 2021
B6: =+'RES Spline Model'!B6:F6 -> SPONSOR: D. E. NELSON
A8: Line
A9: No. | B9: (a) | C9: (b) | D9: (c) | E9: (d) | F9: (e)
A10: 1 | B10: Model: | C10: Substation Spline
A11: =+A10+1 -> 2 | B11: =+'RES Spline Model'!B11 -> After Corrective Procedures for Autocorrelation
A12: =+A11+1 -> 3 | B12: Dependent Variable: | C12: SUBSDMWH
A13: =+A12+1 -> 4 | B13: Estimation Begin Date: | C13: =+'RES Spline Model'!C13 -> 43101
A14: =+A13+1 -> 5 | B14: Estimation End Date: | C14: =+'RES Spline Model'!C14 -> 44196
A15: =+A14+1 -> 6
A16: =+A15+1 -> 7 | B16: Variable | C16: Coefficient | D16: StdErr | E16: T-Stat | F16: P-Value
A17: =+A16+1 -> 8 | B17: CONST | C17: 9368.913 | D17: 523.616 | E17: 17.893 | F17: 0
A18: =+A17+1 -> 9 | B18: Calendar_18_20.DLSav | C18: -207.541 | D18: 91.907 | E18: -2.258 | F18: 0.0241
A19: =+A18+1 -> 10 | B19: Calendar_18_20.Monday | C19: 202.392 | D19: 23.731 | E19: 8.528 | F19: 0
A20: =+A19+1 -> 11 | B20: Calendar_18_20.Tuesday | C20: 211.518 | D20: 29.285 | E20: 7.223 | F20: 0
A21: =+A20+1 -> 12 | B21: Calendar_18_20.Wednesday | C21: 200.4 | D21: 30.652 | E21: 6.538 | F21: 0
A22: =+A21+1 -> 13 | B22: Calendar_18_20.Thursday | C22: 200.964 | D22: 30.636 | E22: 6.56 | F22: 0
A23: =+A22+1 -> 14 | B23: Calendar_18_20.Friday | C23: 222.563 | D23: 29.348 | E23: 7.584 | F23: 0
A24: =+A23+1 -> 15 | B24: Calendar_18_20.Saturday | C24: 102.454 | D24: 23.614 | E24: 4.339 | F24: 0
A25: =+A24+1 -> 16 | B25: Calendar_18_20.MemDay | C25: -168.588 | D25: 134.133 | E25: -1.257 | F25: 0.2091
A26: =+A25+1 -> 17 | B26: Calendar_18_20.XMasDay | C26: -300.001 | D26: 132.987 | E26: -2.256 | F26: 0.0243
A27: =+A26+1 -> 18 | B27: Calendar_18_20.NYDay | C27: -424.168 | D27: 162.861 | E27: -2.604 | F27: 0.0093
A28: =+A27+1 -> 19 | B28: DayTypeVars.Apr | C28: 310.638 | D28: 95.407 | E28: 3.256 | F28: 0.0012
... A48: =+A47+1 -> 39 | B48: AR(13) | C48: 0.039 | D48: 0.031 | E48: 1.278 | F48: 0.2014
A49: =+A48+1 -> 40
A50: =+A49+1 -> 41 | B50: Model Statistics
A51: =+A50+1 -> 42 | B51: Adjusted Observations | C51: 1083
A52: =+A51+1 -> 43 | B52: Deg. of Freedom for Error | C52: 1051
A53: =+A52+1 -> 44 | B53: R-Squared | C53: 0.969
A54: =+A53+1 -> 45 | B54: Adjusted R-Squared | C54: 0.968
A55: =+A54+1 -> 46 | B55: F-Statistic | C55: 1057.141
A56: =+A55+1 -> 47 | B56: Prob (F-Statistic) | C56: 0
A57: =+A56+1 -> 48 | B57: Model Sum of Squares | C57: 2.4920669e+09
A58: =+A57+1 -> 49 | B58: Sum of Squared Errors | C58: 79922247
A59: =+A58+1 -> 50 | B59: Mean Squared Error | C59: 76044
A60: =+A59+1 -> 51 | B60: Std. Error of Regression | C60: 275.76
A61: =+A60+1 -> 52 | B61: Mean Abs. Dev. (MAD) | C61: 205.25
...

Sheet SUBS Spline Graph
B1: =+'RES Spline Model'!B1:F1 -> 2022 RATE CASE
B2: =+'RES Spline Model'!B2:F2 -> ONCOR ELECTRIC DELIVERY COMPANY LLC
B3: =+'RES Spline Model'!B3:F3 -> ADJUSTED WEATHER STATION DATA
B4: =+'RES Spline Model'!B4:F4 -> FOR THE TEST YEAR ENDING DECEMBER 31, 2021
B6: =+'RES Spline Model'!B6:F6 -> SPONSOR: D. E. NELSON
A8: Line
A9: No.
A10: 1 | B10: Substation Spline Model
A11: =+A10+1 -> 2 | B11: =+'RES Spline Graph'!B11:H11 -> After Corrective Procedures for Autocorrelation
A12: =+A11+1 -> 3
A13: =+A12+1 -> 4
A14: =+A13+1 -> 5
A15: =+A14+1 -> 6
A16: =+A15+1 -> 7
A17: =+A16+1 -> 8
A18: =+A17+1 -> 9
A19: =+A18+1 -> 10
A20: =+A19+1 -> 11
A21: =+A20+1 -> 12
A22: =+A21+1 -> 13
A23: =+A22+1 -> 14
... A37: =+A36+1 -> 28

Sheet RES B Spline Model
B1: =+'RES Spline Model'!B1:F1 -> 2022 RATE CASE
B2: =+'RES Spline Model'!B2:F2 -> ONCOR ELECTRIC DELIVERY COMPANY LLC
B3: =+'RES Spline Model'!B3:F3 -> ADJUSTED WEATHER STATION DATA
B4: =+'RES Spline Model'!B4:F4 -> FOR THE TEST YEAR ENDING DECEMBER 31, 2021
B6: =+'RES Spline Model'!B6:F6 -> SPONSOR: D. E. NELSON
A8: Line
A9: No. | B9: (a) | C9: (b) | D9: (c) | E9: (d) | F9: (e)
A10: 1 | B10: Model: | C10: Residential Spline (B)
A11: =+A10+1 -> 2 | B11: Before Corrective Procedures for Autocorrelation
A12: =+A11+1 -> 3 | B12: Dependent Variable: | C12: ResDMWH
A13: =+A12+1 -> 4 | B13: Estimation Begin Date: | C13: =+'RES Spline Model'!C13 -> 43101
A14: =+A13+1 -> 5 | B14: Estimation End Date: | C14: =+'RES Spline Model'!C14 -> 44196
A15: =+A14+1 -> 6
A16: =+A15+1 -> 7 | B16: Variable | C16: Coefficient | D16: StdErr | E16: T-Stat | F16: P-Value
A17: =+A16+1 -> 8 | B17: CONST | C17: 85417.521 | D17: 1502.006 | E17: 56.869 | F17: 0
A18: =+A17+1 -> 9 | B18: Calendar_18_20.DLSav | C18: -4891.04 | D18: 1436.633 | E18: -3.405 | F18: 0.0007
A19: =+A18+1 -> 10 | B19: Calendar_18_20.Monday | C19: -6278.34 | D19: 800.123 | E19: -7.847 | F19: 0
A20: =+A19+1 -> 11 | B20: Calendar_18_20.Tuesday | C20: -6649.896 | D20: 783.023 | E20: -8.493 | F20: 0
A21: =+A20+1 -> 12 | B21: Calendar_18_20.Wednesday | C21: -6090.503 | D21: 783.455 | E21: -7.774 | F21: 0
A22: =+A21+1 -> 13 | B22: Calendar_18_20.Thursday | C22: -5565.523 | D22: 786.727 | E22: -7.074 | F22: 0
A23: =+A22+1 -> 14 | B23: Calendar_18_20.Friday | C23: -8313.135 | D23: 793.482 | E23: -10.477 | F23: 0
A24: =+A23+1 -> 15 | B24: Calendar_18_20.Saturday | C24: -3527.317 | D24: 779.992 | E24: -4.522 | F24: 0
A25: =+A24+1 -> 16 | B25: Calendar_18_20.MLK | C25: 10829.206 | D25: 4141.68 | E25: 2.615 | F25: 0.0091
A26: =+A25+1 -> 17 | B26: Calendar_18_20.PresDay | C26: -9497.042 | D26: 4104.19 | E26: -2.314 | F26: 0.0208
A27: =+A26+1 -> 18 | B27: Calendar_18_20.GoodFri | C27: 2785.36 | D27: 4078.499 | E27: 0.683 | F27: 0.4948
A28: =+A27+1 -> 19 | B28: Calendar_18_20.MemDay | C28: 10162.256 | D28: 4089.343 | E28: 2.485 | F28: 0.0131
... A62: =+A61+1 -> 53 | B62: RESDD_18_20.ResCDD85 | C62: -74.264 | D62: 417.214 | E62: -0.178 | F62: 0.8587
A63: =+A62+1 -> 54
A64: =+A63+1 -> 55 | B64: Model Statistics
A65: =+A64+1 -> 56 | B65: Adjusted Observations | C65: 1096
A66: =+A65+1 -> 57 | B66: Deg. of Freedom for Error | C66: 1050
A67: =+A66+1 -> 58 | B67: R-Squared | C67: 0.971
A68: =+A67+1 -> 59 | B68: Adjusted R-Squared | C68: 0.97
A69: =+A68+1 -> 60 | B69: F-Statistic | C69: 792.438
A70: =+A69+1 -> 61 | B70: Prob (F-Statistic) | C70: 0
A71: =+A70+1 -> 62 | B71: Model Sum of Squares | C71: 1.6828354e+12
A72: =+A71+1 -> 63 | B72: Sum of Squared Errors | C72: 4.9551067e+10
A73: =+A72+1 -> 64 | B73: Mean Squared Error | C73: 47191492
A74: =+A73+1 -> 65 | B74: Std. Error of Regression | C74: 6869.61
A75: =+A74+1 -> 66 | B75: Mean Abs. Dev. (MAD) | C75: 5273.67
...

Sheet RES B Spline Graph
B1: =+'RES Spline Model'!B1:F1 -> 2022 RATE CASE
B2: =+'RES Spline Model'!B2:F2 -> ONCOR ELECTRIC DELIVERY COMPANY LLC
B3: =+'RES Spline Model'!B3:F3 -> ADJUSTED WEATHER STATION DATA
B4: =+'RES Spline Model'!B4:F4 -> FOR THE TEST YEAR ENDING DECEMBER 31, 2021
B6: =+'RES Spline Model'!B6:F6 -> SPONSOR: D. E. NELSON
A8: Line
A9: No.
A10: 1 | B10: Residential Spline (B) Model
A11: =+A10+1 -> 2 | B11: Before Corrective Procedures for Autocorrelation
A12: =+A11+1 -> 3
A13: =+A12+1 -> 4
A14: =+A13+1 -> 5
A15: =+A14+1 -> 6
A16: =+A15+1 -> 7
A17: =+A16+1 -> 8
A18: =+A17+1 -> 9
A19: =+A18+1 -> 10
A20: =+A19+1 -> 11
A21: =+A20+1 -> 12
A22: =+A21+1 -> 13
A23: =+A22+1 -> 14
... A37: =+A36+1 -> 28

Sheet GSS B Spline Model
B1: =+'RES Spline Model'!B1:F1 -> 2022 RATE CASE
B2: =+'RES Spline Model'!B2:F2 -> ONCOR ELECTRIC DELIVERY COMPANY LLC
B3: =+'RES Spline Model'!B3:F3 -> ADJUSTED WEATHER STATION DATA
B4: =+'RES Spline Model'!B4:F4 -> FOR THE TEST YEAR ENDING DECEMBER 31, 2021
B6: =+'RES Spline Model'!B6:F6 -> SPONSOR: D. E. NELSON
A8: Line
A9: No. | B9: (a) | C9: (b) | D9: (c) | E9: (d) | F9: (e)
A10: 1 | B10: Model: | C10: Secondary Service Less Than or Equal to 10 KW Spline (B)
A11: =+A10+1 -> 2 | B11: Before Corrective Procedures for Autocorrelation
A12: =+A11+1 -> 3 | B12: Dependent Variable: | C12: GSSDMWH
A13: =+A12+1 -> 4 | B13: Estimation Begin Date: | C13: =+'RES Spline Model'!C13 -> 43101
A14: =+A13+1 -> 5 | B14: Estimation End Date: | C14: =+'RES Spline Model'!C14 -> 44196
A15: =+A14+1 -> 6
A16: =+A15+1 -> 7 | B16: Variable | C16: Coefficient | D16: StdErr | E16: T-Stat | F16: P-Value
A17: =+A16+1 -> 8 | B17: CONST | C17: 4541.191 | D17: 41.449 | E17: 109.562 | F17: 0
A18: =+A17+1 -> 9 | B18: Calendar_18_20.DLSav | C18: -135.194 | D18: 39.589 | E18: -3.415 | F18: 0.0007
A19: =+A18+1 -> 10 | B19: Calendar_18_20.Monday | C19: 469.848 | D19: 22.028 | E19: 21.329 | F19: 0
A20: =+A19+1 -> 11 | B20: Calendar_18_20.Tuesday | C20: 526.689 | D20: 21.569 | E20: 24.419 | F20: 0
A21: =+A20+1 -> 12 | B21: Calendar_18_20.Wednesday | C21: 567.097 | D21: 21.574 | E21: 26.286 | F21: 0
A22: =+A21+1 -> 13 | B22: Calendar_18_20.Thursday | C22: 577.368 | D22: 21.666 | E22: 26.649 | F22: 0
A23: =+A22+1 -> 14 | B23: Calendar_18_20.Friday | C23: 530.527 | D23: 21.849 | E23: 24.281 | F23: 0
A24: =+A23+1 -> 15 | B24: Calendar_18_20.Saturday | C24: 193.608 | D24: 21.483 | E24: 9.012 | F24: 0
A25: =+A24+1 -> 16 | B25: Calendar_18_20.MLK | C25: 143.982 | D25: 113.557 | E25: 1.268 | F25: 0.2051
A26: =+A25+1 -> 17 | B26: Calendar_18_20.PresDay | C26: -181.139 | D26: 113.047 | E26: -1.602 | F26: 0.1094
A27: =+A26+1 -> 18 | B27: Calendar_18_20.GoodFri | C27: -148.032 | D27: 112.399 | E27: -1.317 | F27: 0.1881
A28: =+A27+1 -> 19 | B28: Calendar_18_20.MemDay | C28: -382.758 | D28: 112.64 | E28: -3.398 | F28: 0.0007
... A62: =+A61+1 -> 53 | B62: GSSDD_18_20.GSSCDD85 | C62: -13.255 | D62: 11.887 | E62: -1.115 | F62: 0.2651
A63: =+A62+1 -> 54
A64: =+A63+1 -> 55 | B64: Model Statistics
A65: =+A64+1 -> 56 | B65: Adjusted Observations | C65: 1096
A66: =+A65+1 -> 57 | B66: Deg. of Freedom for Error | C66: 1050
A67: =+A66+1 -> 58 | B67: R-Squared | C67: 0.924
A68: =+A67+1 -> 59 | B68: Adjusted R-Squared | C68: 0.92
A69: =+A68+1 -> 60 | B69: F-Statistic | C69: 281.773
A70: =+A69+1 -> 61 | B70: Prob (F-Statistic) | C70: 0
A71: =+A70+1 -> 62 | B71: Model Sum of Squares | C71: 4.5404858e+08
A72: =+A71+1 -> 63 | B72: Sum of Squared Errors | C72: 37599309
A73: =+A72+1 -> 64 | B73: Mean Squared Error | C73: 35808.87
A74: =+A73+1 -> 65 | B74: Std. Error of Regression | C74: 189.23
A75: =+A74+1 -> 66 | B75: Mean Abs. Dev. (MAD) | C75: 147.38
...

Sheet GSS B Spline Graph
B1: =+'RES Spline Model'!B1:F1 -> 2022 RATE CASE
B2: =+'RES Spline Model'!B2:F2 -> ONCOR ELECTRIC DELIVERY COMPANY LLC
B3: =+'RES Spline Model'!B3:F3 -> ADJUSTED WEATHER STATION DATA
B4: =+'RES Spline Model'!B4:F4 -> FOR THE TEST YEAR ENDING DECEMBER 31, 2021
B6: =+'RES Spline Model'!B6:F6 -> SPONSOR: D. E. NELSON
A8: Line
A9: No.
A10: 1 | B10: Secondary Service Less Than or Equal to 10 KW Spline (B) Model
A11: =+A10+1 -> 2 | B11: Before Corrective Procedures for Autocorrelation
A12: =+A11+1 -> 3
A13: =+A12+1 -> 4
A14: =+A13+1 -> 5
A15: =+A14+1 -> 6
A16: =+A15+1 -> 7
A17: =+A16+1 -> 8
A18: =+A17+1 -> 9
A19: =+A18+1 -> 10
A20: =+A19+1 -> 11
A21: =+A20+1 -> 12
A22: =+A21+1 -> 13
A23: =+A22+1 -> 14
... A37: =+A36+1 -> 28

Sheet GSL B Spline Model
B1: =+'RES Spline Model'!B1:F1 -> 2022 RATE CASE
B2: =+'RES Spline Model'!B2:F2 -> ONCOR ELECTRIC DELIVERY COMPANY LLC
B3: =+'RES Spline Model'!B3:F3 -> ADJUSTED WEATHER STATION DATA
B4: =+'RES Spline Model'!B4:F4 -> FOR THE TEST YEAR ENDING DECEMBER 31, 2021
B6: =+'RES Spline Model'!B6:F6 -> SPONSOR: D. E. NELSON
A8: Line
A9: No. | B9: (a) | C9: (b) | D9: (c) | E9: (d) | F9: (e)
A10: 1 | B10: Model: | C10: Secondary Service Greater Than 10 KW Spline (B)
A11: =+A10+1 -> 2 | B11: Before Corrective Procedures for Autocorrelation
A12: =+A11+1 -> 3 | B12: Dependent Variable: | C12: GSLMWH
A13: =+A12+1 -> 4 | B13: Estimation Begin Date: | C13: =+'RES Spline Model'!C13 -> 43101
A14: =+A13+1 -> 5 | B14: Estimation End Date: | C14: =+'RES Spline Model'!C14 -> 44196
A15: =+A14+1 -> 6
A16: =+A15+1 -> 7 | B16: Variable | C16: Coefficient | D16: StdErr | E16: T-Stat | F16: P-Value
A17: =+A16+1 -> 8 | B17: CONST | C17: 102794.08 | D17: 1064.329 | E17: 96.581 | F17: 0
A18: =+A17+1 -> 9 | B18: Calendar_18_20.DLSav | C18: -4706.226 | D18: 1050.701 | E18: -4.479 | F18: 0
A19: =+A18+1 -> 10 | B19: Calendar_18_20.Monday | C19: 21083.129 | D19: 584.9 | E19: 36.046 | F19: 0
A20: =+A19+1 -> 11 | B20: Calendar_18_20.Tuesday | C20: 22313.449 | D20: 572.714 | E20: 38.961 | F20: 0
A21: =+A20+1 -> 12 | B21: Calendar_18_20.Wednesday | C21: 23037.726 | D21: 572.853 | E21: 40.216 | F21: 0
A22: =+A21+1 -> 13 | B22: Calendar_18_20.Thursday | C22: 23009.116 | D22: 575.304 | E22: 39.995 | F22: 0
A23: =+A22+1 -> 14 | B23: Calendar_18_20.Friday | C23: 20787.503 | D23: 580.169 | E23: 35.83 | F23: 0
A24: =+A23+1 -> 15 | B24: Calendar_18_20.Saturday | C24: 5664.535 | D24: 570.289 | E24: 9.933 | F24: 0
A25: =+A24+1 -> 16 | B25: Calendar_18_20.MLK | C25: -2060.805 | D25: 3028.757 | E25: -0.68 | F25: 0.4964
A26: =+A25+1 -> 17 | B26: Calendar_18_20.PresDay | C26: -7683.999 | D26: 3000.452 | E26: -2.561 | F26: 0.0106
A27: =+A26+1 -> 18 | B27: Calendar_18_20.GoodFri | C27: -7735.848 | D27: 2981.213 | E27: -2.595 | F27: 0.0096
A28: =+A27+1 -> 19 | B28: Calendar_18_20.MemDay | C28: -19266.362 | D28: 2989.689 | E28: -6.444 | F28: 0
... A62: =+A61+1 -> 53 | B62: GSLDD_18_20.GSLCDD85 | C62: -711.04 | D62: 302.491 | E62: -2.351 | F62: 0.0189
A63: =+A62+1 -> 54
A64: =+A63+1 -> 55 | B64: Model Statistics
A65: =+A64+1 -> 56 | B65: Adjusted Observations | C65: 1096
A66: =+A65+1 -> 57 | B66: Deg. of Freedom for Error | C66: 1050
A67: =+A66+1 -> 58 | B67: R-Squared | C67: 0.95
A68: =+A67+1 -> 59 | B68: Adjusted R-Squared | C68: 0.948
A69: =+A68+1 -> 60 | B69: F-Statistic | C69: 445.632
A70: =+A69+1 -> 61 | B70: Prob (F-Statistic) | C70: 0
A71: =+A70+1 -> 62 | B71: Model Sum of Squares | C71: 5.0590315e+11
A72: =+A71+1 -> 63 | B72: Sum of Squared Errors | C72: 2.6489148e+10
A73: =+A72+1 -> 64 | B73: Mean Squared Error | C73: 25227760
A74: =+A73+1 -> 65 | B74: Std. Error of Regression | C74: 5022.72
A75: =+A74+1 -> 66 | B75: Mean Abs. Dev. (MAD) | C75: 3966.02
...

Sheet GSL B Spline Graph
B1: =+'RES Spline Model'!B1:F1 -> 2022 RATE CASE
B2: =+'RES Spline Model'!B2:F2 -> ONCOR ELECTRIC DELIVERY COMPANY LLC
B3: =+'RES Spline Model'!B3:F3 -> ADJUSTED WEATHER STATION DATA
B4: =+'RES Spline Model'!B4:F4 -> FOR THE TEST YEAR ENDING DECEMBER 31, 2021
B6: =+'RES Spline Model'!B6:F6 -> SPONSOR: D. E. NELSON
A8: Line
A9: No.
A10: 1 | B10: Secondary Service Greater Than 10 KW Spline (B) Model
A11: =+A10+1 -> 2 | B11: Before Corrective Procedures for Autocorrelation
A12: =+A11+1 -> 3
A13: =+A12+1 -> 4
A14: =+A13+1 -> 5
A15: =+A14+1 -> 6
A16: =+A15+1 -> 7
A17: =+A16+1 -> 8
A18: =+A17+1 -> 9
A19: =+A18+1 -> 10
A20: =+A19+1 -> 11
A21: =+A20+1 -> 12
A22: =+A21+1 -> 13
A23: =+A22+1 -> 14
... A37: =+A36+1 -> 28

Sheet GPLD B Spline Model
B1: =+'RES Spline Model'!B1:F1 -> 2022 RATE CASE
B2: =+'RES Spline Model'!B2:F2 -> ONCOR ELECTRIC DELIVERY COMPANY LLC
B3: =+'RES Spline Model'!B3:F3 -> ADJUSTED WEATHER STATION DATA
B4: =+'RES Spline Model'!B4:F4 -> FOR THE TEST YEAR ENDING DECEMBER 31, 2021
B6: =+'RES Spline Model'!B6:F6 -> SPONSOR: D. E. NELSON
A8: Line
A9: No. | B9: (a) | C9: (b) | D9: (c) | E9: (d) | F9: (e)
A10: 1 | B10: Model: | C10: Primary Service Greater Than 10 KW Distribution Spline (B)
A11: =+A10+1 -> 2 | B11: Before Corrective Procedures for Autocorrelation
A12: =+A11+1 -> 3 | B12: Dependent Variable: | C12: GPLDMWH
A13: =+A12+1 -> 4 | B13: Estimation Begin Date: | C13: =+'RES Spline Model'!C13 -> 43101
A14: =+A13+1 -> 5 | B14: Estimation End Date: | C14: =+'RES Spline Model'!C14 -> 44196
A15: =+A14+1 -> 6
A16: =+A15+1 -> 7 | B16: Variable | C16: Coefficient | D16: StdErr | E16: T-Stat | F16: P-Value
A17: =+A16+1 -> 8 | B17: CONST | C17: 37922.133 | D17: 287.731 | E17: 131.797 | F17: 0
A18: =+A17+1 -> 9 | B18: Calendar_18_20.DLSav | C18: -279.29 | D18: 394.923 | E18: -0.707 | F18: 0.4796
A19: =+A18+1 -> 10 | B19: Calendar_18_20.Monday | C19: 2537.005 | D19: 220.124 | E19: 11.525 | F19: 0
A20: =+A19+1 -> 11 | B20: Calendar_18_20.Tuesday | C20: 3067.925 | D20: 215.197 | E20: 14.256 | F20: 0
A21: =+A20+1 -> 12 | B21: Calendar_18_20.Wednesday | C21: 3096.092 | D21: 215.53 | E21: 14.365 | F21: 0
A22: =+A21+1 -> 13 | B22: Calendar_18_20.Thursday | C22: 3139.14 | D22: 216.752 | E22: 14.483 | F22: 0
A23: =+A22+1 -> 14 | B23: Calendar_18_20.Friday | C23: 2934.282 | D23: 218.102 | E23: 13.454 | F23: 0
A24: =+A23+1 -> 15 | B24: Calendar_18_20.Saturday | C24: 1134.557 | D24: 214.827 | E24: 5.281 | F24: 0
A25: =+A24+1 -> 16 | B25: Calendar_18_20.MLK | C25: -493.189 | D25: 1122.713 | E25: -0.439 | F25: 0.6606
A26: =+A25+1 -> 17 | B26: Calendar_18_20.PresDay | C26: 379.532 | D26: 1127.9 | E26: 0.336 | F26: 0.7366
A27: =+A26+1 -> 18 | B27: Calendar_18_20.GoodFri | C27: -848.594 | D27: 1126.285 | E27: -0.753 | F27: 0.4513
A28: =+A27+1 -> 19 | B28: Calendar_18_20.MemDay | C28: -2936.245 | D28: 1124.745 | E28: -2.611 | F28: 0.0092
... A57: =+A56+1 -> 48 | B57: GPDDD_18_20.GPDCDD85 | C57: 144.22 | D57: 113.475 | E57: 1.271 | F57: 0.204
A58: =+A57+1 -> 49
A59: =+A58+1 -> 50 | B59: Model Statistics
A60: =+A59+1 -> 51 | B60: Adjusted Observations | C60: 1096
A61: =+A60+1 -> 52 | B61: Deg. of Freedom for Error | C61: 1055
A62: =+A61+1 -> 53 | B62: R-Squared | C62: 0.539
A63: =+A62+1 -> 54 | B63: Adjusted R-Squared | C63: 0.522
A64: =+A63+1 -> 55 | B64: F-Statistic | C64: 30.839
A65: =+A64+1 -> 56 | B65: Prob (F-Statistic) | C65: 0
A66: =+A65+1 -> 57 | B66: Model Sum of Squares | C66: 4.4249635e+09
A67: =+A66+1 -> 58 | B67: Sum of Squared Errors | C67: 3.7844986e+09
A68: =+A67+1 -> 59 | B68: Mean Squared Error | C68: 3587202.4
A69: =+A68+1 -> 60 | B69: Std. Error of Regression | C69: 1893.99
A70: =+A69+1 -> 61 | B70: Mean Abs. Dev. (MAD) | C70: 1571.23
...

Sheet GPLD B Spline Graph
B1: =+'RES Spline Model'!B1:F1 -> 2022 RATE CASE
B2: =+'RES Spline Model'!B2:F2 -> ONCOR ELECTRIC DELIVERY COMPANY LLC
B3: =+'RES Spline Model'!B3:F3 -> ADJUSTED WEATHER STATION DATA
B4: =+'RES Spline Model'!B4:F4 -> FOR THE TEST YEAR ENDING DECEMBER 31, 2021
B6: =+'RES Spline Model'!B6:F6 -> SPONSOR: D. E. NELSON
A8: Line
A9: No.
A10: 1 | B10: Primary Service Greater Than 10 KW Distribution Spline (B) Model
A11: =+A10+1 -> 2 | B11: Before Corrective Procedures for Autocorrelation
A12: =+A11+1 -> 3
A13: =+A12+1 -> 4
A14: =+A13+1 -> 5
A15: =+A14+1 -> 6
A16: =+A15+1 -> 7
A17: =+A16+1 -> 8
A18: =+A17+1 -> 9
A19: =+A18+1 -> 10
A20: =+A19+1 -> 11
A21: =+A20+1 -> 12
A22: =+A21+1 -> 13
A23: =+A22+1 -> 14
... A37: =+A36+1 -> 28

Sheet SUBS B Spline Model
B1: =+'RES Spline Model'!B1:F1 -> 2022 RATE CASE
B2: =+'RES Spline Model'!B2:F2 -> ONCOR ELECTRIC DELIVERY COMPANY LLC
B3: =+'RES Spline Model'!B3:F3 -> ADJUSTED WEATHER STATION DATA
B4: =+'RES Spline Model'!B4:F4 -> FOR THE TEST YEAR ENDING DECEMBER 31, 2021
B6: =+'RES Spline Model'!B6:F6 -> SPONSOR: D. E. NELSON
A8: Line
A9: No. | B9: (a) | C9: (b) | D9: (c) | E9: (d) | F9: (e)
A10: 1 | B10: Model: | C10: Substation Spline (B)
A11: =+A10+1 -> 2 | B11: Before Corrective Procedures for Autocorrelation
A12: =+A11+1 -> 3 | B12: Dependent Variable: | C12: SUBSDMWH
A13: =+A12+1 -> 4 | B13: Estimation Begin Date: | C13: =+'RES Spline Model'!C13 -> 43101
A14: =+A13+1 -> 5 | B14: Estimation End Date: | C14: =+'RES Spline Model'!C14 -> 44196
A15: =+A14+1 -> 6
A16: =+A15+1 -> 7 | B16: Variable | C16: Coefficient | D16: StdErr | E16: T-Stat | F16: P-Value
A17: =+A16+1 -> 8 | B17: CONST | C17: 8530.227 | D17: 80.133 | E17: 106.45 | F17: 0
A18: =+A17+1 -> 9 | B18: Calendar_18_20.DLSav | C18: -177.639 | D18: 108.048 | E18: -1.644 | F18: 0.1005
A19: =+A18+1 -> 10 | B19: Calendar_18_20.Monday | C19: 228.013 | D19: 60.324 | E19: 3.78 | F19: 0.0002
A20: =+A19+1 -> 11 | B20: Calendar_18_20.Tuesday | C20: 225.928 | D20: 58.978 | E20: 3.831 | F20: 0.0001
A21: =+A20+1 -> 12 | B21: Calendar_18_20.Wednesday | C21: 222.109 | D21: 59.006 | E21: 3.764 | F21: 0.0002
A22: =+A21+1 -> 13 | B22: Calendar_18_20.Thursday | C22: 221.245 | D22: 59.401 | E22: 3.725 | F22: 0.0002
A23: =+A22+1 -> 14 | B23: Calendar_18_20.Friday | C23: 240.025 | D23: 59.688 | E23: 4.021 | F23: 0.0001
A24: =+A23+1 -> 15 | B24: Calendar_18_20.Saturday | C24: 104.626 | D24: 58.81 | E24: 1.779 | F24: 0.0755
A25: =+A24+1 -> 16 | B25: Calendar_18_20.MLK | C25: -49.813 | D25: 307.25 | E25: -0.162 | F25: 0.8712
A26: =+A25+1 -> 17 | B26: Calendar_18_20.PresDay | C26: -159.153 | D26: 308.518 | E26: -0.516 | F26: 0.6061
A27: =+A26+1 -> 18 | B27: Calendar_18_20.GoodFri | C27: 136.892 | D27: 308.778 | E27: 0.443 | F27: 0.6576
A28: =+A27+1 -> 19 | B28: Calendar_18_20.MemDay | C28: -186.643 | D28: 307.926 | E28: -0.606 | F28: 0.5446
... A59: =+A58+1 -> 50 | B59: GSBDD_18_20.GSBCDD85 | C59: -64.886 | D59: 31.959 | E59: -2.03 | F59: 0.0426
A60: =+A59+1 -> 51
A61: =+A60+1 -> 52 | B61: Model Statistics
A62: =+A61+1 -> 53 | B62: Adjusted Observations | C62: 1096
A63: =+A62+1 -> 54 | B63: Deg. of Freedom for Error | C63: 1053
A64: =+A63+1 -> 55 | B64: R-Squared | C64: 0.898
A65: =+A64+1 -> 56 | B65: Adjusted R-Squared | C65: 0.894
A66: =+A65+1 -> 57 | B66: F-Statistic | C66: 221.031
A67: =+A66+1 -> 58 | B67: Prob (F-Statistic) | C67: 0
A68: =+A67+1 -> 59 | B68: Model Sum of Squares | C68: 2.4931541e+09
A69: =+A68+1 -> 60 | B69: Sum of Squared Errors | C69: 2.8279773e+08
A70: =+A69+1 -> 61 | B70: Mean Squared Error | C70: 268563.85
A71: =+A70+1 -> 62 | B71: Std. Error of Regression | C71: 518.23
A72: =+A71+1 -> 63 | B72: Mean Abs. Dev. (MAD) | C72: 410.3
...

Sheet SUBS B Spline Graph
B1: =+'RES Spline Model'!B1:F1 -> 2022 RATE CASE
B2: =+'RES Spline Model'!B2:F2 -> ONCOR ELECTRIC DELIVERY COMPANY LLC
B3: =+'RES Spline Model'!B3:F3 -> ADJUSTED WEATHER STATION DATA
B4: =+'RES Spline Model'!B4:F4 -> FOR THE TEST YEAR ENDING DECEMBER 31, 2021
B6: =+'RES Spline Model'!B6:F6 -> SPONSOR: D. E. NELSON
A8: Line
A9: No.
A10: 1 | B10: Substation Spline (B) Model
A11: =+A10+1 -> 2 | B11: Before Corrective Procedures for Autocorrelation
A12: =+A11+1 -> 3
A13: =+A12+1 -> 4
A14: =+A13+1 -> 5
A15: =+A14+1 -> 6
A16: =+A15+1 -> 7
A17: =+A16+1 -> 8
A18: =+A17+1 -> 9
A19: =+A18+1 -> 10
A20: =+A19+1 -> 11
A21: =+A20+1 -> 12
A22: =+A21+1 -> 13
A23: =+A22+1 -> 14
... A37: =+A36+1 -> 28
