Workbook
Name HOURLY: [1]HOURLY!$A$1:$G$745
Name OLE_LINK2: 'Res Seasonal Weights'!$B$24
Name rngBilled: OFFSET([2]Sheet2!$A$2,0,0,[2]Sheet2!$B$1,9)
Name rngYear: OFFSET('[3]Daily Actual_August'!$A$2,0,0,'[3]Daily Actual_August'!$C$1,8)

Sheet Res Seasonal Weights
B1: PUC DOCKET NO.
B2: ONCOR ELECTRIC DELIVERY COMPANY LLC
B3: WEATHER WEIGHTS
B4: FOR THE TEST YEAR ENDING DECEMBER 31, 2021
B6: SPONSOR: D. E. NELSON
B8: RESIDENTIAL MONTHLY WEIGHTS
A9: Line | B9: (a) | D9: (b) | E9: (c) | F9: (d) | G9: (e) | H9: (f) | I9: (g) | J9: (h) | K9: (i) | L9: (j) | M9: (k) | N9: (l) | O9: (m) | P9: (n)
A10: No. | B10: Weather Station | D10: 36892 | E10: 36923 | F10: 36951 | G10: 36982 | H10: 37012 | I10: 37043 | J10: 37073 | K10: 37104 | L10: 37135 | M10: 37165 | N10: 37196 | O10: 37226 | P10: Annual
A11: 1 | B11: Dallas-Fort Worth | D11: =+'Res Monthly Weather Weights'!C11 -> 0.68709956 | E11: =+'Res Monthly Weather Weights'!D11 -> 0.68879318 | F11: =+'Res Monthly Weather Weights'!E11 -> 0.69243574 | G11: =+'Res Monthly Weather Weights'!F11 -> 0.69209896 | H11: =+'Res Monthly Weather Weights'!G11 -> 0.69628509 | I11: =+'Res Monthly Weather Weights'!H11 -> 0.7026699 | J11: =+'Res Monthly Weather Weights'!I11 -> 0.70950311 | K11: =+'Res Monthly Weather Weights'!J11 -> 0.7084686 | ... P11: =+'Res Monthly Weather Weights'!O11 -> 0.69872108
A12: =+A11+1 -> 2 | B12: Midland-Odessa | D12: =+'Res Monthly Weather Weights'!C12 -> 0.056560098 | E12: =+'Res Monthly Weather Weights'!D12 -> 0.055646288 | F12: =+'Res Monthly Weather Weights'!E12 -> 0.05481438 | G12: =+'Res Monthly Weather Weights'!F12 -> 0.056031992 | H12: =+'Res Monthly Weather Weights'!G12 -> 0.058727011 | I12: =+'Res Monthly Weather Weights'!H12 -> 0.056896675 | J12: =+'Res Monthly Weather Weights'!I12 -> 0.056319089 | K12: =+'Res Monthly Weather Weights'!J12 -> 0.054634107 | ... P12: =+'Res Monthly Weather Weights'!O12 -> 0.055724565
A13: =+A12+1 -> 3 | B13: Lufkin | D13: =+'Res Monthly Weather Weights'!C13 -> 0.029688635 | E13: =+'Res Monthly Weather Weights'!D13 -> 0.029742559 | F13: =+'Res Monthly Weather Weights'!E13 -> 0.027267064 | G13: =+'Res Monthly Weather Weights'!F13 -> 0.028030843 | H13: =+'Res Monthly Weather Weights'!G13 -> 0.026948349 | I13: =+'Res Monthly Weather Weights'!H13 -> 0.02651301 | J13: =+'Res Monthly Weather Weights'!I13 -> 0.025176696 | K13: =+'Res Monthly Weather Weights'!J13 -> 0.024758861 | ... P13: =+'Res Monthly Weather Weights'!O13 -> 0.02698467
A14: =+A13+1 -> 4 | B14: Abilene | D14: =+'Res Monthly Weather Weights'!C14 -> 0.01465283 | E14: =+'Res Monthly Weather Weights'!D14 -> 0.014253049 | F14: =+'Res Monthly Weather Weights'!E14 -> 0.013643821 | G14: =+'Res Monthly Weather Weights'!F14 -> 0.013241611 | H14: =+'Res Monthly Weather Weights'!G14 -> 0.012815129 | I14: =+'Res Monthly Weather Weights'!H14 -> 0.012518242 | J14: =+'Res Monthly Weather Weights'!I14 -> 0.012526363 | K14: =+'Res Monthly Weather Weights'!J14 -> 0.012298306 | ... P14: =+'Res Monthly Weather Weights'!O14 -> 0.013001239
A15: =+A14+1 -> 5 | B15: Sherman-Denison | D15: =+'Res Monthly Weather Weights'!C15 -> 0.026842543 | E15: =+'Res Monthly Weather Weights'!D15 -> 0.028176525 | F15: =+'Res Monthly Weather Weights'!E15 -> 0.0278976 | G15: =+'Res Monthly Weather Weights'!F15 -> 0.025985295 | H15: =+'Res Monthly Weather Weights'!G15 -> 0.023497178 | I15: =+'Res Monthly Weather Weights'!H15 -> 0.021989329 | J15: =+'Res Monthly Weather Weights'!I15 -> 0.022877952 | K15: =+'Res Monthly Weather Weights'!J15 -> 0.02350872 | ... P15: =+'Res Monthly Weather Weights'!O15 -> 0.024726041
A16: =+A15+1 -> 6 | B16: Killeen-Temple | D16: =+'Res Monthly Weather Weights'!C16 -> 0.052662426 | E16: =+'Res Monthly Weather Weights'!D16 -> 0.051389227 | F16: =+'Res Monthly Weather Weights'!E16 -> 0.051150749 | G16: =+'Res Monthly Weather Weights'!F16 -> 0.048580007 | H16: =+'Res Monthly Weather Weights'!G16 -> 0.046802378 | I16: =+'Res Monthly Weather Weights'!H16 -> 0.045186052 | J16: =+'Res Monthly Weather Weights'!I16 -> 0.042879856 | K16: =+'Res Monthly Weather Weights'!J16 -> 0.043488336 | ... P16: =+'Res Monthly Weather Weights'!O16 -> 0.047133936
A17: =+A16+1 -> 7 | B17: Waco | D17: =+'Res Monthly Weather Weights'!C17 -> 0.039296716 | E17: =+'Res Monthly Weather Weights'!D17 -> 0.039822223 | F17: =+'Res Monthly Weather Weights'!E17 -> 0.040258223 | G17: =+'Res Monthly Weather Weights'!F17 -> 0.037574406 | H17: =+'Res Monthly Weather Weights'!G17 -> 0.036258187 | I17: =+'Res Monthly Weather Weights'!H17 -> 0.035367661 | J17: =+'Res Monthly Weather Weights'!I17 -> 0.034672013 | K17: =+'Res Monthly Weather Weights'!J17 -> 0.03606507 | ... P17: =+'Res Monthly Weather Weights'!O17 -> 0.037392541
A18: =+A17+1 -> 8 | B18: Wichita Falls. | D18: =+'Res Monthly Weather Weights'!C18 -> 0.020046388 | E18: =+'Res Monthly Weather Weights'!D18 -> 0.02005032 | F18: =+'Res Monthly Weather Weights'!E18 -> 0.020038562 | G18: =+'Res Monthly Weather Weights'!F18 -> 0.019308588 | H18: =+'Res Monthly Weather Weights'!G18 -> 0.018558901 | I18: =+'Res Monthly Weather Weights'!H18 -> 0.018128872 | J18: =+'Res Monthly Weather Weights'!I18 -> 0.018964083 | K18: =+'Res Monthly Weather Weights'!J18 -> 0.019329542 | ... P18: =+'Res Monthly Weather Weights'!O18 -> 0.01916035
A19: =+A18+1 -> 9 | B19: Longview | D19: =+'Res Monthly Weather Weights'!C19 -> 0.038966903 | E19: =+'Res Monthly Weather Weights'!D19 -> 0.039325245 | F19: =+'Res Monthly Weather Weights'!E19 -> 0.038164762 | G19: =+'Res Monthly Weather Weights'!F19 -> 0.037615111 | H19: =+'Res Monthly Weather Weights'!G19 -> 0.036292026 | I19: =+'Res Monthly Weather Weights'!H19 -> 0.035532292 | J19: =+'Res Monthly Weather Weights'!I19 -> 0.034480561 | K19: =+'Res Monthly Weather Weights'!J19 -> 0.034571142 | ... P19: =+'Res Monthly Weather Weights'!O19 -> 0.036488214
A20: =+A19+1 -> 10 | B20: Austin | D20: =+'Res Monthly Weather Weights'!C20 -> 0.034183904 | E20: =+'Res Monthly Weather Weights'!D20 -> 0.032801387 | F20: =+'Res Monthly Weather Weights'!E20 -> 0.034329096 | G20: =+'Res Monthly Weather Weights'!F20 -> 0.041533186 | H20: =+'Res Monthly Weather Weights'!G20 -> 0.043815749 | I20: =+'Res Monthly Weather Weights'!H20 -> 0.045197967 | J20: =+'Res Monthly Weather Weights'!I20 -> 0.042600273 | K20: =+'Res Monthly Weather Weights'!J20 -> 0.042877318 | ... P20: =+'Res Monthly Weather Weights'!O20 -> 0.040667364
A21: =+A20+1 -> 11 | D21: =SUM(D11:D20) -> 1 | E21: =SUM(E11:E20) -> 1 | F21: =SUM(F11:F20) -> 1 | G21: =SUM(G11:G20) -> 1 | H21: =SUM(H11:H20) -> 1 | I21: =SUM(I11:I20) -> 1 | J21: =SUM(J11:J20) -> 1 | K21: =SUM(K11:K20) -> 1 | ... P21: =SUM(P11:P20) -> 1
A22: =+A21+1 -> 12
A23: =+A22+1 -> 13 | D23: SEASONAL WEIGHTS
A24: =+A23+1 -> 14 | D24: Nov to Mar | F24: May to Sep
A25: =+A24+1 -> 15 | B25: Weather Station | D25: HDD | F25: CDD
A26: =+A25+1 -> 16 | B26: Dallas-Fort Worth | D26: =ROUND(AVERAGE(D11:F11,N11:O11),3) -> 0.689 | F26: =ROUND(AVERAGE(H11:L11),3) -> 0.705
A27: =+A26+1 -> 17 | B27: Midland-Odessa | D27: =ROUND(AVERAGE(D12:F12,N12:O12),3) -> 0.057 | F27: =ROUND(AVERAGE(H12:L12),3) -> 0.056
A28: =+A27+1 -> 18 | B28: Lufkin | D28: =ROUND(AVERAGE(D13:F13,N13:O13),3) -> 0.029 | F28: =ROUND(AVERAGE(H13:L13),3) -> 0.026
A29: =+A28+1 -> 19 | B29: Abilene | D29: =ROUND(AVERAGE(D14:F14,N14:O14),3) -> 0.014 | F29: =ROUND(AVERAGE(H14:L14),3) -> 0.012
A30: =+A29+1 -> 20 | B30: Sherman-Denison | D30: =ROUND(AVERAGE(D15:F15,N15:O15),3) -> 0.027 | F30: =ROUND(AVERAGE(H15:L15),3) -> 0.023
A31: =+A30+1 -> 21 | B31: Killeen-Temple | D31: =ROUND(AVERAGE(D16:F16,N16:O16),3) -> 0.051 | F31: =ROUND(AVERAGE(H16:L16),3) -> 0.045
A32: =+A31+1 -> 22 | B32: Waco | D32: =ROUND(AVERAGE(D17:F17,N17:O17),3) -> 0.039 | F32: =ROUND(AVERAGE(H17:L17),3) -> 0.036
A33: =+A32+1 -> 23 | B33: Wichita Falls. | D33: =ROUND(AVERAGE(D18:F18,N18:O18),3) -> 0.02 | F33: =ROUND(AVERAGE(H18:L18),3) -> 0.019
A34: =+A33+1 -> 24 | B34: Longview | D34: =ROUND(AVERAGE(D19:F19,N19:O19),3) -> 0.038 | F34: =ROUND(AVERAGE(H19:L19),3) -> 0.035
A35: =+A34+1 -> 25 | B35: Austin | D35: =ROUND(AVERAGE(D20:F20,N20:O20),3) -> 0.036 | F35: =ROUND(AVERAGE(H20:L20),3) -> 0.044
A36: =+A35+1 -> 26 | D36: =AVERAGE(D21:F21,N21:O21) -> 1 | F36: =AVERAGE(H21:L21) -> 1

Sheet Res Monthly Weather Weights
B1: PUC DOCKET NO.
B2: ONCOR ELECTRIC DELIVERY COMPANY
B3: WEATHER WEIGHTS
B4: =+'Res Seasonal Weights'!B4:P4 -> FOR THE TEST YEAR ENDING DECEMBER 31, 2021
B6: SPONSOR: D. E. NELSON
B8: RESIDENTIAL MONTHLY WEIGHTS
A9: Line | B9: (a) | C9: (b) | D9: (c) | E9: (d) | F9: (e) | G9: (f) | H9: (g) | I9: (h) | J9: (i) | K9: (j) | L9: (k) | M9: (l) | N9: (m) | O9: (n)
A10: No. | B10: Weather Station | C10: 36892 | D10: 36923 | E10: 36951 | F10: 36982 | G10: 37012 | H10: 37043 | I10: 37073 | J10: 37104 | K10: 37135 | L10: 37165 | M10: 37196 | N10: 37226 | O10: Annual
A11: 1 | B11: Dallas-Fort Worth | C11: =+'Res Weights by Year (18-20)'!D14 -> 0.68709956 | D11: =+'Res Weights by Year (18-20)'!E14 -> 0.68879318 | E11: =+'Res Weights by Year (18-20)'!F14 -> 0.69243574 | F11: =+'Res Weights by Year (18-20)'!G14 -> 0.69209896 | G11: =+'Res Weights by Year (18-20)'!H14 -> 0.69628509 | H11: =+'Res Weights by Year (18-20)'!I14 -> 0.7026699 | I11: =+'Res Weights by Year (18-20)'!J14 -> 0.70950311 | J11: =+'Res Weights by Year (18-20)'!K14 -> 0.7084686 | ... O11: =+'Res Weights by Year (18-20)'!P14 -> 0.69872108
A12: =+A11+1 -> 2 | B12: Midland-Odessa | C12: =+'Res Weights by Year (18-20)'!D54 -> 0.056560098 | D12: =+'Res Weights by Year (18-20)'!E54 -> 0.055646288 | E12: =+'Res Weights by Year (18-20)'!F54 -> 0.05481438 | F12: =+'Res Weights by Year (18-20)'!G54 -> 0.056031992 | G12: =+'Res Weights by Year (18-20)'!H54 -> 0.058727011 | H12: =+'Res Weights by Year (18-20)'!I54 -> 0.056896675 | I12: =+'Res Weights by Year (18-20)'!J54 -> 0.056319089 | J12: =+'Res Weights by Year (18-20)'!K54 -> 0.054634107 | ... O12: =+'Res Weights by Year (18-20)'!P54 -> 0.055724565
A13: =+A12+1 -> 3 | B13: Lufkin | C13: =+'Res Weights by Year (18-20)'!D19 -> 0.029688635 | D13: =+'Res Weights by Year (18-20)'!E19 -> 0.029742559 | E13: =+'Res Weights by Year (18-20)'!F19 -> 0.027267064 | F13: =+'Res Weights by Year (18-20)'!G19 -> 0.028030843 | G13: =+'Res Weights by Year (18-20)'!H19 -> 0.026948349 | H13: =+'Res Weights by Year (18-20)'!I19 -> 0.02651301 | I13: =+'Res Weights by Year (18-20)'!J19 -> 0.025176696 | J13: =+'Res Weights by Year (18-20)'!K19 -> 0.024758861 | ... O13: =+'Res Weights by Year (18-20)'!P19 -> 0.02698467
A14: =+A13+1 -> 4 | B14: Abilene | C14: =+'Res Weights by Year (18-20)'!D44 -> 0.01465283 | D14: =+'Res Weights by Year (18-20)'!E44 -> 0.014253049 | E14: =+'Res Weights by Year (18-20)'!F44 -> 0.013643821 | F14: =+'Res Weights by Year (18-20)'!G44 -> 0.013241611 | G14: =+'Res Weights by Year (18-20)'!H44 -> 0.012815129 | H14: =+'Res Weights by Year (18-20)'!I44 -> 0.012518242 | I14: =+'Res Weights by Year (18-20)'!J44 -> 0.012526363 | J14: =+'Res Weights by Year (18-20)'!K44 -> 0.012298306 | ... O14: =+'Res Weights by Year (18-20)'!P44 -> 0.013001239
A15: =+A14+1 -> 5 | B15: Sherman-Denison | C15: =+'Res Weights by Year (18-20)'!D59 -> 0.026842543 | D15: =+'Res Weights by Year (18-20)'!E59 -> 0.028176525 | E15: =+'Res Weights by Year (18-20)'!F59 -> 0.0278976 | F15: =+'Res Weights by Year (18-20)'!G59 -> 0.025985295 | G15: =+'Res Weights by Year (18-20)'!H59 -> 0.023497178 | H15: =+'Res Weights by Year (18-20)'!I59 -> 0.021989329 | I15: =+'Res Weights by Year (18-20)'!J59 -> 0.022877952 | J15: =+'Res Weights by Year (18-20)'!K59 -> 0.02350872 | ... O15: =+'Res Weights by Year (18-20)'!P59 -> 0.024726041
A16: =+A15+1 -> 6 | B16: Killeen-Temple | C16: =+'Res Weights by Year (18-20)'!D29 -> 0.052662426 | D16: =+'Res Weights by Year (18-20)'!E29 -> 0.051389227 | E16: =+'Res Weights by Year (18-20)'!F29 -> 0.051150749 | F16: =+'Res Weights by Year (18-20)'!G29 -> 0.048580007 | G16: =+'Res Weights by Year (18-20)'!H29 -> 0.046802378 | H16: =+'Res Weights by Year (18-20)'!I29 -> 0.045186052 | I16: =+'Res Weights by Year (18-20)'!J29 -> 0.042879856 | J16: =+'Res Weights by Year (18-20)'!K29 -> 0.043488336 | ... O16: =+'Res Weights by Year (18-20)'!P29 -> 0.047133936
A17: =+A16+1 -> 7 | B17: Waco | C17: =+'Res Weights by Year (18-20)'!D39 -> 0.039296716 | D17: =+'Res Weights by Year (18-20)'!E39 -> 0.039822223 | E17: =+'Res Weights by Year (18-20)'!F39 -> 0.040258223 | F17: =+'Res Weights by Year (18-20)'!G39 -> 0.037574406 | G17: =+'Res Weights by Year (18-20)'!H39 -> 0.036258187 | H17: =+'Res Weights by Year (18-20)'!I39 -> 0.035367661 | I17: =+'Res Weights by Year (18-20)'!J39 -> 0.034672013 | J17: =+'Res Weights by Year (18-20)'!K39 -> 0.03606507 | ... O17: =+'Res Weights by Year (18-20)'!P39 -> 0.037392541
A18: =+A17+1 -> 8 | B18: Wichita Falls. | C18: =+'Res Weights by Year (18-20)'!D49 -> 0.020046388 | D18: =+'Res Weights by Year (18-20)'!E49 -> 0.02005032 | E18: =+'Res Weights by Year (18-20)'!F49 -> 0.020038562 | F18: =+'Res Weights by Year (18-20)'!G49 -> 0.019308588 | G18: =+'Res Weights by Year (18-20)'!H49 -> 0.018558901 | H18: =+'Res Weights by Year (18-20)'!I49 -> 0.018128872 | I18: =+'Res Weights by Year (18-20)'!J49 -> 0.018964083 | J18: =+'Res Weights by Year (18-20)'!K49 -> 0.019329542 | ... O18: =+'Res Weights by Year (18-20)'!P49 -> 0.01916035
A19: =+A18+1 -> 9 | B19: Longview | C19: =+'Res Weights by Year (18-20)'!D34 -> 0.038966903 | D19: =+'Res Weights by Year (18-20)'!E34 -> 0.039325245 | E19: =+'Res Weights by Year (18-20)'!F34 -> 0.038164762 | F19: =+'Res Weights by Year (18-20)'!G34 -> 0.037615111 | G19: =+'Res Weights by Year (18-20)'!H34 -> 0.036292026 | H19: =+'Res Weights by Year (18-20)'!I34 -> 0.035532292 | I19: =+'Res Weights by Year (18-20)'!J34 -> 0.034480561 | J19: =+'Res Weights by Year (18-20)'!K34 -> 0.034571142 | ... O19: =+'Res Weights by Year (18-20)'!P34 -> 0.036488214
A20: =+A19+1 -> 10 | B20: Austin | C20: =+'Res Weights by Year (18-20)'!D24 -> 0.034183904 | D20: =+'Res Weights by Year (18-20)'!E24 -> 0.032801387 | E20: =+'Res Weights by Year (18-20)'!F24 -> 0.034329096 | F20: =+'Res Weights by Year (18-20)'!G24 -> 0.041533186 | G20: =+'Res Weights by Year (18-20)'!H24 -> 0.043815749 | H20: =+'Res Weights by Year (18-20)'!I24 -> 0.045197967 | I20: =+'Res Weights by Year (18-20)'!J24 -> 0.042600273 | J20: =+'Res Weights by Year (18-20)'!K24 -> 0.042877318 | ... O20: =+'Res Weights by Year (18-20)'!P24 -> 0.040667364
C21: =SUM(C11:C20) -> 1 | D21: =SUM(D11:D20) -> 1 | E21: =SUM(E11:E20) -> 1 | F21: =SUM(F11:F20) -> 1 | G21: =SUM(G11:G20) -> 1 | H21: =SUM(H11:H20) -> 1 | I21: =SUM(I11:I20) -> 1 | J21: =SUM(J11:J20) -> 1 | ... O21: =SUM(O11:O20) -> 1

Sheet Res Weights by Year (18-20)
B1: PUC DOCKET NO.
B2: ONCOR ELECTRIC DELIVERY COMPANY
B3: WEATHER WEIGHTS
B4: =+'Res Seasonal Weights'!B4:P4 -> FOR THE TEST YEAR ENDING DECEMBER 31, 2021
B6: SPONSOR: D. E. NELSON
B8: RESIDENTIAL MONTHLY WEIGHTS BY YEAR
A9: Line | B9: (a) | C9: (b) | D9: (c) | E9: (d) | F9: (e) | G9: (f) | H9: (g) | I9: (h) | J9: (i) | K9: (j) | L9: (k) | M9: (l) | N9: (m) | O9: (n) | P9: (o)
A10: No. | B10: Weather Station | C10: Year | D10: 36892 | E10: 36923 | F10: 36951 | G10: 36982 | H10: 37012 | I10: 37043 | J10: 37073 | K10: 37104 | L10: 37135 | M10: 37165 | N10: 37196 | O10: 37226 | P10: Annual
A11: 1 | B11: Dallas-Fort Worth | C11: 2018 | D11: ='Res Sales by Year (18-20)'!D11/'Res Sales by Year (18-20)'!D61 -> 0.69355691 | E11: ='Res Sales by Year (18-20)'!E11/'Res Sales by Year (18-20)'!E$61 -> 0.69042271 | F11: ='Res Sales by Year (18-20)'!F11/'Res Sales by Year (18-20)'!F$61 -> 0.69959812 | G11: ='Res Sales by Year (18-20)'!G11/'Res Sales by Year (18-20)'!G$61 -> 0.69458153 | H11: ='Res Sales by Year (18-20)'!H11/'Res Sales by Year (18-20)'!H$61 -> 0.69693902 | I11: ='Res Sales by Year (18-20)'!I11/'Res Sales by Year (18-20)'!I$61 -> 0.70673279 | J11: ='Res Sales by Year (18-20)'!J11/'Res Sales by Year (18-20)'!J$61 -> 0.71774978 | K11: ='Res Sales by Year (18-20)'!K11/'Res Sales by Year (18-20)'!K$61 -> 0.7133218 | L11: ='Res Sales by Year (18-20)'!L11/'Res Sales by Year (18-20)'!L$61 -> 0.70462884 | ... P11: ='Res Sales by Year (18-20)'!P11/'Res Sales by Year (18-20)'!P$61 -> 0.70160911
A12: =+A11+1 -> 2 | B12: Dallas-Fort Worth | C12: 2019 | D12: ='Res Sales by Year (18-20)'!D12/'Res Sales by Year (18-20)'!D62 -> 0.68224674 | E12: ='Res Sales by Year (18-20)'!E12/'Res Sales by Year (18-20)'!E$62 -> 0.69036637 | F12: ='Res Sales by Year (18-20)'!F12/'Res Sales by Year (18-20)'!F$62 -> 0.69484616 | G12: ='Res Sales by Year (18-20)'!G12/'Res Sales by Year (18-20)'!G$62 -> 0.68843997 | H12: ='Res Sales by Year (18-20)'!H12/'Res Sales by Year (18-20)'!H$62 -> 0.69632771 | I12: ='Res Sales by Year (18-20)'!I12/'Res Sales by Year (18-20)'!I$62 -> 0.70085863 | J12: ='Res Sales by Year (18-20)'!J12/'Res Sales by Year (18-20)'!J$62 -> 0.70583116 | K12: ='Res Sales by Year (18-20)'!K12/'Res Sales by Year (18-20)'!K$62 -> 0.70771104 | L12: ='Res Sales by Year (18-20)'!L12/'Res Sales by Year (18-20)'!L$62 -> 0.7093405 | ... P12: ='Res Sales by Year (18-20)'!P12/'Res Sales by Year (18-20)'!P$62 -> 0.69858551
A13: =+A12+1 -> 3 | B13: Dallas-Fort Worth | C13: 2020 | D13: ='Res Sales by Year (18-20)'!D13/'Res Sales by Year (18-20)'!D63 -> 0.68403286 | E13: ='Res Sales by Year (18-20)'!E13/'Res Sales by Year (18-20)'!E63 -> 0.68516161 | F13: ='Res Sales by Year (18-20)'!F13/'Res Sales by Year (18-20)'!F63 -> 0.68268943 | G13: ='Res Sales by Year (18-20)'!G13/'Res Sales by Year (18-20)'!G63 -> 0.69335288 | H13: ='Res Sales by Year (18-20)'!H13/'Res Sales by Year (18-20)'!H63 -> 0.69566582 | I13: ='Res Sales by Year (18-20)'!I13/'Res Sales by Year (18-20)'!I63 -> 0.69974649 | J13: ='Res Sales by Year (18-20)'!J13/'Res Sales by Year (18-20)'!J63 -> 0.70387261 | K13: ='Res Sales by Year (18-20)'!K13/'Res Sales by Year (18-20)'!K63 -> 0.70428823 | ... P13: ='Res Sales by Year (18-20)'!P13/'Res Sales by Year (18-20)'!P63 -> 0.6958492
A14: =+A13+1 -> 4 | B14: Dallas-Fort Worth | C14: Total | D14: ='Res Sales by Year (18-20)'!D14/'Res Sales by Year (18-20)'!D64 -> 0.68709956 | E14: ='Res Sales by Year (18-20)'!E14/'Res Sales by Year (18-20)'!E64 -> 0.68879318 | F14: ='Res Sales by Year (18-20)'!F14/'Res Sales by Year (18-20)'!F64 -> 0.69243574 | G14: ='Res Sales by Year (18-20)'!G14/'Res Sales by Year (18-20)'!G64 -> 0.69209896 | H14: ='Res Sales by Year (18-20)'!H14/'Res Sales by Year (18-20)'!H64 -> 0.69628509 | I14: ='Res Sales by Year (18-20)'!I14/'Res Sales by Year (18-20)'!I64 -> 0.7026699 | J14: ='Res Sales by Year (18-20)'!J14/'Res Sales by Year (18-20)'!J64 -> 0.70950311 | K14: ='Res Sales by Year (18-20)'!K14/'Res Sales by Year (18-20)'!K64 -> 0.7084686 | ... P14: ='Res Sales by Year (18-20)'!P14/'Res Sales by Year (18-20)'!P64 -> 0.69872108
A15: =+A14+1 -> 5
A16: =+A15+1 -> 6 | B16: Lufkin | C16: =+C11 -> 2018 | D16: ='Res Sales by Year (18-20)'!D16/'Res Sales by Year (18-20)'!D61 -> 0.030982355 | E16: ='Res Sales by Year (18-20)'!E16/'Res Sales by Year (18-20)'!E$61 -> 0.030217889 | F16: ='Res Sales by Year (18-20)'!F16/'Res Sales by Year (18-20)'!F$61 -> 0.025806752 | G16: ='Res Sales by Year (18-20)'!G16/'Res Sales by Year (18-20)'!G$61 -> 0.028510669 | H16: ='Res Sales by Year (18-20)'!H16/'Res Sales by Year (18-20)'!H$61 -> 0.027828354 | I16: ='Res Sales by Year (18-20)'!I16/'Res Sales by Year (18-20)'!I$61 -> 0.025921322 | J16: ='Res Sales by Year (18-20)'!J16/'Res Sales by Year (18-20)'!J$61 -> 0.024855538 | K16: ='Res Sales by Year (18-20)'!K16/'Res Sales by Year (18-20)'!K$61 -> 0.024983821 | L16: ='Res Sales by Year (18-20)'!L16/'Res Sales by Year (18-20)'!L$61 -> 0.02649647 | ... P16: ='Res Sales by Year (18-20)'!P16/'Res Sales by Year (18-20)'!P$61 -> 0.027468162
A17: =+A16+1 -> 7 | B17: Lufkin | C17: =+C12 -> 2019 | D17: ='Res Sales by Year (18-20)'!D17/'Res Sales by Year (18-20)'!D62 -> 0.028330333 | E17: ='Res Sales by Year (18-20)'!E17/'Res Sales by Year (18-20)'!E$62 -> 0.029580761 | F17: ='Res Sales by Year (18-20)'!F17/'Res Sales by Year (18-20)'!F$62 -> 0.027460769 | G17: ='Res Sales by Year (18-20)'!G17/'Res Sales by Year (18-20)'!G$62 -> 0.028147947 | H17: ='Res Sales by Year (18-20)'!H17/'Res Sales by Year (18-20)'!H$62 -> 0.027592107 | I17: ='Res Sales by Year (18-20)'!I17/'Res Sales by Year (18-20)'!I$62 -> 0.028250103 | J17: ='Res Sales by Year (18-20)'!J17/'Res Sales by Year (18-20)'!J$62 -> 0.02573947 | K17: ='Res Sales by Year (18-20)'!K17/'Res Sales by Year (18-20)'!K$62 -> 0.024726948 | L17: ='Res Sales by Year (18-20)'!L17/'Res Sales by Year (18-20)'!L$62 -> 0.024726376 | ... P17: ='Res Sales by Year (18-20)'!P17/'Res Sales by Year (18-20)'!P$62 -> 0.026840797
A18: =+A17+1 -> 8 | B18: Lufkin | C18: =+C13 -> 2020 | D18: ='Res Sales by Year (18-20)'!D18/'Res Sales by Year (18-20)'!D63 -> 0.029490159 | E18: ='Res Sales by Year (18-20)'!E18/'Res Sales by Year (18-20)'!E63 -> 0.029384831 | F18: ='Res Sales by Year (18-20)'!F18/'Res Sales by Year (18-20)'!F63 -> 0.028475431 | G18: ='Res Sales by Year (18-20)'!G18/'Res Sales by Year (18-20)'!G63 -> 0.027467612 | H18: ='Res Sales by Year (18-20)'!H18/'Res Sales by Year (18-20)'!H63 -> 0.025602327 | I18: ='Res Sales by Year (18-20)'!I18/'Res Sales by Year (18-20)'!I63 -> 0.025601935 | J18: ='Res Sales by Year (18-20)'!J18/'Res Sales by Year (18-20)'!J63 -> 0.025024696 | K18: ='Res Sales by Year (18-20)'!K18/'Res Sales by Year (18-20)'!K63 -> 0.024562073 | ... P18: ='Res Sales by Year (18-20)'!P18/'Res Sales by Year (18-20)'!P63 -> 0.026628522
A19: =+A18+1 -> 9 | B19: Lufkin | C19: Total | D19: ='Res Sales by Year (18-20)'!D19/'Res Sales by Year (18-20)'!D64 -> 0.029688635 | E19: ='Res Sales by Year (18-20)'!E19/'Res Sales by Year (18-20)'!E64 -> 0.029742559 | F19: ='Res Sales by Year (18-20)'!F19/'Res Sales by Year (18-20)'!F64 -> 0.027267064 | G19: ='Res Sales by Year (18-20)'!G19/'Res Sales by Year (18-20)'!G64 -> 0.028030843 | H19: ='Res Sales by Year (18-20)'!H19/'Res Sales by Year (18-20)'!H64 -> 0.026948349 | I19: ='Res Sales by Year (18-20)'!I19/'Res Sales by Year (18-20)'!I64 -> 0.02651301 | J19: ='Res Sales by Year (18-20)'!J19/'Res Sales by Year (18-20)'!J64 -> 0.025176696 | K19: ='Res Sales by Year (18-20)'!K19/'Res Sales by Year (18-20)'!K64 -> 0.024758861 | ... P19: ='Res Sales by Year (18-20)'!P19/'Res Sales by Year (18-20)'!P64 -> 0.02698467
A20: =+A19+1 -> 10
A21: =+A20+1 -> 11 | B21: Austin | C21: =+C16 -> 2018 | D21: ='Res Sales by Year (18-20)'!D21/'Res Sales by Year (18-20)'!D61 -> 0.032939541 | E21: ='Res Sales by Year (18-20)'!E21/'Res Sales by Year (18-20)'!E$61 -> 0.031899098 | F21: ='Res Sales by Year (18-20)'!F21/'Res Sales by Year (18-20)'!F$61 -> 0.033758315 | G21: ='Res Sales by Year (18-20)'!G21/'Res Sales by Year (18-20)'!G$61 -> 0.040505983 | H21: ='Res Sales by Year (18-20)'!H21/'Res Sales by Year (18-20)'!H$61 -> 0.041824886 | I21: ='Res Sales by Year (18-20)'!I21/'Res Sales by Year (18-20)'!I$61 -> 0.042592577 | J21: ='Res Sales by Year (18-20)'!J21/'Res Sales by Year (18-20)'!J$61 -> 0.039738908 | K21: ='Res Sales by Year (18-20)'!K21/'Res Sales by Year (18-20)'!K$61 -> 0.041273535 | L21: ='Res Sales by Year (18-20)'!L21/'Res Sales by Year (18-20)'!L$61 -> 0.043761629 | ... P21: ='Res Sales by Year (18-20)'!P21/'Res Sales by Year (18-20)'!P$61 -> 0.038959618
A22: =+A21+1 -> 12 | B22: Austin | C22: =+C17 -> 2019 | D22: ='Res Sales by Year (18-20)'!D22/'Res Sales by Year (18-20)'!D62 -> 0.034331389 | E22: ='Res Sales by Year (18-20)'!E22/'Res Sales by Year (18-20)'!E$62 -> 0.032909197 | F22: ='Res Sales by Year (18-20)'!F22/'Res Sales by Year (18-20)'!F$62 -> 0.033038542 | G22: ='Res Sales by Year (18-20)'!G22/'Res Sales by Year (18-20)'!G$62 -> 0.03949497 | H22: ='Res Sales by Year (18-20)'!H22/'Res Sales by Year (18-20)'!H$62 -> 0.043798201 | I22: ='Res Sales by Year (18-20)'!I22/'Res Sales by Year (18-20)'!I$62 -> 0.046456953 | J22: ='Res Sales by Year (18-20)'!J22/'Res Sales by Year (18-20)'!J$62 -> 0.043855291 | K22: ='Res Sales by Year (18-20)'!K22/'Res Sales by Year (18-20)'!K$62 -> 0.043663371 | L22: ='Res Sales by Year (18-20)'!L22/'Res Sales by Year (18-20)'!L$62 -> 0.043466673 | ... P22: ='Res Sales by Year (18-20)'!P22/'Res Sales by Year (18-20)'!P$62 -> 0.040487061
A23: =+A22+1 -> 13 | B23: Austin | C23: =+C18 -> 2020 | D23: ='Res Sales by Year (18-20)'!D23/'Res Sales by Year (18-20)'!D63 -> 0.035623519 | E23: ='Res Sales by Year (18-20)'!E23/'Res Sales by Year (18-20)'!E63 -> 0.033705742 | F23: ='Res Sales by Year (18-20)'!F23/'Res Sales by Year (18-20)'!F63 -> 0.036354356 | G23: ='Res Sales by Year (18-20)'!G23/'Res Sales by Year (18-20)'!G63 -> 0.044485864 | H23: ='Res Sales by Year (18-20)'!H23/'Res Sales by Year (18-20)'!H63 -> 0.045603011 | I23: ='Res Sales by Year (18-20)'!I23/'Res Sales by Year (18-20)'!I63 -> 0.046984196 | J23: ='Res Sales by Year (18-20)'!J23/'Res Sales by Year (18-20)'!J63 -> 0.044570751 | K23: ='Res Sales by Year (18-20)'!K23/'Res Sales by Year (18-20)'!K63 -> 0.043754483 | ... P23: ='Res Sales by Year (18-20)'!P23/'Res Sales by Year (18-20)'!P63 -> 0.042633478
A24: =+A23+1 -> 14 | B24: Austin | C24: Total | D24: ='Res Sales by Year (18-20)'!D24/'Res Sales by Year (18-20)'!D64 -> 0.034183904 | E24: ='Res Sales by Year (18-20)'!E24/'Res Sales by Year (18-20)'!E64 -> 0.032801387 | F24: ='Res Sales by Year (18-20)'!F24/'Res Sales by Year (18-20)'!F64 -> 0.034329096 | G24: ='Res Sales by Year (18-20)'!G24/'Res Sales by Year (18-20)'!G64 -> 0.041533186 | H24: ='Res Sales by Year (18-20)'!H24/'Res Sales by Year (18-20)'!H64 -> 0.043815749 | I24: ='Res Sales by Year (18-20)'!I24/'Res Sales by Year (18-20)'!I64 -> 0.045197967 | J24: ='Res Sales by Year (18-20)'!J24/'Res Sales by Year (18-20)'!J64 -> 0.042600273 | K24: ='Res Sales by Year (18-20)'!K24/'Res Sales by Year (18-20)'!K64 -> 0.042877318 | ... P24: ='Res Sales by Year (18-20)'!P24/'Res Sales by Year (18-20)'!P64 -> 0.040667364
A25: =+A24+1 -> 15
A26: =+A25+1 -> 16 | B26: Killeen | C26: =+C21 -> 2018 | D26: ='Res Sales by Year (18-20)'!D26/'Res Sales by Year (18-20)'!D61 -> 0.052879828 | E26: ='Res Sales by Year (18-20)'!E26/'Res Sales by Year (18-20)'!E$61 -> 0.052239153 | F26: ='Res Sales by Year (18-20)'!F26/'Res Sales by Year (18-20)'!F$61 -> 0.04954339 | G26: ='Res Sales by Year (18-20)'!G26/'Res Sales by Year (18-20)'!G$61 -> 0.047888047 | H26: ='Res Sales by Year (18-20)'!H26/'Res Sales by Year (18-20)'!H$61 -> 0.04587549 | I26: ='Res Sales by Year (18-20)'!I26/'Res Sales by Year (18-20)'!I$61 -> 0.043222282 | J26: ='Res Sales by Year (18-20)'!J26/'Res Sales by Year (18-20)'!J$61 -> 0.041001436 | K26: ='Res Sales by Year (18-20)'!K26/'Res Sales by Year (18-20)'!K$61 -> 0.04297062 | L26: ='Res Sales by Year (18-20)'!L26/'Res Sales by Year (18-20)'!L$61 -> 0.044205998 | ... P26: ='Res Sales by Year (18-20)'!P26/'Res Sales by Year (18-20)'!P$61 -> 0.046553316
A27: =+A26+1 -> 17 | B27: Killeen | C27: =+C22 -> 2019 | D27: ='Res Sales by Year (18-20)'!D27/'Res Sales by Year (18-20)'!D62 -> 0.053296468 | E27: ='Res Sales by Year (18-20)'!E27/'Res Sales by Year (18-20)'!E$62 -> 0.051660593 | F27: ='Res Sales by Year (18-20)'!F27/'Res Sales by Year (18-20)'!F$62 -> 0.051463431 | G27: ='Res Sales by Year (18-20)'!G27/'Res Sales by Year (18-20)'!G$62 -> 0.049393392 | H27: ='Res Sales by Year (18-20)'!H27/'Res Sales by Year (18-20)'!H$62 -> 0.046668582 | I27: ='Res Sales by Year (18-20)'!I27/'Res Sales by Year (18-20)'!I$62 -> 0.046313597 | J27: ='Res Sales by Year (18-20)'!J27/'Res Sales by Year (18-20)'!J$62 -> 0.043519421 | K27: ='Res Sales by Year (18-20)'!K27/'Res Sales by Year (18-20)'!K$62 -> 0.042926176 | L27: ='Res Sales by Year (18-20)'!L27/'Res Sales by Year (18-20)'!L$62 -> 0.043144988 | ... P27: ='Res Sales by Year (18-20)'!P27/'Res Sales by Year (18-20)'!P$62 -> 0.047222051
A28: =+A27+1 -> 18 | B28: Killeen | C28: =+C23 -> 2020 | D28: ='Res Sales by Year (18-20)'!D28/'Res Sales by Year (18-20)'!D63 -> 0.051700028 | E28: ='Res Sales by Year (18-20)'!E28/'Res Sales by Year (18-20)'!E63 -> 0.050115834 | F28: ='Res Sales by Year (18-20)'!F28/'Res Sales by Year (18-20)'!F63 -> 0.052367729 | G28: ='Res Sales by Year (18-20)'!G28/'Res Sales by Year (18-20)'!G63 -> 0.048432292 | H28: ='Res Sales by Year (18-20)'!H28/'Res Sales by Year (18-20)'!H63 -> 0.047744303 | I28: ='Res Sales by Year (18-20)'!I28/'Res Sales by Year (18-20)'!I63 -> 0.046370337 | J28: ='Res Sales by Year (18-20)'!J28/'Res Sales by Year (18-20)'!J63 -> 0.044336457 | K28: ='Res Sales by Year (18-20)'!K28/'Res Sales by Year (18-20)'!K63 -> 0.044539522 | ... P28: ='Res Sales by Year (18-20)'!P28/'Res Sales by Year (18-20)'!P63 -> 0.047648711
A29: =+A28+1 -> 19 | B29: Killeen | C29: Total | D29: ='Res Sales by Year (18-20)'!D29/'Res Sales by Year (18-20)'!D64 -> 0.052662426 | E29: ='Res Sales by Year (18-20)'!E29/'Res Sales by Year (18-20)'!E64 -> 0.051389227 | F29: ='Res Sales by Year (18-20)'!F29/'Res Sales by Year (18-20)'!F64 -> 0.051150749 | G29: ='Res Sales by Year (18-20)'!G29/'Res Sales by Year (18-20)'!G64 -> 0.048580007 | H29: ='Res Sales by Year (18-20)'!H29/'Res Sales by Year (18-20)'!H64 -> 0.046802378 | I29: ='Res Sales by Year (18-20)'!I29/'Res Sales by Year (18-20)'!I64 -> 0.045186052 | J29: ='Res Sales by Year (18-20)'!J29/'Res Sales by Year (18-20)'!J64 -> 0.042879856 | K29: ='Res Sales by Year (18-20)'!K29/'Res Sales by Year (18-20)'!K64 -> 0.043488336 | ... P29: ='Res Sales by Year (18-20)'!P29/'Res Sales by Year (18-20)'!P64 -> 0.047133936
A30: =+A29+1 -> 20
A31: =+A30+1 -> 21 | B31: Longview | C31: =+C26 -> 2018 | D31: ='Res Sales by Year (18-20)'!D31/'Res Sales by Year (18-20)'!D61 -> 0.039831202 | E31: ='Res Sales by Year (18-20)'!E31/'Res Sales by Year (18-20)'!E$61 -> 0.039807215 | F31: ='Res Sales by Year (18-20)'!F31/'Res Sales by Year (18-20)'!F$61 -> 0.037398049 | G31: ='Res Sales by Year (18-20)'!G31/'Res Sales by Year (18-20)'!G$61 -> 0.037661846 | H31: ='Res Sales by Year (18-20)'!H31/'Res Sales by Year (18-20)'!H$61 -> 0.036925166 | I31: ='Res Sales by Year (18-20)'!I31/'Res Sales by Year (18-20)'!I$61 -> 0.035078021 | J31: ='Res Sales by Year (18-20)'!J31/'Res Sales by Year (18-20)'!J$61 -> 0.034242719 | K31: ='Res Sales by Year (18-20)'!K31/'Res Sales by Year (18-20)'!K$61 -> 0.034826337 | L31: ='Res Sales by Year (18-20)'!L31/'Res Sales by Year (18-20)'!L$61 -> 0.036274479 | ... P31: ='Res Sales by Year (18-20)'!P31/'Res Sales by Year (18-20)'!P$61 -> 0.036928975
A32: =+A31+1 -> 22 | B32: Longview | C32: =+C27 -> 2019 | D32: ='Res Sales by Year (18-20)'!D32/'Res Sales by Year (18-20)'!D62 -> 0.038159119 | E32: ='Res Sales by Year (18-20)'!E32/'Res Sales by Year (18-20)'!E$62 -> 0.039203041 | F32: ='Res Sales by Year (18-20)'!F32/'Res Sales by Year (18-20)'!F$62 -> 0.038325346 | G32: ='Res Sales by Year (18-20)'!G32/'Res Sales by Year (18-20)'!G$62 -> 0.038258264 | H32: ='Res Sales by Year (18-20)'!H32/'Res Sales by Year (18-20)'!H$62 -> 0.036819893 | I32: ='Res Sales by Year (18-20)'!I32/'Res Sales by Year (18-20)'!I$62 -> 0.036870634 | J32: ='Res Sales by Year (18-20)'!J32/'Res Sales by Year (18-20)'!J$62 -> 0.034605234 | K32: ='Res Sales by Year (18-20)'!K32/'Res Sales by Year (18-20)'!K$62 -> 0.034400631 | L32: ='Res Sales by Year (18-20)'!L32/'Res Sales by Year (18-20)'!L$62 -> 0.03499239 | ... P32: ='Res Sales by Year (18-20)'!P32/'Res Sales by Year (18-20)'!P$62 -> 0.036490104
A33: =+A32+1 -> 23 | B33: Longview | C33: =+C28 -> 2020 | D33: ='Res Sales by Year (18-20)'!D33/'Res Sales by Year (18-20)'!D63 -> 0.03872693 | E33: ='Res Sales by Year (18-20)'!E33/'Res Sales by Year (18-20)'!E63 -> 0.038915209 | F33: ='Res Sales by Year (18-20)'!F33/'Res Sales by Year (18-20)'!F63 -> 0.038732266 | G33: ='Res Sales by Year (18-20)'!G33/'Res Sales by Year (18-20)'!G63 -> 0.036942852 | H33: ='Res Sales by Year (18-20)'!H33/'Res Sales by Year (18-20)'!H63 -> 0.035267035 | I33: ='Res Sales by Year (18-20)'!I33/'Res Sales by Year (18-20)'!I63 -> 0.034828561 | J33: ='Res Sales by Year (18-20)'!J33/'Res Sales by Year (18-20)'!J63 -> 0.034626348 | K33: ='Res Sales by Year (18-20)'!K33/'Res Sales by Year (18-20)'!K63 -> 0.034474334 | ... P33: ='Res Sales by Year (18-20)'!P33/'Res Sales by Year (18-20)'!P63 -> 0.036026689
A34: =+A33+1 -> 24 | B34: Longview | C34: Total | D34: ='Res Sales by Year (18-20)'!D34/'Res Sales by Year (18-20)'!D64 -> 0.038966903 | E34: ='Res Sales by Year (18-20)'!E34/'Res Sales by Year (18-20)'!E64 -> 0.039325245 | F34: ='Res Sales by Year (18-20)'!F34/'Res Sales by Year (18-20)'!F64 -> 0.038164762 | G34: ='Res Sales by Year (18-20)'!G34/'Res Sales by Year (18-20)'!G64 -> 0.037615111 | H34: ='Res Sales by Year (18-20)'!H34/'Res Sales by Year (18-20)'!H64 -> 0.036292026 | I34: ='Res Sales by Year (18-20)'!I34/'Res Sales by Year (18-20)'!I64 -> 0.035532292 | J34: ='Res Sales by Year (18-20)'!J34/'Res Sales by Year (18-20)'!J64 -> 0.034480561 | K34: ='Res Sales by Year (18-20)'!K34/'Res Sales by Year (18-20)'!K64 -> 0.034571142 | ... P34: ='Res Sales by Year (18-20)'!P34/'Res Sales by Year (18-20)'!P64 -> 0.036488214
A35: =+A34+1 -> 25
A36: =+A35+1 -> 26 | B36: Waco | C36: =+C31 -> 2018 | D36: ='Res Sales by Year (18-20)'!D36/'Res Sales by Year (18-20)'!D61 -> 0.039102211 | E36: ='Res Sales by Year (18-20)'!E36/'Res Sales by Year (18-20)'!E$61 -> 0.041157995 | F36: ='Res Sales by Year (18-20)'!F36/'Res Sales by Year (18-20)'!F$61 -> 0.04045243 | G36: ='Res Sales by Year (18-20)'!G36/'Res Sales by Year (18-20)'!G$61 -> 0.037188174 | H36: ='Res Sales by Year (18-20)'!H36/'Res Sales by Year (18-20)'!H$61 -> 0.036183032 | I36: ='Res Sales by Year (18-20)'!I36/'Res Sales by Year (18-20)'!I$61 -> 0.034921492 | J36: ='Res Sales by Year (18-20)'!J36/'Res Sales by Year (18-20)'!J$61 -> 0.0349725 | K36: ='Res Sales by Year (18-20)'!K36/'Res Sales by Year (18-20)'!K$61 -> 0.036719322 | L36: ='Res Sales by Year (18-20)'!L36/'Res Sales by Year (18-20)'!L$61 -> 0.038137914 | ... P36: ='Res Sales by Year (18-20)'!P36/'Res Sales by Year (18-20)'!P$61 -> 0.037709149
A37: =+A36+1 -> 27 | B37: Waco | C37: =+C32 -> 2019 | D37: ='Res Sales by Year (18-20)'!D37/'Res Sales by Year (18-20)'!D62 -> 0.039893154 | E37: ='Res Sales by Year (18-20)'!E37/'Res Sales by Year (18-20)'!E$62 -> 0.039866413 | F37: ='Res Sales by Year (18-20)'!F37/'Res Sales by Year (18-20)'!F$62 -> 0.03983479 | G37: ='Res Sales by Year (18-20)'!G37/'Res Sales by Year (18-20)'!G$62 -> 0.038755656 | H37: ='Res Sales by Year (18-20)'!H37/'Res Sales by Year (18-20)'!H$62 -> 0.036363419 | I37: ='Res Sales by Year (18-20)'!I37/'Res Sales by Year (18-20)'!I$62 -> 0.036110301 | J37: ='Res Sales by Year (18-20)'!J37/'Res Sales by Year (18-20)'!J$62 -> 0.034791109 | K37: ='Res Sales by Year (18-20)'!K37/'Res Sales by Year (18-20)'!K$62 -> 0.035326043 | L37: ='Res Sales by Year (18-20)'!L37/'Res Sales by Year (18-20)'!L$62 -> 0.036088357 | ... P37: ='Res Sales by Year (18-20)'!P37/'Res Sales by Year (18-20)'!P$62 -> 0.037510806
A38: =+A37+1 -> 28 | B38: Waco | C38: =+C33 -> 2020 | D38: ='Res Sales by Year (18-20)'!D38/'Res Sales by Year (18-20)'!D63 -> 0.038903972 | E38: ='Res Sales by Year (18-20)'!E38/'Res Sales by Year (18-20)'!E63 -> 0.03825304 | F38: ='Res Sales by Year (18-20)'!F38/'Res Sales by Year (18-20)'!F63 -> 0.040549532 | G38: ='Res Sales by Year (18-20)'!G38/'Res Sales by Year (18-20)'!G63 -> 0.03678123 | H38: ='Res Sales by Year (18-20)'!H38/'Res Sales by Year (18-20)'!H63 -> 0.03623308 | I38: ='Res Sales by Year (18-20)'!I38/'Res Sales by Year (18-20)'!I63 -> 0.035195335 | J38: ='Res Sales by Year (18-20)'!J38/'Res Sales by Year (18-20)'!J63 -> 0.034243178 | K38: ='Res Sales by Year (18-20)'!K38/'Res Sales by Year (18-20)'!K63 -> 0.03610105 | ... P38: ='Res Sales by Year (18-20)'!P38/'Res Sales by Year (18-20)'!P63 -> 0.036940769
A39: =+A38+1 -> 29 | B39: Waco | C39: Total | D39: ='Res Sales by Year (18-20)'!D39/'Res Sales by Year (18-20)'!D64 -> 0.039296716 | E39: ='Res Sales by Year (18-20)'!E39/'Res Sales by Year (18-20)'!E64 -> 0.039822223 | F39: ='Res Sales by Year (18-20)'!F39/'Res Sales by Year (18-20)'!F64 -> 0.040258223 | G39: ='Res Sales by Year (18-20)'!G39/'Res Sales by Year (18-20)'!G64 -> 0.037574406 | H39: ='Res Sales by Year (18-20)'!H39/'Res Sales by Year (18-20)'!H64 -> 0.036258187 | I39: ='Res Sales by Year (18-20)'!I39/'Res Sales by Year (18-20)'!I64 -> 0.035367661 | J39: ='Res Sales by Year (18-20)'!J39/'Res Sales by Year (18-20)'!J64 -> 0.034672013 | K39: ='Res Sales by Year (18-20)'!K39/'Res Sales by Year (18-20)'!K64 -> 0.03606507 | ... P39: ='Res Sales by Year (18-20)'!P39/'Res Sales by Year (18-20)'!P64 -> 0.037392541
A40: =+A39+1 -> 30
A41: =+A40+1 -> 31 | B41: Abilene | C41: =+C36 -> 2018 | D41: ='Res Sales by Year (18-20)'!D41/'Res Sales by Year (18-20)'!D61 -> 0.014399213 | E41: ='Res Sales by Year (18-20)'!E41/'Res Sales by Year (18-20)'!E$61 -> 0.013872113 | F41: ='Res Sales by Year (18-20)'!F41/'Res Sales by Year (18-20)'!F$61 -> 0.013338126 | G41: ='Res Sales by Year (18-20)'!G41/'Res Sales by Year (18-20)'!G$61 -> 0.013235194 | H41: ='Res Sales by Year (18-20)'!H41/'Res Sales by Year (18-20)'!H$61 -> 0.013053948 | I41: ='Res Sales by Year (18-20)'!I41/'Res Sales by Year (18-20)'!I$61 -> 0.012878504 | J41: ='Res Sales by Year (18-20)'!J41/'Res Sales by Year (18-20)'!J$61 -> 0.012532734 | K41: ='Res Sales by Year (18-20)'!K41/'Res Sales by Year (18-20)'!K$61 -> 0.01187196 | L41: ='Res Sales by Year (18-20)'!L41/'Res Sales by Year (18-20)'!L$61 -> 0.011772286 | ... P41: ='Res Sales by Year (18-20)'!P41/'Res Sales by Year (18-20)'!P$61 -> 0.01297002
A42: =+A41+1 -> 32 | B42: Abilene | C42: =+C37 -> 2019 | D42: ='Res Sales by Year (18-20)'!D42/'Res Sales by Year (18-20)'!D62 -> 0.01506189 | E42: ='Res Sales by Year (18-20)'!E42/'Res Sales by Year (18-20)'!E$62 -> 0.013958985 | F42: ='Res Sales by Year (18-20)'!F42/'Res Sales by Year (18-20)'!F$62 -> 0.013576899 | G42: ='Res Sales by Year (18-20)'!G42/'Res Sales by Year (18-20)'!G$62 -> 0.013375411 | H42: ='Res Sales by Year (18-20)'!H42/'Res Sales by Year (18-20)'!H$62 -> 0.012284328 | I42: ='Res Sales by Year (18-20)'!I42/'Res Sales by Year (18-20)'!I$62 -> 0.01176653 | J42: ='Res Sales by Year (18-20)'!J42/'Res Sales by Year (18-20)'!J$62 -> 0.012247159 | K42: ='Res Sales by Year (18-20)'!K42/'Res Sales by Year (18-20)'!K$62 -> 0.012484527 | L42: ='Res Sales by Year (18-20)'!L42/'Res Sales by Year (18-20)'!L$62 -> 0.011751875 | ... P42: ='Res Sales by Year (18-20)'!P42/'Res Sales by Year (18-20)'!P$62 -> 0.012931715
...

Sheet Res Sales by Year (18-20)
B1: PUC DOCKET NO.
B2: ONCOR ELECTRIC DELIVERY COMPANY
B3: WEATHER WEIGHTS
B4: =+'Res Seasonal Weights'!B4:P4 -> FOR THE TEST YEAR ENDING DECEMBER 31, 2021
B6: SPONSOR: D. E. NELSON
B8: RESIDENTIAL MONTHLY KWH SALES BY YEAR
A9: Line | B9: (a) | C9: (b) | D9: (c) | E9: (d) | F9: (e) | G9: (f) | H9: (g) | I9: (h) | J9: (i) | K9: (j) | L9: (k) | M9: (l) | N9: (m) | O9: (n) | P9: (o)
A10: No. | B10: Weather Station | C10: Year | D10: 36892 | E10: 36923 | F10: 36951 | G10: 36982 | H10: 37012 | I10: 37043 | J10: 37073 | K10: 37104 | L10: 37135 | M10: 37165 | N10: 37196 | O10: 37226 | P10: Annual
A11: 1 | B11: Dallas-Fort Worth | C11: =+'Res Weights by Year (18-20)'!C11 -> 2018 | D11: 3126308.4 | E11: 2661392 | F11: 2140665.3 | G11: 1708376.1 | H11: 1825742.7 | I11: 3080666.9 | J11: 3931111.5 | K11: 3932869.4 | L11: 3433388.3 | M11: 2455572.6 | N11: 1778714.4 | O11: 2273925.2 | P11: =SUM(D11:O11) -> 32348733
A12: =+A11+1 -> 2 | B12: Dallas-Fort Worth | C12: =+'Res Weights by Year (18-20)'!C12 -> 2019 | D12: 2579293.5 | E12: 2644761.4 | F12: 2470394.6 | G12: 1769270.9 | H12: 1791772.3 | I12: 2466115 | J12: 3175970.7 | K12: 3642741.7 | L12: 3909479.8 | M12: 3153904.9 | N12: 1985614.6 | O12: 2184504.7 | P12: =SUM(D12:O12) -> 31773824
A13: =+A12+1 -> 3 | B13: Dallas-Fort Worth | C13: =+'Res Weights by Year (18-20)'!C13 -> 2020 | D13: 2400249.3 | E13: 2322171.2 | F13: 2135389.1 | G13: 1823306.8 | H13: 2047587.6 | I13: 2713601.7 | J13: 3580871.9 | K13: 3851103.8 | L13: 3552201.4 | M13: 2335339.5 | N13: 2006988.7 | O13: 2000689.5 | P13: =SUM(D13:O13) -> 30769500
A14: =+A13+1 -> 4 | B14: Dallas-Fort Worth | C14: Total | D14: =SUM(D11:D13) -> 8105851.2 | E14: =SUM(E11:E13) -> 7628324.6 | F14: =SUM(F11:F13) -> 6746449 | G14: =SUM(G11:G13) -> 5300953.7 | H14: =SUM(H11:H13) -> 5665102.6 | I14: =SUM(I11:I13) -> 8260383.6 | J14: =SUM(J11:J13) -> 10687954 | K14: =SUM(K11:K13) -> 11426715 | ... O14: =SUM(O11:O13) -> 6459119.4 | P14: =SUM(D14:O14) -> 94892057
A15: =+A14+1 -> 5
A16: =+A15+1 -> 6 | B16: Lufkin | C16: =+C11 -> 2018 | D16: 139657.46 | E16: 116481.75 | F16: 78964.79 | G16: 70124.159 | H16: 72900.803 | I16: 112991.73 | J16: 136133.64 | K16: 137747.23 | L16: 129107.22 | M16: 95341.086 | N16: 74111.318 | O16: 102899.34 | P16: =SUM(D16:O16) -> 1266460.5
A17: =+A16+1 -> 7 | B17: Lufkin | C17: =+C12 -> 2019 | D17: 107105.3 | E17: 113322.51 | F17: 97631.588 | G17: 72339.412 | H17: 70999.292 | I17: 99403.786 | J17: 115817.78 | K17: 127274.94 | L17: 136277.67 | M17: 107145.68 | N17: 80037.455 | O17: 93446.828 | P17: =SUM(D17:O17) -> 1220802.2
A18: =+A17+1 -> 8 | B18: Lufkin | C18: =+C13 -> 2020 | D18: 103480.02 | E18: 99591.992 | F18: 89068.501 | G18: 72231.448 | H18: 75356.593 | I18: 99283.748 | J18: 127310.3 | K18: 134307.36 | L18: 128139.29 | M18: 87240.144 | N18: 76374.865 | O18: 85092.594 | P18: =SUM(D18:O18) -> 1177476.9
A19: =+A18+1 -> 9 | B19: Lufkin | C19: Total | D19: =SUM(D16:D18) -> 350242.78 | E19: =SUM(E16:E18) -> 329396.26 | F19: =SUM(F16:F18) -> 265664.88 | G19: =SUM(G16:G18) -> 214695.02 | H19: =SUM(H16:H18) -> 219256.69 | I19: =SUM(I16:I18) -> 311679.26 | J19: =SUM(J16:J18) -> 379261.72 | K19: =SUM(K16:K18) -> 399329.54 | ... O19: =SUM(O16:O18) -> 281438.76 | P19: =SUM(D19:O19) -> 3664739.6
A20: =+A19+1 -> 10
A21: =+A20+1 -> 11 | B21: Austin | C21: =+C16 -> 2018 | D21: 148479.76 | E21: 122962.36 | F21: 103295.38 | G21: 99627.546 | H21: 109566.94 | I21: 185662.17 | J21: 217649.77 | K21: 227559.88 | L21: 213233.77 | M21: 147362.05 | N21: 103799.32 | O21: 117092.25 | P21: =SUM(D21:O21) -> 1796291.2
A22: =+A21+1 -> 12 | B22: Austin | C22: =+C17 -> 2019 | D22: 129792.82 | E22: 126073.6 | F22: 117462.31 | G22: 101500.93 | H22: 112700.39 | I22: 163468.33 | J22: 197332.06 | K22: 224744.81 | L22: 239563.48 | M22: 194421.26 | N22: 117013.08 | O22: 117403.36 | P22: =SUM(D22:O22) -> 1841476.4
A23: =+A22+1 -> 13 | B23: Austin | C23: =+C18 -> 2020 | D23: 125001.78 | E23: 114236.56 | F23: 113713.05 | G23: 116984.26 | H23: 134225.6 | I23: 182203.7 | J23: 226748.63 | K23: 239252.97 | L23: 228670.27 | M23: 153089.07 | N23: 131819.18 | O23: 119249.08 | P23: =SUM(D23:O23) -> 1885194.1
A24: =+A23+1 -> 14 | B24: Austin | C24: Total | D24: =SUM(D21:D23) -> 403274.36 | E24: =SUM(E21:E23) -> 363272.52 | F24: =SUM(F21:F23) -> 334470.74 | G24: =SUM(G21:G23) -> 318112.74 | H24: =SUM(H21:H23) -> 356492.93 | I24: =SUM(I21:I23) -> 531334.19 | J24: =SUM(J21:J23) -> 641730.46 | K24: =SUM(K21:K23) -> 691557.66 | ... O24: =SUM(O21:O23) -> 353744.69 | P24: =SUM(D24:O24) -> 5522961.8
A25: =+A24+1 -> 15
A26: =+A25+1 -> 16 | B26: Killeen | C26: =+C21 -> 2018 | D26: 238363.5 | E26: 201367.75 | F26: 151595.34 | G26: 117784.29 | H26: 120178.15 | I26: 188407.07 | J26: 224564.63 | K26: 236916.68 | L26: 215399.01 | M26: 155071.43 | N26: 124677.46 | O26: 172084.63 | P26: =SUM(D26:O26) -> 2146409.9
A27: =+A26+1 -> 17 | B27: Killeen | C27: =+C22 -> 2019 | D27: 201491.96 | E27: 197909.32 | F27: 182968.53 | G27: 126939.59 | H27: 120086.38 | I27: 162963.9 | J27: 195820.78 | K27: 220950.3 | L27: 237790.54 | M27: 195342.53 | N27: 142927.3 | O27: 162613.4 | P27: =SUM(D27:O27) -> 2147804.5
A28: =+A27+1 -> 18 | B28: Killeen | C28: =+C23 -> 2020 | D28: 181413.74 | E28: 169854.16 | F28: 163801.39 | G28: 127362.17 | H28: 140528.17 | I28: 179823.16 | J28: 225556.69 | K28: 243545.63 | L28: 228832.8 | M28: 153253.92 | N28: 144343.55 | O28: 148645.52 | P28: =SUM(D28:O28) -> 2106960.9
A29: =+A28+1 -> 19 | B29: Killeen | C29: Total | D29: =SUM(D26:D28) -> 621269.2 | E29: =SUM(E26:E28) -> 569131.23 | F29: =SUM(F26:F28) -> 498365.26 | G29: =SUM(G26:G28) -> 372086.05 | H29: =SUM(H26:H28) -> 380792.69 | I29: =SUM(I26:I28) -> 531194.13 | J29: =SUM(J26:J28) -> 645942.09 | K29: =SUM(K26:K28) -> 701412.61 | ... O29: =SUM(O26:O28) -> 483343.55 | P29: =SUM(D29:O29) -> 6401175.4
A30: =+A29+1 -> 20
A31: =+A30+1 -> 21 | B31: Longview | C31: =+C26 -> 2018 | D31: 179544.92 | E31: 153446 | F31: 114432.42 | G31: 92632.176 | H31: 96731.349 | I31: 152906.02 | J31: 187547.18 | K31: 192013.53 | L31: 176751.74 | M31: 127380.14 | N31: 97078.714 | O31: 132201.21 | P31: =SUM(D31:O31) -> 1702665.4
A32: =+A31+1 -> 22 | B32: Longview | C32: =+C27 -> 2019 | D32: 144263.89 | E32: 150185.02 | F32: 136258.55 | G32: 98322.636 | H32: 94743.992 | I32: 129736.9 | J32: 155710.34 | K32: 177067.48 | L32: 192858.07 | M32: 152365.89 | N32: 104347.21 | O32: 123822.54 | P32: =SUM(D32:O32) -> 1659682.5
A33: =+A32+1 -> 23 | B33: Longview | C33: =+C28 -> 2020 | D33: 135891.55 | E33: 131892.65 | F33: 121150.93 | G33: 97148.441 | H33: 103803.21 | I33: 135064.41 | J33: 176157.61 | K33: 188508.39 | L33: 173720.31 | M33: 115064.87 | N33: 102437.49 | O33: 112211.1 | P33: =SUM(D33:O33) -> 1593051
A34: =+A33+1 -> 24 | B34: Longview | C34: Total | D34: =SUM(D31:D33) -> 459700.36 | E34: =SUM(E31:E33) -> 435523.67 | F34: =SUM(F31:F33) -> 371841.9 | G34: =SUM(G31:G33) -> 288103.25 | H34: =SUM(H31:H33) -> 295278.55 | I34: =SUM(I31:I33) -> 417707.32 | J34: =SUM(J31:J33) -> 519415.13 | K34: =SUM(K31:K33) -> 557589.39 | ... O34: =SUM(O31:O33) -> 368234.86 | P34: =SUM(D34:O34) -> 4955398.9
A35: =+A34+1 -> 25
A36: =+A35+1 -> 26 | B36: Waco | C36: =+C31 -> 2018 | D36: 176258.89 | E36: 158652.89 | F36: 123778.37 | G36: 91467.143 | H36: 94787.211 | I36: 152223.71 | J36: 191544.18 | K36: 202450.42 | L36: 185831.55 | M36: 132467.98 | N36: 99218.766 | O36: 129955.37 | P36: =SUM(D36:O36) -> 1738636.5
A37: =+A36+1 -> 27 | B37: Waco | C37: =+C32 -> 2019 | D37: 150819.56 | E37: 152726.37 | F37: 141625.09 | G37: 99600.918 | H37: 93569.404 | I37: 127061.51 | J37: 156546.71 | K37: 181830.78 | L37: 198898.42 | M37: 165521.06 | N37: 112498.68 | O37: 125408.7 | P37: =SUM(D37:O37) -> 1706107.2
A38: =+A37+1 -> 28 | B38: Waco | C38: =+C33 -> 2020 | D38: 136512.79 | E38: 129648.4 | F38: 126835.17 | G38: 96723.423 | H38: 106646.62 | I38: 136486.75 | J38: 174208.28 | K38: 197403.4 | L38: 185112.33 | M38: 124605.8 | N38: 110290.37 | O38: 108997.01 | P38: =SUM(D38:O38) -> 1633470.3
A39: =+A38+1 -> 29 | B39: Waco | C39: Total | D39: =SUM(D36:D38) -> 463591.24 | E39: =SUM(E36:E38) -> 441027.66 | F39: =SUM(F36:F38) -> 392238.63 | G39: =SUM(G36:G38) -> 287791.48 | H39: =SUM(H36:H38) -> 295003.23 | I39: =SUM(I36:I38) -> 415771.96 | J39: =SUM(J36:J38) -> 522299.17 | K39: =SUM(K36:K38) -> 581684.6 | ... O39: =SUM(O36:O38) -> 364361.08 | P39: =SUM(D39:O39) -> 5078214
A40: =+A39+1 -> 30
A41: =+A40+1 -> 31 | B41: Abilene | C41: =+C36 -> 2018 | D41: 64906.541 | E41: 53473.229 | F41: 40812.664 | G41: 32552.967 | H41: 34196.894 | I41: 56137.737 | J41: 68641.711 | K41: 65455.548 | L41: 57361.874 | M41: 39586.75 | N41: 35433.165 | O41: 49443.01 | P41: =SUM(D41:O41) -> 598002.09
A42: =+A41+1 -> 32 | B42: Abilene | C42: =+C37 -> 2019 | D42: 56942.792 | E42: 53476.221 | F42: 48270.105 | G42: 34374.421 | H42: 31609.714 | I42: 41402.951 | J42: 55107.539 | K42: 64260.561 | L42: 64769.628 | M42: 50453.622 | N42: 40927.226 | O42: 46579.521 | P42: =SUM(D42:O42) -> 588174.3
...
