Workbook
Name HOURLY: [1]HOURLY!$A$1:$G$745
Name OLE_LINK2: 'SUBS Seasonal Weights'!$B$24
Name rngBilled: OFFSET([2]Sheet2!$A$2,0,0,[2]Sheet2!$B$1,9)
Name rngYear: OFFSET('[3]Daily Actual_August'!$A$2,0,0,'[3]Daily Actual_August'!$C$1,8)

Sheet SUBS Seasonal Weights
B1: PUC DOCKET NO.
B2: ONCOR ELECTRIC DELIVERY COMPANY LLC
B3: WEATHER WEIGHTS
B4: FOR THE TEST YEAR ENDING DECEMBER 31, 2024
B6: SPONSOR: D. E. NELSON
B8: PRIMARY SERVICE GREATER THAN 10 KW SUBSTATION MONTHLY WEIGHTS
A9: Line | B9: (a) | D9: (b) | E9: (c) | F9: (d) | G9: (e) | H9: (f) | I9: (g) | J9: (h) | K9: (i) | L9: (j) | M9: (k) | N9: (l) | O9: (m) | P9: (n)
A10: No. | B10: Weather Station | D10: 36892 | E10: 36923 | F10: 36951 | G10: 36982 | H10: 37012 | I10: 37043 | J10: 37073 | K10: 37104 | L10: 37135 | M10: 37165 | N10: 37196 | O10: 37226 | P10: Annual
A11: 1 | B11: Dallas-Fort Worth | D11: =+'SUBS Monthly Weather Weights'!C11 -> 0.1415486 | E11: =+'SUBS Monthly Weather Weights'!D11 -> 0.13962995 | F11: =+'SUBS Monthly Weather Weights'!E11 -> 0.13634199 | G11: =+'SUBS Monthly Weather Weights'!F11 -> 0.14572047 | H11: =+'SUBS Monthly Weather Weights'!G11 -> 0.14382008 | I11: =+'SUBS Monthly Weather Weights'!H11 -> 0.1434625 | J11: =+'SUBS Monthly Weather Weights'!I11 -> 0.14989086 | K11: =+'SUBS Monthly Weather Weights'!J11 -> 0.13129773 | ... P11: =+'SUBS Monthly Weather Weights'!O11 -> 0.14219326
A12: =+A11+1 -> 2 | B12: Midland-Odessa | D12: =+'SUBS Monthly Weather Weights'!C12 -> 0.6524904 | E12: =+'SUBS Monthly Weather Weights'!D12 -> 0.65531606 | F12: =+'SUBS Monthly Weather Weights'!E12 -> 0.65331011 | G12: =+'SUBS Monthly Weather Weights'!F12 -> 0.64162653 | H12: =+'SUBS Monthly Weather Weights'!G12 -> 0.65333018 | I12: =+'SUBS Monthly Weather Weights'!H12 -> 0.65843089 | J12: =+'SUBS Monthly Weather Weights'!I12 -> 0.64257627 | K12: =+'SUBS Monthly Weather Weights'!J12 -> 0.69529586 | ... P12: =+'SUBS Monthly Weather Weights'!O12 -> 0.65797553
A13: =+A12+1 -> 3 | B13: Lufkin | D13: =+'SUBS Monthly Weather Weights'!C13 -> 0.0206081 | E13: =+'SUBS Monthly Weather Weights'!D13 -> 0.021203115 | F13: =+'SUBS Monthly Weather Weights'!E13 -> 0.022690679 | G13: =+'SUBS Monthly Weather Weights'!F13 -> 0.021886197 | H13: =+'SUBS Monthly Weather Weights'!G13 -> 0.022224289 | I13: =+'SUBS Monthly Weather Weights'!H13 -> 0.023028576 | J13: =+'SUBS Monthly Weather Weights'!I13 -> 0.026105442 | K13: =+'SUBS Monthly Weather Weights'!J13 -> 0.019441099 | ... P13: =+'SUBS Monthly Weather Weights'!O13 -> 0.023204547
A14: =+A13+1 -> 4 | B14: Abilene | D14: =+'SUBS Monthly Weather Weights'!C14 -> 0.058828374 | E14: =+'SUBS Monthly Weather Weights'!D14 -> 0.05718681 | F14: =+'SUBS Monthly Weather Weights'!E14 -> 0.048746367 | G14: =+'SUBS Monthly Weather Weights'!F14 -> 0.05412658 | H14: =+'SUBS Monthly Weather Weights'!G14 -> 0.049721742 | I14: =+'SUBS Monthly Weather Weights'!H14 -> 0.04882885 | J14: =+'SUBS Monthly Weather Weights'!I14 -> 0.046574521 | K14: =+'SUBS Monthly Weather Weights'!J14 -> 0.035978702 | ... P14: =+'SUBS Monthly Weather Weights'!O14 -> 0.047873284
A15: =+A14+1 -> 5 | B15: Sherman-Denison | D15: =+'SUBS Monthly Weather Weights'!C15 -> 0.012058501 | E15: =+'SUBS Monthly Weather Weights'!D15 -> 0.0074608387 | F15: =+'SUBS Monthly Weather Weights'!E15 -> 0.0082529336 | G15: =+'SUBS Monthly Weather Weights'!F15 -> 0.0091278488 | H15: =+'SUBS Monthly Weather Weights'!G15 -> 0.010650656 | I15: =+'SUBS Monthly Weather Weights'!H15 -> 0.012433409 | J15: =+'SUBS Monthly Weather Weights'!I15 -> 0.011261093 | K15: =+'SUBS Monthly Weather Weights'!J15 -> 0.0094969414 | ... P15: =+'SUBS Monthly Weather Weights'!O15 -> 0.0095588756
A16: =+A15+1 -> 6 | B16: Killeen-Temple | D16: =+'SUBS Monthly Weather Weights'!C16 -> 0.069936929 | E16: =+'SUBS Monthly Weather Weights'!D16 -> 0.077000996 | F16: =+'SUBS Monthly Weather Weights'!E16 -> 0.08617944 | G16: =+'SUBS Monthly Weather Weights'!F16 -> 0.083934691 | H16: =+'SUBS Monthly Weather Weights'!G16 -> 0.081291273 | I16: =+'SUBS Monthly Weather Weights'!H16 -> 0.074308478 | J16: =+'SUBS Monthly Weather Weights'!I16 -> 0.080990966 | K16: =+'SUBS Monthly Weather Weights'!J16 -> 0.073742297 | ... P16: =+'SUBS Monthly Weather Weights'!O16 -> 0.078229094
A17: =+A16+1 -> 7 | B17: Waco | D17: =+'SUBS Monthly Weather Weights'!C17 -> 0.0086067885 | E17: =+'SUBS Monthly Weather Weights'!D17 -> 0.0087123329 | F17: =+'SUBS Monthly Weather Weights'!E17 -> 0.0099670018 | G17: =+'SUBS Monthly Weather Weights'!F17 -> 0.010947441 | H17: =+'SUBS Monthly Weather Weights'!G17 -> 0.0085862154 | I17: =+'SUBS Monthly Weather Weights'!H17 -> 0.0086365655 | J17: =+'SUBS Monthly Weather Weights'!I17 -> 0.0096625598 | K17: =+'SUBS Monthly Weather Weights'!J17 -> 0.0085505165 | ... P17: =+'SUBS Monthly Weather Weights'!O17 -> 0.0088712639
A18: =+A17+1 -> 8 | B18: Wichita Falls. | D18: =+'SUBS Monthly Weather Weights'!C18 -> 0.021181036 | E18: =+'SUBS Monthly Weather Weights'!D18 -> 0.020212328 | F18: =+'SUBS Monthly Weather Weights'!E18 -> 0.021882601 | G18: =+'SUBS Monthly Weather Weights'!F18 -> 0.021282689 | H18: =+'SUBS Monthly Weather Weights'!G18 -> 0.020355611 | I18: =+'SUBS Monthly Weather Weights'!H18 -> 0.021973646 | J18: =+'SUBS Monthly Weather Weights'!I18 -> 0.02173623 | K18: =+'SUBS Monthly Weather Weights'!J18 -> 0.017142176 | ... P18: =+'SUBS Monthly Weather Weights'!O18 -> 0.020018852
A19: =+A18+1 -> 9 | B19: Longview | D19: =+'SUBS Monthly Weather Weights'!C19 -> 0.014741276 | E19: =+'SUBS Monthly Weather Weights'!D19 -> 0.013277575 | F19: =+'SUBS Monthly Weather Weights'!E19 -> 0.012628873 | G19: =+'SUBS Monthly Weather Weights'!F19 -> 0.01134756 | H19: =+'SUBS Monthly Weather Weights'!G19 -> 0.010019953 | I19: =+'SUBS Monthly Weather Weights'!H19 -> 0.0088970904 | J19: =+'SUBS Monthly Weather Weights'!I19 -> 0.011202062 | K19: =+'SUBS Monthly Weather Weights'!J19 -> 0.0090546789 | ... P19: =+'SUBS Monthly Weather Weights'!O19 -> 0.012075291
A20: =+A19+1 -> 10 | B20: Austin | D20: =+'SUBS Monthly Weather Weights'!C20 -> 0 | E20: =+'SUBS Monthly Weather Weights'!D20 -> 0 | F20: =+'SUBS Monthly Weather Weights'!E20 -> 0 | G20: =+'SUBS Monthly Weather Weights'!F20 -> 0 | H20: =+'SUBS Monthly Weather Weights'!G20 -> 0 | I20: =+'SUBS Monthly Weather Weights'!H20 -> 0 | J20: =+'SUBS Monthly Weather Weights'!I20 -> 0 | K20: =+'SUBS Monthly Weather Weights'!J20 -> 0 | ... P20: =+'SUBS Monthly Weather Weights'!O20 -> 0
A21: =+A20+1 -> 11 | D21: =SUM(D11:D20) -> 1 | E21: =SUM(E11:E20) -> 1 | F21: =SUM(F11:F20) -> 1 | G21: =SUM(G11:G20) -> 1 | H21: =SUM(H11:H20) -> 1 | I21: =SUM(I11:I20) -> 1 | J21: =SUM(J11:J20) -> 1 | K21: =SUM(K11:K20) -> 1 | ... P21: =SUM(P11:P20) -> 1
A22: =+A21+1 -> 12
A23: =+A22+1 -> 13 | D23: SEASONAL WEIGHTS
A24: =+A23+1 -> 14 | D24: Nov to Mar | F24: May to Sep
A25: =+A24+1 -> 15 | B25: Weather Station | D25: HDD | F25: CDD
A26: =+A25+1 -> 16 | B26: Dallas-Fort Worth | D26: =ROUND(AVERAGE(D11:F11,N11:O11),3) -> 0.138 | F26: =ROUND(AVERAGE(H11:L11),3) -> 0.144
A27: =+A26+1 -> 17 | B27: Midland-Odessa | D27: =ROUND(AVERAGE(D12:F12,N12:O12),3) -> 0.663 | F27: =ROUND(AVERAGE(H12:L12),3) -> 0.656
A28: =+A27+1 -> 18 | B28: Lufkin | D28: =ROUND(AVERAGE(D13:F13,N13:O13),3) -> 0.022 | F28: =ROUND(AVERAGE(H13:L13),3) -> 0.025
A29: =+A28+1 -> 19 | B29: Abilene | D29: =ROUND(AVERAGE(D14:F14,N14:O14),3) -> 0.051 | F29: =ROUND(AVERAGE(H14:L14),3) -> 0.045
A30: =+A29+1 -> 20 | B30: Sherman-Denison | D30: =ROUND(AVERAGE(D15:F15,N15:O15),3) -> 0.009 | F30: =ROUND(AVERAGE(H15:L15),3) -> 0.011
A31: =+A30+1 -> 21 | B31: Killeen-Temple | D31: =ROUND(AVERAGE(D16:F16,N16:O16),3) -> 0.076 | F31: =ROUND(AVERAGE(H16:L16),3) -> 0.079
A32: =+A31+1 -> 22 | B32: Waco | D32: =ROUND(AVERAGE(D17:F17,N17:O17),3) -> 0.008 | F32: =ROUND(AVERAGE(H17:L17),3) -> 0.009
A33: =+A32+1 -> 23 | B33: Wichita Falls. | D33: =ROUND(AVERAGE(D18:F18,N18:O18),3) -> 0.02 | F33: =ROUND(AVERAGE(H18:L18),3) -> 0.02
A34: =+A33+1 -> 24 | B34: Longview | D34: =ROUND(AVERAGE(D19:F19,N19:O19),3) -> 0.014 | F34: =ROUND(AVERAGE(H19:L19),3) -> 0.011
A35: =+A34+1 -> 25 | B35: Austin | D35: =ROUND(AVERAGE(D20:F20,N20:O20),3) -> 0 | F35: =ROUND(AVERAGE(H20:L20),3) -> 0
A36: =+A35+1 -> 26 | D36: =AVERAGE(D21:F21,N21:O21) -> 1 | F36: =AVERAGE(H21:L21) -> 1

Sheet SUBS Monthly Weather Weights
B1: PUC DOCKET NO.
B2: ONCOR ELECTRIC DELIVERY COMPANY
B3: WEATHER WEIGHTS
B4: =+'SUBS Seasonal Weights'!B4:P4 -> FOR THE TEST YEAR ENDING DECEMBER 31, 2024
B6: SPONSOR: D. E. NELSON
B8: PRIMARY SERVICE GREATER THAN 10 KW SUBSTATION MONTHLY WEIGHTS
A9: Line | B9: (a) | C9: (b) | D9: (c) | E9: (d) | F9: (e) | G9: (f) | H9: (g) | I9: (h) | J9: (i) | K9: (j) | L9: (k) | M9: (l) | N9: (m) | O9: (n)
A10: No. | B10: Weather Station | C10: 36892 | D10: 36923 | E10: 36951 | F10: 36982 | G10: 37012 | H10: 37043 | I10: 37073 | J10: 37104 | K10: 37135 | L10: 37165 | M10: 37196 | N10: 37226 | O10: Annual
A11: 1 | B11: Dallas-Fort Worth | C11: =+'SUBS Weights by Year (21-23)'!D14 -> 0.1415486 | D11: =+'SUBS Weights by Year (21-23)'!E14 -> 0.13962995 | E11: =+'SUBS Weights by Year (21-23)'!F14 -> 0.13634199 | F11: =+'SUBS Weights by Year (21-23)'!G14 -> 0.14572047 | G11: =+'SUBS Weights by Year (21-23)'!H14 -> 0.14382008 | H11: =+'SUBS Weights by Year (21-23)'!I14 -> 0.1434625 | I11: =+'SUBS Weights by Year (21-23)'!J14 -> 0.14989086 | J11: =+'SUBS Weights by Year (21-23)'!K14 -> 0.13129773 | ... O11: =+'SUBS Weights by Year (21-23)'!P14 -> 0.14219326
A12: =+A11+1 -> 2 | B12: Midland-Odessa | C12: =+'SUBS Weights by Year (21-23)'!D54 -> 0.6524904 | D12: =+'SUBS Weights by Year (21-23)'!E54 -> 0.65531606 | E12: =+'SUBS Weights by Year (21-23)'!F54 -> 0.65331011 | F12: =+'SUBS Weights by Year (21-23)'!G54 -> 0.64162653 | G12: =+'SUBS Weights by Year (21-23)'!H54 -> 0.65333018 | H12: =+'SUBS Weights by Year (21-23)'!I54 -> 0.65843089 | I12: =+'SUBS Weights by Year (21-23)'!J54 -> 0.64257627 | J12: =+'SUBS Weights by Year (21-23)'!K54 -> 0.69529586 | ... O12: =+'SUBS Weights by Year (21-23)'!P54 -> 0.65797553
A13: =+A12+1 -> 3 | B13: Lufkin | C13: =+'SUBS Weights by Year (21-23)'!D19 -> 0.0206081 | D13: =+'SUBS Weights by Year (21-23)'!E19 -> 0.021203115 | E13: =+'SUBS Weights by Year (21-23)'!F19 -> 0.022690679 | F13: =+'SUBS Weights by Year (21-23)'!G19 -> 0.021886197 | G13: =+'SUBS Weights by Year (21-23)'!H19 -> 0.022224289 | H13: =+'SUBS Weights by Year (21-23)'!I19 -> 0.023028576 | I13: =+'SUBS Weights by Year (21-23)'!J19 -> 0.026105442 | J13: =+'SUBS Weights by Year (21-23)'!K19 -> 0.019441099 | ... O13: =+'SUBS Weights by Year (21-23)'!P19 -> 0.023204547
A14: =+A13+1 -> 4 | B14: Abilene | C14: =+'SUBS Weights by Year (21-23)'!D44 -> 0.058828374 | D14: =+'SUBS Weights by Year (21-23)'!E44 -> 0.05718681 | E14: =+'SUBS Weights by Year (21-23)'!F44 -> 0.048746367 | F14: =+'SUBS Weights by Year (21-23)'!G44 -> 0.05412658 | G14: =+'SUBS Weights by Year (21-23)'!H44 -> 0.049721742 | H14: =+'SUBS Weights by Year (21-23)'!I44 -> 0.04882885 | I14: =+'SUBS Weights by Year (21-23)'!J44 -> 0.046574521 | J14: =+'SUBS Weights by Year (21-23)'!K44 -> 0.035978702 | ... O14: =+'SUBS Weights by Year (21-23)'!P44 -> 0.047873284
A15: =+A14+1 -> 5 | B15: Sherman-Denison | C15: =+'SUBS Weights by Year (21-23)'!D59 -> 0.012058501 | D15: =+'SUBS Weights by Year (21-23)'!E59 -> 0.0074608387 | E15: =+'SUBS Weights by Year (21-23)'!F59 -> 0.0082529336 | F15: =+'SUBS Weights by Year (21-23)'!G59 -> 0.0091278488 | G15: =+'SUBS Weights by Year (21-23)'!H59 -> 0.010650656 | H15: =+'SUBS Weights by Year (21-23)'!I59 -> 0.012433409 | I15: =+'SUBS Weights by Year (21-23)'!J59 -> 0.011261093 | J15: =+'SUBS Weights by Year (21-23)'!K59 -> 0.0094969414 | ... O15: =+'SUBS Weights by Year (21-23)'!P59 -> 0.0095588756
A16: =+A15+1 -> 6 | B16: Killeen-Temple | C16: =+'SUBS Weights by Year (21-23)'!D29 -> 0.069936929 | D16: =+'SUBS Weights by Year (21-23)'!E29 -> 0.077000996 | E16: =+'SUBS Weights by Year (21-23)'!F29 -> 0.08617944 | F16: =+'SUBS Weights by Year (21-23)'!G29 -> 0.083934691 | G16: =+'SUBS Weights by Year (21-23)'!H29 -> 0.081291273 | H16: =+'SUBS Weights by Year (21-23)'!I29 -> 0.074308478 | I16: =+'SUBS Weights by Year (21-23)'!J29 -> 0.080990966 | J16: =+'SUBS Weights by Year (21-23)'!K29 -> 0.073742297 | ... O16: =+'SUBS Weights by Year (21-23)'!P29 -> 0.078229094
A17: =+A16+1 -> 7 | B17: Waco | C17: =+'SUBS Weights by Year (21-23)'!D39 -> 0.0086067885 | D17: =+'SUBS Weights by Year (21-23)'!E39 -> 0.0087123329 | E17: =+'SUBS Weights by Year (21-23)'!F39 -> 0.0099670018 | F17: =+'SUBS Weights by Year (21-23)'!G39 -> 0.010947441 | G17: =+'SUBS Weights by Year (21-23)'!H39 -> 0.0085862154 | H17: =+'SUBS Weights by Year (21-23)'!I39 -> 0.0086365655 | I17: =+'SUBS Weights by Year (21-23)'!J39 -> 0.0096625598 | J17: =+'SUBS Weights by Year (21-23)'!K39 -> 0.0085505165 | ... O17: =+'SUBS Weights by Year (21-23)'!P39 -> 0.0088712639
A18: =+A17+1 -> 8 | B18: Wichita Falls. | C18: =+'SUBS Weights by Year (21-23)'!D49 -> 0.021181036 | D18: =+'SUBS Weights by Year (21-23)'!E49 -> 0.020212328 | E18: =+'SUBS Weights by Year (21-23)'!F49 -> 0.021882601 | F18: =+'SUBS Weights by Year (21-23)'!G49 -> 0.021282689 | G18: =+'SUBS Weights by Year (21-23)'!H49 -> 0.020355611 | H18: =+'SUBS Weights by Year (21-23)'!I49 -> 0.021973646 | I18: =+'SUBS Weights by Year (21-23)'!J49 -> 0.02173623 | J18: =+'SUBS Weights by Year (21-23)'!K49 -> 0.017142176 | ... O18: =+'SUBS Weights by Year (21-23)'!P49 -> 0.020018852
A19: =+A18+1 -> 9 | B19: Longview | C19: =+'SUBS Weights by Year (21-23)'!D34 -> 0.014741276 | D19: =+'SUBS Weights by Year (21-23)'!E34 -> 0.013277575 | E19: =+'SUBS Weights by Year (21-23)'!F34 -> 0.012628873 | F19: =+'SUBS Weights by Year (21-23)'!G34 -> 0.01134756 | G19: =+'SUBS Weights by Year (21-23)'!H34 -> 0.010019953 | H19: =+'SUBS Weights by Year (21-23)'!I34 -> 0.0088970904 | I19: =+'SUBS Weights by Year (21-23)'!J34 -> 0.011202062 | J19: =+'SUBS Weights by Year (21-23)'!K34 -> 0.0090546789 | ... O19: =+'SUBS Weights by Year (21-23)'!P34 -> 0.012075291
A20: =+A19+1 -> 10 | B20: Austin | C20: =+'SUBS Weights by Year (21-23)'!D24 -> 0 | D20: =+'SUBS Weights by Year (21-23)'!E24 -> 0 | E20: =+'SUBS Weights by Year (21-23)'!F24 -> 0 | F20: =+'SUBS Weights by Year (21-23)'!G24 -> 0 | G20: =+'SUBS Weights by Year (21-23)'!H24 -> 0 | H20: =+'SUBS Weights by Year (21-23)'!I24 -> 0 | I20: =+'SUBS Weights by Year (21-23)'!J24 -> 0 | J20: =+'SUBS Weights by Year (21-23)'!K24 -> 0 | ... O20: =+'SUBS Weights by Year (21-23)'!P24 -> 0
C21: =SUM(C11:C20) -> 1 | D21: =SUM(D11:D20) -> 1 | E21: =SUM(E11:E20) -> 1 | F21: =SUM(F11:F20) -> 1 | G21: =SUM(G11:G20) -> 1 | H21: =SUM(H11:H20) -> 1 | I21: =SUM(I11:I20) -> 1 | J21: =SUM(J11:J20) -> 1 | ... O21: =SUM(O11:O20) -> 1

Sheet SUBS Weights by Year (21-23)
B1: PUC DOCKET NO.
B2: ONCOR ELECTRIC DELIVERY COMPANY
B3: WEATHER WEIGHTS
B4: =+'SUBS Seasonal Weights'!B4:P4 -> FOR THE TEST YEAR ENDING DECEMBER 31, 2024
B6: SPONSOR: D. E. NELSON
B8: PRIMARY SERVICE GREATER THAN 10 KW SUBSTATION MONTHLY WEIGHTS
A9: Line | B9: (a) | C9: (b) | D9: (c) | E9: (d) | F9: (e) | G9: (f) | H9: (g) | I9: (h) | J9: (i) | K9: (j) | L9: (k) | M9: (l) | N9: (m) | O9: (n) | P9: (o)
A10: No. | B10: Weather Station | C10: Year | D10: 36892 | E10: 36923 | F10: 36951 | G10: 36982 | H10: 37012 | I10: 37043 | J10: 37073 | K10: 37104 | L10: 37135 | M10: 37165 | N10: 37196 | O10: 37226 | P10: Annual
A11: 1 | B11: Dallas-Fort Worth | C11: 2021 | D11: ='SUBS Sales by Year (21-23)'!D11/'SUBS Sales by Year (21-23)'!D61 -> 0.15953218 | E11: ='SUBS Sales by Year (21-23)'!E11/'SUBS Sales by Year (21-23)'!E$61 -> 0.15746778 | F11: ='SUBS Sales by Year (21-23)'!F11/'SUBS Sales by Year (21-23)'!F$61 -> 0.16646749 | G11: ='SUBS Sales by Year (21-23)'!G11/'SUBS Sales by Year (21-23)'!G$61 -> 0.16274646 | H11: ='SUBS Sales by Year (21-23)'!H11/'SUBS Sales by Year (21-23)'!H$61 -> 0.16139963 | I11: ='SUBS Sales by Year (21-23)'!I11/'SUBS Sales by Year (21-23)'!I$61 -> 0.15291395 | J11: ='SUBS Sales by Year (21-23)'!J11/'SUBS Sales by Year (21-23)'!J$61 -> 0.15546155 | K11: ='SUBS Sales by Year (21-23)'!K11/'SUBS Sales by Year (21-23)'!K$61 -> 0.13814773 | L11: ='SUBS Sales by Year (21-23)'!L11/'SUBS Sales by Year (21-23)'!L$61 -> 0.15033028 | ... P11: ='SUBS Sales by Year (21-23)'!P11/'SUBS Sales by Year (21-23)'!P$61 -> 0.15341859
A12: =+A11+1 -> 2 | B12: Dallas-Fort Worth | C12: 2022 | D12: ='SUBS Sales by Year (21-23)'!D12/'SUBS Sales by Year (21-23)'!D62 -> 0.13111308 | E12: ='SUBS Sales by Year (21-23)'!E12/'SUBS Sales by Year (21-23)'!E$62 -> 0.12506576 | F12: ='SUBS Sales by Year (21-23)'!F12/'SUBS Sales by Year (21-23)'!F$62 -> 0.12580354 | G12: ='SUBS Sales by Year (21-23)'!G12/'SUBS Sales by Year (21-23)'!G$62 -> 0.14082142 | H12: ='SUBS Sales by Year (21-23)'!H12/'SUBS Sales by Year (21-23)'!H$62 -> 0.14130479 | I12: ='SUBS Sales by Year (21-23)'!I12/'SUBS Sales by Year (21-23)'!I$62 -> 0.15303458 | J12: ='SUBS Sales by Year (21-23)'!J12/'SUBS Sales by Year (21-23)'!J$62 -> 0.16769533 | K12: ='SUBS Sales by Year (21-23)'!K12/'SUBS Sales by Year (21-23)'!K$62 -> 0.16270211 | L12: ='SUBS Sales by Year (21-23)'!L12/'SUBS Sales by Year (21-23)'!L$62 -> 0.16044987 | ... P12: ='SUBS Sales by Year (21-23)'!P12/'SUBS Sales by Year (21-23)'!P$62 -> 0.14615964
A13: =+A12+1 -> 3 | B13: Dallas-Fort Worth | C13: 2023 | D13: ='SUBS Sales by Year (21-23)'!D13/'SUBS Sales by Year (21-23)'!D63 -> 0.13656146 | E13: ='SUBS Sales by Year (21-23)'!E13/'SUBS Sales by Year (21-23)'!E63 -> 0.1398744 | F13: ='SUBS Sales by Year (21-23)'!F13/'SUBS Sales by Year (21-23)'!F63 -> 0.12699121 | G13: ='SUBS Sales by Year (21-23)'!G13/'SUBS Sales by Year (21-23)'!G63 -> 0.13693654 | H13: ='SUBS Sales by Year (21-23)'!H13/'SUBS Sales by Year (21-23)'!H63 -> 0.13342811 | I13: ='SUBS Sales by Year (21-23)'!I13/'SUBS Sales by Year (21-23)'!I63 -> 0.12883079 | J13: ='SUBS Sales by Year (21-23)'!J13/'SUBS Sales by Year (21-23)'!J63 -> 0.13122489 | K13: ='SUBS Sales by Year (21-23)'!K13/'SUBS Sales by Year (21-23)'!K63 -> 0.10762451 | ... P13: ='SUBS Sales by Year (21-23)'!P13/'SUBS Sales by Year (21-23)'!P63 -> 0.13092147
A14: =+A13+1 -> 4 | B14: Dallas-Fort Worth | C14: Total | D14: ='SUBS Sales by Year (21-23)'!D14/'SUBS Sales by Year (21-23)'!D64 -> 0.1415486 | E14: ='SUBS Sales by Year (21-23)'!E14/'SUBS Sales by Year (21-23)'!E64 -> 0.13962995 | F14: ='SUBS Sales by Year (21-23)'!F14/'SUBS Sales by Year (21-23)'!F64 -> 0.13634199 | G14: ='SUBS Sales by Year (21-23)'!G14/'SUBS Sales by Year (21-23)'!G64 -> 0.14572047 | H14: ='SUBS Sales by Year (21-23)'!H14/'SUBS Sales by Year (21-23)'!H64 -> 0.14382008 | I14: ='SUBS Sales by Year (21-23)'!I14/'SUBS Sales by Year (21-23)'!I64 -> 0.1434625 | J14: ='SUBS Sales by Year (21-23)'!J14/'SUBS Sales by Year (21-23)'!J64 -> 0.14989086 | K14: ='SUBS Sales by Year (21-23)'!K14/'SUBS Sales by Year (21-23)'!K64 -> 0.13129773 | ... P14: ='SUBS Sales by Year (21-23)'!P14/'SUBS Sales by Year (21-23)'!P64 -> 0.14219326
A15: =+A14+1 -> 5
A16: =+A15+1 -> 6 | B16: Lufkin | C16: =+C11 -> 2021 | D16: ='SUBS Sales by Year (21-23)'!D16/'SUBS Sales by Year (21-23)'!D61 -> 0.015903162 | E16: ='SUBS Sales by Year (21-23)'!E16/'SUBS Sales by Year (21-23)'!E$61 -> 0.017212497 | F16: ='SUBS Sales by Year (21-23)'!F16/'SUBS Sales by Year (21-23)'!F$61 -> 0.022918622 | G16: ='SUBS Sales by Year (21-23)'!G16/'SUBS Sales by Year (21-23)'!G$61 -> 0.019930052 | H16: ='SUBS Sales by Year (21-23)'!H16/'SUBS Sales by Year (21-23)'!H$61 -> 0.023967359 | I16: ='SUBS Sales by Year (21-23)'!I16/'SUBS Sales by Year (21-23)'!I$61 -> 0.022439977 | J16: ='SUBS Sales by Year (21-23)'!J16/'SUBS Sales by Year (21-23)'!J$61 -> 0.025712156 | K16: ='SUBS Sales by Year (21-23)'!K16/'SUBS Sales by Year (21-23)'!K$61 -> 0.018483565 | L16: ='SUBS Sales by Year (21-23)'!L16/'SUBS Sales by Year (21-23)'!L$61 -> 0.021812915 | ... P16: ='SUBS Sales by Year (21-23)'!P16/'SUBS Sales by Year (21-23)'!P$61 -> 0.01995035
A17: =+A16+1 -> 7 | B17: Lufkin | C17: =+C12 -> 2022 | D17: ='SUBS Sales by Year (21-23)'!D17/'SUBS Sales by Year (21-23)'!D62 -> 0.015884855 | E17: ='SUBS Sales by Year (21-23)'!E17/'SUBS Sales by Year (21-23)'!E$62 -> 0.016924133 | F17: ='SUBS Sales by Year (21-23)'!F17/'SUBS Sales by Year (21-23)'!F$62 -> 0.016038241 | G17: ='SUBS Sales by Year (21-23)'!G17/'SUBS Sales by Year (21-23)'!G$62 -> 0.015927083 | H17: ='SUBS Sales by Year (21-23)'!H17/'SUBS Sales by Year (21-23)'!H$62 -> 0.016661058 | I17: ='SUBS Sales by Year (21-23)'!I17/'SUBS Sales by Year (21-23)'!I$62 -> 0.018816095 | J17: ='SUBS Sales by Year (21-23)'!J17/'SUBS Sales by Year (21-23)'!J$62 -> 0.022174819 | K17: ='SUBS Sales by Year (21-23)'!K17/'SUBS Sales by Year (21-23)'!K$62 -> 0.021028376 | L17: ='SUBS Sales by Year (21-23)'!L17/'SUBS Sales by Year (21-23)'!L$62 -> 0.020392795 | ... P17: ='SUBS Sales by Year (21-23)'!P17/'SUBS Sales by Year (21-23)'!P$62 -> 0.019553108
A18: =+A17+1 -> 8 | B18: Lufkin | C18: =+C13 -> 2023 | D18: ='SUBS Sales by Year (21-23)'!D18/'SUBS Sales by Year (21-23)'!D63 -> 0.028728259 | E18: ='SUBS Sales by Year (21-23)'!E18/'SUBS Sales by Year (21-23)'!E63 -> 0.028260353 | F18: ='SUBS Sales by Year (21-23)'!F18/'SUBS Sales by Year (21-23)'!F63 -> 0.029413036 | G18: ='SUBS Sales by Year (21-23)'!G18/'SUBS Sales by Year (21-23)'!G63 -> 0.028849859 | H18: ='SUBS Sales by Year (21-23)'!H18/'SUBS Sales by Year (21-23)'!H63 -> 0.025885357 | I18: ='SUBS Sales by Year (21-23)'!I18/'SUBS Sales by Year (21-23)'!I63 -> 0.026849435 | J18: ='SUBS Sales by Year (21-23)'!J18/'SUBS Sales by Year (21-23)'!J63 -> 0.029602669 | K18: ='SUBS Sales by Year (21-23)'!K18/'SUBS Sales by Year (21-23)'!K63 -> 0.019062427 | ... P18: ='SUBS Sales by Year (21-23)'!P18/'SUBS Sales by Year (21-23)'!P63 -> 0.028495111
A19: =+A18+1 -> 9 | B19: Lufkin | C19: Total | D19: ='SUBS Sales by Year (21-23)'!D19/'SUBS Sales by Year (21-23)'!D64 -> 0.0206081 | E19: ='SUBS Sales by Year (21-23)'!E19/'SUBS Sales by Year (21-23)'!E64 -> 0.021203115 | F19: ='SUBS Sales by Year (21-23)'!F19/'SUBS Sales by Year (21-23)'!F64 -> 0.022690679 | G19: ='SUBS Sales by Year (21-23)'!G19/'SUBS Sales by Year (21-23)'!G64 -> 0.021886197 | H19: ='SUBS Sales by Year (21-23)'!H19/'SUBS Sales by Year (21-23)'!H64 -> 0.022224289 | I19: ='SUBS Sales by Year (21-23)'!I19/'SUBS Sales by Year (21-23)'!I64 -> 0.023028576 | J19: ='SUBS Sales by Year (21-23)'!J19/'SUBS Sales by Year (21-23)'!J64 -> 0.026105442 | K19: ='SUBS Sales by Year (21-23)'!K19/'SUBS Sales by Year (21-23)'!K64 -> 0.019441099 | ... P19: ='SUBS Sales by Year (21-23)'!P19/'SUBS Sales by Year (21-23)'!P64 -> 0.023204547
A20: =+A19+1 -> 10
A21: =+A20+1 -> 11 | B21: Austin | C21: =+C16 -> 2021 | D21: ='SUBS Sales by Year (21-23)'!D21/'SUBS Sales by Year (21-23)'!D61 -> 0 | E21: ='SUBS Sales by Year (21-23)'!E21/'SUBS Sales by Year (21-23)'!E$61 -> 0 | F21: ='SUBS Sales by Year (21-23)'!F21/'SUBS Sales by Year (21-23)'!F$61 -> 0 | G21: ='SUBS Sales by Year (21-23)'!G21/'SUBS Sales by Year (21-23)'!G$61 -> 0 | H21: ='SUBS Sales by Year (21-23)'!H21/'SUBS Sales by Year (21-23)'!H$61 -> 0 | I21: ='SUBS Sales by Year (21-23)'!I21/'SUBS Sales by Year (21-23)'!I$61 -> 0 | J21: ='SUBS Sales by Year (21-23)'!J21/'SUBS Sales by Year (21-23)'!J$61 -> 0 | K21: ='SUBS Sales by Year (21-23)'!K21/'SUBS Sales by Year (21-23)'!K$61 -> 0 | L21: ='SUBS Sales by Year (21-23)'!L21/'SUBS Sales by Year (21-23)'!L$61 -> 0 | ... P21: ='SUBS Sales by Year (21-23)'!P21/'SUBS Sales by Year (21-23)'!P$61 -> 0
A22: =+A21+1 -> 12 | B22: Austin | C22: =+C17 -> 2022 | D22: ='SUBS Sales by Year (21-23)'!D22/'SUBS Sales by Year (21-23)'!D62 -> 0 | E22: ='SUBS Sales by Year (21-23)'!E22/'SUBS Sales by Year (21-23)'!E$62 -> 0 | F22: ='SUBS Sales by Year (21-23)'!F22/'SUBS Sales by Year (21-23)'!F$62 -> 0 | G22: ='SUBS Sales by Year (21-23)'!G22/'SUBS Sales by Year (21-23)'!G$62 -> 0 | H22: ='SUBS Sales by Year (21-23)'!H22/'SUBS Sales by Year (21-23)'!H$62 -> 0 | I22: ='SUBS Sales by Year (21-23)'!I22/'SUBS Sales by Year (21-23)'!I$62 -> 0 | J22: ='SUBS Sales by Year (21-23)'!J22/'SUBS Sales by Year (21-23)'!J$62 -> 0 | K22: ='SUBS Sales by Year (21-23)'!K22/'SUBS Sales by Year (21-23)'!K$62 -> 0 | L22: ='SUBS Sales by Year (21-23)'!L22/'SUBS Sales by Year (21-23)'!L$62 -> 0 | ... P22: ='SUBS Sales by Year (21-23)'!P22/'SUBS Sales by Year (21-23)'!P$62 -> 0
A23: =+A22+1 -> 13 | B23: Austin | C23: =+C18 -> 2023 | D23: ='SUBS Sales by Year (21-23)'!D23/'SUBS Sales by Year (21-23)'!D63 -> 0 | E23: ='SUBS Sales by Year (21-23)'!E23/'SUBS Sales by Year (21-23)'!E63 -> 0 | F23: ='SUBS Sales by Year (21-23)'!F23/'SUBS Sales by Year (21-23)'!F63 -> 0 | G23: ='SUBS Sales by Year (21-23)'!G23/'SUBS Sales by Year (21-23)'!G63 -> 0 | H23: ='SUBS Sales by Year (21-23)'!H23/'SUBS Sales by Year (21-23)'!H63 -> 0 | I23: ='SUBS Sales by Year (21-23)'!I23/'SUBS Sales by Year (21-23)'!I63 -> 0 | J23: ='SUBS Sales by Year (21-23)'!J23/'SUBS Sales by Year (21-23)'!J63 -> 0 | K23: ='SUBS Sales by Year (21-23)'!K23/'SUBS Sales by Year (21-23)'!K63 -> 0 | ... P23: ='SUBS Sales by Year (21-23)'!P23/'SUBS Sales by Year (21-23)'!P63 -> 0
A24: =+A23+1 -> 14 | B24: Austin | C24: Total | D24: ='SUBS Sales by Year (21-23)'!D24/'SUBS Sales by Year (21-23)'!D64 -> 0 | E24: ='SUBS Sales by Year (21-23)'!E24/'SUBS Sales by Year (21-23)'!E64 -> 0 | F24: ='SUBS Sales by Year (21-23)'!F24/'SUBS Sales by Year (21-23)'!F64 -> 0 | G24: ='SUBS Sales by Year (21-23)'!G24/'SUBS Sales by Year (21-23)'!G64 -> 0 | H24: ='SUBS Sales by Year (21-23)'!H24/'SUBS Sales by Year (21-23)'!H64 -> 0 | I24: ='SUBS Sales by Year (21-23)'!I24/'SUBS Sales by Year (21-23)'!I64 -> 0 | J24: ='SUBS Sales by Year (21-23)'!J24/'SUBS Sales by Year (21-23)'!J64 -> 0 | K24: ='SUBS Sales by Year (21-23)'!K24/'SUBS Sales by Year (21-23)'!K64 -> 0 | ... P24: ='SUBS Sales by Year (21-23)'!P24/'SUBS Sales by Year (21-23)'!P64 -> 0
A25: =+A24+1 -> 15
A26: =+A25+1 -> 16 | B26: Killeen | C26: =+C21 -> 2021 | D26: ='SUBS Sales by Year (21-23)'!D26/'SUBS Sales by Year (21-23)'!D61 -> 0.06058763 | E26: ='SUBS Sales by Year (21-23)'!E26/'SUBS Sales by Year (21-23)'!E$61 -> 0.07173617 | F26: ='SUBS Sales by Year (21-23)'!F26/'SUBS Sales by Year (21-23)'!F$61 -> 0.095513854 | G26: ='SUBS Sales by Year (21-23)'!G26/'SUBS Sales by Year (21-23)'!G$61 -> 0.080505208 | H26: ='SUBS Sales by Year (21-23)'!H26/'SUBS Sales by Year (21-23)'!H$61 -> 0.072306601 | I26: ='SUBS Sales by Year (21-23)'!I26/'SUBS Sales by Year (21-23)'!I$61 -> 0.077461158 | J26: ='SUBS Sales by Year (21-23)'!J26/'SUBS Sales by Year (21-23)'!J$61 -> 0.07435456 | K26: ='SUBS Sales by Year (21-23)'!K26/'SUBS Sales by Year (21-23)'!K$61 -> 0.072529709 | L26: ='SUBS Sales by Year (21-23)'!L26/'SUBS Sales by Year (21-23)'!L$61 -> 0.09088835 | ... P26: ='SUBS Sales by Year (21-23)'!P26/'SUBS Sales by Year (21-23)'!P$61 -> 0.082325143
A27: =+A26+1 -> 17 | B27: Killeen | C27: =+C22 -> 2022 | D27: ='SUBS Sales by Year (21-23)'!D27/'SUBS Sales by Year (21-23)'!D62 -> 0.096292032 | E27: ='SUBS Sales by Year (21-23)'!E27/'SUBS Sales by Year (21-23)'!E$62 -> 0.094963409 | F27: ='SUBS Sales by Year (21-23)'!F27/'SUBS Sales by Year (21-23)'!F$62 -> 0.084373722 | G27: ='SUBS Sales by Year (21-23)'!G27/'SUBS Sales by Year (21-23)'!G$62 -> 0.088055423 | H27: ='SUBS Sales by Year (21-23)'!H27/'SUBS Sales by Year (21-23)'!H$62 -> 0.084515126 | I27: ='SUBS Sales by Year (21-23)'!I27/'SUBS Sales by Year (21-23)'!I$62 -> 0.065896831 | J27: ='SUBS Sales by Year (21-23)'!J27/'SUBS Sales by Year (21-23)'!J$62 -> 0.086898452 | K27: ='SUBS Sales by Year (21-23)'!K27/'SUBS Sales by Year (21-23)'!K$62 -> 0.091152552 | L27: ='SUBS Sales by Year (21-23)'!L27/'SUBS Sales by Year (21-23)'!L$62 -> 0.089092287 | ... P27: ='SUBS Sales by Year (21-23)'!P27/'SUBS Sales by Year (21-23)'!P$62 -> 0.083252168
A28: =+A27+1 -> 18 | B28: Killeen | C28: =+C23 -> 2023 | D28: ='SUBS Sales by Year (21-23)'!D28/'SUBS Sales by Year (21-23)'!D63 -> 0.053391388 | E28: ='SUBS Sales by Year (21-23)'!E28/'SUBS Sales by Year (21-23)'!E63 -> 0.064036053 | F28: ='SUBS Sales by Year (21-23)'!F28/'SUBS Sales by Year (21-23)'!F63 -> 0.081773516 | G28: ='SUBS Sales by Year (21-23)'!G28/'SUBS Sales by Year (21-23)'!G63 -> 0.082842769 | H28: ='SUBS Sales by Year (21-23)'!H28/'SUBS Sales by Year (21-23)'!H63 -> 0.08489117 | I28: ='SUBS Sales by Year (21-23)'!I28/'SUBS Sales by Year (21-23)'!I63 -> 0.078764636 | J28: ='SUBS Sales by Year (21-23)'!J28/'SUBS Sales by Year (21-23)'!J63 -> 0.081122498 | K28: ='SUBS Sales by Year (21-23)'!K28/'SUBS Sales by Year (21-23)'!K63 -> 0.063760999 | ... P28: ='SUBS Sales by Year (21-23)'!P28/'SUBS Sales by Year (21-23)'!P63 -> 0.07122457
A29: =+A28+1 -> 19 | B29: Killeen | C29: Total | D29: ='SUBS Sales by Year (21-23)'!D29/'SUBS Sales by Year (21-23)'!D64 -> 0.069936929 | E29: ='SUBS Sales by Year (21-23)'!E29/'SUBS Sales by Year (21-23)'!E64 -> 0.077000996 | F29: ='SUBS Sales by Year (21-23)'!F29/'SUBS Sales by Year (21-23)'!F64 -> 0.08617944 | G29: ='SUBS Sales by Year (21-23)'!G29/'SUBS Sales by Year (21-23)'!G64 -> 0.083934691 | H29: ='SUBS Sales by Year (21-23)'!H29/'SUBS Sales by Year (21-23)'!H64 -> 0.081291273 | I29: ='SUBS Sales by Year (21-23)'!I29/'SUBS Sales by Year (21-23)'!I64 -> 0.074308478 | J29: ='SUBS Sales by Year (21-23)'!J29/'SUBS Sales by Year (21-23)'!J64 -> 0.080990966 | K29: ='SUBS Sales by Year (21-23)'!K29/'SUBS Sales by Year (21-23)'!K64 -> 0.073742297 | ... P29: ='SUBS Sales by Year (21-23)'!P29/'SUBS Sales by Year (21-23)'!P64 -> 0.078229094
A30: =+A29+1 -> 20
A31: =+A30+1 -> 21 | B31: Longview | C31: =+C26 -> 2021 | D31: ='SUBS Sales by Year (21-23)'!D31/'SUBS Sales by Year (21-23)'!D61 -> 0.00965121 | E31: ='SUBS Sales by Year (21-23)'!E31/'SUBS Sales by Year (21-23)'!E$61 -> 0.0097052857 | F31: ='SUBS Sales by Year (21-23)'!F31/'SUBS Sales by Year (21-23)'!F$61 -> 0.011783817 | G31: ='SUBS Sales by Year (21-23)'!G31/'SUBS Sales by Year (21-23)'!G$61 -> 0.010917519 | H31: ='SUBS Sales by Year (21-23)'!H31/'SUBS Sales by Year (21-23)'!H$61 -> 0.012217537 | I31: ='SUBS Sales by Year (21-23)'!I31/'SUBS Sales by Year (21-23)'!I$61 -> 0.010588997 | J31: ='SUBS Sales by Year (21-23)'!J31/'SUBS Sales by Year (21-23)'!J$61 -> 0.010858791 | K31: ='SUBS Sales by Year (21-23)'!K31/'SUBS Sales by Year (21-23)'!K$61 -> 0.009126282 | L31: ='SUBS Sales by Year (21-23)'!L31/'SUBS Sales by Year (21-23)'!L$61 -> 0.013940722 | ... P31: ='SUBS Sales by Year (21-23)'!P31/'SUBS Sales by Year (21-23)'!P$61 -> 0.011862185
A32: =+A31+1 -> 22 | B32: Longview | C32: =+C27 -> 2022 | D32: ='SUBS Sales by Year (21-23)'!D32/'SUBS Sales by Year (21-23)'!D62 -> 0.017578357 | E32: ='SUBS Sales by Year (21-23)'!E32/'SUBS Sales by Year (21-23)'!E$62 -> 0.014673865 | F32: ='SUBS Sales by Year (21-23)'!F32/'SUBS Sales by Year (21-23)'!F$62 -> 0.014202172 | G32: ='SUBS Sales by Year (21-23)'!G32/'SUBS Sales by Year (21-23)'!G$62 -> 0.016050173 | H32: ='SUBS Sales by Year (21-23)'!H32/'SUBS Sales by Year (21-23)'!H$62 -> 0.011649774 | I32: ='SUBS Sales by Year (21-23)'!I32/'SUBS Sales by Year (21-23)'!I$62 -> 0.0088366649 | J32: ='SUBS Sales by Year (21-23)'!J32/'SUBS Sales by Year (21-23)'!J$62 -> 0.0099749195 | K32: ='SUBS Sales by Year (21-23)'!K32/'SUBS Sales by Year (21-23)'!K$62 -> 0.011634806 | L32: ='SUBS Sales by Year (21-23)'!L32/'SUBS Sales by Year (21-23)'!L$62 -> 0.012574455 | ... P32: ='SUBS Sales by Year (21-23)'!P32/'SUBS Sales by Year (21-23)'!P$62 -> 0.013422197
A33: =+A32+1 -> 23 | B33: Longview | C33: =+C28 -> 2023 | D33: ='SUBS Sales by Year (21-23)'!D33/'SUBS Sales by Year (21-23)'!D63 -> 0.016259439 | E33: ='SUBS Sales by Year (21-23)'!E33/'SUBS Sales by Year (21-23)'!E63 -> 0.014663232 | F33: ='SUBS Sales by Year (21-23)'!F33/'SUBS Sales by Year (21-23)'!F63 -> 0.011570645 | G33: ='SUBS Sales by Year (21-23)'!G33/'SUBS Sales by Year (21-23)'!G63 -> 0.0073889821 | H33: ='SUBS Sales by Year (21-23)'!H33/'SUBS Sales by Year (21-23)'!H63 -> 0.007004335 | I33: ='SUBS Sales by Year (21-23)'!I33/'SUBS Sales by Year (21-23)'!I63 -> 0.0077051307 | J33: ='SUBS Sales by Year (21-23)'!J33/'SUBS Sales by Year (21-23)'!J63 -> 0.012458258 | K33: ='SUBS Sales by Year (21-23)'!K33/'SUBS Sales by Year (21-23)'!K63 -> 0.0074178489 | ... P33: ='SUBS Sales by Year (21-23)'!P33/'SUBS Sales by Year (21-23)'!P63 -> 0.011139222
A34: =+A33+1 -> 24 | B34: Longview | C34: Total | D34: ='SUBS Sales by Year (21-23)'!D34/'SUBS Sales by Year (21-23)'!D64 -> 0.014741276 | E34: ='SUBS Sales by Year (21-23)'!E34/'SUBS Sales by Year (21-23)'!E64 -> 0.013277575 | F34: ='SUBS Sales by Year (21-23)'!F34/'SUBS Sales by Year (21-23)'!F64 -> 0.012628873 | G34: ='SUBS Sales by Year (21-23)'!G34/'SUBS Sales by Year (21-23)'!G64 -> 0.01134756 | H34: ='SUBS Sales by Year (21-23)'!H34/'SUBS Sales by Year (21-23)'!H64 -> 0.010019953 | I34: ='SUBS Sales by Year (21-23)'!I34/'SUBS Sales by Year (21-23)'!I64 -> 0.0088970904 | J34: ='SUBS Sales by Year (21-23)'!J34/'SUBS Sales by Year (21-23)'!J64 -> 0.011202062 | K34: ='SUBS Sales by Year (21-23)'!K34/'SUBS Sales by Year (21-23)'!K64 -> 0.0090546789 | ... P34: ='SUBS Sales by Year (21-23)'!P34/'SUBS Sales by Year (21-23)'!P64 -> 0.012075291
A35: =+A34+1 -> 25
A36: =+A35+1 -> 26 | B36: Waco | C36: =+C31 -> 2021 | D36: ='SUBS Sales by Year (21-23)'!D36/'SUBS Sales by Year (21-23)'!D61 -> 0.0092819738 | E36: ='SUBS Sales by Year (21-23)'!E36/'SUBS Sales by Year (21-23)'!E$61 -> 0.00858194 | F36: ='SUBS Sales by Year (21-23)'!F36/'SUBS Sales by Year (21-23)'!F$61 -> 0.01282825 | G36: ='SUBS Sales by Year (21-23)'!G36/'SUBS Sales by Year (21-23)'!G$61 -> 0.014974031 | H36: ='SUBS Sales by Year (21-23)'!H36/'SUBS Sales by Year (21-23)'!H$61 -> 0.0095898052 | I36: ='SUBS Sales by Year (21-23)'!I36/'SUBS Sales by Year (21-23)'!I$61 -> 0.0096054317 | J36: ='SUBS Sales by Year (21-23)'!J36/'SUBS Sales by Year (21-23)'!J$61 -> 0.011678888 | K36: ='SUBS Sales by Year (21-23)'!K36/'SUBS Sales by Year (21-23)'!K$61 -> 0.010282056 | L36: ='SUBS Sales by Year (21-23)'!L36/'SUBS Sales by Year (21-23)'!L$61 -> 0.0099451534 | ... P36: ='SUBS Sales by Year (21-23)'!P36/'SUBS Sales by Year (21-23)'!P$61 -> 0.010371025
A37: =+A36+1 -> 27 | B37: Waco | C37: =+C32 -> 2022 | D37: ='SUBS Sales by Year (21-23)'!D37/'SUBS Sales by Year (21-23)'!D62 -> 0.0089610432 | E37: ='SUBS Sales by Year (21-23)'!E37/'SUBS Sales by Year (21-23)'!E$62 -> 0.0094211688 | F37: ='SUBS Sales by Year (21-23)'!F37/'SUBS Sales by Year (21-23)'!F$62 -> 0.0095139428 | G37: ='SUBS Sales by Year (21-23)'!G37/'SUBS Sales by Year (21-23)'!G$62 -> 0.0089242006 | H37: ='SUBS Sales by Year (21-23)'!H37/'SUBS Sales by Year (21-23)'!H$62 -> 0.0072857832 | I37: ='SUBS Sales by Year (21-23)'!I37/'SUBS Sales by Year (21-23)'!I$62 -> 0.008827748 | J37: ='SUBS Sales by Year (21-23)'!J37/'SUBS Sales by Year (21-23)'!J$62 -> 0.0092294318 | K37: ='SUBS Sales by Year (21-23)'!K37/'SUBS Sales by Year (21-23)'!K$62 -> 0.010541682 | L37: ='SUBS Sales by Year (21-23)'!L37/'SUBS Sales by Year (21-23)'!L$62 -> 0.0099273861 | ... P37: ='SUBS Sales by Year (21-23)'!P37/'SUBS Sales by Year (21-23)'!P$62 -> 0.0088138723
A38: =+A37+1 -> 28 | B38: Waco | C38: =+C33 -> 2023 | D38: ='SUBS Sales by Year (21-23)'!D38/'SUBS Sales by Year (21-23)'!D63 -> 0.0077373604 | E38: ='SUBS Sales by Year (21-23)'!E38/'SUBS Sales by Year (21-23)'!E63 -> 0.0081421631 | F38: ='SUBS Sales by Year (21-23)'!F38/'SUBS Sales by Year (21-23)'!F63 -> 0.0085126573 | G38: ='SUBS Sales by Year (21-23)'!G38/'SUBS Sales by Year (21-23)'!G63 -> 0.0096594681 | H38: ='SUBS Sales by Year (21-23)'!H38/'SUBS Sales by Year (21-23)'!H63 -> 0.0090143006 | I38: ='SUBS Sales by Year (21-23)'!I38/'SUBS Sales by Year (21-23)'!I63 -> 0.007772331 | J38: ='SUBS Sales by Year (21-23)'!J38/'SUBS Sales by Year (21-23)'!J63 -> 0.0085125759 | K38: ='SUBS Sales by Year (21-23)'!K38/'SUBS Sales by Year (21-23)'!K63 -> 0.006235788 | ... P38: ='SUBS Sales by Year (21-23)'!P38/'SUBS Sales by Year (21-23)'!P63 -> 0.0078402263
A39: =+A38+1 -> 29 | B39: Waco | C39: Total | D39: ='SUBS Sales by Year (21-23)'!D39/'SUBS Sales by Year (21-23)'!D64 -> 0.0086067885 | E39: ='SUBS Sales by Year (21-23)'!E39/'SUBS Sales by Year (21-23)'!E64 -> 0.0087123329 | F39: ='SUBS Sales by Year (21-23)'!F39/'SUBS Sales by Year (21-23)'!F64 -> 0.0099670018 | G39: ='SUBS Sales by Year (21-23)'!G39/'SUBS Sales by Year (21-23)'!G64 -> 0.010947441 | H39: ='SUBS Sales by Year (21-23)'!H39/'SUBS Sales by Year (21-23)'!H64 -> 0.0085862154 | I39: ='SUBS Sales by Year (21-23)'!I39/'SUBS Sales by Year (21-23)'!I64 -> 0.0086365655 | J39: ='SUBS Sales by Year (21-23)'!J39/'SUBS Sales by Year (21-23)'!J64 -> 0.0096625598 | K39: ='SUBS Sales by Year (21-23)'!K39/'SUBS Sales by Year (21-23)'!K64 -> 0.0085505165 | ... P39: ='SUBS Sales by Year (21-23)'!P39/'SUBS Sales by Year (21-23)'!P64 -> 0.0088712639
A40: =+A39+1 -> 30
A41: =+A40+1 -> 31 | B41: Abilene | C41: =+C36 -> 2021 | D41: ='SUBS Sales by Year (21-23)'!D41/'SUBS Sales by Year (21-23)'!D61 -> 0.068289623 | E41: ='SUBS Sales by Year (21-23)'!E41/'SUBS Sales by Year (21-23)'!E$61 -> 0.067803117 | F41: ='SUBS Sales by Year (21-23)'!F41/'SUBS Sales by Year (21-23)'!F$61 -> 0.066703326 | G41: ='SUBS Sales by Year (21-23)'!G41/'SUBS Sales by Year (21-23)'!G$61 -> 0.066931152 | H41: ='SUBS Sales by Year (21-23)'!H41/'SUBS Sales by Year (21-23)'!H$61 -> 0.068099859 | I41: ='SUBS Sales by Year (21-23)'!I41/'SUBS Sales by Year (21-23)'!I$61 -> 0.06202838 | J41: ='SUBS Sales by Year (21-23)'!J41/'SUBS Sales by Year (21-23)'!J$61 -> 0.062266354 | K41: ='SUBS Sales by Year (21-23)'!K41/'SUBS Sales by Year (21-23)'!K$61 -> 0.051054521 | L41: ='SUBS Sales by Year (21-23)'!L41/'SUBS Sales by Year (21-23)'!L$61 -> 0.058184055 | ... P41: ='SUBS Sales by Year (21-23)'!P41/'SUBS Sales by Year (21-23)'!P$61 -> 0.06125172
A42: =+A41+1 -> 32 | B42: Abilene | C42: =+C37 -> 2022 | D42: ='SUBS Sales by Year (21-23)'!D42/'SUBS Sales by Year (21-23)'!D62 -> 0.058818923 | E42: ='SUBS Sales by Year (21-23)'!E42/'SUBS Sales by Year (21-23)'!E$62 -> 0.057685591 | F42: ='SUBS Sales by Year (21-23)'!F42/'SUBS Sales by Year (21-23)'!F$62 -> 0.052811004 | G42: ='SUBS Sales by Year (21-23)'!G42/'SUBS Sales by Year (21-23)'!G$62 -> 0.054261648 | H42: ='SUBS Sales by Year (21-23)'!H42/'SUBS Sales by Year (21-23)'!H$62 -> 0.050590309 | I42: ='SUBS Sales by Year (21-23)'!I42/'SUBS Sales by Year (21-23)'!I$62 -> 0.048821225 | J42: ='SUBS Sales by Year (21-23)'!J42/'SUBS Sales by Year (21-23)'!J$62 -> 0.043197862 | K42: ='SUBS Sales by Year (21-23)'!K42/'SUBS Sales by Year (21-23)'!K$62 -> 0.040534015 | L42: ='SUBS Sales by Year (21-23)'!L42/'SUBS Sales by Year (21-23)'!L$62 -> 0.043925804 | ... P42: ='SUBS Sales by Year (21-23)'!P42/'SUBS Sales by Year (21-23)'!P$62 -> 0.049709661
...

Sheet SUBS Sales by Year (21-23)
B1: PUC DOCKET NO.
B2: ONCOR ELECTRIC DELIVERY COMPANY
B3: WEATHER WEIGHTS
B4: =+'SUBS Seasonal Weights'!B4:P4 -> FOR THE TEST YEAR ENDING DECEMBER 31, 2024
B6: SPONSOR: D. E. NELSON
B8: PRIMARY SERVICE GREATER THAN 10 KW SUBSTATION MONTHLY WEIGHTS
A9: Line | B9: (a) | C9: (b) | D9: (c) | E9: (d) | F9: (e) | G9: (f) | H9: (g) | I9: (h) | J9: (i) | K9: (j) | L9: (k) | M9: (l) | N9: (m) | O9: (n) | P9: (o)
A10: No. | B10: Weather Station | C10: Year | D10: 36892 | E10: 36923 | F10: 36951 | G10: 36982 | H10: 37012 | I10: 37043 | J10: 37073 | K10: 37104 | L10: 37135 | M10: 37165 | N10: 37196 | O10: 37226 | P10: Annual
A11: 1 | B11: Dallas-Fort Worth | C11: 2021 | D11: 73653.697 | E11: 69167.498 | F11: 61090.872 | G11: 78273.244 | H11: 77174.168 | I11: 79048.058 | J11: 82009.369 | K11: 86634.959 | L11: 84236.532 | M11: 86730.247 | N11: 80100.531 | O11: 77231.598 | P11: =SUM(D11:O11) -> 935350.77
A12: =+A11+1 -> 2 | B12: Dallas-Fort Worth | C12: 2022 | D12: 68510.535 | E12: 68501.41 | F12: 71012.045 | G12: 79416.666 | H12: 83143.413 | I12: 86807.08 | J12: 96736.037 | K12: 100356.15 | L12: 96141.841 | M12: 83077.76 | N12: 88963.48 | O12: 80347.167 | P12: =SUM(D12:O12) -> 1003013.6
A13: =+A12+1 -> 3 | B13: Dallas-Fort Worth | C13: 2023 | D13: 78037.63 | E13: 81193.983 | F13: 69356.627 | G13: 84586.05 | H13: 88923.656 | I13: 90827.328 | J13: 92863.433 | K13: 107592.92 | L13: 103927.01 | M13: 112300.71 | N13: 101839.67 | O13: 99601.034 | P13: =SUM(D13:O13) -> 1111050.1
A14: =+A13+1 -> 4 | B14: Dallas-Fort Worth | C14: Total | D14: =SUM(D11:D13) -> 220201.86 | E14: =SUM(E11:E13) -> 218862.89 | F14: =SUM(F11:F13) -> 201459.54 | G14: =SUM(G11:G13) -> 242275.96 | H14: =SUM(H11:H13) -> 249241.24 | I14: =SUM(I11:I13) -> 256682.47 | J14: =SUM(J11:J13) -> 271608.84 | K14: =SUM(K11:K13) -> 294584.03 | ... O14: =SUM(O11:O13) -> 257179.8 | P14: =SUM(D14:O14) -> 3049414.4
A15: =+A14+1 -> 5
A16: =+A15+1 -> 6 | B16: Lufkin | C16: =+C11 -> 2021 | D16: 7342.26 | E16: 7560.565 | F16: 8410.763 | G16: 9585.399 | H16: 11460.132 | I16: 11600.227 | J16: 13563.725 | K16: 11591.381 | L16: 12222.716 | M16: 9845.722 | N16: 9876.158 | O16: 8572.725 | P16: =SUM(D16:O16) -> 121631.77
A17: =+A16+1 -> 7 | B17: Lufkin | C17: =+C12 -> 2022 | D17: 8300.315 | E17: 9269.739 | F17: 9053.07 | G17: 8982.127 | H17: 9803.328 | I17: 10673.21 | J17: 12791.675 | K17: 12970.495 | L17: 12219.398 | M17: 11649.982 | N17: 13191.978 | O17: 15276.953 | P17: =SUM(D17:O17) -> 134182.27
A18: =+A17+1 -> 8 | B18: Lufkin | C18: =+C13 -> 2023 | D18: 16416.676 | E18: 16404.508 | F18: 16064.017 | G18: 17820.631 | H18: 17251.392 | I18: 18929.189 | J18: 20948.811 | K18: 19056.833 | L18: 34694.083 | M18: 20085.386 | N18: 22645.686 | O18: 21503.289 | P18: =SUM(D18:O18) -> 241820.5
A19: =+A18+1 -> 9 | B19: Lufkin | C19: Total | D19: =SUM(D16:D18) -> 32059.251 | E19: =SUM(E16:E18) -> 33234.812 | F19: =SUM(F16:F18) -> 33527.85 | G19: =SUM(G16:G18) -> 36388.157 | H19: =SUM(H16:H18) -> 38514.852 | I19: =SUM(I16:I18) -> 41202.626 | J19: =SUM(J16:J18) -> 47304.211 | K19: =SUM(K16:K18) -> 43618.709 | ... O19: =SUM(O16:O18) -> 45352.967 | P19: =SUM(D19:O19) -> 497634.54
A20: =+A19+1 -> 10
A21: =+A20+1 -> 11 | B21: Austin | C21: =+C16 -> 2021 | D21: 0 | E21: 0 | F21: 0 | G21: 0 | H21: 0 | I21: 0 | J21: 0 | K21: 0 | L21: 0 | M21: 0 | N21: 0 | O21: 0 | P21: =SUM(D21:O21) -> 0
A22: =+A21+1 -> 12 | B22: Austin | C22: =+C17 -> 2022 | D22: 0 | E22: 0 | F22: 0 | G22: 0 | H22: 0 | I22: 0 | J22: 0 | K22: 0 | L22: 0 | M22: 0 | N22: 0 | O22: 0 | P22: =SUM(D22:O22) -> 0
A23: =+A22+1 -> 13 | B23: Austin | C23: =+C18 -> 2023 | D23: 0 | E23: 0 | F23: 0 | G23: 0 | H23: 0 | I23: 0 | J23: 0 | K23: 0 | L23: 0 | M23: 0 | N23: 0 | O23: 0 | P23: =SUM(D23:O23) -> 0
A24: =+A23+1 -> 14 | B24: Austin | C24: Total | D24: =SUM(D21:D23) -> 0 | E24: =SUM(E21:E23) -> 0 | F24: =SUM(F21:F23) -> 0 | G24: =SUM(G21:G23) -> 0 | H24: =SUM(H21:H23) -> 0 | I24: =SUM(I21:I23) -> 0 | J24: =SUM(J21:J23) -> 0 | K24: =SUM(K21:K23) -> 0 | ... O24: =SUM(O21:O23) -> 0 | P24: =SUM(D24:O24) -> 0
A25: =+A24+1 -> 15
A26: =+A25+1 -> 16 | B26: Killeen | C26: =+C21 -> 2021 | D26: 27972.432 | E26: 31510.011 | F26: 35052.037 | G26: 38719.144 | H26: 34573.821 | I26: 40043.135 | J26: 39223.657 | K26: 45484.704 | L26: 50928.659 | M26: 49299.77 | N26: 52740.587 | O26: 56365.691 | P26: =SUM(D26:O26) -> 501913.65
A27: =+A26+1 -> 17 | B27: Killeen | C27: =+C22 -> 2022 | D27: 50315.487 | E27: 52013.655 | F27: 47626.246 | G27: 49659.123 | H27: 49728.505 | I27: 37379.208 | J27: 50127.883 | K27: 56223.73 | L27: 53384.253 | M27: 44379.937 | N27: 41492.937 | O27: 38983.076 | P27: =SUM(D27:O27) -> 571314.04
A28: =+A27+1 -> 18 | B28: Killeen | C28: =+C23 -> 2023 | D28: 30510.346 | E28: 37171.508 | F28: 44660.848 | G28: 51172.189 | H28: 56576.035 | I28: 55530.058 | J28: 57407.657 | K28: 63742.287 | L28: 53829.617 | M28: 53036.978 | N28: 53077.761 | O28: 47723.884 | P28: =SUM(D28:O28) -> 604439.17
A29: =+A28+1 -> 19 | B29: Killeen | C29: Total | D29: =SUM(D26:D28) -> 108798.26 | E29: =SUM(E26:E28) -> 120695.17 | F29: =SUM(F26:F28) -> 127339.13 | G29: =SUM(G26:G28) -> 139550.46 | H29: =SUM(H26:H28) -> 140878.36 | I29: =SUM(I26:I28) -> 132952.4 | J29: =SUM(J26:J28) -> 146759.2 | K29: =SUM(K26:K28) -> 165450.72 | ... O29: =SUM(O26:O28) -> 143072.65 | P29: =SUM(D29:O29) -> 1677666.9
A30: =+A29+1 -> 20
A31: =+A30+1 -> 21 | B31: Longview | C31: =+C26 -> 2021 | D31: 4455.824 | E31: 4263.033 | F31: 4324.47 | G31: 5250.803 | H31: 5841.886 | I31: 5473.926 | J31: 5728.25 | K31: 5723.258 | L31: 7811.587 | M31: 6259.478 | N31: 7818.266 | O31: 9369.684 | P31: =SUM(D31:O31) -> 72320.465
A32: =+A31+1 -> 22 | B32: Longview | C32: =+C27 -> 2022 | D32: 9185.221 | E32: 8037.215 | F32: 8016.668 | G32: 9051.544 | H32: 6854.7 | I32: 5012.495 | J32: 5754.091 | K32: 7176.455 | L32: 7534.635 | M32: 7085.243 | N32: 9623.319 | O32: 8777.601 | P32: =SUM(D32:O32) -> 92109.187
A33: =+A32+1 -> 23 | B33: Longview | C33: =+C28 -> 2023 | D33: 9291.407 | E33: 8511.681 | F33: 6319.342 | G33: 4564.193 | H33: 4668.065 | I33: 5432.214 | J33: 8816.289 | K33: 7415.672 | L33: 10198.995 | M33: 9767.199 | N33: 10054.295 | O33: 9492.386 | P33: =SUM(D33:O33) -> 94531.738
A34: =+A33+1 -> 24 | B34: Longview | C34: Total | D34: =SUM(D31:D33) -> 22932.452 | E34: =SUM(E31:E33) -> 20811.929 | F34: =SUM(F31:F33) -> 18660.48 | G34: =SUM(G31:G33) -> 18866.54 | H34: =SUM(H31:H33) -> 17364.651 | I34: =SUM(I31:I33) -> 15918.635 | J34: =SUM(J31:J33) -> 20298.63 | K34: =SUM(K31:K33) -> 20315.385 | ... O34: =SUM(O31:O33) -> 27639.671 | P34: =SUM(D34:O34) -> 258961.39
A35: =+A34+1 -> 25
A36: =+A35+1 -> 26 | B36: Waco | C36: =+C31 -> 2021 | D36: 4285.353 | E36: 3769.605 | F36: 4707.76 | G36: 7201.791 | H36: 4585.421 | I36: 4965.477 | J36: 6160.869 | K36: 6448.065 | L36: 5572.698 | M36: 5629.835 | N36: 5554.947 | O36: 4347.454 | P36: =SUM(D36:O36) -> 63229.275
A37: =+A36+1 -> 27 | B37: Waco | C37: =+C32 -> 2022 | D37: 4682.415 | E37: 5160.192 | F37: 5370.314 | G37: 5032.83 | H37: 4286.938 | I37: 5007.437 | J37: 5324.052 | K37: 6502.206 | L37: 5948.507 | M37: 5249.781 | N37: 3503.831 | O37: 4416.276 | P37: =SUM(D37:O37) -> 60484.779
A38: =+A37+1 -> 28 | B38: Waco | C38: =+C33 -> 2023 | D38: 4421.491 | E38: 4726.345 | F38: 4649.213 | G38: 5966.678 | H38: 6007.614 | I38: 5479.591 | J38: 6024.063 | K38: 6233.958 | L38: 6069.344 | M38: 6286.183 | N38: 5440.822 | O38: 5229.882 | P38: =SUM(D38:O38) -> 66535.184
A39: =+A38+1 -> 29 | B39: Waco | C39: Total | D39: =SUM(D36:D38) -> 13389.259 | E39: =SUM(E36:E38) -> 13656.142 | F39: =SUM(F36:F38) -> 14727.287 | G39: =SUM(G36:G38) -> 18201.299 | H39: =SUM(H36:H38) -> 14879.973 | I39: =SUM(I36:I38) -> 15452.505 | J39: =SUM(J36:J38) -> 17508.984 | K39: =SUM(K36:K38) -> 19184.229 | ... O39: =SUM(O36:O38) -> 13993.612 | P39: =SUM(D39:O39) -> 190249.24
A40: =+A39+1 -> 30
A41: =+A40+1 -> 31 | B41: Abilene | C41: =+C36 -> 2021 | D41: 31528.331 | E41: 29782.423 | F41: 24479.04 | G41: 32190.674 | H41: 32562.343 | I41: 32065.242 | J41: 32846.864 | K41: 32017.222 | L41: 32603.033 | M41: 31548.678 | N41: 31859.683 | O41: 29951.28 | P41: =SUM(D41:O41) -> 373434.81
A42: =+A41+1 -> 32 | B42: Abilene | C42: =+C37 -> 2022 | D42: 30734.659 | E42: 31595.732 | F42: 29810.109 | G42: 30601.021 | H42: 29767.221 | I42: 27693.27 | J42: 24918.941 | K42: 25001.752 | L42: 26320.418 | M42: 30066.182 | N42: 28841.385 | O42: 25779.494 | P42: =SUM(D42:O42) -> 341130.18
...
