Workbook
Name HOURLY: [1]HOURLY!$A$1:$G$745
Name OLE_LINK2: 'SECLE10 Seasonal Weights'!$B$24
Name rngBilled: OFFSET([2]Sheet2!$A$2,0,0,[2]Sheet2!$B$1,9)
Name rngYear: OFFSET('[3]Daily Actual_August'!$A$2,0,0,'[3]Daily Actual_August'!$C$1,8)

Sheet SECLE10 Seasonal Weights
B1: PUC DOCKET NO.
B2: ONCOR ELECTRIC DELIVERY COMPANY LLC
B3: WEATHER WEIGHTS
B4: FOR THE TEST YEAR ENDING DECEMBER 31, 2024
B6: SPONSOR: D. E. NELSON
B8: SECONDARY SERVICE LESS THAN OR EQUAL TO 10 KW MONTHLY WEIGHTS
A9: Line | B9: (a) | D9: (b) | E9: (c) | F9: (d) | G9: (e) | H9: (f) | I9: (g) | J9: (h) | K9: (i) | L9: (j) | M9: (k) | N9: (l) | O9: (m) | P9: (n)
A10: No. | B10: Weather Station | D10: 36892 | E10: 36923 | F10: 36951 | G10: 36982 | H10: 37012 | I10: 37043 | J10: 37073 | K10: 37104 | L10: 37135 | M10: 37165 | N10: 37196 | O10: 37226 | P10: Annual
A11: 1 | B11: Dallas-Fort Worth | D11: =+'SECLE10 Monthly Weather Weights'!C11 -> 0.60631764 | E11: =+'SECLE10 Monthly Weather Weights'!D11 -> 0.60485508 | F11: =+'SECLE10 Monthly Weather Weights'!E11 -> 0.6046097 | G11: =+'SECLE10 Monthly Weather Weights'!F11 -> 0.60280765 | H11: =+'SECLE10 Monthly Weather Weights'!G11 -> 0.60337616 | I11: =+'SECLE10 Monthly Weather Weights'!H11 -> 0.59700025 | J11: =+'SECLE10 Monthly Weather Weights'!I11 -> 0.59613848 | K11: =+'SECLE10 Monthly Weather Weights'!J11 -> 0.59518738 | ... P11: =+'SECLE10 Monthly Weather Weights'!O11 -> 0.60255888
A12: =+A11+1 -> 2 | B12: Midland-Odessa | D12: =+'SECLE10 Monthly Weather Weights'!C12 -> 0.1121114 | E12: =+'SECLE10 Monthly Weather Weights'!D12 -> 0.11172605 | F12: =+'SECLE10 Monthly Weather Weights'!E12 -> 0.11212655 | G12: =+'SECLE10 Monthly Weather Weights'!F12 -> 0.12336185 | H12: =+'SECLE10 Monthly Weather Weights'!G12 -> 0.1238674 | I12: =+'SECLE10 Monthly Weather Weights'!H12 -> 0.11785654 | J12: =+'SECLE10 Monthly Weather Weights'!I12 -> 0.11413823 | K12: =+'SECLE10 Monthly Weather Weights'!J12 -> 0.11292816 | ... P12: =+'SECLE10 Monthly Weather Weights'!O12 -> 0.11425923
A13: =+A12+1 -> 3 | B13: Lufkin | D13: =+'SECLE10 Monthly Weather Weights'!C13 -> 0.037556335 | E13: =+'SECLE10 Monthly Weather Weights'!D13 -> 0.037497687 | F13: =+'SECLE10 Monthly Weather Weights'!E13 -> 0.036935946 | G13: =+'SECLE10 Monthly Weather Weights'!F13 -> 0.036137236 | H13: =+'SECLE10 Monthly Weather Weights'!G13 -> 0.036277942 | I13: =+'SECLE10 Monthly Weather Weights'!H13 -> 0.039078405 | J13: =+'SECLE10 Monthly Weather Weights'!I13 -> 0.04034275 | K13: =+'SECLE10 Monthly Weather Weights'!J13 -> 0.040149354 | ... P13: =+'SECLE10 Monthly Weather Weights'!O13 -> 0.037926078
A14: =+A13+1 -> 4 | B14: Abilene | D14: =+'SECLE10 Monthly Weather Weights'!C14 -> 0.030589786 | E14: =+'SECLE10 Monthly Weather Weights'!D14 -> 0.030531036 | F14: =+'SECLE10 Monthly Weather Weights'!E14 -> 0.029988424 | G14: =+'SECLE10 Monthly Weather Weights'!F14 -> 0.030028298 | H14: =+'SECLE10 Monthly Weather Weights'!G14 -> 0.030323989 | I14: =+'SECLE10 Monthly Weather Weights'!H14 -> 0.03050995 | J14: =+'SECLE10 Monthly Weather Weights'!I14 -> 0.030718329 | K14: =+'SECLE10 Monthly Weather Weights'!J14 -> 0.031108172 | ... P14: =+'SECLE10 Monthly Weather Weights'!O14 -> 0.030297824
A15: =+A14+1 -> 5 | B15: Sherman-Denison | D15: =+'SECLE10 Monthly Weather Weights'!C15 -> 0.033861676 | E15: =+'SECLE10 Monthly Weather Weights'!D15 -> 0.034526089 | F15: =+'SECLE10 Monthly Weather Weights'!E15 -> 0.034599877 | G15: =+'SECLE10 Monthly Weather Weights'!F15 -> 0.031665282 | H15: =+'SECLE10 Monthly Weather Weights'!G15 -> 0.030254308 | I15: =+'SECLE10 Monthly Weather Weights'!H15 -> 0.031986425 | J15: =+'SECLE10 Monthly Weather Weights'!I15 -> 0.033943007 | K15: =+'SECLE10 Monthly Weather Weights'!J15 -> 0.034954884 | ... P15: =+'SECLE10 Monthly Weather Weights'!O15 -> 0.033162782
A16: =+A15+1 -> 6 | B16: Killeen-Temple | D16: =+'SECLE10 Monthly Weather Weights'!C16 -> 0.033968351 | E16: =+'SECLE10 Monthly Weather Weights'!D16 -> 0.034028377 | F16: =+'SECLE10 Monthly Weather Weights'!E16 -> 0.034024712 | G16: =+'SECLE10 Monthly Weather Weights'!F16 -> 0.033168468 | H16: =+'SECLE10 Monthly Weather Weights'!G16 -> 0.033388529 | I16: =+'SECLE10 Monthly Weather Weights'!H16 -> 0.034541828 | J16: =+'SECLE10 Monthly Weather Weights'!I16 -> 0.034227023 | K16: =+'SECLE10 Monthly Weather Weights'!J16 -> 0.034011857 | ... P16: =+'SECLE10 Monthly Weather Weights'!O16 -> 0.03398611
A17: =+A16+1 -> 7 | B17: Waco | D17: =+'SECLE10 Monthly Weather Weights'!C17 -> 0.037977053 | E17: =+'SECLE10 Monthly Weather Weights'!D17 -> 0.038574121 | F17: =+'SECLE10 Monthly Weather Weights'!E17 -> 0.039576559 | G17: =+'SECLE10 Monthly Weather Weights'!F17 -> 0.038266339 | H17: =+'SECLE10 Monthly Weather Weights'!G17 -> 0.03845432 | I17: =+'SECLE10 Monthly Weather Weights'!H17 -> 0.039871657 | J17: =+'SECLE10 Monthly Weather Weights'!I17 -> 0.040043585 | K17: =+'SECLE10 Monthly Weather Weights'!J17 -> 0.040468926 | ... P17: =+'SECLE10 Monthly Weather Weights'!O17 -> 0.039364897
A18: =+A17+1 -> 8 | B18: Wichita Falls. | D18: =+'SECLE10 Monthly Weather Weights'!C18 -> 0.026233139 | E18: =+'SECLE10 Monthly Weather Weights'!D18 -> 0.026527988 | F18: =+'SECLE10 Monthly Weather Weights'!E18 -> 0.026668578 | G18: =+'SECLE10 Monthly Weather Weights'!F18 -> 0.025400783 | H18: =+'SECLE10 Monthly Weather Weights'!G18 -> 0.024870818 | I18: =+'SECLE10 Monthly Weather Weights'!H18 -> 0.025716842 | J18: =+'SECLE10 Monthly Weather Weights'!I18 -> 0.026554728 | K18: =+'SECLE10 Monthly Weather Weights'!J18 -> 0.026995407 | ... P18: =+'SECLE10 Monthly Weather Weights'!O18 -> 0.02618679
A19: =+A18+1 -> 9 | B19: Longview | D19: =+'SECLE10 Monthly Weather Weights'!C19 -> 0.045358047 | E19: =+'SECLE10 Monthly Weather Weights'!D19 -> 0.045467921 | F19: =+'SECLE10 Monthly Weather Weights'!E19 -> 0.045160496 | G19: =+'SECLE10 Monthly Weather Weights'!F19 -> 0.043078721 | H19: =+'SECLE10 Monthly Weather Weights'!G19 -> 0.042952913 | I19: =+'SECLE10 Monthly Weather Weights'!H19 -> 0.046200074 | J19: =+'SECLE10 Monthly Weather Weights'!I19 -> 0.048026967 | K19: =+'SECLE10 Monthly Weather Weights'!J19 -> 0.04864187 | ... P19: =+'SECLE10 Monthly Weather Weights'!O19 -> 0.045854268
A20: =+A19+1 -> 10 | B20: Austin | D20: =+'SECLE10 Monthly Weather Weights'!C20 -> 0.036026579 | E20: =+'SECLE10 Monthly Weather Weights'!D20 -> 0.036265657 | F20: =+'SECLE10 Monthly Weather Weights'!E20 -> 0.036309156 | G20: =+'SECLE10 Monthly Weather Weights'!F20 -> 0.036085369 | H20: =+'SECLE10 Monthly Weather Weights'!G20 -> 0.036233622 | I20: =+'SECLE10 Monthly Weather Weights'!H20 -> 0.037238027 | J20: =+'SECLE10 Monthly Weather Weights'!I20 -> 0.035866895 | K20: =+'SECLE10 Monthly Weather Weights'!J20 -> 0.035553982 | ... P20: =+'SECLE10 Monthly Weather Weights'!O20 -> 0.036403142
A21: =+A20+1 -> 11 | D21: =SUM(D11:D20) -> 1 | E21: =SUM(E11:E20) -> 1 | F21: =SUM(F11:F20) -> 1 | G21: =SUM(G11:G20) -> 1 | H21: =SUM(H11:H20) -> 1 | I21: =SUM(I11:I20) -> 1 | J21: =SUM(J11:J20) -> 1 | K21: =SUM(K11:K20) -> 1 | ... P21: =SUM(P11:P20) -> 1
A22: =+A21+1 -> 12
A23: =+A22+1 -> 13 | D23: SEASONAL WEIGHTS
A24: =+A23+1 -> 14 | D24: Nov to Mar | F24: May to Sep
A25: =+A24+1 -> 15 | B25: Weather Station | D25: HDD | F25: CDD
A26: =+A25+1 -> 16 | B26: Dallas-Fort Worth | D26: =ROUND(AVERAGE(D11:F11,N11:O11),3) -> 0.608 | F26: =ROUND(AVERAGE(H11:L11),3) -> 0.598
A27: =+A26+1 -> 17 | B27: Midland-Odessa | D27: =ROUND(AVERAGE(D12:F12,N12:O12),3) -> 0.112 | F27: =ROUND(AVERAGE(H12:L12),3) -> 0.116
A28: =+A27+1 -> 18 | B28: Lufkin | D28: =ROUND(AVERAGE(D13:F13,N13:O13),3) -> 0.037 | F28: =ROUND(AVERAGE(H13:L13),3) -> 0.039
A29: =+A28+1 -> 19 | B29: Abilene | D29: =ROUND(AVERAGE(D14:F14,N14:O14),3) -> 0.03 | F29: =ROUND(AVERAGE(H14:L14),3) -> 0.031
A30: =+A29+1 -> 20 | B30: Sherman-Denison | D30: =ROUND(AVERAGE(D15:F15,N15:O15),3) -> 0.033 | F30: =ROUND(AVERAGE(H15:L15),3) -> 0.033
A31: =+A30+1 -> 21 | B31: Killeen-Temple | D31: =ROUND(AVERAGE(D16:F16,N16:O16),3) -> 0.034 | F31: =ROUND(AVERAGE(H16:L16),3) -> 0.034
A32: =+A31+1 -> 22 | B32: Waco | D32: =ROUND(AVERAGE(D17:F17,N17:O17),3) -> 0.039 | F32: =ROUND(AVERAGE(H17:L17),3) -> 0.04
A33: =+A32+1 -> 23 | B33: Wichita Falls. | D33: =ROUND(AVERAGE(D18:F18,N18:O18),3) -> 0.026 | F33: =ROUND(AVERAGE(H18:L18),3) -> 0.026
A34: =+A33+1 -> 24 | B34: Longview | D34: =ROUND(AVERAGE(D19:F19,N19:O19),3) -> 0.045 | F34: =ROUND(AVERAGE(H19:L19),3) -> 0.047
A35: =+A34+1 -> 25 | B35: Austin | D35: =ROUND(AVERAGE(D20:F20,N20:O20),3) -> 0.036 | F35: =ROUND(AVERAGE(H20:L20),3) -> 0.036
A36: =+A35+1 -> 26 | D36: =AVERAGE(D21:F21,N21:O21) -> 1 | F36: =AVERAGE(H21:L21) -> 1

Sheet SECLE10 Monthly Weather Weights
B1: PUC DOCKET NO.
B2: ONCOR ELECTRIC DELIVERY COMPANY
B3: WEATHER WEIGHTS
B4: =+'SECLE10 Seasonal Weights'!B4:P4 -> FOR THE TEST YEAR ENDING DECEMBER 31, 2024
B6: SPONSOR: D. E. NELSON
B8: SECONDARY SERVICE LESS THAN OR EQUAL TO 10 KW MONTHLY WEIGHTS
A9: Line | B9: (a) | C9: (b) | D9: (c) | E9: (d) | F9: (e) | G9: (f) | H9: (g) | I9: (h) | J9: (i) | K9: (j) | L9: (k) | M9: (l) | N9: (m) | O9: (n)
A10: No. | B10: Weather Station | C10: 36892 | D10: 36923 | E10: 36951 | F10: 36982 | G10: 37012 | H10: 37043 | I10: 37073 | J10: 37104 | K10: 37135 | L10: 37165 | M10: 37196 | N10: 37226 | O10: Annual
A11: 1 | B11: Dallas-Fort Worth | C11: =+'SECLE10 Weights by Year (21-23)'!D14 -> 0.60631764 | D11: =+'SECLE10 Weights by Year (21-23)'!E14 -> 0.60485508 | E11: =+'SECLE10 Weights by Year (21-23)'!F14 -> 0.6046097 | F11: =+'SECLE10 Weights by Year (21-23)'!G14 -> 0.60280765 | G11: =+'SECLE10 Weights by Year (21-23)'!H14 -> 0.60337616 | H11: =+'SECLE10 Weights by Year (21-23)'!I14 -> 0.59700025 | I11: =+'SECLE10 Weights by Year (21-23)'!J14 -> 0.59613848 | J11: =+'SECLE10 Weights by Year (21-23)'!K14 -> 0.59518738 | ... O11: =+'SECLE10 Weights by Year (21-23)'!P14 -> 0.60255888
A12: =+A11+1 -> 2 | B12: Midland-Odessa | C12: =+'SECLE10 Weights by Year (21-23)'!D54 -> 0.1121114 | D12: =+'SECLE10 Weights by Year (21-23)'!E54 -> 0.11172605 | E12: =+'SECLE10 Weights by Year (21-23)'!F54 -> 0.11212655 | F12: =+'SECLE10 Weights by Year (21-23)'!G54 -> 0.12336185 | G12: =+'SECLE10 Weights by Year (21-23)'!H54 -> 0.1238674 | H12: =+'SECLE10 Weights by Year (21-23)'!I54 -> 0.11785654 | I12: =+'SECLE10 Weights by Year (21-23)'!J54 -> 0.11413823 | J12: =+'SECLE10 Weights by Year (21-23)'!K54 -> 0.11292816 | ... O12: =+'SECLE10 Weights by Year (21-23)'!P54 -> 0.11425923
A13: =+A12+1 -> 3 | B13: Lufkin | C13: =+'SECLE10 Weights by Year (21-23)'!D19 -> 0.037556335 | D13: =+'SECLE10 Weights by Year (21-23)'!E19 -> 0.037497687 | E13: =+'SECLE10 Weights by Year (21-23)'!F19 -> 0.036935946 | F13: =+'SECLE10 Weights by Year (21-23)'!G19 -> 0.036137236 | G13: =+'SECLE10 Weights by Year (21-23)'!H19 -> 0.036277942 | H13: =+'SECLE10 Weights by Year (21-23)'!I19 -> 0.039078405 | I13: =+'SECLE10 Weights by Year (21-23)'!J19 -> 0.04034275 | J13: =+'SECLE10 Weights by Year (21-23)'!K19 -> 0.040149354 | ... O13: =+'SECLE10 Weights by Year (21-23)'!P19 -> 0.037926078
A14: =+A13+1 -> 4 | B14: Abilene | C14: =+'SECLE10 Weights by Year (21-23)'!D44 -> 0.030589786 | D14: =+'SECLE10 Weights by Year (21-23)'!E44 -> 0.030531036 | E14: =+'SECLE10 Weights by Year (21-23)'!F44 -> 0.029988424 | F14: =+'SECLE10 Weights by Year (21-23)'!G44 -> 0.030028298 | G14: =+'SECLE10 Weights by Year (21-23)'!H44 -> 0.030323989 | H14: =+'SECLE10 Weights by Year (21-23)'!I44 -> 0.03050995 | I14: =+'SECLE10 Weights by Year (21-23)'!J44 -> 0.030718329 | J14: =+'SECLE10 Weights by Year (21-23)'!K44 -> 0.031108172 | ... O14: =+'SECLE10 Weights by Year (21-23)'!P44 -> 0.030297824
A15: =+A14+1 -> 5 | B15: Sherman-Denison | C15: =+'SECLE10 Weights by Year (21-23)'!D59 -> 0.033861676 | D15: =+'SECLE10 Weights by Year (21-23)'!E59 -> 0.034526089 | E15: =+'SECLE10 Weights by Year (21-23)'!F59 -> 0.034599877 | F15: =+'SECLE10 Weights by Year (21-23)'!G59 -> 0.031665282 | G15: =+'SECLE10 Weights by Year (21-23)'!H59 -> 0.030254308 | H15: =+'SECLE10 Weights by Year (21-23)'!I59 -> 0.031986425 | I15: =+'SECLE10 Weights by Year (21-23)'!J59 -> 0.033943007 | J15: =+'SECLE10 Weights by Year (21-23)'!K59 -> 0.034954884 | ... O15: =+'SECLE10 Weights by Year (21-23)'!P59 -> 0.033162782
A16: =+A15+1 -> 6 | B16: Killeen-Temple | C16: =+'SECLE10 Weights by Year (21-23)'!D29 -> 0.033968351 | D16: =+'SECLE10 Weights by Year (21-23)'!E29 -> 0.034028377 | E16: =+'SECLE10 Weights by Year (21-23)'!F29 -> 0.034024712 | F16: =+'SECLE10 Weights by Year (21-23)'!G29 -> 0.033168468 | G16: =+'SECLE10 Weights by Year (21-23)'!H29 -> 0.033388529 | H16: =+'SECLE10 Weights by Year (21-23)'!I29 -> 0.034541828 | I16: =+'SECLE10 Weights by Year (21-23)'!J29 -> 0.034227023 | J16: =+'SECLE10 Weights by Year (21-23)'!K29 -> 0.034011857 | ... O16: =+'SECLE10 Weights by Year (21-23)'!P29 -> 0.03398611
A17: =+A16+1 -> 7 | B17: Waco | C17: =+'SECLE10 Weights by Year (21-23)'!D39 -> 0.037977053 | D17: =+'SECLE10 Weights by Year (21-23)'!E39 -> 0.038574121 | E17: =+'SECLE10 Weights by Year (21-23)'!F39 -> 0.039576559 | F17: =+'SECLE10 Weights by Year (21-23)'!G39 -> 0.038266339 | G17: =+'SECLE10 Weights by Year (21-23)'!H39 -> 0.03845432 | H17: =+'SECLE10 Weights by Year (21-23)'!I39 -> 0.039871657 | I17: =+'SECLE10 Weights by Year (21-23)'!J39 -> 0.040043585 | J17: =+'SECLE10 Weights by Year (21-23)'!K39 -> 0.040468926 | ... O17: =+'SECLE10 Weights by Year (21-23)'!P39 -> 0.039364897
A18: =+A17+1 -> 8 | B18: Wichita Falls. | C18: =+'SECLE10 Weights by Year (21-23)'!D49 -> 0.026233139 | D18: =+'SECLE10 Weights by Year (21-23)'!E49 -> 0.026527988 | E18: =+'SECLE10 Weights by Year (21-23)'!F49 -> 0.026668578 | F18: =+'SECLE10 Weights by Year (21-23)'!G49 -> 0.025400783 | G18: =+'SECLE10 Weights by Year (21-23)'!H49 -> 0.024870818 | H18: =+'SECLE10 Weights by Year (21-23)'!I49 -> 0.025716842 | I18: =+'SECLE10 Weights by Year (21-23)'!J49 -> 0.026554728 | J18: =+'SECLE10 Weights by Year (21-23)'!K49 -> 0.026995407 | ... O18: =+'SECLE10 Weights by Year (21-23)'!P49 -> 0.02618679
A19: =+A18+1 -> 9 | B19: Longview | C19: =+'SECLE10 Weights by Year (21-23)'!D34 -> 0.045358047 | D19: =+'SECLE10 Weights by Year (21-23)'!E34 -> 0.045467921 | E19: =+'SECLE10 Weights by Year (21-23)'!F34 -> 0.045160496 | F19: =+'SECLE10 Weights by Year (21-23)'!G34 -> 0.043078721 | G19: =+'SECLE10 Weights by Year (21-23)'!H34 -> 0.042952913 | H19: =+'SECLE10 Weights by Year (21-23)'!I34 -> 0.046200074 | I19: =+'SECLE10 Weights by Year (21-23)'!J34 -> 0.048026967 | J19: =+'SECLE10 Weights by Year (21-23)'!K34 -> 0.04864187 | ... O19: =+'SECLE10 Weights by Year (21-23)'!P34 -> 0.045854268
A20: =+A19+1 -> 10 | B20: Austin | C20: =+'SECLE10 Weights by Year (21-23)'!D24 -> 0.036026579 | D20: =+'SECLE10 Weights by Year (21-23)'!E24 -> 0.036265657 | E20: =+'SECLE10 Weights by Year (21-23)'!F24 -> 0.036309156 | F20: =+'SECLE10 Weights by Year (21-23)'!G24 -> 0.036085369 | G20: =+'SECLE10 Weights by Year (21-23)'!H24 -> 0.036233622 | H20: =+'SECLE10 Weights by Year (21-23)'!I24 -> 0.037238027 | I20: =+'SECLE10 Weights by Year (21-23)'!J24 -> 0.035866895 | J20: =+'SECLE10 Weights by Year (21-23)'!K24 -> 0.035553982 | ... O20: =+'SECLE10 Weights by Year (21-23)'!P24 -> 0.036403142
C21: =SUM(C11:C20) -> 1 | D21: =SUM(D11:D20) -> 1 | E21: =SUM(E11:E20) -> 1 | F21: =SUM(F11:F20) -> 1 | G21: =SUM(G11:G20) -> 1 | H21: =SUM(H11:H20) -> 1 | I21: =SUM(I11:I20) -> 1 | J21: =SUM(J11:J20) -> 1 | ... O21: =SUM(O11:O20) -> 1

Sheet SECLE10 Weights by Year (21-23)
B1: PUC DOCKET NO.
B2: ONCOR ELECTRIC DELIVERY COMPANY
B3: WEATHER WEIGHTS
B4: =+'SECLE10 Seasonal Weights'!B4:P4 -> FOR THE TEST YEAR ENDING DECEMBER 31, 2024
B6: SPONSOR: D. E. NELSON
B8: SECONDARY SERVICE LESS THAN OR EQUAL TO 10 KW MONTHLY WEIGHTS
A9: Line | B9: (a) | C9: (b) | D9: (c) | E9: (d) | F9: (e) | G9: (f) | H9: (g) | I9: (h) | J9: (i) | K9: (j) | L9: (k) | M9: (l) | N9: (m) | O9: (n) | P9: (o)
A10: No. | B10: Weather Station | C10: Year | D10: 36892 | E10: 36923 | F10: 36951 | G10: 36982 | H10: 37012 | I10: 37043 | J10: 37073 | K10: 37104 | L10: 37135 | M10: 37165 | N10: 37196 | O10: 37226 | P10: Annual
A11: 1 | B11: Dallas-Fort Worth | C11: 2021 | D11: ='SECLE10 Sales by Year (21-23)'!D11/'SECLE10 Sales by Year (21-23)'!D61 -> 0.60837276 | E11: ='SECLE10 Sales by Year (21-23)'!E11/'SECLE10 Sales by Year (21-23)'!E$61 -> 0.61185855 | F11: ='SECLE10 Sales by Year (21-23)'!F11/'SECLE10 Sales by Year (21-23)'!F$61 -> 0.61087125 | G11: ='SECLE10 Sales by Year (21-23)'!G11/'SECLE10 Sales by Year (21-23)'!G$61 -> 0.60540664 | H11: ='SECLE10 Sales by Year (21-23)'!H11/'SECLE10 Sales by Year (21-23)'!H$61 -> 0.60194474 | I11: ='SECLE10 Sales by Year (21-23)'!I11/'SECLE10 Sales by Year (21-23)'!I$61 -> 0.60490549 | J11: ='SECLE10 Sales by Year (21-23)'!J11/'SECLE10 Sales by Year (21-23)'!J$61 -> 0.60161619 | K11: ='SECLE10 Sales by Year (21-23)'!K11/'SECLE10 Sales by Year (21-23)'!K$61 -> 0.60178212 | L11: ='SECLE10 Sales by Year (21-23)'!L11/'SECLE10 Sales by Year (21-23)'!L$61 -> 0.59878115 | ... P11: ='SECLE10 Sales by Year (21-23)'!P11/'SECLE10 Sales by Year (21-23)'!P$61 -> 0.60568676
A12: =+A11+1 -> 2 | B12: Dallas-Fort Worth | C12: 2022 | D12: ='SECLE10 Sales by Year (21-23)'!D12/'SECLE10 Sales by Year (21-23)'!D62 -> 0.60732025 | E12: ='SECLE10 Sales by Year (21-23)'!E12/'SECLE10 Sales by Year (21-23)'!E$62 -> 0.59963034 | F12: ='SECLE10 Sales by Year (21-23)'!F12/'SECLE10 Sales by Year (21-23)'!F$62 -> 0.59961532 | G12: ='SECLE10 Sales by Year (21-23)'!G12/'SECLE10 Sales by Year (21-23)'!G$62 -> 0.60284698 | H12: ='SECLE10 Sales by Year (21-23)'!H12/'SECLE10 Sales by Year (21-23)'!H$62 -> 0.59663925 | I12: ='SECLE10 Sales by Year (21-23)'!I12/'SECLE10 Sales by Year (21-23)'!I$62 -> 0.59159813 | J12: ='SECLE10 Sales by Year (21-23)'!J12/'SECLE10 Sales by Year (21-23)'!J$62 -> 0.59466388 | K12: ='SECLE10 Sales by Year (21-23)'!K12/'SECLE10 Sales by Year (21-23)'!K$62 -> 0.59216018 | L12: ='SECLE10 Sales by Year (21-23)'!L12/'SECLE10 Sales by Year (21-23)'!L$62 -> 0.59725774 | ... P12: ='SECLE10 Sales by Year (21-23)'!P12/'SECLE10 Sales by Year (21-23)'!P$62 -> 0.59941963
A13: =+A12+1 -> 3 | B13: Dallas-Fort Worth | C13: 2023 | D13: ='SECLE10 Sales by Year (21-23)'!D13/'SECLE10 Sales by Year (21-23)'!D63 -> 0.6033431 | E13: ='SECLE10 Sales by Year (21-23)'!E13/'SECLE10 Sales by Year (21-23)'!E63 -> 0.60331307 | F13: ='SECLE10 Sales by Year (21-23)'!F13/'SECLE10 Sales by Year (21-23)'!F63 -> 0.60306896 | G13: ='SECLE10 Sales by Year (21-23)'!G13/'SECLE10 Sales by Year (21-23)'!G63 -> 0.60016017 | H13: ='SECLE10 Sales by Year (21-23)'!H13/'SECLE10 Sales by Year (21-23)'!H63 -> 0.61190213 | I13: ='SECLE10 Sales by Year (21-23)'!I13/'SECLE10 Sales by Year (21-23)'!I63 -> 0.59511961 | J13: ='SECLE10 Sales by Year (21-23)'!J13/'SECLE10 Sales by Year (21-23)'!J63 -> 0.5921041 | K13: ='SECLE10 Sales by Year (21-23)'!K13/'SECLE10 Sales by Year (21-23)'!K63 -> 0.5920422 | ... P13: ='SECLE10 Sales by Year (21-23)'!P13/'SECLE10 Sales by Year (21-23)'!P63 -> 0.60267767
A14: =+A13+1 -> 4 | B14: Dallas-Fort Worth | C14: Total | D14: ='SECLE10 Sales by Year (21-23)'!D14/'SECLE10 Sales by Year (21-23)'!D64 -> 0.60631764 | E14: ='SECLE10 Sales by Year (21-23)'!E14/'SECLE10 Sales by Year (21-23)'!E64 -> 0.60485508 | F14: ='SECLE10 Sales by Year (21-23)'!F14/'SECLE10 Sales by Year (21-23)'!F64 -> 0.6046097 | G14: ='SECLE10 Sales by Year (21-23)'!G14/'SECLE10 Sales by Year (21-23)'!G64 -> 0.60280765 | H14: ='SECLE10 Sales by Year (21-23)'!H14/'SECLE10 Sales by Year (21-23)'!H64 -> 0.60337616 | I14: ='SECLE10 Sales by Year (21-23)'!I14/'SECLE10 Sales by Year (21-23)'!I64 -> 0.59700025 | J14: ='SECLE10 Sales by Year (21-23)'!J14/'SECLE10 Sales by Year (21-23)'!J64 -> 0.59613848 | K14: ='SECLE10 Sales by Year (21-23)'!K14/'SECLE10 Sales by Year (21-23)'!K64 -> 0.59518738 | ... P14: ='SECLE10 Sales by Year (21-23)'!P14/'SECLE10 Sales by Year (21-23)'!P64 -> 0.60255888
A15: =+A14+1 -> 5
A16: =+A15+1 -> 6 | B16: Lufkin | C16: =+C11 -> 2021 | D16: ='SECLE10 Sales by Year (21-23)'!D16/'SECLE10 Sales by Year (21-23)'!D61 -> 0.037210978 | E16: ='SECLE10 Sales by Year (21-23)'!E16/'SECLE10 Sales by Year (21-23)'!E$61 -> 0.036608827 | F16: ='SECLE10 Sales by Year (21-23)'!F16/'SECLE10 Sales by Year (21-23)'!F$61 -> 0.037111793 | G16: ='SECLE10 Sales by Year (21-23)'!G16/'SECLE10 Sales by Year (21-23)'!G$61 -> 0.035846929 | H16: ='SECLE10 Sales by Year (21-23)'!H16/'SECLE10 Sales by Year (21-23)'!H$61 -> 0.036674105 | I16: ='SECLE10 Sales by Year (21-23)'!I16/'SECLE10 Sales by Year (21-23)'!I$61 -> 0.038400221 | J16: ='SECLE10 Sales by Year (21-23)'!J16/'SECLE10 Sales by Year (21-23)'!J$61 -> 0.04021927 | K16: ='SECLE10 Sales by Year (21-23)'!K16/'SECLE10 Sales by Year (21-23)'!K$61 -> 0.039700615 | L16: ='SECLE10 Sales by Year (21-23)'!L16/'SECLE10 Sales by Year (21-23)'!L$61 -> 0.040201358 | ... P16: ='SECLE10 Sales by Year (21-23)'!P16/'SECLE10 Sales by Year (21-23)'!P$61 -> 0.03800755
A17: =+A16+1 -> 7 | B17: Lufkin | C17: =+C12 -> 2022 | D17: ='SECLE10 Sales by Year (21-23)'!D17/'SECLE10 Sales by Year (21-23)'!D62 -> 0.037300943 | E17: ='SECLE10 Sales by Year (21-23)'!E17/'SECLE10 Sales by Year (21-23)'!E$62 -> 0.039031915 | F17: ='SECLE10 Sales by Year (21-23)'!F17/'SECLE10 Sales by Year (21-23)'!F$62 -> 0.03830231 | G17: ='SECLE10 Sales by Year (21-23)'!G17/'SECLE10 Sales by Year (21-23)'!G$62 -> 0.036659888 | H17: ='SECLE10 Sales by Year (21-23)'!H17/'SECLE10 Sales by Year (21-23)'!H$62 -> 0.037627021 | I17: ='SECLE10 Sales by Year (21-23)'!I17/'SECLE10 Sales by Year (21-23)'!I$62 -> 0.040280928 | J17: ='SECLE10 Sales by Year (21-23)'!J17/'SECLE10 Sales by Year (21-23)'!J$62 -> 0.041522552 | K17: ='SECLE10 Sales by Year (21-23)'!K17/'SECLE10 Sales by Year (21-23)'!K$62 -> 0.040595429 | L17: ='SECLE10 Sales by Year (21-23)'!L17/'SECLE10 Sales by Year (21-23)'!L$62 -> 0.039892547 | ... P17: ='SECLE10 Sales by Year (21-23)'!P17/'SECLE10 Sales by Year (21-23)'!P$62 -> 0.038657128
A18: =+A17+1 -> 8 | B18: Lufkin | C18: =+C13 -> 2023 | D18: ='SECLE10 Sales by Year (21-23)'!D18/'SECLE10 Sales by Year (21-23)'!D63 -> 0.038135812 | E18: ='SECLE10 Sales by Year (21-23)'!E18/'SECLE10 Sales by Year (21-23)'!E63 -> 0.036776447 | F18: ='SECLE10 Sales by Year (21-23)'!F18/'SECLE10 Sales by Year (21-23)'!F63 -> 0.035237204 | G18: ='SECLE10 Sales by Year (21-23)'!G18/'SECLE10 Sales by Year (21-23)'!G63 -> 0.035876086 | H18: ='SECLE10 Sales by Year (21-23)'!H18/'SECLE10 Sales by Year (21-23)'!H63 -> 0.034460701 | I18: ='SECLE10 Sales by Year (21-23)'!I18/'SECLE10 Sales by Year (21-23)'!I63 -> 0.038372264 | J18: ='SECLE10 Sales by Year (21-23)'!J18/'SECLE10 Sales by Year (21-23)'!J63 -> 0.039134284 | K18: ='SECLE10 Sales by Year (21-23)'!K18/'SECLE10 Sales by Year (21-23)'!K63 -> 0.040090363 | ... P18: ='SECLE10 Sales by Year (21-23)'!P18/'SECLE10 Sales by Year (21-23)'!P63 -> 0.037058074
A19: =+A18+1 -> 9 | B19: Lufkin | C19: Total | D19: ='SECLE10 Sales by Year (21-23)'!D19/'SECLE10 Sales by Year (21-23)'!D64 -> 0.037556335 | E19: ='SECLE10 Sales by Year (21-23)'!E19/'SECLE10 Sales by Year (21-23)'!E64 -> 0.037497687 | F19: ='SECLE10 Sales by Year (21-23)'!F19/'SECLE10 Sales by Year (21-23)'!F64 -> 0.036935946 | G19: ='SECLE10 Sales by Year (21-23)'!G19/'SECLE10 Sales by Year (21-23)'!G64 -> 0.036137236 | H19: ='SECLE10 Sales by Year (21-23)'!H19/'SECLE10 Sales by Year (21-23)'!H64 -> 0.036277942 | I19: ='SECLE10 Sales by Year (21-23)'!I19/'SECLE10 Sales by Year (21-23)'!I64 -> 0.039078405 | J19: ='SECLE10 Sales by Year (21-23)'!J19/'SECLE10 Sales by Year (21-23)'!J64 -> 0.04034275 | K19: ='SECLE10 Sales by Year (21-23)'!K19/'SECLE10 Sales by Year (21-23)'!K64 -> 0.040149354 | ... P19: ='SECLE10 Sales by Year (21-23)'!P19/'SECLE10 Sales by Year (21-23)'!P64 -> 0.037926078
A20: =+A19+1 -> 10
A21: =+A20+1 -> 11 | B21: Austin | C21: =+C16 -> 2021 | D21: ='SECLE10 Sales by Year (21-23)'!D21/'SECLE10 Sales by Year (21-23)'!D61 -> 0.035485925 | E21: ='SECLE10 Sales by Year (21-23)'!E21/'SECLE10 Sales by Year (21-23)'!E$61 -> 0.035384511 | F21: ='SECLE10 Sales by Year (21-23)'!F21/'SECLE10 Sales by Year (21-23)'!F$61 -> 0.035864029 | G21: ='SECLE10 Sales by Year (21-23)'!G21/'SECLE10 Sales by Year (21-23)'!G$61 -> 0.035396553 | H21: ='SECLE10 Sales by Year (21-23)'!H21/'SECLE10 Sales by Year (21-23)'!H$61 -> 0.035758182 | I21: ='SECLE10 Sales by Year (21-23)'!I21/'SECLE10 Sales by Year (21-23)'!I$61 -> 0.036429053 | J21: ='SECLE10 Sales by Year (21-23)'!J21/'SECLE10 Sales by Year (21-23)'!J$61 -> 0.03520029 | K21: ='SECLE10 Sales by Year (21-23)'!K21/'SECLE10 Sales by Year (21-23)'!K$61 -> 0.034857247 | L21: ='SECLE10 Sales by Year (21-23)'!L21/'SECLE10 Sales by Year (21-23)'!L$61 -> 0.036116345 | ... P21: ='SECLE10 Sales by Year (21-23)'!P21/'SECLE10 Sales by Year (21-23)'!P$61 -> 0.035805776
A22: =+A21+1 -> 12 | B22: Austin | C22: =+C17 -> 2022 | D22: ='SECLE10 Sales by Year (21-23)'!D22/'SECLE10 Sales by Year (21-23)'!D62 -> 0.035709895 | E22: ='SECLE10 Sales by Year (21-23)'!E22/'SECLE10 Sales by Year (21-23)'!E$62 -> 0.03665033 | F22: ='SECLE10 Sales by Year (21-23)'!F22/'SECLE10 Sales by Year (21-23)'!F$62 -> 0.037033743 | G22: ='SECLE10 Sales by Year (21-23)'!G22/'SECLE10 Sales by Year (21-23)'!G$62 -> 0.035792357 | H22: ='SECLE10 Sales by Year (21-23)'!H22/'SECLE10 Sales by Year (21-23)'!H$62 -> 0.036503217 | I22: ='SECLE10 Sales by Year (21-23)'!I22/'SECLE10 Sales by Year (21-23)'!I$62 -> 0.036484898 | J22: ='SECLE10 Sales by Year (21-23)'!J22/'SECLE10 Sales by Year (21-23)'!J$62 -> 0.035136262 | K22: ='SECLE10 Sales by Year (21-23)'!K22/'SECLE10 Sales by Year (21-23)'!K$62 -> 0.035044875 | L22: ='SECLE10 Sales by Year (21-23)'!L22/'SECLE10 Sales by Year (21-23)'!L$62 -> 0.036242893 | ... P22: ='SECLE10 Sales by Year (21-23)'!P22/'SECLE10 Sales by Year (21-23)'!P$62 -> 0.036121417
A23: =+A22+1 -> 13 | B23: Austin | C23: =+C18 -> 2023 | D23: ='SECLE10 Sales by Year (21-23)'!D23/'SECLE10 Sales by Year (21-23)'!D63 -> 0.036857587 | E23: ='SECLE10 Sales by Year (21-23)'!E23/'SECLE10 Sales by Year (21-23)'!E63 -> 0.03674669 | F23: ='SECLE10 Sales by Year (21-23)'!F23/'SECLE10 Sales by Year (21-23)'!F63 -> 0.036012634 | G23: ='SECLE10 Sales by Year (21-23)'!G23/'SECLE10 Sales by Year (21-23)'!G63 -> 0.037085621 | H23: ='SECLE10 Sales by Year (21-23)'!H23/'SECLE10 Sales by Year (21-23)'!H63 -> 0.036427024 | I23: ='SECLE10 Sales by Year (21-23)'!I23/'SECLE10 Sales by Year (21-23)'!I63 -> 0.038963309 | J23: ='SECLE10 Sales by Year (21-23)'!J23/'SECLE10 Sales by Year (21-23)'!J63 -> 0.037389263 | K23: ='SECLE10 Sales by Year (21-23)'!K23/'SECLE10 Sales by Year (21-23)'!K63 -> 0.03682885 | ... P23: ='SECLE10 Sales by Year (21-23)'!P23/'SECLE10 Sales by Year (21-23)'!P63 -> 0.037324904
A24: =+A23+1 -> 14 | B24: Austin | C24: Total | D24: ='SECLE10 Sales by Year (21-23)'!D24/'SECLE10 Sales by Year (21-23)'!D64 -> 0.036026579 | E24: ='SECLE10 Sales by Year (21-23)'!E24/'SECLE10 Sales by Year (21-23)'!E64 -> 0.036265657 | F24: ='SECLE10 Sales by Year (21-23)'!F24/'SECLE10 Sales by Year (21-23)'!F64 -> 0.036309156 | G24: ='SECLE10 Sales by Year (21-23)'!G24/'SECLE10 Sales by Year (21-23)'!G64 -> 0.036085369 | H24: ='SECLE10 Sales by Year (21-23)'!H24/'SECLE10 Sales by Year (21-23)'!H64 -> 0.036233622 | I24: ='SECLE10 Sales by Year (21-23)'!I24/'SECLE10 Sales by Year (21-23)'!I64 -> 0.037238027 | J24: ='SECLE10 Sales by Year (21-23)'!J24/'SECLE10 Sales by Year (21-23)'!J64 -> 0.035866895 | K24: ='SECLE10 Sales by Year (21-23)'!K24/'SECLE10 Sales by Year (21-23)'!K64 -> 0.035553982 | ... P24: ='SECLE10 Sales by Year (21-23)'!P24/'SECLE10 Sales by Year (21-23)'!P64 -> 0.036403142
A25: =+A24+1 -> 15
A26: =+A25+1 -> 16 | B26: Killeen | C26: =+C21 -> 2021 | D26: ='SECLE10 Sales by Year (21-23)'!D26/'SECLE10 Sales by Year (21-23)'!D61 -> 0.034345752 | E26: ='SECLE10 Sales by Year (21-23)'!E26/'SECLE10 Sales by Year (21-23)'!E$61 -> 0.033735786 | F26: ='SECLE10 Sales by Year (21-23)'!F26/'SECLE10 Sales by Year (21-23)'!F$61 -> 0.034604738 | G26: ='SECLE10 Sales by Year (21-23)'!G26/'SECLE10 Sales by Year (21-23)'!G$61 -> 0.033409787 | H26: ='SECLE10 Sales by Year (21-23)'!H26/'SECLE10 Sales by Year (21-23)'!H$61 -> 0.034005525 | I26: ='SECLE10 Sales by Year (21-23)'!I26/'SECLE10 Sales by Year (21-23)'!I$61 -> 0.034471271 | J26: ='SECLE10 Sales by Year (21-23)'!J26/'SECLE10 Sales by Year (21-23)'!J$61 -> 0.033931936 | K26: ='SECLE10 Sales by Year (21-23)'!K26/'SECLE10 Sales by Year (21-23)'!K$61 -> 0.033831675 | L26: ='SECLE10 Sales by Year (21-23)'!L26/'SECLE10 Sales by Year (21-23)'!L$61 -> 0.034820854 | ... P26: ='SECLE10 Sales by Year (21-23)'!P26/'SECLE10 Sales by Year (21-23)'!P$61 -> 0.034195341
A27: =+A26+1 -> 17 | B27: Killeen | C27: =+C22 -> 2022 | D27: ='SECLE10 Sales by Year (21-23)'!D27/'SECLE10 Sales by Year (21-23)'!D62 -> 0.033937176 | E27: ='SECLE10 Sales by Year (21-23)'!E27/'SECLE10 Sales by Year (21-23)'!E$62 -> 0.034954911 | F27: ='SECLE10 Sales by Year (21-23)'!F27/'SECLE10 Sales by Year (21-23)'!F$62 -> 0.034581818 | G27: ='SECLE10 Sales by Year (21-23)'!G27/'SECLE10 Sales by Year (21-23)'!G$62 -> 0.033057398 | H27: ='SECLE10 Sales by Year (21-23)'!H27/'SECLE10 Sales by Year (21-23)'!H$62 -> 0.033779704 | I27: ='SECLE10 Sales by Year (21-23)'!I27/'SECLE10 Sales by Year (21-23)'!I$62 -> 0.034367829 | J27: ='SECLE10 Sales by Year (21-23)'!J27/'SECLE10 Sales by Year (21-23)'!J$62 -> 0.034054819 | K27: ='SECLE10 Sales by Year (21-23)'!K27/'SECLE10 Sales by Year (21-23)'!K$62 -> 0.034019578 | L27: ='SECLE10 Sales by Year (21-23)'!L27/'SECLE10 Sales by Year (21-23)'!L$62 -> 0.033921464 | ... P27: ='SECLE10 Sales by Year (21-23)'!P27/'SECLE10 Sales by Year (21-23)'!P$62 -> 0.033972761
A28: =+A27+1 -> 18 | B28: Killeen | C28: =+C23 -> 2023 | D28: ='SECLE10 Sales by Year (21-23)'!D28/'SECLE10 Sales by Year (21-23)'!D63 -> 0.033619345 | E28: ='SECLE10 Sales by Year (21-23)'!E28/'SECLE10 Sales by Year (21-23)'!E63 -> 0.033347285 | F28: ='SECLE10 Sales by Year (21-23)'!F28/'SECLE10 Sales by Year (21-23)'!F63 -> 0.032761492 | G28: ='SECLE10 Sales by Year (21-23)'!G28/'SECLE10 Sales by Year (21-23)'!G63 -> 0.033043861 | H28: ='SECLE10 Sales by Year (21-23)'!H28/'SECLE10 Sales by Year (21-23)'!H63 -> 0.032357723 | I28: ='SECLE10 Sales by Year (21-23)'!I28/'SECLE10 Sales by Year (21-23)'!I63 -> 0.034819432 | J28: ='SECLE10 Sales by Year (21-23)'!J28/'SECLE10 Sales by Year (21-23)'!J63 -> 0.034729546 | K28: ='SECLE10 Sales by Year (21-23)'!K28/'SECLE10 Sales by Year (21-23)'!K63 -> 0.03418306 | ... P28: ='SECLE10 Sales by Year (21-23)'!P28/'SECLE10 Sales by Year (21-23)'!P63 -> 0.033783317
A29: =+A28+1 -> 19 | B29: Killeen | C29: Total | D29: ='SECLE10 Sales by Year (21-23)'!D29/'SECLE10 Sales by Year (21-23)'!D64 -> 0.033968351 | E29: ='SECLE10 Sales by Year (21-23)'!E29/'SECLE10 Sales by Year (21-23)'!E64 -> 0.034028377 | F29: ='SECLE10 Sales by Year (21-23)'!F29/'SECLE10 Sales by Year (21-23)'!F64 -> 0.034024712 | G29: ='SECLE10 Sales by Year (21-23)'!G29/'SECLE10 Sales by Year (21-23)'!G64 -> 0.033168468 | H29: ='SECLE10 Sales by Year (21-23)'!H29/'SECLE10 Sales by Year (21-23)'!H64 -> 0.033388529 | I29: ='SECLE10 Sales by Year (21-23)'!I29/'SECLE10 Sales by Year (21-23)'!I64 -> 0.034541828 | J29: ='SECLE10 Sales by Year (21-23)'!J29/'SECLE10 Sales by Year (21-23)'!J64 -> 0.034227023 | K29: ='SECLE10 Sales by Year (21-23)'!K29/'SECLE10 Sales by Year (21-23)'!K64 -> 0.034011857 | ... P29: ='SECLE10 Sales by Year (21-23)'!P29/'SECLE10 Sales by Year (21-23)'!P64 -> 0.03398611
A30: =+A29+1 -> 20
A31: =+A30+1 -> 21 | B31: Longview | C31: =+C26 -> 2021 | D31: ='SECLE10 Sales by Year (21-23)'!D31/'SECLE10 Sales by Year (21-23)'!D61 -> 0.044580198 | E31: ='SECLE10 Sales by Year (21-23)'!E31/'SECLE10 Sales by Year (21-23)'!E$61 -> 0.045328496 | F31: ='SECLE10 Sales by Year (21-23)'!F31/'SECLE10 Sales by Year (21-23)'!F$61 -> 0.045812263 | G31: ='SECLE10 Sales by Year (21-23)'!G31/'SECLE10 Sales by Year (21-23)'!G$61 -> 0.042406732 | H31: ='SECLE10 Sales by Year (21-23)'!H31/'SECLE10 Sales by Year (21-23)'!H$61 -> 0.042504354 | I31: ='SECLE10 Sales by Year (21-23)'!I31/'SECLE10 Sales by Year (21-23)'!I$61 -> 0.04448375 | J31: ='SECLE10 Sales by Year (21-23)'!J31/'SECLE10 Sales by Year (21-23)'!J$61 -> 0.047207216 | K31: ='SECLE10 Sales by Year (21-23)'!K31/'SECLE10 Sales by Year (21-23)'!K$61 -> 0.047528208 | L31: ='SECLE10 Sales by Year (21-23)'!L31/'SECLE10 Sales by Year (21-23)'!L$61 -> 0.048425233 | ... P31: ='SECLE10 Sales by Year (21-23)'!P31/'SECLE10 Sales by Year (21-23)'!P$61 -> 0.045433745
A32: =+A31+1 -> 22 | B32: Longview | C32: =+C27 -> 2022 | D32: ='SECLE10 Sales by Year (21-23)'!D32/'SECLE10 Sales by Year (21-23)'!D62 -> 0.044693308 | E32: ='SECLE10 Sales by Year (21-23)'!E32/'SECLE10 Sales by Year (21-23)'!E$62 -> 0.046217462 | F32: ='SECLE10 Sales by Year (21-23)'!F32/'SECLE10 Sales by Year (21-23)'!F$62 -> 0.045943135 | G32: ='SECLE10 Sales by Year (21-23)'!G32/'SECLE10 Sales by Year (21-23)'!G$62 -> 0.043707297 | H32: ='SECLE10 Sales by Year (21-23)'!H32/'SECLE10 Sales by Year (21-23)'!H$62 -> 0.043490724 | I32: ='SECLE10 Sales by Year (21-23)'!I32/'SECLE10 Sales by Year (21-23)'!I$62 -> 0.046408368 | J32: ='SECLE10 Sales by Year (21-23)'!J32/'SECLE10 Sales by Year (21-23)'!J$62 -> 0.049083732 | K32: ='SECLE10 Sales by Year (21-23)'!K32/'SECLE10 Sales by Year (21-23)'!K$62 -> 0.049424407 | L32: ='SECLE10 Sales by Year (21-23)'!L32/'SECLE10 Sales by Year (21-23)'!L$62 -> 0.048571048 | ... P32: ='SECLE10 Sales by Year (21-23)'!P32/'SECLE10 Sales by Year (21-23)'!P$62 -> 0.046352806
A33: =+A32+1 -> 23 | B33: Longview | C33: =+C28 -> 2023 | D33: ='SECLE10 Sales by Year (21-23)'!D33/'SECLE10 Sales by Year (21-23)'!D63 -> 0.046745214 | E33: ='SECLE10 Sales by Year (21-23)'!E33/'SECLE10 Sales by Year (21-23)'!E63 -> 0.044819135 | F33: ='SECLE10 Sales by Year (21-23)'!F33/'SECLE10 Sales by Year (21-23)'!F63 -> 0.04356893 | G33: ='SECLE10 Sales by Year (21-23)'!G33/'SECLE10 Sales by Year (21-23)'!G63 -> 0.043088353 | H33: ='SECLE10 Sales by Year (21-23)'!H33/'SECLE10 Sales by Year (21-23)'!H63 -> 0.042837083 | I33: ='SECLE10 Sales by Year (21-23)'!I33/'SECLE10 Sales by Year (21-23)'!I63 -> 0.047740528 | J33: ='SECLE10 Sales by Year (21-23)'!J33/'SECLE10 Sales by Year (21-23)'!J63 -> 0.047683174 | K33: ='SECLE10 Sales by Year (21-23)'!K33/'SECLE10 Sales by Year (21-23)'!K63 -> 0.048864474 | ... P33: ='SECLE10 Sales by Year (21-23)'!P33/'SECLE10 Sales by Year (21-23)'!P63 -> 0.045756326
A34: =+A33+1 -> 24 | B34: Longview | C34: Total | D34: ='SECLE10 Sales by Year (21-23)'!D34/'SECLE10 Sales by Year (21-23)'!D64 -> 0.045358047 | E34: ='SECLE10 Sales by Year (21-23)'!E34/'SECLE10 Sales by Year (21-23)'!E64 -> 0.045467921 | F34: ='SECLE10 Sales by Year (21-23)'!F34/'SECLE10 Sales by Year (21-23)'!F64 -> 0.045160496 | G34: ='SECLE10 Sales by Year (21-23)'!G34/'SECLE10 Sales by Year (21-23)'!G64 -> 0.043078721 | H34: ='SECLE10 Sales by Year (21-23)'!H34/'SECLE10 Sales by Year (21-23)'!H64 -> 0.042952913 | I34: ='SECLE10 Sales by Year (21-23)'!I34/'SECLE10 Sales by Year (21-23)'!I64 -> 0.046200074 | J34: ='SECLE10 Sales by Year (21-23)'!J34/'SECLE10 Sales by Year (21-23)'!J64 -> 0.048026967 | K34: ='SECLE10 Sales by Year (21-23)'!K34/'SECLE10 Sales by Year (21-23)'!K64 -> 0.04864187 | ... P34: ='SECLE10 Sales by Year (21-23)'!P34/'SECLE10 Sales by Year (21-23)'!P64 -> 0.045854268
A35: =+A34+1 -> 25
A36: =+A35+1 -> 26 | B36: Waco | C36: =+C31 -> 2021 | D36: ='SECLE10 Sales by Year (21-23)'!D36/'SECLE10 Sales by Year (21-23)'!D61 -> 0.038090786 | E36: ='SECLE10 Sales by Year (21-23)'!E36/'SECLE10 Sales by Year (21-23)'!E$61 -> 0.03845632 | F36: ='SECLE10 Sales by Year (21-23)'!F36/'SECLE10 Sales by Year (21-23)'!F$61 -> 0.040065448 | G36: ='SECLE10 Sales by Year (21-23)'!G36/'SECLE10 Sales by Year (21-23)'!G$61 -> 0.038118888 | H36: ='SECLE10 Sales by Year (21-23)'!H36/'SECLE10 Sales by Year (21-23)'!H$61 -> 0.038449276 | I36: ='SECLE10 Sales by Year (21-23)'!I36/'SECLE10 Sales by Year (21-23)'!I$61 -> 0.038734549 | J36: ='SECLE10 Sales by Year (21-23)'!J36/'SECLE10 Sales by Year (21-23)'!J$61 -> 0.039349235 | K36: ='SECLE10 Sales by Year (21-23)'!K36/'SECLE10 Sales by Year (21-23)'!K$61 -> 0.039504999 | L36: ='SECLE10 Sales by Year (21-23)'!L36/'SECLE10 Sales by Year (21-23)'!L$61 -> 0.040787142 | ... P36: ='SECLE10 Sales by Year (21-23)'!P36/'SECLE10 Sales by Year (21-23)'!P$61 -> 0.039286257
A37: =+A36+1 -> 27 | B37: Waco | C37: =+C32 -> 2022 | D37: ='SECLE10 Sales by Year (21-23)'!D37/'SECLE10 Sales by Year (21-23)'!D62 -> 0.037962274 | E37: ='SECLE10 Sales by Year (21-23)'!E37/'SECLE10 Sales by Year (21-23)'!E$62 -> 0.038813126 | F37: ='SECLE10 Sales by Year (21-23)'!F37/'SECLE10 Sales by Year (21-23)'!F$62 -> 0.039727604 | G37: ='SECLE10 Sales by Year (21-23)'!G37/'SECLE10 Sales by Year (21-23)'!G$62 -> 0.038723308 | H37: ='SECLE10 Sales by Year (21-23)'!H37/'SECLE10 Sales by Year (21-23)'!H$62 -> 0.039364334 | I37: ='SECLE10 Sales by Year (21-23)'!I37/'SECLE10 Sales by Year (21-23)'!I$62 -> 0.040575791 | J37: ='SECLE10 Sales by Year (21-23)'!J37/'SECLE10 Sales by Year (21-23)'!J$62 -> 0.040920402 | K37: ='SECLE10 Sales by Year (21-23)'!K37/'SECLE10 Sales by Year (21-23)'!K$62 -> 0.04108857 | L37: ='SECLE10 Sales by Year (21-23)'!L37/'SECLE10 Sales by Year (21-23)'!L$62 -> 0.040997212 | ... P37: ='SECLE10 Sales by Year (21-23)'!P37/'SECLE10 Sales by Year (21-23)'!P$62 -> 0.039704521
A38: =+A37+1 -> 28 | B38: Waco | C38: =+C33 -> 2023 | D38: ='SECLE10 Sales by Year (21-23)'!D38/'SECLE10 Sales by Year (21-23)'!D63 -> 0.037876811 | E38: ='SECLE10 Sales by Year (21-23)'!E38/'SECLE10 Sales by Year (21-23)'!E63 -> 0.038440985 | F38: ='SECLE10 Sales by Year (21-23)'!F38/'SECLE10 Sales by Year (21-23)'!F63 -> 0.038861814 | G38: ='SECLE10 Sales by Year (21-23)'!G38/'SECLE10 Sales by Year (21-23)'!G63 -> 0.037931351 | H38: ='SECLE10 Sales by Year (21-23)'!H38/'SECLE10 Sales by Year (21-23)'!H63 -> 0.037501738 | I38: ='SECLE10 Sales by Year (21-23)'!I38/'SECLE10 Sales by Year (21-23)'!I63 -> 0.040227762 | J38: ='SECLE10 Sales by Year (21-23)'!J38/'SECLE10 Sales by Year (21-23)'!J63 -> 0.039773111 | K38: ='SECLE10 Sales by Year (21-23)'!K38/'SECLE10 Sales by Year (21-23)'!K63 -> 0.040727186 | ... P38: ='SECLE10 Sales by Year (21-23)'!P38/'SECLE10 Sales by Year (21-23)'!P63 -> 0.039082519
A39: =+A38+1 -> 29 | B39: Waco | C39: Total | D39: ='SECLE10 Sales by Year (21-23)'!D39/'SECLE10 Sales by Year (21-23)'!D64 -> 0.037977053 | E39: ='SECLE10 Sales by Year (21-23)'!E39/'SECLE10 Sales by Year (21-23)'!E64 -> 0.038574121 | F39: ='SECLE10 Sales by Year (21-23)'!F39/'SECLE10 Sales by Year (21-23)'!F64 -> 0.039576559 | G39: ='SECLE10 Sales by Year (21-23)'!G39/'SECLE10 Sales by Year (21-23)'!G64 -> 0.038266339 | H39: ='SECLE10 Sales by Year (21-23)'!H39/'SECLE10 Sales by Year (21-23)'!H64 -> 0.03845432 | I39: ='SECLE10 Sales by Year (21-23)'!I39/'SECLE10 Sales by Year (21-23)'!I64 -> 0.039871657 | J39: ='SECLE10 Sales by Year (21-23)'!J39/'SECLE10 Sales by Year (21-23)'!J64 -> 0.040043585 | K39: ='SECLE10 Sales by Year (21-23)'!K39/'SECLE10 Sales by Year (21-23)'!K64 -> 0.040468926 | ... P39: ='SECLE10 Sales by Year (21-23)'!P39/'SECLE10 Sales by Year (21-23)'!P64 -> 0.039364897
A40: =+A39+1 -> 30
A41: =+A40+1 -> 31 | B41: Abilene | C41: =+C36 -> 2021 | D41: ='SECLE10 Sales by Year (21-23)'!D41/'SECLE10 Sales by Year (21-23)'!D61 -> 0.030587283 | E41: ='SECLE10 Sales by Year (21-23)'!E41/'SECLE10 Sales by Year (21-23)'!E$61 -> 0.029936164 | F41: ='SECLE10 Sales by Year (21-23)'!F41/'SECLE10 Sales by Year (21-23)'!F$61 -> 0.02854145 | G41: ='SECLE10 Sales by Year (21-23)'!G41/'SECLE10 Sales by Year (21-23)'!G$61 -> 0.029439927 | H41: ='SECLE10 Sales by Year (21-23)'!H41/'SECLE10 Sales by Year (21-23)'!H$61 -> 0.028947721 | I41: ='SECLE10 Sales by Year (21-23)'!I41/'SECLE10 Sales by Year (21-23)'!I$61 -> 0.028741603 | J41: ='SECLE10 Sales by Year (21-23)'!J41/'SECLE10 Sales by Year (21-23)'!J$61 -> 0.029052624 | K41: ='SECLE10 Sales by Year (21-23)'!K41/'SECLE10 Sales by Year (21-23)'!K$61 -> 0.029516302 | L41: ='SECLE10 Sales by Year (21-23)'!L41/'SECLE10 Sales by Year (21-23)'!L$61 -> 0.030240656 | ... P41: ='SECLE10 Sales by Year (21-23)'!P41/'SECLE10 Sales by Year (21-23)'!P$61 -> 0.029346111
A42: =+A41+1 -> 32 | B42: Abilene | C42: =+C37 -> 2022 | D42: ='SECLE10 Sales by Year (21-23)'!D42/'SECLE10 Sales by Year (21-23)'!D62 -> 0.030736392 | E42: ='SECLE10 Sales by Year (21-23)'!E42/'SECLE10 Sales by Year (21-23)'!E$62 -> 0.03093201 | F42: ='SECLE10 Sales by Year (21-23)'!F42/'SECLE10 Sales by Year (21-23)'!F$62 -> 0.031236025 | G42: ='SECLE10 Sales by Year (21-23)'!G42/'SECLE10 Sales by Year (21-23)'!G$62 -> 0.030512681 | H42: ='SECLE10 Sales by Year (21-23)'!H42/'SECLE10 Sales by Year (21-23)'!H$62 -> 0.032308891 | I42: ='SECLE10 Sales by Year (21-23)'!I42/'SECLE10 Sales by Year (21-23)'!I$62 -> 0.032606701 | J42: ='SECLE10 Sales by Year (21-23)'!J42/'SECLE10 Sales by Year (21-23)'!J$62 -> 0.031548956 | K42: ='SECLE10 Sales by Year (21-23)'!K42/'SECLE10 Sales by Year (21-23)'!K$62 -> 0.031542438 | L42: ='SECLE10 Sales by Year (21-23)'!L42/'SECLE10 Sales by Year (21-23)'!L$62 -> 0.030172524 | ... P42: ='SECLE10 Sales by Year (21-23)'!P42/'SECLE10 Sales by Year (21-23)'!P$62 -> 0.030994541
...

Sheet SECLE10 Sales by Year (21-23)
B1: PUC DOCKET NO.
B2: ONCOR ELECTRIC DELIVERY COMPANY
B3: WEATHER WEIGHTS
B4: =+'SECLE10 Seasonal Weights'!B4:P4 -> FOR THE TEST YEAR ENDING DECEMBER 31, 2024
B6: SPONSOR: D. E. NELSON
B8: SECONDARY SERVICE LESS THAN OR EQUAL TO 10 KW MONTHLY WEIGHTS
A9: Line | B9: (a) | C9: (b) | D9: (c) | E9: (d) | F9: (e) | G9: (f) | H9: (g) | I9: (h) | J9: (i) | K9: (j) | L9: (k) | M9: (l) | N9: (m) | O9: (n) | P9: (o)
A10: No. | B10: Weather Station | C10: Year | D10: 36892 | E10: 36923 | F10: 36951 | G10: 36982 | H10: 37012 | I10: 37043 | J10: 37073 | K10: 37104 | L10: 37135 | M10: 37165 | N10: 37196 | O10: 37226 | P10: Annual
A11: 1 | B11: Dallas-Fort Worth | C11: 2021 | D11: 96732.919 | E11: 94768.279 | F11: 98993.93 | G11: 80543.26 | H11: 80816.181 | I11: 86504.008 | J11: 104039.97 | K11: 104186.96 | L11: 104184.4 | M11: 94209.1 | N11: 82955.71 | O11: 84058.618 | P11: =SUM(D11:O11) -> 1111993.3
A12: =+A11+1 -> 2 | B12: Dallas-Fort Worth | C12: 2022 | D12: 88427.803 | E12: 97230.819 | F12: 95118.377 | G12: 84516.346 | H12: 84002.161 | I12: 95481.588 | J12: 111892.73 | K12: 116706.29 | L12: 103018.97 | M12: 92449.778 | N12: 79779.671 | O12: 88013.138 | P12: =SUM(D12:O12) -> 1136637.7
A13: =+A12+1 -> 3 | B13: Dallas-Fort Worth | C13: 2023 | D13: 95891.712 | E13: 92938.778 | F13: 87064.643 | G13: 79632.696 | H13: 81866.233 | I13: 81833.237 | J13: 98305.812 | K13: 102614.6 | L13: 102995.07 | M13: 90345.784 | N13: 76377.878 | O13: 76491.172 | P13: =SUM(D13:O13) -> 1066357.6
A14: =+A13+1 -> 4 | B14: Dallas-Fort Worth | C14: Total | D14: =SUM(D11:D13) -> 281052.43 | E14: =SUM(E11:E13) -> 284937.88 | F14: =SUM(F11:F13) -> 281176.95 | G14: =SUM(G11:G13) -> 244692.3 | H14: =SUM(H11:H13) -> 246684.57 | I14: =SUM(I11:I13) -> 263818.83 | J14: =SUM(J11:J13) -> 314238.51 | K14: =SUM(K11:K13) -> 323507.85 | ... O14: =SUM(O11:O13) -> 248562.93 | P14: =SUM(D14:O14) -> 3314988.6
A15: =+A14+1 -> 5
A16: =+A15+1 -> 6 | B16: Lufkin | C16: =+C11 -> 2021 | D16: 5916.6464 | E16: 5670.1921 | F16: 6014.1023 | G16: 4769.0732 | H16: 4923.8093 | I16: 5491.3918 | J16: 6955.2841 | K16: 6873.3952 | L16: 6994.7999 | M16: 6006.431 | N16: 5109.2196 | O16: 5054.5313 | P16: =SUM(D16:O16) -> 69778.876
A17: =+A16+1 -> 7 | B17: Lufkin | C17: =+C12 -> 2022 | D17: 5431.1385 | E17: 6329.0744 | F17: 6075.9849 | G17: 5139.5459 | H17: 5297.5916 | I17: 6501.1818 | J17: 7812.9376 | K17: 8000.7779 | L17: 6880.9304 | M17: 5890.9325 | N17: 4758.8853 | O17: 5183.8377 | P17: =SUM(D17:O17) -> 73302.818
A18: =+A17+1 -> 8 | B18: Lufkin | C18: =+C13 -> 2023 | D18: 6061.0759 | E18: 5665.3141 | F18: 5087.1704 | G18: 4760.245 | H18: 4610.4885 | I18: 5276.463 | J18: 6497.3838 | K18: 6948.5864 | L18: 6788.5821 | M18: 5371.7111 | N18: 4280.2531 | O18: 4222.0367 | P18: =SUM(D18:O18) -> 65569.31
A19: =+A18+1 -> 9 | B19: Lufkin | C19: Total | D19: =SUM(D16:D18) -> 17408.861 | E19: =SUM(E16:E18) -> 17664.581 | F19: =SUM(F16:F18) -> 17177.258 | G19: =SUM(G16:G18) -> 14668.864 | H19: =SUM(H16:H18) -> 14831.889 | I19: =SUM(I16:I18) -> 17269.037 | J19: =SUM(J16:J18) -> 21265.605 | K19: =SUM(K16:K18) -> 21822.76 | ... O19: =SUM(O16:O18) -> 14460.406 | P19: =SUM(D19:O19) -> 208651.01
A20: =+A19+1 -> 10
A21: =+A20+1 -> 11 | B21: Austin | C21: =+C16 -> 2021 | D21: 5642.3583 | E21: 5480.5628 | F21: 5811.8976 | G21: 4709.1551 | H21: 4800.8388 | I21: 5209.5066 | J21: 6087.3313 | K21: 6034.8595 | L21: 6284.0317 | M21: 5697.0963 | N21: 4984.5631 | O21: 4994.3925 | P21: =SUM(D21:O21) -> 65736.594
A22: =+A21+1 -> 12 | B22: Austin | C22: =+C17 -> 2022 | D22: 5199.4768 | E22: 5942.8975 | F22: 5874.7491 | G22: 5017.9221 | H22: 5139.3687 | I22: 5888.5175 | J22: 6611.285 | K22: 6906.843 | L22: 6251.414 | M22: 5610.3578 | N22: 4834.92 | O22: 5216.775 | P22: =SUM(D22:O22) -> 68494.526
A23: =+A22+1 -> 13 | B23: Austin | C23: =+C18 -> 2023 | D23: 5857.9226 | E23: 5660.7301 | F23: 5199.1188 | G23: 4920.733 | H23: 4873.5624 | I23: 5357.7359 | J23: 6207.6616 | K23: 6383.2909 | L23: 6476.0839 | M23: 5735.8634 | N23: 4759.5517 | O23: 4609.176 | P23: =SUM(D23:O23) -> 66041.43
A24: =+A23+1 -> 14 | B24: Austin | C24: Total | D24: =SUM(D21:D23) -> 16699.758 | E24: =SUM(E21:E23) -> 17084.19 | F24: =SUM(F21:F23) -> 16885.765 | G24: =SUM(G21:G23) -> 14647.81 | H24: =SUM(H21:H23) -> 14813.77 | I24: =SUM(I21:I23) -> 16455.76 | J24: =SUM(J21:J23) -> 18906.278 | K24: =SUM(K21:K23) -> 19324.993 | ... O24: =SUM(O21:O23) -> 14820.343 | P24: =SUM(D24:O24) -> 200272.55
A25: =+A24+1 -> 15
A26: =+A25+1 -> 16 | B26: Killeen | C26: =+C21 -> 2021 | D26: 5461.0678 | E26: 5225.1985 | F26: 5607.8249 | G26: 4444.836 | H26: 4565.5298 | I26: 4929.5355 | J26: 5867.9895 | K26: 5857.3015 | L26: 6058.624 | M26: 5420.6189 | N26: 4643.5599 | O26: 4697.8736 | P26: =SUM(D26:O26) -> 62779.96
A27: =+A26+1 -> 17 | B27: Killeen | C27: =+C22 -> 2022 | D27: 4941.3632 | E27: 5667.9832 | F27: 5485.7945 | G27: 4634.4936 | H27: 4755.9193 | I27: 5546.8311 | J27: 6407.7991 | K27: 6704.7717 | L27: 5850.9984 | M27: 5188.1274 | N27: 4432.18 | O27: 4803.918 | P27: =SUM(D27:O27) -> 64420.179
A28: =+A27+1 -> 18 | B28: Killeen | C28: =+C23 -> 2023 | D28: 5343.2559 | E28: 5137.0609 | F28: 4729.7537 | G28: 4384.4491 | H28: 4329.1316 | I28: 4787.9229 | J28: 5766.0744 | K28: 5924.7143 | L28: 5914.8836 | M28: 5187.1712 | N28: 4238.3736 | O28: 4032.2742 | P28: =SUM(D28:O28) -> 59775.065
A29: =+A28+1 -> 19 | B29: Killeen | C29: Total | D29: =SUM(D26:D28) -> 15745.687 | E29: =SUM(E26:E28) -> 16030.243 | F29: =SUM(F26:F28) -> 15823.373 | G29: =SUM(G26:G28) -> 13463.779 | H29: =SUM(H26:H28) -> 13650.581 | I29: =SUM(I26:I28) -> 15264.289 | J29: =SUM(J26:J28) -> 18041.863 | K29: =SUM(K26:K28) -> 18486.787 | ... O29: =SUM(O26:O28) -> 13534.066 | P29: =SUM(D29:O29) -> 186975.2
A30: =+A29+1 -> 20
A31: =+A30+1 -> 21 | B31: Longview | C31: =+C26 -> 2021 | D31: 7088.3724 | E31: 7020.7461 | F31: 7424.0455 | G31: 5641.7888 | H31: 5706.5696 | I31: 6361.3619 | J31: 8163.7384 | K31: 8228.5918 | L31: 8425.7059 | M31: 7282.6129 | N31: 6046.4534 | O31: 6022.8011 | P31: =SUM(D31:O31) -> 83412.788
A32: =+A31+1 -> 22 | B32: Longview | C32: =+C27 -> 2022 | D32: 6507.4909 | E32: 7494.2199 | F32: 7288.0667 | G32: 6127.56 | H32: 6123.1554 | I32: 7490.1262 | J32: 9235.6591 | K32: 9740.843 | L32: 8377.8556 | M32: 7194.7666 | N32: 5871.5428 | O32: 6444.3093 | P32: =SUM(D32:O32) -> 87895.596
A33: =+A32+1 -> 23 | B33: Longview | C33: =+C28 -> 2023 | D33: 7429.4023 | E33: 6904.2689 | F33: 6290.0159 | G33: 5717.21 | H33: 5731.1626 | I33: 6564.6667 | J33: 7916.7383 | K33: 8469.3427 | L33: 8496.3057 | M33: 6827.0241 | N33: 5344.9601 | O33: 5268.6081 | P33: =SUM(D33:O33) -> 80959.705
A34: =+A33+1 -> 24 | B34: Longview | C34: Total | D34: =SUM(D31:D33) -> 21025.266 | E34: =SUM(E31:E33) -> 21419.235 | F34: =SUM(F31:F33) -> 21002.128 | G34: =SUM(G31:G33) -> 17486.559 | H34: =SUM(H31:H33) -> 17560.888 | I34: =SUM(I31:I33) -> 20416.155 | J34: =SUM(J31:J33) -> 25316.136 | K34: =SUM(K31:K33) -> 26438.778 | ... O34: =SUM(O31:O33) -> 17735.718 | P34: =SUM(D34:O34) -> 252268.09
A35: =+A34+1 -> 25
A36: =+A35+1 -> 26 | B36: Waco | C36: =+C31 -> 2021 | D36: 6056.5383 | E36: 5956.3428 | F36: 6492.753 | G36: 5071.3344 | H36: 5162.1411 | I36: 5539.2021 | J36: 6804.8253 | K36: 6839.5281 | L36: 7096.723 | M36: 6446.1713 | N36: 5351.7596 | O36: 5309.164 | P36: =SUM(D36:O36) -> 72126.483
A37: =+A36+1 -> 27 | B37: Waco | C37: =+C32 -> 2022 | D37: 5527.4305 | E37: 6293.5976 | F37: 6302.0826 | G37: 5428.8278 | H37: 5542.1918 | I37: 6548.7715 | J37: 7699.6362 | K37: 8097.9689 | L37: 7071.4704 | M37: 6228.2223 | N37: 5062.3429 | O37: 5486.3746 | P37: =SUM(D37:O37) -> 75288.917
A38: =+A37+1 -> 28 | B38: Waco | C38: =+C33 -> 2023 | D38: 6019.9118 | E38: 5921.7317 | F38: 5610.4529 | G38: 5032.9493 | H38: 5017.3482 | I38: 5531.6072 | J38: 6603.4469 | K38: 7058.9627 | L38: 7053.5069 | M38: 6004.5394 | N38: 4719.9856 | O38: 4576.8533 | P38: =SUM(D38:O38) -> 69151.296
A39: =+A38+1 -> 29 | B39: Waco | C39: Total | D39: =SUM(D36:D38) -> 17603.881 | E39: =SUM(E36:E38) -> 18171.672 | F39: =SUM(F36:F38) -> 18405.289 | G39: =SUM(G36:G38) -> 15533.111 | H39: =SUM(H36:H38) -> 15721.681 | I39: =SUM(I36:I38) -> 17619.581 | J39: =SUM(J36:J38) -> 21107.908 | K39: =SUM(K36:K38) -> 21996.46 | ... O39: =SUM(O36:O38) -> 15372.392 | P39: =SUM(D39:O39) -> 216566.7
A40: =+A39+1 -> 30
A41: =+A40+1 -> 31 | B41: Abilene | C41: =+C36 -> 2021 | D41: 4863.4609 | E41: 4636.6905 | F41: 4625.2468 | G41: 3916.686 | H41: 3886.4769 | I41: 4110.1691 | J41: 5024.1899 | K41: 5110.1779 | L41: 5261.6964 | M41: 4446.1052 | N41: 3870.013 | O41: 4126.2432 | P41: =SUM(D41:O41) -> 53877.156
A42: =+A41+1 -> 32 | B42: Abilene | C42: =+C37 -> 2022 | D42: 4475.3186 | E42: 5015.6646 | F42: 4955.0436 | G42: 4277.7361 | H42: 4548.8403 | I42: 5262.5919 | J42: 5936.2928 | K42: 6216.5629 | L42: 5204.3566 | M42: 4576.007 | N42: 3851.3357 | O42: 4453.0391 | P42: =SUM(D42:O42) -> 58772.789
...
