Workbook
Name I: "a1..m50"

Sheet Weather Adjustment
AA1: WP/II-H-1.2/1
AA2: Page 1 of 9
A4: PUC DOCKET NO
A5: ONCOR ELECTRIC DELIVERY COMPANY LLC
A6: MONTHLY SALES DATA
A7: TEST YEAR ENDING December 31, 2024
A9: SPONSOR: D. E. NELSON
A11: Weather Adjustment (MWH) By Class (based on 20-year average weather 2004-2023)
A13: Line | C13: Year | E13: Month | G13: Residential | I13: SECLE10 | K13: SECGT10_IDR | M13: SECGT10_NIDR | O13: PRMLE10 | Q13: PRMGT10_IDR_NoSUB | S13: PRMGT10_IDR_SUB | U13: PRMGT10_NIDR | W13: Transmission | Y13: Lighting | AA13: Total
A14: No. | G14: (a) | I14: (b) | K14: (c) | M14: (d) | O14: (e) | Q14: (f) | S14: (g) | U14: (h) | W14: (i) | Y14: (j) | AA14: (k)
A16: 1 | C16: 2024 | E16: 1 | G16: =+Residential!Z52+ResidentialT!AB52 -> 167851.48 | I16: =+SecLE10!W52 -> 4491.5377 | K16: =+SGT10_IDR_NIDR!J34 -> 18204.191 | M16: =+SGT10_IDR_NIDR!M34 -> 25421.05 | O16: 0 | Q16: =+'PrmGT10D IDR_NIDR'!J34 -> 2153.5914 | S16: =+Substation!Q52 -> 1232.4092 | U16: =+'PrmGT10D IDR_NIDR'!M34 -> 205.44764 | W16: 0 | Y16: 0 | AA16: =SUM(G16,I16,K16,M16,O16,Q16,S16,U16,W16,Y16,) -> 219559.71
A17: =+A16+1 -> 2 | C17: =C16 -> 2024 | E17: 2 | G17: =+Residential!Z53+ResidentialT!AB53 -> -276694.62 | I17: =+SecLE10!W53 -> 1426.3578 | K17: =+SGT10_IDR_NIDR!J35 -> -17149.141 | M17: =+SGT10_IDR_NIDR!M35 -> -25145.863 | O17: 0 | Q17: =+'PrmGT10D IDR_NIDR'!J35 -> 1966.3527 | S17: =+Substation!Q53 -> 1165.0167 | U17: =+'PrmGT10D IDR_NIDR'!M35 -> 170.21346 | W17: 0 | Y17: 0 | AA17: =SUM(G17,I17,K17,M17,O17,Q17,S17,U17,W17,Y17,) -> -314261.69
A18: =+A17+1 -> 3 | C18: =C17 -> 2024 | E18: 3 | G18: =+Residential!Z54+ResidentialT!AB54 -> 563688.89 | I18: =+SecLE10!W54 -> 7971.6045 | K18: =+SGT10_IDR_NIDR!J36 -> 20744.357 | M18: =+SGT10_IDR_NIDR!M36 -> 27874.702 | O18: 0 | Q18: =+'PrmGT10D IDR_NIDR'!J36 -> -8421.0009 | S18: =+Substation!Q54 -> -4192.8512 | U18: =+'PrmGT10D IDR_NIDR'!M36 -> -336.6838 | W18: 0 | Y18: 0 | AA18: =SUM(G18,I18,K18,M18,O18,Q18,S18,U18,W18,Y18,) -> 607329.02
A19: =+A18+1 -> 4 | C19: =C18 -> 2024 | E19: 4 | G19: =+Residential!Z55+ResidentialT!AB55 -> 152610.95 | I19: =+SecLE10!W55 -> 1596.2729 | K19: =+SGT10_IDR_NIDR!J37 -> 10762.995 | M19: =+SGT10_IDR_NIDR!M37 -> 14176.13 | O19: 0 | Q19: =+'PrmGT10D IDR_NIDR'!J37 -> 2489.9804 | S19: =+Substation!Q55 -> 763.5103 | U19: =+'PrmGT10D IDR_NIDR'!M37 -> 220.64052 | W19: 0 | Y19: 0 | AA19: =SUM(G19,I19,K19,M19,O19,Q19,S19,U19,W19,Y19,) -> 182620.48
A20: =+A19+1 -> 5 | C20: =C19 -> 2024 | E20: 5 | G20: =+Residential!Z56+ResidentialT!AB56 -> -63074.931 | I20: =+SecLE10!W56 -> -752.36737 | K20: =+SGT10_IDR_NIDR!J38 -> -24412.696 | M20: =+SGT10_IDR_NIDR!M38 -> -34219.904 | O20: 0 | Q20: =+'PrmGT10D IDR_NIDR'!J38 -> -6688.6916 | S20: =+Substation!Q56 -> -2239.4665 | U20: =+'PrmGT10D IDR_NIDR'!M38 -> -564.28893 | W20: 0 | Y20: 0 | AA20: =SUM(G20,I20,K20,M20,O20,Q20,S20,U20,W20,Y20,) -> -131952.35
A21: =+A20+1 -> 6 | C21: =C20 -> 2024 | E21: 6 | G21: =+Residential!Z57+ResidentialT!AB57 -> -143363.28 | I21: =+SecLE10!W57 -> -2207.1426 | K21: =+SGT10_IDR_NIDR!J39 -> -28163.809 | M21: =+SGT10_IDR_NIDR!M39 -> -42552.934 | O21: 0 | Q21: =+'PrmGT10D IDR_NIDR'!J39 -> -12206.307 | S21: =+Substation!Q57 -> -3464.5437 | U21: =+'PrmGT10D IDR_NIDR'!M39 -> -1078.6816 | W21: 0 | Y21: 0 | AA21: =SUM(G21,I21,K21,M21,O21,Q21,S21,U21,W21,Y21,) -> -233036.7
A22: =+A21+1 -> 7 | C22: =C21 -> 2024 | E22: 7 | G22: =+Residential!Z58+ResidentialT!AB58 -> -240111.72 | I22: =+SecLE10!W58 -> -3420.3708 | K22: =+SGT10_IDR_NIDR!J40 -> -36108.774 | M22: =+SGT10_IDR_NIDR!M40 -> -58614.671 | O22: 0 | Q22: =+'PrmGT10D IDR_NIDR'!J40 -> -8523.8033 | S22: =+Substation!Q58 -> -905.3119 | U22: =+'PrmGT10D IDR_NIDR'!M40 -> -845.4541 | W22: 0 | Y22: 0 | AA22: =SUM(G22,I22,K22,M22,O22,Q22,S22,U22,W22,Y22,) -> -348530.11
A23: =+A22+1 -> 8 | C23: =C22 -> 2024 | E23: 8 | G23: =+Residential!Z59+ResidentialT!AB59 -> 221530.83 | I23: =+SecLE10!W59 -> 2760.7303 | K23: =+SGT10_IDR_NIDR!J41 -> 31493.803 | M23: =+SGT10_IDR_NIDR!M41 -> 51290.998 | O23: 0 | Q23: =+'PrmGT10D IDR_NIDR'!J41 -> 3322.6149 | S23: =+Substation!Q59 -> -136.32691 | U23: =+'PrmGT10D IDR_NIDR'!M41 -> 356.19694 | W23: 0 | Y23: 0 | AA23: =SUM(G23,I23,K23,M23,O23,Q23,S23,U23,W23,Y23,) -> 310618.85
A24: =+A23+1 -> 9 | C24: =C23 -> 2024 | E24: 9 | G24: =+Residential!Z60+ResidentialT!AB60 -> -194424.09 | I24: =+SecLE10!W60 -> -3051.4956 | K24: =+SGT10_IDR_NIDR!J42 -> -28539.576 | M24: =+SGT10_IDR_NIDR!M42 -> -46599.711 | O24: 0 | Q24: =+'PrmGT10D IDR_NIDR'!J42 -> -11164.349 | S24: =+Substation!Q60 -> -95.370489 | U24: =+'PrmGT10D IDR_NIDR'!M42 -> -1125.7762 | W24: 0 | Y24: 0 | AA24: =SUM(G24,I24,K24,M24,O24,Q24,S24,U24,W24,Y24,) -> -285000.37
A25: =+A24+1 -> 10 | C25: =C24 -> 2024 | E25: 10 | G25: =+Residential!Z61+ResidentialT!AB61 -> -110530.15 | I25: =+SecLE10!W61 -> -1303.5394 | K25: =+SGT10_IDR_NIDR!J43 -> -25483.497 | M25: =+SGT10_IDR_NIDR!M43 -> -38396.592 | O25: 0 | Q25: =+'PrmGT10D IDR_NIDR'!J43 -> -6060.8869 | S25: =+Substation!Q61 -> -2595.6828 | U25: =+'PrmGT10D IDR_NIDR'!M43 -> -526.14579 | W25: 0 | Y25: 0 | AA25: =SUM(G25,I25,K25,M25,O25,Q25,S25,U25,W25,Y25,) -> -184896.49
A26: =+A25+1 -> 11 | C26: =C25 -> 2024 | E26: 11 | G26: =+Residential!Z62+ResidentialT!AB62 -> -161187.97 | I26: =+SecLE10!W62 -> -1980.1974 | K26: =+SGT10_IDR_NIDR!J44 -> -70966.998 | M26: =+SGT10_IDR_NIDR!M44 -> -100578.2 | O26: 0 | Q26: =+'PrmGT10D IDR_NIDR'!J44 -> -24717.303 | S26: =+Substation!Q62 -> -9052.16 | U26: =+'PrmGT10D IDR_NIDR'!M44 -> -1349.604 | W26: 0 | Y26: 0 | AA26: =SUM(G26,I26,K26,M26,O26,Q26,S26,U26,W26,Y26,) -> -369832.44
A27: =+A26+1 -> 12 | C27: =C26 -> 2024 | E27: 12 | G27: =+Residential!Z63+ResidentialT!AB63 -> 288007.91 | I27: =+SecLE10!W63 -> 2027.7888 | K27: =+SGT10_IDR_NIDR!J45 -> 12844.377 | M27: =+SGT10_IDR_NIDR!M45 -> 16945.59 | O27: 0 | Q27: =+'PrmGT10D IDR_NIDR'!J45 -> -3553.1668 | S27: =+Substation!Q63 -> -1784.5009 | U27: =+'PrmGT10D IDR_NIDR'!M45 -> -273.00911 | W27: 0 | Y27: 0 | AA27: =SUM(G27,I27,K27,M27,O27,Q27,S27,U27,W27,Y27,) -> 314214.99
A28: =+A27+1 -> 13 | C28: Total | G28: =SUM(G16:G27) -> 204303.29 | I28: =SUM(I16:I27) -> 7559.179 | K28: =SUM(K16:K27) -> -136774.77 | M28: =SUM(M16:M27) -> -210399.41 | O28: =SUM(O16:O27) -> 0 | Q28: =SUM(Q16:Q27) -> -71402.97 | S28: =SUM(S16:S27) -> -21305.278 | U28: =SUM(U16:U27) -> -5147.1449 | W28: =SUM(W16:W27) -> 0 | Y28: =SUM(Y16:Y27) -> 0 | AA28: =SUM(AA16:AA27) -> -233167.1
A29: =+A28+1 -> 14
A30: =+A29+1 -> 15 | C30: Customer Count
A31: =+A30+1 -> 16
A32: =+A31+1 -> 17 | C32: Year | E32: Month | G32: Residential | I32: SECLE10 | K32: SECGT10_IDR | M32: SECGT10_NIDR | O32: PRMLE10 | Q32: PRMGT10_IDR_NoSUB | S32: PRMGT10_IDR_SUB | U32: PRMGT10_NIDR | W32: Transmission | Y32: Lighting | AA32: Total
A33: =+A32+1 -> 18 | G33: (l) | I33: (m) | K33: (n) | M33: (o) | O33: (p) | Q33: (q) | S33: (r) | U33: (s) | W33: (t) | Y33: (u) | AA33: (v)
A34: =+A33+1 -> 19
A35: =+A34+1 -> 20 | C35: =+C16 -> 2024 | E35: =+E16 -> 1 | G35: =+[1]RES!E16 -> 3396604 | I35: =+'[1]GS SEC SMALL'!E16 -> 284930 | K35: =+'[1]GS SEC LRG IDR '!E16 -> 5679 | M35: =+'[1]GS SEC LRG NONIDR'!E16 -> 225820 | O35: =+'[1]GS PRI SMALL'!E16 -> 3151 | Q35: =+'[1]GS PRI LRG IDR '!E16 -> 1899 | S35: =+'[1]GS PRI LRG SUB'!E16 -> 151 | U35: =+'[1]GS PRI LRG NONIDR'!E16 -> 5179 | W35: =+[1]TRANSMISSION!E16 -> 319 | Y35: =+'[1]SL - UNMETERED'!E16+'[1]SL - METERED NON CO'!E16+'[1]SL - METERED CO OWNED'!E16+'[1]OUTDOOR LIGHTING'!E16 -> 52286 | AA35: =SUM(G35:Y35) -> 3976018
A36: =+A35+1 -> 21 | C36: =+C17 -> 2024 | E36: =+E17 -> 2 | G36: =+[1]RES!E18 -> 3401024 | I36: =+'[1]GS SEC SMALL'!E18 -> 282336 | K36: =+'[1]GS SEC LRG IDR '!E18 -> 5675 | M36: =+'[1]GS SEC LRG NONIDR'!E18 -> 228780 | O36: =+'[1]GS PRI SMALL'!E18 -> 3086 | Q36: =+'[1]GS PRI LRG IDR '!E18 -> 1903 | S36: =+'[1]GS PRI LRG SUB'!E18 -> 152 | U36: =+'[1]GS PRI LRG NONIDR'!E18 -> 5183 | W36: =+[1]TRANSMISSION!E18 -> 320 | Y36: =+'[1]SL - UNMETERED'!E18+'[1]SL - METERED NON CO'!E18+'[1]SL - METERED CO OWNED'!E18+'[1]OUTDOOR LIGHTING'!E18 -> 52202 | AA36: =SUM(G36:Y36) -> 3980661
A37: =+A36+1 -> 22 | C37: =+C18 -> 2024 | E37: =+E18 -> 3 | G37: =+[1]RES!E20 -> 3407140 | I37: =+'[1]GS SEC SMALL'!E20 -> 283192 | K37: =+'[1]GS SEC LRG IDR '!E20 -> 5674 | M37: =+'[1]GS SEC LRG NONIDR'!E20 -> 228741 | O37: =+'[1]GS PRI SMALL'!E20 -> 3096 | Q37: =+'[1]GS PRI LRG IDR '!E20 -> 1898 | S37: =+'[1]GS PRI LRG SUB'!E20 -> 154 | U37: =+'[1]GS PRI LRG NONIDR'!E20 -> 5177 | W37: =+[1]TRANSMISSION!E20 -> 322 | Y37: =+'[1]SL - UNMETERED'!E20+'[1]SL - METERED NON CO'!E20+'[1]SL - METERED CO OWNED'!E20+'[1]OUTDOOR LIGHTING'!E20 -> 52127 | AA37: =SUM(G37:Y37) -> 3987521
A38: =+A37+1 -> 23 | C38: =+C19 -> 2024 | E38: =+E19 -> 4 | G38: =+[1]RES!E22 -> 3413927 | I38: =+'[1]GS SEC SMALL'!E22 -> 283989 | K38: =+'[1]GS SEC LRG IDR '!E22 -> 5673 | M38: =+'[1]GS SEC LRG NONIDR'!E22 -> 228730 | O38: =+'[1]GS PRI SMALL'!E22 -> 3074 | Q38: =+'[1]GS PRI LRG IDR '!E22 -> 1893 | S38: =+'[1]GS PRI LRG SUB'!E22 -> 157 | U38: =+'[1]GS PRI LRG NONIDR'!E22 -> 5172 | W38: =+[1]TRANSMISSION!E22 -> 322 | Y38: =+'[1]SL - UNMETERED'!E22+'[1]SL - METERED NON CO'!E22+'[1]SL - METERED CO OWNED'!E22+'[1]OUTDOOR LIGHTING'!E22 -> 52051 | AA38: =SUM(G38:Y38) -> 3994988
A39: =+A38+1 -> 24 | C39: =+C20 -> 2024 | E39: =+E20 -> 5 | G39: =+[1]RES!E24 -> 3421241 | I39: =+'[1]GS SEC SMALL'!E24 -> 284452 | K39: =+'[1]GS SEC LRG IDR '!E24 -> 5696 | M39: =+'[1]GS SEC LRG NONIDR'!E24 -> 228854 | O39: =+'[1]GS PRI SMALL'!E24 -> 3079 | Q39: =+'[1]GS PRI LRG IDR '!E24 -> 1949 | S39: =+'[1]GS PRI LRG SUB'!E24 -> 159 | U39: =+'[1]GS PRI LRG NONIDR'!E24 -> 5124 | W39: =+[1]TRANSMISSION!E24 -> 324 | Y39: =+'[1]SL - UNMETERED'!E24+'[1]SL - METERED NON CO'!E24+'[1]SL - METERED CO OWNED'!E24+'[1]OUTDOOR LIGHTING'!E24 -> 51963 | AA39: =SUM(G39:Y39) -> 4002841
A40: =+A39+1 -> 25 | C40: =+C21 -> 2024 | E40: =+E21 -> 6 | G40: =+[1]RES!E26 -> 3425884 | I40: =+'[1]GS SEC SMALL'!E26 -> 284068 | K40: =+'[1]GS SEC LRG IDR '!E26 -> 5688 | M40: =+'[1]GS SEC LRG NONIDR'!E26 -> 229356 | O40: =+'[1]GS PRI SMALL'!E26 -> 3086 | Q40: =+'[1]GS PRI LRG IDR '!E26 -> 1950 | S40: =+'[1]GS PRI LRG SUB'!E26 -> 155 | U40: =+'[1]GS PRI LRG NONIDR'!E26 -> 5124 | W40: =+[1]TRANSMISSION!E26 -> 326 | Y40: =+'[1]SL - UNMETERED'!E26+'[1]SL - METERED NON CO'!E26+'[1]SL - METERED CO OWNED'!E26+'[1]OUTDOOR LIGHTING'!E26 -> 51895 | AA40: =SUM(G40:Y40) -> 4007532
A41: =+A40+1 -> 26 | C41: =+C22 -> 2024 | E41: =+E22 -> 7 | G41: =+[1]RES!E28 -> 3432967 | I41: =+'[1]GS SEC SMALL'!E28 -> 284074 | K41: =+'[1]GS SEC LRG IDR '!E28 -> 5684 | M41: =+'[1]GS SEC LRG NONIDR'!E28 -> 229680 | O41: =+'[1]GS PRI SMALL'!E28 -> 3097 | Q41: =+'[1]GS PRI LRG IDR '!E28 -> 1946 | S41: =+'[1]GS PRI LRG SUB'!E28 -> 158 | U41: =+'[1]GS PRI LRG NONIDR'!E28 -> 5109 | W41: =+[1]TRANSMISSION!E28 -> 327 | Y41: =+'[1]SL - UNMETERED'!E28+'[1]SL - METERED NON CO'!E28+'[1]SL - METERED CO OWNED'!E28+'[1]OUTDOOR LIGHTING'!E28 -> 51745 | AA41: =SUM(G41:Y41) -> 4014787
A42: =+A41+1 -> 27 | C42: =+C23 -> 2024 | E42: =+E23 -> 8 | G42: =+[1]RES!E30 -> 3439507 | I42: =+'[1]GS SEC SMALL'!E30 -> 284801 | K42: =+'[1]GS SEC LRG IDR '!E30 -> 5681 | M42: =+'[1]GS SEC LRG NONIDR'!E30 -> 229568 | O42: =+'[1]GS PRI SMALL'!E30 -> 3100 | Q42: =+'[1]GS PRI LRG IDR '!E30 -> 1945 | S42: =+'[1]GS PRI LRG SUB'!E30 -> 160 | U42: =+'[1]GS PRI LRG NONIDR'!E30 -> 5103 | W42: =+[1]TRANSMISSION!E30 -> 330 | Y42: =+'[1]SL - UNMETERED'!E30+'[1]SL - METERED NON CO'!E30+'[1]SL - METERED CO OWNED'!E30+'[1]OUTDOOR LIGHTING'!E30 -> 51680 | AA42: =SUM(G42:Y42) -> 4021875
A43: =+A42+1 -> 28 | C43: =+C24 -> 2024 | E43: =+E24 -> 9 | G43: =+[1]RES!E32 -> 3444509 | I43: =+'[1]GS SEC SMALL'!E32 -> 285728 | K43: =+'[1]GS SEC LRG IDR '!E32 -> 5732 | M43: =+'[1]GS SEC LRG NONIDR'!E32 -> 228741 | O43: =+'[1]GS PRI SMALL'!E32 -> 3122 | Q43: =+'[1]GS PRI LRG IDR '!E32 -> 1998 | S43: =+'[1]GS PRI LRG SUB'!E32 -> 160 | U43: =+'[1]GS PRI LRG NONIDR'!E32 -> 5040 | W43: =+[1]TRANSMISSION!E32 -> 332 | Y43: =+'[1]SL - UNMETERED'!E32+'[1]SL - METERED NON CO'!E32+'[1]SL - METERED CO OWNED'!E32+'[1]OUTDOOR LIGHTING'!E32 -> 51594 | AA43: =SUM(G43:Y43) -> 4026956
A44: =+A43+1 -> 29 | C44: =+C25 -> 2024 | E44: =+E25 -> 10 | G44: =+[1]RES!E34 -> 3450481 | I44: =+'[1]GS SEC SMALL'!E34 -> 286930 | K44: =+'[1]GS SEC LRG IDR '!E34 -> 5729 | M44: =+'[1]GS SEC LRG NONIDR'!E34 -> 228156 | O44: =+'[1]GS PRI SMALL'!E34 -> 3134 | Q44: =+'[1]GS PRI LRG IDR '!E34 -> 1991 | S44: =+'[1]GS PRI LRG SUB'!E34 -> 161 | U44: =+'[1]GS PRI LRG NONIDR'!E34 -> 5022 | W44: =+[1]TRANSMISSION!E34 -> 332 | Y44: =+'[1]SL - UNMETERED'!E34+'[1]SL - METERED NON CO'!E34+'[1]SL - METERED CO OWNED'!E34+'[1]OUTDOOR LIGHTING'!E34 -> 51419 | AA44: =SUM(G44:Y44) -> 4033355
A45: =+A44+1 -> 30 | C45: =+C26 -> 2024 | E45: =+E26 -> 11 | G45: =+[1]RES!E36 -> 3456155 | I45: =+'[1]GS SEC SMALL'!E36 -> 287446 | K45: =+'[1]GS SEC LRG IDR '!E36 -> 5729 | M45: =+'[1]GS SEC LRG NONIDR'!E36 -> 228028 | O45: =+'[1]GS PRI SMALL'!E36 -> 3143 | Q45: =+'[1]GS PRI LRG IDR '!E36 -> 1990 | S45: =+'[1]GS PRI LRG SUB'!E36 -> 162 | U45: =+'[1]GS PRI LRG NONIDR'!E36 -> 5011 | W45: =+[1]TRANSMISSION!E36 -> 334 | Y45: =+'[1]SL - UNMETERED'!E36+'[1]SL - METERED NON CO'!E36+'[1]SL - METERED CO OWNED'!E36+'[1]OUTDOOR LIGHTING'!E36 -> 51335 | AA45: =SUM(G45:Y45) -> 4039333
...

Sheet Residential
Z1: WP/II-H-1.2/1
Z2: Page 2 of 9
A4: =+'Weather Adjustment'!A4 -> PUC DOCKET NO
A5: =+'Weather Adjustment'!A5 -> ONCOR ELECTRIC DELIVERY COMPANY LLC
A6: =+'Weather Adjustment'!A6 -> MONTHLY SALES DATA
A7: =+'Weather Adjustment'!A7 -> TEST YEAR ENDING December 31, 2024
A9: =+'Weather Adjustment'!A9 -> SPONSOR: D. E. NELSON
A11: Residential Weather Adjustment (MWH)
G12: CDD Model | I12: CDD Model Scaler | Z12: CDD MWH
A13: Line | C13: Year | E13: Month | G13: Coefficient | I13: CoolIndex | K13: CoolUse | M13: Customer | O13: Total GSL | P13: CDD Coefficient | R13: Actual CDD | T13: Normal CDD | V13: Total GPL | X13: CDD Deviation | Z13: Adjustment
G14: (a) | I14: (b) | K14: (c) | M14: (d) | P14: (e) = (a*b*c*d)/1000 | R14: (f) | T14: (g) | X14: (h)=g-f | Z14: (i)=e*h
A16: 1 | C16: =+'Weather Adjustment'!C16 -> 2024 | E16: =+'Weather Adjustment'!E16 -> 1 | G16: =+'[2]RES Model'!$C$18 -> 2.164 | I16: 0.79 | K16: 1.04 | M16: =+'Weather Adjustment'!G35 -> 3396604 | O16: =SUM(K16,M16) -> 3396605 | P16: =PRODUCT(G16,I16,K16,M16)/1000 -> 6038.9663 | R16: =+[3]RES!D13 -> 0.50931182 | T16: =+[3]RES!F13 -> 2.4932806 | V16: =SUM(R16,T16) -> 3.0025924 | X16: =+T16-R16 -> 1.9839688 | Z16: =+P16*X16 -> 11981.121
A17: =+A16+1 -> 2 | C17: =+'Weather Adjustment'!C17 -> 2024 | E17: =+'Weather Adjustment'!E17 -> 2 | G17: =+G16 -> 2.164 | I17: 0.79 | K17: 1.04 | M17: =+'Weather Adjustment'!G36 -> 3401024 | O17: =SUM(K17,M17) -> 3401025 | P17: =PRODUCT(G17,I17,K17,M17)/1000 -> 6046.8248 | R17: =+[3]RES!D14 -> 0.071189207 | T17: =+[3]RES!F14 -> 1.5673923 | V17: =SUM(R17,T17) -> 1.6385815 | X17: =+T17-R17 -> 1.4962031 | Z17: =+P17*X17 -> 9047.2779
A18: =+A17+1 -> 3 | C18: =+'Weather Adjustment'!C18 -> 2024 | E18: =+'Weather Adjustment'!E18 -> 3 | G18: =+G17 -> 2.164 | I18: 0.79 | K18: 1.05 | M18: =+'Weather Adjustment'!G37 -> 3407140 | O18: =SUM(K18,M18) -> 3407141 | P18: =PRODUCT(G18,I18,K18,M18)/1000 -> 6115.9458 | R18: =+[3]RES!D15 -> 14.582078 | T18: =+[3]RES!F15 -> 6.3552179 | V18: =SUM(R18,T18) -> 20.937296 | X18: =+T18-R18 -> -8.2268605 | Z18: =+P18*X18 -> -50315.032
A19: =+A18+1 -> 4 | C19: =+'Weather Adjustment'!C19 -> 2024 | E19: =+'Weather Adjustment'!E19 -> 4 | G19: =+G18 -> 2.164 | I19: 0.79 | K19: 1.04 | M19: =+'Weather Adjustment'!G38 -> 3413927 | O19: =SUM(K19,M19) -> 3413928 | P19: =PRODUCT(G19,I19,K19,M19)/1000 -> 6069.7656 | R19: =+[3]RES!D16 -> 23.336796 | T19: =+[3]RES!F16 -> 25.375167 | V19: =SUM(R19,T19) -> 48.711963 | X19: =+T19-R19 -> 2.0383717 | Z19: =+P19*X19 -> 12372.438
A20: =+A19+1 -> 5 | C20: =+'Weather Adjustment'!C20 -> 2024 | E20: =+'Weather Adjustment'!E20 -> 5 | G20: =+G19 -> 2.164 | I20: 0.79 | K20: 1.04 | M20: =+'Weather Adjustment'!G39 -> 3421241 | O20: =SUM(K20,M20) -> 3421242 | P20: =PRODUCT(G20,I20,K20,M20)/1000 -> 6082.7694 | R20: =+[3]RES!D17 -> 87.833335 | T20: =+[3]RES!F17 -> 71.734338 | V20: =SUM(R20,T20) -> 159.56767 | X20: =+T20-R20 -> -16.098997 | Z20: =+P20*X20 -> -97926.488
A21: =+A20+1 -> 6 | C21: =+'Weather Adjustment'!C21 -> 2024 | E21: =+'Weather Adjustment'!E21 -> 6 | G21: =+G20 -> 2.164 | I21: 0.79 | K21: 1.04 | M21: =+'Weather Adjustment'!G40 -> 3425884 | O21: =SUM(K21,M21) -> 3425885 | P21: =PRODUCT(G21,I21,K21,M21)/1000 -> 6091.0244 | R21: =+[3]RES!D18 -> 238.2623 | T21: =+[3]RES!F18 -> 214.65969 | V21: =SUM(R21,T21) -> 452.92199 | X21: =+T21-R21 -> -23.602611 | Z21: =+P21*X21 -> -143764.08
A22: =+A21+1 -> 7 | C22: =+'Weather Adjustment'!C22 -> 2024 | E22: =+'Weather Adjustment'!E22 -> 7 | G22: =+G21 -> 2.164 | I22: 0.79 | K22: 1.05 | M22: =+'Weather Adjustment'!G41 -> 3432967 | O22: =SUM(K22,M22) -> 3432968 | P22: =PRODUCT(G22,I22,K22,M22)/1000 -> 6162.3062 | R22: =+[3]RES!D19 -> 413.76616 | T22: =+[3]RES!F19 -> 376.74149 | V22: =SUM(R22,T22) -> 790.50765 | X22: =+T22-R22 -> -37.024664 | Z22: =+P22*X22 -> -228157.32
A23: =+A22+1 -> 8 | C23: =+'Weather Adjustment'!C23 -> 2024 | E23: =+'Weather Adjustment'!E23 -> 8 | G23: =+G22 -> 2.164 | I23: 0.79 | K23: 1.05 | M23: =+'Weather Adjustment'!G42 -> 3439507 | O23: =SUM(K23,M23) -> 3439508 | P23: =PRODUCT(G23,I23,K23,M23)/1000 -> 6174.0458 | R23: =+[3]RES!D20 -> 407.79058 | T23: =+[3]RES!F20 -> 441.87555 | V23: =SUM(R23,T23) -> 849.66614 | X23: =+T23-R23 -> 34.08497 | Z23: =+P23*X23 -> 210442.16
A24: =+A23+1 -> 9 | C24: =+'Weather Adjustment'!C24 -> 2024 | E24: =+'Weather Adjustment'!E24 -> 9 | G24: =+G23 -> 2.164 | I24: 0.79 | K24: 1.05 | M24: =+'Weather Adjustment'!G43 -> 3444509 | O24: =SUM(K24,M24) -> 3444510 | P24: =PRODUCT(G24,I24,K24,M24)/1000 -> 6183.0245 | R24: =+[3]RES!D21 -> 427.48317 | T24: =+[3]RES!F21 -> 397.57148 | V24: =SUM(R24,T24) -> 825.05466 | X24: =+T24-R24 -> -29.911688 | Z24: =+P24*X24 -> -184944.7
A25: =+A24+1 -> 10 | C25: =+'Weather Adjustment'!C25 -> 2024 | E25: =+'Weather Adjustment'!E25 -> 10 | G25: =+G24 -> 2.164 | I25: 0.79 | K25: 1.05 | M25: =+'Weather Adjustment'!G44 -> 3450481 | O25: =SUM(K25,M25) -> 3450482 | P25: =PRODUCT(G25,I25,K25,M25)/1000 -> 6193.7445 | R25: =+[3]RES!D22 -> 239.2824 | T25: =+[3]RES!F22 -> 220.30252 | V25: =SUM(R25,T25) -> 459.58492 | X25: =+T25-R25 -> -18.97988 | Z25: =+P25*X25 -> -117556.53
A26: =+A25+1 -> 11 | C26: =+'Weather Adjustment'!C26 -> 2024 | E26: =+'Weather Adjustment'!E26 -> 11 | G26: =+G25 -> 2.164 | I26: 0.79 | K26: 1.04 | M26: =+'Weather Adjustment'!G45 -> 3456155 | O26: =SUM(K26,M26) -> 3456156 | P26: =PRODUCT(G26,I26,K26,M26)/1000 -> 6144.8445 | R26: =+[3]RES!D23 -> 119.20832 | T26: =+[3]RES!F23 -> 65.768035 | V26: =SUM(R26,T26) -> 184.97635 | X26: =+T26-R26 -> -53.440282 | Z26: =+P26*X26 -> -328382.22
A27: =+A26+1 -> 12 | C27: =+'Weather Adjustment'!C27 -> 2024 | E27: =+'Weather Adjustment'!E27 -> 12 | G27: =+G26 -> 2.164 | I27: 0.79 | K27: 1.04 | M27: =+'Weather Adjustment'!G46 -> 3462111 | O27: =SUM(K27,M27) -> 3462112 | P27: =PRODUCT(G27,I27,K27,M27)/1000 -> 6155.4339 | R27: =+[3]RES!D24 -> 14.298436 | T27: =+[3]RES!F24 -> 10.052167 | V27: =SUM(R27,T27) -> 24.350603 | X27: =+T27-R27 -> -4.2462698 | Z27: =+P27*X27 -> -26137.634
A28: =+A27+1 -> 13 | C28: Total | O28: =SUM(O22:O27) -> 20685736 | R28: =SUM(R16:R27) -> 1986.4241 | T28: =SUM(T16:T27) -> 1834.4963 | V28: =SUM(V22:V27) -> 3134.1403 | X28: =+T28-R28 -> -151.92774 | Z28: =SUM(Z16:Z27) -> -933341.01
A29: =+A28+1 -> 14
A30: =+A29+1 -> 15 | G30: HDD Model | I30: HDD Model Scaler | Z30: HDD MWH
A31: =+A30+1 -> 16 | C31: Year | E31: Month | G31: Coefficient | I31: HeatIndex | K31: HeatUse | M31: Customer | O31: Total GSL | P31: HDD Coefficient | R31: Actual HDD | T31: Normal HDD | V31: Total GPL | X31: HDD Deviation | Z31: Adjustment
A32: =+A31+1 -> 17 | G32: (j) | I32: (k) | K32: (l) | M32: (m) | P32: (n) = (j*k*l*m)/1000 | R32: (o) | T32: (p) | X32: (q)=p-o | Z32: (r)=n*q
A33: =+A32+1 -> 18
A34: =+A33+1 -> 19 | C34: =+C16 -> 2024 | E34: =+E16 -> 1 | G34: =+'[2]RES Model'!$C$17 -> 1.939 | I34: 0.99 | K34: 1.04 | M34: =M16 -> 3396604 | P34: =PRODUCT(G34,I34,K34,M34)/1000 -> 6780.9612 | R34: =+[3]RES!C13 -> 192.04714 | S34: =S16 -> 0 | T34: =+[3]RES!E13 -> 213.47102 | X34: =+T34-R34 -> 21.423883 | Z34: =+P34*X34 -> 145274.52
A35: =+A34+1 -> 20 | C35: =+C17 -> 2024 | E35: =+E17 -> 2 | G35: =+G34 -> 1.939 | I35: 0.99 | K35: 1.04 | M35: =M17 -> 3401024 | P35: =PRODUCT(G35,I35,K35,M35)/1000 -> 6789.7853 | R35: =+[3]RES!C14 -> 260.83933 | S35: =S17 -> 0 | T35: =+[3]RES!E14 -> 221.3909 | X35: =+T35-R35 -> -39.448432 | Z35: =+P35*X35 -> -267846.38
A36: =+A35+1 -> 21 | C36: =+C18 -> 2024 | E36: =+E18 -> 3 | G36: =+G35 -> 1.939 | I36: 0.99 | K36: 1.05 | M36: =M18 -> 3407140 | P36: =PRODUCT(G36,I36,K36,M36)/1000 -> 6867.399 | R36: =+[3]RES!C15 -> 65.576036 | S36: =S18 -> 0 | T36: =+[3]RES!E15 -> 149.60668 | X36: =+T36-R36 -> 84.030646 | Z36: =+P36*X36 -> 577071.98
A37: =+A36+1 -> 22 | C37: =+C19 -> 2024 | E37: =+E19 -> 4 | G37: =+G36 -> 1.939 | I37: 0.99 | K37: 1.04 | M37: =M19 -> 3413927 | P37: =PRODUCT(G37,I37,K37,M37)/1000 -> 6815.5447 | R37: =+[3]RES!C16 -> 25.940125 | S37: =S19 -> 0 | T37: =+[3]RES!E16 -> 45.106131 | X37: =+T37-R37 -> 19.166006 | Z37: =+P37*X37 -> 130626.77
A38: =+A37+1 -> 23 | C38: =+C20 -> 2024 | E38: =+E20 -> 5 | G38: =+G37 -> 1.939 | I38: 0.99 | K38: 1.04 | M38: =M20 -> 3421241 | P38: =PRODUCT(G38,I38,K38,M38)/1000 -> 6830.1464 | R38: =+[3]RES!C17 -> 4.9216689 | S38: =S20 -> 0 | T38: =+[3]RES!E17 -> 10.403559 | X38: =+T38-R38 -> 5.4818905 | Z38: =+P38*X38 -> 37442.115
A39: =+A38+1 -> 24 | C39: =+C21 -> 2024 | E39: =+E21 -> 6 | G39: =+G38 -> 1.939 | I39: 0.99 | K39: 1.04 | M39: =M21 -> 3425884 | P39: =PRODUCT(G39,I39,K39,M39)/1000 -> 6839.4156 | R39: =+[3]RES!C18 -> 0.005868752 | S39: =S21 -> 0 | T39: =+[3]RES!E18 -> 1.0969641 | X39: =+T39-R39 -> 1.0910953 | Z39: =+P39*X39 -> 7462.4543
A40: =+A39+1 -> 25 | C40: =+C22 -> 2024 | E40: =+E22 -> 7 | G40: =+G39 -> 1.939 | I40: 0.99 | K40: 1.05 | M40: =M22 -> 3432967 | P40: =PRODUCT(G40,I40,K40,M40)/1000 -> 6919.4557 | R40: =+[3]RES!C19 -> 0 | S40: =S22 -> 0 | T40: =+[3]RES!E19 -> 0.0087872204 | X40: =+T40-R40 -> 0.0087872204 | Z40: =+P40*X40 -> 60.802782
A41: =+A40+1 -> 26 | C41: =+C23 -> 2024 | E41: =+E23 -> 8 | G41: =+G40 -> 1.939 | I41: 0.99 | K41: 1.06 | M41: =M23 -> 3439507 | P41: =PRODUCT(G41,I41,K41,M41)/1000 -> 6998.6628 | R41: =+[3]RES!C20 -> 0 | S41: =S23 -> 0 | T41: =+[3]RES!E20 -> 0.00033797379 | X41: =+T41-R41 -> 0.00033797379 | Z41: =+P41*X41 -> 2.3653646
A42: =+A41+1 -> 27 | C42: =+C24 -> 2024 | E42: =+E24 -> 9 | G42: =+G41 -> 1.939 | I42: 0.99 | K42: 1.05 | M42: =M24 -> 3444509 | P42: =PRODUCT(G42,I42,K42,M42)/1000 -> 6942.7196 | R42: =+[3]RES!C21 -> 0 | S42: =S24 -> 0 | T42: =+[3]RES!E21 -> 0.035522034 | X42: =+T42-R42 -> 0.035522034 | Z42: =+P42*X42 -> 246.61952
A43: =+A42+1 -> 28 | C43: =+C25 -> 2024 | E43: =+E25 -> 10 | G43: =+G42 -> 1.939 | I43: 0.99 | K43: 1.05 | M43: =M25 -> 3450481 | P43: =PRODUCT(G43,I43,K43,M43)/1000 -> 6954.7567 | R43: =+[3]RES!C22 -> 0.16908013 | S43: =S25 -> 0 | T43: =+[3]RES!E22 -> 1.9478264 | X43: =+T43-R43 -> 1.7787463 | Z43: =+P43*X43 -> 12370.748
A44: =+A43+1 -> 29 | C44: =+C26 -> 2024 | E44: =+E26 -> 11 | G44: =+G43 -> 1.939 | I44: 0.99 | K44: 1.04 | M44: =M26 -> 3456155 | P44: =PRODUCT(G44,I44,K44,M44)/1000 -> 6899.8485 | R44: =+[3]RES!C23 -> 2.4301902 | S44: =S26 -> 0 | T44: =+[3]RES!E23 -> 27.452626 | X44: =+T44-R44 -> 25.022436 | Z44: =+P44*X44 -> 172651.01
...

Sheet ResidentialT
AB1: =+'Weather Adjustment'!AA1 -> WP/II-H-1.2/1
AB2: Page 3 of 9
A4: =+'Weather Adjustment'!A4 -> PUC DOCKET NO
A5: =+'Weather Adjustment'!A5 -> ONCOR ELECTRIC DELIVERY COMPANY LLC
A6: =+'Weather Adjustment'!A6 -> MONTHLY SALES DATA
A7: ='Weather Adjustment'!A7 -> TEST YEAR ENDING December 31, 2024
A9: =+'Weather Adjustment'!A9 -> SPONSOR: D. E. NELSON
A11: Residential Weather Adjustment (MWH)
G12: CDD Model | K12: CDD Model Scaler | AB12: CDD MWH
A13: Line | C13: Year | E13: Month | G13: Coefficient | I13: Trend | K13: CoolIndex | M13: CoolUse | O13: Customer | Q13: Total GSL | R13: CDD Coefficient | T13: Actual CDD | V13: Normal CDD | X13: Total GPL | Z13: CDD Deviation | AB13: Adjustment
G14: (a) | I14: (a) | K14: (b) | M14: (c) | O14: (d) | R14: (e) = (a*b*c*d)/1000 | T14: (f) | V14: (g) | Z14: (h)=g-f | AB14: (i)=e*h
A16: 1 | C16: =+'Weather Adjustment'!C16 -> 2024 | E16: =+'Weather Adjustment'!E16 -> 1 | G16: =+'[2]RES Model'!$C$33 -> 0.006 | I16: 19 | K16: =Residential!I16 -> 0.79 | M16: =Residential!K16 -> 1.04 | O16: =+Residential!M16 -> 3396604 | Q16: =SUM(M16,O16) -> 3396605 | R16: =PRODUCT(G16,I16,K16,M16,O16)/1000 -> 318.13408 | T16: =Residential!R16 -> 0.50931182 | V16: =Residential!T16 -> 2.4932806 | X16: =SUM(T16,V16) -> 3.0025924 | Z16: =+V16-T16 -> 1.9839688 | AB16: =+R16*Z16 -> 631.1681
A17: =+A16+1 -> 2 | C17: =+'Weather Adjustment'!C17 -> 2024 | E17: =+'Weather Adjustment'!E17 -> 2 | G17: =+'[2]RES Model'!$C$33 -> 0.006 | I17: 19 | K17: =Residential!I17 -> 0.79 | M17: =Residential!K17 -> 1.04 | O17: =+Residential!M17 -> 3401024 | Q17: =SUM(M17,O17) -> 3401025 | R17: =PRODUCT(G17,I17,K17,M17,O17)/1000 -> 318.54807 | T17: =Residential!R17 -> 0.071189207 | V17: =Residential!T17 -> 1.5673923 | X17: =SUM(T17,V17) -> 1.6385815 | Z17: =+V17-T17 -> 1.4962031 | AB17: =+R17*Z17 -> 476.61261
A18: =+A17+1 -> 3 | C18: =+'Weather Adjustment'!C18 -> 2024 | E18: =+'Weather Adjustment'!E18 -> 3 | G18: =+'[2]RES Model'!$C$33 -> 0.006 | I18: 19 | K18: =Residential!I18 -> 0.79 | M18: =Residential!K18 -> 1.05 | O18: =+Residential!M18 -> 3407140 | Q18: =SUM(M18,O18) -> 3407141 | R18: =PRODUCT(G18,I18,K18,M18,O18)/1000 -> 322.18938 | T18: =Residential!R18 -> 14.582078 | V18: =Residential!T18 -> 6.3552179 | X18: =SUM(T18,V18) -> 20.937296 | Z18: =+V18-T18 -> -8.2268605 | AB18: =+R18*Z18 -> -2650.6071
A19: =+A18+1 -> 4 | C19: =+'Weather Adjustment'!C19 -> 2024 | E19: =+'Weather Adjustment'!E19 -> 4 | G19: =+'[2]RES Model'!$C$33 -> 0.006 | I19: 19 | K19: =Residential!I19 -> 0.79 | M19: =Residential!K19 -> 1.04 | O19: =+Residential!M19 -> 3413927 | Q19: =SUM(M19,O19) -> 3413928 | R19: =PRODUCT(G19,I19,K19,M19,O19)/1000 -> 319.7566 | T19: =Residential!R19 -> 23.336796 | V19: =Residential!T19 -> 25.375167 | X19: =SUM(T19,V19) -> 48.711963 | Z19: =+V19-T19 -> 2.0383717 | AB19: =+R19*Z19 -> 651.7828
A20: =+A19+1 -> 5 | C20: =+'Weather Adjustment'!C20 -> 2024 | E20: =+'Weather Adjustment'!E20 -> 5 | G20: =+'[2]RES Model'!$C$33 -> 0.006 | I20: 19 | K20: =Residential!I20 -> 0.79 | M20: =Residential!K20 -> 1.04 | O20: =+Residential!M20 -> 3421241 | Q20: =SUM(M20,O20) -> 3421242 | R20: =PRODUCT(G20,I20,K20,M20,O20)/1000 -> 320.44164 | T20: =Residential!R20 -> 87.833335 | V20: =Residential!T20 -> 71.734338 | X20: =SUM(T20,V20) -> 159.56767 | Z20: =+V20-T20 -> -16.098997 | AB20: =+R20*Z20 -> -5158.7891
A21: =+A20+1 -> 6 | C21: =+'Weather Adjustment'!C21 -> 2024 | E21: =+'Weather Adjustment'!E21 -> 6 | G21: =+'[2]RES Model'!$C$33 -> 0.006 | I21: 19 | K21: =Residential!I21 -> 0.79 | M21: =Residential!K21 -> 1.04 | O21: =+Residential!M21 -> 3425884 | Q21: =SUM(M21,O21) -> 3425885 | R21: =PRODUCT(G21,I21,K21,M21,O21)/1000 -> 320.87652 | T21: =Residential!R21 -> 238.2623 | V21: =Residential!T21 -> 214.65969 | X21: =SUM(T21,V21) -> 452.92199 | Z21: =+V21-T21 -> -23.602611 | AB21: =+R21*Z21 -> -7573.5236
A22: =+A21+1 -> 7 | C22: =+'Weather Adjustment'!C22 -> 2024 | E22: =+'Weather Adjustment'!E22 -> 7 | G22: =+'[2]RES Model'!$C$33 -> 0.006 | I22: 19 | K22: =Residential!I22 -> 0.79 | M22: =Residential!K22 -> 1.05 | O22: =+Residential!M22 -> 3432967 | Q22: =SUM(M22,O22) -> 3432968 | R22: =PRODUCT(G22,I22,K22,M22,O22)/1000 -> 324.63166 | T22: =Residential!R22 -> 413.76616 | V22: =Residential!T22 -> 376.74149 | X22: =SUM(T22,V22) -> 790.50765 | Z22: =+V22-T22 -> -37.024664 | AB22: =+R22*Z22 -> -12019.378
A23: =+A22+1 -> 8 | C23: =+'Weather Adjustment'!C23 -> 2024 | E23: =+'Weather Adjustment'!E23 -> 8 | G23: =+'[2]RES Model'!$C$33 -> 0.006 | I23: 19 | K23: =Residential!I23 -> 0.79 | M23: =Residential!K23 -> 1.05 | O23: =+Residential!M23 -> 3439507 | Q23: =SUM(M23,O23) -> 3439508 | R23: =PRODUCT(G23,I23,K23,M23,O23)/1000 -> 325.2501 | T23: =Residential!R23 -> 407.79058 | V23: =Residential!T23 -> 441.87555 | X23: =SUM(T23,V23) -> 849.66614 | Z23: =+V23-T23 -> 34.08497 | AB23: =+R23*Z23 -> 11086.14
A24: =+A23+1 -> 9 | C24: =+'Weather Adjustment'!C24 -> 2024 | E24: =+'Weather Adjustment'!E24 -> 9 | G24: =+'[2]RES Model'!$C$33 -> 0.006 | I24: 19 | K24: =Residential!I24 -> 0.79 | M24: =Residential!K24 -> 1.05 | O24: =+Residential!M24 -> 3444509 | Q24: =SUM(M24,O24) -> 3444510 | R24: =PRODUCT(G24,I24,K24,M24,O24)/1000 -> 325.7231 | T24: =Residential!R24 -> 427.48317 | V24: =Residential!T24 -> 397.57148 | X24: =SUM(T24,V24) -> 825.05466 | Z24: =+V24-T24 -> -29.911688 | AB24: =+R24*Z24 -> -9742.9279
A25: =+A24+1 -> 10 | C25: =+'Weather Adjustment'!C25 -> 2024 | E25: =+'Weather Adjustment'!E25 -> 10 | G25: =+'[2]RES Model'!$C$33 -> 0.006 | I25: 19 | K25: =Residential!I25 -> 0.79 | M25: =Residential!K25 -> 1.05 | O25: =+Residential!M25 -> 3450481 | Q25: =SUM(M25,O25) -> 3450482 | R25: =PRODUCT(G25,I25,K25,M25,O25)/1000 -> 326.28783 | T25: =Residential!R25 -> 239.2824 | V25: =Residential!T25 -> 220.30252 | X25: =SUM(T25,V25) -> 459.58492 | Z25: =+V25-T25 -> -18.97988 | AB25: =+R25*Z25 -> -6192.904
A26: =+A25+1 -> 11 | C26: =+'Weather Adjustment'!C26 -> 2024 | E26: =+'Weather Adjustment'!E26 -> 11 | G26: =+'[2]RES Model'!$C$33 -> 0.006 | I26: 19 | K26: =Residential!I26 -> 0.79 | M26: =Residential!K26 -> 1.04 | O26: =+Residential!M26 -> 3456155 | Q26: =SUM(M26,O26) -> 3456156 | R26: =PRODUCT(G26,I26,K26,M26,O26)/1000 -> 323.71177 | T26: =Residential!R26 -> 119.20832 | V26: =Residential!T26 -> 65.768035 | X26: =SUM(T26,V26) -> 184.97635 | Z26: =+V26-T26 -> -53.440282 | AB26: =+R26*Z26 -> -17299.248
A27: =+A26+1 -> 12 | C27: =+'Weather Adjustment'!C27 -> 2024 | E27: =+'Weather Adjustment'!E27 -> 12 | G27: =+'[2]RES Model'!$C$33 -> 0.006 | I27: 19 | K27: =Residential!I27 -> 0.79 | M27: =Residential!K27 -> 1.04 | O27: =+Residential!M27 -> 3462111 | Q27: =SUM(M27,O27) -> 3462112 | R27: =PRODUCT(G27,I27,K27,M27,O27)/1000 -> 324.26963 | T27: =Residential!R27 -> 14.298436 | V27: =Residential!T27 -> 10.052167 | X27: =SUM(T27,V27) -> 24.350603 | Z27: =+V27-T27 -> -4.2462698 | AB27: =+R27*Z27 -> -1376.9363
A28: =+A27+1 -> 13 | C28: Total | Q28: =SUM(Q22:Q27) -> 20685736 | T28: =SUM(T16:T27) -> 1986.4241 | V28: =SUM(V16:V27) -> 1834.4963 | X28: =SUM(X22:X27) -> 3134.1403 | Z28: =+V28-T28 -> -151.92774 | AB28: =SUM(AB16:AB27) -> -49168.611
A29: =+A28+1 -> 14
A30: =+A29+1 -> 15 | G30: HDD Model | K30: HDD Model Scaler | AB30: HDD MWH
A31: =+A30+1 -> 16 | C31: Year | E31: Month | G31: Coefficient | K31: HeatIndex | M31: HeatUse | O31: Customer | Q31: Total GSL | R31: HDD Coefficient | T31: Actual HDD | V31: Normal HDD | X31: Total GPL | Z31: HDD Deviation | AB31: Adjustment
A32: =+A31+1 -> 17 | G32: (j) | K32: (k) | M32: (l) | O32: (m) | R32: (n) = (j*k*l*m)/1000 | T32: (o) | V32: (p) | Z32: (q)=p-o | AB32: (r)=n*q
A33: =+A32+1 -> 18
A34: =+A33+1 -> 19 | C34: =+C16 -> 2024 | E34: =+E16 -> 1 | G34: =+'[2]RES Model'!$C$32 -> 0.007 | I34: 19 | K34: =Residential!I34 -> 0.99 | M34: =Residential!K34 -> 1.04 | O34: =O16 -> 3396604 | R34: =PRODUCT(G34,I34,K34,M34,O34)/1000 -> 465.12008 | T34: =Residential!R34 -> 192.04714 | U34: =U16 -> 0 | V34: =Residential!T34 -> 213.47102 | Z34: =+V34-T34 -> 21.423883 | AB34: =+R34*Z34 -> 9964.6781
A35: =+A34+1 -> 20 | C35: =+C17 -> 2024 | E35: =+E17 -> 2 | G35: =+'[2]RES Model'!$C$32 -> 0.007 | I35: 19 | K35: =Residential!I35 -> 0.99 | M35: =Residential!K35 -> 1.04 | O35: =O17 -> 3401024 | R35: =PRODUCT(G35,I35,K35,M35,O35)/1000 -> 465.72534 | T35: =Residential!R35 -> 260.83933 | U35: =U17 -> 0 | V35: =Residential!T35 -> 221.3909 | Z35: =+V35-T35 -> -39.448432 | AB35: =+R35*Z35 -> -18372.134
A36: =+A35+1 -> 21 | C36: =+C18 -> 2024 | E36: =+E18 -> 3 | G36: =+'[2]RES Model'!$C$32 -> 0.007 | I36: 19 | K36: =Residential!I36 -> 0.99 | M36: =Residential!K36 -> 1.05 | O36: =O18 -> 3407140 | R36: =PRODUCT(G36,I36,K36,M36,O36)/1000 -> 471.04903 | T36: =Residential!R36 -> 65.576036 | U36: =U18 -> 0 | V36: =Residential!T36 -> 149.60668 | Z36: =+V36-T36 -> 84.030646 | AB36: =+R36*Z36 -> 39582.554
A37: =+A36+1 -> 22 | C37: =+C19 -> 2024 | E37: =+E19 -> 4 | G37: =+'[2]RES Model'!$C$32 -> 0.007 | I37: 19 | K37: =Residential!I37 -> 0.99 | M37: =Residential!K37 -> 1.04 | O37: =O19 -> 3413927 | R37: =PRODUCT(G37,I37,K37,M37,O37)/1000 -> 467.49224 | T37: =Residential!R37 -> 25.940125 | U37: =U19 -> 0 | V37: =Residential!T37 -> 45.106131 | Z37: =+V37-T37 -> 19.166006 | AB37: =+R37*Z37 -> 8959.9591
A38: =+A37+1 -> 23 | C38: =+C20 -> 2024 | E38: =+E20 -> 5 | G38: =+'[2]RES Model'!$C$32 -> 0.007 | I38: 19 | K38: =Residential!I38 -> 0.99 | M38: =Residential!K38 -> 1.04 | O38: =O20 -> 3421241 | R38: =PRODUCT(G38,I38,K38,M38,O38)/1000 -> 468.49379 | T38: =Residential!R38 -> 4.9216689 | U38: =U20 -> 0 | V38: =Residential!T38 -> 10.403559 | Z38: =+V38-T38 -> 5.4818905 | AB38: =+R38*Z38 -> 2568.2317
A39: =+A38+1 -> 24 | C39: =+C21 -> 2024 | E39: =+E21 -> 6 | G39: =+'[2]RES Model'!$C$32 -> 0.007 | I39: 19 | K39: =Residential!I39 -> 0.99 | M39: =Residential!K39 -> 1.04 | O39: =O21 -> 3425884 | R39: =PRODUCT(G39,I39,K39,M39,O39)/1000 -> 469.12959 | T39: =Residential!R39 -> 0.005868752 | U39: =U21 -> 0 | V39: =Residential!T39 -> 1.0969641 | Z39: =+V39-T39 -> 1.0910953 | AB39: =+R39*Z39 -> 511.86509
A40: =+A39+1 -> 25 | C40: =+C22 -> 2024 | E40: =+E22 -> 7 | G40: =+'[2]RES Model'!$C$32 -> 0.007 | I40: 19 | K40: =Residential!I40 -> 0.99 | M40: =Residential!K40 -> 1.05 | O40: =O22 -> 3432967 | R40: =PRODUCT(G40,I40,K40,M40,O40)/1000 -> 474.6197 | T40: =Residential!R40 -> 0 | U40: =U22 -> 0 | V40: =Residential!T40 -> 0.0087872204 | Z40: =+V40-T40 -> 0.0087872204 | AB40: =+R40*Z40 -> 4.1705879
A41: =+A40+1 -> 26 | C41: =+C23 -> 2024 | E41: =+E23 -> 8 | G41: =+'[2]RES Model'!$C$32 -> 0.007 | I41: 19 | K41: =Residential!I41 -> 0.99 | M41: =Residential!K41 -> 1.06 | O41: =O23 -> 3439507 | R41: =PRODUCT(G41,I41,K41,M41,O41)/1000 -> 480.05268 | T41: =Residential!R41 -> 0 | U41: =U23 -> 0 | V41: =Residential!T41 -> 0.00033797379 | Z41: =+V41-T41 -> 0.00033797379 | AB41: =+R41*Z41 -> 0.16224522
A42: =+A41+1 -> 27 | C42: =+C24 -> 2024 | E42: =+E24 -> 9 | G42: =+'[2]RES Model'!$C$32 -> 0.007 | I42: 19 | K42: =Residential!I42 -> 0.99 | M42: =Residential!K42 -> 1.05 | O42: =O24 -> 3444509 | R42: =PRODUCT(G42,I42,K42,M42,O42)/1000 -> 476.21543 | T42: =Residential!R42 -> 0 | U42: =U24 -> 0 | V42: =Residential!T42 -> 0.035522034 | Z42: =+V42-T42 -> 0.035522034 | AB42: =+R42*Z42 -> 16.91614
A43: =+A42+1 -> 28 | C43: =+C25 -> 2024 | E43: =+E25 -> 10 | G43: =+'[2]RES Model'!$C$32 -> 0.007 | I43: 19 | K43: =Residential!I43 -> 0.99 | M43: =Residential!K43 -> 1.05 | O43: =O25 -> 3450481 | R43: =PRODUCT(G43,I43,K43,M43,O43)/1000 -> 477.04107 | T43: =Residential!R43 -> 0.16908013 | U43: =U25 -> 0 | V43: =Residential!T43 -> 1.9478264 | Z43: =+V43-T43 -> 1.7787463 | AB43: =+R43*Z43 -> 848.53505
A44: =+A43+1 -> 29 | C44: =+C26 -> 2024 | E44: =+E26 -> 11 | G44: =+'[2]RES Model'!$C$32 -> 0.007 | I44: 19 | K44: =Residential!I44 -> 0.99 | M44: =Residential!K44 -> 1.04 | O44: =O26 -> 3456155 | R44: =PRODUCT(G44,I44,K44,M44,O44)/1000 -> 473.27481 | T44: =Residential!R44 -> 2.4301902 | U44: =U26 -> 0 | V44: =Residential!T44 -> 27.452626 | Z44: =+V44-T44 -> 25.022436 | AB44: =+R44*Z44 -> 11842.488
...

Sheet SecLE10
W1: WP/II-H-1.2/1
W2: Page 4 of 9
A4: =+'Weather Adjustment'!A4 -> PUC DOCKET NO
A5: =+'Weather Adjustment'!A5 -> ONCOR ELECTRIC DELIVERY COMPANY LLC
A6: =+'Weather Adjustment'!A6 -> MONTHLY SALES DATA
A7: =+'Weather Adjustment'!A7 -> TEST YEAR ENDING December 31, 2024
A9: =+'Weather Adjustment'!A9 -> SPONSOR: D. E. NELSON
A11: Secondary Service Less Than or Equal to 10 KW Weather Adjustment (MWH)
G12: CDD Model | W12: CDD MWH
A13: Line | C13: Year | E13: Month | G13: Coefficient | J13: Customer | L13: Total GSL | M13: CDD Coefficient | O13: Actual CDD | Q13: Normal CDD | S13: Total GPL | U13: CDD Deviation | W13: Adjustment
A14: No. | G14: (a) | J14: (b) | M14: (c) = (a*b)/1000 | O14: (d) | Q14: (e) | U14: (f)=e-d | W14: (g)=c*f
A16: 1 | C16: =+'Weather Adjustment'!C16 -> 2024 | E16: =+'Weather Adjustment'!E16 -> 1 | G16: =+'[2]SECLE10KW Model'!$C$18 -> 0.318 | J16: =+'Weather Adjustment'!I35 -> 284930 | L16: =SUM(#REF!,J16) -> #REF! | M16: =PRODUCT(G16,J16)/1000 -> 90.60774 | O16: =+[3]SECLE10KW!D13 -> 0.45216727 | Q16: =+[3]SECLE10KW!F13 -> 2.2527213 | S16: =SUM(O16,Q16) -> 2.7048886 | U16: =+Q16-O16 -> 1.800554 | W16: =+M16*U16 -> 163.14413
A17: =+A16+1 -> 2 | C17: =+'Weather Adjustment'!C17 -> 2024 | E17: =+'Weather Adjustment'!E17 -> 2 | G17: =+G16 -> 0.318 | J17: =+'Weather Adjustment'!I36 -> 282336 | L17: =SUM(#REF!,J17) -> #REF! | M17: =PRODUCT(G17,J17)/1000 -> 89.782848 | O17: =+[3]SECLE10KW!D14 -> 0.070489242 | Q17: =+[3]SECLE10KW!F14 -> 1.4051948 | S17: =SUM(O17,Q17) -> 1.475684 | U17: =+Q17-O17 -> 1.3347055 | W17: =+M17*U17 -> 119.83366
A18: =+A17+1 -> 3 | C18: =+'Weather Adjustment'!C18 -> 2024 | E18: =+'Weather Adjustment'!E18 -> 3 | G18: =+G17 -> 0.318 | J18: =+'Weather Adjustment'!I37 -> 283192 | L18: =SUM(#REF!,J18) -> #REF! | M18: =PRODUCT(G18,J18)/1000 -> 90.055056 | O18: =+[3]SECLE10KW!D15 -> 13.519447 | Q18: =+[3]SECLE10KW!F15 -> 5.9059238 | S18: =SUM(O18,Q18) -> 19.425371 | U18: =+Q18-O18 -> -7.6135229 | W18: =+M18*U18 -> -685.63623
A19: =+A18+1 -> 4 | C19: =+'Weather Adjustment'!C19 -> 2024 | E19: =+'Weather Adjustment'!E19 -> 4 | G19: =+G18 -> 0.318 | J19: =+'Weather Adjustment'!I38 -> 283989 | L19: =SUM(#REF!,J19) -> #REF! | M19: =PRODUCT(G19,J19)/1000 -> 90.308502 | O19: =+[3]SECLE10KW!D16 -> 22.347901 | Q19: =+[3]SECLE10KW!F16 -> 24.813946 | S19: =SUM(O19,Q19) -> 47.161847 | U19: =+Q19-O19 -> 2.4660452 | W19: =+M19*U19 -> 222.70485
A20: =+A19+1 -> 5 | C20: =+'Weather Adjustment'!C20 -> 2024 | E20: =+'Weather Adjustment'!E20 -> 5 | G20: =+G19 -> 0.318 | J20: =+'Weather Adjustment'!I39 -> 284452 | L20: =SUM(#REF!,J20) -> #REF! | M20: =PRODUCT(G20,J20)/1000 -> 90.455736 | O20: =+[3]SECLE10KW!D17 -> 87.941602 | Q20: =+[3]SECLE10KW!F17 -> 72.778808 | S20: =SUM(O20,Q20) -> 160.72041 | U20: =+Q20-O20 -> -15.162794 | W20: =+M20*U20 -> -1371.5617
A21: =+A20+1 -> 6 | C21: =+'Weather Adjustment'!C21 -> 2024 | E21: =+'Weather Adjustment'!E21 -> 6 | G21: =+G20 -> 0.318 | J21: =+'Weather Adjustment'!I40 -> 284068 | L21: =SUM(#REF!,J21) -> #REF! | M21: =PRODUCT(G21,J21)/1000 -> 90.333624 | O21: =+[3]SECLE10KW!D18 -> 245.16695 | Q21: =+[3]SECLE10KW!F18 -> 218.87911 | S21: =SUM(O21,Q21) -> 464.04606 | U21: =+Q21-O21 -> -26.28784 | W21: =+M21*U21 -> -2374.6758
A22: =+A21+1 -> 7 | C22: =+'Weather Adjustment'!C22 -> 2024 | E22: =+'Weather Adjustment'!E22 -> 7 | G22: =+G21 -> 0.318 | J22: =+'Weather Adjustment'!I41 -> 284074 | L22: =SUM(#REF!,J22) -> #REF! | M22: =PRODUCT(G22,J22)/1000 -> 90.335532 | O22: =+[3]SECLE10KW!D19 -> 419.56965 | Q22: =+[3]SECLE10KW!F19 -> 381.68579 | S22: =SUM(O22,Q22) -> 801.25543 | U22: =+Q22-O22 -> -37.883859 | W22: =+M22*U22 -> -3422.2586
A23: =+A22+1 -> 8 | C23: =+'Weather Adjustment'!C23 -> 2024 | E23: =+'Weather Adjustment'!E23 -> 8 | G23: =+G22 -> 0.318 | J23: =+'Weather Adjustment'!I42 -> 284801 | L23: =SUM(#REF!,J23) -> #REF! | M23: =PRODUCT(G23,J23)/1000 -> 90.566718 | O23: =+[3]SECLE10KW!D20 -> 413.22416 | Q23: =+[3]SECLE10KW!F20 -> 443.70545 | S23: =SUM(O23,Q23) -> 856.92961 | U23: =+Q23-O23 -> 30.481286 | W23: =+M23*U23 -> 2760.5901
A24: =+A23+1 -> 9 | C24: =+'Weather Adjustment'!C24 -> 2024 | E24: =+'Weather Adjustment'!E24 -> 9 | G24: =+G23 -> 0.318 | J24: =+'Weather Adjustment'!I43 -> 285728 | L24: =SUM(#REF!,J24) -> #REF! | M24: =PRODUCT(G24,J24)/1000 -> 90.861504 | O24: =+[3]SECLE10KW!D21 -> 430.61029 | Q24: =+[3]SECLE10KW!F21 -> 396.93673 | S24: =SUM(O24,Q24) -> 827.54702 | U24: =+Q24-O24 -> -33.673566 | W24: =+M24*U24 -> -3059.6309
A25: =+A24+1 -> 10 | C25: =+'Weather Adjustment'!C25 -> 2024 | E25: =+'Weather Adjustment'!E25 -> 10 | G25: =+G24 -> 0.318 | J25: =+'Weather Adjustment'!I44 -> 286930 | L25: =SUM(#REF!,J25) -> #REF! | M25: =PRODUCT(G25,J25)/1000 -> 91.24374 | O25: =+[3]SECLE10KW!D22 -> 235.33203 | Q25: =+[3]SECLE10KW!F22 -> 218.36059 | S25: =SUM(O25,Q25) -> 453.69261 | U25: =+Q25-O25 -> -16.971442 | W25: =+M25*U25 -> -1548.5379
A26: =+A25+1 -> 11 | C26: =+'Weather Adjustment'!C26 -> 2024 | E26: =+'Weather Adjustment'!E26 -> 11 | G26: =+G25 -> 0.318 | J26: =+'Weather Adjustment'!I45 -> 287446 | L26: =SUM(#REF!,J26) -> #REF! | M26: =PRODUCT(G26,J26)/1000 -> 91.407828 | O26: =+[3]SECLE10KW!D23 -> 116.06745 | Q26: =+[3]SECLE10KW!F23 -> 63.917958 | S26: =SUM(O26,Q26) -> 179.98541 | U26: =+Q26-O26 -> -52.149496 | W26: =+M26*U26 -> -4766.8721
A27: =+A26+1 -> 12 | C27: =+'Weather Adjustment'!C27 -> 2024 | E27: =+'Weather Adjustment'!E27 -> 12 | G27: =+G26 -> 0.318 | J27: =+'Weather Adjustment'!I46 -> 287174 | L27: =SUM(#REF!,J27) -> #REF! | M27: =PRODUCT(G27,J27)/1000 -> 91.321332 | O27: =+[3]SECLE10KW!D24 -> 13.342508 | Q27: =+[3]SECLE10KW!F24 -> 9.3192345 | S27: =SUM(O27,Q27) -> 22.661742 | U27: =+Q27-O27 -> -4.0232734 | W27: =+M27*U27 -> -367.41069
A28: =+A27+1 -> 13 | C28: Total | L28: =SUM(L22:L27) -> #REF! | O28: =SUM(O16:O27) -> 1997.6446 | Q28: =SUM(Q16:Q27) -> 1839.9614 | S28: =SUM(S22:S27) -> 3142.0718 | U28: =+Q28-O28 -> -157.6832 | W28: =SUM(W16:W27) -> -14330.311
A29: =+A28+1 -> 14
A30: =+A29+1 -> 15 | G30: HDD Model | W30: HDD MWH
A31: =+A30+1 -> 16 | C31: Year | E31: Month | G31: Coefficient | J31: Customer | L31: Total GSL | M31: HDD Coefficient | O31: Actual HDD | Q31: Normal HDD | S31: Total GPL | U31: HDD Deviation | W31: Adjustment
A32: =+A31+1 -> 17 | G32: (h) | J32: (i) | M32: (j) = (h*i)/1000 | O32: (k) | Q32: (l) | U32: (m)=l-k | W32: (n)=j*m
A33: =+A32+1 -> 18
A34: =+A33+1 -> 19 | C34: =+C16 -> 2024 | E34: =+E16 -> 1 | G34: =+'[2]SECLE10KW Model'!$C$17 -> 0.368 | J34: =J16 -> 284930 | M34: =PRODUCT(G34,J34)/1000 -> 104.85424 | O34: =+[3]SECLE10KW!C13 -> 184.63353 | Q34: =+[3]SECLE10KW!E13 -> 225.91363 | U34: =+Q34-O34 -> 41.280101 | W34: =+M34*U34 -> 4328.3936
A35: =+A34+1 -> 20 | C35: =+C17 -> 2024 | E35: =+E17 -> 2 | G35: =+G34 -> 0.368 | J35: =J17 -> 282336 | M35: =PRODUCT(G35,J35)/1000 -> 103.89965 | O35: =+[3]SECLE10KW!C14 -> 220.18738 | Q35: =+[3]SECLE10KW!E14 -> 232.76225 | U35: =+Q35-O35 -> 12.574866 | W35: =+M35*U35 -> 1306.5242
A36: =+A35+1 -> 21 | C36: =+C18 -> 2024 | E36: =+E18 -> 3 | G36: =+G35 -> 0.368 | J36: =J18 -> 283192 | M36: =PRODUCT(G36,J36)/1000 -> 104.21466 | O36: =+[3]SECLE10KW!C15 -> 75.450549 | Q36: =+[3]SECLE10KW!E15 -> 158.52179 | U36: =+Q36-O36 -> 83.071241 | W36: =+M36*U36 -> 8657.2408
A37: =+A36+1 -> 22 | C37: =+C19 -> 2024 | E37: =+E19 -> 4 | G37: =+G36 -> 0.368 | J37: =J19 -> 283989 | M37: =PRODUCT(G37,J37)/1000 -> 104.50795 | O37: =+[3]SECLE10KW!C16 -> 37.755317 | Q37: =+[3]SECLE10KW!E16 -> 50.898509 | U37: =+Q37-O37 -> 13.143192 | W37: =+M37*U37 -> 1373.5681
A38: =+A37+1 -> 23 | C38: =+C20 -> 2024 | E38: =+E20 -> 5 | G38: =+G37 -> 0.368 | J38: =J20 -> 284452 | M38: =PRODUCT(G38,J38)/1000 -> 104.67834 | O38: =+[3]SECLE10KW!C17 -> 7.0957272 | Q38: =+[3]SECLE10KW!E17 -> 13.010937 | U38: =+Q38-O38 -> 5.9152095 | W38: =+M38*U38 -> 619.19429
A39: =+A38+1 -> 24 | C39: =+C21 -> 2024 | E39: =+E21 -> 6 | G39: =+G38 -> 0.368 | J39: =J21 -> 284068 | M39: =PRODUCT(G39,J39)/1000 -> 104.53702 | O39: =+[3]SECLE10KW!C18 -> 0.02147368 | Q39: =+[3]SECLE10KW!E18 -> 1.6240948 | U39: =+Q39-O39 -> 1.6026211 | W39: =+M39*U39 -> 167.53324
A40: =+A39+1 -> 25 | C40: =+C22 -> 2024 | E40: =+E22 -> 7 | G40: =+G39 -> 0.368 | J40: =J22 -> 284074 | M40: =PRODUCT(G40,J40)/1000 -> 104.53923 | O40: =+[3]SECLE10KW!C19 -> 0 | Q40: =+[3]SECLE10KW!E19 -> 0.018058367 | U40: =+Q40-O40 -> 0.018058367 | W40: =+M40*U40 -> 1.8878078
A41: =+A40+1 -> 26 | C41: =+C23 -> 2024 | E41: =+E23 -> 8 | G41: =+G40 -> 0.368 | J41: =J23 -> 284801 | M41: =PRODUCT(G41,J41)/1000 -> 104.80677 | O41: =+[3]SECLE10KW!C20 -> 0 | Q41: =+[3]SECLE10KW!E20 -> 0.001338283 | U41: =+Q41-O41 -> 0.001338283 | W41: =+M41*U41 -> 0.14026112
A42: =+A41+1 -> 27 | C42: =+C24 -> 2024 | E42: =+E24 -> 9 | G42: =+G41 -> 0.368 | J42: =J24 -> 285728 | M42: =PRODUCT(G42,J42)/1000 -> 105.1479 | O42: =+[3]SECLE10KW!C21 -> 0 | Q42: =+[3]SECLE10KW!E21 -> 0.077369928 | U42: =+Q42-O42 -> 0.077369928 | W42: =+M42*U42 -> 8.1352858
A43: =+A42+1 -> 28 | C43: =+C25 -> 2024 | E43: =+E25 -> 10 | G43: =+G42 -> 0.368 | J43: =J25 -> 286930 | M43: =PRODUCT(G43,J43)/1000 -> 105.59024 | O43: =+[3]SECLE10KW!C22 -> 0.30823941 | Q43: =+[3]SECLE10KW!E22 -> 2.6285157 | U43: =+Q43-O43 -> 2.3202762 | W43: =+M43*U43 -> 244.99853
A44: =+A43+1 -> 29 | C44: =+C26 -> 2024 | E44: =+E26 -> 11 | G44: =+G43 -> 0.368 | J44: =J26 -> 287446 | M44: =PRODUCT(G44,J44)/1000 -> 105.78013 | O44: =+[3]SECLE10KW!C23 -> 5.7396961 | Q44: =+[3]SECLE10KW!E23 -> 32.083725 | U44: =+Q44-O44 -> 26.344029 | W44: =+M44*U44 -> 2786.6747
...

Sheet SecGT10
W1: WP/II-H-1.2/1
W2: Page 5 of 9
A4: =+'Weather Adjustment'!A4 -> PUC DOCKET NO
A5: =+'Weather Adjustment'!A5 -> ONCOR ELECTRIC DELIVERY COMPANY LLC
A6: =+'Weather Adjustment'!A6 -> MONTHLY SALES DATA
A7: =+'Weather Adjustment'!A7 -> TEST YEAR ENDING December 31, 2024
A9: =+'Weather Adjustment'!A9 -> SPONSOR: D. E. NELSON
A11: Secondary Service Greater Than 10 KW Weather Adjustment (MWH)
G12: CDD Model | W12: CDD MWH
A13: Line | C13: Year | E13: Month | G13: Coefficient | J13: Customer | L13: Total GSL | M13: CDD Coefficient | O13: Actual CDD | Q13: Normal CDD | S13: Total GPL | U13: CDD Deviation | W13: Adjustment
A14: No. | G14: (a) | J14: (b) | M14: (c) = (a*b)/1000 | O14: (d) | Q14: (e) | U14: (f)=e-d | W14: (g)=c*f
A16: 1 | C16: =+'Weather Adjustment'!C16 -> 2024 | E16: =+'Weather Adjustment'!E16 -> 1 | G16: =+'[2]SECGT10KW Model'!$C$17 -> 10.476 | J16: =SUM('Weather Adjustment'!K35,'Weather Adjustment'!M35) -> 231499 | L16: =SUM(#REF!,J16) -> #REF! | M16: =PRODUCT(G16,J16)/1000 -> 2425.1835 | O16: =+[3]SECGT10KW!D13 -> 4.3887641 | Q16: =+[3]SECGT10KW!F13 -> 9.3847032 | S16: =SUM(O16,Q16) -> 13.773467 | U16: =+Q16-O16 -> 4.9959391 | W16: =+M16*U16 -> 12116.069
A17: =+A16+1 -> 2 | C17: =+'Weather Adjustment'!C17 -> 2024 | E17: =+'Weather Adjustment'!E17 -> 2 | G17: =+G16 -> 10.476 | J17: =SUM('Weather Adjustment'!K36,'Weather Adjustment'!M36) -> 234455 | L17: =SUM(#REF!,J17) -> #REF! | M17: =PRODUCT(G17,J17)/1000 -> 2456.1506 | O17: =+[3]SECGT10KW!D14 -> 3.3728813 | Q17: =+[3]SECGT10KW!F14 -> 7.1464836 | S17: =SUM(O17,Q17) -> 10.519365 | U17: =+Q17-O17 -> 3.7736023 | W17: =+M17*U17 -> 9268.5355
A18: =+A17+1 -> 3 | C18: =+'Weather Adjustment'!C18 -> 2024 | E18: =+'Weather Adjustment'!E18 -> 3 | G18: =+G17 -> 10.476 | J18: =SUM('Weather Adjustment'!K37,'Weather Adjustment'!M37) -> 234415 | L18: =SUM(#REF!,J18) -> #REF! | M18: =PRODUCT(G18,J18)/1000 -> 2455.7315 | O18: =+[3]SECGT10KW!D15 -> 39.813945 | Q18: =+[3]SECGT10KW!F15 -> 20.492493 | S18: =SUM(O18,Q18) -> 60.306438 | U18: =+Q18-O18 -> -19.321453 | W18: =+M18*U18 -> -47448.301
A19: =+A18+1 -> 4 | C19: =+'Weather Adjustment'!C19 -> 2024 | E19: =+'Weather Adjustment'!E19 -> 4 | G19: =+G18 -> 10.476 | J19: =SUM('Weather Adjustment'!K38,'Weather Adjustment'!M38) -> 234403 | L19: =SUM(#REF!,J19) -> #REF! | M19: =PRODUCT(G19,J19)/1000 -> 2455.6058 | O19: =+[3]SECGT10KW!D16 -> 57.995994 | Q19: =+[3]SECGT10KW!F16 -> 59.47417 | S19: =SUM(O19,Q19) -> 117.47016 | U19: =+Q19-O19 -> 1.4781762 | W19: =+M19*U19 -> 3629.818
A20: =+A19+1 -> 5 | C20: =+'Weather Adjustment'!C20 -> 2024 | E20: =+'Weather Adjustment'!E20 -> 5 | G20: =+G19 -> 10.476 | J20: =SUM('Weather Adjustment'!K39,'Weather Adjustment'!M39) -> 234550 | L20: =SUM(#REF!,J20) -> #REF! | M20: =PRODUCT(G20,J20)/1000 -> 2457.1458 | O20: =+[3]SECGT10KW!D17 -> 153.60589 | Q20: =+[3]SECGT10KW!F17 -> 128.11467 | S20: =SUM(O20,Q20) -> 281.72056 | U20: =+Q20-O20 -> -25.491223 | W20: =+M20*U20 -> -62635.651
A21: =+A20+1 -> 6 | C21: =+'Weather Adjustment'!C21 -> 2024 | E21: =+'Weather Adjustment'!E21 -> 6 | G21: =+G20 -> 10.476 | J21: =SUM('Weather Adjustment'!K40,'Weather Adjustment'!M40) -> 235044 | L21: =SUM(#REF!,J21) -> #REF! | M21: =PRODUCT(G21,J21)/1000 -> 2462.3209 | O21: =+[3]SECGT10KW!D18 -> 331.913 | Q21: =+[3]SECGT10KW!F18 -> 303.08085 | S21: =SUM(O21,Q21) -> 634.99385 | U21: =+Q21-O21 -> -28.832145 | W21: =+M21*U21 -> -70993.995
A22: =+A21+1 -> 7 | C22: =+'Weather Adjustment'!C22 -> 2024 | E22: =+'Weather Adjustment'!E22 -> 7 | G22: =+G21 -> 10.476 | J22: =SUM('Weather Adjustment'!K41,'Weather Adjustment'!M41) -> 235364 | L22: =SUM(#REF!,J22) -> #REF! | M22: =PRODUCT(G22,J22)/1000 -> 2465.6733 | O22: =+[3]SECGT10KW!D19 -> 517.14279 | Q22: =+[3]SECGT10KW!F19 -> 478.72574 | S22: =SUM(O22,Q22) -> 995.86853 | U22: =+Q22-O22 -> -38.417049 | W22: =+M22*U22 -> -94723.891
A23: =+A22+1 -> 8 | C23: =+'Weather Adjustment'!C23 -> 2024 | E23: =+'Weather Adjustment'!E23 -> 8 | G23: =+G22 -> 10.476 | J23: =SUM('Weather Adjustment'!K42,'Weather Adjustment'!M42) -> 235249 | L23: =SUM(#REF!,J23) -> #REF! | M23: =PRODUCT(G23,J23)/1000 -> 2464.4685 | O23: =+[3]SECGT10KW!D20 -> 509.54026 | Q23: =+[3]SECGT10KW!F20 -> 543.1316 | S23: =SUM(O23,Q23) -> 1052.6719 | U23: =+Q23-O23 -> 33.59134 | W23: =+M23*U23 -> 82784.801
A24: =+A23+1 -> 9 | C24: =+'Weather Adjustment'!C24 -> 2024 | E24: =+'Weather Adjustment'!E24 -> 9 | G24: =+G23 -> 10.476 | J24: =SUM('Weather Adjustment'!K43,'Weather Adjustment'!M43) -> 234473 | L24: =SUM(#REF!,J24) -> #REF! | M24: =PRODUCT(G24,J24)/1000 -> 2456.3391 | O24: =+[3]SECGT10KW!D21 -> 528.77976 | Q24: =+[3]SECGT10KW!F21 -> 498.18344 | S24: =SUM(O24,Q24) -> 1026.9632 | U24: =+Q24-O24 -> -30.596324 | W24: =+M24*U24 -> -75154.948
A25: =+A24+1 -> 10 | C25: =+'Weather Adjustment'!C25 -> 2024 | E25: =+'Weather Adjustment'!E25 -> 10 | G25: =+G24 -> 10.476 | J25: =SUM('Weather Adjustment'!K44,'Weather Adjustment'!M44) -> 233885 | L25: =SUM(#REF!,J25) -> #REF! | M25: =PRODUCT(G25,J25)/1000 -> 2450.1793 | O25: =+[3]SECGT10KW!D22 -> 331.75949 | Q25: =+[3]SECGT10KW!F22 -> 305.33115 | S25: =SUM(O25,Q25) -> 637.09064 | U25: =+Q25-O25 -> -26.428335 | W25: =+M25*U25 -> -64754.159
A26: =+A25+1 -> 11 | C26: =+'Weather Adjustment'!C26 -> 2024 | E26: =+'Weather Adjustment'!E26 -> 11 | G26: =+G25 -> 10.476 | J26: =SUM('Weather Adjustment'!K45,'Weather Adjustment'!M45) -> 233757 | L26: =SUM(#REF!,J26) -> #REF! | M26: =PRODUCT(G26,J26)/1000 -> 2448.8383 | O26: =+[3]SECGT10KW!D23 -> 192.26682 | Q26: =+[3]SECGT10KW!F23 -> 114.57722 | S26: =SUM(O26,Q26) -> 306.84403 | U26: =+Q26-O26 -> -77.6896 | W26: =+M26*U26 -> -190249.27
A27: =+A26+1 -> 12 | C27: =+'Weather Adjustment'!C27 -> 2024 | E27: =+'Weather Adjustment'!E27 -> 12 | G27: =+G26 -> 10.476 | J27: =SUM('Weather Adjustment'!K46,'Weather Adjustment'!M46) -> 234639 | L27: =SUM(#REF!,J27) -> #REF! | M27: =PRODUCT(G27,J27)/1000 -> 2458.0782 | O27: =+[3]SECGT10KW!D24 -> 35.279521 | Q27: =+[3]SECGT10KW!F24 -> 26.948599 | S27: =SUM(O27,Q27) -> 62.22812 | U27: =+Q27-O27 -> -8.3309217 | W27: =+M27*U27 -> -20478.057
A28: =+A27+1 -> 13 | C28: Total | L28: =SUM(L22:L27) -> #REF! | O28: =SUM(O16:O27) -> 2705.8591 | Q28: =SUM(Q16:Q27) -> 2494.5911 | S28: =SUM(S22:S27) -> 4081.6664 | U28: =+Q28-O28 -> -211.26799 | W28: =SUM(W16:W27) -> -518639.05
A29: =+A28+1 -> 14
A30: =+A29+1 -> 15 | G30: HDD Model | W30: HDD MWH
A31: =+A30+1 -> 16 | C31: Year | E31: Month | G31: Coefficient | J31: Customer | L31: Total GSL | M31: HDD Coefficient | O31: Actual HDD | Q31: Normal HDD | S31: Total GPL | U31: HDD Deviation | W31: Adjustment
A32: =+A31+1 -> 17 | G32: (h) | J32: (i) | M32: (j) = (h*i)/1000 | O32: (k) | Q32: (l) | U32: (m)=l-k | W32: (n)=j*m
A33: =+A32+1 -> 18
A34: =+A33+1 -> 19 | C34: =+C16 -> 2024 | E34: =+E16 -> 1 | G34: =+'[2]SECGT10KW Model'!$C$18 -> 5.685 | J34: =J16 -> 231499 | M34: =PRODUCT(G34,J34)/1000 -> 1316.0718 | O34: =+[3]SECGT10KW!C13 -> 140.09371 | Q34: =+[3]SECGT10KW!E13 -> 164.03554 | U34: =+Q34-O34 -> 23.941833 | W34: =+M34*U34 -> 31509.172
A35: =+A34+1 -> 20 | C35: =+C17 -> 2024 | E35: =+E17 -> 2 | G35: =+G34 -> 5.685 | J35: =J17 -> 234455 | M35: =PRODUCT(G35,J35)/1000 -> 1332.8767 | O35: =+[3]SECGT10KW!C14 -> 211.10812 | Q35: =+[3]SECGT10KW!E14 -> 172.42221 | U35: =+Q35-O35 -> -38.685904 | W35: =+M35*U35 -> -51563.54
A36: =+A35+1 -> 21 | C36: =+C18 -> 2024 | E36: =+E18 -> 3 | G36: =+G35 -> 5.685 | J36: =J18 -> 234415 | M36: =PRODUCT(G36,J36)/1000 -> 1332.6493 | O36: =+[3]SECGT10KW!C15 -> 39.382808 | Q36: =+[3]SECGT10KW!E15 -> 111.47031 | U36: =+Q36-O36 -> 72.087504 | W36: =+M36*U36 -> 96067.36
A37: =+A36+1 -> 22 | C37: =+C19 -> 2024 | E37: =+E19 -> 4 | G37: =+G36 -> 5.685 | J37: =J19 -> 234403 | M37: =PRODUCT(G37,J37)/1000 -> 1332.5811 | O37: =+[3]SECGT10KW!C16 -> 9.546344 | Q37: =+[3]SECGT10KW!E16 -> 25.537347 | U37: =+Q37-O37 -> 15.991003 | W37: =+M37*U37 -> 21309.308
A38: =+A37+1 -> 23 | C38: =+C20 -> 2024 | E38: =+E20 -> 5 | G38: =+G37 -> 5.685 | J38: =J20 -> 234550 | M38: =PRODUCT(G38,J38)/1000 -> 1333.4168 | O38: =+[3]SECGT10KW!C17 -> 0.86870109 | Q38: =+[3]SECGT10KW!E17 -> 3.8708013 | U38: =+Q38-O38 -> 3.0021002 | W38: =+M38*U38 -> 4003.0507
A39: =+A38+1 -> 24 | C39: =+C21 -> 2024 | E39: =+E21 -> 6 | G39: =+G38 -> 5.685 | J39: =J21 -> 235044 | M39: =PRODUCT(G39,J39)/1000 -> 1336.2251 | O39: =+[3]SECGT10KW!C18 -> 0 | Q39: =+[3]SECGT10KW!E18 -> 0.2074887 | U39: =+Q39-O39 -> 0.2074887 | W39: =+M39*U39 -> 277.25161
A40: =+A39+1 -> 25 | C40: =+C22 -> 2024 | E40: =+E22 -> 7 | G40: =+G39 -> 5.685 | J40: =J22 -> 235364 | M40: =PRODUCT(G40,J40)/1000 -> 1338.0443 | O40: =+[3]SECGT10KW!C19 -> 0 | Q40: =+[3]SECGT10KW!E19 -> 0.00033281218 | U40: =+Q40-O40 -> 0.00033281218 | W40: =+M40*U40 -> 0.44531745
A41: =+A40+1 -> 26 | C41: =+C23 -> 2024 | E41: =+E23 -> 8 | G41: =+G40 -> 5.685 | J41: =J23 -> 235249 | M41: =PRODUCT(G41,J41)/1000 -> 1337.3906 | O41: =+[3]SECGT10KW!C20 -> 0 | Q41: =+[3]SECGT10KW!E20 -> 0 | U41: =+Q41-O41 -> 0 | W41: =+M41*U41 -> 0
A42: =+A41+1 -> 27 | C42: =+C24 -> 2024 | E42: =+E24 -> 9 | G42: =+G41 -> 5.685 | J42: =J24 -> 234473 | M42: =PRODUCT(G42,J42)/1000 -> 1332.979 | O42: =+[3]SECGT10KW!C21 -> 0 | Q42: =+[3]SECGT10KW!E21 -> 0.011748856 | U42: =+Q42-O42 -> 0.011748856 | W42: =+M42*U42 -> 15.660978
A43: =+A42+1 -> 28 | C43: =+C25 -> 2024 | E43: =+E25 -> 10 | G43: =+G42 -> 5.685 | J43: =J25 -> 233885 | M43: =PRODUCT(G43,J43)/1000 -> 1329.6362 | O43: =+[3]SECGT10KW!C22 -> 0 | Q43: =+[3]SECGT10KW!E22 -> 0.65737564 | U43: =+Q43-O43 -> 0.65737564 | W43: =+M43*U43 -> 874.07047
A44: =+A43+1 -> 29 | C44: =+C26 -> 2024 | E44: =+E26 -> 11 | G44: =+G43 -> 5.685 | J44: =J26 -> 233757 | M44: =PRODUCT(G44,J44)/1000 -> 1328.9085 | O44: =+[3]SECGT10KW!C23 -> 0.20066932 | Q44: =+[3]SECGT10KW!E23 -> 14.27543 | U44: =+Q44-O44 -> 14.074761 | W44: =+M44*U44 -> 18704.07
...

Sheet SGT10_IDR_NIDR
Q1: WP/II-H-1.2/1
Q2: Page 6 of 9
A4: =+'Weather Adjustment'!A4 -> PUC DOCKET NO
A5: =+'Weather Adjustment'!A5 -> ONCOR ELECTRIC DELIVERY COMPANY LLC
A6: =+'Weather Adjustment'!A6 -> MONTHLY SALES DATA
A7: =+'Weather Adjustment'!A7 -> TEST YEAR ENDING December 31, 2024
A9: =+'Weather Adjustment'!A9 -> SPONSOR: D. E. NELSON
C11: Secondary Service Greater Than 10 KW IDR and Non-IDR Weather Adjustment (MWH)
G12: SECGT10 | J12: SECGT10 | M12: SECGT10 | O12: SECGT10 | Q12: SECGT10
A13: Line | C13: Year | E13: Month | G13: IDR KWH | J13: NIDR KWH | L13: Total GSL | M13: Large KWH | O13: IDR KWH Share | Q13: NIDR KWH Share
G14: (a) | J14: (b) | M14: (c) | O14: (d)=a/c | Q14: (e)=b/c
A16: 1 | C16: =+'Weather Adjustment'!C16 -> 2024 | E16: =+'Weather Adjustment'!E16 -> 1 | G16: =+'[1]GS SEC LRG IDR '!I16 -> 1492735008 | J16: =+'[1]GS SEC LRG NONIDR'!I16 -> 2084514076 | L16: =SUM(#REF!,J16) -> #REF! | M16: =SUM(G16,J16) -> 3577249084 | O16: =+G16/M16 -> 0.41728573 | Q16: =+J16/M16 -> 0.58271427
A17: =+A16+1 -> 2 | C17: =+'Weather Adjustment'!C17 -> 2024 | E17: =+'Weather Adjustment'!E17 -> 2 | G17: =+'[1]GS SEC LRG IDR '!I18 -> 1506024424 | J17: =+'[1]GS SEC LRG NONIDR'!I18 -> 2208290507 | L17: =SUM(#REF!,J17) -> #REF! | M17: =SUM(G17,J17) -> 3714314931 | O17: =+G17/M17 -> 0.40546492 | Q17: =+J17/M17 -> 0.59453508
A18: =+A17+1 -> 3 | C18: =+'Weather Adjustment'!C18 -> 2024 | E18: =+'Weather Adjustment'!E18 -> 3 | G18: =+'[1]GS SEC LRG IDR '!I20 -> 1491444468 | J18: =+'[1]GS SEC LRG NONIDR'!I20 -> 2004090589 | L18: =SUM(#REF!,J18) -> #REF! | M18: =SUM(G18,J18) -> 3495535057 | O18: =+G18/M18 -> 0.42667129 | Q18: =+J18/M18 -> 0.57332871
A19: =+A18+1 -> 4 | C19: =+'Weather Adjustment'!C19 -> 2024 | E19: =+'Weather Adjustment'!E19 -> 4 | G19: =+'[1]GS SEC LRG IDR '!I22 -> 1515063060 | J19: =+'[1]GS SEC LRG NONIDR'!I22 -> 1995516212 | L19: =SUM(#REF!,J19) -> #REF! | M19: =SUM(G19,J19) -> 3510579272 | O19: =+G19/M19 -> 0.43157067 | Q19: =+J19/M19 -> 0.56842933
A20: =+A19+1 -> 5 | C20: =+'Weather Adjustment'!C20 -> 2024 | E20: =+'Weather Adjustment'!E20 -> 5 | G20: =+'[1]GS SEC LRG IDR '!I24 -> 1513871427 | J20: =+'[1]GS SEC LRG NONIDR'!I24 -> 2122032481 | L20: =SUM(#REF!,J20) -> #REF! | M20: =SUM(G20,J20) -> 3635903908 | O20: =+G20/M20 -> 0.41636728 | Q20: =+J20/M20 -> 0.58363272
A21: =+A20+1 -> 6 | C21: =+'Weather Adjustment'!C21 -> 2024 | E21: =+'Weather Adjustment'!E21 -> 6 | G21: =+'[1]GS SEC LRG IDR '!I26 -> 1679481052 | J21: =+'[1]GS SEC LRG NONIDR'!I26 -> 2537541941 | L21: =SUM(#REF!,J21) -> #REF! | M21: =SUM(G21,J21) -> 4217022993 | O21: =+G21/M21 -> 0.39826225 | Q21: =+J21/M21 -> 0.60173775
A22: =+A21+1 -> 7 | C22: =+'Weather Adjustment'!C22 -> 2024 | E22: =+'Weather Adjustment'!E22 -> 7 | G22: =+'[1]GS SEC LRG IDR '!I28 -> 1798253867 | J22: =+'[1]GS SEC LRG NONIDR'!I28 -> 2919070528 | L22: =SUM(#REF!,J22) -> #REF! | M22: =SUM(G22,J22) -> 4717324395 | O22: =+G22/M22 -> 0.38120208 | Q22: =+J22/M22 -> 0.61879792
A23: =+A22+1 -> 8 | C23: =+'Weather Adjustment'!C23 -> 2024 | E23: =+'Weather Adjustment'!E23 -> 8 | G23: =+'[1]GS SEC LRG IDR '!I30 -> 1786784772 | J23: =+'[1]GS SEC LRG NONIDR'!I30 -> 2909968515 | L23: =SUM(#REF!,J23) -> #REF! | M23: =SUM(G23,J23) -> 4696753287 | O23: =+G23/M23 -> 0.38042977 | Q23: =+J23/M23 -> 0.61957023
A24: =+A23+1 -> 9 | C24: =+'Weather Adjustment'!C24 -> 2024 | E24: =+'Weather Adjustment'!E24 -> 9 | G24: =+'[1]GS SEC LRG IDR '!I32 -> 1839584015 | J24: =+'[1]GS SEC LRG NONIDR'!I32 -> 3003691540 | L24: =SUM(#REF!,J24) -> #REF! | M24: =SUM(G24,J24) -> 4843275555 | O24: =+G24/M24 -> 0.37982229 | Q24: =+J24/M24 -> 0.62017771
A25: =+A24+1 -> 10 | C25: =+'Weather Adjustment'!C25 -> 2024 | E25: =+'Weather Adjustment'!E25 -> 10 | G25: =+'[1]GS SEC LRG IDR '!I34 -> 1691268577 | J25: =+'[1]GS SEC LRG NONIDR'!I34 -> 2548274691 | L25: =SUM(#REF!,J25) -> #REF! | M25: =SUM(G25,J25) -> 4239543268 | O25: =+G25/M25 -> 0.39892707 | Q25: =+J25/M25 -> 0.60107293
A26: =+A25+1 -> 11 | C26: =+'Weather Adjustment'!C26 -> 2024 | E26: =+'Weather Adjustment'!E26 -> 11 | G26: =+'[1]GS SEC LRG IDR '!I36 -> 1606937303 | J26: =+'[1]GS SEC LRG NONIDR'!I36 -> 2277436942 | L26: =SUM(#REF!,J26) -> #REF! | M26: =SUM(G26,J26) -> 3884374245 | O26: =+G26/M26 -> 0.41369271 | Q26: =+J26/M26 -> 0.58630729
A27: =+A26+1 -> 12 | C27: =+'Weather Adjustment'!C27 -> 2024 | E27: =+'Weather Adjustment'!E27 -> 12 | G27: =+'[1]GS SEC LRG IDR '!I38 -> 1488553066 | J27: =+'[1]GS SEC LRG NONIDR'!I38 -> 1963848362 | L27: =SUM(#REF!,J27) -> #REF! | M27: =SUM(G27,J27) -> 3452401428 | O27: =+G27/M27 -> 0.43116454 | Q27: =+J27/M27 -> 0.56883546
A28: =+A27+1 -> 13 | C28: Total | G28: =SUM(G16:G27) -> 19410001039 | J28: =SUM(J16:J27) -> 28574276384 | L28: =SUM(L22:L27) -> #REF! | M28: =SUM(M16:M27) -> 47984277423
A29: =+A28+1 -> 14
A30: =+A29+1 -> 15 | G30: SECGT10 | J30: SECGT10 | M30: SECGT10
A31: =+A30+1 -> 16 | C31: Year | E31: Month | G31: KWH Adjustment | J31: IDR KWH Adjustment | L31: Total GSL | M31: NIDR KWH Adjustment
