Workbook
Name HOURLY: [1]HOURLY!$A$1:$G$745
Name OLE_LINK2: 'Res Seasonal Weights'!$B$24
Name rngBilled: OFFSET([2]Sheet2!$A$2,0,0,[2]Sheet2!$B$1,9)
Name rngYear: OFFSET('[3]Daily Actual_August'!$A$2,0,0,'[3]Daily Actual_August'!$C$1,8)

Sheet Res Seasonal Weights
B1: PUC DOCKET NO.
B2: ONCOR ELECTRIC DELIVERY COMPANY LLC
B3: WEATHER WEIGHTS
B4: FOR THE TEST YEAR ENDING DECEMBER 31, 2024
B6: SPONSOR: D. E. NELSON
B8: RESIDENTIAL MONTHLY WEIGHTS
A9: Line | B9: (a) | D9: (b) | E9: (c) | F9: (d) | G9: (e) | H9: (f) | I9: (g) | J9: (h) | K9: (i) | L9: (j) | M9: (k) | N9: (l) | O9: (m) | P9: (n)
A10: No. | B10: Weather Station | D10: 36892 | E10: 36923 | F10: 36951 | G10: 36982 | H10: 37012 | I10: 37043 | J10: 37073 | K10: 37104 | L10: 37135 | M10: 37165 | N10: 37196 | O10: 37226 | P10: Annual
A11: 1 | B11: Dallas-Fort Worth | D11: =+'Res Monthly Weather Weights'!C11 -> 0.68424665 | E11: =+'Res Monthly Weather Weights'!D11 -> 0.68405043 | F11: =+'Res Monthly Weather Weights'!E11 -> 0.68559851 | G11: =+'Res Monthly Weather Weights'!F11 -> 0.68865637 | H11: =+'Res Monthly Weather Weights'!G11 -> 0.68952427 | I11: =+'Res Monthly Weather Weights'!H11 -> 0.69610927 | J11: =+'Res Monthly Weather Weights'!I11 -> 0.70517894 | K11: =+'Res Monthly Weather Weights'!J11 -> 0.71056044 | ... P11: =+'Res Monthly Weather Weights'!O11 -> 0.69612564
A12: =+A11+1 -> 2 | B12: Midland-Odessa | D12: =+'Res Monthly Weather Weights'!C12 -> 0.05632707 | E12: =+'Res Monthly Weather Weights'!D12 -> 0.056672599 | F12: =+'Res Monthly Weather Weights'!E12 -> 0.054263579 | G12: =+'Res Monthly Weather Weights'!F12 -> 0.054894437 | H12: =+'Res Monthly Weather Weights'!G12 -> 0.057650058 | I12: =+'Res Monthly Weather Weights'!H12 -> 0.057171461 | J12: =+'Res Monthly Weather Weights'!I12 -> 0.054274809 | K12: =+'Res Monthly Weather Weights'!J12 -> 0.051466788 | ... P12: =+'Res Monthly Weather Weights'!O12 -> 0.054282928
A13: =+A12+1 -> 3 | B13: Lufkin | D13: =+'Res Monthly Weather Weights'!C13 -> 0.029210749 | E13: =+'Res Monthly Weather Weights'!D13 -> 0.028802294 | F13: =+'Res Monthly Weather Weights'!E13 -> 0.027102349 | G13: =+'Res Monthly Weather Weights'!F13 -> 0.027922034 | H13: =+'Res Monthly Weather Weights'!G13 -> 0.026923798 | I13: =+'Res Monthly Weather Weights'!H13 -> 0.026149408 | J13: =+'Res Monthly Weather Weights'!I13 -> 0.02534795 | K13: =+'Res Monthly Weather Weights'!J13 -> 0.024563015 | ... P13: =+'Res Monthly Weather Weights'!O13 -> 0.026432333
A14: =+A13+1 -> 4 | B14: Abilene | D14: =+'Res Monthly Weather Weights'!C14 -> 0.014502322 | E14: =+'Res Monthly Weather Weights'!D14 -> 0.01462754 | F14: =+'Res Monthly Weather Weights'!E14 -> 0.013729779 | G14: =+'Res Monthly Weather Weights'!F14 -> 0.012922011 | H14: =+'Res Monthly Weather Weights'!G14 -> 0.012842979 | I14: =+'Res Monthly Weather Weights'!H14 -> 0.012411264 | J14: =+'Res Monthly Weather Weights'!I14 -> 0.012142129 | K14: =+'Res Monthly Weather Weights'!J14 -> 0.011859707 | ... P14: =+'Res Monthly Weather Weights'!O14 -> 0.012714991
A15: =+A14+1 -> 5 | B15: Sherman-Denison | D15: =+'Res Monthly Weather Weights'!C15 -> 0.027510074 | E15: =+'Res Monthly Weather Weights'!D15 -> 0.027931991 | F15: =+'Res Monthly Weather Weights'!E15 -> 0.028152503 | G15: =+'Res Monthly Weather Weights'!F15 -> 0.026100432 | H15: =+'Res Monthly Weather Weights'!G15 -> 0.023295878 | I15: =+'Res Monthly Weather Weights'!H15 -> 0.022195851 | J15: =+'Res Monthly Weather Weights'!I15 -> 0.022809322 | K15: =+'Res Monthly Weather Weights'!J15 -> 0.023586126 | ... P15: =+'Res Monthly Weather Weights'!O15 -> 0.024937123
A16: =+A15+1 -> 6 | B16: Killeen-Temple | D16: =+'Res Monthly Weather Weights'!C16 -> 0.052350246 | E16: =+'Res Monthly Weather Weights'!D16 -> 0.053723293 | F16: =+'Res Monthly Weather Weights'!E16 -> 0.05415944 | G16: =+'Res Monthly Weather Weights'!F16 -> 0.049904218 | H16: =+'Res Monthly Weather Weights'!G16 -> 0.049078764 | I16: =+'Res Monthly Weather Weights'!H16 -> 0.047041514 | J16: =+'Res Monthly Weather Weights'!I16 -> 0.044598991 | K16: =+'Res Monthly Weather Weights'!J16 -> 0.043724614 | ... P16: =+'Res Monthly Weather Weights'!O16 -> 0.048269624
A17: =+A16+1 -> 7 | B17: Waco | D17: =+'Res Monthly Weather Weights'!C17 -> 0.038231387 | E17: =+'Res Monthly Weather Weights'!D17 -> 0.039066819 | F17: =+'Res Monthly Weather Weights'!E17 -> 0.040905812 | G17: =+'Res Monthly Weather Weights'!F17 -> 0.038050379 | H17: =+'Res Monthly Weather Weights'!G17 -> 0.036764385 | I17: =+'Res Monthly Weather Weights'!H17 -> 0.035600916 | J17: =+'Res Monthly Weather Weights'!I17 -> 0.035106317 | K17: =+'Res Monthly Weather Weights'!J17 -> 0.035176502 | ... P17: =+'Res Monthly Weather Weights'!O17 -> 0.037182177
A18: =+A17+1 -> 8 | B18: Wichita Falls. | D18: =+'Res Monthly Weather Weights'!C18 -> 0.019416085 | E18: =+'Res Monthly Weather Weights'!D18 -> 0.019545808 | F18: =+'Res Monthly Weather Weights'!E18 -> 0.019845794 | G18: =+'Res Monthly Weather Weights'!F18 -> 0.01846772 | H18: =+'Res Monthly Weather Weights'!G18 -> 0.017801695 | I18: =+'Res Monthly Weather Weights'!H18 -> 0.017725578 | J18: =+'Res Monthly Weather Weights'!I18 -> 0.01821501 | K18: =+'Res Monthly Weather Weights'!J18 -> 0.018702553 | ... P18: =+'Res Monthly Weather Weights'!O18 -> 0.018702767
A19: =+A18+1 -> 9 | B19: Longview | D19: =+'Res Monthly Weather Weights'!C19 -> 0.039423881 | E19: =+'Res Monthly Weather Weights'!D19 -> 0.039091156 | F19: =+'Res Monthly Weather Weights'!E19 -> 0.038490681 | G19: =+'Res Monthly Weather Weights'!F19 -> 0.038257478 | H19: =+'Res Monthly Weather Weights'!G19 -> 0.036702593 | I19: =+'Res Monthly Weather Weights'!H19 -> 0.035932793 | J19: =+'Res Monthly Weather Weights'!I19 -> 0.035399141 | K19: =+'Res Monthly Weather Weights'!J19 -> 0.034795332 | ... P19: =+'Res Monthly Weather Weights'!O19 -> 0.036732626
A20: =+A19+1 -> 10 | B20: Austin | D20: =+'Res Monthly Weather Weights'!C20 -> 0.038781533 | E20: =+'Res Monthly Weather Weights'!D20 -> 0.036488075 | F20: =+'Res Monthly Weather Weights'!E20 -> 0.037751548 | G20: =+'Res Monthly Weather Weights'!F20 -> 0.044824918 | H20: =+'Res Monthly Weather Weights'!G20 -> 0.04941558 | I20: =+'Res Monthly Weather Weights'!H20 -> 0.049661948 | J20: =+'Res Monthly Weather Weights'!I20 -> 0.046927388 | K20: =+'Res Monthly Weather Weights'!J20 -> 0.045564923 | ... P20: =+'Res Monthly Weather Weights'!O20 -> 0.044619788
A21: =+A20+1 -> 11 | D21: =SUM(D11:D20) -> 1 | E21: =SUM(E11:E20) -> 1 | F21: =SUM(F11:F20) -> 1 | G21: =SUM(G11:G20) -> 1 | H21: =SUM(H11:H20) -> 1 | I21: =SUM(I11:I20) -> 1 | J21: =SUM(J11:J20) -> 1 | K21: =SUM(K11:K20) -> 1 | ... P21: =SUM(P11:P20) -> 1
A22: =+A21+1 -> 12
A23: =+A22+1 -> 13 | D23: SEASONAL WEIGHTS
A24: =+A23+1 -> 14 | D24: Nov to Mar | F24: May to Sep
A25: =+A24+1 -> 15 | B25: Weather Station | D25: HDD | F25: CDD
A26: =+A25+1 -> 16 | B26: Dallas-Fort Worth | D26: =ROUND(AVERAGE(D11:F11,N11:O11),3) -> 0.686 | F26: =ROUND(AVERAGE(H11:L11),3) -> 0.702
A27: =+A26+1 -> 17 | B27: Midland-Odessa | D27: =ROUND(AVERAGE(D12:F12,N12:O12),3) -> 0.056 | F27: =ROUND(AVERAGE(H12:L12),3) -> 0.054
A28: =+A27+1 -> 18 | B28: Lufkin | D28: =ROUND(AVERAGE(D13:F13,N13:O13),3) -> 0.028 | F28: =ROUND(AVERAGE(H13:L13),3) -> 0.026
A29: =+A28+1 -> 19 | B29: Abilene | D29: =ROUND(AVERAGE(D14:F14,N14:O14),3) -> 0.014 | F29: =ROUND(AVERAGE(H14:L14),3) -> 0.012
A30: =+A29+1 -> 20 | B30: Sherman-Denison | D30: =ROUND(AVERAGE(D15:F15,N15:O15),3) -> 0.027 | F30: =ROUND(AVERAGE(H15:L15),3) -> 0.023
A31: =+A30+1 -> 21 | B31: Killeen-Temple | D31: =ROUND(AVERAGE(D16:F16,N16:O16),3) -> 0.052 | F31: =ROUND(AVERAGE(H16:L16),3) -> 0.046
A32: =+A31+1 -> 22 | B32: Waco | D32: =ROUND(AVERAGE(D17:F17,N17:O17),3) -> 0.039 | F32: =ROUND(AVERAGE(H17:L17),3) -> 0.036
A33: =+A32+1 -> 23 | B33: Wichita Falls. | D33: =ROUND(AVERAGE(D18:F18,N18:O18),3) -> 0.019 | F33: =ROUND(AVERAGE(H18:L18),3) -> 0.018
A34: =+A33+1 -> 24 | B34: Longview | D34: =ROUND(AVERAGE(D19:F19,N19:O19),3) -> 0.039 | F34: =ROUND(AVERAGE(H19:L19),3) -> 0.036
A35: =+A34+1 -> 25 | B35: Austin | D35: =ROUND(AVERAGE(D20:F20,N20:O20),3) -> 0.04 | F35: =ROUND(AVERAGE(H20:L20),3) -> 0.048
A36: =+A35+1 -> 26 | D36: =AVERAGE(D21:F21,N21:O21) -> 1 | F36: =AVERAGE(H21:L21) -> 1

Sheet Res Monthly Weather Weights
B1: PUC DOCKET NO.
B2: ONCOR ELECTRIC DELIVERY COMPANY
B3: WEATHER WEIGHTS
B4: =+'Res Seasonal Weights'!B4:P4 -> FOR THE TEST YEAR ENDING DECEMBER 31, 2024
B6: SPONSOR: D. E. NELSON
B8: RESIDENTIAL MONTHLY WEIGHTS
A9: Line | B9: (a) | C9: (b) | D9: (c) | E9: (d) | F9: (e) | G9: (f) | H9: (g) | I9: (h) | J9: (i) | K9: (j) | L9: (k) | M9: (l) | N9: (m) | O9: (n)
A10: No. | B10: Weather Station | C10: 36892 | D10: 36923 | E10: 36951 | F10: 36982 | G10: 37012 | H10: 37043 | I10: 37073 | J10: 37104 | K10: 37135 | L10: 37165 | M10: 37196 | N10: 37226 | O10: Annual
A11: 1 | B11: Dallas-Fort Worth | C11: =+'Res Weights by Year (21-23)'!D14 -> 0.68424665 | D11: =+'Res Weights by Year (21-23)'!E14 -> 0.68405043 | E11: =+'Res Weights by Year (21-23)'!F14 -> 0.68559851 | F11: =+'Res Weights by Year (21-23)'!G14 -> 0.68865637 | G11: =+'Res Weights by Year (21-23)'!H14 -> 0.68952427 | H11: =+'Res Weights by Year (21-23)'!I14 -> 0.69610927 | I11: =+'Res Weights by Year (21-23)'!J14 -> 0.70517894 | J11: =+'Res Weights by Year (21-23)'!K14 -> 0.71056044 | ... O11: =+'Res Weights by Year (21-23)'!P14 -> 0.69612564
A12: =+A11+1 -> 2 | B12: Midland-Odessa | C12: =+'Res Weights by Year (21-23)'!D54 -> 0.05632707 | D12: =+'Res Weights by Year (21-23)'!E54 -> 0.056672599 | E12: =+'Res Weights by Year (21-23)'!F54 -> 0.054263579 | F12: =+'Res Weights by Year (21-23)'!G54 -> 0.054894437 | G12: =+'Res Weights by Year (21-23)'!H54 -> 0.057650058 | H12: =+'Res Weights by Year (21-23)'!I54 -> 0.057171461 | I12: =+'Res Weights by Year (21-23)'!J54 -> 0.054274809 | J12: =+'Res Weights by Year (21-23)'!K54 -> 0.051466788 | ... O12: =+'Res Weights by Year (21-23)'!P54 -> 0.054282928
A13: =+A12+1 -> 3 | B13: Lufkin | C13: =+'Res Weights by Year (21-23)'!D19 -> 0.029210749 | D13: =+'Res Weights by Year (21-23)'!E19 -> 0.028802294 | E13: =+'Res Weights by Year (21-23)'!F19 -> 0.027102349 | F13: =+'Res Weights by Year (21-23)'!G19 -> 0.027922034 | G13: =+'Res Weights by Year (21-23)'!H19 -> 0.026923798 | H13: =+'Res Weights by Year (21-23)'!I19 -> 0.026149408 | I13: =+'Res Weights by Year (21-23)'!J19 -> 0.02534795 | J13: =+'Res Weights by Year (21-23)'!K19 -> 0.024563015 | ... O13: =+'Res Weights by Year (21-23)'!P19 -> 0.026432333
A14: =+A13+1 -> 4 | B14: Abilene | C14: =+'Res Weights by Year (21-23)'!D44 -> 0.014502322 | D14: =+'Res Weights by Year (21-23)'!E44 -> 0.01462754 | E14: =+'Res Weights by Year (21-23)'!F44 -> 0.013729779 | F14: =+'Res Weights by Year (21-23)'!G44 -> 0.012922011 | G14: =+'Res Weights by Year (21-23)'!H44 -> 0.012842979 | H14: =+'Res Weights by Year (21-23)'!I44 -> 0.012411264 | I14: =+'Res Weights by Year (21-23)'!J44 -> 0.012142129 | J14: =+'Res Weights by Year (21-23)'!K44 -> 0.011859707 | ... O14: =+'Res Weights by Year (21-23)'!P44 -> 0.012714991
A15: =+A14+1 -> 5 | B15: Sherman-Denison | C15: =+'Res Weights by Year (21-23)'!D59 -> 0.027510074 | D15: =+'Res Weights by Year (21-23)'!E59 -> 0.027931991 | E15: =+'Res Weights by Year (21-23)'!F59 -> 0.028152503 | F15: =+'Res Weights by Year (21-23)'!G59 -> 0.026100432 | G15: =+'Res Weights by Year (21-23)'!H59 -> 0.023295878 | H15: =+'Res Weights by Year (21-23)'!I59 -> 0.022195851 | I15: =+'Res Weights by Year (21-23)'!J59 -> 0.022809322 | J15: =+'Res Weights by Year (21-23)'!K59 -> 0.023586126 | ... O15: =+'Res Weights by Year (21-23)'!P59 -> 0.024937123
A16: =+A15+1 -> 6 | B16: Killeen-Temple | C16: =+'Res Weights by Year (21-23)'!D29 -> 0.052350246 | D16: =+'Res Weights by Year (21-23)'!E29 -> 0.053723293 | E16: =+'Res Weights by Year (21-23)'!F29 -> 0.05415944 | F16: =+'Res Weights by Year (21-23)'!G29 -> 0.049904218 | G16: =+'Res Weights by Year (21-23)'!H29 -> 0.049078764 | H16: =+'Res Weights by Year (21-23)'!I29 -> 0.047041514 | I16: =+'Res Weights by Year (21-23)'!J29 -> 0.044598991 | J16: =+'Res Weights by Year (21-23)'!K29 -> 0.043724614 | ... O16: =+'Res Weights by Year (21-23)'!P29 -> 0.048269624
A17: =+A16+1 -> 7 | B17: Waco | C17: =+'Res Weights by Year (21-23)'!D39 -> 0.038231387 | D17: =+'Res Weights by Year (21-23)'!E39 -> 0.039066819 | E17: =+'Res Weights by Year (21-23)'!F39 -> 0.040905812 | F17: =+'Res Weights by Year (21-23)'!G39 -> 0.038050379 | G17: =+'Res Weights by Year (21-23)'!H39 -> 0.036764385 | H17: =+'Res Weights by Year (21-23)'!I39 -> 0.035600916 | I17: =+'Res Weights by Year (21-23)'!J39 -> 0.035106317 | J17: =+'Res Weights by Year (21-23)'!K39 -> 0.035176502 | ... O17: =+'Res Weights by Year (21-23)'!P39 -> 0.037182177
A18: =+A17+1 -> 8 | B18: Wichita Falls. | C18: =+'Res Weights by Year (21-23)'!D49 -> 0.019416085 | D18: =+'Res Weights by Year (21-23)'!E49 -> 0.019545808 | E18: =+'Res Weights by Year (21-23)'!F49 -> 0.019845794 | F18: =+'Res Weights by Year (21-23)'!G49 -> 0.01846772 | G18: =+'Res Weights by Year (21-23)'!H49 -> 0.017801695 | H18: =+'Res Weights by Year (21-23)'!I49 -> 0.017725578 | I18: =+'Res Weights by Year (21-23)'!J49 -> 0.01821501 | J18: =+'Res Weights by Year (21-23)'!K49 -> 0.018702553 | ... O18: =+'Res Weights by Year (21-23)'!P49 -> 0.018702767
A19: =+A18+1 -> 9 | B19: Longview | C19: =+'Res Weights by Year (21-23)'!D34 -> 0.039423881 | D19: =+'Res Weights by Year (21-23)'!E34 -> 0.039091156 | E19: =+'Res Weights by Year (21-23)'!F34 -> 0.038490681 | F19: =+'Res Weights by Year (21-23)'!G34 -> 0.038257478 | G19: =+'Res Weights by Year (21-23)'!H34 -> 0.036702593 | H19: =+'Res Weights by Year (21-23)'!I34 -> 0.035932793 | I19: =+'Res Weights by Year (21-23)'!J34 -> 0.035399141 | J19: =+'Res Weights by Year (21-23)'!K34 -> 0.034795332 | ... O19: =+'Res Weights by Year (21-23)'!P34 -> 0.036732626
A20: =+A19+1 -> 10 | B20: Austin | C20: =+'Res Weights by Year (21-23)'!D24 -> 0.038781533 | D20: =+'Res Weights by Year (21-23)'!E24 -> 0.036488075 | E20: =+'Res Weights by Year (21-23)'!F24 -> 0.037751548 | F20: =+'Res Weights by Year (21-23)'!G24 -> 0.044824918 | G20: =+'Res Weights by Year (21-23)'!H24 -> 0.04941558 | H20: =+'Res Weights by Year (21-23)'!I24 -> 0.049661948 | I20: =+'Res Weights by Year (21-23)'!J24 -> 0.046927388 | J20: =+'Res Weights by Year (21-23)'!K24 -> 0.045564923 | ... O20: =+'Res Weights by Year (21-23)'!P24 -> 0.044619788
C21: =SUM(C11:C20) -> 1 | D21: =SUM(D11:D20) -> 1 | E21: =SUM(E11:E20) -> 1 | F21: =SUM(F11:F20) -> 1 | G21: =SUM(G11:G20) -> 1 | H21: =SUM(H11:H20) -> 1 | I21: =SUM(I11:I20) -> 1 | J21: =SUM(J11:J20) -> 1 | ... O21: =SUM(O11:O20) -> 1

Sheet Res Weights by Year (21-23)
B1: PUC DOCKET NO.
B2: ONCOR ELECTRIC DELIVERY COMPANY
B3: WEATHER WEIGHTS
B4: =+'Res Seasonal Weights'!B4:P4 -> FOR THE TEST YEAR ENDING DECEMBER 31, 2024
B6: SPONSOR: D. E. NELSON
B8: RESIDENTIAL MONTHLY WEIGHTS BY YEAR
A9: Line | B9: (a) | C9: (b) | D9: (c) | E9: (d) | F9: (e) | G9: (f) | H9: (g) | I9: (h) | J9: (i) | K9: (j) | L9: (k) | M9: (l) | N9: (m) | O9: (n) | P9: (o)
A10: No. | B10: Weather Station | C10: Year | D10: 36892 | E10: 36923 | F10: 36951 | G10: 36982 | H10: 37012 | I10: 37043 | J10: 37073 | K10: 37104 | L10: 37135 | M10: 37165 | N10: 37196 | O10: 37226 | P10: Annual
A11: 1 | B11: Dallas-Fort Worth | C11: 2021 | D11: ='Res Sales by Year (21-23)'!D11/'Res Sales by Year (21-23)'!D61 -> 0.68081362 | E11: ='Res Sales by Year (21-23)'!E11/'Res Sales by Year (21-23)'!E$61 -> 0.6856683 | F11: ='Res Sales by Year (21-23)'!F11/'Res Sales by Year (21-23)'!F$61 -> 0.6876195 | G11: ='Res Sales by Year (21-23)'!G11/'Res Sales by Year (21-23)'!G$61 -> 0.6869969 | H11: ='Res Sales by Year (21-23)'!H11/'Res Sales by Year (21-23)'!H$61 -> 0.68741736 | I11: ='Res Sales by Year (21-23)'!I11/'Res Sales by Year (21-23)'!I$61 -> 0.69278082 | J11: ='Res Sales by Year (21-23)'!J11/'Res Sales by Year (21-23)'!J$61 -> 0.70894374 | K11: ='Res Sales by Year (21-23)'!K11/'Res Sales by Year (21-23)'!K$61 -> 0.71428343 | L11: ='Res Sales by Year (21-23)'!L11/'Res Sales by Year (21-23)'!L$61 -> 0.70863313 | ... P11: ='Res Sales by Year (21-23)'!P11/'Res Sales by Year (21-23)'!P$61 -> 0.69686833
A12: =+A11+1 -> 2 | B12: Dallas-Fort Worth | C12: 2022 | D12: ='Res Sales by Year (21-23)'!D12/'Res Sales by Year (21-23)'!D62 -> 0.69114184 | E12: ='Res Sales by Year (21-23)'!E12/'Res Sales by Year (21-23)'!E$62 -> 0.68256963 | F12: ='Res Sales by Year (21-23)'!F12/'Res Sales by Year (21-23)'!F$62 -> 0.68372926 | G12: ='Res Sales by Year (21-23)'!G12/'Res Sales by Year (21-23)'!G$62 -> 0.68998219 | H12: ='Res Sales by Year (21-23)'!H12/'Res Sales by Year (21-23)'!H$62 -> 0.69063556 | I12: ='Res Sales by Year (21-23)'!I12/'Res Sales by Year (21-23)'!I$62 -> 0.69557197 | J12: ='Res Sales by Year (21-23)'!J12/'Res Sales by Year (21-23)'!J$62 -> 0.71018309 | K12: ='Res Sales by Year (21-23)'!K12/'Res Sales by Year (21-23)'!K$62 -> 0.71313291 | L12: ='Res Sales by Year (21-23)'!L12/'Res Sales by Year (21-23)'!L$62 -> 0.70474766 | ... P12: ='Res Sales by Year (21-23)'!P12/'Res Sales by Year (21-23)'!P$62 -> 0.69690011
A13: =+A12+1 -> 3 | B13: Dallas-Fort Worth | C13: 2023 | D13: ='Res Sales by Year (21-23)'!D13/'Res Sales by Year (21-23)'!D63 -> 0.6818116 | E13: ='Res Sales by Year (21-23)'!E13/'Res Sales by Year (21-23)'!E63 -> 0.68404433 | F13: ='Res Sales by Year (21-23)'!F13/'Res Sales by Year (21-23)'!F63 -> 0.68518395 | G13: ='Res Sales by Year (21-23)'!G13/'Res Sales by Year (21-23)'!G63 -> 0.68875127 | H13: ='Res Sales by Year (21-23)'!H13/'Res Sales by Year (21-23)'!H63 -> 0.69029432 | I13: ='Res Sales by Year (21-23)'!I13/'Res Sales by Year (21-23)'!I63 -> 0.69968343 | J13: ='Res Sales by Year (21-23)'!J13/'Res Sales by Year (21-23)'!J63 -> 0.69637174 | K13: ='Res Sales by Year (21-23)'!K13/'Res Sales by Year (21-23)'!K63 -> 0.70486653 | ... P13: ='Res Sales by Year (21-23)'!P13/'Res Sales by Year (21-23)'!P63 -> 0.69464583
A14: =+A13+1 -> 4 | B14: Dallas-Fort Worth | C14: Total | D14: ='Res Sales by Year (21-23)'!D14/'Res Sales by Year (21-23)'!D64 -> 0.68424665 | E14: ='Res Sales by Year (21-23)'!E14/'Res Sales by Year (21-23)'!E64 -> 0.68405043 | F14: ='Res Sales by Year (21-23)'!F14/'Res Sales by Year (21-23)'!F64 -> 0.68559851 | G14: ='Res Sales by Year (21-23)'!G14/'Res Sales by Year (21-23)'!G64 -> 0.68865637 | H14: ='Res Sales by Year (21-23)'!H14/'Res Sales by Year (21-23)'!H64 -> 0.68952427 | I14: ='Res Sales by Year (21-23)'!I14/'Res Sales by Year (21-23)'!I64 -> 0.69610927 | J14: ='Res Sales by Year (21-23)'!J14/'Res Sales by Year (21-23)'!J64 -> 0.70517894 | K14: ='Res Sales by Year (21-23)'!K14/'Res Sales by Year (21-23)'!K64 -> 0.71056044 | ... P14: ='Res Sales by Year (21-23)'!P14/'Res Sales by Year (21-23)'!P64 -> 0.69612564
A15: =+A14+1 -> 5
A16: =+A15+1 -> 6 | B16: Lufkin | C16: =+C11 -> 2021 | D16: ='Res Sales by Year (21-23)'!D16/'Res Sales by Year (21-23)'!D61 -> 0.030021685 | E16: ='Res Sales by Year (21-23)'!E16/'Res Sales by Year (21-23)'!E$61 -> 0.028526621 | F16: ='Res Sales by Year (21-23)'!F16/'Res Sales by Year (21-23)'!F$61 -> 0.026826842 | G16: ='Res Sales by Year (21-23)'!G16/'Res Sales by Year (21-23)'!G$61 -> 0.029076617 | H16: ='Res Sales by Year (21-23)'!H16/'Res Sales by Year (21-23)'!H$61 -> 0.027997905 | I16: ='Res Sales by Year (21-23)'!I16/'Res Sales by Year (21-23)'!I$61 -> 0.02722968 | J16: ='Res Sales by Year (21-23)'!J16/'Res Sales by Year (21-23)'!J$61 -> 0.025720873 | K16: ='Res Sales by Year (21-23)'!K16/'Res Sales by Year (21-23)'!K$61 -> 0.02507149 | L16: ='Res Sales by Year (21-23)'!L16/'Res Sales by Year (21-23)'!L$61 -> 0.025417335 | ... P16: ='Res Sales by Year (21-23)'!P16/'Res Sales by Year (21-23)'!P$61 -> 0.027057191
A17: =+A16+1 -> 7 | B17: Lufkin | C17: =+C12 -> 2022 | D17: ='Res Sales by Year (21-23)'!D17/'Res Sales by Year (21-23)'!D62 -> 0.028401807 | E17: ='Res Sales by Year (21-23)'!E17/'Res Sales by Year (21-23)'!E$62 -> 0.02979507 | F17: ='Res Sales by Year (21-23)'!F17/'Res Sales by Year (21-23)'!F$62 -> 0.028403154 | G17: ='Res Sales by Year (21-23)'!G17/'Res Sales by Year (21-23)'!G$62 -> 0.02735189 | H17: ='Res Sales by Year (21-23)'!H17/'Res Sales by Year (21-23)'!H$62 -> 0.026763859 | I17: ='Res Sales by Year (21-23)'!I17/'Res Sales by Year (21-23)'!I$62 -> 0.026084783 | J17: ='Res Sales by Year (21-23)'!J17/'Res Sales by Year (21-23)'!J$62 -> 0.024964197 | K17: ='Res Sales by Year (21-23)'!K17/'Res Sales by Year (21-23)'!K$62 -> 0.024035696 | L17: ='Res Sales by Year (21-23)'!L17/'Res Sales by Year (21-23)'!L$62 -> 0.024772186 | ... P17: ='Res Sales by Year (21-23)'!P17/'Res Sales by Year (21-23)'!P$62 -> 0.026340596
A18: =+A17+1 -> 8 | B18: Lufkin | C18: =+C13 -> 2023 | D18: ='Res Sales by Year (21-23)'!D18/'Res Sales by Year (21-23)'!D63 -> 0.029092577 | E18: ='Res Sales by Year (21-23)'!E18/'Res Sales by Year (21-23)'!E63 -> 0.027995195 | F18: ='Res Sales by Year (21-23)'!F18/'Res Sales by Year (21-23)'!F63 -> 0.025886832 | G18: ='Res Sales by Year (21-23)'!G18/'Res Sales by Year (21-23)'!G63 -> 0.027473735 | H18: ='Res Sales by Year (21-23)'!H18/'Res Sales by Year (21-23)'!H63 -> 0.026060669 | I18: ='Res Sales by Year (21-23)'!I18/'Res Sales by Year (21-23)'!I63 -> 0.025267077 | J18: ='Res Sales by Year (21-23)'!J18/'Res Sales by Year (21-23)'!J63 -> 0.025425674 | K18: ='Res Sales by Year (21-23)'!K18/'Res Sales by Year (21-23)'!K63 -> 0.024691394 | ... P18: ='Res Sales by Year (21-23)'!P18/'Res Sales by Year (21-23)'!P63 -> 0.025941635
A19: =+A18+1 -> 9 | B19: Lufkin | C19: Total | D19: ='Res Sales by Year (21-23)'!D19/'Res Sales by Year (21-23)'!D64 -> 0.029210749 | E19: ='Res Sales by Year (21-23)'!E19/'Res Sales by Year (21-23)'!E64 -> 0.028802294 | F19: ='Res Sales by Year (21-23)'!F19/'Res Sales by Year (21-23)'!F64 -> 0.027102349 | G19: ='Res Sales by Year (21-23)'!G19/'Res Sales by Year (21-23)'!G64 -> 0.027922034 | H19: ='Res Sales by Year (21-23)'!H19/'Res Sales by Year (21-23)'!H64 -> 0.026923798 | I19: ='Res Sales by Year (21-23)'!I19/'Res Sales by Year (21-23)'!I64 -> 0.026149408 | J19: ='Res Sales by Year (21-23)'!J19/'Res Sales by Year (21-23)'!J64 -> 0.02534795 | K19: ='Res Sales by Year (21-23)'!K19/'Res Sales by Year (21-23)'!K64 -> 0.024563015 | ... P19: ='Res Sales by Year (21-23)'!P19/'Res Sales by Year (21-23)'!P64 -> 0.026432333
A20: =+A19+1 -> 10
A21: =+A20+1 -> 11 | B21: Austin | C21: =+C16 -> 2021 | D21: ='Res Sales by Year (21-23)'!D21/'Res Sales by Year (21-23)'!D61 -> 0.03679496 | E21: ='Res Sales by Year (21-23)'!E21/'Res Sales by Year (21-23)'!E$61 -> 0.034768476 | F21: ='Res Sales by Year (21-23)'!F21/'Res Sales by Year (21-23)'!F$61 -> 0.035169398 | G21: ='Res Sales by Year (21-23)'!G21/'Res Sales by Year (21-23)'!G$61 -> 0.04485967 | H21: ='Res Sales by Year (21-23)'!H21/'Res Sales by Year (21-23)'!H$61 -> 0.047894541 | I21: ='Res Sales by Year (21-23)'!I21/'Res Sales by Year (21-23)'!I$61 -> 0.04886508 | J21: ='Res Sales by Year (21-23)'!J21/'Res Sales by Year (21-23)'!J$61 -> 0.044693839 | K21: ='Res Sales by Year (21-23)'!K21/'Res Sales by Year (21-23)'!K$61 -> 0.04376685 | L21: ='Res Sales by Year (21-23)'!L21/'Res Sales by Year (21-23)'!L$61 -> 0.046175173 | ... P21: ='Res Sales by Year (21-23)'!P21/'Res Sales by Year (21-23)'!P$61 -> 0.042896894
A22: =+A21+1 -> 12 | B22: Austin | C22: =+C17 -> 2022 | D22: ='Res Sales by Year (21-23)'!D22/'Res Sales by Year (21-23)'!D62 -> 0.040732111 | E22: ='Res Sales by Year (21-23)'!E22/'Res Sales by Year (21-23)'!E$62 -> 0.036615922 | F22: ='Res Sales by Year (21-23)'!F22/'Res Sales by Year (21-23)'!F$62 -> 0.037997804 | G22: ='Res Sales by Year (21-23)'!G22/'Res Sales by Year (21-23)'!G$62 -> 0.043032489 | H22: ='Res Sales by Year (21-23)'!H22/'Res Sales by Year (21-23)'!H$62 -> 0.050548543 | I22: ='Res Sales by Year (21-23)'!I22/'Res Sales by Year (21-23)'!I$62 -> 0.049850177 | J22: ='Res Sales by Year (21-23)'!J22/'Res Sales by Year (21-23)'!J$62 -> 0.045939418 | K22: ='Res Sales by Year (21-23)'!K22/'Res Sales by Year (21-23)'!K$62 -> 0.044756713 | L22: ='Res Sales by Year (21-23)'!L22/'Res Sales by Year (21-23)'!L$62 -> 0.047079918 | ... P22: ='Res Sales by Year (21-23)'!P22/'Res Sales by Year (21-23)'!P$62 -> 0.044606132
A23: =+A22+1 -> 13 | B23: Austin | C23: =+C18 -> 2023 | D23: ='Res Sales by Year (21-23)'!D23/'Res Sales by Year (21-23)'!D63 -> 0.039097333 | E23: ='Res Sales by Year (21-23)'!E23/'Res Sales by Year (21-23)'!E63 -> 0.038072782 | F23: ='Res Sales by Year (21-23)'!F23/'Res Sales by Year (21-23)'!F63 -> 0.040886173 | G23: ='Res Sales by Year (21-23)'!G23/'Res Sales by Year (21-23)'!G63 -> 0.046737767 | H23: ='Res Sales by Year (21-23)'!H23/'Res Sales by Year (21-23)'!H63 -> 0.049588783 | I23: ='Res Sales by Year (21-23)'!I23/'Res Sales by Year (21-23)'!I63 -> 0.050149498 | J23: ='Res Sales by Year (21-23)'!J23/'Res Sales by Year (21-23)'!J63 -> 0.050012396 | K23: ='Res Sales by Year (21-23)'!K23/'Res Sales by Year (21-23)'!K63 -> 0.047867152 | ... P23: ='Res Sales by Year (21-23)'!P23/'Res Sales by Year (21-23)'!P63 -> 0.046243316
A24: =+A23+1 -> 14 | B24: Austin | C24: Total | D24: ='Res Sales by Year (21-23)'!D24/'Res Sales by Year (21-23)'!D64 -> 0.038781533 | E24: ='Res Sales by Year (21-23)'!E24/'Res Sales by Year (21-23)'!E64 -> 0.036488075 | F24: ='Res Sales by Year (21-23)'!F24/'Res Sales by Year (21-23)'!F64 -> 0.037751548 | G24: ='Res Sales by Year (21-23)'!G24/'Res Sales by Year (21-23)'!G64 -> 0.044824918 | H24: ='Res Sales by Year (21-23)'!H24/'Res Sales by Year (21-23)'!H64 -> 0.04941558 | I24: ='Res Sales by Year (21-23)'!I24/'Res Sales by Year (21-23)'!I64 -> 0.049661948 | J24: ='Res Sales by Year (21-23)'!J24/'Res Sales by Year (21-23)'!J64 -> 0.046927388 | K24: ='Res Sales by Year (21-23)'!K24/'Res Sales by Year (21-23)'!K64 -> 0.045564923 | ... P24: ='Res Sales by Year (21-23)'!P24/'Res Sales by Year (21-23)'!P64 -> 0.044619788
A25: =+A24+1 -> 15
A26: =+A25+1 -> 16 | B26: Killeen | C26: =+C21 -> 2021 | D26: ='Res Sales by Year (21-23)'!D26/'Res Sales by Year (21-23)'!D61 -> 0.052972425 | E26: ='Res Sales by Year (21-23)'!E26/'Res Sales by Year (21-23)'!E$61 -> 0.05229503 | F26: ='Res Sales by Year (21-23)'!F26/'Res Sales by Year (21-23)'!F$61 -> 0.055032062 | G26: ='Res Sales by Year (21-23)'!G26/'Res Sales by Year (21-23)'!G$61 -> 0.049986057 | H26: ='Res Sales by Year (21-23)'!H26/'Res Sales by Year (21-23)'!H$61 -> 0.049928964 | I26: ='Res Sales by Year (21-23)'!I26/'Res Sales by Year (21-23)'!I$61 -> 0.047212776 | J26: ='Res Sales by Year (21-23)'!J26/'Res Sales by Year (21-23)'!J$61 -> 0.043246307 | K26: ='Res Sales by Year (21-23)'!K26/'Res Sales by Year (21-23)'!K$61 -> 0.042779938 | L26: ='Res Sales by Year (21-23)'!L26/'Res Sales by Year (21-23)'!L$61 -> 0.044747013 | ... P26: ='Res Sales by Year (21-23)'!P26/'Res Sales by Year (21-23)'!P$61 -> 0.048132532
A27: =+A26+1 -> 17 | B27: Killeen | C27: =+C22 -> 2022 | D27: ='Res Sales by Year (21-23)'!D27/'Res Sales by Year (21-23)'!D62 -> 0.050196015 | E27: ='Res Sales by Year (21-23)'!E27/'Res Sales by Year (21-23)'!E$62 -> 0.055261874 | F27: ='Res Sales by Year (21-23)'!F27/'Res Sales by Year (21-23)'!F$62 -> 0.055465974 | G27: ='Res Sales by Year (21-23)'!G27/'Res Sales by Year (21-23)'!G$62 -> 0.04968784 | H27: ='Res Sales by Year (21-23)'!H27/'Res Sales by Year (21-23)'!H$62 -> 0.048470324 | I27: ='Res Sales by Year (21-23)'!I27/'Res Sales by Year (21-23)'!I$62 -> 0.04682918 | J27: ='Res Sales by Year (21-23)'!J27/'Res Sales by Year (21-23)'!J$62 -> 0.043919422 | K27: ='Res Sales by Year (21-23)'!K27/'Res Sales by Year (21-23)'!K$62 -> 0.043321463 | L27: ='Res Sales by Year (21-23)'!L27/'Res Sales by Year (21-23)'!L$62 -> 0.045595222 | ... P27: ='Res Sales by Year (21-23)'!P27/'Res Sales by Year (21-23)'!P$62 -> 0.048327669
A28: =+A27+1 -> 18 | B28: Killeen | C28: =+C23 -> 2023 | D28: ='Res Sales by Year (21-23)'!D28/'Res Sales by Year (21-23)'!D63 -> 0.053556635 | E28: ='Res Sales by Year (21-23)'!E28/'Res Sales by Year (21-23)'!E63 -> 0.053476203 | F28: ='Res Sales by Year (21-23)'!F28/'Res Sales by Year (21-23)'!F63 -> 0.051410016 | G28: ='Res Sales by Year (21-23)'!G28/'Res Sales by Year (21-23)'!G63 -> 0.050063382 | H28: ='Res Sales by Year (21-23)'!H28/'Res Sales by Year (21-23)'!H63 -> 0.048953202 | I28: ='Res Sales by Year (21-23)'!I28/'Res Sales by Year (21-23)'!I63 -> 0.047136428 | J28: ='Res Sales by Year (21-23)'!J28/'Res Sales by Year (21-23)'!J63 -> 0.046555099 | K28: ='Res Sales by Year (21-23)'!K28/'Res Sales by Year (21-23)'!K63 -> 0.044912026 | ... P28: ='Res Sales by Year (21-23)'!P28/'Res Sales by Year (21-23)'!P63 -> 0.048338801
A29: =+A28+1 -> 19 | B29: Killeen | C29: Total | D29: ='Res Sales by Year (21-23)'!D29/'Res Sales by Year (21-23)'!D64 -> 0.052350246 | E29: ='Res Sales by Year (21-23)'!E29/'Res Sales by Year (21-23)'!E64 -> 0.053723293 | F29: ='Res Sales by Year (21-23)'!F29/'Res Sales by Year (21-23)'!F64 -> 0.05415944 | G29: ='Res Sales by Year (21-23)'!G29/'Res Sales by Year (21-23)'!G64 -> 0.049904218 | H29: ='Res Sales by Year (21-23)'!H29/'Res Sales by Year (21-23)'!H64 -> 0.049078764 | I29: ='Res Sales by Year (21-23)'!I29/'Res Sales by Year (21-23)'!I64 -> 0.047041514 | J29: ='Res Sales by Year (21-23)'!J29/'Res Sales by Year (21-23)'!J64 -> 0.044598991 | K29: ='Res Sales by Year (21-23)'!K29/'Res Sales by Year (21-23)'!K64 -> 0.043724614 | ... P29: ='Res Sales by Year (21-23)'!P29/'Res Sales by Year (21-23)'!P64 -> 0.048269624
A30: =+A29+1 -> 20
A31: =+A30+1 -> 21 | B31: Longview | C31: =+C26 -> 2021 | D31: ='Res Sales by Year (21-23)'!D31/'Res Sales by Year (21-23)'!D61 -> 0.039379055 | E31: ='Res Sales by Year (21-23)'!E31/'Res Sales by Year (21-23)'!E$61 -> 0.040313441 | F31: ='Res Sales by Year (21-23)'!F31/'Res Sales by Year (21-23)'!F$61 -> 0.039095683 | G31: ='Res Sales by Year (21-23)'!G31/'Res Sales by Year (21-23)'!G$61 -> 0.038911797 | H31: ='Res Sales by Year (21-23)'!H31/'Res Sales by Year (21-23)'!H$61 -> 0.03769182 | I31: ='Res Sales by Year (21-23)'!I31/'Res Sales by Year (21-23)'!I$61 -> 0.03624571 | J31: ='Res Sales by Year (21-23)'!J31/'Res Sales by Year (21-23)'!J$61 -> 0.035691333 | K31: ='Res Sales by Year (21-23)'!K31/'Res Sales by Year (21-23)'!K$61 -> 0.035184158 | L31: ='Res Sales by Year (21-23)'!L31/'Res Sales by Year (21-23)'!L$61 -> 0.03538935 | ... P31: ='Res Sales by Year (21-23)'!P31/'Res Sales by Year (21-23)'!P$61 -> 0.037166679
A32: =+A31+1 -> 22 | B32: Longview | C32: =+C27 -> 2022 | D32: ='Res Sales by Year (21-23)'!D32/'Res Sales by Year (21-23)'!D62 -> 0.038622657 | E32: ='Res Sales by Year (21-23)'!E32/'Res Sales by Year (21-23)'!E$62 -> 0.038863627 | F32: ='Res Sales by Year (21-23)'!F32/'Res Sales by Year (21-23)'!F$62 -> 0.038916702 | G32: ='Res Sales by Year (21-23)'!G32/'Res Sales by Year (21-23)'!G$62 -> 0.03821249 | H32: ='Res Sales by Year (21-23)'!H32/'Res Sales by Year (21-23)'!H$62 -> 0.03568242 | I32: ='Res Sales by Year (21-23)'!I32/'Res Sales by Year (21-23)'!I$62 -> 0.035327466 | J32: ='Res Sales by Year (21-23)'!J32/'Res Sales by Year (21-23)'!J$62 -> 0.035142505 | K32: ='Res Sales by Year (21-23)'!K32/'Res Sales by Year (21-23)'!K$62 -> 0.034220325 | L32: ='Res Sales by Year (21-23)'!L32/'Res Sales by Year (21-23)'!L$62 -> 0.035198935 | ... P32: ='Res Sales by Year (21-23)'!P32/'Res Sales by Year (21-23)'!P$62 -> 0.036446176
A33: =+A32+1 -> 23 | B33: Longview | C33: =+C28 -> 2023 | D33: ='Res Sales by Year (21-23)'!D33/'Res Sales by Year (21-23)'!D63 -> 0.040145882 | E33: ='Res Sales by Year (21-23)'!E33/'Res Sales by Year (21-23)'!E63 -> 0.038113898 | F33: ='Res Sales by Year (21-23)'!F33/'Res Sales by Year (21-23)'!F63 -> 0.037167977 | G33: ='Res Sales by Year (21-23)'!G33/'Res Sales by Year (21-23)'!G63 -> 0.037701632 | H33: ='Res Sales by Year (21-23)'!H33/'Res Sales by Year (21-23)'!H63 -> 0.036917856 | I33: ='Res Sales by Year (21-23)'!I33/'Res Sales by Year (21-23)'!I63 -> 0.036358758 | J33: ='Res Sales by Year (21-23)'!J33/'Res Sales by Year (21-23)'!J63 -> 0.035412458 | K33: ='Res Sales by Year (21-23)'!K33/'Res Sales by Year (21-23)'!K63 -> 0.035070628 | ... P33: ='Res Sales by Year (21-23)'!P33/'Res Sales by Year (21-23)'!P63 -> 0.036617794
A34: =+A33+1 -> 24 | B34: Longview | C34: Total | D34: ='Res Sales by Year (21-23)'!D34/'Res Sales by Year (21-23)'!D64 -> 0.039423881 | E34: ='Res Sales by Year (21-23)'!E34/'Res Sales by Year (21-23)'!E64 -> 0.039091156 | F34: ='Res Sales by Year (21-23)'!F34/'Res Sales by Year (21-23)'!F64 -> 0.038490681 | G34: ='Res Sales by Year (21-23)'!G34/'Res Sales by Year (21-23)'!G64 -> 0.038257478 | H34: ='Res Sales by Year (21-23)'!H34/'Res Sales by Year (21-23)'!H64 -> 0.036702593 | I34: ='Res Sales by Year (21-23)'!I34/'Res Sales by Year (21-23)'!I64 -> 0.035932793 | J34: ='Res Sales by Year (21-23)'!J34/'Res Sales by Year (21-23)'!J64 -> 0.035399141 | K34: ='Res Sales by Year (21-23)'!K34/'Res Sales by Year (21-23)'!K64 -> 0.034795332 | ... P34: ='Res Sales by Year (21-23)'!P34/'Res Sales by Year (21-23)'!P64 -> 0.036732626
A35: =+A34+1 -> 25
A36: =+A35+1 -> 26 | B36: Waco | C36: =+C31 -> 2021 | D36: ='Res Sales by Year (21-23)'!D36/'Res Sales by Year (21-23)'!D61 -> 0.038754156 | E36: ='Res Sales by Year (21-23)'!E36/'Res Sales by Year (21-23)'!E$61 -> 0.039365293 | F36: ='Res Sales by Year (21-23)'!F36/'Res Sales by Year (21-23)'!F$61 -> 0.041153236 | G36: ='Res Sales by Year (21-23)'!G36/'Res Sales by Year (21-23)'!G$61 -> 0.037630662 | H36: ='Res Sales by Year (21-23)'!H36/'Res Sales by Year (21-23)'!H$61 -> 0.037625715 | I36: ='Res Sales by Year (21-23)'!I36/'Res Sales by Year (21-23)'!I$61 -> 0.03508072 | J36: ='Res Sales by Year (21-23)'!J36/'Res Sales by Year (21-23)'!J$61 -> 0.034519958 | K36: ='Res Sales by Year (21-23)'!K36/'Res Sales by Year (21-23)'!K$61 -> 0.034408983 | L36: ='Res Sales by Year (21-23)'!L36/'Res Sales by Year (21-23)'!L$61 -> 0.03565469 | ... P36: ='Res Sales by Year (21-23)'!P36/'Res Sales by Year (21-23)'!P$61 -> 0.037123614
A37: =+A36+1 -> 27 | B37: Waco | C37: =+C32 -> 2022 | D37: ='Res Sales by Year (21-23)'!D37/'Res Sales by Year (21-23)'!D62 -> 0.036960774 | E37: ='Res Sales by Year (21-23)'!E37/'Res Sales by Year (21-23)'!E$62 -> 0.039516785 | F37: ='Res Sales by Year (21-23)'!F37/'Res Sales by Year (21-23)'!F$62 -> 0.041315459 | G37: ='Res Sales by Year (21-23)'!G37/'Res Sales by Year (21-23)'!G$62 -> 0.039027643 | H37: ='Res Sales by Year (21-23)'!H37/'Res Sales by Year (21-23)'!H$62 -> 0.036288755 | I37: ='Res Sales by Year (21-23)'!I37/'Res Sales by Year (21-23)'!I$62 -> 0.036154804 | J37: ='Res Sales by Year (21-23)'!J37/'Res Sales by Year (21-23)'!J$62 -> 0.035333955 | K37: ='Res Sales by Year (21-23)'!K37/'Res Sales by Year (21-23)'!K$62 -> 0.035405799 | L37: ='Res Sales by Year (21-23)'!L37/'Res Sales by Year (21-23)'!L$62 -> 0.037109014 | ... P37: ='Res Sales by Year (21-23)'!P37/'Res Sales by Year (21-23)'!P$62 -> 0.037419856
A38: =+A37+1 -> 28 | B38: Waco | C38: =+C33 -> 2023 | D38: ='Res Sales by Year (21-23)'!D38/'Res Sales by Year (21-23)'!D63 -> 0.038788797 | E38: ='Res Sales by Year (21-23)'!E38/'Res Sales by Year (21-23)'!E63 -> 0.038276448 | F38: ='Res Sales by Year (21-23)'!F38/'Res Sales by Year (21-23)'!F63 -> 0.040078577 | G38: ='Res Sales by Year (21-23)'!G38/'Res Sales by Year (21-23)'!G63 -> 0.037377814 | H38: ='Res Sales by Year (21-23)'!H38/'Res Sales by Year (21-23)'!H63 -> 0.036474258 | I38: ='Res Sales by Year (21-23)'!I38/'Res Sales by Year (21-23)'!I63 -> 0.035418421 | J38: ='Res Sales by Year (21-23)'!J38/'Res Sales by Year (21-23)'!J63 -> 0.035390059 | K38: ='Res Sales by Year (21-23)'!K38/'Res Sales by Year (21-23)'!K63 -> 0.03556704 | ... P38: ='Res Sales by Year (21-23)'!P38/'Res Sales by Year (21-23)'!P63 -> 0.03699569
A39: =+A38+1 -> 29 | B39: Waco | C39: Total | D39: ='Res Sales by Year (21-23)'!D39/'Res Sales by Year (21-23)'!D64 -> 0.038231387 | E39: ='Res Sales by Year (21-23)'!E39/'Res Sales by Year (21-23)'!E64 -> 0.039066819 | F39: ='Res Sales by Year (21-23)'!F39/'Res Sales by Year (21-23)'!F64 -> 0.040905812 | G39: ='Res Sales by Year (21-23)'!G39/'Res Sales by Year (21-23)'!G64 -> 0.038050379 | H39: ='Res Sales by Year (21-23)'!H39/'Res Sales by Year (21-23)'!H64 -> 0.036764385 | I39: ='Res Sales by Year (21-23)'!I39/'Res Sales by Year (21-23)'!I64 -> 0.035600916 | J39: ='Res Sales by Year (21-23)'!J39/'Res Sales by Year (21-23)'!J64 -> 0.035106317 | K39: ='Res Sales by Year (21-23)'!K39/'Res Sales by Year (21-23)'!K64 -> 0.035176502 | ... P39: ='Res Sales by Year (21-23)'!P39/'Res Sales by Year (21-23)'!P64 -> 0.037182177
A40: =+A39+1 -> 30
A41: =+A40+1 -> 31 | B41: Abilene | C41: =+C36 -> 2021 | D41: ='Res Sales by Year (21-23)'!D41/'Res Sales by Year (21-23)'!D61 -> 0.015083512 | E41: ='Res Sales by Year (21-23)'!E41/'Res Sales by Year (21-23)'!E$61 -> 0.015057708 | F41: ='Res Sales by Year (21-23)'!F41/'Res Sales by Year (21-23)'!F$61 -> 0.0133768 | G41: ='Res Sales by Year (21-23)'!G41/'Res Sales by Year (21-23)'!G$61 -> 0.01313751 | H41: ='Res Sales by Year (21-23)'!H41/'Res Sales by Year (21-23)'!H$61 -> 0.012829095 | I41: ='Res Sales by Year (21-23)'!I41/'Res Sales by Year (21-23)'!I$61 -> 0.0125383 | J41: ='Res Sales by Year (21-23)'!J41/'Res Sales by Year (21-23)'!J$61 -> 0.011844616 | K41: ='Res Sales by Year (21-23)'!K41/'Res Sales by Year (21-23)'!K$61 -> 0.011685439 | L41: ='Res Sales by Year (21-23)'!L41/'Res Sales by Year (21-23)'!L$61 -> 0.011764979 | ... P41: ='Res Sales by Year (21-23)'!P41/'Res Sales by Year (21-23)'!P$61 -> 0.012752289
A42: =+A41+1 -> 32 | B42: Abilene | C42: =+C37 -> 2022 | D42: ='Res Sales by Year (21-23)'!D42/'Res Sales by Year (21-23)'!D62 -> 0.01422733 | E42: ='Res Sales by Year (21-23)'!E42/'Res Sales by Year (21-23)'!E$62 -> 0.014439063 | F42: ='Res Sales by Year (21-23)'!F42/'Res Sales by Year (21-23)'!F$62 -> 0.014163748 | G42: ='Res Sales by Year (21-23)'!G42/'Res Sales by Year (21-23)'!G$62 -> 0.013032998 | H42: ='Res Sales by Year (21-23)'!H42/'Res Sales by Year (21-23)'!H$62 -> 0.013184428 | I42: ='Res Sales by Year (21-23)'!I42/'Res Sales by Year (21-23)'!I$62 -> 0.013089025 | J42: ='Res Sales by Year (21-23)'!J42/'Res Sales by Year (21-23)'!J$62 -> 0.012205817 | K42: ='Res Sales by Year (21-23)'!K42/'Res Sales by Year (21-23)'!K$62 -> 0.011819666 | L42: ='Res Sales by Year (21-23)'!L42/'Res Sales by Year (21-23)'!L$62 -> 0.011834467 | ... P42: ='Res Sales by Year (21-23)'!P42/'Res Sales by Year (21-23)'!P$62 -> 0.012861276
...

Sheet Res Sales by Year (21-23)
B1: PUC DOCKET NO.
B2: ONCOR ELECTRIC DELIVERY COMPANY
B3: WEATHER WEIGHTS
B4: =+'Res Seasonal Weights'!B4:P4 -> FOR THE TEST YEAR ENDING DECEMBER 31, 2024
B6: SPONSOR: D. E. NELSON
B8: RESIDENTIAL MONTHLY KWH SALES BY YEAR
A9: Line | B9: (a) | C9: (b) | D9: (c) | E9: (d) | F9: (e) | G9: (f) | H9: (g) | I9: (h) | J9: (i) | K9: (j) | L9: (k) | M9: (l) | N9: (m) | O9: (n) | P9: (o)
A10: No. | B10: Weather Station | C10: Year | D10: 36892 | E10: 36923 | F10: 36951 | G10: 36982 | H10: 37012 | I10: 37043 | J10: 37073 | K10: 37104 | L10: 37135 | M10: 37165 | N10: 37196 | O10: 37226 | P10: Annual
A11: 1 | B11: Dallas-Fort Worth | C11: 2021 | D11: 2649047.7 | E11: 2628425.5 | F11: 2955476.1 | G11: 1691420.6 | H11: 1802675 | I11: 2285495.7 | J11: 3450447.5 | K11: 3585804.6 | L11: 3566224.3 | M11: 2727618.7 | N11: 1950158.6 | O11: 1901768.1 | P11: =SUM(D11:O11) -> 31194562
A12: =+A11+1 -> 2 | B12: Dallas-Fort Worth | C12: 2022 | D12: 2298812.6 | E12: 2848013.5 | F12: 2687233.5 | G12: 1994712.6 | H12: 2147767.5 | I12: 3008196.2 | J12: 4133907.9 | K12: 4519053.4 | L12: 3469279.2 | M12: 2693587.6 | N12: 1853723.2 | O12: 2230791.3 | P12: =SUM(D12:O12) -> 33885078
A13: =+A12+1 -> 3 | B13: Dallas-Fort Worth | C13: 2023 | D13: 2681324 | E13: 2615142.9 | F13: 2214394.9 | G13: 1834995.4 | H13: 1854909.9 | I13: 2604469.8 | J13: 3751958.6 | K13: 4331691.5 | L13: 4318988 | M13: 3069907.4 | N13: 1973351.7 | O13: 2031191.5 | P13: =SUM(D13:O13) -> 33282326
A14: =+A13+1 -> 4 | B14: Dallas-Fort Worth | C14: Total | D14: =SUM(D11:D13) -> 7629184.3 | E14: =SUM(E11:E13) -> 8091581.8 | F14: =SUM(F11:F13) -> 7857104.5 | G14: =SUM(G11:G13) -> 5521128.6 | H14: =SUM(H11:H13) -> 5805352.4 | I14: =SUM(I11:I13) -> 7898161.7 | J14: =SUM(J11:J13) -> 11336314 | K14: =SUM(K11:K13) -> 12436549 | ... O14: =SUM(O11:O13) -> 6163750.9 | P14: =SUM(D14:O14) -> 98361966
A15: =+A14+1 -> 5
A16: =+A15+1 -> 6 | B16: Lufkin | C16: =+C11 -> 2021 | D16: 116814.46 | E16: 109353.31 | F16: 115305.18 | G16: 71588.077 | H16: 73421.369 | I16: 89831.178 | J16: 125184.15 | K16: 125862.45 | L16: 127913.75 | M16: 97164.427 | N16: 77780.49 | O16: 80967.268 | P16: =SUM(D16:O16) -> 1211186.1
A17: =+A16+1 -> 7 | B17: Lufkin | C17: =+C12 -> 2022 | D17: 94467.488 | E17: 124319.57 | F17: 111631.77 | G17: 79073.288 | H17: 83231.372 | I17: 112810.97 | J17: 145314.2 | K17: 152311.85 | L17: 121946.67 | M17: 94231.393 | N17: 71700.224 | O17: 89708.82 | P17: =SUM(D17:O17) -> 1280747.6
A18: =+A17+1 -> 8 | B18: Lufkin | C18: =+C13 -> 2023 | D18: 114410.82 | E18: 107027.32 | F18: 83661.723 | G18: 73196.495 | H18: 70028.38 | I18: 94053.021 | J18: 136990.16 | K18: 151738.66 | L18: 146956.96 | M18: 103504.49 | N18: 74869.732 | O18: 86494.84 | P18: =SUM(D18:O18) -> 1242932.6
A19: =+A18+1 -> 9 | B19: Lufkin | C19: Total | D19: =SUM(D16:D18) -> 325692.77 | E19: =SUM(E16:E18) -> 340700.2 | F19: =SUM(F16:F18) -> 310598.67 | G19: =SUM(G16:G18) -> 223857.86 | H19: =SUM(H16:H18) -> 226681.12 | I19: =SUM(I16:I18) -> 296695.17 | J19: =SUM(J16:J18) -> 407488.51 | K19: =SUM(K16:K18) -> 429912.96 | ... O19: =SUM(O16:O18) -> 257170.93 | P19: =SUM(D19:O19) -> 3734866.3
A20: =+A19+1 -> 10
A21: =+A20+1 -> 11 | B21: Austin | C21: =+C16 -> 2021 | D21: 143169.29 | E21: 133280.69 | F21: 151162.55 | G21: 110446.74 | H21: 125598.07 | I21: 161206.73 | J21: 217526.07 | K21: 219715.82 | L21: 232378.39 | M21: 179617.4 | N21: 128308.21 | O21: 117823.4 | P21: =SUM(D21:O21) -> 1920233.4
A22: =+A21+1 -> 12 | B22: Austin | C22: =+C17 -> 2022 | D22: 135479.41 | E22: 152779.49 | F22: 149341.23 | G22: 124405.31 | H22: 157197.98 | I22: 215591.08 | J22: 267408.96 | K22: 283618.91 | L22: 231761.51 | M22: 188109.73 | N22: 130057.36 | O22: 133114.06 | P22: =SUM(D22:O22) -> 2168865
A23: =+A22+1 -> 13 | B23: Austin | C23: =+C18 -> 2023 | D23: 153755.99 | E23: 145554.55 | F23: 132136.97 | G23: 124520.41 | H23: 133251.46 | I23: 186674.22 | J23: 269460.16 | K23: 294163.11 | L23: 291443.92 | M23: 221074.24 | N23: 138767.59 | O23: 124837.4 | P23: =SUM(D23:O23) -> 2215640
A24: =+A23+1 -> 14 | B24: Austin | C24: Total | D24: =SUM(D21:D23) -> 432404.69 | E24: =SUM(E21:E23) -> 431614.73 | F24: =SUM(F21:F23) -> 432640.75 | G24: =SUM(G21:G23) -> 359372.46 | H24: =SUM(H21:H23) -> 416047.51 | I24: =SUM(I21:I23) -> 563472.03 | J24: =SUM(J21:J23) -> 754395.19 | K24: =SUM(K21:K23) -> 797497.84 | ... O24: =SUM(O21:O23) -> 375774.86 | P24: =SUM(D24:O24) -> 6304738.4
A25: =+A24+1 -> 15
A26: =+A25+1 -> 16 | B26: Killeen | C26: =+C21 -> 2021 | D26: 206115.85 | E26: 200466.6 | F26: 236534.8 | G26: 123068.16 | H26: 130933.11 | I26: 155755.75 | J26: 210480.89 | K26: 214761.38 | L26: 225191.12 | M26: 178577.72 | N26: 134426.1 | O26: 138289.63 | P26: =SUM(D26:O26) -> 2154601.1
A27: =+A26+1 -> 17 | B27: Killeen | C27: =+C22 -> 2022 | D27: 166957.38 | E27: 230579.5 | F27: 217995.68 | G27: 143645.68 | H27: 150735.05 | I27: 202525.93 | J27: 255650.76 | K27: 274523.87 | L27: 224452.76 | M27: 180864.42 | N27: 133415.58 | O27: 168469.13 | P27: =SUM(D27:O27) -> 2349815.7
A28: =+A27+1 -> 18 | B28: Killeen | C28: =+C23 -> 2023 | D28: 210619.31 | E28: 204442.76 | F28: 166148.2 | G28: 133380.63 | H28: 131543.57 | I28: 175458.5 | J28: 250832.7 | K28: 276002.67 | L28: 270992.4 | M28: 204632.86 | N28: 141842.11 | O28: 150144.59 | P28: =SUM(D28:O28) -> 2316040.3
A29: =+A28+1 -> 19 | B29: Killeen | C29: Total | D29: =SUM(D26:D28) -> 583692.55 | E29: =SUM(E26:E28) -> 635488.85 | F29: =SUM(F26:F28) -> 620678.68 | G29: =SUM(G26:G28) -> 400094.47 | H29: =SUM(H26:H28) -> 413211.74 | I29: =SUM(I26:I28) -> 533740.18 | J29: =SUM(J26:J28) -> 716964.35 | K29: =SUM(K26:K28) -> 765287.92 | ... O29: =SUM(O26:O28) -> 456903.34 | P29: =SUM(D29:O29) -> 6820457.1
A30: =+A29+1 -> 20
A31: =+A30+1 -> 21 | B31: Longview | C31: =+C26 -> 2021 | D31: 153224.01 | E31: 154536.64 | F31: 168038.22 | G31: 95802.779 | H31: 98842.575 | I31: 119575.21 | J31: 173710.64 | K31: 176629.48 | L31: 178098.31 | M31: 134631.59 | N31: 102165.63 | O31: 108471.37 | P31: =SUM(D31:O31) -> 1663726.5
A32: =+A31+1 -> 22 | B32: Longview | C32: =+C27 -> 2022 | D32: 128463.14 | E32: 162158.01 | F32: 152952.74 | G32: 110470.88 | H32: 110966.69 | I32: 152783.54 | J32: 204561.16 | K32: 216850.85 | L32: 173274.69 | M32: 134303.87 | N32: 99438.698 | O32: 125882.66 | P32: =SUM(D32:O32) -> 1772106.9
A33: =+A32+1 -> 23 | B33: Longview | C33: =+C28 -> 2023 | D33: 157879.56 | E33: 145711.74 | F33: 120120.42 | G33: 100446.02 | H33: 99203.043 | I33: 135340.19 | J33: 190797.63 | K33: 215523.27 | L33: 215466.84 | M33: 151818.39 | N33: 103970.89 | O33: 118177.74 | P33: =SUM(D33:O33) -> 1754455.7
A34: =+A33+1 -> 24 | B34: Longview | C34: Total | D34: =SUM(D31:D33) -> 439566.72 | E34: =SUM(E31:E33) -> 462406.39 | F34: =SUM(F31:F33) -> 441111.37 | G34: =SUM(G31:G33) -> 306719.67 | H34: =SUM(H31:H33) -> 309012.31 | I34: =SUM(I31:I33) -> 407698.95 | J34: =SUM(J31:J33) -> 569069.43 | K34: =SUM(K31:K33) -> 609003.61 | ... O34: =SUM(O31:O33) -> 352531.77 | P34: =SUM(D34:O34) -> 5190289.1
A35: =+A34+1 -> 25
A36: =+A35+1 -> 26 | B36: Waco | C36: =+C31 -> 2021 | D36: 150792.53 | E36: 150902.03 | F36: 176881.84 | G36: 92648.562 | H36: 98669.222 | I36: 115731.89 | J36: 168009.53 | K36: 172738 | L36: 179433.64 | M36: 145767.52 | N36: 106642.34 | O36: 103581.59 | P36: =SUM(D36:O36) -> 1661798.7
A37: =+A36+1 -> 27 | B37: Waco | C37: =+C32 -> 2022 | D37: 122935.54 | E37: 164883.3 | F37: 162380.48 | G37: 112827.45 | H37: 112852.3 | I37: 156361.6 | J37: 205675.58 | K37: 224363.08 | L37: 182677.48 | M37: 147473.75 | N37: 101608.2 | O37: 125411.03 | P37: =SUM(D37:O37) -> 1819449.8
A38: =+A37+1 -> 28 | B38: Waco | C38: =+C33 -> 2023 | D38: 152542.63 | E38: 146333.18 | F38: 129526.97 | G38: 99583.292 | H38: 98011.038 | I38: 131839.92 | J38: 190676.95 | K38: 218573.92 | L38: 219305.45 | M38: 165363.25 | N38: 107946.3 | O38: 112858.82 | P38: =SUM(D38:O38) -> 1772561.7
A39: =+A38+1 -> 29 | B39: Waco | C39: Total | D39: =SUM(D36:D38) -> 426270.69 | E39: =SUM(E36:E38) -> 462118.51 | F39: =SUM(F36:F38) -> 468789.29 | G39: =SUM(G36:G38) -> 305059.31 | H39: =SUM(H36:H38) -> 309532.55 | I39: =SUM(I36:I38) -> 403933.41 | J39: =SUM(J36:J38) -> 564362.05 | K39: =SUM(K36:K38) -> 615675 | ... O39: =SUM(O36:O38) -> 341851.44 | P39: =SUM(D39:O39) -> 5253810.2
A40: =+A39+1 -> 30
A41: =+A40+1 -> 31 | B41: Abilene | C41: =+C36 -> 2021 | D41: 58689.987 | E41: 57721.881 | F41: 57495.187 | G41: 32345.204 | H41: 33642.864 | I41: 41364.063 | J41: 57648.052 | K41: 58662.567 | L41: 59207.723 | M41: 44042.224 | N41: 33120.328 | O41: 36902.454 | P41: =SUM(D41:O41) -> 570842.53
A42: =+A41+1 -> 32 | B42: Abilene | C42: =+C37 -> 2022 | D42: 47321.642 | E42: 60246.814 | F42: 55667.205 | G42: 37677.91 | H42: 41001.487 | I42: 56607.163 | J42: 71048.896 | K42: 74900.063 | L42: 58257.832 | M42: 44315.624 | N42: 32411.586 | O42: 45892.136 | P42: =SUM(D42:O42) -> 625348.36
...
