Workbook
Name a: #REF!
Name HOURLY: [1]HOURLY!$A$1:$G$745
Name rngBilled: OFFSET([2]Sheet2!$A$2,0,0,[2]Sheet2!$B$1,9)
Name rngYear: OFFSET('[3]Daily Actual_August'!$A$2,0,0,'[3]Daily Actual_August'!$C$1,8)

Sheet RES Spline Model
B1: 2025 RATE CASE
B2: ONCOR ELECTRIC DELIVERY COMPANY LLC
B3: ADJUSTED WEATHER STATION DATA
B4: FOR THE TEST YEAR ENDING DECEMBER 31, 2024
B6: SPONSOR: D. E. NELSON
A8: Line
A9: No. | B9: (a) | C9: (b) | D9: (c) | E9: (d) | F9: (e)
A10: 1 | B10: Model: | C10: Residential Spline
A11: =+A10+1 -> 2 | B11: After Corrective Procedures for Autocorrelation
A12: =+A11+1 -> 3 | B12: Dependent Variable: | C12: ResDMWH
A13: =+A12+1 -> 4 | B13: Estimation Begin Date: | C13: 44197
A14: =+A13+1 -> 5 | B14: Estimation End Date: | C14: 45291
A15: =+A14+1 -> 6
A16: =+A15+1 -> 7 | B16: Variable | C16: Coefficient | D16: StdErr | E16: T-Stat | F16: P-Value
A17: =+A16+1 -> 8 | B17: CONST | C17: 93642.033 | D17: 1293.857 | E17: 72.374 | F17: 0
A18: =+A17+1 -> 9 | B18: Calendar.DLSav | C18: -3685.517 | D18: 1258.62 | E18: -2.928 | F18: 0.0035
A19: =+A18+1 -> 10 | B19: Calendar.Monday | C19: -5122.9 | D19: 585.524 | E19: -8.749 | F19: 0
A20: =+A19+1 -> 11 | B20: Calendar.Tuesday | C20: -7372.965 | D20: 654.308 | E20: -11.268 | F20: 0
A21: =+A20+1 -> 12 | B21: Calendar.Wednesday | C21: -7157.421 | D21: 616.309 | E21: -11.613 | F21: 0
A22: =+A21+1 -> 13 | B22: Calendar.Thursday | C22: -7215.614 | D22: 619.351 | E22: -11.65 | F22: 0
A23: =+A22+1 -> 14 | B23: Calendar.Friday | C23: -7804.106 | D23: 653.118 | E23: -11.949 | F23: 0
A24: =+A23+1 -> 15 | B24: Calendar.Saturday | C24: -3797.555 | D24: 574.65 | E24: -6.608 | F24: 0
A25: =+A24+1 -> 16 | B25: Calendar.PresDay | C25: -5474.021 | D25: 3555.631 | E25: -1.54 | F25: 0.124
A26: =+A25+1 -> 17 | B26: Calendar.MemDay | C26: 4062.718 | D26: 2920.158 | E26: 1.391 | F26: 0.1645
A27: =+A26+1 -> 18 | B27: Calendar.LaborDay | C27: 10509.441 | D27: 2869.362 | E27: 3.663 | F27: 0.0003
A28: =+A27+1 -> 19 | B28: Calendar.Thanks | C28: 5994.476 | D28: 2892.652 | E28: 2.072 | F28: 0.0385
... A71: =+A70+1 -> 62 | B71: MA(20) | C71: -0.067 | D71: 0.032 | E71: -2.115 | F71: 0.0346
A72: =+A71+1 -> 63
A73: =+A72+1 -> 64 | B73: Model Statistics
A74: =+A73+1 -> 65 | B74: Adjusted Observations | C74: 1095
A75: =+A74+1 -> 66 | B75: Deg. of Freedom for Error | C75: 1040
A76: =+A75+1 -> 67 | B76: R-Squared | C76: 0.986
A77: =+A76+1 -> 68 | B77: Adjusted R-Squared | C77: 0.986
A78: =+A77+1 -> 69 | B78: F-Statistic | C78: 1390.507
A79: =+A78+1 -> 70 | B79: Prob (F-Statistic) | C79: 0
A80: =+A79+1 -> 71 | B80: Model Sum of Squares | C80: 2.3143919e+12
A81: =+A80+1 -> 72 | B81: Sum of Squared Errors | C81: 3.205555e+10
A82: =+A81+1 -> 73 | B82: Mean Squared Error | C82: 30822644
A83: =+A82+1 -> 74 | B83: Std. Error of Regression | C83: 5551.81
A84: =+A83+1 -> 75 | B84: Mean Abs. Dev. (MAD) | C84: 4084.7
...

Sheet RES Spline Graph
B1: 2025 RATE CASE
B2: ONCOR ELECTRIC DELIVERY COMPANY LLC
B3: ADJUSTED WEATHER STATION DATA
B4: FOR THE TEST YEAR ENDING DECEMBER 31, 2024
B6: SPONSOR: D. E. NELSON
A8: Line
A9: No.
A10: 1 | B10: Residential Spline Model
A11: =+A10+1 -> 2 | B11: After Corrective Procedures for Autocorrelation
A12: =+A11+1 -> 3
A13: =+A12+1 -> 4
A14: =+A13+1 -> 5
A15: =+A14+1 -> 6
A16: =+A15+1 -> 7
A17: =+A16+1 -> 8
A18: =+A17+1 -> 9
A19: =+A18+1 -> 10
A20: =+A19+1 -> 11
A21: =+A20+1 -> 12
A22: =+A21+1 -> 13
A23: =+A22+1 -> 14
... A37: =+A36+1 -> 28

Sheet GSS Spline Model
B1: 2025 RATE CASE
B2: ONCOR ELECTRIC DELIVERY COMPANY LLC
B3: ADJUSTED WEATHER STATION DATA
B4: FOR THE TEST YEAR ENDING DECEMBER 31, 2024
B6: SPONSOR: D. E. NELSON
A8: Line
A9: No. | B9: (a) | C9: (b) | D9: (c) | E9: (d) | F9: (e)
A10: 1 | B10: Model: | C10: Secondary Service Less Than or Equal to 10 KW Spline
A11: =+A10+1 -> 2 | B11: After Corrective Procedures for Autocorrelation
A12: =+A11+1 -> 3 | B12: Dependent Variable: | C12: GSSDMWH
A13: =+A12+1 -> 4 | B13: Estimation Begin Date: | C13: =+'RES Spline Model'!C13 -> 44197
A14: =+A13+1 -> 5 | B14: Estimation End Date: | C14: =+'RES Spline Model'!C14 -> 45291
A15: =+A14+1 -> 6
A16: =+A15+1 -> 7 | B16: Variable | C16: Coefficient | D16: StdErr | E16: T-Stat | F16: P-Value
A17: =+A16+1 -> 8 | B17: CONST | C17: 5578.587 | D17: 729.687 | E17: 7.645 | F17: 0
A18: =+A17+1 -> 9 | B18: Calendar.DLSav | C18: -184.565 | D18: 40.753 | E18: -4.529 | F18: 0
A19: =+A18+1 -> 10 | B19: Calendar.Monday | C19: 464.999 | D19: 12.139 | E19: 38.306 | F19: 0
A20: =+A19+1 -> 11 | B20: Calendar.Tuesday | C20: 495.822 | D20: 16.413 | E20: 30.208 | F20: 0
A21: =+A20+1 -> 12 | B21: Calendar.Wednesday | C21: 514.886 | D21: 17.364 | E21: 29.652 | F21: 0
A22: =+A21+1 -> 13 | B22: Calendar.Thursday | C22: 517.986 | D22: 17.399 | E22: 29.772 | F22: 0
A23: =+A22+1 -> 14 | B23: Calendar.Friday | C23: 494.474 | D23: 16.463 | E23: 30.035 | F23: 0
A24: =+A23+1 -> 15 | B24: Calendar.Saturday | C24: 203.804 | D24: 11.932 | E24: 17.08 | F24: 0
A25: =+A24+1 -> 16 | B25: Calendar.PresDay | C25: -150.07 | D25: 61.137 | E25: -2.455 | F25: 0.0143
A26: =+A25+1 -> 17 | B26: Calendar.GoodFri | C26: -94.861 | D26: 48.832 | E26: -1.943 | F26: 0.0523
A27: =+A26+1 -> 18 | B27: Calendar.MemDay | C27: -423.31 | D27: 49.808 | E27: -8.499 | F27: 0
A28: =+A27+1 -> 19 | B28: Calendar.July4th | C28: -491.618 | D28: 48.615 | E28: -10.112 | F28: 0
... A73: =+A72+1 -> 64 | B73: AR(21) | C73: 0.085 | D73: 0.031 | E73: 2.716 | F73: 0.0067
A74: =+A73+1 -> 65
A75: =+A74+1 -> 66 | B75: Model Statistics
A76: =+A75+1 -> 67 | B76: Adjusted Observations | C76: 1074
A77: =+A76+1 -> 68 | B77: Deg. of Freedom for Error | C77: 1017
A78: =+A77+1 -> 69 | B78: R-Squared | C78: 0.981
A79: =+A78+1 -> 70 | B79: Adjusted R-Squared | C79: 0.98
A80: =+A79+1 -> 71 | B80: F-Statistic | C80: 936.205
A81: =+A80+1 -> 72 | B81: Prob (F-Statistic) | C81: 0
A82: =+A81+1 -> 73 | B82: Model Sum of Squares | C82: 6.2410988e+08
A83: =+A82+1 -> 74 | B83: Sum of Squared Errors | C83: 12106617
A84: =+A83+1 -> 75 | B84: Mean Squared Error | C84: 11904.24
A85: =+A84+1 -> 76 | B85: Std. Error of Regression | C85: 109.11
A86: =+A85+1 -> 77 | B86: Mean Abs. Dev. (MAD) | C86: 76.99
...

Sheet GSS Spline Graph
B1: =+'RES Spline Model'!B1:F1 -> 2025 RATE CASE
B2: =+'RES Spline Model'!B2:F2 -> ONCOR ELECTRIC DELIVERY COMPANY LLC
B3: =+'RES Spline Model'!B3:F3 -> ADJUSTED WEATHER STATION DATA
B4: =+'RES Spline Model'!B4:F4 -> FOR THE TEST YEAR ENDING DECEMBER 31, 2024
B6: =+'RES Spline Model'!B6:F6 -> SPONSOR: D. E. NELSON
A8: Line
A9: No.
A10: 1 | B10: Secondary Service Less Than or Equal to 10 KW Spline Model
A11: =+A10+1 -> 2 | B11: =+'RES Spline Graph'!B11 -> After Corrective Procedures for Autocorrelation
A12: =+A11+1 -> 3
A13: =+A12+1 -> 4
A14: =+A13+1 -> 5
A15: =+A14+1 -> 6
A16: =+A15+1 -> 7
A17: =+A16+1 -> 8
A18: =+A17+1 -> 9
A19: =+A18+1 -> 10
A20: =+A19+1 -> 11
A21: =+A20+1 -> 12
A22: =+A21+1 -> 13
A23: =+A22+1 -> 14
... A37: =+A36+1 -> 28

Sheet GSL Spline Model
B1: =+'RES Spline Model'!B1:F1 -> 2025 RATE CASE
B2: =+'RES Spline Model'!B2:F2 -> ONCOR ELECTRIC DELIVERY COMPANY LLC
B3: =+'RES Spline Model'!B3:F3 -> ADJUSTED WEATHER STATION DATA
B4: =+'RES Spline Model'!B4:F4 -> FOR THE TEST YEAR ENDING DECEMBER 31, 2024
B6: =+'RES Spline Model'!B6:F6 -> SPONSOR: D. E. NELSON
A8: Line
A9: No. | B9: (a) | C9: (b) | D9: (c) | E9: (d) | F9: (e)
A10: 1 | B10: Model: | C10: Secondary Service Greater Than 10 KW Spline
A11: =+A10+1 -> 2 | B11: After Corrective Procedures for Autocorrelation
A12: =+A11+1 -> 3 | B12: Dependent Variable: | C12: GSLDMWH
A13: =+A12+1 -> 4 | B13: Estimation Begin Date: | C13: =+'RES Spline Model'!C13 -> 44197
A14: =+A13+1 -> 5 | B14: Estimation End Date: | C14: =+'RES Spline Model'!C14 -> 45291
A15: =+A14+1 -> 6
A16: =+A15+1 -> 7 | B16: Variable | C16: Coefficient | D16: StdErr | E16: T-Stat | F16: P-Value
A17: =+A16+1 -> 8 | B17: CONST | C17: 81946.314 | D17: 1768.148 | E17: 46.346 | F17: 0
A18: =+A17+1 -> 9 | B18: Calendar.DLSav | C18: -1701.265 | D18: 659.858 | E18: -2.578 | F18: 0.0101
A19: =+A18+1 -> 10 | B19: Calendar.Monday | C19: 21167.76 | D19: 308.968 | E19: 68.511 | F19: 0
A20: =+A19+1 -> 11 | B20: Calendar.Tuesday | C20: 22827.116 | D20: 458.044 | E20: 49.836 | F20: 0
A21: =+A20+1 -> 12 | B21: Calendar.Wednesday | C21: 23571.549 | D21: 530.46 | E21: 44.436 | F21: 0
A22: =+A21+1 -> 13 | B22: Calendar.Thursday | C22: 23261.846 | D22: 531.015 | E22: 43.806 | F22: 0
A23: =+A22+1 -> 14 | B23: Calendar.Friday | C23: 21530.765 | D23: 458.455 | E23: 46.964 | F23: 0
A24: =+A23+1 -> 15 | B24: Calendar.Saturday | C24: 6066.646 | D24: 301.995 | E24: 20.089 | F24: 0
A25: =+A24+1 -> 16 | B25: Calendar.MLK | C25: -6742.509 | D25: 1536.235 | E25: -4.389 | F25: 0
A26: =+A25+1 -> 17 | B26: Calendar.PresDay | C26: -6237.076 | D26: 1565.048 | E26: -3.985 | F26: 0.0001
A27: =+A26+1 -> 18 | B27: Calendar.GoodFri | C27: -7019.318 | D27: 1239.073 | E27: -5.665 | F27: 0
A28: =+A27+1 -> 19 | B28: Calendar.MemDay | C28: -17447.44 | D28: 1270.665 | E28: -13.731 | F28: 0
... A78: =+A77+1 -> 69 | B78: AR(20) | C78: 0.061 | D78: 0.031 | E78: 1.963 | F78: 0.0499
A79: =+A78+1 -> 70
A80: =+A79+1 -> 71 | B80: Model Statistics
A81: =+A80+1 -> 72 | B81: Adjusted Observations | C81: 1075
A82: =+A81+1 -> 73 | B82: Deg. of Freedom for Error | C82: 1013
A83: =+A82+1 -> 74 | B83: R-Squared | C83: 0.987
A84: =+A83+1 -> 75 | B84: Adjusted R-Squared | C84: 0.987
A85: =+A84+1 -> 76 | B85: F-Statistic | C85: 1293.41
A86: =+A85+1 -> 77 | B86: Prob (F-Statistic) | C86: 0
A87: =+A86+1 -> 78 | B87: Model Sum of Squares | C87: 5.4597689e+11
A88: =+A87+1 -> 79 | B88: Sum of Squared Errors | C88: 7.0099964e+09
A89: =+A88+1 -> 80 | B89: Mean Squared Error | C89: 6920035.9
A90: =+A89+1 -> 81 | B90: Std. Error of Regression | C90: 2630.6
A91: =+A90+1 -> 82 | B91: Mean Abs. Dev. (MAD) | C91: 1816.8
...

Sheet GSL Spline Graph
B1: =+'RES Spline Model'!B1:F1 -> 2025 RATE CASE
B2: =+'RES Spline Model'!B2:F2 -> ONCOR ELECTRIC DELIVERY COMPANY LLC
B3: =+'RES Spline Model'!B3:F3 -> ADJUSTED WEATHER STATION DATA
B4: =+'RES Spline Model'!B4:F4 -> FOR THE TEST YEAR ENDING DECEMBER 31, 2024
B6: =+'RES Spline Model'!B6:F6 -> SPONSOR: D. E. NELSON
A8: Line
A9: No.
A10: 1 | B10: Secondary Service Greater Than 10 KW Spline Model
A11: =+A10+1 -> 2 | B11: =+'RES Spline Graph'!B11 -> After Corrective Procedures for Autocorrelation
A12: =+A11+1 -> 3
A13: =+A12+1 -> 4
A14: =+A13+1 -> 5
A15: =+A14+1 -> 6
A16: =+A15+1 -> 7
A17: =+A16+1 -> 8
A18: =+A17+1 -> 9
A19: =+A18+1 -> 10
A20: =+A19+1 -> 11
A21: =+A20+1 -> 12
A22: =+A21+1 -> 13
A23: =+A22+1 -> 14
... A37: =+A36+1 -> 28

Sheet GPLD Spline Model
B1: =+'RES Spline Model'!B1:F1 -> 2025 RATE CASE
B2: =+'RES Spline Model'!B2:F2 -> ONCOR ELECTRIC DELIVERY COMPANY LLC
B3: =+'RES Spline Model'!B3:F3 -> ADJUSTED WEATHER STATION DATA
B4: =+'RES Spline Model'!B4:F4 -> FOR THE TEST YEAR ENDING DECEMBER 31, 2024
B6: =+'RES Spline Model'!B6:F6 -> SPONSOR: D. E. NELSON
A8: Line
A9: No. | B9: (a) | C9: (b) | D9: (c) | E9: (d) | F9: (e)
A10: 1 | B10: Model: | C10: Primary Service Greater Than 10 KW Distribution Spline
A11: =+A10+1 -> 2 | B11: After Corrective Procedures for Autocorrelation
A12: =+A11+1 -> 3 | B12: Dependent Variable: | C12: GPLDDMWH
A13: =+A12+1 -> 4 | B13: Estimation Begin Date: | C13: =+'RES Spline Model'!C13 -> 44197
A14: =+A13+1 -> 5 | B14: Estimation End Date: | C14: =+'RES Spline Model'!C14 -> 45291
A15: =+A14+1 -> 6
A16: =+A15+1 -> 7 | B16: Variable | C16: Coefficient | D16: StdErr | E16: T-Stat | F16: P-Value
A17: =+A16+1 -> 8 | B17: CONST | C17: 21193.792 | D17: 2052.19 | E17: 10.327 | F17: 0
A18: =+A17+1 -> 9 | B18: Calendar.DLSav | C18: -1525.587 | D18: 259.694 | E18: -5.875 | F18: 0
A19: =+A18+1 -> 10 | B19: Calendar.Monday | C19: 2258.141 | D19: 60.68 | E19: 37.214 | F19: 0
A20: =+A19+1 -> 11 | B20: Calendar.Tuesday | C20: 2655.095 | D20: 87.244 | E20: 30.433 | F20: 0
A21: =+A20+1 -> 12 | B21: Calendar.Wednesday | C21: 2652.641 | D21: 99.387 | E21: 26.69 | F21: 0
A22: =+A21+1 -> 13 | B22: Calendar.Thursday | C22: 2714.145 | D22: 99.515 | E22: 27.274 | F22: 0
A23: =+A22+1 -> 14 | B23: Calendar.Friday | C23: 2437.159 | D23: 87.551 | E23: 27.837 | F23: 0
A24: =+A23+1 -> 15 | B24: Calendar.Saturday | C24: 764.341 | D24: 59.262 | E24: 12.898 | F24: 0
A25: =+A24+1 -> 16 | B25: Calendar.MLK | C25: -490.955 | D25: 279.099 | E25: -1.759 | F25: 0.0789
A26: =+A25+1 -> 17 | B26: Calendar.GoodFri | C26: -496.174 | D26: 278.362 | E26: -1.782 | F26: 0.075
A27: =+A26+1 -> 18 | B27: Calendar.MemDay | C27: -2766.51 | D27: 279.168 | E27: -9.91 | F27: 0
A28: =+A27+1 -> 19 | B28: Calendar.July4th | C28: -2103.734 | D28: 275.97 | E28: -7.623 | F28: 0
... A61: =+A60+1 -> 52 | B61: AR(6) | C61: 0.066 | D61: 0.031 | E61: 2.128 | F61: 0.0336
A62: =+A61+1 -> 53
A63: =+A62+1 -> 54 | B63: Model Statistics
A64: =+A63+1 -> 55 | B64: Adjusted Observations | C64: 1089
A65: =+A64+1 -> 56 | B65: Deg. of Freedom for Error | C65: 1044
A66: =+A65+1 -> 57 | B66: R-Squared | C66: 0.987
A67: =+A66+1 -> 58 | B67: Adjusted R-Squared | C67: 0.986
A68: =+A67+1 -> 59 | B68: F-Statistic | C68: 1803.288
A69: =+A68+1 -> 60 | B69: Prob (F-Statistic) | C69: 0
A70: =+A69+1 -> 61 | B70: Model Sum of Squares | C70: 3.6923759e+10
A71: =+A70+1 -> 62 | B71: Sum of Squared Errors | C71: 485834687
A72: =+A71+1 -> 63 | B72: Mean Squared Error | C72: 465358.9
A73: =+A72+1 -> 64 | B73: Std. Error of Regression | C73: 682.17
A74: =+A73+1 -> 65 | B74: Mean Abs. Dev. (MAD) | C74: 464.11
...

Sheet GPLD Spline Graph
B1: =+'RES Spline Model'!B1:F1 -> 2025 RATE CASE
B2: =+'RES Spline Model'!B2:F2 -> ONCOR ELECTRIC DELIVERY COMPANY LLC
B3: =+'RES Spline Model'!B3:F3 -> ADJUSTED WEATHER STATION DATA
B4: =+'RES Spline Model'!B4:F4 -> FOR THE TEST YEAR ENDING DECEMBER 31, 2024
B6: =+'RES Spline Model'!B6:F6 -> SPONSOR: D. E. NELSON
A8: Line
A9: No.
A10: 1 | B10: Primary Service Greater Than 10 KW Distribution Spline Model
A11: =+A10+1 -> 2 | B11: =+'RES Spline Graph'!B11:H11 -> After Corrective Procedures for Autocorrelation
A12: =+A11+1 -> 3
A13: =+A12+1 -> 4
A14: =+A13+1 -> 5
A15: =+A14+1 -> 6
A16: =+A15+1 -> 7
A17: =+A16+1 -> 8
A18: =+A17+1 -> 9
A19: =+A18+1 -> 10
A20: =+A19+1 -> 11
A21: =+A20+1 -> 12
A22: =+A21+1 -> 13
A23: =+A22+1 -> 14
... A37: =+A36+1 -> 28

Sheet SUBS Spline Model
B1: =+'RES Spline Model'!B1:F1 -> 2025 RATE CASE
B2: =+'RES Spline Model'!B2:F2 -> ONCOR ELECTRIC DELIVERY COMPANY LLC
B3: =+'RES Spline Model'!B3:F3 -> ADJUSTED WEATHER STATION DATA
B4: =+'RES Spline Model'!B4:F4 -> FOR THE TEST YEAR ENDING DECEMBER 31, 2024
B6: =+'RES Spline Model'!B6:F6 -> SPONSOR: D. E. NELSON
A8: Line
A9: No. | B9: (a) | C9: (b) | D9: (c) | E9: (d) | F9: (e)
A10: 1 | B10: Model: | C10: Substation Spline
A11: =+A10+1 -> 2 | B11: After Corrective Procedures for Autocorrelation
A12: =+A11+1 -> 3 | B12: Dependent Variable: | C12: SUBSDMWH
A13: =+A12+1 -> 4 | B13: Estimation Begin Date: | C13: =+'RES Spline Model'!C13 -> 44197
A14: =+A13+1 -> 5 | B14: Estimation End Date: | C14: =+'RES Spline Model'!C14 -> 45291
A15: =+A14+1 -> 6
A16: =+A15+1 -> 7 | B16: Variable | C16: Coefficient | D16: StdErr | E16: T-Stat | F16: P-Value
A17: =+A16+1 -> 8 | B17: CONST | C17: -888.388 | D17: 3380.665 | E17: -0.263 | F17: 0.7928
A18: =+A17+1 -> 9 | B18: Calendar.DLSav | C18: -399.866 | D18: 157.741 | E18: -2.535 | F18: 0.0114
A19: =+A18+1 -> 10 | B19: Calendar.Monday | C19: 182.492 | D19: 38.128 | E19: 4.786 | F19: 0
A20: =+A19+1 -> 11 | B20: Calendar.Tuesday | C20: 110.558 | D20: 51.011 | E20: 2.167 | F20: 0.0304
A21: =+A20+1 -> 12 | B21: Calendar.Wednesday | C21: 181.237 | D21: 55.545 | E21: 3.263 | F21: 0.0012
A22: =+A21+1 -> 13 | B22: Calendar.Thursday | C22: 158.209 | D22: 55.474 | E22: 2.852 | F22: 0.0044
A23: =+A22+1 -> 14 | B23: Calendar.Friday | C23: 141.709 | D23: 50.803 | E23: 2.789 | F23: 0.0054
A24: =+A23+1 -> 15 | B24: Calendar.Saturday | C24: 68.243 | D24: 37.563 | E24: 1.817 | F24: 0.0695
A25: =+A24+1 -> 16 | B25: Calendar.MemDay | C25: -408.579 | D25: 189.091 | E25: -2.161 | F25: 0.0309
A26: =+A25+1 -> 17 | B26: Calendar.July4th | C26: -284.33 | D26: 188.037 | E26: -1.512 | F26: 0.1308
A27: =+A26+1 -> 18 | B27: Calendar.XMasWkB4 | C27: 1382.698 | D27: 347.48 | E27: 3.979 | F27: 0.0001
A28: =+A27+1 -> 19 | B28: Calendar.XMasEve | C28: -807.537 | D28: 205.221 | E28: -3.935 | F28: 0.0001
... A48: =+A47+1 -> 39 | B48: AR(2) | C48: -0.081 | D48: 0.039 | E48: -2.05 | F48: 0.0406
B49: AR(3) | C49: 0.129 | D49: 0.04 | E49: 3.262 | F49: 0.0012
B50: AR(4) | C50: -0.071 | D50: 0.04 | E50: -1.773 | F50: 0.0765
B51: AR(5) | C51: 0.081 | D51: 0.04 | E51: 2.034 | F51: 0.0422
B52: AR(6) | C52: 0.043 | D52: 0.04 | E52: 1.091 | F52: 0.2754
B53: AR(7) | C53: 0.079 | D53: 0.031 | E53: 2.549 | F53: 0.0109
A54: =+A48+1 -> 40
A55: =+A54+1 -> 41 | B55: Model Statistics
A56: =+A55+1 -> 42 | B56: Adjusted Observations | C56: 1088
A57: =+A56+1 -> 43 | B57: Deg. of Freedom for Error | C57: 1051
A58: =+A57+1 -> 44 | B58: R-Squared | C58: 0.986
A59: =+A58+1 -> 45 | B59: Adjusted R-Squared | C59: 0.986
A60: =+A59+1 -> 46 | B60: F-Statistic | C60: 2082.202
A61: =+A60+1 -> 47 | B61: Prob (F-Statistic) | C61: 0
...

Sheet SUBS Spline Graph
B1: =+'RES Spline Model'!B1:F1 -> 2025 RATE CASE
B2: =+'RES Spline Model'!B2:F2 -> ONCOR ELECTRIC DELIVERY COMPANY LLC
B3: =+'RES Spline Model'!B3:F3 -> ADJUSTED WEATHER STATION DATA
B4: =+'RES Spline Model'!B4:F4 -> FOR THE TEST YEAR ENDING DECEMBER 31, 2024
B6: =+'RES Spline Model'!B6:F6 -> SPONSOR: D. E. NELSON
A8: Line
A9: No.
A10: 1 | B10: Substation Spline Model
A11: =+A10+1 -> 2 | B11: =+'RES Spline Graph'!B11 -> After Corrective Procedures for Autocorrelation
A12: =+A11+1 -> 3
A13: =+A12+1 -> 4
A14: =+A13+1 -> 5
A15: =+A14+1 -> 6
A16: =+A15+1 -> 7
A17: =+A16+1 -> 8
A18: =+A17+1 -> 9
A19: =+A18+1 -> 10
A20: =+A19+1 -> 11
A21: =+A20+1 -> 12
A22: =+A21+1 -> 13
A23: =+A22+1 -> 14
... A37: =+A36+1 -> 28

Sheet RES B Spline Model
B1: =+'RES Spline Model'!B1:F1 -> 2025 RATE CASE
B2: =+'RES Spline Model'!B2:F2 -> ONCOR ELECTRIC DELIVERY COMPANY LLC
B3: =+'RES Spline Model'!B3:F3 -> ADJUSTED WEATHER STATION DATA
B4: =+'RES Spline Model'!B4:F4 -> FOR THE TEST YEAR ENDING DECEMBER 31, 2024
B6: =+'RES Spline Model'!B6:F6 -> SPONSOR: D. E. NELSON
A8: Line
A9: No. | B9: (a) | C9: (b) | D9: (c) | E9: (d) | F9: (e)
A10: 1 | B10: Model: | C10: Residential Spline (B)
A11: =+A10+1 -> 2 | B11: Before Corrective Procedures for Autocorrelation
A12: =+A11+1 -> 3 | B12: Dependent Variable: | C12: ResDMWH
A13: =+A12+1 -> 4 | B13: Estimation Begin Date: | C13: =+'RES Spline Model'!C13 -> 44197
A14: =+A13+1 -> 5 | B14: Estimation End Date: | C14: =+'RES Spline Model'!C14 -> 45291
A15: =+A14+1 -> 6
A16: =+A15+1 -> 7 | B16: Variable | C16: Coefficient | D16: StdErr | E16: T-Stat | F16: P-Value
A17: =+A16+1 -> 8 | B17: CONST | C17: 89469.885 | D17: 1740.675 | E17: 51.4 | F17: 0
A18: =+A17+1 -> 9 | B18: Calendar.DLSav | C18: -2550.484 | D18: 1064.831 | E18: -2.395 | F18: 0.0168
A19: =+A18+1 -> 10 | B19: Calendar.Monday | C19: -5167.573 | D19: 724.08 | E19: -7.137 | F19: 0
A20: =+A19+1 -> 11 | B20: Calendar.Tuesday | C20: -7334.777 | D20: 710.415 | E20: -10.325 | F20: 0
A21: =+A20+1 -> 12 | B21: Calendar.Wednesday | C21: -7294.044 | D21: 707.639 | E21: -10.308 | F21: 0
A22: =+A21+1 -> 13 | B22: Calendar.Thursday | C22: -7495.742 | D22: 711.844 | E22: -10.53 | F22: 0
A23: =+A22+1 -> 14 | B23: Calendar.Friday | C23: -8205.216 | D23: 712.775 | E23: -11.512 | F23: 0
A24: =+A23+1 -> 15 | B24: Calendar.Saturday | C24: -3930.152 | D24: 702.227 | E24: -5.597 | F24: 0
A25: =+A24+1 -> 16 | B25: Calendar.MLK | C25: 4828.94 | D25: 3690.208 | E25: 1.309 | F25: 0.191
A26: =+A25+1 -> 17 | B26: Calendar.PresDay | C26: -8111.702 | D26: 4529.691 | E26: -1.791 | F26: 0.0736
A27: =+A26+1 -> 18 | B27: Calendar.GoodFri | C27: 2860.822 | D27: 3703.307 | E27: 0.773 | F27: 0.44
A28: =+A27+1 -> 19 | B28: Calendar.MemDay | C28: 5972.715 | D28: 3679.074 | E28: 1.623 | F28: 0.1048
... A63: =+A62+1 -> 54 | B63: DayTypeVars.B16FEB2021 | C63: -87526.658 | D63: 6689.037 | E63: -13.085 | F63: 0
A64: =+A63+1 -> 55
A65: =+A64+1 -> 56 | B65: Model Statistics
A66: =+A65+1 -> 57 | B66: Adjusted Observations | C66: 1095
A67: =+A66+1 -> 58 | B67: Deg. of Freedom for Error | C67: 1048
A68: =+A67+1 -> 59 | B68: R-Squared | C68: 0.983
A69: =+A68+1 -> 60 | B69: Adjusted R-Squared | C69: 0.982
A70: =+A69+1 -> 61 | B70: F-Statistic | C70: 1301.6
A71: =+A70+1 -> 62 | B71: Prob (F-Statistic) | C71: 0
A72: =+A71+1 -> 63 | B72: Model Sum of Squares | C72: 2.3060828e+12
A73: =+A72+1 -> 64 | B73: Sum of Squared Errors | C73: 4.0364614e+10
A74: =+A73+1 -> 65 | B74: Mean Squared Error | C74: 38515853
A75: =+A74+1 -> 66 | B75: Std. Error of Regression | C75: 6206.11
A76: =+A75+1 -> 67 | B76: Mean Abs. Dev. (MAD) | C76: 4663.95
...

Sheet RES B Spline Graph
B1: =+'RES Spline Model'!B1:F1 -> 2025 RATE CASE
B2: =+'RES Spline Model'!B2:F2 -> ONCOR ELECTRIC DELIVERY COMPANY LLC
B3: =+'RES Spline Model'!B3:F3 -> ADJUSTED WEATHER STATION DATA
B4: =+'RES Spline Model'!B4:F4 -> FOR THE TEST YEAR ENDING DECEMBER 31, 2024
B6: =+'RES Spline Model'!B6:F6 -> SPONSOR: D. E. NELSON
A8: Line
A9: No.
A10: 1 | B10: Residential Spline (B) Model
A11: =+A10+1 -> 2 | B11: Before Corrective Procedures for Autocorrelation
A12: =+A11+1 -> 3
A13: =+A12+1 -> 4
A14: =+A13+1 -> 5
A15: =+A14+1 -> 6
A16: =+A15+1 -> 7
A17: =+A16+1 -> 8
A18: =+A17+1 -> 9
A19: =+A18+1 -> 10
A20: =+A19+1 -> 11
A21: =+A20+1 -> 12
A22: =+A21+1 -> 13
A23: =+A22+1 -> 14
... A37: =+A36+1 -> 28

Sheet GSS B Spline Model
B1: =+'RES Spline Model'!B1:F1 -> 2025 RATE CASE
B2: =+'RES Spline Model'!B2:F2 -> ONCOR ELECTRIC DELIVERY COMPANY LLC
B3: =+'RES Spline Model'!B3:F3 -> ADJUSTED WEATHER STATION DATA
B4: =+'RES Spline Model'!B4:F4 -> FOR THE TEST YEAR ENDING DECEMBER 31, 2024
B6: =+'RES Spline Model'!B6:F6 -> SPONSOR: D. E. NELSON
A8: Line
A9: No. | B9: (a) | C9: (b) | D9: (c) | E9: (d) | F9: (e)
A10: 1 | B10: Model: | C10: Secondary Service Less Than or Equal to 10 KW Spline (B)
A11: =+A10+1 -> 2 | B11: Before Corrective Procedures for Autocorrelation
A12: =+A11+1 -> 3 | B12: Dependent Variable: | C12: GSSDMWH
A13: =+A12+1 -> 4 | B13: Estimation Begin Date: | C13: =+'RES Spline Model'!C13 -> 44197
A14: =+A13+1 -> 5 | B14: Estimation End Date: | C14: =+'RES Spline Model'!C14 -> 45291
A15: =+A14+1 -> 6
A16: =+A15+1 -> 7 | B16: Variable | C16: Coefficient | D16: StdErr | E16: T-Stat | F16: P-Value
A17: =+A16+1 -> 8 | B17: CONST | C17: 5134.233 | D17: 57.343 | E17: 89.535 | F17: 0
A18: =+A17+1 -> 9 | B18: Calendar.DLSav | C18: -70.664 | D18: 34.87 | E18: -2.026 | F18: 0.043
A19: =+A18+1 -> 10 | B19: Calendar.Monday | C19: 468.913 | D19: 23.725 | E19: 19.765 | F19: 0
A20: =+A19+1 -> 11 | B20: Calendar.Tuesday | C20: 502.388 | D20: 23.276 | E20: 21.584 | F20: 0
A21: =+A20+1 -> 12 | B21: Calendar.Wednesday | C21: 517.775 | D21: 23.226 | E21: 22.293 | F21: 0
A22: =+A21+1 -> 13 | B22: Calendar.Thursday | C22: 517.374 | D22: 23.347 | E22: 22.16 | F22: 0
A23: =+A22+1 -> 14 | B23: Calendar.Friday | C23: 481.929 | D23: 23.38 | E23: 20.613 | F23: 0
A24: =+A23+1 -> 15 | B24: Calendar.Saturday | C24: 201.81 | D24: 23.004 | E24: 8.773 | F24: 0
A25: =+A24+1 -> 16 | B25: Calendar.MLK | C25: -32.947 | D25: 121.056 | E25: -0.272 | F25: 0.7856
A26: =+A25+1 -> 17 | B26: Calendar.PresDay | C26: -185.193 | D26: 148.416 | E26: -1.248 | F26: 0.2124
A27: =+A26+1 -> 18 | B27: Calendar.GoodFri | C27: -63.783 | D27: 121.378 | E27: -0.525 | F27: 0.5994
A28: =+A27+1 -> 19 | B28: Calendar.MemDay | C28: -405.828 | D28: 120.548 | E28: -3.367 | F28: 0.0008
... A66: =+A65+1 -> 57 | B66: DayTypeVars.B19FEB2021 | C66: -453.206 | D66: 208.652 | E66: -2.172 | F66: 0.0301
A67: =+A66+1 -> 58
A68: =+A67+1 -> 59 | B68: Model Statistics
A69: =+A68+1 -> 60 | B69: Adjusted Observations | C69: 1095
A70: =+A69+1 -> 61 | B70: Deg. of Freedom for Error | C70: 1045
A71: =+A70+1 -> 62 | B71: R-Squared | C71: 0.933
A72: =+A71+1 -> 63 | B72: Adjusted R-Squared | C72: 0.929
A73: =+A72+1 -> 64 | B73: F-Statistic | C73: 294.784
A74: =+A73+1 -> 65 | B74: Prob (F-Statistic) | C74: 0
A75: =+A74+1 -> 66 | B75: Model Sum of Squares | C75: 5.9745831e+08
A76: =+A75+1 -> 67 | B76: Sum of Squared Errors | C76: 43223946
A77: =+A76+1 -> 68 | B77: Mean Squared Error | C77: 41362.63
A78: =+A77+1 -> 69 | B78: Std. Error of Regression | C78: 203.38
A79: =+A78+1 -> 70 | B79: Mean Abs. Dev. (MAD) | C79: 158.78
...

Sheet GSS B Spline Graph
B1: =+'RES Spline Model'!B1:F1 -> 2025 RATE CASE
B2: =+'RES Spline Model'!B2:F2 -> ONCOR ELECTRIC DELIVERY COMPANY LLC
B3: =+'RES Spline Model'!B3:F3 -> ADJUSTED WEATHER STATION DATA
B4: =+'RES Spline Model'!B4:F4 -> FOR THE TEST YEAR ENDING DECEMBER 31, 2024
B6: =+'RES Spline Model'!B6:F6 -> SPONSOR: D. E. NELSON
A8: Line
A9: No.
A10: 1 | B10: Secondary Service Less Than or Equal to 10 KW Spline (B) Model
A11: =+A10+1 -> 2 | B11: Before Corrective Procedures for Autocorrelation
A12: =+A11+1 -> 3
A13: =+A12+1 -> 4
A14: =+A13+1 -> 5
A15: =+A14+1 -> 6
A16: =+A15+1 -> 7
A17: =+A16+1 -> 8
A18: =+A17+1 -> 9
A19: =+A18+1 -> 10
A20: =+A19+1 -> 11
A21: =+A20+1 -> 12
A22: =+A21+1 -> 13
A23: =+A22+1 -> 14
... A37: =+A36+1 -> 28

Sheet GSL B Spline Model
B1: =+'RES Spline Model'!B1:F1 -> 2025 RATE CASE
B2: =+'RES Spline Model'!B2:F2 -> ONCOR ELECTRIC DELIVERY COMPANY LLC
B3: =+'RES Spline Model'!B3:F3 -> ADJUSTED WEATHER STATION DATA
B4: =+'RES Spline Model'!B4:F4 -> FOR THE TEST YEAR ENDING DECEMBER 31, 2024
B6: =+'RES Spline Model'!B6:F6 -> SPONSOR: D. E. NELSON
A8: Line
A9: No. | B9: (a) | C9: (b) | D9: (c) | E9: (d) | F9: (e)
A10: 1 | B10: Model: | C10: Secondary Service Greater Than 10 KW Spline (B)
A11: =+A10+1 -> 2 | B11: Before Corrective Procedures for Autocorrelation
A12: =+A11+1 -> 3 | B12: Dependent Variable: | C12: GSLMWH
A13: =+A12+1 -> 4 | B13: Estimation Begin Date: | C13: =+'RES Spline Model'!C13 -> 44197
A14: =+A13+1 -> 5 | B14: Estimation End Date: | C14: =+'RES Spline Model'!C14 -> 45291
A15: =+A14+1 -> 6
A16: =+A15+1 -> 7 | B16: Variable | C16: Coefficient | D16: StdErr | E16: T-Stat | F16: P-Value
A17: =+A16+1 -> 8 | B17: CONST | C17: 82363.328 | D17: 894.707 | E17: 92.056 | F17: 0
A18: =+A17+1 -> 9 | B18: Calendar.DLSav | C18: -758.866 | D18: 547.471 | E18: -1.386 | F18: 0.166
A19: =+A18+1 -> 10 | B19: Calendar.Monday | C19: 21180.425 | D19: 372.472 | E19: 56.864 | F19: 0
A20: =+A19+1 -> 11 | B20: Calendar.Tuesday | C20: 22815.46 | D20: 365.519 | E20: 62.419 | F20: 0
A21: =+A20+1 -> 12 | B21: Calendar.Wednesday | C21: 23437.091 | D21: 364.539 | E21: 64.292 | F21: 0
A22: =+A21+1 -> 13 | B22: Calendar.Thursday | C22: 23217.531 | D22: 366.648 | E22: 63.324 | F22: 0
A23: =+A22+1 -> 14 | B23: Calendar.Friday | C23: 21317.226 | D23: 367.131 | E23: 58.064 | F23: 0
A24: =+A23+1 -> 15 | B24: Calendar.Saturday | C24: 5935.547 | D24: 361.264 | E24: 16.43 | F24: 0
A25: =+A24+1 -> 16 | B25: Calendar.MLK | C25: -4239.807 | D25: 1898.686 | E25: -2.233 | F25: 0.0257
A26: =+A25+1 -> 17 | B26: Calendar.PresDay | C26: -7060.494 | D26: 2329.848 | E26: -3.03 | F26: 0.0025
A27: =+A26+1 -> 18 | B27: Calendar.GoodFri | C27: -7443.752 | D27: 1903.835 | E27: -3.91 | F27: 0.0001
A28: =+A27+1 -> 19 | B28: Calendar.MemDay | C28: -19905.853 | D28: 1892.217 | E28: -10.52 | F28: 0
... A66: =+A65+1 -> 57 | B66: DayTypeVars.B19FEB2021 | C66: -12539.128 | D66: 3273.459 | E66: -3.831 | F66: 0.0001
A67: =+A66+1 -> 58
A68: =+A67+1 -> 59 | B68: Model Statistics
A69: =+A68+1 -> 60 | B69: Adjusted Observations | C69: 1095
A70: =+A69+1 -> 61 | B70: Deg. of Freedom for Error | C70: 1045
A71: =+A70+1 -> 62 | B71: R-Squared | C71: 0.981
A72: =+A71+1 -> 63 | B72: Adjusted R-Squared | C72: 0.98
A73: =+A72+1 -> 64 | B73: F-Statistic | C73: 1099.48
A74: =+A73+1 -> 65 | B74: Prob (F-Statistic) | C74: 0
A75: =+A74+1 -> 66 | B75: Model Sum of Squares | C75: 5.4896781e+11
A76: =+A75+1 -> 67 | B76: Sum of Squared Errors | C76: 1.0648287e+10
A77: =+A76+1 -> 68 | B77: Mean Squared Error | C77: 10189748
A78: =+A77+1 -> 69 | B78: Std. Error of Regression | C78: 3192.14
A79: =+A78+1 -> 70 | B79: Mean Abs. Dev. (MAD) | C79: 2298.93
...

Sheet GSL B Spline Graph
B1: =+'RES Spline Model'!B1:F1 -> 2025 RATE CASE
B2: =+'RES Spline Model'!B2:F2 -> ONCOR ELECTRIC DELIVERY COMPANY LLC
B3: =+'RES Spline Model'!B3:F3 -> ADJUSTED WEATHER STATION DATA
B4: =+'RES Spline Model'!B4:F4 -> FOR THE TEST YEAR ENDING DECEMBER 31, 2024
B6: =+'RES Spline Model'!B6:F6 -> SPONSOR: D. E. NELSON
A8: Line
A9: No.
A10: 1 | B10: Secondary Service Greater Than 10 KW Spline (B) Model
A11: =+A10+1 -> 2 | B11: Before Corrective Procedures for Autocorrelation
A12: =+A11+1 -> 3
A13: =+A12+1 -> 4
A14: =+A13+1 -> 5
A15: =+A14+1 -> 6
A16: =+A15+1 -> 7
A17: =+A16+1 -> 8
A18: =+A17+1 -> 9
A19: =+A18+1 -> 10
A20: =+A19+1 -> 11
A21: =+A20+1 -> 12
A22: =+A21+1 -> 13
A23: =+A22+1 -> 14
... A37: =+A36+1 -> 28

Sheet GPLD B Spline Model
B1: =+'RES Spline Model'!B1:F1 -> 2025 RATE CASE
B2: =+'RES Spline Model'!B2:F2 -> ONCOR ELECTRIC DELIVERY COMPANY LLC
B3: =+'RES Spline Model'!B3:F3 -> ADJUSTED WEATHER STATION DATA
B4: =+'RES Spline Model'!B4:F4 -> FOR THE TEST YEAR ENDING DECEMBER 31, 2024
B6: =+'RES Spline Model'!B6:F6 -> SPONSOR: D. E. NELSON
A8: Line
A9: No. | B9: (a) | C9: (b) | D9: (c) | E9: (d) | F9: (e)
A10: 1 | B10: Model: | C10: Primary Service Greater Than 10 KW Distribution Spline (B)
A11: =+A10+1 -> 2 | B11: Before Corrective Procedures for Autocorrelation
A12: =+A11+1 -> 3 | B12: Dependent Variable: | C12: GPLDMWH
A13: =+A12+1 -> 4 | B13: Estimation Begin Date: | C13: =+'RES Spline Model'!C13 -> 44197
A14: =+A13+1 -> 5 | B14: Estimation End Date: | C14: =+'RES Spline Model'!C14 -> 45291
A15: =+A14+1 -> 6
A16: =+A15+1 -> 7 | B16: Variable | C16: Coefficient | D16: StdErr | E16: T-Stat | F16: P-Value
A17: =+A16+1 -> 8 | B17: CONST | C17: 19362.58 | D17: 323.574 | E17: 59.84 | F17: 0
A18: =+A17+1 -> 9 | B18: Calendar.DLSav | C18: -201.004 | D18: 232.755 | E18: -0.864 | F18: 0.388
A19: =+A18+1 -> 10 | B19: Calendar.Monday | C19: 2304.308 | D19: 159.213 | E19: 14.473 | F19: 0
A20: =+A19+1 -> 11 | B20: Calendar.Tuesday | C20: 2650.966 | D20: 155.708 | E20: 17.025 | F20: 0
A21: =+A20+1 -> 12 | B21: Calendar.Wednesday | C21: 2618.354 | D21: 155.606 | E21: 16.827 | F21: 0
A22: =+A21+1 -> 13 | B22: Calendar.Thursday | C22: 2685.639 | D22: 156.34 | E22: 17.178 | F22: 0
A23: =+A22+1 -> 14 | B23: Calendar.Friday | C23: 2484.093 | D23: 156.645 | E23: 15.858 | F23: 0
A24: =+A23+1 -> 15 | B24: Calendar.Saturday | C24: 744.163 | D24: 154.703 | E24: 4.81 | F24: 0
A25: =+A24+1 -> 16 | B25: Calendar.MLK | C25: -326.562 | D25: 806.494 | E25: -0.405 | F25: 0.6856
A26: =+A25+1 -> 17 | B26: Calendar.PresDay | C26: 529.716 | D26: 988.489 | E26: 0.536 | F26: 0.5922
A27: =+A26+1 -> 18 | B27: Calendar.GoodFri | C27: -889.363 | D27: 806.865 | E27: -1.102 | F27: 0.2706
A28: =+A27+1 -> 19 | B28: Calendar.MemDay | C28: -2765.407 | D28: 805.711 | E28: -3.432 | F28: 0.0006
... A65: =+A64+1 -> 56 | B65: DayTypeVars.B22FEB2021 | C65: -6480.509 | D65: 1376.027 | E65: -4.71 | F65: 0
A66: =+A65+1 -> 57
A67: =+A66+1 -> 58 | B67: Model Statistics
A68: =+A67+1 -> 59 | B68: Adjusted Observations | C68: 1095
A69: =+A68+1 -> 60 | B69: Deg. of Freedom for Error | C69: 1046
A70: =+A69+1 -> 61 | B70: R-Squared | C70: 0.949
A71: =+A70+1 -> 62 | B71: Adjusted R-Squared | C71: 0.947
A72: =+A71+1 -> 63 | B72: F-Statistic | C72: 406.412
A73: =+A72+1 -> 64 | B73: Prob (F-Statistic) | C73: 0
A74: =+A73+1 -> 65 | B74: Model Sum of Squares | C74: 3.6091629e+10
A75: =+A74+1 -> 66 | B75: Sum of Squared Errors | C75: 1.9352184e+09
A76: =+A75+1 -> 67 | B76: Mean Squared Error | C76: 1850113.2
A77: =+A76+1 -> 68 | B77: Std. Error of Regression | C77: 1360.19
A78: =+A77+1 -> 69 | B78: Mean Abs. Dev. (MAD) | C78: 964.9
...

Sheet GPLD B Spline Graph
B1: =+'RES Spline Model'!B1:F1 -> 2025 RATE CASE
B2: =+'RES Spline Model'!B2:F2 -> ONCOR ELECTRIC DELIVERY COMPANY LLC
B3: =+'RES Spline Model'!B3:F3 -> ADJUSTED WEATHER STATION DATA
B4: =+'RES Spline Model'!B4:F4 -> FOR THE TEST YEAR ENDING DECEMBER 31, 2024
B6: =+'RES Spline Model'!B6:F6 -> SPONSOR: D. E. NELSON
A8: Line
A9: No.
A10: 1 | B10: Primary Service Greater Than 10 KW Distribution Spline (B) Model
A11: =+A10+1 -> 2 | B11: Before Corrective Procedures for Autocorrelation
A12: =+A11+1 -> 3
A13: =+A12+1 -> 4
A14: =+A13+1 -> 5
A15: =+A14+1 -> 6
A16: =+A15+1 -> 7
A17: =+A16+1 -> 8
A18: =+A17+1 -> 9
A19: =+A18+1 -> 10
A20: =+A19+1 -> 11
A21: =+A20+1 -> 12
A22: =+A21+1 -> 13
A23: =+A22+1 -> 14
... A37: =+A36+1 -> 28

Sheet SUBS B Spline Model
B1: =+'RES Spline Model'!B1:F1 -> 2025 RATE CASE
B2: =+'RES Spline Model'!B2:F2 -> ONCOR ELECTRIC DELIVERY COMPANY LLC
B3: =+'RES Spline Model'!B3:F3 -> ADJUSTED WEATHER STATION DATA
B4: =+'RES Spline Model'!B4:F4 -> FOR THE TEST YEAR ENDING DECEMBER 31, 2024
B6: =+'RES Spline Model'!B6:F6 -> SPONSOR: D. E. NELSON
A8: Line
A9: No. | B9: (a) | C9: (b) | D9: (c) | E9: (d) | F9: (e)
A10: 1 | B10: Model: | C10: Substation Spline (B)
A11: =+A10+1 -> 2 | B11: Before Corrective Procedures for Autocorrelation
A12: =+A11+1 -> 3 | B12: Dependent Variable: | C12: SUBSDMWH
A13: =+A12+1 -> 4 | B13: Estimation Begin Date: | C13: =+'RES Spline Model'!C13 -> 44197
A14: =+A13+1 -> 5 | B14: Estimation End Date: | C14: =+'RES Spline Model'!C14 -> 45291
A15: =+A14+1 -> 6
A16: =+A15+1 -> 7 | B16: Variable | C16: Coefficient | D16: StdErr | E16: T-Stat | F16: P-Value
A17: =+A16+1 -> 8 | B17: CONST | C17: -472.866 | D17: 296.997 | E17: -1.592 | F17: 0.1117
A18: =+A17+1 -> 9 | B18: Calendar.DLSav | C18: 131.795 | D18: 214.374 | E18: 0.615 | F18: 0.5388
A19: =+A18+1 -> 10 | B19: Calendar.Monday | C19: 177.964 | D19: 146.706 | E19: 1.213 | F19: 0.2254
A20: =+A19+1 -> 11 | B20: Calendar.Tuesday | C20: 105.516 | D20: 143.73 | E20: 0.734 | F20: 0.463
A21: =+A20+1 -> 12 | B21: Calendar.Wednesday | C21: 171.038 | D21: 143.649 | E21: 1.191 | F21: 0.2341
A22: =+A21+1 -> 13 | B22: Calendar.Thursday | C22: 142.268 | D22: 144.343 | E22: 0.986 | F22: 0.3245
A23: =+A22+1 -> 14 | B23: Calendar.Friday | C23: 137.344 | D23: 144.538 | E23: 0.95 | F23: 0.3422
A24: =+A23+1 -> 15 | B24: Calendar.Saturday | C24: 64.016 | D24: 142.763 | E24: 0.448 | F24: 0.654
A25: =+A24+1 -> 16 | B25: Calendar.MLK | C25: -2.973 | D25: 744.349 | E25: -0.004 | F25: 0.9968
A26: =+A25+1 -> 17 | B26: Calendar.PresDay | C26: -61.805 | D26: 909.567 | E26: -0.068 | F26: 0.9458
A27: =+A26+1 -> 18 | B27: Calendar.GoodFri | C27: 304.53 | D27: 744.285 | E27: 0.409 | F27: 0.6825
A28: =+A27+1 -> 19 | B28: Calendar.MemDay | C28: -247.198 | D28: 743.781 | E28: -0.332 | F28: 0.7397
... A59: =+A58+1 -> 50 | B59: DayTypeVars.B13FEB2021 | C59: -2046.005 | D59: 1269.292 | E59: -1.612 | F59: 0.1073
B60: DayTypeVars.B14FEB2021 | C60: -5111.924 | D60: 1269.347 | E60: -4.027 | F60: 0.0001
B61: DayTypeVars.B20FEB2021 | C61: -5541.953 | D61: 1269.252 | E61: -4.366 | F61: 0
B62: DayTypeVars.B21FEB2021 | C62: -3360.827 | D62: 1269.124 | E62: -2.648 | F62: 0.0082
A63: =+A59+1 -> 51
A64: =+A63+1 -> 52 | B64: Model Statistics
A65: =+A64+1 -> 53 | B65: Adjusted Observations | C65: 1095
A66: =+A65+1 -> 54 | B66: Deg. of Freedom for Error | C66: 1049
A67: =+A66+1 -> 55 | B67: R-Squared | C67: 0.879
A68: =+A67+1 -> 56 | B68: Adjusted R-Squared | C68: 0.873
A69: =+A68+1 -> 57 | B69: F-Statistic | C69: 168.769
A70: =+A69+1 -> 58 | B70: Prob (F-Statistic) | C70: 0
A71: =+A70+1 -> 59 | B71: Model Sum of Squares | C71: 1.1978006e+10
A72: =+A71+1 -> 60 | B72: Sum of Squared Errors | C72: 1.654451e+09
...

Sheet SUBS B Spline Graph
B1: =+'RES Spline Model'!B1:F1 -> 2025 RATE CASE
B2: =+'RES Spline Model'!B2:F2 -> ONCOR ELECTRIC DELIVERY COMPANY LLC
B3: =+'RES Spline Model'!B3:F3 -> ADJUSTED WEATHER STATION DATA
B4: =+'RES Spline Model'!B4:F4 -> FOR THE TEST YEAR ENDING DECEMBER 31, 2024
B6: =+'RES Spline Model'!B6:F6 -> SPONSOR: D. E. NELSON
A8: Line
A9: No.
A10: 1 | B10: Substation Spline (B) Model
A11: =+A10+1 -> 2 | B11: Before Corrective Procedures for Autocorrelation
A12: =+A11+1 -> 3
A13: =+A12+1 -> 4
A14: =+A13+1 -> 5
A15: =+A14+1 -> 6
A16: =+A15+1 -> 7
A17: =+A16+1 -> 8
A18: =+A17+1 -> 9
A19: =+A18+1 -> 10
A20: =+A19+1 -> 11
A21: =+A20+1 -> 12
A22: =+A21+1 -> 13
A23: =+A22+1 -> 14
... A37: =+A36+1 -> 28
