Workbook
Name HOURLY: [1]HOURLY!$A$1:$G$745
Name OLE_LINK2: 'SECGT10 Seasonal Weights'!$B$24
Name rngBilled: OFFSET([2]Sheet2!$A$2,0,0,[2]Sheet2!$B$1,9)
Name rngYear: OFFSET('[3]Daily Actual_August'!$A$2,0,0,'[3]Daily Actual_August'!$C$1,8)

Sheet SECGT10 Seasonal Weights
B1: PUC DOCKET NO.
B2: ONCOR ELECTRIC DELIVERY COMPANY LLC
B3: WEATHER WEIGHTS
B4: FOR THE TEST YEAR ENDING DECEMBER 31, 2024
B6: SPONSOR: D. E. NELSON
B8: SECONDARY SERVICE GREATER THAN 10 KW MONTHLY WEIGHTS
A9: Line | B9: (a) | D9: (b) | E9: (c) | F9: (d) | G9: (e) | H9: (f) | I9: (g) | J9: (h) | K9: (i) | L9: (j) | M9: (k) | N9: (l) | O9: (m) | P9: (n)
A10: No. | B10: Weather Station | D10: 36892 | E10: 36923 | F10: 36951 | G10: 36982 | H10: 37012 | I10: 37043 | J10: 37073 | K10: 37104 | L10: 37135 | M10: 37165 | N10: 37196 | O10: 37226 | P10: Annual
A11: 1 | B11: Dallas-Fort Worth | D11: =+'SECGT10 Monthly Weather Weights'!C11 -> 0.73809943 | E11: =+'SECGT10 Monthly Weather Weights'!D11 -> 0.73645072 | F11: =+'SECGT10 Monthly Weather Weights'!E11 -> 0.73448838 | G11: =+'SECGT10 Monthly Weather Weights'!F11 -> 0.73282169 | H11: =+'SECGT10 Monthly Weather Weights'!G11 -> 0.73368949 | I11: =+'SECGT10 Monthly Weather Weights'!H11 -> 0.74044529 | J11: =+'SECGT10 Monthly Weather Weights'!I11 -> 0.73692629 | K11: =+'SECGT10 Monthly Weather Weights'!J11 -> 0.73888794 | ... P11: =+'SECGT10 Monthly Weather Weights'!O11 -> 0.73696443
A12: =+A11+1 -> 2 | B12: Midland-Odessa | D12: =+'SECGT10 Monthly Weather Weights'!C12 -> 0.07201484 | E12: =+'SECGT10 Monthly Weather Weights'!D12 -> 0.073220001 | F12: =+'SECGT10 Monthly Weather Weights'!E12 -> 0.073166599 | G12: =+'SECGT10 Monthly Weather Weights'!F12 -> 0.075845117 | H12: =+'SECGT10 Monthly Weather Weights'!G12 -> 0.072564185 | I12: =+'SECGT10 Monthly Weather Weights'!H12 -> 0.066924379 | J12: =+'SECGT10 Monthly Weather Weights'!I12 -> 0.067407718 | K12: =+'SECGT10 Monthly Weather Weights'!J12 -> 0.065742487 | ... P12: =+'SECGT10 Monthly Weather Weights'!O12 -> 0.069427566
A13: =+A12+1 -> 3 | B13: Lufkin | D13: =+'SECGT10 Monthly Weather Weights'!C13 -> 0.023933489 | E13: =+'SECGT10 Monthly Weather Weights'!D13 -> 0.024018641 | F13: =+'SECGT10 Monthly Weather Weights'!E13 -> 0.024026881 | G13: =+'SECGT10 Monthly Weather Weights'!F13 -> 0.024485182 | H13: =+'SECGT10 Monthly Weather Weights'!G13 -> 0.024836227 | I13: =+'SECGT10 Monthly Weather Weights'!H13 -> 0.025214532 | J13: =+'SECGT10 Monthly Weather Weights'!I13 -> 0.024974872 | K13: =+'SECGT10 Monthly Weather Weights'!J13 -> 0.024737832 | ... P13: =+'SECGT10 Monthly Weather Weights'!O13 -> 0.02453547
A14: =+A13+1 -> 4 | B14: Abilene | D14: =+'SECGT10 Monthly Weather Weights'!C14 -> 0.010887982 | E14: =+'SECGT10 Monthly Weather Weights'!D14 -> 0.01113668 | F14: =+'SECGT10 Monthly Weather Weights'!E14 -> 0.010844553 | G14: =+'SECGT10 Monthly Weather Weights'!F14 -> 0.010707082 | H14: =+'SECGT10 Monthly Weather Weights'!G14 -> 0.010641905 | I14: =+'SECGT10 Monthly Weather Weights'!H14 -> 0.0068244114 | J14: =+'SECGT10 Monthly Weather Weights'!I14 -> 0.010931988 | K14: =+'SECGT10 Monthly Weather Weights'!J14 -> 0.010987608 | ... P14: =+'SECGT10 Monthly Weather Weights'!O14 -> 0.010359265
A15: =+A14+1 -> 5 | B15: Sherman-Denison | D15: =+'SECGT10 Monthly Weather Weights'!C15 -> 0.023990113 | E15: =+'SECGT10 Monthly Weather Weights'!D15 -> 0.024379689 | F15: =+'SECGT10 Monthly Weather Weights'!E15 -> 0.024528481 | G15: =+'SECGT10 Monthly Weather Weights'!F15 -> 0.023816953 | H15: =+'SECGT10 Monthly Weather Weights'!G15 -> 0.023478476 | I15: =+'SECGT10 Monthly Weather Weights'!H15 -> 0.023671558 | J15: =+'SECGT10 Monthly Weather Weights'!I15 -> 0.023682202 | K15: =+'SECGT10 Monthly Weather Weights'!J15 -> 0.023936227 | ... P15: =+'SECGT10 Monthly Weather Weights'!O15 -> 0.023929384
A16: =+A15+1 -> 6 | B16: Killeen-Temple | D16: =+'SECGT10 Monthly Weather Weights'!C16 -> 0.026520175 | E16: =+'SECGT10 Monthly Weather Weights'!D16 -> 0.026764592 | F16: =+'SECGT10 Monthly Weather Weights'!E16 -> 0.027112216 | G16: =+'SECGT10 Monthly Weather Weights'!F16 -> 0.026901611 | H16: =+'SECGT10 Monthly Weather Weights'!G16 -> 0.027420974 | I16: =+'SECGT10 Monthly Weather Weights'!H16 -> 0.027630763 | J16: =+'SECGT10 Monthly Weather Weights'!I16 -> 0.02730936 | K16: =+'SECGT10 Monthly Weather Weights'!J16 -> 0.027386463 | ... P16: =+'SECGT10 Monthly Weather Weights'!O16 -> 0.027336567
A17: =+A16+1 -> 7 | B17: Waco | D17: =+'SECGT10 Monthly Weather Weights'!C17 -> 0.031941384 | E17: =+'SECGT10 Monthly Weather Weights'!D17 -> 0.03182022 | F17: =+'SECGT10 Monthly Weather Weights'!E17 -> 0.03255243 | G17: =+'SECGT10 Monthly Weather Weights'!F17 -> 0.032402357 | H17: =+'SECGT10 Monthly Weather Weights'!G17 -> 0.033065372 | I17: =+'SECGT10 Monthly Weather Weights'!H17 -> 0.033673475 | J17: =+'SECGT10 Monthly Weather Weights'!I17 -> 0.033763143 | K17: =+'SECGT10 Monthly Weather Weights'!J17 -> 0.033608391 | ... P17: =+'SECGT10 Monthly Weather Weights'!O17 -> 0.033226325
A18: =+A17+1 -> 8 | B18: Wichita Falls. | D18: =+'SECGT10 Monthly Weather Weights'!C18 -> 0.013696096 | E18: =+'SECGT10 Monthly Weather Weights'!D18 -> 0.013998398 | F18: =+'SECGT10 Monthly Weather Weights'!E18 -> 0.01424117 | G18: =+'SECGT10 Monthly Weather Weights'!F18 -> 0.013631317 | H18: =+'SECGT10 Monthly Weather Weights'!G18 -> 0.01376896 | I18: =+'SECGT10 Monthly Weather Weights'!H18 -> 0.01413139 | J18: =+'SECGT10 Monthly Weather Weights'!I18 -> 0.014487373 | K18: =+'SECGT10 Monthly Weather Weights'!J18 -> 0.014722877 | ... P18: =+'SECGT10 Monthly Weather Weights'!O18 -> 0.014193924
A19: =+A18+1 -> 9 | B19: Longview | D19: =+'SECGT10 Monthly Weather Weights'!C19 -> 0.030542201 | E19: =+'SECGT10 Monthly Weather Weights'!D19 -> 0.030313625 | F19: =+'SECGT10 Monthly Weather Weights'!E19 -> 0.030667349 | G19: =+'SECGT10 Monthly Weather Weights'!F19 -> 0.030333631 | H19: =+'SECGT10 Monthly Weather Weights'!G19 -> 0.030702555 | I19: =+'SECGT10 Monthly Weather Weights'!H19 -> 0.031410058 | J19: =+'SECGT10 Monthly Weather Weights'!I19 -> 0.031353177 | K19: =+'SECGT10 Monthly Weather Weights'!J19 -> 0.031216791 | ... P19: =+'SECGT10 Monthly Weather Weights'!O19 -> 0.030883103
A20: =+A19+1 -> 10 | B20: Austin | D20: =+'SECGT10 Monthly Weather Weights'!C20 -> 0.028374288 | E20: =+'SECGT10 Monthly Weather Weights'!D20 -> 0.027897439 | F20: =+'SECGT10 Monthly Weather Weights'!E20 -> 0.028371938 | G20: =+'SECGT10 Monthly Weather Weights'!F20 -> 0.02905506 | H20: =+'SECGT10 Monthly Weather Weights'!G20 -> 0.029831858 | I20: =+'SECGT10 Monthly Weather Weights'!H20 -> 0.030074144 | J20: =+'SECGT10 Monthly Weather Weights'!I20 -> 0.029163875 | K20: =+'SECGT10 Monthly Weather Weights'!J20 -> 0.028773382 | ... P20: =+'SECGT10 Monthly Weather Weights'!O20 -> 0.029143966
A21: =+A20+1 -> 11 | D21: =SUM(D11:D20) -> 1 | E21: =SUM(E11:E20) -> 1 | F21: =SUM(F11:F20) -> 1 | G21: =SUM(G11:G20) -> 1 | H21: =SUM(H11:H20) -> 1 | I21: =SUM(I11:I20) -> 1 | J21: =SUM(J11:J20) -> 1 | K21: =SUM(K11:K20) -> 1 | ... P21: =SUM(P11:P20) -> 1
A22: =+A21+1 -> 12
A23: =+A22+1 -> 13 | D23: SEASONAL WEIGHTS
A24: =+A23+1 -> 14 | D24: Nov to Mar | F24: May to Sep
A25: =+A24+1 -> 15 | B25: Weather Station | D25: HDD | F25: CDD
A26: =+A25+1 -> 16 | B26: Dallas-Fort Worth | D26: =ROUND(AVERAGE(D11:F11,N11:O11),3) -> 0.736 | F26: =ROUND(AVERAGE(H11:L11),3) -> 0.738
A27: =+A26+1 -> 17 | B27: Midland-Odessa | D27: =ROUND(AVERAGE(D12:F12,N12:O12),3) -> 0.073 | F27: =ROUND(AVERAGE(H12:L12),3) -> 0.067
A28: =+A27+1 -> 18 | B28: Lufkin | D28: =ROUND(AVERAGE(D13:F13,N13:O13),3) -> 0.024 | F28: =ROUND(AVERAGE(H13:L13),3) -> 0.025
A29: =+A28+1 -> 19 | B29: Abilene | D29: =ROUND(AVERAGE(D14:F14,N14:O14),3) -> 0.011 | F29: =ROUND(AVERAGE(H14:L14),3) -> 0.01
A30: =+A29+1 -> 20 | B30: Sherman-Denison | D30: =ROUND(AVERAGE(D15:F15,N15:O15),3) -> 0.024 | F30: =ROUND(AVERAGE(H15:L15),3) -> 0.024
A31: =+A30+1 -> 21 | B31: Killeen-Temple | D31: =ROUND(AVERAGE(D16:F16,N16:O16),3) -> 0.027 | F31: =ROUND(AVERAGE(H16:L16),3) -> 0.028
A32: =+A31+1 -> 22 | B32: Waco | D32: =ROUND(AVERAGE(D17:F17,N17:O17),3) -> 0.033 | F32: =ROUND(AVERAGE(H17:L17),3) -> 0.034
A33: =+A32+1 -> 23 | B33: Wichita Falls. | D33: =ROUND(AVERAGE(D18:F18,N18:O18),3) -> 0.014 | F33: =ROUND(AVERAGE(H18:L18),3) -> 0.014
A34: =+A33+1 -> 24 | B34: Longview | D34: =ROUND(AVERAGE(D19:F19,N19:O19),3) -> 0.031 | F34: =ROUND(AVERAGE(H19:L19),3) -> 0.031
A35: =+A34+1 -> 25 | B35: Austin | D35: =ROUND(AVERAGE(D20:F20,N20:O20),3) -> 0.029 | F35: =ROUND(AVERAGE(H20:L20),3) -> 0.029
A36: =+A35+1 -> 26 | D36: =AVERAGE(D21:F21,N21:O21) -> 1 | F36: =AVERAGE(H21:L21) -> 1

Sheet SECGT10 Monthly Weather Weights
B1: PUC DOCKET NO.
B2: ONCOR ELECTRIC DELIVERY COMPANY
B3: WEATHER WEIGHTS
B4: =+'SECGT10 Seasonal Weights'!B4:P4 -> FOR THE TEST YEAR ENDING DECEMBER 31, 2024
B6: SPONSOR: D. E. NELSON
B8: SECONDARY SERVICE GREATER THAN 10 KW MONTHLY WEIGHTS
A9: Line | B9: (a) | C9: (b) | D9: (c) | E9: (d) | F9: (e) | G9: (f) | H9: (g) | I9: (h) | J9: (i) | K9: (j) | L9: (k) | M9: (l) | N9: (m) | O9: (n)
A10: No. | B10: Weather Station | C10: 36892 | D10: 36923 | E10: 36951 | F10: 36982 | G10: 37012 | H10: 37043 | I10: 37073 | J10: 37104 | K10: 37135 | L10: 37165 | M10: 37196 | N10: 37226 | O10: Annual
A11: 1 | B11: Dallas-Fort Worth | C11: =+'SECGT10 Weights by Year (21-23)'!D14 -> 0.73809943 | D11: =+'SECGT10 Weights by Year (21-23)'!E14 -> 0.73645072 | E11: =+'SECGT10 Weights by Year (21-23)'!F14 -> 0.73448838 | F11: =+'SECGT10 Weights by Year (21-23)'!G14 -> 0.73282169 | G11: =+'SECGT10 Weights by Year (21-23)'!H14 -> 0.73368949 | H11: =+'SECGT10 Weights by Year (21-23)'!I14 -> 0.74044529 | I11: =+'SECGT10 Weights by Year (21-23)'!J14 -> 0.73692629 | J11: =+'SECGT10 Weights by Year (21-23)'!K14 -> 0.73888794 | ... O11: =+'SECGT10 Weights by Year (21-23)'!P14 -> 0.73696443
A12: =+A11+1 -> 2 | B12: Midland-Odessa | C12: =+'SECGT10 Weights by Year (21-23)'!D54 -> 0.07201484 | D12: =+'SECGT10 Weights by Year (21-23)'!E54 -> 0.073220001 | E12: =+'SECGT10 Weights by Year (21-23)'!F54 -> 0.073166599 | F12: =+'SECGT10 Weights by Year (21-23)'!G54 -> 0.075845117 | G12: =+'SECGT10 Weights by Year (21-23)'!H54 -> 0.072564185 | H12: =+'SECGT10 Weights by Year (21-23)'!I54 -> 0.066924379 | I12: =+'SECGT10 Weights by Year (21-23)'!J54 -> 0.067407718 | J12: =+'SECGT10 Weights by Year (21-23)'!K54 -> 0.065742487 | ... O12: =+'SECGT10 Weights by Year (21-23)'!P54 -> 0.069427566
A13: =+A12+1 -> 3 | B13: Lufkin | C13: =+'SECGT10 Weights by Year (21-23)'!D19 -> 0.023933489 | D13: =+'SECGT10 Weights by Year (21-23)'!E19 -> 0.024018641 | E13: =+'SECGT10 Weights by Year (21-23)'!F19 -> 0.024026881 | F13: =+'SECGT10 Weights by Year (21-23)'!G19 -> 0.024485182 | G13: =+'SECGT10 Weights by Year (21-23)'!H19 -> 0.024836227 | H13: =+'SECGT10 Weights by Year (21-23)'!I19 -> 0.025214532 | I13: =+'SECGT10 Weights by Year (21-23)'!J19 -> 0.024974872 | J13: =+'SECGT10 Weights by Year (21-23)'!K19 -> 0.024737832 | ... O13: =+'SECGT10 Weights by Year (21-23)'!P19 -> 0.02453547
A14: =+A13+1 -> 4 | B14: Abilene | C14: =+'SECGT10 Weights by Year (21-23)'!D44 -> 0.010887982 | D14: =+'SECGT10 Weights by Year (21-23)'!E44 -> 0.01113668 | E14: =+'SECGT10 Weights by Year (21-23)'!F44 -> 0.010844553 | F14: =+'SECGT10 Weights by Year (21-23)'!G44 -> 0.010707082 | G14: =+'SECGT10 Weights by Year (21-23)'!H44 -> 0.010641905 | H14: =+'SECGT10 Weights by Year (21-23)'!I44 -> 0.0068244114 | I14: =+'SECGT10 Weights by Year (21-23)'!J44 -> 0.010931988 | J14: =+'SECGT10 Weights by Year (21-23)'!K44 -> 0.010987608 | ... O14: =+'SECGT10 Weights by Year (21-23)'!P44 -> 0.010359265
A15: =+A14+1 -> 5 | B15: Sherman-Denison | C15: =+'SECGT10 Weights by Year (21-23)'!D59 -> 0.023990113 | D15: =+'SECGT10 Weights by Year (21-23)'!E59 -> 0.024379689 | E15: =+'SECGT10 Weights by Year (21-23)'!F59 -> 0.024528481 | F15: =+'SECGT10 Weights by Year (21-23)'!G59 -> 0.023816953 | G15: =+'SECGT10 Weights by Year (21-23)'!H59 -> 0.023478476 | H15: =+'SECGT10 Weights by Year (21-23)'!I59 -> 0.023671558 | I15: =+'SECGT10 Weights by Year (21-23)'!J59 -> 0.023682202 | J15: =+'SECGT10 Weights by Year (21-23)'!K59 -> 0.023936227 | ... O15: =+'SECGT10 Weights by Year (21-23)'!P59 -> 0.023929384
A16: =+A15+1 -> 6 | B16: Killeen-Temple | C16: =+'SECGT10 Weights by Year (21-23)'!D29 -> 0.026520175 | D16: =+'SECGT10 Weights by Year (21-23)'!E29 -> 0.026764592 | E16: =+'SECGT10 Weights by Year (21-23)'!F29 -> 0.027112216 | F16: =+'SECGT10 Weights by Year (21-23)'!G29 -> 0.026901611 | G16: =+'SECGT10 Weights by Year (21-23)'!H29 -> 0.027420974 | H16: =+'SECGT10 Weights by Year (21-23)'!I29 -> 0.027630763 | I16: =+'SECGT10 Weights by Year (21-23)'!J29 -> 0.02730936 | J16: =+'SECGT10 Weights by Year (21-23)'!K29 -> 0.027386463 | ... O16: =+'SECGT10 Weights by Year (21-23)'!P29 -> 0.027336567
A17: =+A16+1 -> 7 | B17: Waco | C17: =+'SECGT10 Weights by Year (21-23)'!D39 -> 0.031941384 | D17: =+'SECGT10 Weights by Year (21-23)'!E39 -> 0.03182022 | E17: =+'SECGT10 Weights by Year (21-23)'!F39 -> 0.03255243 | F17: =+'SECGT10 Weights by Year (21-23)'!G39 -> 0.032402357 | G17: =+'SECGT10 Weights by Year (21-23)'!H39 -> 0.033065372 | H17: =+'SECGT10 Weights by Year (21-23)'!I39 -> 0.033673475 | I17: =+'SECGT10 Weights by Year (21-23)'!J39 -> 0.033763143 | J17: =+'SECGT10 Weights by Year (21-23)'!K39 -> 0.033608391 | ... O17: =+'SECGT10 Weights by Year (21-23)'!P39 -> 0.033226325
A18: =+A17+1 -> 8 | B18: Wichita Falls. | C18: =+'SECGT10 Weights by Year (21-23)'!D49 -> 0.013696096 | D18: =+'SECGT10 Weights by Year (21-23)'!E49 -> 0.013998398 | E18: =+'SECGT10 Weights by Year (21-23)'!F49 -> 0.01424117 | F18: =+'SECGT10 Weights by Year (21-23)'!G49 -> 0.013631317 | G18: =+'SECGT10 Weights by Year (21-23)'!H49 -> 0.01376896 | H18: =+'SECGT10 Weights by Year (21-23)'!I49 -> 0.01413139 | I18: =+'SECGT10 Weights by Year (21-23)'!J49 -> 0.014487373 | J18: =+'SECGT10 Weights by Year (21-23)'!K49 -> 0.014722877 | ... O18: =+'SECGT10 Weights by Year (21-23)'!P49 -> 0.014193924
A19: =+A18+1 -> 9 | B19: Longview | C19: =+'SECGT10 Weights by Year (21-23)'!D34 -> 0.030542201 | D19: =+'SECGT10 Weights by Year (21-23)'!E34 -> 0.030313625 | E19: =+'SECGT10 Weights by Year (21-23)'!F34 -> 0.030667349 | F19: =+'SECGT10 Weights by Year (21-23)'!G34 -> 0.030333631 | G19: =+'SECGT10 Weights by Year (21-23)'!H34 -> 0.030702555 | H19: =+'SECGT10 Weights by Year (21-23)'!I34 -> 0.031410058 | I19: =+'SECGT10 Weights by Year (21-23)'!J34 -> 0.031353177 | J19: =+'SECGT10 Weights by Year (21-23)'!K34 -> 0.031216791 | ... O19: =+'SECGT10 Weights by Year (21-23)'!P34 -> 0.030883103
A20: =+A19+1 -> 10 | B20: Austin | C20: =+'SECGT10 Weights by Year (21-23)'!D24 -> 0.028374288 | D20: =+'SECGT10 Weights by Year (21-23)'!E24 -> 0.027897439 | E20: =+'SECGT10 Weights by Year (21-23)'!F24 -> 0.028371938 | F20: =+'SECGT10 Weights by Year (21-23)'!G24 -> 0.02905506 | G20: =+'SECGT10 Weights by Year (21-23)'!H24 -> 0.029831858 | H20: =+'SECGT10 Weights by Year (21-23)'!I24 -> 0.030074144 | I20: =+'SECGT10 Weights by Year (21-23)'!J24 -> 0.029163875 | J20: =+'SECGT10 Weights by Year (21-23)'!K24 -> 0.028773382 | ... O20: =+'SECGT10 Weights by Year (21-23)'!P24 -> 0.029143966
C21: =SUM(C11:C20) -> 1 | D21: =SUM(D11:D20) -> 1 | E21: =SUM(E11:E20) -> 1 | F21: =SUM(F11:F20) -> 1 | G21: =SUM(G11:G20) -> 1 | H21: =SUM(H11:H20) -> 1 | I21: =SUM(I11:I20) -> 1 | J21: =SUM(J11:J20) -> 1 | ... O21: =SUM(O11:O20) -> 1

Sheet SECGT10 Weights by Year (21-23)
B1: PUC DOCKET NO.
B2: ONCOR ELECTRIC DELIVERY COMPANY
B3: WEATHER WEIGHTS
B4: =+'SECGT10 Seasonal Weights'!B4:P4 -> FOR THE TEST YEAR ENDING DECEMBER 31, 2024
B6: SPONSOR: D. E. NELSON
B8: SECONDARY SERVICE GREATER THAN 10 KW MONTHLY WEIGHTS
A9: Line | B9: (a) | C9: (b) | D9: (c) | E9: (d) | F9: (e) | G9: (f) | H9: (g) | I9: (h) | J9: (i) | K9: (j) | L9: (k) | M9: (l) | N9: (m) | O9: (n) | P9: (o)
A10: No. | B10: Weather Station | C10: Year | D10: 36892 | E10: 36923 | F10: 36951 | G10: 36982 | H10: 37012 | I10: 37043 | J10: 37073 | K10: 37104 | L10: 37135 | M10: 37165 | N10: 37196 | O10: 37226 | P10: Annual
A11: 1 | B11: Dallas-Fort Worth | C11: 2021 | D11: ='SECGT10 Sales by Year (21-23)'!D11/'SECGT10 Sales by Year (21-23)'!D61 -> 0.73954677 | E11: ='SECGT10 Sales by Year (21-23)'!E11/'SECGT10 Sales by Year (21-23)'!E$61 -> 0.74100466 | F11: ='SECGT10 Sales by Year (21-23)'!F11/'SECGT10 Sales by Year (21-23)'!F$61 -> 0.73718482 | G11: ='SECGT10 Sales by Year (21-23)'!G11/'SECGT10 Sales by Year (21-23)'!G$61 -> 0.73354604 | H11: ='SECGT10 Sales by Year (21-23)'!H11/'SECGT10 Sales by Year (21-23)'!H$61 -> 0.73184237 | I11: ='SECGT10 Sales by Year (21-23)'!I11/'SECGT10 Sales by Year (21-23)'!I$61 -> 0.74420685 | J11: ='SECGT10 Sales by Year (21-23)'!J11/'SECGT10 Sales by Year (21-23)'!J$61 -> 0.73995547 | K11: ='SECGT10 Sales by Year (21-23)'!K11/'SECGT10 Sales by Year (21-23)'!K$61 -> 0.74304161 | L11: ='SECGT10 Sales by Year (21-23)'!L11/'SECGT10 Sales by Year (21-23)'!L$61 -> 0.74380057 | ... P11: ='SECGT10 Sales by Year (21-23)'!P11/'SECGT10 Sales by Year (21-23)'!P$61 -> 0.73991222
A12: =+A11+1 -> 2 | B12: Dallas-Fort Worth | C12: 2022 | D12: ='SECGT10 Sales by Year (21-23)'!D12/'SECGT10 Sales by Year (21-23)'!D62 -> 0.73956736 | E12: ='SECGT10 Sales by Year (21-23)'!E12/'SECGT10 Sales by Year (21-23)'!E$62 -> 0.73368341 | F12: ='SECGT10 Sales by Year (21-23)'!F12/'SECGT10 Sales by Year (21-23)'!F$62 -> 0.73637557 | G12: ='SECGT10 Sales by Year (21-23)'!G12/'SECGT10 Sales by Year (21-23)'!G$62 -> 0.73556936 | H12: ='SECGT10 Sales by Year (21-23)'!H12/'SECGT10 Sales by Year (21-23)'!H$62 -> 0.73388015 | I12: ='SECGT10 Sales by Year (21-23)'!I12/'SECGT10 Sales by Year (21-23)'!I$62 -> 0.74172031 | J12: ='SECGT10 Sales by Year (21-23)'!J12/'SECGT10 Sales by Year (21-23)'!J$62 -> 0.73903919 | K12: ='SECGT10 Sales by Year (21-23)'!K12/'SECGT10 Sales by Year (21-23)'!K$62 -> 0.73969502 | L12: ='SECGT10 Sales by Year (21-23)'!L12/'SECGT10 Sales by Year (21-23)'!L$62 -> 0.73811149 | ... P12: ='SECGT10 Sales by Year (21-23)'!P12/'SECGT10 Sales by Year (21-23)'!P$62 -> 0.73732735
A13: =+A12+1 -> 3 | B13: Dallas-Fort Worth | C13: 2023 | D13: ='SECGT10 Sales by Year (21-23)'!D13/'SECGT10 Sales by Year (21-23)'!D63 -> 0.73532771 | E13: ='SECGT10 Sales by Year (21-23)'!E13/'SECGT10 Sales by Year (21-23)'!E63 -> 0.73495923 | F13: ='SECGT10 Sales by Year (21-23)'!F13/'SECGT10 Sales by Year (21-23)'!F63 -> 0.72988314 | G13: ='SECGT10 Sales by Year (21-23)'!G13/'SECGT10 Sales by Year (21-23)'!G63 -> 0.72937491 | H13: ='SECGT10 Sales by Year (21-23)'!H13/'SECGT10 Sales by Year (21-23)'!H63 -> 0.73529864 | I13: ='SECGT10 Sales by Year (21-23)'!I13/'SECGT10 Sales by Year (21-23)'!I63 -> 0.73563305 | J13: ='SECGT10 Sales by Year (21-23)'!J13/'SECGT10 Sales by Year (21-23)'!J63 -> 0.73190547 | K13: ='SECGT10 Sales by Year (21-23)'!K13/'SECGT10 Sales by Year (21-23)'!K63 -> 0.73431981 | ... P13: ='SECGT10 Sales by Year (21-23)'!P13/'SECGT10 Sales by Year (21-23)'!P63 -> 0.73383497
A14: =+A13+1 -> 4 | B14: Dallas-Fort Worth | C14: Total | D14: ='SECGT10 Sales by Year (21-23)'!D14/'SECGT10 Sales by Year (21-23)'!D64 -> 0.73809943 | E14: ='SECGT10 Sales by Year (21-23)'!E14/'SECGT10 Sales by Year (21-23)'!E64 -> 0.73645072 | F14: ='SECGT10 Sales by Year (21-23)'!F14/'SECGT10 Sales by Year (21-23)'!F64 -> 0.73448838 | G14: ='SECGT10 Sales by Year (21-23)'!G14/'SECGT10 Sales by Year (21-23)'!G64 -> 0.73282169 | H14: ='SECGT10 Sales by Year (21-23)'!H14/'SECGT10 Sales by Year (21-23)'!H64 -> 0.73368949 | I14: ='SECGT10 Sales by Year (21-23)'!I14/'SECGT10 Sales by Year (21-23)'!I64 -> 0.74044529 | J14: ='SECGT10 Sales by Year (21-23)'!J14/'SECGT10 Sales by Year (21-23)'!J64 -> 0.73692629 | K14: ='SECGT10 Sales by Year (21-23)'!K14/'SECGT10 Sales by Year (21-23)'!K64 -> 0.73888794 | ... P14: ='SECGT10 Sales by Year (21-23)'!P14/'SECGT10 Sales by Year (21-23)'!P64 -> 0.73696443
A15: =+A14+1 -> 5
A16: =+A15+1 -> 6 | B16: Lufkin | C16: =+C11 -> 2021 | D16: ='SECGT10 Sales by Year (21-23)'!D16/'SECGT10 Sales by Year (21-23)'!D61 -> 0.024284365 | E16: ='SECGT10 Sales by Year (21-23)'!E16/'SECGT10 Sales by Year (21-23)'!E$61 -> 0.02428211 | F16: ='SECGT10 Sales by Year (21-23)'!F16/'SECGT10 Sales by Year (21-23)'!F$61 -> 0.024030179 | G16: ='SECGT10 Sales by Year (21-23)'!G16/'SECGT10 Sales by Year (21-23)'!G$61 -> 0.024975023 | H16: ='SECGT10 Sales by Year (21-23)'!H16/'SECGT10 Sales by Year (21-23)'!H$61 -> 0.025466464 | I16: ='SECGT10 Sales by Year (21-23)'!I16/'SECGT10 Sales by Year (21-23)'!I$61 -> 0.025676186 | J16: ='SECGT10 Sales by Year (21-23)'!J16/'SECGT10 Sales by Year (21-23)'!J$61 -> 0.025000793 | K16: ='SECGT10 Sales by Year (21-23)'!K16/'SECGT10 Sales by Year (21-23)'!K$61 -> 0.024898591 | L16: ='SECGT10 Sales by Year (21-23)'!L16/'SECGT10 Sales by Year (21-23)'!L$61 -> 0.025206621 | ... P16: ='SECGT10 Sales by Year (21-23)'!P16/'SECGT10 Sales by Year (21-23)'!P$61 -> 0.024886152
A17: =+A16+1 -> 7 | B17: Lufkin | C17: =+C12 -> 2022 | D17: ='SECGT10 Sales by Year (21-23)'!D17/'SECGT10 Sales by Year (21-23)'!D62 -> 0.023883565 | E17: ='SECGT10 Sales by Year (21-23)'!E17/'SECGT10 Sales by Year (21-23)'!E$62 -> 0.024350583 | F17: ='SECGT10 Sales by Year (21-23)'!F17/'SECGT10 Sales by Year (21-23)'!F$62 -> 0.024189936 | G17: ='SECGT10 Sales by Year (21-23)'!G17/'SECGT10 Sales by Year (21-23)'!G$62 -> 0.024439745 | H17: ='SECGT10 Sales by Year (21-23)'!H17/'SECGT10 Sales by Year (21-23)'!H$62 -> 0.024926718 | I17: ='SECGT10 Sales by Year (21-23)'!I17/'SECGT10 Sales by Year (21-23)'!I$62 -> 0.025435481 | J17: ='SECGT10 Sales by Year (21-23)'!J17/'SECGT10 Sales by Year (21-23)'!J$62 -> 0.02500883 | K17: ='SECGT10 Sales by Year (21-23)'!K17/'SECGT10 Sales by Year (21-23)'!K$62 -> 0.024653463 | L17: ='SECGT10 Sales by Year (21-23)'!L17/'SECGT10 Sales by Year (21-23)'!L$62 -> 0.024859669 | ... P17: ='SECGT10 Sales by Year (21-23)'!P17/'SECGT10 Sales by Year (21-23)'!P$62 -> 0.02457698
A18: =+A17+1 -> 8 | B18: Lufkin | C18: =+C13 -> 2023 | D18: ='SECGT10 Sales by Year (21-23)'!D18/'SECGT10 Sales by Year (21-23)'!D63 -> 0.023651976 | E18: ='SECGT10 Sales by Year (21-23)'!E18/'SECGT10 Sales by Year (21-23)'!E63 -> 0.023441759 | F18: ='SECGT10 Sales by Year (21-23)'!F18/'SECGT10 Sales by Year (21-23)'!F63 -> 0.023855674 | G18: ='SECGT10 Sales by Year (21-23)'!G18/'SECGT10 Sales by Year (21-23)'!G63 -> 0.024063876 | H18: ='SECGT10 Sales by Year (21-23)'!H18/'SECGT10 Sales by Year (21-23)'!H63 -> 0.024121583 | I18: ='SECGT10 Sales by Year (21-23)'!I18/'SECGT10 Sales by Year (21-23)'!I63 -> 0.024556617 | J18: ='SECGT10 Sales by Year (21-23)'!J18/'SECGT10 Sales by Year (21-23)'!J63 -> 0.024915802 | K18: ='SECGT10 Sales by Year (21-23)'!K18/'SECGT10 Sales by Year (21-23)'!K63 -> 0.02467848 | ... P18: ='SECGT10 Sales by Year (21-23)'!P18/'SECGT10 Sales by Year (21-23)'!P63 -> 0.024164829
A19: =+A18+1 -> 9 | B19: Lufkin | C19: Total | D19: ='SECGT10 Sales by Year (21-23)'!D19/'SECGT10 Sales by Year (21-23)'!D64 -> 0.023933489 | E19: ='SECGT10 Sales by Year (21-23)'!E19/'SECGT10 Sales by Year (21-23)'!E64 -> 0.024018641 | F19: ='SECGT10 Sales by Year (21-23)'!F19/'SECGT10 Sales by Year (21-23)'!F64 -> 0.024026881 | G19: ='SECGT10 Sales by Year (21-23)'!G19/'SECGT10 Sales by Year (21-23)'!G64 -> 0.024485182 | H19: ='SECGT10 Sales by Year (21-23)'!H19/'SECGT10 Sales by Year (21-23)'!H64 -> 0.024836227 | I19: ='SECGT10 Sales by Year (21-23)'!I19/'SECGT10 Sales by Year (21-23)'!I64 -> 0.025214532 | J19: ='SECGT10 Sales by Year (21-23)'!J19/'SECGT10 Sales by Year (21-23)'!J64 -> 0.024974872 | K19: ='SECGT10 Sales by Year (21-23)'!K19/'SECGT10 Sales by Year (21-23)'!K64 -> 0.024737832 | ... P19: ='SECGT10 Sales by Year (21-23)'!P19/'SECGT10 Sales by Year (21-23)'!P64 -> 0.02453547
A20: =+A19+1 -> 10
A21: =+A20+1 -> 11 | B21: Austin | C21: =+C16 -> 2021 | D21: ='SECGT10 Sales by Year (21-23)'!D21/'SECGT10 Sales by Year (21-23)'!D61 -> 0.027540912 | E21: ='SECGT10 Sales by Year (21-23)'!E21/'SECGT10 Sales by Year (21-23)'!E$61 -> 0.027037504 | F21: ='SECGT10 Sales by Year (21-23)'!F21/'SECGT10 Sales by Year (21-23)'!F$61 -> 0.02753816 | G21: ='SECGT10 Sales by Year (21-23)'!G21/'SECGT10 Sales by Year (21-23)'!G$61 -> 0.028246025 | H21: ='SECGT10 Sales by Year (21-23)'!H21/'SECGT10 Sales by Year (21-23)'!H$61 -> 0.029109899 | I21: ='SECGT10 Sales by Year (21-23)'!I21/'SECGT10 Sales by Year (21-23)'!I$61 -> 0.029667115 | J21: ='SECGT10 Sales by Year (21-23)'!J21/'SECGT10 Sales by Year (21-23)'!J$61 -> 0.028483648 | K21: ='SECGT10 Sales by Year (21-23)'!K21/'SECGT10 Sales by Year (21-23)'!K$61 -> 0.027965768 | L21: ='SECGT10 Sales by Year (21-23)'!L21/'SECGT10 Sales by Year (21-23)'!L$61 -> 0.029578644 | ... P21: ='SECGT10 Sales by Year (21-23)'!P21/'SECGT10 Sales by Year (21-23)'!P$61 -> 0.028461074
A22: =+A21+1 -> 12 | B22: Austin | C22: =+C17 -> 2022 | D22: ='SECGT10 Sales by Year (21-23)'!D22/'SECGT10 Sales by Year (21-23)'!D62 -> 0.02863931 | E22: ='SECGT10 Sales by Year (21-23)'!E22/'SECGT10 Sales by Year (21-23)'!E$62 -> 0.028064101 | F22: ='SECGT10 Sales by Year (21-23)'!F22/'SECGT10 Sales by Year (21-23)'!F$62 -> 0.027843255 | G22: ='SECGT10 Sales by Year (21-23)'!G22/'SECGT10 Sales by Year (21-23)'!G$62 -> 0.029130358 | H22: ='SECGT10 Sales by Year (21-23)'!H22/'SECGT10 Sales by Year (21-23)'!H$62 -> 0.030185736 | I22: ='SECGT10 Sales by Year (21-23)'!I22/'SECGT10 Sales by Year (21-23)'!I$62 -> 0.030182805 | J22: ='SECGT10 Sales by Year (21-23)'!J22/'SECGT10 Sales by Year (21-23)'!J$62 -> 0.028745774 | K22: ='SECGT10 Sales by Year (21-23)'!K22/'SECGT10 Sales by Year (21-23)'!K$62 -> 0.028618231 | L22: ='SECGT10 Sales by Year (21-23)'!L22/'SECGT10 Sales by Year (21-23)'!L$62 -> 0.029436555 | ... P22: ='SECGT10 Sales by Year (21-23)'!P22/'SECGT10 Sales by Year (21-23)'!P$62 -> 0.029102037
A23: =+A22+1 -> 13 | B23: Austin | C23: =+C18 -> 2023 | D23: ='SECGT10 Sales by Year (21-23)'!D23/'SECGT10 Sales by Year (21-23)'!D63 -> 0.028902016 | E23: ='SECGT10 Sales by Year (21-23)'!E23/'SECGT10 Sales by Year (21-23)'!E63 -> 0.028533925 | F23: ='SECGT10 Sales by Year (21-23)'!F23/'SECGT10 Sales by Year (21-23)'!F63 -> 0.029739439 | G23: ='SECGT10 Sales by Year (21-23)'!G23/'SECGT10 Sales by Year (21-23)'!G63 -> 0.029750647 | H23: ='SECGT10 Sales by Year (21-23)'!H23/'SECGT10 Sales by Year (21-23)'!H63 -> 0.030163396 | I23: ='SECGT10 Sales by Year (21-23)'!I23/'SECGT10 Sales by Year (21-23)'!I63 -> 0.030337347 | J23: ='SECGT10 Sales by Year (21-23)'!J23/'SECGT10 Sales by Year (21-23)'!J63 -> 0.030234161 | K23: ='SECGT10 Sales by Year (21-23)'!K23/'SECGT10 Sales by Year (21-23)'!K63 -> 0.029659779 | ... P23: ='SECGT10 Sales by Year (21-23)'!P23/'SECGT10 Sales by Year (21-23)'!P63 -> 0.029827136
A24: =+A23+1 -> 14 | B24: Austin | C24: Total | D24: ='SECGT10 Sales by Year (21-23)'!D24/'SECGT10 Sales by Year (21-23)'!D64 -> 0.028374288 | E24: ='SECGT10 Sales by Year (21-23)'!E24/'SECGT10 Sales by Year (21-23)'!E64 -> 0.027897439 | F24: ='SECGT10 Sales by Year (21-23)'!F24/'SECGT10 Sales by Year (21-23)'!F64 -> 0.028371938 | G24: ='SECGT10 Sales by Year (21-23)'!G24/'SECGT10 Sales by Year (21-23)'!G64 -> 0.02905506 | H24: ='SECGT10 Sales by Year (21-23)'!H24/'SECGT10 Sales by Year (21-23)'!H64 -> 0.029831858 | I24: ='SECGT10 Sales by Year (21-23)'!I24/'SECGT10 Sales by Year (21-23)'!I64 -> 0.030074144 | J24: ='SECGT10 Sales by Year (21-23)'!J24/'SECGT10 Sales by Year (21-23)'!J64 -> 0.029163875 | K24: ='SECGT10 Sales by Year (21-23)'!K24/'SECGT10 Sales by Year (21-23)'!K64 -> 0.028773382 | ... P24: ='SECGT10 Sales by Year (21-23)'!P24/'SECGT10 Sales by Year (21-23)'!P64 -> 0.029143966
A25: =+A24+1 -> 15
A26: =+A25+1 -> 16 | B26: Killeen | C26: =+C21 -> 2021 | D26: ='SECGT10 Sales by Year (21-23)'!D26/'SECGT10 Sales by Year (21-23)'!D61 -> 0.026956722 | E26: ='SECGT10 Sales by Year (21-23)'!E26/'SECGT10 Sales by Year (21-23)'!E$61 -> 0.025973827 | F26: ='SECGT10 Sales by Year (21-23)'!F26/'SECGT10 Sales by Year (21-23)'!F$61 -> 0.027371005 | G26: ='SECGT10 Sales by Year (21-23)'!G26/'SECGT10 Sales by Year (21-23)'!G$61 -> 0.027063345 | H26: ='SECGT10 Sales by Year (21-23)'!H26/'SECGT10 Sales by Year (21-23)'!H$61 -> 0.027683286 | I26: ='SECGT10 Sales by Year (21-23)'!I26/'SECGT10 Sales by Year (21-23)'!I$61 -> 0.027355955 | J26: ='SECGT10 Sales by Year (21-23)'!J26/'SECGT10 Sales by Year (21-23)'!J$61 -> 0.026245582 | K26: ='SECGT10 Sales by Year (21-23)'!K26/'SECGT10 Sales by Year (21-23)'!K$61 -> 0.026198116 | L26: ='SECGT10 Sales by Year (21-23)'!L26/'SECGT10 Sales by Year (21-23)'!L$61 -> 0.027504522 | ... P26: ='SECGT10 Sales by Year (21-23)'!P26/'SECGT10 Sales by Year (21-23)'!P$61 -> 0.027084252
A27: =+A26+1 -> 17 | B27: Killeen | C27: =+C22 -> 2022 | D27: ='SECGT10 Sales by Year (21-23)'!D27/'SECGT10 Sales by Year (21-23)'!D62 -> 0.025958401 | E27: ='SECGT10 Sales by Year (21-23)'!E27/'SECGT10 Sales by Year (21-23)'!E$62 -> 0.027443349 | F27: ='SECGT10 Sales by Year (21-23)'!F27/'SECGT10 Sales by Year (21-23)'!F$62 -> 0.026843205 | G27: ='SECGT10 Sales by Year (21-23)'!G27/'SECGT10 Sales by Year (21-23)'!G$62 -> 0.026797549 | H27: ='SECGT10 Sales by Year (21-23)'!H27/'SECGT10 Sales by Year (21-23)'!H$62 -> 0.027626645 | I27: ='SECGT10 Sales by Year (21-23)'!I27/'SECGT10 Sales by Year (21-23)'!I$62 -> 0.028011864 | J27: ='SECGT10 Sales by Year (21-23)'!J27/'SECGT10 Sales by Year (21-23)'!J$62 -> 0.027454686 | K27: ='SECGT10 Sales by Year (21-23)'!K27/'SECGT10 Sales by Year (21-23)'!K$62 -> 0.027734656 | L27: ='SECGT10 Sales by Year (21-23)'!L27/'SECGT10 Sales by Year (21-23)'!L$62 -> 0.027764153 | ... P27: ='SECGT10 Sales by Year (21-23)'!P27/'SECGT10 Sales by Year (21-23)'!P$62 -> 0.027397472
A28: =+A27+1 -> 18 | B28: Killeen | C28: =+C23 -> 2023 | D28: ='SECGT10 Sales by Year (21-23)'!D28/'SECGT10 Sales by Year (21-23)'!D63 -> 0.026650674 | E28: ='SECGT10 Sales by Year (21-23)'!E28/'SECGT10 Sales by Year (21-23)'!E63 -> 0.026825935 | F28: ='SECGT10 Sales by Year (21-23)'!F28/'SECGT10 Sales by Year (21-23)'!F63 -> 0.027133876 | G28: ='SECGT10 Sales by Year (21-23)'!G28/'SECGT10 Sales by Year (21-23)'!G63 -> 0.026851846 | H28: ='SECGT10 Sales by Year (21-23)'!H28/'SECGT10 Sales by Year (21-23)'!H63 -> 0.026944666 | I28: ='SECGT10 Sales by Year (21-23)'!I28/'SECGT10 Sales by Year (21-23)'!I63 -> 0.027487139 | J28: ='SECGT10 Sales by Year (21-23)'!J28/'SECGT10 Sales by Year (21-23)'!J63 -> 0.028172455 | K28: ='SECGT10 Sales by Year (21-23)'!K28/'SECGT10 Sales by Year (21-23)'!K63 -> 0.028105063 | ... P28: ='SECGT10 Sales by Year (21-23)'!P28/'SECGT10 Sales by Year (21-23)'!P63 -> 0.027513202
A29: =+A28+1 -> 19 | B29: Killeen | C29: Total | D29: ='SECGT10 Sales by Year (21-23)'!D29/'SECGT10 Sales by Year (21-23)'!D64 -> 0.026520175 | E29: ='SECGT10 Sales by Year (21-23)'!E29/'SECGT10 Sales by Year (21-23)'!E64 -> 0.026764592 | F29: ='SECGT10 Sales by Year (21-23)'!F29/'SECGT10 Sales by Year (21-23)'!F64 -> 0.027112216 | G29: ='SECGT10 Sales by Year (21-23)'!G29/'SECGT10 Sales by Year (21-23)'!G64 -> 0.026901611 | H29: ='SECGT10 Sales by Year (21-23)'!H29/'SECGT10 Sales by Year (21-23)'!H64 -> 0.027420974 | I29: ='SECGT10 Sales by Year (21-23)'!I29/'SECGT10 Sales by Year (21-23)'!I64 -> 0.027630763 | J29: ='SECGT10 Sales by Year (21-23)'!J29/'SECGT10 Sales by Year (21-23)'!J64 -> 0.02730936 | K29: ='SECGT10 Sales by Year (21-23)'!K29/'SECGT10 Sales by Year (21-23)'!K64 -> 0.027386463 | ... P29: ='SECGT10 Sales by Year (21-23)'!P29/'SECGT10 Sales by Year (21-23)'!P64 -> 0.027336567
A30: =+A29+1 -> 20
A31: =+A30+1 -> 21 | B31: Longview | C31: =+C26 -> 2021 | D31: ='SECGT10 Sales by Year (21-23)'!D31/'SECGT10 Sales by Year (21-23)'!D61 -> 0.030783329 | E31: ='SECGT10 Sales by Year (21-23)'!E31/'SECGT10 Sales by Year (21-23)'!E$61 -> 0.030813143 | F31: ='SECGT10 Sales by Year (21-23)'!F31/'SECGT10 Sales by Year (21-23)'!F$61 -> 0.030692731 | G31: ='SECGT10 Sales by Year (21-23)'!G31/'SECGT10 Sales by Year (21-23)'!G$61 -> 0.030835316 | H31: ='SECGT10 Sales by Year (21-23)'!H31/'SECGT10 Sales by Year (21-23)'!H$61 -> 0.031210437 | I31: ='SECGT10 Sales by Year (21-23)'!I31/'SECGT10 Sales by Year (21-23)'!I$61 -> 0.031721856 | J31: ='SECGT10 Sales by Year (21-23)'!J31/'SECGT10 Sales by Year (21-23)'!J$61 -> 0.031520873 | K31: ='SECGT10 Sales by Year (21-23)'!K31/'SECGT10 Sales by Year (21-23)'!K$61 -> 0.031176078 | L31: ='SECGT10 Sales by Year (21-23)'!L31/'SECGT10 Sales by Year (21-23)'!L$61 -> 0.031539824 | ... P31: ='SECGT10 Sales by Year (21-23)'!P31/'SECGT10 Sales by Year (21-23)'!P$61 -> 0.031184754
A32: =+A31+1 -> 22 | B32: Longview | C32: =+C27 -> 2022 | D32: ='SECGT10 Sales by Year (21-23)'!D32/'SECGT10 Sales by Year (21-23)'!D62 -> 0.030257053 | E32: ='SECGT10 Sales by Year (21-23)'!E32/'SECGT10 Sales by Year (21-23)'!E$62 -> 0.030235947 | F32: ='SECGT10 Sales by Year (21-23)'!F32/'SECGT10 Sales by Year (21-23)'!F$62 -> 0.03057242 | G32: ='SECGT10 Sales by Year (21-23)'!G32/'SECGT10 Sales by Year (21-23)'!G$62 -> 0.030305352 | H32: ='SECGT10 Sales by Year (21-23)'!H32/'SECGT10 Sales by Year (21-23)'!H$62 -> 0.030399622 | I32: ='SECGT10 Sales by Year (21-23)'!I32/'SECGT10 Sales by Year (21-23)'!I$62 -> 0.03159301 | J32: ='SECGT10 Sales by Year (21-23)'!J32/'SECGT10 Sales by Year (21-23)'!J$62 -> 0.031534547 | K32: ='SECGT10 Sales by Year (21-23)'!K32/'SECGT10 Sales by Year (21-23)'!K$62 -> 0.031043116 | L32: ='SECGT10 Sales by Year (21-23)'!L32/'SECGT10 Sales by Year (21-23)'!L$62 -> 0.030980139 | ... P32: ='SECGT10 Sales by Year (21-23)'!P32/'SECGT10 Sales by Year (21-23)'!P$62 -> 0.030760381
A33: =+A32+1 -> 23 | B33: Longview | C33: =+C28 -> 2023 | D33: ='SECGT10 Sales by Year (21-23)'!D33/'SECGT10 Sales by Year (21-23)'!D63 -> 0.030590085 | E33: ='SECGT10 Sales by Year (21-23)'!E33/'SECGT10 Sales by Year (21-23)'!E63 -> 0.029924828 | F33: ='SECGT10 Sales by Year (21-23)'!F33/'SECGT10 Sales by Year (21-23)'!F63 -> 0.030740074 | G33: ='SECGT10 Sales by Year (21-23)'!G33/'SECGT10 Sales by Year (21-23)'!G63 -> 0.029883822 | H33: ='SECGT10 Sales by Year (21-23)'!H33/'SECGT10 Sales by Year (21-23)'!H63 -> 0.030526802 | I33: ='SECGT10 Sales by Year (21-23)'!I33/'SECGT10 Sales by Year (21-23)'!I63 -> 0.030930491 | J33: ='SECGT10 Sales by Year (21-23)'!J33/'SECGT10 Sales by Year (21-23)'!J63 -> 0.031009898 | K33: ='SECGT10 Sales by Year (21-23)'!K33/'SECGT10 Sales by Year (21-23)'!K63 -> 0.031429973 | ... P33: ='SECGT10 Sales by Year (21-23)'!P33/'SECGT10 Sales by Year (21-23)'!P63 -> 0.030721435
A34: =+A33+1 -> 24 | B34: Longview | C34: Total | D34: ='SECGT10 Sales by Year (21-23)'!D34/'SECGT10 Sales by Year (21-23)'!D64 -> 0.030542201 | E34: ='SECGT10 Sales by Year (21-23)'!E34/'SECGT10 Sales by Year (21-23)'!E64 -> 0.030313625 | F34: ='SECGT10 Sales by Year (21-23)'!F34/'SECGT10 Sales by Year (21-23)'!F64 -> 0.030667349 | G34: ='SECGT10 Sales by Year (21-23)'!G34/'SECGT10 Sales by Year (21-23)'!G64 -> 0.030333631 | H34: ='SECGT10 Sales by Year (21-23)'!H34/'SECGT10 Sales by Year (21-23)'!H64 -> 0.030702555 | I34: ='SECGT10 Sales by Year (21-23)'!I34/'SECGT10 Sales by Year (21-23)'!I64 -> 0.031410058 | J34: ='SECGT10 Sales by Year (21-23)'!J34/'SECGT10 Sales by Year (21-23)'!J64 -> 0.031353177 | K34: ='SECGT10 Sales by Year (21-23)'!K34/'SECGT10 Sales by Year (21-23)'!K64 -> 0.031216791 | ... P34: ='SECGT10 Sales by Year (21-23)'!P34/'SECGT10 Sales by Year (21-23)'!P64 -> 0.030883103
A35: =+A34+1 -> 25
A36: =+A35+1 -> 26 | B36: Waco | C36: =+C31 -> 2021 | D36: ='SECGT10 Sales by Year (21-23)'!D36/'SECGT10 Sales by Year (21-23)'!D61 -> 0.031848448 | E36: ='SECGT10 Sales by Year (21-23)'!E36/'SECGT10 Sales by Year (21-23)'!E$61 -> 0.031237679 | F36: ='SECGT10 Sales by Year (21-23)'!F36/'SECGT10 Sales by Year (21-23)'!F$61 -> 0.03248311 | G36: ='SECGT10 Sales by Year (21-23)'!G36/'SECGT10 Sales by Year (21-23)'!G$61 -> 0.032598677 | H36: ='SECGT10 Sales by Year (21-23)'!H36/'SECGT10 Sales by Year (21-23)'!H$61 -> 0.033197767 | I36: ='SECGT10 Sales by Year (21-23)'!I36/'SECGT10 Sales by Year (21-23)'!I$61 -> 0.033468366 | J36: ='SECGT10 Sales by Year (21-23)'!J36/'SECGT10 Sales by Year (21-23)'!J$61 -> 0.033270199 | K36: ='SECGT10 Sales by Year (21-23)'!K36/'SECGT10 Sales by Year (21-23)'!K$61 -> 0.032754555 | L36: ='SECGT10 Sales by Year (21-23)'!L36/'SECGT10 Sales by Year (21-23)'!L$61 -> 0.033766318 | ... P36: ='SECGT10 Sales by Year (21-23)'!P36/'SECGT10 Sales by Year (21-23)'!P$61 -> 0.032923895
A37: =+A36+1 -> 27 | B37: Waco | C37: =+C32 -> 2022 | D37: ='SECGT10 Sales by Year (21-23)'!D37/'SECGT10 Sales by Year (21-23)'!D62 -> 0.030920128 | E37: ='SECGT10 Sales by Year (21-23)'!E37/'SECGT10 Sales by Year (21-23)'!E$62 -> 0.031910339 | F37: ='SECGT10 Sales by Year (21-23)'!F37/'SECGT10 Sales by Year (21-23)'!F$62 -> 0.032074445 | G37: ='SECGT10 Sales by Year (21-23)'!G37/'SECGT10 Sales by Year (21-23)'!G$62 -> 0.031986534 | H37: ='SECGT10 Sales by Year (21-23)'!H37/'SECGT10 Sales by Year (21-23)'!H$62 -> 0.032872647 | I37: ='SECGT10 Sales by Year (21-23)'!I37/'SECGT10 Sales by Year (21-23)'!I$62 -> 0.034007249 | J37: ='SECGT10 Sales by Year (21-23)'!J37/'SECGT10 Sales by Year (21-23)'!J$62 -> 0.034100019 | K37: ='SECGT10 Sales by Year (21-23)'!K37/'SECGT10 Sales by Year (21-23)'!K$62 -> 0.033846521 | L37: ='SECGT10 Sales by Year (21-23)'!L37/'SECGT10 Sales by Year (21-23)'!L$62 -> 0.034257631 | ... P37: ='SECGT10 Sales by Year (21-23)'!P37/'SECGT10 Sales by Year (21-23)'!P$62 -> 0.033268379
A38: =+A37+1 -> 28 | B38: Waco | C38: =+C33 -> 2023 | D38: ='SECGT10 Sales by Year (21-23)'!D38/'SECGT10 Sales by Year (21-23)'!D63 -> 0.03301127 | E38: ='SECGT10 Sales by Year (21-23)'!E38/'SECGT10 Sales by Year (21-23)'!E63 -> 0.032274105 | F38: ='SECGT10 Sales by Year (21-23)'!F38/'SECGT10 Sales by Year (21-23)'!F63 -> 0.033113184 | G38: ='SECGT10 Sales by Year (21-23)'!G38/'SECGT10 Sales by Year (21-23)'!G63 -> 0.032632379 | H38: ='SECGT10 Sales by Year (21-23)'!H38/'SECGT10 Sales by Year (21-23)'!H63 -> 0.033140666 | I38: ='SECGT10 Sales by Year (21-23)'!I38/'SECGT10 Sales by Year (21-23)'!I63 -> 0.033514768 | J38: ='SECGT10 Sales by Year (21-23)'!J38/'SECGT10 Sales by Year (21-23)'!J63 -> 0.033889679 | K38: ='SECGT10 Sales by Year (21-23)'!K38/'SECGT10 Sales by Year (21-23)'!K63 -> 0.034136951 | ... P38: ='SECGT10 Sales by Year (21-23)'!P38/'SECGT10 Sales by Year (21-23)'!P63 -> 0.033468745
A39: =+A38+1 -> 29 | B39: Waco | C39: Total | D39: ='SECGT10 Sales by Year (21-23)'!D39/'SECGT10 Sales by Year (21-23)'!D64 -> 0.031941384 | E39: ='SECGT10 Sales by Year (21-23)'!E39/'SECGT10 Sales by Year (21-23)'!E64 -> 0.03182022 | F39: ='SECGT10 Sales by Year (21-23)'!F39/'SECGT10 Sales by Year (21-23)'!F64 -> 0.03255243 | G39: ='SECGT10 Sales by Year (21-23)'!G39/'SECGT10 Sales by Year (21-23)'!G64 -> 0.032402357 | H39: ='SECGT10 Sales by Year (21-23)'!H39/'SECGT10 Sales by Year (21-23)'!H64 -> 0.033065372 | I39: ='SECGT10 Sales by Year (21-23)'!I39/'SECGT10 Sales by Year (21-23)'!I64 -> 0.033673475 | J39: ='SECGT10 Sales by Year (21-23)'!J39/'SECGT10 Sales by Year (21-23)'!J64 -> 0.033763143 | K39: ='SECGT10 Sales by Year (21-23)'!K39/'SECGT10 Sales by Year (21-23)'!K64 -> 0.033608391 | ... P39: ='SECGT10 Sales by Year (21-23)'!P39/'SECGT10 Sales by Year (21-23)'!P64 -> 0.033226325
A40: =+A39+1 -> 30
A41: =+A40+1 -> 31 | B41: Abilene | C41: =+C36 -> 2021 | D41: ='SECGT10 Sales by Year (21-23)'!D41/'SECGT10 Sales by Year (21-23)'!D61 -> 0.011488322 | E41: ='SECGT10 Sales by Year (21-23)'!E41/'SECGT10 Sales by Year (21-23)'!E$61 -> 0.011357073 | F41: ='SECGT10 Sales by Year (21-23)'!F41/'SECGT10 Sales by Year (21-23)'!F$61 -> 0.011305909 | G41: ='SECGT10 Sales by Year (21-23)'!G41/'SECGT10 Sales by Year (21-23)'!G$61 -> 0.010879974 | H41: ='SECGT10 Sales by Year (21-23)'!H41/'SECGT10 Sales by Year (21-23)'!H$61 -> 0.010397003 | I41: ='SECGT10 Sales by Year (21-23)'!I41/'SECGT10 Sales by Year (21-23)'!I$61 -> -0.0017623355 | J41: ='SECGT10 Sales by Year (21-23)'!J41/'SECGT10 Sales by Year (21-23)'!J$61 -> 0.010429046 | K41: ='SECGT10 Sales by Year (21-23)'!K41/'SECGT10 Sales by Year (21-23)'!K$61 -> 0.010664829 | L41: ='SECGT10 Sales by Year (21-23)'!L41/'SECGT10 Sales by Year (21-23)'!L$61 -> 0.01109159 | ... P41: ='SECGT10 Sales by Year (21-23)'!P41/'SECGT10 Sales by Year (21-23)'!P$61 -> 0.0097407629
A42: =+A41+1 -> 32 | B42: Abilene | C42: =+C37 -> 2022 | D42: ='SECGT10 Sales by Year (21-23)'!D42/'SECGT10 Sales by Year (21-23)'!D62 -> 0.010872771 | E42: ='SECGT10 Sales by Year (21-23)'!E42/'SECGT10 Sales by Year (21-23)'!E$62 -> 0.011367098 | F42: ='SECGT10 Sales by Year (21-23)'!F42/'SECGT10 Sales by Year (21-23)'!F$62 -> 0.010658692 | G42: ='SECGT10 Sales by Year (21-23)'!G42/'SECGT10 Sales by Year (21-23)'!G$62 -> 0.010632016 | H42: ='SECGT10 Sales by Year (21-23)'!H42/'SECGT10 Sales by Year (21-23)'!H$62 -> 0.010988667 | I42: ='SECGT10 Sales by Year (21-23)'!I42/'SECGT10 Sales by Year (21-23)'!I$62 -> 0.011382841 | J42: ='SECGT10 Sales by Year (21-23)'!J42/'SECGT10 Sales by Year (21-23)'!J$62 -> 0.011361853 | K42: ='SECGT10 Sales by Year (21-23)'!K42/'SECGT10 Sales by Year (21-23)'!K$62 -> 0.011023538 | L42: ='SECGT10 Sales by Year (21-23)'!L42/'SECGT10 Sales by Year (21-23)'!L$62 -> 0.010347131 | ... P42: ='SECGT10 Sales by Year (21-23)'!P42/'SECGT10 Sales by Year (21-23)'!P$62 -> 0.010768927
...

Sheet SECGT10 Sales by Year (21-23)
B1: PUC DOCKET NO.
B2: ONCOR ELECTRIC DELIVERY COMPANY
B3: WEATHER WEIGHTS
B4: =+'SECGT10 Seasonal Weights'!B4:P4 -> FOR THE TEST YEAR ENDING DECEMBER 31, 2024
B6: SPONSOR: D. E. NELSON
B8: SECONDARY SERVICE GREATER THAN 10 KW MONTHLY WEIGHTS
A9: Line | B9: (a) | C9: (b) | D9: (c) | E9: (d) | F9: (e) | G9: (f) | H9: (g) | I9: (h) | J9: (i) | K9: (j) | L9: (k) | M9: (l) | N9: (m) | O9: (n) | P9: (o)
A10: No. | B10: Weather Station | C10: Year | D10: 36892 | E10: 36923 | F10: 36951 | G10: 36982 | H10: 37012 | I10: 37043 | J10: 37073 | K10: 37104 | L10: 37135 | M10: 37165 | N10: 37196 | O10: 37226 | P10: Annual
A11: 1 | B11: Dallas-Fort Worth | C11: 2021 | D11: 2477886.7 | E11: 2445718 | F11: 2514887.1 | G11: 2405411.5 | H11: 2516767.9 | I11: 2771149.9 | J11: 3317602.3 | K11: 3344596.7 | L11: 3384327.4 | M11: 2988087.4 | N11: 2602111.7 | O11: 2463991.3 | P11: =SUM(D11:O11) -> 33232538
A12: =+A11+1 -> 2 | B12: Dallas-Fort Worth | C12: 2022 | D12: 2538462.6 | E12: 2586692.6 | F12: 2621604.3 | G12: 2538655.4 | H12: 2738759.5 | I12: 3116360.3 | J12: 3538360.5 | K12: 3748532.5 | L12: 3406977.8 | M12: 3017908.4 | N12: 2557180.3 | O12: 2555445.2 | P12: =SUM(D12:O12) -> 34964939
A13: =+A12+1 -> 3 | B13: Dallas-Fort Worth | C13: 2023 | D13: 2623208.5 | E13: 2598864.7 | F13: 2522752.7 | G13: 2509320.3 | H13: 2577456.8 | I13: 2960074.3 | J13: 3454482.2 | K13: 3662908.6 | L13: 3700951.6 | M13: 3271751.1 | N13: 2675445.9 | O13: 2524687.1 | P13: =SUM(D13:O13) -> 35081904
A14: =+A13+1 -> 4 | B14: Dallas-Fort Worth | C14: Total | D14: =SUM(D11:D13) -> 7639557.7 | E14: =SUM(E11:E13) -> 7631275.3 | F14: =SUM(F11:F13) -> 7659244.1 | G14: =SUM(G11:G13) -> 7453387.2 | H14: =SUM(H11:H13) -> 7832984.3 | I14: =SUM(I11:I13) -> 8847584.5 | J14: =SUM(J11:J13) -> 10310445 | K14: =SUM(K11:K13) -> 10756038 | ... O14: =SUM(O11:O13) -> 7544123.5 | P14: =SUM(D14:O14) -> 1.0327938e+08
A15: =+A14+1 -> 5
A16: =+A15+1 -> 6 | B16: Lufkin | C16: =+C11 -> 2021 | D16: 81365.92 | E16: 80144.157 | F16: 81978.34 | G16: 81896.983 | H16: 87577.849 | I16: 95608.58 | J16: 112091.46 | K16: 112074.13 | L16: 114691.3 | M16: 100697.33 | N16: 87720.323 | O16: 81894.285 | P16: =SUM(D16:O16) -> 1117740.7
A17: =+A16+1 -> 7 | B17: Lufkin | C17: =+C12 -> 2022 | D17: 81977.029 | E17: 85851.026 | F17: 86119.697 | G17: 84348.389 | H17: 93023.754 | I17: 106867.94 | J17: 119736.89 | K17: 124935.69 | L17: 114747.36 | M17: 100327.84 | N17: 84718.504 | O17: 82815.497 | P17: =SUM(D17:O17) -> 1165469.6
A18: =+A17+1 -> 8 | B18: Lufkin | C18: =+C13 -> 2023 | D18: 84376.071 | E18: 82891.618 | F18: 82454.25 | G18: 82788.663 | H18: 84553.861 | I18: 98812.053 | J18: 117598.79 | K18: 123100.34 | L18: 123300.4 | M18: 106673.27 | N18: 87372.035 | O18: 81308.681 | P18: =SUM(D18:O18) -> 1155230
A19: =+A18+1 -> 9 | B19: Lufkin | C19: Total | D19: =SUM(D16:D18) -> 247719.02 | E19: =SUM(E16:E18) -> 248886.8 | F19: =SUM(F16:F18) -> 250552.29 | G19: =SUM(G16:G18) -> 249034.03 | H19: =SUM(H16:H18) -> 265155.46 | I19: =SUM(I16:I18) -> 301288.57 | J19: =SUM(J16:J18) -> 349427.14 | K19: =SUM(K16:K18) -> 360110.16 | ... O19: =SUM(O16:O18) -> 246018.46 | P19: =SUM(D19:O19) -> 3438440.3
A20: =+A19+1 -> 10
A21: =+A20+1 -> 11 | B21: Austin | C21: =+C16 -> 2021 | D21: 92277.138 | E21: 89238.455 | F21: 93945.726 | G21: 92623.107 | H21: 100107.43 | I21: 110469.31 | J21: 127706.9 | K21: 125880.19 | L21: 134584.21 | M21: 112159.68 | N21: 102169.64 | O21: 97143.532 | P21: =SUM(D21:O21) -> 1278305.3
A22: =+A21+1 -> 12 | B22: Austin | C22: =+C17 -> 2022 | D22: 98300.464 | E22: 98943.499 | F22: 99126.045 | G22: 100537.01 | H22: 112649.83 | I22: 126813.96 | J22: 137628.57 | K22: 145027.84 | L22: 135873.37 | M22: 121217.27 | N22: 103257.38 | O22: 100677.95 | P22: =SUM(D22:O22) -> 1380053.2
A23: =+A22+1 -> 13 | B23: Austin | C23: =+C18 -> 2023 | D23: 103105.07 | E23: 100897.86 | F23: 102790.77 | G23: 102353.27 | H23: 105732.35 | I23: 122072.82 | J23: 142700.63 | K23: 147947.88 | L23: 150470.59 | M23: 136545.29 | N23: 110309.93 | O23: 100997.28 | P23: =SUM(D23:O23) -> 1425923.7
A24: =+A23+1 -> 14 | B24: Austin | C24: Total | D24: =SUM(D21:D23) -> 293682.67 | E24: =SUM(E21:E23) -> 289079.81 | F24: =SUM(F21:F23) -> 295862.54 | G24: =SUM(G21:G23) -> 295513.38 | H24: =SUM(H21:H23) -> 318489.61 | I24: =SUM(I21:I23) -> 359356.1 | J24: =SUM(J21:J23) -> 408036.1 | K24: =SUM(K21:K23) -> 418855.91 | ... O24: =SUM(O21:O23) -> 298818.76 | P24: =SUM(D24:O24) -> 4084282.2
A25: =+A24+1 -> 15
A26: =+A25+1 -> 16 | B26: Killeen | C26: =+C21 -> 2021 | D26: 90319.782 | E26: 85727.744 | F26: 93375.482 | G26: 88744.915 | H26: 95201.385 | I26: 101863.42 | J26: 117672.49 | K26: 117923.59 | L26: 125146.86 | M26: 111789.72 | N26: 96656.115 | O26: 92045.013 | P26: =SUM(D26:O26) -> 1216466.5
A27: =+A26+1 -> 17 | B27: Killeen | C27: =+C22 -> 2022 | D27: 89098.617 | E27: 96754.958 | F27: 95565.72 | G27: 92485.83 | H27: 103099.58 | I27: 117692.69 | J27: 131447.12 | K27: 140550.17 | L27: 128153.89 | M27: 113655.73 | N27: 96313.285 | O27: 94403.114 | P27: =SUM(D27:O27) -> 1299220.7
A28: =+A27+1 -> 18 | B28: Killeen | C28: =+C23 -> 2023 | D28: 95073.63 | E28: 94858.288 | F28: 93784.958 | G28: 92380.315 | H28: 94449.667 | I28: 110604.02 | J28: 132969.69 | K28: 140192.7 | L28: 142211.43 | M28: 125339.07 | N28: 100772.11 | O28: 92667.374 | P28: =SUM(D28:O28) -> 1315303.2
A29: =+A28+1 -> 19 | B29: Killeen | C29: Total | D29: =SUM(D26:D28) -> 274492.03 | E29: =SUM(E26:E28) -> 277340.99 | F29: =SUM(F26:F28) -> 282726.16 | G29: =SUM(G26:G28) -> 273611.06 | H29: =SUM(H26:H28) -> 292750.63 | I29: =SUM(I26:I28) -> 330160.13 | J29: =SUM(J26:J28) -> 382089.3 | K29: =SUM(K26:K28) -> 398666.45 | ... O29: =SUM(O26:O28) -> 279115.5 | P29: =SUM(D29:O29) -> 3830990.5
A30: =+A29+1 -> 20
A31: =+A30+1 -> 21 | B31: Longview | C31: =+C26 -> 2021 | D31: 103141.01 | E31: 101700.12 | F31: 104707.47 | G31: 101113.79 | H31: 107331.08 | I31: 118120.41 | J31: 141324.34 | K31: 140330.51 | L31: 143507.67 | M31: 126897.58 | N31: 108634.57 | O31: 103828.55 | P31: =SUM(D31:O31) -> 1400637.1
A32: =+A31+1 -> 22 | B32: Longview | C32: =+C27 -> 2022 | D32: 103853.15 | E32: 106600.61 | F32: 108842.27 | G32: 104592.24 | H32: 113448.03 | I32: 132738.99 | J32: 150980.62 | K32: 157316.36 | L32: 142998.25 | M32: 126598.12 | N32: 105686.89 | O32: 105038.33 | P32: =SUM(D32:O32) -> 1458693.8
A33: =+A32+1 -> 23 | B33: Longview | C33: =+C28 -> 2023 | D33: 109127.09 | E33: 105816.18 | F33: 106249.35 | G33: 102811.44 | H33: 107006.2 | I33: 124459.54 | J33: 146361.99 | K33: 156777.9 | L33: 158840.42 | M33: 136383.85 | N33: 110072.85 | O33: 104770.04 | P33: =SUM(D33:O33) -> 1468676.8
A34: =+A33+1 -> 24 | B34: Longview | C34: Total | D34: =SUM(D31:D33) -> 316121.24 | E34: =SUM(E31:E33) -> 314116.91 | F34: =SUM(F31:F33) -> 319799.08 | G34: =SUM(G31:G33) -> 308517.47 | H34: =SUM(H31:H33) -> 327785.3 | I34: =SUM(I31:I33) -> 375318.93 | J34: =SUM(J31:J33) -> 438666.95 | K34: =SUM(K31:K33) -> 454424.77 | ... O34: =SUM(O31:O33) -> 313636.92 | P34: =SUM(D34:O34) -> 4328007.8
A35: =+A34+1 -> 25
A36: =+A35+1 -> 26 | B36: Waco | C36: =+C31 -> 2021 | D36: 106709.74 | E36: 103101.32 | F36: 110815.3 | G36: 106896.13 | H36: 114165.4 | I36: 124623.76 | J36: 149167.47 | K36: 147435.59 | L36: 153638.32 | M36: 136399.91 | N36: 117355.69 | O36: 108440.55 | P36: =SUM(D36:O36) -> 1478749.2
A37: =+A36+1 -> 27 | B37: Waco | C37: =+C32 -> 2022 | D37: 106129.06 | E37: 112503.89 | F37: 114189.7 | G37: 110394.47 | H37: 122677.08 | I37: 142882.48 | J37: 163263.55 | K37: 171523.1 | L37: 158126.51 | M37: 142345.89 | N37: 120036.26 | O37: 113554.1 | P37: =SUM(D37:O37) -> 1577626.1
A38: =+A37+1 -> 28 | B38: Waco | C38: =+C33 -> 2023 | D38: 117764.42 | E38: 114123.38 | F38: 114451.71 | G38: 112267.49 | H38: 116168.63 | I38: 134858.27 | J38: 159954.11 | K38: 170280.76 | L38: 172525.38 | M38: 153954.88 | N38: 123575.63 | O38: 110090.77 | P38: =SUM(D38:O38) -> 1600015.4
A39: =+A38+1 -> 29 | B39: Waco | C39: Total | D39: =SUM(D36:D38) -> 330603.22 | E39: =SUM(E36:E38) -> 329728.59 | F39: =SUM(F36:F38) -> 339456.7 | G39: =SUM(G36:G38) -> 329558.09 | H39: =SUM(H36:H38) -> 353011.11 | I39: =SUM(I36:I38) -> 402364.52 | J39: =SUM(J36:J38) -> 472385.14 | K39: =SUM(K36:K38) -> 489239.45 | ... O39: =SUM(O36:O38) -> 332085.42 | P39: =SUM(D39:O39) -> 4656390.7
A40: =+A39+1 -> 30
A41: =+A40+1 -> 31 | B41: Abilene | C41: =+C36 -> 2021 | D41: 38492.168 | E41: 37484.513 | F41: 38569.819 | G41: 35677.127 | H41: 35754.753 | I41: -6562.2828 | J41: 46758.795 | K41: 48004.784 | L41: 50467.254 | M41: 41026.744 | N41: 35789.184 | O41: 36035.349 | P41: =SUM(D41:O41) -> 437498.21
A42: =+A41+1 -> 32 | B42: Abilene | C42: =+C37 -> 2022 | D42: 37319.28 | E42: 40076.127 | F42: 37946.495 | G42: 36694.059 | H42: 41008.491 | I42: 47825.351 | J42: 54398.103 | K42: 55863.685 | L42: 47760.328 | M42: 42279.001 | N42: 33936.466 | O42: 35567.945 | P42: =SUM(D42:O42) -> 510675.33
...
