Workbook

Sheet Energy Loss Factor
E1: WP/II-H-1.3/1
E3: Page 1 of 3
C4: 2024 Test Year Data
C5: Oncor Electric Delivery Company LLC
C6: Unadjusted Test Year Load Data
C7: For the Test Year Ended December 31, 2024
C8: Sponsor: D. E. Nelson
C10: System Line Loss Calculation (Test Year 2024)
C11: Energy Loss Factor Calculation
A13: Line
A14: No.
A15: (a) | C15: (b) | E15: (c) | G15: (d)
A16: 1 | C16: System Net Consumed, MWh (as Calculated page 3) | G16: ='2024 Stats'!E29 -> 1.9173691e+08
A17: 2
A18: 3 | C18: Booked Sales and Energy Losses by Voltage Level, MWh
A19: 4 | C19: (Booked Sales and Energy Losses Page 3):
A20: 5 | E20: Energy | G20: Booked
A21: 6 | E21: Losses | G21: Sales
A22: 7 | C22: Substation | E22: =('2024 Stats'!E29-'2024 Stats'!E27) -> 788616.45 | G22: ='2024 Stats'!E26 -> 6412195
A23: 8 | C23: Primary | E23: =('2024 Stats'!E25-'2024 Stats'!E23) -> 1451858 | G23: ='2024 Stats'!E22 -> 17209450
A24: 9 | C24: Secondary | E24: ='2024 Stats'!E21-'2024 Stats'!E15 -> 3667714.9 | G24: ='2024 Stats'!E15 -> 1.6220708e+08
A25: 10 | C25: Total | E25: =SUM(E22:E24) -> 5908189.4 | G25: =SUM(G22:G24) -> 1.8582872e+08
A26: 11
A27: 12 | C27: Percent Losses Calculation Procedure
A28: 13 | C28: Substation:
A29: 14 | C29: Input to Distribution Substation Transformation System, MWh | G29: =G16 -> 1.9173691e+08
A30: 15 | C30: Substation Losses, MWh | G30: =E22 -> 788616.45
A31: 16 | C31: Substation Sales, MWh | G31: =G22 -> 6412195
A32: 17 | C32: Remainder to Distribution Primary System, MWh | G32: =G29-G30-G31 -> 1.845361e+08
A33: 18 | C33: Percent Losses (Line 15/Line14) | G33: =G30/G29 -> 0.0041130133
A34: 19 | C34: Primary:
A35: 20 | C35: Input to Distribution Primary System, MWh | G35: =G32 -> 1.845361e+08
A36: 21 | C36: Primary Losses, MWh | G36: =E23 -> 1451858
A37: 22 | C37: Primary Sales, MWh | G37: =G23 -> 17209450
A38: 23 | C38: Remainder to Distribution Secondary System, MWh | G38: =G35-G36-G37 -> 1.6587479e+08
A39: 24 | C39: Percent Losses (Line 21/Line 20) | G39: =G36/G35 -> 0.0078676099
A40: 25 | C40: Secondary:
A41: 26 | C41: Input to Distribution Secondary System, MWh | G41: =G38 -> 1.6587479e+08
A42: 27 | C42: Secondary Losses, MWh | G42: =E24 -> 3667714.9
A43: 28 | C43: Secondary Sales, MWh | G43: =G41-G42 -> 1.6220708e+08
...

Sheet Demand Loss Factor
E1: WP/II-H-1.3/1
E3: Page 2 of 3
C4: 2024 Test Year Data
C5: Oncor Electric Delivery Company LLC
C6: Unadjusted Test Year Load Data
C7: For the Test Year Ended December 31, 2024
C8: Sponsor: D. E. Nelson
C10: System Line Loss Calculation (Test Year 2024)
C11: Demand Loss Factor Calculation
A13: Line
A14: No.
A15: (a) | C15: (b) | E15: (c) | G15: (d)
A16: 1 | C16: System Peak Demand, MW (as Calculated Page 3) | G16: ='2024 Stats'!H29 -> 312153.62
A17: 2
A18: 3 | C18: Coincident Demand and Demand Losses, MW
A19: 4 | C19: (Coincident Demands and Demand Losses Page 3):
A20: 5 | E20: Demand | G20: Coincident
A21: 6 | E21: Losses | G21: Demand
A22: 7 | C22: Substation | E22: ='2024 Stats'!H29-'2024 Stats'!H27 -> 654.14889 | G22: ='2024 Stats'!H26 -> 766.781
A23: 8 | C23: Primary | E23: ='2024 Stats'!H25-'2024 Stats'!H23 -> 4462.3587 | G23: ='2024 Stats'!H22 -> 2197.9
A24: 9 | C24: Secondary | E24: ='2024 Stats'!H21-'2024 Stats'!H15 -> 5979.951 | G24: ='2024 Stats'!H15 -> 298092.48
A25: 10 | C25: Total | E25: =SUM(E22:E24) -> 11096.459 | G25: =SUM(G22:G24) -> 301057.16
A26: 11
A27: 12 | C27: Percent Losses Calculation Procedure
A28: 13 | C28: Substation:
A29: 14 | C29: Input to Distribution Substation System, MW | G29: =G16 -> 312153.62
A30: 15 | C30: Substation Losses, MW | G30: =E22 -> 654.14889
A31: 16 | C31: Substation Demand, MW | G31: =G22 -> 766.781
A32: 17 | C32: Remainder to Distribution Primary System, MW | G32: =G29-G30-G31 -> 310732.69
A33: 18 | C33: Percent Losses (Line 15/Line 14) | G33: =G30/G29 -> 0.0020955992
A34: 19 | C34: Primary:
A35: 20 | C35: Input to Distribution Primary System, MW | G35: =G32 -> 310732.69
A36: 21 | C36: Primary Losses, MW | G36: =E23 -> 4462.3587
A37: 22 | C37: Primary Demand, MW | G37: =G23 -> 2197.9
A38: 23 | C38: Remainder to Distribution Secondary System, MW | G38: =G35-G36-G37 -> 304072.43
A39: 24 | C39: Percent Losses (Line 21/Line 20) | G39: =G36/G35 -> 0.014360764
A40: 25 | C40: Secondary:
A41: 26 | C41: Input to Distribution Secondary System, MW | G41: =G38 -> 304072.43
A42: 27 | C42: Secondary Losses, MW | G42: =E24 -> 5979.951
A43: 28 | C43: Secondary Demand, MW | G43: =G41-G42 -> 298092.48
...

Sheet 2024 Stats
F1: WP/II-H-1.3/1
F2: Page 3 of 3
C4: 2024 Test Year Data
C5: Oncor Electric Delivery Company LLC
C6: Unadjusted Test Year Load Data
C7: For the Test Year Ended December 31, 2024
C8: Sponsor: D. E. Nelson
C10: System Line Loss Calculation (Test Year 2024)
C12: Calculated Losses Using 2015 Oncor Integrated Power System Loss Analysis
E14: MWh | H14: MW
C15: Retail Sales from Service Drop | E15: 1.6220708e+08 | H15: 298092.48
C16: Service Drop Factor * | E16: 1.0037315 | H16: 1.0046
C17: Output from Secondary | E17: =E15*E16 -> 1.6281235e+08 | H17: =H15*H16 -> 299463.71
C18: Secondary Conductor Loss Factor * | E18: 1.00111 | H18: 1.00229
C19: Output from Line Transformers | E19: =E17*E18 -> 1.6299307e+08 | H19: =H17*H18 -> 300149.48
C20: Line Transformer Loss Factor * | E20: 1.01768 | H20: 1.01307
C21: Input to Line Transformers | E21: =E19*E20 -> 1.6587479e+08 | H21: =H19*H20 -> 304072.43
C22: Sales from Primary | E22: 17209450 | H22: 2197.9
C23: Output from Primary Lines | E23: =E21+E22 -> 1.8308424e+08 | H23: =H21+H22 -> 306270.33
C24: Primary Line Loss Factor * | E24: 1.00793 | H24: 1.01457
C25: Output from Distribution Substations | E25: =E23*E24 -> 1.845361e+08 | H25: =H23*H24 -> 310732.69
C26: Sales from Substations | E26: 6412195 | H26: 766.781
C27: Total Output from Distribution Substations | E27: =E25+E26 -> 1.9094829e+08 | H27: =H25+H26 -> 311499.47
C28: Distribution Substation Loss Factor * | E28: 1.00413 | H28: 1.0021
C29: Input to Distribution Substations | E29: =E27*E28 -> 1.9173691e+08 | H29: =H27*H28 -> 312153.62
C31: Total System Losses | E31: =E29-E26-E22-E15 -> 5908189.4 | H31: =H29-H26-H22-H15 -> 11096.459
C33: NOTE:
C34: 2024 Annual Energy from company records and Demand at ERCOT's 2024 annual peak
C36: * For Loss Factors, refer to WP/II-H-1.3/2
