Workbook
Name AFT_DIST: 'II-I-Total'!#REF!
Name Assign_Tbl: #REF!
Name Assign_Tbl_2016: #REF!
Name DA: #REF!
Name DA_0222: #REF!
Name DA_2: #REF!
Name FactorTable: 'II-I-MET'!$G$1318:$T$1412
Name FactorTable: 'II-I-TBILLTDCS'!$G$1318:$T$1412
Name FactorTable: 'II-I-Total'!#REF!
Name FactorTable: 'II-I-DIST'!$G$1318:$T$1412
Name FFT_D: 'II-I-DIST'!$B$1014:$L$1163
Name x: 'II-I-TBILLTDCS'!$G$1318:$T$1412

Sheet LinkSheet
D4: Description | F4: Total | G4: Residential | H4: Secondary | I4: Secondary | J4: Primary DL | K4: Primary DL | L4: Primary | M4: Transmission | N4: Lighting | O4: Wholesale | P4: Wholesale
H5: <=10kW | I5: >10kW | J5: <=10kW | K5: >10kW | L5: Substation | O5: Substation | P5: DLS
D8: DIST Function Revenue ex 565 & A928: Adjusted | F8: =SUM(G8:P8) -> 2.3066259e+09 | G8: ='WP II-I-1.7'!E23 -> 1.2075454e+09 | H8: ='WP II-I-1.7'!F23 -> 41122596 | I8: ='WP II-I-1.7'!G23 -> 8.1825418e+08 | J8: ='WP II-I-1.7'!H23 -> 295364.15 | K8: ='WP II-I-1.7'!I23 -> 1.3369402e+08 | L8: ='WP II-I-1.7'!J23 -> 13404715 | M8: ='WP II-I-1.7'!K23 -> 24606815 | N8: ='WP II-I-1.7'!L23 -> 59672372 | ... P8: ='WP II-I-1.7'!N23 -> 6549864 | S8: =IF(ROUND(F45+F46+F8-'WP II-I-1.1'!G456,1)=0,TRUE,F45+F46+F8-'WP II-I-1.1'!G456) -> TRUE
D10: MET Function Revenue Req | F10: =SUM(G10:P10) -> 2.0034106e+08 | G10: ='WP II-I-1.7'!E25 -> 1.1168499e+08 | H10: ='WP II-I-1.7'!F25 -> 17198917 | I10: ='WP II-I-1.7'!G25 -> 53110886 | J10: ='WP II-I-1.7'!H25 -> 744278.79 | K10: ='WP II-I-1.7'!I25 -> 15544460 | L10: ='WP II-I-1.7'!J25 -> 532402.95 | M10: ='WP II-I-1.7'!K25 -> 1172829.3 | N10: ='WP II-I-1.7'!L25 -> 142786.02 | ... P10: ='WP II-I-1.7'!N25 -> 146686.46 | S10: =IF(ROUND(F10-'WP II-I-1.1'!H456,1)=0,TRUE,F10-'WP II-I-1.1'!H456) -> TRUE
D12: CUSTOMER Function Revenue Req | F12: =SUM(G12:P12) -> 1.0437939e+08 | G12: ='WP II-I-1.7'!E27 -> 57205975 | H12: ='WP II-I-1.7'!F27 -> 8455436.7 | I12: ='WP II-I-1.7'!G27 -> 27857670 | J12: ='WP II-I-1.7'!H27 -> 359398.35 | K12: ='WP II-I-1.7'!I27 -> 7883822.9 | L12: ='WP II-I-1.7'!J27 -> 305330.92 | M12: ='WP II-I-1.7'!K27 -> 741936.81 | N12: ='WP II-I-1.7'!L27 -> 1471849 | ... P12: ='WP II-I-1.7'!N27 -> 68580.765 | S12: =IF(ROUND(F12-'WP II-I-1.1'!I456,1)=0,TRUE,F12-'WP II-I-1.1'!I456) -> TRUE
D14: DIST+MET+CUST:
D15: Total Plant: Gross | F15: =SUM(G15:P15) -> 1.7037413e+10 | G15: ='II-I-Total'!J60 -> 9.2980892e+09 | H15: ='II-I-Total'!K60 -> 4.5976014e+08 | I15: ='II-I-Total'!L60 -> 5.6849262e+09 | J15: ='II-I-Total'!M60 -> 6766368 | K15: ='II-I-Total'!N60 -> 8.8403031e+08 | L15: ='II-I-Total'!O60 -> 75057775 | M15: ='II-I-Total'!P60 -> 21799669 | N15: ='II-I-Total'!Q60 -> 5.5464338e+08 | ... P15: ='II-I-Total'!S60 -> 43359630
D16: Return on Rate Base (cost-based) | F16: =SUM(G16:P16) -> 6.8300051e+08 | G16: ='II-I-Total'!J83 -> 3.7983407e+08 | H16: ='II-I-Total'!K83 -> 15300982 | I16: ='II-I-Total'!L83 -> 2.3799621e+08 | J16: ='II-I-Total'!M83 -> 245203.7 | K16: ='II-I-Total'!N83 -> 38356623 | L16: ='II-I-Total'!O83 -> 3620199.3 | M16: ='II-I-Total'!P83 -> 1383463.3 | N16: ='II-I-Total'!Q83 -> 3922745.9 | ... P16: ='II-I-Total'!S83 -> 1908877.7 | S16: =IF(F16-(SUM('WP II-I-1.1'!G461:I461))=0,TRUE,F16-(SUM('WP II-I-1.1'!G461:I461))) -> TRUE
D17: Depreciation Expense | F17: =SUM(G17:P17) -> 5.4634784e+08 | G17: ='II-I-Total'!J22 -> 2.9377371e+08 | H17: ='II-I-Total'!K22 -> 17898989 | I17: ='II-I-Total'!L22 -> 1.7524036e+08 | J17: ='II-I-Total'!M22 -> 385591.23 | K17: ='II-I-Total'!N22 -> 29457396 | L17: ='II-I-Total'!O22 -> 1951234.2 | M17: ='II-I-Total'!P22 -> 869060.79 | N17: ='II-I-Total'!Q22 -> 25252299 | ... P17: ='II-I-Total'!S22 -> 1286394.1
D18: Federal Income Tax (cost-based) | F18: =SUM(G18:P18) -> 82404686 | G18: ='II-I-Total'!J25 -> 45850278 | H18: ='II-I-Total'!K25 -> 1770897.1 | I18: ='II-I-Total'!L25 -> 28788315 | J18: ='II-I-Total'!M25 -> 25535.902 | K18: ='II-I-Total'!N25 -> 4606241.1 | L18: ='II-I-Total'!O25 -> 442044.23 | M18: ='II-I-Total'!P25 -> 162487.89 | N18: ='II-I-Total'!Q25 -> 473466.34 | ... P18: ='II-I-Total'!S25 -> 232790.75 | S18: =IF(ROUND(F18-(SUM('WP II-I-1.1'!G465:I465)-'WP II-I-1.1'!F465),1)=0,TRUE,F18-(SUM('WP II-I-1.1'!G465:I465)-'WP II-I-1.1'!F36)) -> 2.9802322e-08
D19: Taxes Other Than FIT | F19: =SUM(G19:P19) -> 4.604982e+08 | G19: ='II-I-Total'!J24 -> 2.10698e+08 | H19: ='II-I-Total'!K24 -> 8641668.9 | I19: ='II-I-Total'!L24 -> 1.7865294e+08 | J19: ='II-I-Total'!M24 -> 71539.685 | K19: ='II-I-Total'!N24 -> 28656332 | L19: ='II-I-Total'!O24 -> 3850802.2 | M19: ='II-I-Total'!P24 -> 22791529 | N19: ='II-I-Total'!Q24 -> 5993922.6 | ... P19: ='II-I-Total'!S24 -> 811399.08
C21: DIST Plant Function:
D22: Distribution Plant - Net | F22: =SUM(G22:P22) -> 9.0423092e+09 | G22: ='II-I-DIST'!J313 -> 5.0415428e+09 | H22: ='II-I-DIST'!K313 -> 1.6891482e+08 | I22: ='II-I-DIST'!L313 -> 3.1866993e+09 | J22: ='II-I-DIST'!M313 -> 1134336 | K22: ='II-I-DIST'!N313 -> 4.8010812e+08 | L22: ='II-I-DIST'!O313 -> 41534062 | M22: ='II-I-DIST'!P313 -> 9445430.7 | N22: ='II-I-DIST'!Q313 -> 81890651 | ... P22: ='II-I-DIST'!S313 -> 26061601
C23: A360 | D23: Land and Land Rights - Net | F23: =SUM(G23:P23) -> 13350684 | G23: ='II-I-DIST'!J133-'II-I-DIST'!J280 -> 7271694.3 | H23: ='II-I-DIST'!K133-'II-I-DIST'!K280 -> 299569.28 | I23: ='II-I-DIST'!L133-'II-I-DIST'!L280 -> 4523793.9 | J23: ='II-I-DIST'!M133-'II-I-DIST'!M280 -> 1535.9234 | K23: ='II-I-DIST'!N133-'II-I-DIST'!N280 -> 650080.09 | L23: ='II-I-DIST'!O133-'II-I-DIST'!O280 -> 51624.716 | M23: ='II-I-DIST'!P133-'II-I-DIST'!P280 -> 12272.058 | N23: ='II-I-DIST'!Q133-'II-I-DIST'!Q280 -> 498637.69 | ... P23: ='II-I-DIST'!S133-'II-I-DIST'!S280 -> 35288.15
C24: A361 | D24: Structures and Improvements - Net | F24: =SUM(G24:P24) -> 95316076 | G24: ='II-I-DIST'!J134-'II-I-DIST'!J281 -> 51915646 | H24: ='II-I-DIST'!K134-'II-I-DIST'!K281 -> 2138749.5 | I24: ='II-I-DIST'!L134-'II-I-DIST'!L281 -> 32297244 | J24: ='II-I-DIST'!M134-'II-I-DIST'!M281 -> 10965.595 | K24: ='II-I-DIST'!N134-'II-I-DIST'!N281 -> 4641191.8 | L24: ='II-I-DIST'!O134-'II-I-DIST'!O281 -> 368570.29 | M24: ='II-I-DIST'!P134-'II-I-DIST'!P281 -> 87615.321 | N24: ='II-I-DIST'!Q134-'II-I-DIST'!Q281 -> 3559981.6 | ... P24: ='II-I-DIST'!S134-'II-I-DIST'!S281 -> 251936.76
C25: A362 | D25: Station Equipment - Net | F25: =SUM(G25:P25) -> 1.2965161e+09 | G25: ='II-I-DIST'!J135-'II-I-DIST'!J282 -> 6.8238622e+08 | H25: ='II-I-DIST'!K135-'II-I-DIST'!K282 -> 16664019 | I25: ='II-I-DIST'!L135-'II-I-DIST'!L282 -> 4.3936961e+08 | J25: ='II-I-DIST'!M135-'II-I-DIST'!M282 -> 248393.75 | K25: ='II-I-DIST'!N135-'II-I-DIST'!N282 -> 1.0513274e+08 | L25: ='II-I-DIST'!O135-'II-I-DIST'!O282 -> 38019650 | M25: ='II-I-DIST'!P135-'II-I-DIST'!P282 -> 0 | N25: ='II-I-DIST'!Q135-'II-I-DIST'!Q282 -> 4431672.8 | ... P25: ='II-I-DIST'!S135-'II-I-DIST'!S282 -> 5706896.8
D26: 4CP Retail Allocation Factor | F26: =SUM(G26:P26) -> 1 | G26: ='II-I-DIST'!J1341 -> 0.45880672 | H26: ='II-I-DIST'!K1341 -> 0.012824408 | I26: ='II-I-DIST'!L1341 -> 0.33353593 | J26: ='II-I-DIST'!M1341 -> 0.00013264334 | K26: ='II-I-DIST'!N1341 -> 0.083853975 | L26: ='II-I-DIST'!O1341 -> 0.027463664 | M26: ='II-I-DIST'!P1341 -> 0.083382661 | N26: ='II-I-DIST'!Q1341 -> 0 | O26: 0 | P26: 0
D28: NCP (kW) | G28: ='WP II-I-2.2'!E37 -> 15210693 | H28: ='WP II-I-2.2'!F37 -> 371448.4 | I28: ='WP II-I-2.2'!G37 -> 9793744.4 | J28: ='WP II-I-2.2'!H37 -> 5536.8074 | K28: ='WP II-I-2.2'!I37 -> 2343455.6 | L28: ='WP II-I-2.2'!J37 -> 847474.94 | M28: ='WP II-I-2.2'!K37 -> 2790485.9 | N28: ='WP II-I-2.2'!L37 -> 98783.961 | ... P28: ='WP II-I-2.2'!N37 -> 127209.27
D30: DIST Function Revenue: Adjusted | F30: =SUM(G30:P30) -> 3.9607946e+09 | G30: ='II-I-DIST'!J37 -> 1.9665583e+09 | H30: ='II-I-DIST'!K37 -> 62349174 | I30: ='II-I-DIST'!L37 -> 1.3699899e+09 | J30: ='II-I-DIST'!M37 -> 515183.39 | K30: ='II-I-DIST'!N37 -> 2.7237864e+08 | L30: ='II-I-DIST'!O37 -> 58811986 | M30: ='II-I-DIST'!P37 -> 1.6246169e+08 | N30: ='II-I-DIST'!Q37 -> 59696005 | ... P30: ='II-I-DIST'!S37 -> 6552465.6 | S30: =IF(ROUND(F30-'WP II-I-1.1'!G456,2)=0,TRUE,F30-'WP II-I-1.1'!G456) -> TRUE
D31: TRAN Function Revenue Requirement | F31: ='WP II-I-1.1'!F456 -> 1.4451764e+09
C34: DIST Function:
D35: O&M Expenses | F35: =SUM(G35:P35) -> 1.9676251e+09 | G35: ='II-I-DIST'!J15 -> 9.2562883e+08 | H35: ='II-I-DIST'!K15 -> 25721821 | I35: ='II-I-DIST'!L15 -> 6.5841473e+08 | J35: ='II-I-DIST'!M15 -> 291840.01 | K35: ='II-I-DIST'!N15 -> 1.6020127e+08 | L35: ='II-I-DIST'!O15 -> 47191842 | M35: ='II-I-DIST'!P15 -> 1.3785413e+08 | N35: ='II-I-DIST'!Q15 -> 10957441 | ... P35: ='II-I-DIST'!S15 -> 1148504.9
D36: Customer Expenses | F36: =SUM(G36:P36) -> 245305.53 | G36: ='II-I-DIST'!J16 -> 211382.27 | H36: ='II-I-DIST'!K16 -> 20459.035 | I36: ='II-I-DIST'!L16 -> 10111.178 | J36: ='II-I-DIST'!M16 -> 238.26144 | K36: ='II-I-DIST'!N16 -> 203.54548 | L36: ='II-I-DIST'!O16 -> -91.058921 | M36: ='II-I-DIST'!P16 -> -384.8685 | N36: ='II-I-DIST'!Q16 -> 3371.9531 | ... P36: ='II-I-DIST'!S16 -> 10.906226
D37: A&G Expenses | F37: =SUM(G37:P37) -> 4.2312645e+08 | G37: ='II-I-DIST'!J17 -> 2.283512e+08 | H37: ='II-I-DIST'!K17 -> 7879417.5 | I37: ='II-I-DIST'!L17 -> 1.4405275e+08 | J37: ='II-I-DIST'!M17 -> 73200.4 | K37: ='II-I-DIST'!N17 -> 24811551 | L37: ='II-I-DIST'!O17 -> 2275901 | M37: ='II-I-DIST'!P17 -> 333312.72 | N37: ='II-I-DIST'!Q17 -> 13755289 | ... P37: ='II-I-DIST'!S17 -> 1325254.8
D38: Depreciation & Amortization Expense | F38: =SUM(G38:P38) -> 4.5981714e+08 | G38: ='II-I-DIST'!J20 -> 2.4554112e+08 | H38: ='II-I-DIST'!K20 -> 10276121 | I38: ='II-I-DIST'!L20 -> 1.5254519e+08 | J38: ='II-I-DIST'!M20 -> 53564.308 | K38: ='II-I-DIST'!N20 -> 22671112 | L38: ='II-I-DIST'!O20 -> 1729044.2 | M38: ='II-I-DIST'!P20 -> 355894.65 | N38: ='II-I-DIST'!Q20 -> 25207217 | ... P38: ='II-I-DIST'!S20 -> 1230650.8
D39: Other Expenses (II-E-4) | F39: =SUM(G39:P39) -> -2772903.9 | G39: ='II-I-DIST'!J21 -> -1543390.6 | H39: ='II-I-DIST'!K21 -> -51305.984 | I39: ='II-I-DIST'!L21 -> -976083.78 | J39: ='II-I-DIST'!M21 -> -353.45194 | K39: ='II-I-DIST'!N21 -> -149598.65 | L39: ='II-I-DIST'!O21 -> -14829.983 | M39: ='II-I-DIST'!P21 -> -2808.1134 | N39: ='II-I-DIST'!Q21 -> -24635.28 | ... P39: ='II-I-DIST'!S21 -> -8120.6299
D40: Taxes Other Than Federal Income Tax | F40: =SUM(G40:P40) -> 4.474502e+08 | G40: ='II-I-DIST'!J24 -> 2.0342872e+08 | H40: ='II-I-DIST'!K24 -> 7522309.1 | I40: ='II-I-DIST'!L24 -> 1.7519255e+08 | J40: ='II-I-DIST'!M24 -> 23085.31 | K40: ='II-I-DIST'!N24 -> 27643694 | L40: ='II-I-DIST'!O24 -> 3816059.2 | M40: ='II-I-DIST'!P24 -> 22715111 | N40: ='II-I-DIST'!Q24 -> 5980508.8 | ... P40: ='II-I-DIST'!S24 -> 802088.52 | S40: =IF(ROUND(F40-'WP II-I-1.1'!G464,2)=0,TRUE,F40-'WP II-I-1.1'!G464) -> TRUE
D41: Federal Income Tax | F41: =SUM(G41:P41) -> 78221385 | G41: ='II-I-DIST'!J25 -> 43523262 | H41: ='II-I-DIST'!K25 -> 1413378.3 | I41: ='II-I-DIST'!L25 -> 27675494 | J41: ='II-I-DIST'!M25 -> 10069.517 | K41: ='II-I-DIST'!N25 -> 4281733.1 | L41: ='II-I-DIST'!O25 -> 430785.89 | M41: ='II-I-DIST'!P25 -> 136515.79 | N41: ='II-I-DIST'!Q25 -> 468980.55 | ... P41: ='II-I-DIST'!S25 -> 229814.61 | S41: =IF(ROUND(F41-'WP II-I-1.1'!G465,2)=0,TRUE,F41-'WP II-I-1.1'!G465) -> TRUE
D42: Return on Rate Base | F42: =SUM(G42:P42) -> 6.3883984e+08 | G42: ='II-I-DIST'!J27 -> 3.5527283e+08 | H42: ='II-I-DIST'!K27 -> 11529737 | I42: ='II-I-DIST'!L27 -> 2.2624227e+08 | J42: ='II-I-DIST'!M27 -> 82109.809 | K42: ='II-I-DIST'!N27 -> 34931887 | L42: ='II-I-DIST'!O27 -> 3501360.2 | M42: ='II-I-DIST'!P27 -> 1107731.7 | N42: ='II-I-DIST'!Q27 -> 3875733.7 | ... P42: ='II-I-DIST'!S27 -> 1877498.1
D43: Minus Other Revenues | F43: =SUM(G43:P43) -> 51757982 | G43: ='II-I-DIST'!J31 -> 33855633 | H43: ='II-I-DIST'!K31 -> 1962762 | I43: ='II-I-DIST'!L31 -> 13167153 | J43: ='II-I-DIST'!M31 -> 18570.774 | K43: ='II-I-DIST'!N31 -> 2013214.5 | L43: ='II-I-DIST'!O31 -> 118085.83 | M43: ='II-I-DIST'!P31 -> 37812.6 | N43: ='II-I-DIST'!Q31 -> 527901.22 | ... P43: ='II-I-DIST'!S31 -> 53236.441
D44: Proposed Adjustment to Return On Rate Base | F44: =SUM(G44:P44) -> 0 | G44: ='II-I-DIST'!J35 -> 0 | H44: ='II-I-DIST'!K35 -> 0 | I44: ='II-I-DIST'!L35 -> 0 | J44: ='II-I-DIST'!M35 -> 0 | K44: ='II-I-DIST'!N35 -> 0 | L44: ='II-I-DIST'!O35 -> 0 | M44: ='II-I-DIST'!P35 -> 0 | N44: ='II-I-DIST'!Q35 -> 0 | ... P44: ='II-I-DIST'!S35 -> 0
D45: RateCaseExpense A928 | F45: =SUM(G45:P45) -> 1646625.8 | G45: ='WP II-I-1.7'!E18 -> 824746.22 | H45: ='WP II-I-1.7'!F18 -> 33960.679 | I45: ='WP II-I-1.7'!G18 -> 560215.85 | J45: ='WP II-I-1.7'!H18 -> 623.20619 | K45: ='WP II-I-1.7'!I18 -> 114082.03 | L45: ='WP II-I-1.7'!J18 -> 22961.48 | M45: ='WP II-I-1.7'!K18 -> 63196.956 | N45: ='WP II-I-1.7'!L18 -> 23632.914 | ... P45: ='WP II-I-1.7'!N18 -> 2601.5728
D46: A565 Transmission of Eletricity by Others | F46: =SUM(G46:P46) -> 1.652522e+09 | G46: ='II-I-DIST'!J622 -> 7.5818821e+08 | H46: ='II-I-DIST'!K622 -> 21192617 | I46: ='II-I-DIST'!L622 -> 5.5117546e+08 | J46: ='II-I-DIST'!M622 -> 219196.04 | K46: ='II-I-DIST'!N622 -> 1.3857054e+08 | L46: ='II-I-DIST'!O622 -> 45384309 | M46: ='II-I-DIST'!P622 -> 1.3779168e+08 | N46: ='II-I-DIST'!Q622 -> 0 | ... P46: ='II-I-DIST'!S622 -> 0
D47: Total Distribution Facilities Less A565 & A928 | F47: =SUM(G47:P47) -> 2.3066259e+09 | G47: ='WP II-I-1.7'!E23 -> 1.2075454e+09 | H47: ='WP II-I-1.7'!F23 -> 41122596 | I47: ='WP II-I-1.7'!G23 -> 8.1825418e+08 | J47: ='WP II-I-1.7'!H23 -> 295364.15 | K47: ='WP II-I-1.7'!I23 -> 1.3369402e+08 | L47: ='WP II-I-1.7'!J23 -> 13404715 | M47: ='WP II-I-1.7'!K23 -> 24606815 | N47: ='WP II-I-1.7'!L23 -> 59672372 | ... P47: ='WP II-I-1.7'!N23 -> 6549864

Sheet II-I-1
B2: 2022 RATE CASE
B3: ONCOR ELECTRIC DELIVERY COMPANY LLC
B4: II-I-1: CLASS REVENUE REQUIREMENT ANALYSIS
B5: TEST YEAR ENDING 12/31/2021
B6: SPONSOR: MATTHEW A. TROXLE
F9: 1 | H9: 3 | I9: 4 | J9: 5 | K9: 6 | L9: 7 | M9: 8 | N9: 9 | O9: 10 | P9: 11 | Q9: 12 | R9: 13
F10: Test Year
D11: Line | E11: Description | F11: Revenue | H11: Residential | I11: Secondary | J11: Secondary | K11: Primary | L11: Primary | M11: Primary | N11: Transmission | O11: Lighting | P11: Wholesale | Q11: Wholesale | R11: Total
F12: Requirement | I12: ≤ 10 kW | J12: > 10 kW | K12: ≤ 10 kW | L12: > 10 kW | M12: Substation | P12: XFMR | Q12: DLS | R12: TX- Retail
F13: Total | R13: =3+4+5+6+7+8+9+10
T15: check:
D16: 1 | E16: Distribution (Includes A565 & DIST RCE A928) | F16: ='II-I-DIST'!$F$33 -> 3.9607946e+09 | H16: ='II-I-DIST'!$J$33 -> 1.9665583e+09 | I16: ='II-I-DIST'!$K$33 -> 62349174 | J16: ='II-I-DIST'!$L$33 -> 1.3699899e+09 | K16: ='II-I-DIST'!$M$33 -> 515183.39 | L16: ='II-I-DIST'!$N$33 -> 2.7237864e+08 | M16: ='II-I-DIST'!$O$33 -> 58811986 | N16: ='II-I-DIST'!$P$33 -> 1.6246169e+08 | O16: ='II-I-DIST'!$Q$33 -> 59696005 | P16: ='II-I-DIST'!$R$33 -> 1481240.3 | Q16: ='II-I-DIST'!$S$33 -> 6552465.6 | R16: =SUM(H16+I16+J16+K16+L16+M16+N16+O16) -> 3.9527609e+09 | T16: =F16-P16-Q16-R16 -> 0
D17: 2 | E17: Metering | F17: ='II-I-MET'!$F$33 -> 2.0034106e+08 | H17: ='II-I-MET'!J33 -> 1.1168499e+08 | I17: ='II-I-MET'!K33 -> 17198917 | J17: ='II-I-MET'!L33 -> 53110886 | K17: ='II-I-MET'!M33 -> 744278.79 | L17: ='II-I-MET'!N33 -> 15544460 | M17: ='II-I-MET'!O33 -> 532402.95 | N17: ='II-I-MET'!P33 -> 1172829.3 | O17: ='II-I-MET'!Q33 -> 142786.02 | ... Q17: ='II-I-MET'!S33 -> 146686.46 | R17: =SUM(H17+I17+J17+K17+L17+M17+N17+O17) -> 2.0013155e+08 | T17: =F17-P17-Q17-R17 -> 0
D18: 3 | E18: Customer Function (TBILL+TDCS) | F18: ='II-I-TBILLTDCS'!$F$33 -> 1.0437939e+08 | H18: ='II-I-TBILLTDCS'!J33 -> 57205975 | I18: ='II-I-TBILLTDCS'!K33 -> 8455436.7 | J18: ='II-I-TBILLTDCS'!L33 -> 27857670 | K18: ='II-I-TBILLTDCS'!M33 -> 359398.35 | L18: ='II-I-TBILLTDCS'!N33 -> 7883822.9 | M18: ='II-I-TBILLTDCS'!O33 -> 305330.92 | N18: ='II-I-TBILLTDCS'!P33 -> 741936.81 | O18: ='II-I-TBILLTDCS'!Q33 -> 1471849 | ... Q18: ='II-I-TBILLTDCS'!S33 -> 68580.765 | R18: =SUM(H18+I18+J18+K18+L18+M18+N18+O18) -> 1.0428142e+08 | T18: =F18-P18-Q18-R18 -> 0
D19: 4 | E19: Total: | F19: =SUM(F16:F18) -> 4.265515e+09 | H19: =SUM(H16:H18) -> 2.1354493e+09 | I19: =SUM(I16:I18) -> 88003528 | J19: =SUM(J16:J18) -> 1.4509584e+09 | K19: =SUM(K16:K18) -> 1618860.5 | L19: =SUM(L16:L18) -> 2.9580692e+08 | M19: =SUM(M16:M18) -> 59649719 | N19: =SUM(N16:N18) -> 1.6437646e+08 | O19: =SUM(O16:O18) -> 61310640 | ... Q19: =SUM(Q16:Q18) -> 6767732.8 | R19: =SUM(H19+I19+J19+K19+L19+M19+N19+O19) -> 4.2571738e+09 | T19: =H19+I19+J19+K19+L19+M19+N19+O19-R19 -> 0
E22: Check: | F22: =IF('II-I-DIST'!F33='WP II-I-1.1'!G456,TRUE,'II-I-DIST'!F33-'WP II-I-1.1'!G456) -> 0.0041480064
F23: =IF('II-I-MET'!F33='WP II-I-1.1'!H456,TRUE,'II-I-MET'!F33-'WP II-I-1.1'!H456) -> -0.0024909377
F24: =IF('II-I-TBILLTDCS'!F33='WP II-I-1.1'!I456,TRUE,'II-I-TBILLTDCS'!F33-'WP II-I-1.1'!I456) -> 0.0029119849
F25: =IF(SUM(F16:F18)='II-I-Total'!F33,TRUE,SUM(F16:F18)-'II-I-Total'!F33) -> TRUE | H25: =IF(SUM(H16:H18)='II-I-Total'!J33,TRUE,SUM(H16:H18)-'II-I-Total'!J33) -> TRUE | I25: =IF(SUM(I16:I18)='II-I-Total'!K33,TRUE,SUM(I16:I18)-'II-I-Total'!K33) -> TRUE | J25: =IF(SUM(J16:J18)='II-I-Total'!L33,TRUE,SUM(J16:J18)-'II-I-Total'!L33) -> TRUE | K25: =IF(SUM(K16:K18)='II-I-Total'!M33,TRUE,SUM(K16:K18)-'II-I-Total'!M33) -> TRUE | L25: =IF(SUM(L16:L18)='II-I-Total'!N33,TRUE,SUM(L16:L18)-'II-I-Total'!N33) -> -1.1920929e-07 | M25: =IF(SUM(M16:M18)='II-I-Total'!O33,TRUE,SUM(M16:M18)-'II-I-Total'!O33) -> TRUE | N25: =IF(SUM(N16:N18)='II-I-Total'!P33,TRUE,SUM(N16:N18)-'II-I-Total'!P33) -> TRUE | O25: =IF(SUM(O16:O18)='II-I-Total'!Q33,TRUE,SUM(O16:O18)-'II-I-Total'!Q33) -> TRUE | ... Q25: =IF(SUM(Q16:Q18)='II-I-Total'!S33,TRUE,SUM(Q16:Q18)-'II-I-Total'!S33) -> TRUE | R25: =F19-P19-Q19-R19 -> 0

Sheet WP II-I-1.1
B3: ='II-I-1'!B2 -> 2022 RATE CASE
B4: ='II-I-1'!B3 -> ONCOR ELECTRIC DELIVERY COMPANY LLC
B5: II-I-1: CLASS REVENUE REQUIREMENT ANALYSIS
B6: ='II-I-1'!B5 -> TEST YEAR ENDING 12/31/2021
B7: ='II-I-1'!B6 -> SPONSOR: MATTHEW A. TROXLE
B10: WORKPAPER 1.1 - CONSOLIDATION OF FUNCTIONALIZED COST OF SERVICE
B13: Line | C13: Account | D13: Description | E13: Reference | F13: TRAN | G13: DIST | H13: MET | I13: TDCS | J13: Total
C14: Number | E14: Schedule
C15: (a) | D15: (b) | E15: (c) | F15: (d) | G15: (e) | H15: (f) | I15: (i) | J15: (j)
B17: =B16+1 -> 1 | C17: Intangible Plant - Gross | E17: II-B-1
B18: =B17+1 -> 2 | C18: A301 | D18: Organization | F18: 0 | G18: 0 | H18: 0 | I18: 0 | J18: =SUM(F18:I18) -> 0 | K18: =J18-SUM(F18:I18) -> 0 | V18: 0 | W18: 0 | X18: 0 | Y18: 0
B19: =B18+1 -> 3 | C19: A302 | D19: Franchise & Consents | F19: 0 | G19: 0 | H19: 0 | I19: 0 | J19: =SUM(F19:I19) -> 0 | K19: =J19-SUM(F19:I19) -> 0 | V19: 0 | W19: 0 | X19: 0 | Y19: 0
B20: =B19+1 -> 4 | C20: A303 | D20: Miscellaneous Intangible Plant | F20: 2.4730602e+08 | G20: 3.2333337e+08 | H20: 1.8530171e+08 | I20: 3.1040917e+08 | J20: =SUM(F20:I20) -> 1.0663503e+09 | K20: =J20-SUM(F20:I20) -> 0 | V20: 2.4730602e+08 | W20: 3.2333337e+08 | X20: 1.8530171e+08 | Y20: 3.1040917e+08
B21: =B20+1 -> 5 | C21: Intangible plant - Accumulated Depreciation | E21: II-B-5 | K21: =J21-SUM(F21:I21) -> 0
B22: =B21+1 -> 6 | C22: A301 | D22: Organization | F22: 0 | G22: 0 | H22: 0 | I22: 0 | J22: =SUM(F22:I22) -> 0 | K22: =J22-SUM(F22:I22) -> 0 | V22: 0 | W22: 0 | X22: 0 | Y22: 0
B23: =B22+1 -> 7 | C23: A302 | D23: Franchise and Consents | F23: 0 | G23: 0 | H23: 0 | I23: 0 | J23: =SUM(F23:I23) -> 0 | K23: =J23-SUM(F23:I23) -> 0 | V23: 0 | W23: 0 | X23: 0 | Y23: 0
B24: =B23+1 -> 8 | C24: A303 | D24: Miscellaneous Intangible Plant | F24: 99337446 | G24: 1.1412285e+08 | H24: 1.5516142e+08 | I24: 84146160 | J24: =SUM(F24:I24) -> 4.5276788e+08 | K24: =J24-SUM(F24:I24) -> 0 | V24: 99337446 | W24: 1.1412285e+08 | X24: 1.5516142e+08 | Y24: 84146160
B25: =B24+1 -> 9 | C25: Transmission Plant - Gross | E25: II-B-1 | K25: =J25-SUM(F25:I25) -> 0
B26: =B25+1 -> 10 | C26: A349 | D26: Land Owned in Fee | F26: 1.1590633e+08 | G26: 0 | H26: 0 | I26: 0 | J26: =SUM(F26:I26) -> 1.1590633e+08 | K26: =J26-SUM(F26:I26) -> 0 | V26: 1.1590633e+08 | W26: 0 | X26: 0 | Y26: 0
B27: =B26+1 -> 11 | C27: A350 | D27: Land and Land Rights | F27: 6.159264e+08 | G27: 0 | H27: 0 | I27: 0 | J27: =SUM(F27:I27) -> 6.159264e+08 | K27: =J27-SUM(F27:I27) -> 0 | V27: 6.159264e+08 | W27: 0 | X27: 0 | Y27: 0
B28: =B27+1 -> 12 | C28: A352 | D28: Structures and Improvements | F28: 4.2004589e+08 | G28: 0 | H28: 0 | I28: 0 | J28: =SUM(F28:I28) -> 4.2004589e+08 | K28: =J28-SUM(F28:I28) -> 0 | V28: 4.2004589e+08 | W28: 0 | X28: 0 | Y28: 0
B29: =B28+1 -> 13 | C29: A353 | D29: Station Equipment | F29: 3.4952984e+09 | G29: 3.8186065e+08 | H29: 0 | I29: 0 | J29: =SUM(F29:I29) -> 3.8771591e+09 | K29: =J29-SUM(F29:I29) -> 0 | V29: 3.4952984e+09 | W29: 3.8186065e+08 | X29: 0 | Y29: 0
B30: =B29+1 -> 14 | C30: A354 | D30: Towers and Fixtures | F30: 1.9296528e+09 | G30: 0 | H30: 0 | I30: 0 | J30: =SUM(F30:I30) -> 1.9296528e+09 | K30: =J30-SUM(F30:I30) -> 0 | V30: 1.9296528e+09 | W30: 0 | X30: 0 | Y30: 0
B31: =B30+1 -> 15 | C31: A355 | D31: Poles and Fixtures | F31: 2.8707703e+09 | G31: 0 | H31: 0 | I31: 0 | J31: =SUM(F31:I31) -> 2.8707703e+09 | K31: =J31-SUM(F31:I31) -> 0 | V31: 2.8707703e+09 | W31: 0 | X31: 0 | Y31: 0
B32: =B31+1 -> 16 | C32: A356 | D32: Overhead Conductors and Devices | F32: 3.0445813e+09 | G32: 0 | H32: 0 | I32: 0 | J32: =SUM(F32:I32) -> 3.0445813e+09 | K32: =J32-SUM(F32:I32) -> 0 | V32: 3.0445813e+09 | W32: 0 | X32: 0 | Y32: 0
B33: =B32+1 -> 17 | C33: A357 | D33: Undergound Conduit | F33: 60197135 | G33: 0 | H33: 0 | I33: 0 | J33: =SUM(F33:I33) -> 60197135 | K33: =J33-SUM(F33:I33) -> 0 | V33: 60197135 | W33: 0 | X33: 0 | Y33: 0
B34: =B33+1 -> 18 | C34: A358 | D34: Underground Conductors and Devices | F34: 84097343 | G34: 0 | H34: 0 | I34: 0 | J34: =SUM(F34:I34) -> 84097343 | K34: =J34-SUM(F34:I34) -> 0 | V34: 84097343 | W34: 0 | X34: 0 | Y34: 0
B35: =B34+1 -> 19 | C35: A359 | D35: Roads and Trails | F35: 0 | G35: 0 | H35: 0 | I35: 0 | J35: =SUM(F35:I35) -> 0 | K35: =J35-SUM(F35:I35) -> 0 | V35: 0 | W35: 0 | X35: 0 | Y35: 0
B36: =B35+1 -> 20 | C36: Transmission Plant - Accumulated Depreciation | E36: II-B-5 | K36: =J36-SUM(F36:I36) -> 0
B37: =B36+1 -> 21 | C37: A349 | D37: Land Owned in Fee | F37: 0 | G37: 0 | H37: 0 | I37: 0 | J37: =SUM(F37:I37) -> 0 | K37: =J37-SUM(F37:I37) -> 0 | V37: 0 | W37: 0 | X37: 0 | Y37: 0
B38: =B37+1 -> 22 | C38: A350 | D38: Land and Land Rights | F38: 1.067855e+08 | G38: 0 | H38: 0 | I38: 0 | J38: =SUM(F38:I38) -> 1.067855e+08 | K38: =J38-SUM(F38:I38) -> 0 | V38: 1.067855e+08 | W38: 0 | X38: 0 | Y38: 0
B39: =B38+1 -> 23 | C39: A352 | D39: Structures and Improvements | F39: 1.2805711e+08 | G39: 0 | H39: 0 | I39: 0 | J39: =SUM(F39:I39) -> 1.2805711e+08 | K39: =J39-SUM(F39:I39) -> 0 | V39: 1.2805711e+08 | W39: 0 | X39: 0 | Y39: 0
B40: =B39+1 -> 24 | C40: A353 | D40: Station Equipment | F40: 6.9304648e+08 | G40: 97170477 | H40: 0 | I40: 0 | J40: =SUM(F40:I40) -> 7.9021695e+08 | K40: =J40-SUM(F40:I40) -> 0 | V40: 6.9304648e+08 | W40: 97170477 | X40: 0 | Y40: 0
B41: =B40+1 -> 25 | C41: A354 | D41: Towers and Fixtures | F41: 4.6758005e+08 | G41: 0 | H41: 0 | I41: 0 | J41: =SUM(F41:I41) -> 4.6758005e+08 | K41: =J41-SUM(F41:I41) -> 0 | V41: 4.6758005e+08 | W41: 0 | X41: 0 | Y41: 0
B42: =B41+1 -> 26 | C42: A355 | D42: Poles and Fixtures | F42: 6.648537e+08 | G42: 0 | H42: 0 | I42: 0 | J42: =SUM(F42:I42) -> 6.648537e+08 | K42: =J42-SUM(F42:I42) -> 0 | V42: 6.648537e+08 | W42: 0 | X42: 0 | Y42: 0
B43: =B42+1 -> 27 | C43: A356 | D43: Overhead Conductors and Devices | F43: 9.7899905e+08 | G43: 0 | H43: 0 | I43: 0 | J43: =SUM(F43:I43) -> 9.7899905e+08 | K43: =J43-SUM(F43:I43) -> 0 | V43: 9.7899905e+08 | W43: 0 | X43: 0 | Y43: 0
B44: =B43+1 -> 28 | C44: A357 | D44: Undergound Conduit | F44: 19336448 | G44: 0 | H44: 0 | I44: 0 | J44: =SUM(F44:I44) -> 19336448 | K44: =J44-SUM(F44:I44) -> 0 | V44: 19336448 | W44: 0 | X44: 0 | Y44: 0
B45: =B44+1 -> 29 | C45: A358 | D45: Underground Conductors and Devices | F45: 33548402 | G45: 0 | H45: 0 | I45: 0 | J45: =SUM(F45:I45) -> 33548402 | K45: =J45-SUM(F45:I45) -> 0 | V45: 33548402 | W45: 0 | X45: 0 | Y45: 0
B46: =B45+1 -> 30 | C46: A359 | D46: Roads and Trails | F46: 0 | G46: 0 | H46: 0 | I46: 0 | J46: =SUM(F46:I46) -> 0 | K46: =J46-SUM(F46:I46) -> 0 | V46: 0 | W46: 0 | X46: 0 | Y46: 0
K47: =J47-SUM(F47:I47) -> 0
...

Sheet changes
A1: tbills column removed in wp ii I 1.1
E2: Row additions | H2: Row Deletions
B3: Prev | C3: New | E3: 186 | F3: Rate Case Expenses - Non-std Metering Tariff (Dkt 41890)
B4: Accumulated Deferred State Income Tax | C4: Deferred Margin Tax | E4: 186 | F4: Rate Case Expenses - Final AMS Rec Dkt 49721 | H4: 189 | I4: Gains/Losses on Reacquired Debt Post-Industry Restructure
E5: 186 | F5: Rate Case Expenses - 2018 DCRF Dkt 48231 | H5: 182 | I5: Gains/Losses on Reacquired Debt Pre-Industry Restructure
E6: 186 | F6: Rate Case Expenses - 2019 DCRF Dkt 49427 | H6: 182 | I6: Retrospective Franchise Fees
E7: 186 | F7: Rate Case Expenses - 2017 ED DOCKET 46957
E8: 186 | F8: Rate Case Expenses - 2018 TCJA Dkt 48325 | H8: 186 | I8: Rate Case Expenses - 2008 Dkt 35717 Appeals
E9: 186 | F9: Rate Case Expenses - 2021 Base Rate Case | H9: 186 | I9: Rate Case Expenses - 2010 ED RT CS Dkt 38928
E10: 189 | F10: Unamortized Losses - Reacquired Debt | H10: 186 | I10: Rate Case Expenses - 2017 Municipal Case
E11: 182 | F11: Rocky Mound Series Compensator | H11: 182 | I11: Deferred-Mtr Eqt Substations
E12: 182 | F12: COVID19-ERP Proceeds and Expenses Dkt 50664 & 50719 | H12: 182 | I12: Deferred Depr-Conv/BPL/PLC Meters
E13: 182 | F13: COVID19-Incremental Expense Dkt 50664
E14: 182 | F14: CWIP Tran & Dist Non-Service Cost Pension/OPEBs | H14: 186 | I14: Under/Over-Collected Transition Cost Revenues
E15: 182 | F15: Plant in service Tran & Dist Non-Service Cost Pension/OPEBs | H15: 182 | I15: Asset Retirement Obligations
E16: 182 | F16: TCRF Update 16 TAC 25.193 | H16: 228 | I16: Self Insurance Reserve (Transmission) (a)
E17: 186 | F17: Workers Compensation | H17: 254 | I17: Over Recovered AMS

Sheet  WP II-I-1.4
M2: =" "
B4: ='WP II-I-1.1'!B3 -> 2022 RATE CASE
B5: ='WP II-I-1.1'!B4 -> ONCOR ELECTRIC DELIVERY COMPANY LLC
B6: CONSOLIDATED FUNCTIONALIZED COST OF SERVICE
B7: ='WP II-I-1.1'!B6 -> TEST YEAR ENDING 12/31/2021
B8: ='WP II-I-2.2'!$B$7 -> SPONSOR: MATTHEW A. TROXLE
F10: TRAN | G10: DIST | H10: MET | I10: TDCS | J10: Total | L10: DIST + MET
B11: Line | D11: Revenue Requirement | E11: Source | L11: + TBILLTDCS
B13: (a) | D13: (b) | E13: (c) | F13: (d) | G13: (e) | H13: (f) | I13: (i) | J13: (j) | L13: (l)
B15: =B14+1 -> 1 | D15: O&M Expenses | E15: II-D-2 | F15: =F638+F686 -> 1.2775292e+08 | G15: =G638+G686 -> 1.9676251e+09 | H15: =H638+H686 -> 50235236 | I15: =I638+I686 -> 343150.73 | J15: =SUM(F15:I15) -> 2.1459564e+09 | L15: =SUM(G15:I15) -> 2.0182035e+09
B16: =B15+1 -> 2 | D16: Customer Expenses | E16: II-D-2 | F16: =F706+F716+F726 -> 87420.86 | G16: =G706+G716+G726 -> 245305.53 | H16: =H706+H716+H726 -> 8799722.5 | I16: =I706+I716+I726 -> 13109328 | J16: =SUM(F16:I16) -> 22241777 | L16: =SUM(G16:I16) -> 22154357
B17: =B16+1 -> 3 | D17: A&G Expenses | E17: II-D-2 | F17: =F760 -> 1.1555308e+08 | G17: =G760 -> 4.2312645e+08 | H17: =H760 -> 50135759 | I17: =I760 -> 36701329 | J17: =SUM(F17:I17) -> 6.2551662e+08 | L17: =SUM(G17:I17) -> 5.0996354e+08
B18: =B17+1 -> 4 | D18: O&M + Customer + A&G Expenses | F18: =SUM(F15:F17) -> 2.4339342e+08 | G18: =SUM(G15:G17) -> 2.3909969e+09 | H18: =SUM(H15:H17) -> 1.0917072e+08 | I18: =SUM(I15:I17) -> 50153808 | J18: =SUM(F18:I18) -> 2.7937148e+09 | L18: =SUM(G18:I18) -> 2.5503214e+09 | N18: ='WP II-I-1.1'!J462=J18 -> TRUE | P18: ='WP II-I-1.1'!F462=F18 -> TRUE | Q18: ='WP II-I-1.1'!G462=G18 -> TRUE | R18: ='WP II-I-1.1'!H462=H18 -> TRUE | S18: ='WP II-I-1.1'!I462=I18 -> TRUE | T18: ='WP II-I-1.1'!J462=J18 -> TRUE
B19: =B18+1 -> 5
B20: =B19+1 -> 6 | D20: Depreciation & Amortization (II-E-1) | E20: II-E-1 | F20: =F1035 -> 3.741449e+08 | G20: =G1035 -> 4.5981714e+08 | H20: =H1035 -> 30914364 | I20: =I1035 -> 32929277 | J20: =SUM(F20:I20) -> 8.9780568e+08 | L20: =SUM(G20:I20) -> 5.2366079e+08
B21: =B20+1 -> 7 | D21: Other (II-E-4) | E21: II-E-4 | F21: =F1037+F1038 -> 1167765.4 | G21: =G1037+G1038 -> -2772903.9 | H21: =H1037+H1038 -> 25459958 | I21: =I1037+I1038 -> 0 | J21: =SUM(F21:I21) -> 23854820 | L21: =SUM(G21:I21) -> 22687054
B22: =B21+1 -> 8 | D22: Depreciation, Amortization & Other Expenses | F22: =SUM(F20:F21) -> 3.7531266e+08 | G22: =SUM(G20:G21) -> 4.5704424e+08 | H22: =SUM(H20:H21) -> 56374322 | I22: =SUM(I20:I21) -> 32929277 | J22: =SUM(F22:I22) -> 9.216605e+08 | L22: =SUM(G22:I22) -> 5.4634784e+08 | N22: ='WP II-I-1.1'!J463=J22 -> TRUE | P22: ='WP II-I-1.1'!F463=F22 -> TRUE | Q22: ='WP II-I-1.1'!G463=G22 -> TRUE | R22: ='WP II-I-1.1'!H463=H22 -> TRUE | S22: ='WP II-I-1.1'!I463=I22 -> TRUE | T22: ='WP II-I-1.1'!J463=J22 -> TRUE
B23: =B22+1 -> 9
B24: =B23+1 -> 10 | D24: Taxes Other Than Federal Income Tax | E24: II-E-2 | F24: =+F1072 -> 1.5029276e+08 | G24: =+G1072 -> 4.474502e+08 | H24: =+H1072 -> 8538460.4 | I24: =+I1072 -> 4509539.8 | J24: =SUM(F24:I24) -> 6.1079096e+08 | L24: =SUM(G24:I24) -> 4.604982e+08 | N24: ='WP II-I-1.1'!J464=J24 -> TRUE | P24: ='WP II-I-1.1'!F464=F24 -> TRUE | Q24: ='WP II-I-1.1'!G464=G24 -> TRUE | R24: ='WP II-I-1.1'!H464=H24 -> TRUE | S24: ='WP II-I-1.1'!I464-I24 -> 0 | T24: ='WP II-I-1.1'!J464=J24 -> TRUE
B25: =B24+1 -> 11 | D25: Federal Income Tax | E25: II-E-3 | F25: =+F1132 -> 82799350 | G25: =+G1132 -> 78221385 | H25: =+H1132 -> 1649124.5 | I25: =+I1132 -> 2534176.5 | J25: =SUM(F25:I25) -> 1.6520404e+08 | L25: =SUM(G25:I25) -> 82404686 | N25: ='WP II-I-1.1'!J465=J25 -> TRUE | P25: ='WP II-I-1.1'!F465-F25 -> 0 | Q25: ='WP II-I-1.1'!G465-G25 -> 0 | R25: ='WP II-I-1.1'!H465-H25 -> 0 | S25: ='WP II-I-1.1'!I465-I25 -> 0 | T25: ='WP II-I-1.1'!J465-J25 -> 0
B26: =B25+1 -> 12
B27: =B26+1 -> 13 | D27: Return on Rate Base | E27: II-B | F27: =+F83 -> 6.364015e+08 | G27: =+G83 -> 6.3883984e+08 | H27: =+H83 -> 29703070 | I27: =+I83 -> 14457605 | J27: =SUM(F27:I27) -> 1.319402e+09 | L27: =SUM(G27:I27) -> 6.8300051e+08 | N27: ='WP II-I-1.1'!J461=J27 -> TRUE | P27: ='WP II-I-1.1'!F461-F27 -> 0 | Q27: ='WP II-I-1.1'!G461-G27 -> 0 | R27: ='WP II-I-1.1'!H461-H27 -> 0 | S27: ='WP II-I-1.1'!I461-I27 -> 0 | T27: ='WP II-I-1.1'!J461-J27 -> 0
B28: =B27+1 -> 14
B29: =B28+1 -> 15 | D29: TOTAL COST OF SERVICE | F29: =+F18+F22+F24+F25+F27 -> 1.4881997e+09 | G29: =+G18+G22+G24+G25+G27 -> 4.0125525e+09 | H29: =+H18+H22+H24+H25+H27 -> 2.0543569e+08 | I29: =+I18+I22+I24+I25+I27 -> 1.0458441e+08 | J29: =SUM(F29:I29) -> 5.8107723e+09 | L29: =SUM(G29:I29) -> 4.3225726e+09
B30: 16
B31: =B30+1 -> 17 | D31: Minus: Other Revenues | E31: II-E-5 | F31: =+F1188 -> 43023335 | G31: =+G1188 -> 51757982 | H31: =+H1188 -> 5094631 | I31: =+I1188 -> 205014.65 | J31: =SUM(F31:I31) -> 1.0008096e+08 | L31: =SUM(G31:I31) -> 57057628 | N31: ='WP II-I-1.1'!J466=-J31 -> TRUE
B32: =B31+1 -> 18
B33: =B32+1 -> 19 | D33: COST-BASED Revenue Requirement | F33: =+F29-F31 -> 1.4451764e+09 | G33: =+G29-G31 -> 3.9607946e+09 | H33: =+H29-H31 -> 2.0034106e+08 | I33: =+I29-I31 -> 1.0437939e+08 | J33: =SUM(F33:I33) -> 5.7106914e+09 | L33: =G33+H33+I33 -> 4.265515e+09 | N33: ='WP II-I-1.1'!$J$467-J33 -> 0
B42: =$B$4 -> 2022 RATE CASE
B43: =$B$5 -> ONCOR ELECTRIC DELIVERY COMPANY LLC
B44: =$B$6 -> CONSOLIDATED FUNCTIONALIZED COST OF SERVICE
B45: =$B$7 -> TEST YEAR ENDING 12/31/2021
B46: =$B$8 -> SPONSOR: MATTHEW A. TROXLE
F48: TRAN | G48: DIST | H48: MET | I48: TDCS | J48: Total | L48: =L$10 -> DIST + MET
B49: Line | D49: Return On Rate Base | E49: Source | L49: =L$11 -> + TBILLTDCS
B51: (a) | D51: (b) | E51: (c) | F51: (d) | G51: (e) | H51: (f) | I51: (i) | J51: (j) | L51: (l)
B53: =B52+1 -> 1 | D53: Intangible Plant: Original Cost | E53: II-B-1 | F53: =F106 -> 2.4730602e+08 | G53: =G106 -> 3.2333337e+08 | H53: =H106 -> 1.8530171e+08 | I53: =I106 -> 3.1040917e+08 | J53: =SUM(F53:I53) -> 1.0663503e+09 | L53: =SUM(G53:I53) -> 8.1904426e+08 | N53: =SUM('WP II-I-1.1'!F18:I20)=J53 -> TRUE
B54: =B53+1 -> 2 | D54: Transmission Plant: Original Cost | E54: II-B-1 | F54: =F118 -> 1.2636476e+10 | G54: =G118 -> 3.8186065e+08 | H54: =H118 -> 0 | I54: =I118 -> 0 | J54: =SUM(F54:I54) -> 1.3018337e+10 | L54: =SUM(G54:I54) -> 3.8186065e+08 | N54: =SUM('WP II-I-1.1'!F26:I35)=J54 -> TRUE
B55: =B54+1 -> 3 | D55: Distribution Plant: Original Cost | E55: II-B-1 | F55: =F154 -> 7.0543355e+08 | G55: =G154 -> 1.461882e+10 | H55: =H154 -> 5.7414748e+08 | I55: =I154 -> 0 | J55: =SUM(F55:I55) -> 1.5898401e+10 | L55: =SUM(G55:I55) -> 1.5192967e+10 | N55: =SUM('WP II-I-1.1'!F50:I64)=J55 -> TRUE
B56: =B55+1 -> 4 | D56: Intangible, Transmission, Distribution Plant: Original Cost | F56: =SUM(F53:F55) -> 1.3589215e+10 | G56: =SUM(G53:G55) -> 1.5324014e+10 | H56: =SUM(H53:H55) -> 7.594492e+08 | I56: =SUM(I53:I55) -> 3.1040917e+08 | J56: =SUM(F56:I56) -> 2.9983088e+10 | L56: =SUM(G56:I56) -> 1.6393872e+10 | N56: =SUM(F56:I56)=J56 -> TRUE
...

Sheet II-I-DIST
B4: ='WP II-I-1.1'!B3 -> 2022 RATE CASE
B5: ='WP II-I-1.1'!B4 -> ONCOR ELECTRIC DELIVERY COMPANY LLC
B6: ="II-I-1-DIST: CLASS REVENUE REQUIREMENT" -> II-I-1-DIST: CLASS REVENUE REQUIREMENT
B7: ='WP II-I-1.1'!B6 -> TEST YEAR ENDING 12/31/2021
B8: ='WP II-I-2.2'!$B$7 -> SPONSOR: MATTHEW A. TROXLE
R10: =" "
B11: Line | D11: I-A-1 by Rate Class | E11: Source | F11: DIST | J11: Residential | K11: Secondary | L11: Secondary | M11: Primary | N11: Primary | O11: Primary | P11: Transmission | Q11: Lighting | R11: Wholesale | S11: Wholesale | U11: Total
K12: <=10 kW | L12: > 10 kW | M12: <=10 kW | N12: > 10 kW | O12: Substation | R12: XFMR | S12: DLS
F13: (a) | G13: (b) | H13: (c) | J13: (d) | K13: (e) | L13: (f) | M13: (g) | N13: (h) | O13: (i) | P13: (j) | Q13: (k) | R13: (l) | S13: (m) | U13: (n)
B15: =B14+1 -> 1 | D15: O&M Expenses | E15: II-D-2 | F15: =F638+F686 -> 1.9676251e+09 | J15: =J638+J686 -> 9.2562883e+08 | K15: =K638+K686 -> 25721821 | L15: =L638+L686 -> 6.5841473e+08 | M15: =M638+M686 -> 291840.01 | N15: =N638+N686 -> 1.6020127e+08 | O15: =O638+O686 -> 47191842 | P15: =P638+P686 -> 1.3785413e+08 | Q15: =Q638+Q686 -> 10957441 | ... S15: =S638+S686 -> 1148504.9 | U15: =SUM(I15:T15) -> 1.9676251e+09 | X15: =U15-F15 -> 0
B16: =B15+1 -> 2 | D16: Customer Expenses | E16: II-D-2 | F16: =F706+F716+F726 -> 245305.53 | J16: =J706+J716+J726 -> 211382.27 | K16: =K706+K716+K726 -> 20459.035 | L16: =L706+L716+L726 -> 10111.178 | M16: =M706+M716+M726 -> 238.26144 | N16: =N706+N716+N726 -> 203.54548 | O16: =O706+O716+O726 -> -91.058921 | P16: =P706+P716+P726 -> -384.8685 | Q16: =Q706+Q716+Q726 -> 3371.9531 | ... S16: =S706+S716+S726 -> 10.906226 | U16: =SUM(I16:T16) -> 245305.53 | X16: =U16-F16 -> 0
B17: =B16+1 -> 3 | D17: A&G Expenses | E17: II-D-2 | F17: =F760 -> 4.2312645e+08 | J17: =J760 -> 2.283512e+08 | K17: =K760 -> 7879417.5 | L17: =L760 -> 1.4405275e+08 | M17: =M760 -> 73200.4 | N17: =N760 -> 24811551 | O17: =O760 -> 2275901 | P17: =P760 -> 333312.72 | Q17: =Q760 -> 13755289 | ... S17: =S760 -> 1325254.8 | U17: =SUM(I17:T17) -> 4.2312645e+08 | X17: =U17-F17 -> 0
B18: =B17+1 -> 4 | D18: O&M + Customer + A&G Expenses | F18: =SUM(F15:F17) -> 2.3909969e+09 | J18: =SUM(J15:J17) -> 1.1541914e+09 | K18: =SUM(K15:K17) -> 33621697 | L18: =SUM(L15:L17) -> 8.0247759e+08 | M18: =SUM(M15:M17) -> 365278.68 | N18: =SUM(N15:N17) -> 1.8501303e+08 | O18: =SUM(O15:O17) -> 49467652 | P18: =SUM(P15:P17) -> 1.3818706e+08 | Q18: =SUM(Q15:Q17) -> 24716102 | ... S18: =SUM(S15:S17) -> 2473770.6 | U18: =SUM(I18:T18) -> 2.3909969e+09 | X18: =U18-F18 -> 0 | Y18: ='WP II-I-1.1'!$G$462=U18 -> TRUE | Z18: should match schedule D
B19: =B18+1 -> 5 | X19: =U19-F19 -> 0
B20: =B19+1 -> 6 | D20: Depreciation & Amortization (II-E-1) | E20: II-E-1 | F20: =F1035 -> 4.5981714e+08 | J20: =J1035 -> 2.4554112e+08 | K20: =K1035 -> 10276121 | L20: =L1035 -> 1.5254519e+08 | M20: =M1035 -> 53564.308 | N20: =N1035 -> 22671112 | O20: =O1035 -> 1729044.2 | P20: =P1035 -> 355894.65 | Q20: =Q1035 -> 25207217 | ... S20: =S1035 -> 1230650.8 | U20: =SUM(I20:T20) -> 4.5981714e+08 | X20: =U20-F20 -> 0
B21: =B20+1 -> 7 | D21: Other (II-E-4) | E21: II-E-4 | F21: =F1037+F1038 -> -2772903.9 | J21: =J1037+J1038 -> -1543390.6 | K21: =K1037+K1038 -> -51305.984 | L21: =L1037+L1038 -> -976083.78 | M21: =M1037+M1038 -> -353.45194 | N21: =N1037+N1038 -> -149598.65 | O21: =O1037+O1038 -> -14829.983 | P21: =P1037+P1038 -> -2808.1134 | Q21: =Q1037+Q1038 -> -24635.28 | ... S21: =S1037+S1038 -> -8120.6299 | U21: =SUM(I21:T21) -> -2772903.9 | X21: =U21-F21 -> 0
B22: =B21+1 -> 8 | D22: Depreciation, Amortization & Other Expenses | F22: =SUM(F20:F21) -> 4.5704424e+08 | J22: =SUM(J20:J21) -> 2.4399773e+08 | K22: =SUM(K20:K21) -> 10224815 | L22: =SUM(L20:L21) -> 1.515691e+08 | M22: =SUM(M20:M21) -> 53210.856 | N22: =SUM(N20:N21) -> 22521513 | O22: =SUM(O20:O21) -> 1714214.2 | P22: =SUM(P20:P21) -> 353086.53 | Q22: =SUM(Q20:Q21) -> 25182582 | ... S22: =SUM(S20:S21) -> 1222530.2 | U22: =SUM(I22:T22) -> 4.5704424e+08 | X22: =U22-F22 -> 0 | Y22: ='WP II-I-1.1'!$G$463=U22 -> TRUE
B23: =B22+1 -> 9 | X23: =U23-F23 -> 0
B24: =B23+1 -> 10 | D24: Taxes Other Than Federal Income Tax | E24: II-E-2 | F24: =+F1072 -> 4.474502e+08 | J24: =+J1072 -> 2.0342872e+08 | K24: =+K1072 -> 7522309.1 | L24: =+L1072 -> 1.7519255e+08 | M24: =+M1072 -> 23085.31 | N24: =+N1072 -> 27643694 | O24: =+O1072 -> 3816059.2 | P24: =+P1072 -> 22715111 | Q24: =+Q1072 -> 5980508.8 | ... S24: =+S1072 -> 802088.52 | U24: =SUM(I24:T24) -> 4.474502e+08 | X24: =U24-F24 -> 0 | Y24: ='WP II-I-1.1'!$G$464=U24 -> TRUE
B25: =B24+1 -> 11 | D25: Federal Income Tax | E25: II-E-3 | F25: =+F1130 -> 78221385 | J25: =+J1130 -> 43523262 | K25: =+K1130 -> 1413378.3 | L25: =+L1130 -> 27675494 | M25: =+M1130 -> 10069.517 | N25: =+N1130 -> 4281733.1 | O25: =+O1130 -> 430785.89 | P25: =+P1130 -> 136515.79 | Q25: =+Q1130 -> 468980.55 | ... S25: =+S1130 -> 229814.61 | U25: =SUM(I25:T25) -> 78221385 | X25: =U25-F25 -> 0 | Y25: ='WP II-I-1.1'!$G$465-U25 -> 0
B26: =B25+1 -> 12 | X26: =U26-F26 -> 0
B27: =B26+1 -> 13 | D27: Return on Rate Base | E27: II-B | F27: =+F83 -> 6.3883984e+08 | J27: =+J83 -> 3.5527283e+08 | K27: =+K83 -> 11529737 | L27: =+L83 -> 2.2624227e+08 | M27: =+M83 -> 82109.809 | N27: =+N83 -> 34931887 | O27: =+O83 -> 3501360.2 | P27: =+P83 -> 1107731.7 | Q27: =+Q83 -> 3875733.7 | ... S27: =+S83 -> 1877498.1 | U27: =SUM(I27:T27) -> 6.3883984e+08 | X27: =U27-F27 -> 0 | Y27: ='WP II-I-1.1'!$G$461=U27 -> TRUE
B28: =B27+1 -> 14 | X28: =U28-F28 -> 0
B29: =B28+1 -> 15 | D29: TOTAL COST OF SERVICE | F29: =+F18+F22+F24+F25+F27 -> 4.0125525e+09 | J29: =+J18+J22+J24+J25+J27 -> 2.0004139e+09 | K29: =+K18+K22+K24+K25+K27 -> 64311936 | L29: =+L18+L22+L24+L25+L27 -> 1.383157e+09 | M29: =+M18+M22+M24+M25+M27 -> 533754.17 | N29: =+N18+N22+N24+N25+N27 -> 2.7439186e+08 | O29: =+O18+O22+O24+O25+O27 -> 58930071 | P29: =+P18+P22+P24+P25+P27 -> 1.6249951e+08 | Q29: =+Q18+Q22+Q24+Q25+Q27 -> 60223906 | ... S29: =+S18+S22+S24+S25+S27 -> 6605702.1 | U29: =SUM(I29:T29) -> 4.0125525e+09 | X29: =U29-F29 -> 0 | Y29: ='WP II-I-1.1'!$G$476=U29 -> TRUE
B30: =B29+1 -> 16 | X30: =U30-F30 -> 0
B31: =B30+1 -> 17 | D31: Minus: Other Revenues | E31: II-E-5 | F31: =+F1186 -> 51757982 | J31: =+J1186 -> 33855633 | K31: =+K1186 -> 1962762 | L31: =+L1186 -> 13167153 | M31: =+M1186 -> 18570.774 | N31: =+N1186 -> 2013214.5 | O31: =+O1186 -> 118085.83 | P31: =+P1186 -> 37812.6 | Q31: =+Q1186 -> 527901.22 | ... S31: =+S1186 -> 53236.441 | U31: =SUM(I31:T31) -> 51757982 | X31: =U31-F31 -> 0 | Y31: ='WP II-I-1.1'!$G$466=-U31 -> TRUE
B32: =B31+1 -> 18 | X32: =U32-F32 -> 0
B33: =B32+1 -> 19 | D33: COST-BASED Revenue Requirement | F33: =+F29-F31 -> 3.9607946e+09 | J33: =+J29-J31 -> 1.9665583e+09 | K33: =+K29-K31 -> 62349174 | L33: =+L29-L31 -> 1.3699899e+09 | M33: =+M29-M31 -> 515183.39 | N33: =+N29-N31 -> 2.7237864e+08 | O33: =+O29-O31 -> 58811986 | P33: =+P29-P31 -> 1.6246169e+08 | Q33: =+Q29-Q31 -> 59696005 | ... S33: =+S29-S31 -> 6552465.6 | U33: =SUM(I33:T33) -> 3.9607946e+09 | W33: =IF(' WP II-I-1.4'!G33=U33,TRUE,' WP II-I-1.4'!G33-G33) -> TRUE | X33: =U33-F33 -> 0 | Y33: ='WP II-I-1.1'!$G$467=U33 -> TRUE
B34: =B33+1 -> 20 | X34: =U34-F34 -> 0
B35: =B34+1 -> 21 | D35: Proposed Adjustment to Return On Rate Base | F35: ='WP II-I-1.5'!D54 -> 0 | J35: ='WP II-I-1.5'!F54 -> 0 | K35: ='WP II-I-1.5'!G54 -> 0 | L35: ='WP II-I-1.5'!H54 -> 0 | M35: ='WP II-I-1.5'!I54 -> 0 | N35: ='WP II-I-1.5'!J54 -> 0 | O35: ='WP II-I-1.5'!K54 -> 0 | P35: ='WP II-I-1.5'!L54 -> 0 | Q35: ='WP II-I-1.5'!M54 -> 0 | ... S35: ='WP II-I-1.5'!O54 -> 0 | U35: =SUM(I35:T35) -> 0 | X35: =U35-F35 -> 0
B36: =B35+1 -> 22 | D36: (WP II-I-1.5) | X36: =U36-F36 -> 0
B37: =B36+1 -> 23 | D37: PROPOSED Revenue | F37: =F33+F35 -> 3.9607946e+09 | J37: =J33+J35 -> 1.9665583e+09 | K37: =K33+K35 -> 62349174 | L37: =L33+L35 -> 1.3699899e+09 | M37: =M33+M35 -> 515183.39 | N37: =N33+N35 -> 2.7237864e+08 | O37: =O33+O35 -> 58811986 | P37: =P33+P35 -> 1.6246169e+08 | Q37: =Q33+Q35 -> 59696005 | ... S37: =S33+S35 -> 6552465.6 | U37: =SUM(I37:T37) -> 3.9607946e+09 | X37: =U37-F37 -> 0
B38: =B37+1 -> 24 | X38: =U38-F38 -> 0
B39: =B38+1 -> 25 | D39: PROPOSED Revenue Excl 565 & A928 | F39: =+F37-F622-(0.727923)*F753 -> 2.3066259e+09 | J39: =+J37-J622-(0.727923)*J753 -> 1.2075454e+09 | K39: =+K37-K622-(0.727923)*K753 -> 41122596 | L39: =+L37-L622-(0.727923)*L753 -> 8.1825418e+08 | M39: =+M37-M622-(0.727923)*M753 -> 295364.15 | N39: =+N37-N622-(0.727923)*N753 -> 1.3369402e+08 | O39: =+O37-O622-(0.727923)*O753 -> 13404715 | P39: =+P37-P622-(0.727923)*P753 -> 24606815 | Q39: =+Q37-Q622-(0.727923)*Q753 -> 59672372 | ... S39: =+S37-S622-(0.727923)*S753 -> 6549864 | U39: =SUM(I39:T39) -> 2.3066259e+09 | X39: =U39-F39 -> 0 | Y39: =ROUND('WP II-I-1.1'!$G$467-'WP II-I-1.1'!$G$199-('WP II-I-1.1'!$G$258*(0.727923)),0)-U39 -> 0.14142847
W40: =U39-F39 -> 0 | X40: =U40-F40 -> 0
V41: =$H$2 -> 0
B42: =+$B$4 -> 2022 RATE CASE | X42: =U42-F42 -> 0
B43: =+$B$5 -> ONCOR ELECTRIC DELIVERY COMPANY LLC | X43: =U43-F43 -> 0
B44: =+$B$6 -> II-I-1-DIST: CLASS REVENUE REQUIREMENT | X44: =U44-F44 -> 0
B45: =+$B$7 -> TEST YEAR ENDING 12/31/2021 | X45: =U45-F45 -> 0
...

Sheet II-I-MET
B4: ='WP II-I-1.1'!B3 -> 2022 RATE CASE
B5: ='WP II-I-1.1'!B4 -> ONCOR ELECTRIC DELIVERY COMPANY LLC
B6: ="II-I-1-MET: CLASS REVENUE REQUIREMENT" -> II-I-1-MET: CLASS REVENUE REQUIREMENT
B7: ='WP II-I-1.1'!B6 -> TEST YEAR ENDING 12/31/2021
B8: ='WP II-I-2.2'!$B$7 -> SPONSOR: MATTHEW A. TROXLE
R10: =" "
B11: Line | D11: I-A-1 by Rate Class | E11: Source | F11: MET | J11: Residential | K11: Secondary | L11: Secondary | M11: Primary | N11: Primary | O11: Primary | P11: Transmission | Q11: Lighting | R11: Wholesale | S11: Wholesale | U11: Total
K12: <=10 kW | L12: > 10 kW | M12: <=10 kW | N12: > 10 kW | O12: Substation | R12: XFMR | S12: DLS
F13: (a) | G13: (b) | H13: (c) | J13: (d) | K13: (e) | L13: (f) | M13: (g) | N13: (h) | O13: (i) | P13: (j) | Q13: (k) | R13: (l) | S13: (m) | U13: (n)
B15: =B14+1 -> 1 | D15: O&M Expenses | E15: II-D-2 | F15: =F638+F686 -> 50235236 | J15: =J638+J686 -> 27996970 | K15: =K638+K686 -> 4316260.1 | L15: =L638+L686 -> 13314318 | M15: =M638+M686 -> 186943.1 | N15: =N638+N686 -> 3901170.2 | O15: =O638+O686 -> 133373.69 | P15: =P638+P686 -> 290202.47 | Q15: =Q638+Q686 -> 44680.3 | ... S15: =S638+S686 -> 35928.033 | U15: =SUM(I15:T15) -> 50235236 | W15: =U15-F15 -> 0
B16: =B15+1 -> 2 | D16: Customer Expenses | E16: II-D-2 | F16: =F706+F716+F726 -> 8799722.5 | J16: =J706+J716+J726 -> 4937125.1 | K16: =K706+K716+K726 -> 755666.43 | L16: =L706+L716+L726 -> 2310400.2 | M16: =M706+M716+M726 -> 32448.274 | N16: =N706+N716+N726 -> 675505.49 | O16: =O706+O716+O726 -> 23080.862 | P16: =P706+P716+P726 -> 50245.26 | Q16: =Q706+Q716+Q726 -> 6368.3216 | ... S16: =S706+S716+S726 -> 6219.3896 | U16: =SUM(I16:T16) -> 8799722.5 | W16: =U16-F16 -> 0
B17: =B16+1 -> 3 | D17: A&G Expenses | E17: II-D-2 | F17: =F760 -> 50135759 | J17: =J760 -> 27963844 | K17: =K760 -> 4306829.4 | L17: =L760 -> 13276535 | M17: =M760 -> 186341.24 | N17: =N760 -> 3888500.7 | O17: =O760 -> 133007.13 | P17: =P760 -> 289638.31 | Q17: =Q760 -> 39921.963 | ... S17: =S760 -> 35806.816 | U17: =SUM(I17:T17) -> 50135759 | W17: =U17-F17 -> 0
B18: =B17+1 -> 4 | D18: O&M + Customer + A&G Expenses | F18: =SUM(F15:F17) -> 1.0917072e+08 | J18: =SUM(J15:J17) -> 60897939 | K18: =SUM(K15:K17) -> 9378755.9 | L18: =SUM(L15:L17) -> 28901253 | M18: =SUM(M15:M17) -> 405732.61 | N18: =SUM(N15:N17) -> 8465176.4 | O18: =SUM(O15:O17) -> 289461.69 | P18: =SUM(P15:P17) -> 630086.05 | Q18: =SUM(Q15:Q17) -> 90970.585 | ... S18: =SUM(S15:S17) -> 77954.238 | U18: =SUM(I18:T18) -> 1.0917072e+08 | W18: =U18-F18 -> 0 | X18: ='WP II-I-1.1'!$H$462=U18 -> TRUE
B19: =B18+1 -> 5 | W19: =U19-F19 -> 0
B20: =B19+1 -> 6 | D20: Depreciation & Amortization (II-E-1) | E20: II-E-1 | F20: =F1035 -> 30914364 | J20: =J1035 -> 17234907 | K20: =K1035 -> 2657178.7 | L20: =L1035 -> 8196159.8 | M20: =M1035 -> 115086.53 | N20: =N1035 -> 2401545.8 | O20: =O1035 -> 82068.039 | P20: =P1035 -> 178655.81 | Q20: =Q1035 -> 17180.136 | ... S20: =S1035 -> 22112.843 | U20: =SUM(I20:T20) -> 30914364 | W20: =U20-F20 -> 0
B21: =B20+1 -> 7 | D21: Other (II-E-4) | E21: II-E-4 | F21: =F1037+F1038 -> 25459958 | J21: =J1037+J1038 -> 14194049 | K21: =K1037+K1038 -> 2188356.9 | L21: =L1037+L1038 -> 6750062.4 | M21: =M1037+M1038 -> 94781.126 | N21: =N1037+N1038 -> 1977826.8 | O21: =O1037+O1038 -> 67588.286 | P21: =P1037+P1038 -> 147134.5 | Q21: =Q1037+Q1038 -> 14148.942 | ... S21: =S1037+S1038 -> 18211.342 | U21: =SUM(I21:T21) -> 25459958 | W21: =U21-F21 -> 0
B22: =B21+1 -> 8 | D22: Depreciation, Amortization & Other Expenses | F22: =SUM(F20:F21) -> 56374322 | J22: =SUM(J20:J21) -> 31428956 | K22: =SUM(K20:K21) -> 4845535.6 | L22: =SUM(L20:L21) -> 14946222 | M22: =SUM(M20:M21) -> 209867.65 | N22: =SUM(N20:N21) -> 4379372.6 | O22: =SUM(O20:O21) -> 149656.33 | P22: =SUM(P20:P21) -> 325790.31 | Q22: =SUM(Q20:Q21) -> 31329.078 | ... S22: =SUM(S20:S21) -> 40324.185 | U22: =SUM(I22:T22) -> 56374322 | W22: =U22-F22 -> 0 | X22: ='WP II-I-1.1'!$H$463=U22 -> TRUE
B23: =B22+1 -> 9 | W23: =U23-F23 -> 0
B24: =B23+1 -> 10 | D24: Taxes Other Than Federal Income Tax | E24: II-E-2 | F24: =+F1072 -> 8538460.4 | J24: =+J1072 -> 4759243.1 | K24: =+K1072 -> 733334.04 | L24: =+L1072 -> 2264727.3 | M24: =+M1072 -> 31752.473 | N24: =+N1072 -> 663072.55 | O24: =+O1072 -> 22694.899 | P24: =+P1072 -> 49877.895 | Q24: =+Q1072 -> 5042.9021 | ... S24: =+S1072 -> 6102.0186 | U24: =SUM(I24:T24) -> 8538460.4 | W24: =U24-F24 -> 0 | X24: ='WP II-I-1.1'!$H$464=U24 -> TRUE
B25: =B24+1 -> 11 | D25: Federal Income Tax | E25: II-E-3 | F25: =+F1130 -> 1649124.5 | J25: =+J1130 -> 917265.06 | K25: =+K1130 -> 140880.77 | L25: =+L1130 -> 439447.33 | M25: =+M1130 -> 6093.5196 | N25: =+N1130 -> 127971.6 | O25: =+O1130 -> 4429.4797 | P25: =+P1130 -> 10409.508 | Q25: =+Q1130 -> 952.02616 | ... S25: =+S1130 -> 1172.8056 | U25: =SUM(I25:T25) -> 1649124.5 | W25: =U25-F25 -> 0 | X25: ='WP II-I-1.1'!$H$465=U25 -> TRUE
B26: =B25+1 -> 12 | W26: =U26-F26 -> 0
B27: =B26+1 -> 13 | D27: Return on Rate Base | E27: II-B | F27: =+F83 -> 29703070 | J27: =+J83 -> 16524775 | K27: =+K83 -> 2538756.4 | L27: =+L83 -> 7911329.3 | M27: =+M83 -> 109817.98 | N27: =+N83 -> 2305042.3 | O27: =+O83 -> 79699.057 | P27: =+P83 -> 186137.83 | Q27: =+Q83 -> 17325.576 | ... S27: =+S83 -> 21133.209 | U27: =SUM(I27:T27) -> 29703070 | W27: =U27-F27 -> 0 | X27: ='WP II-I-1.1'!$H$461=U27 -> TRUE
B28: =B27+1 -> 14 | W28: =U28-F28 -> 0
B29: =B28+1 -> 15 | D29: TOTAL COST OF SERVICE | F29: =+F18+F22+F24+F25+F27 -> 2.0543569e+08 | J29: =+J18+J22+J24+J25+J27 -> 1.1452818e+08 | K29: =+K18+K22+K24+K25+K27 -> 17637263 | L29: =+L18+L22+L24+L25+L27 -> 54462979 | M29: =+M18+M22+M24+M25+M27 -> 763264.24 | N29: =+N18+N22+N24+N25+N27 -> 15940635 | O29: =+O18+O22+O24+O25+O27 -> 545941.45 | P29: =+P18+P22+P24+P25+P27 -> 1202301.6 | Q29: =+Q18+Q22+Q24+Q25+Q27 -> 145620.17 | ... S29: =+S18+S22+S24+S25+S27 -> 146686.46 | U29: =SUM(I29:T29) -> 2.0543569e+08 | W29: =U29-F29 -> 0 | X29: ='WP II-I-1.1'!$H$476=U29 -> TRUE
B30: =B29+1 -> 16
B31: =B30+1 -> 17 | D31: Minus: Other Revenues | E31: II-E-5 | F31: =+F1186 -> 5094631 | J31: =+J1186 -> 2843185.9 | K31: =+K1186 -> 438346.05 | L31: =+L1186 -> 1352093.5 | M31: =+M1186 -> 18985.446 | N31: =+N1186 -> 396175.12 | O31: =+O1186 -> 13538.495 | P31: =+P1186 -> 29472.262 | Q31: =+Q1186 -> 2834.1505 | ... S31: =+S1186 -> 0 | U31: =SUM(I31:T31) -> 5094631 | X31: ='WP II-I-1.1'!$H$466=-U31 -> TRUE
B32: =B31+1 -> 18
B33: =B32+1 -> 19 | D33: COST-BASED Revenue Requirement | F33: =+F29-F31 -> 2.0034106e+08 | J33: =+J29-J31 -> 1.1168499e+08 | K33: =+K29-K31 -> 17198917 | L33: =+L29-L31 -> 53110886 | M33: =+M29-M31 -> 744278.79 | N33: =+N29-N31 -> 15544460 | O33: =+O29-O31 -> 532402.95 | P33: =+P29-P31 -> 1172829.3 | Q33: =+Q29-Q31 -> 142786.02 | ... S33: =+S29-S31 -> 146686.46 | U33: =SUM(I33:T33) -> 2.0034106e+08 | W33: =IF(ROUND(U33-'WP II-I-1.1'!H467,2)=0,TRUE,U33-'WP II-I-1.1'!H467) -> TRUE | X33: ='WP II-I-1.1'!$H$467=U33 -> TRUE
B42: =+$B$4 -> 2022 RATE CASE
B43: =+$B$5 -> ONCOR ELECTRIC DELIVERY COMPANY LLC
B44: =+$B$6 -> II-I-1-MET: CLASS REVENUE REQUIREMENT
B45: =+$B$7 -> TEST YEAR ENDING 12/31/2021
B46: =+$B$8 -> SPONSOR: MATTHEW A. TROXLE
R48: =R$10
B49: Line | D49: II-B by Rate Class | E49: Source | F49: =F$11 -> MET | J49: Residential | K49: Secondary | L49: Secondary | M49: Primary | N49: Primary | O49: Primary | P49: Transmission | Q49: Lighting | R49: =R$11 -> Wholesale | S49: =S$11 -> Wholesale | U49: Total
K50: <=10 kW | L50: > 10 kW | M50: <=10 kW | N50: > 10 kW | O50: Substation | R50: =R$12 -> XFMR | S50: =S$12 -> DLS
F51: (a) | G51: (b) | H51: (c) | J51: =J$13 -> (d) | K51: =K$13 -> (e) | L51: =L$13 -> (f) | M51: =M$13 -> (g) | N51: =N$13 -> (h) | O51: =O$13 -> (i) | P51: =P$13 -> (j) | Q51: =Q$13 -> (k) | ... S51: =S$13 -> (m) | U51: (n)
B53: =B52+1 -> 1 | D53: Intangible Plant: Original Cost | E53: II-B-1 | F53: =F106 -> 1.8530171e+08 | J53: =J106 -> 1.033066e+08 | K53: =K106 -> 15927217 | L53: =L106 -> 49128051 | M53: =M106 -> 689832.43 | N53: =N106 -> 14394945 | O53: =O106 -> 491918.53 | P53: =P106 -> 1070868.8 | Q53: =Q106 -> 102978.3 | ... S53: =S106 -> 132545.11 | U53: =SUM(I53:T53) -> 1.8530171e+08 | W53: =U53-F53 -> 0
B54: =B53+1 -> 2 | D54: Transmission Plant: Original Cost | E54: II-B-1 | F54: =F118 -> 0 | J54: =J118 -> 0 | K54: =K118 -> 0 | L54: =L118 -> 0 | M54: =M118 -> 0 | N54: =N118 -> 0 | O54: =O118 -> 0 | P54: =P118 -> 0 | Q54: =Q118 -> 0 | ... S54: =S118 -> 0 | U54: =SUM(I54:T54) -> 0 | W54: =U54-F54 -> 0
B55: =B54+1 -> 3 | D55: Distribution Plant: Original Cost | E55: II-B-1 | F55: =F154 -> 5.7414748e+08 | J55: =J154 -> 3.2008999e+08 | K55: =K154 -> 49349633 | L55: =L154 -> 1.5222065e+08 | M55: =M154 -> 2137409 | N55: =N154 -> 44601969 | O55: =O154 -> 1524183.3 | P55: =P154 -> 3318029.9 | Q55: =Q154 -> 319072.77 | ... S55: =S154 -> 410683.95 | U55: =SUM(I55:T55) -> 5.7414748e+08 | W55: =U55-F55 -> 0
...

Sheet II-I-TBILLTDCS
B4: ='WP II-I-1.1'!B3 -> 2022 RATE CASE
B5: ='WP II-I-1.1'!B4 -> ONCOR ELECTRIC DELIVERY COMPANY LLC
B6: ="II-I-1-TBILLTDCS: CLASS REVENUE REQUIREMENT" -> II-I-1-TBILLTDCS: CLASS REVENUE REQUIREMENT
B7: ='WP II-I-1.1'!B6 -> TEST YEAR ENDING 12/31/2021
B8: ='WP II-I-2.2'!$B$7 -> SPONSOR: MATTHEW A. TROXLE
R10: =" "
B11: Line | D11: I-A-1 by Rate Class | E11: Source | F11: TBILLTDCS | J11: Residential | K11: Secondary | L11: Secondary | M11: Primary | N11: Primary | O11: Primary | P11: Transmission | Q11: Lighting | R11: Wholesale | S11: Wholesale | U11: Total
K12: <=10 kW | L12: > 10 kW | M12: <=10 kW | N12: > 10 kW | O12: Substation | R12: XFMR | S12: DLS
F13: (a) | G13: (b) | H13: (c) | J13: (d) | K13: (e) | L13: (f) | M13: (g) | N13: (h) | O13: (i) | P13: (j) | Q13: (k) | R13: (l) | S13: (m) | U13: (n)
B15: =B14+1 -> 1 | D15: O&M Expenses | E15: II-D-2 | F15: =F638+F686 -> 343150.73 | J15: =J638+J686 -> 0 | K15: =K638+K686 -> 0 | L15: =L638+L686 -> 0 | M15: =M638+M686 -> 0 | N15: =N638+N686 -> 0 | O15: =O638+O686 -> 0 | P15: =P638+P686 -> 0 | Q15: =Q638+Q686 -> 343150.73 | ... S15: =S638+S686 -> 0 | U15: =SUM(I15:T15) -> 343150.73 | W15: =F15-U15 -> 0
B16: =B15+1 -> 2 | D16: Customer Expenses | E16: II-D-2 | F16: =F706+F716+F726 -> 13109328 | J16: =J706+J716+J726 -> 7247520.3 | K16: =K706+K716+K726 -> 1019822.5 | L16: =L706+L716+L726 -> 3611980.2 | M16: =M706+M716+M726 -> 42313.5 | N16: =N706+N716+N726 -> 984478.35 | O16: =O706+O716+O726 -> 43110.051 | P16: =P706+P716+P726 -> 113383 | Q16: =Q706+Q716+Q726 -> 35301.089 | ... S16: =S706+S716+S726 -> 7995.7219 | U16: =SUM(I16:T16) -> 13109328 | W16: =F16-U16 -> 0
B17: =B16+1 -> 3 | D17: A&G Expenses | E17: II-D-2 | F17: =F760 -> 36701329 | J17: =J760 -> 19829491 | K17: =K760 -> 2788109 | L17: =L760 -> 9819896.6 | M17: =M760 -> 115387.34 | N17: =N760 -> 2677421.6 | O17: =O760 -> 116847.22 | P17: =P760 -> 306688.91 | Q17: =Q760 -> 1016370.9 | ... S17: =S760 -> 21787.096 | U17: =SUM(I17:T17) -> 36701329 | W17: =F17-U17 -> 0
B18: =B17+1 -> 4 | D18: O&M + Customer + A&G Expenses | F18: =SUM(F15:F17) -> 50153808 | J18: =SUM(J15:J17) -> 27077011 | K18: =SUM(K15:K17) -> 3807931.5 | L18: =SUM(L15:L17) -> 13431877 | M18: =SUM(M15:M17) -> 157700.84 | N18: =SUM(N15:N17) -> 3661900 | O18: =SUM(O15:O17) -> 159957.27 | P18: =SUM(P15:P17) -> 420071.91 | Q18: =SUM(Q15:Q17) -> 1394822.7 | ... S18: =SUM(S15:S17) -> 29782.818 | U18: =SUM(I18:T18) -> 50153808 | V18: ='WP II-I-1.1'!$I$462=U18 -> TRUE | W18: =F18-U18 -> 0
B19: =B18+1 -> 5 | W19: =F19-U19 -> 0
B20: =B19+1 -> 6 | D20: Depreciation & Amortization (II-E-1) | E20: II-E-1 | F20: =F1035 -> 32929277 | J20: =J1035 -> 18347025 | K20: =K1035 -> 2828638.7 | L20: =L1035 -> 8725034 | M20: =M1035 -> 122512.73 | N20: =N1035 -> 2556510.6 | O20: =O1035 -> 87363.65 | P20: =P1035 -> 190183.95 | Q20: =Q1035 -> 38388.521 | ... S20: =S1035 -> 23539.72 | U20: =SUM(I20:T20) -> 32929277 | W20: =F20-U20 -> 0
B21: =B20+1 -> 7 | D21: Other (II-E-4) | E21: II-E-4 | F21: =F1037+F1038 -> 0 | J21: =J1037+J1038 -> 0 | K21: =K1037+K1038 -> 0 | L21: =L1037+L1038 -> 0 | M21: =M1037+M1038 -> 0 | N21: =N1037+N1038 -> 0 | O21: =O1037+O1038 -> 0 | P21: =P1037+P1038 -> 0 | Q21: =Q1037+Q1038 -> 0 | ... S21: =S1037+S1038 -> 0 | U21: =SUM(I21:T21) -> 0 | W21: =F21-U21 -> 0
B22: =B21+1 -> 8 | D22: Depreciation, Amortization & Other Expenses | F22: =SUM(F20:F21) -> 32929277 | J22: =SUM(J20:J21) -> 18347025 | K22: =SUM(K20:K21) -> 2828638.7 | L22: =SUM(L20:L21) -> 8725034 | M22: =SUM(M20:M21) -> 122512.73 | N22: =SUM(N20:N21) -> 2556510.6 | O22: =SUM(O20:O21) -> 87363.65 | P22: =SUM(P20:P21) -> 190183.95 | Q22: =SUM(Q20:Q21) -> 38388.521 | ... S22: =SUM(S20:S21) -> 23539.72 | U22: =SUM(I22:T22) -> 32929277 | V22: ='WP II-I-1.1'!$I$463=U22 -> TRUE | W22: =F22-U22 -> 0
B23: =B22+1 -> 9 | W23: =F23-U23 -> 0
B24: =B23+1 -> 10 | D24: Taxes Other Than Federal Income Tax | E24: II-E-2 | F24: =+F1072 -> 4509539.8 | J24: =+J1072 -> 2510037.6 | K24: =+K1072 -> 386025.82 | L24: =+L1072 -> 1195666.6 | M24: =+M1072 -> 16701.902 | N24: =+N1072 -> 349565.77 | O24: =+O1072 -> 12048.112 | P24: =+P1072 -> 26539.762 | Q24: =+Q1072 -> 8370.8789 | ... S24: =+S1072 -> 3208.5373 | U24: =SUM(I24:T24) -> 4509539.8 | V24: ='WP II-I-1.1'!$I$464=U24 -> TRUE | W24: =F24-U24 -> 0
B25: =B24+1 -> 11 | D25: Federal Income Tax | E25: II-E-3 | F25: =+F1130 -> 2534176.5 | J25: =+J1130 -> 1409750.9 | K25: =+K1130 -> 216638 | L25: =+L1130 -> 673374.07 | M25: =+M1130 -> 9372.8659 | N25: =+N1130 -> 196536.41 | O25: =+O1130 -> 6828.8633 | P25: =+P1130 -> 15562.589 | Q25: =+Q1130 -> 3533.7599 | ... S25: =+S1130 -> 1803.3297 | U25: =SUM(I25:T25) -> 2534176.5 | V25: ='WP II-I-1.1'!$I$465-U25 -> 0 | W25: =F25-U25 -> 0
B26: =B25+1 -> 12 | W26: =F26-U26 -> 0
B27: =B26+1 -> 13 | D27: Return on Rate Base | E27: II-B | F27: =+F83 -> 14457605 | J27: =+J83 -> 8036462.2 | K27: =+K83 -> 1232489.1 | L27: =+L83 -> 3842610.5 | M27: =+M83 -> 53275.908 | N27: =+N83 -> 1119693.2 | O27: =+O83 -> 39139.978 | P27: =+P83 -> 89593.74 | Q27: =+Q83 -> 29686.704 | ... S27: =+S83 -> 10246.36 | U27: =SUM(I27:T27) -> 14457605 | V27: ='WP II-I-1.1'!$I$461=U27 -> TRUE | W27: =F27-U27 -> 0
B28: =B27+1 -> 14 | W28: =F28-U28 -> 0
B29: =B28+1 -> 15 | D29: TOTAL COST OF SERVICE | F29: =+F18+F22+F24+F25+F27 -> 1.0458441e+08 | J29: =+J18+J22+J24+J25+J27 -> 57380287 | K29: =+K18+K22+K24+K25+K27 -> 8471723.2 | L29: =+L18+L22+L24+L25+L27 -> 27868562 | M29: =+M18+M22+M24+M25+M27 -> 359564.24 | N29: =+N18+N22+N24+N25+N27 -> 7884205.9 | O29: =+O18+O22+O24+O25+O27 -> 305337.88 | P29: =+P18+P22+P24+P25+P27 -> 741951.95 | Q29: =+Q18+Q22+Q24+Q25+Q27 -> 1474802.5 | ... S29: =+S18+S22+S24+S25+S27 -> 68580.765 | U29: =SUM(I29:T29) -> 1.0458441e+08 | V29: ='WP II-I-1.1'!$I$476=U29 -> TRUE | W29: =F29-U29 -> 0
B30: =B29+1 -> 16
B31: =B30+1 -> 17 | D31: Minus: Other Revenues | E31: II-E-5 | F31: =+F1186 -> 205014.65 | J31: =+J1186 -> 174312.16 | K31: =+K1186 -> 16286.446 | L31: =+L1186 -> 10891.584 | M31: =+M1186 -> 165.89781 | N31: =+N1186 -> 382.93986 | O31: =+O1186 -> 6.9547614 | P31: =+P1186 -> 15.139981 | Q31: =+Q1186 -> 2953.5267 | ... S31: =+S1186 -> 0 | U31: =SUM(I31:T31) -> 205014.65 | V31: ='WP II-I-1.1'!$I$466=-U31 -> TRUE | W31: =F31-U31 -> 0
B32: =B31+1 -> 18
B33: =B32+1 -> 19 | D33: COST-BASED Revenue Requirement | F33: =+F29-F31 -> 1.0437939e+08 | J33: =+J29-J31 -> 57205975 | K33: =+K29-K31 -> 8455436.7 | L33: =+L29-L31 -> 27857670 | M33: =+M29-M31 -> 359398.35 | N33: =+N29-N31 -> 7883822.9 | O33: =+O29-O31 -> 305330.92 | P33: =+P29-P31 -> 741936.81 | Q33: =+Q29-Q31 -> 1471849 | ... S33: =+S29-S31 -> 68580.765 | U33: =SUM(I33:T33) -> 1.0437939e+08 | V33: ='WP II-I-1.1'!$I$467=U33 -> TRUE | W33: =F33-U33 -> 0
V41: =$H$2 -> 0
B42: =+$B$4 -> 2022 RATE CASE
B43: =+$B$5 -> ONCOR ELECTRIC DELIVERY COMPANY LLC
B44: =+$B$6 -> II-I-1-TBILLTDCS: CLASS REVENUE REQUIREMENT
B45: =+$B$7 -> TEST YEAR ENDING 12/31/2021
B46: =+$B$8 -> SPONSOR: MATTHEW A. TROXLE
R48: =R$10
B49: Line | D49: II-B by Rate Class | E49: Source | F49: =F$11 -> TBILLTDCS | J49: Residential | K49: Secondary | L49: Secondary | M49: Primary | N49: Primary | O49: Primary | P49: Transmission | Q49: Lighting | R49: =R$11 -> Wholesale | S49: =S$11 -> Wholesale | U49: Total
K50: <=10 kW | L50: > 10 kW | M50: <=10 kW | N50: > 10 kW | O50: Substation | R50: =R$12 -> XFMR | S50: =S$12 -> DLS
F51: (a) | G51: (b) | H51: (c) | J51: =J$13 -> (d) | K51: =K$13 -> (e) | L51: =L$13 -> (f) | M51: =M$13 -> (g) | N51: =N$13 -> (h) | O51: =O$13 -> (i) | P51: =P$13 -> (j) | Q51: =Q$13 -> (k) | ... S51: =S$13 -> (m) | U51: (n)
B53: =B52+1 -> 1 | D53: Intangible Plant: Original Cost | E53: II-B-1 | F53: =F106 -> 3.1040917e+08 | J53: =J106 -> 1.7294898e+08 | K53: =K106 -> 26664279 | L53: =L106 -> 82246889 | M53: =M106 -> 1154871.2 | N53: =N106 -> 24099051 | O53: =O106 -> 823537.02 | P53: =P106 -> 1792776.7 | Q53: =Q106 -> 361870.96 | ... S53: =S106 -> 221898.13 | U53: =SUM(I53:T53) -> 3.1040917e+08 | W53: =F53-U53 -> 0
B54: =B53+1 -> 2 | D54: Transmission Plant: Original Cost | E54: II-B-1 | F54: =F118 -> 0 | J54: =J118 -> 0 | K54: =K118 -> 0 | L54: =L118 -> 0 | M54: =M118 -> 0 | N54: =N118 -> 0 | O54: =O118 -> 0 | P54: =P118 -> 0 | Q54: =Q118 -> 0 | ... S54: =S118 -> 0 | U54: =SUM(I54:T54) -> 0 | W54: =F54-U54 -> 0
...

Sheet II-I-Total
B4: ='WP II-I-1.1'!B3 -> 2022 RATE CASE
B5: ='WP II-I-1.1'!B4 -> ONCOR ELECTRIC DELIVERY COMPANY LLC
B6: ="II-I-1-TOT: CLASS REVENUE REQUIREMENT" -> II-I-1-TOT: CLASS REVENUE REQUIREMENT
B7: ='WP II-I-1.1'!B6 -> TEST YEAR ENDING 12/31/2021
B8: ='WP II-I-2.2'!$B$7 -> SPONSOR: MATTHEW A. TROXLE
R10: =" "
B11: Line | D11: I-A-1 by Rate Class | E11: Source | F11: TOTAL | J11: Residential | K11: Secondary | L11: Secondary | M11: Primary | N11: Primary | O11: Primary | P11: Transmission | Q11: Lighting | R11: Wholesale | S11: Wholesale | U11: Total
F12: (Dist+Met+Cust) | K12: <=10 kW | L12: > 10 kW | M12: <=10 kW | N12: > 10 kW | O12: Substation | R12: XFMR | S12: DLS
