Workbook

Sheet Cover
H1: Exhibit R
H2: Page 1 of
H3: Witness: Jim Adkins
A8: BLUE GRASS ENERGY
A9: COOPERATIVE
A11: CASE NO, 2014-00339
A13: COST OF SERVICE STUDY
A30: October 2014 - Mary Elizabeth Purvis & James Adkins

Sheet 1TestYr
D4: TEST YEAR EXPENSES
A5: 1
A6: 2 | G6: Purchased | H6: Total
A7: 3 | B7: Acct | C7: Description | D7: Actual | F7: GTCCs | G7: Power | H7: Amount of | J7: Adjusted
A8: 4 | B8: No. | D8: Test Year | F8: Adjustment | G8: Adjustment | H8: Adjusments | J8: Test Year
A9: 5 | G9: (a)
A10: 6 | B10: 555 | C10: Purchased Power
A11: 7 | C11: Demand Charges | J11: =[1]Sheet1!$E$20 -> 13020019
C12: Metering Point & Substations Charges | J12: =[1]Sheet1!$G$20+[1]Sheet1!$H$20 -> 1321044
A13: 8 | C13: Energy Charges | H13: 0 | J13: =[1]Sheet1!$F$20-[1]Sheet1!$O$20-[1]Sheet1!$R$20 -> 44259636 | M13: 75910446 | N13: =(M13-J13) -> 31650810
A14: 9 | C14: Renewable Resource Energy | H14: 0 | J14: =[1]Sheet1!$O$20 -> 4430
C15: WellHeads | J15: =[1]Sheet1!$R$20 -> 146741.2
A16: 10 | C16: Total Purchased Power | D16: =57651734+8614470+146741.2 -> 66412945 | G16: =(J16-D16) -> -7661075 | H16: 0 | J16: =SUM(J11:J15) -> 58751870 | L16: =SUM(J11:J14) -> 58605129
A17: 11
A18: 12 | B18: 580 | C18: Operations Supv & Eng | D18: =87147.95 -> 87147.95 | J18: =SUM(D18,F18:H18) -> 87147.95
B19: 581 | C19: Load Dispatching | D19: 0 | J19: =SUM(D19,F19:H19) -> 0
A20: 13 | B20: 582 | C20: Station Expense | D20: 24929.3 | J20: =SUM(D20,F20:H20) -> 24929.3
A21: 14 | B21: 583 | C21: Overhead Line Exp. | D21: =1615846.25+171637.1+97902.87+0+0 -> 1885386.2 | J21: =SUM(D21,F21:H21) -> 1885386.2
A22: 15 | B22: 584 | C22: Underground Line Exp | D22: =24039.57+32871.13 -> 56910.7 | J22: =SUM(D22,F22:H22) -> 56910.7
A23: 16 | B23: 585 | C23: Street Lights | D23: 0 | J23: =SUM(D23,F23:H23) -> 0
A24: 17 | B24: 586 | C24: Meter Expense | D24: =832056.07+711787.3+62955.17+0 -> 1606798.5 | J24: =SUM(D24,F24:H24) -> 1606798.5
A25: 18 | B25: 587 | C25: Consumer Installations | D25: 181345.26 | J25: =SUM(D25,F25:H25) -> 181345.26
A26: 19 | B26: 588 | C26: Misc. Distribution Exp | D26: =508362.91+0+283764.37+14620.11+0+0+218806.08+0 -> 1025553.5 | J26: =SUM(D26,F26:H26) -> 1025553.5
A27: 20 | B27: 589 | C27: Rents | D27: 0 | G27: 0 | J27: =SUM(D27,F27:H27) -> 0
A28: 21 | C28: Total Dist. Operations | D28: =SUM(D18:D27) -> 4868071.4 | G28: =SUM(G18:G27) -> 0 | H28: 0 | I28: =SUM(I18:I27) -> 0 | J28: =SUM(D28,F28:H28) -> 4868071.4 | L28: =SUM(J18:J27) -> 4868071.4
A29: 22
A30: 23 | B30: 590 | C30: Maint Supv & Eng | D30: =0 -> 0 | J30: =SUM(D30,F30:H30) -> 0
A31: 24 | B31: 592 | C31: Maint of Station Equip | D31: 0 | J31: =SUM(D31,F31:H31) -> 0
A32: 25 | B32: 593 | C32: Maint. Overhead Lines | D32: =906159.18+1396601.11+6045.96+0+110453.58+0+0+0+200+351683.32+0+122971.15+416120.71+600+0+2340384.82+0+0+9440+0 -> 5660659.8 | H32: 0 | J32: =SUM(D32,F32:H32) -> 5660659.8
A33: 26 | B33: 594 | C33: Maint of Underground Lines | D33: =5730.59+0 -> 5730.59 | J33: =SUM(D33,F33:H33) -> 5730.59
A34: 27 | B34: 595 | C34: Maint Line Transformers | D34: =16590.86 -> 16590.86 | J34: =SUM(D34,F34:H34) -> 16590.86
A35: 28 | B35: 596 | C35: Maint of Street Lights | D35: =23457.92 -> 23457.92 | J35: =SUM(D35,F35:H35) -> 23457.92
A36: 29 | B36: 597 | C36: Maintenance of Meters | D36: =0 -> 0 | J36: =SUM(D36,F36:H36) -> 0
A37: 30 | B37: 598 | C37: Maint Misc Distrib Plant | D37: 245520.58 | J37: =SUM(D37,F37:H37) -> 245520.58
A38: 31 | C38: Total Dist. Maint. | D38: =SUM(D30:D37) -> 5951959.8 | G38: =SUM(G30:G37) -> 0 | H38: 0 | I38: =SUM(I30:I37) -> 0 | J38: =SUM(D38,F38:H38) -> 5951959.8 | L38: =SUM(J30:J37) -> 5951959.8 | M38: =(J38-L38) -> 0
A39: 32 | J39: =SUM(D39,F39:H39) -> 0
A40: 33 | B40: 901 | C40: Supervision | D40: =75527.05 -> 75527.05 | J40: =SUM(D40,F40:H40) -> 75527.05
A41: 34 | B41: 902 | C41: Meter Reading Expense | D41: =37553.07 -> 37553.07 | J41: =SUM(D41,F41:H41) -> 37553.07
A42: 35 | B42: 903 | C42: Cons Recds & Collections | D42: =165933.06+11393.05+407214.84+602586.78+533854.83+5922.44+563.84+54629.61+15795.41+2620.79+8827.92+0+25204.52+330487.73+215950.72+30815.92+699376.25 -> 3111177.7 | J42: =SUM(D42,F42:H42) -> 3111177.7
A43: 36 | B43: 904 | C43: Uncollectible Accounts | D43: =-104074.25 -> -104074.25 | G43: 0 | J43: =SUM(D43,F43:H43) -> -104074.25
...

Sheet 1TestYr_adj
D4: TEST YEAR EXPENSES
G6: Payroll | J6: Retirement | O6: G&T | P6: Purchased | Q6: Total
B7: Acct | C7: Description | D7: Actual | F7: Wages | G7: Taxes | H7: Depreciaton | I7: Interest | J7: & Security | K7: Property | M7: Administrative | N7: Other | O7: Capital Credits | P7: Power | Q7: Amount of | S7: Adjusted
B8: No. | D8: Test Year | F8: Adjustment | G8: Adjustment | H8: Adjustment | I8: Adjustment | J8: Adjustment | K8: Taxes | L8: Donations | M8: & General | N8: Income | O8: Adjustment | P8: Adjustment | Q8: Adjusments | S8: Test Year
P9: (a)
B10: 555 | C10: Purchased Power
C11: Demand Charges | P11: =(T11-U11) -> 51687.096 | Q11: =P11 -> 51687.096 | S11: =(U11+Q11) -> 18577420 | T11: =SUM('Power Cost'!H92:K92) -> 18577420 | U11: 18525733
C12: Metering Point & Substations Charges | P12: =(T12-U12) -> 57024 | Q12: =P12 -> 57024 | S12: =(U12+Q12) -> 1545492 | T12: =('Power Cost'!U90) -> 1545492 | U12: 1488468
C13: Energy Charges | P13: =(T13-U13) -> -269797.22 | Q13: =P13 -> -269797.22 | S13: =(U13+Q13) -> 63975166 | T13: =SUM('Power Cost'!N93)-(T14) -> 63975166 | U13: 64244963 | V13: 75910446 | W13: =(V13-S13) -> 11935280
C14: Renewable Resource Energy | P14: =(T14-U14) -> 0 | Q14: =P14 -> 0 | S14: =(U14+Q14) -> 6455.25 | T14: =('Power Cost'!U91) -> 6455.25 | U14: 6455.25
C15: By Thru and Metering Point Charges | P15: 0 | Q15: =P15 -> 0 | S15: =(U15+Q15) -> 0 | T15: 0 | U15: 0
C16: Total Purchased Power | D16: 96070322 | P16: =(S16-D16) -> -11965789 | Q16: =SUM(F16:P16) -> -11965789 | S16: =SUM(S11:S15) -> 84104533 | T16: =SUM(T11:T15) -> 84104533 | U16: =SUM(U11:U15) -> 84265620
B18: 580 | C18: Operations Supv & Eng | D18: 234904.52 | F18: ='1.1TYAdj.'!U4 -> 941.74454 | G18: ='1.1TYAdj.'!V4 -> 165.76384 | J18: ='1.1TYAdj.'!X4 -> 751.53893 | Q18: =SUM(F18:P18) -> 1859.0473 | S18: =SUM(D18,F18:P18) -> 236763.57
B19: 581 | C19: Load Dispatching | D19: 0 | Q19: =SUM(F19:P19) -> 0 | S19: =SUM(D19,F19:P19) -> 0 | U19: =SUM(Q11:Q15) -> -161086.12
B20: 582 | C20: Station Expense | D20: 50572.11 | F20: ='1.1TYAdj.'!U5 -> 202.74624 | G20: ='1.1TYAdj.'!V5 -> 35.686955 | J20: ='1.1TYAdj.'!X5 -> 161.79727 | Q20: =SUM(F20:P20) -> 400.23046 | S20: =SUM(D20,F20:P20) -> 50972.34
B21: 583 | C21: Overhead Line Exp. | D21: 1260597.8 | F21: ='1.1TYAdj.'!U6 -> 5053.8028 | G21: ='1.1TYAdj.'!V6 -> 889.55943 | J21: ='1.1TYAdj.'!X6 -> 4033.0783 | Q21: =SUM(F21:P21) -> 9976.4405 | S21: =SUM(D21,F21:P21) -> 1270574.3
B22: 584 | C22: Underground Line Exp | D22: 120534.27 | F22: ='1.1TYAdj.'!U7 -> 483.22821 | G22: ='1.1TYAdj.'!V7 -> 85.056785 | J22: ='1.1TYAdj.'!X7 -> 385.62986 | Q22: =SUM(F22:P22) -> 953.91485 | S22: =SUM(D22,F22:P22) -> 121488.18
B23: 585 | C23: Street Lights | D23: 26089.27 | F23: ='1.1TYAdj.'!U8 -> 104.59325 | G23: ='1.1TYAdj.'!V8 -> 18.410278 | J23: ='1.1TYAdj.'!X8 -> 83.46839 | Q23: =SUM(F23:P23) -> 206.47192 | S23: =SUM(D23,F23:P23) -> 26295.742
B24: 586 | C24: Meter Expense | D24: 517709.94 | F24: ='1.1TYAdj.'!U9 -> 2075.5263 | G24: ='1.1TYAdj.'!V9 -> 365.32965 | J24: ='1.1TYAdj.'!X9 -> 1656.329 | Q24: =SUM(F24:P24) -> 4097.185 | S24: =SUM(D24,F24:P24) -> 521807.12
B25: 587 | C25: Consumer Installations | D25: 305880.98 | F25: ='1.1TYAdj.'!U10 -> 1226.2929 | G25: ='1.1TYAdj.'!V10 -> 215.84942 | J25: ='1.1TYAdj.'!X10 -> 978.61661 | Q25: =SUM(F25:P25) -> 2420.7589 | S25: =SUM(D25,F25:P25) -> 308301.74
B26: 588 | C26: Misc. Distribution Exp | D26: 181456.8 | F26: ='1.1TYAdj.'!U11 -> 727.46983 | G26: ='1.1TYAdj.'!V11 -> 128.04767 | H26: =[3]adjustments!$F$21 -> 846.49746 | J26: ='1.1TYAdj.'!X11 -> 580.54161 | K26: =[3]adjustments!$I$21 -> 16382.168 | Q26: =SUM(F26:P26) -> 18664.725 | S26: =SUM(D26,F26:P26) -> 200121.52
B27: 589 | C27: Rents | D27: 0 | P27: 0 | S27: =SUM(D27,F27:P27) -> 0
C28: Total Dist. Operations | D28: =SUM(D18:D27) -> 2697745.7 | F28: =SUM(F18:F27) -> 10815.404 | G28: =SUM(G18:G27) -> 1903.704 | H28: =SUM(H18:H27) -> 846.49746 | I28: =SUM(I18:I27) -> 0 | J28: =SUM(J18:J27) -> 8631 | K28: =SUM(K18:K27) -> 16382.168 | P28: =SUM(P18:P27) -> 0 | Q28: =SUM(F28:P28) -> 38578.774 | R28: =SUM(R18:R27) -> 0 | S28: =SUM(D28,F28:P28) -> 2736324.5 | U28: =SUM(S18:S27) -> 2736324.5
B30: 590 | C30: Maint Supv & Eng | D30: =24036.59+280697.28 -> 304733.87 | F30: ='1.1TYAdj.'!U15 -> 1738.44 | G30: ='1.1TYAdj.'!V15 -> 305.99645 | J30: ='1.1TYAdj.'!X15 -> 1387.2974 | Q30: =SUM(F30:P30) -> 3431.7339 | S30: =SUM(D30,F30:P30) -> 308165.6
B31: 592 | C31: Maint of Station Equip | D31: 149.99 | F31: ='1.1TYAdj.'!U16 -> 0.85566012 | G31: ='1.1TYAdj.'!V16 -> 0.15061144 | J31: ='1.1TYAdj.'!X16 -> 0.68282775 | Q31: =SUM(F31:P31) -> 1.6890993 | S31: =SUM(D31,F31:P31) -> 151.6791
B32: 593 | C32: Maint. Overhead Lines | D32: =1416756.57+2823570.35+572737.64+0 -> 4813064.6 | F32: ='1.1TYAdj.'!U17 -> 27457.48 | G32: ='1.1TYAdj.'!V17 -> 4833.0062 | J32: ='1.1TYAdj.'!X17 -> 21911.421 | Q32: =SUM(F32:P32) -> 54201.907 | S32: =SUM(D32,F32:P32) -> 4867266.5
B33: 594 | C33: Maint of Underground Lines | D33: =284957.92+17476.89 -> 302434.81 | F33: ='1.1TYAdj.'!U18 -> 1725.3244 | G33: ='1.1TYAdj.'!V18 -> 303.68787 | J33: ='1.1TYAdj.'!X18 -> 1376.831 | Q33: =SUM(F33:P33) -> 3405.8433 | S33: =SUM(D33,F33:P33) -> 305840.65
B34: 595 | C34: Maint Line Transformers | D34: =16801.08 -> 16801.08 | F34: ='1.1TYAdj.'!U19 -> 95.846484 | G34: ='1.1TYAdj.'!V19 -> 16.870691 | J34: ='1.1TYAdj.'!X19 -> 76.486724 | Q34: =SUM(F34:P34) -> 189.2039 | S34: =SUM(D34,F34:P34) -> 16990.284
B35: 596 | C35: Maint of Street Lights | D35: =195353.39 -> 195353.39 | F35: ='1.1TYAdj.'!U20 -> 1114.4483 | G35: ='1.1TYAdj.'!V20 -> 196.16278 | J35: ='1.1TYAdj.'!X20 -> 889.34407 | Q35: =SUM(F35:P35) -> 2199.9552 | S35: =SUM(D35,F35:P35) -> 197553.35
B36: 597 | C36: Maintenance of Meters | D36: =193445.15 -> 193445.15 | F36: ='1.1TYAdj.'!U21 -> 1103.5622 | G36: ='1.1TYAdj.'!V21 -> 194.24664 | J36: ='1.1TYAdj.'!X21 -> 880.65683 | Q36: =SUM(F36:P36) -> 2178.4657 | S36: =SUM(D36,F36:P36) -> 195623.62
B37: 598 | C37: Maint Misc Distrib Plant | D37: 349101.35 | F37: ='1.1TYAdj.'!U22 -> 1991.5468 | G37: ='1.1TYAdj.'!V22 -> 350.54776 | H37: =[3]adjustments!$F$22 -> 1513.4122 | J37: ='1.1TYAdj.'!X22 -> 1589.2799 | Q37: =SUM(F37:P37) -> 5444.7867 | S37: =SUM(D37,F37:P37) -> 354546.14
C38: Total Dist. Maint. | D38: =SUM(D30:D37) -> 6175084.2 | F38: =SUM(F30:F37) -> 35227.504 | G38: =SUM(G30:G37) -> 6200.669 | H38: =SUM(H30:H37) -> 1513.4122 | I38: =SUM(I30:I37) -> 0 | J38: =SUM(J30:J37) -> 28112 | P38: =SUM(P30:P37) -> 0 | Q38: =SUM(E38:P38) -> 71053.585 | R38: =SUM(R30:R37) -> 0 | S38: =SUM(D38,F38:P38) -> 6246137.8 | U38: =SUM(S30:S37) -> 6246137.8 | V38: =(S38-U38) -> 0
S39: =SUM(D39,F39:Q39) -> 0
B40: 901 | C40: Supervision | D40: 140605.04 | F40: ='1.1TYAdj.'!U26 -> 1185.2476 | G40: ='1.1TYAdj.'!V26 -> 208.62472 | H40: =[3]adjustments!$F$23 -> 388.88015 | J40: ='1.1TYAdj.'!X26 -> 945.86103 | Q40: =SUM(F40:P40) -> 2728.6135 | S40: =SUM(D40,F40:P40) -> 143333.65
B41: 902 | C41: Meter Reading Expense | D41: 100208.98 | F41: ='1.1TYAdj.'!U27 -> 844.72401 | G41: ='1.1TYAdj.'!V27 -> 148.68649 | J41: ='1.1TYAdj.'!X27 -> 674.1136 | Q41: =SUM(F41:P41) -> 1667.5241 | S41: =SUM(D41,F41:P41) -> 101876.5
B42: 903 | C42: Cons Recds & Collections | D42: =2281600.99+225.68 -> 2281826.7 | F42: ='1.1TYAdj.'!U28 -> 19234.941 | G42: ='1.1TYAdj.'!V28 -> 3385.6926 | J42: ='1.1TYAdj.'!X28 -> 15350.025 | Q42: =SUM(F42:P42) -> 37970.659 | S42: =SUM(D42,F42:P42) -> 2319797.3
B43: 904 | C43: Uncollectible Accounts | D43: 340357.45 | P43: 0 | Q43: =SUM(F43:P43) -> 0 | S43: =SUM(D43,F43:P43) -> 340357.45
C44: Total Consumer Accts | D44: =SUM(D40:D43) -> 2862998.1 | F44: =SUM(F40:F43) -> 21264.912 | G44: =SUM(G40:G43) -> 3743.0038 | H44: =SUM(H40:H43) -> 388.88015 | J44: =SUM(J40:J43) -> 16970 | K44: =SUM(K40:K43) -> 0 | P44: =SUM(P40:P43) -> 0 | Q44: =SUM(F44:P44) -> 42366.796 | R44: =SUM(R40:R43) -> 0 | S44: =SUM(D44,F44:P44) -> 2905364.9 | U44: =SUM(S40:S43) -> 2905364.9
B46: 907 | C46: Customer Information | D46: 0 | F46: ='1.1TYAdj.'!U32 -> 0 | G46: ='1.1TYAdj.'!V32 -> 0 | J46: ='1.1TYAdj.'!X32 -> 0 | Q46: =SUM(F46:P46) -> 0 | S46: =SUM(D46,F46:P46) -> 0
B47: 908 | C47: Customer Accounting | D47: 944348.21 | F47: ='1.1TYAdj.'!U33 -> 16145.418 | G47: ='1.1TYAdj.'!V33 -> 2841.8816 | J47: ='1.1TYAdj.'!X33 -> 12883.853 | Q47: =SUM(F47:P47) -> 31871.152 | S47: =SUM(D47,F47:P47) -> 976219.36
...

Sheet 1.1TYAdj.
U1: Wages & | V1: Payroll | W1: FAS | Y1: Health
E2: Wages & | F2: Payroll | G2: FAS | I2: Health | U2: Salaries | V2: Tax | W2: 106 | X2: Retirement | Y2: Insurance
E3: Salaries | F3: Tax | G3: 106 | H3: Retirement | I3: Insurance | S3: Amount | T3: Percent | U3: Adj. | V3: Adj. | W3: Adj. | X3: Adj. | Y3: Adj. | AA3: Total
C4: Amount | D4: Percent | E4: Adj. | F4: Adj. | G4: Adj. | H4: Adj. | I4: Adj. | K4: Total | Q4: 580 | R4: Supervision, operations | S4: =C5 -> 234904.52 | T4: =S4/$S$12 -> 0.087074375 | U4: =T4*$U$13 -> 941.74454 | V4: =$V$13*T4 -> 165.76384 | W4: =T4*$W$13 -> 0 | X4: =T4*$X$13 -> 751.53893 | Y4: =T4*$Y$13 -> 0 | AA4: =SUM(U4:Y4) -> 1859.0473
A5: 580 | B5: Supervision, operations | C5: ='1TestYr_adj'!D18 -> 234904.52 | D5: =C5/$C$34 -> 0.014485453 | E5: =(D5*$E$34) -> 1873.0238 | F5: =(D5*$F$34) -> 329.6856 | G5: =(D5*$G$34) -> 0 | H5: =(D5*$H$34) -> 1494.696 | I5: =(D5*$I$34) -> 0 | K5: =SUM(E5:I5) -> 3697.4054 | Q5: 582 | R5: Station | S5: =C6 -> 50572.11 | T5: =S5/$S$12 -> 0.018746063 | U5: =T5*$U$13 -> 202.74624 | V5: =$V$13*T5 -> 35.686955 | W5: =T5*$W$13 -> 0 | X5: =T5*$X$13 -> 161.79727 | Y5: =T5*$Y$13 -> 0 | AA5: =SUM(U5:Y5) -> 400.23046
A6: 582 | B6: Station | C6: ='1TestYr_adj'!D20 -> 50572.11 | D6: =C6/$C$34 -> 0.0031185434 | E6: =(D6*$E$34) -> 403.23944 | F6: =(D6*$F$34) -> 70.977334 | G6: =(D6*$G$34) -> 0 | H6: =(D6*$H$34) -> 321.79002 | I6: =(D6*$I$34) -> 0 | K6: =SUM(E6:I6) -> 796.00679 | Q6: 583 | R6: Overhead line | S6: =C7 -> 1260597.8 | T6: =S6/$S$12 -> 0.46727822 | U6: =T6*$U$13 -> 5053.8028 | V6: =$V$13*T6 -> 889.55943 | W6: =T6*$W$13 -> 0 | X6: =T6*$X$13 -> 4033.0783 | Y6: =T6*$Y$13 -> 0 | AA6: =SUM(U6:Y6) -> 9976.4405
A7: 583 | B7: Overhead line | C7: ='1TestYr_adj'!D21 -> 1260597.8 | D7: =C7/$C$34 -> 0.077735118 | E7: =(D7*$E$34) -> 10051.444 | F7: =(D7*$F$34) -> 1769.2335 | G7: =(D7*$G$34) -> 0 | H7: =(D7*$H$34) -> 8021.1759 | I7: =(D7*$I$34) -> 0 | K7: =SUM(E7:I7) -> 19841.854 | Q7: 584 | R7: Underground Lines | S7: =C8 -> 120534.27 | T7: =S7/$S$12 -> 0.044679626 | U7: =T7*$U$13 -> 483.22821 | V7: =$V$13*T7 -> 85.056785 | W7: =T7*$W$13 -> 0 | X7: =T7*$X$13 -> 385.62986 | Y7: =T7*$Y$13 -> 0 | AA7: =SUM(U7:Y7) -> 953.91485
A8: 584 | B8: Undergound Lines | C8: ='1TestYr_adj'!D22 -> 120534.27 | D8: =C8/$C$34 -> 0.0074327796 | E8: =(D8*$E$34) -> 961.08649 | F8: =(D8*$F$34) -> 169.16837 | G8: =(D8*$G$34) -> 0 | H8: =(D8*$H$34) -> 766.9588 | I8: =(D8*$I$34) -> 0 | K8: =SUM(E8:I8) -> 1897.2137 | Q8: 585 | R8: Street Light Expense | S8: =C9 -> 26089.27 | T8: =S8/$S$12 -> 0.009670767 | U8: =T8*$U$13 -> 104.59325 | V8: =$V$13*T8 -> 18.410278 | W8: =T8*$W$13 -> 0 | X8: =T8*$X$13 -> 83.46839 | Y8: =T8*$Y$13 -> 0 | AA8: =SUM(U8:Y8) -> 206.47192
A9: 585 | B9: Street Lighting | C9: ='1TestYr_adj'!D23 -> 26089.27 | D9: =C9/$C$34 -> 0.0016088022 | E9: =(D9*$E$34) -> 208.0242 | F9: =(D9*$F$34) -> 36.615969 | G9: =(D9*$G$34) -> 0 | H9: =(D9*$H$34) -> 166.00586 | I9: =(D9*$I$34) -> 0 | K9: =SUM(E9:I9) -> 410.64603 | Q9: 586 | R9: Meter | S9: =C10 -> 517709.94 | T9: =S9/$S$12 -> 0.19190465 | U9: =T9*$U$13 -> 2075.5263 | V9: =$V$13*T9 -> 365.32965 | W9: =T9*$W$13 -> 0 | X9: =T9*$X$13 -> 1656.329 | Y9: =T9*$Y$13 -> 0 | AA9: =SUM(U9:Y9) -> 4097.185
A10: 586 | B10: Meter | C10: ='1TestYr_adj'!D24 -> 517709.94 | D10: =C10/$C$34 -> 0.031924729 | E10: =(D10*$E$34) -> 4127.9881 | F10: =(D10*$F$34) -> 726.59953 | G10: =(D10*$G$34) -> 0 | H10: =(D10*$H$34) -> 3294.1851 | I10: =(D10*$I$34) -> 0 | K10: =SUM(E10:I10) -> 8148.7727 | Q10: 587 | R10: Installations | S10: =C11 -> 305880.98 | T10: =S10/$S$12 -> 0.11338392 | U10: =T10*$U$13 -> 1226.2929 | V10: =$V$13*T10 -> 215.84942 | W10: =T10*$W$13 -> 0 | X10: =T10*$X$13 -> 978.61661 | Y10: =T10*$Y$13 -> 0 | AA10: =SUM(U10:Y10) -> 2420.7589
A11: 587 | B11: Installations | C11: ='1TestYr_adj'!D25 -> 305880.98 | D11: =C11/$C$34 -> 0.018862237 | E11: =(D11*$E$34) -> 2438.9585 | F11: =(D11*$F$34) -> 429.30019 | G11: =(D11*$G$34) -> 0 | H11: =(D11*$H$34) -> 1946.3187 | I11: =(D11*$I$34) -> 0 | K11: =SUM(E11:I11) -> 4814.5774 | Q11: 588 | R11: Miscellaneous distribution | S11: =C12 -> 181456.8 | T11: =S11/$S$12 -> 0.067262381 | U11: =T11*$U$13 -> 727.46983 | V11: =$V$13*T11 -> 128.04767 | W11: =T11*$W$13 -> 0 | X11: =T11*$X$13 -> 580.54161 | Y11: =T11*$Y$13 -> 0 | AA11: =SUM(U11:Y11) -> 1436.0591
A12: 588 | B12: Miscellaneous distribution | C12: ='1TestYr_adj'!D26 -> 181456.8 | D12: =C12/$C$34 -> 0.011189585 | E12: =(D12*$E$34) -> 1446.8556 | F12: =(D12*$F$34) -> 254.67239 | G12: =(D12*$G$34) -> 0 | H12: =(D12*$H$34) -> 1154.6085 | I12: =(D12*$I$34) -> 0 | K12: =SUM(E12:I12) -> 2856.1364 | S12: =SUM(S4:S11) -> 2697745.7 | T12: =SUM(T4:T11) -> 1 | U12: =SUM(U4:U11) -> 10815.404 | V12: =SUM(V4:V11) -> 1903.704 | W12: =SUM(W4:W11) -> 0 | X12: =SUM(X4:X11) -> 8631 | Y12: =SUM(Y4:Y11) -> 0 | AA12: =SUM(U12:Y12) -> 21350.108
A13: 590 | B13: Supervision, maintenance | C13: ='1TestYr_adj'!D30 -> 304733.87 | D13: =C13/$C$34 -> 0.0187915 | E13: =(D13*$E$34) -> 2429.8119 | F13: =(D13*$F$34) -> 427.69024 | G13: =(D13*$G$34) -> 0 | H13: =(D13*$H$34) -> 1939.0197 | I13: =(D13*$I$34) -> 0 | K13: =SUM(E13:I13) -> 4796.5218 | U13: =[3]adjustments!$D$21 -> 10815.404 | V13: =[3]adjustments!$E$21 -> 1903.704 | W13: 0 | X13: =[3]adjustments!$H$21 -> 8631 | Y13: 0 | AA13: =SUM(AA4:AA11) -> 21350.108
A14: 592 | B14: Maintenance Station Equip | C14: ='1TestYr_adj'!D31 -> 149.99 | D14: =C14/$C$34 -> 9.2491755e-06 | E14: =(D14*$E$34) -> 1.1959533 | F14: =(D14*$F$34) -> 0.21050912 | G14: =(D14*$G$34) -> 0 | H14: =(D14*$H$34) -> 0.95438543 | I14: =(D14*$I$34) -> 0 | K14: =SUM(E14:I14) -> 2.3608479
A15: 593 | B15: Maintenance | C15: ='1TestYr_adj'!D32 -> 4813064.6 | D15: =C15/$C$34 -> 0.29679898 | E15: =(D15*$E$34) -> 38377.229 | F15: =(D15*$F$34) -> 6755.0769 | G15: =(D15*$G$34) -> 0 | H15: =(D15*$H$34) -> 30625.499 | I15: =(D15*$I$34) -> 0 | K15: =SUM(E15:I15) -> 75757.806 | Q15: 590 | R15: Supervision, maintenance | S15: =C13 -> 304733.87 | T15: =S15/$S$23 -> 0.049348942 | U15: =T15*$U$24 -> 1738.44 | V15: =T15*$V$24 -> 305.99645 | W15: =T15*$W$24 -> 0 | X15: =T15*$X$24 -> 1387.2974 | Y15: =T15*$Y$24 -> 0 | AA15: =SUM(U15:Y15) -> 3431.7339
A16: 594 | B16: Underground | C16: ='1TestYr_adj'!D33 -> 302434.81 | D16: =C16/$C$34 -> 0.018649728 | E16: =(D16*$E$34) -> 2411.4802 | F16: =(D16*$F$34) -> 424.46354 | G16: =(D16*$G$34) -> 0 | H16: =(D16*$H$34) -> 1924.3908 | I16: =(D16*$I$34) -> 0 | K16: =SUM(E16:I16) -> 4760.3346 | Q16: 592 | R16: Maintenance Station Equip | S16: =C14 -> 149.99 | T16: =S16/$S$23 -> 2.4289547e-05 | U16: =T16*$U$24 -> 0.85566012 | V16: =T16*$V$24 -> 0.15061144 | W16: =T16*$W$24 -> 0 | X16: =T16*$X$24 -> 0.68282775 | Y16: =T16*$Y$24 -> 0
A17: 595 | B17: Transformers | C17: ='1TestYr_adj'!D34 -> 16801.08 | D17: =C17/$C$34 -> 0.0010360433 | E17: =(D17*$E$34) -> 133.96432 | F17: =(D17*$F$34) -> 23.580109 | G17: =(D17*$G$34) -> 0 | H17: =(D17*$H$34) -> 106.90517 | I17: =(D17*$I$34) -> 0 | K17: =SUM(E17:I17) -> 264.44959 | Q17: 593 | R17: Maintenance | S17: =C15 -> 4813064.6 | T17: =S17/$S$23 -> 0.77943303 | U17: =T17*$U$24 -> 27457.48 | V17: =T17*$V$24 -> 4833.0062 | W17: =T17*$W$24 -> 0 | X17: =T17*$X$24 -> 21911.421 | Y17: =T17*$Y$24 -> 0 | AA17: =SUM(U17:Y17) -> 54201.907
A18: 596 | B18: Street lights | C18: ='1TestYr_adj'!D35 -> 195353.39 | D18: =C18/$C$34 -> 0.012046522 | E18: =(D18*$E$34) -> 1557.6608 | F18: =(D18*$F$34) -> 274.17608 | G18: =(D18*$G$34) -> 0 | H18: =(D18*$H$34) -> 1243.0324 | I18: =(D18*$I$34) -> 0 | K18: =SUM(E18:I18) -> 3074.8692 | Q18: 594 | R18: Underground | S18: =C16 -> 302434.81 | T18: =S18/$S$23 -> 0.048976629 | U18: =T18*$U$24 -> 1725.3244 | V18: =T18*$V$24 -> 303.68787 | W18: =T18*$W$24 -> 0 | X18: =T18*$X$24 -> 1376.831 | Y18: =T18*$Y$24 -> 0 | AA18: =SUM(U18:Y18) -> 3405.8433
A19: 597 | B19: Meters | C19: ='1TestYr_adj'!D36 -> 193445.15 | D19: =C19/$C$34 -> 0.01192885 | E19: =(D19*$E$34) -> 1542.4453 | F19: =(D19*$F$34) -> 271.49789 | G19: =(D19*$G$34) -> 0 | H19: =(D19*$H$34) -> 1230.8903 | I19: =(D19*$I$34) -> 0 | K19: =SUM(E19:I19) -> 3044.8335 | Q19: 595 | R19: Transformers | S19: =C17 -> 16801.08 | T19: =S19/$S$23 -> 0.0027207856 | U19: =T19*$U$24 -> 95.846484 | V19: =T19*$V$24 -> 16.870691 | W19: =T19*$W$24 -> 0 | X19: =T19*$X$24 -> 76.486724 | Y19: =T19*$Y$24 -> 0 | AA19: =SUM(U19:Y19) -> 189.2039
A20: 598 | B20: Miscellaneous maintenance | C20: ='1TestYr_adj'!D37 -> 349101.35 | D20: =C20/$C$34 -> 0.021527433 | E20: =(D20*$E$34) -> 2783.5784 | F20: =(D20*$F$34) -> 489.95945 | G20: =(D20*$G$34) -> 0 | H20: =(D20*$H$34) -> 2221.3297 | I20: =(D20*$I$34) -> 0 | K20: =SUM(E20:I20) -> 5494.8675 | Q20: 596 | R20: Street lights | S20: =C18 -> 195353.39 | T20: =S20/$S$23 -> 0.031635745 | U20: =T20*$U$24 -> 1114.4483 | V20: =T20*$V$24 -> 196.16278 | W20: =T20*$W$24 -> 0 | X20: =T20*$X$24 -> 889.34407 | Y20: =T20*$Y$24 -> 0 | AA20: =SUM(U20:Y20) -> 2199.9552
A21: 901 | B21: Supervision | C21: ='1TestYr_adj'!D40 -> 140605.04 | D21: =C21/$C$34 -> 0.0086704493 | E21: =(D21*$E$34) -> 1121.1219 | F21: =(D21*$F$34) -> 197.33744 | G21: =(D21*$G$34) -> 0 | H21: =(D21*$H$34) -> 894.66898 | I21: =(D21*$I$34) -> 0 | K21: =SUM(E21:I21) -> 2213.1283 | Q21: 597 | R21: Meters | S21: =C19 -> 193445.15 | T21: =S21/$S$23 -> 0.031326723 | U21: =T21*$U$24 -> 1103.5622 | V21: =T21*$V$24 -> 194.24664 | W21: =T21*$W$24 -> 0 | X21: =T21*$X$24 -> 880.65683 | Y21: =T21*$Y$24 -> 0 | AA21: =SUM(U21:Y21) -> 2178.4657
A22: 902 | B22: Meter reading | C22: ='1TestYr_adj'!D41 -> 100208.98 | D22: =C22/$C$34 -> 0.0061794149 | E22: =(D22*$E$34) -> 799.0217 | F22: =(D22*$F$34) -> 140.64207 | G22: =(D22*$G$34) -> 0 | H22: =(D22*$H$34) -> 637.62911 | I22: =(D22*$I$34) -> 0 | K22: =SUM(E22:I22) -> 1577.2929 | Q22: 598 | R22: Miscellaneous maintenance | S22: =C20 -> 349101.35 | T22: =S22/$S$23 -> 0.056533861 | U22: =T22*$U$24 -> 1991.5468 | V22: =T22*$V$24 -> 350.54776 | W22: =T22*$W$24 -> 0 | X22: =T22*$X$24 -> 1589.2799 | Y22: =T22*$Y$24 -> 0 | AA22: =SUM(U22:Y22) -> 3931.3744
A23: 903 | B23: Consumer records | C23: ='1TestYr_adj'!D42 -> 2281826.7 | D23: =C23/$C$34 -> 0.14070948 | E23: =(D23*$E$34) -> 18194.268 | F23: =(D23*$F$34) -> 3202.5157 | G23: =(D23*$G$34) -> 0 | H23: =(D23*$H$34) -> 14519.249 | I23: =(D23*$I$34) -> 0 | K23: =SUM(E23:I23) -> 35916.032 | S23: =SUM(S15:S22) -> 6175084.2 | T23: =SUM(T15:T22) -> 1 | U23: =SUM(U15:U22) -> 35227.504 | V23: =SUM(V15:V22) -> 6200.669 | W23: =SUM(W15:W22) -> 0 | X23: =SUM(X15:X22) -> 28112 | Y23: =SUM(Y15:Y22) -> 0 | AA23: =SUM(U23:Y23) -> 69540.173
A24: 907 | B24: Supervision, Customer service | C24: ='1TestYr_adj'!D46 -> 0 | D24: =C24/$C$34 -> 0 | E24: =(D24*$E$34) -> 0 | F24: =(D24*$F$34) -> 0 | G24: =(D24*$G$34) -> 0 | H24: =(D24*$H$34) -> 0 | I24: =(D24*$I$34) -> 0 | K24: =SUM(E24:I24) -> 0 | U24: =[3]adjustments!$D$22 -> 35227.504 | V24: =[3]adjustments!$E$22 -> 6200.669 | W24: 0 | X24: =[3]adjustments!$H$22 -> 28112 | Y24: 0
A25: 908 | B25: Consumer accounting | C25: ='1TestYr_adj'!D47 -> 944348.21 | D25: =C25/$C$34 -> 0.058233498 | E25: =(D25*$E$34) -> 7529.8113 | F25: =(D25*$F$34) -> 1325.3811 | G25: =(D25*$G$34) -> 0 | H25: =(D25*$H$34) -> 6008.8817 | I25: =(D25*$I$34) -> 0 | K25: =SUM(E25:I25) -> 14864.074
A26: 909 | B26: Consumer information | C26: ='1TestYr_adj'!D48 -> 0 | D26: =C26/$C$34 -> 0 | E26: =(D26*$E$34) -> 0 | F26: =(D26*$F$34) -> 0 | G26: =(D26*$G$34) -> 0 | H26: =(D26*$H$34) -> 0 | I26: =(D26*$I$34) -> 0 | K26: =SUM(E26:I26) -> 0 | Q26: 901 | R26: Supervision | S26: =C21 -> 140605.04 | T26: =S26/$S$29 -> 0.055737244 | U26: =T26*$U$30 -> 1185.2476 | V26: =T26*$V$30 -> 208.62472 | W26: =T26*$W$30 -> 0 | X26: =T26*$X$30 -> 945.86103 | Y26: =T26*$Y$30 -> 0 | AA26: =SUM(U26:Y26) -> 2339.7334
A27: 910 | B27: Misc customer information | C27: ='1TestYr_adj'!D49 -> 0 | D27: =C27/$C$34 -> 0 | E27: =(D27*$E$34) -> 0 | F27: =(D27*$F$34) -> 0 | G27: =(D27*$G$34) -> 0 | H27: =(D27*$H$34) -> 0 | I27: =(D27*$I$34) -> 0 | K27: =SUM(E27:I27) -> 0 | Q27: 902 | R27: Meter reading | S27: =C22 -> 100208.98 | T27: =S27/$S$29 -> 0.039723842 | U27: =T27*$U$30 -> 844.72401 | V27: =T27*$V$30 -> 148.68649 | W27: =T27*$W$30 -> 0 | X27: =T27*$X$30 -> 674.1136 | Y27: =T27*$Y$30 -> 0 | AA27: =SUM(U27:Y27) -> 1667.5241
A28: 912 | B28: Key Accounts Expenses | C28: ='1TestYr_adj'!D50 -> -11863.33 | D28: =C28/$C$34 -> -0.00073155558 | E28: =(D28*$E$34) -> -94.5929 | F28: =(D28*$F$34) -> -16.650038 | G28: =(D28*$G$34) -> 0 | H28: =(D28*$H$34) -> -75.486294 | I28: =(D28*$I$34) -> 0 | K28: =SUM(E28:I28) -> -186.72923 | Q28: 903 | R28: Consumer records | S28: =C23 -> 2281826.7 | T28: =S28/$S$29 -> 0.90453891 | U28: =T28*$U$30 -> 19234.941 | V28: =T28*$V$30 -> 3385.6926 | W28: =T28*$W$30 -> 0 | X28: =T28*$X$30 -> 15350.025 | Y28: =T28*$Y$30 -> 0 | AA28: =SUM(U28:Y28) -> 37970.659
A29: 920 | B29: Administrative | C29: ='1TestYr_adj'!D54 -> 2590524.3 | D29: =C29/$C$34 -> 0.15974541 | E29: =(D29*$E$34) -> 20655.685 | F29: =(D29*$F$34) -> 3635.769 | G29: =(D29*$G$34) -> 0 | H29: =(D29*$H$34) -> 16483.49 | I29: =(D29*$I$34) -> 0 | K29: =SUM(E29:I29) -> 40774.944 | S29: =SUM(S26:S28) -> 2522640.7 | T29: =SUM(T26:T28) -> 1 | U29: =SUM(U26:U28) -> 21264.912 | V29: =SUM(V26:V28) -> 3743.0038 | W29: =SUM(W26:W28) -> 0 | X29: =SUM(X26:X28) -> 16970 | Y29: =SUM(Y26:Y28) -> 0 | AA29: =SUM(U29:Y29) -> 41977.916
A30: 926 | B30: Emp Pensions & Benefits | C30: ='1TestYr_adj'!D59 -> 0 | D30: =C30/$C$34 -> 0 | E30: =(D30*$E$34) -> 0 | F30: =(D30*$F$34) -> 0 | G30: =(D30*$G$34) -> 0 | H30: =(D30*$H$34) -> 0 | I30: =(D30*$I$34) -> 0 | K30: =SUM(E30:I30) -> 0 | U30: =[3]adjustments!$D$23 -> 21264.912 | V30: =[3]adjustments!$E$23 -> 3743.0038 | W30: 0 | X30: =[3]adjustments!$H$23 -> 16970 | Y30: 0
A31: 930 | B31: Miscellaneous | C31: ='1TestYr_adj'!D62 -> 889238.28 | D31: =C31/$C$34 -> 0.054835129 | E31: =(D31*$E$34) -> 7090.3893 | F31: =(D31*$F$34) -> 1248.035 | G31: =(D31*$G$34) -> 0 | H31: =(D31*$H$34) -> 5658.2176 | I31: =(D31*$I$34) -> 0 | K31: =SUM(E31:I31) -> 13996.642
A32: 935 | B32: Maintenance general plant | C32: ='1TestYr_adj'!D64 -> 408862.49 | D32: =C32/$C$34 -> 0.02521262 | E32: =(D32*$E$34) -> 3260.0871 | F32: =(D32*$F$34) -> 573.83347 | G32: =(D32*$G$34) -> 0 | H32: =(D32*$H$34) -> 2601.5894 | I32: =(D32*$I$34) -> 0 | K32: =SUM(E32:I32) -> 6435.51 | Q32: 907 | R32: Supervision, Customer service | S32: =C24 -> 0 | T32: =S32/$S$37 -> 0 | U32: =T32*$U$38 -> 0 | V32: =T32*$V$38 -> 0 | W32: =T32*$W$38 -> 0 | X32: =T32*$X$38 -> 0 | Y32: =T32*$Y$38 -> 0 | AA32: =SUM(U32:Y32) -> 0
Q33: 908 | R33: Consumer accounting | S33: =C25 -> 944348.21 | T33: =S33/$S$37 -> 1.0127223 | U33: =T33*$U$38 -> 16145.418 | V33: =T33*$V$38 -> 2841.8816 | W33: =T33*$W$38 -> 0 | X33: =T33*$X$38 -> 12883.853 | Y33: =T33*$Y$38 -> 0 | AA33: =SUM(U33:Y33) -> 31871.152
B34: Total | C34: =SUM(C5:C32) -> 16216581 | D34: =SUM(D5:D32) -> 1 | E34: =U49 -> 129303.78 | F34: =V49 -> 22759.771 | G34: =W49 -> 0 | H34: =X49 -> 103186 | I34: =Y49 -> 0 | J34: =SUM(D34:H34) -> 255250.55 | K34: =SUM(E34:I34) -> 255249.55 | Q34: 909 | R34: Consumer information | S34: =C26 -> 0 | T34: =S34/$S$37 -> 0 | U34: =T34*$U$38 -> 0 | V34: =T34*$V$38 -> 0 | W34: =T34*$W$38 -> 0 | X34: =T34*$X$38 -> 0 | Y34: =T34*$Y$38 -> 0 | AA34: =SUM(U34:Y34) -> 0
Q35: 910 | R35: Misc Customer Info | S35: =C27 -> 0 | T35: =S35/$S$37 -> 0 | U35: =T35*$U$38 -> 0 | V35: =T35*$V$38 -> 0 | W35: =T35*$W$38 -> 0 | X35: =T35*$X$38 -> 0 | Y35: =T35*$Y$38 -> 0 | AA35: =SUM(U35:Y35) -> 0
D36: =SUM(D5:D32) -> 1 | E36: =SUM(E5:E32) -> 129303.78 | F36: =SUM(F5:F32) -> 22759.771 | G36: =SUM(G5:G32) -> 0 | H36: =SUM(H5:H32) -> 103186 | I36: =SUM(I5:I32) -> 0 | K36: =SUM(K5:K32) -> 255249.55 | Q36: 912 | R36: Key Accounts expenses | S36: =C28 -> -11863.33 | T36: =S36/$S$37 -> -0.012722276 | U36: =T36*$U$38 -> -202.82605 | V36: =T36*$V$38 -> -35.701003 | W36: =T36*$W$38 -> 0 | X36: =T36*$X$38 -> -161.8528 | Y36: =T36*$Y$38 -> 0 | AA36: =SUM(U36:Y36) -> -400.37985
S37: =SUM(S32:S36) -> 932484.88 | T37: =SUM(T32:T36) -> 1 | U37: =T37*$U$38 -> 15942.592 | V37: =T37*$V$38 -> 2806.1805 | W37: =T37*$W$38 -> 0 | X37: =T37*$X$38 -> 12722 | Y37: =T37*$Y$38 -> 0 | AA37: =SUM(U37:Y37) -> 31470.772
U38: =[3]adjustments!$D$24 -> 15942.592 | V38: =[3]adjustments!$E$24 -> 2806.1805 | W38: 0 | X38: =[3]adjustments!$H$24 -> 12722 | Y38: 0 | AA38: =SUM(U38:Y38) -> 31470.772
Q41: 920 | R41: Administrative | S41: =C29 -> 2590524.3 | T41: =S41/$S$45 -> 0.66618002 | U41: =T41*$U$46 -> 30679.832 | V41: =T41*$V$46 -> 5400.1977 | W41: =T41*$W$46 -> 0 | X41: =T41*$X$46 -> 24482.782 | Y41: =T41*$Y$46 -> 0 | AA41: =SUM(U41:Y41) -> 60562.812
Q42: 926 | R42: Employee Benefits | S42: =C30 -> 0 | T42: =S42/$S$45 -> 0 | U42: =T42*$U$46 -> 0 | V42: =T42*$V$46 -> 0 | W42: =T42*$W$46 -> 0 | X42: =T42*$X$46 -> 0 | Y42: =T42*$Y$46 -> 0 | AA42: =SUM(U42:Y42) -> 0
...

Sheet 2 Functionalization2
C1: Expenses | G1: FUNCTIONALIZATION | R1: FOOTNOTES
M2: Consumer
A3: Acct | B3: Description | C3: Actual | D3: Adjust | E3: Adjusted | G3: Puchased | J3: Trans- | M3: Services & | N3: Security | O3: Street | Q3: Alloc.
A4: No. | C4: Test Year | D4: ments | E4: Test Year | G4: Power | H4: Stations | I4: Lines | J4: formers | K4: Services | L4: Meters | M4: Accounting | N4: Lighting | O4: Lighting | P4: Total | Q4: Basis
A6: 555 | B6: ='1TestYr_adj'!C10 -> Purchased Power | C6: =('1TestYr'!D10) -> 0 | D6: =('1TestYr'!E10) -> 0
B7: ='1TestYr_adj'!C11 -> Demand Charges | C7: 14211359 | D7: 1465107 | E7: ='1TestYr_adj'!S11 -> 18577420 | G7: =(E7) -> 18577420 | P7: =SUM(G7:N7) -> 18577420 | S7: 1 | T7: Line Expenses are Allocated between Lines and Services Based on Plant Investment.
B8: ='1TestYr_adj'!C12 -> Metering Point & Substations Charges | E8: ='1TestYr_adj'!S12 -> 1545492 | G8: =(E8) -> 1545492 | P8: =SUM(G8:N8) -> 1545492 | W8: $$$ | X8: %
B9: ='1TestYr_adj'!C13 -> Energy Charges | C9: 2758291 | D9: =-(C9) -> -2758291 | E9: ='1TestYr_adj'!S13 -> 63975166 | G9: =(E9) -> 63975166 | P9: =SUM(G9:N9) -> 63975166 | T9: Poles and Conductor | W9: =('2.22Rate Base'!H18) -> 1.2268778e+08 | X9: =(W9/$W$11) -> 0.80522155
B10: ='1TestYr_adj'!C14 -> Renewable Resource Energy | C10: =SUM(C7:C9) -> 16969650 | D10: =SUM(D7:D9) -> -1293184 | E10: ='1TestYr_adj'!S14 -> 6455.25 | G10: =(E10) -> 6455.25 | P10: =SUM(G10:N10) -> 6455.25 | T10: Services | W10: =('2.22Rate Base'!J18) -> 29677466 | X10: =(W10/$W$11) -> 0.19477845
B11: ='1TestYr_adj'!C15 -> By Thru and Metering Point Charges | C11: =SUM(C8:C10) -> 19727941 | D11: =SUM(D8:D10) -> -4051475 | E11: ='1TestYr_adj'!S15 -> 0 | G11: =(E11) -> 0 | P11: =SUM(G11:N11) -> 0 | T11: Total | W11: =SUM(W9:W10) -> 1.5236524e+08 | X11: =SUM(X9:X10) -> 1
B12: ='1TestYr_adj'!C16 -> Total Purchased Power | E12: =SUM(E7:E11) -> 84104533 | G12: =SUM(G7:G11) -> 84104533 | P12: =SUM(G12:O12) -> 84104533 | Q12: DA | AC12: Miscell.
C13: 76777.74 | D13: =(#REF!) -> #REF! | P13: =SUM(G13:O13) -> 0 | S13: 2 | T13: Allocation of Dist. Oper. Supervision & Miscellaneous Expenses | Y13: Actual | Z13: % | AB13: Superv | AC13: Exp. | AD13: Rents
A14: 580 | B14: ='1TestYr_adj'!C18 -> Operations Supv & Eng | C14: 0 | D14: =(#REF!) -> #REF! | E14: ='1TestYr_adj'!S18 -> 236763.57 | H14: =AB14 -> 5248.4067 | I14: =AB15 -> 115416.26 | J14: =AB16 -> 0 | K14: =AB17 -> 27918.53 | L14: =AB18 -> 53728.277 | M14: =AB19 -> 0 | N14: =AB20 -> 31744.529 | O14: =AB21 -> 2707.5616 | P14: =SUM(H14:O14) -> 236763.57 | Q14: 2 | T14: Stations | Y14: =E16 -> 50972.34 | Z14: =Y14/$Y$23 -> 0.02216729 | AB14: =(Z14*$AB$23) -> 5248.4067 | AC14: =(Z14*$AC$23) -> 4436.1519 | AD14: =$AD$24*Z14 -> 0
A15: 581 | B15: ='1TestYr_adj'!C19 -> Load Dispatching | C15: 189903.91 | D15: =(#REF!) -> #REF! | E15: ='1TestYr_adj'!S19 -> 0 | H15: =(E15) -> 0 | P15: =SUM(H15:O15) -> 0 | Q15: DA | T15: Lines | Y15: =I17+I18 -> 1120918.7 | Z15: =Y15/$Y$23 -> 0.48747476 | AB15: =(Z15*$AB$23) -> 115416.26 | AC15: =(Z15*$AC$23) -> 97554.193 | AD15: =$AD$24*Z15 -> 0
A16: =('1TestYr'!B20) -> 582 | B16: ='1TestYr_adj'!C20 -> Station Expense | C16: 0 | D16: =(#REF!) -> #REF! | E16: ='1TestYr_adj'!S20 -> 50972.34 | H16: =(E16) -> 50972.34 | P16: =SUM(H16:O16) -> 50972.34 | Q16: DA | T16: Transformers | Y16: =0 -> 0 | Z16: =Y16/$Y$23 -> 0 | AB16: =(Z16*$AB$23) -> 0 | AC16: =(Z16*$AC$23) -> 0 | AD16: =$AD$24*Z16 -> 0
A17: =('1TestYr'!B21) -> 583 | B17: ='1TestYr_adj'!C21 -> Overhead Line Exp. | C17: =(354789.72+70911.29) -> 425701.01 | D17: =(#REF!) -> #REF! | E17: ='1TestYr_adj'!S21 -> 1270574.3 | I17: =(X9*E17) -> 1023093.8 | K17: =E17*X10 -> 247480.49 | P17: =SUM(H17:O17) -> 1270574.3 | Q17: 1 | T17: Services | Y17: =K17+K18 -> 271143.77 | Z17: =Y17/$Y$23 -> 0.11791734 | AB17: =(Z17*$AB$23) -> 27918.53 | AC17: =(Z17*$AC$23) -> 23597.797 | AD17: =$AD$24*Z17 -> 0
A18: =('1TestYr'!B22) -> 584 | B18: ='1TestYr_adj'!C22 -> Underground Line Exp | E18: ='1TestYr_adj'!S22 -> 121488.18 | I18: =(X9*E18) -> 97824.904 | K18: =E18*X10 -> 23663.281 | P18: =SUM(H18:O18) -> 121488.18 | Q18: 1 | T18: Meters | Y18: =L20 -> 521807.12 | Z18: =Y18/$Y$23 -> 0.22692798 | AB18: =(Z18*$AB$23) -> 53728.277 | AC18: =(Z18*$AC$23) -> 45413.173 | AD18: =$AD$24*Z18 -> 0
A19: =('1TestYr'!B23) -> 585 | B19: ='1TestYr_adj'!C23 -> Street Lights | C19: 42228.91 | D19: =(#REF!) -> #REF! | E19: ='1TestYr_adj'!S23 -> 26295.742 | O19: =E19 -> 26295.742 | P19: =SUM(H19:O19) -> 26295.742 | Q19: DA | T19: Cunsumer Services & Acct | Y19: 0 | Z19: =Y19/$Y$23 -> 0 | AB19: =(Z19*$AB$23) -> 0 | AC19: =(Z19*$AC$23) -> 0 | AD19: =$AD$24*Z19 -> 0 | AG19: =SUM(AD17:AD22) -> 0
A20: =('1TestYr'!B24) -> 586 | B20: ='1TestYr_adj'!C24 -> Meter Expense | C20: =(101430.3+63260.76) -> 164691.06 | D20: =(#REF!) -> #REF! | E20: ='1TestYr_adj'!S24 -> 521807.12 | L20: =(E20) -> 521807.12 | P20: =SUM(H20:O20) -> 521807.12 | Q20: DA | T20: Security Lighting | Y20: =N21 -> 308301.74 | Z20: =Y20/$Y$23 -> 0.13407692 | AB20: =(Z20*$AB$23) -> 31744.529 | AC20: =(Z20*$AC$23) -> 26831.677 | AD20: =$AD$24*Z20 -> 0
A21: =('1TestYr'!B25) -> 587 | B21: ='1TestYr_adj'!C25 -> Consumer Installations | C21: 0 | D21: =(C21/$C$22)*(103795) -> 0 | E21: ='1TestYr_adj'!S25 -> 308301.74 | M21: 0 | N21: =(E21) -> 308301.74 | O21: 0 | P21: =SUM(H21:O21) -> 308301.74 | Q21: DA | T21: Street Lighting | Y21: =O19 -> 26295.742 | Z21: =Y21/$Y$23 -> 0.011435719 | AB21: =(Z21*$AB$23) -> 2707.5616 | AC21: =(Z21*$AC$23) -> 2288.5335 | AD21: =$AD$24*Z21 -> 0
A22: =('1TestYr'!B26) -> 588 | B22: ='1TestYr_adj'!C26 -> Misc. Distribution Exp | C22: =SUM(C13:C21) -> 899302.63 | D22: =SUM(D13:D21) -> #REF! | E22: ='1TestYr_adj'!S26 -> 200121.52 | H22: =AC14 -> 4436.1519 | I22: =AC15 -> 97554.193 | J22: =AC16 -> 0 | K22: =AC17 -> 23597.797 | L22: =AC18 -> 45413.173 | M22: =AC19 -> 0 | N22: =AC20 -> 26831.677 | O22: =AC21 -> 2288.5335 | P22: =SUM(H22:O22) -> 200121.52 | Q22: 2
A23: =('1TestYr'!B27) -> 589 | B23: ='1TestYr_adj'!C27 -> Rents | E23: ='1TestYr_adj'!S27 -> 0 | P23: =SUM(H23:O23) -> 0 | Q23: DA | Y23: =SUM(Y13:Y22) -> 2299439.4 | Z23: =SUM(Z14:Z22) -> 1 | AB23: =(E14) -> 236763.57 | AC23: =(E22) -> 200121.52 | AD23: 0 | AE23: =SUM(Y23+AB23+AC23) -> 2736324.5
B24: ='1TestYr_adj'!C28 -> Total Dist. Operations | E24: =SUM(E14:E23) -> 2736324.5 | H24: =SUM(H14:H23) -> 60656.899 | I24: =SUM(I14:I23) -> 1333889.1 | J24: =SUM(J14:J23) -> 0 | K24: =SUM(K14:K23) -> 322660.1 | L24: =SUM(L14:L23) -> 620948.57 | M24: =SUM(M14:M23) -> 0 | N24: =SUM(N14:N23) -> 366877.94 | O24: =SUM(O14:O23) -> 31291.837 | P24: =SUM(P14:P23) -> 2736324.5 | AB24: =SUM(AB14:AB22) -> 236763.57 | AC24: =SUM(AC14:AC22) -> 200121.52 | AD24: =E23 -> 0
C25: 75345.47 | D25: =(#REF!) -> #REF! | S25: 3 | T25: Allocation of Dist. Maint. Supervision & Miscellaneous Expenses | Y25: Actual | Z25: % | AB25: Superv | AC25: Misc. Exp.
A26: 590 | B26: ='1TestYr_adj'!C30 -> Maint Supv & Eng | C26: 3408.56 | D26: =(#REF!) -> #REF! | E26: ='1TestYr_adj'!S30 -> 308165.6 | H26: =(AB26) -> 8.3716129 | I26: =+AB27 -> 229905.97 | J26: =+AB28 -> 937.74343 | K26: =+AB29 -> 55612.931 | L26: =+AB30 -> 10797.039 | N26: =+AB31 -> 0 | O26: =+AB33 -> 10903.547 | P26: =SUM(G26:O26) -> 308165.6 | Q26: 3 | T26: Stations | Y26: =H27 -> 151.6791 | Z26: =(Y26/$Y$34) -> 2.7165955e-05 | AB26: =($AB$34*Z26) -> 8.3716129 | AC26: =Z26*$AC$35 -> 9.6315843
A27: 592 | B27: ='1TestYr_adj'!C31 -> Maint of Station Equip | C27: =(367239.65+75667.75+334721.48) -> 777628.88 | D27: =(#REF!)+(417787) -> #REF! | E27: ='1TestYr_adj'!S31 -> 151.6791 | H27: =E27 -> 151.6791 | P27: =SUM(G27:O27) -> 151.6791 | Q27: DA | T27: Lines | Y27: =I28+I29 -> 4165497.3 | Z27: =(Y27/$Y$34) -> 0.74604683 | AB27: =($AB$34*Z27) -> 229905.97 | AC27: =Z27*$AC$35 -> 264508.02
A28: 593 | B28: ='1TestYr_adj'!C32 -> Maint. Overhead Lines | C28: 0 | D28: 0 | E28: ='1TestYr_adj'!S32 -> 4867266.5 | I28: =E28*X9 -> 3919227.8 | K28: =E28*X10 -> 948038.64 | P28: =SUM(G28:O28) -> 4867266.5 | Q28: 1 | T28: Transformers | Y28: =J30 -> 16990.284 | Z28: =(Y28/$Y$34) -> 0.0030429854 | AB28: =($AB$34*Z28) -> 937.74343 | AC28: =Z28*$AC$35 -> 1078.8787
A29: 594 | B29: ='1TestYr_adj'!C33 -> Maint of Underground Lines | C29: 52902.09 | D29: =(#REF!) -> #REF! | E29: ='1TestYr_adj'!S33 -> 305840.65 | I29: =E29*X9 -> 246269.48 | K29: =E29*X10 -> 59571.17 | P29: =SUM(G29:O29) -> 305840.65 | Q29: 1 | T29: Services | Y29: =K28+K29 -> 1007609.8 | Z29: =(Y29/$Y$34) -> 0.18046443 | AB29: =($AB$34*Z29) -> 55612.931 | AC29: =Z29*$AC$35 -> 63982.967
A30: 595 | B30: ='1TestYr_adj'!C34 -> Maint Line Transformers | C30: 0 | D30: 0 | E30: ='1TestYr_adj'!S34 -> 16990.284 | J30: =(E30) -> 16990.284 | P30: =SUM(G30:O30) -> 16990.284 | Q30: DA | T30: Meters | Y30: =L32 -> 195623.62 | Z30: =(Y30/$Y$34) -> 0.035036484 | AB30: =($AB$34*Z30) -> 10797.039 | AC30: =Z30*$AC$35 -> 12422.05
A31: 596 | B31: ='1TestYr_adj'!C35 -> Maint of Street Lights | C31: 1001 | D31: =(#REF!) -> #REF! | E31: ='1TestYr_adj'!S35 -> 197553.35 | O31: =E31 -> 197553.35 | P31: =SUM(G31:O31) -> 197553.35 | Q31: DA | T31: Cunsumer Services & Acct | Y31: 0 | Z31: =(Y31/$Y$34) -> 0 | AB31: =($AB$34*Z31) -> 0 | AC31: =Z31*$AC$35 -> 0
A32: 597 | B32: ='1TestYr_adj'!C36 -> Maintenance of Meters | C32: 72405.6 | D32: =(#REF!) -> #REF! | E32: ='1TestYr_adj'!S36 -> 195623.62 | L32: =E32 -> 195623.62 | P32: =SUM(G32:O32) -> 195623.62 | Q32: DA | T32: Security Lighting | Y32: =0 -> 0 | Z32: =(Y32/$Y$34) -> 0 | AB32: 0 | AC32: =Z32*$AC$35 -> 0
A33: 598 | B33: ='1TestYr_adj'!C37 -> Maint Misc Distrib Plant | E33: ='1TestYr_adj'!S37 -> 354546.14 | H33: =AC26 -> 9.6315843 | I33: =AC27 -> 264508.02 | J33: =AC28 -> 1078.8787 | K33: =AC29 -> 63982.967 | L33: =AC30 -> 12422.05 | M33: =AC31 -> 0 | N33: =AC32 -> 0 | O33: =AC33 -> 12544.587 | P33: =SUM(G33:O33) -> 354546.14 | Q33: 3 | T33: Street Lighting | Y33: =O31 -> 197553.35 | Z33: =(Y33/$Y$34) -> 0.035382101 | AB33: =($AB$34*Z33) -> 10903.547 | AC33: =Z33*$AC$35 -> 12544.587
B34: ='1TestYr_adj'!C38 -> Total Dist. Maint. | E34: =SUM(E26:E33) -> 6246137.8 | G34: =SUM(G26:G33) -> 0 | H34: =SUM(H26:H33) -> 169.6823 | I34: =SUM(I26:I33) -> 4659911.3 | J34: =SUM(J26:J33) -> 19006.906 | K34: =SUM(K26:K33) -> 1127205.7 | L34: =SUM(L26:L33) -> 218842.7 | M34: =SUM(M26:M33) -> 0 | N34: =SUM(N26:N33) -> 0 | ... P34: =SUM(P26:P33) -> 6246137.8 | Y34: =SUM(Y26:Y33) -> 5583426 | Z34: =SUM(Z26:Z33) -> 1 | AB34: =(E26) -> 308165.6 | AC34: =SUM(AC26:AC33) -> 354546.14 | AE34: =SUM(AC34,AB34,Y34) -> 6246137.8
A35: =('1TestYr'!B38) | C35: 0 | P35: =SUM(G35:O35) -> 0 | AB35: =E26 -> 308165.6 | AC35: =E33 -> 354546.14
A36: 901 | B36: ='1TestYr_adj'!C40 -> Supervision | C36: 57203.53 | E36: ='1TestYr_adj'!S40 -> 143333.65 | M36: =(E36) -> 143333.65 | P36: =SUM(G36:O36) -> 143333.65 | Q36: DA | S36: 4 | T36: General Plant Allocation Comes From the Rate Base Schedule Line General Plant Percent
A37: 902 | B37: ='1TestYr_adj'!C41 -> Meter Reading Expense | C37: =(467413.25+813.58) -> 468226.83 | D37: 35476 | E37: ='1TestYr_adj'!S41 -> 101876.5 | M37: =(E37) -> 101876.5 | P37: =SUM(G37:O37) -> 101876.5 | Q37: DA
A38: 903 | B38: ='1TestYr_adj'!C42 -> Cons Recds & Collections | C38: 84000 | E38: ='1TestYr_adj'!S42 -> 2319797.3 | M38: =(E38) -> 2319797.3 | P38: =SUM(G38:O38) -> 2319797.3 | Q38: DA | S38: 5 | T38: Rate Base Allocation Comes from the Rate Base Schedule Line Rate Base Percent.
A39: 904 | B39: ='1TestYr_adj'!C43 -> Uncollectible Accounts | C39: =SUM(C36:C38) -> 609430.36 | D39: 35476 | E39: ='1TestYr_adj'!S43 -> 340357.45 | M39: =(E39) -> 340357.45 | P39: =SUM(G39:O39) -> 340357.45 | Q39: DA
B40: ='1TestYr_adj'!C44 -> Total Consumer Accts | E40: =SUM(E36:E39) -> 2905364.9 | M40: =SUM(M36:M39) -> 2905364.9 | P40: =SUM(G40:O40) -> 2905364.9 | S40: 6 | T40: Depreciation Expense Allocation Comes from the Distribution Plant Percent in Rate Base
A41: =('1TestYr'!B44) | C41: 0 | P41: =SUM(G41:O41) -> 0
...

Sheet 2.1 SummaryFunc.
J2: Consumer
D3: Purchased | J3: Services & | K3: Security | L3: Street
B4: Expense | D4: Power | E4: Stations | F4: Lines | G4: Transformers | H4: Services | I4: Meters | J4: Accounting | K4: Lighting | L4: Lighting | M4: Total
B5: Purchased Power | D5: =('2 Functionalization2'!G12) -> 84104533 | M5: =SUM(D5:L5) -> 84104533
B6: Distibution Operations | E6: =('2 Functionalization2'!H24) -> 60656.899 | F6: =('2 Functionalization2'!I24) -> 1333889.1 | G6: =('2 Functionalization2'!J24) -> 0 | H6: =('2 Functionalization2'!K24) -> 322660.1 | I6: =('2 Functionalization2'!L24) -> 620948.57 | J6: =('2 Functionalization2'!M24) -> 0 | K6: =('2 Functionalization2'!N24) -> 366877.94 | L6: =('2 Functionalization2'!O24) -> 31291.837 | M6: =SUM(D6:L6) -> 2736324.5
B7: Distribution Maintenance | E7: =('2 Functionalization2'!H34) -> 169.6823 | F7: =('2 Functionalization2'!I34) -> 4659911.3 | G7: =('2 Functionalization2'!J34) -> 19006.906 | H7: =('2 Functionalization2'!K34) -> 1127205.7 | I7: =('2 Functionalization2'!L34) -> 218842.7 | J7: =('2 Functionalization2'!M34) -> 0 | K7: =('2 Functionalization2'!N34) -> 0 | L7: =('2 Functionalization2'!O34) -> 221001.48 | M7: =SUM(D7:L7) -> 6246137.8
B8: Consumer Accounts | E8: ='2 Functionalization2'!H40 -> 0 | F8: ='2 Functionalization2'!I40 -> 0 | G8: ='2 Functionalization2'!J40 -> 0 | H8: ='2 Functionalization2'!K40 -> 0 | I8: ='2 Functionalization2'!L40 -> 0 | J8: ='2 Functionalization2'!M40 -> 2905364.9 | K8: ='2 Functionalization2'!N40 -> 0 | L8: ='2 Functionalization2'!O40 -> 0 | M8: =SUM(D8:L8) -> 2905364.9
B9: Customer Service | E9: ='2 Functionalization2'!H48 -> 0 | F9: ='2 Functionalization2'!I48 -> 0 | G9: ='2 Functionalization2'!J48 -> 0 | H9: ='2 Functionalization2'!K48 -> 0 | I9: ='2 Functionalization2'!L48 -> 0 | J9: ='2 Functionalization2'!M48 -> 1024972.7 | K9: ='2 Functionalization2'!N48 -> 0 | L9: ='2 Functionalization2'!O48 -> 0 | M9: =SUM(D9:L9) -> 1024972.7
B10: Administative & General | E10: =('2 Functionalization2'!H61) -> 20747.167 | F10: =('2 Functionalization2'!I61) -> 2044408.4 | G10: =('2 Functionalization2'!J61) -> 6483.0118 | H10: =('2 Functionalization2'!K61) -> 494530.63 | I10: =('2 Functionalization2'!L61) -> 286442.03 | J10: =('2 Functionalization2'!M61) -> 1340587.7 | K10: =('2 Functionalization2'!N61) -> 125137.36 | L10: =('2 Functionalization2'!O61) -> 86054.013 | M10: =SUM(D10:L10) -> 4404390.4
B11: Depreciation | E11: =('2 Functionalization2'!H66) -> 75944.39 | F11: =('2 Functionalization2'!I66) -> 5004877.9 | G11: =('2 Functionalization2'!J66) -> 1271406.8 | H11: =('2 Functionalization2'!K66) -> 1210651.1 | I11: =('2 Functionalization2'!L66) -> 319750.94 | J11: =('2 Functionalization2'!M66) -> 150047.46 | K11: =('2 Functionalization2'!N66) -> 224968.77 | L11: =('2 Functionalization2'!O66) -> 126646.5 | M11: =SUM(D11:L11) -> 8384293.9
B12: Miscellaneous | E12: =('2 Functionalization2'!H71) -> 185.7659 | F12: =('2 Functionalization2'!I71) -> 12166.281 | G12: =('2 Functionalization2'!J71) -> 3148.2372 | H12: =('2 Functionalization2'!K71) -> 2942.9533 | I12: =('2 Functionalization2'!L71) -> 759.77829 | J12: =('2 Functionalization2'!M71) -> 221.0852 | K12: =('2 Functionalization2'!N71) -> 543.14019 | L12: =('2 Functionalization2'!O71) -> 304.00884 | M12: =SUM(D12:L12) -> 20271.25
B13: Interest on Long Term Debt | E13: =('2 Functionalization2'!H76) -> 43087.286 | F13: =('2 Functionalization2'!I76) -> 2821895.9 | G13: =('2 Functionalization2'!J76) -> 730214.72 | H13: =('2 Functionalization2'!K76) -> 682600.36 | I13: =('2 Functionalization2'!L76) -> 176226.01 | J13: =('2 Functionalization2'!M76) -> 51279.386 | K13: =('2 Functionalization2'!N76) -> 125978.11 | L13: =('2 Functionalization2'!O76) -> 70513.025 | M13: =SUM(D13:L13) -> 4701794.8
B14: Short Term Interest | E14: =('2 Functionalization2'!H79) -> 26.381897 | F14: =('2 Functionalization2'!I79) -> 1727.8175 | G14: =('2 Functionalization2'!J79) -> 447.10287 | H14: =('2 Functionalization2'!K79) -> 417.9491 | I14: =('2 Functionalization2'!L79) -> 107.90135 | J14: =('2 Functionalization2'!M79) -> 31.397834 | K14: =('2 Functionalization2'!N79) -> 77.135083 | L14: =('2 Functionalization2'!O79) -> 43.174391 | M14: =SUM(D14:L14) -> 2878.86
B15: Total Costs | D15: =SUM(D5:D14) -> 84104533 | E15: =SUM(E5:E14) -> 200817.57 | F15: =SUM(F5:F14) -> 15878877 | G15: =SUM(G5:G14) -> 2030706.7 | H15: =SUM(H5:H14) -> 3841008.8 | I15: =SUM(I5:I14) -> 1623077.9 | J15: =SUM(J5:J14) -> 5472504.6 | K15: =SUM(K5:K14) -> 843582.46 | L15: =SUM(L5:L14) -> 535854.04 | M15: =SUM(D15:L15) -> 1.1453096e+08
B16: Margin Requirements | D16: =(D13) -> 0 | E16: =('2 Functionalization2'!H82) -> 43087.288 | F16: =('2 Functionalization2'!I82) -> 2821896 | G16: =('2 Functionalization2'!J82) -> 730214.76 | H16: =('2 Functionalization2'!K82) -> 682600.39 | I16: =('2 Functionalization2'!L82) -> 176226.02 | J16: =('2 Functionalization2'!M82) -> 51279.388 | K16: =('2 Functionalization2'!N82) -> 125978.11 | L16: =('2 Functionalization2'!O82) -> 70513.028 | M16: =SUM(D16:L16) -> 4701795
B17: Revenue Requirements | D17: =SUM(D15:D16) -> 84104533 | E17: =SUM(E15:E16) -> 243904.86 | F17: =SUM(F15:F16) -> 18700773 | G17: =SUM(G15:G16) -> 2760921.5 | H17: =SUM(H15:H16) -> 4523609.2 | I17: =SUM(I15:I16) -> 1799304 | J17: =SUM(J15:J16) -> 5523784 | K17: =SUM(K15:K16) -> 969560.57 | L17: =SUM(L15:L16) -> 606367.06 | M17: =SUM(D17:L17) -> 1.1923276e+08
E19: =(E16/E17) -> 0.17665613 | M19: =SUM(M5:M14) -> 1.1453096e+08

Sheet 2.22Rate Base
A1: FUNCTIONALIZATION OF RATE BASE
H2: Distribution Plant Balances
L3: Consumer
B4: Plant | L4: & Accounting | M4: Security | N4: Street
B5: Account | C5: Description | E5: $$$$ | G5: Stations | H5: Lines | I5: Transformers | J5: Services | K5: Meters | L5: Services | M5: Lighting | N5: Lighting
A6: 1 | B6: =([6]adjustment!B36) -> 301 | C6: =([6]adjustment!C36) -> Organization | E6: 0 | H6: =(E6) -> 0 | P6: =SUM(H6:N6) -> 0
A7: 2 | B7: 389 | C7: Land and Land Rights | H7: =(E7) -> 0 | P7: =SUM(G7:N7) -> 0
A8: 3 | B8: 362 | C8: Station Equipment | E8: =1345642.26+545573.23 -> 1891215.5 | G8: =(E8) -> 1891215.5 | P8: =SUM(G8:N8) -> 1891215.5
A9: 4 | B9: =([6]adjustment!B38) -> 364 | C9: Poles, Towers & Fixtures | E9: 57805699 | H9: =(E9) -> 57805699 | P9: =SUM(G9:N9) -> 57805699
A10: 5 | B10: =([6]adjustment!B39) -> 365 | C10: Overhead Conductor & Devices | E10: 50743404 | H10: =(E10-M10) -> 50743404 | P10: =SUM(G10:N10) -> 50743404
B11: 366 | C11: Underground Conduit | E11: 0 | H11: =(E11-M11) -> 0
A12: 6 | B12: 367 | C12: Underground Conductor | E12: 14138673 | H12: =(E12) -> 14138673 | P12: =SUM(G12:N12) -> 14138673
A13: 7 | B13: =([6]adjustment!B42) -> 368 | C13: Line Transformers | E13: =22840564.83+9800824.43 -> 32641389 | I13: =(E13) -> 32641389 | P13: =SUM(G13:N13) -> 32641389 | R13: 370 | S13: 450100.68
A14: 8 | B14: =([6]adjustment!B43) -> 369 | C14: Services | E14: =10324375.44+19353090.97 -> 29677466 | J14: =(E14) -> 29677466 | P14: =SUM(G14:N14) -> 29677466 | R14: 370.1 | S14: 6940121.4
A15: 9 | B15: =([6]adjustment!B44) -> 370 | C15: Meters | E15: =450100.68+6940121.39 -> 7390222.1 | K15: =(E15) -> 7390222.1 | P15: =SUM(G15:N15) -> 7390222.1 | R15: 370.2
A16: 10 | B16: =([6]adjustment!B46) -> 371 | C16: Security Lights | E16: 5419228.4 | M16: =(E16) -> 5419228.4 | P16: =SUM(G16:N16) -> 5419228.4 | R16: 370.3
A17: 11 | B17: =([6]adjustment!B47) -> 373 | C17: Street Lights | E17: 3005887.4 | N17: =(E17) -> 3005887.4 | P17: =SUM(G17:N17) -> 3005887.4 | S17: =SUM(S13:S16) -> 7390222.1
A18: 12 | C18: Total Distribution Plant | E18: =SUM(E6:E17) -> 2.0271318e+08 | G18: =SUM(G6:G17) -> 1891215.5 | H18: =SUM(H6:H17) -> 1.2268778e+08 | I18: =SUM(I7:I17) -> 32641389 | J18: =SUM(J7:J17) -> 29677466 | K18: =SUM(K7:K17) -> 7390222.1 | L18: =SUM(L7:L17) -> 0 | M18: =SUM(M7:M17) -> 5419228.4 | N18: =SUM(N7:N17) -> 3005887.4 | P18: =SUM(G18:N18) -> 2.0271318e+08
A19: 13 | C19: Distibution Plant Percent | E19: =(E18/$E$18) -> 1 | G19: =(G18/$E$18) -> 0.009329514 | H19: =(H18/$E$18) -> 0.6052284 | I19: =(I18/$E$18) -> 0.16102253 | J19: =(J18/$E$18) -> 0.14640126 | K19: =(K18/$E$18) -> 0.036456544 | L19: =(L18/$E$18) -> 0 | M19: =(M18/$E$18) -> 0.026733478 | N19: =(N18/$E$18) -> 0.014828278 | P19: =SUM(G19:N19) -> 1
A20: 14 | T20: 108.7 | U20: 2408194.7 | W20: 108.6 | X20: 16403586 | Z20: 108.54 | AA20: 2610145.7 | AC20: 108.8 | AD20: -150372.41
A21: 15 | C21: Total General Plant | E21: =9491445+8067755 -> 17559200 | G21: =($E$21*'2 Functionalization2'!U91) -> 82713.751 | H21: =($E$21*'2 Functionalization2'!V91) -> 8150543.8 | I21: =($E$21*'2 Functionalization2'!W91) -> 25846.142 | J21: =($E$21*'2 Functionalization2'!X91) -> 1971569.6 | K21: =($E$21*'2 Functionalization2'!Y91) -> 1141972.6 | L21: =($E$21*'2 Functionalization2'!Z91) -> 5344587.1 | M21: =($E$21*'2 Functionalization2'!AA91) -> 498891.28 | N21: =($E$21*'2 Functionalization2'!AB91) -> 343075.77 | P21: =SUM(G21:N21) -> 17559200 | T21: 108.71 | U21: 220990.02 | W21: 108.61 | X21: 11845342 | Z21: 108.55 | AA21: 3488.88 | AC21: 108.81
A22: 16 | C22: General Plant Percent | E22: =(E21/$E$21) -> 1 | G22: =(G21/$E$21) -> 0.0047105649 | H22: =(H21/$E$21) -> 0.46417512 | I22: =(I21/$E$21) -> 0.0014719431 | J22: =(J21/$E$21) -> 0.11228129 | K22: =(K21/$E$21) -> 0.065035569 | L22: =(L21/$E$21) -> 0.30437532 | M22: =(M21/$E$21) -> 0.028411959 | N22: =(N21/$E$21) -> 0.019538235 | P22: =SUM(G22:N22) -> 1 | T22: 108.72 | U22: 986635.75 | W22: 108.62 | X22: 3411482.4 | Z22: 108.56 | AA22: 7448.99 | AC22: 108.9
A23: 17 | T23: 108.73 | U23: 1289079.9 | W23: 108.63 | X23: 7773861.5 | Z23: 108.57 | AA23: 292660.3
A24: 18 | C24: Total Utility Plant | E24: =(E18+E21) -> 2.2027238e+08 | G24: =(G18+G21) -> 1973929.2 | H24: =(H18+H21) -> 1.3083832e+08 | I24: =(I18+I21) -> 32667235 | J24: =(J18+J21) -> 31649036 | K24: =(K18+K21) -> 8532194.6 | L24: =(L18+L21) -> 5344587.1 | M24: =(M18+M21) -> 5918119.7 | N24: =(N18+N21) -> 3348963.2 | P24: =SUM(G24:N24) -> 2.2027238e+08 | T24: 108.74 | U24: 273721.82 | W24: 108.64 | X24: 2889538.6 | Z24: 108.58 | AA24: 703827.15
A25: 19 | C25: Utility Plant Percent | E25: =(E24/$E$24) -> 1 | G25: =(G24/$E$24) -> 0.0089613105 | H25: =(H24/$E$24) -> 0.59398421 | I25: =(I24/$E$24) -> 0.14830382 | J25: =(J24/$E$24) -> 0.14368136 | K25: =(K24/$E$24) -> 0.038734745 | L25: =(L24/$E$24) -> 0.024263537 | M25: =(M24/$E$24) -> 0.026867279 | N25: =(N24/$E$24) -> 0.015203736 | P25: =SUM(G25:N25) -> 1 | T25: 108.75 | U25: 154309.72 | W25: 108.65 | X25: 2957191.2 | Z25: 108.59 | AA25: 1701892.7
A26: 20 | T26: 108.76 | U26: 288227.84 | W26: 108.66 | X26: 6805979.4
A27: 21 | C27: Accum. Depreciation | T27: 108.77 | U27: 802207.07 | W27: 108.67 | X27: 332260.67
A28: 22 | C28: Distribution Plant | E28: =X30+AD30 -> 54621212 | G28: =(G19*$E$28) -> 509589.36 | H28: =(H19*$E$28) -> 33058309 | I28: =(I19*$E$28) -> 8795245.6 | J28: =(J19*$E$28) -> 7996614.5 | K28: =(K19*$E$28) -> 1991300.6 | L28: =(L19*$E$28) -> 0 | M28: =(M19*$E$28) -> 1460215 | N28: =(N19*$E$28) -> 809938.51 | P28: =SUM(G28:N28) -> 54621212 | T28: 108.78 | U28: 164796.08 | W28: 108.68 | X28: 1079865.5
A29: 23 | C29: General Plant | E29: =U30+AA30 -> 11977110 | G29: =($E$29*G22) -> 56418.953 | H29: =($E$29*H22) -> 5559476.4 | I29: =($E$29*I22) -> 17629.624 | J29: =($E$29*J22) -> 1344805.3 | K29: =($E$29*K22) -> 778938.15 | L29: =($E$29*L22) -> 3645536.7 | M29: =($E$29*M22) -> 340293.16 | N29: =($E$29*N22) -> 234011.59 | P29: =SUM(G29:N29) -> 11977110 | Q29: =SUM(P28:P29) -> 66598322 | R29: 57505856 | T29: 108.79 | U29: 69483.17 | W29: 108.69 | X29: 1272477.4
A30: 24 | R30: =R29-Q29 -> -9092466.3 | U30: =SUM(U20:U29) -> 6657646.1 | X30: =SUM(X20:X29) -> 54771585 | AA30: =SUM(AA20:AA29) -> 5319463.8 | AD30: =SUM(AD20:AD29) -> -150372.41 | AE30: =SUM(U30:AD30) -> 66598322
A31: 25 | C31: Net Plant | E31: =(E24-E28-E29) -> 1.5367406e+08 | G31: =(G24-G28-G29) -> 1407920.9 | H31: =(H24-H28-H29) -> 92220534 | I31: =(I24-I28-I29) -> 23854360 | J31: =(J24-J28-J29) -> 22307616 | K31: =(K24-K28-K29) -> 5761955.9 | L31: =(L24-L28-L29) -> 1699050.5 | M31: =(M24-M28-M29) -> 4117611.6 | N31: =(N24-N28-N29) -> 2305013.1 | P31: =SUM(G31:N31) -> 1.5367406e+08
A32: 26 | C32: Net Plant Percent | E32: =(E31/$E$31) -> 1 | G32: =(G31/$E$31) -> 0.0091617343 | H32: =(H31/$E$31) -> 0.60010475 | I32: =(I31/$E$31) -> 0.15522698 | J32: =(J31/$E$31) -> 0.14516188 | K32: =(K31/$E$31) -> 0.037494654 | L32: =(L31/$E$31) -> 0.011056195 | M32: =(M31/$E$31) -> 0.026794447 | N32: =(N31/$E$31) -> 0.014999363 | P32: =SUM(G32:N32) -> 1 | U32: CWIP | W32: Cash Working capital | Z32: Materials and Supplies | AC32: Prepayments | AF32: Consumer Advances
A33: 27 | P33: =SUM(H33:N33) -> 0 | T33: 107.2 | U33: 1731296.6 | W33: 131.2 | X33: 6023 | Z33: 154 | AA33: 1378197.1 | AC33: 165.12 | AD33: -4257.23 | AF33: 252 | AG33: -384769.68
A34: 28 | C34: CWIP | E34: 1731297 | G34: =(G18/$E$18)*($E$34) -> 16152.16 | H34: =(H18/$E$18)*($E$34) -> 1047830.1 | I34: =(I18/$E$18)*($E$34) -> 278777.82 | J34: =(J18/$E$18)*($E$34) -> 253464.07 | K34: =(K18/$E$18)*($E$34) -> 63117.105 | L34: =(L18/$E$18)*($E$34) -> 0 | M34: =(M18/$E$18)*($E$34) -> 46283.59 | N34: =(N18/$E$18)*($E$34) -> 25672.153 | P34: =SUM(G34:N34) -> 1731297 | T34: 107.21 | W34: 131.31 | X34: 100 | Z34: 154.01 | AA34: -22171.72 | AC34: 165.14 | AD34: 179338 | AF34: 252.1
A35: 29 | C35: Subtotal | E35: =(E31+E34) -> 1.5540536e+08 | G35: =(G31+G34) -> 1424073.1 | H35: =(H31+H34) -> 93268364 | I35: =(I31+I34) -> 24133138 | J35: =(J31+J34) -> 22561080 | K35: =(K31+K34) -> 5825073 | L35: =(L31+L34) -> 1699050.5 | M35: =(M31+M34) -> 4163895.1 | N35: =(N31+N34) -> 2330685.2 | P35: =SUM(G35:N35) -> 1.5540536e+08 | T35: 107.22 | W35: 131.4 | X35: 109067.99 | Z35: 154.1 | AA35: 14899.26 | AC35: 165.15 | AD35: 120.95
A36: 30 | C36: Plus | P36: =SUM(G36:N36) -> 0 | T36: 107.3 | W36: 131.85 | X36: 53825.98 | Z36: 154.6 | AA36: 0 | AC36: 165.16 | AD36: -233.09
A37: 31 | C37: Cash Working Capital | E37: =X54 -> 205662.54 | G37: =(G35/$E$35)*($E$37) -> 1884.61 | H37: =(H35/$E$35)*($E$37) -> 123430.81 | I37: =(I35/$E$35)*($E$37) -> 31937.653 | J37: =(J35/$E$35)*($E$37) -> 29857.201 | K37: =(K35/$E$35)*($E$37) -> 7708.8673 | L37: =(L35/$E$35)*($E$37) -> 2248.5134 | M37: =(M35/$E$35)*($E$37) -> 5510.4744 | N37: =(N35/$E$35)*($E$37) -> 3084.4151 | P37: =SUM(G37:N37) -> 205662.54 | T37: 107.31 | W37: 131.9 | X37: 28902 | AC37: 165.2 | AD37: 44674.16
A38: 32 | C38: Materials & Supplies | E38: =AA54 -> 1370924.6 | G38: =(G35/$E$35)*($E$38) -> 12562.61 | H38: =(H35/$E$35)*($E$38) -> 822776.63 | I38: =(I35/$E$35)*($E$38) -> 212893 | J38: =(J35/$E$35)*($E$38) -> 199024.93 | K38: =(K35/$E$35)*($E$38) -> 51386.49 | L38: =(L35/$E$35)*($E$38) -> 14988.351 | M38: =(M35/$E$35)*($E$38) -> 36732.236 | N38: =(N35/$E$35)*($E$38) -> 20560.384 | P38: =SUM(G38:N38) -> 1370924.6 | T38: 107.32 | W38: 131.95 | X38: 7743.57 | AC38: 165.21 | AD38: 10067
A39: 33 | C39: Prepayments | E39: =AD54 -> 301267.41 | G39: =(G35/$E$35)*($E$39) -> 2760.6951 | H39: =(H35/$E$35)*($E$39) -> 180809.2 | I39: =(I35/$E$35)*($E$39) -> 46784.281 | J39: =(J35/$E$35)*($E$39) -> 43736.704 | K39: =(K35/$E$35)*($E$39) -> 11292.433 | L39: =(L35/$E$35)*($E$39) -> 3293.7637 | M39: =(M35/$E$35)*($E$39) -> 8072.0891 | N39: =(N35/$E$35)*($E$39) -> 4518.2451 | P39: =SUM(G39:N39) -> 301267.41 | U39: =SUM(U33:U38) -> 1731296.6 | W39: 131.16 | X39: 0 | AC39: 165.22 | AD39: 3547.03
A40: 34 | C40: Minus: Consumer Advances | E40: =AG54 -> -384769.68 | G40: =(G18/$E$18)*($E$40) -> -3589.7141 | H40: =(H18/$E$18)*($E$40) -> -232873.54 | I40: =(I18/$E$18)*($E$40) -> -61956.586 | J40: =(J18/$E$18)*($E$40) -> -56330.767 | K40: =(K18/$E$18)*($E$40) -> -14027.373 | L40: =(L18/$E$18)*($E$40) -> 0 | M40: =(M18/$E$18)*($E$40) -> -10286.232 | N40: =(N18/$E$18)*($E$40) -> -5705.4717 | P40: =SUM(G40:N40) -> -384769.68 | W40: 131.17 | X40: 0 | AC40: 165.23 | AD40: 12954.98
...

Sheet 3Classific. Summary
A2: SUMMARY OF CLASSIFICATION OF EXPENSES
D5: Consumer | E5: Demand | F5: Energy
D6: Related | E6: Related | F6: Related | G6: Security | H6: Street
D7: Costs | E7: Costs | F7: Costs | G7: Lighting | H7: Lighting | I7: Total
B9: Purchased Power | D9: 0 | E9: =('3.2 Classific. 2'!G41) -> 20122912 | F9: =('3.2 Classific. 2'!F41) -> 63981621 | G9: 0 | H9: 0 | I9: =SUM(D9:H9) -> 84104533
B10: Stations | E10: =('3.2 Classific. 2'!K36) -> 243904.86 | I10: =SUM(D10:H10) -> 243904.86
B11: Lines | D11: =('3.2 Classific. 2'!F18) -> 6359168.4 | E11: =('3.2 Classific. 2'!G18) -> 12341604 | F11: 0 | G11: 0 | H11: 0 | I11: =SUM(D11:H11) -> 18700773
B12: Transformers | D12: =('3.2 Classific. 2'!F36) -> 575268.74 | E12: =('3.2 Classific. 2'!G36) -> 2185652.8 | F12: 0 | G12: 0 | H12: 0 | I12: =SUM(D12:H12) -> 2760921.5
B13: Services | D13: =('3.2 Classific. 2'!K18) -> 4523609.2 | E13: 0 | F13: 0 | G13: 0 | H13: 0 | I13: =SUM(D13:H13) -> 4523609.2
B14: Meters | D14: =('3.2 Classific. 2'!L18) -> 1799304 | E14: 0 | G14: 0 | H14: 0 | I14: =SUM(D14:H14) -> 1799304
B15: Consumer Services | I15: =SUM(D15:H15) -> 0
B16: & Accounting | D16: =('3.2 Classific. 2'!M18) -> 5523784 | E16: 0 | F16: 0 | I16: =SUM(D16:H16) -> 5523784
B17: Lighting | G17: =('3.2 Classific. 2'!L36) -> 969560.57 | H17: =('3.2 Classific. 2'!M36) -> 606367.06 | I17: =SUM(D17:H17) -> 1575927.6
D18: =SUM(D9:D17) -> 18781134 | E18: =SUM(E9:E17) -> 34894074 | F18: =SUM(F9:F17) -> 63981621 | G18: =SUM(G9:G17) -> 969560.57 | H18: =SUM(H9:H17) -> 606367.06 | I18: =SUM(D18:H18) -> 1.1923276e+08
K38: =SUM('2.22Rate Base'!G66:J66) -> 0

Sheet 3.2 Classific. 2
K1: Consumer Related Costs
F3: Consumer | G3: Demand | M3: Consumer
D4: 2 | F4: Related | G4: Related | M4: Services &
B5: =('2.1 SummaryFunc.'!B4) -> Expense | D5: =('2.1 SummaryFunc.'!F4) -> Lines | F5: Costs | G5: Costs | H5: Total | I5: =(B5) -> Expense | K5: Services | L5: Meters | M5: Accounting | N5: Total
B6: =('2.1 SummaryFunc.'!B5) -> Purchased Power | D6: =('2.1 SummaryFunc.'!F5) -> 0 | F6: =(D6*'3.1 PlantClass.'!$D$100) -> 0 | G6: =(D6*'3.1 PlantClass.'!$F$100) -> 0 | H6: =(F6+G6) -> 0 | I6: =(B6) -> Purchased Power | K6: =('2.1 SummaryFunc.'!H5) -> 0 | L6: =('2.1 SummaryFunc.'!I5) -> 0 | M6: =('2.1 SummaryFunc.'!J5) -> 0 | N6: =SUM(K6:M6) -> 0
