Workbook
Name \P: #REF!
Name \T: '[1]Rec HCI AP'!#REF!
Name \X: #REF!
Name ____Qtr1: '[2]2006 G&A'!#REF!
Name ____Qtr2: '[2]2006 G&A'!#REF!
Name ____Qtr3: '[2]2006 G&A'!#REF!
Name ____Qtr4: '[2]2006 G&A'!#REF!
Name ___Qtr1: '[2]2006 G&A'!#REF!
Name ___Qtr2: '[2]2006 G&A'!#REF!
Name ___Qtr3: '[2]2006 G&A'!#REF!
Name ___Qtr4: '[2]2006 G&A'!#REF!
Name __Qtr1: '[2]2006 G&A'!#REF!
Name __Qtr2: '[2]2006 G&A'!#REF!
Name __Qtr3: '[2]2006 G&A'!#REF!
Name __Qtr4: '[2]2006 G&A'!#REF!
Name _1NTP_FACTOR: '[6]D-3a'!#REF!
Name _2H: #REF!
Name _2SCH_G_1: #REF!
Name _3SCH_H_1: #REF!
Name _4SCH_I_O_M: #REF!
Name _Feb1: #REF!
Name _Feb2: #REF!
Name _Qtr1: '[2]2006 G&A'!#REF!
Name _Qtr2: '[2]2006 G&A'!#REF!
Name _Qtr3: '[2]2006 G&A'!#REF!
Name _Qtr4: '[2]2006 G&A'!#REF!
Name a: [9]Mar01!$A$1:$AR$85
Name Account: '[10]Balance recorded'!#REF!
Name Account2: '[10]Balance recorded'!#REF!
Name AccountDescr: '[10]Balance recorded'!#REF!
Name AccountDescr2: '[10]Balance recorded'!#REF!
Name Activity: '[10]Balance recorded'!#REF!
Name Activity2: '[10]Balance recorded'!#REF!
Name ActivityDescr: '[10]Balance recorded'!#REF!
Name ActivityDescr2: '[10]Balance recorded'!#REF!
Name ACTMNTH: '[11]BW Earn Stmt New'!$I$16:$I$5000
Name ACTYTD: '[11]BW Earn Stmt New'!$J$16:$J$5000
Name Adjust: #REF!
Name Affiliate: '[10]Balance recorded'!#REF!
Name Affiliate2: '[10]Balance recorded'!#REF!
Name AffiliateDescr: '[10]Balance recorded'!#REF!
Name Allocation: #REF!
Name Altus: #REF!
Name AltusTax: #REF!
Name AMT: '[12]All Drill'!$AD:$AD
Name Apr01Other: #REF!
Name Apr01SU: #REF!
Name AprHPLP: #REF!
Name ASD: '[10]Balance recorded'!#REF!
Name asdf: [9]Mar01!$A$87:$AR$153
Name aug: #REF!
Name ax: #REF!
Name BAL: #REF!
Name Beg_Cash_Error: '[13]Cash Flow Statement'!#REF!
Name BR: #REF!
Name BS: #REF!
Name BS_Date: [14]Dates!$A$3
Name BU: '[12]All Drill'!$C:$C
Name BUCH331: [15]E!$D$249
Name BUCH332: [15]E!$D$253

Sheet Draft workpaper
A1: 2022 Rate Case
A2: Oncor Electric Delivery Company LLC
A3: Regulatory Asset - Wholesale Distribution Substation Service (Account 1824300)
A4: For Test Year Ending December 31, 2021
A5: Sponsor: W. Alan Ledbetter
A8: WDSS received from Sharyland Utilities by month/year:
A9: 43040 | B9: ='2017 SU pmts'!M14 -> 621058.01
A10: 43070 | B10: ='2018 SU pmts'!M24 -> 978758
A11: 43101 | B11: ='2018 SU pmts'!M25 -> 1004966.9
A12: 43132 | B12: ='2018 SU pmts'!M26 -> 1066736
A13: 43160 | B13: ='2018 SU pmts'!M27 -> 1099749
A14: 43191 | B14: ='2018 SU pmts'!M28 -> 1133321.6
A15: 43221 | B15: ='2018 SU pmts'!M29 -> 1196979.2
A16: 43252 | B16: ='2018 SU pmts'!M30 -> 1246328.1
A17: 43282 | B17: ='2018 SU pmts'!M31 -> 1267172.7
A18: 43313 | B18: ='2018 SU pmts'!M32 -> 1291921.3
A19: 43344 | B19: ='2018 SU pmts'!M33 -> 1323224.9
A20: 43374 | B20: ='2018 SU pmts'!M34 -> 1391374.1
A21: 43405 | B21: ='2019 SU pmts'!M23 -> 1420460.5
A22: 43435 | B22: ='2019 SU pmts'!M24 -> 1429188.2
A23: 43466 | B23: ='2019 SU pmts'!M25 -> 1440053.7
A24: 43497 | B24: ='2019 SU pmts'!M26 -> 1452720
A25: 43525 | B25: ='2019 SU pmts'!M27 -> 1468132.9
A26: 43556 | B26: 1492527.9
A27: Apr-19 portion payable to NTU after acquisition | B27: -1426951.6 | C27: Was NTX A/R at InfraREIT acq; Oncor paid NTU after acquisition of NTU
A28: 43586 | B28: ='2020 SU pmts'!M18-B29 -> 828996.33
A29: May-19 portion payable to NTU after acquisition | B29: -763420.33 | C29: =C27 -> Was NTX A/R at InfraREIT acq; Oncor paid NTU after acquisition of NTU
A30: 43617 | B30: ='2019 SU pmts'!M29 -> 65576
A31: 43647 | B31: ='2019 SU pmts'!M31 -> 63049.75
A32: 43678 | B32: ='2019 SU pmts'!M32 -> 59338.77
A33: 43709 | B33: ='2019 SU pmts'!M28 -> 57916.24
A34: 43739 | B34: ='2019 SU pmts'!M30 -> 57916.24
A35: 43770 | B35: ='2020 SU pmts'!M17 -> 40313.61
A36: Total payments to Sharyland Utilities | B36: =SUM(B9:B35) -> 21307408 | C36: Docket Nos. 46957 and 47649
A38: WDSS received from Oncor NTU by month/year:
A39: 43556 | B39: =-B27 -> 1426951.6
A40: 43586 | B40: =-B29+667992.78-36161.87 -> 1395251.2
A41: 43617 | B41: 1488410.4
A42: 43647 | B42: 1510769.4
A43: 43678 | B43: 1587220.3
...

Sheet Initial Summary
A3: A1824300 WDSS
A4: Payments to SU | B4: =20832145.14 -> 20832145 | C4: thru mar 2019 | E4: =1-E9-E10 -> 0.30782277
A5: STU Jun-Oct 2019 pmts | B5: 303797
A6: SU accrual | B6: 100550.28 | C6: A2429300 | D6: June 2019 | E6: May 2019 16/30
A7: STU 2020 pmts (below) | B7: 171465.88 | C7: Apr, May, Nov 2019
A8: AEP sale of McAllen | B8: -1445018.1 | C8: 43770 | E8: Oncor's change to retail delivery service tariff effective 11-21-2019, removing the cities of Mission and McAllen
A9: NTUSU | B9: =13963856.47+20844126.32+10271967.72 -> 45079951 | E9: =B9/B12 -> 0.6951198
A10: Excel refund | B10: -190831.62 | E10: =B10/B12 -> -0.0029425684
A12: Balance at 6-30-2021 | B12: =SUM(B4:B11) -> 64852059
B14: 2019
A15: Apr | B15: 65576.27
A16: Nov | B16: 40313.61
A17: May | B17: 65576
A18: Paid 2020 | B18: =SUM(B15:B17) -> 171465.88
A22: Notes:
A23: Oncor Sharyland exchange closed November 9, 2017 (Docket No. 47469). Sharyland's retail delivery customers transitioned/became retail delivery customers of Oncor.
A24: Sharyland owned McAllen and Stanton Division substations (37 substations) and billed Oncor for WDSS related to these 37 substations.
A26: Oncor's acquisition of InfraREIT/NTX/NTU closed May 16, 2019. Oncor NTU's tariffs effective May 17, 2019 (Docket No. 48929).
A27: NTU owns 34 substations and bills Oncor for WDSS related to these 34 substations.
A28: Sharyland (STX) continued to own three substations in McAllen Division (Bentsen, Railroad, and Taylor) and billed Oncor for WDSS related to these three substations.
A30: AEP's acquisition of Oncor's facilities in Mission and McAllen; Oncor's updated retail delivery tariff excluded these cities effective November 21, 2019 (Docket No. 49402).
A31: Oncor no longer incurs and Sharyland no longer bills Oncor for WDSS related to SU's three substations since AEP now serves the retail delivery customers in Mission and McAllen.
A33: Docket No. 46957 Order
A34: Finding of Fact No.
A35: 53. Oncor is authorized to establish a regulatory asset to capture the amounts Oncor pays to Sharyland under Sharyland's Wholesale Distribution Substation Service Tariff.
A36: Ordering Paragraph No.
... A44: 10. Oncor may establish a regulatory asset to capture the amounts that Oncor pays to the North Texas Utility under Sharyland Utilities, L.P.'s wholesale-distribution-substation-service tariff until rates are established to recover those costs.

Sheet 2020 SU pmts
B1: %,HLedger,RTU_PUR_DIST_VW,FLEDGER | C1: %,HTemplate,RTU_PUR_DIST_VW,FAPPL_JRNL_ID,B | D1: %,HJournal,RTU_PUR_DIST_VW,FJOURNAL_ID,B | E1: %,HYear,RTU_PUR_DIST_VW,FFISCAL_YEAR,B | F1: %,HPeriod,RTU_PUR_DIST_VW,FACCOUNTING_PERIOD,B | G1: %,HDeptID,RTU_PUR_DIST_VW,FDEPTID,B | H1: %,HAccount,RTU_PUR_DIST_VW,FACCOUNT,B | I1: %,HExpnd Cd,RTU_PUR_DIST_VW,FTU_EC,B | J1: %,HTU Loc,RTU_PUR_DIST_VW,FTU_LOCATION,B | K1: %,HProj,RTU_PUR_DIST_VW,FPROJECT_ID,B | L1: %,HActivity,RTU_PUR_DIST_VW,FTU_ACTIVITY,B | M1: %,HMonetary Amount,RTU_PUR_DIST_VW,FMONETARY_AMOUNT,B | N1: %,HProd,RTU_PUR_DIST_VW,FPRODUCT,B | O1: %,HAffl,RTU_PUR_DIST_VW,FAFFILIATE,B | P1: %,HStatistic Amount,RTU_PUR_DIST_VW,FSTATISTIC_AMOUNT,B | Q1: %,HForeign Amount,RTU_PUR_DIST_VW,FFOREIGN_AMOUNT,B | R1: %,HVoucher ID,RTU_PUR_DIST_VW,FVOUCHER_ID,B | S1: %,HVoucher Number,RTU_PUR_DIST_VW,FTU_VOUCHER_H,B | T1: %,HVendor Name,RTU_PUR_DIST_VW,FTU_VENDOR_N,B | U1: %,HNew Vendor ID,RTU_PUR_DIST_VW,FVENDOR_ID,AA,B | V1: %,Hvendor,RTU_PUR_DIST_VW,FTU_VENDOR_H,B | W1: %,Hcheckno,RTU_PUR_DIST_VW,FTU_CHECK_H,B | X1: %,HInvoice Number,RTU_PUR_DIST_VW,FTU_INVOICE_H,B | Y1: %,Hpo,RTU_PUR_DIST_VW,FTU_PO_H,B | Z1: %,HStock#,RTU_PUR_DIST_VW,FTU_STOCK_H,B | AA1: %,HWarehouse,RTU_PUR_DIST_VW,FTU_WHSE_H,B | AB1: %,HAcctg Date,RTU_PUR_DIST_VW,FACCOUNTING_DT,B | AC1: %,HGL Unit,RTU_PUR_DIST_VW,FBUSINESS_UNIT_GL,B | AD1: %,HCurrency,RTU_PUR_DIST_VW,FCURRENCY_CD,B | AE1: %,HForeign Currency,RTU_PUR_DIST_VW,FFOREIGN_CURRENCY,B | AF1: %,HGL Status,RTU_PUR_DIST_VW,FGL_DISTRIB_STATUS,B | AG1: %,HPC Status,RTU_PUR_DIST_VW,FPC_DISTRIB_STATUS,B | AH1: %,HDate,RTU_PUR_DIST_VW,FJOURNAL_DATE,B | AI1: %,HLedger Grp,RTU_PUR_DIST_VW,FLEDGER_GROUP,B | AJ1: %,HInstance,RTU_PUR_DIST_VW,FPROCESS_INSTANCE,B | AK1: %,HRef,RTU_PUR_DIST_VW,FJRNL_LN_REF,B | AL1: %,HJournal Descrption,RTU_PUR_DIST_VW,FJRNL_DESCR,B | AM1: %,HStatistic,RTU_PUR_DIST_VW,FSTATISTIC_CD,B | AN1: %,HWork Order,RTU_PUR_DIST_VW,FTU_WO,B | AO1: %,Hfdr src cd,RTU_PUR_DIST_VW,FTU_FEEDER_SRC_C,B | AP1: %,HTUloadflag,RTU_PUR_DIST_VW,FTU_LOADING_FLAG,B | AQ1: %,HTUerrprcs,RTU_PUR_DIST_VW,FTU_ERR_PROCESS_INS,B | AR1: %,Htaxcode,RTU_PUR_DIST_VW,FTU_TAX_C,B | AS1: %,Hvouline,RTU_PUR_DIST_VW,FTU_VOU_LINE_H,B | AT1: %,Hpoline,RTU_PUR_DIST_VW,FTU_PO_LINE_H,B | AU1: %,Htaxact,RTU_PUR_DIST_VW,FTU_TAX_ACT_C,B | AV1: %,Hvehcard,RTU_PUR_DIST_VW,FTU_VEH_CARD_H,B | AW1: %,HgasticketD,RTU_PUR_DIST_VW,FTU_GASTICKET_INV_D,B | AX1: %,HMaterialRR,RTU_PUR_DIST_VW,FTU_MRR,B | AY1: %,HPosting Date Time Stamp,RTU_PUR_DIST_VW,FTU_POST_D,B | AZ1: %,HSeq,RTU_PUR_DIST_VW,FTU_SEQ_H,B | BA1: %,HFDRLNeffdt,RTU_PUR_DIST_VW,FTU_FDR_LINE_EFF_D,B | BB1: %,HUnit,RTU_PUR_DIST_VW,FBUSINESS_UNIT,B | BC1: %,HFile ID,RTU_PUR_DIST_VW,FTU_FEEDER_FILE_ID,B | BD1: %,Htucmmtln1,RTU_PUR_DIST_VW,FTU_CMMT_LINE1,B | BE1: %,HID,RTU_PUR_DIST_VW,FEX_DOC_ID,AA,B | BF1: %,HEmplid,RTU_PUR_DIST_VW,FEMPLID,AA,B
B2: TU FINANCIAL INFORMATION MANAGEMENT REPORT | BZ2: =NvsElapsedTime -> 8.1018523e-05
B4: PURCHASE DRILL
A6: %,OH | B6: Ledger | C6: Template | D6: Journal | E6: Year | F6: Period | G6: DeptID | H6: Account | I6: Expnd Cd | J6: TU Loc | K6: Proj | L6: Activity | M6: Monetary Amount | N6: Prod | O6: Affl | P6: Statistic Amount | Q6: Foreign Amount | R6: New Voucher ID | S6: PMMS Voucher Number | T6: Vendor Name | U6: New Vendor ID | V6: PMMS Vendor ID | W6: checkno | X6: Invoice Number | Y6: po | Z6: Stock# | AA6: Warehouse | AB6: Acctg Date | AC6: GL Unit | AD6: Currency | AE6: Currency | AF6: Status | AG6: Status | AH6: Date | AI6: Ledger Grp | AJ6: Instance | AK6: Ref | AL6: Journal Descrption | AM6: Statistic | AN6: Work Order | AO6: fdr src cd | AP6: TUloadflag | AQ6: TUerrprcs | AR6: taxcode | AS6: vouline | AT6: poline | AU6: taxact | AV6: vehcard | AW6: gasticketD | AX6: MaterialRR | AY6: Posting Date Time Stamp | AZ6: Seq | BA6: FDRLNeffdt | BB6: Unit | BC6: File ID | BD6: Local PO No | BE6: Expense Report ID | BF6: Emplid
A7: %,OA | B7: ACTUALS | C7: PURCHASE | D7: PUR0943878 | E7: 2020 | F7: 3 | G7: 528400 | H7: 1824300 | I7: 000 | J7: 0000 | K7: 00007100 | L7: 7100 | M7: 65576.27 | N7: 000000 | P7: 0 | Q7: 65576.27 | R7: 00421337 | S7: 00421337 | T7: SHARYLAND UTILITIES | U7: 0007498 | V7: 010998453 | W7: 0000214673 | X7: 180000290A | AB7: 2020-03-17 | AC7: ESD | AD7: USD | AE7: USD | AF7: Dist | AG7: D | AH7: 2020-03-17 | AI7: ACTUALS | AJ7: 1839854 | AO7: 24 | AP7: 3 | AQ7: 0 | AS7: 0 | AT7: 0 | AY7: 2020-03-17-21.02.43.047874 | AZ7: 368 | BA7: 2020-03-17 | BB7: ESD | BC7: APV024
B8: ACTUALS | C8: PURCHASE | D8: PUR0944404 | E8: 2020 | F8: 4 | G8: 528400 | H8: 1824300 | I8: 000 | J8: 0000 | K8: 00007100 | L8: 7100 | M8: 40313.61 | N8: 000000 | P8: 0 | Q8: 40313.61 | R8: 00423966 | S8: 00423966 | T8: SHARYLAND UTILITIES | U8: 0007498 | V8: 010998453 | W8: 0000217519 | X8: 1800000155 | AB8: 2020-04-02 | AC8: ESD | AD8: USD | AE8: USD | AF8: Dist | AG8: D | AH8: 2020-04-02 | AI8: ACTUALS | AJ8: 1854273 | AO8: 24 | AP8: 3 | AQ8: 0 | AS8: 0 | AT8: 0 | AY8: 2020-04-02-20.09.19.376008 | AZ8: 861 | BA8: 2020-04-02 | BB8: ESD | BC8: APV024
B9: ACTUALS | C9: PURCHASE | D9: PUR0949443 | E9: 2020 | F9: 9 | G9: 528400 | H9: 1824300 | I9: 000 | J9: 0000 | K9: 00007100 | L9: 7100 | M9: 65576 | N9: 000000 | P9: 0 | Q9: 65576 | R9: 00455061 | S9: 00455061 | T9: SHARYLAND UTILITIES LP | U9: 0007498 | V9: 010998451 | W9: 0000231364 | X9: 18000006344 | AB9: 2020-09-15 | AC9: ESD | AD9: USD | AE9: USD | AF9: Dist | AG9: D | AH9: 2020-09-15 | AI9: ACTUALS | AJ9: 1998447 | AO9: 24 | AP9: 3 | AQ9: 0 | AS9: 0 | AT9: 0 | AY9: 2020-09-15-20.25.50.910312 | AZ9: 688 | BA9: 2020-09-15 | BB9: ESD | BC9: APV024
A11: %,OT | M11: =SUM(M7:M10) -> 171465.88 | P11: =SUM(P7:P10) -> 0 | Q11: =SUM(Q7:Q10) -> 171465.88
B13: Report generated: | C13: =NvsEndTime -> 44405.33
B14: ="Y" -> Y
L15: WDSS month
L16: 43556 | M16: =M7 -> 65576.27
L17: 43770 | M17: =M8 -> 40313.61
L18: 43586 | M18: =M9 -> 65576 | P18: Where is the actual invoice? DA reflect invoice # 1800000344 not 18000006344 as shown above
P19: Only see "May19_reads" in monthly journals 937601

Sheet 2019 SU pmts
B1: %,HLedger,RTU_PUR_DIST_VW,FLEDGER | C1: %,HTemplate,RTU_PUR_DIST_VW,FAPPL_JRNL_ID,B | D1: %,HJournal,RTU_PUR_DIST_VW,FJOURNAL_ID,B | E1: %,HYear,RTU_PUR_DIST_VW,FFISCAL_YEAR,B | F1: %,HPeriod,RTU_PUR_DIST_VW,FACCOUNTING_PERIOD,B | G1: %,HDeptID,RTU_PUR_DIST_VW,FDEPTID,B | H1: %,HAccount,RTU_PUR_DIST_VW,FACCOUNT,B | I1: %,HExpnd Cd,RTU_PUR_DIST_VW,FTU_EC,B | J1: %,HTU Loc,RTU_PUR_DIST_VW,FTU_LOCATION,B | K1: %,HProj,RTU_PUR_DIST_VW,FPROJECT_ID,B | L1: %,HActivity,RTU_PUR_DIST_VW,FTU_ACTIVITY,B | M1: %,HMonetary Amount,RTU_PUR_DIST_VW,FMONETARY_AMOUNT,B | N1: %,HProd,RTU_PUR_DIST_VW,FPRODUCT,B | O1: %,HAffl,RTU_PUR_DIST_VW,FAFFILIATE,B | P1: %,HStatistic Amount,RTU_PUR_DIST_VW,FSTATISTIC_AMOUNT,B | Q1: %,HForeign Amount,RTU_PUR_DIST_VW,FFOREIGN_AMOUNT,B | R1: %,HVoucher ID,RTU_PUR_DIST_VW,FVOUCHER_ID,B | S1: %,HVoucher Number,RTU_PUR_DIST_VW,FTU_VOUCHER_H,B | T1: %,HVendor Name,RTU_PUR_DIST_VW,FTU_VENDOR_N,B | U1: %,HNew Vendor ID,RTU_PUR_DIST_VW,FVENDOR_ID,AA,B | V1: %,Hvendor,RTU_PUR_DIST_VW,FTU_VENDOR_H,B | W1: %,Hcheckno,RTU_PUR_DIST_VW,FTU_CHECK_H,B | X1: %,HInvoice Number,RTU_PUR_DIST_VW,FTU_INVOICE_H,B | Y1: %,Hpo,RTU_PUR_DIST_VW,FTU_PO_H,B | Z1: %,HStock#,RTU_PUR_DIST_VW,FTU_STOCK_H,B | AA1: %,HWarehouse,RTU_PUR_DIST_VW,FTU_WHSE_H,B | AB1: %,HAcctg Date,RTU_PUR_DIST_VW,FACCOUNTING_DT,B | AC1: %,HGL Unit,RTU_PUR_DIST_VW,FBUSINESS_UNIT_GL,B | AD1: %,HCurrency,RTU_PUR_DIST_VW,FCURRENCY_CD,B | AE1: %,HForeign Currency,RTU_PUR_DIST_VW,FFOREIGN_CURRENCY,B | AF1: %,HGL Status,RTU_PUR_DIST_VW,FGL_DISTRIB_STATUS,B | AG1: %,HPC Status,RTU_PUR_DIST_VW,FPC_DISTRIB_STATUS,B | AH1: %,HDate,RTU_PUR_DIST_VW,FJOURNAL_DATE,B | AI1: %,HLedger Grp,RTU_PUR_DIST_VW,FLEDGER_GROUP,B | AJ1: %,HInstance,RTU_PUR_DIST_VW,FPROCESS_INSTANCE,B | AK1: %,HRef,RTU_PUR_DIST_VW,FJRNL_LN_REF,B | AL1: %,HJournal Descrption,RTU_PUR_DIST_VW,FJRNL_DESCR,B | AM1: %,HStatistic,RTU_PUR_DIST_VW,FSTATISTIC_CD,B | AN1: %,HWork Order,RTU_PUR_DIST_VW,FTU_WO,B | AO1: %,Hfdr src cd,RTU_PUR_DIST_VW,FTU_FEEDER_SRC_C,B | AP1: %,HTUloadflag,RTU_PUR_DIST_VW,FTU_LOADING_FLAG,B | AQ1: %,HTUerrprcs,RTU_PUR_DIST_VW,FTU_ERR_PROCESS_INS,B | AR1: %,Htaxcode,RTU_PUR_DIST_VW,FTU_TAX_C,B | AS1: %,Hvouline,RTU_PUR_DIST_VW,FTU_VOU_LINE_H,B | AT1: %,Hpoline,RTU_PUR_DIST_VW,FTU_PO_LINE_H,B | AU1: %,Htaxact,RTU_PUR_DIST_VW,FTU_TAX_ACT_C,B | AV1: %,Hvehcard,RTU_PUR_DIST_VW,FTU_VEH_CARD_H,B | AW1: %,HgasticketD,RTU_PUR_DIST_VW,FTU_GASTICKET_INV_D,B | AX1: %,HMaterialRR,RTU_PUR_DIST_VW,FTU_MRR,B | AY1: %,HPosting Date Time Stamp,RTU_PUR_DIST_VW,FTU_POST_D,B | AZ1: %,HSeq,RTU_PUR_DIST_VW,FTU_SEQ_H,B | BA1: %,HFDRLNeffdt,RTU_PUR_DIST_VW,FTU_FDR_LINE_EFF_D,B | BB1: %,HUnit,RTU_PUR_DIST_VW,FBUSINESS_UNIT,B | BC1: %,HFile ID,RTU_PUR_DIST_VW,FTU_FEEDER_FILE_ID,B | BD1: %,Htucmmtln1,RTU_PUR_DIST_VW,FTU_CMMT_LINE1,B | BE1: %,HID,RTU_PUR_DIST_VW,FEX_DOC_ID,AA,B | BF1: %,HEmplid,RTU_PUR_DIST_VW,FEMPLID,AA,B
B2: TU FINANCIAL INFORMATION MANAGEMENT REPORT | BZ2: =NvsElapsedTime -> 6.9444446e-05
B4: PURCHASE DRILL
A6: %,OH | B6: Ledger | C6: Template | D6: Journal | E6: Year | F6: Period | G6: DeptID | H6: Account | I6: Expnd Cd | J6: TU Loc | K6: Proj | L6: Activity | M6: Monetary Amount | N6: Prod | O6: Affl | P6: Statistic Amount | Q6: Foreign Amount | R6: New Voucher ID | S6: PMMS Voucher Number | T6: Vendor Name | U6: New Vendor ID | V6: PMMS Vendor ID | W6: checkno | X6: Invoice Number | Y6: po | Z6: Stock# | AA6: Warehouse | AB6: Acctg Date | AC6: GL Unit | AD6: Currency | AE6: Currency | AF6: Status | AG6: Status | AH6: Date | AI6: Ledger Grp | AJ6: Instance | AK6: Ref | AL6: Journal Descrption | AM6: Statistic | AN6: Work Order | AO6: fdr src cd | AP6: TUloadflag | AQ6: TUerrprcs | AR6: taxcode | AS6: vouline | AT6: poline | AU6: taxact | AV6: vehcard | AW6: gasticketD | AX6: MaterialRR | AY6: Posting Date Time Stamp | AZ6: Seq | BA6: FDRLNeffdt | BB6: Unit | BC6: File ID | BD6: Local PO No | BE6: Expense Report ID | BF6: Emplid
A7: %,OA | B7: ACTUALS | C7: PURCHASE | D7: PUR0930750 | E7: 2019 | F7: 1 | G7: 528400 | H7: 1824300 | I7: 000 | J7: 0000 | K7: 00007100 | L7: 7100 | M7: 1420460.5 | N7: 000000 | P7: 0 | Q7: 1420460.5 | R7: 00345591 | S7: 00345591 | T7: SHARYLAND UTILITIES | U7: 0007498 | V7: 010998453 | W7: 0000163899 | X7: 1800000719 | AB7: 2019-01-11 | AC7: ESD | AD7: USD | AE7: USD | AF7: Dist | AG7: D | AH7: 2019-01-11 | AI7: ACTUALS | AJ7: 1467315 | AO7: 24 | AP7: 3 | AQ7: 0 | AS7: 0 | AT7: 0 | AY7: 2019-01-11-19.36.04.850295 | AZ7: 319 | BA7: 2019-01-11 | BB7: ESD | BC7: APV024
B8: ACTUALS | C8: PURCHASE | D8: PUR0931782 | E8: 2019 | F8: 2 | G8: 528400 | H8: 1824300 | I8: 000 | J8: 0000 | K8: 00007100 | L8: 7100 | M8: 1429188.2 | N8: 000000 | P8: 0 | Q8: 1429188.2 | R8: 00353338 | S8: 00353338 | T8: SHARYLAND UTILITIES LP | U8: 0007498 | V8: 010998451 | W8: 0000167778 | X8: 180000002 | AB8: 2019-02-20 | AC8: ESD | AD8: USD | AE8: USD | AF8: Dist | AG8: D | AH8: 2019-02-20 | AI8: ACTUALS | AJ8: 1500616 | AO8: 24 | AP8: 3 | AQ8: 0 | AS8: 0 | AT8: 0 | AY8: 2019-02-20-20.55.42.581204 | AZ8: 194 | BA8: 2019-02-20 | BB8: ESD | BC8: APV024
B9: ACTUALS | C9: PURCHASE | D9: PUR0932444 | E9: 2019 | F9: 3 | G9: 528400 | H9: 1824300 | I9: 000 | J9: 0000 | K9: 00007100 | L9: 7100 | M9: 1440053.7 | N9: 000000 | P9: 0 | Q9: 1440053.7 | R9: 00357272 | S9: 00357272 | T9: SHARYLAND UTILITIES | U9: 0007498 | V9: 010998453 | W9: 0000171154 | X9: 1800000094 | AB9: 2019-03-14 | AC9: ESD | AD9: USD | AE9: USD | AF9: Dist | AG9: D | AH9: 2019-03-14 | AI9: ACTUALS | AJ9: 1519518 | AO9: 24 | AP9: 3 | AQ9: 0 | AS9: 0 | AT9: 0 | AY9: 2019-03-14-20.04.37.072298 | AZ9: 669 | BA9: 2019-03-14 | BB9: ESD | BC9: APV024
B10: ACTUALS | C10: PURCHASE | D10: PUR0932729 | E10: 2019 | F10: 3 | G10: 528400 | H10: 1824300 | I10: 000 | J10: 0000 | K10: 00007100 | L10: 7100 | M10: 1452720 | N10: 000000 | P10: 0 | Q10: 1452720 | R10: 00358855 | S10: 00358855 | T10: SHARYLAND UTILITIES | U10: 0007498 | V10: 010998453 | W10: 0000174757 | X10: 1800000159 | AB10: 2019-03-27 | AC10: ESD | AD10: USD | AE10: USD | AF10: Dist | AG10: D | AH10: 2019-03-27 | AI10: ACTUALS | AJ10: 1530479 | AO10: 24 | AP10: 3 | AQ10: 0 | AS10: 0 | AT10: 0 | AY10: 2019-03-27-22.45.37.168613 | AZ10: 440 | BA10: 2019-03-27 | BB10: ESD | BC10: APV024
B11: ACTUALS | C11: PURCHASE | D11: PUR0933791 | E11: 2019 | F11: 5 | G11: 528400 | H11: 1824300 | I11: 000 | J11: 0000 | K11: 00007100 | L11: 7100 | M11: 1468132.9 | N11: 000000 | P11: 0 | Q11: 1468132.9 | R11: 00365951 | S11: 00365951 | T11: SHARYLAND UTILITIES | U11: 0007498 | V11: 010998453 | W11: 0000177568 | X11: 1800000215 | AB11: 2019-05-02 | AC11: ESD | AD11: USD | AE11: USD | AF11: Dist | AG11: D | AH11: 2019-05-02 | AI11: ACTUALS | AJ11: 1561708 | AO11: 24 | AP11: 3 | AQ11: 0 | AS11: 0 | AT11: 0 | AY11: 2019-05-02-20.05.46.274936 | AZ11: 58 | BA11: 2019-05-02 | BB11: ESD | BC11: APV024
B12: ACTUALS | C12: PURCHASE | D12: PUR0940978 | E12: 2019 | F12: 12 | G12: 528400 | H12: 1824300 | I12: 000 | J12: 0000 | K12: 00007100 | L12: 7100 | M12: 57916.24 | N12: 000000 | P12: 0 | Q12: 57916.24 | R12: 00406096 | S12: 00406096 | T12: SHARYLAND UTILITIES | U12: 0007498 | V12: 010998453 | W12: 0000202934 | X12: 1800000499 | AB12: 2019-12-19 | AC12: ESD | AD12: USD | AE12: USD | AF12: Dist | AG12: D | AH12: 2019-12-19 | AI12: ACTUALS | AJ12: 1765263 | AO12: 24 | AP12: 3 | AQ12: 0 | AS12: 0 | AT12: 0 | AY12: 2019-12-19-20.05.38.678020 | AZ12: 701 | BA12: 2019-12-19 | BB12: ESD | BC12: APV024
B13: ACTUALS | C13: PURCHASE | D13: PUR0940978 | E13: 2019 | F13: 12 | G13: 528400 | H13: 1824300 | I13: 000 | J13: 0000 | K13: 00007100 | L13: 7100 | M13: 65576 | N13: 000000 | P13: 0 | Q13: 65576 | R13: 00406097 | S13: 00406097 | T13: SHARYLAND UTILITIES LP | U13: 0007498 | V13: 010998451 | W13: 0000202933 | X13: 1800000354 | AB13: 2019-12-19 | AC13: ESD | AD13: USD | AE13: USD | AF13: Dist | AG13: D | AH13: 2019-12-19 | AI13: ACTUALS | AJ13: 1765263 | AO13: 24 | AP13: 3 | AQ13: 0 | AS13: 0 | AT13: 0 | AY13: 2019-12-19-20.05.38.678020 | AZ13: 703 | BA13: 2019-12-19 | BB13: ESD | BC13: APV024
B14: ACTUALS | C14: PURCHASE | D14: PUR0940978 | E14: 2019 | F14: 12 | G14: 528400 | H14: 1824300 | I14: 000 | J14: 0000 | K14: 00007100 | L14: 7100 | M14: 57916.24 | N14: 000000 | P14: 0 | Q14: 57916.24 | R14: 00406066 | S14: 00406066 | T14: SHARYLAND UTILITIES LP | U14: 0007498 | V14: 010998451 | W14: 0000202933 | X14: 1800000549 | AB14: 2019-12-19 | AC14: ESD | AD14: USD | AE14: USD | AF14: Dist | AG14: D | AH14: 2019-12-19 | AI14: ACTUALS | AJ14: 1765263 | AO14: 24 | AP14: 3 | AQ14: 0 | AS14: 0 | AT14: 0 | AY14: 2019-12-19-20.05.38.678020 | AZ14: 344 | BA14: 2019-12-19 | BB14: ESD | BC14: APV024
B15: ACTUALS | C15: PURCHASE | D15: PUR0940978 | E15: 2019 | F15: 12 | G15: 528400 | H15: 1824300 | I15: 000 | J15: 0000 | K15: 00007100 | L15: 7100 | M15: 63049.75 | N15: 000000 | P15: 0 | Q15: 63049.75 | R15: 00406088 | S15: 00406088 | T15: SHARYLAND UTILITIES LP | U15: 0007498 | V15: 010998451 | W15: 0000202933 | X15: 1800000406 | AB15: 2019-12-19 | AC15: ESD | AD15: USD | AE15: USD | AF15: Dist | AG15: D | AH15: 2019-12-19 | AI15: ACTUALS | AJ15: 1765263 | AO15: 24 | AP15: 3 | AQ15: 0 | AS15: 0 | AT15: 0 | AY15: 2019-12-19-20.05.38.678020 | AZ15: 977 | BA15: 2019-12-19 | BB15: ESD | BC15: APV024
B16: ACTUALS | C16: PURCHASE | D16: PUR0940978 | E16: 2019 | F16: 12 | G16: 528400 | H16: 1824300 | I16: 000 | J16: 0000 | K16: 00007100 | L16: 7100 | M16: 59338.77 | N16: 000000 | P16: 0 | Q16: 59338.77 | R16: 00406080 | S16: 00406080 | T16: SHARYLAND UTILITIES LP | U16: 0007498 | V16: 010998451 | W16: 0000202933 | X16: 1800000457 | AB16: 2019-12-19 | AC16: ESD | AD16: USD | AE16: USD | AF16: Dist | AG16: D | AH16: 2019-12-19 | AI16: ACTUALS | AJ16: 1765263 | AO16: 24 | AP16: 3 | AQ16: 0 | AS16: 0 | AT16: 0 | AY16: 2019-12-19-20.05.38.678020 | AZ16: 1696 | BA16: 2019-12-19 | BB16: ESD | BC16: APV024
A18: %,OT | M18: =SUM(M7:M17) -> 7514352.2 | P18: =SUM(P7:P17) -> 0 | Q18: =SUM(Q7:Q17) -> 7514352.2
B20: Report generated: | C20: =NvsEndTime -> 44405.342
B21: ="Y" -> Y
L22: WDSS month
L23: 43405 | M23: =M7 -> 1420460.5
L24: 43435 | M24: =M8 -> 1429188.2
L25: 43466 | M25: =M9 -> 1440053.7
L26: 43497 | M26: =M10 -> 1452720
L27: 43525 | M27: =M11 -> 1468132.9
L28: 43709 | M28: =M12 -> 57916.24 | N28: AP/voucher doc backup is invoice 1800000549 | S28: Sep WDSS inv 1800000499 is provided in UJE 937601 for Nov 2019; see last worksheet in this file for copy of invoice
L29: 43617 | M29: =M13 -> 65576
L30: 43739 | M30: =M14 -> 57916.24 | N30: Invoice 1800000549 is provided as documentation in both voucher 00406066 and 00406096
L31: 43647 | M31: =M15 -> 63049.75
L32: 43678 | M32: =M16 -> 59338.77

Sheet 2018 SU pmts
B1: %,HLedger,RTU_PUR_DIST_VW,FLEDGER | C1: %,HTemplate,RTU_PUR_DIST_VW,FAPPL_JRNL_ID,B | D1: %,HJournal,RTU_PUR_DIST_VW,FJOURNAL_ID,B | E1: %,HYear,RTU_PUR_DIST_VW,FFISCAL_YEAR,B | F1: %,HPeriod,RTU_PUR_DIST_VW,FACCOUNTING_PERIOD,B | G1: %,HDeptID,RTU_PUR_DIST_VW,FDEPTID,B | H1: %,HAccount,RTU_PUR_DIST_VW,FACCOUNT,B | I1: %,HExpnd Cd,RTU_PUR_DIST_VW,FTU_EC,B | J1: %,HTU Loc,RTU_PUR_DIST_VW,FTU_LOCATION,B | K1: %,HProj,RTU_PUR_DIST_VW,FPROJECT_ID,B | L1: %,HActivity,RTU_PUR_DIST_VW,FTU_ACTIVITY,B | M1: %,HMonetary Amount,RTU_PUR_DIST_VW,FMONETARY_AMOUNT,B | N1: %,HProd,RTU_PUR_DIST_VW,FPRODUCT,B | O1: %,HAffl,RTU_PUR_DIST_VW,FAFFILIATE,B | P1: %,HStatistic Amount,RTU_PUR_DIST_VW,FSTATISTIC_AMOUNT,B | Q1: %,HForeign Amount,RTU_PUR_DIST_VW,FFOREIGN_AMOUNT,B | R1: %,HVoucher ID,RTU_PUR_DIST_VW,FVOUCHER_ID,B | S1: %,HVoucher Number,RTU_PUR_DIST_VW,FTU_VOUCHER_H,B | T1: %,HVendor Name,RTU_PUR_DIST_VW,FTU_VENDOR_N,B | U1: %,HNew Vendor ID,RTU_PUR_DIST_VW,FVENDOR_ID,AA,B | V1: %,Hvendor,RTU_PUR_DIST_VW,FTU_VENDOR_H,B | W1: %,Hcheckno,RTU_PUR_DIST_VW,FTU_CHECK_H,B | X1: %,HInvoice Number,RTU_PUR_DIST_VW,FTU_INVOICE_H,B | Y1: %,Hpo,RTU_PUR_DIST_VW,FTU_PO_H,B | Z1: %,HStock#,RTU_PUR_DIST_VW,FTU_STOCK_H,B | AA1: %,HWarehouse,RTU_PUR_DIST_VW,FTU_WHSE_H,B | AB1: %,HAcctg Date,RTU_PUR_DIST_VW,FACCOUNTING_DT,B | AC1: %,HGL Unit,RTU_PUR_DIST_VW,FBUSINESS_UNIT_GL,B | AD1: %,HCurrency,RTU_PUR_DIST_VW,FCURRENCY_CD,B | AE1: %,HForeign Currency,RTU_PUR_DIST_VW,FFOREIGN_CURRENCY,B | AF1: %,HGL Status,RTU_PUR_DIST_VW,FGL_DISTRIB_STATUS,B | AG1: %,HPC Status,RTU_PUR_DIST_VW,FPC_DISTRIB_STATUS,B | AH1: %,HDate,RTU_PUR_DIST_VW,FJOURNAL_DATE,B | AI1: %,HLedger Grp,RTU_PUR_DIST_VW,FLEDGER_GROUP,B | AJ1: %,HInstance,RTU_PUR_DIST_VW,FPROCESS_INSTANCE,B | AK1: %,HRef,RTU_PUR_DIST_VW,FJRNL_LN_REF,B | AL1: %,HJournal Descrption,RTU_PUR_DIST_VW,FJRNL_DESCR,B | AM1: %,HStatistic,RTU_PUR_DIST_VW,FSTATISTIC_CD,B | AN1: %,HWork Order,RTU_PUR_DIST_VW,FTU_WO,B | AO1: %,Hfdr src cd,RTU_PUR_DIST_VW,FTU_FEEDER_SRC_C,B | AP1: %,HTUloadflag,RTU_PUR_DIST_VW,FTU_LOADING_FLAG,B | AQ1: %,HTUerrprcs,RTU_PUR_DIST_VW,FTU_ERR_PROCESS_INS,B | AR1: %,Htaxcode,RTU_PUR_DIST_VW,FTU_TAX_C,B | AS1: %,Hvouline,RTU_PUR_DIST_VW,FTU_VOU_LINE_H,B | AT1: %,Hpoline,RTU_PUR_DIST_VW,FTU_PO_LINE_H,B | AU1: %,Htaxact,RTU_PUR_DIST_VW,FTU_TAX_ACT_C,B | AV1: %,Hvehcard,RTU_PUR_DIST_VW,FTU_VEH_CARD_H,B | AW1: %,HgasticketD,RTU_PUR_DIST_VW,FTU_GASTICKET_INV_D,B | AX1: %,HMaterialRR,RTU_PUR_DIST_VW,FTU_MRR,B | AY1: %,HPosting Date Time Stamp,RTU_PUR_DIST_VW,FTU_POST_D,B | AZ1: %,HSeq,RTU_PUR_DIST_VW,FTU_SEQ_H,B | BA1: %,HFDRLNeffdt,RTU_PUR_DIST_VW,FTU_FDR_LINE_EFF_D,B | BB1: %,HUnit,RTU_PUR_DIST_VW,FBUSINESS_UNIT,B | BC1: %,HFile ID,RTU_PUR_DIST_VW,FTU_FEEDER_FILE_ID,B | BD1: %,Htucmmtln1,RTU_PUR_DIST_VW,FTU_CMMT_LINE1,B | BE1: %,HID,RTU_PUR_DIST_VW,FEX_DOC_ID,AA,B | BF1: %,HEmplid,RTU_PUR_DIST_VW,FEMPLID,AA,B
B2: TU FINANCIAL INFORMATION MANAGEMENT REPORT | BZ2: =NvsElapsedTime -> 5.7870369e-05
B4: PURCHASE DRILL
A6: %,OH | B6: Ledger | C6: Template | D6: Journal | E6: Year | F6: Period | G6: DeptID | H6: Account | I6: Expnd Cd | J6: TU Loc | K6: Proj | L6: Activity | M6: Monetary Amount | N6: Prod | O6: Affl | P6: Statistic Amount | Q6: Foreign Amount | R6: New Voucher ID | S6: PMMS Voucher Number | T6: Vendor Name | U6: New Vendor ID | V6: PMMS Vendor ID | W6: checkno | X6: Invoice Number | Y6: po | Z6: Stock# | AA6: Warehouse | AB6: Acctg Date | AC6: GL Unit | AD6: Currency | AE6: Currency | AF6: Status | AG6: Status | AH6: Date | AI6: Ledger Grp | AJ6: Instance | AK6: Ref | AL6: Journal Descrption | AM6: Statistic | AN6: Work Order | AO6: fdr src cd | AP6: TUloadflag | AQ6: TUerrprcs | AR6: taxcode | AS6: vouline | AT6: poline | AU6: taxact | AV6: vehcard | AW6: gasticketD | AX6: MaterialRR | AY6: Posting Date Time Stamp | AZ6: Seq | BA6: FDRLNeffdt | BB6: Unit | BC6: File ID | BD6: Local PO No | BE6: Expense Report ID | BF6: Emplid
A7: %,OA | B7: ACTUALS | C7: PURCHASE | D7: PUR0921422 | E7: 2018 | F7: 2 | G7: 528400 | H7: 1824300 | I7: 000 | J7: 0000 | K7: 00007100 | L7: 7100 | M7: 978758 | N7: 000000 | P7: 0 | Q7: 978758 | R7: 00287398 | S7: 00287398 | T7: SHARYLAND UTILITIES | U7: 0007498 | V7: 010998453 | W7: 0000127375 | X7: 1800000200 | AB7: 2018-02-02 | AC7: ESD | AD7: USD | AE7: USD | AF7: Dist | AG7: D | AH7: 2018-02-02 | AI7: ACTUALS | AJ7: 1169363 | AO7: 24 | AP7: 3 | AQ7: 0 | AS7: 0 | AT7: 0 | AY7: 2018-02-02-19.30.56.848215 | AZ7: 453 | BA7: 2018-02-02 | BB7: ESD | BC7: APV024
B8: ACTUALS | C8: PURCHASE | D8: PUR0921930 | E8: 2018 | F8: 2 | G8: 528400 | H8: 1824300 | I8: 000 | J8: 0000 | K8: 00007100 | L8: 7100 | M8: 1004966.9 | N8: 000000 | P8: 0 | Q8: 1004966.9 | R8: 00290026 | S8: 00290026 | T8: SHARYLAND UTILITIES | U8: 0007498 | V8: 010998453 | W8: 0000130778 | X8: 1800000068 | AB8: 2018-02-21 | AC8: ESD | AD8: USD | AE8: USD | AF8: Dist | AG8: D | AH8: 2018-02-21 | AI8: ACTUALS | AJ8: 1186311 | AO8: 24 | AP8: 3 | AQ8: 0 | AS8: 0 | AT8: 0 | AY8: 2018-02-21-20.43.42.757971 | AZ8: 377 | BA8: 2018-02-21 | BB8: ESD | BC8: APV024
B9: ACTUALS | C9: PURCHASE | D9: PUR0923035 | E9: 2018 | F9: 4 | G9: 528400 | H9: 1824300 | I9: 000 | J9: 0000 | K9: 00007100 | L9: 7100 | M9: 1066736 | N9: 000000 | P9: 0 | Q9: 1066736 | R9: 00296831 | S9: 00296831 | T9: SHARYLAND UTILITIES | U9: 0007498 | V9: 010998453 | W9: 0000133926 | X9: 1800000128 | AB9: 2018-04-02 | AC9: ESD | AD9: USD | AE9: USD | AF9: Dist | AG9: D | AH9: 2018-04-02 | AI9: ACTUALS | AJ9: 1224622 | AO9: 24 | AP9: 3 | AQ9: 0 | AS9: 0 | AT9: 0 | AY9: 2018-04-02-20.36.11.734949 | AZ9: 289 | BA9: 2018-04-02 | BB9: ESD | BC9: APV024
B10: ACTUALS | C10: PURCHASE | D10: PUR0924112 | E10: 2018 | F10: 5 | G10: 528400 | H10: 1824300 | I10: 000 | J10: 0000 | K10: 00007100 | L10: 7100 | M10: 1099749 | N10: 000000 | P10: 0 | Q10: 1099749 | R10: 00303916 | S10: 00303916 | T10: SHARYLAND UTILITIES | U10: 0007498 | V10: 010998453 | W10: 0000137008 | X10: 18000001280318 | AB10: 2018-05-04 | AC10: ESD | AD10: USD | AE10: USD | AF10: Dist | AG10: D | AH10: 2018-05-04 | AI10: ACTUALS | AJ10: 1253223 | AO10: 24 | AP10: 3 | AQ10: 0 | AS10: 0 | AT10: 0 | AY10: 2018-05-04-19.37.45.146254 | AZ10: 191 | BA10: 2018-05-04 | BB10: ESD | BC10: APV024
B11: ACTUALS | C11: PURCHASE | D11: PUR0924504 | E11: 2018 | F11: 5 | G11: 528400 | H11: 1824300 | I11: 000 | J11: 0000 | K11: 00007100 | L11: 7100 | M11: 1133321.6 | N11: 000000 | P11: 0 | Q11: 1133321.6 | R11: 00306582 | S11: 00306582 | T11: SHARYLAND UTILITIES | U11: 0007498 | V11: 010998453 | W11: 0000141254 | X11: 1800000264 | AB11: 2018-05-23 | AC11: ESD | AD11: USD | AE11: USD | AF11: Dist | AG11: D | AH11: 2018-05-23 | AI11: ACTUALS | AJ11: 1268751 | AO11: 24 | AP11: 3 | AQ11: 0 | AS11: 0 | AT11: 0 | AY11: 2018-05-23-20.30.59.446084 | AZ11: 404 | BA11: 2018-05-23 | BB11: ESD | BC11: APV024
B12: ACTUALS | C12: PURCHASE | D12: PUR0925446 | E12: 2018 | F12: 6 | G12: 528400 | H12: 1824300 | I12: 000 | J12: 0000 | K12: 00007100 | L12: 7100 | M12: 1196979.2 | N12: 000000 | P12: 0 | Q12: 1196979.2 | R12: 00312732 | S12: 00312732 | T12: SHARYLAND UTILITIES | U12: 0007498 | V12: 010998453 | W12: 0000144304 | X12: 1800000329 | AB12: 2018-06-28 | AC12: ESD | AD12: USD | AE12: USD | AF12: Dist | AG12: D | AH12: 2018-06-28 | AI12: ACTUALS | AJ12: 1299539 | AO12: 24 | AP12: 3 | AQ12: 0 | AS12: 0 | AT12: 0 | AY12: 2018-06-28-19.46.48.581959 | AZ12: 1823 | BA12: 2018-06-28 | BB12: ESD | BC12: APV024
B13: ACTUALS | C13: PURCHASE | D13: PUR0926590 | E13: 2018 | F13: 8 | G13: 528400 | H13: 1824300 | I13: 000 | J13: 0000 | K13: 00007100 | L13: 7100 | M13: 1246328.1 | N13: 000000 | P13: 0 | Q13: 1246328.1 | R13: 00319618 | S13: 00319618 | T13: SHARYLAND UTILITIES | U13: 0007498 | V13: 010998453 | W13: 0000148288 | X13: 100007657 | AB13: 2018-08-07 | AC13: ESD | AD13: USD | AE13: USD | AF13: Dist | AG13: D | AH13: 2018-08-07 | AI13: ACTUALS | AJ13: 1333691 | AO13: 24 | AP13: 3 | AQ13: 0 | AS13: 0 | AT13: 0 | AY13: 2018-08-07-19.48.43.029227 | AZ13: 242 | BA13: 2018-08-07 | BB13: ESD | BC13: APV024
B14: ACTUALS | C14: PURCHASE | D14: PUR0927379 | E14: 2018 | F14: 9 | G14: 528400 | H14: 1824300 | I14: 000 | J14: 0000 | K14: 00007100 | L14: 7100 | M14: 1267172.7 | N14: 000000 | P14: 0 | Q14: 1267172.7 | R14: 00324885 | S14: 00324885 | T14: SHARYLAND UTILITIES | U14: 0007498 | V14: 010998453 | W14: 0000151388 | X14: 100008314 | AB14: 2018-09-07 | AC14: ESD | AD14: USD | AE14: USD | AF14: Dist | AG14: D | AH14: 2018-09-07 | AI14: ACTUALS | AJ14: 1360298 | AO14: 24 | AP14: 3 | AQ14: 0 | AS14: 0 | AT14: 0 | AY14: 2018-09-07-19.36.18.345884 | AZ14: 430 | BA14: 2018-09-07 | BB14: ESD | BC14: APV024
B15: ACTUALS | C15: PURCHASE | D15: PUR0928326 | E15: 2018 | F15: 10 | G15: 528400 | H15: 1824300 | I15: 000 | J15: 0000 | K15: 00007100 | L15: 7100 | M15: 1291921.3 | N15: 000000 | P15: 0 | Q15: 1291921.3 | R15: 00330738 | S15: 00330738 | T15: SHARYLAND UTILITIES | U15: 0007498 | V15: 010998453 | W15: 0000155554 | X15: 1800000522 | AB15: 2018-10-12 | AC15: ESD | AD15: USD | AE15: USD | AF15: Dist | AG15: D | AH15: 2018-10-12 | AI15: ACTUALS | AJ15: 1390250 | AO15: 24 | AP15: 3 | AQ15: 0 | AS15: 0 | AT15: 0 | AY15: 2018-10-12-19.33.26.498889 | AZ15: 203 | BA15: 2018-10-12 | BB15: ESD | BC15: APV024
B16: ACTUALS | C16: PURCHASE | D16: PUR0929165 | E16: 2018 | F16: 11 | G16: 528400 | H16: 1824300 | I16: 000 | J16: 0000 | K16: 00007100 | L16: 7100 | M16: 1323224.9 | N16: 000000 | P16: 0 | Q16: 1323224.9 | R16: 00336013 | S16: 00336013 | T16: SHARYLAND UTILITIES | U16: 0007498 | V16: 010998453 | W16: 0000157781 | X16: 1800000582 | AB16: 2018-11-13 | AC16: ESD | AD16: USD | AE16: USD | AF16: Dist | AG16: D | AH16: 2018-11-13 | AI16: ACTUALS | AJ16: 1417519 | AO16: 24 | AP16: 3 | AQ16: 0 | AS16: 0 | AT16: 0 | AY16: 2018-11-13-20.04.55.792148 | AZ16: 65 | BA16: 2018-11-13 | BB16: ESD | BC16: APV024
B17: ACTUALS | C17: PURCHASE | D17: PUR0929638 | E17: 2018 | F17: 12 | G17: 528400 | H17: 1824300 | I17: 000 | J17: 0000 | K17: 00007100 | L17: 7100 | M17: 1391374.1 | N17: 000000 | P17: 0 | Q17: 1391374.1 | R17: 00339353 | S17: 00339353 | T17: SHARYLAND UTILITIES | U17: 0007498 | V17: 010998453 | W17: 0000161661 | X17: 1800000666 | AB17: 2018-12-04 | AC17: ESD | AD17: USD | AE17: USD | AF17: Dist | AG17: D | AH17: 2018-12-04 | AI17: ACTUALS | AJ17: 1434605 | AO17: 24 | AP17: 3 | AQ17: 0 | AS17: 0 | AT17: 0 | AY17: 2018-12-04-19.51.13.158559 | AZ17: 892 | BA17: 2018-12-04 | BB17: ESD | BC17: APV024
A19: %,OT | M19: =SUM(M7:M18) -> 13000532 | P19: =SUM(P7:P18) -> 0 | Q19: =SUM(Q7:Q18) -> 13000532
B21: Report generated: | C21: =NvsEndTime -> 44405.344
B22: ="Y" -> Y
L23: WDSS month
L24: 43070 | M24: =M7 -> 978758
L25: 43101 | M25: =M8 -> 1004966.9
L26: 43132 | M26: =M9 -> 1066736
L27: 43160 | M27: =M10 -> 1099749
L28: 43191 | M28: =M11 -> 1133321.6
L29: 43221 | M29: =M12 -> 1196979.2
L30: 43252 | M30: =M13 -> 1246328.1
L31: 43282 | M31: =M14 -> 1267172.7
L32: 43313 | M32: =M15 -> 1291921.3
L33: 43344 | M33: =M16 -> 1323224.9
L34: 43374 | M34: =M17 -> 1391374.1

Sheet 2017 SU pmts
B1: %,HLedger,RTU_PUR_DIST_VW,FLEDGER | C1: %,HTemplate,RTU_PUR_DIST_VW,FAPPL_JRNL_ID,B | D1: %,HJournal,RTU_PUR_DIST_VW,FJOURNAL_ID,B | E1: %,HYear,RTU_PUR_DIST_VW,FFISCAL_YEAR,B | F1: %,HPeriod,RTU_PUR_DIST_VW,FACCOUNTING_PERIOD,B | G1: %,HDeptID,RTU_PUR_DIST_VW,FDEPTID,B | H1: %,HAccount,RTU_PUR_DIST_VW,FACCOUNT,B | I1: %,HExpnd Cd,RTU_PUR_DIST_VW,FTU_EC,B | J1: %,HTU Loc,RTU_PUR_DIST_VW,FTU_LOCATION,B | K1: %,HProj,RTU_PUR_DIST_VW,FPROJECT_ID,B | L1: %,HActivity,RTU_PUR_DIST_VW,FTU_ACTIVITY,B | M1: %,HMonetary Amount,RTU_PUR_DIST_VW,FMONETARY_AMOUNT,B | N1: %,HProd,RTU_PUR_DIST_VW,FPRODUCT,B | O1: %,HAffl,RTU_PUR_DIST_VW,FAFFILIATE,B | P1: %,HStatistic Amount,RTU_PUR_DIST_VW,FSTATISTIC_AMOUNT,B | Q1: %,HForeign Amount,RTU_PUR_DIST_VW,FFOREIGN_AMOUNT,B | R1: %,HVoucher ID,RTU_PUR_DIST_VW,FVOUCHER_ID,B | S1: %,HVoucher Number,RTU_PUR_DIST_VW,FTU_VOUCHER_H,B | T1: %,HVendor Name,RTU_PUR_DIST_VW,FTU_VENDOR_N,B | U1: %,HNew Vendor ID,RTU_PUR_DIST_VW,FVENDOR_ID,AA,B | V1: %,Hvendor,RTU_PUR_DIST_VW,FTU_VENDOR_H,B | W1: %,Hcheckno,RTU_PUR_DIST_VW,FTU_CHECK_H,B | X1: %,HInvoice Number,RTU_PUR_DIST_VW,FTU_INVOICE_H,B | Y1: %,Hpo,RTU_PUR_DIST_VW,FTU_PO_H,B | Z1: %,HStock#,RTU_PUR_DIST_VW,FTU_STOCK_H,B | AA1: %,HWarehouse,RTU_PUR_DIST_VW,FTU_WHSE_H,B | AB1: %,HAcctg Date,RTU_PUR_DIST_VW,FACCOUNTING_DT,B | AC1: %,HGL Unit,RTU_PUR_DIST_VW,FBUSINESS_UNIT_GL,B | AD1: %,HCurrency,RTU_PUR_DIST_VW,FCURRENCY_CD,B | AE1: %,HForeign Currency,RTU_PUR_DIST_VW,FFOREIGN_CURRENCY,B | AF1: %,HGL Status,RTU_PUR_DIST_VW,FGL_DISTRIB_STATUS,B | AG1: %,HPC Status,RTU_PUR_DIST_VW,FPC_DISTRIB_STATUS,B | AH1: %,HDate,RTU_PUR_DIST_VW,FJOURNAL_DATE,B | AI1: %,HLedger Grp,RTU_PUR_DIST_VW,FLEDGER_GROUP,B | AJ1: %,HInstance,RTU_PUR_DIST_VW,FPROCESS_INSTANCE,B | AK1: %,HRef,RTU_PUR_DIST_VW,FJRNL_LN_REF,B | AL1: %,HJournal Descrption,RTU_PUR_DIST_VW,FJRNL_DESCR,B | AM1: %,HStatistic,RTU_PUR_DIST_VW,FSTATISTIC_CD,B | AN1: %,HWork Order,RTU_PUR_DIST_VW,FTU_WO,B | AO1: %,Hfdr src cd,RTU_PUR_DIST_VW,FTU_FEEDER_SRC_C,B | AP1: %,HTUloadflag,RTU_PUR_DIST_VW,FTU_LOADING_FLAG,B | AQ1: %,HTUerrprcs,RTU_PUR_DIST_VW,FTU_ERR_PROCESS_INS,B | AR1: %,Htaxcode,RTU_PUR_DIST_VW,FTU_TAX_C,B | AS1: %,Hvouline,RTU_PUR_DIST_VW,FTU_VOU_LINE_H,B | AT1: %,Hpoline,RTU_PUR_DIST_VW,FTU_PO_LINE_H,B | AU1: %,Htaxact,RTU_PUR_DIST_VW,FTU_TAX_ACT_C,B | AV1: %,Hvehcard,RTU_PUR_DIST_VW,FTU_VEH_CARD_H,B | AW1: %,HgasticketD,RTU_PUR_DIST_VW,FTU_GASTICKET_INV_D,B | AX1: %,HMaterialRR,RTU_PUR_DIST_VW,FTU_MRR,B | AY1: %,HPosting Date Time Stamp,RTU_PUR_DIST_VW,FTU_POST_D,B | AZ1: %,HSeq,RTU_PUR_DIST_VW,FTU_SEQ_H,B | BA1: %,HFDRLNeffdt,RTU_PUR_DIST_VW,FTU_FDR_LINE_EFF_D,B | BB1: %,HUnit,RTU_PUR_DIST_VW,FBUSINESS_UNIT,B | BC1: %,HFile ID,RTU_PUR_DIST_VW,FTU_FEEDER_FILE_ID,B | BD1: %,Htucmmtln1,RTU_PUR_DIST_VW,FTU_CMMT_LINE1,B | BE1: %,HID,RTU_PUR_DIST_VW,FEX_DOC_ID,AA,B | BF1: %,HEmplid,RTU_PUR_DIST_VW,FEMPLID,AA,B
B2: TU FINANCIAL INFORMATION MANAGEMENT REPORT | BZ2: =NvsElapsedTime -> 5.7870369e-05
B4: PURCHASE DRILL
A6: %,OH | B6: Ledger | C6: Template | D6: Journal | E6: Year | F6: Period | G6: DeptID | H6: Account | I6: Expnd Cd | J6: TU Loc | K6: Proj | L6: Activity | M6: Monetary Amount | N6: Prod | O6: Affl | P6: Statistic Amount | Q6: Foreign Amount | R6: New Voucher ID | S6: PMMS Voucher Number | T6: Vendor Name | U6: New Vendor ID | V6: PMMS Vendor ID | W6: checkno | X6: Invoice Number | Y6: po | Z6: Stock# | AA6: Warehouse | AB6: Acctg Date | AC6: GL Unit | AD6: Currency | AE6: Currency | AF6: Status | AG6: Status | AH6: Date | AI6: Ledger Grp | AJ6: Instance | AK6: Ref | AL6: Journal Descrption | AM6: Statistic | AN6: Work Order | AO6: fdr src cd | AP6: TUloadflag | AQ6: TUerrprcs | AR6: taxcode | AS6: vouline | AT6: poline | AU6: taxact | AV6: vehcard | AW6: gasticketD | AX6: MaterialRR | AY6: Posting Date Time Stamp | AZ6: Seq | BA6: FDRLNeffdt | BB6: Unit | BC6: File ID | BD6: Local PO No | BE6: Expense Report ID | BF6: Emplid
A7: %,OA | B7: ACTUALS | C7: PURCHASE | D7: PUR0920077 | E7: 2017 | F7: 12 | G7: 528400 | H7: 1824300 | I7: 000 | J7: 0000 | K7: 00000000 | L7: 0000 | M7: 621058.01 | N7: 000000 | P7: 0 | Q7: 621058.01 | R7: 00278963 | S7: 00278963 | T7: SHARYLAND UTILITIES | U7: 0007498 | V7: 010998453 | W7: 0000124622 | X7: 1800000131 | AB7: 2017-12-19 | AC7: ESD | AD7: USD | AE7: USD | AF7: Dist | AG7: I | AH7: 2017-12-19 | AI7: ACTUALS | AJ7: 1131363 | AO7: 24 | AP7: 3 | AQ7: 0 | AS7: 0 | AT7: 0 | AY7: 2017-12-19-20.06.58.499506 | AZ7: 1064 | BA7: 2017-12-19 | BB7: ESD | BC7: APV024
A9: %,OT | M9: =SUM(M7:M8) -> 621058.01 | P9: =SUM(P7:P8) -> 0 | Q9: =SUM(Q7:Q8) -> 621058.01
B11: Report generated: | C11: =NvsEndTime -> 44405.348
B12: ="Y" -> Y
L13: WDSS month
L14: 43040 | M14: =M7 -> 621058.01

Sheet Sep19_invoice
N37: 57916.24

Sheet Dkt47469 Item69
AB151: Refund with interest
AB152: -185831.26
AB153: =AB154-AB152 -> -5000.36
AB154: ='Draft workpaper'!B76 -> -190831.62

Sheet Doc 45414 Test

Sheet Doc 45414 WP-II-E-4.1-2
