Workbook

Sheet WP II-E-3.3
A1: 2022 RATE CASE
A2: ONCOR ELECTRIC DELIVERY COMPANY LLC
A3: PLANT ADJUSTMENTS
A4: TEST YEAR ENDING DECEMBER 31, 2021
A5: SPONSOR: B. L. CLUTTER
A10: Line No. | B10: Tax Class | D10: Rate | E10: Convention | F10: 2017 Oncor Tax Additions | G10: 2018 Oncor Tax Additions | H10: 2019 Oncor Tax Additions | I10: 2019 Acquired NTU | J10: 2019 NTU Tax Additions | K10: 2020 Oncor Tax Additions | L10: 2020 NTU Tax Additions | M10: 2021 Oncor Tax Additions | N10: 2021 NTU Tax Additions | O10: Total Tax Depr Basis | P10: 2021 Oncor Depr on V2017-V2021 | Q10: 2021 NTU Depr on all Vintages | R10: 2022 Oncor Forecast Depr on V2017-V2021 | S10: 2022 NTU Forecast Depr on all Vintages | T10: 2023 Oncor Forecast Depr on V2017-V2021 | U10: 2023 NTU Forecast Depr on all Vintages | V10: Oncor V2017-V2021 ADFIT at 12/31/2021 | W10: NTU ADFIT at 12/31/2021
B11: (a) | D11: (b) | E11: (c) | F11: (d) | G11: (e) | H11: (f) | I11: (g) | J11: (h) | K11: (i) | L11: (j) | M11: (k) | N11: (l) | O11: (m) | P11: (n) | Q11: (o) | R11: (p) | S11: (q) | T11: (r) | U11: (s) | V11: (t) | W11: (u)
A12: 1 | B12: TOTAL
A13: =+A12+1 -> 2 | B13: 00.11 | C13: 00.11: Furn, Fixt, Equip | D13: MACRS 7 | E13: HY | F13: 997544.61 | G13: 1256688 | H13: 2620218.9 | I13: 4042130.8 | J13: -1156147.4 | K13: 11311160 | L13: 23509.07 | M13: 4973457.1 | O13: =SUM(F13:N13) -> 24068561 | P13: 4496527.3 | Q13: 228222.86 | R13: 3937498.6 | S13: 97512.89 | T13: 2869265.1 | U13: 85017.53
A14: =+A13+1 -> 3 | B14: 00.12 | C14: 00.12: Info Systems | D14: MACRS 5 | E14: HY | F14: 12290349 | G14: 5655897.6 | H14: 10602111 | I14: 7332.55 | K14: 61719114 | M14: 15137581 | O14: =SUM(F14:N14) -> 1.0541239e+08 | P14: 30315005 | Q14: 454.84 | R14: 22148345 | S14: 454.84 | T14: 12840933 | U14: 454.84
A15: =+A14+1 -> 4 | B15: 00.21 | C15: 00.21: Airplanes | D15: MACRS 5 | E15: HY | F15: 0 | G15: 2617666 | H15: 1659975 | K15: 0 | M15: 0 | O15: =SUM(F15:N15) -> 4277641 | P15: 620270.32 | R15: 492784.24 | T15: 342006.69
A16: =+A15+1 -> 5 | B16: 00.22 | C16: 00.22: Automobiles | D16: MACRS 5 | E16: HY | F16: 636668.55 | G16: 328794.84 | H16: 553113.08 | K16: 2072740.9 | L16: 55488.85 | M16: 1002860.7 | O16: =SUM(F16:N16) -> 4649667 | P16: 1184134.6 | Q16: 14427.1 | R16: 940073.06 | S16: 8656.26 | T16: 553519.14 | U16: 6109.32
A17: =+A16+1 -> 6 | B17: 00.241 | C17: 00.241: Light Trucks | D17: MACRS 5 | E17: HY | F17: 2196684 | G17: 310098.92 | H17: 0 | I17: 1044540.5 | J17: -70853.49 | K17: 1191.54 | M17: 0 | O17: =SUM(F17:N17) -> 3481661.4 | P17: 264472.83 | Q17: 53261.19 | R17: 230005.35 | S17: 51658.47 | T17: 17997.18 | U17: 51658.47
A18: =+A17+1 -> 7 | B18: 00.242 | C18: 00.242: Heavy Trucks | D18: MACRS 5 | E18: HY | F18: 678187.2 | G18: 365428.77 | H18: 0 | K18: 328223.75 | M18: 90231.47 | O18: =SUM(F18:N18) -> 1462071.2 | P18: 238724.69 | R18: 194075 | T18: 76917.85
A19: =+A18+1 -> 8 | B19: 00.27 | C19: 00.27: Trailers | D19: MACRS 5 | E19: HY | F19: 643724.17 | G19: 1429135.1 | H19: 615251.77 | K19: 739247.33 | L19: 52908.96 | M19: 181842.34 | O19: =SUM(F19:N19) -> 3662109.7 | P19: 608559.19 | Q19: 20105.4 | R19: 485546.92 | S19: 12063.24 | T19: 274921.46 | U19: 7237.95
A20: =+A19+1 -> 9 | B20: 00.28 | C20: 00.28: Boats | D20: MACRS 10 | E20: HY | F20: 0 | G20: 0 | H20: 30721.49 | K20: 20022.04 | M20: 0 | O20: =SUM(F20:N20) -> 50743.53 | P20: 10430.5 | R20: 7143.09 | T20: 5107.8
A21: =+A20+1 -> 10 | B21: 00.3 | C21: 00.3: Land Improv | D21: MACRS 15 | E21: HY | F21: 4989496.9 | G21: 19641172 | H21: 11911238 | I21: 9057063.5 | K21: 30575380 | M21: 46702065 | O21: =SUM(F21:N21) -> 1.2287641e+08 | P21: 8155124.7 | Q21: 590551.27 | R21: 9693942.2 | S21: 557559.29 | T21: 8701942.9 | U21: 535080.06
A22: =+A21+1 -> 11 | B22: 40.4 | C22: 40.4: Railroad Track | D22: MACRS 7 | E22: HY | F22: 0 | G22: 0 | H22: 0 | K22: -1809.55 | M22: 0 | O22: =SUM(F22:N22) -> -1809.55 | P22: -498.55 | R22: -356.12 | T22: -254.35
A23: =+A22+1 -> 12 | B23: 49.14 | C23: 49.14: Trans & Dist Plnt | D23: MACRS 20 | E23: HY | F23: 2.4981591e+08 | G23: 4.9424941e+08 | H23: 6.1199045e+08 | I23: 69329950 | J23: -39105.31 | K23: 7.7413801e+08 | L23: -670469.08 | M23: 8.1088021e+08 | N23: 75378.79 | O23: =SUM(F23:N23) -> 3.0097697e+09 | P23: 1.7059666e+08 | Q23: 3072367.3 | R23: 1.8785376e+08 | S23: 2916950 | T23: 1.7375818e+08 | U23: 2980955.1
A24: =+A23+1 -> 13 | B24: 49.14A | C24: 49.14A: Trans 4/05-1/11 | D24: MACRS 15 | E24: HY | F24: 3.1107071e+08 | G24: 6.3205006e+08 | H24: 8.576742e+08 | I24: 1.1339067e+09 | J24: 7749330.4 | K24: 1.0595922e+09 | L24: 4858263.8 | M24: 1.0439354e+09 | N24: -985173.21 | O24: =SUM(F24:N24) -> 5.0498517e+09 | P24: 2.9681672e+08 | Q24: 75021714 | R24: 3.1997054e+08 | S24: 71729914 | T24: 2.88126e+08 | U24: 69253131
A25: =+A24+1 -> 14 | B25: 49.14B | C25: 49.14B: Meters | D25: MACRS 20 | E25: HY | F25: 2820858.1 | G25: 2161648.7 | H25: 10305819 | K25: 11539390 | M25: 10353307 | O25: =SUM(F25:N25) -> 37181022 | P25: 2884770.6 | R25: 2981793.2 | T25: 2566586.8
A26: =+A25+1 -> 15 | B26: 49.14C | C26: 49.14C: Smart Meters | D26: MACRS 10 | E26: HY | F26: 23415151 | G26: 61086583 | H26: 74518693 | J26: 16797.86 | K26: 80368252 | M26: 84161731 | O26: =SUM(F26:N26) -> 3.2356721e+08 | P26: 27767506 | Q26: 1981.14 | R26: 29757214 | S26: 1683.82 | T26: 26616408 | U26: 1468.13
A27: =+A26+1 -> 16 | B27: 49.14D | C27: 49.14D Street Lighting | D27: MACRS 7 | E27: HY | F27: 10656252 | G27: 18364980 | H27: 23595625 | I27: 7252.15 | K27: 24821565 | M27: 24029801 | O27: =SUM(F27:N27) -> 1.0147548e+08 | P27: 6269286.8 | Q27: 906.16 | R27: 6635773.4 | S27: 647.25 | T27: 6191830.5 | U27: 647.25
A28: =+A27+1 -> 17 | B28: 57.0 | C28: 57.0: Distr Trades Serv | D28: MACRS 5 | E28: HY | F28: 3979411.9 | G28: 6265981.6 | H28: 4872319.7 | I28: 2199555.5 | J28: -1949432 | K28: 13966086 | M28: 9342711.6 | O28: =SUM(F28:N28) -> 38676634 | P28: 9003207 | Q28: 13497.52 | R28: 7673680.5 | S28: 12972.53 | T28: 4546039.5 | U28: 12872.26
A29: =+A28+1 -> 18 | B29: AM15 | C29: AM15: 197 Amortization | D29: SL 15 | E29: MM | F29: 15900000 | G29: 0 | H29: 0 | K29: 0 | M29: 0 | O29: =SUM(F29:N29) -> 15900000 | P29: 1059894 | R29: 1060053 | T29: 1060053
A30: =+A29+1 -> 19 | B30: LH | C30: LH: LH Improv | D30: MACRS 39 | E30: MM | F30: 42773.84 | G30: 9976.32 | H30: 0 | K30: 25686592 | M30: 153213.54 | O30: =SUM(F30:N30) -> 25892555 | P30: 662894.85 | R30: 663885.2 | T30: 663885.53
A31: =+A30+1 -> 20 | B31: LR46 | C31: LR46: Easements 46 Yr | D31: SL 46 | E31: HY | F31: 1230506.4 | G31: 2071283.8 | H31: 6130177.1 | K31: -110121.84 | M31: 8326189.2 | O31: =SUM(F31:N31) -> 17648035 | P31: 346158.18 | R31: 463814.41 | T31: 454988.96
A32: =+A31+1 -> 21 | B32: LR84 | C32: LR84: Easements 84 Yr | D32: SL 84 | E32: HY | F32: 10669200 | G32: 3784851.2 | H32: 17561905 | I32: 1.0001237e+08 | K32: 46742174 | M32: 15495569 | N32: 5751215.3 | O32: =SUM(F32:N32) -> 2.0001728e+08 | P32: 7215863.2 | Q32: 1533463.2 | R32: 7293055 | S32: 1725432.1 | T32: 6577507 | U32: 1692240.7
A33: =+A32+1 -> 22 | B33: ND | C33: ND: Non Depr | D33: None | F33: 8022096.7 | G33: 28547869 | H33: 3043427.7 | I33: 54778215 | J33: -3235813.3 | K33: 15424521 | M33: 33730417 | N33: -5751215.3 | O33: =SUM(F33:N33) -> 1.3455952e+08 | P33: 0 | R33: 0 | T33: 0
A34: =+A33+1 -> 23 | B34: RP | C34: RP: RP 81-86 & Post92 | D34: MACRS 39 | E34: MM | F34: 21658814 | G34: 31181436 | H34: 29050181 | I34: 1.3369469e+08 | J34: -700090.72 | K34: 40037827 | L34: 1146038.8 | M34: 55251619 | N34: -215000 | O34: =SUM(F34:N34) -> 3.1110551e+08 | P34: 3598506.2 | Q34: 3327434.4 | R34: 4539045.6 | S34: 3272797.8 | T34: 4539119 | U34: 3256712
A35: =+A34+1 -> 24 | B35: TOTAL | F35: =SUM(F13:F34) -> 6.8171434e+08 | G35: =SUM(G13:G34) -> 1.311379e+09 | H35: =SUM(H13:H34) -> 1.6667354e+09 | I35: =SUM(I13:I34) -> 1.5080798e+09 | J35: =SUM(J13:J34) -> 614686.02 | K35: =SUM(K13:K34) -> 2.1989718e+09 | L35: =SUM(L13:L34) -> 5465740.5 | M35: =SUM(M13:M34) -> 2.1637482e+09 | ... U35: =SUM(U13:U34) -> 77883584 | V35: 6.0617061e+08 | W35: 1.3986956e+08
A36: =+A35+1 -> 25
A37: =+A36+1 -> 26 | B37: TRAN | E37: =+'[1]II-F Alloc_Factor'!$E$40 -> 0.46423244
A38: =+A37+1 -> 27 | B38: 00.11 | C38: 00.11: Furn, Fixt, Equip | D38: MACRS 7 | E38: HY | F38: =ROUND(+'WP II-E-3.3'!F13*$E$37,2) -> 463092.57 | G38: =ROUND(+'WP II-E-3.3'!G13*$E$37,2) -> 583395.34 | H38: =ROUND(+'WP II-E-3.3'!H13*$E$37,2) -> 1216390.6 | I38: 0 | J38: 0 | K38: =ROUND(+'WP II-E-3.3'!K13*$E$37,2) -> 5251007.6 | L38: 0 | M38: =ROUND(+'WP II-E-3.3'!M13*$E$37,2) -> 2308840.1 | N38: 0 | O38: =SUM(F38:N38) -> 9822726.2 | P38: =ROUND(+'WP II-E-3.3'!P13*$E$37,2) -> 2087433.9 | Q38: 0 | R38: =ROUND(+'WP II-E-3.3'!R13*$E$37,2) -> 1827914.6 | S38: 0 | T38: =ROUND(+'WP II-E-3.3'!T13*$E$37,2) -> 1332006 | U38: 0 | V38: =+'WP II-E-3.3'!V13*$E$37 -> 0 | W38: =+'WP II-E-3.3'!W13*$E$37 -> 0
A39: =+A38+1 -> 28 | B39: 00.12 | C39: 00.12: Info Systems | D39: MACRS 5 | E39: HY | F39: =ROUND(+'WP II-E-3.3'!F14*$E$37,2) -> 5705578.6 | G39: =ROUND(+'WP II-E-3.3'!G14*$E$37,2) -> 2625651.1 | H39: =ROUND(+'WP II-E-3.3'!H14*$E$37,2) -> 4921844.1 | I39: 0 | J39: 0 | K39: =ROUND(+'WP II-E-3.3'!K14*$E$37,2) -> 28652015 | L39: 0 | M39: =ROUND(+'WP II-E-3.3'!M14*$E$37,2) -> 7027356.2 | N39: 0 | O39: =SUM(F39:N39) -> 48932445 | P39: =ROUND(+'WP II-E-3.3'!P14*$E$37,2) -> 14073209 | Q39: 0 | R39: =ROUND(+'WP II-E-3.3'!R14*$E$37,2) -> 10281980 | S39: 0 | T39: =ROUND(+'WP II-E-3.3'!T14*$E$37,2) -> 5961177.8 | U39: 0 | V39: =+'WP II-E-3.3'!V14*$E$37 -> 0 | W39: =+'WP II-E-3.3'!W14*$E$37 -> 0
A40: =+A39+1 -> 29 | B40: 00.21 | C40: 00.21: Airplanes | D40: MACRS 5 | E40: HY | F40: =ROUND(+'WP II-E-3.3'!F15*$E$37,2) -> 0 | G40: =ROUND(+'WP II-E-3.3'!G15*$E$37,2) -> 1215205.5 | H40: =ROUND(+'WP II-E-3.3'!H15*$E$37,2) -> 770614.25 | I40: 0 | J40: 0 | K40: =ROUND(+'WP II-E-3.3'!K15*$E$37,2) -> 0 | L40: 0 | M40: =ROUND(+'WP II-E-3.3'!M15*$E$37,2) -> 0 | N40: 0 | O40: =SUM(F40:N40) -> 1985819.7 | P40: =ROUND(+'WP II-E-3.3'!P15*$E$37,2) -> 287949.61 | Q40: 0 | R40: =ROUND(+'WP II-E-3.3'!R15*$E$37,2) -> 228766.43 | S40: 0 | T40: =ROUND(+'WP II-E-3.3'!T15*$E$37,2) -> 158770.6 | U40: 0 | V40: =+'WP II-E-3.3'!V15*$E$37 -> 0 | W40: =+'WP II-E-3.3'!W15*$E$37 -> 0
A41: =+A40+1 -> 30 | B41: 00.22 | C41: 00.22: Automobiles | D41: MACRS 5 | E41: HY | F41: =ROUND(+'WP II-E-3.3'!F16*$E$37,2) -> 295562.2 | G41: =ROUND(+'WP II-E-3.3'!G16*$E$37,2) -> 152637.23 | H41: =ROUND(+'WP II-E-3.3'!H16*$E$37,2) -> 256773.04 | I41: 0 | J41: 0 | K41: =ROUND(+'WP II-E-3.3'!K16*$E$37,2) -> 962233.59 | L41: 0 | M41: =ROUND(+'WP II-E-3.3'!M16*$E$37,2) -> 465560.48 | N41: 0 | O41: =SUM(F41:N41) -> 2132766.5 | P41: =ROUND(+'WP II-E-3.3'!P16*$E$37,2) -> 549713.71 | Q41: 0 | R41: =ROUND(+'WP II-E-3.3'!R16*$E$37,2) -> 436412.42 | S41: 0 | T41: =ROUND(+'WP II-E-3.3'!T16*$E$37,2) -> 256961.54 | U41: 0 | V41: =+'WP II-E-3.3'!V16*$E$37 -> 0 | W41: =+'WP II-E-3.3'!W16*$E$37 -> 0
A42: =+A41+1 -> 31 | B42: 00.241 | C42: 00.241: Light Trucks | D42: MACRS 5 | E42: HY | F42: =ROUND(+'WP II-E-3.3'!F17*$E$37,2) -> 1019772 | G42: =ROUND(+'WP II-E-3.3'!G17*$E$37,2) -> 143957.98 | H42: =ROUND(+'WP II-E-3.3'!H17*$E$37,2) -> 0 | I42: 0 | J42: 0 | K42: =ROUND(+'WP II-E-3.3'!K17*$E$37,2) -> 553.15 | L42: 0 | M42: =ROUND(+'WP II-E-3.3'!M17*$E$37,2) -> 0 | N42: 0 | O42: =SUM(F42:N42) -> 1164283.1 | P42: =ROUND(+'WP II-E-3.3'!P17*$E$37,2) -> 122776.87 | Q42: 0 | R42: =ROUND(+'WP II-E-3.3'!R17*$E$37,2) -> 106775.95 | S42: 0 | T42: =ROUND(+'WP II-E-3.3'!T17*$E$37,2) -> 8354.87 | U42: 0 | V42: =+'WP II-E-3.3'!V17*$E$37 -> 0 | W42: =+'WP II-E-3.3'!W17*$E$37 -> 0
A43: =+A42+1 -> 32 | B43: 00.242 | C43: 00.242: Heavy Trucks | D43: MACRS 5 | E43: HY | F43: =ROUND(+'WP II-E-3.3'!F18*$E$37,2) -> 314836.5 | G43: =ROUND(+'WP II-E-3.3'!G18*$E$37,2) -> 169643.89 | H43: =ROUND(+'WP II-E-3.3'!H18*$E$37,2) -> 0 | I43: 0 | J43: 0 | K43: =ROUND(+'WP II-E-3.3'!K18*$E$37,2) -> 152372.11 | L43: 0 | M43: =ROUND(+'WP II-E-3.3'!M18*$E$37,2) -> 41888.38 | N43: 0 | O43: =SUM(F43:N43) -> 678740.88 | P43: =ROUND(+'WP II-E-3.3'!P18*$E$37,2) -> 110823.75 | Q43: 0 | R43: =ROUND(+'WP II-E-3.3'!R18*$E$37,2) -> 90095.91 | S43: 0 | T43: =ROUND(+'WP II-E-3.3'!T18*$E$37,2) -> 35707.76 | U43: 0 | V43: =+'WP II-E-3.3'!V18*$E$37 -> 0 | W43: =+'WP II-E-3.3'!W18*$E$37 -> 0
A44: =+A43+1 -> 33 | B44: 00.27 | C44: 00.27: Trailers | D44: MACRS 5 | E44: HY | F44: =ROUND(+'WP II-E-3.3'!F19*$E$37,2) -> 298837.65 | G44: =ROUND(+'WP II-E-3.3'!G19*$E$37,2) -> 663450.89 | H44: =ROUND(+'WP II-E-3.3'!H19*$E$37,2) -> 285619.83 | I44: 0 | J44: 0 | K44: =ROUND(+'WP II-E-3.3'!K19*$E$37,2) -> 343182.6 | L44: 0 | M44: =ROUND(+'WP II-E-3.3'!M19*$E$37,2) -> 84417.11 | N44: 0 | O44: =SUM(F44:N44) -> 1675508.1 | P44: =ROUND(+'WP II-E-3.3'!P19*$E$37,2) -> 282512.92 | Q44: 0 | R44: =ROUND(+'WP II-E-3.3'!R19*$E$37,2) -> 225406.63 | S44: 0 | T44: =ROUND(+'WP II-E-3.3'!T19*$E$37,2) -> 127627.46 | U44: 0 | V44: =+'WP II-E-3.3'!V19*$E$37 -> 0 | W44: =+'WP II-E-3.3'!W19*$E$37 -> 0
...
