Workbook
Name \0: #REF!
Name \F: #REF!
Name \S: #REF!
Name \V: #REF!
Name \Y: #REF!
Name _\4: #REF!
Name _0: #REF!
Name _2_ALT_Y_: #REF!
Name _3_ALT_F: #REF!
Name _P: #REF!
Name A_R_INTERCOMPANY: #REF!
Name Account: #REF!
Name Account2: #REF!
Name AccountDescr: #REF!
Name AccountDescr2: #REF!
Name acct: #REF!
Name acct_mo: #REF!
Name Activity: #REF!
Name Activity2: #REF!
Name ActivityDescr: #REF!
Name ActivityDescr2: #REF!
Name Affiliate: #REF!
Name Affiliate2: #REF!
Name AffiliateDescr: #REF!
Name APN: #REF!
Name arintercompany: #REF!
Name ASD: '[1]FIM trial bal'!$M$5
Name backup_servicer_start_date: [2]Main!#REF!
Name Backup_Servicing_Trigger: [2]Main!#REF!
Name Bond_Cashflows: #REF!
Name BU: #REF!
Name BUDGET: #REF!
Name BUNODE: #REF!
Name BusinessUnit: #REF!
Name BusinessUnit2: #REF!
Name By_Summary_Ledger: #REF!
Name calc_method: [2]Main!#REF!
Name calc_res: [2]Main!#REF!
Name Cancel: [3]!Cancel
Name Choice_Period_Lag: [2]Main!#REF!
Name Class_A1: #REF!
Name Class_A2: #REF!
Name Class_A3: #REF!
Name colcurve: '[4]Classes & Groups'!$C$89
Name Completed: #REF!
Name COPY: #REF!
Name Credit: [5]JOURNAL!#REF!
Name Credit: [5]JOURNAL!#REF!
Name Credit: [6]JOURNAL!#REF!
Name D: 41291.2506944444
Name Date: #REF!
Name Date_Choice: [2]Main!#REF!
Name Date_Closing: [7]Main!$B$7
Name Date_First_Payment: [7]Main!$B$8
Name Date_Interim_TrueUp: [2]Main!#REF!
Name Date1: #REF!
Name Date2: #REF!
Name DATES: #REF!
Name Debit: [5]JOURNAL!#REF!
Name Debit: [5]JOURNAL!#REF!

Sheet Coversheet

Sheet Connect Information
A7: Web Server Machine Name: | B7: fimprod.corp.oncor.com
A8: Portal: | B8: EMPLOYEE
A9: HTTP Port: | B9: 44300
A10: Protocol: | B10: https
A11: PeopleSoft Site Name: | B11: fimprod
A12: Node: | B12: PSFT_EP
A13: Blocking Factor: | B13: 40
A15: Action: | B15: CREATE
A16: Chunking | B16: 50
A20: TU_ACCT_REC_ENTRY

Sheet Template
A2: TU_ACCT_REC_ENTRY
A5: Collection | D5: TU_ACCT_REC_ENTRY | E5: TU_ACCT_REC_ENTRY | F5: TU_ACCT_REC_ENTRY | G5: TU_ACCT_REC_ENTRY | H5: TU_ACCT_REC_ENTRY | I5: TU_ACCT_REC_ENTRY | J5: TU_ACCT_REC_ENTRY | K5: TU_ACCT_REC_ENTRY | L5: TU_ACCT_REC_ENTRY | M5: TU_ACCT_REC_ENTRY | N5: TU_ACCT_REC_ENTRY | O5: TU_ACCT_REC_ENTRY | P5: TU_ACCT_REC_ENTRY | Q5: TU_ACCT_REC_ENTRY | R5: TU_ACCT_REC_ENTRY | S5: TU_ACCT_REC_ENTRY | T5: TU_ACCT_REC_LN | U5: TU_ACCT_REC_LN | V5: TU_ACCT_REC_LN | W5: TU_ACCT_REC_LN | X5: TU_ACCT_REC_LN | Y5: TU_ACCT_REC_LN | Z5: TU_ACCT_REC_LN | AA5: TU_ACCT_REC_LN | AB5: TU_ACCT_REC_LN | AC5: TU_ACCT_REC_LN | AD5: TU_ACCT_REC_LN
A6: Property | D6: BUSINESS_UNIT | E6: MONTH | F6: YEAR | G6: TU_ACCT_REF_NUM | H6: TU_BU_TYPE | I6: TU_BU_GROUP | J6: TU_RECON_FREQ | K6: TU_SOURCE_OF_INFO | L6: TU_BAL_PER_GL | M6: TU_BAL_PER_SYS | N6: TU_TOT_HRS_ACCTRCN | O6: OPRID | P6: TU_REC_PREP_DT | Q6: TU_APPROVER_ID | R6: TU_REC_APPRV_DT | S6: TU_ACCOUNTINGOWNER | T6: SEQNBR | U6: TU_ACCT_REC_DTL_BU | V6: ACCOUNT | W6: DEPTID | X6: AFFILIATE | Y6: TU_EC | Z6: TU_ACTIVITY | AA6: TU_LOCATION | AB6: PROJECT_ID | AC6: MONETARY_AMOUNT | AD6: TU_ACCT_REC_DTLCMT
A7: Record Type | D7: 000 | E7: 000 | F7: 000 | G7: 000 | H7: 000 | I7: 000 | J7: 000 | K7: 000 | L7: 000 | M7: 000 | N7: 000 | O7: 000 | P7: 000 | Q7: 000 | R7: 000 | S7: 000 | T7: 100 | U7: 100 | V7: 100 | W7: 100 | X7: 100 | Y7: 100 | Z7: 100 | AA7: 100 | AB7: 100 | AC7: 100 | AD7: 100
A8: Field Type | P8: CHAR | R8: CHAR
A9: Key / Required | D9: Y/R | E9: Y/R | F9: Y/R | G9: Y/R | H9: Y/R | I9: Y/R | J9: / | K9: / | L9: / | M9: / | N9: / | O9: / | P9: / | Q9: / | R9: / | S9: / | T9: Y/ | U9: / | V9: / | W9: / | X9: / | Y9: / | Z9: / | AA9: / | AB9: / | AC9: / | AD9: /
A10: Sequence | D10: 1 | E10: 2 | F10: 3 | G10: 4 | H10: 5 | I10: 6 | J10: 7 | K10: 8 | L10: 9 | M10: 10 | N10: 11 | O10: 12 | P10: 13 | Q10: 14 | R10: 15 | S10: 16 | T10: 17 | U10: 18 | V10: 19 | W10: 20 | X10: 21 | Y10: 22 | Z10: 23 | AA10: 24 | AB10: 25 | AC10: 26 | AD10: 27
A11: Status | B11: Line No | C11: Record type | D11: Business Unit | E11: Month | F11: Year | G11: Account Recon Reference Group | H11: Business Unit Type | I11: Business Unit Recon Group | J11: Reconcile Frequency | K11: Source of Information | L11: General Ledger Balance | M11: Balance Per System/WorkSheet | N11: Total Hours Doing Acct Recon | O11: User ID | P11: Account Recon Prep Date | Q11: Approver ID | R11: Account Recon Approved Date | S11: Accounting Owner | T11: Sequence Number | U11: Acct Recon Detail Line BU | V11: Account | W11: Department | X11: Affiliate | Y11: Expense Code | Z11: Activity | AA11: Location | AB11: Project | AC11: Monetary Amount | AD11: Acct Recon Detail Line Comment
A12: Template | C12: 000
A13: Template | C13: 100

Sheet Data Input
A2: Business Unit | B2: Month | C2: Year | D2: Account Recon Reference Group | E2: Business Unit Type | F2: Business Unit Recon Group | G2: Reconcile Frequency | H2: Source of Information | I2: General Ledger Balance | J2: Balance Per System/WorkSheet | K2: Total Hours Doing Acct Recon | L2: User ID | M2: Account Recon Prep Date | N2: Approver ID | O2: Account Recon Approved Date | P2: Accounting Owner | Q2: Acct Recon Detail Line BU | R2: Account | S2: Department | T2: Affiliate | U2: Expense Code | V2: Activity | W2: Location | X2: Project | Y2: Monetary Amount | Z2: Acct Recon Detail Line Comment

Sheet WP II-E-4.1.1 AMS RCE
I6: 5
E7: Approved | F7: Amortizations | G7: At 12-31-2021 | I7: year | K7: Account 928
A8: Unit | B8: Account | C8: Project | D8: Description | E8: Rate Case Expenses | F8: through 12-31-2021 | G8: Reconciled Balance | I8: Amortization | J8: Test year amortizations | K8: K&M adjustment #36
A9: ESD | B9: 1861101 | C9: 11AMSREC | D9: 2011 AMS Reconciliation Case | E9: ='11AMSREC'!B22+SUM('11AMSREC'!F22:F25)+'11AMSREC'!F46 -> 608959.52 | F9: =ROUND(SUM('11AMSREC'!D17:D144),2) -> 580688.66 | G9: =+E9-F9 -> 28270.86 | I9: =ROUND(G9/I$6,2) -> 5654.17 | J9: =SUM('11AMSREC'!D133:D144) -> 31219.68 | K9: =I9-J9 -> -25565.51
A10: ESD | B10: 1861101 | C10: 13AMSREC | D10: 2013 AMS Reconciliation Expense | E10: ='13AMSREC'!B48+'13AMSREC'!F49+'13AMSREC'!F51+'13AMSREC'!F52 -> 312730.25 | F10: =SUM('13AMSREC'!D48:D145) -> 293148.48 | G10: =+E10-F10 -> 19581.768 | I10: =ROUND(G10/I$6,2) -> 3916.35 | J10: =SUM('13AMSREC'!D134:D145) -> 21624 | K10: =I10-J10 -> -17707.65
A11: ESD | B11: 1861101 | C11: DOC35718 | D11: Rate Case Expenses for AMS | E11: ='DOC35718'!B12+SUM('DOC35718'!F12:F71) -> 921535.55 | F11: =ROUND(SUM('DOC35718'!D11:D168),2) -> 889308.49 | G11: =+E11-F11 -> 32227.06 | I11: =ROUND(G11/I$6,2) -> 6445.41 | J11: =SUM('DOC35718'!D157:D168) -> 35588.28 | K11: =I11-J11 -> -29142.87
E12: =SUM(E9:E11) -> 1843225.3 | F12: =SUM(F9:F11) -> 1763145.6 | G12: =SUM(G9:G11) -> 80079.688 | I12: =SUM(I9:I11) -> 16015.93 | J12: =SUM(J9:J11) -> 88431.96 | K12: =SUM(K9:K11) -> -72416.03
A14: These rate case expenses were approved in Docket No. 46957. Reference Docket No. 46957 Finding of Fact Nos.:
A15: 36. All Oncor investment, including advanced metering system (AMS) investment, through
A16: the end of the test year (December 31, 2016) of $10,989,502,464, including
A17: $12,570,327,998 of net plant in service, as presented in Oncor's RFP, is prudent and
A18: includable in rate base, except that the six neighborhood reliability lithium-ion batteries
A19: used by Oncor are not included in this finding. Oncor can seek a prudence finding related
A20: to these batteries in a future proceeding.
A21: 37. All investment in the distribution and transmission assets that are provided to Oncor in the
A22: Sharyland Transaction are used by and useful to Oncor in providing service, are prudent,
A23: reasonable, and necessary, and are includable in Oncor's rate base, which with the
A24: inclusion of those assets is $10,991,993,213.
A26: Five-year amortizations were approved in Docket No. 46957 and began 11-27-2017 when rates were effective. In this case, requesting five-year amortization of unamortized balances at 12-31-2021 that were previously approved.

Sheet 11AMSREC
A10: Date | B10: Beginning Balance | D10: Monthly Amortization | F10: Adjustments | H10: Ending Balance | J10: Periods Remaining
A12: 40544 | D12: =B12/J12 -> 0 | H12: =B12-D12+F12 -> 0 | J12: 108
A13: 40575 | D13: =B13/J13 -> 0 | H13: =B13-D13+F13 -> 0 | J13: 107
A14: 40603 | D14: =B14/J14 -> 0 | H14: =B14-D14+F14 -> 0 | J14: 106
A15: 40634 | D15: =B15/J15 -> 0 | H15: =B15-D15+F15 -> 0 | J15: 105
A16: 40664 | D16: =B16/J16 -> 0 | H16: =B16-D16+F16 -> 0 | J16: 104
A17: 40695 | D17: =B17/J17 -> 0 | H17: =B17-D17+F17 -> 0 | J17: 103
A18: 40725 | D18: =B18/J18 -> 0 | H18: =B18-D18+F18 -> 0 | J18: 102
A19: 40756 | D19: =B19/J19 -> 0 | H19: =B19-D19+F19 -> 0 | J19: 101
A20: 40787 | D20: =B20/J20 -> 0 | H20: =B20-D20+F20 -> 0 | J20: 100
A21: 40817 | D21: =B21/J21 -> 0 | H21: =B21-D21+F21 -> 0 | J21: 99
A22: 40848 | B22: 597920.8 | D22: =B22/J22 -> 6101.2327 | F22: 52254.57 | H22: =B22-D22+F22 -> 644074.14 | J22: 98
A23: 40878 | B23: =H22 -> 644074.14 | D23: =B23/J23 -> 6639.9396 | F23: -55795.45 | H23: =B23-D23+F23 -> 581638.75 | J23: 97
A24: 40909 | B24: =H23 -> 581638.75 | D24: =B24/J24 -> 6058.737 | F24: 14624.96 | H24: =B24-D24+F24 -> 590204.97 | J24: 96
A25: 40940 | B25: =H24 -> 590204.97 | D25: =B25/J25 -> 6212.6839 | F25: 381.04 | H25: =B25-D25+F25 -> 584373.33 | J25: 95
A26: 40969 | B26: =H25 -> 584373.33 | D26: =ROUND((B26/J26),2) -> 6216.74 | F26: 0 | H26: =B26-D26+F26 -> 578156.59 | J26: 94
A27: 41000 | B27: =H26 -> 578156.59 | D27: =ROUND((B27/J27),2) -> 6216.74 | H27: =B27-D27+F27 -> 571939.85 | J27: 93
A28: 41030 | B28: =H27 -> 571939.85 | D28: =ROUND((B28/J28),2) -> 6216.74 | H28: =B28-D28+F28 -> 565723.11 | J28: 92
A29: 41061 | B29: =H28 -> 565723.11 | D29: =ROUND((B29/J29),2) -> 6216.74 | H29: =B29-D29+F29 -> 559506.37 | J29: 91
A30: 41091 | B30: =H29 -> 559506.37 | D30: =ROUND((B30/J30),2) -> 6216.74 | H30: =B30-D30+F30 -> 553289.63 | J30: 90
A31: 41122 | B31: =H30 -> 553289.63 | D31: =ROUND((B31/J31),2) -> 6216.74 | H31: =B31-D31+F31 -> 547072.89 | J31: 89
A32: 41153 | B32: =H31 -> 547072.89 | D32: =ROUND((B32/J32),2) -> 6216.74 | F32: 719.55 | H32: =B32-D32+F32 -> 541575.7 | J32: 88
A33: 41183 | B33: =H32 -> 541575.7 | D33: =ROUND((B33/J33),2) -> 6225.01 | F33: -719.55 | H33: =B33-D33+F33 -> 534631.14 | J33: 87
A34: 41214 | B34: =H33 -> 534631.14 | D34: =ROUND((B34/J34),2) -> 6216.64 | H34: =B34-D34+F34 -> 528414.5 | J34: 86
A35: 41244 | B35: =H34 -> 528414.5 | D35: =ROUND((B35/J35),2) -> 6216.64 | H35: =B35-D35+F35 -> 522197.86 | J35: 85
A36: 41275 | B36: =H35 -> 522197.86 | D36: =ROUND((B36/J36),2) -> 6216.64 | H36: =B36-D36+F36 -> 515981.22 | J36: 84
A37: 41306 | B37: =H36 -> 515981.22 | D37: =ROUND((B37/J37),2) -> 6216.64 | H37: =B37-D37+F37 -> 509764.58 | J37: 83
A38: 41334 | B38: =H37 -> 509764.58 | D38: =ROUND((B38/J38),2) -> 6216.64 | H38: =B38-D38+F38 -> 503547.94 | J38: 82
A39: 41365 | B39: =H38 -> 503547.94 | D39: =ROUND((B39/J39),2) -> 6216.64 | H39: =B39-D39+F39 -> 497331.3 | J39: 81
A40: 41395 | B40: =H39 -> 497331.3 | D40: =ROUND(B40/J40,2) -> 6216.64 | H40: =B40-D40+F40 -> 491114.66 | J40: 80
A41: 41426 | B41: =H40 -> 491114.66 | D41: =B41/J41 -> 6216.6412 | H41: =B41-D41+F41 -> 484898.02 | J41: 79
A42: 41456 | B42: =H41 -> 484898.02 | D42: =B42/J42 -> 6216.6412 | H42: =B42-D42+F42+0.01 -> 478681.38 | J42: 78
A43: 41487 | B43: =H42 -> 478681.38 | D43: =B43/J43 -> 6216.6414 | H43: =B43-D43+F43 -> 472464.74 | J43: 77
A44: 41518 | B44: =H43 -> 472464.74 | D44: =B44/J44 -> 6216.6414 | H44: =B44-D44+F44 -> 466248.1 | J44: 76
A45: 41548 | B45: =H44 -> 466248.1 | D45: =B45/J45 -> 6216.6414 | H45: =B45-D45+F45 -> 460031.46 | J45: 75
A46: 41579 | B46: =H45 -> 460031.46 | D46: =B46/J46 -> 6216.6414 | F46: =-636.55+210.15 -> -426.4 | H46: =B46-D46+F46 -> 453388.42 | J46: 74
A47: 41609 | B47: =H46 -> 453388.42 | D47: =B47/J47 -> 6210.8003 | F47: 0 | H47: =B47-D47+F47 -> 447177.62 | J47: 73
A48: 41640 | B48: =H47 -> 447177.62 | D48: =B48/J48 -> 6210.8003 | H48: =B48-D48+F48 -> 440966.82 | J48: 72
A49: 41671 | B49: =H48 -> 440966.82 | D49: =B49/J49 -> 6210.8003 | H49: =B49-D49+F49 -> 434756.02 | J49: 71
A50: 41699 | B50: =H49 -> 434756.02 | D50: =B50/J50 -> 6210.8003 | H50: =B50-D50+F50 -> 428545.22 | J50: 70
...

Sheet 13AMSREC
A11: Date | B11: Beginning Balance | D11: Monthly Amortization | F11: Adjustments | H11: Ending Balance | J11: Periods Remaining
A13: 40544 | D13: =B13/J13 -> 0 | H13: =B13-D13+F13 -> 0 | J13: 108
A14: 40575 | D14: =B14/J14 -> 0 | H14: =B14-D14+F14 -> 0 | J14: 107
A15: 40603 | D15: =B15/J15 -> 0 | H15: =B15-D15+F15 -> 0 | J15: 106
A16: 40634 | D16: =B16/J16 -> 0 | H16: =B16-D16+F16 -> 0 | J16: 105
A17: 40664 | D17: =B17/J17 -> 0 | H17: =B17-D17+F17 -> 0 | J17: 104
A18: 40695 | D18: =B18/J18 -> 0 | H18: =B18-D18+F18 -> 0 | J18: 103
A19: 40725 | D19: =B19/J19 -> 0 | H19: =B19-D19+F19 -> 0 | J19: 102
A20: 40756 | D20: =B20/J20 -> 0 | H20: =B20-D20+F20 -> 0 | J20: 101
A21: 40787 | D21: =B21/J21 -> 0 | H21: =B21-D21+F21 -> 0 | J21: 100
A22: 40817 | D22: =B22/J22 -> 0 | H22: =B22-D22+F22 -> 0 | J22: 99
A23: 40848 | B23: 0 | D23: =B23/J23 -> 0 | H23: =B23-D23+F23 -> 0 | J23: 98
A24: 40878 | B24: 0 | D24: =B24/J24 -> 0 | H24: =B24-D24+F24 -> 0 | J24: 97
A25: 40909 | B25: 0 | D25: =B25/J25 -> 0 | H25: =B25-D25+F25 -> 0 | J25: 96
A26: 40940 | B26: 0 | D26: =B26/J26 -> 0 | H26: =B26-D26+F26 -> 0 | J26: 95
A27: 40969 | B27: 0 | D27: =ROUND((B27/J27),2) -> 0 | H27: =B27-D27+F27 -> 0 | J27: 94
A28: 41000 | B28: 0 | D28: =ROUND((B28/J28),2) -> 0 | H28: =B28-D28+F28 -> 0 | J28: 93
A29: 41030 | B29: 0 | D29: =ROUND((B29/J29),2) -> 0 | H29: =B29-D29+F29 -> 0 | J29: 92
A30: 41061 | B30: 0 | D30: =ROUND((B30/J30),2) -> 0 | H30: =B30-D30+F30 -> 0 | J30: 91
A31: 41091 | B31: 0 | D31: =ROUND((B31/J31),2) -> 0 | H31: =B31-D31+F31 -> 0 | J31: 90
A32: 41122 | B32: 0 | D32: =ROUND((B32/J32),2) -> 0 | H32: =B32-D32+F32 -> 0 | J32: 89
A33: 41153 | B33: 0 | D33: =ROUND((B33/J33),2) -> 0 | H33: =B33-D33+F33 -> 0 | J33: 88
A34: 41183 | B34: 0 | D34: =ROUND((B34/J34),2) -> 0 | H34: =B34-D34+F34 -> 0 | J34: 87
A35: 41214 | B35: 0 | D35: =ROUND((B35/J35),2) -> 0 | H35: =B35-D35+F35 -> 0 | J35: 86
A36: 41244 | B36: 0 | D36: =ROUND((B36/J36),2) -> 0 | H36: =B36-D36+F36 -> 0 | J36: 85
A37: 41275 | B37: 0 | D37: =ROUND((B37/J37),2) -> 0 | H37: =B37-D37+F37 -> 0 | J37: 84
A38: 41306 | B38: 0 | D38: =ROUND((B38/J38),2) -> 0 | H38: =B38-D38+F38 -> 0 | J38: 83
... A40: 41365 | B40: 0 | D40: =ROUND((B40/J40),2) -> 0 | H40: =B40-D40+F40 -> 0 | J40: 81
A41: 41395 | B41: 0 | D41: =ROUND(B41/J41,2) -> 0 | H41: =B41-D41+F41 -> 0 | J41: 80
A42: 41426 | B42: 0 | D42: =B42/J42 -> 0 | H42: =B42-D42+F42 -> 0 | J42: 79
A43: 41456 | B43: 0 | D43: =B43/J43 -> 0 | H43: =B43-D43+F43+0.01 -> 0.01 | J43: 78
A44: 41487 | B44: 0 | D44: =B44/J44 -> 0 | H44: =B44-D44+F44 -> 0 | J44: 77
A45: 41518 | B45: 0 | D45: =B45/J45 -> 0 | H45: =B45-D45+F45 -> 0 | J45: 76
A46: 41548 | B46: 0 | D46: =B46/J46 -> 0 | H46: =B46-D46+F46 -> 0 | J46: 75
A47: 41579 | B47: 0 | D47: =B47/J47 -> 0 | H47: =B47-D47+F47 -> 0 | J47: 74
A48: 41609 | B48: 276508.26 | D48: =B48/J48 -> 3787.7844 | H48: =B48-D48+F48 -> 272720.48 | J48: 73
A49: 41640 | B49: =H48 -> 272720.48 | D49: =B49/J49 -> 3787.7844 | F49: 26733 | H49: =B49-D49+F49 -> 295665.69 | J49: 72
A50: 41671 | B50: =H49 -> 295665.69 | D50: =B50/J50 -> 4164.3055 | H50: =B50-D50+F50 -> 291501.39 | J50: 71
A51: 41699 | B51: =H50 -> 291501.39 | D51: =B51/J51 -> 4164.3055 | F51: 9342.99 | H51: =B51-D51+F51 -> 296680.07 | J51: 70
A52: 41730 | B52: =H51 -> 296680.07 | D52: =B52/J52 -> 4299.7112 | F52: 146 | H52: =B52-D52+F52 -> 292526.36 | J52: 69
...

Sheet DOC35718
A10: Date | B10: Beginning Balance | D10: Monthly Amortization | F10: Adjustments | H10: Ending Balance | J10: Periods Remaining
A12: 39814 | B12: 889574.23 | D12: =ROUND(B12/J12,2) -> 6739.2 | F12: 3044.78 | H12: =B12-D12+F12 -> 885879.81 | J12: 132
A13: 39845 | B13: =H12 -> 885879.81 | D13: =ROUND(B13/J13,2) -> 6762.44 | F13: 18469.94 | H13: =B13-D13+F13 -> 897587.31 | J13: 131
A14: 39873 | B14: =H13 -> 897587.31 | D14: =ROUND(B14/J14,2) -> 6904.52 | F14: -58992.68 | H14: =B14-D14+F14 -> 831690.11 | J14: 130
A15: 39904 | B15: =H14 -> 831690.11 | D15: =ROUND(B15/J15,2) -> 6447.21 | F15: 3613.81 | H15: =B15-D15+F15 -> 828856.71 | J15: 129
A16: 39934 | B16: =H15 -> 828856.71 | D16: =ROUND(B16/J16,2) -> 6475.44 | F16: 13496.48 | H16: =B16-D16+F16 -> 835877.75 | J16: 128
A17: 39965 | B17: =H16 -> 835877.75 | D17: =ROUND(B17/J17,2) -> 6581.71 | F17: 1882.57 | H17: =B17-D17+F17 -> 831178.61 | J17: 127
A18: 39995 | B18: =H17 -> 831178.61 | D18: =ROUND(B18/J18,2) -> 6596.66 | F18: 1558.99 | H18: =B18-D18+F18 -> 826140.94 | J18: 126
A19: 40026 | B19: =H18 -> 826140.94 | D19: =ROUND(B19/J19,2) -> 6609.13 | F19: 1306.99 | H19: =B19-D19+F19 -> 820838.8 | J19: 125
A20: 40057 | B20: =H19 -> 820838.8 | D20: =ROUND(B20/J20,2) -> 6619.67 | F20: 1233.88 | H20: =B20-D20+F20 -> 815453.01 | J20: 124
A21: 40087 | B21: =H20 -> 815453.01 | D21: =ROUND(B21/J21,2) -> 6629.7 | F21: 137.18 | H21: =B21-D21+F21 -> 808960.49 | J21: 123
A22: 40118 | B22: =H21 -> 808960.49 | D22: =ROUND(B22/J22,2) -> 6630.82 | F22: 315.91 | H22: =B22-D22+F22 -> 802645.58 | J22: 122
A23: 40148 | B23: =H22 -> 802645.58 | D23: =ROUND(B23/J23,2) -> 6633.43 | F23: 703.74 | H23: =B23-D23+F23 -> 796715.89 | J23: 121
A24: 40179 | B24: =H23 -> 796715.89 | D24: =ROUND(B24/J24,2) -> 6639.3 | F24: 403.11 | H24: =B24-D24+F24 -> 790479.7 | J24: 120
... A59: 41244 | B59: =H58 -> 601166.91 | D59: =ROUND(B59/J59,2) -> 7072.55 | F59: 626.96 | H59: =B59-D59+F59 -> 594721.32 | J59: 85
A60: 41275 | B60: =H59 -> 594721.32 | D60: =ROUND(B60/J60,2) -> 7080.02 | H60: =B60-D60+F60 -> 587641.3 | J60: 84
A61: 41306 | B61: =H60 -> 587641.3 | D61: =ROUND(B61/J61,2) -> 7080.02 | H61: =B61-D61+F61 -> 580561.28 | J61: 83
A62: 41334 | B62: =H61 -> 580561.28 | D62: =ROUND(B62/J62,2) -> 7080.02 | H62: =B62-D62+F62 -> 573481.26 | J62: 82
A63: 41365 | B63: =H62 -> 573481.26 | D63: =ROUND(B63/J63,2) -> 7080.02 | H63: =B63-D63+F63 -> 566401.24 | J63: 81
A64: 41395 | B64: =H63 -> 566401.24 | D64: =ROUND(B64/J64,2) -> 7080.02 | H64: =B64-D64+F64 -> 559321.22 | J64: 80
A65: 41426 | B65: =H64 -> 559321.22 | D65: =ROUND(B65/J65,2) -> 7080.02 | H65: =B65-D65+F65 -> 552241.2 | J65: 79
A66: 41456 | B66: =H65 -> 552241.2 | D66: =ROUND(B66/J66,2) -> 7080.02 | H66: =B66-D66+F66 -> 545161.18 | J66: 78
A67: 41487 | B67: =H66 -> 545161.18 | D67: =B67/J67 -> 7080.0153 | H67: =B67-D67+F67 -> 538081.16 | J67: 77
A68: 41518 | B68: =H67 -> 538081.16 | D68: =B68/J68 -> 7080.0153 | H68: =B68-D68+F68-0.01 -> 531001.14 | J68: 76
A69: 41548 | B69: =H68 -> 531001.14 | D69: =B69/J69 -> 7080.0152 | H69: =B69-D69+F69 -> 523921.12 | J69: 75
A70: 41579 | B70: =H69 -> 523921.12 | D70: =B70/J70 -> 7080.0152 | F70: -9 | H70: =B70-D70+F70-0.01 -> 516832.1 | J70: 74
A71: 41609 | B71: =H70 -> 516832.1 | D71: =B71/J71 -> 7079.8918 | F71: 0 | H71: =B71-D71+F71 -> 509752.21 | J71: 73
A72: 41640 | B72: =H71 -> 509752.21 | D72: =B72/J72 -> 7079.8918 | H72: =B72-D72+F72 -> 502672.32 | J72: 72
A73: 41671 | B73: =H72 -> 502672.32 | D73: =B73/J73 -> 7079.8918 | H73: =B73-D73+F73+0.01 -> 495592.43 | J73: 71
A74: 41699 | B74: =H73 -> 495592.43 | D74: =B74/J74 -> 7079.8919 | H74: =B74-D74+F74 -> 488512.54 | J74: 70
A75: 41730 | B75: =H74 -> 488512.54 | D75: =B75/J75 -> 7079.8919 | H75: =B75-D75+F75 -> 481432.65 | J75: 69
A76: 41760 | B76: =H75 -> 481432.65 | D76: =B76/J76 -> 7079.8919 | H76: =B76-D76+F76 -> 474352.76 | J76: 68
A77: 41791 | B77: =H76 -> 474352.76 | D77: =B77/J77 -> 7079.8919 | H77: =B77-D77+F77 -> 467272.87 | J77: 67
A78: 41821 | B78: =H77 -> 467272.87 | D78: =B78/J78 -> 7079.8919 | H78: =B78-D78+F78 -> 460192.97 | J78: 66
A79: 41852 | B79: =H78 -> 460192.97 | D79: =B79/J79 -> 7079.8919 | H79: =B79-D79+F79 -> 453113.08 | J79: 65
A80: 41883 | B80: =H79 -> 453113.08 | D80: =B80/J80-0.01 -> 7079.8819 | H80: =B80-D80+F80 -> 446033.2 | J80: 64
A81: 41913 | B81: =H80 -> 446033.2 | D81: =B81/J81 -> 7079.8921 | H81: =B81-D81+F81 -> 438953.31 | J81: 63
A82: 41944 | B82: =H81 -> 438953.31 | D82: =B82/J82 -> 7079.8921 | H82: =B82-D82+F82 -> 431873.42 | J82: 62
A83: 41974 | B83: =H82 -> 431873.42 | D83: =B83/J83 -> 7079.8921 | H83: =B83-D83+F83 -> 424793.52 | J83: 61
A84: 42005 | B84: =H83 -> 424793.52 | D84: =B84/J84 -> 7079.8921 | H84: =B84-D84+F84 -> 417713.63 | J84: 60
...
