Workbook
Name IQ_CH: 110000
Name IQ_CQ: 5000
Name IQ_CY: 10000
Name IQ_DAILY: 500000
Name IQ_FH: 100000
Name IQ_FQ: 500
Name IQ_FY: 1000
Name IQ_LTM: 2000
Name IQ_MONTH: 15000
Name IQ_NTM: 6000
Name IQ_WEEK: 50000
Name IQ_YTD: 3000

Sheet AEB-2 Summary
B2: SUMMARY OF COE ANALYSES RESULTS
J4: X | K4: Y
B5: Constant Growth DCF | I5: Constant Growth Mean DCF | J5: =C12 -> 0.087007831 | K5: 7.5
C6: Minimum | D6: Average | E6: Maximum | J6: =D12 -> 0.099570678 | K6: 7.5
C7: Growth Rate | D7: Growth Rate | E7: Growth Rate | J7: =E12 -> 0.11159326 | K7: 7.5
B8: Mean Results: | I8: Constant Growth Median DCF | J8: =C18 -> 0.086894916 | K8: 6.5
B9: 30-Day Average | C9: ='AEB-4 CGDCF'!K21 -> 0.086842598 | D9: ='AEB-4 CGDCF'!L21 -> 0.099403256 | E9: ='AEB-4 CGDCF'!M21 -> 0.11142474 | J9: =D18 -> 0.098058195 | K9: 6.5
B10: 90-Day Average | C10: ='AEB-4 CGDCF'!K57 -> 0.087744025 | D10: ='AEB-4 CGDCF'!L57 -> 0.10031114 | E10: ='AEB-4 CGDCF'!M57 -> 0.11233823 | J10: =E18 -> 0.10709428 | K10: 6.5
B11: 180-Day Average | C11: ='AEB-4 CGDCF'!K93 -> 0.086436869 | D11: ='AEB-4 CGDCF'!L93 -> 0.098997633 | E11: ='AEB-4 CGDCF'!M93 -> 0.11101681 | I11: CAPM | J11: =MIN(C26:E28) -> 0.10385584 | K11: 3
B12: Average | C12: =AVERAGE(C9:C11) -> 0.087007831 | D12: =AVERAGE(D9:D11) -> 0.099570678 | E12: =AVERAGE(E9:E11) -> 0.11159326 | J12: =MAX(C26:E28) -> 0.11630715 | K12: 3
I13: ECAPM | J13: =MIN(C31:E33) -> 0.10844022 | K13: 2
B14: Median Results: | J14: =MAX(C31:E33) -> 0.11777871 | K14: 2
B15: 30-Day Average | C15: ='AEB-4 CGDCF'!K22 -> 0.087327287 | D15: ='AEB-4 CGDCF'!L22 -> 0.09811952 | E15: ='AEB-4 CGDCF'!M22 -> 0.10766884 | I15: Risk Premium | J15: =C35 -> 0.10353074 | K15: 1
B16: 90-Day Average | C16: ='AEB-4 CGDCF'!K58 -> 0.087821922 | D16: ='AEB-4 CGDCF'!L58 -> 0.09919911 | E16: ='AEB-4 CGDCF'!M58 -> 0.10857999 | J16: =E35 -> 0.10298988 | K16: 1
B17: 180-Day Average | C17: ='AEB-4 CGDCF'!K94 -> 0.085535541 | D17: ='AEB-4 CGDCF'!L94 -> 0.096855957 | E17: ='AEB-4 CGDCF'!M94 -> 0.10503401 | I17: Low End ROE Recommendation | J17: 0.1 | K17: 0
B18: Average | C18: =AVERAGE(C15:C17) -> 0.086894916 | D18: =AVERAGE(D15:D17) -> 0.098058195 | E18: =AVERAGE(E15:E17) -> 0.10709428 | J18: =J17 -> 0.1 | K18: 9 | M18: 0
I19: High End ROE Recommendation | J19: 0.11 | K19: =K17 -> 0 | M19: 9
B20: CAPM / ECAPM / Bond Yield Risk Premium | J20: =J19 -> 0.11 | K20: 9 | M20: =M18 -> 0
C21: Current | D21: Near-Term | E21: Longer-Term | I21: Recommended ROE | J21: 0.106 | K21: 4 | M21: 9
C22: 30-Day Avg | D22: Projected | E22: Projected | M22: 2.8
C23: 30-Year | D23: 30-Year | E23: 30-Year
C24: Treasury Yield | D24: Treasury Yield | E24: Treasury Yield
B25: CAPM:
B26: Value Line Beta | C26: ='AEB-5 CAPM'!H24 -> 0.11630715 | D26: ='AEB-5 CAPM'!H58 -> 0.1162392 | E26: ='AEB-5 CAPM'!H92 -> 0.1162392
B27: Bloomberg Beta | C27: ='AEB-5 CAPM'!H126 -> 0.10637532 | D27: ='AEB-5 CAPM'!H160 -> 0.1061927 | E27: ='AEB-5 CAPM'!H194 -> 0.1061927
B28: Long-term Avg. Beta | C28: ='AEB-5 CAPM'!H228 -> 0.10406513 | D28: ='AEB-5 CAPM'!H262 -> 0.10385584 | E28: ='AEB-5 CAPM'!H296 -> 0.10385584
B30: ECAPM:
B31: Value Line Beta | C31: ='AEB-5 CAPM'!I24 -> 0.11777871 | D31: ='AEB-5 CAPM'!I58 -> 0.11772774 | E31: ='AEB-5 CAPM'!I92 -> 0.11772774
B32: Bloomberg Beta | C32: ='AEB-5 CAPM'!I126 -> 0.11032983 | D32: ='AEB-5 CAPM'!I160 -> 0.11019287 | E32: ='AEB-5 CAPM'!I194 -> 0.11019287
B33: Long-term Avg. Beta | C33: ='AEB-5 CAPM'!I228 -> 0.10859719 | D33: ='AEB-5 CAPM'!I262 -> 0.10844022 | E33: ='AEB-5 CAPM'!I296 -> 0.10844022
B35: Bond Yield Risk Premium: | C35: ='AEB-8 Risk Premium'!L47 -> 0.10353074 | D35: ='AEB-8 Risk Premium'!L48 -> 0.10298988 | E35: ='AEB-8 Risk Premium'!L49 -> 0.10298988

Sheet AEB-3 Proxy Selection
B2: PROXY GROUP SCREENING DATA AND RESULTS
D4: [1] | E4: [2] | F4: [3] | G4: [4] | H4: [5] | I4: [6] | J4: [7]
B5: Company | C5: Ticker | D5: Dividends | E5: S&P Credit Rating Between BBB- and AAA | F5: Covered by More Than 1 Analyst | G5: Positive Growth Rates from at least two sources (Value Line, Yahoo! First Call, and Zacks) | H5: % Regulated Operating Income > 60% | I5: % Regulated Electric Operating Income > 80% | J5: Announced Merger
B6: ALLETE, Inc. | C6: ALE | D6: Yes | E6: BBB | F6: Yes | G6: Yes | H6: 1.0283657 | I6: 0.97763701 | J6: No
B7: Alliant Energy Corporation | C7: LNT | D7: Yes | E7: A- | F7: Yes | G7: Yes | H7: 0.96960694 | I7: 0.90661304 | J7: No
B8: Ameren Corporation | C8: AEE | D8: Yes | E8: BBB+ | F8: Yes | G8: Yes | H8: 1 | I8: 0.84572446 | J8: No
B9: Duke Energy Corporation | C9: DUK | D9: Yes | E9: BBB+ | F9: Yes | G9: Yes | H9: 0.9965541 | I9: 0.91341602 | J9: No
B10: Edison International | C10: EIX | D10: Yes | E10: BBB | F10: Yes | G10: Yes | H10: 0.989318 | I10: 1 | J10: No
B11: Entergy Corporation | C11: ETR | D11: Yes | E11: BBB+ | F11: Yes | G11: Yes | H11: 0.9873811 | I11: 0.99461878 | J11: No
B12: Eversource Energy | C12: ES | D12: Yes | E12: A- | F12: Yes | G12: Yes | H12: 0.92382204 | I12: 0.85354453 | J12: No
B13: Evergy, Inc. | C13: EVRG | D13: Yes | E13: BBB+ | F13: Yes | G13: Yes | H13: 1 | I13: 1 | J13: No
B14: IDACORP, Inc. | C14: IDA | D14: Yes | E14: BBB | F14: Yes | G14: Yes | H14: 0.99910992 | I14: 1 | J14: No
B15: NextEra Energy, Inc. | C15: NEE | D15: Yes | E15: A- | F15: Yes | G15: Yes | H15: 0.92156219 | I15: 1 | J15: No
B16: NorthWestern Corporation | C16: NWE | D16: Yes | E16: BBB | F16: Yes | G16: Yes | H16: 0.99748805 | I16: 0.84487532 | J16: No
B17: OGE Energy Corporation | C17: OGE | D17: Yes | E17: BBB+ | F17: Yes | G17: Yes | H17: 1 | I17: 1 | J17: No
... B20: Xcel Energy Inc. | C20: XEL | D20: Yes | E20: A- | F20: Yes | G20: Yes | H20: 1 | I20: 0.86467189 | J20: No
B23: Notes:
B24: [1] Bloomberg Professional
B25: [2] Bloomberg Professional
B26: [3] Yahoo! Finance and Zacks
B27: [4] Yahoo! Finance, Value Line Investment Survey, and Zacks
B28: [5] Form 10-K's for 2022, 2021, and 2020
B29: [6] Form 10-K's for 2022, 2021, and 2020
B30: [7] S&P Capital IQ Pro Financial News Releases

Sheet AEB-4 CGDCF
A2: 30-DAY CONSTANT GROWTH DCF -- AEP TEXAS PROXY GROUP
C4: [1] | D4: [2] | E4: [3] | F4: [4] | G4: [5] | H4: [6] | I4: [7] | J4: [8] | K4: [9] | L4: [10] | M4: [11]
A5: Company | B5: Ticker | C5: Annualized Dividend | D5: Stock Price | E5: Dividend Yield | F5: Expected Dividend Yield | G5: Value Line EPS Growth | H5: Yahoo! Finance EPS Growth | I5: Zacks EPS Growth | J5: Average Growth Rate | K5: Low ROE | L5: Mean ROE | M5: High ROE
A6: ='AEB-3 Proxy Selection'!B6 -> ALLETE, Inc. | B6: ='AEB-3 Proxy Selection'!C6 -> ALE | C6: 2.71 | D6: 60.598 | E6: =C6/D6 -> 0.044720948 | F6: =IFERROR(E6*(1+0.5*J6),"") -> 0.046375623 | G6: 0.06 | H6: 0.081 | I6: 0.081 | J6: =AVERAGE(G6:I6) -> 0.074 | K6: =$E6*(1+0.5*MIN($G6:$I6))+MIN($G6:$I6) -> 0.10606258 | L6: =F6+J6 -> 0.12037562 | M6: =$E6*(1+0.5*MAX($G6:$I6))+MAX($G6:$I6) -> 0.12753215
A7: ='AEB-3 Proxy Selection'!B7 -> Alliant Energy Corporation | B7: ='AEB-3 Proxy Selection'!C7 -> LNT | C7: 1.92 | D7: 49.881497 | E7: =C7/D7 -> 0.038491227 | F7: =IFERROR(E7*(1+0.5*J7),"") -> 0.039732569 | G7: 0.065 | H7: 0.0655 | I7: 0.063 | J7: =AVERAGE(G7:I7) -> 0.0645 | K7: =$E7*(1+0.5*MIN($G7:$I7))+MIN($G7:$I7) -> 0.1027037 | L7: =F7+J7 -> 0.10423257 | M7: =$E7*(1+0.5*MAX($G7:$I7))+MAX($G7:$I7) -> 0.10525181
A8: ='AEB-3 Proxy Selection'!B8 -> Ameren Corporation | B8: ='AEB-3 Proxy Selection'!C8 -> AEE | C8: 2.52 | D8: 71.507333 | E8: =C8/D8 -> 0.035241141 | F8: =IFERROR(E8*(1+0.5*J8),"") -> 0.036269007 | G8: 0.065 | H8: 0.048 | I8: 0.062 | J8: =AVERAGE(G8:I8) -> 0.058333333 | K8: =$E8*(1+0.5*MIN($G8:$I8))+MIN($G8:$I8) -> 0.084086928 | L8: =F8+J8 -> 0.094602341 | M8: =$E8*(1+0.5*MAX($G8:$I8))+MAX($G8:$I8) -> 0.10138648
A9: ='AEB-3 Proxy Selection'!B9 -> Duke Energy Corporation | B9: ='AEB-3 Proxy Selection'!C9 -> DUK | C9: 4.1 | D9: 96.902667 | E9: =C9/D9 -> 0.042310497 | F9: =IFERROR(E9*(1+0.5*J9),"") -> 0.043569234 | G9: 0.05 | H9: 0.0655 | I9: 0.063 | J9: =AVERAGE(G9:I9) -> 0.0595 | K9: =$E9*(1+0.5*MIN($G9:$I9))+MIN($G9:$I9) -> 0.09336826 | L9: =F9+J9 -> 0.10306923 | M9: =$E9*(1+0.5*MAX($G9:$I9))+MAX($G9:$I9) -> 0.10919617
A10: ='AEB-3 Proxy Selection'!B10 -> Edison International | B10: ='AEB-3 Proxy Selection'!C10 -> EIX | C10: 3.12 | D10: 69.70901 | E10: =C10/D10 -> 0.044757485 | F10: =IFERROR(E10*(1+0.5*J10),"") -> 0.045712312 | G10: 0.045 | H10: 0.046 | I10: 0.037 | J10: =AVERAGE(G10:I10) -> 0.042666667 | K10: =$E10*(1+0.5*MIN($G10:$I10))+MIN($G10:$I10) -> 0.082585499 | L10: =F10+J10 -> 0.088378978 | M10: =$E10*(1+0.5*MAX($G10:$I10))+MAX($G10:$I10) -> 0.091786908
A11: ='AEB-3 Proxy Selection'!B11 -> Entergy Corporation | B11: ='AEB-3 Proxy Selection'!C11 -> ETR | C11: 4.52 | D11: 101.03067 | E11: =C11/D11 -> 0.044738891 | F11: =IFERROR(E11*(1+0.5*J11),"") -> 0.04611834 | G11: 0.005 | H11: 0.11 | I11: 0.07 | J11: =AVERAGE(G11:I11) -> 0.061666667 | K11: =$E11*(1+0.5*MIN($G11:$I11))+MIN($G11:$I11) -> 0.049850738 | L11: =F11+J11 -> 0.10778501 | M11: =$E11*(1+0.5*MAX($G11:$I11))+MAX($G11:$I11) -> 0.15719953
A12: ='AEB-3 Proxy Selection'!B12 -> Eversource Energy | B12: ='AEB-3 Proxy Selection'!C12 -> ES | C12: 2.7 | D12: 58.34 | E12: =C12/D12 -> 0.046280425 | F12: =IFERROR(E12*(1+0.5*J12),"") -> 0.047344875 | G12: 0.06 | H12: 0.036 | I12: 0.042 | J12: =AVERAGE(G12:I12) -> 0.046 | K12: =$E12*(1+0.5*MIN($G12:$I12))+MIN($G12:$I12) -> 0.083113473 | L12: =F12+J12 -> 0.093344875 | M12: =$E12*(1+0.5*MAX($G12:$I12))+MAX($G12:$I12) -> 0.10766884
A13: ='AEB-3 Proxy Selection'!B13 -> Evergy, Inc. | B13: ='AEB-3 Proxy Selection'!C13 -> EVRG | C13: 2.57 | D13: 51.868 | E13: =C13/D13 -> 0.049548855 | F13: =IFERROR(E13*(1+0.5*J13),"") -> 0.050729769 | G13: 0.075 | H13: 0.025 | I13: 0.043 | J13: =AVERAGE(G13:I13) -> 0.047666667 | K13: =$E13*(1+0.5*MIN($G13:$I13))+MIN($G13:$I13) -> 0.075168215 | L13: =F13+J13 -> 0.098396436 | M13: =$E13*(1+0.5*MAX($G13:$I13))+MAX($G13:$I13) -> 0.12640694
A14: ='AEB-3 Proxy Selection'!B14 -> IDACORP, Inc. | B14: ='AEB-3 Proxy Selection'!C14 -> IDA | C14: 3.32 | D14: 95.875333 | E14: =C14/D14 -> 0.034628302 | F14: =IFERROR(E14*(1+0.5*J14),"") -> 0.035367039 | G14: 0.04 | H14: 0.044 | I14: 0.044 | J14: =AVERAGE(G14:I14) -> 0.042666667 | K14: =$E14*(1+0.5*MIN($G14:$I14))+MIN($G14:$I14) -> 0.075320868 | L14: =F14+J14 -> 0.078033706 | M14: =$E14*(1+0.5*MAX($G14:$I14))+MAX($G14:$I14) -> 0.079390125
A15: ='AEB-3 Proxy Selection'!B15 -> NextEra Energy, Inc. | B15: ='AEB-3 Proxy Selection'!C15 -> NEE | C15: 1.87 | D15: 59.981 | E15: =C15/D15 -> 0.031176539 | F15: =IFERROR(E15*(1+0.5*J15),"") -> 0.032502062 | G15: 0.095 | H15: 0.0781 | I15: 0.082 | J15: =AVERAGE(G15:I15) -> 0.085033333 | K15: =$E15*(1+0.5*MIN($G15:$I15))+MIN($G15:$I15) -> 0.11049398 | L15: =F15+J15 -> 0.1175354 | M15: =$E15*(1+0.5*MAX($G15:$I15))+MAX($G15:$I15) -> 0.12765742
A16: ='AEB-3 Proxy Selection'!B16 -> NorthWestern Corporation | B16: ='AEB-3 Proxy Selection'!C16 -> NWE | C16: 2.56 | D16: 49.779 | E16: =C16/D16 -> 0.051427309 | F16: =IFERROR(E16*(1+0.5*J16),"") -> 0.05252271 | G16: 0.035 | H16: 0.0408 | I16: 0.052 | J16: =AVERAGE(G16:I16) -> 0.0426 | K16: =$E16*(1+0.5*MIN($G16:$I16))+MIN($G16:$I16) -> 0.087327287 | L16: =F16+J16 -> 0.09512271 | M16: =$E16*(1+0.5*MAX($G16:$I16))+MAX($G16:$I16) -> 0.10476442
A17: ='AEB-3 Proxy Selection'!B17 -> OGE Energy Corporation | B17: ='AEB-3 Proxy Selection'!C17 -> OGE | C17: 1.6728 | D17: 34.14228 | E17: =C17/D17 -> 0.04899497 | F17: =IFERROR(E17*(1+0.5*J17),"") -> 0.050281088 | G17: 0.065 | H17: negative | I17: 0.04 | J17: =AVERAGE(G17:I17) -> 0.0525 | K17: =$E17*(1+0.5*MIN($G17:$I17))+MIN($G17:$I17) -> 0.08997487 | L17: =F17+J17 -> 0.10278109 | M17: =$E17*(1+0.5*MAX($G17:$I17))+MAX($G17:$I17) -> 0.11558731
A18: ='AEB-3 Proxy Selection'!B18 -> Pinnacle West Capital Corporation | B18: ='AEB-3 Proxy Selection'!C18 -> PNW | C18: 3.52 | D18: 70.492387 | E18: =C18/D18 -> 0.04993447 | F18: =IFERROR(E18*(1+0.5*J18),"") -> 0.05096645 | G18: 0.025 | H18: 0.059 | I18: 0.04 | J18: =AVERAGE(G18:I18) -> 0.041333333 | K18: =$E18*(1+0.5*MIN($G18:$I18))+MIN($G18:$I18) -> 0.075558651 | L18: =F18+J18 -> 0.092299783 | M18: =$E18*(1+0.5*MAX($G18:$I18))+MAX($G18:$I18) -> 0.11040754
A19: ='AEB-3 Proxy Selection'!B19 -> Portland General Electric Company | B19: ='AEB-3 Proxy Selection'!C19 -> POR | C19: 1.9 | D19: 42.268437 | E19: =C19/D19 -> 0.044950799 | F19: =IFERROR(E19*(1+0.5*J19),"") -> 0.04611952 | G19: 0.05 | H19: 0.046 | I19: 0.06 | J19: =AVERAGE(G19:I19) -> 0.052 | K19: =$E19*(1+0.5*MIN($G19:$I19))+MIN($G19:$I19) -> 0.091984667 | L19: =F19+J19 -> 0.09811952 | M19: =$E19*(1+0.5*MAX($G19:$I19))+MAX($G19:$I19) -> 0.10629932
A20: ='AEB-3 Proxy Selection'!B20 -> Xcel Energy Inc. | B20: ='AEB-3 Proxy Selection'!C20 -> XEL | C20: 2.08 | D20: 61.14286 | E20: =C20/D20 -> 0.03401869 | F20: =IFERROR(E20*(1+0.5*J20),"") -> 0.035071568 | G20: 0.06 | H20: 0.0657 | I20: 0.06 | J20: =AVERAGE(G20:I20) -> 0.0619 | K20: =$E20*(1+0.5*MIN($G20:$I20))+MIN($G20:$I20) -> 0.095039251 | L20: =F20+J20 -> 0.096971568 | M20: =$E20*(1+0.5*MAX($G20:$I20))+MAX($G20:$I20) -> 0.1008362
A21: Mean | E21: =AVERAGE(E6:E20) -> 0.042748037 | F21: =AVERAGE(F6:F20) -> 0.043912144 | G21: =AVERAGE(G6:G20) -> 0.053 | H21: =AVERAGE(H6:H20) -> 0.0579 | I21: =AVERAGE(I6:I20) -> 0.055933333 | J21: =AVERAGE(J6:J20) -> 0.055491111 | K21: =AVERAGE(K6:K20) -> 0.086842598 | L21: =AVERAGE(L6:L20) -> 0.099403256 | M21: =AVERAGE(M6:M20) -> 0.11142474
A22: Median | E22: =MEDIAN(E6:E20) -> 0.044738891 | F22: =MEDIAN(F6:F20) -> 0.04611834 | G22: =MEDIAN(G6:G20) -> 0.06 | H22: =MEDIAN(H6:H20) -> 0.0535 | I22: =MEDIAN(I6:I20) -> 0.06 | J22: =MEDIAN(J6:J20) -> 0.0525 | K22: =MEDIAN(K6:K20) -> 0.087327287 | L22: =MEDIAN(L6:L20) -> 0.09811952 | M22: =MEDIAN(M6:M20) -> 0.10766884
A24: Notes:
A25: [1] Source: Bloomberg Professional
A26: [2] Source: Bloomberg Professional, equals 30-day average as of January 31, 2024
A27: [3] Equals [1] / [2]
A28: [4] Equals [3] x (1 + 0.50 x [8])
A29: [5] Source: Value Line
A30: [6] Source: Yahoo! Finance
A31: [7] Source: Zacks
A32: [8] Equals Average ([5], [6], [7])
A33: [9] Equals [3] x (1 + 0.50 x Minimum ([5], [6], [7]) + Minimum ([5], [6], [7])
A34: [10] Equals [4] + [8]
A35: [11] Equals [3] x (1 + 0.50 x Maximum ([5], [6], [7]) + Maximum ([5], [6], [7])
A38: 90-DAY CONSTANT GROWTH DCF -- AEP TEXAS PROXY GROUP
C40: [1] | D40: [2] | E40: [3] | F40: [4] | G40: [5] | H40: [6] | I40: [7] | J40: [8] | K40: [9] | L40: [10] | M40: [11]
A41: Company | B41: Ticker | C41: Annualized Dividend | D41: Stock Price | E41: Dividend Yield | F41: Expected Dividend Yield | G41: Value Line EPS Growth | H41: Yahoo! Finance EPS Growth | I41: Zacks EPS Growth | J41: Average Growth Rate | K41: Low ROE | L41: Mean ROE | M41: High ROE
A42: =A6 -> ALLETE, Inc. | B42: =B6 -> ALE | C42: =C6 -> 2.71 | D42: 56.725876 | E42: =C42/D42 -> 0.047773613 | F42: =IFERROR(E42*(1+0.5*J42),"") -> 0.049541236 | G42: =G6 -> 0.06 | H42: =H6 -> 0.081 | I42: =I6 -> 0.081 | J42: =AVERAGE(G42:I42) -> 0.074 | K42: =$E42*(1+0.5*MIN($G42:$I42))+MIN($G42:$I42) -> 0.10920682 | L42: =F42+J42 -> 0.12354124 | M42: =$E42*(1+0.5*MAX($G42:$I42))+MAX($G42:$I42) -> 0.13070844
A43: =A7 -> Alliant Energy Corporation | B43: =B7 -> LNT | C43: =C7 -> 1.92 | D43: 49.294667 | E43: =C43/D43 -> 0.038949447 | F43: =IFERROR(E43*(1+0.5*J43),"") -> 0.040205567 | G43: =G7 -> 0.065 | H43: =H7 -> 0.0655 | I43: =I7 -> 0.063 | J43: =AVERAGE(G43:I43) -> 0.0645 | K43: =$E43*(1+0.5*MIN($G43:$I43))+MIN($G43:$I43) -> 0.10317635 | L43: =F43+J43 -> 0.10470557 | M43: =$E43*(1+0.5*MAX($G43:$I43))+MAX($G43:$I43) -> 0.10572504
A44: =A8 -> Ameren Corporation | B44: =B8 -> AEE | C44: =C8 -> 2.52 | D44: 74.628454 | E44: =C44/D44 -> 0.033767281 | F44: =IFERROR(E44*(1+0.5*J44),"") -> 0.03475216 | G44: =G8 -> 0.065 | H44: =H8 -> 0.048 | I44: =I8 -> 0.062 | J44: =AVERAGE(G44:I44) -> 0.058333333 | K44: =$E44*(1+0.5*MIN($G44:$I44))+MIN($G44:$I44) -> 0.082577696 | L44: =F44+J44 -> 0.093085493 | M44: =$E44*(1+0.5*MAX($G44:$I44))+MAX($G44:$I44) -> 0.099864718
A45: =A9 -> Duke Energy Corporation | B45: =B9 -> DUK | C45: =C9 -> 4.1 | D45: 91.918216 | E45: =C45/D45 -> 0.044604869 | F45: =IFERROR(E45*(1+0.5*J45),"") -> 0.045931864 | G45: =G9 -> 0.05 | H45: =H9 -> 0.0655 | I45: =I9 -> 0.063 | J45: =AVERAGE(G45:I45) -> 0.0595 | K45: =$E45*(1+0.5*MIN($G45:$I45))+MIN($G45:$I45) -> 0.095719991 | L45: =F45+J45 -> 0.10543186 | M45: =$E45*(1+0.5*MAX($G45:$I45))+MAX($G45:$I45) -> 0.11156568
A46: =A10 -> Edison International | B46: =B10 -> EIX | C46: =C10 -> 3.12 | D46: 66.060798 | E46: =C46/D46 -> 0.047229221 | F46: =IFERROR(E46*(1+0.5*J46),"") -> 0.048236777 | G46: =G10 -> 0.045 | H46: =H10 -> 0.046 | I46: =I10 -> 0.037 | J46: =AVERAGE(G46:I46) -> 0.042666667 | K46: =$E46*(1+0.5*MIN($G46:$I46))+MIN($G46:$I46) -> 0.085102961 | L46: =F46+J46 -> 0.090903444 | M46: =$E46*(1+0.5*MAX($G46:$I46))+MAX($G46:$I46) -> 0.094315493
...

Sheet AEB-5 CAPM
B2: CAPITAL ASSET PRICING MODEL -- CURRENT RISK-FREE RATE & VL BETA
B4: K = Rf + β (Rm − Rf)
B5: K = Rf + 0.25 x (Rm - Rf) + 0.75 x β x (Rm − Rf)
D7: [1] | E7: [2] | F7: [3] | G7: [4] | H7: [5] | I7: [6]
B8: Company | C8: Ticker | D8: Current 30-day average of 30-year U.S. Treasury bond yield | E8: Beta (β) | F8: Market Return (Rm) | G8: Market Risk Premium (Rm − Rf) | H8: ROE (K) | I8: ECAPM ROE (K)
B9: ='AEB-4 CGDCF'!A6 -> ALLETE, Inc. | C9: ='AEB-4 CGDCF'!B6 -> ALE | D9: ='AEB-8 Risk Premium'!J47 -> 0.041926667 | E9: 0.95 | F9: ='AEB-7 Market Return'!B8 -> 0.12219338 | G9: =F9-D9 -> 0.080266712 | H9: =IFERROR(G9*E9+D9, "") -> 0.11818004 | I9: =IFERROR((0.25*G9)+(0.75*E9*G9)+D9, "") -> 0.11918338
B10: ='AEB-4 CGDCF'!A7 -> Alliant Energy Corporation | C10: ='AEB-4 CGDCF'!B7 -> LNT | D10: =$D$9 -> 0.041926667 | E10: 0.9 | F10: =$F$9 -> 0.12219338 | G10: =F10-D10 -> 0.080266712 | H10: =IFERROR(G10*E10+D10, "") -> 0.11416671 | I10: =IFERROR((0.25*G10)+(0.75*E10*G10)+D10, "") -> 0.11617337
B11: ='AEB-4 CGDCF'!A8 -> Ameren Corporation | C11: ='AEB-4 CGDCF'!B8 -> AEE | D11: =$D$9 -> 0.041926667 | E11: 0.9 | F11: =$F$9 -> 0.12219338 | G11: =F11-D11 -> 0.080266712 | H11: =IFERROR(G11*E11+D11, "") -> 0.11416671 | I11: =IFERROR((0.25*G11)+(0.75*E11*G11)+D11, "") -> 0.11617337
B12: ='AEB-4 CGDCF'!A9 -> Duke Energy Corporation | C12: ='AEB-4 CGDCF'!B9 -> DUK | D12: =$D$9 -> 0.041926667 | E12: 0.85 | F12: =$F$9 -> 0.12219338 | G12: =F12-D12 -> 0.080266712 | H12: =IFERROR(G12*E12+D12, "") -> 0.11015337 | I12: =IFERROR((0.25*G12)+(0.75*E12*G12)+D12, "") -> 0.11316337
B13: ='AEB-4 CGDCF'!A10 -> Edison International | C13: ='AEB-4 CGDCF'!B10 -> EIX | D13: =$D$9 -> 0.041926667 | E13: 1 | F13: =$F$9 -> 0.12219338 | G13: =F13-D13 -> 0.080266712 | H13: =IFERROR(G13*E13+D13, "") -> 0.12219338 | I13: =IFERROR((0.25*G13)+(0.75*E13*G13)+D13, "") -> 0.12219338
B14: ='AEB-4 CGDCF'!A11 -> Entergy Corporation | C14: ='AEB-4 CGDCF'!B11 -> ETR | D14: =$D$9 -> 0.041926667 | E14: 0.95 | F14: =$F$9 -> 0.12219338 | G14: =F14-D14 -> 0.080266712 | H14: =IFERROR(G14*E14+D14, "") -> 0.11818004 | I14: =IFERROR((0.25*G14)+(0.75*E14*G14)+D14, "") -> 0.11918338
B15: ='AEB-4 CGDCF'!A12 -> Eversource Energy | C15: ='AEB-4 CGDCF'!B12 -> ES | D15: =$D$9 -> 0.041926667 | E15: 0.9 | F15: =$F$9 -> 0.12219338 | G15: =F15-D15 -> 0.080266712 | H15: =IFERROR(G15*E15+D15, "") -> 0.11416671 | I15: =IFERROR((0.25*G15)+(0.75*E15*G15)+D15, "") -> 0.11617337
B16: ='AEB-4 CGDCF'!A13 -> Evergy, Inc. | C16: ='AEB-4 CGDCF'!B13 -> EVRG | D16: =$D$9 -> 0.041926667 | E16: 0.95 | F16: =$F$9 -> 0.12219338 | G16: =F16-D16 -> 0.080266712 | H16: =IFERROR(G16*E16+D16, "") -> 0.11818004 | I16: =IFERROR((0.25*G16)+(0.75*E16*G16)+D16, "") -> 0.11918338
B17: ='AEB-4 CGDCF'!A14 -> IDACORP, Inc. | C17: ='AEB-4 CGDCF'!B14 -> IDA | D17: =$D$9 -> 0.041926667 | E17: 0.85 | F17: =$F$9 -> 0.12219338 | G17: =F17-D17 -> 0.080266712 | H17: =IFERROR(G17*E17+D17, "") -> 0.11015337 | I17: =IFERROR((0.25*G17)+(0.75*E17*G17)+D17, "") -> 0.11316337
B18: ='AEB-4 CGDCF'!A15 -> NextEra Energy, Inc. | C18: ='AEB-4 CGDCF'!B15 -> NEE | D18: =$D$9 -> 0.041926667 | E18: 0.95 | F18: =$F$9 -> 0.12219338 | G18: =F18-D18 -> 0.080266712 | H18: =IFERROR(G18*E18+D18, "") -> 0.11818004 | I18: =IFERROR((0.25*G18)+(0.75*E18*G18)+D18, "") -> 0.11918338
B19: ='AEB-4 CGDCF'!A16 -> NorthWestern Corporation | C19: ='AEB-4 CGDCF'!B16 -> NWE | D19: =$D$9 -> 0.041926667 | E19: 0.95 | F19: =$F$9 -> 0.12219338 | G19: =F19-D19 -> 0.080266712 | H19: =IFERROR(G19*E19+D19, "") -> 0.11818004 | I19: =IFERROR((0.25*G19)+(0.75*E19*G19)+D19, "") -> 0.11918338
B20: ='AEB-4 CGDCF'!A17 -> OGE Energy Corporation | C20: ='AEB-4 CGDCF'!B17 -> OGE | D20: =$D$9 -> 0.041926667 | E20: 1.05 | F20: =$F$9 -> 0.12219338 | G20: =F20-D20 -> 0.080266712 | H20: =IFERROR(G20*E20+D20, "") -> 0.12620671 | I20: =IFERROR((0.25*G20)+(0.75*E20*G20)+D20, "") -> 0.12520338
B21: ='AEB-4 CGDCF'!A18 -> Pinnacle West Capital Corporation | C21: ='AEB-4 CGDCF'!B18 -> PNW | D21: =$D$9 -> 0.041926667 | E21: 0.95 | F21: =$F$9 -> 0.12219338 | G21: =F21-D21 -> 0.080266712 | H21: =IFERROR(G21*E21+D21, "") -> 0.11818004 | I21: =IFERROR((0.25*G21)+(0.75*E21*G21)+D21, "") -> 0.11918338
... B23: ='AEB-4 CGDCF'!A20 -> Xcel Energy Inc. | C23: ='AEB-4 CGDCF'!B20 -> XEL | D23: =$D$9 -> 0.041926667 | E23: 0.85 | F23: =$F$9 -> 0.12219338 | G23: =F23-D23 -> 0.080266712 | H23: =IFERROR(G23*E23+D23, "") -> 0.11015337 | I23: =IFERROR((0.25*G23)+(0.75*E23*G23)+D23, "") -> 0.11316337
B24: Mean | H24: =AVERAGE(H9:H23) -> 0.11630715 | I24: =AVERAGE(I9:I23) -> 0.11777871
B25: Median | H25: =MEDIAN(H9:H23) -> 0.11818004 | I25: =MEDIAN(I9:I23) -> 0.11918338
B27: Notes:
B28: [1] Source: Bloomberg Professional, as of January 31, 2024
B29: [2] Source: Value Line
B30: [3] Source: Market Return
B31: [4] Equals [3] - [1]
B32: [5] Equals [1] + [2] x [4]
B33: [6] Equals [1] + 0.25 x ([4]) + 0.75 x ([2] x [4])
B36: CAPITAL ASSET PRICING MODEL -- NEAR-TERM PROJECTED RISK-FREE RATE & VL BETA
B38: K = Rf + β (Rm − Rf)
B39: K = Rf + 0.25 x (Rm - Rf) + 0.75 x β x (Rm − Rf)
D41: [1] | E41: [2] | F41: [3] | G41: [4] | H41: [5] | I41: [6]
B42: Company | C42: Ticker | D42: Near-term projected 30-year U.S. Treasury bond yield (Q2 2024 - Q2 2025) | E42: Beta (β) | F42: Market Return (Rm) | G42: Market Risk Premium (Rm − Rf) | H42: ROE (K) | I42: ECAPM ROE (K)
B43: =B9 -> ALLETE, Inc. | C43: =C9 -> ALE | D43: ='AEB-8 Risk Premium'!J48 -> 0.041 | E43: =E9 -> 0.95 | F43: =F9 -> 0.12219338 | G43: =F43-D43 -> 0.081193378 | H43: =IFERROR(G43*E43+D43,"") -> 0.11813371 | I43: =IFERROR((0.25*G43)+(0.75*E43*G43)+D43,"") -> 0.11914863
B44: =B10 -> Alliant Energy Corporation | C44: =C10 -> LNT | D44: =$D$43 -> 0.041 | E44: =E10 -> 0.9 | F44: =F10 -> 0.12219338 | G44: =F44-D44 -> 0.081193378 | H44: =IFERROR(G44*E44+D44,"") -> 0.11407404 | I44: =IFERROR((0.25*G44)+(0.75*E44*G44)+D44,"") -> 0.11610387
B45: =B11 -> Ameren Corporation | C45: =C11 -> AEE | D45: =$D$43 -> 0.041 | E45: =E11 -> 0.9 | F45: =F11 -> 0.12219338 | G45: =F45-D45 -> 0.081193378 | H45: =IFERROR(G45*E45+D45,"") -> 0.11407404 | I45: =IFERROR((0.25*G45)+(0.75*E45*G45)+D45,"") -> 0.11610387
B46: =B12 -> Duke Energy Corporation | C46: =C12 -> DUK | D46: =$D$43 -> 0.041 | E46: =E12 -> 0.85 | F46: =F12 -> 0.12219338 | G46: =F46-D46 -> 0.081193378 | H46: =IFERROR(G46*E46+D46,"") -> 0.11001437 | I46: =IFERROR((0.25*G46)+(0.75*E46*G46)+D46,"") -> 0.11305912
B47: =B13 -> Edison International | C47: =C13 -> EIX | D47: =$D$43 -> 0.041 | E47: =E13 -> 1 | F47: =F13 -> 0.12219338 | G47: =F47-D47 -> 0.081193378 | H47: =IFERROR(G47*E47+D47,"") -> 0.12219338 | I47: =IFERROR((0.25*G47)+(0.75*E47*G47)+D47,"") -> 0.12219338
B48: =B14 -> Entergy Corporation | C48: =C14 -> ETR | D48: =$D$43 -> 0.041 | E48: =E14 -> 0.95 | F48: =F14 -> 0.12219338 | G48: =F48-D48 -> 0.081193378 | H48: =IFERROR(G48*E48+D48,"") -> 0.11813371 | I48: =IFERROR((0.25*G48)+(0.75*E48*G48)+D48,"") -> 0.11914863
B49: =B15 -> Eversource Energy | C49: =C15 -> ES | D49: =$D$43 -> 0.041 | E49: =E15 -> 0.9 | F49: =F15 -> 0.12219338 | G49: =F49-D49 -> 0.081193378 | H49: =IFERROR(G49*E49+D49,"") -> 0.11407404 | I49: =IFERROR((0.25*G49)+(0.75*E49*G49)+D49,"") -> 0.11610387
...

Sheet AEB-6 LT Beta
A2: HISTORICAL BETA - 2013 - 2022
C4: [1] | D4: [2] | E4: [3] | F4: [4] | G4: [5] | H4: [6] | I4: [7] | J4: [8] | K4: [9] | L4: [10] | M4: [11] | N4: [12]
A5: Company | B5: Ticker | C5: 41639 | D5: 42004 | E5: 42369 | F5: 42735 | G5: 43100 | H5: 43465 | I5: 43830 | J5: 44196 | K5: 44561 | L5: 44926 | M5: 45291 | N5: Average
A6: ='AEB-4 CGDCF'!A6 -> ALLETE, Inc. | B6: ='AEB-4 CGDCF'!B6 -> ALE | C6: 0.75 | D6: 0.8 | E6: 0.8 | F6: 0.75 | G6: 0.8 | H6: 0.65 | I6: 0.65 | J6: 0.85 | K6: 0.9 | L6: 0.9 | M6: 0.9 | N6: =AVERAGE(C6:M6) -> 0.79545455
A7: ='AEB-4 CGDCF'!A7 -> Alliant Energy Corporation | B7: ='AEB-4 CGDCF'!B7 -> LNT | C7: 0.75 | D7: 0.8 | E7: 0.8 | F7: 0.7 | G7: 0.7 | H7: 0.6 | I7: 0.6 | J7: 0.85 | K7: 0.85 | L7: 0.85 | M7: 0.9 | N7: =AVERAGE(C7:M7) -> 0.76363636
A8: ='AEB-4 CGDCF'!A8 -> Ameren Corporation | B8: ='AEB-4 CGDCF'!B8 -> AEE | C8: 0.8 | D8: 0.75 | E8: 0.75 | F8: 0.65 | G8: 0.7 | H8: 0.55 | I8: 0.55 | J8: 0.85 | K8: 0.8 | L8: 0.85 | M8: 0.9 | N8: =AVERAGE(C8:M8) -> 0.74090909
A9: ='AEB-4 CGDCF'!A9 -> Duke Energy Corporation | B9: ='AEB-4 CGDCF'!B9 -> DUK | C9: 0.65 | D9: 0.6 | E9: 0.65 | F9: 0.6 | G9: 0.6 | H9: 0.5 | I9: 0.5 | J9: 0.85 | K9: 0.85 | L9: 0.85 | M9: 0.9 | N9: =AVERAGE(C9:M9) -> 0.68636364
A10: ='AEB-4 CGDCF'!A10 -> Edison International | B10: ='AEB-4 CGDCF'!B10 -> EIX | C10: 0.8 | D10: 0.75 | E10: 0.7 | F10: 0.65 | G10: 0.65 | H10: 0.55 | I10: 0.55 | J10: 0.95 | K10: 0.95 | L10: 0.95 | M10: 1 | N10: =AVERAGE(C10:M10) -> 0.77272727
A11: ='AEB-4 CGDCF'!A11 -> Entergy Corporation | B11: ='AEB-4 CGDCF'!B11 -> ETR | C11: 0.7 | D11: 0.7 | E11: 0.7 | F11: 0.65 | G11: 0.65 | H11: 0.6 | I11: 0.6 | J11: 0.95 | K11: 0.95 | L11: 0.95 | M11: 0.95 | N11: =AVERAGE(C11:M11) -> 0.76363636
A12: ='AEB-4 CGDCF'!A12 -> Eversource Energy | B12: ='AEB-4 CGDCF'!B12 -> ES | E12: 0.75 | F12: 0.7 | G12: 0.65 | H12: 0.6 | I12: 0.55 | J12: 0.9 | K12: 0.9 | L12: 0.9 | M12: 0.9 | N12: =AVERAGE(C12:M12) -> 0.76111111
A13: ='AEB-4 CGDCF'!A13 -> Evergy, Inc. | B13: ='AEB-4 CGDCF'!B13 -> EVRG | H13: NMF | I13: NMF | J13: 1 | K13: 0.95 | L13: 0.9 | M13: 0.9 | N13: =AVERAGE(C13:M13) -> 0.9375
A14: ='AEB-4 CGDCF'!A14 -> IDACORP, Inc. | B14: ='AEB-4 CGDCF'!B14 -> IDA | C14: 0.75 | D14: 0.8 | E14: 0.8 | F14: 0.75 | G14: 0.7 | H14: 0.55 | I14: 0.55 | J14: 0.8 | K14: 0.8 | L14: 0.8 | M14: 0.85 | N14: =AVERAGE(C14:M14) -> 0.74090909
A15: ='AEB-4 CGDCF'!A15 -> NextEra Energy, Inc. | B15: ='AEB-4 CGDCF'!B15 -> NEE | C15: 0.7 | D15: 0.7 | E15: 0.75 | F15: 0.65 | G15: 0.65 | H15: 0.55 | I15: 0.55 | J15: 0.9 | K15: 0.9 | L15: 0.95 | M15: 1 | N15: =AVERAGE(C15:M15) -> 0.75454545
A16: ='AEB-4 CGDCF'!A16 -> NorthWestern Corporation | B16: ='AEB-4 CGDCF'!B16 -> NWE | C16: 0.7 | D16: 0.7 | E16: 0.7 | F16: 0.7 | G16: 0.7 | H16: 0.55 | I16: 0.6 | J16: 0.95 | K16: 0.95 | L16: 0.9 | M16: 0.95 | N16: =AVERAGE(C16:M16) -> 0.76363636
A17: ='AEB-4 CGDCF'!A17 -> OGE Energy Corporation | B17: ='AEB-4 CGDCF'!B17 -> OGE | C17: 0.85 | D17: 0.9 | E17: 0.95 | F17: 0.9 | G17: 0.95 | H17: 0.85 | I17: 0.75 | J17: 1.1 | K17: 1.05 | L17: 1 | M17: 1.05 | N17: =AVERAGE(C17:M17) -> 0.94090909
A18: ='AEB-4 CGDCF'!A18 -> Pinnacle West Capital Corporation | B18: ='AEB-4 CGDCF'!B18 -> PNW | C18: 0.75 | D18: 0.7 | E18: 0.75 | F18: 0.7 | G18: 0.7 | H18: 0.55 | I18: 0.5 | J18: 0.9 | K18: 0.9 | L18: 0.9 | M18: 0.95 | N18: =AVERAGE(C18:M18) -> 0.75454545
A19: ='AEB-4 CGDCF'!A19 -> Portland General Electric Company | B19: ='AEB-4 CGDCF'!B19 -> POR | C19: 0.75 | D19: 0.8 | E19: 0.8 | F19: 0.7 | G19: 0.7 | H19: 0.6 | I19: 0.55 | J19: 0.85 | K19: 0.9 | L19: 0.85 | M19: 0.9 | N19: =AVERAGE(C19:M19) -> 0.76363636
A20: ='AEB-4 CGDCF'!A20 -> Xcel Energy Inc. | B20: ='AEB-4 CGDCF'!B20 -> XEL | C20: 0.65 | D20: 0.65 | E20: 0.65 | F20: 0.6 | G20: 0.6 | H20: 0.5 | I20: 0.5 | J20: 0.8 | K20: 0.8 | L20: 0.8 | M20: 0.85 | N20: =AVERAGE(C20:M20) -> 0.67272727
A21: Mean | C21: =AVERAGE(C6:C20) -> 0.73846154 | D21: =AVERAGE(D6:D20) -> 0.74230769 | E21: =AVERAGE(E6:E20) -> 0.75357143 | F21: =AVERAGE(F6:F20) -> 0.69285714 | G21: =AVERAGE(G6:G20) -> 0.69642857 | H21: =AVERAGE(H6:H20) -> 0.58571429 | I21: =AVERAGE(I6:I20) -> 0.57142857 | J21: =AVERAGE(J6:J20) -> 0.9 | ... N21: =AVERAGE(N6:N20) -> 0.77414983
A23: Notes:
A24: [1] Value Line, dated December 26, 2013.
A25: [2] Value Line, dated December 31, 2014.
A26: [3] Value Line, dated December 30, 2015.
A27: [4] Value Line, dated December 29, 2016.
A28: [5] Value Line, dated December 28, 2017.
A29: [6] Value Line, dated December 27, 2018.
A30: [7] Value Line, dated December 26, 2019.
A31: [8] Value Line, dated December 30, 2020.
A32: [9] Value Line, dated December 29, 2021.
A33: [10] Value Line, dated December 30, 2022.
A34: [11] Value Line, dated December 29, 2023.
A35: [12] Average ([1] - [11])

Sheet AEB-7 Market Return
A1: MARKET RISK PREMIUM DERIVED FROM ANALYSTS' LONG-TERM GROWTH ESTIMATES
A4: [1] Estimated Weighted Average Dividend Yield | B4: =SUM(H19:H521) -> 0.016275252
A6: [2] Estimated Weighted Average Long-Term Growth Rate | B6: =SUM(J19:J521) -> 0.10506316
A8: [3] S&P 500 Estimated Required Market Return | B8: =B4*(1+0.5*B6)+B6 -> 0.12219338
A12: STANDARD AND POOR'S 500 INDEX
C14: [4] | D14: [5] | E14: [6] | F14: [7] | G14: [8] | H14: [9] | I14: [10] | J14: [11]
I15: Bloomberg | J15: Cap-Weighted
C16: Shares | E16: Market | F16: Weight in | G16: Estimated | H16: Cap-Weighted | I16: Long-Term | J16: Long-Term
A17: Name | B17: Ticker | C17: Outst'g | D17: Price | E17: Capitalization | F17: Index | G17: Dividend Yield | H17: Dividend Yield | I17: Growth Est. | J17: Growth Est.
A19: LyondellBasell Industries NV | B19: LYB | C19: 324.362 | D19: 94.12 | E19: =IFERROR(C19*D19,"") -> 30528.951 | F19: =IF(AND(ISNUMBER($I19)), IF(AND($I19<=20%,$I19>0%), $E19/SUMIFS($E$19:$E$521,$I$19:$I$521, ">"&0%,$I$19:$I$521, "<="&20%),""),"") -> 0.00096447138 | G19: 0.053123672 | H19: =IFERROR($G19*$F19,"") -> 5.1236261e-05 | I19: 0.08 | J19: =IFERROR($I19*$F19,"") -> 7.715771e-05
A20: American Express Co | B20: AXP | C20: 723 | D20: 200.74 | E20: =IFERROR(C20*D20,"") -> 145135.02 | F20: =IF(AND(ISNUMBER($I20)), IF(AND($I20<=20%,$I20>0%), $E20/SUMIFS($E$19:$E$521,$I$19:$I$521, ">"&0%,$I$19:$I$521, "<="&20%),""),"") -> 0.0045851091 | G20: 0.011955764 | H20: =IFERROR($G20*$F20,"") -> 5.4818481e-05 | I20: 0.1417 | J20: =IFERROR($I20*$F20,"") -> 0.00064970996
A21: Verizon Communications Inc | B21: VZ | C21: 4204 | D21: 42.35 | E21: =IFERROR(C21*D21,"") -> 178039.4 | F21: =IF(AND(ISNUMBER($I21)), IF(AND($I21<=20%,$I21>0%), $E21/SUMIFS($E$19:$E$521,$I$19:$I$521, ">"&0%,$I$19:$I$521, "<="&20%),""),"") | G21: 0.062809917 | H21: =IFERROR($G21*$F21,"") | I21: -0.041 | J21: =IFERROR($I21*$F21,"")
A22: Broadcom Inc | B22: AVGO | C22: 468.141 | D22: 1180 | E22: =IFERROR(C22*D22,"") -> 552406.38 | F22: =IF(AND(ISNUMBER($I22)), IF(AND($I22<=20%,$I22>0%), $E22/SUMIFS($E$19:$E$521,$I$19:$I$521, ">"&0%,$I$19:$I$521, "<="&20%),""),"") -> 0.017451636 | G22: 0.01779661 | H22: =IFERROR($G22*$F22,"") -> 0.00031057996 | I22: 0.139 | J22: =IFERROR($I22*$F22,"") -> 0.0024257774
A23: Boeing Co/The | B23: BA | C23: 610.135 | D23: 211.04 | E23: =IFERROR(C23*D23,"") -> 128762.89 | F23: =IF(AND(ISNUMBER($I23)), IF(AND($I23<=20%,$I23>0%), $E23/SUMIFS($E$19:$E$521,$I$19:$I$521, ">"&0%,$I$19:$I$521, "<="&20%),""),"") | H23: =IFERROR($G23*$F23,"") | J23: =IFERROR($I23*$F23,"")
A24: Caterpillar Inc | B24: CAT | C24: 509.085 | D24: 300.31 | E24: =IFERROR(C24*D24,"") -> 152883.32 | F24: =IF(AND(ISNUMBER($I24)), IF(AND($I24<=20%,$I24>0%), $E24/SUMIFS($E$19:$E$521,$I$19:$I$521, ">"&0%,$I$19:$I$521, "<="&20%),""),"") -> 0.0048298935 | G24: 0.017315441 | H24: =IFERROR($G24*$F24,"") -> 8.3631734e-05 | I24: 0.2 | J24: =IFERROR($I24*$F24,"") -> 0.00096597869
A25: JPMorgan Chase & Co | B25: JPM | C25: 2891.008 | D25: 174.36 | E25: =IFERROR(C25*D25,"") -> 504076.15 | F25: =IF(AND(ISNUMBER($I25)), IF(AND($I25<=20%,$I25>0%), $E25/SUMIFS($E$19:$E$521,$I$19:$I$521, ">"&0%,$I$19:$I$521, "<="&20%),""),"") -> 0.015924786 | G25: 0.024088094 | H25: =IFERROR($G25*$F25,"") -> 0.00038359774 | I25: 0.02 | J25: =IFERROR($I25*$F25,"") -> 0.00031849572
A26: Chevron Corp | B26: CVX | C26: 1887.749 | D26: 147.43 | E26: =IFERROR(C26*D26,"") -> 278310.84 | F26: =IF(AND(ISNUMBER($I26)), IF(AND($I26<=20%,$I26>0%), $E26/SUMIFS($E$19:$E$521,$I$19:$I$521, ">"&0%,$I$19:$I$521, "<="&20%),""),"") -> 0.0087924027 | G26: 0.040968595 | H26: =IFERROR($G26*$F26,"") -> 0.00036021239 | I26: 0.07265 | J26: =IFERROR($I26*$F26,"") -> 0.00063876806
A27: Coca-Cola Co/The | B27: KO | C27: 4323.414 | D27: 59.49 | E27: =IFERROR(C27*D27,"") -> 257199.9 | F27: =IF(AND(ISNUMBER($I27)), IF(AND($I27<=20%,$I27>0%), $E27/SUMIFS($E$19:$E$521,$I$19:$I$521, ">"&0%,$I$19:$I$521, "<="&20%),""),"") -> 0.0081254655 | G27: 0.030929568 | H27: =IFERROR($G27*$F27,"") -> 0.00025131714 | I27: 0.0658 | J27: =IFERROR($I27*$F27,"") -> 0.00053465563
A28: AbbVie Inc | B28: ABBV | C28: 1765.537 | D28: 164.4 | E28: =IFERROR(C28*D28,"") -> 290254.28 | F28: =IF(AND(ISNUMBER($I28)), IF(AND($I28<=20%,$I28>0%), $E28/SUMIFS($E$19:$E$521,$I$19:$I$521, ">"&0%,$I$19:$I$521, "<="&20%),""),"") -> 0.0091697204 | G28: 0.037712895 | H28: =IFERROR($G28*$F28,"") -> 0.00034581671 | I28: 0.09088 | J28: =IFERROR($I28*$F28,"") -> 0.00083334419
A29: Walt Disney Co/The | B29: DIS | C29: 1830.316 | D29: 96.05 | E29: =IFERROR(C29*D29,"") -> 175801.85 | F29: =IF(AND(ISNUMBER($I29)), IF(AND($I29<=20%,$I29>0%), $E29/SUMIFS($E$19:$E$521,$I$19:$I$521, ">"&0%,$I$19:$I$521, "<="&20%),""),"") -> 0.0055539364 | G29: 0.0062467465 | H29: =IFERROR($G29*$F29,"") -> 3.4694033e-05 | I29: 0.18875 | J29: =IFERROR($I29*$F29,"") -> 0.0010483055
A30: FleetCor Technologies Inc | B30: FLT | C30: 72.204 | D30: 289.93 | E30: =IFERROR(C30*D30,"") -> 20934.106 | F30: =IF(AND(ISNUMBER($I30)), IF(AND($I30<=20%,$I30>0%), $E30/SUMIFS($E$19:$E$521,$I$19:$I$521, ">"&0%,$I$19:$I$521, "<="&20%),""),"") -> 0.00066135078 | H30: =IFERROR($G30*$F30,"") | I30: 0.1279 | J30: =IFERROR($I30*$F30,"") -> 8.4586765e-05
A31: Extra Space Storage Inc | B31: EXR | C31: 211.278 | D31: 144.44 | E31: =IFERROR(C31*D31,"") -> 30516.994 | F31: =IF(AND(ISNUMBER($I31)), IF(AND($I31<=20%,$I31>0%), $E31/SUMIFS($E$19:$E$521,$I$19:$I$521, ">"&0%,$I$19:$I$521, "<="&20%),""),"") -> 0.00096409363 | G31: 0.044862919 | H31: =IFERROR($G31*$F31,"") -> 4.3252054e-05 | I31: 0.012 | J31: =IFERROR($I31*$F31,"") -> 1.1569124e-05
A32: Exxon Mobil Corp | B32: XOM | C32: 4006.133 | D32: 102.81 | E32: =IFERROR(C32*D32,"") -> 411870.53 | F32: =IF(AND(ISNUMBER($I32)), IF(AND($I32<=20%,$I32>0%), $E32/SUMIFS($E$19:$E$521,$I$19:$I$521, ">"&0%,$I$19:$I$521, "<="&20%),""),"") -> 0.013011824 | G32: 0.036961385 | H32: =IFERROR($G32*$F32,"") -> 0.00048093504 | I32: 0.1321 | J32: =IFERROR($I32*$F32,"") -> 0.0017188619
A33: Phillips 66 | B33: PSX | C33: 439.956 | D33: 144.31 | E33: =IFERROR(C33*D33,"") -> 63490.05 | F33: =IF(AND(ISNUMBER($I33)), IF(AND($I33<=20%,$I33>0%), $E33/SUMIFS($E$19:$E$521,$I$19:$I$521, ">"&0%,$I$19:$I$521, "<="&20%),""),"") | G33: 0.029104012 | H33: =IFERROR($G33*$F33,"") | I33: -0.0756 | J33: =IFERROR($I33*$F33,"")
A34: General Electric Co | B34: GE | C34: 1088.386 | D34: 132.42 | E34: =IFERROR(C34*D34,"") -> 144124.07 | F34: =IF(AND(ISNUMBER($I34)), IF(AND($I34<=20%,$I34>0%), $E34/SUMIFS($E$19:$E$521,$I$19:$I$521, ">"&0%,$I$19:$I$521, "<="&20%),""),"") -> 0.0045531713 | G34: 0.0024165534 | H34: =IFERROR($G34*$F34,"") -> 1.1002981e-05 | I34: 0.07 | J34: =IFERROR($I34*$F34,"") -> 0.00031872199
A35: HP Inc | B35: HPQ | C35: 990.902 | D35: 28.71 | E35: =IFERROR(C35*D35,"") -> 28448.796 | F35: =IF(AND(ISNUMBER($I35)), IF(AND($I35<=20%,$I35>0%), $E35/SUMIFS($E$19:$E$521,$I$19:$I$521, ">"&0%,$I$19:$I$521, "<="&20%),""),"") -> 0.00089875507 | G35: 0.038397771 | H35: =IFERROR($G35*$F35,"") -> 3.4510191e-05 | I35: 0.03 | J35: =IFERROR($I35*$F35,"") -> 2.6962652e-05
A36: Home Depot Inc/The | B36: HD | C36: 995.262 | D36: 352.96 | E36: =IFERROR(C36*D36,"") -> 351287.68 | F36: =IF(AND(ISNUMBER($I36)), IF(AND($I36<=20%,$I36>0%), $E36/SUMIFS($E$19:$E$521,$I$19:$I$521, ">"&0%,$I$19:$I$521, "<="&20%),""),"") -> 0.011097889 | G36: 0.023685403 | H36: =IFERROR($G36*$F36,"") -> 0.00026285797 | I36: 0.0182 | J36: =IFERROR($I36*$F36,"") -> 0.00020198158
A37: Monolithic Power Systems Inc | B37: MPWR | C37: 47.912 | D37: 602.72 | E37: =IFERROR(C37*D37,"") -> 28877.521 | F37: =IF(AND(ISNUMBER($I37)), IF(AND($I37<=20%,$I37>0%), $E37/SUMIFS($E$19:$E$521,$I$19:$I$521, ">"&0%,$I$19:$I$521, "<="&20%),""),"") -> 0.00091229934 | G37: 0.0066365808 | H37: =IFERROR($G37*$F37,"") -> 6.0545483e-06 | I37: 0.08 | J37: =IFERROR($I37*$F37,"") -> 7.2983947e-05
A38: International Business Machines Corp | B38: IBM | C38: 913.119 | D38: 183.66 | E38: =IFERROR(C38*D38,"") -> 167703.44 | F38: =IF(AND(ISNUMBER($I38)), IF(AND($I38<=20%,$I38>0%), $E38/SUMIFS($E$19:$E$521,$I$19:$I$521, ">"&0%,$I$19:$I$521, "<="&20%),""),"") -> 0.005298091 | G38: 0.036153762 | H38: =IFERROR($G38*$F38,"") -> 0.00019154592 | I38: 0.0514 | J38: =IFERROR($I38*$F38,"") -> 0.00027232188
A39: Johnson & Johnson | B39: JNJ | C39: 2407.279 | D39: 158.9 | E39: =IFERROR(C39*D39,"") -> 382516.63 | F39: =IF(AND(ISNUMBER($I39)), IF(AND($I39<=20%,$I39>0%), $E39/SUMIFS($E$19:$E$521,$I$19:$I$521, ">"&0%,$I$19:$I$521, "<="&20%),""),"") -> 0.012084475 | G39: 0.029955947 | H39: =IFERROR($G39*$F39,"") -> 0.00036200189 | I39: 0.0376 | J39: =IFERROR($I39*$F39,"") -> 0.00045437625
A40: Lululemon Athletica Inc | B40: LULU | C40: 121.075 | D40: 453.82 | E40: =IFERROR(C40*D40,"") -> 54946.257 | F40: =IF(AND(ISNUMBER($I40)), IF(AND($I40<=20%,$I40>0%), $E40/SUMIFS($E$19:$E$521,$I$19:$I$521, ">"&0%,$I$19:$I$521, "<="&20%),""),"") -> 0.0017358635 | H40: =IFERROR($G40*$F40,"") | I40: 0.17 | J40: =IFERROR($I40*$F40,"") -> 0.00029509679
A41: McDonald's Corp | B41: MCD | C41: 725.342 | D41: 292.72 | E41: =IFERROR(C41*D41,"") -> 212322.11 | F41: =IF(AND(ISNUMBER($I41)), IF(AND($I41<=20%,$I41>0%), $E41/SUMIFS($E$19:$E$521,$I$19:$I$521, ">"&0%,$I$19:$I$521, "<="&20%),""),"") -> 0.0067076853 | G41: 0.022820443 | H41: =IFERROR($G41*$F41,"") -> 0.00015307235 | I41: 0.0953 | J41: =IFERROR($I41*$F41,"") -> 0.00063924241
A42: Merck & Co Inc | B42: MRK | C42: 2534.023 | D42: 120.78 | E42: =IFERROR(C42*D42,"") -> 306059.3 | F42: =IF(AND(ISNUMBER($I42)), IF(AND($I42<=20%,$I42>0%), $E42/SUMIFS($E$19:$E$521,$I$19:$I$521, ">"&0%,$I$19:$I$521, "<="&20%),""),"") -> 0.0096690328 | G42: 0.025500911 | H42: =IFERROR($G42*$F42,"") -> 0.00024656914 | I42: 0.1733 | J42: =IFERROR($I42*$F42,"") -> 0.0016756434
A43: 3M Co | B43: MMM | C43: 552.317 | D43: 94.35 | E43: =IFERROR(C43*D43,"") -> 52111.109 | F43: =IF(AND(ISNUMBER($I43)), IF(AND($I43<=20%,$I43>0%), $E43/SUMIFS($E$19:$E$521,$I$19:$I$521, ">"&0%,$I$19:$I$521, "<="&20%),""),"") -> 0.0016462954 | G43: 0.063593005 | H43: =IFERROR($G43*$F43,"") -> 0.00010469287 | I43: 0.055 | J43: =IFERROR($I43*$F43,"") -> 9.0546248e-05
A44: American Water Works Co Inc | B44: AWK | C44: 194.705 | D44: 124.02 | E44: =IFERROR(C44*D44,"") -> 24147.314 | F44: =IF(AND(ISNUMBER($I44)), IF(AND($I44<=20%,$I44>0%), $E44/SUMIFS($E$19:$E$521,$I$19:$I$521, ">"&0%,$I$19:$I$521, "<="&20%),""),"") -> 0.00076286254 | G44: 0.0228189 | H44: =IFERROR($G44*$F44,"") -> 1.7407684e-05 | I44: 0.07755 | J44: =IFERROR($I44*$F44,"") -> 5.915999e-05
A45: Bank of America Corp | B45: BAC | C45: 7895.5 | D45: 34.01 | E45: =IFERROR(C45*D45,"") -> 268525.95 | F45: =IF(AND(ISNUMBER($I45)), IF(AND($I45<=20%,$I45>0%), $E45/SUMIFS($E$19:$E$521,$I$19:$I$521, ">"&0%,$I$19:$I$521, "<="&20%),""),"") | G45: 0.028226992 | H45: =IFERROR($G45*$F45,"") | I45: -0.07 | J45: =IFERROR($I45*$F45,"")
A46: Pfizer Inc | B46: PFE | C46: 5646.413 | D46: 27.08 | E46: =IFERROR(C46*D46,"") -> 152904.86 | F46: =IF(AND(ISNUMBER($I46)), IF(AND($I46<=20%,$I46>0%), $E46/SUMIFS($E$19:$E$521,$I$19:$I$521, ">"&0%,$I$19:$I$521, "<="&20%),""),"") | G46: 0.062038405 | H46: =IFERROR($G46*$F46,"") | I46: 0.33346 | J46: =IFERROR($I46*$F46,"")
A47: Procter & Gamble Co/The | B47: PG | C47: 2353.021 | D47: 157.14 | E47: =IFERROR(C47*D47,"") -> 369753.72 | F47: =IF(AND(ISNUMBER($I47)), IF(AND($I47<=20%,$I47>0%), $E47/SUMIFS($E$19:$E$521,$I$19:$I$521, ">"&0%,$I$19:$I$521, "<="&20%),""),"") -> 0.011681269 | G47: 0.023945526 | H47: =IFERROR($G47*$F47,"") -> 0.00027971412 | I47: 0.0756 | J47: =IFERROR($I47*$F47,"") -> 0.0008831039
A48: AT&T Inc | B48: T | C48: 7150 | D48: 17.69 | E48: =IFERROR(C48*D48,"") -> 126483.5 | F48: =IF(AND(ISNUMBER($I48)), IF(AND($I48<=20%,$I48>0%), $E48/SUMIFS($E$19:$E$521,$I$19:$I$521, ">"&0%,$I$19:$I$521, "<="&20%),""),"") | G48: 0.062747315 | H48: =IFERROR($G48*$F48,"") | I48: -0.04613 | J48: =IFERROR($I48*$F48,"")
A49: Travelers Cos Inc/The | B49: TRV | C49: 228.2 | D49: 211.36 | E49: =IFERROR(C49*D49,"") -> 48232.352 | F49: =IF(AND(ISNUMBER($I49)), IF(AND($I49<=20%,$I49>0%), $E49/SUMIFS($E$19:$E$521,$I$19:$I$521, ">"&0%,$I$19:$I$521, "<="&20%),""),"") -> 0.0015237576 | G49: 0.018925057 | H49: =IFERROR($G49*$F49,"") -> 2.88372e-05 | I49: 0.19025 | J49: =IFERROR($I49*$F49,"") -> 0.00028989489
...

Sheet AEB-8 Risk Premium
B2: BOND YIELD PLUS RISK PREMIUM
C4: [1] | D4: [2] | E4: [3]
B5: Quarter | C5: Average Authorized Electric ROE | D5: U.S. Govt. 30-year Treasury | E5: Risk Premium
B6: 1980.1 | C6: 0.13968571 | D6: 0.11657097 | E6: =C6-D6 -> 0.023114747
B7: 1980.2 | C7: 0.142532 | D7: 0.10524921 | E7: =C7-D7 -> 0.037282794
B8: 1980.3 | C8: 0.142956 | D8: 0.1085 | E8: =C8-D8 -> 0.034456
B9: 1980.4 | C9: 0.14322121 | D9: 0.1209623 | E9: =C9-D9 -> 0.022258917
B10: 1981.1 | C10: 0.14817 | D10: 0.12533279 | E10: =C10-D10 -> 0.022837213
B11: 1981.2 | C11: 0.15049512 | D11: 0.13242857 | E11: =C11-D11 -> 0.018066551
B12: 1981.3 | C12: 0.15305385 | D12: 0.14132344 | E12: =C12-D12 -> 0.011730409
B13: 1981.4 | C13: 0.15588286 | D13: 0.13847869 | E13: =C13-D13 -> 0.017404169
B14: 1982.1 | C14: 0.15713103 | D14: 0.13962131 | E14: =C14-D14 -> 0.017509723
B15: 1982.2 | C15: 0.15602571 | D15: 0.13521905 | E15: =C15-D15 -> 0.020806667
B16: 1982.3 | C16: 0.1585 | D16: 0.12794375 | E16: =C16-D16 -> 0.03055625
B17: 1982.4 | C17: 0.16028387 | D17: 0.1074623 | E17: =C17-D17 -> 0.052821576
... B21: 1983.4 | C21: 0.15368148 | D21: 0.11737 | E21: =C21-D21 -> 0.036311481
B22: 1984.1 | C22: 0.150605 | D22: 0.1203629 | E22: =C22-D22 -> 0.030242097 | G22: SUMMARY OUTPUT
B23: 1984.2 | C23: 0.15182667 | D23: 0.13183968 | E23: =C23-D23 -> 0.019986984
B24: 1984.3 | C24: 0.15382273 | D24: 0.12689048 | E24: =C24-D24 -> 0.026932251 | G24: Regression Statistics
B25: 1984.4 | C25: 0.15690526 | D25: 0.11698852 | E25: =C25-D25 -> 0.039916739 | G25: Multiple R | H25: 0.91431368
B26: 1985.1 | C26: 0.1548 | D26: 0.11584 | E26: =C26-D26 -> 0.03896 | G26: R Square | H26: 0.8359695
B27: 1985.2 | C27: 0.152675 | D27: 0.10995873 | E27: =C27-D27 -> 0.04271627 | G27: Adjusted R Square | H27: 0.83503218
B28: 1985.3 | C28: 0.14910714 | D28: 0.10553016 | E28: =C28-D28 -> 0.043576984 | G28: Standard Error | H28: 0.0056694111
B29: 1985.4 | C29: 0.15107647 | D29: 0.10039839 | E29: =C29-D29 -> 0.050678083 | G29: Observations | H29: 177
B30: 1986.1 | C30: 0.14423333 | D30: 0.087693333 | E30: =C30-D30 -> 0.05654
B31: 1986.2 | C31: 0.14272667 | D31: 0.07490625 | E31: =C31-D31 -> 0.067820417 | G31: ANOVA
B32: 1986.3 | C32: 0.1326 | D32: 0.074042187 | E32: =C32-D32 -> 0.058557812 | H32: df | I32: SS | J32: MS | K32: F | L32: Significance F
B33: 1986.4 | C33: 0.13515556 | D33: 0.075280645 | E33: =C33-D33 -> 0.05987491 | G33: Regression | H33: 1 | I33: 0.028666836 | J33: 0.028666836 | K33: 891.87475 | L33: 1.3308493e-70
B34: 1987.1 | C34: 0.12895556 | D34: 0.074936066 | E34: =C34-D34 -> 0.05401949 | G34: Residual | H34: 175 | I34: 0.0056248889 | J34: 3.2142222e-05
B35: 1987.2 | C35: 0.1317 | D35: 0.085306349 | E35: =C35-D35 -> 0.046393651 | G35: Total | H35: 176 | I35: 0.034291725
B36: 1987.3 | C36: 0.13144 | D36: 0.090592187 | E36: =C36-D36 -> 0.040847813
B37: 1987.4 | C37: 0.1276125 | D37: 0.092301538 | E37: =C37-D37 -> 0.035310962 | H37: Coefficients | I37: Standard Error | J37: t Stat | K37: P-value | L37: Lower 95% | M37: Upper 95% | N37: Lower 95.0% | O37: Upper 95.0%
B38: 1988.1 | C38: 0.1273625 | D38: 0.086266129 | E38: =C38-D38 -> 0.041096371 | G38: Intercept | H38: 0.079059704 | I38: 0.00094791235 | J38: 83.404023 | K38: 7.926274e-143 | L38: 0.077188892 | M38: 0.080930515 | N38: 0.077188892 | O38: 0.080930515
B39: 1988.2 | C39: 0.12695714 | D39: 0.090614286 | E39: =C39-D39 -> 0.036342857 | G39: U.S. Govt. 30-year Treasury | H39: -0.4163371 | I39: 0.013940976 | J39: -29.864272 | K39: 1.3308493e-70 | L39: -0.44385118 | M39: -0.38882301 | N39: -0.44385118 | O39: -0.38882301
B40: 1988.3 | C40: 0.12778571 | D40: 0.091754688 | E40: =C40-D40 -> 0.036031027
B41: 1988.4 | C41: 0.1296875 | D41: 0.089730159 | E41: =C41-D41 -> 0.039957341
B42: 1989.1 | C42: 0.13022857 | D42: 0.09036129 | E42: =C42-D42 -> 0.039867281
B43: 1989.2 | C43: 0.13221429 | D43: 0.086979687 | E43: =C43-D43 -> 0.045234598 | J43: U.S. Govt.
B44: 1989.3 | C44: 0.12375 | D44: 0.081187302 | E44: =C44-D44 -> 0.042562698 | J44: 30-year | K44: Risk
B45: 1989.4 | C45: 0.12828571 | D45: 0.079334375 | E45: =C45-D45 -> 0.048951339 | J45: Treasury | K45: Premium | L45: ROE
...

Sheet AEB-9 Flotation Cost
A2: FLOTATION COST ADJUSTMENT
C4: [1] | D4: [2] | E4: [3] | F4: [4] | G4: [5] | H4: [6] | I4: [7] | J4: [8] | K4: [9] | L4: [10]
A5: Company | B5: Ticker | C5: Date [i] | D5: Shares Issued (000) | E5: Offering Price | F5: Under-writing Discount [ii] | G5: Offering Expense ($000) | H5: Net Proceeds Per Share | I5: Total Flotation Costs ($000) | J5: Gross Equity Issue Before Costs ($000) | K5: Net Proceeds ($000) | L5: Flotation Cost Percentage
A7: American Electric Power Company, Inc. | B7: AEP | C7: 39904 | D7: 69000 | E7: 24.5 | F7: 0.735 | G7: 400 | H7: =K7/D7 -> 23.759203 | I7: =F7*D7+G7 -> 51115 | J7: =D7*E7 -> 1690500 | K7: =J7-I7 -> 1639385 | L7: =I7/J7 -> 0.030236616
A8: American Electric Power Company, Inc. | B8: AEP | C8: 37679 | D8: 57500 | E8: 20.95 | F8: 0.6285 | G8: 550 | H8: =K8/D8 -> 20.311935 | I8: =F8*D8+G8 -> 36688.75 | J8: =D8*E8 -> 1204625 | K8: =J8-I8 -> 1167936.2 | L8: =I8/J8 -> 0.030456574
A10: Total | I10: =SUM(I7:I8) -> 87803.75 | J10: =SUM(J7:J8) -> 2895125 | K10: =SUM(K7:K8) -> 2807321.2
I11: WEIGHTED AVERAGE FLOTATION COSTS | L11: =I10/J10 -> 0.030328138
A12: Notes:
A13: [i] Offering Completion Date
A14: [ii] Underwriting discount is calculated as the market price minus the offering price when not explicitly given in the prospectus.
A16: ="The flotation cost adjustment is derived by dividing the dividend yield by 1 − F (where F = flotation costs expressed in percentage terms), or by "&TEXT(1-L11,"0.0000")&", and adding that result to the constant growth rate" -> The flotation cost adjustment is derived by dividing the dividend yield by 1 − F (where F = flotation costs expressed in percentage terms), or by 0.9697, and adding that result to the constant growth rate
A17: to determine the cost of equity. Using the formulas shown previously in my testimony, the Constant Growth DCF calculation is modified as follows to accommodate an adjustment for flotation costs:
C23: [11] | D23: [12] | E23: [13] | F23: [14] | G23: [15] | H23: [16] | I23: [17] | J23: [18] | K23: [19] | L23: [20] | M23: [21]
A24: Company | B24: Ticker | C24: Annualized Dividend | D24: Stock Price | E24: Dividend Yield | F24: Expected Dividend Yield | G24: Expected Dividend Yield Adjusted for Flotation Costs | H24: Value Line Earnings Growth | I24: Yahoo! Finance Earnings Growth | J24: Zacks Earnings Growth | K24: Average Earnings Growth | L24: Cost of Equity: Mean Growth Rate | M24: Cost of Equity Adjusted for Flotation Costs
A26: ='AEB-4 CGDCF'!A6 -> ALLETE, Inc. | B26: ='AEB-4 CGDCF'!B6 -> ALE | C26: ='AEB-4 CGDCF'!C6 -> 2.71 | D26: ='AEB-4 CGDCF'!D6 -> 60.598 | E26: =C26/D26 -> 0.044720948 | F26: =IFERROR(E26*(1+0.5*K26),"") -> 0.046375623 | G26: =F26/(1-$L$11) -> 0.047826099 | H26: ='AEB-4 CGDCF'!G6 -> 0.06 | I26: ='AEB-4 CGDCF'!H6 -> 0.081 | J26: ='AEB-4 CGDCF'!I6 -> 0.081 | K26: =AVERAGE(H26:J26) -> 0.074 | L26: =K26+F26 -> 0.12037562 | M26: =K26+G26 -> 0.1218261
A27: ='AEB-4 CGDCF'!A7 -> Alliant Energy Corporation | B27: ='AEB-4 CGDCF'!B7 -> LNT | C27: ='AEB-4 CGDCF'!C7 -> 1.92 | D27: ='AEB-4 CGDCF'!D7 -> 49.881497 | E27: =C27/D27 -> 0.038491227 | F27: =IFERROR(E27*(1+0.5*K27),"") -> 0.039732569 | G27: =F27/(1-$L$11) -> 0.040975273 | H27: ='AEB-4 CGDCF'!G7 -> 0.065 | I27: ='AEB-4 CGDCF'!H7 -> 0.0655 | J27: ='AEB-4 CGDCF'!I7 -> 0.063 | K27: =AVERAGE(H27:J27) -> 0.0645 | L27: =K27+F27 -> 0.10423257 | M27: =K27+G27 -> 0.10547527
A28: ='AEB-4 CGDCF'!A8 -> Ameren Corporation | B28: ='AEB-4 CGDCF'!B8 -> AEE | C28: ='AEB-4 CGDCF'!C8 -> 2.52 | D28: ='AEB-4 CGDCF'!D8 -> 71.507333 | E28: =C28/D28 -> 0.035241141 | F28: =IFERROR(E28*(1+0.5*K28),"") -> 0.036269007 | G28: =F28/(1-$L$11) -> 0.037403382 | H28: ='AEB-4 CGDCF'!G8 -> 0.065 | I28: ='AEB-4 CGDCF'!H8 -> 0.048 | J28: ='AEB-4 CGDCF'!I8 -> 0.062 | K28: =AVERAGE(H28:J28) -> 0.058333333 | L28: =K28+F28 -> 0.094602341 | M28: =K28+G28 -> 0.095736716
A29: ='AEB-4 CGDCF'!A9 -> Duke Energy Corporation | B29: ='AEB-4 CGDCF'!B9 -> DUK | C29: ='AEB-4 CGDCF'!C9 -> 4.1 | D29: ='AEB-4 CGDCF'!D9 -> 96.902667 | E29: =C29/D29 -> 0.042310497 | F29: =IFERROR(E29*(1+0.5*K29),"") -> 0.043569234 | G29: =F29/(1-$L$11) -> 0.044931936 | H29: ='AEB-4 CGDCF'!G9 -> 0.05 | I29: ='AEB-4 CGDCF'!H9 -> 0.0655 | J29: ='AEB-4 CGDCF'!I9 -> 0.063 | K29: =AVERAGE(H29:J29) -> 0.0595 | L29: =K29+F29 -> 0.10306923 | M29: =K29+G29 -> 0.10443194
A30: ='AEB-4 CGDCF'!A10 -> Edison International | B30: ='AEB-4 CGDCF'!B10 -> EIX | C30: ='AEB-4 CGDCF'!C10 -> 3.12 | D30: ='AEB-4 CGDCF'!D10 -> 69.70901 | E30: =C30/D30 -> 0.044757485 | F30: =IFERROR(E30*(1+0.5*K30),"") -> 0.045712312 | G30: =F30/(1-$L$11) -> 0.047142042 | H30: ='AEB-4 CGDCF'!G10 -> 0.045 | I30: ='AEB-4 CGDCF'!H10 -> 0.046 | J30: ='AEB-4 CGDCF'!I10 -> 0.037 | K30: =AVERAGE(H30:J30) -> 0.042666667 | L30: =K30+F30 -> 0.088378978 | M30: =K30+G30 -> 0.089808709
A31: ='AEB-4 CGDCF'!A11 -> Entergy Corporation | B31: ='AEB-4 CGDCF'!B11 -> ETR | C31: ='AEB-4 CGDCF'!C11 -> 4.52 | D31: ='AEB-4 CGDCF'!D11 -> 101.03067 | E31: =C31/D31 -> 0.044738891 | F31: =IFERROR(E31*(1+0.5*K31),"") -> 0.04611834 | G31: =F31/(1-$L$11) -> 0.04756077 | H31: ='AEB-4 CGDCF'!G11 -> 0.005 | I31: ='AEB-4 CGDCF'!H11 -> 0.11 | J31: ='AEB-4 CGDCF'!I11 -> 0.07 | K31: =AVERAGE(H31:J31) -> 0.061666667 | L31: =K31+F31 -> 0.10778501 | M31: =K31+G31 -> 0.10922744
A32: ='AEB-4 CGDCF'!A12 -> Eversource Energy | B32: ='AEB-4 CGDCF'!B12 -> ES | C32: ='AEB-4 CGDCF'!C12 -> 2.7 | D32: ='AEB-4 CGDCF'!D12 -> 58.34 | E32: =C32/D32 -> 0.046280425 | F32: =IFERROR(E32*(1+0.5*K32),"") -> 0.047344875 | G32: =F32/(1-$L$11) -> 0.048825666 | H32: ='AEB-4 CGDCF'!G12 -> 0.06 | I32: ='AEB-4 CGDCF'!H12 -> 0.036 | J32: ='AEB-4 CGDCF'!I12 -> 0.042 | K32: =AVERAGE(H32:J32) -> 0.046 | L32: =K32+F32 -> 0.093344875 | M32: =K32+G32 -> 0.094825666
A33: ='AEB-4 CGDCF'!A13 -> Evergy, Inc. | B33: ='AEB-4 CGDCF'!B13 -> EVRG | C33: ='AEB-4 CGDCF'!C13 -> 2.57 | D33: ='AEB-4 CGDCF'!D13 -> 51.868 | E33: =C33/D33 -> 0.049548855 | F33: =IFERROR(E33*(1+0.5*K33),"") -> 0.050729769 | G33: =F33/(1-$L$11) -> 0.052316429 | H33: ='AEB-4 CGDCF'!G13 -> 0.075 | I33: ='AEB-4 CGDCF'!H13 -> 0.025 | J33: ='AEB-4 CGDCF'!I13 -> 0.043 | K33: =AVERAGE(H33:J33) -> 0.047666667 | L33: =K33+F33 -> 0.098396436 | M33: =K33+G33 -> 0.099983096
A34: ='AEB-4 CGDCF'!A14 -> IDACORP, Inc. | B34: ='AEB-4 CGDCF'!B14 -> IDA | C34: ='AEB-4 CGDCF'!C14 -> 3.32 | D34: ='AEB-4 CGDCF'!D14 -> 95.875333 | E34: =C34/D34 -> 0.034628302 | F34: =IFERROR(E34*(1+0.5*K34),"") -> 0.035367039 | G34: =F34/(1-$L$11) -> 0.036473203 | H34: ='AEB-4 CGDCF'!G14 -> 0.04 | I34: ='AEB-4 CGDCF'!H14 -> 0.044 | J34: ='AEB-4 CGDCF'!I14 -> 0.044 | K34: =AVERAGE(H34:J34) -> 0.042666667 | L34: =K34+F34 -> 0.078033706 | M34: =K34+G34 -> 0.07913987
A35: ='AEB-4 CGDCF'!A15 -> NextEra Energy, Inc. | B35: ='AEB-4 CGDCF'!B15 -> NEE | C35: ='AEB-4 CGDCF'!C15 -> 1.87 | D35: ='AEB-4 CGDCF'!D15 -> 59.981 | E35: =C35/D35 -> 0.031176539 | F35: =IFERROR(E35*(1+0.5*K35),"") -> 0.032502062 | G35: =F35/(1-$L$11) -> 0.033518619 | H35: ='AEB-4 CGDCF'!G15 -> 0.095 | I35: ='AEB-4 CGDCF'!H15 -> 0.0781 | J35: ='AEB-4 CGDCF'!I15 -> 0.082 | K35: =AVERAGE(H35:J35) -> 0.085033333 | L35: =K35+F35 -> 0.1175354 | M35: =K35+G35 -> 0.11855195
A36: ='AEB-4 CGDCF'!A16 -> NorthWestern Corporation | B36: ='AEB-4 CGDCF'!B16 -> NWE | C36: ='AEB-4 CGDCF'!C16 -> 2.56 | D36: ='AEB-4 CGDCF'!D16 -> 49.779 | E36: =C36/D36 -> 0.051427309 | F36: =IFERROR(E36*(1+0.5*K36),"") -> 0.05252271 | G36: =F36/(1-$L$11) -> 0.054165448 | H36: ='AEB-4 CGDCF'!G16 -> 0.035 | I36: ='AEB-4 CGDCF'!H16 -> 0.0408 | J36: ='AEB-4 CGDCF'!I16 -> 0.052 | K36: =AVERAGE(H36:J36) -> 0.0426 | L36: =K36+F36 -> 0.09512271 | M36: =K36+G36 -> 0.096765448
A37: ='AEB-4 CGDCF'!A17 -> OGE Energy Corporation | B37: ='AEB-4 CGDCF'!B17 -> OGE | C37: ='AEB-4 CGDCF'!C17 -> 1.6728 | D37: ='AEB-4 CGDCF'!D17 -> 34.14228 | E37: =C37/D37 -> 0.04899497 | F37: =IFERROR(E37*(1+0.5*K37),"") -> 0.050281088 | G37: =F37/(1-$L$11) -> 0.051853715 | H37: ='AEB-4 CGDCF'!G17 -> 0.065 | I37: ='AEB-4 CGDCF'!H17 -> negative | J37: ='AEB-4 CGDCF'!I17 -> 0.04 | K37: =AVERAGE(H37:J37) -> 0.0525 | L37: =K37+F37 -> 0.10278109 | M37: =K37+G37 -> 0.10435372
... A40: ='AEB-4 CGDCF'!A20 -> Xcel Energy Inc. | B40: ='AEB-4 CGDCF'!B20 -> XEL | C40: ='AEB-4 CGDCF'!C20 -> 2.08 | D40: ='AEB-4 CGDCF'!D20 -> 61.14286 | E40: =C40/D40 -> 0.03401869 | F40: =IFERROR(E40*(1+0.5*K40),"") -> 0.035071568 | G40: =F40/(1-$L$11) -> 0.036168491 | H40: ='AEB-4 CGDCF'!G20 -> 0.06 | I40: ='AEB-4 CGDCF'!H20 -> 0.0657 | J40: ='AEB-4 CGDCF'!I20 -> 0.06 | K40: =AVERAGE(H40:J40) -> 0.0619 | L40: =K40+F40 -> 0.096971568 | M40: =K40+G40 -> 0.098068491
A42: Mean | L42: =AVERAGE(L26:L40) -> 0.099403256 | M42: =AVERAGE(M26:M40) -> 0.10077668
A43: Median | L43: =MEDIAN(L26:L40) -> 0.09811952 | M43: =MEDIAN(M26:M40) -> 0.099561986
A45: Flotation Cost Adjustment (Mean) [22] | M45: =M42-L42 -> 0.0013734271
A46: Flotation Cost Adjustment (Median) [23] | M46: =M43-L43 -> 0.0014424665
A50: Notes:
A51: [1] - [5] Source: American Electric Power Company, Inc. - Prospectus dated February 26, 2003 and Prospectus dated December 22, 2008
A52: [6] Equals [9]/[2]
A53: [7] Equals [5] + ([4] x [2])
A54: [8] Equals [2] x [3]
A55: [9] Equals [8] - [7]
A56: [10] Equals [7] / [8]
A57: [11] Bloomberg Professional
A58: [12] Bloomberg Professional, equals 30-day average as of January 31, 2024
...

Sheet AEB-10 Reg Risk
B2: COMPARISON OF AEP TEXAS AND PROXY GROUP COMPANIES
B3: RISK ASSESSMENT
G5: [1] | H5: [2] | K5: [3] | M5: [4] | O5: [5] | Q5: [6] | T5: [7] | V5: [8] | X5: [9] | Z5: [10] | AB5: [11]
B6: Proxy Group Company | C6: Operating Subsidiary | D6: Jurisdiction | E6: Service | G6: Electric fuel/gas commodity/purchase power | I6: Test Year | K6: Non-Volumetric Rate Design | T6: Capital Cost Recovery
K7: Revenue Decoupling | M7: Formula-based rates | O7: Straight Fixed-Variable Rate Design | Q7: Non-Volumetric Rate Design | T7: Traditional Generation | V7: Renewables/Non-Traditional Generation | X7: Delivery Infrastructure | Z7: Environmental Compliance | AB7: Capital Cost Recovery
B8: ALLETE, Inc. | C8: ALLETE (Minnesota Power) | D8: Minnesota | E8: Electric | G8: Yes | I8: Fully Forecast | L8: No | N8: No | P8: No | R8: =IF(AND(L8="No",N8="No",P8="No"),"No","Yes") -> No | U8: No | W8: Yes | Y8: No | AA8: No | AC8: =IF(AND(U8="No",W8="No",Y8="No",AA8="No"),"No","Yes") -> Yes
B9: Alliant Energy Corporation | C9: Interstate Power & Light Co. | D9: Iowa | E9: Electric | G9: Yes | I9: Historical | L9: No | N9: No | P9: No | R9: =IF(AND(L9="No",N9="No",P9="No"),"No","Yes") -> No | U9: No | W9: Yes | Y9: No | AA9: Yes | AC9: =IF(AND(U9="No",W9="No",Y9="No",AA9="No"),"No","Yes") -> Yes
C10: Interstate Power & Light Co. | D10: Iowa | E10: Gas | G10: Yes | I10: Historical | L10: No | N10: No | P10: No | R10: =IF(AND(L10="No",N10="No",P10="No"),"No","Yes") -> No | U10: No | W10: No | Y10: No | AA10: No | AC10: =IF(AND(U10="No",W10="No",Y10="No",AA10="No"),"No","Yes") -> No
C11: Wisconsin Power & Light Co. | D11: Wisconsin | E11: Electric | G11: Yes | I11: Fully Forecast | L11: No | N11: No | P11: No | R11: =IF(AND(L11="No",N11="No",P11="No"),"No","Yes") -> No | U11: No | W11: No | Y11: No | AA11: No | AC11: =IF(AND(U11="No",W11="No",Y11="No",AA11="No"),"No","Yes") -> No
C12: Wisconsin Power & Light Co. | D12: Wisconsin | E12: Gas | G12: Yes | I12: Fully Forecast | L12: No | N12: No | P12: No | R12: =IF(AND(L12="No",N12="No",P12="No"),"No","Yes") -> No | U12: No | W12: No | Y12: No | AA12: No | AC12: =IF(AND(U12="No",W12="No",Y12="No",AA12="No"),"No","Yes") -> No
B13: Ameren Corporation | C13: Ameren Illinois Co. | D13: Illinois | E13: Electric | G13: N/A | I13: Historical | L13: Partial | N13: Yes | P13: No | R13: =IF(AND(L13="No",N13="No",P13="No"),"No","Yes") -> Yes | U13: No | W13: Yes | Y13: No | AA13: Yes | AC13: =IF(AND(U13="No",W13="No",Y13="No",AA13="No"),"No","Yes") -> Yes
C14: Ameren Illinois Co. | D14: Illinois | E14: Gas | G14: Yes | I14: Fully Forecast | L14: Partial | N14: No | P14: No | R14: =IF(AND(L14="No",N14="No",P14="No"),"No","Yes") -> Yes | U14: No | W14: No | Y14: Yes | AA14: Yes | AC14: =IF(AND(U14="No",W14="No",Y14="No",AA14="No"),"No","Yes") -> Yes
C15: Union Electric Co. | D15: Missouri | E15: Electric | G15: Yes - Sharing Band | I15: Historical | L15: Partial | N15: No | P15: No | R15: =IF(AND(L15="No",N15="No",P15="No"),"No","Yes") -> Yes | U15: No | W15: Yes | Y15: Yes | AA15: No | AC15: =IF(AND(U15="No",W15="No",Y15="No",AA15="No"),"No","Yes") -> Yes
C16: Union Electric Co. | D16: Missouri | E16: Gas | G16: Yes | I16: Historical | L16: Partial | N16: No | P16: No | R16: =IF(AND(L16="No",N16="No",P16="No"),"No","Yes") -> Yes | U16: No | W16: No | Y16: Yes | AA16: No | AC16: =IF(AND(U16="No",W16="No",Y16="No",AA16="No"),"No","Yes") -> Yes
B17: Duke Energy Corporation | C17: Duke Energy Florida LLC | D17: Florida | E17: Electric | G17: Yes | I17: Fully Forecast | L17: No | N17: No | P17: No | R17: =IF(AND(L17="No",N17="No",P17="No"),"No","Yes") -> No | U17: Yes | W17: Yes | Y17: No | AA17: Yes | AC17: =IF(AND(U17="No",W17="No",Y17="No",AA17="No"),"No","Yes") -> Yes
C18: Duke Energy Indiana LLC | D18: Indiana | E18: Electric | G18: Yes | I18: Historical | L18: Partial | N18: No | P18: No | R18: =IF(AND(L18="No",N18="No",P18="No"),"No","Yes") -> Yes | U18: No | W18: Yes | Y18: Yes | AA18: Yes | AC18: =IF(AND(U18="No",W18="No",Y18="No",AA18="No"),"No","Yes") -> Yes
C19: Duke Energy Kentucky Inc. | D19: Kentucky | E19: Electric | G19: Yes | I19: Fully Forecast | L19: Partial | N19: No | P19: No | R19: =IF(AND(L19="No",N19="No",P19="No"),"No","Yes") -> Yes | U19: No | W19: No | Y19: No | AA19: Yes | AC19: =IF(AND(U19="No",W19="No",Y19="No",AA19="No"),"No","Yes") -> Yes
C20: Duke Energy Kentucky Inc. | D20: Kentucky | E20: Gas | G20: Yes | I20: Fully Forecast | L20: Partial | N20: No | P20: No | R20: =IF(AND(L20="No",N20="No",P20="No"),"No","Yes") -> Yes | U20: No | W20: No | Y20: Yes | AA20: No | AC20: =IF(AND(U20="No",W20="No",Y20="No",AA20="No"),"No","Yes") -> Yes
C21: Duke Energy Carolinas LLC/Duke Energy Progress LLC | D21: North Carolina | E21: Electric | G21: Yes | I21: Historical | L21: No | N21: No | P21: No | R21: =IF(AND(L21="No",N21="No",P21="No"),"No","Yes") -> No | U21: No | W21: Yes | Y21: No | AA21: Yes | AC21: =IF(AND(U21="No",W21="No",Y21="No",AA21="No"),"No","Yes") -> Yes
C22: Piedmont Natural Gas Co. Inc. | D22: North Carolina | E22: Gas | G22: Yes | I22: Historical | L22: Full | N22: No | P22: No | R22: =IF(AND(L22="No",N22="No",P22="No"),"No","Yes") -> Yes | U22: No | W22: No | Y22: Yes | AA22: No | AC22: =IF(AND(U22="No",W22="No",Y22="No",AA22="No"),"No","Yes") -> Yes
