Workbook
Name a: #REF!
Name a: #REF!
Name H_Rate_Class: 'Tariff Mapping'!$E$5:$E$114
Name page1: #REF!
Name page10: #REF!
Name page2: #REF!
Name page3: #REF!
Name page4: #REF!
Name page5: #REF!
Name page6: #REF!
Name page7: #REF!
Name page8: #REF!
Name page9: #REF!
Name q: [2]Summary!#REF!
Name q: [2]Summary!#REF!
Name Rate_Class2: '[3]Tariff Mapping'!$E$5:$E$59
Name ResBasic: [4]Summary!#REF!
Name ResBasic: [4]Summary!#REF!
Name ResEconomy1: [4]Summary!#REF!
Name ResEconomy1: [4]Summary!#REF!
Name ResEconomy2: [4]Summary!#REF!
Name ResEconomy2: [4]Summary!#REF!
Name ResWaterHeating: [4]Summary!#REF!
Name ResWaterHeating: [4]Summary!#REF!
Name test: [2]Summary!#REF!
Name test: [2]Summary!#REF!
Name test1: [2]Summary!#REF!
Name test1: [2]Summary!#REF!
Name total: #REF!
Name w: [2]Summary!#REF!
Name w: [2]Summary!#REF!

Sheet II-H-1
B2: PUBLIC UTILITY COMMISSION OF TEXAS
B3: AEP TEXAS INC
B4: II-H-1 SUMMARY OF TEST YEAR ADJUSTMENTS
B5: TEST YEAR ENDING 9/30/2023
B6: DOCKET 56165
B9: Refer to Schedule II-H-1.1 for the summary of test year adjustments

Sheet II-H-1.1
B2: PUBLIC UTILITY COMMISSION OF TEXAS
B3: AEP TEXAS INC
B4: II-H-1.1 TEST YEAR SALES DATA
B5: ='II-H-1'!B5 -> TEST YEAR ENDING 9/30/2023
B6: =+'II-H-1'!B6 -> DOCKET 56165
A8: AEP TEXAS
A9: TEST YEAR DATA BY RATE CLASS
D10: FOR TEST YEAR ENDED SEPTEMBER 30, 2023
D12: Average | E12: Year-end | F12: Unadjusted | G12: Weather kWh | H12: Customer kWh | I12: Other kWh | J12: Adjusted
A13: LINE | B13: DESCRIPTION | C13: VOLT | D13: Customers | E13: Customers | F13: kWh at Meter | G13: Adjustment | H13: Adjustment | I13: Adjustment | J13: kWh
A15: 1 | B15: RESIDENTIAL SERVICE | C15: SEC | D15: ='II-H-3.1-3'!Q14 -> 926197.58 | E15: ='II-H-3.1-3'!O14 -> 935238 | F15: ='II-H-1.2'!P14 -> 12797050643 | G15: ='II-H-1.2'!P46 -> -3.1306872e+08 | H15: ='II-H-1.2'!P78 -> 1.0590063e+08 | I15: ='II-H-1.2'!P112 -> 0 | J15: ='II-H-1.2'!P144 -> 1.2589883e+10
A17: 2 | B17: SECONDARY < 10 kW | C17: SEC | D17: ='II-H-3.1-3'!Q16 -> 98796.167 | E17: ='II-H-3.1-3'!O16 -> 99366 | F17: ='II-H-1.2'!P16 -> 678758664 | G17: ='II-H-1.2'!P48 -> -8767706.8 | H17: ='II-H-1.2'!P80 -> 2109148.9 | I17: ='II-H-1.2'!P114 -> 0 | J17: ='II-H-1.2'!P146 -> 6.7210011e+08
A19: 3 | B19: SECONDARY > 10 kW NCP | C19: SEC | D19: ='II-H-3.1-3'!Q18 -> 71496.417 | E19: ='II-H-3.1-3'!O18 -> 71833 | F19: ='II-H-1.2'!P18 -> 7956360402 | G19: ='II-H-1.2'!P50 -> -1.1227043e+08 | H19: ='II-H-1.2'!P82 -> 51400456 | I19: ='II-H-1.2'!P116 -> 0 | J19: ='II-H-1.2'!P148 -> 7.8954904e+09
A20: 4 | B20: SECONDARY > 10 kW 4CP | C20: SEC | D20: ='II-H-3.1-3'!Q19 -> 570.66667 | E20: ='II-H-3.1-3'!O19 -> 576 | F20: ='II-H-1.2'!P19 -> 1307495001 | G20: ='II-H-1.2'!P51 -> -8524699.1 | H20: ='II-H-1.2'!P83 -> 10596481 | I20: ='II-H-1.2'!P117 -> 0 | J20: ='II-H-1.2'!P149 -> 1.3095668e+09
A21: 5 | B21: TOTAL SECONDARY > 10 kW | D21: =SUM(D19:D20) -> 72067.083 | E21: =SUM(E19:E20) -> 72409 | F21: =SUM(F19:F20) -> 9263855403 | G21: =SUM(G19:G20) -> -1.2079513e+08 | H21: =SUM(H19:H20) -> 61996937 | I21: =SUM(I19:I20) -> 0 | J21: =SUM(J19:J20) -> 9.2050572e+09
A23: 6 | B23: PRIMARY NCP | C23: PRI | D23: ='II-H-3.1-3'!Q22 -> 550.33333 | E23: ='II-H-3.1-3'!O22 -> 550 | F23: ='II-H-1.2'!P22 -> 263796669 | G23: ='II-H-1.2'!P54 -> -2124654.5 | H23: ='II-H-1.2'!P86 -> -514363.46 | I23: ='II-H-1.2'!P120 -> 0 | J23: ='II-H-1.2'!P152 -> 2.6115765e+08
A24: 7 | B24: PRIMARY 4CP | C24: PRI | D24: ='II-H-3.1-3'!Q23 -> 475.08333 | E24: ='II-H-3.1-3'!O23 -> 469 | F24: ='II-H-1.2'!P23 -> 3828118181 | G24: ='II-H-1.2'!P55 -> -29574766 | H24: ='II-H-1.2'!P87 -> -40429397 | I24: ='II-H-1.2'!P121 -> 0 | J24: ='II-H-1.2'!P153 -> 3.758114e+09
A25: 8 | B25: PRIMARY SUB NCP | C25: PRI | D25: ='II-H-3.1-3'!Q24 -> 9 | E25: ='II-H-3.1-3'!O24 -> 9 | F25: ='II-H-1.2'!P24 -> 5880600 | G25: ='II-H-1.2'!P56 -> 0 | H25: ='II-H-1.2'!P88 -> 0 | I25: ='II-H-1.2'!P122 -> 0 | J25: ='II-H-1.2'!P154 -> 5880600
A26: 9 | B26: PRIMARY SUB 4CP | C26: PRI | D26: ='II-H-3.1-3'!Q25 -> 58 | E26: ='II-H-3.1-3'!O25 -> 58 | F26: ='II-H-1.2'!P25 -> 499919380 | G26: ='II-H-1.2'!P57 -> 0 | H26: ='II-H-1.2'!P89 -> 0 | I26: ='II-H-1.2'!P123 -> 0 | J26: ='II-H-1.2'!P155 -> 499919380
A27: 10 | B27: TOTAL PRIMARY | D27: =SUM(D23:D26) -> 1092.4167 | E27: =SUM(E23:E26) -> 1086 | F27: =SUM(F23:F26) -> 4597714830 | G27: =SUM(G23:G26) -> -31699420 | H27: =SUM(H23:H26) -> -40943761 | I27: =SUM(I23:I26) -> 0 | J27: =SUM(J23:J26) -> 4.5250716e+09
A29: 11 | B29: TRANSMISSION | C29: TRA | D29: ='II-H-3.1-3'!Q28 -> 124.16667 | E29: ='II-H-3.1-3'!O28 -> 123 | F29: ='II-H-1.2'!P28 -> 11207029849 | G29: ='II-H-1.2'!P60 -> -1282930 | H29: ='II-H-1.2'!P92 -> -1.7005016e+08 | I29: ='II-H-1.2'!P126 -> 0 | J29: ='II-H-1.2'!P158 -> 1.1035697e+10
A31: 12 | B31: LIGHTING | C31: SEC | D31: ='II-H-3.1-3'!Q30 -> 221912.58 | E31: ='II-H-3.1-3'!O30 -> 221390 | F31: ='II-H-1.2'!P30 -> 240936337 | G31: ='II-H-1.2'!P62 -> 39 | H31: ='II-H-1.2'!P94 -> -2551478.4 | I31: ='II-H-1.2'!P128 -> 0 | J31: ='II-H-1.2'!P160 -> 2.383849e+08
A33: 13 | B33: TOTAL RETAIL | D33: =D31+D29+D27+D21+D17+D15 -> 1320190 | E33: =E31+E29+E27+E21+E17+E15 -> 1329612 | F33: =F31+F29+F27+F21+F17+F15 -> 38785345726 | G33: =G31+G29+G27+G21+G17+G15 -> -4.7561387e+08 | H33: =H31+H29+H27+H21+H17+H15 -> -43538688 | I33: =I31+I29+I27+I21+I17+I15 -> 0 | J33: =J31+J29+J27+J21+J17+J15 -> 3.8266193e+10
A35: 14 | B35: WHOLESALE PRI | C35: PRI | D35: ='II-H-3.1-3'!Q34 -> 0 | E35: ='II-H-3.1-3'!O34 -> 0 | F35: ='II-H-1.2'!P34 -> 0 | G35: ='II-H-1.2'!P66 -> 0 | H35: ='II-H-1.2'!P98 -> 0 | I35: ='II-H-1.2'!P132 -> 0 | J35: ='II-H-1.2'!P164 -> 0
A36: 15 | B36: WHOLESALE TRANS | C36: TRA | D36: ='II-H-3.1-3'!Q35 -> 0 | E36: ='II-H-3.1-3'!O35 -> 0 | F36: ='II-H-1.2'!P35 -> 0 | G36: ='II-H-1.2'!P67 -> 0 | H36: ='II-H-1.2'!P99 -> 0 | I36: ='II-H-1.2'!P133 -> 0
A37: 16 | B37: TOTAL WHOLESALE | D37: ='II-H-3.1-3'!Q139 -> 0 | E37: ='II-H-3.1-3'!O139 -> 0 | F37: =SUM(F35:F36) -> 0 | G37: =SUM(G35:G36) -> 0 | H37: =SUM(H35:H36) -> 0 | I37: =SUM(I35:I36) -> 0 | J37: =SUM(J35:J36) -> 0
A39: 17 | B39: TOTAL AEP TEXAS | D39: =+D37+D33 -> 1320190 | E39: =+E37+E33 -> 1329612 | F39: =+F37+F33 -> 38785345726 | G39: =+G37+G33 -> -4.7561387e+08 | H39: =+H37+H33 -> -43538688 | I39: =+I37+I33 -> 0 | J39: =+J37+J33 -> 3.8266193e+10
B41: Note: Secondary < 10 kW includes Unmetered service; Lighting customers are fixture counts.

Sheet II-H-1.2
B2: PUBLIC UTILITY COMMISSION OF TEXAS
B3: AEP TEXAS INC
B4: II-H-1.2 MONTHLY SALES DATA
B5: ='II-H-1.1'!B5 -> TEST YEAR ENDING 9/30/2023
B6: =+'II-H-1'!B6 -> DOCKET 56165
B7: AEP TEXAS
B8: UNADJUSTED BILLING KWH AT METER
G9: FOR TEST YEAR ENDED SEPTEMBER 30, 2023
A12: LINE | B12: DESCRIPTION | C12: VOLT | D12: Oct-22 | E12: Nov-22 | F12: Dec-22 | G12: Jan-23 | H12: Feb-23 | I12: Mar-23 | J12: Apr-23 | K12: May-23 | L12: Jun-23 | M12: Jul-23 | N12: Aug-23 | O12: Sep-23 | P12: TOTAL
Q13: dist rate | R13: trans rate
A14: 1 | B14: RESIDENTIAL SERVICE | C14: SEC | D14: {=SUMPRODUCT((H_Rate_Class=$B14)*[5]Energy!D$9:D$118)} -> 1030830606 | E14: {=SUMPRODUCT((H_Rate_Class=$B14)*[5]Energy!E$9:E$118)} -> 795799107 | F14: {=SUMPRODUCT((H_Rate_Class=$B14)*[5]Energy!F$9:F$118)} -> 926112371 | G14: {=SUMPRODUCT((H_Rate_Class=$B14)*[5]Energy!G$9:G$118)} -> 993225833 | H14: {=SUMPRODUCT((H_Rate_Class=$B14)*[5]Energy!H$9:H$118)} -> 874152468 | I14: {=SUMPRODUCT((H_Rate_Class=$B14)*[5]Energy!I$9:I$118)} -> 802450848 | J14: {=SUMPRODUCT((H_Rate_Class=$B14)*[5]Energy!J$9:J$118)} -> 790703542 | K14: {=SUMPRODUCT((H_Rate_Class=$B14)*[5]Energy!K$9:K$118)} -> 863356125 | ... O14: {=SUMPRODUCT((H_Rate_Class=$B14)*[5]Energy!O$9:O$118)} -> 1492215334 | P14: =SUM(D14:O14) -> 12797050643 | Q14: ='II-H-4.1 Functions'!F15/'II-H-1.2'!P14 -> 0.021785842 | R14: ='II-H-4.1 Functions'!I15/'II-H-1.2'!P14 -> 0.015254793
A16: 2 | B16: SECONDARY < 10 kW | C16: SEC | D16: {=SUMPRODUCT((H_Rate_Class=$B16)*[5]Energy!D$9:D$118)} -> 57029485 | E16: {=SUMPRODUCT((H_Rate_Class=$B16)*[5]Energy!E$9:E$118)} -> 50491315 | F16: {=SUMPRODUCT((H_Rate_Class=$B16)*[5]Energy!F$9:F$118)} -> 53528583 | G16: {=SUMPRODUCT((H_Rate_Class=$B16)*[5]Energy!G$9:G$118)} -> 54161558 | H16: {=SUMPRODUCT((H_Rate_Class=$B16)*[5]Energy!H$9:H$118)} -> 49615650 | I16: {=SUMPRODUCT((H_Rate_Class=$B16)*[5]Energy!I$9:I$118)} -> 48863762 | J16: {=SUMPRODUCT((H_Rate_Class=$B16)*[5]Energy!J$9:J$118)} -> 48592645 | K16: {=SUMPRODUCT((H_Rate_Class=$B16)*[5]Energy!K$9:K$118)} -> 50905532 | ... O16: {=SUMPRODUCT((H_Rate_Class=$B16)*[5]Energy!O$9:O$118)} -> 69458368 | P16: =SUM(D16:O16) -> 678758664 | Q16: ='II-H-4.1 Functions'!F17/'II-H-1.2'!P16 -> 0.021063902 | R16: ='II-H-4.1 Functions'!I17/'II-H-1.2'!P16 -> 0.009622364
A18: 3 | B18: SECONDARY > 10 kW NCP | C18: SEC | D18: {=SUMPRODUCT((H_Rate_Class=$B18)*[5]Energy!D$9:D$118)} -> 677255540 | E18: {=SUMPRODUCT((H_Rate_Class=$B18)*[5]Energy!E$9:E$118)} -> 581315754 | F18: {=SUMPRODUCT((H_Rate_Class=$B18)*[5]Energy!F$9:F$118)} -> 584049090 | G18: {=SUMPRODUCT((H_Rate_Class=$B18)*[5]Energy!G$9:G$118)} -> 586060179 | H18: {=SUMPRODUCT((H_Rate_Class=$B18)*[5]Energy!H$9:H$118)} -> 535341103 | I18: {=SUMPRODUCT((H_Rate_Class=$B18)*[5]Energy!I$9:I$118)} -> 564700229 | J18: {=SUMPRODUCT((H_Rate_Class=$B18)*[5]Energy!J$9:J$118)} -> 580527274 | K18: {=SUMPRODUCT((H_Rate_Class=$B18)*[5]Energy!K$9:K$118)} -> 612828213 | ... O18: {=SUMPRODUCT((H_Rate_Class=$B18)*[5]Energy!O$9:O$118)} -> 847276494 | P18: =SUM(D18:O18) -> 7956360402
A19: 4 | B19: SECONDARY > 10 kW 4CP | C19: SEC | D19: {=SUMPRODUCT((H_Rate_Class=$B19)*[5]Energy!D$9:D$118)} -> 112154601 | E19: {=SUMPRODUCT((H_Rate_Class=$B19)*[5]Energy!E$9:E$118)} -> 99177738 | F19: {=SUMPRODUCT((H_Rate_Class=$B19)*[5]Energy!F$9:F$118)} -> 103548456 | G19: {=SUMPRODUCT((H_Rate_Class=$B19)*[5]Energy!G$9:G$118)} -> 98923977 | H19: {=SUMPRODUCT((H_Rate_Class=$B19)*[5]Energy!H$9:H$118)} -> 90170835 | I19: {=SUMPRODUCT((H_Rate_Class=$B19)*[5]Energy!I$9:I$118)} -> 95019133 | J19: {=SUMPRODUCT((H_Rate_Class=$B19)*[5]Energy!J$9:J$118)} -> 101144648 | K19: {=SUMPRODUCT((H_Rate_Class=$B19)*[5]Energy!K$9:K$118)} -> 101827371 | ... O19: {=SUMPRODUCT((H_Rate_Class=$B19)*[5]Energy!O$9:O$118)} -> 138130242 | P19: =SUM(D19:O19) -> 1307495001
A20: 5 | B20: TOTAL SECONDARY > 10 kW | D20: =SUM(D18:D19) -> 789410141 | E20: =SUM(E18:E19) -> 680493492 | F20: =SUM(F18:F19) -> 687597546 | G20: =SUM(G18:G19) -> 684984156 | H20: =SUM(H18:H19) -> 625511938 | I20: =SUM(I18:I19) -> 659719362 | J20: =SUM(J18:J19) -> 681671922 | K20: =SUM(K18:K19) -> 714655584 | ... P20: =SUM(P18:P19) -> 9263855403
A22: 6 | B22: PRIMARY NCP | C22: PRI | D22: {=SUMPRODUCT((H_Rate_Class=$B22)*[5]Energy!D$9:D$118)-D24} -> 19380025 | E22: {=SUMPRODUCT((H_Rate_Class=$B22)*[5]Energy!E$9:E$118)-E24} -> 19173997 | F22: {=SUMPRODUCT((H_Rate_Class=$B22)*[5]Energy!F$9:F$118)-F24} -> 21118424 | G22: {=SUMPRODUCT((H_Rate_Class=$B22)*[5]Energy!G$9:G$118)-G24} -> 19277379 | H22: {=SUMPRODUCT((H_Rate_Class=$B22)*[5]Energy!H$9:H$118)-H24} -> 19145834 | I22: {=SUMPRODUCT((H_Rate_Class=$B22)*[5]Energy!I$9:I$118)-I24} -> 20878902 | J22: {=SUMPRODUCT((H_Rate_Class=$B22)*[5]Energy!J$9:J$118)-J24} -> 22537497 | K22: {=SUMPRODUCT((H_Rate_Class=$B22)*[5]Energy!K$9:K$118)-K24} -> 24721739 | ... O22: {=SUMPRODUCT((H_Rate_Class=$B22)*[5]Energy!O$9:O$118)-O24} -> 25271869 | P22: =SUM(D22:O22) -> 263796669
A23: 7 | B23: PRIMARY 4CP | C23: PRI | D23: {=SUMPRODUCT((H_Rate_Class=$B23)*[5]Energy!D$9:D$118)-D25} -> 308798023 | E23: {=SUMPRODUCT((H_Rate_Class=$B23)*[5]Energy!E$9:E$118)-E25} -> 300702542 | F23: {=SUMPRODUCT((H_Rate_Class=$B23)*[5]Energy!F$9:F$118)-F25} -> 309414261 | G23: {=SUMPRODUCT((H_Rate_Class=$B23)*[5]Energy!G$9:G$118)-G25} -> 317946576 | H23: {=SUMPRODUCT((H_Rate_Class=$B23)*[5]Energy!H$9:H$118)-H25} -> 290350982 | I23: {=SUMPRODUCT((H_Rate_Class=$B23)*[5]Energy!I$9:I$118)-I25} -> 296423645 | J23: {=SUMPRODUCT((H_Rate_Class=$B23)*[5]Energy!J$9:J$118)-J25} -> 308572852 | K23: {=SUMPRODUCT((H_Rate_Class=$B23)*[5]Energy!K$9:K$118)-K25} -> 312036499 | ... O23: {=SUMPRODUCT((H_Rate_Class=$B23)*[5]Energy!O$9:O$118)-O25} -> 350324818 | P23: =SUM(D23:O23) -> 3828118181
A24: 8 | B24: PRIMARY SUB NCP | C24: PRI | D24: =+'Primary Sub'!C18 -> 431400 | E24: =+'Primary Sub'!D18 -> 410400 | F24: =+'Primary Sub'!E18 -> 467000 | G24: =+'Primary Sub'!F18 -> 366800 | H24: =+'Primary Sub'!G18 -> 371400 | I24: =+'Primary Sub'!H18 -> 472200 | J24: =+'Primary Sub'!I18 -> 495400 | K24: =+'Primary Sub'!J18 -> 550400 | ... O24: =+'Primary Sub'!N18 -> 578000 | P24: =IF(SUM(D24:O24)='Primary Sub'!O18,SUM(D24:O24),0) -> 5880600
A25: 9 | B25: PRIMARY SUB 4CP | C25: PRI | D25: =+'Primary Sub'!C19 -> 47509460 | E25: =+'Primary Sub'!D19 -> 42370760 | F25: =+'Primary Sub'!E19 -> 45245780 | G25: =+'Primary Sub'!F19 -> 48271520 | H25: =+'Primary Sub'!G19 -> 46462940 | I25: =+'Primary Sub'!H19 -> 39455100 | J25: =+'Primary Sub'!I19 -> 44769280 | K25: =+'Primary Sub'!J19 -> 41432480 | ... O25: =+'Primary Sub'!N19 -> 37295980 | P25: =IF(SUM(D25:O25)='Primary Sub'!O19,SUM(D25:O25),0) -> 499919380
A26: 10 | B26: TOTAL PRIMARY | D26: =SUM(D22:D25) -> 376118908 | E26: =SUM(E22:E25) -> 362657699 | F26: =SUM(F22:F25) -> 376245465 | G26: =SUM(G22:G25) -> 385862275 | H26: =SUM(H22:H25) -> 356331156 | I26: =SUM(I22:I25) -> 357229847 | J26: =SUM(J22:J25) -> 376375029 | K26: =SUM(K22:K25) -> 378741118 | ... P26: =SUM(P22:P25) -> 4597714830
A28: 11 | B28: TRANSMISSION | C28: TRA | D28: {=SUMPRODUCT((H_Rate_Class=$B28)*[5]Energy!D$9:D$118)} -> 748095972 | E28: {=SUMPRODUCT((H_Rate_Class=$B28)*[5]Energy!E$9:E$118)} -> 953393948 | F28: {=SUMPRODUCT((H_Rate_Class=$B28)*[5]Energy!F$9:F$118)} -> 832830028 | G28: {=SUMPRODUCT((H_Rate_Class=$B28)*[5]Energy!G$9:G$118)} -> 982961652 | H28: {=SUMPRODUCT((H_Rate_Class=$B28)*[5]Energy!H$9:H$118)} -> 900610195 | I28: {=SUMPRODUCT((H_Rate_Class=$B28)*[5]Energy!I$9:I$118)} -> 959433826 | J28: {=SUMPRODUCT((H_Rate_Class=$B28)*[5]Energy!J$9:J$118)} -> 908905693 | K28: {=SUMPRODUCT((H_Rate_Class=$B28)*[5]Energy!K$9:K$118)} -> 967240722 | ... O28: {=SUMPRODUCT((H_Rate_Class=$B28)*[5]Energy!O$9:O$118)} -> 976672890 | P28: =SUM(D28:O28) -> 11207029849
A30: 12 | B30: LIGHTING | C30: SEC | D30: {=SUMPRODUCT((H_Rate_Class=$B30)*[5]Energy!D$9:D$118)} -> 20205776 | E30: {=SUMPRODUCT((H_Rate_Class=$B30)*[5]Energy!E$9:E$118)} -> 20288043 | F30: {=SUMPRODUCT((H_Rate_Class=$B30)*[5]Energy!F$9:F$118)} -> 20121015 | G30: {=SUMPRODUCT((H_Rate_Class=$B30)*[5]Energy!G$9:G$118)} -> 20163075 | H30: {=SUMPRODUCT((H_Rate_Class=$B30)*[5]Energy!H$9:H$118)} -> 20042292 | I30: {=SUMPRODUCT((H_Rate_Class=$B30)*[5]Energy!I$9:I$118)} -> 20100508 | J30: {=SUMPRODUCT((H_Rate_Class=$B30)*[5]Energy!J$9:J$118)} -> 20075515 | K30: {=SUMPRODUCT((H_Rate_Class=$B30)*[5]Energy!K$9:K$118)} -> 20064594 | ... O30: {=SUMPRODUCT((H_Rate_Class=$B30)*[5]Energy!O$9:O$118)} -> 19927259 | P30: =SUM(D30:O30) -> 240936337 | Q30: ='II-H-4.1 Functions'!F31/'II-H-1.2'!P30 -> 0.089806652 | R30: ='II-H-4.1 Functions'!I31/'II-H-1.2'!P30 -> 0.0095956343
A32: 13 | B32: TOTAL RETAIL | D32: =D30+D28+D26+D20+D16+D14 -> 3021690888 | E32: =E30+E28+E26+E20+E16+E14 -> 2863123604 | F32: =F30+F28+F26+F20+F16+F14 -> 2896435008 | G32: =G30+G28+G26+G20+G16+G14 -> 3121358549 | H32: =H30+H28+H26+H20+H16+H14 -> 2826263699 | I32: =I30+I28+I26+I20+I16+I14 -> 2847798153 | J32: =J30+J28+J26+J20+J16+J14 -> 2826324346 | K32: =K30+K28+K26+K20+K16+K14 -> 2994963675 | ... P32: =P30+P28+P26+P20+P16+P14 -> 38785345726
A34: 14 | B34: WHOLESALE PRI | C34: PRI | D34: 0 | E34: 0 | F34: 0 | G34: 0 | H34: 0 | I34: 0 | J34: 0 | K34: 0 | L34: 0 | M34: 0 | N34: 0 | O34: 0 | P34: =SUM(D34:O34) -> 0
A35: 15 | B35: WHOLESALE TRANS | C35: TRA | P35: =SUM(D35:O35) -> 0
A36: 16 | B36: TOTAL WHOLESALE | D36: =SUM(D34:D35) -> 0 | E36: =SUM(E34:E35) -> 0 | F36: =SUM(F34:F35) -> 0 | G36: =SUM(G34:G35) -> 0 | H36: =SUM(H34:H35) -> 0 | I36: =SUM(I34:I35) -> 0 | J36: =SUM(J34:J35) -> 0 | K36: =SUM(K34:K35) -> 0 | ... P36: =SUM(P34:P35) -> 0
A38: 17 | B38: TOTAL AEP TEXAS | D38: =+D36+D32 -> 3021690888 | E38: =+E36+E32 -> 2863123604 | F38: =+F36+F32 -> 2896435008 | G38: =+G36+G32 -> 3121358549 | H38: =+H36+H32 -> 2826263699 | I38: =+I36+I32 -> 2847798153 | J38: =+J36+J32 -> 2826324346 | K38: =+K36+K32 -> 2994963675 | ... P38: =+P36+P32 -> 38785345726
B39: =+B7 -> AEP TEXAS
B40: WEATHER ADJUSTMENTS TO KWH AT METER
B41: =+G9 -> FOR TEST YEAR ENDED SEPTEMBER 30, 2023
A44: LINE | B44: DESCRIPTION | C44: VOLT | D44: =D12 -> Oct-22 | E44: =E12 -> Nov-22 | F44: =F12 -> Dec-22 | G44: =G12 -> Jan-23 | H44: =H12 -> Feb-23 | I44: =I12 -> Mar-23 | J44: =J12 -> Apr-23 | K44: =K12 -> May-23 | ... O44: =O12 -> Sep-23 | P44: =+P12 -> TOTAL
A46: 1 | B46: RESIDENTIAL SERVICE | C46: SEC | D46: {=SUMPRODUCT((H_Rate_Class=$B46)*[5]Energy!D$249:D$358)} -> 17189148 | E46: {=SUMPRODUCT((H_Rate_Class=$B46)*[5]Energy!E$249:E$358)} -> 15633310 | F46: {=SUMPRODUCT((H_Rate_Class=$B46)*[5]Energy!F$249:F$358)} -> -47947373 | G46: {=SUMPRODUCT((H_Rate_Class=$B46)*[5]Energy!G$249:G$358)} -> -27919851 | H46: {=SUMPRODUCT((H_Rate_Class=$B46)*[5]Energy!H$249:H$358)} -> 26733188 | I46: {=SUMPRODUCT((H_Rate_Class=$B46)*[5]Energy!I$249:I$358)} -> -14331354 | J46: {=SUMPRODUCT((H_Rate_Class=$B46)*[5]Energy!J$249:J$358)} -> -37905950 | K46: {=SUMPRODUCT((H_Rate_Class=$B46)*[5]Energy!K$249:K$358)} -> 39401720 | ... O46: {=SUMPRODUCT((H_Rate_Class=$B46)*[5]Energy!O$249:O$358)} -> -1.002524e+08 | P46: =SUM(D46:O46) -> -3.1306872e+08
A48: 2 | B48: SECONDARY < 10 kW | C48: SEC | D48: {=SUMPRODUCT((H_Rate_Class=$B48)*[5]Energy!D$249:D$358)} -> 394320.47 | E48: {=SUMPRODUCT((H_Rate_Class=$B48)*[5]Energy!E$249:E$358)} -> 557596.02 | F48: {=SUMPRODUCT((H_Rate_Class=$B48)*[5]Energy!F$249:F$358)} -> -465909.78 | G48: {=SUMPRODUCT((H_Rate_Class=$B48)*[5]Energy!G$249:G$358)} -> -207014.55 | H48: {=SUMPRODUCT((H_Rate_Class=$B48)*[5]Energy!H$249:H$358)} -> 30275.713 | I48: {=SUMPRODUCT((H_Rate_Class=$B48)*[5]Energy!I$249:I$358)} -> -1450271.7 | J48: {=SUMPRODUCT((H_Rate_Class=$B48)*[5]Energy!J$249:J$358)} -> -669167.44 | K48: {=SUMPRODUCT((H_Rate_Class=$B48)*[5]Energy!K$249:K$358)} -> 826854.58 | ... O48: {=SUMPRODUCT((H_Rate_Class=$B48)*[5]Energy!O$249:O$358)} -> -2815636.2 | P48: =SUM(D48:O48) -> -8767706.8
A50: 3 | B50: SECONDARY > 10 kW NCP | C50: SEC | D50: {=SUMPRODUCT((H_Rate_Class=$B50)*[5]Energy!D$249:D$358)} -> 5817363.6 | E50: {=SUMPRODUCT((H_Rate_Class=$B50)*[5]Energy!E$249:E$358)} -> 7553430.9 | F50: {=SUMPRODUCT((H_Rate_Class=$B50)*[5]Energy!F$249:F$358)} -> -5625246.1 | G50: {=SUMPRODUCT((H_Rate_Class=$B50)*[5]Energy!G$249:G$358)} -> -3726325.8 | H50: {=SUMPRODUCT((H_Rate_Class=$B50)*[5]Energy!H$249:H$358)} -> 104767.9 | I50: {=SUMPRODUCT((H_Rate_Class=$B50)*[5]Energy!I$249:I$358)} -> -21904165 | J50: {=SUMPRODUCT((H_Rate_Class=$B50)*[5]Energy!J$249:J$358)} -> -9875784.2 | K50: {=SUMPRODUCT((H_Rate_Class=$B50)*[5]Energy!K$249:K$358)} -> 12362465 | ... O50: {=SUMPRODUCT((H_Rate_Class=$B50)*[5]Energy!O$249:O$358)} -> -34765280 | P50: =SUM(D50:O50) -> -1.1227043e+08
A51: 4 | B51: SECONDARY > 10 kW 4CP | C51: SEC | D51: {=SUMPRODUCT((H_Rate_Class=$B51)*[5]Energy!D$249:D$358)} -> 966162.22 | E51: {=SUMPRODUCT((H_Rate_Class=$B51)*[5]Energy!E$249:E$358)} -> 1070592 | F51: {=SUMPRODUCT((H_Rate_Class=$B51)*[5]Energy!F$249:F$358)} -> -454323.46 | G51: {=SUMPRODUCT((H_Rate_Class=$B51)*[5]Energy!G$249:G$358)} -> -555951.68 | H51: {=SUMPRODUCT((H_Rate_Class=$B51)*[5]Energy!H$249:H$358)} -> 98748.563 | I51: {=SUMPRODUCT((H_Rate_Class=$B51)*[5]Energy!I$249:I$358)} -> -2960432.5 | J51: {=SUMPRODUCT((H_Rate_Class=$B51)*[5]Energy!J$249:J$358)} -> -1165612.6 | K51: {=SUMPRODUCT((H_Rate_Class=$B51)*[5]Energy!K$249:K$358)} -> 1886488.8 | ... O51: {=SUMPRODUCT((H_Rate_Class=$B51)*[5]Energy!O$249:O$358)} -> -2488630.1 | P51: =SUM(D51:O51) -> -8524699.1
A52: 5 | B52: TOTAL SECONDARY > 10 kW | D52: =SUM(D50:D51) -> 6783525.8 | E52: =SUM(E50:E51) -> 8624022.9 | F52: =SUM(F50:F51) -> -6079569.6 | G52: =SUM(G50:G51) -> -4282277.5 | H52: =SUM(H50:H51) -> 203516.46 | I52: =SUM(I50:I51) -> -24864598 | J52: =SUM(J50:J51) -> -11041397 | K52: =SUM(K50:K51) -> 14248954 | ... P52: =SUM(P50:P51) -> -1.2079513e+08
A54: 6 | B54: PRIMARY NCP | C54: PRI | D54: {=SUMPRODUCT((H_Rate_Class=$B54)*[5]Energy!D$249:D$358)} -> 31000.271 | E54: {=SUMPRODUCT((H_Rate_Class=$B54)*[5]Energy!E$249:E$358)} -> 46161.732 | F54: {=SUMPRODUCT((H_Rate_Class=$B54)*[5]Energy!F$249:F$358)} -> -119421.47 | G54: {=SUMPRODUCT((H_Rate_Class=$B54)*[5]Energy!G$249:G$358)} -> -134194.54 | H54: {=SUMPRODUCT((H_Rate_Class=$B54)*[5]Energy!H$249:H$358)} -> -54882.845 | I54: {=SUMPRODUCT((H_Rate_Class=$B54)*[5]Energy!I$249:I$358)} -> -515031.11 | J54: {=SUMPRODUCT((H_Rate_Class=$B54)*[5]Energy!J$249:J$358)} -> -275766.07 | K54: {=SUMPRODUCT((H_Rate_Class=$B54)*[5]Energy!K$249:K$358)} -> 284859.35 | ... O54: {=SUMPRODUCT((H_Rate_Class=$B54)*[5]Energy!O$249:O$358)} -> -417713.56 | P54: =SUM(D54:O54) -> -2124654.5
A55: 7 | B55: PRIMARY 4CP | C55: PRI | D55: {=SUMPRODUCT((H_Rate_Class=$B55)*[5]Energy!D$249:D$358)} -> 697003.47 | E55: {=SUMPRODUCT((H_Rate_Class=$B55)*[5]Energy!E$249:E$358)} -> 1138237.3 | F55: {=SUMPRODUCT((H_Rate_Class=$B55)*[5]Energy!F$249:F$358)} -> -1770534.2 | G55: {=SUMPRODUCT((H_Rate_Class=$B55)*[5]Energy!G$249:G$358)} -> -1775289.4 | H55: {=SUMPRODUCT((H_Rate_Class=$B55)*[5]Energy!H$249:H$358)} -> -332037.33 | I55: {=SUMPRODUCT((H_Rate_Class=$B55)*[5]Energy!I$249:I$358)} -> -5834055.5 | J55: {=SUMPRODUCT((H_Rate_Class=$B55)*[5]Energy!J$249:J$358)} -> -2861691.6 | K55: {=SUMPRODUCT((H_Rate_Class=$B55)*[5]Energy!K$249:K$358)} -> 2342914.4 | ... O55: {=SUMPRODUCT((H_Rate_Class=$B55)*[5]Energy!O$249:O$358)} -> -7127486.3 | P55: =SUM(D55:O55) -> -29574766
A56: 8 | B56: PRIMARY SUB NCP | C56: PRI | D56: {=SUMPRODUCT((H_Rate_Class=$B56)*[5]Energy!D$249:D$358)} -> 0 | E56: {=SUMPRODUCT((H_Rate_Class=$B56)*[5]Energy!E$249:E$358)} -> 0 | F56: {=SUMPRODUCT((H_Rate_Class=$B56)*[5]Energy!F$249:F$358)} -> 0 | G56: {=SUMPRODUCT((H_Rate_Class=$B56)*[5]Energy!G$249:G$358)} -> 0 | H56: {=SUMPRODUCT((H_Rate_Class=$B56)*[5]Energy!H$249:H$358)} -> 0 | I56: {=SUMPRODUCT((H_Rate_Class=$B56)*[5]Energy!I$249:I$358)} -> 0 | J56: {=SUMPRODUCT((H_Rate_Class=$B56)*[5]Energy!J$249:J$358)} -> 0 | K56: {=SUMPRODUCT((H_Rate_Class=$B56)*[5]Energy!K$249:K$358)} -> 0 | ... O56: {=SUMPRODUCT((H_Rate_Class=$B56)*[5]Energy!O$249:O$358)} -> 0 | P56: =SUM(D56:O56) -> 0
A57: 9 | B57: PRIMARY SUB 4CP | C57: PRI | D57: {=SUMPRODUCT((H_Rate_Class=$B57)*[5]Energy!D$249:D$358)} -> 0 | E57: {=SUMPRODUCT((H_Rate_Class=$B57)*[5]Energy!E$249:E$358)} -> 0 | F57: {=SUMPRODUCT((H_Rate_Class=$B57)*[5]Energy!F$249:F$358)} -> 0 | G57: {=SUMPRODUCT((H_Rate_Class=$B57)*[5]Energy!G$249:G$358)} -> 0 | H57: {=SUMPRODUCT((H_Rate_Class=$B57)*[5]Energy!H$249:H$358)} -> 0 | I57: {=SUMPRODUCT((H_Rate_Class=$B57)*[5]Energy!I$249:I$358)} -> 0 | J57: {=SUMPRODUCT((H_Rate_Class=$B57)*[5]Energy!J$249:J$358)} -> 0 | K57: {=SUMPRODUCT((H_Rate_Class=$B57)*[5]Energy!K$249:K$358)} -> 0 | ... O57: {=SUMPRODUCT((H_Rate_Class=$B57)*[5]Energy!O$249:O$358)} -> 0 | P57: =SUM(D57:O57) -> 0
...

Sheet II-H-1.3
B2: PUBLIC UTILITY COMMISSION OF TEXAS
B3: AEP TEXAS INC
B4: II-H-1.3 UNADJUSTED TEST YEAR KWH DATA
B5: ='II-H-1.2'!B5 -> TEST YEAR ENDING 9/30/2023
B6: =+'II-H-1'!B6 -> DOCKET 56165
A7: AEP TEXAS
A8: UNADJUSTED BILLING KWH
A9: FOR TEST YEAR ENDED SEPTEMBER 30, 2023
A12: LINE | B12: DESCRIPTION | C12: VOLT | D12: KWH @ Source | E12: Percentage | F12: KWH @ Meter | G12: Percentage
A14: 1 | B14: RESIDENTIAL SERVICE | C14: SEC | D14: =+'II-H-1.2'!P177 -> 1.3761948e+10 | E14: =+D14/$D$38 -> 0.33608277 | F14: ='II-H-1.2'!P14 -> 12797050643 | G14: =F14/$F$38 -> 0.32994551
A16: 2 | B16: SECONDARY < 10 kW | C16: SEC | D16: =+'II-H-1.2'!P179 -> 7.2993707e+08 | E16: =+D16/$D$38 -> 0.017825912 | F16: ='II-H-1.2'!P16 -> 678758664 | G16: =F16/$F$38 -> 0.01750039
A18: 3 | B18: SECONDARY > 10 kW NCP | C18: SEC | D18: =+'II-H-1.2'!P181 -> 8.55627e+09 | E18: =+D18/$D$38 -> 0.20895406 | F18: ='II-H-1.2'!P18 -> 7956360402 | G18: =F18/$F$38 -> 0.20513831
A19: 4 | B19: SECONDARY > 10 kW 4CP | C19: SEC | D19: =+'II-H-1.2'!P182 -> 1.4060801e+09 | E19: =+D19/$D$38 -> 0.034338111 | F19: ='II-H-1.2'!P19 -> 1307495001 | G19: =F19/$F$38 -> 0.033711057
A20: 5 | B20: TOTAL SECONDARY > 10 kW | D20: =SUM(D18:D19) -> 9.9623501e+09 | E20: =SUM(E18:E19) -> 0.24329217 | F20: ='II-H-1.2'!P20 -> 9263855403 | G20: =F20/$F$38 -> 0.23884937
A22: 6 | B22: PRIMARY NCP | C22: PRI | D22: =+'II-H-1.2'!P185 -> 2.7556991e+08 | E22: =+D22/$D$38 -> 0.0067297376 | F22: ='II-H-1.2'!P22 -> 263796669 | G22: =F22/$F$38 -> 0.006801452
A23: 7 | B23: PRIMARY 4CP | C23: PRI | D23: =+'II-H-1.2'!P186 -> 3.9989671e+09 | E23: =+D23/$D$38 -> 0.097659424 | F23: ='II-H-1.2'!P23 -> 3828118181 | G23: =F23/$F$38 -> 0.098700118
A24: 8 | B24: PRIMARY SUB NCP | C24: PRI | D24: =+'II-H-1.2'!P187 -> 6143051.2 | E24: =+D24/$D$38 -> 0.00015002045 | F24: ='II-H-1.2'!P24 -> 5880600 | G24: =F24/$F$38 -> 0.00015161912
A25: 9 | B25: PRIMARY SUB 4CP | C25: PRI | D25: =+'II-H-1.2'!P188 -> 5.2223078e+08 | E25: =+D25/$D$38 -> 0.012753483 | F25: ='II-H-1.2'!P25 -> 499919380 | G25: =F25/$F$38 -> 0.012889388
A26: 10 | B26: TOTAL PRIMARY | D26: =SUM(D22:D25) -> 4.8029108e+09 | E26: =SUM(E22:E23) -> 0.10438916 | F26: =SUM(F22:F25) -> 4597714830 | G26: =F26/$F$38 -> 0.11854258
A28: 11 | B28: TRANSMISSION | C28: TRA | D28: =+'II-H-1.2'!P191 -> 1.1431843e+10 | E28: =+D28/$D$38 -> 0.27917889 | F28: ='II-H-1.2'!P28 -> 11207029849 | G28: =F28/$F$38 -> 0.28895011
A30: 12 | B30: LIGHTING | C30: SEC | D30: =+'II-H-1.2'!P193 -> 2.5910294e+08 | E30: =+D30/$D$38 -> 0.0063275949 | F30: ='II-H-1.2'!P30 -> 240936337 | G30: =F30/$F$38 -> 0.0062120456
A32: 13 | B32: TOTAL RETAIL | D32: =+D14+D16+D20+D26+D28+D30 -> 4.0948092e+10 | E32: =+E14+E16+E20+E26+E28+E30 -> 0.9870965 | F32: =+F14+F16+F20+F26+F28+F30 -> 38785345726 | G32: =F32/$F$38 -> 1
A34: 14 | B34: WHOLESALE PRI | C34: PRI | D34: 0 | F34: ='II-H-1.2'!P34 -> 0 | G34: =F34/$F$38 -> 0
A35: 15 | B35: WHOLESALE TRANS | C35: TRA | D35: 0 | F35: ='II-H-1.2'!P35 -> 0 | G35: =F35/$F$38 -> 0
A36: 16 | B36: TOTAL WHOLESALE | D36: =SUM(D34:D35) -> 0 | F36: ='II-H-1.2'!P36 -> 0 | G36: =F36/$F$38 -> 0
A38: 17 | B38: TOTAL AEP TEXAS | D38: =+D32+D36 -> 4.0948092e+10 | E38: =+E32+E36 -> 0.9870965 | F38: =+F32+F36 -> 38785345726 | G38: =+G32+G36 -> 1

Sheet Sch II-H-1.5
B2: PUBLIC UTILITY COMMISSION OF TEXAS
B3: AEP TEXAS INC
B4: II-H-1.5 ADJUSTMENTS TO OPERATING STATISTICS
B5: ='II-H-1'!B5 -> TEST YEAR ENDING 9/30/2023
B6: =+'II-H-1'!B6 -> DOCKET 56165
A9: Line | B9: Description
A10: 1 | B10: This schedule provides a narrative explanation of all adjustments made to Test Year operating
B11: statistics provided in RFP Schedule II-H-1.
A13: 2 | B13: Residential Service: adjustment made for weather normalized kWh sales; annualize to
B14: year-end customer count and associated kWh sales.
A16: 3 | B16: Secondary ≤ 10 kW Service: adjustment made for weather normalized kWh sales; annualize to
B17: year-end customer count and associated kWh sales.
A19: 4 | B19: Secondary ≥10 kW Service: adjustment made for weather normalized kWh sales; annualize to
B20: year-end customer count and associated kWh sales.
A22: 5 | B22: Primary Service: Segmented into primary line and primary substation; adjustment made for weather normalized kWh sales; annualize to year-end
B23: customer count and associated kWh sales.
A25: 6 | B25: Transmission Service: annualize to year-end customer count and associated kWh sales.
A27: 7 | B27: Lighting Service: annualize to year-end customer count and associated kWh sales.

Sheet II-H-3.1-3
B2: PUBLIC UTILITY COMMISSION OF TEXAS
B3: AEP TEXAS INC
B4: II-H-3.1-3 CUSTOMER ADJUSTMENTS
B5: ='II-H-1'!B5 -> TEST YEAR ENDING 9/30/2023
B6: =+'II-H-1'!B6 -> DOCKET 56165
B7: ='II-H-1.2'!B7:O7 -> AEP TEXAS
B8: BOOKED CUSTOMER COUNT
B9: ='II-H-1.1'!D10 -> FOR TEST YEAR ENDED SEPTEMBER 30, 2023
A12: LINE | B12: DESCRIPTION | C12: VOLT | D12: ='II-H-1.2'!D12 -> Oct-22 | E12: ='II-H-1.2'!E12 -> Nov-22 | F12: ='II-H-1.2'!F12 -> Dec-22 | G12: ='II-H-1.2'!G12 -> Jan-23 | H12: ='II-H-1.2'!H12 -> Feb-23 | I12: ='II-H-1.2'!I12 -> Mar-23 | J12: ='II-H-1.2'!J12 -> Apr-23 | K12: ='II-H-1.2'!K12 -> May-23 | ... O12: ='II-H-1.2'!O12 -> Sep-23 | P12: TOTAL | Q12: AVERAGE
R13: cust | S13: meter | T13: Dist
A14: 1 | B14: RESIDENTIAL SERVICE | C14: SEC | D14: {=SUMPRODUCT((H_Rate_Class=$B14)*[5]Customer!D$9:D$118)} -> 917398 | E14: {=SUMPRODUCT((H_Rate_Class=$B14)*[5]Customer!E$9:E$118)} -> 918668 | F14: {=SUMPRODUCT((H_Rate_Class=$B14)*[5]Customer!F$9:F$118)} -> 919604 | G14: {=SUMPRODUCT((H_Rate_Class=$B14)*[5]Customer!G$9:G$118)} -> 920684 | H14: {=SUMPRODUCT((H_Rate_Class=$B14)*[5]Customer!H$9:H$118)} -> 921997 | I14: {=SUMPRODUCT((H_Rate_Class=$B14)*[5]Customer!I$9:I$118)} -> 923215 | J14: {=SUMPRODUCT((H_Rate_Class=$B14)*[5]Customer!J$9:J$118)} -> 925269 | K14: {=SUMPRODUCT((H_Rate_Class=$B14)*[5]Customer!K$9:K$118)} -> 929499 | ... O14: {=SUMPRODUCT((H_Rate_Class=$B14)*[5]Customer!O$9:O$118)} -> 935238 | P14: =SUM(D14:O14) -> 11114371 | Q14: =P14/12 -> 926197.58 | R14: =+'II-H-4.1 Functions'!D15/'II-H-3.1-3'!P14 -> 1.3996686 | S14: =+'II-H-4.1 Functions'!E15/'II-H-3.1-3'!P14 -> 3.3891976 | T14: 0.021791
A16: 2 | B16: SECONDARY < 10 kW | C16: SEC | D16: {=SUMPRODUCT((H_Rate_Class=$B16)*[5]Customer!D$9:D$118)} -> 99093 | E16: {=SUMPRODUCT((H_Rate_Class=$B16)*[5]Customer!E$9:E$118)} -> 99298 | F16: {=SUMPRODUCT((H_Rate_Class=$B16)*[5]Customer!F$9:F$118)} -> 99126 | G16: {=SUMPRODUCT((H_Rate_Class=$B16)*[5]Customer!G$9:G$118)} -> 98051 | H16: {=SUMPRODUCT((H_Rate_Class=$B16)*[5]Customer!H$9:H$118)} -> 97626 | I16: {=SUMPRODUCT((H_Rate_Class=$B16)*[5]Customer!I$9:I$118)} -> 97730 | J16: {=SUMPRODUCT((H_Rate_Class=$B16)*[5]Customer!J$9:J$118)} -> 98315 | K16: {=SUMPRODUCT((H_Rate_Class=$B16)*[5]Customer!K$9:K$118)} -> 99018 | ... O16: {=SUMPRODUCT((H_Rate_Class=$B16)*[5]Customer!O$9:O$118)} -> 99366 | P16: =SUM(D16:O16) -> 1185554 | Q16: =P16/12 -> 98796.167 | R16: 1.4 | S16: 4.39 | T16: 0.021093
A18: 3 | B18: SECONDARY > 10 kW NCP | C18: SEC | D18: {=SUMPRODUCT((H_Rate_Class=$B18)*[5]Customer!D$9:D$118)} -> 70606 | E18: {=SUMPRODUCT((H_Rate_Class=$B18)*[5]Customer!E$9:E$118)} -> 70437 | F18: {=SUMPRODUCT((H_Rate_Class=$B18)*[5]Customer!F$9:F$118)} -> 70560 | G18: {=SUMPRODUCT((H_Rate_Class=$B18)*[5]Customer!G$9:G$118)} -> 71618 | H18: {=SUMPRODUCT((H_Rate_Class=$B18)*[5]Customer!H$9:H$118)} -> 72104 | I18: {=SUMPRODUCT((H_Rate_Class=$B18)*[5]Customer!I$9:I$118)} -> 72136 | J18: {=SUMPRODUCT((H_Rate_Class=$B18)*[5]Customer!J$9:J$118)} -> 71584 | K18: {=SUMPRODUCT((H_Rate_Class=$B18)*[5]Customer!K$9:K$118)} -> 71627 | ... O18: {=SUMPRODUCT((H_Rate_Class=$B18)*[5]Customer!O$9:O$118)} -> 71833 | P18: =SUM(D18:O18) -> 857957 | Q18: =P18/12 -> 71496.417 | R18: =+'II-H-4.1 Functions'!D19/'II-H-3.1-3'!P18 -> 2.0102705 | S18: 12.67 | T18: 4.869
A19: 4 | B19: SECONDARY > 10 kW 4CP | C19: SEC | D19: {=SUMPRODUCT((H_Rate_Class=$B19)*[5]Customer!D$9:D$118)} -> 556 | E19: {=SUMPRODUCT((H_Rate_Class=$B19)*[5]Customer!E$9:E$118)} -> 564 | F19: {=SUMPRODUCT((H_Rate_Class=$B19)*[5]Customer!F$9:F$118)} -> 565 | G19: {=SUMPRODUCT((H_Rate_Class=$B19)*[5]Customer!G$9:G$118)} -> 564 | H19: {=SUMPRODUCT((H_Rate_Class=$B19)*[5]Customer!H$9:H$118)} -> 568 | I19: {=SUMPRODUCT((H_Rate_Class=$B19)*[5]Customer!I$9:I$118)} -> 571 | J19: {=SUMPRODUCT((H_Rate_Class=$B19)*[5]Customer!J$9:J$118)} -> 571 | K19: {=SUMPRODUCT((H_Rate_Class=$B19)*[5]Customer!K$9:K$118)} -> 574 | ... O19: {=SUMPRODUCT((H_Rate_Class=$B19)*[5]Customer!O$9:O$118)} -> 576 | P19: =SUM(D19:O19) -> 6848 | Q19: =P19/12 -> 570.66667 | R19: 2.02 | S19: 12.67 | T19: 4.869
A20: 5 | B20: TOTAL SECONDARY > 10 kW | D20: =SUM(D18:D19) -> 71162 | E20: =SUM(E18:E19) -> 71001 | F20: =SUM(F18:F19) -> 71125 | G20: =SUM(G18:G19) -> 72182 | H20: =SUM(H18:H19) -> 72672 | I20: =SUM(I18:I19) -> 72707 | J20: =SUM(J18:J19) -> 72155 | K20: =SUM(K18:K19) -> 72201 | ... O20: =SUM(O18:O19) -> 72409 | P20: =SUM(D20:O20) -> 864805 | Q20: =P20/12 -> 72067.083
A22: 6 | B22: PRIMARY NCP | C22: PRI | D22: {=SUMPRODUCT((H_Rate_Class=$B22)*[5]Customer!D$9:D$118)-D24} -> 550 | E22: {=SUMPRODUCT((H_Rate_Class=$B22)*[5]Customer!E$9:E$118)-E24} -> 550 | F22: {=SUMPRODUCT((H_Rate_Class=$B22)*[5]Customer!F$9:F$118)-F24} -> 550 | G22: {=SUMPRODUCT((H_Rate_Class=$B22)*[5]Customer!G$9:G$118)-G24} -> 550 | H22: {=SUMPRODUCT((H_Rate_Class=$B22)*[5]Customer!H$9:H$118)-H24} -> 549 | I22: {=SUMPRODUCT((H_Rate_Class=$B22)*[5]Customer!I$9:I$118)-I24} -> 548 | J22: {=SUMPRODUCT((H_Rate_Class=$B22)*[5]Customer!J$9:J$118)-J24} -> 550 | K22: {=SUMPRODUCT((H_Rate_Class=$B22)*[5]Customer!K$9:K$118)-K24} -> 552 | ... O22: {=SUMPRODUCT((H_Rate_Class=$B22)*[5]Customer!O$9:O$118)-O24} -> 550 | P22: =SUM(D22:O22) -> 6604 | Q22: =P22/12 -> 550.33333 | R22: =+'II-H-4.1 Functions'!D23/'II-H-3.1-3'!P22 -> 7.2940636 | S22: 126.87 | T22: 3.112
A23: 7 | B23: PRIMARY 4CP | C23: PRI | D23: {=SUMPRODUCT((H_Rate_Class=$B23)*[5]Customer!D$9:D$118)-D25} -> 459 | E23: {=SUMPRODUCT((H_Rate_Class=$B23)*[5]Customer!E$9:E$118)-E25} -> 472 | F23: {=SUMPRODUCT((H_Rate_Class=$B23)*[5]Customer!F$9:F$118)-F25} -> 477 | G23: {=SUMPRODUCT((H_Rate_Class=$B23)*[5]Customer!G$9:G$118)-G25} -> 473 | H23: {=SUMPRODUCT((H_Rate_Class=$B23)*[5]Customer!H$9:H$118)-H25} -> 481 | I23: {=SUMPRODUCT((H_Rate_Class=$B23)*[5]Customer!I$9:I$118)-I25} -> 475 | J23: {=SUMPRODUCT((H_Rate_Class=$B23)*[5]Customer!J$9:J$118)-J25} -> 471 | K23: {=SUMPRODUCT((H_Rate_Class=$B23)*[5]Customer!K$9:K$118)-K25} -> 485 | ... O23: {=SUMPRODUCT((H_Rate_Class=$B23)*[5]Customer!O$9:O$118)-O25} -> 469 | P23: =SUM(D23:O23) -> 5701 | Q23: =P23/12 -> 475.08333 | R23: =+'II-H-4.1 Functions'!D24/'II-H-3.1-3'!P23 -> 7.341047 | S23: 126.87 | T23: 3.112
A24: 8 | B24: PRIMARY SUB NCP | C24: PRI | D24: 9 | E24: 9 | F24: 9 | G24: 9 | H24: 9 | I24: 9 | J24: 9 | K24: 9 | L24: 9 | M24: 9 | N24: 9 | O24: 9 | P24: =SUM(D24:O24) -> 108 | Q24: =P24/12 -> 9 | R24: =+'II-H-4.1 Functions'!D25/'II-H-3.1-3'!P24 -> 7.3373322 | S24: 126.87 | T24: 3.112
A25: 9 | B25: PRIMARY SUB 4CP | C25: PRI | D25: 58 | E25: 58 | F25: 58 | G25: 58 | H25: 58 | I25: 58 | J25: 58 | K25: 58 | L25: 58 | M25: 58 | N25: 58 | O25: 58 | P25: =SUM(D25:O25) -> 696 | Q25: =P25/12 -> 58 | R25: 735 | S25: 126.87 | T25: 3.112
A26: 10 | B26: TOTAL PRIMARY | D26: =SUM(D22:D25) -> 1076 | E26: =SUM(E22:E25) -> 1089 | F26: =SUM(F22:F25) -> 1094 | G26: =SUM(G22:G25) -> 1090 | H26: =SUM(H22:H25) -> 1097 | I26: =SUM(I22:I25) -> 1090 | J26: =SUM(J22:J25) -> 1088 | K26: =SUM(K22:K25) -> 1104 | ... P26: =SUM(P22:P25) -> 13109 | Q26: =P26/12 -> 1092.4167
A28: 11 | B28: TRANSMISSION | C28: TRA | D28: {=SUMPRODUCT((H_Rate_Class=$B28)*[5]Customer!D$9:D$118)} -> 124 | E28: {=SUMPRODUCT((H_Rate_Class=$B28)*[5]Customer!E$9:E$118)} -> 121 | F28: {=SUMPRODUCT((H_Rate_Class=$B28)*[5]Customer!F$9:F$118)} -> 119 | G28: {=SUMPRODUCT((H_Rate_Class=$B28)*[5]Customer!G$9:G$118)} -> 122 | H28: {=SUMPRODUCT((H_Rate_Class=$B28)*[5]Customer!H$9:H$118)} -> 122 | I28: {=SUMPRODUCT((H_Rate_Class=$B28)*[5]Customer!I$9:I$118)} -> 124 | J28: {=SUMPRODUCT((H_Rate_Class=$B28)*[5]Customer!J$9:J$118)} -> 122 | K28: {=SUMPRODUCT((H_Rate_Class=$B28)*[5]Customer!K$9:K$118)} -> 127 | ... O28: {=SUMPRODUCT((H_Rate_Class=$B28)*[5]Customer!O$9:O$118)} -> 123 | P28: =SUM(D28:O28) -> 1490 | Q28: =P28/12 -> 124.16667 | R28: 7.48 | S28: 761.5 | T28: 0.249
A30: 12 | B30: LIGHTING | C30: SEC | D30: {=SUMPRODUCT((H_Rate_Class=$B30)*[5]Customer!D$9:D$118)} -> 221814 | E30: {=SUMPRODUCT((H_Rate_Class=$B30)*[5]Customer!E$9:E$118)} -> 222695 | F30: {=SUMPRODUCT((H_Rate_Class=$B30)*[5]Customer!F$9:F$118)} -> 221811 | G30: {=SUMPRODUCT((H_Rate_Class=$B30)*[5]Customer!G$9:G$118)} -> 220960 | H30: {=SUMPRODUCT((H_Rate_Class=$B30)*[5]Customer!H$9:H$118)} -> 223166 | I30: {=SUMPRODUCT((H_Rate_Class=$B30)*[5]Customer!I$9:I$118)} -> 220819 | J30: {=SUMPRODUCT((H_Rate_Class=$B30)*[5]Customer!J$9:J$118)} -> 221724 | K30: {=SUMPRODUCT((H_Rate_Class=$B30)*[5]Customer!K$9:K$118)} -> 222243 | ... O30: {=SUMPRODUCT((H_Rate_Class=$B30)*[5]Customer!O$9:O$118)} -> 221390 | P30: =SUM(D30:O30) -> 2662951 | Q30: =P30/12 -> 221912.58 | T30: 0.021093
A32: 13 | B32: TOTAL RETAIL | D32: =D30+D28+D26+D20+D16+D14 -> 1310667 | E32: =E30+E28+E26+E20+E16+E14 -> 1312872 | F32: =F30+F28+F26+F20+F16+F14 -> 1312879 | G32: =G30+G28+G26+G20+G16+G14 -> 1313089 | H32: =H30+H28+H26+H20+H16+H14 -> 1316680 | I32: =I30+I28+I26+I20+I16+I14 -> 1315685 | J32: =J30+J28+J26+J20+J16+J14 -> 1318673 | K32: =K30+K28+K26+K20+K16+K14 -> 1324192 | ... O32: =O30+O28+O26+O20+O16+O14 -> 1329612 | P32: =SUM(D32:O32) -> 15842280 | Q32: =P32/12 -> 1320190
A34: 14 | B34: WHOLESALE PRI | C34: PRI
A35: 15 | B35: WHOLESALE TRANS | C35: TRA
A36: 16 | B36: TOTAL WHOLESALE
A38: 17 | B38: TOTAL AEP TEXAS | D38: =D36+D32 -> 1310667 | E38: =+E36+E32 -> 1312872 | F38: =+F36+F32 -> 1312879 | G38: =+G36+G32 -> 1313089 | H38: =+H36+H32 -> 1316680 | I38: =+I36+I32 -> 1315685 | J38: =+J36+J32 -> 1318673 | K38: =+K36+K32 -> 1324192 | L38: =+L36+L32 -> 1326629 | ... O38: =+O36+O32 -> 1329612 | P38: =SUM(D38:O38) -> 15842280 | Q38: =+Q36+Q32 -> 1320190
B39: Note: Secondary < 10 kW includes Unmetered service; Lighting customers are fixture counts.
B41: =+B7 -> AEP TEXAS
B42: CUSTOMER COUNT ADJUSTMENT
B43: =B9 -> FOR TEST YEAR ENDED SEPTEMBER 30, 2023
D45: =D11 -> 0 | G45: =G11 -> 0
A46: LINE | B46: DESCRIPTION | C46: VOLT | D46: =+D12 -> Oct-22 | E46: =+E12 -> Nov-22 | F46: =+F12 -> Dec-22 | G46: =+G12 -> Jan-23 | H46: =+H12 -> Feb-23 | I46: =+I12 -> Mar-23 | J46: =+J12 -> Apr-23 | K46: =+K12 -> May-23 | ... O46: =+O12 -> Sep-23 | P46: TOTAL | Q46: AVERAGE
A48: =A14 -> 1 | B48: =B14 -> RESIDENTIAL SERVICE | C48: =C14 -> SEC | D48: {=SUMPRODUCT((H_Rate_Class=$B48)*[5]Customer!D$129:D$238)} -> 17840 | E48: {=SUMPRODUCT((H_Rate_Class=$B48)*[5]Customer!E$129:E$238)} -> 16570 | F48: {=SUMPRODUCT((H_Rate_Class=$B48)*[5]Customer!F$129:F$238)} -> 15634 | G48: {=SUMPRODUCT((H_Rate_Class=$B48)*[5]Customer!G$129:G$238)} -> 14554 | H48: {=SUMPRODUCT((H_Rate_Class=$B48)*[5]Customer!H$129:H$238)} -> 13241 | I48: {=SUMPRODUCT((H_Rate_Class=$B48)*[5]Customer!I$129:I$238)} -> 12023 | J48: {=SUMPRODUCT((H_Rate_Class=$B48)*[5]Customer!J$129:J$238)} -> 9969 | K48: {=SUMPRODUCT((H_Rate_Class=$B48)*[5]Customer!K$129:K$238)} -> 5739 | ... O48: {=SUMPRODUCT((H_Rate_Class=$B48)*[5]Customer!O$129:O$238)} -> 0 | P48: =SUM(D48:O48) -> 108485 | Q48: =P48/12 -> 9040.4167
A50: =A16 -> 2 | B50: =B16 -> SECONDARY < 10 kW | C50: =C16 -> SEC | D50: {=SUMPRODUCT((H_Rate_Class=$B50)*[5]Customer!D$129:D$238)} -> 273 | E50: {=SUMPRODUCT((H_Rate_Class=$B50)*[5]Customer!E$129:E$238)} -> 68 | F50: {=SUMPRODUCT((H_Rate_Class=$B50)*[5]Customer!F$129:F$238)} -> 240 | G50: {=SUMPRODUCT((H_Rate_Class=$B50)*[5]Customer!G$129:G$238)} -> 1315 | H50: {=SUMPRODUCT((H_Rate_Class=$B50)*[5]Customer!H$129:H$238)} -> 1740 | I50: {=SUMPRODUCT((H_Rate_Class=$B50)*[5]Customer!I$129:I$238)} -> 1636 | J50: {=SUMPRODUCT((H_Rate_Class=$B50)*[5]Customer!J$129:J$238)} -> 1051 | K50: {=SUMPRODUCT((H_Rate_Class=$B50)*[5]Customer!K$129:K$238)} -> 348 | ... O50: {=SUMPRODUCT((H_Rate_Class=$B50)*[5]Customer!O$129:O$238)} -> 0 | P50: =SUM(D50:O50) -> 6838 | Q50: =P50/12 -> 569.83333
A52: =A18 -> 3 | B52: =B18 -> SECONDARY > 10 kW NCP | C52: =C18 -> SEC | D52: {=SUMPRODUCT((H_Rate_Class=$B52)*[5]Customer!D$129:D$238)} -> 1227 | E52: {=SUMPRODUCT((H_Rate_Class=$B52)*[5]Customer!E$129:E$238)} -> 1396 | F52: {=SUMPRODUCT((H_Rate_Class=$B52)*[5]Customer!F$129:F$238)} -> 1273 | G52: {=SUMPRODUCT((H_Rate_Class=$B52)*[5]Customer!G$129:G$238)} -> 215 | H52: {=SUMPRODUCT((H_Rate_Class=$B52)*[5]Customer!H$129:H$238)} -> -271 | I52: {=SUMPRODUCT((H_Rate_Class=$B52)*[5]Customer!I$129:I$238)} -> -303 | J52: {=SUMPRODUCT((H_Rate_Class=$B52)*[5]Customer!J$129:J$238)} -> 249 | K52: {=SUMPRODUCT((H_Rate_Class=$B52)*[5]Customer!K$129:K$238)} -> 206 | ... O52: {=SUMPRODUCT((H_Rate_Class=$B52)*[5]Customer!O$129:O$238)} -> 0 | P52: =SUM(D52:O52) -> 4039 | Q52: =P52/12 -> 336.58333
A53: =A19 -> 4 | B53: =B19 -> SECONDARY > 10 kW 4CP | C53: =C19 -> SEC | D53: {=SUMPRODUCT((H_Rate_Class=$B53)*[5]Customer!D$129:D$238)} -> 20 | E53: {=SUMPRODUCT((H_Rate_Class=$B53)*[5]Customer!E$129:E$238)} -> 12 | F53: {=SUMPRODUCT((H_Rate_Class=$B53)*[5]Customer!F$129:F$238)} -> 11 | G53: {=SUMPRODUCT((H_Rate_Class=$B53)*[5]Customer!G$129:G$238)} -> 12 | H53: {=SUMPRODUCT((H_Rate_Class=$B53)*[5]Customer!H$129:H$238)} -> 8 | I53: {=SUMPRODUCT((H_Rate_Class=$B53)*[5]Customer!I$129:I$238)} -> 5 | J53: {=SUMPRODUCT((H_Rate_Class=$B53)*[5]Customer!J$129:J$238)} -> 5 | K53: {=SUMPRODUCT((H_Rate_Class=$B53)*[5]Customer!K$129:K$238)} -> 2 | ... O53: {=SUMPRODUCT((H_Rate_Class=$B53)*[5]Customer!O$129:O$238)} -> 0 | P53: =SUM(D53:O53) -> 64 | Q53: =P53/12 -> 5.3333333
A54: =A20 -> 5 | B54: =B20 -> TOTAL SECONDARY > 10 kW | D54: =SUM(D52:D53) -> 1247 | E54: =SUM(E52:E53) -> 1408 | F54: =SUM(F52:F53) -> 1284 | G54: =SUM(G52:G53) -> 227 | H54: =SUM(H52:H53) -> -263 | I54: =SUM(I52:I53) -> -298 | J54: =SUM(J52:J53) -> 254 | K54: =SUM(K52:K53) -> 208 | ... O54: =SUM(O52:O53) -> 0 | P54: =SUM(D54:O54) -> 4103 | Q54: =SUM(Q52:Q53) -> 341.91667
A56: =A22 -> 6 | B56: =B22 -> PRIMARY NCP | C56: =C22 -> PRI | D56: {=SUMPRODUCT((H_Rate_Class=$B56)*[5]Customer!D$129:D$238)} -> -3.0642155e-14 | E56: {=SUMPRODUCT((H_Rate_Class=$B56)*[5]Customer!E$129:E$238)} -> -3.0642155e-14 | F56: {=SUMPRODUCT((H_Rate_Class=$B56)*[5]Customer!F$129:F$238)} -> -3.0642155e-14 | G56: {=SUMPRODUCT((H_Rate_Class=$B56)*[5]Customer!G$129:G$238)} -> -3.0642155e-14 | H56: {=SUMPRODUCT((H_Rate_Class=$B56)*[5]Customer!H$129:H$238)} -> 1 | I56: {=SUMPRODUCT((H_Rate_Class=$B56)*[5]Customer!I$129:I$238)} -> 2 | J56: {=SUMPRODUCT((H_Rate_Class=$B56)*[5]Customer!J$129:J$238)} -> 0 | K56: {=SUMPRODUCT((H_Rate_Class=$B56)*[5]Customer!K$129:K$238)} -> -2 | ... O56: {=SUMPRODUCT((H_Rate_Class=$B56)*[5]Customer!O$129:O$238)} -> 0 | P56: =SUM(D56:O56) -> -4 | Q56: =P56/12 -> -0.33333333
A57: =A23 -> 7 | B57: =B23 -> PRIMARY 4CP | C57: =C23 -> PRI | D57: {=SUMPRODUCT((H_Rate_Class=$B57)*[5]Customer!D$129:D$238)} -> 10 | E57: {=SUMPRODUCT((H_Rate_Class=$B57)*[5]Customer!E$129:E$238)} -> -3 | F57: {=SUMPRODUCT((H_Rate_Class=$B57)*[5]Customer!F$129:F$238)} -> -8 | G57: {=SUMPRODUCT((H_Rate_Class=$B57)*[5]Customer!G$129:G$238)} -> -4 | H57: {=SUMPRODUCT((H_Rate_Class=$B57)*[5]Customer!H$129:H$238)} -> -12 | I57: {=SUMPRODUCT((H_Rate_Class=$B57)*[5]Customer!I$129:I$238)} -> -6 | J57: {=SUMPRODUCT((H_Rate_Class=$B57)*[5]Customer!J$129:J$238)} -> -2 | K57: {=SUMPRODUCT((H_Rate_Class=$B57)*[5]Customer!K$129:K$238)} -> -16 | ... O57: {=SUMPRODUCT((H_Rate_Class=$B57)*[5]Customer!O$129:O$238)} -> 0 | P57: =SUM(D57:O57) -> -73 | Q57: =P57/12 -> -6.0833333
...

Sheet II-H-4.1 Monthly
B2: PUBLIC UTILITY COMMISSION OF TEXAS
B3: AEP TEXAS INC
B4: II-H-4.1 REVENUE IMPACTS MONTHLY
B5: ='II-H-3.1-3'!B5 -> TEST YEAR ENDING 9/30/2023
B6: =+'II-H-1'!B6 -> DOCKET 56165
B8: AEP TEXAS
B9: UNADJUSTED BILLED REVENUE
B10: FOR TEST YEAR ENDED SEPTEMBER 30, 2023
D11: 5 | E11: 6 | F11: 7 | G11: 8 | H11: 9 | I11: 10 | J11: 11 | K11: 12 | L11: 13 | M11: 14 | N11: 15 | O11: 16
A13: LINE | B13: DESCRIPTION | C13: VOLT | D13: ='II-H-3.1-3'!D12 -> Oct-22 | E13: ='II-H-3.1-3'!E12 -> Nov-22 | F13: ='II-H-3.1-3'!F12 -> Dec-22 | G13: ='II-H-3.1-3'!G12 -> Jan-23 | H13: ='II-H-3.1-3'!H12 -> Feb-23 | I13: ='II-H-3.1-3'!I12 -> Mar-23 | J13: ='II-H-3.1-3'!J12 -> Apr-23 | K13: ='II-H-3.1-3'!K12 -> May-23 | ... O13: ='II-H-3.1-3'!O12 -> Sep-23 | P13: TOTAL
A15: 1 | B15: RESIDENTIAL SERVICE | C15: SEC | D15: 56425580 | E15: 44601434 | F15: 51081571 | G15: 54442758 | H15: 48394601 | I15: 38431846 | J15: 37998133 | K15: 41079166 | L15: 53959354 | M15: 69030332 | N15: 69605383 | O15: 83420626 | P15: =SUM(D15:O15) -> 6.4847078e+08
A17: 2 | B17: SECONDARY < 10 kW | C17: SEC | D17: 3290499.5 | E17: 2982371.1 | F17: 3115337.3 | G17: 3134083.5 | H17: 2908578.4 | I17: 2852572.8 | J17: 2848318.7 | K17: 2967369.7 | L17: 3325482 | M17: 3775007.9 | N17: 3875852.2 | O17: 4332345.5 | P17: =SUM(D17:O17) -> 39407819
A19: 3 | B19: SECONDARY > 10 kW NCP | C19: SEC | D19: 27415277 | E19: 26622320 | F19: 27540490 | G19: 27940911 | H19: 27840854 | I19: 26036947 | J19: 25481203 | K19: 25209442 | L19: 26480058 | M19: 28017106 | N19: 28378038 | O19: 30857212 | P19: =SUM(D19:O19) -> 3.2781986e+08
A20: 4 | B20: SECONDARY > 10 kW 4CP | C20: SEC | D20: 3439438.2 | E20: 3354056.8 | F20: 3326930.7 | G20: 3194064.7 | H20: 3113972.2 | I20: 3034245.7 | J20: 3060922.5 | K20: 3062978.1 | L20: 3211856 | M20: 3329063.6 | N20: 3481281 | O20: 3791890.9 | P20: =SUM(D20:O20) -> 39400700
A21: 5 | B21: TOTAL SECONDARY > 10 kW | D21: =SUM(D19:D20) -> 30854715 | E21: =SUM(E19:E20) -> 29976377 | F21: =SUM(F19:F20) -> 30867420 | G21: =SUM(G19:G20) -> 31134976 | H21: =SUM(H19:H20) -> 30954826 | I21: =SUM(I19:I20) -> 29071192 | J21: =SUM(J19:J20) -> 28542125 | K21: =SUM(K19:K20) -> 28272420 | ... P21: =SUM(P19:P20) -> 3.6722056e+08
A23: 6 | B23: PRIMARY NCP | C23: PRI | D23: =584355.83-D25 -> 569597.3 | E23: =600062.04-E25 -> 586768.88 | F23: =605611.34-F25 -> 592974.94 | G23: =584201.35-G25 -> 571817.45 | H23: =597124.06-H25 -> 584652.52 | I23: =568938.52-I25 -> 557524.27 | J23: =589184.42-J25 -> 577422.65 | K23: =592425.87-K25 -> 579676.47 | L23: =555871.09-L25 -> 543175.2 | M23: =611473.68-M25 -> 598841.47 | N23: =573060.08-N25 -> 560488.82 | O23: =625239.3-O25 -> 611742.9 | P23: =SUM(D23:O23) -> 6934682.9
A24: 7 | B24: PRIMARY 4CP | C24: PRI | D24: =7538118.02-D26 -> 6054429.9 | E24: =7460604.66-E26 -> 5975983.3 | F24: =7465778.22-F26 -> 5991397.9 | G24: =7482120.87-G26 -> 5961338.8 | H24: =7540518.99-H26 -> 6035698 | I24: =7468393.11-I26 -> 6024476.4 | J24: =7190599.96-J26 -> 5753850.8 | K24: =7325868.61-K26 -> 5939152.5 | L24: =7513156.01-L26 -> 6098734.3 | M24: =7549634.37-M26 -> 6174380.7 | N24: =7643794.46-N26 -> 6265912 | O24: =7655581.08-O26 -> 6244177.8 | P24: =SUM(D24:O24) -> 72519532
A25: 8 | B25: PRIMARY SUB NCP | C25: PRI | D25: =+'Primary Sub'!C6 -> 14758.53 | E25: =+'Primary Sub'!D6 -> 13293.16 | F25: =+'Primary Sub'!E6 -> 12636.4 | G25: =+'Primary Sub'!F6 -> 12383.9 | H25: =+'Primary Sub'!G6 -> 12471.54 | I25: =+'Primary Sub'!H6 -> 11414.25 | J25: =+'Primary Sub'!I6 -> 11761.77 | K25: =+'Primary Sub'!J6 -> 12749.4 | ... O25: =+'Primary Sub'!N6 -> 13496.4 | P25: =IF(SUM(D25:O25)='Primary Sub'!O6,SUM(D25:O25),0) -> 152864.71
A26: 9 | B26: PRIMARY SUB 4CP | C26: PRI | D26: =+'Primary Sub'!C7 -> 1483688.1 | E26: =+'Primary Sub'!D7 -> 1484621.4 | F26: =+'Primary Sub'!E7 -> 1474380.3 | G26: =+'Primary Sub'!F7 -> 1520782 | H26: =+'Primary Sub'!G7 -> 1504820.9 | I26: =+'Primary Sub'!H7 -> 1443916.7 | J26: =+'Primary Sub'!I7 -> 1436749.2 | K26: =+'Primary Sub'!J7 -> 1386716.1 | ... O26: =+'Primary Sub'!N7 -> 1411403.3 | P26: =IF(SUM(D26:O26)='Primary Sub'!O7,SUM(D26:O26),0) -> 17314636
A27: 10 | B27: TOTAL PRIMARY | D27: =SUM(D23:D26) -> 8122473.8 | E27: =SUM(E23:E26) -> 8060666.7 | F27: =SUM(F23:F26) -> 8071389.6 | G27: =SUM(G23:G26) -> 8066322.2 | H27: =SUM(H23:H26) -> 8137643.1 | I27: =SUM(I23:I26) -> 8037331.6 | J27: =SUM(J23:J26) -> 7779784.4 | K27: =SUM(K23:K26) -> 7918294.5 | ... P27: =SUM(P23:P26) -> 96921716
A29: 11 | B29: TRANSMISSION | C29: TRA | D29: 5580730.5 | E29: 5814365.7 | F29: 5595855.6 | G29: 6465557.5 | H29: 7059961.4 | I29: 5836392.2 | J29: 5282637.5 | K29: 4284472.4 | L29: 4980371.8 | M29: 5236512.5 | N29: 5177563.3 | O29: 4945189 | P29: =SUM(D29:O29) -> 66259609
A31: 12 | B31: LIGHTING | C31: SEC | D31: 2419720 | E31: 2431884.8 | F31: 2412705.2 | G31: 2414277 | H31: 2421519.7 | I31: 2403129.9 | J31: 2402975.8 | K31: 2402760.9 | L31: 2399047.2 | M31: 2407605.3 | N31: 2391978.4 | O31: 2542454.2 | P31: =SUM(D31:O31) -> 29050058
A33: 13 | B33: TOTAL RETAIL | D33: =D31+D29+D27+D21+D17+D15 -> 1.0669372e+08 | E33: =E31+E29+E27+E21+E17+E15 -> 93867099 | F33: =F31+F29+F27+F21+F17+F15 -> 1.0114428e+08 | G33: =G31+G29+G27+G21+G17+G15 -> 1.0565797e+08 | H33: =H31+H29+H27+H21+H17+H15 -> 99877130 | I33: =I31+I29+I27+I21+I17+I15 -> 86632465 | J33: =J31+J29+J27+J21+J17+J15 -> 84853975 | K33: =K31+K29+K27+K21+K17+K15 -> 86924483 | ... P33: =P31+P29+P27+P21+P17+P15 -> 1.2473305e+09
A35: 14 | B35: WHOLESALE PRI | C35: PRI | P35: =SUM(D35:O35) -> 0
A36: 15 | B36: WHOLESALE TRANS | C36: TRA | P36: =SUM(D36:O36) -> 0
A37: 16 | B37: TOTAL WHOLESALE | D37: =SUM(D35:D36) -> 0 | E37: =SUM(E35:E36) -> 0 | F37: =SUM(F35:F36) -> 0 | G37: =SUM(G35:G36) -> 0 | H37: =SUM(H35:H36) -> 0 | I37: =SUM(I35:I36) -> 0 | J37: =SUM(J35:J36) -> 0 | K37: =SUM(K35:K36) -> 0 | ... P37: =SUM(P35:P36) -> 0
A39: 17 | B39: TOTAL AEP TEXAS | D39: =+D37+D33 -> 1.0669372e+08 | E39: =+E37+E33 -> 93867099 | F39: =+F37+F33 -> 1.0114428e+08 | G39: =+G37+G33 -> 1.0565797e+08 | H39: =+H37+H33 -> 99877130 | I39: =+I37+I33 -> 86632465 | J39: =+J37+J33 -> 84853975 | K39: =+K37+K33 -> 86924483 | ... P39: =+P37+P33 -> 1.2473305e+09
B42: AEP TEXAS
B43: TTRAR RIDER ADJUSTMENT
B44: =B10 -> FOR TEST YEAR ENDED SEPTEMBER 30, 2023
B46: =Riders!C272 -> TTRAR
A47: LINE | B47: DESCRIPTION | C47: VOLT | D47: =+D13 -> Oct-22 | E47: =+E13 -> Nov-22 | F47: =+F13 -> Dec-22 | G47: =+G13 -> Jan-23 | H47: =+H13 -> Feb-23 | I47: =+I13 -> Mar-23 | J47: =+J13 -> Apr-23 | K47: =+K13 -> May-23 | ... O47: =+O13 -> Sep-23 | P47: TOTAL
A49: 1 | B49: RESIDENTIAL SERVICE | C49: SEC | D49: =-VLOOKUP(CONCATENATE($B$46,$B49),Riders!$A$12:$Q$357,'II-H-4.1 Monthly'!D$11,FALSE) -> -240172.01 | E49: =-VLOOKUP(CONCATENATE($B$46,$B49),Riders!$A$12:$Q$357,'II-H-4.1 Monthly'!E$11,FALSE) -> -185417.99 | F49: =-VLOOKUP(CONCATENATE($B$46,$B49),Riders!$A$12:$Q$357,'II-H-4.1 Monthly'!F$11,FALSE) -> -215773.04 | G49: =-VLOOKUP(CONCATENATE($B$46,$B49),Riders!$A$12:$Q$357,'II-H-4.1 Monthly'!G$11,FALSE) -> -231410.9 | H49: =-VLOOKUP(CONCATENATE($B$46,$B49),Riders!$A$12:$Q$357,'II-H-4.1 Monthly'!H$11,FALSE) -> -203666.94 | I49: =-VLOOKUP(CONCATENATE($B$46,$B49),Riders!$A$12:$Q$357,'II-H-4.1 Monthly'!I$11,FALSE) -> -186964.84 | J49: =-VLOOKUP(CONCATENATE($B$46,$B49),Riders!$A$12:$Q$357,'II-H-4.1 Monthly'!J$11,FALSE) -> -184233.9 | K49: =-VLOOKUP(CONCATENATE($B$46,$B49),Riders!$A$12:$Q$357,'II-H-4.1 Monthly'!K$11,FALSE) -> -201160.68 | ... O49: =-VLOOKUP(CONCATENATE($B$46,$B49),Riders!$A$12:$Q$357,'II-H-4.1 Monthly'!O$11,FALSE) -> -347687.62 | P49: =SUM(D49:O49) -> -2981645.4
A51: 2 | B51: SECONDARY < 10 kW | C51: SEC | D51: =-VLOOKUP(CONCATENATE($B$46,$B51),Riders!$A$12:$Q$357,'II-H-4.1 Monthly'!D$11,FALSE) -> -9738.37 | E51: =-VLOOKUP(CONCATENATE($B$46,$B51),Riders!$A$12:$Q$357,'II-H-4.1 Monthly'!E$11,FALSE) -> -8620.42 | F51: =-VLOOKUP(CONCATENATE($B$46,$B51),Riders!$A$12:$Q$357,'II-H-4.1 Monthly'!F$11,FALSE) -> -9141.16 | G51: =-VLOOKUP(CONCATENATE($B$46,$B51),Riders!$A$12:$Q$357,'II-H-4.1 Monthly'!G$11,FALSE) -> -9250.52 | H51: =-VLOOKUP(CONCATENATE($B$46,$B51),Riders!$A$12:$Q$357,'II-H-4.1 Monthly'!H$11,FALSE) -> -8471.09 | I51: =-VLOOKUP(CONCATENATE($B$46,$B51),Riders!$A$12:$Q$357,'II-H-4.1 Monthly'!I$11,FALSE) -> -8342.48 | J51: =-VLOOKUP(CONCATENATE($B$46,$B51),Riders!$A$12:$Q$357,'II-H-4.1 Monthly'!J$11,FALSE) -> -8296.32 | K51: =-VLOOKUP(CONCATENATE($B$46,$B51),Riders!$A$12:$Q$357,'II-H-4.1 Monthly'!K$11,FALSE) -> -8690.12 | ... O51: =-VLOOKUP(CONCATENATE($B$46,$B51),Riders!$A$12:$Q$357,'II-H-4.1 Monthly'!O$11,FALSE) -> -11865.33 | P51: =SUM(D51:O51) -> -115912.84
A53: 3 | B53: SECONDARY > 10 kW NCP | C53: SEC | D53: =-VLOOKUP(CONCATENATE($B$46,$B53),Riders!$A$12:$Q$357,'II-H-4.1 Monthly'!D$11,FALSE) -> -119411.68 | E53: =-VLOOKUP(CONCATENATE($B$46,$B53),Riders!$A$12:$Q$357,'II-H-4.1 Monthly'!E$11,FALSE) -> -116745.57 | F53: =-VLOOKUP(CONCATENATE($B$46,$B53),Riders!$A$12:$Q$357,'II-H-4.1 Monthly'!F$11,FALSE) -> -121510.78 | G53: =-VLOOKUP(CONCATENATE($B$46,$B53),Riders!$A$12:$Q$357,'II-H-4.1 Monthly'!G$11,FALSE) -> -123304.48 | H53: =-VLOOKUP(CONCATENATE($B$46,$B53),Riders!$A$12:$Q$357,'II-H-4.1 Monthly'!H$11,FALSE) -> -123424.46 | I53: =-VLOOKUP(CONCATENATE($B$46,$B53),Riders!$A$12:$Q$357,'II-H-4.1 Monthly'!I$11,FALSE) -> -121481.7 | J53: =-VLOOKUP(CONCATENATE($B$46,$B53),Riders!$A$12:$Q$357,'II-H-4.1 Monthly'!J$11,FALSE) -> -118411.5 | K53: =-VLOOKUP(CONCATENATE($B$46,$B53),Riders!$A$12:$Q$357,'II-H-4.1 Monthly'!K$11,FALSE) -> -116442.54 | ... O53: =-VLOOKUP(CONCATENATE($B$46,$B53),Riders!$A$12:$Q$357,'II-H-4.1 Monthly'!O$11,FALSE) -> -130763.36 | P53: =SUM(D53:O53) -> -1471094.9
A54: 4 | B54: SECONDARY > 10 kW 4CP | C54: SEC | D54: =-VLOOKUP(CONCATENATE($B$46,$B54),Riders!$A$12:$Q$357,'II-H-4.1 Monthly'!D$11,FALSE) -> -16224.01 | E54: =-VLOOKUP(CONCATENATE($B$46,$B54),Riders!$A$12:$Q$357,'II-H-4.1 Monthly'!E$11,FALSE) -> -15867.58 | F54: =-VLOOKUP(CONCATENATE($B$46,$B54),Riders!$A$12:$Q$357,'II-H-4.1 Monthly'!F$11,FALSE) -> -15500.13 | G54: =-VLOOKUP(CONCATENATE($B$46,$B54),Riders!$A$12:$Q$357,'II-H-4.1 Monthly'!G$11,FALSE) -> -14818.11 | H54: =-VLOOKUP(CONCATENATE($B$46,$B54),Riders!$A$12:$Q$357,'II-H-4.1 Monthly'!H$11,FALSE) -> -14239.84 | I54: =-VLOOKUP(CONCATENATE($B$46,$B54),Riders!$A$12:$Q$357,'II-H-4.1 Monthly'!I$11,FALSE) -> -14697.86 | J54: =-VLOOKUP(CONCATENATE($B$46,$B54),Riders!$A$12:$Q$357,'II-H-4.1 Monthly'!J$11,FALSE) -> -14737.91 | K54: =-VLOOKUP(CONCATENATE($B$46,$B54),Riders!$A$12:$Q$357,'II-H-4.1 Monthly'!K$11,FALSE) -> -15082.86 | ... O54: =-VLOOKUP(CONCATENATE($B$46,$B54),Riders!$A$12:$Q$357,'II-H-4.1 Monthly'!O$11,FALSE) -> -18301.78 | P54: =SUM(D54:O54) -> -189910.7
A55: 5 | B55: TOTAL SECONDARY > 10 kW | D55: =SUM(D53:D54) -> -135635.69 | E55: =SUM(E53:E54) -> -132613.15 | F55: =SUM(F53:F54) -> -137010.91 | G55: =SUM(G53:G54) -> -138122.59 | H55: =SUM(H53:H54) -> -137664.3 | I55: =SUM(I53:I54) -> -136179.56 | J55: =SUM(J53:J54) -> -133149.41 | K55: =SUM(K53:K54) -> -131525.4 | ... P55: =SUM(P53:P54) -> -1661005.6
A57: 6 | B57: PRIMARY NCP | C57: PRI | D57: =-VLOOKUP(CONCATENATE($B$46,$B57),Riders!$A$12:$Q$357,'II-H-4.1 Monthly'!D$11,FALSE) -> -2470.67 | E57: =-VLOOKUP(CONCATENATE($B$46,$B57),Riders!$A$12:$Q$357,'II-H-4.1 Monthly'!E$11,FALSE) -> -2576.75 | F57: =-VLOOKUP(CONCATENATE($B$46,$B57),Riders!$A$12:$Q$357,'II-H-4.1 Monthly'!F$11,FALSE) -> -2608.04 | G57: =-VLOOKUP(CONCATENATE($B$46,$B57),Riders!$A$12:$Q$357,'II-H-4.1 Monthly'!G$11,FALSE) -> -2508.79 | H57: =-VLOOKUP(CONCATENATE($B$46,$B57),Riders!$A$12:$Q$357,'II-H-4.1 Monthly'!H$11,FALSE) -> -2573.03 | I57: =-VLOOKUP(CONCATENATE($B$46,$B57),Riders!$A$12:$Q$357,'II-H-4.1 Monthly'!I$11,FALSE) -> -2779.94 | J57: =-VLOOKUP(CONCATENATE($B$46,$B57),Riders!$A$12:$Q$357,'II-H-4.1 Monthly'!J$11,FALSE) -> -2866.86 | K57: =-VLOOKUP(CONCATENATE($B$46,$B57),Riders!$A$12:$Q$357,'II-H-4.1 Monthly'!K$11,FALSE) -> -2922.14 | ... O57: =-VLOOKUP(CONCATENATE($B$46,$B57),Riders!$A$12:$Q$357,'II-H-4.1 Monthly'!O$11,FALSE) -> -2792.79 | P57: =SUM(D57:O57) -> -32510.42
A58: 7 | B58: PRIMARY 4CP | C58: PRI | D58: =-VLOOKUP(CONCATENATE($B$46,$B58),Riders!$A$12:$Q$357,'II-H-4.1 Monthly'!D$11,FALSE) -> -30189.27 | E58: =-VLOOKUP(CONCATENATE($B$46,$B58),Riders!$A$12:$Q$357,'II-H-4.1 Monthly'!E$11,FALSE) -> -29077.19 | F58: =-VLOOKUP(CONCATENATE($B$46,$B58),Riders!$A$12:$Q$357,'II-H-4.1 Monthly'!F$11,FALSE) -> -29381.06 | G58: =-VLOOKUP(CONCATENATE($B$46,$B58),Riders!$A$12:$Q$357,'II-H-4.1 Monthly'!G$11,FALSE) -> -27402.57 | H58: =-VLOOKUP(CONCATENATE($B$46,$B58),Riders!$A$12:$Q$357,'II-H-4.1 Monthly'!H$11,FALSE) -> -28527.79 | I58: =-VLOOKUP(CONCATENATE($B$46,$B58),Riders!$A$12:$Q$357,'II-H-4.1 Monthly'!I$11,FALSE) -> -30374.36 | J58: =-VLOOKUP(CONCATENATE($B$46,$B58),Riders!$A$12:$Q$357,'II-H-4.1 Monthly'!J$11,FALSE) -> -28444.46 | K58: =-VLOOKUP(CONCATENATE($B$46,$B58),Riders!$A$12:$Q$357,'II-H-4.1 Monthly'!K$11,FALSE) -> -31087.72 | ... O58: =-VLOOKUP(CONCATENATE($B$46,$B58),Riders!$A$12:$Q$357,'II-H-4.1 Monthly'!O$11,FALSE) -> -29666.63 | P58: =SUM(D58:O58) -> -359059.31
A59: 8 | B59: PRIMARY SUB NCP | C59: PRI | D59: =-VLOOKUP(CONCATENATE($B$46,$B59),Riders!$A$12:$Q$357,'II-H-4.1 Monthly'!D$11,FALSE) -> -70.66 | E59: =-VLOOKUP(CONCATENATE($B$46,$B59),Riders!$A$12:$Q$357,'II-H-4.1 Monthly'!E$11,FALSE) -> -69.61 | F59: =-VLOOKUP(CONCATENATE($B$46,$B59),Riders!$A$12:$Q$357,'II-H-4.1 Monthly'!F$11,FALSE) -> -66.66 | G59: =-VLOOKUP(CONCATENATE($B$46,$B59),Riders!$A$12:$Q$357,'II-H-4.1 Monthly'!G$11,FALSE) -> -65.37 | H59: =-VLOOKUP(CONCATENATE($B$46,$B59),Riders!$A$12:$Q$357,'II-H-4.1 Monthly'!H$11,FALSE) -> -65.71 | I59: =-VLOOKUP(CONCATENATE($B$46,$B59),Riders!$A$12:$Q$357,'II-H-4.1 Monthly'!I$11,FALSE) -> -64.3 | J59: =-VLOOKUP(CONCATENATE($B$46,$B59),Riders!$A$12:$Q$357,'II-H-4.1 Monthly'!J$11,FALSE) -> -65.41 | K59: =-VLOOKUP(CONCATENATE($B$46,$B59),Riders!$A$12:$Q$357,'II-H-4.1 Monthly'!K$11,FALSE) -> -70.02 | ... O59: =-VLOOKUP(CONCATENATE($B$46,$B59),Riders!$A$12:$Q$357,'II-H-4.1 Monthly'!O$11,FALSE) -> -66.93 | P59: =SUM(D59:O59) -> -814.53
...

Sheet II-H-4.1 Functions
B2: PUBLIC UTILITY COMMISSION OF TEXAS
B3: AEP TEXAS INC
B4: II-H-4.1 REVENUE IMPACTS FUNCTIONS
B5: ='II-H-4.1 Monthly'!B5 -> TEST YEAR ENDING 9/30/2023
B6: =+'II-H-1'!B6 -> DOCKET 56165
A8: AEP TEXAS
A9: UNADJUSTED BILLED REVENUE
A10: FOR TEST YEAR ENDED SEPTEMBER 30, 2023
A13: LINE | B13: DESCRIPTION | C13: VOLT | D13: Customer Revenue - Base Tariff | E13: Meter Revenue - Base Tariff | F13: Distribution Service Revenue - Base Tariff | G13: Facilities Charge | H13: DCRF Revenue | I13: TCRF Revenue | J13: Total Base Tariff Revenue | L13: ='II-H-4.1 Monthly'!B46 -> TTRAR | M13: ='II-H-4.1 Monthly'!B80 -> EECR | N13: ='II-H-4.1 Monthly'!B114 -> TC3 | O13: ='II-H-4.1 Monthly'!B148 -> MTEEE | P13: ='II-H-4.1 Monthly'!B181 -> SRC | Q13: =Riders!A40 -> Miscellaneous Riders | R13: Total Riders | T13: Total Revenue
A15: 1 | B15: RESIDENTIAL SERVICE | C15: SEC | D15: =+'[6]Functional Rev Unadjusted'!C55 -> 15556436 | E15: =+'[6]Functional Rev Unadjusted'!$D$55 -> 37668799 | F15: =+'[6]Functional Rev Unadjusted'!$E$55 -> 2.7879452e+08 | H15: =+'TCRF and DCRF Rider Revenues'!P17 -> 60613642 | I15: =+'TCRF and DCRF Rider Revenues'!P5 -> 1.9521636e+08 | J15: =SUM(D15:I15) -> 5.8784976e+08 | L15: =VLOOKUP(_xlfn.CONCAT(L$13,$B15),Riders!$A$11:$Q$328,17,FALSE) -> 2981645.4 | M15: =VLOOKUP(_xlfn.CONCAT(M$13,$B15),Riders!$A$11:$Q$328,17,FALSE) -> 14232787 | N15: =VLOOKUP(_xlfn.CONCAT(N$13,$B15),Riders!$A$11:$Q$328,17,FALSE) -> 27997172 | O15: =VLOOKUP(_xlfn.CONCAT(O$13,$B15),Riders!$A$11:$Q$328,17,FALSE) -> 1232462.1 | P15: =VLOOKUP(_xlfn.CONCAT(P$13,$B15),Riders!$A$11:$Q$328,17,FALSE) -> 14176856 | Q15: =SUMIF(Riders!$A:$A,_xlfn.CONCAT('II-H-4.1 Functions'!Q$13,'II-H-4.1 Functions'!$B15),Riders!$Q:$Q) -> 96.33 | R15: =L15+M15+N15+O15+P15+Q15 -> 60621019 | T15: =R15+J15 -> 6.4847078e+08
A17: 2 | B17: SECONDARY < 10 kW | C17: SEC | D17: =+'[6]Functional Rev Unadjusted'!$C$56 -> 1657485.9 | E17: =+'[6]Functional Rev Unadjusted'!$D$56 -> 5069882.1 | F17: =+'[6]Functional Rev Unadjusted'!$E$56 -> 14297306 | H17: =+'TCRF and DCRF Rider Revenues'!P18 -> 5782103.6 | I17: =+'TCRF and DCRF Rider Revenues'!P6 -> 6531262.9 | J17: =SUM(D17:I17) -> 33338041 | L17: =VLOOKUP(_xlfn.CONCAT(L$13,$B17),Riders!$A$11:$Q$328,17,FALSE) -> 115912.84 | M17: =VLOOKUP(_xlfn.CONCAT(M$13,$B17),Riders!$A$11:$Q$328,17,FALSE) -> 627738 | N17: =VLOOKUP(_xlfn.CONCAT(N$13,$B17),Riders!$A$11:$Q$328,17,FALSE) -> 4512469.5 | O17: =VLOOKUP(_xlfn.CONCAT(O$13,$B17),Riders!$A$11:$Q$328,17,FALSE) -> 107094.36 | P17: =VLOOKUP(_xlfn.CONCAT(P$13,$B17),Riders!$A$11:$Q$328,17,FALSE) -> 706508.43 | Q17: =SUMIF(Riders!$A:$A,_xlfn.CONCAT('II-H-4.1 Functions'!Q$13,'II-H-4.1 Functions'!$B17),Riders!$Q:$Q) -> 54.79 | R17: =L17+M17+N17+O17+P17+Q17 -> 6069777.9 | T17: =R17+J17 -> 39407819
