Workbook
Name Print_Area_0: #REF!
Name Print_Area_0: #REF!
Name Print_Area_0: #REF!
Name Print_Area_0: #REF!
Name Print_Area_0: #REF!
Name Print_Area_1: #REF!
Name Print_Area_1: #REF!
Name Print_Area_1: #REF!
Name Print_Area_1: #REF!
Name Print_Area_1: #REF!
Name Print_Area_2: #REF!
Name Print_Area_2: #REF!
Name Print_Area_2: #REF!
Name Print_Area_2: #REF!
Name Print_Area_2: #REF!
Name Print_Area_3: #REF!
Name Print_Area_3: #REF!
Name Print_Area_3: #REF!
Name Print_Area_3: #REF!
Name Print_Area_3: #REF!
Name Print_Area_4: #REF!
Name Print_Area_4: #REF!
Name Print_Area_4: #REF!
Name Print_Area_4: #REF!
Name Print_Area_4: #REF!

Sheet Index
A1: American Electric Power Service Corporation
A2: Monthly Variance Reporting Package
A3: September 2023
A9: Tab 1 | C9: AEPSC Bill Variance Summary
A11: Tab 2 | C11: AEPSC Bill Cost Category Summary - Income Statement
A13: Tab 3 | C13: AEPSC Variance Analysis
A15: Word Document | C15: Discussion of Major Variances
A17: Tab 4 | C17: Employee Fringe Benefit Loading Rates
A19: Tab 5 | C19: Total Bill Variance
A21: Tab 6 | C21: Income Statement Variance

Sheet Tab 1
A2: American Electric Power Service Corporation
A3: Total Bill Variances ( Favorable ) / UnFavorable
A4: Biiled + Manuals
A5: AEPSC Capital
A8: AEPSC Bill Entries
B10: EAST | I10: EAST | J10: WEST | M10: WEST | N10: NON-REG | O10: TRANSCO | P10: JV | Q10: AEPGR | R10: TRANSOURCE | S10: ETT | T10: AEPSC
B11: AEG | C11: APCO | D11: I&M | E11: KENT | F11: KINGS | G11: OPCO | H11: WHEEL | I11: TOTAL | J11: PSO | K11: SWEPCO | L11: AEP TEXAS | M11: TOTAL | N11: TOTAL | O11: TOTAL | P11: TOTAL | Q11: TOTAL | R11: TOTAL | S11: TOTAL | T11: TOTAL
A12: =EOMONTH(TEXT(Index!A3,"mmm-yyyy"),-12) -> 44834 | B12: 0 | C12: 20257693 | D12: 13635994 | E12: 3395405.8 | F12: 779546.29 | G12: 16753924 | H12: 2073638.3 | I12: 56896201 | J12: 8060334 | K12: 10210366 | L12: 16621277 | M12: 34891977 | N12: 1291197.6 | O12: 17722949 | P12: 0 | Q12: 220.33 | R12: 154285.28 | S12: 1734412.3 | T12: 1.1269124e+08
A13: =EOMONTH(A12,12) -> 45199 | B13: 0 | C13: 11749046 | D13: 6132540.4 | E13: 1689956.9 | F13: 527843.42 | G13: 11710481 | H13: 1860869.6 | I13: 33670737 | J13: 4794349.7 | K13: 6625010.1 | L13: 11411481 | M13: 22830841 | N13: 164126.64 | O13: 13595630 | P13: 0 | Q13: -165.13 | R13: 97204.83 | S13: 1709600.7 | T13: 72067975
A14: Variance | B14: =+B13-B12 -> 0 | C14: =+C13-C12 -> -8508647 | D14: =+D13-D12 -> -7503453.2 | E14: =+E13-E12 -> -1705448.9 | F14: =+F13-F12 -> -251702.87 | G14: =+G13-G12 -> -5043443.2 | H14: =+H13-H12 -> -212768.73 | I14: =SUM(B14:H14) -> -23225464 | J14: =+J13-J12 -> -3265984.3 | K14: =+K13-K12 -> -3585355.8 | L14: =+L13-L12 -> -5209795.3 | M14: =SUM(J14:L14) -> -12061135 | N14: =+N13-N12 -> -1127071 | O14: =+O13-O12 -> -4127319.4 | P14: =+P13-P12 -> 0 | Q14: =+Q13-Q12 -> -385.46 | R14: =+R13-R12 -> -57080.45 | S14: =+S13-S12 -> -24811.65 | T14: =SUM(I14,M14,N14:S14) -> -40623267
A16: Manual Entries - Other
B18: EAST | I18: EAST | J18: WEST | M18: WEST | N18: NON-REG | O18: TRANSCO | P18: JV | Q18: AEPGR | R18: TRANSOURCE | S18: ETT | T18: AEPSC
B19: AEG | C19: APCO | D19: I&M | E19: KENT | F19: KINGS | G19: OPCO | H19: WHEEL | I19: TOTAL | J19: PSO | K19: SWEPCO | L19: AEP TEXAS | M19: TOTAL | N19: TOTAL | O19: TOTAL | P19: TOTAL | Q19: TOTAL | R19: TOTAL | S19: TOTAL | T19: TOTAL
A20: =+$A$12 -> 44834 | B20: 0 | C20: -3910585.5 | D20: -4293128.4 | E20: -814957.35 | F20: -132344.21 | G20: -3609985.5 | H20: -214496.7 | I20: -12975498 | J20: -2216245.8 | K20: -2738807.2 | L20: -3758790.2 | M20: -8713843.2 | N20: -512620.66 | O20: -1714437.2 | P20: 0 | Q20: 0 | R20: -32306.81 | S20: -204608.02 | T20: -24153314
A21: =+$A$13 -> 45199 | B21: 0 | C21: 0 | D21: 0 | E21: 0 | F21: 0 | G21: 0 | H21: 0 | I21: 0 | J21: -0.01 | K21: 0 | L21: 0 | M21: -0.01 | N21: 0 | O21: 0 | P21: 0 | Q21: 0 | R21: 0 | S21: 0 | T21: -0.01
A22: Variance | B22: =+B21-B20 -> 0 | C22: =+C21-C20 -> 3910585.5 | D22: =+D21-D20 -> 4293128.4 | E22: =+E21-E20 -> 814957.35 | F22: =+F21-F20 -> 132344.21 | G22: =+G21-G20 -> 3609985.5 | H22: =+H21-H20 -> 214496.7 | I22: =SUM(B22:H22) -> 12975498 | J22: =+J21-J20 -> 2216245.8 | K22: =+K21-K20 -> 2738807.2 | L22: =+L21-L20 -> 3758790.2 | M22: =SUM(J22:L22) -> 8713843.2 | N22: =+N21-N20 -> 512620.66 | O22: =+O21-O20 -> 1714437.2 | P22: =+P21-P20 -> 0 | Q22: =+Q21-Q20 -> 0 | R22: =+R21-R20 -> 32306.81 | S22: =+S21-S20 -> 204608.02 | T22: =SUM(I22,M22,N22:S22) -> 24153314
A24: Total AEPSC Capital
B26: EAST | I26: EAST | J26: WEST | M26: WEST | N26: NON-REG | O26: TRANSCO | P26: JV | Q26: AEPGR | R26: TRANSOURCE | S26: ETT | T26: AEPSC
B27: AEG | C27: APCO | D27: I&M | E27: KENT | F27: KINGS | G27: OPCO | H27: WHEEL | I27: TOTAL | J27: PSO | K27: SWEPCO | L27: AEP TEXAS | M27: TOTAL | N27: TOTAL | O27: TOTAL | P27: TOTAL | Q27: TOTAL | R27: TOTAL | S27: TOTAL | T27: TOTAL
A28: =+$A$12 -> 44834 | B28: =+B12+B20 -> 0 | C28: =+C12+C20 -> 16347107 | D28: =+D12+D20 -> 9342865.1 | E28: =+E12+E20 -> 2580448.4 | F28: =+F12+F20 -> 647202.08 | G28: =+G12+G20 -> 13143938 | H28: =+H12+H20 -> 1859141.6 | I28: =SUM(B28:H28) -> 43920703 | J28: =+J12+J20 -> 5844088.2 | K28: =+K12+K20 -> 7471558.8 | L28: =+L12+L20 -> 12862487 | M28: =SUM(J28:L28) -> 26178133 | N28: =+N12+N20 -> 778576.98 | O28: =+O12+O20 -> 16008512 | P28: =+P12+P20 -> 0 | Q28: =+Q12+Q20 -> 220.33 | R28: =+R12+R20 -> 121978.47 | S28: =+S12+S20 -> 1529804.3 | T28: =SUM(I28,M28,N28:S28) -> 88537929
A29: =+$A$13 -> 45199 | B29: =+B13+B21 -> 0 | C29: =+C13+C21 -> 11749046 | D29: =+D13+D21 -> 6132540.4 | E29: =+E13+E21 -> 1689956.9 | F29: =+F13+F21 -> 527843.42 | G29: =+G13+G21 -> 11710481 | H29: =+H13+H21 -> 1860869.6 | I29: =SUM(B29:H29) -> 33670737 | J29: =+J13+J21 -> 4794349.7 | K29: =+K13+K21 -> 6625010.1 | L29: =+L13+L21 -> 11411481 | M29: =SUM(J29:L29) -> 22830841 | N29: =+N13+N21 -> 164126.64 | O29: =+O13+O21 -> 13595630 | P29: =+P13+P21 -> 0 | Q29: =+Q13+Q21 -> -165.13 | R29: =+R13+R21 -> 97204.83 | S29: =+S13+S21 -> 1709600.7 | T29: =SUM(I29,M29,N29:S29) -> 72067975
A30: Variance | B30: =+B14+B22 -> 0 | C30: =+C14+C22 -> -4598061.5 | D30: =+D14+D22 -> -3210324.8 | E30: =+E14+E22 -> -890491.51 | F30: =+F14+F22 -> -119358.66 | G30: =+G14+G22 -> -1433457.7 | H30: =+H14+H22 -> 1727.97 | I30: =SUM(B30:H30) -> -10249966 | J30: =+J14+J22 -> -1049738.5 | K30: =+K14+K22 -> -846548.65 | L30: =+L14+L22 -> -1451005.1 | M30: =SUM(J30:L30) -> -3347292.2 | N30: =+N14+N22 -> -614450.34 | O30: =+O14+O22 -> -2412882.1 | P30: =+P14+P22 -> 0 | Q30: =+Q14+Q22 -> -385.46 | R30: =+R14+R22 -> -24773.64 | S30: =+S14+S22 -> 179796.37 | T30: =SUM(I30,M30,N30:S30) -> -16469954
A32: AEPSC Other Balance Sheet
A34: AEPSC Bill Entries
B36: EAST | I36: EAST | J36: WEST | M36: WEST | N36: NON-REG | O36: TRANSCO | P36: JV | Q36: AEPGR | R36: TRANSOURCE | S36: ETT | T36: AEPSC
B37: AEG | C37: APCO | D37: I&M | E37: KENT | F37: KINGS | G37: OPCO | H37: WHEEL | I37: TOTAL | J37: PSO | K37: SWEPCO | L37: AEP TEXAS | M37: TOTAL | N37: TOTAL | O37: TOTAL | P37: TOTAL | Q37: TOTAL | R37: TOTAL | S37: TOTAL | T37: TOTAL
A38: =+$A$12 -> 44834 | B38: 65446.85 | C38: 1197796.3 | D38: 1097314.3 | E38: 178363.93 | F38: 13436.16 | G38: 905935.24 | H38: 177370.89 | I38: 3635663.7 | J38: 986072.64 | K38: 1271261.9 | L38: 798916.83 | M38: 3056251.4 | N38: 61104.04 | O38: 651829.46 | P38: 14869.09 | Q38: -728750.92 | R38: 3299.13 | S38: 115784.68 | T38: 6810050.6
A39: =+$A$13 -> 45199 | B39: 11678.82 | C39: 1353182.3 | D39: 838377.32 | E39: 175800.12 | F39: 17422.48 | G39: 696867.79 | H39: 212711.57 | I39: 3306040.4 | J39: 517780.06 | K39: 830396.86 | L39: 617897.14 | M39: 1966074.1 | N39: 42009.01 | O39: 384080.68 | P39: 25780.83 | Q39: -3331124.6 | R39: 1506.23 | S39: 71835.64 | T39: 2466202.3
A40: Variance | B40: =+B39-B38 -> -53768.03 | C40: =+C39-C38 -> 155386.01 | D40: =+D39-D38 -> -258937.01 | E40: =+E39-E38 -> -2563.81 | F40: =+F39-F38 -> 3986.32 | G40: =+G39-G38 -> -209067.45 | H40: =+H39-H38 -> 35340.68 | I40: =SUM(B40:H40) -> -329623.29 | J40: =+J39-J38 -> -468292.58 | K40: =+K39-K38 -> -440865.06 | L40: =+L39-L38 -> -181019.69 | M40: =SUM(J40:L40) -> -1090177.3 | N40: =+N39-N38 -> -19095.03 | O40: =+O39-O38 -> -267748.78 | P40: =+P39-P38 -> 10911.74 | Q40: =+Q39-Q38 -> -2602373.7 | R40: =+R39-R38 -> -1792.9 | S40: =+S39-S38 -> -43949.04 | T40: =SUM(I40,M40,N40:S40) -> -4343848.3
A42: Manual Entries - Other
B44: EAST | I44: EAST | J44: WEST | M44: WEST | N44: NON-REG | O44: TRANSCO | P44: JV | Q44: AEPGR | R44: TRANSOURCE | S44: ETT | T44: AEPSC
B45: AEG | C45: APCO | D45: I&M | E45: KENT | F45: KINGS | G45: OPCO | H45: WHEEL | I45: TOTAL | J45: PSO | K45: SWEPCO | L45: AEP TEXAS | M45: TOTAL | N45: TOTAL | O45: TOTAL | P45: TOTAL | Q45: TOTAL | R45: TOTAL | S45: TOTAL | T45: TOTAL
A46: =+$A$12 -> 44834 | B46: -22496.2 | C46: 0 | D46: -27958.3 | E46: 0 | F46: 0 | G46: 0 | H46: 0 | I46: -50454.5 | J46: 0 | K46: 0 | L46: 0 | M46: 0 | N46: 0 | O46: 0 | P46: 0 | Q46: 0 | R46: 0 | S46: -9.91 | T46: -50464.41
A47: =+$A$13 -> 45199 | B47: 0 | C47: 0 | D47: 0 | E47: 0 | F47: 0 | G47: 0 | H47: 0 | I47: 0 | J47: 0 | K47: 0 | L47: 0 | M47: 0 | N47: 0 | O47: 0 | P47: 0 | Q47: 0 | R47: 0 | S47: 0 | T47: 0
A48: Variance | B48: =+B47-B46 -> 22496.2 | C48: =+C47-C46 -> 0 | D48: =+D47-D46 -> 27958.3 | E48: =+E47-E46 -> 0 | F48: =+F47-F46 -> 0 | G48: =+G47-G46 -> 0 | H48: =+H47-H46 -> 0 | I48: =SUM(B48:H48) -> 50454.5 | J48: =+J47-J46 -> 0 | K48: =+K47-K46 -> 0 | L48: =+L47-L46 -> 0 | M48: =SUM(J48:L48) -> 0 | N48: =+N47-N46 -> 0 | O48: =+O47-O46 -> 0 | P48: =+P47-P46 -> 0 | Q48: =+Q47-Q46 -> 0 | R48: =+R47-R46 -> 0 | S48: =+S47-S46 -> 9.91 | T48: =SUM(I48,M48,N48:S48) -> 50464.41
A50: Total AEPSC Other Balance Sheet
B52: EAST | I52: EAST | J52: WEST | M52: WEST | N52: NON-REG | O52: TRANSCO | P52: JV | Q52: AEPGR | R52: TRANSOURCE | S52: ETT | T52: AEPSC
B53: AEG | C53: APCO | D53: I&M | E53: KENT | F53: KINGS | G53: OPCO | H53: WHEEL | I53: TOTAL | J53: PSO | K53: SWEPCO | L53: AEP TEXAS | M53: TOTAL | N53: TOTAL | O53: TOTAL | P53: TOTAL | Q53: TOTAL | R53: TOTAL | S53: TOTAL | T53: TOTAL
A54: =+$A$12 -> 44834 | B54: =+B38+B46 -> 42950.65 | C54: =+C38+C46 -> 1197796.3 | D54: =+D38+D46 -> 1069356 | E54: =+E38+E46 -> 178363.93 | F54: =+F38+F46 -> 13436.16 | G54: =+G38+G46 -> 905935.24 | H54: =+H38+H46 -> 177370.89 | I54: =SUM(B54:H54) -> 3585209.2 | J54: =+J38+J46 -> 986072.64 | K54: =+K38+K46 -> 1271261.9 | L54: =+L38+L46 -> 798916.83 | M54: =SUM(J54:L54) -> 3056251.4 | N54: =+N38+N46 -> 61104.04 | O54: =+O38+O46 -> 651829.46 | P54: =+P38+P46 -> 14869.09 | Q54: =+Q38+Q46 -> -728750.92 | R54: =+R38+R46 -> 3299.13 | S54: =+S38+S46 -> 115774.77 | T54: =SUM(I54,M54,N54:S54) -> 6759586.2
A55: =+$A$13 -> 45199 | B55: =+B39+B47 -> 11678.82 | C55: =+C39+C47 -> 1353182.3 | D55: =+D39+D47 -> 838377.32 | E55: =+E39+E47 -> 175800.12 | F55: =+F39+F47 -> 17422.48 | G55: =+G39+G47 -> 696867.79 | H55: =+H39+H47 -> 212711.57 | I55: =SUM(B55:H55) -> 3306040.4 | J55: =+J39+J47 -> 517780.06 | K55: =+K39+K47 -> 830396.86 | L55: =+L39+L47 -> 617897.14 | M55: =SUM(J55:L55) -> 1966074.1 | N55: =+N39+N47 -> 42009.01 | O55: =+O39+O47 -> 384080.68 | P55: =+P39+P47 -> 25780.83 | Q55: =+Q39+Q47 -> -3331124.6 | R55: =+R39+R47 -> 1506.23 | S55: =+S39+S47 -> 71835.64 | T55: =SUM(I55,M55,N55:S55) -> 2466202.3
...

Sheet Tab 2
B2: AEPSC Bill Variance Summary ( Favorable ) / Unfavorable
B4: No Manual adjustments reflected in these amounts; only items system Billed
B5: Income Statement
B7: Labor Variance (11X, 125, 129, 13X, 190, 1AA, 1AB, U3E)
C8: EAST | J8: EAST | K8: WEST | N8: WEST | O8: NON-REG | P8: TRANSCO | Q8: JV | R8: AEPGR | S8: TRANSOURCE | T8: ETT | U8: AEPSC
C9: AEG | D9: APCO | E9: I&M | F9: KENT | G9: KINGS | H9: OPCO | I9: WHEEL | J9: TOTAL | K9: PSO | L9: SWEPCO | M9: AEP TEXAS | N9: TOTAL | O9: TOTAL | P9: TOTAL | Q9: TOTAL | R9: TOTAL | S9: TOTAL | T9: TOTAL | U9: TOTAL
B10: =TEXT(+'Tab 1'!A12,"mmm-yyyy") -> Sep-2022 | C10: 13327.17 | D10: 4973108.4 | E10: 2971770.1 | F10: 855480.92 | G10: 100162.61 | H10: 3800311.2 | I10: 465351.89 | J10: 13179512 | K10: 2527741.9 | L10: 3056861.1 | M10: 2868542.2 | N10: 8453145.2 | O10: 1351170.2 | P10: 3093107.8 | Q10: 33748.96 | R10: 50061.17 | S10: 111642.23 | T10: 650079.59 | U10: 26922467
B11: =EOMONTH(B10,12) -> 45199 | C11: 26781.37 | D11: 4869395 | E11: 2788468 | F11: 784492.37 | G11: 101219.83 | H11: 3598154.4 | I11: 507846.58 | J11: 12676358 | K11: 2452785.4 | L11: 2848519 | M11: 2802541.4 | N11: 8103845.8 | O11: 848951.69 | P11: 2834608.3 | Q11: 26829.46 | R11: 27253.64 | S11: 143530.3 | T11: 612018.19 | U11: 25273395
B12: Variance | C12: =+C11-C10 -> 13454.2 | D12: =+D11-D10 -> -103713.31 | E12: =+E11-E10 -> -183302.15 | F12: =+F11-F10 -> -70988.55 | G12: =+G11-G10 -> 1057.22 | H12: =+H11-H10 -> -202156.8 | I12: =+I11-I10 -> 42494.69 | J12: =+J11-J10 -> -503154.7 | ... U12: =+U11-U10 -> -1649072.5
B15: Labor Fringe Variance (120, 121, 123, 126, 128, 170)
C16: EAST | J16: EAST | K16: WEST | N16: WEST | O16: NON-REG | P16: TRANSCO | Q16: JV | R16: AEPGR | S16: TRANSOURCE | T16: ETT | U16: AEPSC
C17: AEG | D17: APCO | E17: I&M | F17: KENT | G17: KINGS | H17: OPCO | I17: WHEEL | J17: TOTAL | K17: PSO | L17: SWEPCO | M17: AEP TEXAS | N17: TOTAL | O17: TOTAL | P17: TOTAL | Q17: TOTAL | R17: TOTAL | S17: TOTAL | T17: TOTAL | U17: TOTAL
B18: =+$B$10 -> Sep-2022 | C18: 2941.01 | D18: 961965.66 | E18: 599265.13 | F18: 139145.99 | G18: 13558.16 | H18: 719994.61 | I18: 122496.46 | J18: 2559367 | K18: 536315.7 | L18: 624232.15 | M18: 506440.96 | N18: 1666988.8 | O18: -114170.95 | P18: 493542.1 | Q18: 9702.28 | R18: 11924.14 | S18: 24116.06 | T18: 131667.42 | U18: 4783136.9
B19: =+$B$11 -> 45199 | C19: 4705.07 | D19: 509810.28 | E19: 325118.49 | F19: 93809.24 | G19: 4728.33 | H19: 326956.47 | I19: 46884.83 | J19: 1312012.7 | K19: 314319.02 | L19: 312393.83 | M19: 193692.38 | N19: 820405.23 | O19: 124807.12 | P19: 166337.22 | Q19: 7095.97 | R19: 4453.09 | S19: 30077.39 | T19: 89619.24 | U19: 2554808
B20: Variance | C20: =+C19-C18 -> 1764.06 | D20: =+D19-D18 -> -452155.38 | E20: =+E19-E18 -> -274146.64 | F20: =+F19-F18 -> -45336.75 | G20: =+G19-G18 -> -8829.83 | H20: =+H19-H18 -> -393038.14 | I20: =+I19-I18 -> -75611.63 | J20: =+J19-J18 -> -1247354.3 | ... U20: =+U19-U18 -> -2228328.9
B23: Annual Incentive Variance (122, 140, 141, 146-152, 155, 158, 161)
C24: EAST | J24: EAST | K24: WEST | N24: WEST | O24: NON-REG | P24: TRANSCO | Q24: JV | R24: AEPGR | S24: TRANSOURCE | T24: ETT | U24: AEPSC
C25: AEG | D25: APCO | E25: I&M | F25: KENT | G25: KINGS | H25: OPCO | I25: WHEEL | J25: TOTAL | K25: PSO | L25: SWEPCO | M25: AEP TEXAS | N25: TOTAL | O25: TOTAL | P25: TOTAL | Q25: TOTAL | R25: TOTAL | S25: TOTAL | T25: TOTAL | U25: TOTAL
B26: =+$B$10 -> Sep-2022 | C26: 3702.18 | D26: 1214659.8 | E26: 769190.96 | F26: 195779.92 | G26: 23728.71 | H26: 855703.12 | I26: 133225.69 | J26: 3195990.4 | K26: 642798.41 | L26: 754077.36 | M26: 683542.91 | N26: 2080418.7 | O26: 458298.26 | P26: 722565.37 | Q26: 10687.97 | R26: 14459.78 | S26: 34523.72 | T26: 170662.72 | U26: 6687606.9
B27: =+$B$11 -> 45199 | C27: -1720.87 | D27: -223172.81 | E27: -158631.81 | F27: -47988.56 | G27: -6070.27 | H27: -182468.88 | I27: -25709.91 | J27: -645763.11 | K27: -134805.65 | L27: -146781.45 | M27: -163682 | N27: -445269.1 | O27: -55828.57 | P27: -152996.99 | Q27: -1729.78 | R27: -1305.77 | S27: -10319.7 | T27: -32725.05 | U27: -1345938.1
B28: Variance | C28: =+C27-C26 -> -5423.05 | D28: =+D27-D26 -> -1437832.6 | E28: =+E27-E26 -> -927822.77 | F28: =+F27-F26 -> -243768.48 | G28: =+G27-G26 -> -29798.98 | H28: =+H27-H26 -> -1038172 | I28: =+I27-I26 -> -158935.6 | J28: =+J27-J26 -> -3841753.5 | ... U28: =+U27-U26 -> -8033544.9
B31: Long Term Incentive Variance (145, 153, 154, 157)
C32: EAST | J32: EAST | K32: WEST | N32: WEST | O32: NON-REG | P32: TRANSCO | Q32: JV | R32: AEPGR | S32: TRANSOURCE | T32: ETT | U32: AEPSC
C33: AEG | D33: APCO | E33: I&M | F33: KENT | G33: KINGS | H33: OPCO | I33: WHEEL | J33: TOTAL | K33: PSO | L33: SWEPCO | M33: AEP TEXAS | N33: TOTAL | O33: TOTAL | P33: TOTAL | Q33: TOTAL | R33: TOTAL | S33: TOTAL | T33: TOTAL | U33: TOTAL
B34: =+$B$10 -> Sep-2022 | C34: 2078.31 | D34: 556665.57 | E34: 429349.84 | F34: 91079.18 | G34: 10831.07 | H34: 375010.3 | I34: 69306.13 | J34: 1534320.4 | K34: 321948.63 | L34: 356424.95 | M34: 364284.85 | N34: 1042658.4 | O34: 328282.91 | P34: 345056.5 | Q34: 3437.58 | R34: 10123.01 | S34: 10631.69 | T34: 46274.87 | U34: 3320785.4
B35: =+$B$11 -> 45199 | C35: 2560.99 | D35: 483185.77 | E35: 368142.66 | F35: 86845.78 | G35: 12585.58 | H35: 302456.77 | I35: 62787.42 | J35: 1318565 | K35: 265676.31 | L35: 297286.61 | M35: 326346.46 | N35: 889309.38 | O35: 202601.63 | P35: 295441.42 | Q35: 2099.59 | R35: 6436.02 | S35: 9367.59 | T35: 28979.94 | U35: 2752800.5
B36: Variance | C36: =+C35-C34 -> 482.68 | D36: =+D35-D34 -> -73479.8 | E36: =+E35-E34 -> -61207.18 | F36: =+F35-F34 -> -4233.4 | G36: =+G35-G34 -> 1754.51 | H36: =+H35-H34 -> -72553.53 | I36: =+I35-I34 -> -6518.71 | J36: =+J35-J34 -> -215755.43 | ... U36: =+U35-U34 -> -567984.85
B39: Relocation/Severance Variance (124, 142-144)
C40: EAST | J40: EAST | K40: WEST | N40: WEST | O40: NON-REG | P40: TRANSCO | Q40: JV | R40: AEPGR | S40: TRANSOURCE | T40: ETT | U40: AEPSC
C41: AEG | D41: APCO | E41: I&M | F41: KENT | G41: KINGS | H41: OPCO | I41: WHEEL | J41: TOTAL | K41: PSO | L41: SWEPCO | M41: AEP TEXAS | N41: TOTAL | O41: TOTAL | P41: TOTAL | Q41: TOTAL | R41: TOTAL | S41: TOTAL | T41: TOTAL | U41: TOTAL
B42: =+$B$10 -> Sep-2022 | C42: -1.61 | D42: 151768.78 | E42: 137703.09 | F42: 26894.39 | G42: 3004.56 | H42: 102114.99 | I42: 19343.45 | J42: 440827.65 | K42: 92077.03 | L42: 98887.19 | M42: 119294.55 | N42: 310258.77 | O42: 236.71 | P42: 138815.93 | Q42: 0.03 | R42: -12.99 | S42: 145.77 | T42: 4027.56 | U42: 894299.43
B43: =+$B$11 -> 45199 | C43: 16618.62 | D43: 387481.52 | E43: 266482.16 | F43: 98450.32 | G43: 41288.29 | H43: 418488.1 | I43: 68188.77 | J43: 1296997.8 | K43: 221052.36 | L43: 273257.71 | M43: 351370.39 | N43: 845680.46 | O43: 190079.06 | P43: 91249.56 | Q43: 639.13 | R43: 14116.07 | S43: 18628.95 | T43: 22500.48 | U43: 2479891.5
B44: Variance | C44: =+C43-C42 -> 16620.23 | D44: =+D43-D42 -> 235712.74 | E44: =+E43-E42 -> 128779.07 | F44: =+F43-F42 -> 71555.93 | G44: =+G43-G42 -> 38283.73 | H44: =+H43-H42 -> 316373.11 | I44: =+I43-I42 -> 48845.32 | J44: =+J43-J42 -> 856170.13 | ... U44: =+U43-U42 -> 1585592.1
B47: Outside Services Variance (2xx, 9AA, 9AB)
C48: EAST | J48: EAST | K48: WEST | N48: WEST | O48: NON-REG | P48: TRANSCO | Q48: JV | R48: AEPGR | S48: TRANSOURCE | T48: ETT | U48: AEPSC
C49: AEG | D49: APCO | E49: I&M | F49: KENT | G49: KINGS | H49: OPCO | I49: WHEEL | J49: TOTAL | K49: PSO | L49: SWEPCO | M49: AEP TEXAS | N49: TOTAL | O49: TOTAL | P49: TOTAL | Q49: TOTAL | R49: TOTAL | S49: TOTAL | T49: TOTAL | U49: TOTAL
B50: =+$B$10 -> Sep-2022 | C50: 4430.52 | D50: 2596117 | E50: 1516893 | F50: 294973.72 | G50: 73902.41 | H50: 1695173.5 | I50: 547725.28 | J50: 6729215.4 | K50: 1664544.4 | L50: 1804494.2 | M50: 1261081 | N50: 4730119.5 | O50: 814171.08 | P50: 690559.36 | Q50: 4982.94 | R50: 81776.31 | S50: 105821.19 | T50: 199016.45 | U50: 13355662
B51: =+$B$11 -> 45199 | C51: 5207.99 | D51: 1625020.1 | E51: 1212763.5 | F51: 245387.72 | G51: 39215.02 | H51: 1413365.8 | I51: 158536.57 | J51: 4699496.6 | K51: 874040.57 | L51: 1124036.2 | M51: 1028849.9 | N51: 3026926.7 | O51: -158775.22 | P51: 662255.47 | Q51: 5652.41 | R51: 8666.5 | S51: 51245.26 | T51: 126222.75 | U51: 8421690.5
B52: Variance | C52: =+C51-C50 -> 777.47 | D52: =+D51-D50 -> -971096.96 | E52: =+E51-E50 -> -304129.5 | F52: =+F51-F50 -> -49586 | G52: =+G51-G50 -> -34687.39 | H52: =+H51-H50 -> -281807.69 | I52: =+I51-I50 -> -389188.71 | J52: =+J51-J50 -> -2029718.8 | ... U52: =+U51-U50 -> -4933971.7
B55: Material & Supplies Variance (3xx)
...

Sheet Tab 3
B2: American Electric Power Service Corporation Income Statement Variance Analysis Favorable/(Unfavorable)
B3: Billed + Manuals
B4: ( Favorable ) / Unfavorable
D5: EAST | K5: EAST | M5: WEST | P5: WEST | R5: NON-REG | S5: TRANSCO | T5: JV | U5: AEPGR | V5: TRANSOURCE | W5: ETT | Y5: AEPSC
B6: FERC Account Grouping | C6: FERC Account | D6: AEG | E6: APCO | F6: I&M | G6: KENT | H6: KINGS | I6: OPCO | J6: WHEEL | K6: TOTAL | M6: PSO | N6: SWEPCO | O6: AEP TEXAS | P6: TOTAL | R6: TOTAL | S6: TOTAL | T6: TOTAL | U6: TOTAL | V6: TOTAL | W6: TOTAL | Y6: TOTAL
B8: Other Income & Deductions | C8: 4171 Exps of Non-Utility Oper | F8: -16066.38 | K8: =SUM(D8:J8) -> -16066.38 | P8: =SUM(M8:O8) -> 0 | Y8: =+K8+P8+R8+S8+T8+U8+V8+W8 -> -16066.38
C9: 4210 Misc Non-Operating Income | D9: -1146.98 | E9: -10382.87 | F9: -230.43 | G9: -83.37 | H9: -8.12 | I9: -209.2 | J9: -9.75 | K9: =SUM(D9:J9) -> -12070.72 | M9: -102.7 | N9: -191.22 | O9: -133.2 | P9: =SUM(M9:O9) -> -427.12 | R9: -8.87 | S9: -191.75 | U9: -4.11 | V9: 0.83 | Y9: =+K9+P9+R9+S9+T9+U9+V9+W9 -> -12701.74
C10: 4261 Donations | D10: 3.26 | E10: 1428.58 | F10: 787.05 | G10: 283.73 | H10: 45.28 | I10: 1129.11 | J10: 91.63 | K10: =SUM(D10:J10) -> 3768.64 | M10: 589.42 | N10: 796.69 | O10: 979.99 | P10: =SUM(M10:O10) -> 2366.1 | R10: 16.8 | S10: 1173.99 | U10: 6.71 | Y10: =+K10+P10+R10+S10+T10+U10+V10+W10 -> 7332.24
C11: 4263 Penalties | D11: -0.01 | E11: -8.98 | F11: -8.21 | G11: -1.56 | H11: -0.18 | I11: -5.91 | J11: -1.16 | K11: =SUM(D11:J11) -> -26.01 | M11: -5.37 | N11: -5.67 | O11: -7.14 | P11: =SUM(M11:O11) -> -18.18 | R11: -0.62 | S11: -8.01 | U11: -0.26 | V11: -0.31 | W11: -2.09 | Y11: =+K11+P11+R11+S11+T11+U11+V11+W11 -> -55.48
C12: 4264 Civic & Political Activities | D12: -117.91 | E12: -72378.39 | F12: -66494 | G12: -12796.72 | H12: -1407.71 | I12: -54933.65 | J12: -8931.85 | K12: =SUM(D12:J12) -> -217060.23 | M12: 113674.49 | N12: -45568.08 | O12: -54530 | P12: =SUM(M12:O12) -> 13576.41 | R12: -5401.98 | S12: -60760.8 | U12: -1493.08 | V12: -79.65 | W12: 184883.2 | Y12: =+K12+P12+R12+S12+T12+U12+V12+W12 -> -86336.13
C13: 4265 Other Deductions | D13: -32.64 | E13: -21409.35 | F13: -18166.12 | G13: -4057.21 | H13: -423.24 | I13: -14799.04 | J13: -15874.87 | K13: =SUM(D13:J13) -> -74762.47 | M13: -12195.85 | N13: -13486.33 | O13: -17031.32 | P13: =SUM(M13:O13) -> -42713.5 | R13: -1479.73 | S13: -19144.03 | U13: -608.1 | V13: -20.77 | Y13: =+K13+P13+R13+S13+T13+U13+V13+W13 -> -138728.6
B14: Other Income & Deductions Total | D14: -1294.28 | E14: -102751.01 | F14: -100178.09 | G14: -16655.13 | H14: -1793.97 | I14: -68818.69 | J14: -24726 | K14: =SUM(D14:J14) -> -316217.17 | M14: 101959.99 | N14: -58454.61 | O14: -70721.67 | P14: =SUM(M14:O14) -> -27216.29 | R14: -6874.4 | S14: -78930.6 | U14: -2098.84 | V14: -99.9 | W14: 184881.11 | Y14: =+K14+P14+R14+S14+T14+U14+V14+W14 -> -246556.09
B15: Steam Power Generation Expenses | C15: 5000 Oper Supv and Eng | D15: 592.58 | E15: -746558.19 | F15: -404469.39 | G15: -82373.85 | H15: 299.52 | I15: 6910.8 | J15: -164769.42 | K15: =SUM(D15:J15) -> -1390368 | M15: -549100.02 | N15: -648462.83 | O15: 20832.75 | P15: =SUM(M15:O15) -> -1176730.1 | R15: -457.54 | S15: 12677.68 | T15: 0.09 | U15: 2080.97 | V15: 95.05 | W15: 418.73 | Y15: =+K15+P15+R15+S15+T15+U15+V15+W15 -> -2552283.1
C16: 5010 Fuel | D16: 0.94 | E16: 52225.5 | F16: 5184.56 | G16: 7167.2 | H16: -16.73 | I16: -511.69 | J16: 4453.66 | K16: =SUM(D16:J16) -> 68503.44 | M16: 49101.27 | N16: 61157.23 | O16: -450.42 | P16: =SUM(M16:O16) -> 109808.08 | R16: -298.01 | S16: -581.79 | U16: -1837.18 | Y16: =+K16+P16+R16+S16+T16+U16+V16+W16 -> 175594.54
C17: 5020 Steam Exps | E17: -2660.67 | F17: -226.23 | G17: -1.58 | J17: -2769.76 | K17: =SUM(D17:J17) -> -5658.24 | M17: -585.63 | N17: -6453.87 | P17: =SUM(M17:O17) -> -7039.5 | U17: 0.25 | Y17: =+K17+P17+R17+S17+T17+U17+V17+W17 -> -12697.49
C18: 5060 Misc Steam Pwr Exps | D18: -5.2 | E18: -13365.65 | F18: -4126.81 | G18: -1260.53 | H18: -139.79 | I18: -4686.52 | J18: 5529.77 | K18: =SUM(D18:J18) -> -18054.73 | M18: -36630.96 | N18: -20688.72 | O18: -5182.31 | P18: =SUM(M18:O18) -> -62501.99 | R18: -16.35 | S18: -15028.57 | U18: 183.5 | V18: 93.37 | W18: 894.74 | Y18: =+K18+P18+R18+S18+T18+U18+V18+W18 -> -94430.03
C19: 5100 Maint Supv & Eng | E19: 25137.31 | F19: 35485.95 | G19: 1238.15 | H19: -0.03 | I19: -3.24 | J19: -2905.47 | K19: =SUM(D19:J19) -> 58952.67 | M19: -704.45 | N19: 6217.6 | O19: -4.1 | P19: =SUM(M19:O19) -> 5509.05 | S19: -1.53 | Y19: =+K19+P19+R19+S19+T19+U19+V19+W19 -> 64460.19
C20: 5110 Maint of Structures | E20: 33268.21 | F20: -129.29 | G20: -172.73 | J20: -5861.59 | K20: =SUM(D20:J20) -> 27104.6 | M20: 5874.22 | N20: -3695.59 | P20: =SUM(M20:O20) -> 2178.63 | Y20: =+K20+P20+R20+S20+T20+U20+V20+W20 -> 29283.23
C21: 5120 Maint of Boiler Plant | E21: -24800.77 | F21: 2669.79 | G21: 4842 | H21: 0.36 | I21: 34.47 | J21: 16919.01 | K21: =SUM(D21:J21) -> -335.14 | M21: 14561.57 | N21: 880.03 | O21: 59.36 | P21: =SUM(M21:O21) -> 15500.96 | S21: 40.83 | Y21: =+K21+P21+R21+S21+T21+U21+V21+W21 -> 15206.65
C22: 5130 Maint of Electric Plant | E22: 14299.06 | F22: -21875.8 | G22: -112683 | H22: -0.43 | I22: -48.31 | J22: -31168.05 | K22: =SUM(D22:J22) -> -151476.53 | M22: -24019.24 | N22: -7797.39 | O22: -61.46 | P22: =SUM(M22:O22) -> -31878.09 | S22: -23.35 | Y22: =+K22+P22+R22+S22+T22+U22+V22+W22 -> -183377.97
C23: 5140 Maint of Misc Steam Plt | E23: 7981 | F23: -1335.04 | G23: 3195.39 | H23: -0.06 | I23: -6.93 | J23: 2648.91 | K23: =SUM(D23:J23) -> 12483.27 | M23: -3110.65 | N23: -18607.27 | O23: -8.77 | P23: =SUM(M23:O23) -> -21726.69 | S23: -3.31 | U23: -0.43 | Y23: =+K23+P23+R23+S23+T23+U23+V23+W23 -> -9247.16
B24: Steam Power Generation Expenses Total | D24: 588.32 | E24: -654474.2 | F24: -388822.26 | G24: -180048.95 | H24: 142.84 | I24: 1688.58 | J24: -177922.94 | K24: =SUM(D24:J24) -> -1398848.6 | M24: -544613.89 | N24: -637450.81 | O24: 15185.05 | P24: =SUM(M24:O24) -> -1166879.6 | R24: -771.9 | S24: -2920.04 | T24: 0.09 | U24: 427.11 | V24: 188.42 | W24: 1313.47 | Y24: =+K24+P24+R24+S24+T24+U24+V24+W24 -> -2567491.1
B25: Nuclear Power Generation | C25: 5170 Oper Supv & Eng | D25: -0.05 | E25: -20.83 | F25: 1932.27 | G25: -4.28 | H25: -0.63 | I25: -16.38 | J25: -1.18 | K25: =SUM(D25:J25) -> 1888.92 | M25: -7.79 | N25: -11.56 | O25: -14.23 | P25: =SUM(M25:O25) -> -33.58 | R25: -0.26 | S25: -17.22 | U25: -0.13 | Y25: =+K25+P25+R25+S25+T25+U25+V25+W25 -> 1837.73
C26: 5240 Misc Nuclear Power Exps | D26: -4.13 | E26: -958.65 | F26: -370249.87 | G26: -224.98 | H26: -23.96 | I26: -838.94 | J26: -26.58 | K26: =SUM(D26:J26) -> -372327.11 | M26: -435.34 | N26: -591.32 | O26: -830.71 | P26: =SUM(M26:O26) -> -1857.37 | R26: -13.48 | S26: -640.99 | U26: -7.77 | Y26: =+K26+P26+R26+S26+T26+U26+V26+W26 -> -374846.72
C27: 5280 Maint Supv & Eng | D27: 0.7 | E27: -150.02 | F27: -10.83 | G27: 24.54 | H27: 5.07 | I27: 154.84 | J27: -69.94 | K27: =SUM(D27:J27) -> -45.64 | M27: -128.31 | N27: -335.92 | O27: 136.3 | P27: =SUM(M27:O27) -> -327.93 | R27: 3.84 | S27: 176.03 | U27: 2.14 | Y27: =+K27+P27+R27+S27+T27+U27+V27+W27 -> -191.56
C28: 5300 Maint of Reactor Plant Equip | D28: -0.33 | E28: -3785.61 | F28: -120155.75 | G28: -9673.53 | H28: 8.75 | I28: 133.03 | J28: 8683.86 | K28: =SUM(D28:J28) -> -124789.58 | M28: 56.95 | N28: 86.16 | O28: 103.7 | P28: =SUM(M28:O28) -> 246.81 | R28: -2.62 | S28: 92.07 | U28: -2.84 | W28: -3.26 | Y28: =+K28+P28+R28+S28+T28+U28+V28+W28 -> -124459.42
B29: Nuclear Power Generation Total | D29: -3.81 | E29: -4915.11 | F29: -488484.18 | G29: -9878.25 | H29: -10.77 | I29: -567.45 | J29: 8586.16 | K29: =SUM(D29:J29) -> -495273.41 | M29: -514.49 | N29: -852.64 | O29: -604.94 | P29: =SUM(M29:O29) -> -1972.07 | R29: -12.52 | S29: -390.11 | U29: -8.6 | W29: -3.26 | Y29: =+K29+P29+R29+S29+T29+U29+V29+W29 -> -497659.97
B30: Hydraulic Power Generation | C30: 5350 Oper Supv & Eng | E30: 21633.44 | F30: -20855.37 | G30: 123.95 | J30: 107.07 | K30: =SUM(D30:J30) -> 1009.09 | M30: 309.42 | N30: 421.34 | P30: =SUM(M30:O30) -> 730.76 | Y30: =+K30+P30+R30+S30+T30+U30+V30+W30 -> 1739.85
C31: 5370 Hydraulic Expenses | E31: -20395.89 | F31: -7922.9 | G31: -175.87 | J31: -128.71 | K31: =SUM(D31:J31) -> -28623.37 | M31: -637.08 | N31: -857.02 | P31: =SUM(M31:O31) -> -1494.1 | Y31: =+K31+P31+R31+S31+T31+U31+V31+W31 -> -30117.47
C32: 5380 Electric Expenses | E32: 4868.03 | F32: -1380.45 | K32: =SUM(D32:J32) -> 3487.58 | P32: =SUM(M32:O32) -> 0 | Y32: =+K32+P32+R32+S32+T32+U32+V32+W32 -> 3487.58
C33: 5390 Misc Hydr Pwr Gen Exp | E33: -28793.61 | F33: -26314.15 | G33: -11.47 | H33: -0.62 | I33: -80.01 | J33: 19.22 | K33: =SUM(D33:J33) -> -55180.64 | M33: -277.75 | N33: -374.76 | O33: -101.39 | P33: =SUM(M33:O33) -> -753.9 | S33: -38.21 | Y33: =+K33+P33+R33+S33+T33+U33+V33+W33 -> -55972.75
C34: 5400 Rents | E34: -25.68 | F34: -10.23 | I34: -418.98 | K34: =SUM(D34:J34) -> -454.89 | P34: =SUM(M34:O34) -> 0 | Y34: =+K34+P34+R34+S34+T34+U34+V34+W34 -> -454.89
C35: 5410 Maint Supv & Eng | E35: 6370.64 | F35: -326.25 | K35: =SUM(D35:J35) -> 6044.39 | P35: =SUM(M35:O35) -> 0 | Y35: =+K35+P35+R35+S35+T35+U35+V35+W35 -> 6044.39
C36: 5420 Maint of Structures | E36: -2544.84 | F36: -4594.38 | G36: 40.89 | J36: 43.32 | K36: =SUM(D36:J36) -> -7055.01 | M36: 38.23 | N36: 51.46 | P36: =SUM(M36:O36) -> 89.69 | U36: -27 | Y36: =+K36+P36+R36+S36+T36+U36+V36+W36 -> -6992.32
C37: 5430 Maint Rsrvoirs,Dams,&Wtrways | E37: 6469.33 | F37: -558.41 | G37: 900.14 | J37: 33.95 | K37: =SUM(D37:J37) -> 6845.01 | M37: 103.55 | N37: 139.34 | P37: =SUM(M37:O37) -> 242.89 | Y37: =+K37+P37+R37+S37+T37+U37+V37+W37 -> 7087.9
C38: 5440 Maint of Electric Plant | E38: -44401.85 | F38: 12119.32 | G38: 763.25 | H38: -1.06 | I38: -130.34 | J38: 277.42 | K38: =SUM(D38:J38) -> -31373.26 | M38: -66.31 | N38: -95.58 | O38: -169.06 | P38: =SUM(M38:O38) -> -330.95 | S38: -68.29 | Y38: =+K38+P38+R38+S38+T38+U38+V38+W38 -> -31772.5
C39: 5450 Maint of Misc Hydraulic Plant | D39: -0.38 | E39: 142.42 | F39: -17.63 | G39: -27.23 | H39: -2.64 | I39: -82.84 | J39: -1.58 | K39: =SUM(D39:J39) -> 10.12 | M39: -2141.85 | N39: -59.62 | O39: 208.51 | P39: =SUM(M39:O39) -> -1992.96 | R39: -2.14 | S39: -95.17 | U39: -1.23 | Y39: =+K39+P39+R39+S39+T39+U39+V39+W39 -> -2081.38
B40: Hydraulic Power Generation Total | D40: -0.38 | E40: -56678.01 | F40: -49860.45 | G40: 1613.66 | H40: -4.32 | I40: -712.17 | J40: 350.69 | K40: =SUM(D40:J40) -> -105290.98 | M40: -2671.79 | N40: -774.84 | O40: -61.94 | P40: =SUM(M40:O40) -> -3508.57 | R40: -2.14 | S40: -201.67 | U40: -28.23 | Y40: =+K40+P40+R40+S40+T40+U40+V40+W40 -> -109031.59
B41: Other Power Generation | C41: 5460 Oper Supv & Eng | E41: 2412.05 | F41: 870.3 | G41: 350.96 | J41: 328.59 | K41: =SUM(D41:J41) -> 3961.9 | M41: 31082.55 | N41: 2644.43 | P41: =SUM(M41:O41) -> 33726.98 | U41: 15.2 | Y41: =+K41+P41+R41+S41+T41+U41+V41+W41 -> 37704.08
C42: 5470 Fuel Gas Turbine | E42: -1326.8 | K42: =SUM(D42:J42) -> -1326.8 | M42: -17.97 | N42: -24.04 | P42: =SUM(M42:O42) -> -42.01 | Y42: =+K42+P42+R42+S42+T42+U42+V42+W42 -> -1368.81
...

Sheet Tab 4
A1: American Electric Power Service Corporation
A2: Employee Fringe Benefit Loading Rate & Carrying Balance
A3: =+Index!A3 -> September 2023
F4: Carrying Balance (103-1860071)
A5: Month | B5: =RIGHT(A3,5) -> 2023 | C5: =+B5-1 -> 2022 | D5: Variance | F5: =+B5 -> 2023 | G5: =+C5 -> 2022 | H5: Variance
D6: INC (DEC)
A7: January | B7: 0.3026 | C7: 0.3284 | D7: =B7-C7 -> -0.0258 | F7: 1169844.7 | G7: 212128.31 | H7: =+F7-G7 -> 957716.4
A8: February | B8: 0.3026 | C8: 0.3284 | D8: =B8-C8 -> -0.0258 | F8: 2926077.9 | G8: 823771.54 | H8: =+F8-G8 -> 2102306.4
A9: March | B9: 0.3026 | C9: 0.3284 | D9: =B9-C9 -> -0.0258 | F9: 1451912.1 | G9: -3612806.6 | H9: =+F9-G9 -> 5064718.7
A10: April | B10: 0.3026 | C10: 0.3284 | D10: =B10-C10 -> -0.0258 | F10: 886927.93 | G10: 2883953.7 | H10: =+F10-G10 -> -1997025.8
A11: May | B11: 0.3026 | C11: 0.325 | D11: =B11-C11 -> -0.0224 | F11: -1349468.3 | G11: -3913449.1 | H11: =+F11-G11 -> 2563980.8
A12: June | B12: 0.28 | C12: 0.297 | D12: =B12-C12 -> -0.017 | F12: 2345064.6 | G12: -3151710.5 | H12: =+F12-G12 -> 5496775.2 | I12: (a)
A13: July | B13: 0.335 | C13: 0.267 | D13: =B13-C13 -> 0.068 | F13: -555121.2 | G13: -2340753.2 | H13: =+F13-G13 -> 1785632
A14: August | B14: 0.32 | C14: 0.272 | D14: =B14-C14 -> 0.048 | F14: -4634707 | G14: -2724875.1 | H14: =+F14-G14 -> -1909831.9
A15: September | B15: 0.265 | C15: 0.288 | D15: =B15-C15 -> -0.023 | F15: -3601591.7 | G15: -5487995.5 | H15: =+F15-G15 -> 1886403.8
A16: October | C16: 0.3 | D16: =B16-C16 -> -0.3 | F16: 0 | G16: -6435297 | H16: =+F16-G16 -> 6435297
A17: November | C17: 0.294 | D17: =B17-C17 -> -0.294 | F17: 0 | G17: -5581342.8 | H17: =+F17-G17 -> 5581342.8
A18: December | C18: 0.282 | D18: =B18-C18 -> -0.282 | F18: 0 | G18: 0 | H18: =+F18-G18 -> 0
A20: December residual Fringe balance cleared to affiliates (post billing Manual): | F20: TBD | G20: 1909741 | H20: =+F20-G20 -> #VALUE!
H21: =+F21-G21 -> 0
A24: (a) - overall overbilling of Fringes at June 2022 was ($10M). In June 2022, ($7M) credit was manually billed to all affiliates 9230003 account to reflect appropriate fringe billings at quarter end. The remaining ($3M) represents the estimated Capital portion not yet billed back to affiliates

Sheet Tab 5
B1: =+'Tab 1'!$A$4 -> Biiled + Manuals | F1: Tab 1: | G1: ='Tab 1'!T30+'Tab 1'!T56+'Tab 1'!T82 -> -41658639 | H1: =ROUND(+G1-SUMIF(B:B,"Grand Total",G:G),2) -> 0
B2: American Electric Power Service Corporation Total Bill Variances - Associated Companies
B3: Region | C3: Affiliate | D3: Affiliate Number and Name | E3: =+'Tab 1'!A12 -> 44834 | F3: =+'Tab 1'!A13 -> 45199 | G3: Variance | H3: Variance %age
B4: a-East | C4: a-AEG | D4: 153 AEG - Rockport | E4: 2379.73 | F4: 730.42 | G4: =+F4-E4 -> -1649.31 | H4: =IF(OR(E4="",F4=""),100%,+G4/E4) -> -0.69306602
D5: 270 AEG Cook Coal Terminal | E5: 76705.41 | F5: 78380.02 | G5: =+F5-E5 -> 1674.61 | H5: =IF(OR(E5="",F5=""),100%,+G5/E5) -> 0.021831707
C6: a-AEG Total | E6: 79085.14 | F6: 79110.44 | G6: =+F6-E6 -> 25.3 | H6: =IF(OR(E6="",F6=""),100%,+G6/E6) -> 0.00031990839
C7: b-APCO | D7: 140 Appalachian Power Co - Dist | E7: 11354697 | F7: 9518491.8 | G7: =+F7-E7 -> -1836205.6 | H7: =IF(OR(E7="",F7=""),100%,+G7/E7) -> -0.1617133
D8: 150 Appalachian Power Co - Trans | E8: 10195117 | F8: 7546613.9 | G8: =+F8-E8 -> -2648503.5 | H8: =IF(OR(E8="",F8=""),100%,+G8/E8) -> -0.25978156
D9: 215 Appalachian Power Co - Gen | E9: 11465350 | F9: 7910707.8 | G9: =+F9-E9 -> -3554642.2 | H9: =IF(OR(E9="",F9=""),100%,+G9/E9) -> -0.31003347
D10: 490 APCO Renewables | E10: 215963.08 | F10: 1143.13 | G10: =+F10-E10 -> -214819.95 | H10: =IF(OR(E10="",F10=""),100%,+G10/E10) -> -0.99470683
C11: b-APCO Total | E11: 33231128 | F11: 24976957 | G11: =+F11-E11 -> -8254171.3 | H11: =IF(OR(E11="",F11=""),100%,+G11/E11) -> -0.24838673
C12: c-I&M | D12: 120 Indiana Michigan Pwr Co - Tran | E12: 3453475.8 | F12: 2229093.6 | G12: =+F12-E12 -> -1224382.2 | H12: =IF(OR(E12="",F12=""),100%,+G12/E12) -> -0.3545362
D13: 132 Indiana Michigan Pwr Co - Gen | E13: 3832806.6 | F13: 2738283.9 | G13: =+F13-E13 -> -1094522.7 | H13: =IF(OR(E13="",F13=""),100%,+G13/E13) -> -0.28556689
D14: 170 Indiana Michigan Pwr Co - Dist | E14: 6734471.6 | F14: 5673590.6 | G14: =+F14-E14 -> -1060881.1 | H14: =IF(OR(E14="",F14=""),100%,+G14/E14) -> -0.15752996
D15: 190 Indiana Michigan Pwr Co - Nuc | E15: 6050665.7 | F15: 3658501.4 | G15: =+F15-E15 -> -2392164.3 | H15: =IF(OR(E15="",F15=""),100%,+G15/E15) -> -0.39535555
D16: 280 Ind Mich River Transp Lakin | E16: 158592.21 | F16: 103878.63 | G16: =+F16-E16 -> -54713.58 | H16: =IF(OR(E16="",F16=""),100%,+G16/E16) -> -0.34499538
C17: c-I&M Total | E17: 20230012 | F17: 14403348 | G17: =+F17-E17 -> -5826663.8 | H17: =IF(OR(E17="",F17=""),100%,+G17/E17) -> -0.28802078
C18: d-KENT | D18: 110 Kentucky Power Co - Dist | E18: 2528841.5 | F18: 1719974.8 | G18: =+F18-E18 -> -808866.75 | H18: =IF(OR(E18="",F18=""),100%,+G18/E18) -> -0.31985664
D19: 117 Kentucky Power Co - Gene | E19: 1112092.9 | F19: 646371.47 | G19: =+F19-E19 -> -465721.4 | H19: =IF(OR(E19="",F19=""),100%,+G19/E19) -> -0.41877923
D20: 180 Kentucky Power Co - Trans | E20: 1734009.4 | F20: 1435411.2 | G20: =+F20-E20 -> -298598.18 | H20: =IF(OR(E20="",F20=""),100%,+G20/E20) -> -0.17220102
C21: d-KENT Total | E21: 5374943.8 | F21: 3801757.4 | G21: =+F21-E21 -> -1573186.3 | H21: =IF(OR(E21="",F21=""),100%,+G21/E21) -> -0.29268889
C22: e-KINGS | D22: 230 Kingsport Power Co - Dist | E22: 709133.86 | F22: 667794.22 | G22: =+F22-E22 -> -41339.64 | H22: =IF(OR(E22="",F22=""),100%,+G22/E22) -> -0.058295961
D23: 260 Kingsport Power Co - Trans | E23: 325974.05 | F23: 182716.43 | G23: =+F23-E23 -> -143257.62 | H23: =IF(OR(E23="",F23=""),100%,+G23/E23) -> -0.43947553
C24: e-KINGS Total | E24: 1035107.9 | F24: 850510.65 | G24: =+F24-E24 -> -184597.26 | H24: =IF(OR(E24="",F24=""),100%,+G24/E24) -> -0.17833625
C25: f-OPCO | D25: 160 Ohio Power Co - Transmission | E25: 8628467.1 | F25: 7552060 | G25: =+F25-E25 -> -1076407.1 | H25: =IF(OR(E25="",F25=""),100%,+G25/E25) -> -0.12475068
D26: 250 Ohio Power Co - Distribution | E26: 17177006 | F26: 14449714 | G26: =+F26-E26 -> -2727292.1 | H26: =IF(OR(E26="",F26=""),100%,+G26/E26) -> -0.15877575
C27: f-OPCO Total | E27: 25805473 | F27: 22001774 | G27: =+F27-E27 -> -3803699.2 | H27: =IF(OR(E27="",F27=""),100%,+G27/E27) -> -0.14739893
C28: g-WHEEL | D28: 200 Wheeling Power Co - Trans | E28: 232126.43 | F28: 304714.48 | G28: =+F28-E28 -> 72588.05 | H28: =IF(OR(E28="",F28=""),100%,+G28/E28) -> 0.31270911
D29: 210 Wheeling Power Co - Dist | E29: 482267.6 | F29: 469996.44 | G29: =+F29-E29 -> -12271.16 | H29: =IF(OR(E29="",F29=""),100%,+G29/E29) -> -0.025444712
D30: 413 Wheeling Power Co - Generation | E30: 2999398.5 | F30: 2563772.9 | G30: =+F30-E30 -> -435625.65 | H30: =IF(OR(E30="",F30=""),100%,+G30/E30) -> -0.14523767
C31: g-WHEEL Total | E31: 3713792.6 | F31: 3338483.8 | G31: =+F31-E31 -> -375308.76 | H31: =IF(OR(E31="",F31=""),100%,+G31/E31) -> -0.10105808
B32: a-East Total | E32: 89469543 | F32: 69451941 | G32: =+F32-E32 -> -20017601 | H32: =IF(OR(E32="",F32=""),100%,+G32/E32) -> -0.22373649
B33: b-West | C33: h-PSO | D33: 114 Public Service Co of OK - Tran | E33: 2690590.7 | F33: 2149731.7 | G33: =+F33-E33 -> -540858.97 | H33: =IF(OR(E33="",F33=""),100%,+G33/E33) -> -0.20101867
D34: 167 Public Service Co of Ok - Dist | E34: 6472940.9 | F34: 5209597.9 | G34: =+F34-E34 -> -1263343.1 | H34: =IF(OR(E34="",F34=""),100%,+G34/E34) -> -0.19517296
D35: 198 Public Service Co of OK - Gen | E35: 4412970.2 | F35: 3009678.9 | G35: =+F35-E35 -> -1403291.3 | H35: =IF(OR(E35="",F35=""),100%,+G35/E35) -> -0.31799248
D36: 474 Public Service Co of OK- Wind | E36: 1441868.1 | F36: 1116363.9 | G36: =+F36-E36 -> -325504.26 | H36: =IF(OR(E36="",F36=""),100%,+G36/E36) -> -0.22575175
C37: h-PSO Total | E37: 15018370 | F37: 11485372 | G37: =+F37-E37 -> -3532997.6 | H37: =IF(OR(E37="",F37=""),100%,+G37/E37) -> -0.23524508
C38: i-SWEPC | D38: 159 SWEPCO-Distribution | E38: 6253771.6 | F38: 4870237 | G38: =+F38-E38 -> -1383534.5 | H38: =IF(OR(E38="",F38=""),100%,+G38/E38) -> -0.22123202
D39: 161 SWEPCO-TX-Distribution | E39: 335783.39 | F39: 404802.81 | G39: =+F39-E39 -> 69019.42 | H39: =IF(OR(E39="",F39=""),100%,+G39/E39) -> 0.20554745
D40: 168 SWEPCO-Generation | E40: 6989707.3 | F40: 4546202.8 | G40: =+F40-E40 -> -2443504.4 | H40: =IF(OR(E40="",F40=""),100%,+G40/E40) -> -0.34958609
...

Sheet Tab 6
B1: =+'Tab 1'!$A$4 -> Biiled + Manuals | F1: Tab 1: | G1: =+'Tab 1'!T82 -> -20895302 | H1: =ROUND(G1-SUMIF(B:B,"Grand Total",G:G),2) -> 0
B2: American Electric Power Service Corporation AEPSC Income Statement
B3: Region | C3: Affiliate | D3: Affiliate Number and Name | E3: =+'Tab 1'!A12 -> 44834 | F3: =+'Tab 1'!A13 -> 45199 | G3: Variance | H3: Variance %age
B4: a-East | C4: a-AEG | D4: 153 AEG - Rockport | E4: 2379.73 | F4: 730.42 | G4: =+F4-E4 -> -1649.31 | H4: =IF(OR(E4="",F4=""),100%,+G4/E4) -> -0.69306602
D5: 270 AEG Cook Coal Terminal | E5: 33754.76 | F5: 66701.2 | G5: =+F5-E5 -> 32946.44 | H5: =IF(OR(E5="",F5=""),100%,+G5/E5) -> 0.97605316
C6: a-AEG Total | E6: 36134.49 | F6: 67431.62 | G6: =+F6-E6 -> 31297.13 | H6: =IF(OR(E6="",F6=""),100%,+G6/E6) -> 0.86612901
C7: b-APCO | D7: 140 Appalachian Power Co - Dist | E7: 5402400.3 | F7: 4554309.4 | G7: =+F7-E7 -> -848090.93 | H7: =IF(OR(E7="",F7=""),100%,+G7/E7) -> -0.1569841
D8: 150 Appalachian Power Co - Trans | E8: 3966262 | F8: 2771542 | G8: =+F8-E8 -> -1194720.1 | H8: =IF(OR(E8="",F8=""),100%,+G8/E8) -> -0.30122067
D9: 215 Appalachian Power Co - Gen | E9: 6317561.9 | F9: 4548877 | G9: =+F9-E9 -> -1768684.8 | H9: =IF(OR(E9="",F9=""),100%,+G9/E9) -> -0.2799632
C10: b-APCO Total | E10: 15686224 | F10: 11874728 | G10: =+F10-E10 -> -3811495.9 | H10: =IF(OR(E10="",F10=""),100%,+G10/E10) -> -0.24298364
C11: c-I&M | D11: 120 Indiana Michigan Pwr Co - Tran | E11: 1396054.9 | F11: 954009.56 | G11: =+F11-E11 -> -442045.31 | H11: =IF(OR(E11="",F11=""),100%,+G11/E11) -> -0.31663892
D12: 132 Indiana Michigan Pwr Co - Gen | E12: 2057360.4 | F12: 1373021.9 | G12: =+F12-E12 -> -684338.52 | H12: =IF(OR(E12="",F12=""),100%,+G12/E12) -> -0.33262939
D13: 170 Indiana Michigan Pwr Co - Dist | E13: 3028202.8 | F13: 2580961.7 | G13: =+F13-E13 -> -447241.08 | H13: =IF(OR(E13="",F13=""),100%,+G13/E13) -> -0.14769192
D14: 190 Indiana Michigan Pwr Co - Nuc | E14: 3229073.4 | F14: 2433197.5 | G14: =+F14-E14 -> -795875.99 | H14: =IF(OR(E14="",F14=""),100%,+G14/E14) -> -0.24647194
D15: 280 Ind Mich River Transp Lakin | E15: 107099.28 | F15: 91239.89 | G15: =+F15-E15 -> -15859.39 | H15: =IF(OR(E15="",F15=""),100%,+G15/E15) -> -0.1480812
C16: c-I&M Total | E16: 9817790.7 | F16: 7432430.4 | G16: =+F16-E16 -> -2385360.3 | H16: =IF(OR(E16="",F16=""),100%,+G16/E16) -> -0.24296304
C17: d-KENT | D17: 110 Kentucky Power Co - Dist | E17: 1228391.3 | F17: 1019154.7 | G17: =+F17-E17 -> -209236.64 | H17: =IF(OR(E17="",F17=""),100%,+G17/E17) -> -0.17033386
D18: 117 Kentucky Power Co - Gene | E18: 701812.12 | F18: 349600.48 | G18: =+F18-E18 -> -352211.64 | H18: =IF(OR(E18="",F18=""),100%,+G18/E18) -> -0.5018603
D19: 180 Kentucky Power Co - Trans | E19: 685927.93 | F19: 567245.2 | G19: =+F19-E19 -> -118682.73 | H19: =IF(OR(E19="",F19=""),100%,+G19/E19) -> -0.17302507
C20: d-KENT Total | E20: 2616131.4 | F20: 1936000.4 | G20: =+F20-E20 -> -680131.01 | H20: =IF(OR(E20="",F20=""),100%,+G20/E20) -> -0.25997586
C21: e-KINGS | D21: 230 Kingsport Power Co - Dist | E21: 300171.39 | F21: 261838.86 | G21: =+F21-E21 -> -38332.53 | H21: =IF(OR(E21="",F21=""),100%,+G21/E21) -> -0.12770214
D22: 260 Kingsport Power Co - Trans | E22: 74298.28 | F22: 43405.89 | G22: =+F22-E22 -> -30892.39 | H22: =IF(OR(E22="",F22=""),100%,+G22/E22) -> -0.41578876
C23: e-KINGS Total | E23: 374469.67 | F23: 305244.75 | G23: =+F23-E23 -> -69224.92 | H23: =IF(OR(E23="",F23=""),100%,+G23/E23) -> -0.18486122
C24: f-OPCO | D24: 160 Ohio Power Co - Transmission | E24: 3195459.1 | F24: 2268086.3 | G24: =+F24-E24 -> -927372.82 | H24: =IF(OR(E24="",F24=""),100%,+G24/E24) -> -0.29021583
D25: 250 Ohio Power Co - Distribution | E25: 8560140.5 | F25: 7326339.3 | G25: =+F25-E25 -> -1233801.3 | H25: =IF(OR(E25="",F25=""),100%,+G25/E25) -> -0.1441333
C26: f-OPCO Total | E26: 11755600 | F26: 9594425.5 | G26: =+F26-E26 -> -2161174.1 | H26: =IF(OR(E26="",F26=""),100%,+G26/E26) -> -0.1838421
C27: g-WHEEL | D27: 200 Wheeling Power Co - Trans | E27: 101592.41 | F27: 83627.48 | G27: =+F27-E27 -> -17964.93 | H27: =IF(OR(E27="",F27=""),100%,+G27/E27) -> -0.17683339
D28: 210 Wheeling Power Co - Dist | E28: 242752.19 | F28: 214163.5 | G28: =+F28-E28 -> -28588.69 | H28: =IF(OR(E28="",F28=""),100%,+G28/E28) -> -0.11776903
D29: 413 Wheeling Power Co - Generation | E29: 1332935.5 | F29: 967111.69 | G29: =+F29-E29 -> -365823.79 | H29: =IF(OR(E29="",F29=""),100%,+G29/E29) -> -0.27444974
C30: g-WHEEL Total | E30: 1677280.1 | F30: 1264902.7 | G30: =+F30-E30 -> -412377.41 | H30: =IF(OR(E30="",F30=""),100%,+G30/E30) -> -0.24586079
B31: a-East Total | E31: 41963630 | F31: 32475164 | G31: =+F31-E31 -> -9488466.5 | H31: =IF(OR(E31="",F31=""),100%,+G31/E31) -> -0.22611167
B32: b-West | C32: h-PSO | D32: 114 Public Service Co of OK - Tran | E32: 1108054.6 | F32: 832792.85 | G32: =+F32-E32 -> -275261.8 | H32: =IF(OR(E32="",F32=""),100%,+G32/E32) -> -0.24841897
D33: 167 Public Service Co of Ok - Dist | E33: 3311712.2 | F33: 2819865.8 | G33: =+F33-E33 -> -491846.36 | H33: =IF(OR(E33="",F33=""),100%,+G33/E33) -> -0.14851724
D34: 198 Public Service Co of OK - Gen | E34: 2849601.7 | F34: 1733895.3 | G34: =+F34-E34 -> -1115706.3 | H34: =IF(OR(E34="",F34=""),100%,+G34/E34) -> -0.39153063
D35: 474 Public Service Co of OK- Wind | E35: 918840.61 | F35: 786688.52 | G35: =+F35-E35 -> -132152.09 | H35: =IF(OR(E35="",F35=""),100%,+G35/E35) -> -0.14382483
C36: h-PSO Total | E36: 8188209.1 | F36: 6173242.6 | G36: =+F36-E36 -> -2014966.6 | H36: =IF(OR(E36="",F36=""),100%,+G36/E36) -> -0.24608147
C37: i-SWEPC | D37: 159 SWEPCO-Distribution | E37: 3207357.4 | F37: 2650493 | G37: =+F37-E37 -> -556864.48 | H37: =IF(OR(E37="",F37=""),100%,+G37/E37) -> -0.17362096
D38: 161 SWEPCO-TX-Distribution | E38: 209535.32 | F38: 203449.43 | G38: =+F38-E38 -> -6085.89 | H38: =IF(OR(E38="",F38=""),100%,+G38/E38) -> -0.029044698
D39: 168 SWEPCO-Generation | E39: 4117775.2 | F39: 2671873.5 | G39: =+F39-E39 -> -1445901.7 | H39: =IF(OR(E39="",F39=""),100%,+G39/E39) -> -0.35113662
D40: 194 SWEPCO-Transmission | E40: 2022387.4 | F40: 1626255.4 | G40: =+F40-E40 -> -396131.96 | H40: =IF(OR(E40="",F40=""),100%,+G40/E40) -> -0.19587343
...

Sheet 457-PQ
A4: BUSINESS_UNIT | B4: DESCR | C4: FISCAL_YEAR | D4: ACCOUNT | E4: DESCR2 | F4: SUM(A.POSTED_TOTAL_AMT)
A5: 103 | B5: AEP Service Corporation | C5: 2022 | D5: 4571001 | E5: Service Rev - Direct Affil | F5: -1.5712888e+08
A6: 103 | B6: AEP Service Corporation | C6: 2022 | D6: 4572001 | E6: Service Rev-Indirect Cost-Affi | F6: -25022085
A7: 103 | B7: AEP Service Corporation | C7: 2022 | D7: 4573001 | E7: Compensation for Capital-Affil | F7: 1394582.6
A8: 103 | B8: AEP Service Corporation | C8: 2023 | D8: 4571001 | E8: Service Rev - Direct Affil | F8: -1.117754e+08
A9: 103 | B9: AEP Service Corporation | C9: 2023 | D9: 4572001 | E9: Service Rev-Indirect Cost-Affi | F9: -24843496
A10: 103 | B10: AEP Service Corporation | C10: 2023 | D10: 4573001 | E10: Compensation for Capital-Affil | F10: -2478846.8
