Workbook

Sheet Exempt Non-managerial
A1: AEP Texas: Target TCC Exempt positions Versus Market Survey
C3: AEP Incumbent Data | G3: Survey Results1 | J3: % Difference
A4: Rate case job identifier | B4: Employee Count | C4: Avg Base | D4: Target Incentive (2) | E4: Target TCC | G4: Base | H4: Target Incentive | I4: Target TCC | J4: Target TCC vs Survey Target TCC
A5: AEP Texas
A6: AEP Texas_EX1 | B6: 22 | C6: 79263.079 | D6: =E6-C6 -> 7133.6771 | E6: 86396.756 | G6: 92654.216 | H6: =I6-G6 -> 6679.9684 | I6: 99334.185 | J6: =(E6-I6)/I6 -> -0.13024146
A7: AEP Texas_EX2 | B7: 11 | C7: 73947.774 | D7: =E7-C7 -> 5915.8219 | E7: 79863.596 | G7: 79194.39 | H7: =I7-G7 -> 5795.6531 | I7: 84990.043 | J7: =(E7-I7)/I7 -> -0.060318218
A8: AEP Texas_EX3 | B8: 2 | C8: 127456.2 | D8: =E8-C8 -> 19118.429 | E8: 146574.62 | G8: 141227.38 | H8: =I8-G8 -> 17878.071 | I8: 159105.46 | J8: =(E8-I8)/I8 -> -0.078758023
A9: AEP Texas_EX4 | B9: 13 | C9: 112938.86 | D9: =E9-C9 -> 11293.886 | E9: 124232.75 | G9: 117847.8 | H9: =I9-G9 -> 12516.342 | I9: 130364.15 | J9: =(E9-I9)/I9 -> -0.047032873
A10: AEP Texas_EX5 | B10: 5 | C10: 104402.16 | D10: =E10-C10 -> 10440.216 | E10: 114842.38 | G10: 117828.57 | H10: =I10-G10 -> 13641.063 | I10: 131469.63 | J10: =(E10-I10)/I10 -> -0.12647218
A11: AEP Texas_EX6 | B11: 3 | C11: 76757.347 | D11: =E11-C11 -> 6140.5877 | E11: 82897.934 | G11: 63033.395 | H11: =I11-G11 -> 3779.7977 | I11: 66813.192 | J11: =(E11-I11)/I11 -> 0.24074201
A12: AEP Texas_EX7 | B12: 4 | C12: 93473.135 | D12: =E12-C12 -> 9347.3135 | E12: 102820.45 | G12: 97031.114 | H12: =I12-G12 -> 9703.2364 | I12: 106734.35 | J12: =(E12-I12)/I12 -> -0.036669559
A13: AEP Texas_EX8 | B13: 4 | C13: 109500 | D13: =E13-C13 -> 10950 | E13: 120450 | G13: 113044.9 | H13: =I13-G13 -> 7964.5187 | I13: 121009.42 | J13: =(E13-I13)/I13 -> -0.0046229384
A14: AEP Texas_EX9 | B14: 4 | C14: 85046.792 | D14: =E14-C14 -> 8504.6793 | E14: 93551.472 | G14: 91940.595 | H14: =I14-G14 -> 9194.1071 | I14: 101134.7 | J14: =(E14-I14)/I14 -> -0.074981482
A15: AEP Texas_EX10 | B15: 2 | C15: 100774.21 | D15: =E15-C15 -> 10077.421 | E15: 110851.63 | G15: 120876.9 | H15: =I15-G15 -> 16534.969 | I15: 137411.87 | J15: =(E15-I15)/I15 -> -0.19328933
A16: AEP Texas_EX11 | B16: 2 | C16: 72993.99 | D16: =E16-C16 -> 5839.5192 | E16: 78833.509 | G16: 79712.388 | H16: =I16-G16 -> 7720.4812 | I16: 87432.869 | J16: =(E16-I16)/I16 -> -0.098353858
A17: AEP Texas_EX12 | B17: 2 | C17: 117966.97 | D17: =E17-C17 -> 11796.697 | E17: 129763.67 | G17: 127583.65 | H17: =I17-G17 -> 14347.975 | I17: 141931.63 | J17: =(E17-I17)/I17 -> -0.085731141
... A67: AEP Texas_EX62 | B67: 3 | C67: 83532.363 | D67: =E67-C67 -> 7517.9127 | E67: 91050.276 | G67: 85589.733 | H67: =I67-G67 -> 5561.0094 | I67: 91150.742 | J67: =(E67-I67)/I67 -> -0.0011021946
A68: AEP Texas Count | B68: =COUNT(B6:B67) -> 62
A69: AEP Texas Incumbents | B69: =SUM(B6:B68) -> 390 | H69: AEP Texas AVERAGE | J69: =AVERAGE(J6:J67) -> -0.07100934
A71: AEP SERVICE CORP
A72: SVC_E1 | B72: 22 | C72: 83976.173 | D72: =E72-C72 -> 7557.8555 | E72: 91534.028 | G72: 90497.101 | H72: =I72-G72 -> 3290.7181 | I72: 93787.819 | J72: =(E72-I72)/I72 -> -0.024030739
A73: SVC_E2 | B73: 4 | C73: 76280.595 | D73: =E73-C73 -> 6102.4476 | E73: 82383.043 | G73: 77410.864 | H73: =I73-G73 -> 2701.3602 | I73: 80112.224 | J73: =(E73-I73)/I73 -> 0.028345468
A74: SVC_E3 | B74: 52 | C74: 114272.6 | D74: =E74-C74 -> 11427.26 | E74: 125699.86 | G74: 111890.15 | H74: =I74-G74 -> 8253.6395 | I74: 120143.79 | J74: =(E74-I74)/I74 -> 0.046245165
A75: SVC_E4 | B75: 125 | C75: 83416.799 | D75: =E75-C75 -> 7507.5119 | E75: 90924.311 | G75: 90497.101 | H75: =I75-G75 -> 3290.7181 | I75: 93787.819 | J75: =(E75-I75)/I75 -> -0.030531765
A76: SVC_E5 | B76: 74 | C76: 75741.329 | D76: =E76-C76 -> 6059.3063 | E76: 81800.635 | G76: 79194.39 | H76: =I76-G76 -> 5795.6531 | I76: 84990.043 | J76: =(E76-I76)/I76 -> -0.037526849
A77: SVC_E6 | B77: 105 | C77: 135120.54 | D77: =E77-C77 -> 20268.08 | E77: 155388.62 | G77: 139545.44 | H77: =I77-G77 -> 11624.662 | I77: 151170.1 | J77: =(E77-I77)/I77 -> 0.027905732
A78: SVC_E7 | B78: 230 | C78: 114037.83 | D78: =E78-C78 -> 11403.783 | E78: 125441.61 | G78: 111890.15 | H78: =I78-G78 -> 8253.6395 | I78: 120143.79 | J78: =(E78-I78)/I78 -> 0.044095702
A79: SVC_E8 | B79: 53 | C79: 158416.5 | D79: =E79-C79 -> 31683.299 | E79: 190099.8 | G79: 167012.79 | H79: =I79-G79 -> 19959.944 | I79: 186972.73 | J79: =(E79-I79)/I79 -> 0.016724705
A80: SVC_E9 | B80: 4 | C80: 124049.05 | D80: =E80-C80 -> 18607.357 | E80: 142656.4 | G80: 137561.97 | H80: =I80-G80 -> 12588.849 | I80: 150150.82 | J80: =(E80-I80)/I80 -> -0.049912588
A81: SVC_E10 | B81: 5 | C81: 102760.37 | D81: =E81-C81 -> 10276.037 | E81: 113036.4 | G81: 109069.38 | H81: =I81-G81 -> 7438.124 | I81: 116507.5 | J81: =(E81-I81)/I81 -> -0.029792924
A82: SVC_E11 | B82: 3 | C82: 79463.91 | D82: =E82-C82 -> 7151.7519 | E82: 86615.662 | G82: 76015.497 | H82: =I82-G82 -> 2174.2522 | I82: 78189.749 | J82: =(E82-I82)/I82 -> 0.10776237
A83: SVC_E12 | B83: 44 | C83: 107994.46 | D83: =E83-C83 -> 10799.446 | E83: 118793.9 | G83: 125080.63 | H83: =I83-G83 -> 7407.0705 | I83: 132487.7 | J83: =(E83-I83)/I83 -> -0.10335898
... A298: SVC_E227 | B298: 3 | C298: 106368.33 | D298: =E298-C298 -> 10636.833 | E298: 117005.17 | G298: 138776.04 | H298: =I298-G298 -> 15431.285 | I298: 154207.32 | J298: =(E298-I298)/I298 -> -0.24124765
A299: AEPSC Job Count | B299: =COUNT(B72:B298) -> 227 | H299: AEPSC AVERAGE | J299: =AVERAGE(J72:J298) -> -0.033541943
A300: AEPSC Incumbent Count | B300: =SUM(B72:B298) -> 2646
I302: AVERAGE | J302: =AVERAGE(J6:J67,J72:J298) -> -0.041579931
A303: TOTAL JOB COUNT | B303: =B299+B68 -> 289 | F303: % of Jobs Above Market Competitive Range4 | J303: =COUNTIF(J6:J298,">.15")/$B$303 -> 0.048442907
A304: TOTAL INCUMBENT Count | B304: =B300+B69 -> 3036 | F304: % of Jobs Below Market Competitive Range4 | J304: =COUNTIF(J6:J298,"<-.15")/$B$303 -> 0.14878893
A306: Notes:
A307: (1) All survey data aged to September 30, 2023 @ 4% annual rate
...

Sheet Exempt Graph Data All
A3: AEP Job | B3: AEP Target TCC vs. Survey Target TCC | C3: Market Low | D3: Market Median Compensation | E3: Market Competitive Range | F3: Market Max
A4: SVC_E111 | B4: =VLOOKUP($A4,'Exempt Non-managerial'!$A:$J,10,FALSE)+1 -> 1.497762 | C4: 0.85 | D4: 1 | E4: 0.3 | F4: 0.35
A5: SVC_E138 | B5: =VLOOKUP($A5,'Exempt Non-managerial'!$A:$J,10,FALSE)+1 -> 1.3151012 | C5: 0.85 | D5: 1 | E5: 0.3 | F5: 0.35
A6: SVC_E62 | B6: =VLOOKUP($A6,'Exempt Non-managerial'!$A:$J,10,FALSE)+1 -> 1.2491422 | C6: 0.85 | D6: 1 | E6: 0.3 | F6: 0.35
A7: AEP Texas_EX6 | B7: =VLOOKUP($A7,'Exempt Non-managerial'!$A:$J,10,FALSE)+1 -> 1.240742 | C7: 0.85 | D7: 1 | E7: 0.3 | F7: 0.35
A8: SVC_E109 | B8: =VLOOKUP($A8,'Exempt Non-managerial'!$A:$J,10,FALSE)+1 -> 1.2204236 | C8: 0.85 | D8: 1 | E8: 0.3 | F8: 0.35
A9: SVC_E15 | B9: =VLOOKUP($A9,'Exempt Non-managerial'!$A:$J,10,FALSE)+1 -> 1.2099921 | C9: 0.85 | D9: 1 | E9: 0.3 | F9: 0.35
A10: AEP Texas_EX30 | B10: =VLOOKUP($A10,'Exempt Non-managerial'!$A:$J,10,FALSE)+1 -> 1.2067529 | C10: 0.85 | D10: 1 | E10: 0.3 | F10: 0.35
A11: SVC_E14 | B11: =VLOOKUP($A11,'Exempt Non-managerial'!$A:$J,10,FALSE)+1 -> 1.1939249 | C11: 0.85 | D11: 1 | E11: 0.3 | F11: 0.35
A12: SVC_E146 | B12: =VLOOKUP($A12,'Exempt Non-managerial'!$A:$J,10,FALSE)+1 -> 1.1907645 | C12: 0.85 | D12: 1 | E12: 0.3 | F12: 0.35
A13: SVC_E124 | B13: =VLOOKUP($A13,'Exempt Non-managerial'!$A:$J,10,FALSE)+1 -> 1.1766433 | C13: 0.85 | D13: 1 | E13: 0.3 | F13: 0.35
A14: SVC_E55 | B14: =VLOOKUP($A14,'Exempt Non-managerial'!$A:$J,10,FALSE)+1 -> 1.171818 | C14: 0.85 | D14: 1 | E14: 0.3 | F14: 0.35
A15: SVC_E154 | B15: =VLOOKUP($A15,'Exempt Non-managerial'!$A:$J,10,FALSE)+1 -> 1.161615 | C15: 0.85 | D15: 1 | E15: 0.3 | F15: 0.35
... A292: AEP Texas_EX15 | B292: =VLOOKUP($A292,'Exempt Non-managerial'!$A:$J,10,FALSE)+1 -> 0.70201955 | C292: 0.85 | D292: 1 | E292: 0.3 | F292: 0.35
