Workbook
Name End_of_Report: '[1]Current Month Balance Sheet'!#REF!
Name NvsASD: "V2017-02-28"
Name NvsAutoDrillOk: "VN"
Name NvsElapsedTime: 0.00332175925723277
Name NvsEndTime: 42803.5989467593
Name NvsInstanceHook: """nvsMacro"""
Name NvsInstLang: "VENG"
Name NvsInstSpec: "%,FBUSINESS_UNIT,TGL_PRPT_CONS,NSWEPCO_INT_CONSOL"
Name NvsInstSpec1: ","
Name NvsInstSpec2: ","
Name NvsInstSpec3: ","
Name NvsInstSpec4: ","
Name NvsInstSpec5: ","
Name NvsInstSpec6: ","
Name NvsInstSpec7: ","
Name NvsInstSpec8: ","
Name NvsInstSpec9: ","
Name NvsLayoutType: "M3"
Name NvsNplSpec: "%,X,RZF..,CZF.."
Name NvsPanelBusUnit: "V"
Name NvsPanelEffdt: "V2002-06-13"
Name NvsPanelSetid: "VAEP"
Name NvsReqBU: "V159"
Name NvsReqBUOnly: "VN"
Name NvsTransLed: "VN"
Name NvsTreeASD: "V2017-02-28"
Name NvsValTbl.ACCOUNT: "GL_ACCOUNT_TBL"
Name NvsValTbl.BUSINESS_UNIT: "BUS_UNIT_TBL_GL"
Name NvsValTbl.CURRENCY_CD: "CURRENCY_CD_TBL"
Name search_directory_name: "R:\fcm90prd\nvision\rpts\Fin_Reports\"

Sheet Attachment A - Summary
B1: AEP TEXAS
B2: SUMMARY OF RATE CASE EXPENSES THROUGH JANUARY 31, 2024
B3: PUCT DOCKET NOS. 51984, 53451, 54824,55820, 53267 and 56165
B5: PUCT Docket No 51984 (AEP TEXAS 2021 DCRF)
B6: Cities Expenses | C6: ='Attachment B Docket 51984'!H19 -> 24763.5
B7: Legal Expenses | C7: ='Attachment B Docket 51984'!H23 -> 0
B8: Other Expenses | C8: ='Attachment B Docket 51984'!H27 -> 13.75
B9: Employee Expenses | C9: ='Attachment B Docket 51984'!H35 -> 5692.99
B10: Total Company Expenses Docket No. 51984 | C10: =SUM(C6:C9) -> 30470.24
B12: PUCT Docket No 53451 (AEP TEXAS 2022 DCRF)
B13: Cities Expenses | C13: ='Attachment B Docket 53451'!H14 -> 27173.5
B14: Legal Expenses | C14: ='Attachment B Docket 53451'!H18 -> 0
B15: Other Expenses | C15: ='Attachment B Docket 53451'!H25 -> 667
B16: Employee Expenses | C16: ='Attachment B Docket 53451'!H34 -> 830.24
B17: Total Company Expenses Docket No. 53451 | C17: =SUM(C13:C16) -> 28670.74
B19: PUCT Docket No 54824 (AEP TEXAS 2023 DCRF) and 55187
B20: Cities Expenses | C20: ='Attachment B Docket 54824'!H18 -> 30418
B21: Legal Expenses | C21: ='Attachment B Docket 54824'!H31 -> 84223
B22: Other Expenses | C22: ='Attachment B Docket 54824'!H39 -> 707.6
B23: Employee Expenses | C23: ='Attachment B Docket 54824'!H46 -> 510.16
B24: Total Company Expenses Docket No. 54824 | C24: =SUM(C20:C23) -> 115858.76
B26: PUCT Docket No 53267 (AEP TEXAS Wholesale Distribution Energy Storage)
B27: Cities Expenses | C27: ='Attachment B Docket 53267'!H11 -> 0
B28: Legal Expenses | C28: ='Attachment B Docket 53267'!H16 -> 19336.12
B29: Other Expenses | C29: ='Attachment B Docket 53267'!H20 -> 0
B30: Employee Expenses | C30: ='Attachment B Docket 53267'!H24 -> 0
B31: Total Company Expenses Docket No. 53267 | C31: =SUM(C27:C30) -> 19336.12
B33: PUCT Docket No 55820 (AEP TEXAS 2023 DCRF)
B34: Cities Expenses | C34: ='Attachment B Docket 55820'!H11 -> 0
B35: Legal Expenses | C35: ='Attachment B Docket 55820'!H15 -> 6662.52
B36: Other Expenses | C36: ='Attachment B Docket 54824'!H45 -> 0
B37: Employee Expenses | C37: ='Attachment B Docket 55820'!H24 -> 198.53
B38: Total Company Expenses Docket No. 55820 | C38: =SUM(C34:C37) -> 6861.05
B40: Current Case Docket No 56165 (AEP TEXAS 2024 BASE RATE CASE)
B41: Cities Expenses | C41: ='Attachment B Docket 56165'!H11 -> 0
B42: Legal Expenses | C42: ='Attachment B Docket 56165'!H24 -> 203515.33
B43: Other Expenses | C43: ='Attachment B Docket 56165'!H45 -> 269882
B44: Employee Expenses | C44: ='Attachment B Docket 56165'!H51 -> 0
B45: Total Company Expenses Current Case | C45: =SUM(C41:C44) -> 473397.33
B47: Combined Expenses Requested
...

Sheet Attachment B Docket 51984
A1: AEP TEXAS
A2: SUMMARY OF RATE CASE EXPENSES
A3: INCURRED AS OF 01-31-2024
A4: PUCT DOCKET NO. 51984
A7: Category | B7: Desc | C7: Voucher | D7: Vendor | E7: Name | F7: Amount | G7: Adjustment | H7: Requested | I7: Employee Name | J7: Year | K7: Period | L7: Invoice | M7: Invoice Date
A9: Cities' Expenses | B9: Legal | C9: 02579098 | D9: 0000097118 | E9: MCALLEN, CITY OF | F9: 6954.5 | G9: 0 | H9: 6954.5 | J9: 2021 | K9: 12 | L9: 97522523DKT51984 | M9: 44334
A10: Cities' Expenses | B10: Legal | C10: 02579005 | D10: 0000097118 | E10: MCALLEN, CITY OF | F10: 6870.5 | G10: 0 | H10: 6870.5 | J10: 2021 | K10: 12 | L10: 97523259DKT51984 | M10: 44407
A11: Cities' Expenses | B11: Legal | C11: 02579006 | D11: 0000097118 | E11: MCALLEN, CITY OF | F11: 3955 | G11: 0 | H11: 3955 | J11: 2021 | K11: 12 | L11: 97524052DKT51984 | M11: 44406
A12: Cities' Expenses | B12: Legal | C12: 02579007 | D12: 0000097118 | E12: MCALLEN, CITY OF | F12: 278 | G12: 0 | H12: 278 | J12: 2021 | K12: 12 | L12: 97524963DKT51984 | M12: 44431
A13: Cities' Expenses | B13: Legal | C13: 02579008 | D13: 0000097118 | E13: MCALLEN, CITY OF | F13: 528 | G13: 0 | H13: 528 | J13: 2021 | K13: 12 | L13: 97525697DKT51984 | M13: 44531
A14: Cities' Expenses | B14: Legal | C14: 02579009 | D14: 0000097118 | E14: MCALLEN, CITY OF | F14: 3455.5 | G14: 0 | H14: 3455.5 | J14: 2021 | K14: 12 | L14: 97526504DKT51984 | M14: 44488
A15: Cities' Expenses | B15: Legal | C15: 02579010 | D15: 0000097118 | E15: MCALLEN, CITY OF | F15: 507 | G15: 0 | H15: 507 | J15: 2021 | K15: 12 | L15: 97526844DKT51984 | M15: 44531
A16: Cities' Expenses | B16: Legal | C16: 02595566 | D16: 0000097118 | E16: MCALLEN, CITY OF | F16: 2090 | G16: 0 | H16: 2090 | J16: 2022 | K16: 4 | L16: 97523347DKT51984 | M16: 44370
A17: Cities' Expenses | B17: Legal | C17: 02597561 | D17: 0000097118 | E17: MCALLEN, CITY OF | F17: 125 | G17: 0 | H17: 125 | J17: 2022 | K17: 5 | L17: 97527555DKT51984 | M17: 44670
E19: Total Cities' | F19: =SUM(F9:F18) -> 24763.5 | G19: =SUM(G9:G18) -> 0 | H19: =SUM(H9:H18) -> 24763.5
A21: Legal | B21: Legal | E21: N/A
E23: Total Legal | F23: =SUM(F21:F21) -> 0 | G23: =SUM(G21:G21) -> 0 | H23: =SUM(H21:H21) -> 0
A25: Other | B25: Temporary Employees | C25: M2198436 | D25: 0001007765 | E25: ETTAIN GROUP | F25: 13.75 | G25: 0 | H25: 13.75 | J25: 2021 | K25: 4 | L25: AEPIN00331112TS | M25: 44305
E27: Total Other | F27: =SUM(F25:F25) -> 13.75 | G27: =SUM(G25:G25) -> 0 | H27: =SUM(H25:H25) -> 13.75
A29: Employee Expenses | B29: Meals - Business | C29: 00987477 | D29: 0000161803 | E29: BANK OF AMERICA | F29: 14.82 | G29: 0 | H29: 14.82 | I29: Gregory K Gullickson | J29: 2021 | K29: 4 | L29: 0000106587EX0001035455 | M29: 44302
A30: Employee Expenses | B30: Postage | C30: 00987691 | D30: 0000161803 | E30: BANK OF AMERICA | F30: 5316.84 | G30: 0 | H30: 5316.84 | I30: Gregory K Gullickson | J30: 2021 | K30: 4 | L30: 0000106587EX0001036756 | M30: 44307
A31: Employee Expenses | B31: Purchased Materials | C31: 00987693 | D31: 0000161803 | E31: BANK OF AMERICA | F31: 76.93 | G31: 0 | H31: 76.93 | I31: Gregory K Gullickson | J31: 2021 | K31: 4 | L31: 0000106587EX0001036777 | M31: 44307
A32: Employee Expenses | B32: Postage | C32: 00989230 | D32: 0000161803 | E32: BANK OF AMERICA | F32: 242.73 | G32: 0 | H32: 242.73 | I32: Gregory K Gullickson | J32: 2021 | K32: 5 | L32: 0000106587EX0001046863 | M32: 44342
A33: Employee Expenses | B33: Postage | C33: 00990621 | D33: 0000161803 | E33: BANK OF AMERICA | F33: 41.67 | G33: 0 | H33: 41.67 | I33: Gregory K Gullickson | J33: 2021 | K33: 6 | L33: 0000106587EX0001056067 | M33: 44376
E35: Total Employee | F35: =SUM(F29:F33) -> 5692.99 | G35: =SUM(G29:G33) -> 0 | H35: =SUM(H29:H33) -> 5692.99
E37: Grand Total 51984 | F37: =SUM(F19,F23,F27,F35) -> 30470.24 | G37: =SUM(G19,G23,G27,G35) -> 0 | H37: =SUM(H19,H23,H27,H35) -> 30470.24

Sheet Attachment B Docket 53451
A1: AEP TEXAS
A2: SUMMARY OF RATE CASE EXPENSES
A3: INCURRED AS OF 01-31-2024
A4: PUCT DOCKET NO. 53451
A7: Category | B7: Desc | C7: Voucher | D7: Vendor | E7: Name | F7: Amount | G7: Adjustment | H7: Requested | I7: Employee Name | J7: Year | K7: Period | L7: Invoice | M7: Invoice Date
A9: Cities' Expenses | B9: Legal | C9: 02615702 | D9: 0000097118 | E9: MCALLEN, CITY OF | F9: 9998.5 | G9: 0 | H9: 9998.5 | J9: 2022 | K9: 8 | L9: 97531824DKT53451 | M9: 44718
A10: Cities' Expenses | B10: Legal | C10: 02615703 | D10: 0000097118 | E10: MCALLEN, CITY OF | F10: 12898 | G10: 0 | H10: 12898 | J10: 2022 | K10: 8 | L10: 97532540DKT53451 | M10: 44733
A11: Cities' Expenses | B11: Legal | C11: 02615704 | D11: 0000097118 | E11: MCALLEN, CITY OF | F11: 3875.5 | G11: 0 | H11: 3875.5 | J11: 2022 | K11: 8 | L11: 97533221DKT53541 | M11: 44760
A12: Cities' Expenses | B12: Legal | C12: 02615705 | D12: 0000097118 | E12: MCALLEN, CITY OF | F12: 401.5 | G12: 0 | H12: 401.5 | J12: 2022 | K12: 8 | L12: 97533944DKT53451 | M12: 44785
E14: Total Cities' | F14: =SUM(F9:F12) -> 27173.5 | G14: =SUM(G9:G12) -> 0 | H14: =SUM(H9:H12) -> 27173.5
A16: Legal | B16: Legal | E16: N/A
E18: Total Legal | F18: =SUM(F16:F16) -> 0 | G18: =SUM(G16:G16) -> 0 | H18: =SUM(H16:H16) -> 0
A20: Other | B20: Temporary Employees | C20: M2820262 | D20: 0000010536 | E20: APEX SYSTEMS INC | F20: 464 | G20: 0 | H20: 464 | J20: 2022 | K20: 4 | L20: AEPIN00390645TS | M20: 44669
A21: Other | B21: Temporary Employees | C21: M2858429 | D21: 0000010536 | E21: APEX SYSTEMS INC | F21: 87 | G21: 0 | H21: 87 | J21: 2022 | K21: 5 | L21: AEPIN00393853TS | M21: 44687
A22: Other | B22: Temporary Employees | C22: M2871194 | D22: 0000164660 | E22: UNICON INTERNATIONAL INC | F22: 58 | G22: 0 | H22: 58 | J22: 2022 | K22: 5 | L22: AEPIN00395477TS | M22: 44697
A23: Other | B23: Temporary Employees | C23: M2885110 | D23: 0000010536 | E23: APEX SYSTEMS INC | F23: 58 | G23: 0 | H23: 58 | J23: 2022 | K23: 5 | L23: AEPIN00396659TS | M23: 44704
E25: Total Other | F25: =SUM(F20:F24) -> 667 | G25: =SUM(G20:G24) -> 0 | H25: =SUM(H20:H24) -> 667
A27: Employee Expenses | B27: Meals - Business | C27: 01005137 | D27: 0000161803 | E27: BANK OF AMERICA | F27: 19.13 | G27: 0 | H27: 19.13 | I27: Gregory K Gullickson | J27: 2022 | K27: 5 | L27: 0000106587EX0001156825 | M27: 44705
A28: Employee Expenses | B28: Meals - Business | C28: 01005137 | D28: 0000161803 | E28: BANK OF AMERICA | F28: 4.33 | G28: 0 | H28: 4.33 | I28: Gregory K Gullickson | J28: 2022 | K28: 5 | L28: 0000106587EX0001156825 | M28: 44705
A29: Employee Expenses | B29: Postage | C29: 01006725 | D29: 0000161803 | E29: BANK OF AMERICA | F29: 478.53 | G29: 0 | H29: 478.53 | I29: Gregory K Gullickson | J29: 2022 | K29: 6 | L29: 0000106587EX0001165526 | M29: 44736
A30: Employee Expenses | B30: Postage | C30: 01006789 | D30: 0000161803 | E30: BANK OF AMERICA | F30: 73.86 | G30: 0 | H30: 73.86 | I30: Gregory K Gullickson | J30: 2022 | K30: 6 | L30: 0000106587EX0001172820 | M30: 44739
A31: Employee Expenses | B31: Printing | C31: 01006796 | D31: 0000161803 | E31: BANK OF AMERICA | F31: 235 | G31: 0 | H31: 235 | I31: Gregory K Gullickson | J31: 2022 | K31: 6 | L31: 0000106587EX0001173053 | M31: 44739
A32: Employee Expenses | B32: Printing - Tax | C32: 01006796 | D32: 0000161803 | E32: BANK OF AMERICA | F32: 19.39 | G32: 0 | H32: 19.39 | I32: Gregory K Gullickson | J32: 2022 | K32: 6 | L32: 0000106587EX0001173053 | M32: 44739
E34: Total Employee | F34: =SUM(F27:F32) -> 830.24 | G34: =SUM(G27:G32) -> 0 | H34: =SUM(H27:H32) -> 830.24
E36: Grand Total 53451 | F36: =SUM(F14,F18,F25,F34) -> 28670.74 | G36: =SUM(G14,G18,G25,G34) -> 0 | H36: =SUM(H14,H18,H25,H34) -> 28670.74

Sheet Attachment B Docket 54824
A1: AEP TEXAS
A2: SUMMARY OF RATE CASE EXPENSES
A3: INCURRED AS OF 01-31-2024
A4: PUCT DOCKET NO. 54824 & 55187
A7: Category | B7: Desc | C7: Voucher | D7: Vendor | E7: Name | F7: Amount | G7: Adjustment | H7: Requested | I7: Employee Name | J7: Year | K7: Period | L7: Invoice | M7: Invoice Date
A9: Cities' Expenses | B9: Legal | C9: 02697739 | D9: 0000097118 | E9: MCALLEN, CITY OF | F9: 13025 | G9: 0 | H9: 13025 | J9: 2023 | K9: 11 | L9: 97542404DKT54824 | M9: 45125
A10: Cities' Expenses | B10: Legal | C10: 02697737 | D10: 0000097118 | E10: MCALLEN, CITY OF | F10: 7375 | G10: 0 | H10: 7375 | J10: 2023 | K10: 11 | L10: 97540927DKT54824 | M10: 45155
A11: Cities' Expenses | B11: Legal | C11: 02697738 | D11: 0000097118 | E11: MCALLEN, CITY OF | F11: 7287 | G11: 0 | H11: 7287 | J11: 2023 | K11: 11 | L11: 97541415DKT54824 | M11: 45155
A12: Cities' Expenses | B12: Legal | C12: 02697740 | D12: 0000097118 | E12: MCALLEN, CITY OF | F12: 1341.5 | G12: 0 | H12: 1341.5 | J12: 2023 | K12: 11 | L12: 97543172DKT54824 | M12: 45155
A13: Cities' Expenses | B13: Legal | C13: 02697741 | D13: 0000097118 | E13: MCALLEN, CITY OF | F13: 1305.5 | G13: 0 | H13: 1305.5 | J13: 2023 | K13: 11 | L13: 97543949DKT54824 | M13: 45187
A14: Cities' Expenses | B14: Legal | C14: 02697742 | D14: 0000097118 | E14: MCALLEN, CITY OF | F14: 84 | G14: 0 | H14: 84 | J14: 2023 | K14: 11 | L14: 97545264DKT54824 | M14: 45225
E18: Total Cities' | F18: =SUM(F9:F17) -> 30418 | G18: =SUM(G9:G17) -> 0 | H18: =SUM(H9:H17) -> 30418
A20: Legal | B20: Legal | C20: 01018359 | D20: 0000256019 | E20: DUGGINS WREN MANN & ROMERO LLP | F20: 325 | G20: 0 | H20: 325 | J20: 2023 | K20: 3 | L20: 39213 | M20: 44971
A21: Legal | B21: Legal | C21: 01019218 | D21: 0000256019 | E21: DUGGINS WREN MANN & ROMERO LLP | F21: 15470 | G21: 0 | H21: 15470 | J21: 2023 | K21: 3 | L21: 39337 | M21: 44998
A22: Legal | B22: Legal | C22: 01020681 | D22: 0000256019 | E22: DUGGINS WREN MANN & ROMERO LLP | F22: 24181.3 | G22: 0 | H22: 24181.3 | J22: 2023 | K22: 4 | L22: 39475R | M22: 45029
A23: Legal | B23: Legal | C23: 01023134 | D23: 0000256019 | E23: DUGGINS WREN MANN & ROMERO LLP | F23: 3739.68 | G23: 0 | H23: 3739.68 | J23: 2023 | K23: 5 | L23: 39623 | M23: 45058
A24: Legal | B24: Legal | C24: 01024477 | D24: 0000256019 | E24: DUGGINS WREN MANN & ROMERO LLP | F24: 15604.91 | G24: 0 | H24: 15604.91 | J24: 2023 | K24: 6 | L24: 39776 | M24: 45090
A25: Legal | B25: Legal | C25: 01025833 | D25: 0000256019 | E25: DUGGINS WREN MANN & ROMERO LLP | F25: 12822.37 | G25: 0 | H25: 12822.37 | J25: 2023 | K25: 7 | L25: 39900 | M25: 45120
A26: Legal | B26: Legal | C26: 01026958 | D26: 0000256019 | E26: DUGGINS WREN MANN & ROMERO LLP | F26: 7508.81 | G26: 0 | H26: 7508.81 | J26: 2023 | K26: 8 | L26: 40050 | M26: 45149
A27: Legal | B27: Legal | C27: 01028961 | D27: 0000256019 | E27: DUGGINS WREN MANN & ROMERO LLP | F27: 3588.39 | G27: 0 | H27: 3588.39 | J27: 2023 | K27: 9 | L27: 40156 | M27: 45182
A28: Legal | B28: Legal | C28: 01032035 | D28: 0000256019 | E28: DUGGINS WREN MANN & ROMERO LLP | F28: 837.46 | G28: 0 | H28: 837.46 | J28: 2023 | K28: 10 | L28: 40339 | M28: 45211
A29: Legal | B29: Legal | C29: 01036700 | D29: 0000256019 | E29: DUGGINS WREN MANN & ROMERO LLP | F29: 145.08 | G29: 0 | H29: 145.08 | J29: 2023 | K29: 12 | L29: 40497 | M29: 45244
E31: Total Legal | F31: =SUM(F20:F30) -> 84223 | G31: =SUM(G20:G30) -> 0 | H31: =SUM(H20:H30) -> 84223
A33: Other | B33: Temporary Employees | C33: M3468275 | D33: 0000010536 | E33: APEX SYSTEMS INC | F33: 174 | G33: 0 | H33: 174 | J33: 2023 | K33: 4 | L33: AEPIN00450831TS | M33: 45016
A34: Other | B34: Temporary Employees | C34: M3480159 | D34: 0000010536 | E34: APEX SYSTEMS INC | F34: 290 | G34: 0 | H34: 290 | J34: 2023 | K34: 4 | L34: AEPIN00451978TS | M34: 45022
A35: Other | B35: Temporary Employees | C35: M3493582 | D35: 0000010536 | E35: APEX SYSTEMS INC | F35: 58 | G35: 0 | H35: 58 | J35: 2023 | K35: 4 | L35: AEPIN00453355TS | M35: 45030
A36: Other | B36: Temporary Employees | C36: M3520817 | D36: 0000010536 | E36: APEX SYSTEMS INC | F36: 29 | G36: 0 | H36: 29 | J36: 2023 | K36: 5 | L36: AEPIN00456094TS | M36: 45044
A37: Other | B37: Temporary Employees | C37: M3533286 | D37: 0000010536 | E37: APEX SYSTEMS INC | F37: 156.6 | G37: 0 | H37: 156.6 | J37: 2023 | K37: 5 | L37: AEPIN00457067TS | M37: 45051
E39: Total Other | F39: =SUM(F33:F37) -> 707.6 | G39: =SUM(G33:G37) -> 0 | H39: =SUM(H33:H37) -> 707.6
A41: Employee Expense | B41: Transportation - Parking Fees | C41: 02660648 | D41: 0000161803 | E41: BANK OF AMERICA | F41: 12 | G41: 0 | H41: 12 | I41: Ashley M Price | J41: 2023 | K41: 5 | L41: 0000221859EX0001294740 | M41: 45062
A42: Employee Expense | B42: Transportation - Parking Fees | C42: 02660648 | D42: 0000161803 | E42: BANK OF AMERICA | F42: 12 | G42: 0 | H42: 12 | I42: Ashley M Price | J42: 2023 | K42: 5 | L42: 0000221859EX0001294740 | M42: 45062
A43: Employee Expense | B43: Purchased Services | C43: 01023047 | D43: 0000161803 | E43: BANK OF AMERICA | F43: 335 | G43: 0 | H43: 335 | I43: Gregory K Gullickson | J43: 2023 | K43: 5 | L43: 0000106587EX0001311270 | M43: 45070
A44: Employee Expense | B44: Purchased Services | C44: 01024424 | D44: 0000161803 | E44: BANK OF AMERICA | F44: 151.16 | G44: 0 | H44: 151.16 | I44: Gregory K Gullickson | J44: 2023 | K44: 6 | L44: 0000106587EX0001322288 | M44: 45100
E46: Total Employee | F46: =SUM(F41:F45) -> 510.16 | G46: =SUM(G41:G45) -> 0 | H46: =SUM(H41:H45) -> 510.16
E48: Grand Total 54824 & 55820 | F48: =SUM(F18,F31,F39,F46) -> 115858.76 | G48: =SUM(G18,G31,G39,G46) -> 0 | H48: =SUM(H18,H31,H39,H46) -> 115858.76

Sheet Attachment B Docket 55820
A1: AEP TEXAS
A2: SUMMARY OF RATE CASE EXPENSES
A3: INCURRED AS OF 01-31-2024
A4: PUCT DOCKET NO. 55820
A7: Category | B7: Desc | C7: Voucher | D7: Vendor | E7: Name | F7: Amount | G7: Adjustment | H7: Requested | I7: Employee Name | J7: Year | K7: Period | L7: Invoice | M7: Invoice Date
A9: Cities' Expenses | B9: Legal | E9: N/A
E11: Total Cities' | F11: =SUM(F9:F10) -> 0 | G11: =SUM(G9:G10) -> 0 | H11: =SUM(H9:H10) -> 0
A13: Legal | B13: Legal | C13: 00349213 | D13: 0000256019 | E13: DUGGINS WREN MANN & ROMERO LLP | F13: 6662.52 | G13: 0 | H13: 6662.52 | J13: 2023 | K13: 12 | L13: 40656 | M13: 45272
E15: Total Legal | F15: =SUM(F13:F14) -> 6662.52 | G15: =SUM(G13:G14) -> 0 | H15: =SUM(H13:H14) -> 6662.52
A18: Other | E18: N/A
E20: Total Other | F20: =SUM(F17:F18) -> 0 | G20: =SUM(G17:G18) -> 0 | H20: =SUM(H17:H18) -> 0
A22: Employee Expense | B22: Postage | C22: 01038884 | D22: 0000161803 | E22: BANK OF AMERICA | F22: 198.53 | G22: 0 | H22: 198.53 | I22: Gregory K Gullickson | J22: 2023 | K22: 12 | L22: 0000106587EX0001391334 | M22: 45289
E24: Total Employee | F24: =SUM(F22:F23) -> 198.53 | G24: =SUM(G22:G23) -> 0 | H24: =SUM(H22:H23) -> 198.53
E26: Grand Total 54824 & 55820 | F26: =SUM(F11,F15,F20,F24) -> 6861.05 | G26: =SUM(G11,G15,G20,G24) -> 0 | H26: =SUM(H11,H15,H20,H24) -> 6861.05

Sheet Attachment B Docket 53267
A1: AEP TEXAS
A2: SUMMARY OF RATE CASE EXPENSES
A3: INCURRED AS OF 01-31-2024
A4: PUCT DOCKET NO. 53267
A7: Category | B7: Desc | C7: Voucher | D7: Vendor | E7: Name | F7: Amount | G7: Adjustment | H7: Requested | I7: Employee Name | J7: Year | K7: Period | L7: Invoice | M7: Invoice Date
A9: Cities' Expenses | B9: Legal | E9: N/A
E11: Total Cities' | F11: =SUM(F9:F9) -> 0 | G11: =SUM(G9:G9) -> 0 | H11: =SUM(H9:H9) -> 0
A13: Legal | B13: Legal | C13: 01028960 | D13: 0000256019 | E13: DUGGINS WREN MANN & ROMERO LLP | F13: 11179.07 | G13: 0 | H13: 11179.07 | J13: 2023 | K13: 9 | L13: 40151 | M13: 45182
A14: Legal | B14: Legal | C14: 01032034 | D14: 0000256019 | E14: DUGGINS WREN MANN & ROMERO LLP | F14: 8157.05 | H14: 8157.05 | J14: 2023 | K14: 10 | L14: 40333 | M14: 45211
E16: Total Legal | F16: =SUM(F13:F14) -> 19336.12 | G16: =SUM(G13:G14) -> 0 | H16: =SUM(H13:H14) -> 19336.12
A18: Other | E18: N/A
E20: Total Other | F20: =SUM(F18:F18) -> 0 | G20: =SUM(G18:G18) -> 0 | H20: =SUM(H18:H18) -> 0
A22: Employee Expense | E22: N/A | F22: 0 | G22: 0 | H22: 0
E24: Total Employee | F24: =SUM(F22) -> 0 | G24: =SUM(G22) -> 0 | H24: =SUM(H22) -> 0
E26: Grand Total 53267 | F26: =SUM(F11,F16,F20,F24) -> 19336.12 | G26: =SUM(G11,G16,G20,G24) -> 0 | H26: =SUM(H11,H16,H20,H24) -> 19336.12

Sheet Attachment B Docket 56165
A1: SOUTHWESTERN ELECTRIC POWER COMPANY
A2: SUMMARY OF RATE CASE EXPENSES
A3: INCURRED AS OF 01-31-2024
A4: CURRENT CASE - PUCT DOCKET NO. XXXXX
A7: Category | B7: Desc | C7: Voucher | D7: Vendor | E7: Name | F7: Amount | G7: Adjustment | H7: Requested | I7: Emp. Name | J7: Year | K7: Period | L7: Invoice | M7: Invoice Date
A9: Cities' Expenses | B9: Legal | E9: N/A
E11: Total Cities' | F11: =SUM(F9:F9) -> 0 | G11: =SUM(G9:G9) -> 0 | H11: =SUM(H9:H9) -> 0
A13: Legal | B13: Legal | C13: 00343470 | D13: 0000256019 | E13: DUGGINS WREN MANN & ROMERO LLP | F13: 406.12 | G13: 0 | H13: 406.12 | J13: 2023 | K13: 4 | L13: 39471 | M13: 45029
A14: Legal | B14: Legal | C14: 00344321 | D14: 0000256019 | E14: DUGGINS WREN MANN & ROMERO LLP | F14: 270.75 | G14: 0 | H14: 270.75 | J14: 2023 | K14: 5 | L14: 39619 | M14: 45058
A15: Legal | B15: Legal | C15: 00345172 | D15: 0000256019 | E15: DUGGINS WREN MANN & ROMERO LLP | F15: 13183.69 | G15: 0 | H15: 13183.69 | J15: 2023 | K15: 6 | L15: 39774 | M15: 45090
A16: Legal | B16: Legal | C16: 00346162 | D16: 0000256019 | E16: DUGGINS WREN MANN & ROMERO LLP | F16: 26232.46 | G16: 0 | H16: 26232.46 | J16: 2023 | K16: 8 | L16: 39898 | M16: 45120
A17: Legal | B17: Legal | C17: 00346163 | D17: 0000256019 | E17: DUGGINS WREN MANN & ROMERO LLP | F17: 22558.05 | G17: 0 | H17: 22558.05 | J17: 2023 | K17: 8 | L17: 40048 | M17: 45149
A18: Legal | B18: Legal | C18: 00346820 | D18: 0000256019 | E18: DUGGINS WREN MANN & ROMERO LLP | F18: 27779.98 | G18: 0 | H18: 27779.98 | J18: 2023 | K18: 9 | L18: 40154 | M18: 45182
A19: Legal | B19: Legal | C19: 00347606 | D19: 0000256019 | E19: DUGGINS WREN MANN & ROMERO LLP | F19: 13024.66 | G19: 0 | H19: 13024.66 | J19: 2023 | K19: 10 | L19: 40337 | M19: 45211
A20: Legal | B20: Legal | C20: 00348880 | D20: 0000256019 | E20: DUGGINS WREN MANN & ROMERO LLP | F20: 23953.54 | G20: 0 | H20: 23953.54 | J20: 2023 | K20: 12 | L20: 40495 | M20: 45244
A21: Legal | B21: Legal | C21: 00349169 | D21: 0000256019 | E21: DUGGINS WREN MANN & ROMERO LLP | F21: 55283.85 | G21: 0 | H21: 55283.85 | J21: 2023 | K21: 12 | L21: 40645 | M21: 45272
A22: Legal | B22: Legal | C22: 00349715 | D22: 0000256019 | E22: DUGGINS WREN MANN & ROMERO LLP | F22: 20822.23 | G22: 0 | H22: 20822.23 | J22: 2024 | K22: 1 | L22: 40846 | M22: 45303
E24: Total Legal | F24: =+SUM(F13:F23) -> 203515.33 | G24: =+SUM(G13:G23) -> 0 | H24: =+SUM(H13:H23) -> 203515.33
A26: Other | B26: Professional Services | C26: 01030468 | D26: 0000241323 | E26: EXPERGY | F26: 3187 | G26: 0 | H26: 3187 | J26: 2023 | K26: 10 | L26: AEP2356 | M26: 45204
A27: Other | B27: Professional Services | C27: 01035227 | D27: 0001009108 | E27: HAMLETT, RANDALL W | F27: 229.5 | G27: 0 | H27: 229.5 | J27: 2023 | K27: 11 | L27: AEPTXSEP2023 | M27: 45203
A28: Other | B28: Professional Services | C28: 01032050 | D28: 0000216133 | E28: LEWIS & ELLIS INC | F28: 245 | G28: 0 | H28: 245 | J28: 2023 | K28: 10 | L28: 31208 | M28: 45208
A29: Other | B29: Professional Services | C29: 01032049 | D29: 0001027641 | E29: UTILITY CREDIT CONSULTANCY LLC | F29: 12445 | G29: 0 | H29: 12445 | J29: 2023 | K29: 10 | L29: 0211 | M29: 45200
A30: Other | B30: Professional Services | C30: 01034052 | D30: 0001027641 | E30: UTILITY CREDIT CONSULTANCY LLC | F30: 7205 | G30: 0 | H30: 7205 | J30: 2023 | K30: 11 | L30: 0212 | M30: 45231
A31: Other | B31: Professional Services | C31: 01027121 | D31: 0001015758 | E31: WYMAN IDEAS LLC | F31: 900 | G31: 0 | H31: 900 | J31: 2023 | K31: 8 | L31: 0001 | M31: 45153
A32: Other | B32: Professional Services | C32: 01028055 | D32: 0001015758 | E32: WYMAN IDEAS LLC | F32: 15420 | G32: 0 | H32: 15420 | J32: 2023 | K32: 9 | L32: 0002 | M32: 45173
A33: Other | B33: Professional Services | C33: 01030467 | D33: 0001015758 | E33: WYMAN IDEAS LLC | F33: 11160 | G33: 0 | H33: 11160 | J33: 2023 | K33: 10 | L33: 0003 | M33: 45201
A34: Other | B34: Professional Services | C34: 01035226 | D34: 0001015758 | E34: WYMAN IDEAS LLC | F34: 13920 | G34: 0 | H34: 13920 | J34: 2023 | K34: 11 | L34: 0004 | M34: 45238
A35: Other | B35: Professional Services | C35: 01038669 | D35: 0000085508 | E35: BRATTLE GROUP | F35: 27137.5 | G35: 0 | H35: 27137.5 | J35: 2023 | K35: 12 | L35: 075414 | M35: 45272
A36: Other | B36: Professional Services | C36: 01038673 | D36: 0000216133 | E36: LEWIS & ELLIS INC | F36: 2450 | G36: 0 | H36: 2450 | J36: 2023 | K36: 12 | L36: 31926 | M36: 45266
A37: Other | B37: Professional Services | C37: 01038674 | D37: 0000241323 | E37: EXPERGY | F37: 9562 | G37: 0 | H37: 9562 | J37: 2023 | K37: 12 | L37: AEP2365 | M37: 45265
... A43: Other | B43: Professional Services | C43: 01039232 | D43: 0001009108 | E43: HAMLETT, RANDALL W | F43: 178.5 | G43: 0 | H43: 178.5 | J43: 2024 | K43: 1 | L43: AEPTXNOV2023 | M43: 45266
E45: Total Other | F45: =SUM(F26:F44) -> 269882 | G45: =SUM(G26:G44) -> 0 | H45: =SUM(H26:H44) -> 269882
A49: Employee Expense | E49: N/A
E51: Total Employee | F51: =SUM(F47:F50) -> 0 | G51: =SUM(G47:G50) -> 0 | H51: =SUM(H47:H50) -> 0
E53: Grand Total Current Case | F53: =SUM(F11,F24,F45,F51) -> 473397.33 | G53: =SUM(G11,G24,G45,G51) -> 0 | H53: =SUM(H11,H24,H45,H51) -> 473397.33
