Workbook

Sheet non exempt
A1: AEP Texas: Target TCC NonExempt positions Versus Market Survey
C3: AEP Incumbent Data | G3: Survey Results1 | J3: % Difference
A4: Rate case job identifier | B4: Employee Count | C4: Avg Base | D4: Target Incentive (2) | E4: Target TCC | G4: Base | H4: Target Incentive | I4: Target TCC | J4: Target TCC vs Survey Target TCC
A5: AEP Texas
A6: AEP Texas_NE1 | B6: 3 | C6: 55650.36 | D6: =E6-C6 -> 3339.0216 | E6: 58989.382 | G6: 65549.487 | H6: =I6-G6 -> 1661.5697 | I6: 67211.057 | J6: =(E6-I6)/I6 -> -0.12232623
A7: AEP Texas_NE2 | B7: 6 | C7: 49790.782 | D7: =E7-C7 -> 2489.5391 | E7: 52280.321 | G7: 52641.776 | H7: =I7-G7 -> 1514.4256 | I7: 54156.201 | J7: =(E7-I7)/I7 -> -0.034638332
A8: AEP Texas_NE3 | B8: 2 | C8: 71765.79 | D8: =E8-C8 -> 5741.2632 | E8: 77507.053 | G8: 74230.343 | H8: =I8-G8 -> 3471.1425 | I8: 77701.485 | J8: =(E8-I8)/I8 -> -0.0025022921
A9: AEP Texas_NE4 | B9: 6 | C9: 44596.822 | D9: =E9-C9 -> 2229.8411 | E9: 46826.663 | G9: 45328.793 | H9: =I9-G9 -> 3299.2043 | I9: 48627.997 | J9: =(E9-I9)/I9 -> -0.03704315
A10: AEP Texas_NE5 | B10: 17 | C10: 50574.672 | D10: =E10-C10 -> 2528.7336 | E10: 53103.406 | G10: 56451.235 | H10: =I10-G10 -> 3039.2317 | I10: 59490.466 | J10: =(E10-I10)/I10 -> -0.10736275
A11: AEP Texas_NE6 | B11: 32 | C11: 61893.395 | D11: =E11-C11 -> 3713.6037 | E11: 65606.999 | G11: 67247.898 | H11: =I11-G11 -> 3762.1291 | I11: 71010.028 | J11: =(E11-I11)/I11 -> -0.076088252
A12: AEP Texas_NE7 | B12: 4 | C12: 66967.333 | D12: =E12-C12 -> 5357.3867 | E12: 72324.72 | G12: 86330.351 | H12: =I12-G12 -> 4728.5724 | I12: 91058.923 | J12: =(E12-I12)/I12 -> -0.20573715
A13: AEP Texas_NE8 | B13: 2 | C13: 59500 | D13: =E13-C13 -> 3570 | E13: 63070 | G13: 63916.987 | H13: =I13-G13 -> -367.69051 | I13: 63549.296 | J13: =(E13-I13)/I13 -> -0.0075421146
A14: AEP Texas_NE9 | B14: 17 | C14: 68746.203 | D14: =E14-C14 -> 5499.6962 | E14: 74245.899 | G14: 78688.971 | H14: =I14-G14 -> 0 | I14: 78688.971 | J14: =(E14-I14)/I14 -> -0.056463712
A15: AEP Texas_NE10 | B15: 3 | C15: 81115.379 | D15: =E15-C15 -> 7300.3841 | E15: 88415.763 | G15: 88530.189 | H15: =I15-G15 -> 4595.4396 | I15: 93125.628 | J15: =(E15-I15)/I15 -> -0.050575388
A16: AEP Texas_NE11 | B16: 16 | C16: 97327.613 | D16: =E16-C16 -> 9732.7613 | E16: 107060.37 | G16: 92191.658 | H16: =I16-G16 -> 1557.0419 | I16: 93748.7 | J16: =(E16-I16)/I16 -> 0.14199316
A17: AEP Texas_NE12 | B17: 8 | C17: 51458.635 | D17: =E17-C17 -> 2572.9317 | E17: 54031.567 | G17: 55759.884 | H17: =I17-G17 -> 1095.3976 | I17: 56855.281 | J17: =(E17-I17)/I17 -> -0.049664948
... A26: AEP Texas_NE21 | B26: 17 | C26: 62437.326 | D26: =E26-C26 -> 3746.2396 | E26: 66183.565 | G26: 54998.745 | H26: =I26-G26 -> 2371.0698 | I26: 57369.814 | J26: =(E26-I26)/I26 -> 0.15363046
A28: AEP Texas Count | B28: =COUNT(B6:B27) -> 21
A29: AEP Texas Incumbents | B29: =SUM(B6:B27) -> 201
A31: AEP SERVICE CORP
A32: SVC_NE1 | B32: 6 | C32: 64777.873 | D32: =E32-C32 -> 5182.2299 | E32: 69960.103 | G32: 74230.343 | H32: =I32-G32 -> 3471.1425 | I32: 77701.485 | J32: =(E32-I32)/I32 -> -0.099629779
A33: SVC_NE2 | B33: 16 | C33: 47948.692 | D33: =E33-C33 -> 2397.4346 | E33: 50346.127 | G33: 52496.01 | H33: =I33-G33 -> 947.64645 | I33: 53443.656 | J33: =(E33-I33)/I33 -> -0.057958784
A34: SVC_NE3 | B34: 57 | C34: 60975.062 | D34: =E34-C34 -> 3658.5037 | E34: 64633.565 | G34: 64062.461 | H34: =I34-G34 -> 753.91813 | I34: 64816.379 | J34: =(E34-I34)/I34 -> -0.0028204883
A35: SVC_NE4 | B35: 4 | C35: 40212.017 | D35: =E35-C35 -> 2010.6009 | E35: 42222.618 | G35: 46846.545 | H35: =I35-G35 -> 90.494763 | I35: 46937.039 | J35: =(E35-I35)/I35 -> -0.10044138
A36: SVC_NE5 | B36: 3 | C36: 59309.977 | D36: =E36-C36 -> 3558.5986 | E36: 62868.575 | G36: 56456.847 | H36: =I36-G36 -> 44.532416 | I36: 56501.379 | J36: =(E36-I36)/I36 -> 0.11269099
A37: SVC_NE6 | B37: 3 | C37: 70990.607 | D37: =E37-C37 -> 5679.2485 | E37: 76669.855 | G37: 66363.111 | H37: =I37-G37 -> 312.93738 | I37: 66676.049 | J37: =(E37-I37)/I37 -> 0.149886
A38: SVC_NE7 | B38: 3 | C38: 60342.5 | D38: =E38-C38 -> 3620.55 | E38: 63963.05 | G38: 69569.908 | H38: =I38-G38 -> 1625.639 | I38: 71195.547 | J38: =(E38-I38)/I38 -> -0.10158637
A39: SVC_NE8 | B39: 3 | C39: 71415.81 | D39: =E39-C39 -> 5713.2648 | E39: 77129.075 | G39: 74351.169 | H39: =I39-G39 -> 4789.369 | I39: 79140.538 | J39: =(E39-I39)/I39 -> -0.025416348
A40: SVC_NE9 | B40: 218 | C40: 49047.82 | D40: =E40-C40 -> 2452.391 | E40: 51500.211 | G40: 53514.331 | H40: =I40-G40 -> 1412.7203 | I40: 54927.051 | J40: =(E40-I40)/I40 -> -0.062388935
A41: SVC_NE10 | B41: 10 | C41: 53729.9 | D41: =E41-C41 -> 3223.794 | E41: 56953.694 | G41: 69180.019 | H41: =I41-G41 -> 4634.4677 | I41: 73814.487 | J41: =(E41-I41)/I41 -> -0.22842119
A42: SVC_NE11 | B42: 4 | C42: 52586.573 | D42: =E42-C42 -> 2629.3286 | E42: 55215.901 | G42: 55759.884 | H42: =I42-G42 -> 1095.3976 | I42: 56855.281 | J42: =(E42-I42)/I42 -> -0.028834262
A43: SVC_NE12 | B43: 6 | C43: 57011.097 | D43: =E43-C43 -> 3420.6658 | E43: 60431.762 | G43: 60391.138 | H43: =I43-G43 -> 3322.3689 | I43: 63713.507 | J43: =(E43-I43)/I43 -> -0.05150783
... A55: SVC_NE24 | B55: 4 | C55: 61111.772 | D55: =E55-C55 -> 3666.7064 | E55: 64778.479 | G55: 74558.095 | H55: =I55-G55 -> -0.09529 | I55: 74558 | J55: =(E55-I55)/I55 -> -0.13116662
A56: AEPSC Job Count | B56: =COUNT(B32:B55) -> 24
A57: AEPSC Incumbent Count | B57: =SUM(B32:B55) -> 516 | I57: AVERAGE | J57: =AVERAGE(J6:J55) -> -0.030216629
A58: TOTAL JOB COUNT | B58: =B56+B28 -> 45 | F58: % of Jobs Above Market Competitive Range3 | J58: =COUNTIF(J6:J55,">.1")/$B$58 -> 0.13333333
A59: TOTAL INCUMBENT Count | B59: =B57+B29 -> 717 | F59: % of Jobs Below Market Competitive Range3 | J59: =COUNTIF(J6:J55,"<-.1")/$B$58 -> 0.22222222
A61: Notes:
A62: (1) Survey Data from April 2023 Towers Watson Energy Services Middle Management, Professional & Support Survey and Towers Watson General Industry Middle Management Professional & Support Survey, aged toSeptember 30, 2023 @ 4% annual rate.
A63: (2) Reflects annual target incentive.
...

Sheet Graph Data
B1: L
A3: ='[1]Mkt data_12.31.2019'!A4 -> AEP Job | B3: AEP Target TCC vs. Survey Actual TCC | C3: Market Low | D3: Market Median Compensation | E3: Market Competitive Range | F3: Market Max
A4: AEP Texas_NE21 | B4: =VLOOKUP($A4,'non exempt'!$A:$J,10,FALSE)+1 -> 1.1536305 | C4: 0.9 | D4: 1 | E4: 0.2 | F4: 0.4
A5: SVC_NE6 | B5: =VLOOKUP($A5,'non exempt'!$A:$J,10,FALSE)+1 -> 1.149886 | C5: 0.9 | D5: 1 | E5: 0.2 | F5: 0.4
A6: AEP Texas_NE11 | B6: =VLOOKUP($A6,'non exempt'!$A:$J,10,FALSE)+1 -> 1.1419932 | C6: 0.9 | D6: 1 | E6: 0.2 | F6: 0.4
A7: SVC_NE5 | B7: =VLOOKUP($A7,'non exempt'!$A:$J,10,FALSE)+1 -> 1.112691 | C7: 0.9 | D7: 1 | E7: 0.2 | F7: 0.4
A8: AEP Texas_NE15 | B8: =VLOOKUP($A8,'non exempt'!$A:$J,10,FALSE)+1 -> 1.1040744 | C8: 0.9 | D8: 1 | E8: 0.2 | F8: 0.4
A9: AEP Texas_NE19 | B9: =VLOOKUP($A9,'non exempt'!$A:$J,10,FALSE)+1 -> 1.1032847 | C9: 0.9 | D9: 1 | E9: 0.2 | F9: 0.4
A10: AEP Texas_NE20 | B10: =VLOOKUP($A10,'non exempt'!$A:$J,10,FALSE)+1 -> 1.0511304 | C10: 0.9 | D10: 1 | E10: 0.2 | F10: 0.4
A11: AEP Texas_NE17 | B11: =VLOOKUP($A11,'non exempt'!$A:$J,10,FALSE)+1 -> 1.0211956 | C11: 0.9 | D11: 1 | E11: 0.2 | F11: 0.4
A12: AEP Texas_NE3 | B12: =VLOOKUP($A12,'non exempt'!$A:$J,10,FALSE)+1 -> 0.99749771 | C12: 0.9 | D12: 1 | E12: 0.2 | F12: 0.4
A13: SVC_NE3 | B13: =VLOOKUP($A13,'non exempt'!$A:$J,10,FALSE)+1 -> 0.99717951 | C13: 0.9 | D13: 1 | E13: 0.2 | F13: 0.4
A14: AEP Texas_NE8 | B14: =VLOOKUP($A14,'non exempt'!$A:$J,10,FALSE)+1 -> 0.99245789 | C14: 0.9 | D14: 1 | E14: 0.2 | F14: 0.4
A15: AEP Texas_NE18 | B15: =VLOOKUP($A15,'non exempt'!$A:$J,10,FALSE)+1 -> 0.97909993 | C15: 0.9 | D15: 1 | E15: 0.2 | F15: 0.4
... A35: AEP Texas_NE13 | B35: =VLOOKUP($A35,'non exempt'!$A:$J,10,FALSE)+1 -> 0.74580505 | C35: 0.9 | D35: 1 | E35: 0.2 | F35: 0.4
