Workbook
Name IQ_CH: 110000
Name IQ_CQ: 5000
Name IQ_CY: 10000
Name IQ_DAILY: 500000
Name IQ_FH: 100000
Name IQ_FQ: 500
Name IQ_FY: 1000
Name IQ_LTM: 2000
Name IQ_MONTH: 15000
Name IQ_NTM: 6000
Name IQ_WEEK: 50000
Name IQ_YTD: 3000

Sheet II-I-1
C2: PUBLIC UTILITY COMMISSION OF TEXAS
C3: AEP TEXAS INC
C4: II-I-1 CLASS REVENUE REQUIREMENT ANALYSIS
C5: TEST YEAR ENDING 09/30/2023
C6: DOCKET 56165
D8: 1 | E8: 2 | F8: 3 | G8: 4 | H8: 5 | I8: 6 | J8: 7 | K8: 8 | L8: 9
D9: Test Year
C10: Description | D10: Revenue | E10: Residential | F10: Secondary | G10: Secondary | H10: Primary | I10: Transmission | J10: Lighting | K10: Total | L10: BESS
A11: Line | B11: Ref | D11: Requirement | F11: =< 10 kW | G11: > 10 kW | K11: TX Retail
A12: No. | B12: Sch | D12: Total
A14: 1 | B14: IV-J-7 | C14: Transmission (ERCOT Matrix) | D14: 4.2854577e+08 | E14: 2.0657001e+08 | F14: 9203652.3 | G14: 1.2361279e+08 | H14: 39981726 | I14: 49177593 | K14: =SUM(E14:J14) -> 4.2854578e+08
A15: =+A14+1 -> 2 | C15: Distribution | D15: =+'II-I TOTAL COMPANY'!K75 -> 7.9827524e+08 | E15: =+Distribution!K75 -> 4.5485514e+08 | F15: =+Distribution!L75 -> 17570580 | G15: =+Distribution!N75+Distribution!O75 -> 2.3558577e+08 | H15: =+Distribution!Q75+Distribution!R75 -> 48232797 | I15: =+Distribution!T75 -> 4886329 | J15: =+Distribution!U75 -> 28747963 | K15: =SUM(E15:J15) -> 7.8987858e+08 | L15: =+Distribution!V75 -> 1861985.4
A16: =+A15+1 -> 3 | C16: Metering | D16: =+'II-I TOTAL COMPANY'!L75 -> 50185561 | E16: =+Meter!K75 -> 23527397 | F16: =+Meter!L75 -> 4470397.7 | G16: =+Meter!N75+Meter!O75 -> 17747327 | H16: =+Meter!Q75+Meter!R75 -> 2239528.6 | I16: =+Meter!T75 -> 2011888.2 | J16: =+Meter!U75 -> 7.5539466 | K16: =SUM(E16:J16) -> 49996546 | L16: =+Meter!V75 -> 41759.103
A17: =+A16+1 -> 4 | C17: Billling/Customer Service | D17: =+'II-I TOTAL COMPANY'!M75 -> 18851935 | E17: =+TDCustSvc!K75 -> 14986684 | F17: =+TDCustSvc!L75 -> 1592197 | G17: =+TDCustSvc!N75+TDCustSvc!O75 -> 1966806.3 | H17: =+TDCustSvc!Q75+TDCustSvc!R75 -> 27866.936 | I17: =+TDCustSvc!T75 -> 3357.327 | J17: =+TDCustSvc!U75 -> 272365.74 | K17: =SUM(E17:J17) -> 18849278 | L17: =+TDCustSvc!V75 -> 524.32801
A18: =+A17+1 -> 5
A19: =+A18+1 -> 6 | D19: =SUM(D14:D18) -> 1.2958585e+09 | E19: =SUM(E14:E18) -> 6.9993924e+08 | F19: =SUM(F14:F18) -> 32836827 | G19: =SUM(G14:G18) -> 3.7891269e+08 | H19: =SUM(H14:H18) -> 90481919 | I19: =SUM(I14:I18) -> 56079168 | J19: =SUM(J14:J18) -> 29020337 | K19: =SUM(K14:K18) -> 1.2872702e+09 | L19: =SUM(L14:L18) -> 1904268.8
C21: Acctg Schedule I-A | D21: =+D15+D16+D17 -> 8.6731274e+08
D23: =+'[1]I-A-1'!$K$29 -> 8.6731274e+08
D24: =+D21-D23 -> -0.17025912

Sheet II-I-2
B2: PUBLIC UTILITY COMMISSION OF TEXAS
B3: AEP TEXAS INC
B4: II-I-1-2 CLASS ALLOCATION FACTORS
B5: TEST YEAR ENDING 09/30/2023
B6: DOCKET 56165
A9: Line | B9: Description | C9: Allocation | D9: Residential | E9: Secondary | F9: Secondary | G9: Primary | H9: Transmission | I9: Lighting | J9: BESS | K9: Total
A10: No. | C10: Label | E10: =< 10 kW | F10: > 10 kW | K10: TX
A13: 1 | B13: =+Distribution!B669 -> Generation Demand TX 4CP | C13: =+Distribution!E669 -> DEMANDG | D13: =+Distribution!K669 -> 3260753.1 | E13: =+Distribution!L669 -> 128972.63 | F13: =+Distribution!M669 -> 1920489.8 | G13: =+Distribution!P669 -> 544116.53 | H13: =+Distribution!T669 -> 872123.19 | I13: =+Distribution!U669 -> 0 | J13: =+Distribution!V669 -> 0 | K13: =SUM(D13:J13) -> 6726455.3
A14: =+A13+1 -> 2 | B14: =+Distribution!B670 -> Retail Generation Demand | C14: =+Distribution!E670 -> TDEMANDG | D14: =+Distribution!K670 -> 3260753.1 | E14: =+Distribution!L670 -> 128972.63 | F14: =+Distribution!M670 -> 1920489.8 | G14: =+Distribution!P670 -> 544116.53 | H14: =+Distribution!T670 -> 872123.19 | I14: =+Distribution!U670 -> 0 | J14: =+Distribution!V670 -> 0 | K14: =SUM(D14:J14) -> 6726455.3
A15: =+A14+1 -> 3 | B15: =+Distribution!B671 -> Transmission Demands | C15: =+Distribution!E671 -> DEMANDT | D15: =+Distribution!K671 -> 2576796 | E15: =+Distribution!L671 -> 95632 | F15: =+Distribution!M671 -> 1558412 | G15: =+Distribution!P671 -> 578236 | H15: =+Distribution!T671 -> 596099 | I15: =+Distribution!U671 -> 0 | J15: =+Distribution!V671 -> 0 | K15: =SUM(D15:J15) -> 5405175
A16: =+A15+1 -> 4 | B16: =+Distribution!B672 -> Distribution Primary Demands - MDD | C16: =+Distribution!E672 -> DEMANDDP | D16: =+Distribution!K672 -> 4044549.9 | E16: =+Distribution!L672 -> 141089.14 | F16: =+Distribution!M672 -> 2127839.4 | G16: =+Distribution!P672 -> 730743.31 | H16: =+Distribution!T672 -> 0 | I16: =+Distribution!U672 -> 79180.024 | J16: =+Distribution!V672 -> 27135.076 | K16: =SUM(D16:J16) -> 7150536.9
A17: =+A16+1 -> 5 | B17: =+Distribution!B673 -> Distribution Secondary Demand | C17: =+Distribution!E673 -> DEMANDDS | D17: =+Distribution!K673 -> 4044549.9 | E17: =+Distribution!L673 -> 141089.14 | F17: =+Distribution!M673 -> 2127839.4 | G17: =+Distribution!P673 -> 0 | H17: =+Distribution!T673 -> 0 | I17: =+Distribution!U673 -> 79180.024 | J17: =+Distribution!V673 -> 0 | K17: =SUM(D17:J17) -> 6392658.5
A18: =+A17+1 -> 6 | B18: =+Distribution!B674 -> Energy | C18: =+Distribution!E674 -> ENERGY | D18: =+Distribution!K674 -> 1.2589883e+10 | E18: =+Distribution!L674 -> 6.7210011e+08 | F18: =+Distribution!M674 -> 9.2050572e+09 | G18: =+Distribution!P674 -> 4.5250716e+09 | H18: =+Distribution!T674 -> 1.1035697e+10 | I18: =+Distribution!U674 -> 2.383849e+08 | J18: =+Distribution!V674 -> 29603831 | K18: =SUM(D18:J18) -> 3.8295797e+10
A19: =+A18+1 -> 7 | B19: =+Distribution!B675 -> Non-Coincident Peaks | C19: =+Distribution!E675 -> NCP | D19: =+Distribution!K675 -> 79181811 | E19: =+Distribution!L675 -> 2897445.4 | F19: =+Distribution!M675 -> 31023216 | G19: =+Distribution!P675 -> 10189738 | H19: =+Distribution!T675 -> 25972434 | I19: =+Distribution!U675 -> 809370.8 | J19: =+Distribution!V675 -> 550613.44 | K19: =SUM(D19:J19) -> 1.5062463e+08
A20: =+A19+1 -> 8 | B20: =+Distribution!B676 -> Customers | C20: =+Distribution!E676 -> CUSTOMERS | D20: =+Distribution!K676 -> 935238 | E20: =+Distribution!L676 -> 99366 | F20: =+Distribution!M676 -> 72409 | G20: =+Distribution!P676 -> 1086 | H20: =+Distribution!T676 -> 123 | I20: =+Distribution!U676 -> 221390 | J20: =+Distribution!V676 -> 19 | K20: =SUM(D20:J20) -> 1329631
A21: =+A20+1 -> 9 | B21: =+Distribution!B677 -> Distribution Customers | C21: =+Distribution!E677 -> DCUSTOMERS | D21: =+Distribution!K677 -> 935238 | E21: =+Distribution!L677 -> 99366 | F21: =+Distribution!M677 -> 72409 | G21: =+Distribution!P677 -> 1086 | H21: =+Distribution!T677 -> 0 | I21: =+Distribution!U677 -> 220232 | J21: =+Distribution!V677 -> 19 | K21: =SUM(D21:J21) -> 1328350
A22: =+A21+1 -> 10 | B22: =+Distribution!B678 -> Services Account 369 | C22: =+Distribution!E678 -> SERVICES | D22: =+Distribution!K678 -> 935238 | E22: =+Distribution!L678 -> 94498 | F22: =+Distribution!M678 -> 125662 | G22: =+Distribution!P678 -> 0 | H22: =+Distribution!T678 -> 0 | I22: =+Distribution!U678 -> 0 | J22: =+Distribution!V678 -> 0 | K22: =SUM(D22:J22) -> 1155398
A23: =+A22+1 -> 11 | B23: =+Distribution!B679 -> Meters Account 370 | C23: =+Distribution!E679 -> METERS | D23: =+Distribution!K679 -> 935238 | E23: =+Distribution!L679 -> 177705.24 | F23: =+Distribution!M679 -> 705477.84 | G23: =+Distribution!P679 -> 94875.887 | H23: =+Distribution!T679 -> 79975.918 | I23: =+Distribution!U679 -> 0 | J23: =+Distribution!V679 -> 1659.8912 | K23: =SUM(D23:J23) -> 1994932.8
A24: =+A23+1 -> 12 | B24: =+Distribution!B680 -> Non-Roadway Lighting Account 371 | C24: =+Distribution!E680 -> NROADLIGHT | D24: =+Distribution!K680 -> 0 | E24: =+Distribution!L680 -> 0 | F24: =+Distribution!M680 -> 0 | G24: =+Distribution!P680 -> 0 | H24: =+Distribution!T680 -> 0 | I24: =+Distribution!U680 -> 1.1290995e+08 | J24: =+Distribution!V680 -> 0 | K24: =SUM(D24:J24) -> 1.1290995e+08
A25: =+A24+1 -> 13 | B25: =+Distribution!B681 -> Roadway Lighting Account 373 | C25: =+Distribution!E681 -> ROADLIGHT | D25: =+Distribution!K681 -> 0 | E25: =+Distribution!L681 -> 0 | F25: =+Distribution!M681 -> 0 | G25: =+Distribution!P681 -> 0 | H25: =+Distribution!T681 -> 0 | I25: =+Distribution!U681 -> 1.2547495e+08 | J25: =+Distribution!V681 -> 0 | K25: =SUM(D25:J25) -> 1.2547495e+08
... A83: =+A82+1 -> 71 | B83: =+Distribution!B739 -> Excess Mitigation Credit | C83: =+Distribution!E739 -> EMC | D83: =+Distribution!K739 -> 0 | E83: =+Distribution!L739 -> 0 | F83: =+Distribution!M739 -> 0 | G83: =+Distribution!P739 -> 0 | H83: =+Distribution!T739 -> 0 | I83: =+Distribution!U739 -> 0 | J83: =+Distribution!V739 -> 0 | K83: =SUM(D83:J83) -> 0

Sheet II-I-2.c
B2: PUBLIC UTILITY COMMISSION OF TEXAS
B3: AEP TEXAS INC
B4: II-I-1-2 CLASS ALLOCATION FACTORS
B5: TEST YEAR ENDING 09/30/2023
B6: DOCKET 56165
A9: Line | B9: Description | C9: Allocation | D9: Residential | E9: Secondary | F9: Secondary | G9: Primary | H9: Transmission | I9: Lighting | J9: BESS | K9: Total
A10: No. | C10: Label | E10: =< 10 kW | F10: > 10 kW | K10: TX
A13: 1 | B13: =+Distribution!B741 -> Generation Demand TX 4CP | C13: =+Distribution!E741 -> DEMANDG | D13: =+Distribution!K741 -> 0.48476544 | E13: =+Distribution!L741 -> 0.019173937 | F13: =+Distribution!M741 -> 0.28551292 | G13: =+Distribution!P741 -> 0.080892017 | H13: =+Distribution!T741 -> 0.12965569 | I13: =+Distribution!U741 -> 0 | J13: =+Distribution!V741 -> 0 | K13: =SUM(D13:J13) -> 1
A14: =+A13+1 -> 2 | B14: =+Distribution!B742 -> Retail Generation Demand | C14: =+Distribution!E742 -> TDEMANDG | D14: =+Distribution!K742 -> 0.48476544 | E14: =+Distribution!L742 -> 0.019173937 | F14: =+Distribution!M742 -> 0.28551292 | G14: =+Distribution!P742 -> 0.080892017 | H14: =+Distribution!T742 -> 0.12965569 | I14: =+Distribution!U742 -> 0 | J14: =+Distribution!V742 -> 0 | K14: =SUM(D14:J14) -> 1
A15: =+A14+1 -> 3 | B15: =+Distribution!B743 -> Transmission Demands | C15: =+Distribution!E743 -> DEMANDT | D15: =+Distribution!K743 -> 0.47672758 | E15: =+Distribution!L743 -> 0.017692674 | F15: =+Distribution!M743 -> 0.28831851 | G15: =+Distribution!P743 -> 0.10697822 | H15: =+Distribution!T743 -> 0.11028302 | I15: =+Distribution!U743 -> 0 | J15: =+Distribution!V743 -> 0 | K15: =SUM(D15:J15) -> 1
A16: =+A15+1 -> 4 | B16: =+Distribution!B744 -> Distribution Primary Demands - MDD | C16: =+Distribution!E744 -> DEMANDDP | D16: =+Distribution!K744 -> 0.56562885 | E16: =+Distribution!L744 -> 0.019731265 | F16: =+Distribution!M744 -> 0.29757757 | G16: =+Distribution!P744 -> 0.10219419 | H16: =+Distribution!T744 -> 0 | I16: =+Distribution!U744 -> 0.011073298 | J16: =+Distribution!V744 -> 0.0037948306 | K16: =SUM(D16:J16) -> 1
A17: =+A16+1 -> 5 | B17: =+Distribution!B745 -> Distribution Secondary Demand | C17: =+Distribution!E745 -> DEMANDDS | D17: =+Distribution!K745 -> 0.63268669 | E17: =+Distribution!L745 -> 0.022070496 | F17: =+Distribution!M745 -> 0.33285673 | G17: =+Distribution!P745 -> 0 | H17: =+Distribution!T745 -> 0 | I17: =+Distribution!U745 -> 0.012386087 | J17: =+Distribution!V745 -> 0 | K17: =SUM(D17:J17) -> 1
A18: =+A17+1 -> 6 | B18: =+Distribution!B746 -> Energy | C18: =+Distribution!E746 -> ENERGY | D18: =+Distribution!K746 -> 0.32875364 | E18: =+Distribution!L746 -> 0.017550232 | F18: =+Distribution!M746 -> 0.2403673 | G18: =+Distribution!P746 -> 0.11816105 | H18: =+Distribution!T746 -> 0.28816992 | I18: =+Distribution!U746 -> 0.0062248319 | J18: =+Distribution!V746 -> 0.00077303081 | K18: =SUM(D18:J18) -> 1
A19: =+A18+1 -> 7 | B19: =+Distribution!B747 -> Non-Coincident Peaks | C19: =+Distribution!E747 -> NCP | D19: =+Distribution!K747 -> 0.52568967 | E19: =+Distribution!L747 -> 0.019236199 | F19: =+Distribution!M747 -> 0.20596377 | G19: =+Distribution!P747 -> 0.067649878 | H19: =+Distribution!T747 -> 0.17243152 | I19: =+Distribution!U747 -> 0.0053734293 | J19: =+Distribution!V747 -> 0.0036555339 | K19: =SUM(D19:J19) -> 1
A20: =+A19+1 -> 8 | B20: =+Distribution!B748 -> Customers | C20: =+Distribution!E748 -> CUSTOMERS | D20: =+Distribution!K748 -> 0.70338161 | E20: =+Distribution!L748 -> 0.074732012 | F20: =+Distribution!M748 -> 0.054457966 | G20: =+Distribution!P748 -> 0.00081676796 | H20: =+Distribution!T748 -> 9.2506868e-05 | I20: =+Distribution!U748 -> 0.16650484 | J20: =+Distribution!V748 -> 1.4289679e-05 | K20: =SUM(D20:J20) -> 1
A21: =+A20+1 -> 9 | B21: =+Distribution!B749 -> Distribution Customers | C21: =+Distribution!E749 -> DCUSTOMERS | D21: =+Distribution!K749 -> 0.70405992 | E21: =+Distribution!L749 -> 0.07480408 | F21: =+Distribution!M749 -> 0.054510483 | G21: =+Distribution!P749 -> 0.00081755561 | H21: =+Distribution!T749 -> 0 | I21: =+Distribution!U749 -> 0.16579365 | J21: =+Distribution!V749 -> 1.4303459e-05 | K21: =SUM(D21:J21) -> 1
A22: =+A21+1 -> 10 | B22: =+Distribution!B750 -> Services Account 369 | C22: =+Distribution!E750 -> SERVICES | D22: =+Distribution!K750 -> 0.80945094 | E22: =+Distribution!L750 -> 0.081788267 | F22: =+Distribution!M750 -> 0.10876079 | G22: =+Distribution!P750 -> 0 | H22: =+Distribution!T750 -> 0 | I22: =+Distribution!U750 -> 0 | J22: =+Distribution!V750 -> 0 | K22: =SUM(D22:J22) -> 1
A23: =+A22+1 -> 11 | B23: =+Distribution!B751 -> Meters Account 370 | C23: =+Distribution!E751 -> METERS | D23: =+Distribution!K751 -> 0.46880677 | E23: =+Distribution!L751 -> 0.08907831 | F23: =+Distribution!M751 -> 0.35363489 | G23: =+Distribution!P751 -> 0.047558438 | H23: =+Distribution!T751 -> 0.04008953 | I23: =+Distribution!U751 -> 0 | J23: =+Distribution!V751 -> 0.00083205371 | K23: =SUM(D23:J23) -> 1
A24: =+A23+1 -> 12 | B24: =+Distribution!B752 -> Non-Roadway Lighting Account 371 | C24: =+Distribution!E752 -> NROADLIGHT | D24: =+Distribution!K752 -> 0 | E24: =+Distribution!L752 -> 0 | F24: =+Distribution!M752 -> 0 | G24: =+Distribution!P752 -> 0 | H24: =+Distribution!T752 -> 0 | I24: =+Distribution!U752 -> 1 | J24: =+Distribution!V752 -> 0 | K24: =SUM(D24:J24) -> 1
A25: =+A24+1 -> 13 | B25: =+Distribution!B753 -> Roadway Lighting Account 373 | C25: =+Distribution!E753 -> ROADLIGHT | D25: =+Distribution!K753 -> 0 | E25: =+Distribution!L753 -> 0 | F25: =+Distribution!M753 -> 0 | G25: =+Distribution!P753 -> 0 | H25: =+Distribution!T753 -> 0 | I25: =+Distribution!U753 -> 1 | J25: =+Distribution!V753 -> 0 | K25: =SUM(D25:J25) -> 1
... A83: =+A82+1 -> 71 | B83: =+Distribution!B811 -> Excess Mitigation Credit | C83: =+Distribution!E811 -> EMC | D83: =+Distribution!K811 -> 0 | E83: =+Distribution!L811 -> 0 | F83: =+Distribution!M811 -> 0 | G83: =+Distribution!P811 -> 0 | H83: =+Distribution!T811 -> 0 | I83: =+Distribution!U811 -> 0 | J83: =+Distribution!V811 -> 0 | K83: =SUM(D83:J83) -> 0

Sheet II-I-2.f
B2: PUBLIC UTILITY COMMISSION OF TEXAS
B3: AEP TEXAS INC
B4: II-I-1-2 CLASS ALLOCATION RATIONALE
B5: TEST YEAR ENDING 09/30/2023
B6: DOCKET 56165
A9: Acct | B9: Description | C9: Function | D9: Allocation | E9: Description of Allocation | F9: Rationale
A10: No. | D10: Factor
B13: PLANT IN SERVICE
B14: Intangible Plant
A15: 301 | B15: Organization | C15: TDCS | D15: LABOR | E15: Labor for AEP Texas and Service Company | F15: Related to functionalized labor
A16: 303 | B16: Misc Intangible Plant | C16: DIST | D16: LABOR | E16: Labor for AEP Texas and Service Company | F16: Related to functionalized labor
A17: 303 | B17: Misc Intangible Plant | C17: MET | D17: LABOR | E17: Labor for AEP Texas and Service Company | F17: Related to functionalized labor
A18: 303 | B18: Misc Intangible Plant | C18: TDCS | D18: LABOR | E18: Labor for AEP Texas and Service Company | F18: Related to functionalized labor
B20: Transmission Plant
A21: 350-359 | B21: Transmission Plant | C21: TRAN | D21: TRANPLT | E21: N/A | F21: N/A
B23: Distribution Plant
A24: 360-363 | B24: Accounts 360-363 | C24: DIST | D24: DEMANDDP | E24: Distribution Primary Demands (MDD) | F24: Related to customer demand
A25: 364 | B25: Poles,Towers & Fixtures Primary | C25: DIST | D25: DEMANDDP | E25: Distribution Primary Demands (MDD) | F25: Related to customer demand
A26: 364 | B26: Poles,Towers & Fixtures Secondary | C26: DIST | D26: DEMANDDP | E26: Distribution Primary Demands (MDD) | F26: Related to customer demand
A27: 365 | B27: O.H. Conductors & Devices Primary | C27: DIST | D27: DEMANDDP | E27: Distribution Primary Demands (MDD) | F27: Related to customer demand
A28: 365 | B28: O.H. Conductors & Devices Secondary | C28: DIST | D28: DEMANDDS | E28: Distribution Secondary Demands (MDD) | F28: Related to customer demand
A29: 366 | B29: Underground Conduits Primary | C29: DIST | D29: DEMANDDP | E29: Distribution Primary Demands (MDD) | F29: Related to customer demand
A30: 366 | B30: Underground Conduits Secondary | C30: DIST | D30: DEMANDDS | E30: Distribution Secondary Demands (MDD) | F30: Related to customer demand
A31: 367 | B31: U.G. Conductors & Devices Primary | C31: DIST | D31: DEMANDDP | E31: Distribution Primary Demands (MDD) | F31: Related to customer demand
A32: 367 | B32: U.G. Conductors & Devices Secondary | C32: DIST | D32: DEMANDDS | E32: Distribution Secondary Demands (MDD) | F32: Related to customer demand
A33: 368 | B33: Line Transformers Primary | C33: DIST | D33: DEMANDDP | E33: Distribution Primary Demands (MDD) | F33: Related to customer demand
A34: 368 | B34: Line Transformers Secondary | C34: DIST | D34: DEMANDDS | E34: Distribution Secondary Demands (MDD) | F34: Related to customer demand
A35: 369 | B35: Services | C35: DIST | D35: SERVICES | E35: Services Account 369 | F35: Related to customer count
A36: 370 | B36: Meters | C36: DIST | D36: METERS | E36: Meters Account 370 | F36: Related to customer count
... A39: 373 | B39: Street Lights | C39: DIST | D39: ROADLIGHT | E39: Roadway Lighting Account 373 | F39: Related to fixture count
B41: General Plant
A42: 389-399 | B42: General Plant | C42: DIST | D42: LABOR | E42: Labor for AEP Texas and Service Company | F42: Related to functionalized labor
A43: 389-399 | B43: General Plant | C43: MET | D43: LABOR | E43: Labor for AEP Texas and Service Company | F43: Related to functionalized labor
A44: 389-399 | B44: General Plant | C44: TDCS | D44: LABOR | E44: Labor for AEP Texas and Service Company | F44: Related to functionalized labor
A45: 397 | B45: Communicaiton Equipment | C45: DIST | D45: LABOR | E45: Labor for AEP Texas and Service Company | F45: Related to functionalized labor
A46: 398 | B46: Communicaiton Equipment | C46: MET | D46: LABOR | E46: Labor for AEP Texas and Service Company | F46: Related to functionalized labor
A47: 399 | B47: Communicaiton Equipment | C47: TDCS | D47: LABOR | E47: Labor for AEP Texas and Service Company | F47: Related to functionalized labor
B49: Accumulated Depreciation
B50: Intangible Plant Accum. Depr.
A51: 303 | B51: Misc Intangible Plant | C51: DIST | D51: LABOR | E51: Labor for AEP Texas and Service Company | F51: Depreciation allocated based on plant
...

Sheet II-I TOTAL COMPANY
D1: 1 | E1: 2 | H1: 7 | J1: 3 | K1: =J1+1 -> 4 | L1: =K1+1 -> 5 | M1: =L1+1 -> 6
B4: PUBLIC UTILITY COMMISION OF TEXAS
B5: AEP TEXAS INC
B6: II-I COST OF SERVICE
B7: TEST YEAR ENDING 09/30/2023
B8: DOCKET 56165
A10: Line | B10: Account | C10: Description | D10: Fuctionalization | E10: Reference | F10: Total AEP TX | G10: Difference | H10: Total AEP Texas | J10: Functionalized | K10: Functionalized | L10: Functionalized | M10: Functionalized | N10: INPUT | P10: Verification
A11: No. | B11: No. | D11: FACTOR | E11: Schedule | F11: As Filed | J11: TRANSMISSION | K11: DISTRIBUTION | L11: T&D METERING | M11: T&D CUST SERV
A12: (1) | B12: (2) | C12: (3) | D12: (4) | E12: (5) | H12: (6) | J12: (7) | K12: (8) | M12: (10)
B13: Schedule I-A Cost of Service by Function | N13: INPUT | P13: Verification
B15: Summary of Results @ Present ROR
A17: 1 | B17: Rate Base by Function
A18: =+A17+1 -> 2 | B18: Plant Investment
A19: =+A18+1 -> 3 | C19: Intangible | F19: =+H19 -> 1.5606761e+08 | G19: =+H19-F19 -> 0 | H19: =SUM(J19:M19) -> 1.5606761e+08 | J19: =+J96 -> 0 | K19: =+K96 -> 1.5236904e+08 | L19: =+L96 -> 3698361.7 | M19: =+M96 -> 212.22859
A20: =+A19+1 -> 4 | C20: Transmission | F20: =+H20 -> 0 | G20: =+H20-F20 -> 0 | H20: =SUM(J20:M20) -> 0 | J20: =+J111 -> 0 | K20: =+K111 -> 0 | L20: =+L111 -> 0 | M20: =+M111 -> 0
A21: =+A20+1 -> 5 | C21: Distribution | F21: =+H21 -> 5.7424589e+09 | G21: =+H21-F21 -> 0 | H21: =SUM(J21:M21) -> 5.7424589e+09 | J21: =+J147 -> 0 | K21: =+K147 -> 5.530937e+09 | L21: =+L147 -> 2.1152186e+08 | M21: =+M147 -> 0
A22: =+A21+1 -> 6 | C22: General | F22: =+H22 -> 6.660567e+08 | G22: =+H22-F22 -> 0 | H22: =SUM(J22:M22) -> 6.660567e+08 | J22: =+J162+J168 -> 0 | K22: =+K162+K168 -> 6.5153933e+08 | L22: =+L162+L168 -> 9067590.5 | M22: =+M162+M168 -> 5449781.4
A23: =+A22+1 -> 7
A24: =+A23+1 -> 8 | B24: Total Plant Investment | F24: =SUM(F19:F23) -> 6.5645832e+09 | G24: =SUM(G19:G23) -> 0 | H24: =SUM(J24:M24) -> 6.5645832e+09 | J24: =SUM(J19:J23) -> 0 | K24: =SUM(K19:K23) -> 6.3348454e+09 | L24: =SUM(L19:L23) -> 2.2428781e+08 | M24: =SUM(M19:M23) -> 5449993.6
A25: =+A24+1 -> 9
A26: =+A25+1 -> 10 | C26: Less Accumulated Depreciation | F26: =+H26 -> -1.6725996e+09 | G26: =+H26-F26 -> 0 | H26: =SUM(J26:M26) -> -1.6725996e+09 | J26: =-J247 -> 0 | K26: =-K247 -> -1.5577575e+09 | L26: =-L247 -> -1.1381186e+08 | M26: =-M247 -> -1030145.8
A27: =+A26+1 -> 11
A28: =+A27+1 -> 12 | B28: Net Plant Investment | F28: =SUM(F24:F26) -> 4.8919836e+09 | G28: =SUM(G24:G26) -> 0 | H28: =SUM(J28:M28) -> 4.8919836e+09 | J28: =+J24+J26 -> 0 | K28: =+K24+K26 -> 4.7770878e+09 | L28: =+L24+L26 -> 1.1047595e+08 | M28: =+M24+M26 -> 4419847.8
A29: =+A28+1 -> 13
A30: =+A29+1 -> 14 | B30: Material and Supplies | F30: =+H30 -> 1.1803546e+08 | G30: =+H30-F30 -> 0 | H30: =SUM(J30:M30) -> 1.1803546e+08 | J30: =+J266 -> 0 | K30: =+K266 -> 1.1523846e+08 | L30: =+L266 -> 2797003.6 | M30: =+M266 -> 0
A31: =+A30+1 -> 15 | B31: Cash Working Capital | F31: =+H31 -> -16937327 | G31: =+H31-F31 -> 0 | H31: =SUM(J31:M31) -> -16937327 | J31: =+J270 -> 0 | K31: =+K270 -> -16416706 | L31: =+L270 -> -467377.98 | M31: =+M270 -> -53243.142
A32: =+A31+1 -> 16 | B32: Prepayments | F32: =+H32 -> 80201587 | G32: =+H32-F32 -> 0 | H32: =SUM(J32:M32) -> 80201587 | J32: =+J276 -> 0 | K32: =+K276 -> 57619309 | L32: =+L276 -> 12780986 | M32: =+M276 -> 9801291.6
A33: =+A32+1 -> 17 | B33: Other Rate Base | F33: =+H33 -> -2.5206533e+08 | G33: =+H33-F33 -> 0 | H33: =SUM(J33:M33) -> -2.5206533e+08 | J33: =+J253+J259+J292 -> 0 | K33: =+K253+K259+K292 -> -2.5972059e+08 | L33: =+L253+L259+L292 -> 7523261.8 | M33: =+M253+M259+M292 -> 131997.36
A34: =+A33+1 -> 18 | B34: Accumulated Deferred Income Taxes | F34: =+H34 -> -5.7272313e+08 | G34: =+H34-F34 -> 0 | H34: =SUM(J34:M34) -> -5.7272313e+08 | J34: =+J306 -> 0 | K34: =+K306 -> -5.5590275e+08 | L34: =+L306 -> -15875665 | M34: =+M306 -> -944718.08
A35: =+A34+1 -> 19 | B35: Customer Deposits | F35: =+H35 -> -42130 | G35: =+H35-F35 -> 0 | H35: =SUM(J35:M35) -> -42130 | K35: =K271 -> -42130 | L35: =L271 -> 0 | M35: =M271 -> 0
A36: =+A35+1 -> 20 | B36: Total Rate Base | F36: =SUM(F28:F35) -> 4.2484528e+09 | G36: =SUM(G28:G34) -> 0 | H36: =SUM(J36:M36) -> 4.2484528e+09 | J36: =SUM(J28:J35) -> 0 | K36: =SUM(K28:K35) -> 4.1178634e+09 | L36: =SUM(L28:L35) -> 1.1723416e+08 | M36: =SUM(M28:M35) -> 13355176
A37: =+A36+1 -> 21
A38: =+A37+1 -> 22
A39: =+A38+1 -> 23 | B39: Current Tariff Revenues | F39: =+H39 -> 5.8173587e+08 | G39: =+H39-F39 -> 0 | H39: =SUM(J39:M39) -> 5.8173587e+08 | K39: =+'[2]II-H-4.1 Functions'!$F$213 -> 5.0555742e+08 | L39: =+'[2]II-H-4.1 Functions'!$E$213 -> 56905339 | M39: =+'[2]II-H-4.1 Functions'!$D$213 -> 19273107 | N39: Sch H
A40: =+A39+1 -> 24 | B40: Current Miscellaneous Revenues | F40: =+H40 -> 26846753 | G40: =+H40-F40 -> 0 | H40: =SUM(J40:M40) -> 26846753 | J40: =+J664 -> 0 | K40: =+K664 -> 25990116 | L40: =+L664 -> 856637.48 | M40: =+M664 -> 0
A41: =+A40+1 -> 25 | B41: Current TCRF Revenues | F41: =+H41 -> 0 | G41: =+H41-F41 -> 0 | H41: =SUM(J41:M41) -> 0 | J41: =+J665 -> 0 | K41: 0 | L41: =+L665 -> 0 | M41: =+M665 -> 0
A42: =+A41+1 -> 26 | B42: Current Rider Revenues | F42: =+H42 -> 0 | G42: =+H42-F42 -> 0 | H42: =SUM(J42:M42) -> 0 | J42: 0 | L42: 0 | M42: 0
A43: =+A42+1 -> 27 | B43: Current Total Revenues | F43: =SUM(F39:F42) -> 6.0858262e+08 | G43: =SUM(G39:G42) -> 0 | H43: =SUM(J43:M43) -> 6.0858262e+08 | J43: =SUM(J39:J42) -> 0 | K43: =SUM(K39:K42) -> 5.3154754e+08 | L43: =SUM(L39:L42) -> 57761977 | M43: =SUM(M39:M42) -> 19273107
A44: =+A43+1 -> 28
A45: =+A44+1 -> 29 | B45: Operation & Maintenance | F45: =+H45 -> 2.0133135e+08 | G45: =+H45-F45 -> 0 | H45: =SUM(J45:M45) -> 2.0133135e+08 | J45: =+J429 -> 0 | K45: =+K429 -> 1.6039674e+08 | L45: =+L429 -> 24275503 | M45: =+M429 -> 16659108
...

Sheet Juris Alloc Split
D1: 1 | E1: 2 | F1: 7 | G1: 13 | H1: 4
B3: ='II-I TOTAL COMPANY'!B4 -> PUBLIC UTILITY COMMISION OF TEXAS
B4: ='II-I TOTAL COMPANY'!B5 -> AEP TEXAS INC
B5: ='II-I TOTAL COMPANY'!B6 -> II-I COST OF SERVICE
B6: ='II-I TOTAL COMPANY'!B7 -> TEST YEAR ENDING 09/30/2023
B7: DOCKET 56165 | E7: Jurisdictional Split
A10: Line | B10: Account | C10: Description | E10: Reference | F10: Total | G10: Oth Jurisdiction | H10: Texas Retail | I10: Retail | J10: Distribution | K10: Dist Other | L10: Distr Retail | M10: Dist Retail | N10: Check
A11: No. | B11: No. | D11: ALLOC | E11: Schedule | F11: AEP TX | I11: Jurisdiction | J11: Total | K11: Jurisdiction | L11: Jurisdiction | M11: Allocation | N11: Column
A12: -1 | B12: =+A12-1 -> -2 | C12: =+B12-1 -> -3 | D12: =+C12-1 -> -4 | E12: =+D12-1 -> -5 | F12: =+E12-1 -> -6 | G12: =+F12-1 -> -7 | H12: =+G12-1 -> -8
B13: Schedule I-A Cost of Service by Function
B15: Schedule II-B-1 Original Cost of Utility Plant
A17: 1 | B17: Intangible Plant
A18: =+A17+1 -> 2 | B18: A301 | C18: Organization | F18: =+'II-I TOTAL COMPANY'!H93 -> 18123.34 | G18: =+Distribution!I93+Meter!I93+TDCustSvc!I93 -> 0 | H18: =+Distribution!J93+Meter!J93+TDCustSvc!J93 -> 18123.34 | I18: =IFERROR(+H18/F18,0) -> 1 | J18: =+Distribution!H93+Meter!H93+TDCustSvc!H93 -> 18123.34 | K18: =+Distribution!I93+Meter!I93+TDCustSvc!I93 -> 0 | L18: =+Distribution!J93+Meter!J93+TDCustSvc!J93 -> 18123.34 | M18: =IFERROR(+L18/J18,0) -> 1
A19: =+A18+1 -> 3 | B19: A303 | C19: Miscellaneous Intangible Plant | F19: =+'II-I TOTAL COMPANY'!H94 -> 0 | G19: =+Distribution!I94+Meter!I94+TDCustSvc!I94 -> 0 | H19: =Distribution!J94+Meter!J94+TDCustSvc!J94 -> 0 | I19: =IFERROR(+H19/F19,0) -> 0 | J19: =+Distribution!H94+Meter!H94+TDCustSvc!H94 -> 0 | K19: =+Distribution!I94+Meter!I94+TDCustSvc!I94 -> 0 | L19: =+Distribution!J94+Meter!J94+TDCustSvc!J94 -> 0 | M19: =IFERROR(+L19/J19,0) -> 0 | N19: =IF(SUM(G19+H19)=F19,"OK",0) -> OK
A20: =+A19+1 -> 4 | B20: A303 | C20: Miscellaneous Intangible Plant | F20: =+'II-I TOTAL COMPANY'!H95 -> 1.5604949e+08 | G20: =+Distribution!I95+Meter!I95+TDCustSvc!I95 -> 0 | H20: =+Distribution!J95+Meter!J95+TDCustSvc!J95 -> 1.5604949e+08 | I20: =IFERROR(+H20/F20,0) -> 1 | J20: =+Distribution!H95+Meter!H95+TDCustSvc!H95 -> 1.5604949e+08 | K20: =+Distribution!I95+Meter!I95+TDCustSvc!I95 -> 0 | L20: =+Distribution!J95+Meter!J95+TDCustSvc!J95 -> 1.5604949e+08 | M20: =IFERROR(+L20/J20,0) -> 1 | N20: =IF(SUM(G20+H20)=F20,"OK",0) -> OK
A21: =+A20+1 -> 5 | C21: Total Intangible Plant | F21: =+'II-I TOTAL COMPANY'!H96 -> 1.5606761e+08 | G21: =+Distribution!I96+Meter!I96+TDCustSvc!I96 -> 0 | H21: =+Distribution!J96+Meter!J96+TDCustSvc!J96 -> 1.5606761e+08 | I21: =+H21/F21 -> 1 | J21: =+Distribution!H96+Meter!H96+TDCustSvc!H96 -> 1.5606761e+08 | K21: =+Distribution!I96+Meter!I96+TDCustSvc!I96 -> 0 | L21: =+Distribution!J96+Meter!J96+TDCustSvc!J96 -> 1.5606761e+08 | M21: =+L21/J21 -> 1 | N21: =IF(SUM(G21+H21)=F21,"OK",0) -> OK
A22: =+A21+1 -> 6 | N22: =IF(SUM(G22+H22)=F22,"OK",0) -> OK
A23: =+A22+1 -> 7 | B23: Schedule II-B-1 Original Cost of Utility Plant (Continued) | N23: =IF(SUM(G23+H23)=F23,"OK",0) -> OK
A24: =+A23+1 -> 8 | N24: =IF(SUM(G24+H24)=F24,"OK",0) -> OK
A25: =+A24+1 -> 9 | B25: Transmission Plant | N25: =IF(SUM(G25+H25)=F25,"OK",0) -> OK
A26: =+A25+1 -> 10 | B26: A350 | C26: Land and Land Rights | F26: =+'II-I TOTAL COMPANY'!H101 -> 0 | G26: =+Distribution!I101+Meter!I101+TDCustSvc!I101 -> 0 | H26: =+Distribution!J101+Meter!J101+TDCustSvc!J101 -> 0 | I26: =IFERROR(+H26/F26,) -> 0 | J26: =+Distribution!H101+Meter!H101+TDCustSvc!H101 -> 0 | K26: =+Distribution!I101+Meter!I101+TDCustSvc!I101 -> 0 | L26: =+Distribution!J101+Meter!J101+TDCustSvc!J101 -> 0 | M26: =IFERROR(+L26/J26,0) -> 0 | N26: =IF(SUM(G26+H26)=F26,"OK",0) -> OK
A27: =+A26+1 -> 11 | B27: A352 | C27: Structures and Improvements | F27: =+'II-I TOTAL COMPANY'!H102 -> 0 | G27: =+Distribution!I102+Meter!I102+TDCustSvc!I102 -> 0 | H27: =+Distribution!J102+Meter!J102+TDCustSvc!J102 -> 0 | I27: =IFERROR(+H27/F27,) -> 0 | J27: =+Distribution!H102+Meter!H102+TDCustSvc!H102 -> 0 | K27: =+Distribution!I102+Meter!I102+TDCustSvc!I102 -> 0 | L27: =+Distribution!J102+Meter!J102+TDCustSvc!J102 -> 0 | M27: =IFERROR(+L27/J27,0) -> 0 | N27: =IF(SUM(G27+H27)=F27,"OK",0) -> OK
A28: =+A27+1 -> 12 | B28: A353 | C28: Station Equipment | F28: =+'II-I TOTAL COMPANY'!H103 -> 0 | G28: =+Distribution!I103+Meter!I103+TDCustSvc!I103 -> 0 | H28: =+Distribution!J103+Meter!J103+TDCustSvc!J103 -> 0 | I28: =IFERROR(+H28/F28,) -> 0 | J28: =+Distribution!H103+Meter!H103+TDCustSvc!H103 -> 0 | K28: =+Distribution!I103+Meter!I103+TDCustSvc!I103 -> 0 | L28: =+Distribution!J103+Meter!J103+TDCustSvc!J103 -> 0 | M28: =IFERROR(+L28/J28,0) -> 0 | N28: =IF(SUM(G28+H28)=F28,"OK",0) -> OK
A29: =+A28+1 -> 13 | B29: A354 | C29: Towers and Fixtures | F29: =+'II-I TOTAL COMPANY'!H104 -> 0 | G29: =+Distribution!I104+Meter!I104+TDCustSvc!I104 -> 0 | H29: =+Distribution!J104+Meter!J104+TDCustSvc!J104 -> 0 | I29: =IFERROR(+H29/F29,) -> 0 | J29: =+Distribution!H104+Meter!H104+TDCustSvc!H104 -> 0 | K29: =+Distribution!I104+Meter!I104+TDCustSvc!I104 -> 0 | L29: =+Distribution!J104+Meter!J104+TDCustSvc!J104 -> 0 | M29: =IFERROR(+L29/J29,0) -> 0 | N29: =IF(SUM(G29+H29)=F29,"OK",0) -> OK
A30: =+A29+1 -> 14 | B30: A355 | C30: Poles and Fixtures | F30: =+'II-I TOTAL COMPANY'!H105 -> 0 | G30: =+Distribution!I105+Meter!I105+TDCustSvc!I105 -> 0 | H30: =+Distribution!J105+Meter!J105+TDCustSvc!J105 -> 0 | I30: =IFERROR(+H30/F30,) -> 0 | J30: =+Distribution!H105+Meter!H105+TDCustSvc!H105 -> 0 | K30: =+Distribution!I105+Meter!I105+TDCustSvc!I105 -> 0 | L30: =+Distribution!J105+Meter!J105+TDCustSvc!J105 -> 0 | M30: =IFERROR(+L30/J30,0) -> 0 | N30: =IF(SUM(G30+H30)=F30,"OK",0) -> OK
A31: =+A30+1 -> 15 | B31: A356 | C31: O.H. Conductors & Devices | F31: =+'II-I TOTAL COMPANY'!H106 -> 0 | G31: =+Distribution!I106+Meter!I106+TDCustSvc!I106 -> 0 | H31: =+Distribution!J106+Meter!J106+TDCustSvc!J106 -> 0 | I31: =IFERROR(+H31/F31,) -> 0 | J31: =+Distribution!H106+Meter!H106+TDCustSvc!H106 -> 0 | K31: =+Distribution!I106+Meter!I106+TDCustSvc!I106 -> 0 | L31: =+Distribution!J106+Meter!J106+TDCustSvc!J106 -> 0 | M31: =IFERROR(+L31/J31,0) -> 0 | N31: =IF(SUM(G31+H31)=F31,"OK",0) -> OK
A32: =+A31+1 -> 16 | B32: A357 | C32: Undergound Conduit | F32: =+'II-I TOTAL COMPANY'!H107 -> 0 | G32: =+Distribution!I107+Meter!I107+TDCustSvc!I107 -> 0 | H32: =+Distribution!J107+Meter!J107+TDCustSvc!J107 -> 0 | I32: =IFERROR(+H32/F32,) -> 0 | J32: =+Distribution!H107+Meter!H107+TDCustSvc!H107 -> 0 | K32: =+Distribution!I107+Meter!I107+TDCustSvc!I107 -> 0 | L32: =+Distribution!J107+Meter!J107+TDCustSvc!J107 -> 0 | M32: =IFERROR(+L32/J32,0) -> 0 | N32: =IF(SUM(G32+H32)=F32,"OK",0) -> OK
A33: =+A32+1 -> 17 | B33: A358 | C33: Underground Conductors | F33: =+'II-I TOTAL COMPANY'!H108 -> 0 | G33: =+Distribution!I108+Meter!I108+TDCustSvc!I108 -> 0 | H33: =+Distribution!J108+Meter!J108+TDCustSvc!J108 -> 0 | I33: =IFERROR(+H33/F33,) -> 0 | J33: =+Distribution!H108+Meter!H108+TDCustSvc!H108 -> 0 | K33: =+Distribution!I108+Meter!I108+TDCustSvc!I108 -> 0 | L33: =+Distribution!J108+Meter!J108+TDCustSvc!J108 -> 0 | M33: =IFERROR(+L33/J33,0) -> 0 | N33: =IF(SUM(G33+H33)=F33,"OK",0) -> OK
A34: =+A33+1 -> 18 | B34: A359 | C34: Roads and Trails | F34: =+'II-I TOTAL COMPANY'!H109 -> 0 | G34: =+Distribution!I109+Meter!I109+TDCustSvc!I109 -> 0 | H34: =+Distribution!J109+Meter!J109+TDCustSvc!J109 -> 0 | I34: =IFERROR(+H34/F34,) -> 0 | J34: =+Distribution!H109+Meter!H109+TDCustSvc!H109 -> 0 | K34: =+Distribution!I109+Meter!I109+TDCustSvc!I109 -> 0 | L34: =+Distribution!J109+Meter!J109+TDCustSvc!J109 -> 0 | M34: =IFERROR(+L34/J34,0) -> 0 | N34: =IF(SUM(G34+H34)=F34,"OK",0) -> OK
A35: =+A34+1 -> 19 | N35: =IF(SUM(G35+H35)=F35,"OK",0) -> OK
A36: =+A35+1 -> 20 | C36: Total Transmission Plant | F36: =+'II-I TOTAL COMPANY'!H111 -> 0 | G36: =+Distribution!I111+Meter!I111+TDCustSvc!I111 -> 0 | H36: =+Distribution!J111+Meter!J111+TDCustSvc!J111 -> 0 | I36: =IFERROR(+H36/F36,) -> 0 | J36: =+Distribution!H111+Meter!H111+TDCustSvc!H111 -> 0 | K36: =+Distribution!I111+Meter!I111+TDCustSvc!I111 -> 0 | L36: =+Distribution!J111+Meter!J111+TDCustSvc!J111 -> 0 | M36: =IFERROR(+L36/J36,0) -> 0 | N36: =IF(SUM(G36+H36)=F36,"OK",0) -> OK
A37: =+A36+1 -> 21 | N37: =IF(SUM(G37+H37)=F37,"OK",0) -> OK
A38: =+A37+1 -> 22 | B38: Distribution Plant | N38: =IF(SUM(G38+H38)=F38,"OK",0) -> OK
A39: =+A38+1 -> 23 | B39: A360 | C39: Land and Land Rights | F39: =+'II-I TOTAL COMPANY'!H114 -> 42018495 | G39: =+Distribution!I114+Meter!I114+TDCustSvc!I114 -> 0 | H39: =+Distribution!J114+Meter!J114+TDCustSvc!J114 -> 42018495 | I39: =+H39/F39 -> 1 | J39: =+Distribution!H114+Meter!H114+TDCustSvc!H114 -> 42018495 | K39: =+Distribution!I114+Meter!I114+TDCustSvc!I114 -> 0 | L39: =+Distribution!J114+Meter!J114+TDCustSvc!J114 -> 42018495 | M39: =+L39/J39 -> 1 | N39: =IF(SUM(G39+H39)=F39,"OK",0) -> OK
A40: =+A39+1 -> 24 | B40: A361 | C40: Structures and Improvements | F40: =+'II-I TOTAL COMPANY'!H115 -> 88124441 | G40: =+Distribution!I115+Meter!I115+TDCustSvc!I115 -> 0 | H40: =+Distribution!J115+Meter!J115+TDCustSvc!J115 -> 88124441 | I40: =+H40/F40 -> 1 | J40: =+Distribution!H115+Meter!H115+TDCustSvc!H115 -> 88124441 | K40: =+Distribution!I115+Meter!I115+TDCustSvc!I115 -> 0 | L40: =+Distribution!J115+Meter!J115+TDCustSvc!J115 -> 88124441 | M40: =+L40/J40 -> 1 | N40: =IF(SUM(G40+H40)=F40,"OK",0) -> OK
A41: =+A40+1 -> 25 | B41: A362 | C41: Station Equipment | F41: =+'II-I TOTAL COMPANY'!H116 -> 9.3770968e+08 | G41: =+Distribution!I116+Meter!I116+TDCustSvc!I116 -> 0 | H41: =+Distribution!J116+Meter!J116+TDCustSvc!J116 -> 9.3770968e+08 | I41: =+H41/F41 -> 1 | J41: =+Distribution!H116+Meter!H116+TDCustSvc!H116 -> 9.3770968e+08 | K41: =+Distribution!I116+Meter!I116+TDCustSvc!I116 -> 0 | L41: =+Distribution!J116+Meter!J116+TDCustSvc!J116 -> 9.3770968e+08 | M41: =+L41/J41 -> 1 | N41: =IF(SUM(G41+H41)=F41,"OK",0) -> OK
A42: =+A41+1 -> 26 | B42: A363 | C42: Storage Battery Equipment | F42: =+'II-I TOTAL COMPANY'!H117 -> 0 | G42: =+Distribution!I117+Meter!I117+TDCustSvc!I117 -> 0 | H42: =+Distribution!J117+Meter!J117+TDCustSvc!J117 -> 0 | J42: =+Distribution!H117+Meter!H117+TDCustSvc!H117 -> 0 | K42: =+Distribution!I117+Meter!I117+TDCustSvc!I117 -> 0 | L42: =+Distribution!J117+Meter!J117+TDCustSvc!J117 -> 0 | N42: =IF(SUM(G42+H42)=F42,"OK",0) -> OK
A43: =+A42+1 -> 27 | B43: A364 | C43: Poles,Towers & Fixtures | N43: =IF(SUM(G43+H43)=F43,"OK",0) -> OK
A44: =+A43+1 -> 28 | C44: Primary | F44: =+'II-I TOTAL COMPANY'!H119 -> 8.5392307e+08 | G44: =+Distribution!I119+Meter!I119+TDCustSvc!I119 -> 0 | H44: =+Distribution!J119+Meter!J119+TDCustSvc!J119 -> 8.5392307e+08 | I44: =+H44/F44 -> 1 | J44: =+Distribution!H119+Meter!H119+TDCustSvc!H119 -> 8.5392307e+08 | K44: =+Distribution!I119+Meter!I119+TDCustSvc!I119 -> 0 | L44: =+Distribution!J119+Meter!J119+TDCustSvc!J119 -> 8.5392307e+08 | M44: =+L44/J44 -> 1 | N44: =IF(SUM(G44+H44)=F44,"OK",0) -> OK
A45: =+A44+1 -> 29 | C45: Secondary | F45: =+'II-I TOTAL COMPANY'!H120 -> 3.6231831e+08 | G45: =+Distribution!I120+Meter!I120+TDCustSvc!I120 -> 0 | H45: =+Distribution!J120+Meter!J120+TDCustSvc!J120 -> 3.6231831e+08 | I45: =+H45/F45 -> 1 | J45: =+Distribution!H120+Meter!H120+TDCustSvc!H120 -> 3.6231831e+08 | K45: =+Distribution!I120+Meter!I120+TDCustSvc!I120 -> 0 | L45: =+Distribution!J120+Meter!J120+TDCustSvc!J120 -> 3.6231831e+08 | M45: =+L45/J45 -> 1 | N45: =IF(SUM(G45+H45)=F45,"OK",0) -> OK
...

Sheet Retail Summary Proposed
W2: =+V2+1 -> 1
B3: ='II-I TOTAL COMPANY'!B4 -> PUBLIC UTILITY COMMISION OF TEXAS
B4: ='II-I TOTAL COMPANY'!B5 -> AEP TEXAS INC
B5: ='II-I TOTAL COMPANY'!B6 -> II-I COST OF SERVICE
B6: ='II-I TOTAL COMPANY'!B7 -> TEST YEAR ENDING 09/30/2023
B7: DOCKET 56165
I8: Total | L8: Total
H9: Secondary | I9: Secondary | J9: Secondary | K9: Secondary | L9: Primary | M9: Primary | N9: Primary | O9: Primary | P9: Transmission | Q9: Lighting | R9: BESS
A10: Line | D10: Total | E10: Oth Jurisdiction | F10: Texas Retail | G10: Residential | H10: GS < = 10kw | I10: GS > 10kw | J10: GS > 10kw | K10: GS > 10kw | M10: 4CP | N10: NCP | O10: Sub | S10: Check
A11: No. | D11: AEP Texas | J11: 4CP | K11: NCP | S11: Column
A12: -1 | B12: =+A12-1 -> -2 | C12: =+B12-1 -> -3 | D12: =+C12-1 -> -4 | E12: =+D12-1 -> -5 | F12: =+E12-1 -> -6 | G12: =+F12-1 -> -7 | H12: =+G12-1 -> -8 | I12: =+H12-1 -> -9 | ... R12: =+Q12-1 -> -18
B13: Unit Cost
B15: Unit Cost @ Present Rates
A16: 1 | B16: Transmission | D16: =E16+F16 -> 0 | E16: 0 | F16: =SUM(G16:R16)-(L16+I16) -> 0 | G16: =+Distribution!K332 -> 0 | H16: =+Distribution!L332 -> 0 | I16: =+Distribution!M332 -> 0 | J16: =+Distribution!N332 -> 0 | K16: =+Distribution!O332 -> 0 | L16: =+Distribution!P332 -> 0 | M16: =+Distribution!Q332 -> 0 | N16: =+Distribution!R332 -> 0 | ... R16: =+Distribution!V332 -> 0
B17: $ / kw - NCP | D17: =D16/D$100 -> 0 | E17: =IFERROR(E16/E$100,0) -> 0 | F17: =F16/F$100 -> 0 | G17: =G16/G$100 -> 0 | H17: =H16/H$100 -> 0 | I17: =I16/I$100 -> 0 | J17: =J16/J$100 -> 0 | K17: =K16/K$100 -> 0 | L17: =L16/L$100 -> 0 | M17: =M16/M$100 -> 0 | ... Q17: =Q16/Q$100 -> 0 | R17: =IFERROR(R16/R$100,0) -> 0
B18: $ / kWh | D18: =D16/D$101 -> 0 | E18: =IFERROR(E16/E$101,0) -> 0 | F18: =F16/F$101 -> 0 | G18: =G16/G$101 -> 0 | H18: =H16/H$101 -> 0 | I18: =I16/I$101 -> 0 | J18: =J16/J$101 -> 0 | K18: =K16/K$101 -> 0 | L18: =L16/L$101 -> 0 | M18: =M16/M$101 -> 0 | ... Q18: =Q16/Q$101 -> 0 | R18: =IFERROR(R16/R$101,0) -> 0
B19: $ / Cust / Month | D19: =+(D16/D$102)/12 -> 0 | E19: =IFERROR(+(E16/E$102)/12,0) -> 0 | F19: =+(F16/F$102)/12 -> 0 | G19: =+(G16/G$102)/12 -> 0 | H19: =+(H16/H$102)/12 -> 0 | I19: =+(I16/I$102)/12 -> 0 | J19: =+(J16/J$102)/12 -> 0 | K19: =+(K16/K$102)/12 -> 0 | L19: =+(L16/L$102)/12 -> 0 | M19: =+(M16/M$102)/12 -> 0 | ... Q19: =+(Q16/Q$102)/12 -> 0 | R19: =IFERROR(+(R16/R$102)/12,0) -> 0
A21: 2 | B21: Distribution | D21: =E21+F21 -> 5.0555742e+08 | E21: =Distribution!I39 -> 0 | F21: =Distribution!J39 -> 5.0555742e+08 | G21: =Distribution!K39 -> 2.7428025e+08 | H21: =Distribution!L39 -> 14156857 | I21: =Distribution!M39 -> 1.5308902e+08 | J21: =Distribution!N39 -> 17640817 | K21: =Distribution!O39 -> 1.3544821e+08 | L21: =Distribution!P39 -> 34155357 | ... R21: =Distribution!V39 -> 1
B22: $ / kw - NCP | D22: =D21/D$100 -> 3.3564061 | E22: =IFERROR(E21/E$100,0) -> 0 | F22: =F21/F$100 -> 3.3564061 | G22: =G21/G$100 -> 3.46393 | H22: =H21/H$100 -> 4.885979 | I22: =I21/I$100 -> 4.8443026 | J22: =J21/J$100 -> 4.8360199 | K22: =K21/K$100 -> 4.8453835 | L22: =L21/L$100 -> 3.1043426 | M22: =M21/M$100 -> 3.1081296 | ... Q22: =Q21/Q$100 -> 26.665747 | R22: =IFERROR(R21/R$100,0) -> 1.8161562e-06
B23: $ / kWh | D23: =D21/D$101 -> 0.013201381 | E23: =IFERROR(E21/E$101,0) -> 0 | F23: =F21/F$101 -> 0.013201381 | G23: =G21/G$101 -> 0.021785767 | H23: =H21/H$101 -> 0.021063614 | I23: =I21/I$101 -> 0.016630969 | J23: =J21/J$101 -> 0.013470728 | K23: =K21/K$101 -> 0.017155135 | L23: =L21/L$101 -> 0.0075480258 | M23: =M21/M$101 -> 0.0067152445 | ... Q23: =Q21/Q$101 -> 0.09053626 | R23: =IFERROR(R21/R$101,0) -> 3.3779412e-08
B24: $ / Cust / Month | D24: =+(D21/D$102)/12 -> 31.685321 | E24: =IFERROR(+(E21/E$102)/12,0) -> 0 | F24: =+(F21/F$102)/12 -> 31.685321 | G24: =+(G21/G$102)/12 -> 24.439434 | H24: =+(H21/H$102)/12 -> 11.872654 | I24: =+(I21/I$102)/12 -> 176.18554 | J24: =+(J21/J$102)/12 -> 2552.2016 | K24: =+(K21/K$102)/12 -> 157.13322 | L24: =+(L21/L$102)/12 -> 2620.8838 | M24: =+(M21/M$102)/12 -> 4484.1248 | ... Q24: =+(Q21/Q$102)/12 -> 8.1238528 | R24: =IFERROR(+(R21/R$102)/12,0) -> 0.0043859649
A26: 3 | B26: Meters | D26: =E26+F26 -> 56905340 | E26: =Meter!I39 -> 0 | F26: =Meter!J39 -> 56905340 | G26: =Meter!K39 -> 38036476 | H26: =Meter!L39 -> 5099901 | I26: =Meter!M39 -> 10956923 | J26: =Meter!N39 -> 87790.73 | K26: =Meter!O39 -> 10869132 | L26: =Meter!P39 -> 1645621.7 | ... R26: =Meter!V39 -> 1
B27: $ / kw - NCP | D27: =D26/D$100 -> 0.37779572 | E27: =IFERROR(E26/E$100,0) -> 0 | F27: =F26/F$100 -> 0.37779572 | G27: =G26/G$100 -> 0.48036886 | H27: =H26/H$100 -> 1.7601371 | I27: =I26/I$100 -> 0.34671753 | J27: =J26/J$100 -> 0.024066782 | K27: =K26/K$100 -> 0.38882103 | L27: =L26/L$100 -> 0.14956873 | M27: =M26/M$100 -> 0.087830258 | ... Q27: =Q26/Q$100 -> 0 | R27: =IFERROR(R26/R$100,0) -> 1.8161562e-06
B28: $ / kWh | D28: =D26/D$101 -> 0.0014859422 | E28: =IFERROR(E26/E$101,0) -> 0 | F28: =F26/F$101 -> 0.0014859422 | G28: =G26/G$101 -> 0.0030211939 | H28: =H26/H$101 -> 0.007588008 | I28: =I26/I$101 -> 0.0011903155 | J28: =J26/J$101 -> 6.7037994e-05 | K28: =K26/K$101 -> 0.0013766253 | L28: =L26/L$101 -> 0.00036366754 | M28: =M26/M$101 -> 0.00018976096 | ... Q28: =Q26/Q$101 -> 0 | R28: =IFERROR(R26/R$101,0) -> 3.3779412e-08
B29: $ / Cust / Month | D29: =+(D26/D$102)/12 -> 3.566487 | E29: =IFERROR(+(E26/E$102)/12,0) -> 0 | F29: =+(F26/F$102)/12 -> 3.566487 | G29: =+(G26/G$102)/12 -> 3.3891976 | H29: =+(H26/H$102)/12 -> 4.2770339 | I29: =+(I26/I$102)/12 -> 12.609992 | J29: =+(J26/J$102)/12 -> 12.701205 | K29: =+(K26/K$102)/12 -> 12.60926 | L29: =+(L26/L$102)/12 -> 126.27545 | M29: =+(M26/M$102)/12 -> 126.71346 | ... Q29: =+(Q26/Q$102)/12 -> 0 | R29: =IFERROR(+(R26/R$102)/12,0) -> 0.0043859649
A31: 4 | B31: T&D Customer Service | D31: =E31+F31 -> 19273108 | E31: =TDCustSvc!I39 -> 0 | F31: =TDCustSvc!J39 -> 19273108 | G31: =TDCustSvc!K39 -> 15708279 | H31: =TDCustSvc!L39 -> 1667059.1 | I31: =TDCustSvc!M39 -> 1746841.8 | J31: =TDCustSvc!N39 -> 13996.628 | K31: =TDCustSvc!O39 -> 1732845.2 | L31: =TDCustSvc!P39 -> 95337.2 | ... R31: =TDCustSvc!V39 -> 1
B32: $ / kw - NCP | D32: =D31/D$100 -> 0.12795456 | E32: =IFERROR(E31/E$100,0) -> 0 | F32: =F31/F$100 -> 0.12795456 | G32: =G31/G$100 -> 0.19838242 | H32: =H31/H$100 -> 0.57535481 | I32: =I31/I$100 -> 0.055276532 | J32: =J31/J$100 -> 0.0038370087 | K32: =K31/K$100 -> 0.061989003 | L32: =L31/L$100 -> 0.0086650926 | M32: =M31/M$100 -> 0.0050883787 | ... Q32: =Q31/Q$100 -> 0.054525948 | R32: =IFERROR(R31/R$100,0) -> 1.8161562e-06
B33: $ / kWh | D33: =D31/D$101 -> 0.00050326952 | E33: =IFERROR(E31/E$101,0) -> 0 | F33: =F31/F$101 -> 0.00050326952 | G33: =G31/G$101 -> 0.0012476907 | H33: =H31/H$101 -> 0.0024803733 | I33: =I31/I$101 -> 0.00018976979 | J33: =J31/J$101 -> 1.0687983e-05 | K33: =K31/K$101 -> 0.00021947277 | L33: =L31/L$101 -> 2.1068661e-05 | M33: =M31/M$101 -> 1.0993656e-05 | ... Q33: =Q31/Q$101 -> 0.00018512796 | R33: =IFERROR(R31/R$101,0) -> 3.3779412e-08
B34: $ / Cust / Month | D34: =+(D31/D$102)/12 -> 1.2079233 | E34: =IFERROR(+(E31/E$102)/12,0) -> 0 | F34: =+(F31/F$102)/12 -> 1.2079233 | G34: =+(G31/G$102)/12 -> 1.3996686 | H34: =+(H31/H$102)/12 -> 1.3980798 | I34: =+(I31/I$102)/12 -> 2.0103875 | J34: =+(J31/J$102)/12 -> 2.0249751 | K34: =+(K31/K$102)/12 -> 2.0102705 | L34: =+(L31/L$102)/12 -> 7.3156231 | M34: =+(M31/M$102)/12 -> 7.341047 | ... Q34: =+(Q31/Q$102)/12 -> 0.016611602 | R34: =IFERROR(+(R31/R$102)/12,0) -> 0.0043859649
A36: 5 | B36: Municipal Gross Receipt Fee | D36: =E36+F36 -> 0 | E36: 0 | F36: 0 | G36: 0 | H36: 0 | I36: =SUM(G36:H36) -> 0 | J36: 0 | K36: 0 | L36: =SUM(M36:O36) -> 0 | M36: 0 | N36: 0 | O36: 0 | P36: 0 | Q36: 0 | R36: 0
B37: $ / kw - NCP | D37: =D36/D$100 -> 0 | E37: =IFERROR(E36/E$100,0) -> 0 | F37: =F36/F$100 -> 0 | G37: =G36/G$100 -> 0 | H37: =H36/H$100 -> 0 | I37: =I36/I$100 -> 0 | J37: =J36/J$100 -> 0 | K37: =K36/K$100 -> 0 | L37: =L36/L$100 -> 0 | M37: =M36/M$100 -> 0 | ... Q37: =Q36/Q$100 -> 0 | R37: =IFERROR(R36/R$100,0) -> 0
B38: $ / kWh | D38: =D36/D$101 -> 0 | E38: =IFERROR(E36/E$101,0) -> 0 | F38: =F36/F$101 -> 0 | G38: =G36/G$101 -> 0 | H38: =H36/H$101 -> 0 | I38: =I36/I$101 -> 0 | J38: =J36/J$101 -> 0 | K38: =K36/K$101 -> 0 | L38: =L36/L$101 -> 0 | M38: =M36/M$101 -> 0 | ... Q38: =Q36/Q$101 -> 0 | R38: =IFERROR(R36/R$101,0) -> 0
B39: $ / Cust / Month | D39: =+(D36/D$102)/12 -> 0 | E39: =IFERROR(+(E36/E$102)/12,0) -> 0 | F39: =+(F36/F$102)/12 -> 0 | G39: =+(G36/G$102)/12 -> 0 | H39: =+(H36/H$102)/12 -> 0 | I39: =+(I36/I$102)/12 -> 0 | J39: =+(J36/J$102)/12 -> 0 | K39: =+(K36/K$102)/12 -> 0 | L39: =+(L36/L$102)/12 -> 0 | M39: =+(M36/M$102)/12 -> 0 | ... Q39: =+(Q36/Q$102)/12 -> 0 | R39: =IFERROR(+(R36/R$102)/12,0) -> 0
A41: 6 | B41: Nuclear Decommissioning | D41: =E41+F41 -> 0 | E41: 0 | F41: 0 | G41: 0 | H41: 0 | I41: 0 | J41: 0 | K41: 0 | L41: 0 | M41: 0 | N41: 0 | O41: 0 | P41: 0 | Q41: 0 | R41: 0
B42: $ / kw - NCP | D42: =D41/D$100 -> 0 | E42: =IFERROR(E41/E$100,0) -> 0 | F42: =F41/F$100 -> 0 | G42: =G41/G$100 -> 0 | H42: =H41/H$100 -> 0 | I42: =I41/I$100 -> 0 | J42: =J41/J$100 -> 0 | K42: =K41/K$100 -> 0 | L42: =L41/L$100 -> 0 | M42: =M41/M$100 -> 0 | ... Q42: =Q41/Q$100 -> 0 | R42: =IFERROR(R41/R$100,0) -> 0
B43: $ / kWh | D43: =D41/D$101 -> 0 | E43: =IFERROR(E41/E$101,0) -> 0 | F43: =F41/F$101 -> 0 | G43: =G41/G$101 -> 0 | H43: =H41/H$101 -> 0 | I43: =I41/I$101 -> 0 | J43: =J41/J$101 -> 0 | K43: =K41/K$101 -> 0 | L43: =L41/L$101 -> 0 | M43: =M41/M$101 -> 0 | ... Q43: =Q41/Q$101 -> 0 | R43: =IFERROR(R41/R$101,0) -> 0
B44: $ / Cust / Month | D44: =+(D41/D$102)/12 -> 0 | E44: =IFERROR(+(E41/E$102)/12,0) -> 0 | F44: =+(F41/F$102)/12 -> 0 | G44: =+(G41/G$102)/12 -> 0 | H44: =+(H41/H$102)/12 -> 0 | I44: =+(I41/I$102)/12 -> 0 | J44: =+(J41/J$102)/12 -> 0 | K44: =+(K41/K$102)/12 -> 0 | L44: =+(L41/L$102)/12 -> 0 | M44: =+(M41/M$102)/12 -> 0 | ... Q44: =+(Q41/Q$102)/12 -> 0 | R44: =IFERROR(+(R41/R$102)/12,0) -> 0
A46: 7 | B46: Total Revenue Requirement | D46: =E46+F46 -> 5.8173587e+08 | E46: 0 | F46: =+F41+F36+F31+F26+F21+F16 -> 5.8173587e+08 | G46: =+G41+G36+G31+G26+G21+G16 -> 3.28025e+08 | H46: =+H41+H36+H31+H26+H21+H16 -> 20923817 | I46: =+I41+I36+I31+I26+I21+I16 -> 1.6579279e+08 | J46: =+J41+J36+J31+J26+J21+J16 -> 17742605 | K46: =+K41+K36+K31+K26+K21+K16 -> 1.4805018e+08 | L46: =+L41+L36+L31+L26+L21+L16 -> 35896316 | M46: =+M41+M36+M31+M26+M21+M16 -> 25991113 | ... R46: =+R41+R36+R31+R26+R21+R16 -> 3
B47: $ / kw - NCP | D47: =D46/D$100 -> 3.8621564 | E47: =IFERROR(E46/E$100,0) -> 0 | F47: =F46/F$100 -> 3.8621564 | G47: =G46/G$100 -> 4.1426813 | H47: =H46/H$100 -> 7.2214708 | I47: =I46/I$100 -> 5.2462967 | J47: =J46/J$100 -> 4.8639236 | K47: =K46/K$100 -> 5.2961935 | L47: =L46/L$100 -> 3.2625764 | M47: =M46/M$100 -> 3.2010482 | ... Q47: =Q46/Q$100 -> 26.720273 | R47: =IFERROR(R46/R$100,0) -> 5.4484685e-06
B48: $ / kWh | D48: =D46/D$101 -> 0.015190593 | E48: =IFERROR(E46/E$101,0) -> 0 | F48: =F46/F$101 -> 0.015190593 | G48: =G46/G$101 -> 0.026054652 | H48: =H46/H$101 -> 0.031131995 | I48: =I46/I$101 -> 0.018011055 | J48: =J46/J$101 -> 0.013548454 | K48: =K46/K$101 -> 0.018751233 | L48: =L46/L$101 -> 0.007932762 | M48: =M46/M$101 -> 0.0069159992 | ... Q48: =Q46/Q$101 -> 0.090721388 | R48: =IFERROR(R46/R$101,0) -> 1.0133824e-07
...

Sheet Distribution
D1: 1 | E1: 2 | H1: 7 | I1: 13 | J1: 6 | K1: =J1+1 -> 7 | L1: =K1+1 -> 8 | M1: =L1+1 -> 9 | N1: =M1+1 -> 10 | O1: =N1+1 -> 11 | P1: =O1+1 -> 12 | Q1: =P1+1 -> 13 | R1: =Q1+1 -> 14 | ... V1: =U1+1 -> 18
B3: ='II-I TOTAL COMPANY'!B4 -> PUBLIC UTILITY COMMISION OF TEXAS
B4: ='II-I TOTAL COMPANY'!B5 -> AEP TEXAS INC
B5: ='II-I TOTAL COMPANY'!B6 -> II-I COST OF SERVICE
B6: ='II-I TOTAL COMPANY'!B7 -> TEST YEAR ENDING 09/30/2023
B7: DOCKET 56165 | D7: Distribution
M8: Total | P8: Total
L9: Secondary | M9: Secondary | N9: Secondary | O9: Secondary | P9: Primary | Q9: Primary | R9: Primary | S9: Primary | T9: Transmission | U9: Lighting | V9: BESS
A10: Line | B10: Account | C10: Description | E10: Reference | F10: Total AEP Texas | G10: Difference | H10: Total | I10: Oth Jurisdiction | J10: Texas Retail | K10: Residential | L10: GS < = 10kw | M10: GS > 10kw | N10: GS > 10kw | O10: GS > 10kw | Q10: 4CP | R10: NCP | S10: Sub | W10: Check
A11: No. | B11: No. | D11: ALLOC | E11: Schedule | F11: As Filed | N11: 4CP | O11: NCP | W11: Column
A12: -1 | B12: =+A12-1 -> -2 | C12: =+B12-1 -> -3 | D12: =+C12-1 -> -4 | E12: =+D12-1 -> -5 | H12: =+E12-1 -> -6 | I12: =+H12-1 -> -7 | J12: =+I12-1 -> -8 | K12: =+J12-1 -> -9 | L12: =+K12-1 -> -10 | M12: =+L12-1 -> -11 | N12: =+M12-1 -> -12 | O12: =+N12-1 -> -13 | P12: =+O12-1 -> -14 | ... V12: =+U12-1 -> -20
B13: Schedule I-A Cost of Service by Function
B15: Summary of Results @ Present ROR
A17: =+A16+1 -> 1 | B17: Rate Base by Function
A18: =+A17+1 -> 2 | B18: Plant Investment
A19: =+A18+1 -> 3 | C19: Intangible | H19: =+I19+J19 -> 1.5236904e+08 | I19: 0 | J19: =+K19+L19+M19+P19+T19+U19+V19 -> 1.5236904e+08 | K19: =+K96 -> 87564019 | L19: =+L96 -> 3238501.3 | M19: =SUM(N19:O19) -> 44981883 | N19: =+N96 -> 5991324.3 | O19: =+O96 -> 38990559 | P19: =SUM(Q19:S19) -> 11862740 | Q19: =+Q96 -> 9650052.6 | R19: =+R96 -> 698380.78 | S19: =+S96 -> 1514306.7 | T19: =+T96 -> 820.99542 | U19: =+U96 -> 4280695.4 | V19: =+V96 -> 440379.82 | W19: =IF((+K19+L19+M19+P19+T19+U19+V19)-H19=0,"OK",(+K19+L19+M19+P19+T19+U19+V19)-H19) -> OK | X19: =+'II-I TOTAL COMPANY'!K19-Distribution!H19 -> 0
A20: =+A19+1 -> 4 | C20: Transmission | H20: =+I20+J20 -> 0 | I20: 0 | J20: =+K20+L20+M20+P20+T20+U20+V20 -> 0 | K20: =+K111 -> 0 | L20: =+L111 -> 0 | M20: =SUM(N20:O20) -> 0 | N20: =+N111 -> 0 | O20: =+O111 -> 0 | P20: =SUM(Q20:S20) -> 0 | Q20: =+Q111 -> 0 | R20: =+R111 -> 0 | S20: =+S111 -> 0 | T20: =+T111 -> 0 | U20: =+U111 -> 0 | V20: =+V111 -> 0 | W20: =IF((+K20+L20+M20+P20+T20+U20+V20)-H20=0,"OK",(+K20+L20+M20+P20+T20+U20+V20)-H20) -> OK | X20: =+'II-I TOTAL COMPANY'!K20-Distribution!H20 -> 0
A21: =+A20+1 -> 5 | C21: Distribution | H21: =+I21+J21 -> 5.530937e+09 | I21: 0 | J21: =+K21+L21+M21+P21+T21+U21+V21 -> 5.530937e+09 | K21: =+K147 -> 3.2154441e+09 | L21: =+L147 -> 1.3415403e+08 | M21: =SUM(N21:O21) -> 1.5614549e+09 | N21: =+N147 -> 2.0385822e+08 | O21: =+O147 -> 1.3575967e+09 | P21: =SUM(Q21:S21) -> 3.369426e+08 | Q21: =+Q147 -> 2.7410183e+08 | R21: =+R147 -> 19835589 | S21: =+S147 -> 43005177 | T21: =+T147 -> 0 | U21: =+U147 -> 2.7042948e+08 | V21: =+V147 -> 12511867 | W21: =IF((+K21+L21+M21+P21+T21+U21+V21)-H21=0,"OK",(+K21+L21+M21+P21+T21+U21+V21)-H21) -> OK | X21: =+'II-I TOTAL COMPANY'!K21-Distribution!H21 -> 0
A22: =+A21+1 -> 6 | C22: General | H22: =+I22+J22 -> 6.5153933e+08 | I22: 0 | J22: =+K22+L22+M22+P22+T22+U22+V22 -> 6.5153933e+08 | K22: =+K162+K168 -> 3.744291e+08 | L22: =+L162+L168 -> 13848030 | M22: =SUM(N22:O22) -> 1.9234528e+08 | N22: =+N162+N168 -> 25619269 | O22: =+O162+O168 -> 1.6672601e+08 | P22: =SUM(Q22:S22) -> 50725802 | Q22: =+Q162+Q168 -> 41264215 | R22: =+R162+R168 -> 2986318.9 | S22: =+S162+S168 -> 6475268.2 | T22: =+T162+T168 -> 3510.6266 | U22: =+U162+U168 -> 18304515 | V22: =+V162+V168 -> 1883091 | W22: =IF((+K22+L22+M22+P22+T22+U22+V22)-H22=0,"OK",(+K22+L22+M22+P22+T22+U22+V22)-H22) -> OK | X22: =+'II-I TOTAL COMPANY'!K22-Distribution!H22 -> 0
A23: =+A22+1 -> 7 | W23: =IF((+K23+L23+M23+P23+T23+U23+V23)-H23=0,"OK",(+K23+L23+M23+P23+T23+U23+V23)-H23) -> OK | X23: =+'II-I TOTAL COMPANY'!K23-Distribution!H23 -> 0
A24: =+A23+1 -> 8 | B24: Total Plant Investment | H24: =+I24+J24 -> 6.3348454e+09 | I24: 0 | J24: =+K24+L24+M24+P24+T24+U24+V24 -> 6.3348454e+09 | K24: =SUM(K19:K23) -> 3.6774373e+09 | L24: =SUM(L19:L23) -> 1.5124056e+08 | M24: =SUM(N24:O24) -> 1.7987821e+09 | N24: =SUM(N19:N23) -> 2.3546881e+08 | O24: =SUM(O19:O23) -> 1.5633133e+09 | P24: =SUM(Q24:S24) -> 3.9953114e+08 | Q24: =SUM(Q19:Q23) -> 3.250161e+08 | R24: =SUM(R19:R23) -> 23520289 | S24: =SUM(S19:S23) -> 50994752 | T24: =SUM(T19:T23) -> 4331.622 | U24: =SUM(U19:U23) -> 2.9301469e+08 | V24: =SUM(V19:V23) -> 14835338 | W24: =IF((+K24+L24+M24+P24+T24+U24+V24)-H24=0,"OK",(+K24+L24+M24+P24+T24+U24+V24)-H24) -> OK | X24: =+'II-I TOTAL COMPANY'!K24-Distribution!H24 -> 0
A25: =+A24+1 -> 9 | W25: =IF((+K25+L25+M25+P25+T25+U25+V25)-H25=0,"OK",(+K25+L25+M25+P25+T25+U25+V25)-H25) -> OK | X25: =+'II-I TOTAL COMPANY'!K25-Distribution!H25 -> 0
A26: =+A25+1 -> 10 | C26: Less Accumulated Depreciation | H26: =+I26+J26 -> -1.5577575e+09 | I26: 0 | J26: =+K26+L26+M26+P26+T26+U26+V26 -> -1.5577575e+09 | K26: =-K247 -> -9.1116697e+08 | L26: =-L247 -> -42978044 | M26: =SUM(N26:O26) -> -4.130936e+08 | N26: =-N247 -> -52510669 | O26: =-O247 -> -3.6058293e+08 | P26: =SUM(Q26:S26) -> -89509328 | Q26: =-Q247 -> -72815200 | R26: =-R247 -> -5269399 | S26: =-S247 -> -11424728 | T26: =-T247 -> -1235.542 | U26: =-U247 -> -97684756 | V26: =-V247 -> -3323608 | W26: =IF((+K26+L26+M26+P26+T26+U26+V26)-H26=0,"OK",(+K26+L26+M26+P26+T26+U26+V26)-H26) -> OK | X26: =+'II-I TOTAL COMPANY'!K26-Distribution!H26 -> 0
A27: =+A26+1 -> 11 | W27: =IF((+K27+L27+M27+P27+T27+U27+V27)-H27=0,"OK",(+K27+L27+M27+P27+T27+U27+V27)-H27) -> OK | X27: =+'II-I TOTAL COMPANY'!K27-Distribution!H27 -> 0
A28: =+A27+1 -> 12 | B28: Net Plant Investment | H28: =+I28+J28 -> 4.7770878e+09 | I28: 0 | J28: =+K28+L28+M28+P28+T28+U28+V28 -> 4.7770878e+09 | K28: =+K24+K26 -> 2.7662703e+09 | L28: =+L24+L26 -> 1.0826251e+08 | M28: =SUM(N28:O28) -> 1.3856885e+09 | N28: =+N24+N26 -> 1.8295814e+08 | O28: =+O24+O26 -> 1.2027303e+09 | P28: =SUM(Q28:S28) -> 3.1002181e+08 | Q28: =+Q24+Q26 -> 2.522009e+08 | R28: =+R24+R26 -> 18250890 | S28: =+S24+S26 -> 39570023 | T28: =+T24+T26 -> 3096.08 | U28: =+U24+U26 -> 1.9532993e+08 | V28: =+V24+V26 -> 11511730 | W28: =IF((+K28+L28+M28+P28+T28+U28+V28)-H28=0,"OK",(+K28+L28+M28+P28+T28+U28+V28)-H28) -> OK | X28: =+'II-I TOTAL COMPANY'!K28-Distribution!H28 -> 0
A29: =+A28+1 -> 13 | W29: =IF((+K29+L29+M29+P29+T29+U29+V29)-H29=0,"OK",(+K29+L29+M29+P29+T29+U29+V29)-H29) -> OK | X29: =+'II-I TOTAL COMPANY'!K29-Distribution!H29 -> 0
A30: =+A29+1 -> 14 | B30: Material and Supplies | H30: =+I30+J30 -> 1.1523846e+08 | I30: 0 | J30: =+K30+L30+M30+P30+T30+U30+V30 -> 1.1523846e+08 | K30: =+K266 -> 66897006 | L30: =+L266 -> 2751247.6 | M30: =SUM(N30:O30) -> 32722009 | N30: =+N266 -> 4283460.8 | O30: =+O266 -> 28438548 | P30: =SUM(Q30:S30) -> 7267951.9 | Q30: =+Q266 -> 5912433.7 | R30: =+R266 -> 427862.34 | S30: =+S266 -> 927655.86 | T30: =+T266 -> 78.797413 | U30: =+U266 -> 5330289.6 | V30: =+V266 -> 269872.63 | W30: =IF((+K30+L30+M30+P30+T30+U30+V30)-H30=0,"OK",(+K30+L30+M30+P30+T30+U30+V30)-H30) -> OK | X30: =+'II-I TOTAL COMPANY'!K30-Distribution!H30 -> 0
A31: =+A30+1 -> 15 | B31: Cash Working Capital | H31: =+I31+J31 -> -16416706 | I31: 0 | J31: =+K31+L31+M31+P31+T31+U31+V31 -> -16416706 | K31: =+K270 -> -9449452.8 | L31: =+L270 -> -352463.19 | M31: =SUM(N31:O31) -> -4843118.5 | N31: =+N270 -> -643964.5 | O31: =+O270 -> -4199154 | P31: =SUM(Q31:S31) -> -1240918 | Q31: =+Q270 -> -1008991.2 | R31: =+R270 -> -73108.72 | S31: =+S270 -> -158818.14 | T31: =+T270 -> -1601.2039 | U31: =+U270 -> -483317.19 | V31: =+V270 -> -45834.79 | W31: =IF((+K31+L31+M31+P31+T31+U31+V31)-H31=0,"OK",(+K31+L31+M31+P31+T31+U31+V31)-H31) -> OK | X31: =+'II-I TOTAL COMPANY'!K31-Distribution!H31 -> 0
A32: =+A31+1 -> 16 | B32: Prepayments | H32: =+I32+J32 -> 57619309 | I32: 0 | J32: =+K32+L32+M32+P32+T32+U32+V32 -> 57619309 | K32: =+K276 -> 33448550 | L32: =+L276 -> 1375625.7 | M32: =SUM(N32:O32) -> 16361028 | N32: =+N276 -> 2141733.4 | O32: =+O276 -> 14219294 | P32: =SUM(Q32:S32) -> 3633981.1 | Q32: =+Q276 -> 2956221 | R32: =+R276 -> 213931.47 | S32: =+S276 -> 463828.58 | T32: =+T276 -> 39.398762 | U32: =+U276 -> 2665148.5 | V32: =+V276 -> 134936.51 | W32: =IF((+K32+L32+M32+P32+T32+U32+V32)-H32=0,"OK",(+K32+L32+M32+P32+T32+U32+V32)-H32) -> OK | X32: =+'II-I TOTAL COMPANY'!K32-Distribution!H32 -> 0
A33: =+A32+1 -> 17 | B33: Other Rate Base | H33: =+I33+J33 -> -2.5972059e+08 | I33: 0 | J33: =+K33+L33+M33+P33+T33+U33+V33 -> -2.5972059e+08 | K33: =+K253+K259+K292 -> -1.5115887e+08 | L33: =+L253+L259+L292 -> -6348106.3 | M33: =SUM(N33:O33) -> -73158728 | N33: =+N253+N259+N292 -> -9539471.3 | O33: =+O253+O259+O292 -> -63619257 | P33: =SUM(Q33:S33) -> -15379319 | Q33: =+Q253+Q259+Q292 -> -12511032 | R33: =+R253+R259+R292 -> -905370.4 | S33: =+S253+S259+S292 -> -1962916.9 | T33: =+T253+T259+T292 -> 0 | U33: =+U253+U259+U292 -> -13104482 | V33: =+V253+V259+V292 -> -571088.35 | W33: =IF((+K33+L33+M33+P33+T33+U33+V33)-H33=0,"OK",(+K33+L33+M33+P33+T33+U33+V33)-H33) -> OK | X33: =+'II-I TOTAL COMPANY'!K33-Distribution!H33 -> 0
A34: =+A33+1 -> 18 | B34: Accumulated Deferred Income Taxes | H34: =+I34+J34 -> -5.5590275e+08 | I34: 0 | J34: =+K34+L34+M34+P34+T34+U34+V34 -> -5.5590275e+08 | K34: =+K306 -> -3.2317747e+08 | L34: =+L306 -> -13483537 | M34: =+M306 -> -1.5693852e+08 | N34: =+N306 -> -20489357 | O34: =+O306 -> -1.3644916e+08 | P34: =+P306 -> -33865386 | Q34: =+Q306 -> -27549394 | R34: =+R306 -> -1993633 | ... V34: =+V306 -> -1257541.2 | W34: =IF((+K34+L34+M34+P34+T34+U34+V34)-H34=0,"OK",(+K34+L34+M34+P34+T34+U34+V34)-H34) -> OK | X34: =+'II-I TOTAL COMPANY'!K34-Distribution!H34 -> 0
A35: =+A34+1 -> 19 | B35: Customer Deposits | H35: =+I35+J35 -> -42130 | J35: =+K35+L35+M35+P35+T35+U35+V35 -> -42130 | K35: =K271 -> -29633.467 | L35: =L271 -> -3148.4597 | M35: =M271 -> -2294.3141 | N35: =N271 -> -18.250838 | O35: =O271 -> -2276.0633 | P35: =P271 -> -34.410434 | Q35: =Q271 -> -14.860491 | R35: =R271 -> -17.427015 | ... V35: =V271 -> -0.60202417 | W35: =IF((+K35+L35+M35+P35+T35+U35+V35)-H35=0,"OK",(+K35+L35+M35+P35+T35+U35+V35)-H35) -> OK | X35: =+'II-I TOTAL COMPANY'!K35-Distribution!H35 -> 0
A36: =+A35+1 -> 20 | B36: Total Rate Base | H36: =+I36+J36 -> 4.1178634e+09 | I36: 0 | J36: =+K36+L36+M36+P36+T36+U36+V36 -> 4.1178634e+09 | K36: =SUM(K28:K35) -> 2.3828004e+09 | L36: =SUM(L28:L35) -> 92202132 | M36: =SUM(N36:O36) -> 1.1998288e+09 | N36: =SUM(N28:N35) -> 1.5871052e+08 | O36: =SUM(O28:O35) -> 1.0411183e+09 | P36: =SUM(Q36:S36) -> 2.7043809e+08 | Q36: =SUM(Q28:Q35) -> 2.2000012e+08 | R36: =SUM(R28:R35) -> 15920554 | S36: =SUM(S28:S35) -> 34517412 | T36: =SUM(T28:T35) -> 1609.175 | U36: =SUM(U28:U35) -> 1.6255026e+08 | V36: =SUM(V28:V35) -> 10042074 | W36: =IF((+K36+L36+M36+P36+T36+U36+V36)-H36=0,"OK",(+K36+L36+M36+P36+T36+U36+V36)-H36) -> OK | X36: =+'II-I TOTAL COMPANY'!K36-Distribution!H36 -> 0
A37: =+A36+1 -> 21 | W37: =IF((+K37+L37+M37+P37+T37+U37+V37)-H37=0,"OK",(+K37+L37+M37+P37+T37+U37+V37)-H37) -> OK
A38: =+A37+1 -> 22 | W38: =IF((+K38+L38+M38+P38+T38+U38+V38)-H38=0,"OK",(+K38+L38+M38+P38+T38+U38+V38)-H38) -> OK
A39: =+A38+1 -> 23 | B39: Current Tariff Revenues | H39: =+I39+J39 -> 5.0555742e+08 | I39: 0 | J39: =+K39+L39+M39+P39+T39+U39+V39 -> 5.0555742e+08 | K39: =+'[2]II-H-4.1 Functions'!$F$189 -> 2.7428025e+08 | L39: =+'[2]II-H-4.1 Functions'!$F$191 -> 14156857 | M39: =SUM(N39:O39) -> 1.5308902e+08 | N39: =+'[2]II-H-4.1 Functions'!$F$194 -> 17640817 | O39: =+'[2]II-H-4.1 Functions'!$F$193 -> 1.3544821e+08 | P39: =SUM(Q39:S39) -> 34155357 | Q39: =+'[2]II-H-4.1 Functions'!$F$198 -> 25236655 | R39: =+'[2]II-H-4.1 Functions'!$F$197 -> 2304334.5 | S39: =+'[2]II-H-4.1 Functions'!$F$199+'[2]II-H-4.1 Functions'!$F$200 -> 6614368.3 | T39: =+'[2]II-H-4.1 Functions'!$F$203 -> 8293460.5 | U39: =+'[2]II-H-4.1 Functions'!$F$205 -> 21582477 | V39: 1 | W39: =IF((+K39+L39+M39+P39+T39+U39+V39)-H39=0,"OK",(+K39+L39+M39+P39+T39+U39+V39)-H39) -> OK | X39: =+'II-I TOTAL COMPANY'!K39-Distribution!H39 -> -0.99999994
