Workbook
Name AlocList: '[1]Functional Alloc'!$A$4:$A$35
Name AlocList: '[2]Functional Alloc'!$A$4:$A$35
Name AlocTable: '[1]Functional Alloc'!$A$4:$K$35
Name AlocTable: '[2]Functional Alloc'!$A$4:$K$35
Name Recover: [3]Macro1!$A$1734
Name Recover: [3]Macro1!$A$1734
Name TableName: "Dummy"

Sheet Sales
A3: MIDAMERCIAN ENERGY COMPANY
A4: =C10&" TCA RECONCILIATION and "&YEAR(G13)&" NEW FACTOR CALCULATION" -> 2020 TCA RECONCILIATION and 2021 NEW FACTOR CALCULATION
R6: Page 1 of 7
A8: ACTUAL KWH SALES | F8: FORECAST KWH SALES | N8: FORECAST KW SALES
C10: =YEAR(G13)-1&"" -> 2020 | D10: Allocator for forecasts | H10: =YEAR(G13)&" & "&YEAR(G25)&" Forecast" -> 2021 & 2022 Forecast | K10: =TEXT(G13,"mmm-yy")&" through "&TEXT(G15,"mmm-yy") -> Jan-21 through Mar-21 | L10: =TEXT(G16,"mmm-yy")&" through "&TEXT(G27,"mmm-yy") -> Apr-21 through Mar-22 | Q10: =K10 -> Jan-21 through Mar-21 | R10: =L10 -> Apr-21 through Mar-22
C11: (a) | D11: (b) | H11: (c) | K11: (d) | L11: (e) | P11: (f) | Q11: (g) | R11: (h)
A12: Line No. | C12: kWh | D12: % | F12: Line No. | H12: kWh | K12: kWh | L12: kWh | N12: Line No. | P12: Hours | Q12: kW | R12: kW
A13: 1 | B13: Residential | C13: 5955310808 | D13: =C13/$C$21 -> 0.24440495 | F13: 1 | G13: 44197 | H13: 2101711427 | J13: Residential | K13: =$H$29*D13 -> 1.5218513e+09 | L13: =$H$31*D13 -> 6.3596688e+09 | N13: 1 | O13: SGSD | P13: =R20 -> 355.84391 | Q13: =K14/P13 -> 1434868.4 | R13: =L14/P13 -> 5996175.5
A14: =A13+1 -> 2 | B14: SGSD | C14: 1998038290 | D14: =C14/$C$21 -> 0.081999155 | F14: =F13+1 -> 2 | G14: =EDATE(G13,1) -> 44228 | H14: 2.069965e+09 | J14: SGSD | K14: =$H$29*D14 -> 5.1058918e+08 | L14: =$H$31*D14 -> 2.1337025e+09 | N14: =N13+1 -> 2 | O14: LGS & SS | P14: =R21 -> 441.2284 | Q14: =K16/P14 -> 3926686.4 | R14: =L16/P14 -> 16409241
A15: =A14+1 -> 3 | B15: SGSE | C15: 1606644111 | D15: =C15/$C$21 -> 0.065936404 | F15: =F14+1 -> 3 | G15: =EDATE(G14,1) -> 44256 | H15: 2.055085e+09 | J15: SGSE | K15: =$H$29*D15 -> 4.1057026e+08 | L15: =$H$31*D15 -> 1.7157332e+09 | N15: =N14+1 -> 3 | O15: ICR | P15: =R22 -> 588.42827 | Q15: =K17/P15 -> 3428269.3 | R15: =L17/P15 -> 14326404
A16: =A15+1 -> 4 | B16: LGS & SS | C16: 6779878078 | D16: =C16/$C$21 -> 0.27824506 | F16: =F15+1 -> 4 | G16: =EDATE(G15,1) -> 44287 | H16: 2.0080403e+09 | J16: LGS & SS | K16: =$H$29*D16 -> 1.7325656e+09 | L16: =$H$31*D16 -> 7.2402231e+09
A17: =A16+1 -> 5 | B17: ICR | C17: 7894064202 | D17: =C17/$C$21 -> 0.32397107 | F17: =F16+1 -> 5 | G17: =EDATE(G16,1) -> 44317 | H17: 1.9859643e+09 | J17: ICR | K17: =$H$29*D17 -> 2.0172905e+09 | L17: =$H$31*D17 -> 8.430061e+09
A18: =A17+1 -> 6 | B18: Traffic Controls | C18: 5215265 | D18: =C18/$C$21 -> 0.0002140336 | F18: =F17+1 -> 6 | G18: =EDATE(G17,1) -> 44348 | H18: 2.0210621e+09 | J18: Traffic Controls | K18: =$H$29*D18 -> 1332736.1 | L18: =$H$31*D18 -> 5569374.8
A19: =A18+1 -> 7 | B19: Water Pumping | C19: 48251692 | D19: =C19/$C$21 -> 0.0019802413 | F19: =F18+1 -> 7 | G19: =EDATE(G18,1) -> 44378 | H19: 2.4198364e+09 | J19: Water Pumping | K19: =$H$29*D19 -> 12330490 | L19: =$H$31*D19 -> 51527920 | P19: =C10&" kWh" -> 2020 kWh | Q19: =C10&" kW" -> 2020 kW | R19: Hours
A20: =A19+1 -> 8 | B20: Lighting | C20: 79169156 | D20: =C20/$C$21 -> 0.0032490888 | F20: =F19+1 -> 8 | G20: =EDATE(G19,1) -> 44409 | H20: 2.3714244e+09 | J20: Lighting | K20: =$H$29*D20 -> 20231301 | L20: =$H$31*D20 -> 84544640 | N20: =N15+1 -> 4 | O20: SGSD | P20: =C14 -> 1998038290 | Q20: 5614929 | R20: =P20/Q20 -> 355.84391
A21: =A20+1 -> 9 | B21: Grand Total | C21: =SUM(C13:C20) -> 24366571602 | D21: =SUM(D13:D20) -> 1 | F21: =F20+1 -> 9 | G21: =EDATE(G20,1) -> 44440 | H21: 2.2137889e+09 | J21: Grand Total | K21: =SUM(K13:K20) -> 6.2267614e+09 | L21: =SUM(L13:L20) -> 2.602103e+10 | N21: =N20+1 -> 5 | O21: LGS & SS | P21: =C16 -> 6779878078 | Q21: 15365915 | R21: =P21/Q21 -> 441.2284
F22: =F21+1 -> 10 | G22: =EDATE(G21,1) -> 44470 | H22: 2.1320286e+09 | N22: =N21+1 -> 6 | O22: ICR | P22: =C17 -> 7894064202 | Q22: 13415508 | R22: =P22/Q22 -> 588.42827
F23: =F22+1 -> 11 | G23: =EDATE(G22,1) -> 44501 | H23: 1.8889686e+09
F24: =F23+1 -> 12 | G24: =EDATE(G23,1) -> 44531 | H24: 2.22998e+09
F25: =F24+1 -> 13 | G25: =EDATE(G24,1) -> 44562 | H25: 2.440322e+09
F26: =F25+1 -> 14 | G26: =EDATE(G25,1) -> 44593 | H26: 2.158987e+09
F27: =F26+1 -> 15 | G27: =EDATE(G26,1) -> 44621 | H27: 2.1506277e+09
F29: =F27+1 -> 16 | H29: =SUM(H13:H15) -> 6.2267614e+09 | I29: ="January "&YEAR(G15)&" through March "&YEAR(G13) -> January 2021 through March 2021
F31: =F29+1 -> 17 | H31: =SUM(H16:H27) -> 2.602103e+10 | I31: ="April "&YEAR(G16)&" through March "&YEAR(G27) -> April 2021 through March 2022
B33: Sources:
B34: Columns (a) and (c) from Company books/forecasts.
B35: Columns (d) and (e) are the allocation of total forecast sales for the period to revenue class.
B36: Columns (g) and (h), Lines 1-3 are the forecast demand sales for the period * hours.
B37: Column (g) Lines 4-6 from Company books.

Sheet A&G Credit
A3: MIDAMERCIAN ENERGY COMPANY
A4: =Sales!A4 -> 2020 TCA RECONCILIATION and 2021 NEW FACTOR CALCULATION
C5: Page 2 of 7
B8: MULTI-VALUE PROJECT A&G CREDIT
B9: Total Company Electric Operations
B10: ="Year Ending December 31, "&YEAR(Sales!G13) -> Year Ending December 31, 2021
A12: Line No.
B13: Description | C13: Value
C14: (a)
A15: 1 | B15: Rate Template Attachment MM Annual Allocation Factor for Other Expense | C15: 4372386
A16: 2 | B16: MidAmerican Energy Ratio as a Percentage of Total MISO Energy | C16: 0.062823838
A17: 3 | B17: Allocation of Other Expenses to MidAmerican | C17: =C15*C16 -> 274690.07
A19: Line No. | B19: Sources:
A20: 1 | B20: ="MidAmerican's "&YEAR(Sales!G13)&" Attachment MM Rate Template" -> MidAmerican's 2021 Attachment MM Rate Template
A21: 2 | B21: ="Calculation of MidAmerican's "&YEAR(Sales!G13)&" energy forecast divided by total MISO energy " -> Calculation of MidAmerican's 2021 energy forecast divided by total MISO energy
A22: 3 | B22: Line 1 x Line 2

Sheet Forecast Costs & Credits
A3: MIDAMERCIAN ENERGY COMPANY
A4: =Sales!A4 -> 2020 TCA RECONCILIATION and 2021 NEW FACTOR CALCULATION
O5: Page 3 of 7
A8: MISO COSTS
A9: Total Company Electric Operations
C11: (a) | D11: (b) | E11: (c) | F11: (d) | G11: (e) | H11: (f) | I11: (g) | J11: (h) | K11: (i) | L11: (j) | M11: (k) | N11: (l) | O11: (m)
C12: Actual | D12: Actual | E12: Forecast | F12: Forecast | G12: Forecast | H12: Forecast | I12: Forecast | J12: Forecast | K12: Forecast | L12: Forecast | M12: Forecast | N12: Forecast
A13: Line No. | B13: MidAmerican TCA Transmission Charges | C13: =Sales!G13 -> 44197 | D13: =EDATE(C13,1) -> 44228 | E13: =EDATE(D13,1) -> 44256 | F13: =EDATE(E13,1) -> 44287 | G13: =EDATE(F13,1) -> 44317 | H13: =EDATE(G13,1) -> 44348 | I13: =EDATE(H13,1) -> 44378 | J13: =EDATE(I13,1) -> 44409 | K13: =EDATE(J13,1) -> 44440 | ... N13: =EDATE(M13,1) -> 44531 | O13: =YEAR(C13)&" TOTAL" -> 2021 TOTAL
A15: 1 | B15: Schedule 9 Charge | C15: 12610 | D15: 14111 | E15: 411 | F15: 7995 | G15: 6116 | H15: 838 | I15: 6765 | J15: 1548 | K15: 42174 | L15: 617 | M15: 7940 | N15: 1521 | O15: =SUM(C15:N15) -> 102646
A16: =A15+1 -> 2 | B16: Schedule 10 Charge (MISO Adder) | C16: 519896 | D16: 507799 | E16: 463316 | F16: 485104 | G16: 511209 | H16: 470226 | I16: 454795 | J16: 512281 | K16: 453156 | L16: 513449 | M16: 482460 | N16: 456960 | O16: =SUM(C16:N16) -> 5830651
A17: =A16+1 -> 3 | B17: Schedule 10-FERC Charge | C17: 164756 | D17: 191918 | E17: 167554 | F17: 169663 | G17: 152870 | H17: 191919 | I17: 216035 | J17: 238569 | K17: 229623 | L17: 208154 | M17: 168871 | N17: 168039 | O17: =SUM(C17:N17) -> 2267971
A18: =A17+1 -> 4 | B18: Schedule 26 Charge | C18: 41290 | D18: 104052 | E18: 102136 | F18: 93413 | G18: 86973 | H18: 105667 | I18: 122910 | J18: 131351 | K18: 126426 | L18: 118426 | M18: 92977 | N18: 95603 | O18: =SUM(C18:N18) -> 1221224
A19: =A18+1 -> 5 | B19: Schedule 26-A Charge | C19: 3839578 | D19: 4076988 | E19: 4008154 | F19: 4153040 | G19: 4738583 | H19: 4474886 | I19: 3734738 | J19: 3829872 | K19: 4044617 | L19: 4160378 | M19: 4288366 | N19: 3616078 | O19: =SUM(C19:N19) -> 48965278
A20: =A19+1 -> 6 | B20: MISO MVP Distributions | C20: -23852.36 | D20: -13182.45 | E20: -13182.45 | F20: -13182.45 | G20: -13182.45 | H20: -13182.45 | I20: -13182.45 | J20: -13182.45 | K20: -13182.45 | L20: -13182.45 | M20: -13182.45 | N20: -13182.45 | O20: =SUM(C20:N20) -> -168859.31
A21: =A20+1 -> 7 | B21: TOTAL | C21: =SUM(C15:C20) -> 4554277.6 | D21: =SUM(D15:D20) -> 4881685.6 | E21: =SUM(E15:E20) -> 4728388.6 | F21: =SUM(F15:F20) -> 4896032.6 | G21: =SUM(G15:G20) -> 5482568.6 | H21: =SUM(H15:H20) -> 5230353.6 | I21: =SUM(I15:I20) -> 4522060.6 | J21: =SUM(J15:J20) -> 4700438.6 | ... O21: =SUM(O15:O20) -> 58218911
A24: MISO CREDITS
A25: Total Company Electric Operations
B27: Description | C27: =C13 -> 44197 | D27: =D13 -> 44228 | E27: =E13 -> 44256 | F27: =F13 -> 44287 | G27: =G13 -> 44317 | H27: =H13 -> 44348 | I27: =I13 -> 44378 | J27: =J13 -> 44409 | ... O27: =O13 -> 2021 TOTAL
A29: =A21+1 -> 8 | B29: Forecasted A&G in MISO rates (CREDIT) | C29: ='A&G Credit'!$C$17/12 -> 22890.839 | D29: ='A&G Credit'!$C$17/12 -> 22890.839 | E29: ='A&G Credit'!$C$17/12 -> 22890.839 | F29: ='A&G Credit'!$C$17/12 -> 22890.839 | G29: ='A&G Credit'!$C$17/12 -> 22890.839 | H29: ='A&G Credit'!$C$17/12 -> 22890.839 | I29: ='A&G Credit'!$C$17/12 -> 22890.839 | J29: ='A&G Credit'!$C$17/12 -> 22890.839 | ... N29: ='A&G Credit'!$C$17/12 -> 22890.839 | O29: =SUM(C29:N29) -> 274690.07
A31: Line No. | B31: Sources:
B32: Columns (a) - (b) are ACTUAL, columns (c) - (l) are FORECAST
A33: 6 | B33: January is an actual, the remaining months are an average of the previous two years.
A34: 8 | B34: Each month is 1/12 of Page 2, Column (a), Line 3.

Sheet Net Forecast Costs
A3: MIDAMERCIAN ENERGY COMPANY
A4: =Sales!A4 -> 2020 TCA RECONCILIATION and 2021 NEW FACTOR CALCULATION
O5: Page 4 of 7
A8: NET MISO COSTS
A9: Total Company Electric Operations
C11: (a) | D11: (b) | E11: (c) | F11: (d) | G11: (e) | H11: (f) | I11: (g) | J11: (h) | K11: (i) | L11: (j) | M11: (k) | N11: (l) | O11: (m)
C12: Actual | D12: Forecast | E12: Forecast | F12: Forecast | G12: Forecast | H12: Forecast | I12: Forecast | J12: Forecast | K12: Forecast | L12: Forecast | M12: Forecast | N12: Forecast
A13: Line No. | C13: =Sales!G13 -> 44197 | D13: =EDATE(C13,1) -> 44228 | E13: =EDATE(D13,1) -> 44256 | F13: =EDATE(E13,1) -> 44287 | G13: =EDATE(F13,1) -> 44317 | H13: =EDATE(G13,1) -> 44348 | I13: =EDATE(H13,1) -> 44378 | J13: =EDATE(I13,1) -> 44409 | K13: =EDATE(J13,1) -> 44440 | ... N13: =EDATE(M13,1) -> 44531 | O13: =YEAR(C13)&" TOTAL" -> 2021 TOTAL
A14: 1 | B14: NET MISO COSTS | C14: ='Forecast Costs & Credits'!C21-'Forecast Costs & Credits'!C29 -> 4531386.8 | D14: ='Forecast Costs & Credits'!D21-'Forecast Costs & Credits'!D29 -> 4858794.7 | E14: ='Forecast Costs & Credits'!E21-'Forecast Costs & Credits'!E29 -> 4705497.7 | F14: ='Forecast Costs & Credits'!F21-'Forecast Costs & Credits'!F29 -> 4873141.7 | G14: ='Forecast Costs & Credits'!G21-'Forecast Costs & Credits'!G29 -> 5459677.7 | H14: ='Forecast Costs & Credits'!H21-'Forecast Costs & Credits'!H29 -> 5207462.7 | I14: ='Forecast Costs & Credits'!I21-'Forecast Costs & Credits'!I29 -> 4499169.7 | J14: ='Forecast Costs & Credits'!J21-'Forecast Costs & Credits'!J29 -> 4677547.7 | ... N14: ='Forecast Costs & Credits'!N21-'Forecast Costs & Credits'!N29 -> 4302127.7 | O14: =SUM(C14:N14) -> 57944221
A17: NET MISO COSTS
A18: IOWA ONLY
C20: =+C12 -> Actual | D20: =+D12 -> Forecast | E20: Forecast | F20: Forecast | G20: Forecast | H20: Forecast | I20: Forecast | J20: Forecast | K20: Forecast | L20: Forecast | M20: Forecast | N20: Forecast
C21: =C13 -> 44197 | D21: =D13 -> 44228 | E21: =E13 -> 44256 | F21: =F13 -> 44287 | G21: =G13 -> 44317 | H21: =H13 -> 44348 | I21: =I13 -> 44378 | J21: =J13 -> 44409 | ... O21: =O13 -> 2021 TOTAL
A22: 2 | B22: IA ALLOCATION | C22: 0.904 | D22: =$C$22 -> 0.904 | E22: =$C$22 -> 0.904 | F22: =$C$22 -> 0.904 | G22: =$C$22 -> 0.904 | H22: =$C$22 -> 0.904 | I22: =$C$22 -> 0.904 | J22: =$C$22 -> 0.904 | K22: =$C$22 -> 0.904 | ... N22: =$C$22 -> 0.904
A23: 3 | B23: IA ALLOCATION OF NET MISO COSTS | C23: =C14*C22 -> 4096373.7 | D23: =D14*D22 -> 4392350.4 | E23: =E14*E22 -> 4253769.9 | F23: =F14*F22 -> 4405320.1 | G23: =G14*G22 -> 4935548.7 | H23: =H14*H22 -> 4707546.3 | I23: =I14*I22 -> 4067249.4 | J23: =J14*J22 -> 4228503.1 | ... N23: =N14*N22 -> 3889123.5 | O23: =SUM(C23:N23) -> 52381575
A26: NET MISO COSTS
A27: IOWA ONLY by Revenue Class
C29: =+C12 -> Actual | D29: =+D12 -> Forecast | E29: Forecast | F29: Forecast | G29: Forecast | H29: Forecast | I29: Forecast | J29: Forecast | K29: Forecast | L29: Forecast | M29: Forecast | N29: Forecast
C30: =C13 -> 44197 | D30: =D13 -> 44228 | E30: =E13 -> 44256 | F30: =F13 -> 44287 | G30: =G13 -> 44317 | H30: =H13 -> 44348 | I30: =I13 -> 44378 | J30: =J13 -> 44409 | ... O30: =O13 -> 2021 TOTAL
A31: 4 | B31: Residential | C31: =C$23*$C44 -> 1290164.9 | D31: =D$23*$C44 -> 1383383.6 | E31: =E$23*$C44 -> 1339737.3 | F31: =F$23*$C44 -> 1387468.4 | G31: =G$23*$C44 -> 1554465.5 | H31: =H$23*$C44 -> 1482655.5 | I31: =I$23*$C44 -> 1280992.1 | J31: =J$23*$C44 -> 1331779.4 | ... N31: =N$23*$C44 -> 1224890.8 | O31: =SUM(C31:N31) -> 16497730
A32: 5 | B32: Small General Service Demand | C32: =C$23*$C45 -> 402673.29 | D32: =D$23*$C45 -> 431767.79 | E32: =E$23*$C45 -> 418145.34 | F32: =F$23*$C45 -> 433042.71 | G32: =G$23*$C45 -> 485164.14 | H32: =H$23*$C45 -> 462751.52 | I32: =I$23*$C45 -> 399810.38 | J32: =J$23*$C45 -> 415661.61 | ... N32: =N$23*$C45 -> 382300.61 | O32: =SUM(C32:N32) -> 5149105.8
A33: 6 | B33: Small General Service Energy | C33: =C$23*$C46 -> 306434.42 | D33: =D$23*$C46 -> 328575.34 | E33: =E$23*$C46 -> 318208.65 | F33: =F$23*$C46 -> 329545.55 | G33: =G$23*$C46 -> 369209.97 | H33: =H$23*$C46 -> 352153.96 | I33: =I$23*$C46 -> 304255.74 | J33: =J$23*$C46 -> 316318.53 | ... N33: =N$23*$C46 -> 290930.81 | O33: =SUM(C33:N33) -> 3918470.1
A34: 7 | B34: Large General Service & Substation | C34: =C$23*$C47 -> 1125108.3 | D34: =D$23*$C47 -> 1206401.1 | E34: =E$23*$C47 -> 1168338.7 | F34: =F$23*$C47 -> 1209963.4 | G34: =G$23*$C47 -> 1355595.7 | H34: =H$23*$C47 -> 1292972.7 | I34: =I$23*$C47 -> 1117109 | J34: =J$23*$C47 -> 1161398.9 | ... N34: =N$23*$C47 -> 1068185 | O34: =SUM(C34:N34) -> 14387102
A35: 8 | B35: Individual Contract Rates | C35: =C$23*$C48 -> 959492.02 | D35: =D$23*$C48 -> 1028818.5 | E35: =E$23*$C48 -> 996358.88 | F35: =F$23*$C48 -> 1031856.4 | G35: =G$23*$C48 -> 1156051.6 | H35: =H$23*$C48 -> 1102646.7 | I35: =I$23*$C48 -> 952670.26 | J35: =J$23*$C48 -> 990440.65 | ... N35: =N$23*$C48 -> 910947.88 | O35: =SUM(C35:N35) -> 12269316
A36: 9 | B36: Traffic Control Service | C36: =C$23*$C49 -> 703.05059 | D36: =D$23*$C49 -> 753.84835 | E36: =E$23*$C49 -> 730.06412 | F36: =F$23*$C49 -> 756.07431 | G36: =G$23*$C49 -> 847.07614 | H36: =H$23*$C49 -> 807.94465 | I36: =I$23*$C49 -> 698.05207 | J36: =J$23*$C49 -> 725.72765 | ... N36: =N$23*$C49 -> 667.48074 | O36: =SUM(C36:N36) -> 8990.1216
A37: 10 | B37: Water Pumping Service | C37: =C$23*$C50 -> 6417.7506 | D37: =D$23*$C50 -> 6881.4546 | E37: =E$23*$C50 -> 6664.3418 | F37: =F$23*$C50 -> 6901.7741 | G37: =G$23*$C50 -> 7732.4782 | H37: =H$23*$C50 -> 7375.269 | I37: =I$23*$C50 -> 6372.1219 | J37: =J$23*$C50 -> 6624.7566 | ... N37: =N$23*$C50 -> 6093.0536 | O37: =SUM(C37:N37) -> 82065.727
A38: 11 | B38: Lighting | C38: =C$23*$C51 -> 5379.9924 | D38: =D$23*$C51 -> 5768.7149 | E38: =E$23*$C51 -> 5586.7095 | F38: =F$23*$C51 -> 5785.7487 | G38: =G$23*$C51 -> 6482.1269 | H38: =H$23*$C51 -> 6182.6789 | I38: =I$23*$C51 -> 5341.7419 | J38: =J$23*$C51 -> 5553.5252 | ... N38: =N$23*$C51 -> 5107.7993 | O38: =SUM(C38:N38) -> 68795.598
A39: 12 | B39: TOTAL | C39: =SUM(C31:C38) -> 4096373.7 | D39: =SUM(D31:D38) -> 4392350.4 | E39: =SUM(E31:E38) -> 4253769.9 | F39: =SUM(F31:F38) -> 4405320.1 | G39: =SUM(G31:G38) -> 4935548.7 | H39: =SUM(H31:H38) -> 4707546.3 | I39: =SUM(I31:I38) -> 4067249.4 | J39: =SUM(J31:J38) -> 4228503.1 | ... N39: =SUM(N31:N38) -> 3889123.5 | O39: =SUM(C39:N39) -> 52381575
B43: 12-CP ALLOCATORS:
A44: =A39+1 -> 13 | B44: Residential | C44: 0.31495292
A45: =A44+1 -> 14 | B45: Small General Service Demand | C45: 0.098299941
A46: =A45+1 -> 15 | B46: Small General Service Energy | C46: 0.074806267
A47: =A46+1 -> 16 | B47: Large General Service & Substation | C47: 0.27465958
A48: =A47+1 -> 17 | B48: Individual Contract Rates | C48: 0.23422961
A49: =A48+1 -> 18 | B49: Traffic Control Service | C49: 0.00017162755
A50: =A49+1 -> 19 | B50: Water Pumping Service | C50: 0.0015666907
A51: =A50+1 -> 20 | B51: Lighting | C51: 0.0013133549
C52: =SUM(C44:C51) -> 1
A54: Line No. | B54: Sources:
A55: 1 | B55: Page 3, Line 7 less Line 8.
...

Sheet Actual O-U by Rev Class
A3: MIDAMERCIAN ENERGY COMPANY
A4: =Sales!A4 -> 2020 TCA RECONCILIATION and 2021 NEW FACTOR CALCULATION
P6: Page 5 of 7
A8: TCA COSTS AND REVENUE
A9: IOWA ONLY Electric Operations by REVENUE CLASS
C11: (a) | D11: (b) | E11: (c) | F11: (d) | G11: (e) | H11: (f) | I11: (g) | J11: (h) | K11: (i) | L11: (j) | M11: (k) | N11: (l) | O11: (m) | P11: (n)
C12: Over/Under | P12: Over/Under
C13: Balance at | P13: Balance at
A14: Line No. | C14: =TEXT(EOMONTH(Sales!G13,-13),"mm/dd/yy") -> 12/31/19 | D14: =EDATE(Sales!G13,-12) -> 43831 | E14: =EDATE(D14,1) -> 43862 | F14: =EDATE(E14,1) -> 43891 | G14: =EDATE(F14,1) -> 43922 | H14: =EDATE(G14,1) -> 43952 | I14: =EDATE(H14,1) -> 43983 | J14: =EDATE(I14,1) -> 44013 | K14: =EDATE(J14,1) -> 44044 | L14: =EDATE(K14,1) -> 44075 | ... O14: =EDATE(N14,1) -> 44166 | P14: =TEXT(EOMONTH(Sales!G13,-1),"mm/dd/yy") -> 12/31/20
A15: 1 | B15: Residential - COSTS | C15: 53126608 | D15: 1278179 | E15: 1331483.9 | F15: 1124318.2 | G15: 1313335.1 | H15: 1092765.6 | I15: 1136483.1 | J15: 1236429.9 | K15: 1389105.6 | L15: 1171986.7 | M15: 1275995.3 | N15: 1101190 | O15: 1376945.3 | P15: =SUM(C15:O15) -> 67954826
B16: MISO ROE Refund - INTEREST | C16: 297.5896 | E16: 0 | F16: 0 | G16: 0 | H16: 0 | I16: 0 | J16: 0 | K16: 0 | L16: 0 | M16: 0 | N16: 0 | O16: 0 | P16: =SUM(C16:O16) -> 297.5896
A17: 2 | B17: Residential - REVENUE | C17: 53075280 | D17: 1068840.3 | E17: 887568.62 | F17: 865376.26 | G17: 1086657.6 | H17: 903427.41 | I17: 1335645.8 | J17: 1766489.5 | K17: 1592768.3 | L17: 1450673.2 | M17: 1005851 | N17: 966110.09 | O17: 1309880.2 | P17: =SUM(C17:O17) -> 67314568
A18: 3 | B18: (Under-)/Over-collection | C18: -51030.801 | D18: -209338.67 | E18: -443915.33 | F18: -258941.97 | G18: -226677.51 | H18: -189338.15 | I18: 199162.71 | J18: 530059.57 | K18: 203662.68 | L18: 278686.45 | M18: -270144.21 | N18: -135079.91 | O18: -67065.17 | P18: =SUM(C18:O18) -> -639960.3
A20: 4 | B20: SGS Demand - COSTS | C20: 19907417 | D20: 412629.01 | E20: 429837.23 | F20: 362958.81 | G20: 423978.32 | H20: 352772.8 | I20: 366885.94 | J20: 399151.34 | K20: 448438.99 | L20: 378347.43 | M20: 411924.05 | N20: 355492.43 | O20: 444513.34 | P20: =SUM(C20:O20) -> 24694347
B21: MISO ROE Refund - INTEREST | C21: 109.91841 | E21: 0 | F21: 0 | G21: 0 | H21: 0 | I21: 0 | J21: 0 | K21: 0 | L21: 0 | M21: 0 | N21: 0 | O21: 0 | P21: =SUM(C21:O21) -> 109.91841
A22: 5 | B22: SGS Demand - REVENUE | C22: 19372389 | D22: 316833.39 | E22: 279015.16 | F22: 315417.97 | G22: 381412.2 | H22: 339244.41 | I22: 440131.62 | J22: 480301.17 | K22: 443200.94 | L22: 451982.69 | M22: 400351.33 | N22: 355636.92 | O22: 366008.7 | P22: =SUM(C22:O22) -> 23941925
A23: 6 | B23: (Under-)/Over-collection | C23: -534918.91 | D23: -95795.622 | E23: -150822.07 | F23: -47540.84 | G23: -42566.118 | H23: -13528.389 | I23: 73245.677 | J23: 81149.829 | K23: -5238.0465 | L23: 73635.262 | M23: -11572.722 | N23: 144.49489 | O23: -78504.636 | P23: =SUM(C23:O23) -> -752312.09
A25: 7 | B25: SGS Energy - COSTS | C25: 12150187 | D25: 313830.6 | E25: 326918.54 | F25: 276053.25 | G25: 322462.47 | H25: 268306.15 | I25: 279040.09 | J25: 303579.98 | K25: 341066.36 | L25: 287757.28 | M25: 313294.43 | N25: 270374.59 | O25: 338080.66 | P25: =SUM(C25:O25) -> 15790951
B26: MISO ROE Refund - INTEREST | C26: 71.159403 | E26: 0 | F26: 0 | G26: 0 | H26: 0 | I26: 0 | J26: 0 | K26: 0 | L26: 0 | M26: 0 | N26: 0 | O26: 0 | P26: =SUM(C26:O26) -> 71.159403
A27: 8 | B27: SGS Energy - REVENUE | C27: 12240351 | D27: 329548.56 | E27: 276960.98 | F27: 275991.16 | G27: 249802.2 | H27: 200461.08 | I27: 265640.79 | J27: 327186.58 | K27: 310201.43 | L27: 306136.81 | M27: 287486.09 | N27: 272729.57 | O27: 322041.52 | P27: =SUM(C27:O27) -> 15664537
A28: 9 | B28: (Under-)/Over-collection | C28: 90235.294 | D28: 15717.959 | E28: -49957.564 | F28: -62.094881 | G28: -72660.271 | H28: -67845.066 | I28: -13399.299 | J28: 23606.604 | K28: -30864.934 | L28: 18379.533 | M28: -25808.345 | N28: 2354.9759 | O28: -16039.138 | P28: =SUM(C28:O28) -> -126342.34
A30: 10 | B30: LGS & SS - COSTS | C30: 49122152 | D30: 1202146.8 | E30: 1252281 | F30: 1057438.4 | G30: 1235211.7 | H30: 1027762.7 | I30: 1068879.7 | J30: 1162881.2 | K30: 1306475 | L30: 1102271.4 | M30: 1200093 | N30: 1035686 | O30: 1295038.1 | P30: =SUM(C30:O30) -> 63068317
B31: MISO ROE Refund - INTEREST | C31: 295.30995 | E31: 0 | F31: 0 | G31: 0 | H31: 0 | I31: 0 | J31: 0 | K31: 0 | L31: 0 | M31: 0 | N31: 0 | O31: 0 | P31: =SUM(C31:O31) -> 295.30995
A32: 11 | B32: LGS & SS - REVENUE | C32: 47783203 | D32: 912285.67 | E32: 809518.73 | F32: 939231.91 | G32: 1119089.5 | H32: 1022462.3 | I32: 1297888.4 | J32: 1315555.3 | K32: 1283528.4 | L32: 1259492.4 | M32: 1169001.9 | N32: 1160722.3 | O32: 1101345.1 | P32: =SUM(C32:O32) -> 61173325
A33: 12 | B33: (Under-)/Over-collection | C33: -1338653.8 | D33: -289861.15 | E33: -442762.24 | F33: -118206.54 | G33: -116122.24 | H33: -5300.3424 | I33: 229008.71 | J33: 152674.13 | K33: -22946.627 | L33: 157220.97 | M33: -31091.076 | N33: 125036.34 | O33: -193693 | P33: =SUM(C33:O33) -> -1894696.8
A35: 13 | B35: ICR - COSTS | C35: 27274695 | D35: 858353.24 | E35: 894149.87 | F35: 755029 | G35: 881962.13 | H35: 733840 | I35: 763198.25 | J35: 830316.91 | K35: 932845.36 | L35: 787040.49 | M35: 856886.78 | N35: 739497.39 | O35: 924679.2 | P35: =SUM(C35:O35) -> 37232493
B36: MISO ROE Refund - INTEREST | C36: 155.61832 | E36: 0 | F36: 0 | G36: 0 | H36: 0 | I36: 0 | J36: 0 | K36: 0 | L36: 0 | M36: 0 | N36: 0 | O36: 0 | P36: =SUM(C36:O36) -> 155.61832
A37: 14 | B37: ICR - REVENUE | C37: 26472156 | D37: 630071.03 | E37: 605016.09 | F37: 683580.49 | G37: 660338.52 | H37: 939023.54 | I37: 1016736.6 | J37: 1062413.2 | K37: 1035291.5 | L37: 1145912.9 | M37: 989147.25 | N37: 1062576.1 | O37: 1052516 | P37: =SUM(C37:O37) -> 37354779
A38: 15 | B38: (Under-)/Over-collection | C38: -802383.38 | D38: -228282.21 | E38: -289133.78 | F38: -71448.514 | G38: -221623.61 | H38: 205183.54 | I38: 253538.38 | J38: 232096.26 | K38: 102446.17 | L38: 358872.46 | M38: 132260.47 | N38: 323078.67 | O38: 127836.81 | P38: =SUM(C38:O38) -> 122441.26
A40: 16 | B40: Traffic Control - COSTS | C40: 29489.631 | D40: 700.08152 | E40: 729.27761 | F40: 615.80923 | G40: 719.33717 | H40: 598.52727 | I40: 622.47215 | J40: 677.21481 | K40: 760.83804 | L40: 641.91813 | M40: 698.88546 | N40: 603.14149 | O40: 754.17763 | P40: =SUM(C40:O40) -> 37611.312
B41: MISO ROE Refund - INTEREST | C41: 0.18491777 | E41: 0 | F41: 0 | G41: 0 | H41: 0 | I41: 0 | J41: 0 | K41: 0 | L41: 0 | M41: 0 | N41: 0 | O41: 0 | P41: =SUM(C41:O41) -> 0.18491777
A42: 17 | B42: Traffic Control - REVENUE | C42: 29438.13 | D42: 753.16 | E42: 598.57 | F42: 647.81 | G42: 658.73 | H42: 580.91 | I42: 635.44 | J42: 618.44 | K42: 581.66 | L42: 642.59 | M42: 608.4 | N42: 604.99 | O42: 709.09 | P42: =SUM(C42:O42) -> 37077.92
A43: 18 | B43: (Under-)/Over-collection | C43: -51 | D43: 53.078482 | E43: -130.70761 | F43: 32.000767 | G43: -60.607168 | H43: -17.617273 | I43: 12.96785 | J43: -58.774809 | K43: -179.17804 | L43: 0.67187471 | M43: -90.485459 | N43: 1.8485103 | O43: -45.087634 | P43: =ROUND(SUM(C43:O43),0) -> -533
A45: 19 | B45: Water Pumping - COSTS | C45: 253486.78 | D45: 6606.4662 | E45: 6881.9812 | F45: 5811.2131 | G45: 6788.1762 | H45: 5648.1283 | I45: 5874.0891 | J45: 6390.6797 | K45: 7179.8078 | L45: 6057.5951 | M45: 6595.1793 | N45: 5691.6713 | O45: 7116.9556 | P45: =SUM(C45:O45) -> 330128.72
B46: MISO ROE Refund - INTEREST | C46: 1.6006035 | E46: 0 | F46: 0 | G46: 0 | H46: 0 | I46: 0 | J46: 0 | K46: 0 | L46: 0 | M46: 0 | N46: 0 | O46: 0 | P46: =SUM(C46:O46) -> 1.6006035
A47: 20 | B47: Water Pumping - REVENUE | C47: 251418.96 | D47: 4318.2 | E47: 4060.12 | F47: 4286.97 | G47: 7731.82 | H47: 6302.46 | I47: 7029.77 | J47: 8186.68 | K47: 7233.97 | L47: 8748.01 | M47: 6940.37 | N47: 5625.44 | O47: 7277.56 | P47: =SUM(C47:O47) -> 329160.33
A48: 21 | B48: (Under-)/Over-collection | C48: -2066.2152 | D48: -2288.2662 | E48: -2821.8612 | F48: -1524.2431 | G48: 943.64381 | H48: 654.33175 | I48: 1155.6809 | J48: 1796.0003 | K48: 54.162161 | L48: 2690.4149 | M48: 345.19066 | N48: -66.23128 | O48: 160.60444 | P48: =SUM(C48:O48) -> -966.78813
A50: 22 | B50: Lighting - COSTS | C50: 388420.25 | D50: 5301.9911 | E50: 5523.1046 | F50: 4663.7642 | G50: 5447.8217 | H50: 4532.8811 | I50: 4714.225 | J50: 5128.8126 | K50: 5762.124 | L50: 4861.497 | M50: 5292.9329 | N50: 4567.8264 | O50: 5711.6822 | P50: =SUM(C50:O50) -> 449928.91
B51: MISO ROE Refund - INTEREST | C51: 2.0988003 | E51: 0 | F51: 0 | G51: 0 | H51: 0 | I51: 0 | J51: 0 | K51: 0 | L51: 0 | M51: 0 | N51: 0 | O51: 0 | P51: =SUM(C51:O51) -> 2.0988003
A52: 23 | B52: Lighting - REVENUE | C52: 382754.08 | D52: 5691.83 | E52: 4311.21 | F52: 4417.46 | G52: 4848.3 | H52: 4065.59 | I52: 4293.64 | J52: 4303.46 | K52: 4213.67 | L52: 4866.76 | M52: 6061.65 | N52: 4759.46 | O52: 6948.77 | P52: =SUM(C52:O52) -> 441535.88
...

Sheet Rev Difference by Rev Class
A3: MIDAMERCIAN ENERGY COMPANY
A4: =Sales!A4 -> 2020 TCA RECONCILIATION and 2021 NEW FACTOR CALCULATION
F5: Page 6 of 7
A8: JANUARY THROUGH MARCH REVENUE DIFFERENCE
A9: IOWA ONLY Electric Operations by REVENUE CLASS
C12: =TEXT(Sales!G13,"mmm-yy")&" through "&TEXT(Sales!G15,"mmm-yy") -> Jan-21 through Mar-21
C13: (a) | D13: (b) | E13: (c) | F13: (d)
D14: Current TCA | E14: Hypothetical TCA | F14: Revenue
A15: Line No. | C15: Sales | D15: Factor | E15: Factor | F15: Difference
A16: 1 | B16: Residential - COSTS | E16: ='Net Forecast Costs'!C31+'Net Forecast Costs'!D31+'Net Forecast Costs'!E31 -> 4013285.7
A17: =A16+1 -> 2 | B17: Residential - KWH SALES | C17: =Sales!K13 -> 1.5218513e+09 | D17: 0.00259 | E17: =E16/C17 -> 0.0026371076
A18: =A17+1 -> 3 | B18: Residential - REVENUE | D18: =C17*D17 -> 3941594.9 | E18: =C17*E17 -> 4013285.7
A19: 4 | B19: (Under-)/Over-collection | F19: =D18-E18 -> -71690.778
A21: =A19+1 -> 5 | B21: SGS Demand - COSTS | E21: ='Net Forecast Costs'!C32+'Net Forecast Costs'!D32+'Net Forecast Costs'!E32 -> 1252586.4
A22: =A21+1 -> 6 | B22: SGS Demand - KW SALES | C22: =Sales!Q13 -> 1434868.4 | D22: 0.87 | E22: =E21/C22 -> 0.87296259
A23: =A22+1 -> 7 | B23: SGS Demand - REVENUE | D23: =C22*D22 -> 1248335.5 | E23: =C22*E22 -> 1252586.4
A24: =A23+1 -> 8 | B24: (Under-)/Over-collection | F24: =D23-E23 -> -4250.9244
A26: =A24+1 -> 9 | B26: SGS Energy - COSTS | E26: ='Net Forecast Costs'!C33+'Net Forecast Costs'!D33+'Net Forecast Costs'!E33 -> 953218.41
A27: =A26+1 -> 10 | B27: SGS Energy - KWH SALES | C27: =Sales!K15 -> 4.1057026e+08 | D27: 0.00221 | E27: =E26/C27 -> 0.0023216938
A28: =A27+1 -> 11 | B28: SGS Energy - REVENUE | D28: =C27*D27 -> 907360.26 | E28: =C27*E27 -> 953218.41
A29: =A28+1 -> 12 | B29: (Under-)/Over-collection | F29: =D28-E28 -> -45858.141
A31: =A29+1 -> 13 | B31: LGS & SS - COSTS | E31: ='Net Forecast Costs'!C34+'Net Forecast Costs'!D34+'Net Forecast Costs'!E34 -> 3499848.1
A32: =A31+1 -> 14 | B32: LGS & SS - KW SALES | C32: =Sales!Q14 -> 3926686.4 | D32: 0.93 | E32: =E31/C32 -> 0.89129808
A33: =A32+1 -> 15 | B33: LGS & SS - REVENUE | D33: =C32*D32 -> 3651818.4 | E33: =C32*E32 -> 3499848.1
A34: =A33+1 -> 16 | B34: (Under-)/Over-collection | F34: =D33-E33 -> 151970.29
A36: =A34+1 -> 17 | B36: ICR - COSTS | E36: ='Net Forecast Costs'!C35+'Net Forecast Costs'!D35+'Net Forecast Costs'!E35 -> 2984669.4
A37: =A36+1 -> 18 | B37: ICR - KW SALES | C37: =Sales!Q15 -> 3428269.3 | D37: 0.91 | E37: =E36/C37 -> 0.87060532
A38: =A37+1 -> 19 | B38: ICR - REVENUE | D38: =C37*D37 -> 3119725 | E38: =C37*E37 -> 2984669.4
A39: =A38+1 -> 20 | B39: (Under-)/Over-collection | F39: =D38-E38 -> 135055.58
A41: =A39+1 -> 21 | B41: Traffic Control - COSTS | E41: ='Net Forecast Costs'!C36+'Net Forecast Costs'!D36+'Net Forecast Costs'!E36 -> 2186.9631
A42: =A41+1 -> 22 | B42: Traffic Control - KWH SALES | C42: =Sales!K18 -> 1332736.1 | D42: 0.00149 | E42: =E41/C42 -> 0.0016409573
A43: =A42+1 -> 23 | B43: Traffic Control - REVENUE | D43: =C42*D42 -> 1985.7769 | E43: =C42*E42 -> 2186.9631
A44: =A43+1 -> 24 | B44: (Under-)/Over-collection | F44: =D43-E43 -> -201.18621
A46: =A44+1 -> 25 | B46: Water Pumping - COSTS | E46: ='Net Forecast Costs'!C37+'Net Forecast Costs'!D37+'Net Forecast Costs'!E37 -> 19963.547
A47: =A46+1 -> 26 | B47: Water Pumping - KWH SALES | C47: =Sales!K19 -> 12330490 | D47: 0.00184 | E47: =E46/C47 -> 0.0016190392
A48: =A47+1 -> 27 | B48: Water Pumping - REVENUE | D48: =C47*D47 -> 22688.102 | E48: =C47*E47 -> 19963.547
A49: =A48+1 -> 28 | B49: (Under-)/Over-collection | F49: =D48-E48 -> 2724.5551
A51: =A49+1 -> 29 | B51: Lighting - COSTS | E51: ='Net Forecast Costs'!C38+'Net Forecast Costs'!D38+'Net Forecast Costs'!E38 -> 16735.417
A52: =A51+1 -> 30 | B52: Lighting - KWH SALES | C52: =Sales!K20 -> 20231301 | D52: 0.0008 | E52: =E51/C52 -> 0.00082720418
A53: =A52+1 -> 31 | B53: Lighting - REVENUE | D53: =C52*D52 -> 16185.041 | E53: =C52*E52 -> 16735.417
...

Sheet TCA factor calc
A3: MIDAMERCIAN ENERGY COMPANY
A4: =Sales!A4 -> 2020 TCA RECONCILIATION and 2021 NEW FACTOR CALCULATION
J6: Page 7 of 7
B8: TCA FACTOR CALCULATION
D11: Cumulative | G11: Forecasted | H11: Forecasted
C12: =YEAR(Sales!G13)&" Forecasted" -> 2021 Forecasted | D12: Over/(Under) | E12: =YEAR(Sales!G13)&" Forecast" -> 2021 Forecast | G12: Sales (kWh) | H12: Demand (kW)
A13: Line | C13: Transmission | D13: Balance | E13: Over/(Under) | F13: Total | G13: =TEXT(Sales!G16,"mmm-yy")&" through" -> Apr-21 through | H13: =G13 -> Apr-21 through | I13: TCA Rate | J13: TCA Rate
A14: No. | C14: Expense | D14: ='Actual O-U by Rev Class'!P14 -> 12/31/20 | E14: Jan-Mar | F14: Recoverable | G14: =Sales!G27 -> 44621 | H14: =G14 -> 44621 | I14: $ per kWh | J14: $ per kW
C15: (a) | D15: (b) | E15: (c) | F15: (d) | G15: (e) | H15: (f) | I15: (g) | J15: (h)
F16: (a) - (b) - (c) | I16: (d) / (e) | J16: (d) / (f)
A17: 1 | B17: Residential | C17: ='Net Forecast Costs'!O31 -> 16497730 | D17: ='Actual O-U by Rev Class'!$P$18 -> -639960.3 | E17: ='Rev Difference by Rev Class'!F19 -> -71690.778 | F17: =ROUND(C17-D17-E17,0) -> 17209381 | G17: =ROUND(Sales!L13,0) -> 6359668756 | I17: =F17/G17 -> 0.0027060185
A18: =A17+1 -> 2 | B18: Small General Service Demand | C18: ='Net Forecast Costs'!O32 -> 5149105.8 | D18: ='Actual O-U by Rev Class'!$P$23 -> -752312.09 | E18: ='Rev Difference by Rev Class'!F24 -> -4250.9244 | F18: =ROUND(C18-D18-E18,0) -> 5905669 | H18: =ROUND(Sales!R13,0) -> 5996175 | J18: =F18/H18 -> 0.98490604
A19: =A18+1 -> 3 | B19: Small General Service Energy | C19: ='Net Forecast Costs'!O33 -> 3918470.1 | D19: ='Actual O-U by Rev Class'!$P$28 -> -126342.34 | E19: ='Rev Difference by Rev Class'!F29 -> -45858.141 | F19: =ROUND(C19-D19-E19,0) -> 4090671 | G19: =ROUND(Sales!L15,0) -> 1715733181 | I19: =F19/G19 -> 0.0023842116
A20: =A19+1 -> 4 | B20: Large General Service & Substation | C20: ='Net Forecast Costs'!O34 -> 14387102 | D20: ='Actual O-U by Rev Class'!$P$33 -> -1894696.8 | E20: ='Rev Difference by Rev Class'!F34 -> 151970.29 | F20: =ROUND(C20-D20-E20,0) -> 16129828 | H20: =ROUND(Sales!R14,0) -> 16409241 | J20: =F20/H20 -> 0.98297222
A21: =A20+1 -> 5 | B21: Individual Contract Rates | C21: ='Net Forecast Costs'!O35 -> 12269316 | D21: ='Actual O-U by Rev Class'!$P$38 -> 122441.26 | E21: ='Rev Difference by Rev Class'!F39 -> 135055.58 | F21: =ROUND(C21-D21-E21,0) -> 12011819 | H21: =ROUND(Sales!R15,0) -> 14326404 | J21: =F21/H21 -> 0.83843922
A22: =A21+1 -> 6 | B22: Traffic Control Service | C22: ='Net Forecast Costs'!O36 -> 8990.1216 | D22: ='Actual O-U by Rev Class'!$P$43 -> -533 | E22: ='Rev Difference by Rev Class'!F44 -> -201.18621 | F22: =ROUND(C22-D22-E22,0) -> 9724 | G22: =ROUND(Sales!L18,0) -> 5569375 | I22: =F22/G22 -> 0.0017459769
A23: =A22+1 -> 7 | B23: Water Pumping Service | C23: ='Net Forecast Costs'!O37 -> 82065.727 | D23: ='Actual O-U by Rev Class'!$P$48 -> -966.78813 | E23: ='Rev Difference by Rev Class'!F49 -> 2724.5551 | F23: =ROUND(C23-D23-E23,0) -> 80308 | G23: =ROUND(Sales!L19,0) -> 51527920 | I23: =F23/G23 -> 0.0015585337
A24: =A23+1 -> 8 | B24: Lighting | C24: ='Net Forecast Costs'!O38 -> 68795.598 | D24: ='Actual O-U by Rev Class'!$P$53 -> -8390.9331 | E24: ='Rev Difference by Rev Class'!F54 -> -550.37597 | F24: =ROUND(C24-D24-E24,0) -> 77737 | G24: =ROUND(Sales!L20,0) -> 84544640 | I24: =F24/G24 -> 0.00091947875
A25: =A24+1 -> 9 | B25: Total | C25: =SUM(C17:C24) -> 52381575 | D25: =SUM(D17:D24) -> -3300761 | E25: =SUM(E17:E24) -> 167199.02 | F25: =SUM(F17:F24) -> 55515137
B27: Sources:
B28: Column (a) is from Page 4, Column (m), Lines 4-11
B29: Column (b) is from Page 5, Column (n), "(Under-)/Over-collection" lines
B30: Column (c) is from Page 6, Column (d), "(Under-)/Over-collection" lines
B31: Column (e) is from Page 1, Column (e)
B32: Column (f) is from Page 1, Column (h)
