Workbook
Name AlocList: '[1]Functional Alloc'!$A$4:$A$35
Name AlocList: '[2]Functional Alloc'!$A$4:$A$35
Name AlocTable: '[1]Functional Alloc'!$A$4:$K$35
Name AlocTable: '[2]Functional Alloc'!$A$4:$K$35
Name Recover: [3]Macro1!$A$1734
Name Recover: [3]Macro1!$A$1734
Name TableName: "Dummy"

Sheet Sales
A3: MIDAMERCIAN ENERGY COMPANY
A4: 2019 TCA RECONCILIATION and 2020 NEW FACTOR CALCULATION
R6: Page 1 of 7
A8: ACTUAL KWH SALES | F8: FORECAST KWH SALES | N8: FORECAST KW SALES
C10: 2019 | D10: Allocator for forecasts | H10: 2020 & 2021 Forecast | K10: Jan-20 through Mar-20 | L10: Apr-20 through Mar-21 | Q10: =K10 -> Jan-20 through Mar-20 | R10: =L10 -> Apr-20 through Mar-21
C11: (a) | D11: (b) | H11: (c) | K11: (d) | L11: (e) | P11: (f) | Q11: (g) | R11: (h)
A12: Line No. | C12: kWh | D12: % | F12: Line No. | H12: kWh | K12: kWh | L12: kWh | N12: Line No. | P12: Hours | Q12: kW | R12: kW
A13: 1 | B13: Residential | C13: 5869282682 | D13: =C13/$C$21 -> 0.24482766 | F13: 1 | G13: 43831 | H13: 2105567683 | J13: Residential | K13: =$H$29*D13 -> 1.4875184e+09 | L13: =$H$31*D13 -> 5.9819156e+09 | N13: 1 | O13: SGSD | P13: =R20 -> 356.58172 | Q13: =K14/P13 -> 1537898.8 | R13: =L14/P13 -> 6184515.7
A14: =A13+1 -> 2 | B14: SGSD | C14: 2163762105 | D14: =C14/$C$21 -> 0.090257845 | F14: =F13+1 -> 2 | G14: 43862 | H14: 1.9926991e+09 | J14: SGSD | K14: =$H$29*D14 -> 5.4838659e+08 | L14: =$H$31*D14 -> 2.2052852e+09 | N14: =N13+1 -> 2 | O14: LGS & SS | P14: =R21 -> 440.58757 | Q14: =K16/P14 -> 4138945.4 | R14: =L16/P14 -> 16644381
A15: =A14+1 -> 3 | B15: SGSE | C15: 1591388319 | D15: =C15/$C$21 -> 0.066382196 | F15: =F14+1 -> 3 | G15: 43891 | H15: 1.9775109e+09 | J15: SGSE | K15: =$H$29*D15 -> 4.0332346e+08 | L15: =$H$31*D15 -> 1.6219274e+09 | N15: =N14+1 -> 3 | O15: ICR | P15: =R22 -> 581.2297 | Q15: =K17/P15 -> 3060946.2 | R15: =L17/P15 -> 12309308
A16: =A15+1 -> 4 | B16: LGS & SS | C16: 7195228954 | D16: =C16/$C$21 -> 0.30013737 | F16: =F15+1 -> 4 | G16: 43922 | H16: 1.8839652e+09 | J16: LGS & SS | K16: =$H$29*D16 -> 1.8235679e+09 | L16: =$H$31*D16 -> 7.3333071e+09
A17: =A16+1 -> 5 | B17: ICR | C17: 7019823264 | D17: =C17/$C$21 -> 0.2928206 | F17: =F16+1 -> 5 | G17: 43952 | H17: 1.8608309e+09 | J17: ICR | K17: =$H$29*D17 -> 1.7791129e+09 | L17: =$H$31*D17 -> 7.1545354e+09
A18: =A17+1 -> 6 | B18: Traffic Controls | C18: 5287802 | D18: =C18/$C$21 -> 0.00022057213 | F18: =F17+1 -> 6 | G18: 43983 | H18: 1.92212e+09 | J18: Traffic Controls | K18: =$H$29*D18 -> 1340147.2 | L18: =$H$31*D18 -> 5389276.2
A19: =A18+1 -> 7 | B19: Water Pumping | C19: 45110759 | D19: =C19/$C$21 -> 0.0018817225 | F19: =F18+1 -> 7 | G19: 44013 | H19: 2.2894635e+09 | J19: Water Pumping | K19: =$H$29*D19 -> 11432928 | L19: =$H$31*D19 -> 45976445 | P19: 2019 kWh | Q19: 2019 kW | R19: Hours
A20: =A19+1 -> 8 | B20: Lighting | C20: 83235633 | D20: =C20/$C$21 -> 0.0034720401 | F20: =F19+1 -> 8 | G20: 44044 | H20: 2.2389178e+09 | J20: Lighting | K20: =$H$29*D20 -> 21095344 | L20: =$H$31*D20 -> 84832945 | N20: =N15+1 -> 4 | O20: SGSD | P20: =C14 -> 2163762105 | Q20: 6068068 | R20: =P20/Q20 -> 356.58172
A21: =A20+1 -> 9 | B21: Grand Total | C21: =SUM(C13:C20) -> 23973119518 | D21: =SUM(D13:D20) -> 1 | F21: =F20+1 -> 9 | G21: 44075 | H21: 2.0879054e+09 | J21: Grand Total | K21: =SUM(K13:K20) -> 6.0757776e+09 | L21: =SUM(L13:L20) -> 2.4433169e+10 | N21: =N20+1 -> 5 | O21: LGS & SS | P21: =C16 -> 7195228954 | Q21: 16330985 | R21: =P21/Q21 -> 440.58757
F22: =F21+1 -> 10 | G22: 44105 | H22: 1.9691495e+09 | N22: =N21+1 -> 6 | O22: ICR | P22: =C17 -> 7019823264 | Q22: 12077537 | R22: =P22/Q22 -> 581.2297
F23: =F22+1 -> 11 | G23: 44136 | H23: 1.7924631e+09
F24: =F23+1 -> 12 | G24: 44166 | H24: 2.1091471e+09
F25: =F24+1 -> 13 | G25: 44197 | H25: 2.2670813e+09
F26: =F25+1 -> 14 | G26: 44228 | H26: 2.0133396e+09
F27: =F26+1 -> 15 | G27: 44256 | H27: 1.998786e+09
F29: =F27+1 -> 16 | H29: =SUM(H13:H15) -> 6.0757776e+09 | I29: January 2020 through March 2020
F31: =F29+1 -> 17 | H31: =SUM(H16:H27) -> 2.4433169e+10 | I31: April 2020 through March 2021
B33: Sources:
B34: Columns (a) and (c) from Company books/forecasts.
B35: Columns (d) and (e) are the allocation of total forecast sales for the period to revenue class.
B36: Columns (g) and (h), Lines 1-3 are the forecast demand sales for the period * hours.
B37: Column (g) Lines 4-6 from Company books.

Sheet A&G Credit
A3: MIDAMERCIAN ENERGY COMPANY
A4: =Sales!A4 -> 2019 TCA RECONCILIATION and 2020 NEW FACTOR CALCULATION
C5: Page 2 of 7
B8: MULTI-VALUE PROJECT A&G CREDIT
B9: Total Company Electric Operations
B10: Year Ending December 31, 2020
A12: Line No.
B13: Description | C13: Value
C14: (a)
A15: 1 | B15: Rate Template Attachment MM Annual Allocation Factor for Other Expense | C15: 4310065
A16: 2 | B16: MidAmerican Energy Ratio as a Percentage of Total MISO Energy | C16: 0.057986852
A17: 3 | B17: Allocation of Other Expenses to MidAmerican | C17: =C15*C16 -> 249927.1
A19: Line No. | B19: Sources:
A20: 1 | B20: MidAmerican's 2020 Attachment MM Rate Template
A21: 2 | B21: Calculation of MidAmerican's 2020 energy forecast divided by total MISO energy
A22: 3 | B22: Line 1 x Line 2

Sheet Forecast Costs & Credits
A3: MIDAMERCIAN ENERGY COMPANY
A4: =Sales!A4 -> 2019 TCA RECONCILIATION and 2020 NEW FACTOR CALCULATION
O5: Page 3 of 7
A8: MISO COSTS
A9: Total Company Electric Operations
C11: (a) | D11: (b) | E11: (c) | F11: (d) | G11: (e) | H11: (f) | I11: (g) | J11: (h) | K11: (i) | L11: (j) | M11: (k) | N11: (l) | O11: (m)
C12: Actual | D12: Actual | E12: Forecast | F12: Forecast | G12: Forecast | H12: Forecast | I12: Forecast | J12: Forecast | K12: Forecast | L12: Forecast | M12: Forecast | N12: Forecast
A13: Line No. | B13: MidAmerican TCA Transmission Charges | C13: 43831 | D13: 43862 | E13: 43891 | F13: 43922 | G13: 43952 | H13: 43983 | I13: 44013 | J13: 44044 | K13: 44075 | L13: 44105 | M13: 44136 | N13: 44166 | O13: 2020 TOTAL
A15: 1 | B15: Schedule 9 Charge | C15: 20833 | D15: 8103 | E15: 2380.49 | F15: 9952.63 | G15: 1138.65 | H15: 5529.9 | I15: 4750.22 | J15: 7720.32 | K15: 5281.4913 | L15: 584.72 | M15: 4516.9794 | N15: -965.51 | O15: =SUM(C15:N15) -> 69825.891
A16: =A15+1 -> 2 | B16: Schedule 10 Charge (MISO Adder) | C16: 429916 | D16: 336133 | E16: 436136.99 | F16: 380610.62 | G16: 457832.7 | H16: 503318.15 | I16: 454894.54 | J16: 483615.06 | K16: 487922.44 | L16: 477507.91 | M16: 425860.57 | N16: 421830.16 | O16: =SUM(C16:N16) -> 5295578.1
A17: =A16+1 -> 3 | B17: Schedule 10-FERC Charge | C17: 151587 | D17: 154051 | E17: 144880.64 | F17: 141421.93 | G17: 127539.5 | H17: 160919.11 | I17: 181676.82 | J17: 200251.47 | K17: 192260.38 | L17: 173933.28 | M17: 140299.89 | N17: 140086.97 | O17: =SUM(C17:N17) -> 1908908
A18: =A17+1 -> 4 | B18: Schedule 26 Charge | C18: 29277 | D18: 30662 | E18: 30335.463 | F18: 27700.867 | G18: 25814.383 | H18: 31519.854 | I18: 36771.94 | J18: 39224.038 | K18: 37658.792 | L18: 35204.624 | M18: 27481.087 | N18: 28354.028 | O18: =SUM(C18:N18) -> 380004.08
A19: =A18+1 -> 5 | B19: Schedule 26-A Charge | C19: 3411328 | D19: 4042392 | E19: 3694445.6 | F19: 3576384.4 | G19: 3917357.4 | H19: 3716549.1 | I19: 3599813.5 | J19: 3560364.2 | K19: 3758348.1 | L19: 3770884.2 | M19: 3754143.4 | N19: 3317955.3 | O19: =SUM(C19:N19) -> 44119965
A20: =A19+1 -> 6 | B20: MISO MVP Distributions | C20: -34627.82 | D20: -12892 | E20: -12892 | F20: -12892 | G20: -12892 | H20: -12892 | I20: -12892 | J20: -12892 | K20: -12892 | L20: -12892 | M20: -12892 | N20: -12892 | O20: =SUM(C20:N20) -> -176439.82
A21: =A20+1 -> 7 | B21: TOTAL | C21: =SUM(C15:C20) -> 4008313.2 | D21: =SUM(D15:D20) -> 4558449 | E21: =SUM(E15:E20) -> 4295287.2 | F21: =SUM(F15:F20) -> 4123178.5 | G21: =SUM(G15:G20) -> 4516790.6 | H21: =SUM(H15:H20) -> 4404944.1 | I21: =SUM(I15:I20) -> 4265015.1 | J21: =SUM(J15:J20) -> 4278283.1 | ... O21: =SUM(O15:O20) -> 51597842
A24: MISO CREDITS
A25: Total Company Electric Operations
B27: Description | C27: =C13 -> 43831 | D27: =D13 -> 43862 | E27: =E13 -> 43891 | F27: =F13 -> 43922 | G27: =G13 -> 43952 | H27: =H13 -> 43983 | I27: =I13 -> 44013 | J27: =J13 -> 44044 | ... O27: =O13 -> 2020 TOTAL
A29: =A21+1 -> 8 | B29: Forecasted A&G in MISO rates (CREDIT) | C29: ='A&G Credit'!$C$17/12 -> 20827.259 | D29: ='A&G Credit'!$C$17/12 -> 20827.259 | E29: ='A&G Credit'!$C$17/12 -> 20827.259 | F29: ='A&G Credit'!$C$17/12 -> 20827.259 | G29: ='A&G Credit'!$C$17/12 -> 20827.259 | H29: ='A&G Credit'!$C$17/12 -> 20827.259 | I29: ='A&G Credit'!$C$17/12 -> 20827.259 | J29: ='A&G Credit'!$C$17/12 -> 20827.259 | ... N29: ='A&G Credit'!$C$17/12 -> 20827.259 | O29: =SUM(C29:N29) -> 249927.1
A31: Line No. | B31: Sources:
B32: Columns (a) - (b) are ACTUAL, columns (c) - (l) are FORECAST
A33: 6 | B33: January is an actual, the remaining months are an average of the previous two years.
A34: =A29+1 -> 9 | B34: Each month is 1/12 of Page 2, Column (a), Line 3.

Sheet Net Forecast Costs
A3: MIDAMERCIAN ENERGY COMPANY
A4: =Sales!A4 -> 2019 TCA RECONCILIATION and 2020 NEW FACTOR CALCULATION
O5: Page 4 of 7
A8: NET MISO COSTS
A9: Total Company Electric Operations
C11: (a) | D11: (b) | E11: (c) | F11: (d) | G11: (e) | H11: (f) | I11: (g) | J11: (h) | K11: (i) | L11: (j) | M11: (k) | N11: (l) | O11: (m)
C12: Actual | D12: Actual | E12: Forecast | F12: Forecast | G12: Forecast | H12: Forecast | I12: Forecast | J12: Forecast | K12: Forecast | L12: Forecast | M12: Forecast | N12: Forecast
A13: Line No. | C13: 43831 | D13: 43862 | E13: 43891 | F13: 43922 | G13: 43952 | H13: 43983 | I13: 44013 | J13: 44044 | K13: 44075 | L13: 44105 | M13: 44136 | N13: 44166 | O13: 2020 TOTAL
A14: 1 | B14: NET MISO COSTS | C14: ='Forecast Costs & Credits'!C21-'Forecast Costs & Credits'!C29 -> 3987485.9 | D14: ='Forecast Costs & Credits'!D21-'Forecast Costs & Credits'!D29 -> 4537621.7 | E14: ='Forecast Costs & Credits'!E21-'Forecast Costs & Credits'!E29 -> 4274459.9 | F14: ='Forecast Costs & Credits'!F21-'Forecast Costs & Credits'!F29 -> 4102351.2 | G14: ='Forecast Costs & Credits'!G21-'Forecast Costs & Credits'!G29 -> 4495963.4 | H14: ='Forecast Costs & Credits'!H21-'Forecast Costs & Credits'!H29 -> 4384116.9 | I14: ='Forecast Costs & Credits'!I21-'Forecast Costs & Credits'!I29 -> 4244187.8 | J14: ='Forecast Costs & Credits'!J21-'Forecast Costs & Credits'!J29 -> 4257455.8 | ... N14: ='Forecast Costs & Credits'!N21-'Forecast Costs & Credits'!N29 -> 3873541.7 | O14: =SUM(C14:N14) -> 51347914
A17: NET MISO COSTS
A18: IOWA ONLY
C20: =+C12 -> Actual | D20: =+D12 -> Actual | E20: Forecast | F20: Forecast | G20: Forecast | H20: Forecast | I20: Forecast | J20: Forecast | K20: Forecast | L20: Forecast | M20: Forecast | N20: Forecast
C21: =C13 -> 43831 | D21: =D13 -> 43862 | E21: =E13 -> 43891 | F21: =F13 -> 43922 | G21: =G13 -> 43952 | H21: =H13 -> 43983 | I21: =I13 -> 44013 | J21: =J13 -> 44044 | ... O21: =O13 -> 2020 TOTAL
A22: 2 | B22: IA ALLOCATION | C22: 0.9025 | D22: =$C$22 -> 0.9025 | E22: =$C$22 -> 0.9025 | F22: =$C$22 -> 0.9025 | G22: =$C$22 -> 0.9025 | H22: =$C$22 -> 0.9025 | I22: =$C$22 -> 0.9025 | J22: =$C$22 -> 0.9025 | K22: =$C$22 -> 0.9025 | ... N22: =$C$22 -> 0.9025
A23: 3 | B23: IA ALLOCATION OF NET MISO COSTS | C23: =C14*C22 -> 3598706 | D23: =D14*D22 -> 4095203.6 | E23: =E14*E22 -> 3857700.1 | F23: =F14*F22 -> 3702372 | G23: =G14*G22 -> 4057606.9 | H23: =H14*H22 -> 3956665.5 | I23: =I14*I22 -> 3830379.5 | J23: =J14*J22 -> 3842353.9 | ... N23: =N14*N22 -> 3495871.4 | O23: =SUM(C23:N23) -> 46341493
A26: NET MISO COSTS
A27: IOWA ONLY by Revenue Class
C29: =+C12 -> Actual | D29: =+D12 -> Actual | E29: Forecast | F29: Forecast | G29: Forecast | H29: Forecast | I29: Forecast | J29: Forecast | K29: Forecast | L29: Forecast | M29: Forecast | N29: Forecast
C30: =C13 -> 43831 | D30: =D13 -> 43862 | E30: =E13 -> 43891 | F30: =F13 -> 43922 | G30: =G13 -> 43952 | H30: =H13 -> 43983 | I30: =I13 -> 44013 | J30: =J13 -> 44044 | ... O30: =O13 -> 2020 TOTAL
A31: 4 | B31: Residential | C31: =C$23*$C44 -> 1128014.4 | D31: =D$23*$C44 -> 1283641.6 | E31: =E$23*$C44 -> 1209196.1 | F31: =F$23*$C44 -> 1160508.5 | G31: =G$23*$C44 -> 1271856.9 | H31: =H$23*$C44 -> 1240216.8 | I31: =I$23*$C44 -> 1200632.4 | J31: =J$23*$C44 -> 1204385.8 | ... N31: =N$23*$C44 -> 1095780.9 | O31: =SUM(C31:N31) -> 14525741
A32: 5 | B32: Small General Service Demand | C32: =C$23*$C45 -> 364153.06 | D32: =D$23*$C45 -> 414393.65 | E32: =E$23*$C45 -> 390360.67 | F32: =F$23*$C45 -> 374643.02 | G32: =G$23*$C45 -> 410589.25 | H32: =H$23*$C45 -> 400374.98 | I32: =I$23*$C45 -> 387596.1 | J32: =J$23*$C45 -> 388807.79 | ... N32: =N$23*$C45 -> 353747.22 | O32: =SUM(C32:N32) -> 4689295.7
A33: 6 | B33: Small General Service Energy | C33: =C$23*$C46 -> 276956.42 | D33: =D$23*$C46 -> 315166.87 | E33: =E$23*$C46 -> 296888.6 | F33: =F$23*$C46 -> 284934.55 | G33: =G$23*$C46 -> 312273.43 | H33: =H$23*$C46 -> 304504.98 | I33: =I$23*$C46 -> 294786.01 | J33: =J$23*$C46 -> 295707.55 | ... N33: =N$23*$C46 -> 269042.26 | O33: =SUM(C33:N33) -> 3566441.3
A34: 7 | B34: Large General Service & Substation | C34: =C$23*$C47 -> 1060934.5 | D34: =D$23*$C47 -> 1207307 | E34: =E$23*$C47 -> 1137288.6 | F34: =F$23*$C47 -> 1091496.3 | G34: =G$23*$C47 -> 1196223.1 | H34: =H$23*$C47 -> 1166464.6 | I34: =I$23*$C47 -> 1129234.2 | J34: =J$23*$C47 -> 1132764.3 | ... N34: =N$23*$C47 -> 1030617.8 | O34: =SUM(C34:N34) -> 13661936
A35: 8 | B35: Individual Contract Rates | C35: =C$23*$C48 -> 757527.62 | D35: =D$23*$C48 -> 862040.36 | E35: =E$23*$C48 -> 812045.87 | F35: =F$23*$C48 -> 779349.3 | G35: =G$23*$C48 -> 854126.26 | H35: =H$23*$C48 -> 832878.09 | I35: =I$23*$C48 -> 806294.88 | J35: =J$23*$C48 -> 808815.49 | ... N35: =N$23*$C48 -> 735880.92 | O35: =SUM(C35:N35) -> 9754884.2
A36: 9 | B36: Traffic Control Service | C36: =C$23*$C49 -> 611.78003 | D36: =D$23*$C49 -> 696.18462 | E36: =E$23*$C49 -> 655.80901 | F36: =F$23*$C49 -> 629.40324 | G36: =G$23*$C49 -> 689.79318 | H36: =H$23*$C49 -> 672.63313 | I36: =I$23*$C49 -> 651.16451 | J36: =J$23*$C49 -> 653.20016 | ... N36: =N$23*$C49 -> 594.29813 | O36: =SUM(C36:N36) -> 7878.0538
A37: 10 | B37: Water Pumping Service | C37: =C$23*$C50 -> 5829.9038 | D37: =D$23*$C50 -> 6634.2299 | E37: =E$23*$C50 -> 6249.4741 | F37: =F$23*$C50 -> 5997.8426 | G37: =G$23*$C50 -> 6573.3232 | H37: =H$23*$C50 -> 6409.7981 | I37: =I$23*$C50 -> 6205.2148 | J37: =J$23*$C50 -> 6224.6132 | ... N37: =N$23*$C50 -> 5663.3116 | O37: =SUM(C37:N37) -> 75073.218
A38: 11 | B38: Lighting | C38: =C$23*$C51 -> 4678.3179 | D38: =D$23*$C51 -> 5323.7647 | E38: =E$23*$C51 -> 5015.0101 | F38: =F$23*$C51 -> 4813.0836 | G38: =G$23*$C51 -> 5274.889 | H38: =H$23*$C51 -> 5143.6651 | I38: =I$23*$C51 -> 4979.4933 | J38: =J$23*$C51 -> 4995.06 | ... N38: =N$23*$C51 -> 4544.6328 | O38: =SUM(C38:N38) -> 60243.941
A39: 12 | B39: TOTAL | C39: =SUM(C31:C38) -> 3598706 | D39: =SUM(D31:D38) -> 4095203.6 | E39: =SUM(E31:E38) -> 3857700.1 | F39: =SUM(F31:F38) -> 3702372 | G39: =SUM(G31:G38) -> 4057606.9 | H39: =SUM(H31:H38) -> 3956665.5 | I39: =SUM(I31:I38) -> 3830379.5 | J39: =SUM(J31:J38) -> 3842353.9 | ... N39: =SUM(N31:N38) -> 3495871.4 | O39: =SUM(C39:N39) -> 46341493
B43: 12-CP ALLOCATORS:
A44: =A39+1 -> 13 | B44: Residential | C44: 0.31345
A45: =A44+1 -> 14 | B45: Small General Service Demand | C45: 0.10119
A46: =A45+1 -> 15 | B46: Small General Service Energy | C46: 0.07696
A47: =A46+1 -> 16 | B47: Large General Service & Substation | C47: 0.29481
A48: =A47+1 -> 17 | B48: Individual Contract Rates | C48: 0.2105
A49: =A48+1 -> 18 | B49: Traffic Control Service | C49: 0.00017
A50: =A49+1 -> 19 | B50: Water Pumping Service | C50: 0.00162
A51: =A50+1 -> 20 | B51: Lighting | C51: 0.0013
C52: =SUM(C44:C51) -> 1
A54: Line No. | B54: Sources:
A55: 1 | B55: Page 3, Line 7 less Line 8.
...

Sheet Actual O-U by Rev Class
A3: MIDAMERCIAN ENERGY COMPANY
A4: =Sales!A4 -> 2019 TCA RECONCILIATION and 2020 NEW FACTOR CALCULATION
P6: Page 5 of 7
A8: TCA COSTS AND REVENUE
A9: IOWA ONLY Electric Operations by REVENUE CLASS
C11: (a) | D11: (b) | E11: (c) | F11: (d) | G11: (e) | H11: (f) | I11: (g) | J11: (h) | K11: (i) | L11: (j) | M11: (k) | N11: (l) | O11: (m) | P11: (n)
C12: Over/Under | P12: Over/Under
C13: Balance at | P13: Balance at
A14: Line No. | C14: 12/31/18 | D14: 43466 | E14: 43497 | F14: 43525 | G14: 43556 | H14: 43586 | I14: 43617 | J14: 43647 | K14: 43678 | L14: 43709 | M14: 43739 | N14: 43770 | O14: 43800 | P14: 12/31/19
A15: 1 | B15: Residential - COSTS | C15: 40655885 | D15: 942669.14 | E15: 1159205 | F15: 944535.48 | G15: 1019576.1 | H15: 853678.03 | I15: 1053808.3 | J15: 1141059.3 | K15: 1273515.1 | L15: 1105751.6 | M15: 1157152.5 | N15: 895149.7 | O15: 924622.85 | P15: =SUM(C15:O15) -> 53126608
B16: MISO ROE Refund - INTEREST | C16: 297.5896 | E16: 0 | F16: 0 | G16: 0 | H16: 0 | I16: 0 | J16: 0 | K16: 0 | L16: 0 | M16: 0 | N16: 0 | O16: 0 | P16: =SUM(C16:O16) -> 297.5896
A17: 2 | B17: Residential - REVENUE | C17: 41408845 | D17: 1391169.3 | E17: 1346352.4 | F17: 1277517.4 | G17: 718622.59 | H17: 645591.54 | I17: 745195.48 | J17: 1135090.9 | K17: 1130149.3 | L17: 905025.66 | M17: 823944.22 | N17: 654439.13 | O17: 893336.72 | P17: =SUM(C17:O17) -> 53075280
A18: 3 | B18: (Under-)/Over-collection | C18: 753257.63 | D18: 448500.11 | E18: 187147.34 | F18: 332981.92 | G18: -300953.47 | H18: -208086.49 | I18: -308612.8 | J18: -5968.34 | K18: -143365.73 | L18: -200725.96 | M18: -333208.31 | N18: -240710.57 | O18: -31286.131 | P18: =SUM(C18:O18) -> -51030.801
A20: 4 | B20: SGS Demand - COSTS | C20: 15434078 | D20: 338142.27 | E20: 415815.27 | F20: 338811.74 | G20: 365729.34 | H20: 306220.51 | I20: 378008.69 | J20: 409306.26 | K20: 456819.11 | L20: 396641.14 | M20: 415079.02 | N20: 321096.7 | O20: 331668.94 | P20: =SUM(C20:O20) -> 19907417
B21: MISO ROE Refund - INTEREST | C21: 109.91841 | E21: 0 | F21: 0 | G21: 0 | H21: 0 | I21: 0 | J21: 0 | K21: 0 | L21: 0 | M21: 0 | N21: 0 | O21: 0 | P21: =SUM(C21:O21) -> 109.91841
A22: 5 | B22: SGS Demand - REVENUE | C22: 15255771 | D22: 340912.05 | E22: 343028.44 | F22: 354417.65 | G22: 327148.5 | H22: 339247.92 | I22: 331291.76 | J22: 392362.83 | K22: 384950.71 | L22: 347455.72 | M22: 387407.61 | N22: 278548.6 | O22: 289845.81 | P22: =SUM(C22:O22) -> 19372389
A23: 6 | B23: (Under-)/Over-collection | C23: -178197.52 | D23: 2769.7806 | E23: -72786.829 | F23: 15605.909 | G23: -38580.842 | H23: 33027.407 | I23: -46716.926 | J23: -16943.426 | K23: -71868.399 | L23: -49185.422 | M23: -27671.412 | N23: -42548.101 | O23: -41823.126 | P23: =SUM(C23:O23) -> -534918.91
A25: 7 | B25: SGS Energy - COSTS | C25: 8899515 | D25: 245720.13 | E25: 302163.29 | F25: 246206.62 | G25: 265767.01 | H25: 222523.33 | I25: 274690.13 | J25: 297433.34 | K25: 331959.83 | L25: 288229.9 | M25: 301628.28 | N25: 233333.51 | O25: 241016.11 | P25: =SUM(C25:O25) -> 12150187
B26: MISO ROE Refund - INTEREST | C26: 71.159403 | E26: 0 | F26: 0 | G26: 0 | H26: 0 | I26: 0 | J26: 0 | K26: 0 | L26: 0 | M26: 0 | N26: 0 | O26: 0 | P26: =SUM(C26:O26) -> 71.159403
A27: 8 | B27: SGS Energy - REVENUE | C27: 9119239.8 | D27: 315826.49 | E27: 313266.22 | F27: 303560.9 | G27: 227856.46 | H27: 187482.81 | I27: 201885.09 | J27: 266674.77 | K27: 266540.58 | L27: 236491.11 | M27: 232321.07 | N27: 250459.49 | O27: 318745.89 | P27: =SUM(C27:O27) -> 12240351
A28: 9 | B28: (Under-)/Over-collection | C28: 219795.88 | D28: 70106.362 | E28: 11102.929 | F28: 57354.283 | G28: -37910.552 | H28: -35040.519 | I28: -72805.036 | J28: -30758.572 | K28: -65419.248 | L28: -51738.789 | M28: -69307.207 | N28: 17125.98 | O28: 77729.783 | P28: =SUM(C28:O28) -> 90235.294
A30: 10 | B30: LGS & SS - COSTS | C30: 36278531 | D30: 970856.74 | E30: 1193867.5 | F30: 972778.89 | G30: 1050063.3 | H30: 879204.63 | I30: 1085319.1 | J30: 1175179.1 | K30: 1311595.6 | L30: 1138815.7 | M30: 1191753.6 | N30: 921916.38 | O30: 952270.83 | P30: =SUM(C30:O30) -> 49122152
B31: MISO ROE Refund - INTEREST | C31: 295.30995 | E31: 0 | F31: 0 | G31: 0 | H31: 0 | I31: 0 | J31: 0 | K31: 0 | L31: 0 | M31: 0 | N31: 0 | O31: 0 | P31: =SUM(C31:O31) -> 295.30995
A32: 11 | B32: LGS & SS - REVENUE | C32: 36109230 | D32: 917275.29 | E32: 919447.99 | F32: 914242.76 | G32: 1008408.4 | H32: 990501.77 | I32: 927168.77 | J32: 1107597.1 | K32: 1030429 | L32: 1015456.2 | M32: 1051448.2 | N32: 886020.97 | O32: 905976.44 | P32: =SUM(C32:O32) -> 47783203
A33: 12 | B33: (Under-)/Over-collection | C33: -169005.21 | D33: -53581.448 | E33: -274419.48 | F33: -58536.131 | G33: -41654.926 | H33: 111297.14 | I33: -158150.38 | J33: -67582.064 | K33: -281166.59 | L33: -123359.51 | M33: -140305.38 | N33: -35895.407 | O33: -46294.394 | P33: =SUM(C33:O33) -> -1338653.8
A35: 13 | B35: ICR - COSTS | C35: 18937386 | D35: 630221.99 | E35: 774987.18 | F35: 631469.73 | G35: 681638.15 | H35: 570726.93 | I35: 704524.12 | J35: 762855.83 | K35: 851409.22 | L35: 739250.87 | M35: 773614.98 | N35: 598452.84 | O35: 618157.13 | P35: =SUM(C35:O35) -> 27274695
B36: MISO ROE Refund - INTEREST | C36: 155.61832 | E36: 0 | F36: 0 | G36: 0 | H36: 0 | I36: 0 | J36: 0 | K36: 0 | L36: 0 | M36: 0 | N36: 0 | O36: 0 | P36: =SUM(C36:O36) -> 155.61832
A37: 14 | B37: ICR - REVENUE | C37: 20541568 | D37: 248797.12 | E37: 248678.3 | F37: 245575.98 | G37: 324335.08 | H37: 547167.77 | I37: 563468.29 | J37: 697525.14 | K37: 611129.67 | L37: 584823.34 | M37: 623487.22 | N37: 602644.29 | O37: 632955.54 | P37: =SUM(C37:O37) -> 26472156
A38: 15 | B38: (Under-)/Over-collection | C38: 1604337.9 | D38: -381424.87 | E38: -526308.88 | F38: -385893.75 | G38: -357303.07 | H38: -23559.161 | I38: -141055.83 | J38: -65330.688 | K38: -240279.55 | L38: -154427.53 | M38: -150127.76 | N38: 4191.4525 | O38: 14798.409 | P38: =SUM(C38:O38) -> -802383.38
A40: 16 | B40: Traffic Control - COSTS | C40: 21853.915 | D40: 577.18821 | E40: 709.77128 | F40: 578.33096 | G40: 624.27766 | H40: 522.69972 | I40: 645.23775 | J40: 698.66079 | K40: 779.76233 | L40: 677.04222 | M40: 708.51455 | N40: 548.09247 | O40: 566.13863 | P40: =SUM(C40:O40) -> 29489.631
B41: MISO ROE Refund - INTEREST | C41: 0.18491777 | E41: 0 | F41: 0 | G41: 0 | H41: 0 | I41: 0 | J41: 0 | K41: 0 | L41: 0 | M41: 0 | N41: 0 | O41: 0 | P41: =SUM(C41:O41) -> 0.18491777
A42: 17 | B42: Traffic Control - REVENUE | C42: 22034.54 | D42: 764.82 | E42: 632.24 | F42: 638.27 | G42: 590.54 | H42: 595.55 | I42: 551.86 | J42: 605.56 | K42: 591.46 | L42: 585.77 | M42: 641.66 | N42: 552.11 | O42: 653.75 | P42: =SUM(C42:O42) -> 29438.13
A43: 18 | B43: (Under-)/Over-collection | C43: 181 | D43: 187.63179 | E43: -77.531279 | F43: 59.939042 | G43: -33.73766 | H43: 72.850279 | I43: -93.37775 | J43: -93.100791 | K43: -188.30233 | L43: -91.272216 | M43: -66.85455 | N43: 4.0175333 | O43: 87.611375 | P43: =ROUND(SUM(C43:O43),0) -> -51
A45: 19 | B45: Water Pumping - COSTS | C45: 190586.03 | D45: 4754.7036 | E45: 5846.8832 | F45: 4764.1172 | G45: 5142.6124 | H45: 4305.8438 | I45: 5315.2753 | J45: 5755.3583 | K45: 6423.4485 | L45: 5577.271 | M45: 5836.5307 | N45: 4515.0216 | O45: 4663.6804 | P45: =SUM(C45:O45) -> 253486.78
B46: MISO ROE Refund - INTEREST | C46: 1.6006035 | E46: 0 | F46: 0 | G46: 0 | H46: 0 | I46: 0 | J46: 0 | K46: 0 | L46: 0 | M46: 0 | N46: 0 | O46: 0 | P46: =SUM(C46:O46) -> 1.6006035
A47: 20 | B47: Water Pumping - REVENUE | C47: 200148.18 | D47: 6728.19 | E47: 6404.74 | F47: 6993.24 | G47: 2711.4 | H47: 1187.23 | I47: 4471.89 | J47: 4321.06 | K47: 4371.1 | L47: 3622.72 | M47: 3579.5 | N47: 3090.92 | O47: 3788.79 | P47: =SUM(C47:O47) -> 251418.96
A48: 21 | B48: (Under-)/Over-collection | C48: 9563.7509 | D48: 1973.4864 | E48: 557.85679 | F48: 2229.1228 | G48: -2431.2124 | H48: -3118.6138 | I48: -843.38533 | J48: -1434.2983 | K48: -2052.3485 | L48: -1954.551 | M48: -2257.0307 | N48: -1424.1016 | O48: -874.89043 | P48: =SUM(C48:O48) -> -2066.2152
A50: 22 | B50: Lighting - COSTS | C50: 339603.64 | D50: 3690.0757 | E50: 4537.7048 | F50: 3697.3815 | G50: 3991.1276 | H50: 3341.7202 | I50: 4125.1295 | J50: 4466.6733 | K50: 4985.1711 | L50: 4328.4616 | M50: 4529.6703 | N50: 3504.061 | O50: 3619.4335 | P50: =SUM(C50:O50) -> 388420.25
B51: MISO ROE Refund - INTEREST | C51: 2.0988003 | E51: 0 | F51: 0 | G51: 0 | H51: 0 | I51: 0 | J51: 0 | K51: 0 | L51: 0 | M51: 0 | N51: 0 | O51: 0 | P51: =SUM(C51:O51) -> 2.0988003
A52: 23 | B52: Lighting - REVENUE | C52: 315373.48 | D52: 11932.18 | E52: 9819.85 | F52: 8860.92 | G52: 5032.12 | H52: 3788.29 | I52: 3063.94 | J52: 3444.17 | K52: 3927.83 | L52: 3279.23 | M52: 5093.62 | N52: 3901.08 | O52: 5237.37 | P52: =SUM(C52:O52) -> 382754.08
...

Sheet Rev Difference by Rev Class
A3: MIDAMERCIAN ENERGY COMPANY
A4: =Sales!A4 -> 2019 TCA RECONCILIATION and 2020 NEW FACTOR CALCULATION
F5: Page 6 of 7
A8: JANUARY THROUGH MARCH REVENUE DIFFERENCE
A9: IOWA ONLY Electric Operations by REVENUE CLASS
C12: Jan-20 through Mar-20
C13: (a) | D13: (b) | E13: (c) | F13: (d)
D14: Current TCA | E14: Hypothetical TCA | F14: Revenue
A15: Line No. | C15: Sales | D15: Factor | E15: Factor | F15: Difference
A16: 1 | B16: Residential - COSTS | E16: ='Net Forecast Costs'!C31+'Net Forecast Costs'!D31+'Net Forecast Costs'!E31 -> 3620852.1
A17: =A16+1 -> 2 | B17: Residential - KWH SALES | C17: =Sales!K13 -> 1.4875184e+09 | D17: 0.00183 | E17: =E16/C17 -> 0.0024341562
A18: =A17+1 -> 3 | B18: Residential - REVENUE | D18: =C17*D17 -> 2722158.7 | E18: =C17*E17 -> 3620852.1
A19: 4 | B19: (Under-)/Over-collection | F19: =D18-E18 -> -898693.4
A21: =A19+1 -> 5 | B21: SGS Demand - COSTS | E21: ='Net Forecast Costs'!C32+'Net Forecast Costs'!D32+'Net Forecast Costs'!E32 -> 1168907.4
A22: =A21+1 -> 6 | B22: SGS Demand - KW SALES | C22: =Sales!Q13 -> 1537898.8 | D22: 0.67 | E22: =E21/C22 -> 0.76006782
A23: =A22+1 -> 7 | B23: SGS Demand - REVENUE | D23: =C22*D22 -> 1030392.2 | E23: =C22*E22 -> 1168907.4
A24: =A23+1 -> 8 | B24: (Under-)/Over-collection | F24: =D23-E23 -> -138515.19
A26: =A24+1 -> 9 | B26: SGS Energy - COSTS | E26: ='Net Forecast Costs'!C33+'Net Forecast Costs'!D33+'Net Forecast Costs'!E33 -> 889011.89
A27: =A26+1 -> 10 | B27: SGS Energy - KWH SALES | C27: =Sales!K15 -> 4.0332346e+08 | D27: 0.00193 | E27: =E26/C27 -> 0.0022042157
A28: =A27+1 -> 11 | B28: SGS Energy - REVENUE | D28: =C27*D27 -> 778414.28 | E28: =C27*E27 -> 889011.89
A29: =A28+1 -> 12 | B29: (Under-)/Over-collection | F29: =D28-E28 -> -110597.61
A31: =A29+1 -> 13 | B31: LGS & SS - COSTS | E31: ='Net Forecast Costs'!C34+'Net Forecast Costs'!D34+'Net Forecast Costs'!E34 -> 3405530.1
A32: =A31+1 -> 14 | B32: LGS & SS - KW SALES | C32: =Sales!Q14 -> 4138945.4 | D32: 0.72 | E32: =E31/C32 -> 0.8228014
A33: =A32+1 -> 15 | B33: LGS & SS - REVENUE | D33: =C32*D32 -> 2980040.7 | E33: =C32*E32 -> 3405530.1
A34: =A33+1 -> 16 | B34: (Under-)/Over-collection | F34: =D33-E33 -> -425489.37
A36: =A34+1 -> 17 | B36: ICR - COSTS | E36: ='Net Forecast Costs'!C35+'Net Forecast Costs'!D35+'Net Forecast Costs'!E35 -> 2431613.9
A37: =A36+1 -> 18 | B37: ICR - KW SALES | C37: =Sales!Q15 -> 3060946.2 | D37: 0.59 | E37: =E36/C37 -> 0.79439941
A38: =A37+1 -> 19 | B38: ICR - REVENUE | D38: =C37*D37 -> 1805958.3 | E38: =C37*E37 -> 2431613.9
A39: =A38+1 -> 20 | B39: (Under-)/Over-collection | F39: =D38-E38 -> -625655.59
A41: =A39+1 -> 21 | B41: Traffic Control - COSTS | E41: ='Net Forecast Costs'!C36+'Net Forecast Costs'!D36+'Net Forecast Costs'!E36 -> 1963.7737
A42: =A41+1 -> 22 | B42: Traffic Control - KWH SALES | C42: =Sales!K18 -> 1340147.2 | D42: 0.0014 | E42: =E41/C42 -> 0.0014653418
A43: =A42+1 -> 23 | B43: Traffic Control - REVENUE | D43: =C42*D42 -> 1876.2061 | E43: =C42*E42 -> 1963.7737
A44: =A43+1 -> 24 | B44: (Under-)/Over-collection | F44: =D43-E43 -> -87.567573
A46: =A44+1 -> 25 | B46: Water Pumping - COSTS | E46: ='Net Forecast Costs'!C37+'Net Forecast Costs'!D37+'Net Forecast Costs'!E37 -> 18713.608
A47: =A46+1 -> 26 | B47: Water Pumping - KWH SALES | C47: =Sales!K19 -> 11432928 | D47: 0.00099 | E47: =E46/C47 -> 0.0016368168
A48: =A47+1 -> 27 | B48: Water Pumping - REVENUE | D48: =C47*D47 -> 11318.598 | E48: =C47*E47 -> 18713.608
A49: =A48+1 -> 28 | B49: (Under-)/Over-collection | F49: =D48-E48 -> -7395.0095
A51: =A49+1 -> 29 | B51: Lighting - COSTS | E51: ='Net Forecast Costs'!C38+'Net Forecast Costs'!D38+'Net Forecast Costs'!E38 -> 15017.093
A52: =A51+1 -> 30 | B52: Lighting - KWH SALES | C52: =Sales!K20 -> 21095344 | D52: 0.00062 | E52: =E51/C52 -> 0.00071186765
A53: =A52+1 -> 31 | B53: Lighting - REVENUE | D53: =C52*D52 -> 13079.113 | E53: =C52*E52 -> 15017.093
...

Sheet TCA factor calc
A3: MIDAMERCIAN ENERGY COMPANY
A4: =Sales!A4 -> 2019 TCA RECONCILIATION and 2020 NEW FACTOR CALCULATION
J6: Page 7 of 7
B8: TCA FACTOR CALCULATION
D11: Cumulative | G11: Forecasted | H11: Forecasted
C12: 2020 Forecasted | D12: Over/(Under) | E12: 2020 Forecast | G12: Sales (kWh) | H12: Demand (kW)
A13: Line | C13: Transmission | D13: Balance | E13: Over/(Under) | F13: Total | G13: Apr-20 through | H13: Apr-20 through | I13: TCA Rate | J13: TCA Rate
A14: No. | C14: Expense | D14: 12/31/19 | E14: Jan-Mar | F14: Recoverable | G14: Mar-21 | H14: Mar-21 | I14: $ per kWh | J14: $ per kW
C15: (a) | D15: (b) | E15: (c) | F15: (d) | G15: (e) | H15: (f) | I15: (g) | J15: (h)
F16: (a) - (b) - (c) | I16: (d) / (e) | J16: (d) / (f)
A17: 1 | B17: Residential | C17: ='Net Forecast Costs'!O31 -> 14525741 | D17: ='Actual O-U by Rev Class'!$P$18 -> -51030.801 | E17: ='Rev Difference by Rev Class'!F19 -> -898693.4 | F17: =ROUND(C17-D17-E17,0) -> 15475465 | G17: =ROUND(Sales!L13,0) -> 5981915622 | I17: =F17/G17 -> 0.0025870417
A18: =A17+1 -> 2 | B18: Small General Service Demand | C18: ='Net Forecast Costs'!O32 -> 4689295.7 | D18: ='Actual O-U by Rev Class'!$P$23 -> -534918.91 | E18: ='Rev Difference by Rev Class'!F24 -> -138515.19 | F18: =ROUND(C18-D18-E18,0) -> 5362730 | H18: =ROUND(Sales!R13,0) -> 6184516 | J18: =F18/H18 -> 0.86712202
A19: =A18+1 -> 3 | B19: Small General Service Energy | C19: ='Net Forecast Costs'!O33 -> 3566441.3 | D19: ='Actual O-U by Rev Class'!$P$28 -> 90235.294 | E19: ='Rev Difference by Rev Class'!F29 -> -110597.61 | F19: =ROUND(C19-D19-E19,0) -> 3586804 | G19: =ROUND(Sales!L15,0) -> 1621927442 | I19: =F19/G19 -> 0.0022114454
A20: =A19+1 -> 4 | B20: Large General Service & Substation | C20: ='Net Forecast Costs'!O34 -> 13661936 | D20: ='Actual O-U by Rev Class'!$P$33 -> -1338653.8 | E20: ='Rev Difference by Rev Class'!F34 -> -425489.37 | F20: =ROUND(C20-D20-E20,0) -> 15426079 | H20: =ROUND(Sales!R14,0) -> 16644381 | J20: =F20/H20 -> 0.92680401
A21: =A20+1 -> 5 | B21: Individual Contract Rates | C21: ='Net Forecast Costs'!O35 -> 9754884.2 | D21: ='Actual O-U by Rev Class'!$P$38 -> -802383.38 | E21: ='Rev Difference by Rev Class'!F39 -> -625655.59 | F21: =ROUND(C21-D21-E21,0) -> 11182923 | H21: =ROUND(Sales!R15,0) -> 12309308 | J21: =F21/H21 -> 0.90849323
A22: =A21+1 -> 6 | B22: Traffic Control Service | C22: ='Net Forecast Costs'!O36 -> 7878.0538 | D22: ='Actual O-U by Rev Class'!$P$43 -> -51 | E22: ='Rev Difference by Rev Class'!F44 -> -87.567573 | F22: =ROUND(C22-D22-E22,0) -> 8017 | G22: =ROUND(Sales!L18,0) -> 5389276 | I22: =F22/G22 -> 0.0014875839
A23: =A22+1 -> 7 | B23: Water Pumping Service | C23: ='Net Forecast Costs'!O37 -> 75073.218 | D23: ='Actual O-U by Rev Class'!$P$48 -> -2066.2152 | E23: ='Rev Difference by Rev Class'!F49 -> -7395.0095 | F23: =ROUND(C23-D23-E23,0) -> 84534 | G23: =ROUND(Sales!L19,0) -> 45976445 | I23: =F23/G23 -> 0.0018386372
A24: =A23+1 -> 8 | B24: Lighting | C24: ='Net Forecast Costs'!O38 -> 60243.941 | D24: ='Actual O-U by Rev Class'!$P$53 -> -5664.0702 | E24: ='Rev Difference by Rev Class'!F54 -> -1937.9796 | F24: =ROUND(C24-D24-E24,0) -> 67846 | G24: =ROUND(Sales!L20,0) -> 84832945 | I24: =F24/G24 -> 0.00079976005
A25: =A24+1 -> 9 | B25: Total | C25: =SUM(C17:C24) -> 46341493 | D25: =SUM(D17:D24) -> -2644532.9 | E25: =SUM(E17:E24) -> -2208371.7 | F25: =SUM(F17:F24) -> 51194398
B27: Sources:
B28: Column (a) is from Page 4, Column (m), Lines 4-11
B29: Column (b) is from Page 5, Column (n), "(Under-)/Over-collection" lines
B30: Column (c) is from Page 6, Column (d), "(Under-)/Over-collection" lines
B31: Column (e) is from Page 1, Column (e)
B32: Column (f) is from Page 1, Column (h)
